
#######################################################################
# +-----------------------------------------------------------------+ #
# |                            BO3 object                           | #
# +-----------------------------------------------------------------+ #
#######################################################################

Author: Unknown

Description: Converted version of the BO2 AcaciaSavanna5

Version: 3

SettingsMode: WriteWithoutComments


#######################################################################
# +-----------------------------------------------------------------+ #
# |                          Main settings                          | #
# +-----------------------------------------------------------------+ #
#######################################################################

Tree: true

Frequency: 1

Rarity: 5.0

RotateRandomly: true

SpawnHeight: highestSolidBlock

SpawnHeightOffset: 0

SpawnHeightVariance: 0

##############################
# Height Limits for the BO3. #
##############################

MinHeight: 62

MaxHeight: 210

######################
# Extrusion settings #
######################

ExtrudeMode: None

ExtrudeThroughBlocks: AIR

MaxBranchDepth: 10

ExcludedBiomes: All


#######################################################################
# +-----------------------------------------------------------------+ #
# |                      Source block settings                      | #
# +-----------------------------------------------------------------+ #
#######################################################################

SourceBlocks: AIR

MaxPercentageOutsideSourceBlock: 0

OutsideSourceBlock: placeAnyway

DoReplaceBlocks: true

IsOTGPlus: false


#######################################################################
# +-----------------------------------------------------------------+ #
# |                              Blocks                             | #
# +-----------------------------------------------------------------+ #
#######################################################################

Block(-4,8,2,LEAVES_2)
Block(-4,7,2,LEAVES_2)
Block(3,8,-3,LEAVES_2)
Block(1,8,-4,LEAVES_2)
Block(2,8,2,LEAVES_2)
Block(1,9,-4,LEAVES_2)
Block(-3,7,4,LEAVES_2)
Block(-3,6,4,LOG_2)
Block(-3,8,4,LEAVES_2)
Block(-7,7,3,LEAVES_2)
Block(-5,8,-2,LEAVES_2)
Block(3,8,0,LEAVES_2)
Block(-1,7,0,LEAVES_2)
Block(-2,8,6,LEAVES_2)
Block(-1,9,0,LEAVES_2)
Block(-2,7,6,LEAVES_2)
Block(-1,8,0,LEAVES_2)
Block(-2,6,6,LEAVES_2)
Block(-6,8,5,LEAVES_2)
Block(-6,7,5,LEAVES_2)
Block(-6,6,5,LEAVES_2)
Block(-1,9,-3,LEAVES_2)
Block(-1,8,-3,LEAVES_2)
Block(-1,7,-3,LEAVES_2)
Block(-3,7,-2,LEAVES_2)
Block(-5,8,7,LEAVES_2)
Block(-5,7,7,LEAVES_2)
Block(-3,8,-2,LEAVES_2)
Block(-3,9,-2,LEAVES_2)
Block(0,7,-1,LEAVES_2)
Block(3,8,-2,LEAVES_2)
Block(3,9,-2,LEAVES_2)
Block(-4,7,9,LEAVES_2)
Block(0,9,-1,LEAVES_2)
Block(0,8,-1,LEAVES_2)
Block(-5,7,9,LEAVES_2)
Block(-4,7,1,LEAVES_2)
Block(1,9,-3,LEAVES_2)
Block(1,8,-3,LEAVES_2)
Block(-3,8,3,LEAVES_2)
Block(-3,7,3,LEAVES_2)
Block(-7,7,4,LEAVES_2)
Block(-3,5,3,LOG_2)
Block(-2,9,5,LEAVES_2)
Block(-2,8,5,LEAVES_2)
Block(-2,7,5,LEAVES_2)
Block(-2,6,5,LEAVES_2)
Block(3,8,1,LEAVES_2)
Block(-6,8,6,LEAVES_2)
Block(-6,7,6,LEAVES_2)
Block(-1,7,7,LEAVES_2)
Block(-1,9,-2,LEAVES_2)
Block(-1,8,-2,LEAVES_2)
Block(-1,7,-2,LEAVES_2)
Block(-5,7,8,LEAVES_2)
Block(-3,8,-1,LEAVES_2)
Block(-3,9,-1,LEAVES_2)
Block(0,10,-1,LEAVES_2)
Block(0,7,6,LEAVES_2)
Block(-4,8,4,LEAVES_2)
Block(-4,7,4,LEAVES_2)
Block(-4,6,4,LEAVES_2)
Block(0,7,0,LEAVES_2)
Block(-4,9,4,LEAVES_2)
Block(-3,9,6,LEAVES_2)
Block(-3,8,6,LEAVES_2)
Block(1,8,-2,LEAVES_2)
Block(1,9,-2,LEAVES_2)
Block(1,7,-2,LEAVES_2)
Block(-3,7,6,LEAVES_2)
Block(-3,6,6,LEAVES_2)
Block(-6,7,8,LEAVES_2)
Block(-2,8,-5,LEAVES_2)
Block(0,8,-6,LEAVES_2)
Block(-7,8,5,LEAVES_2)
Block(-7,7,5,LEAVES_2)
Block(-4,8,-1,LEAVES_2)
Block(-2,7,8,LEAVES_2)
Block(-1,9,2,LEAVES_2)
Block(-1,8,2,LEAVES_2)
Block(-6,7,7,LEAVES_2)
Block(-2,9,0,LEAVES_2)
Block(-2,8,0,LEAVES_2)
Block(-1,9,-5,LEAVES_2)
Block(-2,7,0,LEAVES_2)
Block(-1,8,-5,LEAVES_2)
Block(-2,5,0,LOG_2)
Block(-5,7,1,LEAVES_2)
Block(0,8,1,LEAVES_2)
Block(2,9,-1,LEAVES_2)
Block(0,7,1,LEAVES_2)
Block(2,8,-1,LEAVES_2)
Block(0,9,1,LEAVES_2)
Block(-4,8,3,LEAVES_2)
Block(-4,7,3,LEAVES_2)
Block(-4,6,3,LEAVES_2)
Block(3,8,-4,LEAVES_2)
Block(-8,7,4,LEAVES_2)
Block(-3,9,5,LEAVES_2)
Block(1,9,-1,LEAVES_2)
Block(-3,6,5,LEAVES_2)
Block(1,7,-1,LEAVES_2)
Block(1,8,-1,LEAVES_2)
Block(-3,8,5,LEAVES_2)
Block(-3,7,5,LEAVES_2)
Block(-7,7,6,LEAVES_2)
Block(-5,8,-1,LEAVES_2)
Block(-2,8,7,LEAVES_2)
Block(-2,7,7,LEAVES_2)
Block(-1,8,1,LEAVES_2)
Block(-1,7,1,LEAVES_2)
Block(-1,9,1,LEAVES_2)
Block(-1,9,-4,LEAVES_2)
Block(-1,8,-4,LEAVES_2)
Block(-1,7,-4,LEAVES_2)
Block(-5,7,2,LEAVES_2)
Block(-5,8,2,LEAVES_2)
Block(2,8,-2,LEAVES_2)
Block(0,9,0,LEAVES_2)
Block(0,8,0,LEAVES_2)
Block(2,9,-2,LEAVES_2)
Block(-4,6,6,LEAVES_2)
Block(1,9,0,LEAVES_2)
Block(-4,9,6,LEAVES_2)
Block(0,8,-4,LEAVES_2)
Block(1,8,0,LEAVES_2)
Block(-4,8,6,LEAVES_2)
Block(-4,7,6,LEAVES_2)
Block(-8,7,5,LEAVES_2)
Block(-3,7,8,LEAVES_2)
Block(-2,9,-3,LEAVES_2)
Block(-2,8,-3,LEAVES_2)
Block(1,10,-3,LEAVES_2)
Block(-2,7,-3,LEAVES_2)
Block(-3,8,8,LEAVES_2)
Block(0,9,-4,LEAVES_2)
Block(-3,9,0,LEAVES_2)
Block(0,10,-4,LEAVES_2)
Block(-3,8,0,LEAVES_2)
Block(-4,8,-3,LEAVES_2)
Block(-1,7,4,LEAVES_2)
Block(-2,8,2,LEAVES_2)
Block(-2,7,2,LEAVES_2)
Block(-1,8,4,LEAVES_2)
Block(-5,6,3,LEAVES_2)
Block(-5,8,3,LEAVES_2)
Block(-1,10,-2,LEAVES_2)
Block(-5,7,3,LEAVES_2)
Block(0,8,3,LEAVES_2)
Block(2,9,-3,LEAVES_2)
Block(2,8,-3,LEAVES_2)
Block(-4,7,5,LOG_2)
Block(-4,6,5,LOG_2)
Block(1,9,1,LEAVES_2)
Block(1,8,1,LEAVES_2)
Block(-4,9,5,LEAVES_2)
Block(-4,8,5,LEAVES_2)
Block(-3,8,7,LEAVES_2)
Block(-3,7,7,LEAVES_2)
Block(-1,10,-1,LEAVES_2)
Block(4,8,-2,LEAVES_2)
Block(-3,6,7,LEAVES_2)
Block(-2,8,-4,LEAVES_2)
Block(-2,9,-4,LEAVES_2)
Block(0,9,-5,LEAVES_2)
Block(0,8,-5,LEAVES_2)
Block(-4,9,-2,LEAVES_2)
Block(-4,8,-2,LEAVES_2)
Block(-1,8,3,LEAVES_2)
Block(-1,7,3,LEAVES_2)
Block(-2,9,1,LEAVES_2)
Block(-2,8,1,LEAVES_2)
Block(-2,7,1,LEAVES_2)
Block(-1,8,-6,LEAVES_2)
Block(-6,7,2,LEAVES_2)
Block(-5,7,4,LEAVES_2)
Block(-5,6,4,LEAVES_2)
Block(-5,9,4,LEAVES_2)
Block(-5,8,4,LEAVES_2)
Block(-3,8,-5,LEAVES_2)
Block(0,9,2,LEAVES_2)
Block(0,8,2,LEAVES_2)
Block(2,9,-4,LEAVES_2)
Block(2,8,-4,LEAVES_2)
Block(3,8,-1,LEAVES_2)
Block(3,9,-1,LEAVES_2)
Block(0,8,-2,LOG_2)
Block(1,8,2,LEAVES_2)
Block(-4,8,8,LEAVES_2)
Block(0,7,-2,LEAVES_2)
Block(-4,7,8,LEAVES_2)
Block(0,9,-2,LOG_2)
Block(-4,8,0,LEAVES_2)
Block(-2,10,-2,LEAVES_2)
Block(1,8,-6,LEAVES_2)
Block(-1,10,-3,LEAVES_2)
Block(-2,9,-1,LEAVES_2)
Block(4,8,-1,LEAVES_2)
Block(2,9,0,LEAVES_2)
Block(2,8,0,LEAVES_2)
Block(-3,4,2,LOG_2)
Block(-3,7,2,LEAVES_2)
Block(-2,8,-1,LEAVES_2)
Block(-2,7,-1,LEAVES_2)
Block(-1,7,-1,LOG_2)
Block(-1,6,-1,LOG_2)
Block(-2,8,4,LEAVES_2)
Block(-2,7,4,LEAVES_2)
Block(-2,6,4,LEAVES_2)
Block(-1,7,6,LEAVES_2)
Block(-6,8,3,LEAVES_2)
Block(-1,8,6,LEAVES_2)
Block(-6,7,3,LEAVES_2)
Block(-1,9,-1,LEAVES_2)
Block(-1,8,-1,LEAVES_2)
Block(-5,6,5,LEAVES_2)
Block(-5,8,5,LEAVES_2)
Block(-5,7,5,LEAVES_2)
Block(-5,9,5,LEAVES_2)
Block(-3,8,-4,LEAVES_2)
Block(0,10,-3,LEAVES_2)
Block(0,7,5,LEAVES_2)
Block(2,8,-5,LEAVES_2)
Block(-3,0,1,LOG_2)
Block(1,8,3,LEAVES_2)
Block(0,7,-3,LEAVES_2)
Block(-4,8,7,LEAVES_2)
Block(-4,7,7,LEAVES_2)
Block(0,9,-3,LEAVES_2)
Block(-4,6,7,LEAVES_2)
Block(0,8,-3,LEAVES_2)
Block(1,9,-5,LEAVES_2)
Block(1,8,-5,LEAVES_2)
Block(-2,9,-2,LEAVES_2)
Block(-3,7,9,LEAVES_2)
Block(-2,8,-2,LEAVES_2)
Block(2,8,1,LEAVES_2)
Block(-3,8,1,LEAVES_2)
Block(0,10,-2,LEAVES_2)
Block(-3,2,1,LOG_2)
Block(-2,7,-2,LEAVES_2)
Block(-3,1,1,LOG_2)
Block(-3,4,1,LOG_2)
Block(-3,3,1,LOG_2)
Block(-1,6,5,LEAVES_2)
Block(-2,8,3,LEAVES_2)
Block(-2,7,3,LEAVES_2)
Block(-1,8,5,LEAVES_2)
Block(-1,7,5,LEAVES_2)
Block(-6,8,4,LEAVES_2)
Block(-6,7,4,LEAVES_2)
Block(-6,6,4,LEAVES_2)
Block(-4,8,-4,LEAVES_2)
Block(1,10,-2,LEAVES_2)
Block(-5,7,6,LEAVES_2)
Block(-5,6,6,LEAVES_2)
Block(-5,8,6,LEAVES_2)
Block(-3,8,-3,LEAVES_2)
Block(-3,9,-3,LEAVES_2)

#######################################################################
# +-----------------------------------------------------------------+ #
# |                            BO3 checks                           | #
# +-----------------------------------------------------------------+ #
#######################################################################

BlockCheck(-3,-1,1,GRASS,DIRT,DIRT:2)

#######################################################################
# +-----------------------------------------------------------------+ #
# |                             Branches                            | #
# +-----------------------------------------------------------------+ #
#######################################################################


#######################################################################
# +-----------------------------------------------------------------+ #
# |                             Entities                            | #
# +-----------------------------------------------------------------+ #
#######################################################################


#######################################################################
# +-----------------------------------------------------------------+ #
# |                            Particles                            | #
# +-----------------------------------------------------------------+ #
#######################################################################


#######################################################################
# +-----------------------------------------------------------------+ #
# |                             Spawners                            | #
# +-----------------------------------------------------------------+ #
#######################################################################


#######################################################################
# +-----------------------------------------------------------------+ #
# |                             ModData                             | #
# +-----------------------------------------------------------------+ #
#######################################################################

