
#######################################################################
# +-----------------------------------------------------------------+ #
# |                            BO3 object                           | #
# +-----------------------------------------------------------------+ #
#######################################################################

# This is the config file of a custom object.
# If you add this object correctly to your BiomeConfigs, it will spawn in the world.

# This is the creator of this BO3 object
Author: Unknown

# A short description of this BO3 object
Description: Converted version of the BO2 PumpkinHead1

# The BO3 version, don't change this! It can be used by external applications to do a version check.
Version: 3

# The settings mode, WriteAll, WriteWithoutComments or WriteDisable. See WorldConfig.
SettingsMode: WriteDisable


#######################################################################
# +-----------------------------------------------------------------+ #
# |                          Main settings                          | #
# +-----------------------------------------------------------------+ #
#######################################################################

# This needs to be set to true to spawn the object in the Tree and Sapling resources.
Tree: false

# The frequency of the BO3 from 1 to 200. Tries this many times to spawn this BO3 when using the CustomObject(...) resource.
# Ignored by Tree(..), Sapling(..) and CustomStructure(..)
Frequency: 1

# The rarity of the BO3 from 0 to 100. Each spawn attempt has rarity% chance to succeed when using the CustomObject(...) resource.
# Ignored by Tree(..), Sapling(..) and CustomStructure(..)
Rarity: 0.7

# If you set this to true, the BO3 will be placed with a random rotation.
RotateRandomly: true

# The spawn height of the BO3 - atMinY, randomY, highestBlock or highestSolidBlock.
SpawnHeight: highestSolidBlock

# The offset from the spawn height to spawn this BO3
# Ex. SpawnHeight = highestSolidBlock, SpawnHeightOffset = 3; This object will spawn 3 blocks above the highest solid block
SpawnHeightOffset: 0

# A random amount to offset the spawn location from the spawn offset height
# Ex. SpawnHeightOffset = 3, SpawnHeightVariance = 3; This object will spawn 3 to 6 blocks above the original spot it would have spawned
SpawnHeightVariance: 0

##############################
# Height Limits for the BO3. #
##############################

# When in randomY mode used as the minimum Y or in atMinY mode as the actual Y to spawn this BO3 at.
MinHeight: 62

# When in randomY mode used as the maximum Y to spawn this BO3 at.
MaxHeight: 111

######################
# Extrusion settings #
######################

# The style of extrusion you wish to use - BottomDown, TopUp, None (Default)
ExtrudeMode: None

# The blocks to extrude your BO3 through
ExtrudeThroughBlocks: AIR

# Objects can have other objects attacthed to it: branches. Branches can also
# have branches attached to it, which can also have branches, etc. This is the
# maximum branch depth for this objects.
MaxBranchDepth: 10

# When spawned with the UseWorld keyword, this BO3 should NOT spawn in the following biomes.
# If you write the BO3 name directly in the BiomeConfigs, this will be ignored.
ExcludedBiomes: 


#######################################################################
# +-----------------------------------------------------------------+ #
# |                      Source block settings                      | #
# +-----------------------------------------------------------------+ #
#######################################################################

# The B(s) the BO3 should spawn in.
SourceBlocks: AIR

# The maximum percentage of the BO3 that can be outside the SourceBlock.
# The BO3 won't be placed on a location with more blocks outside the SourceBlock than this percentage.
MaxPercentageOutsideSourceBlock: 100

# What to do when a block is about to be placed outside the SourceBlock? (dontPlace, placeAnyway)
OutsideSourceBlock: placeAnyway


#######################################################################
# +-----------------------------------------------------------------+ #
# |                              Blocks                             | #
# +-----------------------------------------------------------------+ #
#######################################################################

# All the blocks used in the BO3 are listed here. Possible blocks:
# B(x,y,z,id[.data][,nbtfile.nbt)
# RB(x,y,z,id[:data][,nbtfile.nbt],chance[,id[:data][,nbtfile.nbt],chance[,...]])
#  So RB(0,0,0,CHEST,chest.nbt,50,CHEST,anotherchest.nbt,100) will spawn a chest at
#  the BO3 origin, and give it a 50% chance to have the contents of chest.nbt, or, if that
#  fails, a 100% percent chance to have the contents of anotherchest.nbt.
# MinecraftObject(x,y,z,name)
#  Spawns an object in the Mojang NBT structure format. For example, 
#  MinecraftObject(0,0,0,minecraft:igloo/igloo_bottom)
#  spawns the bottom part of an igloo.
B(4,-8,-2,LOG_2:1)
B(-8,-8,0,LOG_2:1)
B(-1,-8,2,LOG_2:1)
B(1,-8,2,LOG_2:1)
B(-2,-7,-8,LOG_2:1)
B(-9,-7,-7,LOG_2:1)
B(6,-7,-7,LOG_2:1)
B(7,-7,-6,LOG_2:1)
B(-8,-7,-2,LOG_2:1)
B(4,-7,-2,LOG_2:1)
B(-8,-7,0,LOG_2:1)
B(6,-7,0,LOG_2:1)
B(9,-7,0,LOG_2:1)
B(0,-7,1,LOG_2:1)
B(3,-7,1,LOG_2:1)
B(-8,-7,2,LOG_2:1)
B(-1,-7,2,LOG_2:1)
B(1,-7,2,LOG_2:1)
B(-7,-7,6,LOG_2:1)
B(7,-7,7,LOG_2:1)
B(-2,-6,-8,LOG_2:1)
B(-9,-6,-7,LOG_2:1)
B(6,-6,-7,LOG_2:9)
B(-8,-6,-6,LOG_2:1)
B(6,-6,-6,LOG_2:1)
B(7,-6,-6,LOG_2:5)
B(4,-6,-3,LOG_2:1)
B(8,-6,-3,LOG_2:1)
B(10,-6,-3,LOG_2:1)
B(-8,-6,-2,LOG_2:1)
B(4,-6,-2,LOG_2:1)
B(-8,-6,0,LOG_2:1)
B(-5,-6,0,LOG_2:1)
B(3,-6,0,LOG_2:1)
B(6,-6,0,LOG_2:1)
B(9,-6,0,LOG_2:1)
B(-8,-6,1,161:1)
B(-3,-6,1,LOG_2:1)
B(-1,-6,1,LOG_2:5)
B(0,-6,1,LOG_2:1)
B(3,-6,1,LOG_2:9)
B(-8,-6,2,LOG_2:5)
B(-7,-6,2,LOG_2:1)
B(-1,-6,2,LOG_2:9)
B(1,-6,2,LOG_2:1)
B(1,-6,3,161:1)
B(10,-6,3,LOG_2:1)
B(-8,-6,5,161:1)
B(-7,-6,5,LOG_2:5)
B(-6,-6,5,LOG_2:1)
B(-7,-6,6,LOG_2:9)
B(-2,-6,7,LOG_2:1)
B(3,-6,7,LOG_2:1)
B(7,-6,7,LOG_2:1)
B(4,-6,8,LOG_2:1)
B(-2,-5,-9,161:1)
B(1,-5,-9,LOG_2:1)
B(-3,-5,-8,161:1)
B(-2,-5,-8,LOG_2:1)
B(-1,-5,-8,LOG_2:5)
B(-9,-5,-7,LOG_2:1)
B(-8,-5,-6,LOG_2:1)
B(6,-5,-6,LOG_2:1)
B(6,-5,-5,LOG_2:1)
B(-7,-5,-3,LOG_2:1)
B(4,-5,-3,LOG_2:1)
B(8,-5,-3,LOG_2:1)
B(10,-5,-3,LOG_2:1)
B(-9,-5,-2,161:1)
B(-8,-5,-2,LOG_2:1)
B(3,-5,-2,161:1)
B(4,-5,-2,LOG_2:1)
B(5,-5,-2,161:1)
B(-8,-5,-1,161:1)
B(-3,-5,-1,161:1)
B(-9,-5,0,161:1)
B(-8,-5,0,LOG_2:9)
B(-5,-5,0,LOG_2:5)
B(-4,-5,0,LOG_2:5)
B(-3,-5,0,LOG_2:5)
B(-2,-5,0,LOG_2:1)
B(3,-5,0,LOG_2:1)
B(6,-5,0,LOG_2:1)
B(9,-5,0,LOG_2:1)
B(10,-5,0,LOG_2:1)
B(-8,-5,1,LOG_2:1)
B(-3,-5,1,LOG_2:9)
B(0,-5,1,LOG_2:1)
B(1,-5,1,WEB)
B(3,-5,1,161:1)
B(8,-5,1,161:1)
B(9,-5,1,161:1)
B(-8,-5,2,161:1)
B(-7,-5,2,LOG_2:1)
B(-3,-5,2,161:1)
B(-2,-5,2,161:1)
B(0,-5,2,161:1)
B(1,-5,2,LOG_2:1)
B(3,-5,2,161:1)
B(-8,-5,3,161:1)
B(0,-5,3,161:1)
B(10,-5,3,LOG_2:1)
B(-6,-5,5,LOG_2:1)
B(-3,-5,5,LOG_2:1)
B(6,-5,5,LOG_2:1)
B(8,-5,5,LOG_2:1)
B(-7,-5,6,161:1)
B(-6,-5,6,161:1)
B(-5,-5,6,LOG_2:1)
B(-2,-5,7,LOG_2:1)
B(3,-5,7,LOG_2:1)
B(6,-5,7,LOG_2:1)
B(7,-5,7,LOG_2:5)
B(-2,-5,8,161:1)
B(4,-5,8,LOG_2:1)
B(0,-4,-10,161:1)
B(0,-4,-9,161:1)
B(1,-4,-9,LOG_2:9)
B(-2,-4,-8,LOG_2:9)
B(-1,-4,-8,161:1)
B(0,-4,-8,161:1)
B(1,-4,-8,LOG_2:1)
B(-9,-4,-7,LOG_2:1)
B(-7,-4,-7,161:1)
B(-3,-4,-7,LOG_2:1)
B(-2,-4,-7,LOG_2:5)
B(-9,-4,-6,161:1)
B(-8,-4,-6,LOG_2:1)
B(-7,-4,-6,LOG_2:1)
B(6,-4,-6,LOG_2:1)
B(6,-4,-5,LOG_2:1)
B(-8,-4,-3,161:1)
B(-7,-4,-3,LOG_2:1)
B(-6,-4,-3,161:1)
B(-1,-4,-3,WEB)
B(1,-4,-3,161:1)
B(4,-4,-3,LOG_2:1)
B(5,-4,-3,161:1)
B(8,-4,-3,LOG_2:1)
B(9,-4,-3,161:1)
B(10,-4,-3,LOG_2:1)
B(-8,-4,-2,LOG_2:1)
B(-7,-4,-2,161:1)
B(-6,-4,-2,161:1)
B(-1,-4,-2,161:1)
B(1,-4,-2,161:1)
B(4,-4,-2,LOG_2:9)
B(5,-4,-2,LOG_2:5)
B(-8,-4,-1,161:1)
B(-7,-4,-1,161:1)
B(-5,-4,-1,161:1)
B(-2,-4,-1,161:1)
B(-1,-4,-1,LOG_2:5)
B(0,-4,-1,LOG_2:5)
B(1,-4,-1,LOG_2:1)
B(2,-4,-1,161:1)
B(-5,-4,0,161:1)
B(-4,-4,0,161:1)
B(-2,-4,0,LOG_2:5)
B(-1,-4,0,LOG_2:9)
B(0,-4,0,161:1)
B(1,-4,0,LOG_2:9)
B(2,-4,0,LOG_2:5)
B(3,-4,0,LOG_2:5)
B(4,-4,0,161:1)
B(5,-4,0,LOG_2:1)
B(6,-4,0,LOG_2:5)
B(7,-4,0,161:1)
B(9,-4,0,LOG_2:1)
B(10,-4,0,LOG_2:5)
B(-9,-4,1,161:1)
B(-8,-4,1,LOG_2:9)
B(-3,-4,1,161:1)
B(-2,-4,1,161:1)
B(0,-4,1,LOG_2:5)
B(1,-4,1,LOG_2:9)
B(3,-4,1,161:1)
B(6,-4,1,161:1)
B(7,-4,1,161:1)
B(9,-4,1,161:1)
B(10,-4,1,161:1)
B(-9,-4,2,161:1)
B(-8,-4,2,LOG_2:1)
B(-7,-4,2,LOG_2:1)
B(0,-4,2,161:1)
B(1,-4,2,LOG_2:5)
B(2,-4,2,LOG_2:1)
B(3,-4,2,161:1)
B(0,-4,3,161:1)
B(1,-4,3,LOG_2:9)
B(10,-4,3,LOG_2:1)
B(1,-4,4,161:1)
B(10,-4,4,161:1)
B(-6,-4,5,LOG_2:1)
B(-5,-4,5,LOG_2:1)
B(-3,-4,5,LOG_2:1)
B(-2,-4,5,161:1)
B(1,-4,5,161:1)
B(6,-4,5,LOG_2:1)
B(8,-4,5,LOG_2:1)
B(9,-4,5,161:1)
B(-6,-4,6,161:1)
B(-5,-4,6,LOG_2:9)
B(-3,-4,6,161:1)
B(-2,-4,6,LOG_2:1)
B(8,-4,6,161:1)
B(-6,-4,7,161:1)
B(-5,-4,7,161:1)
B(-3,-4,7,161:1)
B(-2,-4,7,LOG_2:9)
B(1,-4,7,161:1)
B(2,-4,7,161:1)
B(3,-4,7,LOG_2:1)
B(6,-4,7,LOG_2:1)
B(7,-4,7,161:1)
B(3,-4,8,161:1)
B(4,-4,8,LOG_2:1)
B(7,-4,8,161:1)
B(1,-3,-10,161:1)
B(1,-3,-9,161:1)
B(2,-3,-9,161:1)
B(-9,-3,-8,161:1)
B(-8,-3,-8,161:1)
B(-3,-3,-8,161:1)
B(0,-3,-8,161:1)
B(1,-3,-8,LOG_2:9)
B(2,-3,-8,161:1)
B(-9,-3,-7,LOG_2:5)
B(-8,-3,-7,LOG_2:9)
B(-3,-3,-7,LOG_2:9)
B(1,-3,-7,LOG_2:1)
B(2,-3,-7,161:1)
B(-8,-3,-6,LOG_2:1)
B(-7,-3,-6,LOG_2:1)
B(-6,-3,-6,161:1)
B(-3,-3,-6,LOG_2:5)
B(-2,-3,-6,LOG_2:1)
B(6,-3,-6,LOG_2:9)
B(-8,-3,-5,161:1)
B(-6,-3,-5,161:1)
B(-3,-3,-5,161:1)
B(-2,-3,-5,161:1)
B(5,-3,-5,LOG_2:9)
B(6,-3,-5,LOG_2:5)
B(7,-3,-5,161:1)
B(10,-3,-5,161:1)
B(3,-3,-4,161:1)
B(5,-3,-4,LOG_2:1)
B(8,-3,-4,LOG_2:1)
B(9,-3,-4,161:1)
B(10,-3,-4,161:1)
B(-7,-3,-3,LOG_2:1)
B(2,-3,-3,161:1)
B(3,-3,-3,LOG_2:1)
B(4,-3,-3,LOG_2:5)
B(8,-3,-3,LOG_2:1)
B(9,-3,-3,LOG_2:1)
B(10,-3,-3,LOG_2:5)
B(-9,-3,-2,161:1)
B(-8,-3,-2,LOG_2:5)
B(-7,-3,-2,LOG_2:9)
B(0,-3,-2,161:1)
B(9,-3,-2,161:1)
B(0,-3,-1,161:1)
B(1,-3,-1,LOG_2:1)
B(5,-3,-1,LOG_2:1)
B(6,-3,-1,161:1)
B(-2,-3,0,161:1)
B(-1,-3,0,161:1)
B(3,-3,0,161:1)
B(4,-3,0,161:1)
B(5,-3,0,LOG_2:9)
B(9,-3,0,LOG_2:1)
B(10,-3,0,161:1)
B(-9,-3,1,161:1)
B(-8,-3,1,161:1)
B(-1,-3,1,161:1)
B(9,-3,1,161:1)
B(10,-3,1,161:1)
B(-9,-3,2,161:1)
B(-8,-3,2,LOG_2:5)
B(-7,-3,2,LOG_2:1)
B(-1,-3,2,161:1)
B(0,-3,2,161:1)
B(1,-3,2,161:1)
B(2,-3,2,LOG_2:1)
B(3,-3,2,161:1)
B(-8,-3,3,161:1)
B(-7,-3,3,LOG_2:9)
B(-6,-3,3,LOG_2:5)
B(-3,-3,3,161:1)
B(2,-3,3,161:1)
B(9,-3,3,LOG_2:1)
B(10,-3,3,LOG_2:1)
B(-5,-3,4,LOG_2:9)
B(-3,-3,4,161:1)
B(-2,-3,4,161:1)
B(4,-3,4,LOG_2:1)
B(8,-3,4,LOG_2:1)
B(10,-3,4,161:1)
B(-8,-3,5,161:1)
B(-7,-3,5,161:1)
B(-6,-3,5,LOG_2:5)
B(-5,-3,5,LOG_2:1)
B(-3,-3,5,LOG_2:1)
B(-2,-3,5,LOG_2:5)
B(1,-3,5,161:1)
B(2,-3,5,161:1)
B(6,-3,5,LOG_2:1)
B(8,-3,5,LOG_2:9)
B(-2,-3,6,LOG_2:9)
B(1,-3,6,161:1)
B(2,-3,6,LOG_2:1)
B(-6,-3,7,161:1)
B(-2,-3,7,161:1)
B(1,-3,7,161:1)
B(2,-3,7,LOG_2:9)
B(3,-3,7,LOG_2:5)
B(4,-3,7,LOG_2:5)
B(5,-3,7,LOG_2:5)
B(6,-3,7,LOG_2:5)
B(7,-3,7,161:1)
B(-6,-3,8,161:1)
B(3,-3,8,161:1)
B(4,-3,8,LOG_2:9)
B(5,-3,8,161:1)
B(-8,-2,-9,161:1)
B(1,-2,-9,161:1)
B(-8,-2,-8,161:1)
B(-2,-2,-8,161:1)
B(1,-2,-8,161:1)
B(2,-2,-8,161:1)
B(-3,-2,-7,LOG_2:5)
B(-2,-2,-7,LOG_2:9)
B(1,-2,-7,LOG_2:9)
B(2,-2,-7,WEB)
B(-9,-2,-6,161:1)
B(-8,-2,-6,LOG_2:1)
B(-7,-2,-6,LOG_2:1)
B(-6,-2,-6,161:1)
B(-2,-2,-6,LOG_2:9)
B(1,-2,-6,LOG_2:1)
B(6,-2,-6,161:1)
B(8,-2,-6,161:1)
B(-8,-2,-5,161:1)
B(-2,-2,-5,LOG_2:1)
B(-1,-2,-5,161:1)
B(0,-2,-5,161:1)
B(5,-2,-5,161:1)
B(8,-2,-5,161:1)
B(0,-2,-4,PUMPKIN:3)
B(1,-2,-4,161:1)
B(2,-2,-4,WEB)
B(5,-2,-4,LOG_2:1)
B(8,-2,-4,LOG_2:1)
B(-8,-2,-3,161:1)
B(-7,-2,-3,LOG_2:5)
B(-6,-2,-3,LOG_2:1)
B(0,-2,-3,PUMPKIN:0)
B(1,-2,-3,PUMPKIN:0)
B(2,-2,-3,PUMPKIN:0)
B(3,-2,-3,LOG_2:1)
B(8,-2,-3,LOG_2:1)
B(9,-2,-3,LOG_2:5)
B(10,-2,-3,161:1)
B(-9,-2,-2,161:1)
B(-7,-2,-2,161:1)
B(-1,-2,-2,PUMPKIN:0)
B(0,-2,-2,PUMPKIN:0)
B(1,-2,-2,PUMPKIN:0)
B(2,-2,-2,PUMPKIN:0)
B(3,-2,-2,PUMPKIN:0)
B(4,-2,-2,161:1)
B(5,-2,-2,161:1)
B(8,-2,-2,161:1)
B(9,-2,-2,161:1)
B(10,-2,-2,161:1)
B(-1,-2,-1,PUMPKIN:0)
B(0,-2,-1,PUMPKIN:0)
B(1,-2,-1,LOG_2:9)
B(2,-2,-1,PUMPKIN:0)
B(3,-2,-1,PUMPKIN:0)
B(4,-2,-1,161:1)
B(5,-2,-1,LOG_2:1)
B(-7,-2,0,161:1)
B(-1,-2,0,PUMPKIN:0)
B(0,-2,0,PUMPKIN:0)
B(1,-2,0,PUMPKIN:0)
B(2,-2,0,PUMPKIN:0)
B(3,-2,0,PUMPKIN:0)
B(4,-2,0,161:1)
B(5,-2,0,161:1)
B(8,-2,0,LOG_2:1)
B(9,-2,0,LOG_2:5)
B(-8,-2,1,161:1)
B(-7,-2,1,LOG_2:1)
B(0,-2,1,PUMPKIN:0)
B(1,-2,1,PUMPKIN:0)
B(2,-2,1,PUMPKIN:0)
B(4,-2,1,161:1)
B(8,-2,1,161:1)
B(-8,-2,2,161:1)
B(-7,-2,2,LOG_2:9)
B(-1,-2,2,161:1)
B(1,-2,2,LOG_2:9)
B(2,-2,2,LOG_2:1)
B(3,-2,2,LOG_2:1)
B(4,-2,2,161:1)
B(-7,-2,3,161:1)
B(-6,-2,3,LOG_2:1)
B(1,-2,3,161:1)
B(9,-2,3,LOG_2:1)
B(10,-2,3,LOG_2:5)
B(-6,-2,4,161:1)
B(-5,-2,4,LOG_2:1)
B(-4,-2,4,161:1)
B(-2,-2,4,161:1)
B(4,-2,4,LOG_2:5)
B(5,-2,4,LOG_2:1)
B(8,-2,4,LOG_2:1)
B(9,-2,4,161:1)
B(10,-2,4,161:1)
B(-7,-2,5,161:1)
B(-6,-2,5,161:1)
B(-5,-2,5,LOG_2:9)
B(-4,-2,5,161:1)
B(-3,-2,5,LOG_2:1)
B(2,-2,5,161:1)
B(3,-2,5,LOG_2:1)
B(5,-2,5,LOG_2:9)
B(6,-2,5,LOG_2:5)
B(8,-2,5,161:1)
B(-3,-2,6,161:1)
B(1,-2,6,161:1)
B(2,-2,6,LOG_2:1)
B(6,-2,6,161:1)
B(2,-2,7,161:1)
B(4,-2,7,161:1)
B(6,-2,7,161:1)
B(4,-2,8,161:1)
B(-4,-1,-8,161:1)
B(-3,-1,-8,161:1)
B(-2,-1,-8,WEB)
B(1,-1,-8,LOG_2:9)
B(-8,-1,-7,WEB)
B(-7,-1,-7,161:1)
B(-4,-1,-7,LOG_2:5)
B(-3,-1,-7,LOG_2:1)
B(-2,-1,-7,161:1)
B(0,-1,-7,161:1)
B(1,-1,-7,LOG_2:9)
B(2,-1,-7,161:1)
B(-9,-1,-6,161:1)
B(-8,-1,-6,LOG_2:5)
B(-7,-1,-6,LOG_2:1)
B(-2,-1,-6,161:1)
B(0,-1,-6,161:1)
B(1,-1,-6,LOG_2:9)
B(2,-1,-6,161:1)
B(4,-1,-6,161:1)
B(6,-1,-6,161:1)
B(-7,-1,-5,161:1)
B(-3,-1,-5,161:1)
B(-2,-1,-5,LOG_2:9)
B(-1,-1,-5,PUMPKIN:0)
B(0,-1,-5,PUMPKIN:0)
B(1,-1,-5,PUMPKIN:0)
B(2,-1,-5,PUMPKIN:0)
B(3,-1,-5,PUMPKIN:0)
B(4,-1,-5,161:1)
B(-7,-1,-4,WEB)
B(-6,-1,-4,161:1)
B(-2,-1,-4,PUMPKIN:0)
B(-1,-1,-4,PUMPKIN:0)
B(1,-1,-4,PUMPKIN:0)
B(2,-1,-4,PUMPKIN:0)
B(3,-1,-4,PUMPKIN:0)
B(4,-1,-4,PUMPKIN:0)
B(5,-1,-4,LOG_2:9)
B(8,-1,-4,LOG_2:9)
B(-7,-1,-3,161:1)
B(-6,-1,-3,LOG_2:1)
B(-5,-1,-3,LOG_2:1)
B(-3,-1,-3,PUMPKIN:0)
B(-2,-1,-3,PUMPKIN:0)
B(-1,-1,-3,PUMPKIN:0)
B(3,-1,-3,LOG_2:5)
B(4,-1,-3,PUMPKIN:0)
B(5,-1,-3,PUMPKIN:0)
B(7,-1,-3,LOG_2:1)
B(8,-1,-3,LOG_2:5)
B(9,-1,-3,LOG_2:5)
B(-7,-1,-2,161:1)
B(-6,-1,-2,161:1)
B(-3,-1,-2,PUMPKIN:0)
B(-2,-1,-2,PUMPKIN:0)
B(4,-1,-2,PUMPKIN:0)
B(5,-1,-2,PUMPKIN:0)
B(7,-1,-2,LOG_2:1)
B(8,-1,-2,LOG_2:5)
B(9,-1,-2,161:1)
B(-6,-1,-1,161:1)
B(-3,-1,-1,PUMPKIN:0)
B(-2,-1,-1,PUMPKIN:0)
B(1,-1,-1,LOG_2:1)
B(3,-1,-1,WEB)
B(4,-1,-1,PUMPKIN:0)
B(5,-1,-1,LOG_2:5)
B(-7,-1,0,161:1)
B(-6,-1,0,LOG_2:1)
B(-3,-1,0,PUMPKIN:0)
B(-2,-1,0,PUMPKIN:0)
B(1,-1,0,PUMPKIN:1)
B(4,-1,0,PUMPKIN:0)
B(5,-1,0,PUMPKIN:0)
B(8,-1,0,LOG_2:1)
B(9,-1,0,161:1)
B(10,-1,0,161:1)
B(-8,-1,1,161:1)
B(-7,-1,1,LOG_2:5)
B(-6,-1,1,LOG_2:1)
B(-3,-1,1,PUMPKIN:0)
B(-2,-1,1,PUMPKIN:0)
B(-1,-1,1,PUMPKIN:0)
B(2,-1,1,LOG_2:5)
B(3,-1,1,PUMPKIN:0)
B(4,-1,1,PUMPKIN:0)
B(5,-1,1,PUMPKIN:0)
B(8,-1,1,161:1)
B(9,-1,1,WEB)
B(-7,-1,2,161:1)
B(-2,-1,2,PUMPKIN:0)
B(-1,-1,2,PUMPKIN:0)
B(0,-1,2,PUMPKIN:0)
B(1,-1,2,PUMPKIN:0)
B(2,-1,2,LOG_2:5)
B(3,-1,2,PUMPKIN:0)
B(4,-1,2,PUMPKIN:0)
B(5,-1,2,161:1)
B(7,-1,2,LOG_2:1)
B(8,-1,2,161:1)
B(-7,-1,3,161:1)
B(-6,-1,3,LOG_2:1)
B(-1,-1,3,PUMPKIN:0)
B(0,-1,3,PUMPKIN:0)
B(1,-1,3,PUMPKIN:0)
B(2,-1,3,PUMPKIN:0)
B(3,-1,3,PUMPKIN:0)
B(5,-1,3,LOG_2:1)
B(7,-1,3,LOG_2:9)
B(8,-1,3,LOG_2:5)
B(9,-1,3,LOG_2:5)
B(-7,-1,4,161:1)
B(-6,-1,4,161:1)
B(-5,-1,4,LOG_2:5)
B(-4,-1,4,LOG_2:5)
B(-3,-1,4,LOG_2:5)
B(-2,-1,4,LOG_2:1)
B(0,-1,4,161:1)
B(1,-1,4,LOG_2:1)
B(2,-1,4,LOG_2:5)
B(5,-1,4,LOG_2:9)
B(6,-1,4,161:1)
B(7,-1,4,161:1)
B(8,-1,4,LOG_2:9)
B(9,-1,4,161:1)
B(-6,-1,5,161:1)
B(-5,-1,5,161:1)
B(-4,-1,5,161:1)
B(-3,-1,5,LOG_2:9)
B(-2,-1,5,161:1)
B(-1,-1,5,161:1)
B(0,-1,5,161:1)
B(1,-1,5,161:1)
B(2,-1,5,LOG_2:9)
B(3,-1,5,LOG_2:5)
B(5,-1,5,161:1)
B(-4,-1,6,161:1)
B(-3,-1,6,161:1)
B(1,-1,6,161:1)
B(2,-1,6,LOG_2:9)
B(-4,0,-9,161:1)
B(-5,0,-8,161:1)
B(-4,0,-8,161:1)
B(-1,0,-8,161:1)
B(0,0,-8,161:1)
B(2,0,-8,LOG_2:9)
B(-6,0,-7,161:1)
B(-5,0,-7,161:1)
B(-4,0,-7,LOG_2:5)
B(-3,0,-7,PUMPKIN:0)
B(-1,0,-7,161:1)
B(0,0,-7,LOG_2:9)
B(1,0,-7,161:1)
B(2,0,-7,161:1)
B(-8,0,-6,161:1)
B(-7,0,-6,LOG_2:5)
B(-6,0,-6,LOG_2:5)
B(-5,0,-6,PUMPKIN:0)
B(-4,0,-6,PUMPKIN:0)
B(-3,0,-6,PUMPKIN:0)
B(-2,0,-6,161:1)
B(-1,0,-6,PUMPKIN:0)
B(0,0,-6,PUMPKIN:0)
B(1,0,-6,PUMPKIN:0)
B(2,0,-6,PUMPKIN:0)
B(3,0,-6,PUMPKIN:0)
B(4,0,-6,161:1)
B(5,0,-6,161:1)
B(-7,0,-5,161:1)
B(-6,0,-5,PUMPKIN:0)
B(-5,0,-5,PUMPKIN:0)
B(-3,0,-5,PUMPKIN:0)
B(-2,0,-5,PUMPKIN:0)
B(1,0,-5,PUMPKIN:0)
B(4,0,-5,PUMPKIN:0)
B(5,0,-5,LOG_2:9)
B(6,0,-5,161:1)
B(-6,0,-4,PUMPKIN:0)
B(-5,0,-4,PUMPKIN:0)
B(-4,0,-4,PUMPKIN:0)
B(-3,0,-4,PUMPKIN:0)
B(1,0,-4,LOG_2:1)
B(4,0,-4,LOG_2:9)
B(5,0,-4,PUMPKIN:0)
B(6,0,-4,161:1)
B(7,0,-4,161:1)
B(-7,0,-3,161:1)
B(-6,0,-3,LOG_2:5)
B(-5,0,-3,LOG_2:5)
B(-4,0,-3,PUMPKIN:0)
B(-2,0,-3,LOG_2:1)
B(3,0,-3,LOG_2:1)
B(6,0,-3,PUMPKIN:0)
B(7,0,-3,LOG_2:1)
B(8,0,-3,161:1)
B(9,0,-3,161:1)
B(-6,0,-2,161:1)
B(-5,0,-2,PUMPKIN:0)
B(-4,0,-2,PUMPKIN:0)
B(-2,0,-2,LOG_2:1)
B(6,0,-2,PUMPKIN:0)
B(7,0,-2,LOG_2:5)
B(-7,0,-1,161:1)
B(-6,0,-1,PUMPKIN:1)
B(-5,0,-1,PUMPKIN:0)
B(-4,0,-1,PUMPKIN:0)
B(1,0,-1,LOG_2:1)
B(5,0,-1,LOG_2:1)
B(6,0,-1,PUMPKIN:0)
B(8,0,-1,161:1)
B(-6,0,0,LOG_2:5)
B(-5,0,0,LOG_2:9)
B(-4,0,0,PUMPKIN:0)
B(6,0,0,PUMPKIN:0)
B(7,0,0,LOG_2:1)
B(8,0,0,LOG_2:5)
B(-7,0,1,161:1)
B(-6,0,1,PUMPKIN:0)
B(-5,0,1,PUMPKIN:0)
B(-4,0,1,PUMPKIN:0)
B(2,0,1,LOG_2:1)
B(6,0,1,PUMPKIN:0)
B(8,0,1,161:1)
B(-6,0,2,LOG_2:5)
B(-5,0,2,LOG_2:5)
B(-4,0,2,LOG_2:9)
B(-3,0,2,PUMPKIN:0)
B(-2,0,2,LOG_2:1)
B(1,0,2,PUMPKIN:1)
B(2,0,2,LOG_2:1)
B(5,0,2,PUMPKIN:0)
B(6,0,2,161:1)
B(7,0,2,LOG_2:1)
B(8,0,2,161:1)
B(9,0,2,161:1)
B(-7,0,3,161:1)
B(-6,0,3,LOG_2:9)
B(-2,0,3,PUMPKIN:0)
B(-1,0,3,LOG_2:9)
B(0,0,3,WEB)
B(1,0,3,LOG_2:9)
B(4,0,3,PUMPKIN:0)
B(5,0,3,LOG_2:5)
B(7,0,3,161:1)
B(9,0,3,161:1)
B(-6,0,4,161:1)
B(-5,0,4,161:1)
B(-4,0,4,161:1)
B(-3,0,4,161:1)
B(-2,0,4,LOG_2:1)
B(-1,0,4,PUMPKIN:0)
B(0,0,4,PUMPKIN:0)
B(1,0,4,LOG_2:5)
B(2,0,4,PUMPKIN:0)
B(3,0,4,PUMPKIN:0)
B(5,0,4,161:1)
B(8,0,4,161:1)
B(-5,0,5,161:1)
B(-3,0,5,161:1)
B(-2,0,5,LOG_2:9)
B(-1,0,5,161:1)
B(0,0,5,LOG_2:9)
B(2,0,5,161:1)
B(3,0,5,161:1)
B(-4,0,6,161:1)
B(-3,0,6,161:1)
B(-1,0,6,161:1)
B(0,0,6,161:1)
B(2,0,6,161:1)
B(0,0,7,161:1)
B(-6,1,-9,161:1)
B(-5,1,-9,161:1)
B(-2,1,-9,WEB)
B(0,1,-9,161:1)
B(2,1,-9,161:1)
B(-7,1,-8,161:1)
B(-6,1,-8,161:1)
B(-5,1,-8,161:1)
B(-4,1,-8,161:1)
B(-2,1,-8,161:1)
B(-1,1,-8,161:1)
B(0,1,-8,LOG_2:9)
B(1,1,-8,161:1)
B(2,1,-8,161:1)
B(3,1,-8,LOG_2:9)
B(4,1,-8,161:1)
B(-8,1,-7,161:1)
B(-7,1,-7,161:1)
B(-6,1,-7,LOG_2:1)
B(-5,1,-7,PUMPKIN:0)
B(-3,1,-7,PUMPKIN:0)
B(-2,1,-7,PUMPKIN:0)
B(-1,1,-7,PUMPKIN:0)
B(0,1,-7,PUMPKIN:0)
B(1,1,-7,PUMPKIN:0)
B(2,1,-7,PUMPKIN:0)
B(3,1,-7,PUMPKIN:0)
B(4,1,-7,161:1)
B(-7,1,-6,161:1)
B(-6,1,-6,PUMPKIN:0)
B(-5,1,-6,PUMPKIN:0)
B(-4,1,-6,PUMPKIN:0)
B(-3,1,-6,PUMPKIN:0)
B(-2,1,-6,PUMPKIN:0)
B(-1,1,-6,PUMPKIN:0)
B(0,1,-6,PUMPKIN:0)
B(4,1,-6,PUMPKIN:0)
B(5,1,-6,161:1)
B(-6,1,-5,PUMPKIN:3)
B(-5,1,-5,PUMPKIN:0)
B(-4,1,-5,PUMPKIN:0)
B(-3,1,-5,PUMPKIN:0)
B(4,1,-5,LOG_2:1)
B(5,1,-5,PUMPKIN:0)
B(6,1,-5,161:1)
B(7,1,-5,WEB)
B(-5,1,-4,STAINED_CLAY:15)
B(-4,1,-4,PUMPKIN:0)
B(1,1,-4,LOG_2:1)
B(6,1,-4,PUMPKIN:0)
B(7,1,-4,161:1)
B(-6,1,-3,PUMPKIN:0)
B(-5,1,-3,PUMPKIN:0)
B(-3,1,-3,161:1)
B(-2,1,-3,LOG_2:1)
B(3,1,-3,LOG_2:1)
B(7,1,-3,PUMPKIN:0)
B(8,1,-3,161:1)
B(-6,1,-2,PUMPKIN:3)
B(-5,1,-2,PUMPKIN:0)
B(-2,1,-2,LOG_2:1)
B(0,1,-2,WEB)
B(7,1,-2,PUMPKIN:0)
B(8,1,-2,161:1)
B(-5,1,-1,STAINED_CLAY:15)
B(-2,1,-1,161:1)
B(1,1,-1,LOG_2:1)
B(2,1,-1,LOG_2:5)
B(4,1,-1,LOG_2:5)
B(5,1,-1,LOG_2:1)
B(7,1,-1,PUMPKIN:0)
B(8,1,-1,161:1)
B(-6,1,0,PUMPKIN:3)
B(-5,1,0,PUMPKIN:0)
B(7,1,0,LOG_2:1)
B(8,1,0,161:1)
B(9,1,0,161:1)
B(-5,1,1,STAINED_CLAY:15)
B(2,1,1,PUMPKIN:1)
B(7,1,1,PUMPKIN:0)
B(-6,1,2,PUMPKIN:0)
B(-5,1,2,PUMPKIN:0)
B(-4,1,2,PUMPKIN:0)
B(1,1,2,PUMPKIN:1)
B(2,1,2,LOG_2:1)
B(6,1,2,PUMPKIN:0)
B(7,1,2,LOG_2:5)
B(8,1,2,161:1)
B(-7,1,3,161:1)
B(-6,1,3,161:1)
B(-5,1,3,PUMPKIN:3)
B(-4,1,3,PUMPKIN:0)
B(-3,1,3,PUMPKIN:0)
B(-2,1,3,LOG_2:1)
B(-1,1,3,LOG_2:1)
B(1,1,3,LOG_2:1)
B(5,1,3,PUMPKIN:0)
B(6,1,3,LOG_2:1)
B(7,1,3,LOG_2:5)
B(8,1,3,161:1)
B(-6,1,4,161:1)
B(-5,1,4,161:1)
B(-4,1,4,PUMPKIN:0)
B(-3,1,4,PUMPKIN:0)
B(-2,1,4,LOG_2:1)
B(4,1,4,PUMPKIN:0)
B(5,1,4,161:1)
B(6,1,4,WEB)
B(7,1,4,161:1)
B(8,1,4,161:1)
B(-4,1,5,161:1)
B(-3,1,5,LOG_2:9)
B(-2,1,5,PUMPKIN:0)
B(-1,1,5,PUMPKIN:0)
B(0,1,5,PUMPKIN:0)
B(1,1,5,PUMPKIN:0)
B(2,1,5,PUMPKIN:3)
B(3,1,5,PUMPKIN:3)
B(4,1,5,161:1)
B(5,1,5,161:1)
B(7,1,5,161:1)
B(-3,1,6,161:1)
B(-2,1,6,LOG_2:9)
B(-1,1,6,161:1)
B(0,1,6,LOG_2:9)
B(1,1,6,161:1)
B(2,1,6,161:1)
B(4,1,6,161:1)
B(-2,1,7,161:1)
B(0,1,7,161:1)
B(2,1,7,161:1)
B(-1,2,-10,161:1)
B(0,2,-10,161:1)
B(-2,2,-9,161:1)
B(-1,2,-9,LOG_2:9)
B(0,2,-9,LOG_2:9)
B(1,2,-9,161:1)
B(-6,2,-8,161:1)
B(-5,2,-8,161:1)
B(-4,2,-8,LOG_2:9)
B(-2,2,-8,LOG_2:5)
B(-1,2,-8,PUMPKIN:0)
B(0,2,-8,PUMPKIN:0)
B(1,2,-8,PUMPKIN:0)
B(2,2,-8,PUMPKIN:0)
B(3,2,-8,161:1)
B(-7,2,-7,161:1)
B(-6,2,-7,LOG_2:1)
B(-5,2,-7,PUMPKIN:0)
B(-4,2,-7,PUMPKIN:0)
B(-3,2,-7,PUMPKIN:0)
B(-2,2,-7,PUMPKIN:0)
B(-1,2,-7,PUMPKIN:3)
B(0,2,-7,PUMPKIN:1)
B(1,2,-7,PUMPKIN:1)
B(2,2,-7,PUMPKIN:1)
B(3,2,-7,PUMPKIN:1)
B(4,2,-7,161:1)
B(5,2,-7,LOG_2:9)
B(6,2,-7,161:1)
B(-7,2,-6,161:1)
B(-6,2,-6,PUMPKIN:0)
B(-5,2,-6,PUMPKIN:0)
B(-4,2,-6,PUMPKIN:0)
B(-3,2,-6,PUMPKIN:0)
B(-2,2,-6,PUMPKIN)
B(-1,2,-6,PUMPKIN:1)
B(0,2,-6,PUMPKIN:1)
B(4,2,-6,PUMPKIN:3)
B(5,2,-6,161:1)
B(6,2,-6,LOG_2:9)
B(-6,2,-5,PUMPKIN:3)
B(-5,2,-5,PUMPKIN:0)
B(-4,2,-5,PUMPKIN:0)
B(-3,2,-5,PUMPKIN)
B(4,2,-5,LOG_2:1)
B(5,2,-5,PUMPKIN:3)
B(6,2,-5,LOG_2:5)
B(7,2,-5,161:1)
B(-5,2,-4,STAINED_CLAY:15)
B(-4,2,-4,PUMPKIN:3)
B(-1,2,-4,161:1)
B(2,2,-4,161:1)
B(4,2,-4,LOG_2:9)
B(6,2,-4,PUMPKIN:3)
B(7,2,-4,161:1)
B(8,2,-4,161:1)
B(-5,2,-3,STAINED_CLAY:15)
B(-2,2,-3,161:1)
B(-1,2,-3,LOG_2:5)
B(2,2,-3,LOG_2:5)
B(3,2,-3,LOG_2:1)
B(7,2,-3,PUMPKIN:0)
B(-6,2,-2,PUMPKIN:3)
B(-5,2,-2,PUMPKIN:0)
B(-1,2,-2,161:1)
B(0,2,-2,LOG_2:5)
B(1,2,-2,LOG_2:5)
B(2,2,-2,LOG_2:9)
B(7,2,-2,PUMPKIN:0)
B(-5,2,-1,STAINED_CLAY:15)
B(1,2,-1,PUMPKIN:0)
B(2,2,-1,LOG_2:1)
B(4,2,-1,LOG_2:1)
B(7,2,-1,PUMPKIN:0)
B(-5,2,0,STAINED_CLAY:15)
B(7,2,0,PUMPKIN:0)
B(8,2,0,161:1)
B(-5,2,1,STAINED_CLAY:15)
B(1,2,1,161:1)
B(2,2,1,LOG_2:9)
B(7,2,1,PUMPKIN)
B(-5,2,2,STAINED_CLAY:15)
B(-4,2,2,PUMPKIN:1)
B(2,2,2,LOG_2:1)
B(6,2,2,PUMPKIN:0)
B(7,2,2,161:1)
B(-6,2,3,PUMPKIN:3)
B(-5,2,3,PUMPKIN:3)
B(-4,2,3,PUMPKIN:1)
B(-3,2,3,PUMPKIN:1)
B(-2,2,3,LOG_2:1)
B(5,2,3,PUMPKIN:0)
B(6,2,3,LOG_2:1)
B(7,2,3,161:1)
B(-6,2,4,161:1)
B(-4,2,4,PUMPKIN:3)
B(-3,2,4,PUMPKIN:1)
B(-2,2,4,PUMPKIN:1)
B(4,2,4,PUMPKIN:0)
B(5,2,4,161:1)
B(6,2,4,161:1)
B(-3,2,5,PUMPKIN:3)
B(-2,2,5,PUMPKIN:1)
B(-1,2,5,PUMPKIN:0)
B(0,2,5,PUMPKIN:0)
B(1,2,5,PUMPKIN:0)
B(2,2,5,PUMPKIN:0)
B(3,2,5,PUMPKIN:3)
B(4,2,5,161:1)
B(-2,2,6,161:1)
B(-1,2,6,161:1)
B(0,2,6,PUMPKIN:3)
B(1,2,6,LOG_2:5)
B(2,2,6,PUMPKIN:1)
B(4,2,6,WEB)
B(0,2,7,LOG_2:9)
B(1,2,7,161:1)
B(2,2,7,LOG_2:9)
B(3,2,7,161:1)
B(0,2,8,161:1)
B(2,2,8,161:1)
B(-3,3,-9,161:1)
B(-2,3,-9,161:1)
B(-1,3,-9,161:1)
B(0,3,-9,161:1)
B(-4,3,-8,161:1)
B(-3,3,-8,LOG_2:9)
B(-2,3,-8,LOG_2:9)
B(-1,3,-8,PUMPKIN:0)
B(0,3,-8,PUMPKIN:0)
B(1,3,-8,PUMPKIN:0)
B(2,3,-8,PUMPKIN:0)
B(3,3,-8,PUMPKIN:0)
B(-6,3,-7,161:1)
B(-5,3,-7,PUMPKIN:0)
B(-4,3,-7,PUMPKIN:0)
B(-3,3,-7,PUMPKIN:0)
B(-2,3,-7,PUMPKIN:0)
B(-1,3,-7,PUMPKIN:0)
B(3,3,-7,PUMPKIN:0)
B(4,3,-7,PUMPKIN:0)
B(5,3,-7,PUMPKIN:0)
B(-6,3,-6,PUMPKIN:3)
B(-5,3,-6,PUMPKIN:0)
B(-4,3,-6,PUMPKIN:0)
B(-3,3,-6,PUMPKIN:1)
B(-1,3,-6,PUMPKIN:1)
B(0,3,-6,PUMPKIN:1)
B(4,3,-6,PUMPKIN:0)
B(6,3,-6,PUMPKIN:0)
B(-5,3,-5,STAINED_CLAY:15)
B(-4,3,-5,PUMPKIN:1)
B(5,3,-5,PUMPKIN:0)
B(7,3,-5,PUMPKIN:0)
B(-6,3,-4,PUMPKIN:3)
B(-5,3,-4,PUMPKIN:0)
B(5,3,-4,WEB)
B(6,3,-4,PUMPKIN:0)
B(7,3,-4,PUMPKIN:0)
B(-5,3,-3,STAINED_CLAY:15)
B(-1,3,-3,161:1)
B(2,3,-3,161:1)
B(3,3,-3,161:1)
B(7,3,-3,PUMPKIN:0)
B(-5,3,-2,STAINED_CLAY:15)
B(1,3,-2,161:1)
B(2,3,-2,LOG_2:1)
B(4,3,-2,161:1)
B(8,3,-2,PUMPKIN:0)
B(-5,3,-1,STAINED_CLAY:15)
B(2,3,-1,LOG_2:1)
B(4,3,-1,LOG_2:1)
B(7,3,-1,PUMPKIN:0)
B(8,3,-1,PUMPKIN:0)
B(-6,3,0,PUMPKIN:3)
B(-5,3,0,PUMPKIN:3)
B(1,3,0,161:1)
B(2,3,0,LOG_2:9)
B(7,3,0,PUMPKIN)
B(8,3,0,PUMPKIN)
B(-5,3,1,STAINED_CLAY:15)
B(2,3,1,PUMPKIN:1)
B(7,3,1,PUMPKIN:0)
B(-6,3,2,PUMPKIN:0)
B(-5,3,2,PUMPKIN:0)
B(6,3,2,PUMPKIN:1)
B(7,3,2,PUMPKIN:0)
B(-6,3,3,PUMPKIN:3)
B(-5,3,3,PUMPKIN:0)
B(-4,3,3,PUMPKIN:3)
B(5,3,3,PUMPKIN)
B(6,3,3,LOG_2:5)
B(7,3,3,PUMPKIN)
B(-5,3,4,PUMPKIN:3)
B(-4,3,4,PUMPKIN:3)
B(-3,3,4,PUMPKIN:3)
B(4,3,4,PUMPKIN)
B(6,3,4,PUMPKIN)
B(-3,3,5,PUMPKIN:3)
B(-2,3,5,PUMPKIN:3)
B(-1,3,5,PUMPKIN:0)
B(3,3,5,PUMPKIN:0)
B(4,3,5,PUMPKIN:3)
B(5,3,5,PUMPKIN)
B(-1,3,6,PUMPKIN:3)
B(0,3,6,PUMPKIN:0)
B(1,3,6,PUMPKIN:0)
B(2,3,6,PUMPKIN:0)
B(3,3,6,PUMPKIN)
B(-3,3,7,161:1)
B(-2,3,7,LOG_2:5)
B(-1,3,7,LOG_2:9)
B(0,3,7,LOG_2:5)
B(1,3,7,PUMPKIN:3)
B(2,3,7,PUMPKIN)
B(3,3,7,LOG_2:9)
B(4,3,7,161:1)
B(-2,3,8,161:1)
B(-1,3,8,161:1)
B(0,3,8,161:1)
B(1,3,8,161:1)
B(2,3,8,WEB)
B(3,3,8,161:1)
B(-3,4,-9,161:1)
B(-1,4,-9,WEB)
B(-4,4,-8,WEB)
B(-3,4,-8,LOG_2:9)
B(-2,4,-8,PUMPKIN:0)
B(-1,4,-8,PUMPKIN:0)
B(1,4,-8,PUMPKIN:0)
B(2,4,-8,PUMPKIN:0)
B(3,4,-8,PUMPKIN:0)
B(4,4,-8,PUMPKIN:0)
B(-5,4,-7,PUMPKIN:0)
B(-4,4,-7,PUMPKIN:0)
B(-3,4,-7,PUMPKIN:0)
B(-2,4,-7,PUMPKIN:0)
B(-1,4,-7,PUMPKIN:0)
B(0,4,-7,PUMPKIN:0)
B(3,4,-7,PUMPKIN:3)
B(4,4,-7,PUMPKIN:0)
B(5,4,-7,PUMPKIN:0)
B(-6,4,-6,PUMPKIN:0)
B(-5,4,-6,PUMPKIN:0)
B(-4,4,-6,PUMPKIN:0)
B(-3,4,-6,PUMPKIN:1)
B(-1,4,-6,PUMPKIN:1)
B(0,4,-6,PUMPKIN:1)
B(5,4,-6,PUMPKIN:0)
B(6,4,-6,PUMPKIN:0)
B(-6,4,-5,PUMPKIN:0)
B(-5,4,-5,PUMPKIN:0)
B(-4,4,-5,PUMPKIN:1)
B(4,4,-5,PUMPKIN)
B(5,4,-5,PUMPKIN:1)
B(6,4,-5,PUMPKIN:1)
B(7,4,-5,PUMPKIN:0)
B(-6,4,-4,PUMPKIN:3)
B(-5,4,-4,PUMPKIN:0)
B(7,4,-4,PUMPKIN:0)
B(-5,4,-3,STAINED_CLAY:15)
B(4,4,-3,161:1)
B(8,4,-3,PUMPKIN:0)
B(-6,4,-2,PUMPKIN:3)
B(-5,4,-2,PUMPKIN:0)
B(2,4,-2,161:1)
B(4,4,-2,161:1)
B(8,4,-2,PUMPKIN)
B(-5,4,-1,STAINED_CLAY:15)
B(1,4,-1,161:1)
B(2,4,-1,LOG_2:1)
B(4,4,-1,LOG_2:1)
B(7,4,-1,PUMPKIN:0)
B(-6,4,0,PUMPKIN:0)
B(-5,4,0,PUMPKIN:3)
B(7,4,0,PUMPKIN)
B(8,4,0,PUMPKIN:0)
B(-6,4,1,PUMPKIN:0)
B(-5,4,1,STAINED_CLAY:15)
B(8,4,1,PUMPKIN)
B(-6,4,2,PUMPKIN:0)
B(-5,4,2,PUMPKIN:0)
B(7,4,2,PUMPKIN:0)
B(-6,4,3,PUMPKIN:0)
B(-5,4,3,PUMPKIN:0)
B(5,4,3,PUMPKIN:0)
B(6,4,3,PUMPKIN:1)
B(7,4,3,PUMPKIN)
B(-6,4,4,PUMPKIN:3)
B(-5,4,4,PUMPKIN:0)
B(-4,4,4,PUMPKIN:0)
B(5,4,4,PUMPKIN)
B(6,4,4,PUMPKIN)
B(-5,4,5,PUMPKIN:3)
B(-4,4,5,PUMPKIN:3)
B(-3,4,5,PUMPKIN:3)
B(-2,4,5,PUMPKIN:0)
B(4,4,5,PUMPKIN:0)
B(5,4,5,PUMPKIN)
B(-2,4,6,PUMPKIN:3)
B(-1,4,6,PUMPKIN:0)
B(0,4,6,PUMPKIN:0)
B(1,4,6,PUMPKIN:0)
B(2,4,6,PUMPKIN:0)
B(3,4,6,PUMPKIN:0)
B(4,4,6,PUMPKIN)
B(-3,4,7,161:1)
B(-2,4,7,LOG_2:9)
B(-1,4,7,PUMPKIN:3)
B(0,4,7,PUMPKIN:3)
B(1,4,7,PUMPKIN:3)
B(2,4,7,PUMPKIN:3)
B(3,4,7,PUMPKIN)
B(-2,4,8,161:1)
B(-4,5,-8,PUMPKIN:0)
B(-3,5,-8,PUMPKIN:0)
B(-2,5,-8,PUMPKIN:0)
B(1,5,-8,WEB)
B(2,5,-8,PUMPKIN:0)
B(3,5,-8,PUMPKIN:0)
B(-5,5,-7,PUMPKIN:0)
B(-4,5,-7,PUMPKIN:0)
B(-3,5,-7,PUMPKIN:0)
B(-2,5,-7,PUMPKIN:0)
B(-1,5,-7,PUMPKIN:0)
B(0,5,-7,PUMPKIN:0)
B(1,5,-7,PUMPKIN:0)
B(2,5,-7,PUMPKIN:0)
B(3,5,-7,PUMPKIN:3)
B(4,5,-7,PUMPKIN:0)
B(5,5,-7,PUMPKIN:0)
B(-6,5,-6,PUMPKIN:3)
B(-5,5,-6,PUMPKIN:0)
B(-4,5,-6,PUMPKIN:0)
B(-3,5,-6,PUMPKIN:1)
B(-1,5,-6,PUMPKIN)
B(0,5,-6,PUMPKIN:1)
B(2,5,-6,PUMPKIN:0)
B(3,5,-6,PUMPKIN:0)
B(4,5,-6,PUMPKIN:0)
B(5,5,-6,PUMPKIN:0)
B(6,5,-6,PUMPKIN:0)
B(-5,5,-5,STAINED_CLAY:15)
B(-4,5,-5,PUMPKIN:1)
B(7,5,-5,PUMPKIN:0)
B(-6,5,-4,PUMPKIN:0)
B(-5,5,-4,PUMPKIN:0)
B(7,5,-4,PUMPKIN:0)
B(-6,5,-3,PUMPKIN:0)
B(-5,5,-3,PUMPKIN:0)
B(8,5,-3,PUMPKIN:0)
B(-6,5,-2,PUMPKIN:0)
B(-5,5,-2,PUMPKIN:0)
B(3,5,-2,161:1)
B(8,5,-2,PUMPKIN)
B(-6,5,-1,PUMPKIN:0)
B(-5,5,-1,PUMPKIN:3)
B(1,5,-1,LOG_2:1)
B(2,5,-1,LOG_2:1)
B(3,5,-1,LOG_2:1)
B(7,5,-1,PUMPKIN:0)
B(-6,5,0,PUMPKIN:3)
B(-5,5,0,PUMPKIN:3)
B(7,5,0,PUMPKIN)
B(-5,5,1,STAINED_CLAY:15)
B(8,5,1,PUMPKIN:1)
B(-5,5,2,STAINED_CLAY:15)
B(7,5,2,PUMPKIN:1)
B(-6,5,3,PUMPKIN:0)
B(-5,5,3,PUMPKIN:0)
B(4,5,3,WEB)
B(5,5,3,PUMPKIN:0)
B(6,5,3,PUMPKIN:0)
B(-6,5,4,PUMPKIN:3)
B(-5,5,4,PUMPKIN:3)
B(-4,5,4,PUMPKIN:0)
B(6,5,4,PUMPKIN)
B(-4,5,5,PUMPKIN:3)
B(-3,5,5,PUMPKIN:3)
B(-2,5,5,PUMPKIN:0)
B(4,5,5,PUMPKIN:0)
B(5,5,5,PUMPKIN)
B(6,5,5,WEB)
B(-3,5,6,161:1)
B(-2,5,6,PUMPKIN:3)
B(-1,5,6,PUMPKIN:0)
B(0,5,6,PUMPKIN:0)
B(1,5,6,PUMPKIN:0)
B(2,5,6,PUMPKIN:3)
B(3,5,6,PUMPKIN:0)
B(4,5,6,PUMPKIN)
B(-2,5,7,161:1)
B(-1,5,7,PUMPKIN:3)
B(0,5,7,PUMPKIN:3)
B(1,5,7,PUMPKIN:1)
B(2,5,7,WEB)
B(3,5,7,PUMPKIN)
B(-4,6,-8,PUMPKIN:0)
B(-3,6,-8,PUMPKIN:0)
B(-5,6,-7,PUMPKIN:0)
B(-4,6,-7,PUMPKIN:0)
B(-3,6,-7,PUMPKIN:0)
B(-2,6,-7,PUMPKIN:0)
B(-1,6,-7,PUMPKIN:0)
B(0,6,-7,PUMPKIN:0)
B(1,6,-7,PUMPKIN:0)
B(2,6,-7,PUMPKIN:0)
B(-6,6,-6,PUMPKIN:3)
B(-5,6,-6,PUMPKIN:0)
B(-4,6,-6,PUMPKIN:0)
B(-3,6,-6,PUMPKIN:1)
B(-1,6,-6,PUMPKIN)
B(1,6,-6,PUMPKIN:0)
B(2,6,-6,PUMPKIN:0)
B(4,6,-6,PUMPKIN:0)
B(5,6,-6,PUMPKIN:0)
B(-5,6,-5,STAINED_CLAY:15)
B(-4,6,-5,PUMPKIN:1)
B(2,6,-5,PUMPKIN:0)
B(3,6,-5,PUMPKIN:0)
B(4,6,-5,PUMPKIN:0)
B(5,6,-5,PUMPKIN:0)
B(6,6,-5,PUMPKIN:0)
B(7,6,-5,PUMPKIN:0)
B(-5,6,-4,STAINED_CLAY:15)
B(5,6,-4,PUMPKIN:0)
B(6,6,-4,PUMPKIN:0)
B(7,6,-4,PUMPKIN:0)
B(-6,6,-3,PUMPKIN:0)
B(-5,6,-3,PUMPKIN:0)
B(6,6,-3,PUMPKIN:0)
B(7,6,-3,PUMPKIN:0)
B(-6,6,-2,PUMPKIN:0)
B(-5,6,-2,PUMPKIN:0)
B(1,6,-2,161:1)
B(2,6,-2,161:1)
B(8,6,-2,PUMPKIN:1)
B(-6,6,-1,PUMPKIN:3)
B(-5,6,-1,PUMPKIN:3)
B(1,6,-1,LOG_2:1)
B(2,6,-1,PUMPKIN:0)
B(7,6,-1,PUMPKIN)
B(-5,6,0,STAINED_CLAY:15)
B(0,6,0,161:1)
B(1,6,0,LOG_2:9)
B(7,6,0,PUMPKIN)
B(-5,6,1,STAINED_CLAY:15)
B(8,6,1,PUMPKIN:1)
B(-5,6,2,STAINED_CLAY:15)
B(7,6,2,PUMPKIN:1)
B(-6,6,3,PUMPKIN:0)
B(-5,6,3,PUMPKIN:0)
B(5,6,3,PUMPKIN:0)
B(6,6,3,PUMPKIN:0)
B(-6,6,4,PUMPKIN:3)
B(-5,6,4,PUMPKIN:3)
B(-4,6,4,PUMPKIN:3)
B(4,6,4,PUMPKIN:0)
B(5,6,4,PUMPKIN:0)
B(6,6,4,PUMPKIN)
B(-3,6,5,PUMPKIN:3)
B(-2,6,5,PUMPKIN:3)
B(-1,6,5,PUMPKIN:0)
B(0,6,5,PUMPKIN:0)
B(1,6,5,WEB)
B(2,6,5,PUMPKIN:0)
B(4,6,5,PUMPKIN:0)
B(5,6,5,PUMPKIN:0)
B(-3,6,6,WEB)
B(-1,6,6,PUMPKIN:3)
B(0,6,6,PUMPKIN:0)
B(1,6,6,PUMPKIN:3)
B(2,6,6,PUMPKIN:3)
B(3,6,6,PUMPKIN:3)
B(4,6,6,PUMPKIN:3)
B(5,6,6,PUMPKIN)
B(0,6,7,PUMPKIN)
B(-3,7,-8,PUMPKIN:0)
B(-2,7,-8,PUMPKIN:0)
B(-5,7,-7,PUMPKIN:0)
B(-4,7,-7,PUMPKIN:0)
B(-3,7,-7,PUMPKIN:0)
B(-2,7,-7,PUMPKIN:0)
B(-1,7,-7,PUMPKIN:0)
B(0,7,-7,PUMPKIN:0)
B(1,7,-7,PUMPKIN:0)
B(-6,7,-6,PUMPKIN:3)
B(-5,7,-6,PUMPKIN:0)
B(-4,7,-6,PUMPKIN:0)
B(-3,7,-6,PUMPKIN:1)
B(1,7,-6,PUMPKIN:0)
B(-5,7,-5,STAINED_CLAY:15)
B(0,7,-5,WEB)
B(1,7,-5,PUMPKIN:0)
B(2,7,-5,PUMPKIN:0)
B(-5,7,-4,STAINED_CLAY:15)
B(1,7,-4,PUMPKIN:0)
B(2,7,-4,PUMPKIN:0)
B(3,7,-4,PUMPKIN:0)
B(4,7,-4,PUMPKIN:0)
B(5,7,-4,PUMPKIN:0)
B(7,7,-4,WEB)
B(-5,7,-3,STAINED_CLAY:15)
B(2,7,-3,PUMPKIN:0)
B(4,7,-3,PUMPKIN:0)
B(5,7,-3,PUMPKIN:0)
B(6,7,-3,PUMPKIN:0)
B(7,7,-3,PUMPKIN:0)
B(-6,7,-2,PUMPKIN:3)
B(-5,7,-2,PUMPKIN:0)
B(8,7,-2,PUMPKIN:0)
B(-5,7,-1,STAINED_CLAY:15)
B(8,7,-1,PUMPKIN:0)
B(-5,7,0,STAINED_CLAY:15)
B(1,7,0,LOG_2:1)
B(2,7,0,WEB)
B(8,7,0,PUMPKIN)
B(-5,7,1,STAINED_CLAY:15)
B(7,7,1,PUMPKIN:1)
B(-6,7,2,PUMPKIN:0)
B(-5,7,2,PUMPKIN:0)
B(6,7,2,PUMPKIN:0)
B(-6,7,3,PUMPKIN:3)
B(-5,7,3,PUMPKIN)
B(5,7,3,PUMPKIN:1)
B(6,7,3,PUMPKIN:1)
B(-4,7,4,PUMPKIN:3)
B(-3,7,4,WEB)
B(0,7,4,PUMPKIN:0)
B(4,7,4,PUMPKIN:0)
B(-3,7,5,PUMPKIN:3)
B(-2,7,5,PUMPKIN:3)
B(-1,7,5,PUMPKIN:3)
B(0,7,5,PUMPKIN:3)
B(1,7,5,PUMPKIN:3)
B(2,7,5,PUMPKIN:3)
B(4,7,5,PUMPKIN:0)
B(3,7,6,PUMPKIN:3)
B(4,7,6,PUMPKIN)
B(-2,8,-8,PUMPKIN:0)
B(-1,8,-8,PUMPKIN:0)
B(-4,8,-7,WEB)
B(-3,8,-7,PUMPKIN:0)
B(-2,8,-7,PUMPKIN:0)
B(-1,8,-7,PUMPKIN:0)
B(0,8,-7,PUMPKIN:0)
B(-5,8,-6,PUMPKIN:0)
B(-4,8,-6,PUMPKIN:0)
B(-3,8,-6,PUMPKIN:0)
B(0,8,-6,PUMPKIN:0)
B(-6,8,-5,PUMPKIN:3)
B(-5,8,-5,PUMPKIN:3)
B(-4,8,-5,PUMPKIN:0)
B(1,8,-5,PUMPKIN:0)
B(-5,8,-4,STAINED_CLAY:15)
B(1,8,-4,PUMPKIN:0)
B(2,8,-4,PUMPKIN:0)
B(3,8,-4,PUMPKIN:0)
B(-5,8,-3,STAINED_CLAY:15)
B(3,8,-3,PUMPKIN:0)
B(4,8,-3,PUMPKIN:0)
B(-6,8,-2,PUMPKIN:3)
B(-5,8,-2,PUMPKIN:0)
B(3,8,-2,PUMPKIN:0)
B(4,8,-2,PUMPKIN:0)
B(5,8,-2,PUMPKIN:0)
B(6,8,-2,PUMPKIN:0)
B(7,8,-2,PUMPKIN:0)
B(-5,8,-1,STAINED_CLAY:15)
B(0,8,-1,161:1)
B(1,8,-1,161:1)
B(4,8,-1,PUMPKIN:0)
B(7,8,-1,PUMPKIN:0)
B(-5,8,0,STAINED_CLAY:15)
B(0,8,0,161:1)
B(1,8,0,LOG_2:1)
B(7,8,0,PUMPKIN:1)
B(-6,8,1,PUMPKIN:0)
B(-5,8,1,PUMPKIN:0)
B(6,8,1,PUMPKIN:0)
B(-6,8,2,PUMPKIN:3)
B(-5,8,2,PUMPKIN:0)
B(6,8,2,PUMPKIN:1)
B(-5,8,3,PUMPKIN:3)
B(-4,8,3,PUMPKIN:3)
B(-3,8,3,PUMPKIN:0)
B(-2,8,3,PUMPKIN:0)
B(5,8,3,PUMPKIN:1)
B(-3,8,4,PUMPKIN:3)
B(-2,8,4,PUMPKIN:0)
B(-1,8,4,PUMPKIN:0)
B(0,8,4,PUMPKIN:0)
B(1,8,4,PUMPKIN:0)
B(2,8,4,PUMPKIN:3)
B(4,8,4,PUMPKIN:0)
B(-2,8,5,PUMPKIN:3)
B(-1,8,5,PUMPKIN:3)
B(0,8,5,PUMPKIN:3)
B(1,8,5,PUMPKIN:1)
B(3,8,5,PUMPKIN:0)
B(4,8,5,PUMPKIN)
B(3,8,6,PUMPKIN)
B(-2,9,-8,WEB)
B(-1,9,-8,PUMPKIN:0)
B(0,9,-8,PUMPKIN:0)
B(-3,9,-7,PUMPKIN:0)
B(-2,9,-7,PUMPKIN:0)
B(-1,9,-7,PUMPKIN:0)
B(0,9,-7,PUMPKIN:0)
B(1,9,-7,PUMPKIN:1)
B(-4,9,-6,PUMPKIN:0)
B(-3,9,-6,PUMPKIN:0)
B(-2,9,-6,PUMPKIN:0)
B(-1,9,-6,WEB)
B(0,9,-6,PUMPKIN:0)
B(-5,9,-5,PUMPKIN:0)
B(-4,9,-5,PUMPKIN:0)
B(-3,9,-5,PUMPKIN:0)
B(0,9,-5,PUMPKIN:0)
B(-6,9,-4,PUMPKIN:0)
B(-5,9,-4,PUMPKIN:0)
B(-4,9,-4,PUMPKIN:0)
B(1,9,-4,PUMPKIN:0)
B(-6,9,-3,PUMPKIN:0)
B(-5,9,-3,PUMPKIN:0)
B(2,9,-3,PUMPKIN:0)
B(3,9,-3,PUMPKIN:0)
B(-6,9,-2,PUMPKIN:0)
B(-5,9,-2,PUMPKIN:0)
B(3,9,-2,PUMPKIN:0)
B(5,9,-2,PUMPKIN:0)
B(-6,9,-1,PUMPKIN:0)
B(-5,9,-1,PUMPKIN:0)
B(1,9,-1,161:1)
B(4,9,-1,PUMPKIN:0)
B(5,9,-1,PUMPKIN:0)
B(6,9,-1,PUMPKIN:1)
B(7,9,-1,PUMPKIN:1)
B(-6,9,0,PUMPKIN:3)
B(-5,9,0,PUMPKIN:0)
B(-1,9,0,161:1)
B(0,9,0,161:1)
B(1,9,0,LOG_2:1)
B(6,9,0,PUMPKIN:1)
B(-6,9,1,WEB)
B(-5,9,1,PUMPKIN:0)
B(1,9,1,161:1)
B(5,9,1,WEB)
B(6,9,1,PUMPKIN:1)
B(-5,9,2,PUMPKIN:3)
B(-4,9,2,PUMPKIN:3)
B(-3,9,2,PUMPKIN:3)
B(-2,9,2,PUMPKIN:0)
B(-1,9,2,PUMPKIN:0)
B(5,9,2,PUMPKIN:1)
B(-2,9,3,PUMPKIN:3)
B(-1,9,3,PUMPKIN:0)
B(0,9,3,PUMPKIN:0)
B(4,9,3,PUMPKIN:0)
B(-1,9,4,PUMPKIN:0)
B(0,9,4,PUMPKIN:0)
B(1,9,4,PUMPKIN:3)
B(2,9,4,PUMPKIN:3)
B(3,9,4,PUMPKIN:0)
B(4,9,4,PUMPKIN)
B(-1,9,5,PUMPKIN:3)
B(0,9,5,PUMPKIN)
B(1,9,5,WEB)
B(3,9,5,PUMPKIN)
B(-2,10,-7,PUMPKIN:0)
B(0,10,-7,PUMPKIN:0)
B(1,10,-7,PUMPKIN:0)
B(-3,10,-6,PUMPKIN:0)
B(-2,10,-6,PUMPKIN:0)
B(-1,10,-6,PUMPKIN:0)
B(0,10,-6,PUMPKIN:0)
B(1,10,-6,PUMPKIN:1)
B(2,10,-6,PUMPKIN:1)
B(-3,10,-5,PUMPKIN:0)
B(-2,10,-5,PUMPKIN:0)
B(0,10,-5,PUMPKIN:0)
B(-4,10,-4,PUMPKIN:0)
B(-3,10,-4,PUMPKIN:0)
B(1,10,-4,PUMPKIN:0)
B(-4,10,-3,PUMPKIN:0)
B(2,10,-3,PUMPKIN:0)
B(-4,10,-2,PUMPKIN:0)
B(3,10,-2,PUMPKIN:0)
B(4,10,-2,WEB)
B(-4,10,-1,PUMPKIN:0)
B(0,10,-1,161:1)
B(1,10,-1,LOG_2:1)
B(4,10,-1,PUMPKIN:0)
B(5,10,-1,PUMPKIN:0)
B(6,10,-1,PUMPKIN:0)
B(-4,10,0,PUMPKIN:0)
B(1,10,0,LOG_2:9)
B(6,10,0,PUMPKIN:0)
B(-4,10,1,PUMPKIN:0)
B(-2,10,1,PUMPKIN:3)
B(0,10,1,161:1)
B(1,10,1,LOG_2:9)
B(5,10,1,PUMPKIN:1)
B(6,10,1,PUMPKIN)
B(-4,10,2,PUMPKIN:3)
B(-3,10,2,PUMPKIN)
B(-1,10,2,PUMPKIN:0)
B(0,10,2,PUMPKIN:0)
B(4,10,2,PUMPKIN:1)
B(-1,10,3,PUMPKIN:0)
B(0,10,3,PUMPKIN:0)
B(1,10,3,PUMPKIN:0)
B(2,10,3,PUMPKIN:0)
B(3,10,3,PUMPKIN:0)
B(-1,10,4,PUMPKIN:3)
B(0,10,4,PUMPKIN:0)
B(1,10,4,PUMPKIN:3)
B(2,10,4,PUMPKIN:3)
B(3,10,4,PUMPKIN)
B(0,10,5,PUMPKIN)
B(-2,11,-5,WEB)
B(-1,11,-5,PUMPKIN:0)
B(0,11,-5,PUMPKIN:0)
B(1,11,-5,PUMPKIN:0)
B(2,11,-5,PUMPKIN:0)
B(-2,11,-4,PUMPKIN:0)
B(-1,11,-4,PUMPKIN:0)
B(0,11,-4,PUMPKIN:0)
B(1,11,-4,PUMPKIN:0)
B(2,11,-4,PUMPKIN:0)
B(-3,11,-3,PUMPKIN:0)
B(-2,11,-3,PUMPKIN:0)
B(-1,11,-3,PUMPKIN:0)
B(3,11,-3,PUMPKIN:0)
B(-3,11,-2,PUMPKIN:0)
B(-2,11,-2,PUMPKIN:0)
B(3,11,-2,PUMPKIN:0)
B(4,11,-2,PUMPKIN:0)
B(-3,11,-1,PUMPKIN:0)
B(-2,11,-1,PUMPKIN:0)
B(1,11,-1,LOG_2:1)
B(4,11,-1,PUMPKIN:0)
B(5,11,-1,PUMPKIN:0)
B(-3,11,0,PUMPKIN:0)
B(-2,11,0,PUMPKIN:0)
B(4,11,0,PUMPKIN:0)
B(5,11,0,WEB)
B(6,11,0,PUMPKIN:1)
B(-3,11,1,PUMPKIN:3)
B(-2,11,1,PUMPKIN:0)
B(-1,11,1,PUMPKIN:0)
B(1,11,1,PUMPKIN:0)
B(3,11,1,PUMPKIN:0)
B(4,11,1,PUMPKIN:0)
B(5,11,1,PUMPKIN:1)
B(-2,11,2,PUMPKIN:3)
B(-1,11,2,PUMPKIN:0)
B(0,11,2,PUMPKIN:0)
B(3,11,2,PUMPKIN:0)
B(4,11,2,PUMPKIN)
B(-1,11,3,PUMPKIN:3)
B(2,11,3,PUMPKIN:3)
B(3,11,3,PUMPKIN)
B(0,11,4,PUMPKIN:3)
B(1,11,4,PUMPKIN:3)
B(2,11,4,PUMPKIN:1)
B(0,12,-3,PUMPKIN:0)
B(1,12,-3,PUMPKIN:0)
B(2,12,-3,PUMPKIN:0)
B(-1,12,-2,PUMPKIN:0)
B(0,12,-2,PUMPKIN:0)
B(1,12,-2,PUMPKIN:0)
B(2,12,-2,PUMPKIN:0)
B(3,12,-2,PUMPKIN:0)
B(-1,12,-1,PUMPKIN:0)
B(0,12,-1,PUMPKIN:0)
B(1,12,-1,LOG_2:5)
B(2,12,-1,PUMPKIN:0)
B(3,12,-1,PUMPKIN:0)
B(-1,12,0,PUMPKIN:3)
B(0,12,0,PUMPKIN:0)
B(1,12,0,PUMPKIN:0)
B(2,12,0,PUMPKIN:0)
B(3,12,0,PUMPKIN)
B(4,12,0,PUMPKIN:3)
B(5,12,0,PUMPKIN:1)
B(0,12,1,PUMPKIN:3)
B(1,12,1,PUMPKIN:0)
B(2,12,1,PUMPKIN)
B(3,12,1,WEB)
B(0,12,2,PUMPKIN:0)
B(1,12,2,PUMPKIN:0)
B(2,12,2,PUMPKIN:0)
B(0,12,3,PUMPKIN:3)
B(1,12,3,PUMPKIN:3)
B(2,12,3,PUMPKIN:1)
B(1,13,-1,LOG_2:1)
B(2,13,-1,WEB)
B(1,14,-1,LOG_2:1)
B(2,14,-1,161:1)
B(2,14,0,LOG_2:5)
B(3,14,0,161:1)
B(2,14,1,161:1)
B(1,15,-1,161:1)
B(2,15,0,161:1)
B(0,15,1,161:1)
B(1,15,1,LOG_2:9)
B(2,15,1,161:1)
B(1,16,0,161:1)
B(2,16,1,161:1)
B(0,16,2,161:1)
B(1,16,2,LOG_2:9)
B(2,16,2,161:1)
B(0,17,1,161:1)
B(1,17,1,161:1)
B(2,17,1,WEB)
B(0,17,2,LOG_2:5)
B(1,17,2,161:1)
B(-1,17,3,161:1)
B(0,17,3,LOG_2:9)
B(-1,17,4,161:1)
B(1,17,4,161:1)
B(-1,18,2,161:1)
B(0,18,2,161:1)
B(0,18,3,LOG_2:1)
B(1,18,3,161:1)
B(-1,18,4,161:1)
B(0,18,4,161:1)
B(1,18,4,161:1)
B(0,18,5,161:1)
B(0,19,3,161:1)
B(0,19,4,161:1)
B(2,13,1,RED_MUSHROOM)
B(0,13,-1,RED_MUSHROOM)
B(1,-1,1,RED_MUSHROOM)
B(-1,12,3,RED_MUSHROOM)
B(4,12,1,RED_MUSHROOM)
B(-3,12,1,RED_MUSHROOM)
B(2,1,-6,RED_MUSHROOM)
B(-2,2,-2,RED_MUSHROOM)
B(1,3,-7,RED_MUSHROOM)
B(2,3,-7,RED_MUSHROOM)
B(2,12,-4,RED_MUSHROOM)
B(3,11,4,RED_MUSHROOM)
B(0,3,-2,RED_MUSHROOM)
B(0,11,-6,RED_MUSHROOM)
B(2,3,2,RED_MUSHROOM)
B(-2,3,4,RED_MUSHROOM)
B(2,4,0,RED_MUSHROOM)
B(8,5,0,RED_MUSHROOM)
B(2,6,-8,RED_MUSHROOM)
B(7,10,-1,RED_MUSHROOM)
B(3,6,-1,RED_MUSHROOM)
B(-5,7,4,RED_MUSHROOM)
B(-4,9,3,RED_MUSHROOM)
B(8,8,0,RED_MUSHROOM)
B(7,9,-2,RED_MUSHROOM)
B(7,8,1,RED_MUSHROOM)
B(0,7,6,BROWN_MUSHROOM)
B(6,9,2,BROWN_MUSHROOM)
B(8,8,-1,BROWN_MUSHROOM)
B(4,8,6,BROWN_MUSHROOM)
B(5,7,5,BROWN_MUSHROOM)
B(-5,10,-4,BROWN_MUSHROOM)
B(-4,7,-8,BROWN_MUSHROOM)
B(-6,10,-2,BROWN_MUSHROOM)
B(8,6,-3,BROWN_MUSHROOM)
B(-6,10,0,BROWN_MUSHROOM)
B(-2,6,-8,BROWN_MUSHROOM)
B(-5,10,1,BROWN_MUSHROOM)
B(4,5,-1,BROWN_MUSHROOM)
B(4,10,4,BROWN_MUSHROOM)
B(8,4,-1,BROWN_MUSHROOM)
B(7,4,-3,BROWN_MUSHROOM)
B(-1,10,5,BROWN_MUSHROOM)
B(0,11,-7,BROWN_MUSHROOM)
B(7,3,-2,BROWN_MUSHROOM)
B(2,11,-6,BROWN_MUSHROOM)
B(-2,3,-6,BROWN_MUSHROOM)
B(-2,12,-2,BROWN_MUSHROOM)
B(4,12,-2,BROWN_MUSHROOM)
B(1,2,3,BROWN_MUSHROOM)
B(5,2,-1,BROWN_MUSHROOM)
B(-2,12,-1,BROWN_MUSHROOM)
B(-4,1,-2,BROWN_MUSHROOM)
B(-4,1,-3,BROWN_MUSHROOM)
B(5,12,-1,BROWN_MUSHROOM)
B(-1,0,-4,BROWN_MUSHROOM)
B(0,13,-3,BROWN_MUSHROOM)
B(0,-1,0,BROWN_MUSHROOM)
B(0,-1,-1,BROWN_MUSHROOM)

#######################################################################
# +-----------------------------------------------------------------+ #
# |                            BO3 checks                           | #
# +-----------------------------------------------------------------+ #
#######################################################################

# Require a condition at a certain location in order for the BO3 to be spawned.
# BlockCheck(x,y,z,BlockName[,BlockName[,...]]) - one of the blocks must be at the location
# BlockCheckNot(x,y,z,BlockName[,BlockName[,...]]) - all the blocks must not be at the location
# LightCheck(x,y,z,minLightLevel,maxLightLevel) - light must be between min and max (inclusive)

# You can use "Solid" as a BlockName for matching all solid blocks or "All" to match all blocks that aren't air.

# Examples:
#   BlockCheck(0,-1,0,GRASS,DIRT,biomesoplenty:grass:0,biomesoplenty:grass:1,biomesoplenty:grass:2,biomesoplenty:grass:3,biomesoplenty:grass:4,biomesoplenty:grass:5,biomesoplenty:grass:6,biomesoplenty:grass:7,biomesoplenty:dirt:0,biomesoplenty:dirt:1,biomesoplenty:dirt:2,biomesoplenty:dirt:3,biomesoplenty:dirt:4,biomesoplenty:dirt:5,biomesoplenty:dirt:6,biomesoplenty:dirt:7,biomesoplenty:dirt:8,biomesoplenty:dirt:9,biomesoplenty:dirt:10,biomesoplenty:dried_sand:0,biomesoplenty:hard_ice:0,biomesoplenty:white_sand:0,biomesoplenty:white_sandstone:0,biomesoplenty:mud:0,biomesoplenty:ash_block:0)  Require grass or dirt just below the object
#   BlockCheck(0,-1,0,Solid)       Require any solid block just below the object
#   BlockCheck(0,-1,0,WOOL)        Require any type of wool just below the object
#   BlockCheck(0,-1,0,WOOL:0)      Require white wool just below the object
#   BlockCheckNot(0,-1,0,WOOL:0)   Require that there is no white wool below the object
#   LightCheck(0,0,0,0,1)          Require almost complete darkness just below the object
BlockCheck(0,-1,0,GRASS,biomesoplenty:grass:0,biomesoplenty:grass:1,biomesoplenty:grass:2,biomesoplenty:grass:3,biomesoplenty:grass:4,biomesoplenty:grass:5,biomesoplenty:grass:6,biomesoplenty:grass:7)
#######################################################################
# +-----------------------------------------------------------------+ #
# |                             Branches                            | #
# +-----------------------------------------------------------------+ #
#######################################################################

# Branches are objects that will spawn when this object spawns when it is used in
# the CustomStructure resource. Branches can also have branches, making complex
# structures possible. See the wiki for more details.

# Regular Branches spawn each branch with an independent chance of spawning.
# Branch(x,y,z,branchName,rotation,chance[,anotherBranchName,rotation,chance[,...]][IndividualChance])
# branchName - name of the object to spawn.
# rotation - NORTH, SOUTH, EAST or WEST.
# IndividualChance - The chance each branch has to spawn, assumed to be 100 when left blank

# Weighted Branches spawn branches with a dependent chance of spawning.
# WBR(x,y,z,branchName,rotation,chance[,anotherBranchName,rotation,chance[,...]][MaxChanceOutOf])
# MaxChanceOutOf - The chance all branches have to spawn out of, assumed to be 100 when left blank
