
#######################################################################
# +-----------------------------------------------------------------+ #
# |                            BO3 object                           | #
# +-----------------------------------------------------------------+ #
#######################################################################

Author: LordSmellyPants

Description: No description given

Version: 3

SettingsMode: WriteWithoutComments


#######################################################################
# +-----------------------------------------------------------------+ #
# |                          Main settings                          | #
# +-----------------------------------------------------------------+ #
#######################################################################

Tree: true

Frequency: 0

Rarity: 100.0

RotateRandomly: true

SpawnHeight: highestSolidBlock

SpawnHeightOffset: 0

SpawnHeightVariance: 0

##############################
# Height Limits for the BO3. #
##############################

MinHeight: 0

MaxHeight: 255

######################
# Extrusion settings #
######################

ExtrudeMode: None

ExtrudeThroughBlocks: AIR

MaxBranchDepth: 10

ExcludedBiomes: All


#######################################################################
# +-----------------------------------------------------------------+ #
# |                      Source block settings                      | #
# +-----------------------------------------------------------------+ #
#######################################################################

SourceBlocks: AIR

MaxPercentageOutsideSourceBlock: 100

OutsideSourceBlock: placeAnyway

DoReplaceBlocks: true

IsOTGPlus: false


#######################################################################
# +-----------------------------------------------------------------+ #
# |                              Blocks                             | #
# +-----------------------------------------------------------------+ #
#######################################################################

Block(-3,31,-1,CONCRETE:6)
Block(-3,31,1,CONCRETE:6)
Block(-3,32,-1,CONCRETE:6)
Block(-3,32,1,CONCRETE:6)
Block(-3,33,-1,CONCRETE:6)
Block(-3,33,1,CONCRETE:6)
Block(-2,30,-1,CONCRETE:6)
Block(-2,30,1,CONCRETE:6)
Block(-2,31,-2,CONCRETE:6)
Block(-2,31,-1,CONCRETE:6)
Block(-2,31,0,CONCRETE:5)
Block(-2,31,1,CONCRETE:6)
Block(-2,31,2,CONCRETE:6)
Block(-2,32,-1,CONCRETE:5)
Block(-2,32,0,CONCRETE:5)
Block(-2,32,1,CONCRETE:5)
Block(-2,33,0,CONCRETE:5)
Block(-1,3,-1,STAINED_CLAY:2)
Block(-1,3,0,STAINED_CLAY:2)
Block(-1,3,1,STAINED_CLAY:2)
Block(-1,7,-1,STAINED_CLAY:2)
Block(-1,7,0,STAINED_CLAY:2)
Block(-1,7,1,STAINED_CLAY:2)
Block(-1,11,-1,STAINED_CLAY:2)
Block(-1,11,0,STAINED_CLAY:2)
Block(-1,11,1,STAINED_CLAY:2)
Block(-1,15,-1,STAINED_CLAY:2)
Block(-1,15,0,STAINED_CLAY:2)
Block(-1,15,1,STAINED_CLAY:2)
Block(-1,19,-1,STAINED_CLAY:2)
Block(-1,19,0,STAINED_CLAY:2)
Block(-1,19,1,STAINED_CLAY:2)
Block(-1,23,-1,STAINED_CLAY:2)
Block(-1,23,0,STAINED_CLAY:2)
Block(-1,23,1,STAINED_CLAY:2)
Block(-1,27,0,STAINED_CLAY:2)
Block(-1,29,-1,CONCRETE:6)
Block(-1,29,0,STAINED_CLAY:2)
Block(-1,29,1,CONCRETE:6)
Block(-1,30,-2,CONCRETE:6)
Block(-1,30,-1,CONCRETE:6)
Block(-1,30,0,CONCRETE:5)
Block(-1,30,1,CONCRETE:6)
Block(-1,30,2,CONCRETE:6)
Block(-1,31,-3,CONCRETE:6)
Block(-1,31,-2,CONCRETE:6)
Block(-1,31,-1,SLIME_BLOCK)
Block(-1,31,0,SLIME_BLOCK)
Block(-1,31,1,SLIME_BLOCK)
Block(-1,31,2,CONCRETE:6)
Block(-1,31,3,CONCRETE:6)
Block(-1,32,-3,CONCRETE:6)
Block(-1,32,-2,CONCRETE:5)
Block(-1,32,2,CONCRETE:5)
Block(-1,32,3,CONCRETE:6)
Block(-1,33,-3,CONCRETE:6)
Block(-1,33,3,CONCRETE:6)
Block(0,0,0,STAINED_CLAY:11)
Block(0,1,0,STAINED_CLAY:11)
Block(0,2,0,STAINED_CLAY:11)
Block(0,3,-1,STAINED_CLAY:2)
Block(0,3,0,STAINED_CLAY:11)
Block(0,3,1,STAINED_CLAY:2)
Block(0,4,0,STAINED_CLAY:11)
Block(0,5,0,STAINED_CLAY:11)
Block(0,6,0,STAINED_CLAY:11)
Block(0,7,-1,STAINED_CLAY:2)
Block(0,7,0,STAINED_CLAY:11)
Block(0,7,1,STAINED_CLAY:2)
Block(0,8,0,STAINED_CLAY:11)
Block(0,9,0,STAINED_CLAY:11)
Block(0,10,0,STAINED_CLAY:11)
Block(0,11,-1,STAINED_CLAY:2)
Block(0,11,0,STAINED_CLAY:11)
Block(0,11,1,STAINED_CLAY:2)
Block(0,12,0,STAINED_CLAY:11)
Block(0,13,0,STAINED_CLAY:11)
Block(0,14,0,STAINED_CLAY:11)
Block(0,15,-1,STAINED_CLAY:2)
Block(0,15,0,STAINED_CLAY:11)
Block(0,15,1,STAINED_CLAY:2)
Block(0,16,0,STAINED_CLAY:11)
Block(0,17,0,STAINED_CLAY:11)
Block(0,18,0,STAINED_CLAY:11)
Block(0,19,-1,STAINED_CLAY:2)
Block(0,19,0,STAINED_CLAY:11)
Block(0,19,1,STAINED_CLAY:2)
Block(0,20,0,STAINED_CLAY:11)
Block(0,21,0,STAINED_CLAY:11)
Block(0,22,0,STAINED_CLAY:11)
Block(0,23,-1,STAINED_CLAY:2)
Block(0,23,0,STAINED_CLAY:11)
Block(0,23,1,STAINED_CLAY:2)
Block(0,24,0,STAINED_CLAY:11)
Block(0,25,0,STAINED_CLAY:11)
Block(0,26,0,STAINED_CLAY:11)
Block(0,27,-1,STAINED_CLAY:2)
Block(0,27,0,STAINED_CLAY:11)
Block(0,27,1,STAINED_CLAY:2)
Block(0,28,0,STAINED_CLAY:11)
Block(0,29,-1,STAINED_CLAY:2)
Block(0,29,0,STAINED_CLAY:2)
Block(0,29,1,STAINED_CLAY:2)
Block(0,30,-1,CONCRETE:5)
Block(0,30,0,CONCRETE:5)
Block(0,30,1,CONCRETE:5)
Block(0,31,-2,CONCRETE:5)
Block(0,31,-1,SLIME_BLOCK)
Block(0,31,0,SLIME_BLOCK)
Block(0,31,1,SLIME_BLOCK)
Block(0,31,2,CONCRETE:5)
Block(0,32,-2,CONCRETE:5)
Block(0,32,2,CONCRETE:5)
Block(0,33,-2,CONCRETE:5)
Block(0,33,2,CONCRETE:5)
Block(1,3,-1,STAINED_CLAY:2)
Block(1,3,0,STAINED_CLAY:2)
Block(1,3,1,STAINED_CLAY:2)
Block(1,7,-1,STAINED_CLAY:2)
Block(1,7,0,STAINED_CLAY:2)
Block(1,7,1,STAINED_CLAY:2)
Block(1,11,-1,STAINED_CLAY:2)
Block(1,11,0,STAINED_CLAY:2)
Block(1,11,1,STAINED_CLAY:2)
Block(1,15,-1,STAINED_CLAY:2)
Block(1,15,0,STAINED_CLAY:2)
Block(1,15,1,STAINED_CLAY:2)
Block(1,19,-1,STAINED_CLAY:2)
Block(1,19,0,STAINED_CLAY:2)
Block(1,19,1,STAINED_CLAY:2)
Block(1,23,-1,STAINED_CLAY:2)
Block(1,23,0,STAINED_CLAY:2)
Block(1,23,1,STAINED_CLAY:2)
Block(1,27,0,STAINED_CLAY:2)
Block(1,29,-1,CONCRETE:6)
Block(1,29,0,STAINED_CLAY:2)
Block(1,29,1,CONCRETE:6)
Block(1,30,-2,CONCRETE:6)
Block(1,30,-1,CONCRETE:6)
Block(1,30,0,CONCRETE:5)
Block(1,30,1,CONCRETE:6)
Block(1,30,2,CONCRETE:6)
Block(1,31,-3,CONCRETE:6)
Block(1,31,-2,CONCRETE:6)
Block(1,31,-1,SLIME_BLOCK)
Block(1,31,0,SLIME_BLOCK)
Block(1,31,1,SLIME_BLOCK)
Block(1,31,2,CONCRETE:6)
Block(1,31,3,CONCRETE:6)
Block(1,32,-3,CONCRETE:6)
Block(1,32,-2,CONCRETE:5)
Block(1,32,2,CONCRETE:5)
Block(1,32,3,CONCRETE:6)
Block(1,33,-3,CONCRETE:6)
Block(1,33,3,CONCRETE:6)
Block(2,30,-1,CONCRETE:6)
Block(2,30,1,CONCRETE:6)
Block(2,31,-2,CONCRETE:6)
Block(2,31,-1,CONCRETE:6)
Block(2,31,0,CONCRETE:5)
Block(2,31,1,CONCRETE:6)
Block(2,31,2,CONCRETE:6)
Block(2,32,-1,CONCRETE:5)
Block(2,32,0,CONCRETE:5)
Block(2,32,1,CONCRETE:5)
Block(2,33,0,CONCRETE:5)
Block(3,31,-1,CONCRETE:6)
Block(3,31,1,CONCRETE:6)
Block(3,32,-1,CONCRETE:6)
Block(3,32,1,CONCRETE:6)
Block(3,33,-1,CONCRETE:6)
Block(3,33,1,CONCRETE:6)

#######################################################################
# +-----------------------------------------------------------------+ #
# |                            BO3 checks                           | #
# +-----------------------------------------------------------------+ #
#######################################################################

BlockCheck(0,-1,0,GRASS,DIRT)

#######################################################################
# +-----------------------------------------------------------------+ #
# |                             Branches                            | #
# +-----------------------------------------------------------------+ #
#######################################################################


#######################################################################
# +-----------------------------------------------------------------+ #
# |                             Entities                            | #
# +-----------------------------------------------------------------+ #
#######################################################################


#######################################################################
# +-----------------------------------------------------------------+ #
# |                            Particles                            | #
# +-----------------------------------------------------------------+ #
#######################################################################


#######################################################################
# +-----------------------------------------------------------------+ #
# |                             Spawners                            | #
# +-----------------------------------------------------------------+ #
#######################################################################


#######################################################################
# +-----------------------------------------------------------------+ #
# |                             ModData                             | #
# +-----------------------------------------------------------------+ #
#######################################################################

