
#######################################################################
# +-----------------------------------------------------------------+ #
# |                            BO3 object                           | #
# +-----------------------------------------------------------------+ #
#######################################################################

Author: MC_Pitman

Description: No description given

Version: 3

SettingsMode: WriteWithoutComments


#######################################################################
# +-----------------------------------------------------------------+ #
# |                          Main settings                          | #
# +-----------------------------------------------------------------+ #
#######################################################################

Tree: false

Frequency: 1

Rarity: 1.0

RotateRandomly: true

SpawnHeight: highestSolidBlock

SpawnHeightOffset: 0

SpawnHeightVariance: 0

##############################
# Height Limits for the BO3. #
##############################

MinHeight: 52

MaxHeight: 80

######################
# Extrusion settings #
######################

ExtrudeMode: None

ExtrudeThroughBlocks: AIR

MaxBranchDepth: 10

ExcludedBiomes: All


#######################################################################
# +-----------------------------------------------------------------+ #
# |                      Source block settings                      | #
# +-----------------------------------------------------------------+ #
#######################################################################

SourceBlocks: AIR

MaxPercentageOutsideSourceBlock: 0

OutsideSourceBlock: placeAnyway

DoReplaceBlocks: true

IsOTGPlus: false


#######################################################################
# +-----------------------------------------------------------------+ #
# |                              Blocks                             | #
# +-----------------------------------------------------------------+ #
#######################################################################

Block(-9,-8,1,STONE)
Block(-9,-7,-1,STONE)
Block(-9,-7,0,STONE)
Block(-9,-7,1,STONE)
Block(-9,-6,0,STONE)
Block(-8,-9,0,STONE)
Block(-8,-9,1,STONE)
Block(-8,-9,2,STONE)
Block(-8,-8,-2,STONE)
Block(-8,-8,-1,STONE)
Block(-8,-8,0,STONE)
Block(-8,-8,1,STONE)
Block(-8,-8,2,STONE)
Block(-8,-8,3,STONE)
Block(-8,-8,4,STONE)
Block(-8,-7,-3,STONE)
Block(-8,-7,-2,STONE)
Block(-8,-7,-1,STONE)
Block(-8,-7,0,STONE)
Block(-8,-7,1,STONE)
Block(-8,-7,2,STONE)
Block(-8,-7,3,STONE)
Block(-8,-7,4,STONE)
Block(-8,-7,5,STONE)
Block(-8,-6,-3,STONE)
Block(-8,-6,-2,STONE)
Block(-8,-6,-1,STONE)
Block(-8,-6,0,STONE)
Block(-8,-6,1,STONE)
Block(-8,-6,2,STONE)
Block(-8,-6,3,STONE)
Block(-8,-6,4,STONE)
Block(-8,-5,-3,STONE)
Block(-8,-5,-2,STONE)
Block(-8,-5,-1,STONE)
Block(-8,-5,0,STONE)
Block(-8,-5,1,STONE)
Block(-8,-4,-3,STONE)
Block(-8,-4,-2,STONE)
Block(-7,-11,1,STONE)
Block(-7,-10,0,STONE)
Block(-7,-10,1,STONE)
Block(-7,-10,2,STONE)
Block(-7,-9,-2,STONE)
Block(-7,-9,-1,STONE)
Block(-7,-9,0,STONE)
Block(-7,-9,1,STONE)
Block(-7,-9,2,STONE)
Block(-7,-9,3,STONE)
Block(-7,-9,4,STONE)
Block(-7,-8,-3,STONE)
Block(-7,-8,-2,STONE)
Block(-7,-8,-1,STONE)
Block(-7,-8,0,STONE)
Block(-7,-8,1,STONE)
Block(-7,-8,2,STONE)
Block(-7,-8,3,STONE)
Block(-7,-8,4,STONE)
Block(-7,-8,5,STONE)
Block(-7,-8,6,STONE)
Block(-7,-7,-4,STONE)
Block(-7,-7,-3,STONE)
Block(-7,-7,-2,STONE)
Block(-7,-7,-1,STONE)
Block(-7,-7,0,STONE)
Block(-7,-7,1,STONE)
Block(-7,-7,2,STONE)
Block(-7,-7,3,STONE)
Block(-7,-7,4,STONE)
Block(-7,-7,5,STONE)
Block(-7,-7,6,STONE)
Block(-7,-7,7,STONE)
Block(-7,-7,8,STONE)
Block(-7,-6,-4,STONE)
Block(-7,-6,-3,STONE)
Block(-7,-6,-2,STONE)
Block(-7,-6,-1,STONE)
Block(-7,-6,0,STONE)
Block(-7,-6,1,STONE)
Block(-7,-6,2,STONE)
Block(-7,-6,3,STONE)
Block(-7,-6,4,STONE)
Block(-7,-6,5,STONE)
Block(-7,-6,6,STONE)
Block(-7,-6,7,STONE)
Block(-7,-6,8,STONE)
Block(-7,-5,-4,STONE)
Block(-7,-5,-3,STONE)
Block(-7,-5,-2,STONE)
Block(-7,-5,-1,STONE)
Block(-7,-5,0,STONE)
Block(-7,-5,1,STONE)
Block(-7,-5,2,STONE)
Block(-7,-5,3,STONE)
Block(-7,-5,4,STONE)
Block(-7,-5,5,STONE)
Block(-7,-5,6,STONE)
Block(-7,-5,7,STONE)
Block(-7,-5,8,STONE)
Block(-7,-4,-4,STONE)
Block(-7,-4,-3,STONE)
Block(-7,-4,-2,STONE)
Block(-7,-4,-1,STONE)
Block(-7,-4,0,STONE)
Block(-7,-4,1,STONE)
Block(-7,-4,2,STONE)
Block(-7,-4,3,STONE)
Block(-7,-4,4,STONE)
Block(-7,-4,5,STONE)
Block(-7,-3,-4,STONE)
Block(-7,-3,-3,STONE)
Block(-7,-3,-2,STONE)
Block(-7,-3,-1,STONE)
Block(-7,-3,0,STONE)
Block(-7,-3,1,STONE)
Block(-7,-3,2,STONE)
Block(-7,-2,-3,STONE)
Block(-7,-2,-2,STONE)
Block(-7,-2,-1,STONE)
Block(-7,-1,-3,STONE)
Block(-6,-12,1,STONE)
Block(-6,-11,0,STONE)
Block(-6,-11,1,STONE)
Block(-6,-11,2,STONE)
Block(-6,-11,3,STONE)
Block(-6,-10,-2,STONE)
Block(-6,-10,-1,STONE)
Block(-6,-10,0,STONE)
Block(-6,-10,1,STONE)
Block(-6,-10,2,STONE)
Block(-6,-10,3,STONE)
Block(-6,-10,4,STONE)
Block(-6,-9,-3,STONE)
Block(-6,-9,-2,STONE)
Block(-6,-9,-1,STONE)
Block(-6,-9,0,STONE)
Block(-6,-9,1,STONE)
Block(-6,-9,2,STONE)
Block(-6,-9,3,STONE)
Block(-6,-9,4,STONE)
Block(-6,-9,5,STONE)
Block(-6,-9,6,STONE)
Block(-6,-8,-4,STONE)
Block(-6,-8,-3,STONE)
Block(-6,-8,-2,STONE)
Block(-6,-8,-1,STONE)
Block(-6,-8,0,STONE)
Block(-6,-8,1,STONE)
Block(-6,-8,2,STONE)
Block(-6,-8,3,STONE)
Block(-6,-8,4,STONE)
Block(-6,-8,5,STONE)
Block(-6,-8,6,STONE)
Block(-6,-8,7,STONE)
Block(-6,-8,8,STONE)
Block(-6,-7,-5,STONE)
Block(-6,-7,-4,STONE)
Block(-6,-7,-3,STONE)
Block(-6,-7,-2,STONE)
Block(-6,-7,-1,STONE)
Block(-6,-7,0,STONE)
Block(-6,-7,1,STONE)
Block(-6,-7,2,STONE)
Block(-6,-7,3,STONE)
Block(-6,-7,4,STONE)
Block(-6,-7,5,STONE)
Block(-6,-7,6,STONE)
Block(-6,-7,7,STONE)
Block(-6,-7,8,STONE)
Block(-6,-7,9,STONE)
Block(-6,-6,-5,STONE)
Block(-6,-6,-4,STONE)
Block(-6,-6,-3,STONE)
Block(-6,-6,-2,STONE)
Block(-6,-6,-1,STONE)
Block(-6,-6,0,STONE)
Block(-6,-6,1,STONE)
Block(-6,-6,2,STONE)
Block(-6,-6,3,STONE)
Block(-6,-6,4,STONE)
Block(-6,-6,5,STONE)
Block(-6,-6,6,STONE)
Block(-6,-6,7,STONE)
Block(-6,-6,8,STONE)
Block(-6,-6,9,STONE)
Block(-6,-5,-5,STONE)
Block(-6,-5,-4,STONE)
Block(-6,-5,-3,STONE)
Block(-6,-5,-2,STONE)
Block(-6,-5,-1,STONE)
Block(-6,-5,0,STONE)
Block(-6,-5,1,STONE)
Block(-6,-5,2,STONE)
Block(-6,-5,3,STONE)
Block(-6,-5,4,STONE)
Block(-6,-5,5,STONE)
Block(-6,-5,6,STONE)
Block(-6,-5,7,STONE)
Block(-6,-5,8,STONE)
Block(-6,-5,9,STONE)
Block(-6,-4,-5,STONE)
Block(-6,-4,-4,STONE)
Block(-6,-4,-3,STONE)
Block(-6,-4,-2,STONE)
Block(-6,-4,-1,STONE)
Block(-6,-4,0,STONE)
Block(-6,-4,1,STONE)
Block(-6,-4,2,STONE)
Block(-6,-4,3,STONE)
Block(-6,-4,4,STONE)
Block(-6,-4,5,STONE)
Block(-6,-4,6,STONE)
Block(-6,-4,7,STONE)
Block(-6,-4,8,STONE)
Block(-6,-3,-4,STONE)
Block(-6,-3,-3,STONE)
Block(-6,-3,-2,STONE)
Block(-6,-3,-1,STONE)
Block(-6,-3,0,STONE)
Block(-6,-3,1,STONE)
Block(-6,-3,2,STONE)
Block(-6,-3,3,STONE)
Block(-6,-3,4,STONE)
Block(-6,-3,5,STONE)
Block(-6,-3,6,STONE)
Block(-6,-3,7,STONE)
Block(-6,-3,8,STONE)
Block(-6,-2,-4,STONE)
Block(-6,-2,-3,STONE)
Block(-6,-2,-2,STONE)
Block(-6,-2,-1,STONE)
Block(-6,-2,0,STONE)
Block(-6,-2,1,STONE)
Block(-6,-2,2,STONE)
Block(-6,-2,3,STONE)
Block(-6,-2,4,STONE)
Block(-6,-2,5,STONE)
Block(-6,-2,6,STONE)
Block(-6,-2,7,STONE)
Block(-6,-1,-4,STONE)
Block(-6,-1,-3,STONE)
Block(-6,-1,-2,STONE)
Block(-6,-1,-1,STONE)
Block(-6,-1,0,STONE)
Block(-6,-1,1,STONE)
Block(-6,-1,2,STONE)
Block(-6,-1,3,STONE)
Block(-6,-1,4,STONE)
Block(-6,-1,5,STONE)
Block(-6,0,-3,STONE)
Block(-6,0,-2,STONE)
Block(-6,0,-1,STONE)
Block(-6,0,0,STONE)
Block(-6,0,1,STONE)
Block(-6,1,-3,STONE)
Block(-6,1,-2,STONE)
Block(-6,1,-1,STONE)
Block(-6,1,0,STONE)
Block(-6,1,1,STONE)
Block(-6,2,-3,STONE)
Block(-6,2,-2,STONE)
Block(-6,2,-1,STONE)
Block(-6,2,0,STONE)
Block(-6,3,-3,STONE)
Block(-6,3,-2,STONE)
Block(-6,3,-1,STONE)
Block(-5,-12,0,STONE)
Block(-5,-12,1,STONE)
Block(-5,-11,-1,STONE)
Block(-5,-11,0,STONE)
Block(-5,-11,1,STONE)
Block(-5,-11,2,STONE)
Block(-5,-11,3,STONE)
Block(-5,-10,-3,STONE)
Block(-5,-10,-2,STONE)
Block(-5,-10,-1,STONE)
Block(-5,-10,0,STONE)
Block(-5,-10,1,STONE)
Block(-5,-10,2,STONE)
Block(-5,-10,3,STONE)
Block(-5,-10,4,STONE)
Block(-5,-10,5,STONE)
Block(-5,-10,6,STONE)
Block(-5,-9,-4,STONE)
Block(-5,-9,-3,STONE)
Block(-5,-9,-2,STONE)
Block(-5,-9,-1,STONE)
Block(-5,-9,0,STONE)
Block(-5,-9,1,STONE)
Block(-5,-9,2,STONE)
Block(-5,-9,3,STONE)
Block(-5,-9,4,STONE)
Block(-5,-9,5,STONE)
Block(-5,-9,6,STONE)
Block(-5,-9,7,STONE)
Block(-5,-9,8,STONE)
Block(-5,-8,-6,STONE)
Block(-5,-8,-5,STONE)
Block(-5,-8,-4,STONE)
Block(-5,-8,-3,STONE)
Block(-5,-8,-2,STONE)
Block(-5,-8,-1,STONE)
Block(-5,-8,0,STONE)
Block(-5,-8,1,STONE)
Block(-5,-8,2,STONE)
Block(-5,-8,3,STONE)
Block(-5,-8,4,STONE)
Block(-5,-8,5,STONE)
Block(-5,-8,6,STONE)
Block(-5,-8,7,STONE)
Block(-5,-8,8,STONE)
Block(-5,-8,9,STONE)
Block(-5,-7,-6,STONE)
Block(-5,-7,-5,STONE)
Block(-5,-7,-4,STONE)
Block(-5,-7,-3,STONE)
Block(-5,-7,-2,STONE)
Block(-5,-7,-1,STONE)
Block(-5,-7,0,STONE)
Block(-5,-7,1,STONE)
Block(-5,-7,2,STONE)
Block(-5,-7,3,STONE)
Block(-5,-7,4,STONE)
Block(-5,-7,5,STONE)
Block(-5,-7,6,STONE)
Block(-5,-7,7,STONE)
Block(-5,-7,8,STONE)
Block(-5,-7,9,STONE)
Block(-5,-6,-5,STONE)
Block(-5,-6,-4,STONE)
Block(-5,-6,-3,STONE)
Block(-5,-6,-2,STONE)
Block(-5,-6,-1,STONE)
Block(-5,-6,0,STONE)
Block(-5,-6,1,STONE)
Block(-5,-6,2,STONE)
Block(-5,-6,3,STONE)
Block(-5,-6,4,STONE)
Block(-5,-6,5,STONE)
Block(-5,-6,6,STONE)
Block(-5,-6,7,STONE)
Block(-5,-6,8,STONE)
Block(-5,-6,9,STONE)
Block(-5,-5,-5,STONE)
Block(-5,-5,-4,STONE)
Block(-5,-5,-3,STONE)
Block(-5,-5,-2,STONE)
Block(-5,-5,-1,STONE)
Block(-5,-5,0,STONE)
Block(-5,-5,1,STONE)
Block(-5,-5,2,STONE)
Block(-5,-5,3,STONE)
Block(-5,-5,4,STONE)
Block(-5,-5,5,STONE)
Block(-5,-5,6,STONE)
Block(-5,-5,7,STONE)
Block(-5,-5,8,STONE)
Block(-5,-4,-5,STONE)
Block(-5,-4,-4,STONE)
Block(-5,-4,-3,STONE)
Block(-5,-4,-2,STONE)
Block(-5,-4,-1,STONE)
Block(-5,-4,0,STONE)
Block(-5,-4,1,STONE)
Block(-5,-4,2,STONE)
Block(-5,-4,3,STONE)
Block(-5,-4,4,STONE)
Block(-5,-4,5,STONE)
Block(-5,-4,6,STONE)
Block(-5,-4,7,STONE)
Block(-5,-4,8,STONE)
Block(-5,-3,-5,STONE)
Block(-5,-3,-4,STONE)
Block(-5,-3,-3,STONE)
Block(-5,-3,-2,STONE)
Block(-5,-3,-1,STONE)
Block(-5,-3,0,STONE)
Block(-5,-3,1,STONE)
Block(-5,-3,2,STONE)
Block(-5,-3,3,STONE)
Block(-5,-3,4,STONE)
Block(-5,-3,5,STONE)
Block(-5,-3,6,STONE)
Block(-5,-3,7,STONE)
Block(-5,-3,8,STONE)
Block(-5,-2,-5,STONE)
Block(-5,-2,-4,STONE)
Block(-5,-2,-3,STONE)
Block(-5,-2,-2,STONE)
Block(-5,-2,-1,STONE)
Block(-5,-2,0,STONE)
Block(-5,-2,1,STONE)
Block(-5,-2,2,STONE)
Block(-5,-2,3,STONE)
Block(-5,-2,4,STONE)
Block(-5,-2,5,STONE)
Block(-5,-2,6,STONE)
Block(-5,-2,7,STONE)
Block(-5,-2,8,STONE)
Block(-5,-1,-5,STONE)
Block(-5,-1,-4,STONE)
Block(-5,-1,-3,STONE)
Block(-5,-1,-2,STONE)
Block(-5,-1,-1,STONE)
Block(-5,-1,0,STONE)
Block(-5,-1,1,STONE)
Block(-5,-1,2,STONE)
Block(-5,-1,3,STONE)
Block(-5,-1,4,STONE)
Block(-5,-1,5,STONE)
Block(-5,-1,6,STONE)
Block(-5,-1,7,STONE)
Block(-5,0,-4,STONE)
Block(-5,0,-3,STONE)
Block(-5,0,-2,STONE)
Block(-5,0,-1,STONE)
Block(-5,0,0,STONE)
Block(-5,0,1,STONE)
Block(-5,0,2,STONE)
Block(-5,0,3,STONE)
Block(-5,0,4,STONE)
Block(-5,0,5,STONE)
Block(-5,0,6,STONE)
Block(-5,1,-4,STONE)
Block(-5,1,-3,STONE)
Block(-5,1,-2,STONE)
Block(-5,1,-1,STONE)
Block(-5,1,0,STONE)
Block(-5,1,1,STONE)
Block(-5,1,2,STONE)
Block(-5,1,3,STONE)
Block(-5,1,4,STONE)
Block(-5,1,5,STONE)
Block(-5,2,-4,STONE)
Block(-5,2,-3,STONE)
Block(-5,2,-2,STONE)
Block(-5,2,-1,STONE)
Block(-5,2,0,STONE)
Block(-5,2,1,STONE)
Block(-5,2,2,STONE)
Block(-5,2,3,STONE)
Block(-5,2,4,STONE)
Block(-5,3,-4,STONE)
Block(-5,3,-3,STONE)
Block(-5,3,-2,STONE)
Block(-5,3,-1,STONE)
Block(-5,3,0,STONE)
Block(-5,3,1,STONE)
Block(-5,3,2,STONE)
Block(-5,3,3,STONE)
Block(-5,4,-3,STONE)
Block(-5,4,-2,STONE)
Block(-5,4,-1,STONE)
Block(-5,4,0,STONE)
Block(-5,4,1,STONE)
Block(-5,5,-3,STONE)
Block(-5,5,-2,STONE)
Block(-4,-12,-2,STONE)
Block(-4,-12,-1,STONE)
Block(-4,-12,0,STONE)
Block(-4,-12,1,STONE)
Block(-4,-11,-3,STONE)
Block(-4,-11,-2,STONE)
Block(-4,-11,-1,STONE)
Block(-4,-11,0,STONE)
Block(-4,-11,1,STONE)
Block(-4,-11,2,STONE)
Block(-4,-11,3,STONE)
Block(-4,-11,4,STONE)
Block(-4,-10,-4,STONE)
Block(-4,-10,-3,STONE)
Block(-4,-10,-2,STONE)
Block(-4,-10,-1,STONE)
Block(-4,-10,0,STONE)
Block(-4,-10,1,STONE)
Block(-4,-10,2,STONE)
Block(-4,-10,3,STONE)
Block(-4,-10,4,STONE)
Block(-4,-10,5,STONE)
Block(-4,-10,6,STONE)
Block(-4,-9,-6,STONE)
Block(-4,-9,-5,STONE)
Block(-4,-9,-4,STONE)
Block(-4,-9,-3,STONE)
Block(-4,-9,-2,STONE)
Block(-4,-9,-1,STONE)
Block(-4,-9,0,STONE)
Block(-4,-9,1,STONE)
Block(-4,-9,2,STONE)
Block(-4,-9,3,STONE)
Block(-4,-9,4,STONE)
Block(-4,-9,5,STONE)
Block(-4,-9,6,STONE)
Block(-4,-9,7,STONE)
Block(-4,-9,8,STONE)
Block(-4,-8,-6,STONE)
Block(-4,-8,-5,STONE)
Block(-4,-8,-4,STONE)
Block(-4,-8,-3,STONE)
Block(-4,-8,-2,STONE)
Block(-4,-8,-1,STONE)
Block(-4,-8,0,STONE)
Block(-4,-8,1,STONE)
Block(-4,-8,2,STONE)
Block(-4,-8,3,STONE)
Block(-4,-8,4,STONE)
Block(-4,-8,5,STONE)
Block(-4,-8,6,STONE)
Block(-4,-8,7,STONE)
Block(-4,-8,8,STONE)
Block(-4,-8,9,STONE)
Block(-4,-7,-6,STONE)
Block(-4,-7,-5,STONE)
Block(-4,-7,-4,STONE)
Block(-4,-7,-3,STONE)
Block(-4,-7,-2,STONE)
Block(-4,-7,-1,STONE)
Block(-4,-7,0,STONE)
Block(-4,-7,1,STONE)
Block(-4,-7,2,STONE)
Block(-4,-7,3,STONE)
Block(-4,-7,4,STONE)
Block(-4,-7,5,STONE)
Block(-4,-7,6,STONE)
Block(-4,-7,7,STONE)
Block(-4,-7,8,STONE)
Block(-4,-7,9,STONE)
Block(-4,-6,-6,STONE)
Block(-4,-6,-5,STONE)
Block(-4,-6,-4,STONE)
Block(-4,-6,-3,STONE)
Block(-4,-6,-2,STONE)
Block(-4,-6,-1,STONE)
Block(-4,-6,0,STONE)
Block(-4,-6,1,STONE)
Block(-4,-6,2,STONE)
Block(-4,-6,3,STONE)
Block(-4,-6,4,STONE)
Block(-4,-6,5,STONE)
Block(-4,-6,6,STONE)
Block(-4,-6,7,STONE)
Block(-4,-6,8,STONE)
Block(-4,-6,9,STONE)
Block(-4,-5,-6,STONE)
Block(-4,-5,-5,STONE)
Block(-4,-5,-4,STONE)
Block(-4,-5,-3,STONE)
Block(-4,-5,-2,STONE)
Block(-4,-5,-1,STONE)
Block(-4,-5,0,STONE)
Block(-4,-5,1,STONE)
Block(-4,-5,2,STONE)
Block(-4,-5,3,STONE)
Block(-4,-5,4,STONE)
Block(-4,-5,5,STONE)
Block(-4,-5,6,STONE)
Block(-4,-5,7,STONE)
Block(-4,-5,8,STONE)
Block(-4,-4,-6,STONE)
Block(-4,-4,-5,STONE)
Block(-4,-4,-4,STONE)
Block(-4,-4,-3,STONE)
Block(-4,-4,-2,STONE)
Block(-4,-4,-1,STONE)
Block(-4,-4,0,STONE)
Block(-4,-4,1,STONE)
Block(-4,-4,2,STONE)
Block(-4,-4,3,STONE)
Block(-4,-4,4,STONE)
Block(-4,-4,5,STONE)
Block(-4,-4,6,STONE)
Block(-4,-4,7,STONE)
Block(-4,-4,8,STONE)
Block(-4,-3,-5,STONE)
Block(-4,-3,-4,STONE)
Block(-4,-3,-3,STONE)
Block(-4,-3,-2,STONE)
Block(-4,-3,-1,STONE)
Block(-4,-3,0,STONE)
Block(-4,-3,1,STONE)
Block(-4,-3,2,STONE)
Block(-4,-3,3,STONE)
Block(-4,-3,4,STONE)
Block(-4,-3,5,STONE)
Block(-4,-3,6,STONE)
Block(-4,-3,7,STONE)
Block(-4,-3,8,STONE)
Block(-4,-2,-5,STONE)
Block(-4,-2,-4,STONE)
Block(-4,-2,-3,STONE)
Block(-4,-2,-2,STONE)
Block(-4,-2,-1,STONE)
Block(-4,-2,0,STONE)
Block(-4,-2,1,STONE)
Block(-4,-2,2,STONE)
Block(-4,-2,3,STONE)
Block(-4,-2,4,STONE)
Block(-4,-2,5,STONE)
Block(-4,-2,6,STONE)
Block(-4,-2,7,STONE)
Block(-4,-2,8,STONE)
Block(-4,-1,-5,STONE)
Block(-4,-1,-4,STONE)
Block(-4,-1,-3,STONE)
Block(-4,-1,-2,STONE)
Block(-4,-1,-1,STONE)
Block(-4,-1,0,STONE)
Block(-4,-1,1,STONE)
Block(-4,-1,2,STONE)
Block(-4,-1,3,STONE)
Block(-4,-1,4,STONE)
Block(-4,-1,5,STONE)
Block(-4,-1,6,STONE)
Block(-4,-1,7,STONE)
Block(-4,-1,8,STONE)
Block(-4,0,-5,STONE)
Block(-4,0,-4,STONE)
Block(-4,0,-3,STONE)
Block(-4,0,-2,STONE)
Block(-4,0,-1,STONE)
Block(-4,0,0,STONE)
Block(-4,0,1,STONE)
Block(-4,0,2,STONE)
Block(-4,0,3,STONE)
Block(-4,0,4,STONE)
Block(-4,0,5,STONE)
Block(-4,0,6,STONE)
Block(-4,0,7,STONE)
Block(-4,1,-5,STONE)
Block(-4,1,-4,STONE)
Block(-4,1,-3,STONE)
Block(-4,1,-2,STONE)
Block(-4,1,-1,STONE)
Block(-4,1,0,STONE)
Block(-4,1,1,STONE)
Block(-4,1,2,STONE)
Block(-4,1,3,STONE)
Block(-4,1,4,STONE)
Block(-4,1,5,STONE)
Block(-4,1,6,STONE)
Block(-4,2,-5,STONE)
Block(-4,2,-4,STONE)
Block(-4,2,-3,STONE)
Block(-4,2,-2,STONE)
Block(-4,2,-1,STONE)
Block(-4,2,0,STONE)
Block(-4,2,1,STONE)
Block(-4,2,2,STONE)
Block(-4,2,3,STONE)
Block(-4,2,4,STONE)
Block(-4,2,5,STONE)
Block(-4,3,-5,STONE)
Block(-4,3,-4,STONE)
Block(-4,3,-3,STONE)
Block(-4,3,-2,STONE)
Block(-4,3,-1,STONE)
Block(-4,3,0,STONE)
Block(-4,3,1,STONE)
Block(-4,3,2,STONE)
Block(-4,3,3,STONE)
Block(-4,3,4,STONE)
Block(-4,4,-4,STONE)
Block(-4,4,-3,STONE)
Block(-4,4,-2,STONE)
Block(-4,4,-1,STONE)
Block(-4,4,0,STONE)
Block(-4,4,1,STONE)
Block(-4,4,2,STONE)
Block(-4,4,3,STONE)
Block(-4,5,-4,STONE)
Block(-4,5,-3,STONE)
Block(-4,5,-2,STONE)
Block(-4,5,-1,STONE)
Block(-4,5,0,STONE)
Block(-4,5,1,STONE)
Block(-4,5,2,STONE)
Block(-4,5,3,STONE)
Block(-4,6,-3,STONE)
Block(-4,6,-2,STONE)
Block(-4,6,-1,STONE)
Block(-4,6,0,STONE)
Block(-4,6,1,STONE)
Block(-3,-12,-3,STONE)
Block(-3,-12,-2,STONE)
Block(-3,-12,-1,STONE)
Block(-3,-12,0,STONE)
Block(-3,-12,1,STONE)
Block(-3,-11,-5,STONE)
Block(-3,-11,-4,STONE)
Block(-3,-11,-3,STONE)
Block(-3,-11,-2,STONE)
Block(-3,-11,-1,STONE)
Block(-3,-11,0,STONE)
Block(-3,-11,1,STONE)
Block(-3,-11,2,STONE)
Block(-3,-11,3,STONE)
Block(-3,-11,4,STONE)
Block(-3,-10,-6,STONE)
Block(-3,-10,-5,STONE)
Block(-3,-10,-4,STONE)
Block(-3,-10,-3,STONE)
Block(-3,-10,-2,STONE)
Block(-3,-10,-1,STONE)
Block(-3,-10,0,STONE)
Block(-3,-10,1,STONE)
Block(-3,-10,2,STONE)
Block(-3,-10,3,STONE)
Block(-3,-10,4,STONE)
Block(-3,-10,5,STONE)
Block(-3,-10,6,STONE)
Block(-3,-9,-7,STONE)
Block(-3,-9,-6,STONE)
Block(-3,-9,-5,STONE)
Block(-3,-9,-4,STONE)
Block(-3,-9,-3,STONE)
Block(-3,-9,-2,STONE)
Block(-3,-9,-1,STONE)
Block(-3,-9,0,STONE)
Block(-3,-9,1,STONE)
Block(-3,-9,2,STONE)
Block(-3,-9,3,STONE)
Block(-3,-9,4,STONE)
Block(-3,-9,5,STONE)
Block(-3,-9,6,STONE)
Block(-3,-9,7,STONE)
Block(-3,-9,8,STONE)
Block(-3,-8,-7,STONE)
Block(-3,-8,-6,STONE)
Block(-3,-8,-5,STONE)
Block(-3,-8,-4,STONE)
Block(-3,-8,-3,STONE)
Block(-3,-8,-2,STONE)
Block(-3,-8,-1,STONE)
Block(-3,-8,0,STONE)
Block(-3,-8,1,STONE)
Block(-3,-8,2,STONE)
Block(-3,-8,3,STONE)
Block(-3,-8,4,STONE)
Block(-3,-8,5,STONE)
Block(-3,-8,6,STONE)
Block(-3,-8,7,STONE)
Block(-3,-8,8,STONE)
Block(-3,-8,9,STONE)
Block(-3,-7,-7,STONE)
Block(-3,-7,-6,STONE)
Block(-3,-7,-5,STONE)
Block(-3,-7,-4,STONE)
Block(-3,-7,-3,STONE)
Block(-3,-7,-2,STONE)
Block(-3,-7,-1,STONE)
Block(-3,-7,0,STONE)
Block(-3,-7,1,STONE)
Block(-3,-7,2,STONE)
Block(-3,-7,3,STONE)
Block(-3,-7,4,STONE)
Block(-3,-7,5,STONE)
Block(-3,-7,6,STONE)
Block(-3,-7,7,STONE)
Block(-3,-7,8,STONE)
Block(-3,-7,9,STONE)
Block(-3,-6,-7,STONE)
Block(-3,-6,-6,STONE)
Block(-3,-6,-5,STONE)
Block(-3,-6,-4,STONE)
Block(-3,-6,-3,STONE)
Block(-3,-6,-2,STONE)
Block(-3,-6,-1,STONE)
Block(-3,-6,0,STONE)
Block(-3,-6,1,STONE)
Block(-3,-6,2,STONE)
Block(-3,-6,3,STONE)
Block(-3,-6,4,STONE)
Block(-3,-6,5,STONE)
Block(-3,-6,6,STONE)
Block(-3,-6,7,STONE)
Block(-3,-6,8,STONE)
Block(-3,-6,9,STONE)
Block(-3,-5,-6,STONE)
Block(-3,-5,-5,STONE)
Block(-3,-5,-4,STONE)
Block(-3,-5,-3,STONE)
Block(-3,-5,-2,STONE)
Block(-3,-5,-1,STONE)
Block(-3,-5,0,STONE)
Block(-3,-5,1,STONE)
Block(-3,-5,2,STONE)
Block(-3,-5,3,STONE)
Block(-3,-5,4,STONE)
Block(-3,-5,5,STONE)
Block(-3,-5,6,STONE)
Block(-3,-5,7,STONE)
Block(-3,-5,8,STONE)
Block(-3,-4,-6,STONE)
Block(-3,-4,-5,STONE)
Block(-3,-4,-4,STONE)
Block(-3,-4,-3,STONE)
Block(-3,-4,-2,STONE)
Block(-3,-4,-1,STONE)
Block(-3,-4,0,STONE)
Block(-3,-4,1,STONE)
Block(-3,-4,2,STONE)
Block(-3,-4,3,STONE)
Block(-3,-4,4,STONE)
Block(-3,-4,5,STONE)
Block(-3,-4,6,STONE)
Block(-3,-4,7,STONE)
Block(-3,-4,8,STONE)
Block(-3,-3,-6,STONE)
Block(-3,-3,-5,STONE)
Block(-3,-3,-4,STONE)
Block(-3,-3,-3,STONE)
Block(-3,-3,-2,STONE)
Block(-3,-3,-1,STONE)
Block(-3,-3,0,STONE)
Block(-3,-3,1,STONE)
Block(-3,-3,2,STONE)
Block(-3,-3,3,STONE)
Block(-3,-3,4,STONE)
Block(-3,-3,5,STONE)
Block(-3,-3,6,STONE)
Block(-3,-3,7,STONE)
Block(-3,-3,8,STONE)
Block(-3,-2,-6,STONE)
Block(-3,-2,-5,STONE)
Block(-3,-2,-4,STONE)
Block(-3,-2,-3,STONE)
Block(-3,-2,-2,STONE)
Block(-3,-2,-1,STONE)
Block(-3,-2,0,STONE)
Block(-3,-2,1,STONE)
Block(-3,-2,2,STONE)
Block(-3,-2,3,STONE)
Block(-3,-2,4,STONE)
Block(-3,-2,5,STONE)
Block(-3,-2,6,STONE)
Block(-3,-2,7,STONE)
Block(-3,-2,8,STONE)
Block(-3,-1,-6,STONE)
Block(-3,-1,-5,STONE)
Block(-3,-1,-4,STONE)
Block(-3,-1,-3,STONE)
Block(-3,-1,-2,STONE)
Block(-3,-1,-1,STONE)
Block(-3,-1,0,STONE)
Block(-3,-1,1,STONE)
Block(-3,-1,2,STONE)
Block(-3,-1,3,STONE)
Block(-3,-1,4,STONE)
Block(-3,-1,5,STONE)
Block(-3,-1,6,STONE)
Block(-3,-1,7,STONE)
Block(-3,-1,8,STONE)
Block(-3,0,-6,STONE)
Block(-3,0,-5,STONE)
Block(-3,0,-4,STONE)
Block(-3,0,-3,STONE)
Block(-3,0,-2,STONE)
Block(-3,0,-1,STONE)
Block(-3,0,0,STONE)
Block(-3,0,1,STONE)
Block(-3,0,2,STONE)
Block(-3,0,3,STONE)
Block(-3,0,4,STONE)
Block(-3,0,5,STONE)
Block(-3,0,6,STONE)
Block(-3,0,7,STONE)
Block(-3,0,8,STONE)
Block(-3,1,-5,STONE)
Block(-3,1,-4,STONE)
Block(-3,1,-3,STONE)
Block(-3,1,-2,STONE)
Block(-3,1,-1,STONE)
Block(-3,1,0,STONE)
Block(-3,1,1,STONE)
Block(-3,1,2,STONE)
Block(-3,1,3,STONE)
Block(-3,1,4,STONE)
Block(-3,1,5,STONE)
Block(-3,1,6,STONE)
Block(-3,1,7,STONE)
Block(-3,2,-5,STONE)
Block(-3,2,-4,STONE)
Block(-3,2,-3,STONE)
Block(-3,2,-2,STONE)
Block(-3,2,-1,STONE)
Block(-3,2,0,STONE)
Block(-3,2,1,STONE)
Block(-3,2,2,STONE)
Block(-3,2,3,STONE)
Block(-3,2,4,STONE)
Block(-3,2,5,STONE)
Block(-3,2,6,STONE)
Block(-3,3,-5,STONE)
Block(-3,3,-4,STONE)
Block(-3,3,-3,STONE)
Block(-3,3,-2,STONE)
Block(-3,3,-1,STONE)
Block(-3,3,0,STONE)
Block(-3,3,1,STONE)
Block(-3,3,2,STONE)
Block(-3,3,3,STONE)
Block(-3,3,4,STONE)
Block(-3,3,5,STONE)
Block(-3,4,-5,STONE)
Block(-3,4,-4,STONE)
Block(-3,4,-3,STONE)
Block(-3,4,-2,STONE)
Block(-3,4,-1,STONE)
Block(-3,4,0,STONE)
Block(-3,4,1,STONE)
Block(-3,4,2,STONE)
Block(-3,4,3,STONE)
Block(-3,4,4,STONE)
Block(-3,4,5,STONE)
Block(-3,5,-4,STONE)
Block(-3,5,-3,STONE)
Block(-3,5,-2,STONE)
Block(-3,5,-1,STONE)
Block(-3,5,0,STONE)
Block(-3,5,1,STONE)
Block(-3,5,2,STONE)
Block(-3,5,3,STONE)
Block(-3,5,4,STONE)
Block(-3,6,-2,STONE)
Block(-3,6,-1,STONE)
Block(-3,6,0,STONE)
Block(-3,6,1,STONE)
Block(-3,6,2,STONE)
Block(-3,6,3,STONE)
Block(-2,-13,-4,STONE)
Block(-2,-13,-3,STONE)
Block(-2,-13,-2,STONE)
Block(-2,-12,-5,STONE)
Block(-2,-12,-4,STONE)
Block(-2,-12,-3,STONE)
Block(-2,-12,-2,STONE)
Block(-2,-12,-1,STONE)
Block(-2,-12,0,STONE)
Block(-2,-12,1,STONE)
Block(-2,-12,2,STONE)
Block(-2,-11,-7,STONE)
Block(-2,-11,-6,STONE)
Block(-2,-11,-5,STONE)
Block(-2,-11,-4,STONE)
Block(-2,-11,-3,STONE)
Block(-2,-11,-2,STONE)
Block(-2,-11,-1,STONE)
Block(-2,-11,0,STONE)
Block(-2,-11,1,STONE)
Block(-2,-11,2,STONE)
Block(-2,-11,3,STONE)
Block(-2,-11,4,STONE)
Block(-2,-10,-7,STONE)
Block(-2,-10,-6,STONE)
Block(-2,-10,-5,STONE)
Block(-2,-10,-4,STONE)
Block(-2,-10,-3,STONE)
Block(-2,-10,-2,STONE)
Block(-2,-10,-1,STONE)
Block(-2,-10,0,STONE)
Block(-2,-10,1,STONE)
Block(-2,-10,2,STONE)
Block(-2,-10,3,STONE)
Block(-2,-10,4,STONE)
Block(-2,-10,5,STONE)
Block(-2,-10,6,STONE)
Block(-2,-9,-7,STONE)
Block(-2,-9,-6,STONE)
Block(-2,-9,-5,STONE)
Block(-2,-9,-4,STONE)
Block(-2,-9,-3,STONE)
Block(-2,-9,-2,STONE)
Block(-2,-9,-1,STONE)
Block(-2,-9,0,STONE)
Block(-2,-9,1,STONE)
Block(-2,-9,2,STONE)
Block(-2,-9,3,STONE)
Block(-2,-9,4,STONE)
Block(-2,-9,5,STONE)
Block(-2,-9,6,STONE)
Block(-2,-9,7,STONE)
Block(-2,-9,8,STONE)
Block(-2,-8,-7,STONE)
Block(-2,-8,-6,STONE)
Block(-2,-8,-5,STONE)
Block(-2,-8,-4,STONE)
Block(-2,-8,-3,STONE)
Block(-2,-8,-2,STONE)
Block(-2,-8,-1,STONE)
Block(-2,-8,0,STONE)
Block(-2,-8,1,STONE)
Block(-2,-8,2,STONE)
Block(-2,-8,3,STONE)
Block(-2,-8,4,STONE)
Block(-2,-8,5,STONE)
Block(-2,-8,6,STONE)
Block(-2,-8,7,STONE)
Block(-2,-8,8,STONE)
Block(-2,-8,9,STONE)
Block(-2,-7,-7,STONE)
Block(-2,-7,-6,STONE)
Block(-2,-7,-5,STONE)
Block(-2,-7,-4,STONE)
Block(-2,-7,-3,STONE)
Block(-2,-7,-2,STONE)
Block(-2,-7,-1,STONE)
Block(-2,-7,0,STONE)
Block(-2,-7,1,STONE)
Block(-2,-7,2,STONE)
Block(-2,-7,3,STONE)
Block(-2,-7,4,STONE)
Block(-2,-7,5,STONE)
Block(-2,-7,6,STONE)
Block(-2,-7,7,STONE)
Block(-2,-7,8,STONE)
Block(-2,-7,9,STONE)
Block(-2,-6,-7,STONE)
Block(-2,-6,-6,STONE)
Block(-2,-6,-5,STONE)
Block(-2,-6,-4,STONE)
Block(-2,-6,-3,STONE)
Block(-2,-6,-2,STONE)
Block(-2,-6,-1,STONE)
Block(-2,-6,0,STONE)
Block(-2,-6,1,STONE)
Block(-2,-6,2,STONE)
Block(-2,-6,3,STONE)
Block(-2,-6,4,STONE)
Block(-2,-6,5,STONE)
Block(-2,-6,6,STONE)
Block(-2,-6,7,STONE)
Block(-2,-6,8,STONE)
Block(-2,-5,-7,STONE)
Block(-2,-5,-6,STONE)
Block(-2,-5,-5,STONE)
Block(-2,-5,-4,STONE)
Block(-2,-5,-3,STONE)
Block(-2,-5,-2,STONE)
Block(-2,-5,-1,STONE)
Block(-2,-5,0,STONE)
Block(-2,-5,1,STONE)
Block(-2,-5,2,STONE)
Block(-2,-5,3,STONE)
Block(-2,-5,4,STONE)
Block(-2,-5,5,STONE)
Block(-2,-5,6,STONE)
Block(-2,-5,7,STONE)
Block(-2,-5,8,STONE)
Block(-2,-4,-7,STONE)
Block(-2,-4,-6,STONE)
Block(-2,-4,-5,STONE)
Block(-2,-4,-4,STONE)
Block(-2,-4,-3,STONE)
Block(-2,-4,-2,STONE)
Block(-2,-4,-1,STONE)
Block(-2,-4,0,STONE)
Block(-2,-4,1,STONE)
Block(-2,-4,2,STONE)
Block(-2,-4,3,STONE)
Block(-2,-4,4,STONE)
Block(-2,-4,5,STONE)
Block(-2,-4,6,STONE)
Block(-2,-4,7,STONE)
Block(-2,-4,8,STONE)
Block(-2,-3,-7,STONE)
Block(-2,-3,-6,STONE)
Block(-2,-3,-5,STONE)
Block(-2,-3,-4,STONE)
Block(-2,-3,-3,STONE)
Block(-2,-3,-2,STONE)
Block(-2,-3,-1,STONE)
Block(-2,-3,0,STONE)
Block(-2,-3,1,STONE)
Block(-2,-3,2,STONE)
Block(-2,-3,3,STONE)
Block(-2,-3,4,STONE)
Block(-2,-3,5,STONE)
Block(-2,-3,6,STONE)
Block(-2,-3,7,STONE)
Block(-2,-3,8,STONE)
Block(-2,-2,-7,STONE)
Block(-2,-2,-6,STONE)
Block(-2,-2,-5,STONE)
Block(-2,-2,-4,STONE)
Block(-2,-2,-3,STONE)
Block(-2,-2,-2,STONE)
Block(-2,-2,-1,STONE)
Block(-2,-2,0,STONE)
Block(-2,-2,1,STONE)
Block(-2,-2,2,STONE)
Block(-2,-2,3,STONE)
Block(-2,-2,4,STONE)
Block(-2,-2,5,STONE)
Block(-2,-2,6,STONE)
Block(-2,-2,7,STONE)
Block(-2,-2,8,STONE)
Block(-2,-1,-6,STONE)
Block(-2,-1,-5,STONE)
Block(-2,-1,-4,STONE)
Block(-2,-1,-3,STONE)
Block(-2,-1,-2,STONE)
Block(-2,-1,-1,STONE)
Block(-2,-1,0,STONE)
Block(-2,-1,1,STONE)
Block(-2,-1,2,STONE)
Block(-2,-1,3,STONE)
Block(-2,-1,4,STONE)
Block(-2,-1,5,STONE)
Block(-2,-1,6,STONE)
Block(-2,-1,7,STONE)
Block(-2,-1,8,STONE)
Block(-2,0,-6,STONE)
Block(-2,0,-5,STONE)
Block(-2,0,-4,STONE)
Block(-2,0,-3,STONE)
Block(-2,0,-2,STONE)
Block(-2,0,-1,STONE)
Block(-2,0,0,STONE)
Block(-2,0,1,STONE)
Block(-2,0,2,STONE)
Block(-2,0,3,STONE)
Block(-2,0,4,STONE)
Block(-2,0,5,STONE)
Block(-2,0,6,STONE)
Block(-2,0,7,STONE)
Block(-2,1,-6,STONE)
Block(-2,1,-5,STONE)
Block(-2,1,-4,STONE)
Block(-2,1,-3,STONE)
Block(-2,1,-2,STONE)
Block(-2,1,-1,STONE)
Block(-2,1,0,STONE)
Block(-2,1,1,STONE)
Block(-2,1,2,STONE)
Block(-2,1,3,STONE)
Block(-2,1,4,STONE)
Block(-2,1,5,STONE)
Block(-2,1,6,STONE)
Block(-2,1,7,STONE)
Block(-2,2,-6,STONE)
Block(-2,2,-5,STONE)
Block(-2,2,-4,STONE)
Block(-2,2,-3,STONE)
Block(-2,2,-2,STONE)
Block(-2,2,-1,STONE)
Block(-2,2,0,STONE)
Block(-2,2,1,STONE)
Block(-2,2,2,STONE)
Block(-2,2,3,STONE)
Block(-2,2,4,STONE)
Block(-2,2,5,STONE)
Block(-2,2,6,STONE)
Block(-2,2,7,STONE)
Block(-2,3,-6,STONE)
Block(-2,3,-5,STONE)
Block(-2,3,-4,STONE)
Block(-2,3,-3,STONE)
Block(-2,3,-2,STONE)
Block(-2,3,-1,STONE)
Block(-2,3,0,STONE)
Block(-2,3,1,STONE)
Block(-2,3,2,STONE)
Block(-2,3,3,STONE)
Block(-2,3,4,STONE)
Block(-2,3,5,STONE)
Block(-2,3,6,STONE)
Block(-2,4,-5,STONE)
Block(-2,4,-4,STONE)
Block(-2,4,-3,STONE)
Block(-2,4,-2,STONE)
Block(-2,4,-1,STONE)
Block(-2,4,0,STONE)
Block(-2,4,1,STONE)
Block(-2,4,2,STONE)
Block(-2,4,3,STONE)
Block(-2,4,4,STONE)
Block(-2,4,5,STONE)
Block(-2,4,6,STONE)
Block(-2,5,-4,STONE)
Block(-2,5,-3,STONE)
Block(-2,5,-2,STONE)
Block(-2,5,-1,STONE)
Block(-2,5,0,STONE)
Block(-2,5,1,STONE)
Block(-2,5,2,STONE)
Block(-2,5,3,STONE)
Block(-2,5,4,STONE)
Block(-2,5,5,STONE)
Block(-2,6,-1,STONE)
Block(-2,6,0,STONE)
Block(-2,6,1,STONE)
Block(-2,6,2,STONE)
Block(-2,6,3,STONE)
Block(-2,6,4,STONE)
Block(-1,-13,-5,STONE)
Block(-1,-13,-4,STONE)
Block(-1,-13,-3,STONE)
Block(-1,-13,-2,STONE)
Block(-1,-13,-1,STONE)
Block(-1,-12,-6,STONE)
Block(-1,-12,-5,STONE)
Block(-1,-12,-4,STONE)
Block(-1,-12,-3,STONE)
Block(-1,-12,-2,STONE)
Block(-1,-12,-1,STONE)
Block(-1,-12,0,STONE)
Block(-1,-12,1,STONE)
Block(-1,-12,2,STONE)
Block(-1,-11,-7,STONE)
Block(-1,-11,-6,STONE)
Block(-1,-11,-5,STONE)
Block(-1,-11,-4,STONE)
Block(-1,-11,-3,STONE)
Block(-1,-11,-2,STONE)
Block(-1,-11,-1,STONE)
Block(-1,-11,0,STONE)
Block(-1,-11,1,STONE)
Block(-1,-11,2,STONE)
Block(-1,-11,3,STONE)
Block(-1,-11,4,STONE)
Block(-1,-10,-7,STONE)
Block(-1,-10,-6,STONE)
Block(-1,-10,-5,STONE)
Block(-1,-10,-4,STONE)
Block(-1,-10,-3,STONE)
Block(-1,-10,-2,STONE)
Block(-1,-10,-1,STONE)
Block(-1,-10,0,STONE)
Block(-1,-10,1,STONE)
Block(-1,-10,2,STONE)
Block(-1,-10,3,STONE)
Block(-1,-10,4,STONE)
Block(-1,-10,5,STONE)
Block(-1,-10,6,STONE)
Block(-1,-9,-7,STONE)
Block(-1,-9,-6,STONE)
Block(-1,-9,-5,STONE)
Block(-1,-9,-4,STONE)
Block(-1,-9,-3,STONE)
Block(-1,-9,-2,STONE)
Block(-1,-9,-1,STONE)
Block(-1,-9,0,STONE)
Block(-1,-9,1,STONE)
Block(-1,-9,2,STONE)
Block(-1,-9,3,STONE)
Block(-1,-9,4,STONE)
Block(-1,-9,5,STONE)
Block(-1,-9,6,STONE)
Block(-1,-9,7,STONE)
Block(-1,-9,8,STONE)
Block(-1,-8,-7,STONE)
Block(-1,-8,-6,STONE)
Block(-1,-8,-5,STONE)
Block(-1,-8,-4,STONE)
Block(-1,-8,-3,STONE)
Block(-1,-8,-2,STONE)
Block(-1,-8,-1,STONE)
Block(-1,-8,0,STONE)
Block(-1,-8,1,STONE)
Block(-1,-8,2,STONE)
Block(-1,-8,3,STONE)
Block(-1,-8,4,STONE)
Block(-1,-8,5,STONE)
Block(-1,-8,6,STONE)
Block(-1,-8,7,STONE)
Block(-1,-8,8,STONE)
Block(-1,-8,9,STONE)
Block(-1,-7,-8,STONE)
Block(-1,-7,-7,STONE)
Block(-1,-7,-6,STONE)
Block(-1,-7,-5,STONE)
Block(-1,-7,-4,STONE)
Block(-1,-7,-3,STONE)
Block(-1,-7,-2,STONE)
Block(-1,-7,-1,STONE)
Block(-1,-7,0,STONE)
Block(-1,-7,1,STONE)
Block(-1,-7,2,STONE)
Block(-1,-7,3,STONE)
Block(-1,-7,4,STONE)
Block(-1,-7,5,STONE)
Block(-1,-7,6,STONE)
Block(-1,-7,7,STONE)
Block(-1,-7,8,STONE)
Block(-1,-6,-8,STONE)
Block(-1,-6,-7,STONE)
Block(-1,-6,-6,STONE)
Block(-1,-6,-5,STONE)
Block(-1,-6,-4,STONE)
Block(-1,-6,-3,STONE)
Block(-1,-6,-2,STONE)
Block(-1,-6,-1,STONE)
Block(-1,-6,0,STONE)
Block(-1,-6,1,STONE)
Block(-1,-6,2,STONE)
Block(-1,-6,3,STONE)
Block(-1,-6,4,STONE)
Block(-1,-6,5,STONE)
Block(-1,-6,6,STONE)
Block(-1,-6,7,STONE)
Block(-1,-6,8,STONE)
Block(-1,-5,-8,STONE)
Block(-1,-5,-7,STONE)
Block(-1,-5,-6,STONE)
Block(-1,-5,-5,STONE)
Block(-1,-5,-4,STONE)
Block(-1,-5,-3,STONE)
Block(-1,-5,-2,STONE)
Block(-1,-5,-1,STONE)
Block(-1,-5,0,STONE)
Block(-1,-5,1,STONE)
Block(-1,-5,2,STONE)
Block(-1,-5,3,STONE)
Block(-1,-5,4,STONE)
Block(-1,-5,5,STONE)
Block(-1,-5,6,STONE)
Block(-1,-5,7,STONE)
Block(-1,-5,8,STONE)
Block(-1,-4,-8,STONE)
Block(-1,-4,-7,STONE)
Block(-1,-4,-6,STONE)
Block(-1,-4,-5,STONE)
Block(-1,-4,-4,STONE)
Block(-1,-4,-3,STONE)
Block(-1,-4,-2,STONE)
Block(-1,-4,-1,STONE)
Block(-1,-4,0,STONE)
Block(-1,-4,1,STONE)
Block(-1,-4,2,STONE)
Block(-1,-4,3,STONE)
Block(-1,-4,4,STONE)
Block(-1,-4,5,STONE)
Block(-1,-4,6,STONE)
Block(-1,-4,7,STONE)
Block(-1,-4,8,STONE)
Block(-1,-3,-7,STONE)
Block(-1,-3,-6,STONE)
Block(-1,-3,-5,STONE)
Block(-1,-3,-4,STONE)
Block(-1,-3,-3,STONE)
Block(-1,-3,-2,STONE)
Block(-1,-3,-1,STONE)
Block(-1,-3,0,STONE)
Block(-1,-3,1,STONE)
Block(-1,-3,2,STONE)
Block(-1,-3,3,STONE)
Block(-1,-3,4,STONE)
Block(-1,-3,5,STONE)
Block(-1,-3,6,STONE)
Block(-1,-3,7,STONE)
Block(-1,-3,8,STONE)
Block(-1,-2,-7,STONE)
Block(-1,-2,-6,STONE)
Block(-1,-2,-5,STONE)
Block(-1,-2,-4,STONE)
Block(-1,-2,-3,STONE)
Block(-1,-2,-2,STONE)
Block(-1,-2,-1,STONE)
Block(-1,-2,0,STONE)
Block(-1,-2,1,STONE)
Block(-1,-2,2,STONE)
Block(-1,-2,3,STONE)
Block(-1,-2,4,STONE)
Block(-1,-2,5,STONE)
Block(-1,-2,6,STONE)
Block(-1,-2,7,STONE)
Block(-1,-2,8,STONE)
Block(-1,-1,-7,STONE)
Block(-1,-1,-6,STONE)
Block(-1,-1,-5,STONE)
Block(-1,-1,-4,STONE)
Block(-1,-1,-3,STONE)
Block(-1,-1,-2,STONE)
Block(-1,-1,-1,STONE)
Block(-1,-1,0,STONE)
Block(-1,-1,1,STONE)
Block(-1,-1,2,STONE)
Block(-1,-1,3,STONE)
Block(-1,-1,4,STONE)
Block(-1,-1,5,STONE)
Block(-1,-1,6,STONE)
Block(-1,-1,7,STONE)
Block(-1,-1,8,STONE)
Block(-1,0,-7,STONE)
Block(-1,0,-6,STONE)
Block(-1,0,-5,STONE)
Block(-1,0,-4,STONE)
Block(-1,0,-3,STONE)
Block(-1,0,-2,STONE)
Block(-1,0,-1,STONE)
Block(-1,0,0,STONE)
Block(-1,0,1,STONE)
Block(-1,0,2,STONE)
Block(-1,0,3,STONE)
Block(-1,0,4,STONE)
Block(-1,0,5,STONE)
Block(-1,0,6,STONE)
Block(-1,0,7,STONE)
Block(-1,1,-7,STONE)
Block(-1,1,-6,STONE)
Block(-1,1,-5,STONE)
Block(-1,1,-4,STONE)
Block(-1,1,-3,STONE)
Block(-1,1,-2,STONE)
Block(-1,1,-1,STONE)
Block(-1,1,0,STONE)
Block(-1,1,1,STONE)
Block(-1,1,2,STONE)
Block(-1,1,3,STONE)
Block(-1,1,4,STONE)
Block(-1,1,5,STONE)
Block(-1,1,6,STONE)
Block(-1,1,7,STONE)
Block(-1,2,-6,STONE)
Block(-1,2,-5,STONE)
Block(-1,2,-4,STONE)
Block(-1,2,-3,STONE)
Block(-1,2,-2,STONE)
Block(-1,2,-1,STONE)
Block(-1,2,0,STONE)
Block(-1,2,1,STONE)
Block(-1,2,2,STONE)
Block(-1,2,3,STONE)
Block(-1,2,4,STONE)
Block(-1,2,5,STONE)
Block(-1,2,6,STONE)
Block(-1,2,7,STONE)
Block(-1,3,-6,STONE)
Block(-1,3,-5,STONE)
Block(-1,3,-4,STONE)
Block(-1,3,-3,STONE)
Block(-1,3,-2,STONE)
Block(-1,3,-1,STONE)
Block(-1,3,0,STONE)
Block(-1,3,1,STONE)
Block(-1,3,2,STONE)
Block(-1,3,3,STONE)
Block(-1,3,4,STONE)
Block(-1,3,5,STONE)
Block(-1,3,6,STONE)
Block(-1,4,-6,STONE)
Block(-1,4,-5,STONE)
Block(-1,4,-4,STONE)
Block(-1,4,-3,STONE)
Block(-1,4,-2,STONE)
Block(-1,4,-1,STONE)
Block(-1,4,0,STONE)
Block(-1,4,1,STONE)
Block(-1,4,2,STONE)
Block(-1,4,3,STONE)
Block(-1,4,4,STONE)
Block(-1,4,5,STONE)
Block(-1,4,6,STONE)
Block(-1,5,-2,STONE)
Block(-1,5,-1,STONE)
Block(-1,5,0,STONE)
Block(-1,5,1,STONE)
Block(-1,5,2,STONE)
Block(-1,5,3,STONE)
Block(-1,5,4,STONE)
Block(-1,5,5,STONE)
Block(-1,6,1,STONE)
Block(-1,6,2,STONE)
Block(-1,6,3,STONE)
Block(-1,6,4,STONE)
Block(0,-13,-4,STONE)
Block(0,-13,-3,STONE)
Block(0,-13,-2,STONE)
Block(0,-13,-1,STONE)
Block(0,-12,-6,STONE)
Block(0,-12,-5,STONE)
Block(0,-12,-4,STONE)
Block(0,-12,-3,STONE)
Block(0,-12,-2,STONE)
Block(0,-12,-1,STONE)
Block(0,-12,0,STONE)
Block(0,-12,1,STONE)
Block(0,-11,-6,STONE)
Block(0,-11,-5,STONE)
Block(0,-11,-4,STONE)
Block(0,-11,-3,STONE)
Block(0,-11,-2,STONE)
Block(0,-11,-1,STONE)
Block(0,-11,0,STONE)
Block(0,-11,1,STONE)
Block(0,-11,2,STONE)
Block(0,-11,3,STONE)
Block(0,-11,4,STONE)
Block(0,-10,-7,STONE)
Block(0,-10,-6,STONE)
Block(0,-10,-5,STONE)
Block(0,-10,-4,STONE)
Block(0,-10,-3,STONE)
Block(0,-10,-2,STONE)
Block(0,-10,-1,STONE)
Block(0,-10,0,STONE)
Block(0,-10,1,STONE)
Block(0,-10,2,STONE)
Block(0,-10,3,STONE)
Block(0,-10,4,STONE)
Block(0,-10,5,STONE)
Block(0,-10,6,STONE)
Block(0,-10,7,STONE)
Block(0,-9,-7,STONE)
Block(0,-9,-6,STONE)
Block(0,-9,-5,STONE)
Block(0,-9,-4,STONE)
Block(0,-9,-3,STONE)
Block(0,-9,-2,STONE)
Block(0,-9,-1,STONE)
Block(0,-9,0,STONE)
Block(0,-9,1,STONE)
Block(0,-9,2,STONE)
Block(0,-9,3,STONE)
Block(0,-9,4,STONE)
Block(0,-9,5,STONE)
Block(0,-9,6,STONE)
Block(0,-9,7,STONE)
Block(0,-9,8,STONE)
Block(0,-8,-7,STONE)
Block(0,-8,-6,STONE)
Block(0,-8,-5,STONE)
Block(0,-8,-4,STONE)
Block(0,-8,-3,STONE)
Block(0,-8,-2,STONE)
Block(0,-8,-1,STONE)
Block(0,-8,0,STONE)
Block(0,-8,1,STONE)
Block(0,-8,2,STONE)
Block(0,-8,3,STONE)
Block(0,-8,4,STONE)
Block(0,-8,5,STONE)
Block(0,-8,6,STONE)
Block(0,-8,7,STONE)
Block(0,-8,8,STONE)
Block(0,-8,9,STONE)
Block(0,-7,-7,STONE)
Block(0,-7,-6,STONE)
Block(0,-7,-5,STONE)
Block(0,-7,-4,STONE)
Block(0,-7,-3,STONE)
Block(0,-7,-2,STONE)
Block(0,-7,-1,STONE)
Block(0,-7,0,STONE)
Block(0,-7,1,STONE)
Block(0,-7,2,STONE)
Block(0,-7,3,STONE)
Block(0,-7,4,STONE)
Block(0,-7,5,STONE)
Block(0,-7,6,STONE)
Block(0,-7,7,STONE)
Block(0,-7,8,STONE)
Block(0,-6,-8,STONE)
Block(0,-6,-7,STONE)
Block(0,-6,-6,STONE)
Block(0,-6,-5,STONE)
Block(0,-6,-4,STONE)
Block(0,-6,-3,STONE)
Block(0,-6,-2,STONE)
Block(0,-6,-1,STONE)
Block(0,-6,0,STONE)
Block(0,-6,1,STONE)
Block(0,-6,2,STONE)
Block(0,-6,3,STONE)
Block(0,-6,4,STONE)
Block(0,-6,5,STONE)
Block(0,-6,6,STONE)
Block(0,-6,7,STONE)
Block(0,-6,8,STONE)
Block(0,-5,-8,STONE)
Block(0,-5,-7,STONE)
Block(0,-5,-6,STONE)
Block(0,-5,-5,STONE)
Block(0,-5,-4,STONE)
Block(0,-5,-3,STONE)
Block(0,-5,-2,STONE)
Block(0,-5,-1,STONE)
Block(0,-5,0,STONE)
Block(0,-5,1,STONE)
Block(0,-5,2,STONE)
Block(0,-5,3,STONE)
Block(0,-5,4,STONE)
Block(0,-5,5,STONE)
Block(0,-5,6,STONE)
Block(0,-5,7,STONE)
Block(0,-5,8,STONE)
Block(0,-4,-8,STONE)
Block(0,-4,-7,STONE)
Block(0,-4,-6,STONE)
Block(0,-4,-5,STONE)
Block(0,-4,-4,STONE)
Block(0,-4,-3,STONE)
Block(0,-4,-2,STONE)
Block(0,-4,-1,STONE)
Block(0,-4,0,STONE)
Block(0,-4,1,STONE)
Block(0,-4,2,STONE)
Block(0,-4,3,STONE)
Block(0,-4,4,STONE)
Block(0,-4,5,STONE)
Block(0,-4,6,STONE)
Block(0,-4,7,STONE)
Block(0,-4,8,STONE)
Block(0,-3,-8,STONE)
Block(0,-3,-7,STONE)
Block(0,-3,-6,STONE)
Block(0,-3,-5,STONE)
Block(0,-3,-4,STONE)
Block(0,-3,-3,STONE)
Block(0,-3,-2,STONE)
Block(0,-3,-1,STONE)
Block(0,-3,0,STONE)
Block(0,-3,1,STONE)
Block(0,-3,2,STONE)
Block(0,-3,3,STONE)
Block(0,-3,4,STONE)
Block(0,-3,5,STONE)
Block(0,-3,6,STONE)
Block(0,-3,7,STONE)
Block(0,-3,8,STONE)
Block(0,-2,-8,STONE)
Block(0,-2,-7,STONE)
Block(0,-2,-6,STONE)
Block(0,-2,-5,STONE)
Block(0,-2,-4,STONE)
Block(0,-2,-3,STONE)
Block(0,-2,-2,STONE)
Block(0,-2,-1,STONE)
Block(0,-2,0,STONE)
Block(0,-2,1,STONE)
Block(0,-2,2,STONE)
Block(0,-2,3,STONE)
Block(0,-2,4,STONE)
Block(0,-2,5,STONE)
Block(0,-2,6,STONE)
Block(0,-2,7,STONE)
Block(0,-2,8,STONE)
Block(0,-1,-8,STONE)
Block(0,-1,-7,STONE)
Block(0,-1,-6,STONE)
Block(0,-1,-5,STONE)
Block(0,-1,-4,STONE)
Block(0,-1,-3,STONE)
Block(0,-1,-2,STONE)
Block(0,-1,-1,STONE)
Block(0,-1,0,STONE)
Block(0,-1,1,STONE)
Block(0,-1,2,STONE)
Block(0,-1,3,STONE)
Block(0,-1,4,STONE)
Block(0,-1,5,STONE)
Block(0,-1,6,STONE)
Block(0,-1,7,STONE)
Block(0,0,-7,STONE)
Block(0,0,-6,STONE)
Block(0,0,-5,STONE)
Block(0,0,-4,STONE)
Block(0,0,-3,STONE)
Block(0,0,-2,STONE)
Block(0,0,-1,STONE)
Block(0,0,0,STONE)
Block(0,0,1,STONE)
Block(0,0,2,STONE)
Block(0,0,3,STONE)
Block(0,0,4,STONE)
Block(0,0,5,STONE)
Block(0,0,6,STONE)
Block(0,0,7,STONE)
Block(0,1,-7,STONE)
Block(0,1,-6,STONE)
Block(0,1,-5,STONE)
Block(0,1,-4,STONE)
Block(0,1,-3,STONE)
Block(0,1,-2,STONE)
Block(0,1,-1,STONE)
Block(0,1,0,STONE)
Block(0,1,1,STONE)
Block(0,1,2,STONE)
Block(0,1,3,STONE)
Block(0,1,4,STONE)
Block(0,1,5,STONE)
Block(0,1,6,STONE)
Block(0,1,7,STONE)
Block(0,2,-7,STONE)
Block(0,2,-6,STONE)
Block(0,2,-5,STONE)
Block(0,2,-4,STONE)
Block(0,2,-3,STONE)
Block(0,2,-2,STONE)
Block(0,2,-1,STONE)
Block(0,2,0,STONE)
Block(0,2,1,STONE)
Block(0,2,2,STONE)
Block(0,2,3,STONE)
Block(0,2,4,STONE)
Block(0,2,5,STONE)
Block(0,2,6,STONE)
Block(0,3,-7,STONE)
Block(0,3,-6,STONE)
Block(0,3,-5,STONE)
Block(0,3,-4,STONE)
Block(0,3,-3,STONE)
Block(0,3,-2,STONE)
Block(0,3,-1,STONE)
Block(0,3,0,STONE)
Block(0,3,1,STONE)
Block(0,3,2,STONE)
Block(0,3,3,STONE)
Block(0,3,4,STONE)
Block(0,3,5,STONE)
Block(0,3,6,STONE)
Block(0,4,-4,STONE)
Block(0,4,-3,STONE)
Block(0,4,-2,STONE)
Block(0,4,-1,STONE)
Block(0,4,0,STONE)
Block(0,4,1,STONE)
Block(0,4,2,STONE)
Block(0,4,3,STONE)
Block(0,4,4,STONE)
Block(0,4,5,STONE)
Block(0,4,6,STONE)
Block(0,5,0,STONE)
Block(0,5,1,STONE)
Block(0,5,2,STONE)
Block(0,5,3,STONE)
Block(0,5,4,STONE)
Block(0,5,5,STONE)
Block(0,6,3,STONE)
Block(0,6,4,STONE)
Block(1,-13,-3,STONE)
Block(1,-13,-2,STONE)
Block(1,-13,-1,STONE)
Block(1,-12,-5,STONE)
Block(1,-12,-4,STONE)
Block(1,-12,-3,STONE)
Block(1,-12,-2,STONE)
Block(1,-12,-1,STONE)
Block(1,-12,0,STONE)
Block(1,-12,1,STONE)
Block(1,-11,-6,STONE)
Block(1,-11,-5,STONE)
Block(1,-11,-4,STONE)
Block(1,-11,-3,STONE)
Block(1,-11,-2,STONE)
Block(1,-11,-1,STONE)
Block(1,-11,0,STONE)
Block(1,-11,1,STONE)
Block(1,-11,2,STONE)
Block(1,-11,3,STONE)
Block(1,-11,4,STONE)
Block(1,-10,-6,STONE)
Block(1,-10,-5,STONE)
Block(1,-10,-4,STONE)
Block(1,-10,-3,STONE)
Block(1,-10,-2,STONE)
Block(1,-10,-1,STONE)
Block(1,-10,0,STONE)
Block(1,-10,1,STONE)
Block(1,-10,2,STONE)
Block(1,-10,3,STONE)
Block(1,-10,4,STONE)
Block(1,-10,5,STONE)
Block(1,-10,6,STONE)
Block(1,-10,7,STONE)
Block(1,-9,-7,STONE)
Block(1,-9,-6,STONE)
Block(1,-9,-5,STONE)
Block(1,-9,-4,STONE)
Block(1,-9,-3,STONE)
Block(1,-9,-2,STONE)
Block(1,-9,-1,STONE)
Block(1,-9,0,STONE)
Block(1,-9,1,STONE)
Block(1,-9,2,STONE)
Block(1,-9,3,STONE)
Block(1,-9,4,STONE)
Block(1,-9,5,STONE)
Block(1,-9,6,STONE)
Block(1,-9,7,STONE)
Block(1,-9,8,STONE)
Block(1,-8,-7,STONE)
Block(1,-8,-6,STONE)
Block(1,-8,-5,STONE)
Block(1,-8,-4,STONE)
Block(1,-8,-3,STONE)
Block(1,-8,-2,STONE)
Block(1,-8,-1,STONE)
Block(1,-8,0,STONE)
Block(1,-8,1,STONE)
Block(1,-8,2,STONE)
Block(1,-8,3,STONE)
Block(1,-8,4,STONE)
Block(1,-8,5,STONE)
Block(1,-8,6,STONE)
Block(1,-8,7,STONE)
Block(1,-8,8,STONE)
Block(1,-8,9,STONE)
Block(1,-7,-7,STONE)
Block(1,-7,-6,STONE)
Block(1,-7,-5,STONE)
Block(1,-7,-4,STONE)
Block(1,-7,-3,STONE)
Block(1,-7,-2,STONE)
Block(1,-7,-1,STONE)
Block(1,-7,0,STONE)
Block(1,-7,1,STONE)
Block(1,-7,2,STONE)
Block(1,-7,3,STONE)
Block(1,-7,4,STONE)
Block(1,-7,5,STONE)
Block(1,-7,6,STONE)
Block(1,-7,7,STONE)
Block(1,-7,8,STONE)
Block(1,-6,-7,STONE)
Block(1,-6,-6,STONE)
Block(1,-6,-5,STONE)
Block(1,-6,-4,STONE)
Block(1,-6,-3,STONE)
Block(1,-6,-2,STONE)
Block(1,-6,-1,STONE)
Block(1,-6,0,STONE)
Block(1,-6,1,STONE)
Block(1,-6,2,STONE)
Block(1,-6,3,STONE)
Block(1,-6,4,STONE)
Block(1,-6,5,STONE)
Block(1,-6,6,STONE)
Block(1,-6,7,STONE)
Block(1,-6,8,STONE)
Block(1,-5,-8,STONE)
Block(1,-5,-7,STONE)
Block(1,-5,-6,STONE)
Block(1,-5,-5,STONE)
Block(1,-5,-4,STONE)
Block(1,-5,-3,STONE)
Block(1,-5,-2,STONE)
Block(1,-5,-1,STONE)
Block(1,-5,0,STONE)
Block(1,-5,1,STONE)
Block(1,-5,2,STONE)
Block(1,-5,3,STONE)
Block(1,-5,4,STONE)
Block(1,-5,5,STONE)
Block(1,-5,6,STONE)
Block(1,-5,7,STONE)
Block(1,-5,8,STONE)
Block(1,-4,-8,STONE)
Block(1,-4,-7,STONE)
Block(1,-4,-6,STONE)
Block(1,-4,-5,STONE)
Block(1,-4,-4,STONE)
Block(1,-4,-3,STONE)
Block(1,-4,-2,STONE)
Block(1,-4,-1,STONE)
Block(1,-4,0,STONE)
Block(1,-4,1,STONE)
Block(1,-4,2,STONE)
Block(1,-4,3,STONE)
Block(1,-4,4,STONE)
Block(1,-4,5,STONE)
Block(1,-4,6,STONE)
Block(1,-4,7,STONE)
Block(1,-4,8,STONE)
Block(1,-3,-8,STONE)
Block(1,-3,-7,STONE)
Block(1,-3,-6,STONE)
Block(1,-3,-5,STONE)
Block(1,-3,-4,STONE)
Block(1,-3,-3,STONE)
Block(1,-3,-2,STONE)
Block(1,-3,-1,STONE)
Block(1,-3,0,STONE)
Block(1,-3,1,STONE)
Block(1,-3,2,STONE)
Block(1,-3,3,STONE)
Block(1,-3,4,STONE)
Block(1,-3,5,STONE)
Block(1,-3,6,STONE)
Block(1,-3,7,STONE)
Block(1,-3,8,STONE)
Block(1,-2,-8,STONE)
Block(1,-2,-7,STONE)
Block(1,-2,-6,STONE)
Block(1,-2,-5,STONE)
Block(1,-2,-4,STONE)
Block(1,-2,-3,STONE)
Block(1,-2,-2,STONE)
Block(1,-2,-1,STONE)
Block(1,-2,0,STONE)
Block(1,-2,1,STONE)
Block(1,-2,2,STONE)
Block(1,-2,3,STONE)
Block(1,-2,4,STONE)
Block(1,-2,5,STONE)
Block(1,-2,6,STONE)
Block(1,-2,7,STONE)
Block(1,-2,8,STONE)
Block(1,-1,-8,STONE)
Block(1,-1,-7,STONE)
Block(1,-1,-6,STONE)
Block(1,-1,-5,STONE)
Block(1,-1,-4,STONE)
Block(1,-1,-3,STONE)
Block(1,-1,-2,STONE)
Block(1,-1,-1,STONE)
Block(1,-1,0,STONE)
Block(1,-1,1,STONE)
Block(1,-1,2,STONE)
Block(1,-1,3,STONE)
Block(1,-1,4,STONE)
Block(1,-1,5,STONE)
Block(1,-1,6,STONE)
Block(1,-1,7,STONE)
Block(1,0,-8,STONE)
Block(1,0,-7,STONE)
Block(1,0,-6,STONE)
Block(1,0,-5,STONE)
Block(1,0,-4,STONE)
Block(1,0,-3,STONE)
Block(1,0,-2,STONE)
Block(1,0,-1,STONE)
Block(1,0,0,STONE)
Block(1,0,1,STONE)
Block(1,0,2,STONE)
Block(1,0,3,STONE)
Block(1,0,4,STONE)
Block(1,0,5,STONE)
Block(1,0,6,STONE)
Block(1,0,7,STONE)
Block(1,1,-8,STONE)
Block(1,1,-7,STONE)
Block(1,1,-6,STONE)
Block(1,1,-5,STONE)
Block(1,1,-4,STONE)
Block(1,1,-3,STONE)
Block(1,1,-2,STONE)
Block(1,1,-1,STONE)
Block(1,1,0,STONE)
Block(1,1,1,STONE)
Block(1,1,2,STONE)
Block(1,1,3,STONE)
Block(1,1,4,STONE)
Block(1,1,5,STONE)
Block(1,1,6,STONE)
Block(1,1,7,STONE)
Block(1,2,-8,STONE)
Block(1,2,-7,STONE)
Block(1,2,-6,STONE)
Block(1,2,-5,STONE)
Block(1,2,-4,STONE)
Block(1,2,-3,STONE)
Block(1,2,-2,STONE)
Block(1,2,-1,STONE)
Block(1,2,0,STONE)
Block(1,2,1,STONE)
Block(1,2,2,STONE)
Block(1,2,3,STONE)
Block(1,2,4,STONE)
Block(1,2,5,STONE)
Block(1,2,6,STONE)
Block(1,3,-6,STONE)
Block(1,3,-5,STONE)
Block(1,3,-4,STONE)
Block(1,3,-3,STONE)
Block(1,3,-2,STONE)
Block(1,3,-1,STONE)
Block(1,3,0,STONE)
Block(1,3,1,STONE)
Block(1,3,2,STONE)
Block(1,3,3,STONE)
Block(1,3,4,STONE)
Block(1,3,5,STONE)
Block(1,3,6,STONE)
Block(1,4,-2,STONE)
Block(1,4,-1,STONE)
Block(1,4,0,STONE)
Block(1,4,1,STONE)
Block(1,4,2,STONE)
Block(1,4,3,STONE)
Block(1,4,4,STONE)
Block(1,4,5,STONE)
Block(1,5,1,STONE)
Block(1,5,2,STONE)
Block(1,5,3,STONE)
Block(1,5,4,STONE)
Block(2,-13,-3,STONE)
Block(2,-13,-2,STONE)
Block(2,-13,-1,STONE)
Block(2,-12,-4,STONE)
Block(2,-12,-3,STONE)
Block(2,-12,-2,STONE)
Block(2,-12,-1,STONE)
Block(2,-12,0,STONE)
Block(2,-12,1,STONE)
Block(2,-12,2,STONE)
Block(2,-11,-6,STONE)
Block(2,-11,-5,STONE)
Block(2,-11,-4,STONE)
Block(2,-11,-3,STONE)
Block(2,-11,-2,STONE)
Block(2,-11,-1,STONE)
Block(2,-11,0,STONE)
Block(2,-11,1,STONE)
Block(2,-11,2,STONE)
Block(2,-11,3,STONE)
Block(2,-11,4,STONE)
Block(2,-10,-6,STONE)
Block(2,-10,-5,STONE)
Block(2,-10,-4,STONE)
Block(2,-10,-3,STONE)
Block(2,-10,-2,STONE)
Block(2,-10,-1,STONE)
Block(2,-10,0,STONE)
Block(2,-10,1,STONE)
Block(2,-10,2,STONE)
Block(2,-10,3,STONE)
Block(2,-10,4,STONE)
Block(2,-10,5,STONE)
Block(2,-10,6,STONE)
Block(2,-10,7,STONE)
Block(2,-9,-6,STONE)
Block(2,-9,-5,STONE)
Block(2,-9,-4,STONE)
Block(2,-9,-3,STONE)
Block(2,-9,-2,STONE)
Block(2,-9,-1,STONE)
Block(2,-9,0,STONE)
Block(2,-9,1,STONE)
Block(2,-9,2,STONE)
Block(2,-9,3,STONE)
Block(2,-9,4,STONE)
Block(2,-9,5,STONE)
Block(2,-9,6,STONE)
Block(2,-9,7,STONE)
Block(2,-9,8,STONE)
Block(2,-8,-7,STONE)
Block(2,-8,-6,STONE)
Block(2,-8,-5,STONE)
Block(2,-8,-4,STONE)
Block(2,-8,-3,STONE)
Block(2,-8,-2,STONE)
Block(2,-8,-1,STONE)
Block(2,-8,0,STONE)
Block(2,-8,1,STONE)
Block(2,-8,2,STONE)
Block(2,-8,3,STONE)
Block(2,-8,4,STONE)
Block(2,-8,5,STONE)
Block(2,-8,6,STONE)
Block(2,-8,7,STONE)
Block(2,-8,8,STONE)
Block(2,-8,9,STONE)
Block(2,-7,-7,STONE)
Block(2,-7,-6,STONE)
Block(2,-7,-5,STONE)
Block(2,-7,-4,STONE)
Block(2,-7,-3,STONE)
Block(2,-7,-2,STONE)
Block(2,-7,-1,STONE)
Block(2,-7,0,STONE)
Block(2,-7,1,STONE)
Block(2,-7,2,STONE)
Block(2,-7,3,STONE)
Block(2,-7,4,STONE)
Block(2,-7,5,STONE)
Block(2,-7,6,STONE)
Block(2,-7,7,STONE)
Block(2,-7,8,STONE)
Block(2,-6,-7,STONE)
Block(2,-6,-6,STONE)
Block(2,-6,-5,STONE)
Block(2,-6,-4,STONE)
Block(2,-6,-3,STONE)
Block(2,-6,-2,STONE)
Block(2,-6,-1,STONE)
Block(2,-6,0,STONE)
Block(2,-6,1,STONE)
Block(2,-6,2,STONE)
Block(2,-6,3,STONE)
Block(2,-6,4,STONE)
Block(2,-6,5,STONE)
Block(2,-6,6,STONE)
Block(2,-6,7,STONE)
Block(2,-6,8,STONE)
Block(2,-5,-7,STONE)
Block(2,-5,-6,STONE)
Block(2,-5,-5,STONE)
Block(2,-5,-4,STONE)
Block(2,-5,-3,STONE)
Block(2,-5,-2,STONE)
Block(2,-5,-1,STONE)
Block(2,-5,0,STONE)
Block(2,-5,1,STONE)
Block(2,-5,2,STONE)
Block(2,-5,3,STONE)
Block(2,-5,4,STONE)
Block(2,-5,5,STONE)
Block(2,-5,6,STONE)
Block(2,-5,7,STONE)
Block(2,-5,8,STONE)
Block(2,-4,-7,STONE)
Block(2,-4,-6,STONE)
Block(2,-4,-5,STONE)
Block(2,-4,-4,STONE)
Block(2,-4,-3,STONE)
Block(2,-4,-2,STONE)
Block(2,-4,-1,STONE)
Block(2,-4,0,STONE)
Block(2,-4,1,STONE)
Block(2,-4,2,STONE)
Block(2,-4,3,STONE)
Block(2,-4,4,STONE)
Block(2,-4,5,STONE)
Block(2,-4,6,STONE)
Block(2,-4,7,STONE)
Block(2,-4,8,STONE)
Block(2,-3,-8,STONE)
Block(2,-3,-7,STONE)
Block(2,-3,-6,STONE)
Block(2,-3,-5,STONE)
Block(2,-3,-4,STONE)
Block(2,-3,-3,STONE)
Block(2,-3,-2,STONE)
Block(2,-3,-1,STONE)
Block(2,-3,0,STONE)
Block(2,-3,1,STONE)
Block(2,-3,2,STONE)
Block(2,-3,3,STONE)
Block(2,-3,4,STONE)
Block(2,-3,5,STONE)
Block(2,-3,6,STONE)
Block(2,-3,7,STONE)
Block(2,-3,8,STONE)
Block(2,-2,-8,STONE)
Block(2,-2,-7,STONE)
Block(2,-2,-6,STONE)
Block(2,-2,-5,STONE)
Block(2,-2,-4,STONE)
Block(2,-2,-3,STONE)
Block(2,-2,-2,STONE)
Block(2,-2,-1,STONE)
Block(2,-2,0,STONE)
Block(2,-2,1,STONE)
Block(2,-2,2,STONE)
Block(2,-2,3,STONE)
Block(2,-2,4,STONE)
Block(2,-2,5,STONE)
Block(2,-2,6,STONE)
Block(2,-2,7,STONE)
Block(2,-1,-8,STONE)
Block(2,-1,-7,STONE)
Block(2,-1,-6,STONE)
Block(2,-1,-5,STONE)
Block(2,-1,-4,STONE)
Block(2,-1,-3,STONE)
Block(2,-1,-2,STONE)
Block(2,-1,-1,STONE)
Block(2,-1,0,STONE)
Block(2,-1,1,STONE)
Block(2,-1,2,STONE)
Block(2,-1,3,STONE)
Block(2,-1,4,STONE)
Block(2,-1,5,STONE)
Block(2,-1,6,STONE)
Block(2,-1,7,STONE)
Block(2,0,-8,STONE)
Block(2,0,-7,STONE)
Block(2,0,-6,STONE)
Block(2,0,-5,STONE)
Block(2,0,-4,STONE)
Block(2,0,-3,STONE)
Block(2,0,-2,STONE)
Block(2,0,-1,STONE)
Block(2,0,0,STONE)
Block(2,0,1,STONE)
Block(2,0,2,STONE)
Block(2,0,3,STONE)
Block(2,0,4,STONE)
Block(2,0,5,STONE)
Block(2,0,6,STONE)
Block(2,0,7,STONE)
Block(2,1,-8,STONE)
Block(2,1,-7,STONE)
Block(2,1,-6,STONE)
Block(2,1,-5,STONE)
Block(2,1,-4,STONE)
Block(2,1,-3,STONE)
Block(2,1,-2,STONE)
Block(2,1,-1,STONE)
Block(2,1,0,STONE)
Block(2,1,1,STONE)
Block(2,1,2,STONE)
Block(2,1,3,STONE)
Block(2,1,4,STONE)
Block(2,1,5,STONE)
Block(2,1,6,STONE)
Block(2,2,-8,STONE)
Block(2,2,-7,STONE)
Block(2,2,-6,STONE)
Block(2,2,-5,STONE)
Block(2,2,-4,STONE)
Block(2,2,-3,STONE)
Block(2,2,-2,STONE)
Block(2,2,-1,STONE)
Block(2,2,0,STONE)
Block(2,2,1,STONE)
Block(2,2,2,STONE)
Block(2,2,3,STONE)
Block(2,2,4,STONE)
Block(2,2,5,STONE)
Block(2,2,6,STONE)
Block(2,3,-5,STONE)
Block(2,3,-4,STONE)
Block(2,3,-3,STONE)
Block(2,3,-2,STONE)
Block(2,3,-1,STONE)
Block(2,3,0,STONE)
Block(2,3,1,STONE)
Block(2,3,2,STONE)
Block(2,3,3,STONE)
Block(2,3,4,STONE)
Block(2,3,5,STONE)
Block(2,4,0,STONE)
Block(2,4,1,STONE)
Block(2,4,2,STONE)
Block(2,4,3,STONE)
Block(2,4,4,STONE)
Block(2,4,5,STONE)
Block(2,5,2,STONE)
Block(2,5,3,STONE)
Block(2,5,4,STONE)
Block(3,-13,-2,STONE)
Block(3,-13,-1,STONE)
Block(3,-12,-4,STONE)
Block(3,-12,-3,STONE)
Block(3,-12,-2,STONE)
Block(3,-12,-1,STONE)
Block(3,-12,0,STONE)
Block(3,-12,1,STONE)
Block(3,-12,2,STONE)
Block(3,-11,-5,STONE)
Block(3,-11,-4,STONE)
Block(3,-11,-3,STONE)
Block(3,-11,-2,STONE)
Block(3,-11,-1,STONE)
Block(3,-11,0,STONE)
Block(3,-11,1,STONE)
Block(3,-11,2,STONE)
Block(3,-11,3,STONE)
Block(3,-11,4,STONE)
Block(3,-11,5,STONE)
Block(3,-10,-6,STONE)
Block(3,-10,-5,STONE)
Block(3,-10,-4,STONE)
Block(3,-10,-3,STONE)
Block(3,-10,-2,STONE)
Block(3,-10,-1,STONE)
Block(3,-10,0,STONE)
Block(3,-10,1,STONE)
Block(3,-10,2,STONE)
Block(3,-10,3,STONE)
Block(3,-10,4,STONE)
Block(3,-10,5,STONE)
Block(3,-10,6,STONE)
Block(3,-10,7,STONE)
Block(3,-9,-6,STONE)
Block(3,-9,-5,STONE)
Block(3,-9,-4,STONE)
Block(3,-9,-3,STONE)
Block(3,-9,-2,STONE)
Block(3,-9,-1,STONE)
Block(3,-9,0,STONE)
Block(3,-9,1,STONE)
Block(3,-9,2,STONE)
Block(3,-9,3,STONE)
Block(3,-9,4,STONE)
Block(3,-9,5,STONE)
Block(3,-9,6,STONE)
Block(3,-9,7,STONE)
Block(3,-9,8,STONE)
Block(3,-8,-6,STONE)
Block(3,-8,-5,STONE)
Block(3,-8,-4,STONE)
Block(3,-8,-3,STONE)
Block(3,-8,-2,STONE)
Block(3,-8,-1,STONE)
Block(3,-8,0,STONE)
Block(3,-8,1,STONE)
Block(3,-8,2,STONE)
Block(3,-8,3,STONE)
Block(3,-8,4,STONE)
Block(3,-8,5,STONE)
Block(3,-8,6,STONE)
Block(3,-8,7,STONE)
Block(3,-8,8,STONE)
Block(3,-8,9,STONE)
Block(3,-7,-6,STONE)
Block(3,-7,-5,STONE)
Block(3,-7,-4,STONE)
Block(3,-7,-3,STONE)
Block(3,-7,-2,STONE)
Block(3,-7,-1,STONE)
Block(3,-7,0,STONE)
Block(3,-7,1,STONE)
Block(3,-7,2,STONE)
Block(3,-7,3,STONE)
Block(3,-7,4,STONE)
Block(3,-7,5,STONE)
Block(3,-7,6,STONE)
Block(3,-7,7,STONE)
Block(3,-7,8,STONE)
Block(3,-6,-7,STONE)
Block(3,-6,-6,STONE)
Block(3,-6,-5,STONE)
Block(3,-6,-4,STONE)
Block(3,-6,-3,STONE)
Block(3,-6,-2,STONE)
Block(3,-6,-1,STONE)
Block(3,-6,0,STONE)
Block(3,-6,1,STONE)
Block(3,-6,2,STONE)
Block(3,-6,3,STONE)
Block(3,-6,4,STONE)
Block(3,-6,5,STONE)
Block(3,-6,6,STONE)
Block(3,-6,7,STONE)
Block(3,-6,8,STONE)
Block(3,-5,-7,STONE)
Block(3,-5,-6,STONE)
Block(3,-5,-5,STONE)
Block(3,-5,-4,STONE)
Block(3,-5,-3,STONE)
Block(3,-5,-2,STONE)
Block(3,-5,-1,STONE)
Block(3,-5,0,STONE)
Block(3,-5,1,STONE)
Block(3,-5,2,STONE)
Block(3,-5,3,STONE)
Block(3,-5,4,STONE)
Block(3,-5,5,STONE)
Block(3,-5,6,STONE)
Block(3,-5,7,STONE)
Block(3,-5,8,STONE)
Block(3,-4,-7,STONE)
Block(3,-4,-6,STONE)
Block(3,-4,-5,STONE)
Block(3,-4,-4,STONE)
Block(3,-4,-3,STONE)
Block(3,-4,-2,STONE)
Block(3,-4,-1,STONE)
Block(3,-4,0,STONE)
Block(3,-4,1,STONE)
Block(3,-4,2,STONE)
Block(3,-4,3,STONE)
Block(3,-4,4,STONE)
Block(3,-4,5,STONE)
Block(3,-4,6,STONE)
Block(3,-4,7,STONE)
Block(3,-4,8,STONE)
Block(3,-3,-7,STONE)
Block(3,-3,-6,STONE)
Block(3,-3,-5,STONE)
Block(3,-3,-4,STONE)
Block(3,-3,-3,STONE)
Block(3,-3,-2,STONE)
Block(3,-3,-1,STONE)
Block(3,-3,0,STONE)
Block(3,-3,1,STONE)
Block(3,-3,2,STONE)
Block(3,-3,3,STONE)
Block(3,-3,4,STONE)
Block(3,-3,5,STONE)
Block(3,-3,6,STONE)
Block(3,-3,7,STONE)
Block(3,-3,8,STONE)
Block(3,-2,-8,STONE)
Block(3,-2,-7,STONE)
Block(3,-2,-6,STONE)
Block(3,-2,-5,STONE)
Block(3,-2,-4,STONE)
Block(3,-2,-3,STONE)
Block(3,-2,-2,STONE)
Block(3,-2,-1,STONE)
Block(3,-2,0,STONE)
Block(3,-2,1,STONE)
Block(3,-2,2,STONE)
Block(3,-2,3,STONE)
Block(3,-2,4,STONE)
Block(3,-2,5,STONE)
Block(3,-2,6,STONE)
Block(3,-2,7,STONE)
Block(3,-1,-8,STONE)
Block(3,-1,-7,STONE)
Block(3,-1,-6,STONE)
Block(3,-1,-5,STONE)
Block(3,-1,-4,STONE)
Block(3,-1,-3,STONE)
Block(3,-1,-2,STONE)
Block(3,-1,-1,STONE)
Block(3,-1,0,STONE)
Block(3,-1,1,STONE)
Block(3,-1,2,STONE)
Block(3,-1,3,STONE)
Block(3,-1,4,STONE)
Block(3,-1,5,STONE)
Block(3,-1,6,STONE)
Block(3,-1,7,STONE)
Block(3,0,-8,STONE)
Block(3,0,-7,STONE)
Block(3,0,-6,STONE)
Block(3,0,-5,STONE)
Block(3,0,-4,STONE)
Block(3,0,-3,STONE)
Block(3,0,-2,STONE)
Block(3,0,-1,STONE)
Block(3,0,0,STONE)
Block(3,0,1,STONE)
Block(3,0,2,STONE)
Block(3,0,3,STONE)
Block(3,0,4,STONE)
Block(3,0,5,STONE)
Block(3,0,6,STONE)
Block(3,1,-8,STONE)
Block(3,1,-7,STONE)
Block(3,1,-6,STONE)
Block(3,1,-5,STONE)
Block(3,1,-4,STONE)
Block(3,1,-3,STONE)
Block(3,1,-2,STONE)
Block(3,1,-1,STONE)
Block(3,1,0,STONE)
Block(3,1,1,STONE)
Block(3,1,2,STONE)
Block(3,1,3,STONE)
Block(3,1,4,STONE)
Block(3,1,5,STONE)
Block(3,1,6,STONE)
Block(3,2,-6,STONE)
Block(3,2,-5,STONE)
Block(3,2,-4,STONE)
Block(3,2,-3,STONE)
Block(3,2,-2,STONE)
Block(3,2,-1,STONE)
Block(3,2,0,STONE)
Block(3,2,1,STONE)
Block(3,2,2,STONE)
Block(3,2,3,STONE)
Block(3,2,4,STONE)
Block(3,2,5,STONE)
Block(3,3,-2,STONE)
Block(3,3,-1,STONE)
Block(3,3,0,STONE)
Block(3,3,1,STONE)
Block(3,3,2,STONE)
Block(3,3,3,STONE)
Block(3,3,4,STONE)
Block(3,3,5,STONE)
Block(3,4,1,STONE)
Block(3,4,2,STONE)
Block(3,4,3,STONE)
Block(3,4,4,STONE)
Block(3,4,5,STONE)
Block(3,5,3,STONE)
Block(4,-13,-2,STONE)
Block(4,-13,-1,STONE)
Block(4,-12,-3,STONE)
Block(4,-12,-2,STONE)
Block(4,-12,-1,STONE)
Block(4,-12,0,STONE)
Block(4,-12,1,STONE)
Block(4,-12,2,STONE)
Block(4,-11,-5,STONE)
Block(4,-11,-4,STONE)
Block(4,-11,-3,STONE)
Block(4,-11,-2,STONE)
Block(4,-11,-1,STONE)
Block(4,-11,0,STONE)
Block(4,-11,1,STONE)
Block(4,-11,2,STONE)
Block(4,-11,3,STONE)
Block(4,-11,4,STONE)
Block(4,-11,5,STONE)
Block(4,-10,-5,STONE)
Block(4,-10,-4,STONE)
Block(4,-10,-3,STONE)
Block(4,-10,-2,STONE)
Block(4,-10,-1,STONE)
Block(4,-10,0,STONE)
Block(4,-10,1,STONE)
Block(4,-10,2,STONE)
Block(4,-10,3,STONE)
Block(4,-10,4,STONE)
Block(4,-10,5,STONE)
Block(4,-10,6,STONE)
Block(4,-10,7,STONE)
Block(4,-9,-5,STONE)
Block(4,-9,-4,STONE)
Block(4,-9,-3,STONE)
Block(4,-9,-2,STONE)
Block(4,-9,-1,STONE)
Block(4,-9,0,STONE)
Block(4,-9,1,STONE)
Block(4,-9,2,STONE)
Block(4,-9,3,STONE)
Block(4,-9,4,STONE)
Block(4,-9,5,STONE)
Block(4,-9,6,STONE)
Block(4,-9,7,STONE)
Block(4,-9,8,STONE)
Block(4,-8,-6,STONE)
Block(4,-8,-5,STONE)
Block(4,-8,-4,STONE)
Block(4,-8,-3,STONE)
Block(4,-8,-2,STONE)
Block(4,-8,-1,STONE)
Block(4,-8,0,STONE)
Block(4,-8,1,STONE)
Block(4,-8,2,STONE)
Block(4,-8,3,STONE)
Block(4,-8,4,STONE)
Block(4,-8,5,STONE)
Block(4,-8,6,STONE)
Block(4,-8,7,STONE)
Block(4,-8,8,STONE)
Block(4,-8,9,STONE)
Block(4,-7,-6,STONE)
Block(4,-7,-5,STONE)
Block(4,-7,-4,STONE)
Block(4,-7,-3,STONE)
Block(4,-7,-2,STONE)
Block(4,-7,-1,STONE)
Block(4,-7,0,STONE)
Block(4,-7,1,STONE)
Block(4,-7,2,STONE)
Block(4,-7,3,STONE)
Block(4,-7,4,STONE)
Block(4,-7,5,STONE)
Block(4,-7,6,STONE)
Block(4,-7,7,STONE)
Block(4,-7,8,STONE)
Block(4,-6,-6,STONE)
Block(4,-6,-5,STONE)
Block(4,-6,-4,STONE)
Block(4,-6,-3,STONE)
Block(4,-6,-2,STONE)
Block(4,-6,-1,STONE)
Block(4,-6,0,STONE)
Block(4,-6,1,STONE)
Block(4,-6,2,STONE)
Block(4,-6,3,STONE)
Block(4,-6,4,STONE)
Block(4,-6,5,STONE)
Block(4,-6,6,STONE)
Block(4,-6,7,STONE)
Block(4,-6,8,STONE)
Block(4,-5,-6,STONE)
Block(4,-5,-5,STONE)
Block(4,-5,-4,STONE)
Block(4,-5,-3,STONE)
Block(4,-5,-2,STONE)
Block(4,-5,-1,STONE)
Block(4,-5,0,STONE)
Block(4,-5,1,STONE)
Block(4,-5,2,STONE)
Block(4,-5,3,STONE)
Block(4,-5,4,STONE)
Block(4,-5,5,STONE)
Block(4,-5,6,STONE)
Block(4,-5,7,STONE)
Block(4,-5,8,STONE)
Block(4,-4,-7,STONE)
Block(4,-4,-6,STONE)
Block(4,-4,-5,STONE)
Block(4,-4,-4,STONE)
Block(4,-4,-3,STONE)
Block(4,-4,-2,STONE)
Block(4,-4,-1,STONE)
Block(4,-4,0,STONE)
Block(4,-4,1,STONE)
Block(4,-4,2,STONE)
Block(4,-4,3,STONE)
Block(4,-4,4,STONE)
Block(4,-4,5,STONE)
Block(4,-4,6,STONE)
Block(4,-4,7,STONE)
Block(4,-4,8,STONE)
Block(4,-3,-7,STONE)
Block(4,-3,-6,STONE)
Block(4,-3,-5,STONE)
Block(4,-3,-4,STONE)
Block(4,-3,-3,STONE)
Block(4,-3,-2,STONE)
Block(4,-3,-1,STONE)
Block(4,-3,0,STONE)
Block(4,-3,1,STONE)
Block(4,-3,2,STONE)
Block(4,-3,3,STONE)
Block(4,-3,4,STONE)
Block(4,-3,5,STONE)
Block(4,-3,6,STONE)
Block(4,-3,7,STONE)
Block(4,-2,-7,STONE)
Block(4,-2,-6,STONE)
Block(4,-2,-5,STONE)
Block(4,-2,-4,STONE)
Block(4,-2,-3,STONE)
Block(4,-2,-2,STONE)
Block(4,-2,-1,STONE)
Block(4,-2,0,STONE)
Block(4,-2,1,STONE)
Block(4,-2,2,STONE)
Block(4,-2,3,STONE)
Block(4,-2,4,STONE)
Block(4,-2,5,STONE)
Block(4,-2,6,STONE)
Block(4,-2,7,STONE)
Block(4,-1,-8,STONE)
Block(4,-1,-7,STONE)
Block(4,-1,-6,STONE)
Block(4,-1,-5,STONE)
Block(4,-1,-4,STONE)
Block(4,-1,-3,STONE)
Block(4,-1,-2,STONE)
Block(4,-1,-1,STONE)
Block(4,-1,0,STONE)
Block(4,-1,1,STONE)
Block(4,-1,2,STONE)
Block(4,-1,3,STONE)
Block(4,-1,4,STONE)
Block(4,-1,5,STONE)
Block(4,-1,6,STONE)
Block(4,0,-8,STONE)
Block(4,0,-7,STONE)
Block(4,0,-6,STONE)
Block(4,0,-5,STONE)
Block(4,0,-4,STONE)
Block(4,0,-3,STONE)
Block(4,0,-2,STONE)
Block(4,0,-1,STONE)
Block(4,0,0,STONE)
Block(4,0,1,STONE)
Block(4,0,2,STONE)
Block(4,0,3,STONE)
Block(4,0,4,STONE)
Block(4,0,5,STONE)
Block(4,0,6,STONE)
Block(4,1,-8,STONE)
Block(4,1,-7,STONE)
Block(4,1,-6,STONE)
Block(4,1,-5,STONE)
Block(4,1,-4,STONE)
Block(4,1,-3,STONE)
Block(4,1,-2,STONE)
Block(4,1,-1,STONE)
Block(4,1,0,STONE)
Block(4,1,1,STONE)
Block(4,1,2,STONE)
Block(4,1,3,STONE)
Block(4,1,4,STONE)
Block(4,1,5,STONE)
Block(4,1,6,STONE)
Block(4,2,-5,STONE)
Block(4,2,-4,STONE)
Block(4,2,-3,STONE)
Block(4,2,-2,STONE)
Block(4,2,-1,STONE)
Block(4,2,0,STONE)
Block(4,2,1,STONE)
Block(4,2,2,STONE)
Block(4,2,3,STONE)
Block(4,2,4,STONE)
Block(4,2,5,STONE)
Block(4,3,0,STONE)
Block(4,3,1,STONE)
Block(4,3,2,STONE)
Block(4,3,3,STONE)
Block(4,3,4,STONE)
Block(4,3,5,STONE)
Block(4,4,2,STONE)
Block(4,4,3,STONE)
Block(4,4,4,STONE)
Block(5,-13,-2,STONE)
Block(5,-13,-1,STONE)
Block(5,-12,-3,STONE)
Block(5,-12,-2,STONE)
Block(5,-12,-1,STONE)
Block(5,-12,0,STONE)
Block(5,-12,1,STONE)
Block(5,-12,2,STONE)
Block(5,-11,-5,STONE)
Block(5,-11,-4,STONE)
Block(5,-11,-3,STONE)
Block(5,-11,-2,STONE)
Block(5,-11,-1,STONE)
Block(5,-11,0,STONE)
Block(5,-11,1,STONE)
Block(5,-11,2,STONE)
Block(5,-11,3,STONE)
Block(5,-11,4,STONE)
Block(5,-11,5,STONE)
Block(5,-10,-5,STONE)
Block(5,-10,-4,STONE)
Block(5,-10,-3,STONE)
Block(5,-10,-2,STONE)
Block(5,-10,-1,STONE)
Block(5,-10,0,STONE)
Block(5,-10,1,STONE)
Block(5,-10,2,STONE)
Block(5,-10,3,STONE)
Block(5,-10,4,STONE)
Block(5,-10,5,STONE)
Block(5,-10,6,STONE)
Block(5,-10,7,STONE)
Block(5,-9,-5,STONE)
Block(5,-9,-4,STONE)
Block(5,-9,-3,STONE)
Block(5,-9,-2,STONE)
Block(5,-9,-1,STONE)
Block(5,-9,0,STONE)
Block(5,-9,1,STONE)
Block(5,-9,2,STONE)
Block(5,-9,3,STONE)
Block(5,-9,4,STONE)
Block(5,-9,5,STONE)
Block(5,-9,6,STONE)
Block(5,-9,7,STONE)
Block(5,-9,8,STONE)
Block(5,-8,-5,STONE)
Block(5,-8,-4,STONE)
Block(5,-8,-3,STONE)
Block(5,-8,-2,STONE)
Block(5,-8,-1,STONE)
Block(5,-8,0,STONE)
Block(5,-8,1,STONE)
Block(5,-8,2,STONE)
Block(5,-8,3,STONE)
Block(5,-8,4,STONE)
Block(5,-8,5,STONE)
Block(5,-8,6,STONE)
Block(5,-8,7,STONE)
Block(5,-8,8,STONE)
Block(5,-7,-5,STONE)
Block(5,-7,-4,STONE)
Block(5,-7,-3,STONE)
Block(5,-7,-2,STONE)
Block(5,-7,-1,STONE)
Block(5,-7,0,STONE)
Block(5,-7,1,STONE)
Block(5,-7,2,STONE)
Block(5,-7,3,STONE)
Block(5,-7,4,STONE)
Block(5,-7,5,STONE)
Block(5,-7,6,STONE)
Block(5,-7,7,STONE)
Block(5,-7,8,STONE)
Block(5,-6,-6,STONE)
Block(5,-6,-5,STONE)
Block(5,-6,-4,STONE)
Block(5,-6,-3,STONE)
Block(5,-6,-2,STONE)
Block(5,-6,-1,STONE)
Block(5,-6,0,STONE)
Block(5,-6,1,STONE)
Block(5,-6,2,STONE)
Block(5,-6,3,STONE)
Block(5,-6,4,STONE)
Block(5,-6,5,STONE)
Block(5,-6,6,STONE)
Block(5,-6,7,STONE)
Block(5,-6,8,STONE)
Block(5,-5,-6,STONE)
Block(5,-5,-5,STONE)
Block(5,-5,-4,STONE)
Block(5,-5,-3,STONE)
Block(5,-5,-2,STONE)
Block(5,-5,-1,STONE)
Block(5,-5,0,STONE)
Block(5,-5,1,STONE)
Block(5,-5,2,STONE)
Block(5,-5,3,STONE)
Block(5,-5,4,STONE)
Block(5,-5,5,STONE)
Block(5,-5,6,STONE)
Block(5,-5,7,STONE)
Block(5,-5,8,STONE)
Block(5,-4,-6,STONE)
Block(5,-4,-5,STONE)
Block(5,-4,-4,STONE)
Block(5,-4,-3,STONE)
Block(5,-4,-2,STONE)
Block(5,-4,-1,STONE)
Block(5,-4,0,STONE)
Block(5,-4,1,STONE)
Block(5,-4,2,STONE)
Block(5,-4,3,STONE)
Block(5,-4,4,STONE)
Block(5,-4,5,STONE)
Block(5,-4,6,STONE)
Block(5,-4,7,STONE)
Block(5,-3,-7,STONE)
Block(5,-3,-6,STONE)
Block(5,-3,-5,STONE)
Block(5,-3,-4,STONE)
Block(5,-3,-3,STONE)
Block(5,-3,-2,STONE)
Block(5,-3,-1,STONE)
Block(5,-3,0,STONE)
Block(5,-3,1,STONE)
Block(5,-3,2,STONE)
Block(5,-3,3,STONE)
Block(5,-3,4,STONE)
Block(5,-3,5,STONE)
Block(5,-3,6,STONE)
Block(5,-3,7,STONE)
Block(5,-2,-7,STONE)
Block(5,-2,-6,STONE)
Block(5,-2,-5,STONE)
Block(5,-2,-4,STONE)
Block(5,-2,-3,STONE)
Block(5,-2,-2,STONE)
Block(5,-2,-1,STONE)
Block(5,-2,0,STONE)
Block(5,-2,1,STONE)
Block(5,-2,2,STONE)
Block(5,-2,3,STONE)
Block(5,-2,4,STONE)
Block(5,-2,5,STONE)
Block(5,-2,6,STONE)
Block(5,-1,-7,STONE)
Block(5,-1,-6,STONE)
Block(5,-1,-5,STONE)
Block(5,-1,-4,STONE)
Block(5,-1,-3,STONE)
Block(5,-1,-2,STONE)
Block(5,-1,-1,STONE)
Block(5,-1,0,STONE)
Block(5,-1,1,STONE)
Block(5,-1,2,STONE)
Block(5,-1,3,STONE)
Block(5,-1,4,STONE)
Block(5,-1,5,STONE)
Block(5,-1,6,STONE)
Block(5,0,-8,STONE)
Block(5,0,-7,STONE)
Block(5,0,-6,STONE)
Block(5,0,-5,STONE)
Block(5,0,-4,STONE)
Block(5,0,-3,STONE)
Block(5,0,-2,STONE)
Block(5,0,-1,STONE)
Block(5,0,0,STONE)
Block(5,0,1,STONE)
Block(5,0,2,STONE)
Block(5,0,3,STONE)
Block(5,0,4,STONE)
Block(5,0,5,STONE)
Block(5,0,6,STONE)
Block(5,1,-7,STONE)
Block(5,1,-6,STONE)
Block(5,1,-5,STONE)
Block(5,1,-4,STONE)
Block(5,1,-3,STONE)
Block(5,1,-2,STONE)
Block(5,1,-1,STONE)
Block(5,1,0,STONE)
Block(5,1,1,STONE)
Block(5,1,2,STONE)
Block(5,1,3,STONE)
Block(5,1,4,STONE)
Block(5,1,5,STONE)
Block(5,2,-3,STONE)
Block(5,2,-2,STONE)
Block(5,2,-1,STONE)
Block(5,2,0,STONE)
Block(5,2,1,STONE)
Block(5,2,2,STONE)
Block(5,2,3,STONE)
Block(5,2,4,STONE)
Block(5,2,5,STONE)
Block(5,3,1,STONE)
Block(5,3,2,STONE)
Block(5,3,3,STONE)
Block(5,3,4,STONE)
Block(5,4,3,STONE)
Block(6,-13,-1,STONE)
Block(6,-12,-3,STONE)
Block(6,-12,-2,STONE)
Block(6,-12,-1,STONE)
Block(6,-12,0,STONE)
Block(6,-12,1,STONE)
Block(6,-12,2,STONE)
Block(6,-11,-4,STONE)
Block(6,-11,-3,STONE)
Block(6,-11,-2,STONE)
Block(6,-11,-1,STONE)
Block(6,-11,0,STONE)
Block(6,-11,1,STONE)
Block(6,-11,2,STONE)
Block(6,-11,3,STONE)
Block(6,-11,4,STONE)
Block(6,-10,-5,STONE)
Block(6,-10,-4,STONE)
Block(6,-10,-3,STONE)
Block(6,-10,-2,STONE)
Block(6,-10,-1,STONE)
Block(6,-10,0,STONE)
Block(6,-10,1,STONE)
Block(6,-10,2,STONE)
Block(6,-10,3,STONE)
Block(6,-10,4,STONE)
Block(6,-10,5,STONE)
Block(6,-10,6,STONE)
Block(6,-10,7,STONE)
Block(6,-9,-5,STONE)
Block(6,-9,-4,STONE)
Block(6,-9,-3,STONE)
Block(6,-9,-2,STONE)
Block(6,-9,-1,STONE)
Block(6,-9,0,STONE)
Block(6,-9,1,STONE)
Block(6,-9,2,STONE)
Block(6,-9,3,STONE)
Block(6,-9,4,STONE)
Block(6,-9,5,STONE)
Block(6,-9,6,STONE)
Block(6,-9,7,STONE)
Block(6,-9,8,STONE)
Block(6,-8,-5,STONE)
Block(6,-8,-4,STONE)
Block(6,-8,-3,STONE)
Block(6,-8,-2,STONE)
Block(6,-8,-1,STONE)
Block(6,-8,0,STONE)
Block(6,-8,1,STONE)
Block(6,-8,2,STONE)
Block(6,-8,3,STONE)
Block(6,-8,4,STONE)
Block(6,-8,5,STONE)
Block(6,-8,6,STONE)
Block(6,-8,7,STONE)
Block(6,-8,8,STONE)
Block(6,-7,-5,STONE)
Block(6,-7,-4,STONE)
Block(6,-7,-3,STONE)
Block(6,-7,-2,STONE)
Block(6,-7,-1,STONE)
Block(6,-7,0,STONE)
Block(6,-7,1,STONE)
Block(6,-7,2,STONE)
Block(6,-7,3,STONE)
Block(6,-7,4,STONE)
Block(6,-7,5,STONE)
Block(6,-7,6,STONE)
Block(6,-7,7,STONE)
Block(6,-7,8,STONE)
Block(6,-6,-5,STONE)
Block(6,-6,-4,STONE)
Block(6,-6,-3,STONE)
Block(6,-6,-2,STONE)
Block(6,-6,-1,STONE)
Block(6,-6,0,STONE)
Block(6,-6,1,STONE)
Block(6,-6,2,STONE)
Block(6,-6,3,STONE)
Block(6,-6,4,STONE)
Block(6,-6,5,STONE)
Block(6,-6,6,STONE)
Block(6,-6,7,STONE)
Block(6,-6,8,STONE)
Block(6,-5,-6,STONE)
Block(6,-5,-5,STONE)
Block(6,-5,-4,STONE)
Block(6,-5,-3,STONE)
Block(6,-5,-2,STONE)
Block(6,-5,-1,STONE)
Block(6,-5,0,STONE)
Block(6,-5,1,STONE)
Block(6,-5,2,STONE)
Block(6,-5,3,STONE)
Block(6,-5,4,STONE)
Block(6,-5,5,STONE)
Block(6,-5,6,STONE)
Block(6,-5,7,STONE)
Block(6,-5,8,STONE)
Block(6,-4,-6,STONE)
Block(6,-4,-5,STONE)
Block(6,-4,-4,STONE)
Block(6,-4,-3,STONE)
Block(6,-4,-2,STONE)
Block(6,-4,-1,STONE)
Block(6,-4,0,STONE)
Block(6,-4,1,STONE)
Block(6,-4,2,STONE)
Block(6,-4,3,STONE)
Block(6,-4,4,STONE)
Block(6,-4,5,STONE)
Block(6,-4,6,STONE)
Block(6,-4,7,STONE)
Block(6,-3,-6,STONE)
Block(6,-3,-5,STONE)
Block(6,-3,-4,STONE)
Block(6,-3,-3,STONE)
Block(6,-3,-2,STONE)
Block(6,-3,-1,STONE)
Block(6,-3,0,STONE)
Block(6,-3,1,STONE)
Block(6,-3,2,STONE)
Block(6,-3,3,STONE)
Block(6,-3,4,STONE)
Block(6,-3,5,STONE)
Block(6,-3,6,STONE)
Block(6,-3,7,STONE)
Block(6,-2,-7,STONE)
Block(6,-2,-6,STONE)
Block(6,-2,-5,STONE)
Block(6,-2,-4,STONE)
Block(6,-2,-3,STONE)
Block(6,-2,-2,STONE)
Block(6,-2,-1,STONE)
Block(6,-2,0,STONE)
Block(6,-2,1,STONE)
Block(6,-2,2,STONE)
Block(6,-2,3,STONE)
Block(6,-2,4,STONE)
Block(6,-2,5,STONE)
Block(6,-2,6,STONE)
Block(6,-1,-7,STONE)
Block(6,-1,-6,STONE)
Block(6,-1,-5,STONE)
Block(6,-1,-4,STONE)
Block(6,-1,-3,STONE)
Block(6,-1,-2,STONE)
Block(6,-1,-1,STONE)
Block(6,-1,0,STONE)
Block(6,-1,1,STONE)
Block(6,-1,2,STONE)
Block(6,-1,3,STONE)
Block(6,-1,4,STONE)
Block(6,-1,5,STONE)
Block(6,-1,6,STONE)
Block(6,0,-7,STONE)
Block(6,0,-6,STONE)
Block(6,0,-5,STONE)
Block(6,0,-4,STONE)
Block(6,0,-3,STONE)
Block(6,0,-2,STONE)
Block(6,0,-1,STONE)
Block(6,0,0,STONE)
Block(6,0,1,STONE)
Block(6,0,2,STONE)
Block(6,0,3,STONE)
Block(6,0,4,STONE)
Block(6,0,5,STONE)
Block(6,1,-5,STONE)
Block(6,1,-4,STONE)
Block(6,1,-3,STONE)
Block(6,1,-2,STONE)
Block(6,1,-1,STONE)
Block(6,1,0,STONE)
Block(6,1,1,STONE)
Block(6,1,2,STONE)
Block(6,1,3,STONE)
Block(6,1,4,STONE)
Block(6,1,5,STONE)
Block(6,2,-2,STONE)
Block(6,2,-1,STONE)
Block(6,2,0,STONE)
Block(6,2,1,STONE)
Block(6,2,2,STONE)
Block(6,2,3,STONE)
Block(6,2,4,STONE)
Block(6,2,5,STONE)
Block(6,3,1,STONE)
Block(6,3,2,STONE)
Block(6,3,3,STONE)
Block(6,3,4,STONE)
Block(7,-12,-2,STONE)
Block(7,-12,-1,STONE)
Block(7,-12,0,STONE)
Block(7,-12,1,STONE)
Block(7,-12,2,STONE)
Block(7,-11,-4,STONE)
Block(7,-11,-3,STONE)
Block(7,-11,-2,STONE)
Block(7,-11,-1,STONE)
Block(7,-11,0,STONE)
Block(7,-11,1,STONE)
Block(7,-11,2,STONE)
Block(7,-11,3,STONE)
Block(7,-11,4,STONE)
Block(7,-10,-4,STONE)
Block(7,-10,-3,STONE)
Block(7,-10,-2,STONE)
Block(7,-10,-1,STONE)
Block(7,-10,0,STONE)
Block(7,-10,1,STONE)
Block(7,-10,2,STONE)
Block(7,-10,3,STONE)
Block(7,-10,4,STONE)
Block(7,-10,5,STONE)
Block(7,-10,6,STONE)
Block(7,-9,-4,STONE)
Block(7,-9,-3,STONE)
Block(7,-9,-2,STONE)
Block(7,-9,-1,STONE)
Block(7,-9,0,STONE)
Block(7,-9,1,STONE)
Block(7,-9,2,STONE)
Block(7,-9,3,STONE)
Block(7,-9,4,STONE)
Block(7,-9,5,STONE)
Block(7,-9,6,STONE)
Block(7,-8,-5,STONE)
Block(7,-8,-4,STONE)
Block(7,-8,-3,STONE)
Block(7,-8,-2,STONE)
Block(7,-8,-1,STONE)
Block(7,-8,0,STONE)
Block(7,-8,1,STONE)
Block(7,-8,2,STONE)
Block(7,-8,3,STONE)
Block(7,-8,4,STONE)
Block(7,-8,5,STONE)
Block(7,-8,6,STONE)
Block(7,-8,7,STONE)
Block(7,-7,-5,STONE)
Block(7,-7,-4,STONE)
Block(7,-7,-3,STONE)
Block(7,-7,-2,STONE)
Block(7,-7,-1,STONE)
Block(7,-7,0,STONE)
Block(7,-7,1,STONE)
Block(7,-7,2,STONE)
Block(7,-7,3,STONE)
Block(7,-7,4,STONE)
Block(7,-7,5,STONE)
Block(7,-7,6,STONE)
Block(7,-7,7,STONE)
Block(7,-6,-5,STONE)
Block(7,-6,-4,STONE)
Block(7,-6,-3,STONE)
Block(7,-6,-2,STONE)
Block(7,-6,-1,STONE)
Block(7,-6,0,STONE)
Block(7,-6,1,STONE)
Block(7,-6,2,STONE)
Block(7,-6,3,STONE)
Block(7,-6,4,STONE)
Block(7,-6,5,STONE)
Block(7,-6,6,STONE)
Block(7,-6,7,STONE)
Block(7,-5,-6,STONE)
Block(7,-5,-5,STONE)
Block(7,-5,-4,STONE)
Block(7,-5,-3,STONE)
Block(7,-5,-2,STONE)
Block(7,-5,-1,STONE)
Block(7,-5,0,STONE)
Block(7,-5,1,STONE)
Block(7,-5,2,STONE)
Block(7,-5,3,STONE)
Block(7,-5,4,STONE)
Block(7,-5,5,STONE)
Block(7,-5,6,STONE)
Block(7,-5,7,STONE)
Block(7,-4,-6,STONE)
Block(7,-4,-5,STONE)
Block(7,-4,-4,STONE)
Block(7,-4,-3,STONE)
Block(7,-4,-2,STONE)
Block(7,-4,-1,STONE)
Block(7,-4,0,STONE)
Block(7,-4,1,STONE)
Block(7,-4,2,STONE)
Block(7,-4,3,STONE)
Block(7,-4,4,STONE)
Block(7,-4,5,STONE)
Block(7,-4,6,STONE)
Block(7,-4,7,STONE)
Block(7,-3,-6,STONE)
Block(7,-3,-5,STONE)
Block(7,-3,-4,STONE)
Block(7,-3,-3,STONE)
Block(7,-3,-2,STONE)
Block(7,-3,-1,STONE)
Block(7,-3,0,STONE)
Block(7,-3,1,STONE)
Block(7,-3,2,STONE)
Block(7,-3,3,STONE)
Block(7,-3,4,STONE)
Block(7,-3,5,STONE)
Block(7,-3,6,STONE)
Block(7,-2,-5,STONE)
Block(7,-2,-4,STONE)
Block(7,-2,-3,STONE)
Block(7,-2,-2,STONE)
Block(7,-2,-1,STONE)
Block(7,-2,0,STONE)
Block(7,-2,1,STONE)
Block(7,-2,2,STONE)
Block(7,-2,3,STONE)
Block(7,-2,4,STONE)
Block(7,-2,5,STONE)
Block(7,-2,6,STONE)
Block(7,-1,-5,STONE)
Block(7,-1,-4,STONE)
Block(7,-1,-3,STONE)
Block(7,-1,-2,STONE)
Block(7,-1,-1,STONE)
Block(7,-1,0,STONE)
Block(7,-1,1,STONE)
Block(7,-1,2,STONE)
Block(7,-1,3,STONE)
Block(7,-1,4,STONE)
Block(7,-1,5,STONE)
Block(7,-1,6,STONE)
Block(7,0,-5,STONE)
Block(7,0,-4,STONE)
Block(7,0,-3,STONE)
Block(7,0,-2,STONE)
Block(7,0,-1,STONE)
Block(7,0,0,STONE)
Block(7,0,1,STONE)
Block(7,0,2,STONE)
Block(7,0,3,STONE)
Block(7,0,4,STONE)
Block(7,0,5,STONE)
Block(7,1,-4,STONE)
Block(7,1,-3,STONE)
Block(7,1,-2,STONE)
Block(7,1,-1,STONE)
Block(7,1,0,STONE)
Block(7,1,1,STONE)
Block(7,1,2,STONE)
Block(7,1,3,STONE)
Block(7,1,4,STONE)
Block(7,1,5,STONE)
Block(7,2,0,STONE)
Block(7,2,1,STONE)
Block(7,2,2,STONE)
Block(7,2,3,STONE)
Block(7,2,4,STONE)
Block(7,3,2,STONE)
Block(7,3,3,STONE)
Block(7,3,4,STONE)
Block(8,-10,-2,STONE)
Block(8,-10,-1,STONE)
Block(8,-10,0,STONE)
Block(8,-10,1,STONE)
Block(8,-9,-3,STONE)
Block(8,-9,-2,STONE)
Block(8,-9,-1,STONE)
Block(8,-9,0,STONE)
Block(8,-9,1,STONE)
Block(8,-9,2,STONE)
Block(8,-9,3,STONE)
Block(8,-9,4,STONE)
Block(8,-8,-3,STONE)
Block(8,-8,-2,STONE)
Block(8,-8,-1,STONE)
Block(8,-8,0,STONE)
Block(8,-8,1,STONE)
Block(8,-8,2,STONE)
Block(8,-8,3,STONE)
Block(8,-8,4,STONE)
Block(8,-8,5,STONE)
Block(8,-7,-3,STONE)
Block(8,-7,-2,STONE)
Block(8,-7,-1,STONE)
Block(8,-7,0,STONE)
Block(8,-7,1,STONE)
Block(8,-7,2,STONE)
Block(8,-7,3,STONE)
Block(8,-7,4,STONE)
Block(8,-7,5,STONE)
Block(8,-6,-3,STONE)
Block(8,-6,-2,STONE)
Block(8,-6,-1,STONE)
Block(8,-6,0,STONE)
Block(8,-6,1,STONE)
Block(8,-6,2,STONE)
Block(8,-6,3,STONE)
Block(8,-6,4,STONE)
Block(8,-6,5,STONE)
Block(8,-6,6,STONE)
Block(8,-5,-3,STONE)
Block(8,-5,-2,STONE)
Block(8,-5,-1,STONE)
Block(8,-5,0,STONE)
Block(8,-5,1,STONE)
Block(8,-5,2,STONE)
Block(8,-5,3,STONE)
Block(8,-5,4,STONE)
Block(8,-5,5,STONE)
Block(8,-5,6,STONE)
Block(8,-4,-3,STONE)
Block(8,-4,-2,STONE)
Block(8,-4,-1,STONE)
Block(8,-4,0,STONE)
Block(8,-4,1,STONE)
Block(8,-4,2,STONE)
Block(8,-4,3,STONE)
Block(8,-4,4,STONE)
Block(8,-4,5,STONE)
Block(8,-4,6,STONE)
Block(8,-3,-2,STONE)
Block(8,-3,-1,STONE)
Block(8,-3,0,STONE)
Block(8,-3,1,STONE)
Block(8,-3,2,STONE)
Block(8,-3,3,STONE)
Block(8,-3,4,STONE)
Block(8,-3,5,STONE)
Block(8,-3,6,STONE)
Block(8,-2,-2,STONE)
Block(8,-2,-1,STONE)
Block(8,-2,0,STONE)
Block(8,-2,1,STONE)
Block(8,-2,2,STONE)
Block(8,-2,3,STONE)
Block(8,-2,4,STONE)
Block(8,-2,5,STONE)
Block(8,-2,6,STONE)
Block(8,-1,-1,STONE)
Block(8,-1,0,STONE)
Block(8,-1,1,STONE)
Block(8,-1,2,STONE)
Block(8,-1,3,STONE)
Block(8,-1,4,STONE)
Block(8,-1,5,STONE)
Block(8,0,-1,STONE)
Block(8,0,0,STONE)
Block(8,0,1,STONE)
Block(8,0,2,STONE)
Block(8,0,3,STONE)
Block(8,0,4,STONE)
Block(8,0,5,STONE)
Block(8,1,-1,STONE)
Block(8,1,0,STONE)
Block(8,1,1,STONE)
Block(8,1,2,STONE)
Block(8,1,3,STONE)
Block(8,1,4,STONE)
Block(8,2,1,STONE)
Block(8,2,2,STONE)
Block(8,2,3,STONE)
Block(8,2,4,STONE)
Block(8,3,3,STONE)
Block(9,-7,2,STONE)
Block(9,-6,2,STONE)
Block(9,-6,3,STONE)
Block(9,-6,4,STONE)
Block(9,-5,2,STONE)
Block(9,-5,3,STONE)
Block(9,-5,4,STONE)
Block(9,-4,2,STONE)
Block(9,-4,3,STONE)
Block(9,-4,4,STONE)
Block(9,-4,5,STONE)
Block(9,-3,2,STONE)
Block(9,-3,3,STONE)
Block(9,-3,4,STONE)
Block(9,-3,5,STONE)
Block(9,-2,3,STONE)
Block(9,-2,4,STONE)
Block(9,-2,5,STONE)
Block(9,-1,3,STONE)
Block(9,-1,4,STONE)
Block(9,-1,5,STONE)
Block(9,0,3,STONE)
Block(9,0,4,STONE)

#######################################################################
# +-----------------------------------------------------------------+ #
# |                            BO3 checks                           | #
# +-----------------------------------------------------------------+ #
#######################################################################


#######################################################################
# +-----------------------------------------------------------------+ #
# |                             Branches                            | #
# +-----------------------------------------------------------------+ #
#######################################################################


#######################################################################
# +-----------------------------------------------------------------+ #
# |                             Entities                            | #
# +-----------------------------------------------------------------+ #
#######################################################################


#######################################################################
# +-----------------------------------------------------------------+ #
# |                            Particles                            | #
# +-----------------------------------------------------------------+ #
#######################################################################


#######################################################################
# +-----------------------------------------------------------------+ #
# |                             Spawners                            | #
# +-----------------------------------------------------------------+ #
#######################################################################


#######################################################################
# +-----------------------------------------------------------------+ #
# |                             ModData                             | #
# +-----------------------------------------------------------------+ #
#######################################################################

