
#######################################################################
# +-----------------------------------------------------------------+ #
# |                            BO3 object                           | #
# +-----------------------------------------------------------------+ #
#######################################################################

# This is the config file of a custom object.
# If you add this object correctly to your BiomeConfigs, it will spawn in the world.

# This is the creator of this BO3 object
Author: LordSmellyPants

# A short description of this BO3 object
Description: No description given

# The BO3 version, don't change this! It can be used by external applications to do a version check.
Version: 3

# The settings mode, WriteAll, WriteWithoutComments or WriteDisable. See WorldConfig.
SettingsMode: WriteDisable


#######################################################################
# +-----------------------------------------------------------------+ #
# |                          Main settings                          | #
# +-----------------------------------------------------------------+ #
#######################################################################

# This needs to be set to true to spawn the object in the Tree and Sapling resources.
Tree: false

# The frequency of the BO3 from 1 to 200. Tries this many times to spawn this BO3 when using the CustomObject(...) resource.
# Ignored by Tree(..), Sapling(..) and CustomStructure(..)
Frequency: 1

# The rarity of the BO3 from 0 to 100. Each spawn attempt has rarity% chance to succeed when using the CustomObject(...) resource.
# Ignored by Tree(..), Sapling(..) and CustomStructure(..)
Rarity: 5.0

# If you set this to true, the BO3 will be placed with a random rotation.
RotateRandomly: false

# The spawn height of the BO3 - atMinY, randomY, highestBlock or highestSolidBlock.
SpawnHeight: highestSolidBlock

# The offset from the spawn height to spawn this BO3
# Ex. SpawnHeight = highestSolidBlock, SpawnHeightOffset = 3; This object will spawn 3 blocks above the highest solid block
SpawnHeightOffset: 0

# A random amount to offset the spawn location from the spawn offset height
# Ex. SpawnHeightOffset = 3, SpawnHeightVariance = 3; This object will spawn 3 to 6 blocks above the original spot it would have spawned
SpawnHeightVariance: 0

##############################
# Height Limits for the BO3. #
##############################

# When in randomY mode used as the minimum Y or in atMinY mode as the actual Y to spawn this BO3 at.
MinHeight: 61

# When in randomY mode used as the maximum Y to spawn this BO3 at.
MaxHeight: 256

######################
# Extrusion settings #
######################

# The style of extrusion you wish to use - BottomDown, TopUp, None (Default)
ExtrudeMode: None

# The blocks to extrude your BO3 through
ExtrudeThroughBlocks: AIR

# Objects can have other objects attacthed to it: branches. Branches can also
# have branches attached to it, which can also have branches, etc. This is the
# maximum branch depth for this objects.
MaxBranchDepth: 10

# When spawned with the UseWorld keyword, this BO3 should NOT spawn in the following biomes.
# If you write the BO3 name directly in the BiomeConfigs, this will be ignored.
ExcludedBiomes: All


#######################################################################
# +-----------------------------------------------------------------+ #
# |                      Source block settings                      | #
# +-----------------------------------------------------------------+ #
#######################################################################

# The B(s) the BO3 should spawn in.
SourceBlocks: AIR

# The maximum percentage of the BO3 that can be outside the SourceBlock.
# The BO3 won't be placed on a location with more blocks outside the SourceBlock than this percentage.
MaxPercentageOutsideSourceBlock: 100

# What to do when a block is about to be placed outside the SourceBlock? (dontPlace, placeAnyway)
OutsideSourceBlock: placeAnyway


#######################################################################
# +-----------------------------------------------------------------+ #
# |                              Blocks                             | #
# +-----------------------------------------------------------------+ #
#######################################################################

# All the blocks used in the BO3 are listed here. Possible blocks:
# B(x,y,z,id[.data][,nbtfile.nbt)
# RandomB(x,y,z,id[:data][,nbtfile.nbt],chance[,id[:data][,nbtfile.nbt],chance[,...]])
#  So RandomB(0,0,0,CHEST,chest.nbt,50,CHEST,anotherchest.nbt,100) will spawn a chest at
#  the BO3 origin, and give it a 50% chance to have the contents of chest.nbt, or, if that
#  fails, a 100% percent chance to have the contents of anotherchest.nbt.
# MinecraftObject(x,y,z,name)
#  Spawns an object in the Mojang NBT structure format. For example, 
#  MinecraftObject(0,0,0,minecraft:igloo/igloo_bottom)
#  spawns the bottom part of an igloo.
B(-16,-10,-5,STONE)
B(-16,-10,-4,STONE)
B(-16,-10,-3,STONE)
B(-16,-10,-2,STONE)
B(-16,-10,-1,STONE)
B(-16,-10,4,STONE)
B(-16,-10,5,STONE)
B(-15,-10,-10,STONE)
B(-15,-10,-9,STONE)
B(-15,-10,-8,STONE)
B(-15,-10,-7,STONE)
B(-15,-10,-6,STONE)
B(-15,-10,-5,STONE)
B(-15,-10,-4,STONE)
B(-15,-10,-3,STONE)
B(-15,-10,-2,STONE)
B(-15,-10,-1,STONE)
B(-15,-10,0,STONE)
B(-15,-10,1,STONE)
B(-15,-10,2,STONE)
B(-15,-10,3,STONE)
B(-15,-10,4,STONE)
B(-15,-10,5,STONE)
B(-15,-10,6,STONE)
B(-15,-10,7,STONE)
B(-15,-10,8,STONE)
B(-15,-10,9,STONE)
B(-15,-10,10,STONE)
B(-15,-9,-4,STONE)
B(-15,-9,-3,STONE)
B(-15,-9,-2,STONE)
B(-15,-9,-1,STONE)
B(-15,-9,0,STONE)
B(-15,-8,-3,STONE)
B(-15,-8,-2,STONE)
B(-15,-8,-1,STONE)
B(-14,-10,-11,STONE)
B(-14,-10,-10,STONE)
B(-14,-10,-9,STONE)
B(-14,-10,-8,STONE)
B(-14,-10,-7,STONE)
B(-14,-10,-6,STONE)
B(-14,-10,-5,STONE)
B(-14,-10,-4,STONE)
B(-14,-10,-3,STONE)
B(-14,-10,-2,STONE)
B(-14,-10,-1,STONE)
B(-14,-10,0,STONE)
B(-14,-10,1,STONE)
B(-14,-10,2,STONE)
B(-14,-10,3,STONE)
B(-14,-10,4,STONE)
B(-14,-10,5,STONE)
B(-14,-10,6,STONE)
B(-14,-10,7,STONE)
B(-14,-10,8,STONE)
B(-14,-10,9,STONE)
B(-14,-10,10,STONE)
B(-14,-10,11,STONE)
B(-14,-10,12,STONE)
B(-14,-9,-10,STONE)
B(-14,-9,-9,STONE)
B(-14,-9,-8,STONE)
B(-14,-9,-7,STONE)
B(-14,-9,-6,STONE)
B(-14,-9,-5,STONE)
B(-14,-9,-4,STONE)
B(-14,-9,-3,STONE)
B(-14,-9,-2,STONE)
B(-14,-9,-1,STONE)
B(-14,-9,0,STONE)
B(-14,-9,1,STONE)
B(-14,-9,4,STONE)
B(-14,-9,5,STONE)
B(-14,-9,6,STONE)
B(-14,-9,7,STONE)
B(-14,-9,8,STONE)
B(-14,-9,9,STONE)
B(-14,-8,-10,STONE)
B(-14,-8,-9,STONE)
B(-14,-8,-6,STONE)
B(-14,-8,-5,STONE)
B(-14,-8,-4,STONE)
B(-14,-8,-3,STONE)
B(-14,-8,-2,STONE)
B(-14,-8,-1,STONE)
B(-14,-8,0,STONE)
B(-14,-8,7,STONE)
B(-14,-8,8,STONE)
B(-14,-7,-5,STONE)
B(-14,-7,-4,STONE)
B(-14,-7,-3,STONE)
B(-14,-7,-2,STONE)
B(-14,-7,-1,STONE)
B(-14,-6,-5,STONE)
B(-13,-10,-12,STONE)
B(-13,-10,-11,STONE)
B(-13,-10,-10,STONE)
B(-13,-10,-9,STONE)
B(-13,-10,-8,STONE)
B(-13,-10,-7,STONE)
B(-13,-10,-6,STONE)
B(-13,-10,-5,STONE)
B(-13,-10,-4,STONE)
B(-13,-10,-3,STONE)
B(-13,-10,-2,STONE)
B(-13,-10,-1,STONE)
B(-13,-10,0,STONE)
B(-13,-10,1,STONE)
B(-13,-10,2,STONE)
B(-13,-10,3,STONE)
B(-13,-10,4,STONE)
B(-13,-10,5,STONE)
B(-13,-10,6,STONE)
B(-13,-10,7,STONE)
B(-13,-10,8,STONE)
B(-13,-10,9,STONE)
B(-13,-10,10,STONE)
B(-13,-10,11,STONE)
B(-13,-10,12,STONE)
B(-13,-10,13,STONE)
B(-13,-9,-11,STONE)
B(-13,-9,-10,STONE)
B(-13,-9,-9,STONE)
B(-13,-9,-8,STONE)
B(-13,-9,-7,STONE)
B(-13,-9,-6,STONE)
B(-13,-9,-5,STONE)
B(-13,-9,-4,STONE)
B(-13,-9,-3,STONE)
B(-13,-9,-2,STONE)
B(-13,-9,-1,STONE)
B(-13,-9,0,STONE)
B(-13,-9,1,STONE)
B(-13,-9,2,STONE)
B(-13,-9,3,STONE)
B(-13,-9,4,STONE)
B(-13,-9,5,STONE)
B(-13,-9,6,STONE)
B(-13,-9,7,STONE)
B(-13,-9,8,STONE)
B(-13,-9,9,STONE)
B(-13,-9,10,STONE)
B(-13,-8,-11,STONE)
B(-13,-8,-10,STONE)
B(-13,-8,-9,STONE)
B(-13,-8,-8,STONE)
B(-13,-8,-7,STONE)
B(-13,-8,-6,STONE)
B(-13,-8,-5,STONE)
B(-13,-8,-4,STONE)
B(-13,-8,-3,STONE)
B(-13,-8,-2,STONE)
B(-13,-8,-1,STONE)
B(-13,-8,0,STONE)
B(-13,-8,1,STONE)
B(-13,-8,2,STONE)
B(-13,-8,3,STONE)
B(-13,-8,4,STONE)
B(-13,-8,5,STONE)
B(-13,-8,6,STONE)
B(-13,-8,7,STONE)
B(-13,-8,8,STONE)
B(-13,-8,9,STONE)
B(-13,-7,-9,STONE)
B(-13,-7,-7,STONE)
B(-13,-7,-6,STONE)
B(-13,-7,-5,STONE)
B(-13,-7,-4,STONE)
B(-13,-7,-3,STONE)
B(-13,-7,-2,STONE)
B(-13,-7,-1,STONE)
B(-13,-7,0,STONE)
B(-13,-7,1,STONE)
B(-13,-7,2,STONE)
B(-13,-7,3,STONE)
B(-13,-7,4,STONE)
B(-13,-7,5,STONE)
B(-13,-7,7,STONE)
B(-13,-7,8,STONE)
B(-13,-6,-6,STONE)
B(-13,-6,-5,STONE)
B(-13,-6,-4,STONE)
B(-13,-6,-3,STONE)
B(-13,-6,-2,STONE)
B(-13,-6,-1,STONE)
B(-13,-6,0,STONE)
B(-13,-6,1,STONE)
B(-13,-6,2,STONE)
B(-13,-6,3,STONE)
B(-13,-5,-6,STONE)
B(-13,-5,-5,STONE)
B(-13,-5,-4,STONE)
B(-13,-5,-3,STONE)
B(-13,-5,-2,STONE)
B(-12,-10,-12,STONE)
B(-12,-10,-11,STONE)
B(-12,-10,-10,STONE)
B(-12,-10,-9,STONE)
B(-12,-10,-8,STONE)
B(-12,-10,-7,STONE)
B(-12,-10,-6,STONE)
B(-12,-10,-5,STONE)
B(-12,-10,-4,STONE)
B(-12,-10,-3,STONE)
B(-12,-10,-2,STONE)
B(-12,-10,-1,STONE)
B(-12,-10,0,STONE)
B(-12,-10,1,STONE)
B(-12,-10,2,STONE)
B(-12,-10,3,STONE)
B(-12,-10,4,STONE)
B(-12,-10,5,STONE)
B(-12,-10,6,STONE)
B(-12,-10,7,STONE)
B(-12,-10,8,STONE)
B(-12,-10,9,STONE)
B(-12,-10,10,STONE)
B(-12,-10,11,STONE)
B(-12,-10,12,STONE)
B(-12,-10,13,STONE)
B(-12,-9,-12,STONE)
B(-12,-9,-11,STONE)
B(-12,-9,-10,STONE)
B(-12,-9,-9,STONE)
B(-12,-9,-8,STONE)
B(-12,-9,-7,STONE)
B(-12,-9,-6,STONE)
B(-12,-9,-5,STONE)
B(-12,-9,-4,STONE)
B(-12,-9,-3,STONE)
B(-12,-9,-2,STONE)
B(-12,-9,-1,STONE)
B(-12,-9,0,STONE)
B(-12,-9,1,STONE)
B(-12,-9,2,STONE)
B(-12,-9,3,STONE)
B(-12,-9,4,STONE)
B(-12,-9,5,STONE)
B(-12,-9,6,STONE)
B(-12,-9,7,STONE)
B(-12,-9,8,STONE)
B(-12,-9,9,STONE)
B(-12,-9,10,STONE)
B(-12,-9,11,STONE)
B(-12,-9,12,STONE)
B(-12,-8,-12,STONE)
B(-12,-8,-10,STONE)
B(-12,-8,-9,STONE)
B(-12,-8,-8,STONE)
B(-12,-8,-7,STONE)
B(-12,-8,-6,STONE)
B(-12,-8,-5,STONE)
B(-12,-8,-4,STONE)
B(-12,-8,-3,STONE)
B(-12,-8,-2,STONE)
B(-12,-8,-1,STONE)
B(-12,-8,0,STONE)
B(-12,-8,1,STONE)
B(-12,-8,2,STONE)
B(-12,-8,3,STONE)
B(-12,-8,4,STONE)
B(-12,-8,5,STONE)
B(-12,-8,6,STONE)
B(-12,-8,7,STONE)
B(-12,-8,8,STONE)
B(-12,-8,9,STONE)
B(-12,-8,10,STONE)
B(-12,-8,11,STONE)
B(-12,-7,-9,STONE)
B(-12,-7,-8,STONE)
B(-12,-7,-7,STONE)
B(-12,-7,-6,STONE)
B(-12,-7,-5,STONE)
B(-12,-7,-4,STONE)
B(-12,-7,-3,STONE)
B(-12,-7,-2,STONE)
B(-12,-7,-1,STONE)
B(-12,-7,0,STONE)
B(-12,-7,1,STONE)
B(-12,-7,2,STONE)
B(-12,-7,3,STONE)
B(-12,-7,4,STONE)
B(-12,-7,5,STONE)
B(-12,-7,6,STONE)
B(-12,-7,7,STONE)
B(-12,-7,8,STONE)
B(-12,-7,9,STONE)
B(-12,-7,10,STONE)
B(-12,-6,-8,STONE)
B(-12,-6,-7,STONE)
B(-12,-6,-6,STONE)
B(-12,-6,-5,STONE)
B(-12,-6,-4,STONE)
B(-12,-6,-3,STONE)
B(-12,-6,-2,STONE)
B(-12,-6,-1,STONE)
B(-12,-6,0,STONE)
B(-12,-6,1,STONE)
B(-12,-6,2,STONE)
B(-12,-6,3,STONE)
B(-12,-6,4,STONE)
B(-12,-6,5,STONE)
B(-12,-6,6,STONE)
B(-12,-6,7,STONE)
B(-12,-6,8,STONE)
B(-12,-6,9,STONE)
B(-12,-5,-7,STONE)
B(-12,-5,-6,STONE)
B(-12,-5,-5,STONE)
B(-12,-5,-4,STONE)
B(-12,-5,-3,STONE)
B(-12,-5,-2,STONE)
B(-12,-5,-1,STONE)
B(-12,-5,0,STONE)
B(-12,-5,1,STONE)
B(-12,-5,2,STONE)
B(-12,-5,3,STONE)
B(-12,-5,4,STONE)
B(-12,-5,5,STONE)
B(-12,-4,-7,STONE)
B(-12,-4,-6,STONE)
B(-12,-4,-5,STONE)
B(-12,-4,-4,STONE)
B(-12,-4,-3,STONE)
B(-12,-4,-2,STONE)
B(-12,-4,-1,STONE)
B(-12,-4,0,STONE)
B(-12,-4,1,STONE)
B(-12,-4,2,STONE)
B(-12,-4,3,STONE)
B(-12,-4,4,STONE)
B(-12,-4,5,STONE)
B(-12,-3,-1,STONE)
B(-12,-3,3,STONE)
B(-12,-3,5,STONE)
B(-12,-2,3,STONE)
B(-11,-10,-13,STONE)
B(-11,-10,-12,STONE)
B(-11,-10,-11,STONE)
B(-11,-10,-10,STONE)
B(-11,-10,-9,STONE)
B(-11,-10,-8,STONE)
B(-11,-10,-7,STONE)
B(-11,-10,-6,STONE)
B(-11,-10,-5,STONE)
B(-11,-10,-4,STONE)
B(-11,-10,-3,STONE)
B(-11,-10,-2,STONE)
B(-11,-10,-1,STONE)
B(-11,-10,0,STONE)
B(-11,-10,1,STONE)
B(-11,-10,2,STONE)
B(-11,-10,3,STONE)
B(-11,-10,4,STONE)
B(-11,-10,5,STONE)
B(-11,-10,6,STONE)
B(-11,-10,7,STONE)
B(-11,-10,8,STONE)
B(-11,-10,9,STONE)
B(-11,-10,10,STONE)
B(-11,-10,11,STONE)
B(-11,-10,12,STONE)
B(-11,-10,13,STONE)
B(-11,-10,14,STONE)
B(-11,-9,-12,STONE)
B(-11,-9,-11,STONE)
B(-11,-9,-10,STONE)
B(-11,-9,-9,STONE)
B(-11,-9,-8,STONE)
B(-11,-9,-7,STONE)
B(-11,-9,-6,STONE)
B(-11,-9,-5,STONE)
B(-11,-9,-4,STONE)
B(-11,-9,-3,STONE)
B(-11,-9,-2,STONE)
B(-11,-9,-1,STONE)
B(-11,-9,0,STONE)
B(-11,-9,1,STONE)
B(-11,-9,2,STONE)
B(-11,-9,3,STONE)
B(-11,-9,4,STONE)
B(-11,-9,5,STONE)
B(-11,-9,6,STONE)
B(-11,-9,7,STONE)
B(-11,-9,8,STONE)
B(-11,-9,9,STONE)
B(-11,-9,10,STONE)
B(-11,-9,11,STONE)
B(-11,-9,12,STONE)
B(-11,-9,13,STONE)
B(-11,-8,-12,STONE)
B(-11,-8,-11,STONE)
B(-11,-8,-10,STONE)
B(-11,-8,-9,STONE)
B(-11,-8,-8,STONE)
B(-11,-8,-7,STONE)
B(-11,-8,-6,STONE)
B(-11,-8,-5,STONE)
B(-11,-8,-4,STONE)
B(-11,-8,-3,STONE)
B(-11,-8,-2,STONE)
B(-11,-8,-1,STONE)
B(-11,-8,0,STONE)
B(-11,-8,1,STONE)
B(-11,-8,2,STONE)
B(-11,-8,3,STONE)
B(-11,-8,4,STONE)
B(-11,-8,5,STONE)
B(-11,-8,6,STONE)
B(-11,-8,7,STONE)
B(-11,-8,8,STONE)
B(-11,-8,9,STONE)
B(-11,-8,10,STONE)
B(-11,-8,11,STONE)
B(-11,-8,12,STONE)
B(-11,-7,-11,STONE)
B(-11,-7,-10,STONE)
B(-11,-7,-9,STONE)
B(-11,-7,-8,STONE)
B(-11,-7,-7,STONE)
B(-11,-7,-6,STONE)
B(-11,-7,-5,STONE)
B(-11,-7,-4,STONE)
B(-11,-7,-3,STONE)
B(-11,-7,-2,STONE)
B(-11,-7,-1,STONE)
B(-11,-7,0,STONE)
B(-11,-7,1,STONE)
B(-11,-7,2,STONE)
B(-11,-7,3,STONE)
B(-11,-7,4,STONE)
B(-11,-7,5,STONE)
B(-11,-7,6,STONE)
B(-11,-7,7,STONE)
B(-11,-7,8,STONE)
B(-11,-7,9,STONE)
B(-11,-7,10,STONE)
B(-11,-7,11,STONE)
B(-11,-6,-9,STONE)
B(-11,-6,-8,STONE)
B(-11,-6,-7,STONE)
B(-11,-6,-6,STONE)
B(-11,-6,-5,STONE)
B(-11,-6,-4,STONE)
B(-11,-6,-3,STONE)
B(-11,-6,-2,STONE)
B(-11,-6,-1,STONE)
B(-11,-6,0,STONE)
B(-11,-6,1,STONE)
B(-11,-6,2,STONE)
B(-11,-6,3,STONE)
B(-11,-6,4,STONE)
B(-11,-6,5,STONE)
B(-11,-6,6,STONE)
B(-11,-6,7,STONE)
B(-11,-6,8,STONE)
B(-11,-6,9,STONE)
B(-11,-6,10,STONE)
B(-11,-5,-9,STONE)
B(-11,-5,-8,STONE)
B(-11,-5,-7,STONE)
B(-11,-5,-6,STONE)
B(-11,-5,-5,STONE)
B(-11,-5,-4,STONE)
B(-11,-5,-3,STONE)
B(-11,-5,-2,STONE)
B(-11,-5,-1,STONE)
B(-11,-5,0,STONE)
B(-11,-5,1,STONE)
B(-11,-5,2,STONE)
B(-11,-5,3,STONE)
B(-11,-5,4,STONE)
B(-11,-5,5,STONE)
B(-11,-5,6,STONE)
B(-11,-5,7,STONE)
B(-11,-4,-9,STONE)
B(-11,-4,-8,STONE)
B(-11,-4,-7,STONE)
B(-11,-4,-6,STONE)
B(-11,-4,-5,STONE)
B(-11,-4,-4,STONE)
B(-11,-4,-3,STONE)
B(-11,-4,-2,STONE)
B(-11,-4,-1,STONE)
B(-11,-4,0,STONE)
B(-11,-4,1,STONE)
B(-11,-4,2,STONE)
B(-11,-4,3,STONE)
B(-11,-4,6,STONE)
B(-11,-3,-7,STONE)
B(-11,-3,-6,STONE)
B(-11,-3,-5,STONE)
B(-11,-3,-4,STONE)
B(-11,-3,-3,STONE)
B(-11,-3,-2,STONE)
B(-11,-3,-1,STONE)
B(-11,-3,0,STONE)
B(-11,-3,1,STONE)
B(-11,-3,2,STONE)
B(-11,-3,3,STONE)
B(-11,-3,6,STONE)
B(-11,-2,-7,STONE)
B(-11,-2,-6,STONE)
B(-11,-2,-5,STONE)
B(-11,-2,-4,STONE)
B(-11,-2,2,STONE)
B(-11,-2,3,STONE)
B(-11,-2,6,STONE)
B(-10,-10,-14,STONE)
B(-10,-10,-13,STONE)
B(-10,-10,-12,STONE)
B(-10,-10,-11,STONE)
B(-10,-10,-10,STONE)
B(-10,-10,-9,STONE)
B(-10,-10,-8,STONE)
B(-10,-10,-7,STONE)
B(-10,-10,-6,STONE)
B(-10,-10,-5,STONE)
B(-10,-10,-4,STONE)
B(-10,-10,-3,STONE)
B(-10,-10,-2,STONE)
B(-10,-10,-1,STONE)
B(-10,-10,0,STONE)
B(-10,-10,1,STONE)
B(-10,-10,2,STONE)
B(-10,-10,3,STONE)
B(-10,-10,4,STONE)
B(-10,-10,5,STONE)
B(-10,-10,6,STONE)
B(-10,-10,7,STONE)
B(-10,-10,8,STONE)
B(-10,-10,9,STONE)
B(-10,-10,10,STONE)
B(-10,-10,11,STONE)
B(-10,-10,12,STONE)
B(-10,-10,13,STONE)
B(-10,-10,14,STONE)
B(-10,-10,15,STONE)
B(-10,-9,-12,STONE)
B(-10,-9,-11,STONE)
B(-10,-9,-10,STONE)
B(-10,-9,-9,STONE)
B(-10,-9,-8,STONE)
B(-10,-9,-7,STONE)
B(-10,-9,-6,STONE)
B(-10,-9,-5,STONE)
B(-10,-9,-4,STONE)
B(-10,-9,-3,STONE)
B(-10,-9,-2,STONE)
B(-10,-9,-1,STONE)
B(-10,-9,0,STONE)
B(-10,-9,1,STONE)
B(-10,-9,2,STONE)
B(-10,-9,3,STONE)
B(-10,-9,4,STONE)
B(-10,-9,5,STONE)
B(-10,-9,6,STONE)
B(-10,-9,7,STONE)
B(-10,-9,8,STONE)
B(-10,-9,9,STONE)
B(-10,-9,10,STONE)
B(-10,-9,11,STONE)
B(-10,-9,12,STONE)
B(-10,-9,13,STONE)
B(-10,-9,14,STONE)
B(-10,-9,15,STONE)
B(-10,-8,-12,STONE)
B(-10,-8,-11,STONE)
B(-10,-8,-10,STONE)
B(-10,-8,-9,STONE)
B(-10,-8,-8,STONE)
B(-10,-8,-7,STONE)
B(-10,-8,-6,STONE)
B(-10,-8,-5,STONE)
B(-10,-8,-4,STONE)
B(-10,-8,-3,STONE)
B(-10,-8,-2,STONE)
B(-10,-8,-1,STONE)
B(-10,-8,0,STONE)
B(-10,-8,1,STONE)
B(-10,-8,2,STONE)
B(-10,-8,3,STONE)
B(-10,-8,4,STONE)
B(-10,-8,5,STONE)
B(-10,-8,6,STONE)
B(-10,-8,7,STONE)
B(-10,-8,8,STONE)
B(-10,-8,9,STONE)
B(-10,-8,10,STONE)
B(-10,-8,11,STONE)
B(-10,-8,12,STONE)
B(-10,-8,13,STONE)
B(-10,-8,14,STONE)
B(-10,-7,-12,STONE)
B(-10,-7,-11,STONE)
B(-10,-7,-10,STONE)
B(-10,-7,-9,STONE)
B(-10,-7,-8,STONE)
B(-10,-7,-7,STONE)
B(-10,-7,-6,STONE)
B(-10,-7,-5,STONE)
B(-10,-7,-4,STONE)
B(-10,-7,-3,STONE)
B(-10,-7,-2,STONE)
B(-10,-7,-1,STONE)
B(-10,-7,0,STONE)
B(-10,-7,1,STONE)
B(-10,-7,2,STONE)
B(-10,-7,3,STONE)
B(-10,-7,4,STONE)
B(-10,-7,5,STONE)
B(-10,-7,6,STONE)
B(-10,-7,7,STONE)
B(-10,-7,8,STONE)
B(-10,-7,9,STONE)
B(-10,-7,10,STONE)
B(-10,-7,11,STONE)
B(-10,-7,12,STONE)
B(-10,-6,-11,STONE)
B(-10,-6,-10,STONE)
B(-10,-6,-9,STONE)
B(-10,-6,-8,STONE)
B(-10,-6,-7,STONE)
B(-10,-6,-6,STONE)
B(-10,-6,-5,STONE)
B(-10,-6,-4,STONE)
B(-10,-6,-3,STONE)
B(-10,-6,-2,STONE)
B(-10,-6,-1,STONE)
B(-10,-6,0,STONE)
B(-10,-6,1,STONE)
B(-10,-6,2,STONE)
B(-10,-6,3,STONE)
B(-10,-6,4,STONE)
B(-10,-6,5,STONE)
B(-10,-6,6,STONE)
B(-10,-6,7,STONE)
B(-10,-6,8,STONE)
B(-10,-6,9,STONE)
B(-10,-6,10,STONE)
B(-10,-6,11,STONE)
B(-10,-5,-9,STONE)
B(-10,-5,-8,STONE)
B(-10,-5,-7,STONE)
B(-10,-5,-6,STONE)
B(-10,-5,-5,STONE)
B(-10,-5,-4,STONE)
B(-10,-5,-3,STONE)
B(-10,-5,-2,STONE)
B(-10,-5,-1,STONE)
B(-10,-5,0,STONE)
B(-10,-5,1,STONE)
B(-10,-5,2,STONE)
B(-10,-5,3,STONE)
B(-10,-5,4,STONE)
B(-10,-5,5,STONE)
B(-10,-5,6,STONE)
B(-10,-5,7,STONE)
B(-10,-5,9,STONE)
B(-10,-5,10,STONE)
B(-10,-4,-9,STONE)
B(-10,-4,-8,STONE)
B(-10,-4,-7,STONE)
B(-10,-4,-6,STONE)
B(-10,-4,-5,STONE)
B(-10,-4,-4,STONE)
B(-10,-4,-3,STONE)
B(-10,-4,-2,STONE)
B(-10,-4,-1,STONE)
B(-10,-4,0,STONE)
B(-10,-4,1,STONE)
B(-10,-4,2,STONE)
B(-10,-4,3,STONE)
B(-10,-4,4,STONE)
B(-10,-4,5,STONE)
B(-10,-4,6,STONE)
B(-10,-4,7,STONE)
B(-10,-4,10,STONE)
B(-10,-3,-9,STONE)
B(-10,-3,-8,STONE)
B(-10,-3,-7,STONE)
B(-10,-3,-6,STONE)
B(-10,-3,-5,STONE)
B(-10,-3,-4,STONE)
B(-10,-3,-3,STONE)
B(-10,-3,-2,STONE)
B(-10,-3,-1,STONE)
B(-10,-3,0,STONE)
B(-10,-3,1,STONE)
B(-10,-3,2,STONE)
B(-10,-3,3,STONE)
B(-10,-3,4,STONE)
B(-10,-3,5,STONE)
B(-10,-3,6,STONE)
B(-10,-2,-9,STONE)
B(-10,-2,-8,STONE)
B(-10,-2,-7,STONE)
B(-10,-2,-6,STONE)
B(-10,-2,-5,STONE)
B(-10,-2,-4,STONE)
B(-10,-2,-3,STONE)
B(-10,-2,-2,STONE)
B(-10,-2,-1,STONE)
B(-10,-2,0,STONE)
B(-10,-2,1,STONE)
B(-10,-2,2,STONE)
B(-10,-2,3,STONE)
B(-10,-2,4,STONE)
B(-10,-1,-7,STONE)
B(-10,-1,-6,STONE)
B(-10,-1,-5,STONE)
B(-10,-1,-2,STONE)
B(-10,-1,0,STONE)
B(-10,-1,1,STONE)
B(-10,-1,2,STONE)
B(-10,-1,3,STONE)
B(-10,-1,4,STONE)
B(-10,0,-6,STONE)
B(-10,0,-5,STONE)
B(-10,0,-2,STONE)
B(-10,0,1,STONE)
B(-10,0,2,STONE)
B(-10,0,4,STONE)
B(-9,-10,-14,STONE)
B(-9,-10,-13,STONE)
B(-9,-10,-12,STONE)
B(-9,-10,-11,STONE)
B(-9,-10,-10,STONE)
B(-9,-10,-9,STONE)
B(-9,-10,-8,STONE)
B(-9,-10,-7,STONE)
B(-9,-10,-6,STONE)
B(-9,-10,-5,STONE)
B(-9,-10,-4,STONE)
B(-9,-10,-3,STONE)
B(-9,-10,-2,STONE)
B(-9,-10,-1,STONE)
B(-9,-10,0,STONE)
B(-9,-10,1,STONE)
B(-9,-10,2,STONE)
B(-9,-10,3,STONE)
B(-9,-10,4,STONE)
B(-9,-10,5,STONE)
B(-9,-10,6,STONE)
B(-9,-10,7,STONE)
B(-9,-10,8,STONE)
B(-9,-10,9,STONE)
B(-9,-10,10,STONE)
B(-9,-10,11,STONE)
B(-9,-10,12,STONE)
B(-9,-10,13,STONE)
B(-9,-10,14,STONE)
B(-9,-10,15,STONE)
B(-9,-9,-12,STONE)
B(-9,-9,-11,STONE)
B(-9,-9,-10,STONE)
B(-9,-9,-9,STONE)
B(-9,-9,-8,STONE)
B(-9,-9,-7,STONE)
B(-9,-9,-6,STONE)
B(-9,-9,-5,STONE)
B(-9,-9,-4,STONE)
B(-9,-9,-3,STONE)
B(-9,-9,-2,STONE)
B(-9,-9,-1,STONE)
B(-9,-9,0,STONE)
B(-9,-9,1,STONE)
B(-9,-9,2,STONE)
B(-9,-9,3,STONE)
B(-9,-9,4,STONE)
B(-9,-9,5,STONE)
B(-9,-9,6,STONE)
B(-9,-9,7,STONE)
B(-9,-9,8,STONE)
B(-9,-9,9,STONE)
B(-9,-9,10,STONE)
B(-9,-9,11,STONE)
B(-9,-9,12,STONE)
B(-9,-9,13,STONE)
B(-9,-9,14,STONE)
B(-9,-9,15,STONE)
B(-9,-8,-12,STONE)
B(-9,-8,-11,STONE)
B(-9,-8,-10,STONE)
B(-9,-8,-9,STONE)
B(-9,-8,-8,STONE)
B(-9,-8,-7,STONE)
B(-9,-8,-6,STONE)
B(-9,-8,-5,STONE)
B(-9,-8,-4,STONE)
B(-9,-8,-3,STONE)
B(-9,-8,-2,STONE)
B(-9,-8,-1,STONE)
B(-9,-8,0,STONE)
B(-9,-8,1,STONE)
B(-9,-8,2,STONE)
B(-9,-8,3,STONE)
B(-9,-8,4,STONE)
B(-9,-8,5,STONE)
B(-9,-8,6,STONE)
B(-9,-8,7,STONE)
B(-9,-8,8,STONE)
B(-9,-8,9,STONE)
B(-9,-8,10,STONE)
B(-9,-8,11,STONE)
B(-9,-8,12,STONE)
B(-9,-8,13,STONE)
B(-9,-8,14,STONE)
B(-9,-7,-11,STONE)
B(-9,-7,-10,STONE)
B(-9,-7,-9,STONE)
B(-9,-7,-8,STONE)
B(-9,-7,-7,STONE)
B(-9,-7,-6,STONE)
B(-9,-7,-5,STONE)
B(-9,-7,-4,STONE)
B(-9,-7,-3,STONE)
B(-9,-7,-2,STONE)
B(-9,-7,-1,STONE)
B(-9,-7,0,STONE)
B(-9,-7,1,STONE)
B(-9,-7,2,STONE)
B(-9,-7,3,STONE)
B(-9,-7,4,STONE)
B(-9,-7,5,STONE)
B(-9,-7,6,STONE)
B(-9,-7,7,STONE)
B(-9,-7,8,STONE)
B(-9,-7,9,STONE)
B(-9,-7,10,STONE)
B(-9,-7,11,STONE)
B(-9,-7,12,STONE)
B(-9,-7,13,STONE)
B(-9,-6,-11,STONE)
B(-9,-6,-10,STONE)
B(-9,-6,-9,STONE)
B(-9,-6,-8,STONE)
B(-9,-6,-7,STONE)
B(-9,-6,-6,STONE)
B(-9,-6,-5,STONE)
B(-9,-6,-4,STONE)
B(-9,-6,-3,STONE)
B(-9,-6,-2,STONE)
B(-9,-6,-1,STONE)
B(-9,-6,0,STONE)
B(-9,-6,1,STONE)
B(-9,-6,2,STONE)
B(-9,-6,3,STONE)
B(-9,-6,4,STONE)
B(-9,-6,5,STONE)
B(-9,-6,6,STONE)
B(-9,-6,7,STONE)
B(-9,-6,8,STONE)
B(-9,-6,9,STONE)
B(-9,-6,10,STONE)
B(-9,-6,11,STONE)
B(-9,-6,12,STONE)
B(-9,-5,-10,STONE)
B(-9,-5,-9,STONE)
B(-9,-5,-8,STONE)
B(-9,-5,-7,STONE)
B(-9,-5,-6,STONE)
B(-9,-5,-5,STONE)
B(-9,-5,-4,STONE)
B(-9,-5,-3,STONE)
B(-9,-5,-2,STONE)
B(-9,-5,-1,STONE)
B(-9,-5,0,STONE)
B(-9,-5,1,STONE)
B(-9,-5,2,STONE)
B(-9,-5,3,STONE)
B(-9,-5,4,STONE)
B(-9,-5,5,STONE)
B(-9,-5,6,STONE)
B(-9,-5,7,STONE)
B(-9,-5,8,STONE)
B(-9,-5,9,STONE)
B(-9,-5,10,STONE)
B(-9,-5,12,STONE)
B(-9,-4,-10,STONE)
B(-9,-4,-9,STONE)
B(-9,-4,-8,STONE)
B(-9,-4,-7,STONE)
B(-9,-4,-6,STONE)
B(-9,-4,-5,STONE)
B(-9,-4,-4,STONE)
B(-9,-4,-3,STONE)
B(-9,-4,-2,STONE)
B(-9,-4,-1,STONE)
B(-9,-4,0,STONE)
B(-9,-4,1,STONE)
B(-9,-4,2,STONE)
B(-9,-4,3,STONE)
B(-9,-4,4,STONE)
B(-9,-4,5,STONE)
B(-9,-4,6,STONE)
B(-9,-4,7,STONE)
B(-9,-4,8,STONE)
B(-9,-4,9,STONE)
B(-9,-3,-9,STONE)
B(-9,-3,-8,STONE)
B(-9,-3,-7,STONE)
B(-9,-3,-6,STONE)
B(-9,-3,-5,STONE)
B(-9,-3,-4,STONE)
B(-9,-3,-3,STONE)
B(-9,-3,-2,STONE)
B(-9,-3,-1,STONE)
B(-9,-3,0,STONE)
B(-9,-3,1,STONE)
B(-9,-3,2,STONE)
B(-9,-3,3,STONE)
B(-9,-3,4,STONE)
B(-9,-3,5,STONE)
B(-9,-3,6,STONE)
B(-9,-3,7,STONE)
B(-9,-3,8,STONE)
B(-9,-2,-9,STONE)
B(-9,-2,-8,STONE)
B(-9,-2,-7,STONE)
B(-9,-2,-6,STONE)
B(-9,-2,-5,STONE)
B(-9,-2,-4,STONE)
B(-9,-2,-3,STONE)
B(-9,-2,-2,STONE)
B(-9,-2,-1,STONE)
B(-9,-2,0,STONE)
B(-9,-2,1,STONE)
B(-9,-2,2,STONE)
B(-9,-2,3,STONE)
B(-9,-2,4,STONE)
B(-9,-2,5,STONE)
B(-9,-2,6,STONE)
B(-9,-2,7,STONE)
B(-9,-2,8,STONE)
B(-9,-1,-9,STONE)
B(-9,-1,-8,STONE)
B(-9,-1,-7,STONE)
B(-9,-1,-6,STONE)
B(-9,-1,-5,STONE)
B(-9,-1,-4,STONE)
B(-9,-1,-3,STONE)
B(-9,-1,-2,STONE)
B(-9,-1,-1,STONE)
B(-9,-1,0,STONE)
B(-9,-1,1,STONE)
B(-9,-1,2,STONE)
B(-9,-1,3,STONE)
B(-9,-1,4,STONE)
B(-9,-1,5,STONE)
B(-9,-1,6,STONE)
B(-9,-1,7,STONE)
B(-9,-1,8,STONE)
B(-9,0,-8,STONE)
B(-9,0,-7,STONE)
B(-9,0,-6,STONE)
B(-9,0,-5,STONE)
B(-9,0,-4,STONE)
B(-9,0,-3,STONE)
B(-9,0,-2,STONE)
B(-9,0,-1,STONE)
B(-9,0,0,STONE)
B(-9,0,1,STONE)
B(-9,0,2,STONE)
B(-9,0,3,STONE)
B(-9,0,4,STONE)
B(-9,0,5,STONE)
B(-9,0,6,STONE)
B(-9,0,7,STONE)
B(-9,0,8,STONE)
B(-9,1,-7,STONE)
B(-9,1,-6,STONE)
B(-9,1,-5,STONE)
B(-9,1,-4,STONE)
B(-9,1,-2,STONE)
B(-9,1,-1,STONE)
B(-9,1,0,STONE)
B(-9,1,1,STONE)
B(-9,1,2,STONE)
B(-9,1,5,STONE)
B(-9,1,6,STONE)
B(-9,1,7,STONE)
B(-9,2,-6,STONE)
B(-9,2,-5,STONE)
B(-9,2,-4,STONE)
B(-9,2,-2,STONE)
B(-9,2,-1,STONE)
B(-9,2,1,STONE)
B(-9,3,-6,STONE)
B(-9,3,-5,STONE)
B(-9,3,-1,STONE)
B(-9,3,1,STONE)
B(-9,4,-1,STONE)
B(-9,5,-1,STONE)
B(-9,6,-1,STONE)
B(-9,20,-2,WOOD_STEP:12)
B(-9,20,-1,WOOD_STEP:12)
B(-9,20,0,WOOD_STEP:12)
B(-9,20,1,WOOD_STEP:12)
B(-9,20,2,WOOD_STEP:12)
B(-9,42,-2,ACACIA_STAIRS:4)
B(-9,42,-1,ACACIA_STAIRS:4)
B(-9,42,0,ACACIA_STAIRS:4)
B(-9,42,1,ACACIA_STAIRS:4)
B(-9,42,2,ACACIA_STAIRS:4)
B(-8,-10,-13,STONE)
B(-8,-10,-12,STONE)
B(-8,-10,-11,STONE)
B(-8,-10,-10,STONE)
B(-8,-10,-9,STONE)
B(-8,-10,-8,STONE)
B(-8,-10,-7,STONE)
B(-8,-10,-6,STONE)
B(-8,-10,-5,STONE)
B(-8,-10,-4,STONE)
B(-8,-10,-3,STONE)
B(-8,-10,-2,STONE)
B(-8,-10,-1,STONE)
B(-8,-10,0,STONE)
B(-8,-10,1,STONE)
B(-8,-10,2,STONE)
B(-8,-10,3,STONE)
B(-8,-10,4,STONE)
B(-8,-10,5,STONE)
B(-8,-10,6,STONE)
B(-8,-10,7,STONE)
B(-8,-10,8,STONE)
B(-8,-10,9,STONE)
B(-8,-10,10,STONE)
B(-8,-10,11,STONE)
B(-8,-10,12,STONE)
B(-8,-10,13,STONE)
B(-8,-10,14,STONE)
B(-8,-10,15,STONE)
B(-8,-9,-13,STONE)
B(-8,-9,-12,STONE)
B(-8,-9,-11,STONE)
B(-8,-9,-10,STONE)
B(-8,-9,-9,STONE)
B(-8,-9,-8,STONE)
B(-8,-9,-7,STONE)
B(-8,-9,-6,STONE)
B(-8,-9,-5,STONE)
B(-8,-9,-4,STONE)
B(-8,-9,-3,STONE)
B(-8,-9,-2,STONE)
B(-8,-9,-1,STONE)
B(-8,-9,0,STONE)
B(-8,-9,1,STONE)
B(-8,-9,2,STONE)
B(-8,-9,3,STONE)
B(-8,-9,4,STONE)
B(-8,-9,5,STONE)
B(-8,-9,6,STONE)
B(-8,-9,7,STONE)
B(-8,-9,8,STONE)
B(-8,-9,9,STONE)
B(-8,-9,10,STONE)
B(-8,-9,11,STONE)
B(-8,-9,12,STONE)
B(-8,-9,13,STONE)
B(-8,-9,14,STONE)
B(-8,-9,15,STONE)
B(-8,-8,-13,STONE)
B(-8,-8,-12,STONE)
B(-8,-8,-11,STONE)
B(-8,-8,-10,STONE)
B(-8,-8,-9,STONE)
B(-8,-8,-8,STONE)
B(-8,-8,-7,STONE)
B(-8,-8,-6,STONE)
B(-8,-8,-5,STONE)
B(-8,-8,-4,STONE)
B(-8,-8,-3,STONE)
B(-8,-8,-2,STONE)
B(-8,-8,-1,STONE)
B(-8,-8,0,STONE)
B(-8,-8,1,STONE)
B(-8,-8,2,STONE)
B(-8,-8,3,STONE)
B(-8,-8,4,STONE)
B(-8,-8,5,STONE)
B(-8,-8,6,STONE)
B(-8,-8,7,STONE)
B(-8,-8,8,STONE)
B(-8,-8,9,STONE)
B(-8,-8,10,STONE)
B(-8,-8,11,STONE)
B(-8,-8,12,STONE)
B(-8,-8,13,STONE)
B(-8,-8,14,STONE)
B(-8,-7,-13,STONE)
B(-8,-7,-12,STONE)
B(-8,-7,-11,STONE)
B(-8,-7,-10,STONE)
B(-8,-7,-9,STONE)
B(-8,-7,-8,STONE)
B(-8,-7,-7,STONE)
B(-8,-7,-6,STONE)
B(-8,-7,-5,STONE)
B(-8,-7,-4,STONE)
B(-8,-7,-3,STONE)
B(-8,-7,-2,STONE)
B(-8,-7,-1,STONE)
B(-8,-7,0,STONE)
B(-8,-7,1,STONE)
B(-8,-7,2,STONE)
B(-8,-7,3,STONE)
B(-8,-7,4,STONE)
B(-8,-7,5,STONE)
B(-8,-7,6,STONE)
B(-8,-7,7,STONE)
B(-8,-7,8,STONE)
B(-8,-7,9,STONE)
B(-8,-7,10,STONE)
B(-8,-7,11,STONE)
B(-8,-7,12,STONE)
B(-8,-7,13,STONE)
B(-8,-7,14,STONE)
B(-8,-6,-10,STONE)
B(-8,-6,-9,STONE)
B(-8,-6,-8,STONE)
B(-8,-6,-7,STONE)
B(-8,-6,-6,STONE)
B(-8,-6,-5,STONE)
B(-8,-6,-4,STONE)
B(-8,-6,-3,STONE)
B(-8,-6,-2,STONE)
B(-8,-6,-1,STONE)
B(-8,-6,0,STONE)
B(-8,-6,1,STONE)
B(-8,-6,2,STONE)
B(-8,-6,3,STONE)
B(-8,-6,4,STONE)
B(-8,-6,5,STONE)
B(-8,-6,6,STONE)
B(-8,-6,7,STONE)
B(-8,-6,8,STONE)
B(-8,-6,9,STONE)
B(-8,-6,10,STONE)
B(-8,-6,11,STONE)
B(-8,-6,12,STONE)
B(-8,-6,13,STONE)
B(-8,-5,-10,STONE)
B(-8,-5,-9,STONE)
B(-8,-5,-8,STONE)
B(-8,-5,-7,STONE)
B(-8,-5,-6,STONE)
B(-8,-5,-5,STONE)
B(-8,-5,-4,STONE)
B(-8,-5,-3,STONE)
B(-8,-5,-2,STONE)
B(-8,-5,-1,STONE)
B(-8,-5,0,STONE)
B(-8,-5,1,STONE)
B(-8,-5,2,STONE)
B(-8,-5,3,STONE)
B(-8,-5,4,STONE)
B(-8,-5,5,STONE)
B(-8,-5,6,STONE)
B(-8,-5,7,STONE)
B(-8,-5,8,STONE)
B(-8,-5,9,STONE)
B(-8,-5,10,STONE)
B(-8,-5,11,STONE)
B(-8,-5,12,STONE)
B(-8,-4,-10,STONE)
B(-8,-4,-9,STONE)
B(-8,-4,-8,STONE)
B(-8,-4,-7,STONE)
B(-8,-4,-6,STONE)
B(-8,-4,-5,STONE)
B(-8,-4,-4,STONE)
B(-8,-4,-3,STONE)
B(-8,-4,-2,STONE)
B(-8,-4,-1,STONE)
B(-8,-4,0,STONE)
B(-8,-4,1,STONE)
B(-8,-4,2,STONE)
B(-8,-4,3,STONE)
B(-8,-4,4,STONE)
B(-8,-4,5,STONE)
B(-8,-4,6,STONE)
B(-8,-4,7,STONE)
B(-8,-4,8,STONE)
B(-8,-4,9,STONE)
B(-8,-4,10,STONE)
B(-8,-4,11,STONE)
B(-8,-3,-9,STONE)
B(-8,-3,-8,STONE)
B(-8,-3,-7,STONE)
B(-8,-3,-6,STONE)
B(-8,-3,-5,STONE)
B(-8,-3,-4,STONE)
B(-8,-3,-3,STONE)
B(-8,-3,-2,STONE)
B(-8,-3,-1,STONE)
B(-8,-3,0,STONE)
B(-8,-3,1,STONE)
B(-8,-3,2,STONE)
B(-8,-3,3,STONE)
B(-8,-3,4,STONE)
B(-8,-3,5,STONE)
B(-8,-3,6,STONE)
B(-8,-3,7,STONE)
B(-8,-3,8,STONE)
B(-8,-3,9,STONE)
B(-8,-3,10,STONE)
B(-8,-2,-9,STONE)
B(-8,-2,-8,STONE)
B(-8,-2,-7,STONE)
B(-8,-2,-6,STONE)
B(-8,-2,-5,STONE)
B(-8,-2,-4,STONE)
B(-8,-2,-3,STONE)
B(-8,-2,-2,STONE)
B(-8,-2,-1,STONE)
B(-8,-2,0,STONE)
B(-8,-2,1,STONE)
B(-8,-2,2,STONE)
B(-8,-2,3,STONE)
B(-8,-2,4,STONE)
B(-8,-2,5,STONE)
B(-8,-2,6,STONE)
B(-8,-2,7,STONE)
B(-8,-2,8,STONE)
B(-8,-2,9,STONE)
B(-8,-1,-9,STONE)
B(-8,-1,-8,STONE)
B(-8,-1,-7,STONE)
B(-8,-1,-6,STONE)
B(-8,-1,-5,STONE)
B(-8,-1,-4,STONE)
B(-8,-1,-3,STONE)
B(-8,-1,-2,STONE)
B(-8,-1,-1,STONE)
B(-8,-1,0,STONE)
B(-8,-1,1,STONE)
B(-8,-1,2,STONE)
B(-8,-1,3,STONE)
B(-8,-1,4,STONE)
B(-8,-1,5,STONE)
B(-8,-1,6,STONE)
B(-8,-1,7,STONE)
B(-8,-1,8,STONE)
B(-8,-1,9,STONE)
B(-8,0,-8,STONE)
B(-8,0,-7,STONE)
B(-8,0,-6,STONE)
B(-8,0,-5,STONE)
B(-8,0,-4,STONE)
B(-8,0,-3,STONE)
B(-8,0,-2,STONE)
B(-8,0,-1,STONE)
B(-8,0,0,STONE)
B(-8,0,1,STONE)
B(-8,0,2,STONE)
B(-8,0,3,STONE)
B(-8,0,4,STONE)
B(-8,0,5,STONE)
B(-8,0,6,STONE)
B(-8,0,7,STONE)
B(-8,0,8,STONE)
B(-8,0,9,STONE)
B(-8,1,-8,STONE)
B(-8,1,-7,STONE)
B(-8,1,-6,STONE)
B(-8,1,-5,STONE)
B(-8,1,-4,STONE)
B(-8,1,-3,STONE)
B(-8,1,-2,STONE)
B(-8,1,-1,STONE)
B(-8,1,0,STONE)
B(-8,1,1,STONE)
B(-8,1,2,STONE)
B(-8,1,3,STONE)
B(-8,1,4,STONE)
B(-8,1,5,STONE)
B(-8,1,6,STONE)
B(-8,1,7,STONE)
B(-8,2,-8,STONE)
B(-8,2,-7,STONE)
B(-8,2,-6,STONE)
B(-8,2,-5,STONE)
B(-8,2,-4,STONE)
B(-8,2,-3,STONE)
B(-8,2,-2,STONE)
B(-8,2,-1,STONE)
B(-8,2,0,STONE)
B(-8,2,1,STONE)
B(-8,2,2,STONE)
B(-8,2,3,STONE)
B(-8,2,5,STONE)
B(-8,2,6,STONE)
B(-8,2,7,STONE)
B(-8,3,-7,STONE)
B(-8,3,-6,STONE)
B(-8,3,-5,STONE)
B(-8,3,-4,STONE)
B(-8,3,-3,STONE)
B(-8,3,-2,STONE)
B(-8,3,-1,STONE)
B(-8,3,0,STONE)
B(-8,3,1,STONE)
B(-8,3,2,STONE)
B(-8,3,3,STONE)
B(-8,4,-7,STONE)
B(-8,4,-6,STONE)
B(-8,4,-5,STONE)
B(-8,4,-4,STONE)
B(-8,4,-3,STONE)
B(-8,4,-2,STONE)
B(-8,4,-1,STONE)
B(-8,4,0,STONE)
B(-8,4,1,STONE)
B(-8,4,2,STONE)
B(-8,4,3,STONE)
B(-8,5,-6,STONE)
B(-8,5,-5,STONE)
B(-8,5,-3,STONE)
B(-8,5,-2,STONE)
B(-8,5,-1,STONE)
B(-8,5,0,STONE)
B(-8,5,1,STONE)
B(-8,5,2,STONE)
B(-8,6,-2,STONE)
B(-8,6,-1,STONE)
B(-8,6,0,STONE)
B(-8,6,1,STONE)
B(-8,6,2,STONE)
B(-8,7,-2,STONE)
B(-8,7,-1,STONE)
B(-8,7,0,STONE)
B(-8,7,1,STONE)
B(-8,8,-1,STONE)
B(-8,8,0,STONE)
B(-8,8,1,STONE)
B(-8,9,0,STONE)
B(-8,9,1,STONE)
B(-8,10,0,STONE)
B(-8,10,1,STONE)
B(-8,11,1,STONE)
B(-8,20,-3,WOOD_STEP:12)
B(-8,20,-2,SMOOTH_BRICK)
B(-8,20,-1,SMOOTH_BRICK)
B(-8,20,0,SMOOTH_BRICK)
B(-8,20,1,SMOOTH_BRICK)
B(-8,20,2,SMOOTH_BRICK)
B(-8,20,3,WOOD_STEP:12)
B(-8,21,-2,ACACIA_STAIRS:2)
B(-8,21,-1,ACACIA_STAIRS:0)
B(-8,21,0,ACACIA_STAIRS:0)
B(-8,21,1,ACACIA_STAIRS:0)
B(-8,21,2,ACACIA_STAIRS:0)
B(-8,41,-2,WOOD_STEP:12)
B(-8,41,-1,WOOD_STEP:12)
B(-8,41,0,WOOD_STEP:12)
B(-8,41,1,WOOD_STEP:12)
B(-8,41,2,WOOD_STEP:12)
B(-8,42,-3,ACACIA_STAIRS:6)
B(-8,42,-2,WOOD:4)
B(-8,42,-1,WOOD:4)
B(-8,42,0,WOOD:4)
B(-8,42,1,WOOD:4)
B(-8,42,2,WOOD:4)
B(-8,42,3,ACACIA_STAIRS:4)
B(-8,43,-1,ACACIA_STAIRS:0)
B(-8,43,0,ACACIA_STAIRS:0)
B(-8,43,1,ACACIA_STAIRS:0)
B(-7,-10,-14,STONE)
B(-7,-10,-13,STONE)
B(-7,-10,-12,STONE)
B(-7,-10,-11,STONE)
B(-7,-10,-10,STONE)
B(-7,-10,-9,STONE)
B(-7,-10,-8,STONE)
B(-7,-10,-7,STONE)
B(-7,-10,-6,STONE)
B(-7,-10,-5,STONE)
B(-7,-10,-4,STONE)
B(-7,-10,-3,STONE)
B(-7,-10,-2,STONE)
B(-7,-10,-1,STONE)
B(-7,-10,0,STONE)
B(-7,-10,1,STONE)
B(-7,-10,2,STONE)
B(-7,-10,3,STONE)
B(-7,-10,4,STONE)
B(-7,-10,5,STONE)
B(-7,-10,6,STONE)
B(-7,-10,7,STONE)
B(-7,-10,8,STONE)
B(-7,-10,9,STONE)
B(-7,-10,10,STONE)
B(-7,-10,11,STONE)
B(-7,-10,12,STONE)
B(-7,-10,13,STONE)
B(-7,-10,14,STONE)
B(-7,-10,15,STONE)
B(-7,-9,-13,STONE)
B(-7,-9,-12,STONE)
B(-7,-9,-11,STONE)
B(-7,-9,-10,STONE)
B(-7,-9,-9,STONE)
B(-7,-9,-8,STONE)
B(-7,-9,-7,STONE)
B(-7,-9,-6,STONE)
B(-7,-9,-5,STONE)
B(-7,-9,-4,STONE)
B(-7,-9,-3,STONE)
B(-7,-9,-2,STONE)
B(-7,-9,-1,STONE)
B(-7,-9,0,STONE)
B(-7,-9,1,STONE)
B(-7,-9,2,STONE)
B(-7,-9,3,STONE)
B(-7,-9,4,STONE)
B(-7,-9,5,STONE)
B(-7,-9,6,STONE)
B(-7,-9,7,STONE)
B(-7,-9,8,STONE)
B(-7,-9,9,STONE)
B(-7,-9,10,STONE)
B(-7,-9,11,STONE)
B(-7,-9,12,STONE)
B(-7,-9,13,STONE)
B(-7,-9,14,STONE)
B(-7,-9,15,STONE)
B(-7,-8,-13,STONE)
B(-7,-8,-12,STONE)
B(-7,-8,-11,STONE)
B(-7,-8,-10,STONE)
B(-7,-8,-9,STONE)
B(-7,-8,-8,STONE)
B(-7,-8,-7,STONE)
B(-7,-8,-6,STONE)
B(-7,-8,-5,STONE)
B(-7,-8,-4,STONE)
B(-7,-8,-3,STONE)
B(-7,-8,-2,STONE)
B(-7,-8,-1,STONE)
B(-7,-8,0,STONE)
B(-7,-8,1,STONE)
B(-7,-8,2,STONE)
B(-7,-8,3,STONE)
B(-7,-8,4,STONE)
B(-7,-8,5,STONE)
B(-7,-8,6,STONE)
B(-7,-8,7,STONE)
B(-7,-8,8,STONE)
B(-7,-8,9,STONE)
B(-7,-8,10,STONE)
B(-7,-8,11,STONE)
B(-7,-8,12,STONE)
B(-7,-8,13,STONE)
B(-7,-8,14,STONE)
B(-7,-7,-11,STONE)
B(-7,-7,-10,STONE)
B(-7,-7,-9,STONE)
B(-7,-7,-8,STONE)
B(-7,-7,-7,STONE)
B(-7,-7,-6,STONE)
B(-7,-7,-5,STONE)
B(-7,-7,-4,STONE)
B(-7,-7,-3,STONE)
B(-7,-7,-2,STONE)
B(-7,-7,-1,STONE)
B(-7,-7,0,STONE)
B(-7,-7,1,STONE)
B(-7,-7,2,STONE)
B(-7,-7,3,STONE)
B(-7,-7,4,STONE)
B(-7,-7,5,STONE)
B(-7,-7,6,STONE)
B(-7,-7,7,STONE)
B(-7,-7,8,STONE)
B(-7,-7,9,STONE)
B(-7,-7,10,STONE)
B(-7,-7,11,STONE)
B(-7,-7,12,STONE)
B(-7,-7,13,STONE)
B(-7,-7,14,STONE)
B(-7,-6,-11,STONE)
B(-7,-6,-10,STONE)
B(-7,-6,-9,STONE)
B(-7,-6,-8,STONE)
B(-7,-6,-7,STONE)
B(-7,-6,-6,STONE)
B(-7,-6,-5,STONE)
B(-7,-6,-4,STONE)
B(-7,-6,-3,STONE)
B(-7,-6,-2,STONE)
B(-7,-6,-1,STONE)
B(-7,-6,0,STONE)
B(-7,-6,1,STONE)
B(-7,-6,2,STONE)
B(-7,-6,3,STONE)
B(-7,-6,4,STONE)
B(-7,-6,5,STONE)
B(-7,-6,6,STONE)
B(-7,-6,7,STONE)
B(-7,-6,8,STONE)
B(-7,-6,9,STONE)
B(-7,-6,10,STONE)
B(-7,-6,11,STONE)
B(-7,-6,12,STONE)
B(-7,-6,14,STONE)
B(-7,-5,-10,STONE)
B(-7,-5,-9,STONE)
B(-7,-5,-8,STONE)
B(-7,-5,-7,STONE)
B(-7,-5,-6,STONE)
B(-7,-5,-5,STONE)
B(-7,-5,-4,STONE)
B(-7,-5,-3,STONE)
B(-7,-5,-2,STONE)
B(-7,-5,-1,STONE)
B(-7,-5,0,STONE)
B(-7,-5,1,STONE)
B(-7,-5,2,STONE)
B(-7,-5,3,STONE)
B(-7,-5,4,STONE)
B(-7,-5,5,STONE)
B(-7,-5,6,STONE)
B(-7,-5,7,STONE)
B(-7,-5,8,STONE)
B(-7,-5,9,STONE)
B(-7,-5,10,STONE)
B(-7,-5,11,STONE)
B(-7,-5,12,STONE)
B(-7,-4,-10,STONE)
B(-7,-4,-9,STONE)
B(-7,-4,-8,STONE)
B(-7,-4,-7,STONE)
B(-7,-4,-6,STONE)
B(-7,-4,-5,STONE)
B(-7,-4,-4,STONE)
B(-7,-4,-3,STONE)
B(-7,-4,-2,STONE)
B(-7,-4,-1,STONE)
B(-7,-4,0,STONE)
B(-7,-4,1,STONE)
B(-7,-4,2,STONE)
B(-7,-4,3,STONE)
B(-7,-4,4,STONE)
B(-7,-4,5,STONE)
B(-7,-4,6,STONE)
B(-7,-4,7,STONE)
B(-7,-4,8,STONE)
B(-7,-4,9,STONE)
B(-7,-4,10,STONE)
B(-7,-3,-10,STONE)
B(-7,-3,-9,STONE)
B(-7,-3,-8,STONE)
B(-7,-3,-7,STONE)
B(-7,-3,-6,STONE)
B(-7,-3,-5,STONE)
B(-7,-3,-4,STONE)
B(-7,-3,-3,STONE)
B(-7,-3,-2,STONE)
B(-7,-3,-1,STONE)
B(-7,-3,0,STONE)
B(-7,-3,1,STONE)
B(-7,-3,2,STONE)
B(-7,-3,3,STONE)
B(-7,-3,4,STONE)
B(-7,-3,5,STONE)
B(-7,-3,6,STONE)
B(-7,-3,7,STONE)
B(-7,-3,8,STONE)
B(-7,-3,9,STONE)
B(-7,-3,10,STONE)
B(-7,-2,-10,STONE)
B(-7,-2,-9,STONE)
B(-7,-2,-8,STONE)
B(-7,-2,-7,STONE)
B(-7,-2,-6,STONE)
B(-7,-2,-5,STONE)
B(-7,-2,-4,STONE)
B(-7,-2,-3,STONE)
B(-7,-2,-2,STONE)
B(-7,-2,-1,STONE)
B(-7,-2,0,STONE)
B(-7,-2,1,STONE)
B(-7,-2,2,STONE)
B(-7,-2,3,STONE)
B(-7,-2,4,STONE)
B(-7,-2,5,STONE)
B(-7,-2,6,STONE)
B(-7,-2,7,STONE)
B(-7,-2,8,STONE)
B(-7,-2,9,STONE)
B(-7,-2,10,STONE)
B(-7,-1,-10,STONE)
B(-7,-1,-9,STONE)
B(-7,-1,-8,STONE)
B(-7,-1,-7,STONE)
B(-7,-1,-6,STONE)
B(-7,-1,-5,STONE)
B(-7,-1,-4,STONE)
B(-7,-1,-3,STONE)
B(-7,-1,-2,STONE)
B(-7,-1,-1,STONE)
B(-7,-1,0,STONE)
B(-7,-1,1,STONE)
B(-7,-1,2,STONE)
B(-7,-1,3,STONE)
B(-7,-1,4,STONE)
B(-7,-1,5,STONE)
B(-7,-1,6,STONE)
B(-7,-1,7,STONE)
B(-7,-1,8,STONE)
B(-7,-1,9,STONE)
B(-7,-1,10,STONE)
B(-7,0,-10,STONE)
B(-7,0,-8,STONE)
B(-7,0,-7,STONE)
B(-7,0,-6,STONE)
B(-7,0,-5,STONE)
B(-7,0,-4,STONE)
B(-7,0,-3,STONE)
B(-7,0,-2,STONE)
B(-7,0,-1,STONE)
B(-7,0,0,STONE)
B(-7,0,1,STONE)
B(-7,0,2,STONE)
B(-7,0,3,STONE)
B(-7,0,4,STONE)
B(-7,0,5,STONE)
B(-7,0,6,STONE)
B(-7,0,7,STONE)
B(-7,0,8,STONE)
B(-7,1,-8,STONE)
B(-7,1,-7,STONE)
B(-7,1,-6,STONE)
B(-7,1,-5,STONE)
B(-7,1,-4,STONE)
B(-7,1,-3,STONE)
B(-7,1,-2,STONE)
B(-7,1,-1,STONE)
B(-7,1,0,STONE)
B(-7,1,1,STONE)
B(-7,1,2,STONE)
B(-7,1,3,STONE)
B(-7,1,4,STONE)
B(-7,1,5,STONE)
B(-7,1,6,STONE)
B(-7,1,7,STONE)
B(-7,2,-8,STONE)
B(-7,2,-7,STONE)
B(-7,2,-6,STONE)
B(-7,2,-5,STONE)
B(-7,2,-4,STONE)
B(-7,2,-3,STONE)
B(-7,2,-2,STONE)
B(-7,2,-1,STONE)
B(-7,2,0,STONE)
B(-7,2,1,STONE)
B(-7,2,2,STONE)
B(-7,2,3,STONE)
B(-7,2,4,STONE)
B(-7,2,5,STONE)
B(-7,2,6,STONE)
B(-7,2,7,STONE)
B(-7,3,-8,STONE)
B(-7,3,-7,STONE)
B(-7,3,-6,STONE)
B(-7,3,-5,STONE)
B(-7,3,-4,STONE)
B(-7,3,-3,STONE)
B(-7,3,-2,STONE)
B(-7,3,-1,STONE)
B(-7,3,0,STONE)
B(-7,3,1,STONE)
B(-7,3,2,STONE)
B(-7,3,3,STONE)
B(-7,3,4,STONE)
B(-7,3,5,STONE)
B(-7,3,6,STONE)
B(-7,4,-7,STONE)
B(-7,4,-6,STONE)
B(-7,4,-5,STONE)
B(-7,4,-4,STONE)
B(-7,4,-3,STONE)
B(-7,4,-2,STONE)
B(-7,4,-1,STONE)
B(-7,4,0,STONE)
B(-7,4,1,STONE)
B(-7,4,2,STONE)
B(-7,4,3,STONE)
B(-7,4,4,STONE)
B(-7,4,5,STONE)
B(-7,5,-7,STONE)
B(-7,5,-6,STONE)
B(-7,5,-5,STONE)
B(-7,5,-4,STONE)
B(-7,5,-3,STONE)
B(-7,5,-2,STONE)
B(-7,5,-1,STONE)
B(-7,5,0,STONE)
B(-7,5,1,STONE)
B(-7,5,2,STONE)
B(-7,5,3,STONE)
B(-7,5,4,STONE)
B(-7,5,5,STONE)
B(-7,6,-7,STONE)
B(-7,6,-6,STONE)
B(-7,6,-5,STONE)
B(-7,6,-4,STONE)
B(-7,6,-3,STONE)
B(-7,6,-2,STONE)
B(-7,6,-1,STONE)
B(-7,6,0,STONE)
B(-7,6,1,STONE)
B(-7,6,2,STONE)
B(-7,6,3,STONE)
B(-7,6,4,STONE)
B(-7,7,-5,STONE)
B(-7,7,-4,STONE)
B(-7,7,-2,STONE)
B(-7,7,-1,STONE)
B(-7,7,0,STONE)
B(-7,7,1,STONE)
B(-7,7,2,STONE)
B(-7,7,3,STONE)
B(-7,7,4,STONE)
B(-7,8,-2,STONE)
B(-7,8,-1,STONE)
B(-7,8,0,STONE)
B(-7,8,1,STONE)
B(-7,8,2,STONE)
B(-7,8,3,STONE)
B(-7,9,-1,STONE)
B(-7,9,0,STONE)
B(-7,9,1,STONE)
B(-7,9,2,STONE)
B(-7,10,1,STONE)
B(-7,10,2,STONE)
B(-7,11,1,STONE)
B(-7,11,2,STONE)
B(-7,19,-2,SMOOTH_BRICK)
B(-7,19,-1,SMOOTH_BRICK)
B(-7,19,0,SMOOTH_BRICK)
B(-7,19,1,SMOOTH_BRICK)
B(-7,19,2,SMOOTH_BRICK)
B(-7,20,-4,WOOD_STEP:12)
B(-7,20,-3,SMOOTH_BRICK)
B(-7,20,-2,SMOOTH_BRICK)
B(-7,20,-1,SMOOTH_BRICK)
B(-7,20,0,SMOOTH_BRICK)
B(-7,20,1,SMOOTH_BRICK)
B(-7,20,2,SMOOTH_BRICK)
B(-7,20,3,SMOOTH_BRICK)
B(-7,20,4,WOOD_STEP:12)
B(-7,21,-3,ACACIA_STAIRS:2)
B(-7,21,-2,ACACIA_STAIRS:0)
B(-7,21,-1,WOOD:4)
B(-7,21,0,WOOD:4)
B(-7,21,1,WOOD:4)
B(-7,21,2,ACACIA_STAIRS)
B(-7,21,3,ACACIA_STAIRS:0)
B(-7,22,-1,WOOD_STEP:4)
B(-7,22,0,WOOD_STEP:4)
B(-7,22,1,WOOD_STEP:4)
B(-7,30,-2,WOOD_STEP:12)
B(-7,30,-1,ACACIA_STAIRS:4)
B(-7,30,1,ACACIA_STAIRS:4)
B(-7,30,2,WOOD_STEP:12)
B(-7,31,-1,ACACIA_STAIRS:0)
B(-7,31,0,ACACIA_STAIRS:0)
B(-7,31,1,ACACIA_STAIRS:0)
B(-7,36,-1,ACACIA_STAIRS:4)
B(-7,36,0,ACACIA_STAIRS:4)
B(-7,36,1,ACACIA_STAIRS:4)
B(-7,37,-1,SMOOTH_BRICK)
B(-7,37,0,SMOOTH_BRICK)
B(-7,37,1,SMOOTH_BRICK)
B(-7,38,-1,SMOOTH_BRICK)
B(-7,38,0,SMOOTH_BRICK)
B(-7,38,1,SMOOTH_BRICK)
B(-7,39,-1,SMOOTH_BRICK)
B(-7,39,0,ACACIA_FENCE)
B(-7,39,1,SMOOTH_BRICK)
B(-7,40,-1,SMOOTH_BRICK)
B(-7,40,0,ACACIA_FENCE)
B(-7,40,1,SMOOTH_BRICK)
B(-7,41,-3,WOOD_STEP:12)
B(-7,41,-2,WOOD_STEP:12)
B(-7,41,-1,SMOOTH_BRICK)
B(-7,41,0,SMOOTH_BRICK)
B(-7,41,1,SMOOTH_BRICK)
B(-7,41,2,WOOD_STEP:12)
B(-7,41,3,WOOD_STEP:12)
B(-7,42,-4,ACACIA_STAIRS:6)
B(-7,42,-3,WOOD:4)
B(-7,42,-2,WOOD:4)
B(-7,42,-1,SMOOTH_BRICK)
B(-7,42,0,SMOOTH_BRICK)
B(-7,42,1,SMOOTH_BRICK)
B(-7,42,2,WOOD:4)
B(-7,42,3,WOOD:4)
B(-7,42,4,ACACIA_STAIRS:4)
B(-7,43,-2,ACACIA_STAIRS:0)
B(-7,43,-1,WOOD:4)
B(-7,43,0,WOOD:4)
B(-7,43,1,WOOD:4)
B(-7,43,2,ACACIA_STAIRS:0)
B(-7,44,0,ACACIA_STAIRS:0)
B(-6,-10,-14,STONE)
B(-6,-10,-13,STONE)
B(-6,-10,-12,STONE)
B(-6,-10,-11,STONE)
B(-6,-10,-10,STONE)
B(-6,-10,-9,STONE)
B(-6,-10,-8,STONE)
B(-6,-10,-7,STONE)
B(-6,-10,-6,STONE)
B(-6,-10,-5,STONE)
B(-6,-10,-4,STONE)
B(-6,-10,-3,STONE)
B(-6,-10,-2,STONE)
B(-6,-10,-1,STONE)
B(-6,-10,0,STONE)
B(-6,-10,1,STONE)
B(-6,-10,2,STONE)
B(-6,-10,3,STONE)
B(-6,-10,4,STONE)
B(-6,-10,5,STONE)
B(-6,-10,6,STONE)
B(-6,-10,7,STONE)
B(-6,-10,8,STONE)
B(-6,-10,9,STONE)
B(-6,-10,10,STONE)
B(-6,-10,11,STONE)
B(-6,-10,12,STONE)
B(-6,-10,13,STONE)
B(-6,-10,14,STONE)
B(-6,-10,15,STONE)
B(-6,-10,16,STONE)
B(-6,-9,-13,STONE)
B(-6,-9,-12,STONE)
B(-6,-9,-11,STONE)
B(-6,-9,-10,STONE)
B(-6,-9,-9,STONE)
B(-6,-9,-8,STONE)
B(-6,-9,-7,STONE)
B(-6,-9,-6,STONE)
B(-6,-9,-5,STONE)
B(-6,-9,-4,STONE)
B(-6,-9,-3,STONE)
B(-6,-9,-2,STONE)
B(-6,-9,-1,STONE)
B(-6,-9,0,STONE)
B(-6,-9,1,STONE)
B(-6,-9,2,STONE)
B(-6,-9,3,STONE)
B(-6,-9,4,STONE)
B(-6,-9,5,STONE)
B(-6,-9,6,STONE)
B(-6,-9,7,STONE)
B(-6,-9,8,STONE)
B(-6,-9,9,STONE)
B(-6,-9,10,STONE)
B(-6,-9,11,STONE)
B(-6,-9,12,STONE)
B(-6,-9,13,STONE)
B(-6,-9,14,STONE)
B(-6,-8,-12,STONE)
B(-6,-8,-11,STONE)
B(-6,-8,-10,STONE)
B(-6,-8,-9,STONE)
B(-6,-8,-8,STONE)
B(-6,-8,-7,STONE)
B(-6,-8,-6,STONE)
B(-6,-8,-5,STONE)
B(-6,-8,-4,STONE)
B(-6,-8,-3,STONE)
B(-6,-8,-2,STONE)
B(-6,-8,-1,STONE)
B(-6,-8,0,STONE)
B(-6,-8,1,STONE)
B(-6,-8,2,STONE)
B(-6,-8,3,STONE)
B(-6,-8,4,STONE)
B(-6,-8,5,STONE)
B(-6,-8,6,STONE)
B(-6,-8,7,STONE)
B(-6,-8,8,STONE)
B(-6,-8,9,STONE)
B(-6,-8,10,STONE)
B(-6,-8,11,STONE)
B(-6,-8,12,STONE)
B(-6,-8,13,STONE)
B(-6,-8,14,STONE)
B(-6,-7,-11,STONE)
B(-6,-7,-10,STONE)
B(-6,-7,-9,STONE)
B(-6,-7,-8,STONE)
B(-6,-7,-7,STONE)
B(-6,-7,-6,STONE)
B(-6,-7,-5,STONE)
B(-6,-7,-4,STONE)
B(-6,-7,-3,STONE)
B(-6,-7,-2,STONE)
B(-6,-7,-1,STONE)
B(-6,-7,0,STONE)
B(-6,-7,1,STONE)
B(-6,-7,2,STONE)
B(-6,-7,3,STONE)
B(-6,-7,4,STONE)
B(-6,-7,5,STONE)
B(-6,-7,6,STONE)
B(-6,-7,7,STONE)
B(-6,-7,8,STONE)
B(-6,-7,9,STONE)
B(-6,-7,10,STONE)
B(-6,-7,11,STONE)
B(-6,-7,12,STONE)
B(-6,-7,13,STONE)
B(-6,-7,14,STONE)
B(-6,-6,-11,STONE)
B(-6,-6,-10,STONE)
B(-6,-6,-9,STONE)
B(-6,-6,-8,STONE)
B(-6,-6,-7,STONE)
B(-6,-6,-6,STONE)
B(-6,-6,-5,STONE)
B(-6,-6,-4,STONE)
B(-6,-6,-3,STONE)
B(-6,-6,-2,STONE)
B(-6,-6,-1,STONE)
B(-6,-6,0,STONE)
B(-6,-6,1,STONE)
B(-6,-6,2,STONE)
B(-6,-6,3,STONE)
B(-6,-6,4,STONE)
B(-6,-6,5,STONE)
B(-6,-6,6,STONE)
B(-6,-6,7,STONE)
B(-6,-6,8,STONE)
B(-6,-6,9,STONE)
B(-6,-6,10,STONE)
B(-6,-6,11,STONE)
B(-6,-6,12,STONE)
B(-6,-5,-10,STONE)
B(-6,-5,-9,STONE)
B(-6,-5,-8,STONE)
B(-6,-5,-7,STONE)
B(-6,-5,-6,STONE)
B(-6,-5,-5,STONE)
B(-6,-5,-4,STONE)
B(-6,-5,-3,STONE)
B(-6,-5,-2,STONE)
B(-6,-5,-1,STONE)
B(-6,-5,0,STONE)
B(-6,-5,1,STONE)
B(-6,-5,2,STONE)
B(-6,-5,3,STONE)
B(-6,-5,4,STONE)
B(-6,-5,5,STONE)
B(-6,-5,6,STONE)
B(-6,-5,7,STONE)
B(-6,-5,8,STONE)
B(-6,-5,9,STONE)
B(-6,-5,10,STONE)
B(-6,-5,11,STONE)
B(-6,-5,12,STONE)
B(-6,-4,-10,STONE)
B(-6,-4,-9,STONE)
B(-6,-4,-8,STONE)
B(-6,-4,-7,STONE)
B(-6,-4,-6,STONE)
B(-6,-4,-5,STONE)
B(-6,-4,-4,STONE)
B(-6,-4,-3,STONE)
B(-6,-4,-2,STONE)
B(-6,-4,-1,STONE)
B(-6,-4,0,STONE)
B(-6,-4,1,STONE)
B(-6,-4,2,STONE)
B(-6,-4,3,STONE)
B(-6,-4,4,STONE)
B(-6,-4,5,STONE)
B(-6,-4,6,STONE)
B(-6,-4,7,STONE)
B(-6,-4,8,STONE)
B(-6,-4,9,STONE)
B(-6,-4,10,STONE)
B(-6,-4,12,STONE)
B(-6,-3,-10,STONE)
B(-6,-3,-9,STONE)
B(-6,-3,-8,STONE)
B(-6,-3,-7,STONE)
B(-6,-3,-6,STONE)
B(-6,-3,-5,STONE)
B(-6,-3,-4,STONE)
B(-6,-3,-3,STONE)
B(-6,-3,-2,STONE)
B(-6,-3,-1,STONE)
B(-6,-3,0,STONE)
B(-6,-3,1,STONE)
B(-6,-3,2,STONE)
B(-6,-3,3,STONE)
B(-6,-3,4,STONE)
B(-6,-3,5,STONE)
B(-6,-3,6,STONE)
B(-6,-3,7,STONE)
B(-6,-3,8,STONE)
B(-6,-3,9,STONE)
B(-6,-3,10,STONE)
B(-6,-2,-10,STONE)
B(-6,-2,-9,STONE)
B(-6,-2,-8,STONE)
B(-6,-2,-7,STONE)
B(-6,-2,-6,STONE)
B(-6,-2,-5,STONE)
B(-6,-2,-4,STONE)
B(-6,-2,-3,STONE)
B(-6,-2,-2,STONE)
B(-6,-2,-1,STONE)
B(-6,-2,0,STONE)
B(-6,-2,1,STONE)
B(-6,-2,2,STONE)
B(-6,-2,3,STONE)
B(-6,-2,4,STONE)
B(-6,-2,5,STONE)
B(-6,-2,6,STONE)
B(-6,-2,7,STONE)
B(-6,-2,8,STONE)
B(-6,-2,9,STONE)
B(-6,-2,10,STONE)
B(-6,-1,-10,STONE)
B(-6,-1,-9,STONE)
B(-6,-1,-8,STONE)
B(-6,-1,-7,STONE)
B(-6,-1,-6,STONE)
B(-6,-1,-5,STONE)
B(-6,-1,-4,STONE)
B(-6,-1,-3,STONE)
B(-6,-1,-2,STONE)
B(-6,-1,-1,STONE)
B(-6,-1,0,STONE)
B(-6,-1,1,STONE)
B(-6,-1,2,STONE)
B(-6,-1,3,STONE)
B(-6,-1,4,STONE)
B(-6,-1,5,STONE)
B(-6,-1,6,STONE)
B(-6,-1,7,STONE)
B(-6,-1,8,STONE)
B(-6,-1,9,STONE)
B(-6,-1,10,STONE)
B(-6,0,-10,STONE)
B(-6,0,-9,STONE)
B(-6,0,-8,STONE)
B(-6,0,-7,STONE)
B(-6,0,-6,STONE)
B(-6,0,-5,STONE)
B(-6,0,-4,STONE)
B(-6,0,-3,STONE)
B(-6,0,-2,STONE)
B(-6,0,-1,STONE)
B(-6,0,0,STONE)
B(-6,0,1,STONE)
B(-6,0,2,STONE)
B(-6,0,3,STONE)
B(-6,0,4,STONE)
B(-6,0,5,STONE)
B(-6,0,6,STONE)
B(-6,0,7,STONE)
B(-6,0,8,STONE)
B(-6,0,9,STONE)
B(-6,1,-9,STONE)
B(-6,1,-8,STONE)
B(-6,1,-7,STONE)
B(-6,1,-6,STONE)
B(-6,1,-5,STONE)
B(-6,1,-4,STONE)
B(-6,1,-3,STONE)
B(-6,1,-2,STONE)
B(-6,1,-1,STONE)
B(-6,1,0,STONE)
B(-6,1,1,STONE)
B(-6,1,2,STONE)
B(-6,1,3,STONE)
B(-6,1,4,STONE)
B(-6,1,5,STONE)
B(-6,1,6,STONE)
B(-6,1,7,STONE)
B(-6,1,8,STONE)
B(-6,1,9,STONE)
B(-6,2,-9,STONE)
B(-6,2,-8,STONE)
B(-6,2,-7,STONE)
B(-6,2,-6,STONE)
B(-6,2,-5,STONE)
B(-6,2,-4,STONE)
B(-6,2,-3,STONE)
B(-6,2,-2,STONE)
B(-6,2,-1,STONE)
B(-6,2,0,STONE)
B(-6,2,1,STONE)
B(-6,2,2,STONE)
B(-6,2,3,STONE)
B(-6,2,4,STONE)
B(-6,2,5,STONE)
B(-6,2,6,STONE)
B(-6,2,7,STONE)
B(-6,3,-8,STONE)
B(-6,3,-7,STONE)
B(-6,3,-6,STONE)
B(-6,3,-5,STONE)
B(-6,3,-4,STONE)
B(-6,3,-3,STONE)
B(-6,3,-2,STONE)
B(-6,3,-1,STONE)
B(-6,3,0,STONE)
B(-6,3,1,STONE)
B(-6,3,2,STONE)
B(-6,3,3,STONE)
B(-6,3,4,STONE)
B(-6,3,5,STONE)
B(-6,3,6,STONE)
B(-6,4,-8,STONE)
B(-6,4,-7,STONE)
B(-6,4,-6,STONE)
B(-6,4,-5,STONE)
B(-6,4,-4,STONE)
B(-6,4,-3,STONE)
B(-6,4,-2,STONE)
B(-6,4,-1,STONE)
B(-6,4,0,STONE)
B(-6,4,1,STONE)
B(-6,4,2,STONE)
B(-6,4,3,STONE)
B(-6,4,4,STONE)
B(-6,4,5,STONE)
B(-6,4,6,STONE)
B(-6,5,-7,STONE)
B(-6,5,-6,STONE)
B(-6,5,-5,STONE)
B(-6,5,-4,STONE)
B(-6,5,-3,STONE)
B(-6,5,-2,STONE)
B(-6,5,-1,STONE)
B(-6,5,0,STONE)
B(-6,5,1,STONE)
B(-6,5,2,STONE)
B(-6,5,3,STONE)
B(-6,5,4,STONE)
B(-6,5,5,STONE)
B(-6,6,-7,STONE)
B(-6,6,-6,STONE)
B(-6,6,-5,STONE)
B(-6,6,-4,STONE)
B(-6,6,-3,STONE)
B(-6,6,-2,STONE)
B(-6,6,-1,STONE)
B(-6,6,0,STONE)
B(-6,6,1,STONE)
B(-6,6,2,STONE)
B(-6,6,3,STONE)
B(-6,6,4,STONE)
B(-6,6,5,STONE)
B(-6,7,-6,STONE)
B(-6,7,-5,STONE)
B(-6,7,-4,STONE)
B(-6,7,-3,STONE)
B(-6,7,-2,STONE)
B(-6,7,-1,STONE)
B(-6,7,0,STONE)
B(-6,7,1,STONE)
B(-6,7,2,STONE)
B(-6,7,3,STONE)
B(-6,7,4,STONE)
B(-6,8,-5,STONE)
B(-6,8,-4,STONE)
B(-6,8,-3,STONE)
B(-6,8,-2,STONE)
B(-6,8,-1,STONE)
B(-6,8,0,STONE)
B(-6,8,1,STONE)
B(-6,8,2,STONE)
B(-6,8,3,STONE)
B(-6,8,4,STONE)
B(-6,9,-5,STONE)
B(-6,9,-4,STONE)
B(-6,9,-3,STONE)
B(-6,9,-2,STONE)
B(-6,9,-1,STONE)
B(-6,9,0,STONE)
B(-6,9,1,STONE)
B(-6,9,2,STONE)
B(-6,9,3,STONE)
B(-6,9,4,STONE)
B(-6,10,-4,STONE)
B(-6,10,-3,STONE)
B(-6,10,-2,STONE)
B(-6,10,-1,STONE)
B(-6,10,0,STONE)
B(-6,10,1,STONE)
B(-6,10,2,STONE)
B(-6,10,3,STONE)
B(-6,10,4,STONE)
B(-6,11,-3,STONE)
B(-6,11,-2,STONE)
B(-6,11,-1,STONE)
B(-6,11,0,STONE)
B(-6,11,1,STONE)
B(-6,11,2,STONE)
B(-6,11,3,STONE)
B(-6,12,-3,STONE)
B(-6,12,-2,SMOOTH_BRICK)
B(-6,12,2,SMOOTH_BRICK)
B(-6,13,-3,STONE)
B(-6,13,-2,SMOOTH_BRICK)
B(-6,13,2,SMOOTH_BRICK)
B(-6,14,-2,SMOOTH_BRICK)
B(-6,14,-1,SMOOTH_BRICK)
B(-6,14,0,SMOOTH_BRICK)
B(-6,14,1,SMOOTH_BRICK)
B(-6,14,2,SMOOTH_BRICK)
B(-6,15,-2,SMOOTH_BRICK)
B(-6,15,-1,SMOOTH_BRICK)
B(-6,15,0,SMOOTH_BRICK)
B(-6,15,1,SMOOTH_BRICK)
B(-6,15,2,SMOOTH_BRICK)
B(-6,16,-2,SMOOTH_BRICK)
B(-6,16,-1,SMOOTH_BRICK)
B(-6,16,0,SMOOTH_BRICK)
B(-6,16,1,SMOOTH_BRICK)
B(-6,16,2,SMOOTH_BRICK)
B(-6,17,-2,SMOOTH_BRICK)
B(-6,17,-1,SMOOTH_BRICK)
B(-6,17,0,ACACIA_FENCE)
B(-6,17,1,SMOOTH_BRICK)
B(-6,17,2,SMOOTH_BRICK)
B(-6,18,-2,SMOOTH_BRICK)
B(-6,18,-1,SMOOTH_BRICK)
B(-6,18,0,ACACIA_FENCE)
B(-6,18,1,SMOOTH_BRICK)
B(-6,18,2,SMOOTH_BRICK)
B(-6,19,-3,SMOOTH_BRICK)
B(-6,19,-2,SMOOTH_BRICK)
B(-6,19,-1,SMOOTH_BRICK)
B(-6,19,0,SMOOTH_BRICK)
B(-6,19,1,SMOOTH_BRICK)
B(-6,19,2,SMOOTH_BRICK)
B(-6,19,3,SMOOTH_BRICK)
B(-6,20,-5,WOOD_STEP:12)
B(-6,20,-4,SMOOTH_BRICK)
B(-6,20,-3,SMOOTH_BRICK)
B(-6,20,-2,SMOOTH_BRICK)
B(-6,20,-1,SMOOTH_BRICK)
B(-6,20,0,SMOOTH_BRICK)
B(-6,20,1,SMOOTH_BRICK)
B(-6,20,2,SMOOTH_BRICK)
B(-6,20,3,SMOOTH_BRICK)
B(-6,20,4,SMOOTH_BRICK)
B(-6,20,5,WOOD_STEP:12)
B(-6,21,-4,ACACIA_STAIRS:2)
B(-6,21,-3,ACACIA_STAIRS:0)
B(-6,21,-2,WOOD:4)
B(-6,21,-1,WOOD:4)
B(-6,21,0,WOOD:4)
B(-6,21,1,WOOD:4)
B(-6,21,2,WOOD:4)
B(-6,21,3,ACACIA_STAIRS)
B(-6,21,4,ACACIA_STAIRS:0)
B(-6,22,-2,WOOD_STEP:4)
B(-6,22,-1,SMOOTH_BRICK)
B(-6,22,0,SMOOTH_BRICK)
B(-6,22,1,SMOOTH_BRICK)
B(-6,22,2,WOOD_STEP:4)
B(-6,23,-1,SMOOTH_BRICK)
B(-6,23,0,SMOOTH_BRICK)
B(-6,23,1,SMOOTH_BRICK)
B(-6,24,-1,SMOOTH_BRICK)
B(-6,24,0,SMOOTH_BRICK)
B(-6,24,1,SMOOTH_BRICK)
B(-6,25,-1,SMOOTH_BRICK)
B(-6,25,0,SMOOTH_BRICK)
B(-6,25,1,SMOOTH_BRICK)
B(-6,26,-1,SMOOTH_BRICK)
B(-6,26,0,SMOOTH_BRICK)
B(-6,26,1,SMOOTH_BRICK)
B(-6,27,-1,SMOOTH_BRICK)
B(-6,27,0,ACACIA_FENCE)
B(-6,27,1,SMOOTH_BRICK)
B(-6,28,-1,SMOOTH_BRICK)
B(-6,28,0,ACACIA_FENCE)
B(-6,28,1,SMOOTH_BRICK)
B(-6,29,-1,SMOOTH_BRICK)
B(-6,29,0,ACACIA_FENCE)
B(-6,29,1,SMOOTH_BRICK)
B(-6,30,-2,ACACIA_STAIRS:6)
B(-6,30,-1,SMOOTH_BRICK)
B(-6,30,0,ACACIA_FENCE)
B(-6,30,1,SMOOTH_BRICK)
B(-6,30,2,ACACIA_STAIRS:7)
B(-6,31,-2,ACACIA_STAIRS:2)
B(-6,31,-1,SMOOTH_BRICK)
B(-6,31,0,SMOOTH_BRICK)
B(-6,31,1,SMOOTH_BRICK)
B(-6,31,2,ACACIA_STAIRS)
B(-6,32,-1,SMOOTH_BRICK)
B(-6,32,0,SMOOTH_BRICK)
B(-6,32,1,SMOOTH_BRICK)
B(-6,33,-1,SMOOTH_BRICK)
B(-6,33,0,SMOOTH_BRICK)
B(-6,33,1,SMOOTH_BRICK)
B(-6,34,-1,SMOOTH_BRICK)
B(-6,34,0,SMOOTH_BRICK)
B(-6,34,1,SMOOTH_BRICK)
B(-6,35,-2,SMOOTH_BRICK)
B(-6,35,-1,SMOOTH_BRICK)
B(-6,35,0,SMOOTH_BRICK)
B(-6,35,1,SMOOTH_BRICK)
B(-6,35,2,SMOOTH_BRICK)
B(-6,36,-2,SMOOTH_BRICK)
B(-6,36,-1,SMOOTH_BRICK)
B(-6,36,0,SMOOTH_BRICK)
B(-6,36,1,SMOOTH_BRICK)
B(-6,36,2,SMOOTH_BRICK)
B(-6,37,-2,SMOOTH_BRICK)
B(-6,37,-1,SMOOTH_BRICK)
B(-6,37,0,SMOOTH_BRICK)
B(-6,37,1,SMOOTH_BRICK)
B(-6,37,2,SMOOTH_BRICK)
B(-6,38,-2,SMOOTH_BRICK)
RB(-6,38,0,COAL_BLOCK,50,IRON_BLOCK,25,GOLD_BLOCK,5,LAPIS_BLOCK,100)
B(-6,38,2,SMOOTH_BRICK)
B(-6,39,-2,SMOOTH_BRICK)
B(-6,39,2,SMOOTH_BRICK)
B(-6,40,-2,SMOOTH_BRICK)
B(-6,40,2,SMOOTH_BRICK)
B(-6,41,-4,WOOD_STEP:12)
B(-6,41,-3,WOOD_STEP:12)
B(-6,41,-2,SMOOTH_BRICK)
B(-6,41,2,SMOOTH_BRICK)
B(-6,41,3,WOOD_STEP:12)
B(-6,41,4,WOOD_STEP:12)
B(-6,42,-5,ACACIA_STAIRS:6)
B(-6,42,-4,WOOD:4)
B(-6,42,-3,WOOD:4)
B(-6,42,-2,SMOOTH_BRICK)
B(-6,42,-1,WOOD_DOUBLE_STEP:4)
B(-6,42,0,WOOD_DOUBLE_STEP:4)
B(-6,42,1,WOOD_DOUBLE_STEP:4)
B(-6,42,2,SMOOTH_BRICK)
B(-6,42,3,WOOD:4)
B(-6,42,4,WOOD:4)
B(-6,42,5,ACACIA_STAIRS:4)
B(-6,43,-3,ACACIA_STAIRS:0)
B(-6,43,-2,WOOD:4)
B(-6,43,-1,WOOD:4)
B(-6,43,0,TORCH)
B(-6,43,1,WOOD:4)
B(-6,43,2,WOOD:4)
B(-6,43,3,WOOD:4)
B(-6,44,-1,ACACIA_STAIRS:0)
B(-6,44,0,WOOD:4)
B(-6,44,1,ACACIA_STAIRS:0)
B(-6,45,0,WOOD:4)
B(-6,46,0,ACACIA_STAIRS:0)
B(-5,-10,-14,STONE)
B(-5,-10,-13,STONE)
B(-5,-10,-12,STONE)
B(-5,-10,-11,STONE)
B(-5,-10,-10,STONE)
B(-5,-10,-9,STONE)
B(-5,-10,-8,STONE)
B(-5,-10,-7,STONE)
B(-5,-10,-6,STONE)
B(-5,-10,-5,STONE)
B(-5,-10,-4,STONE)
B(-5,-10,-3,STONE)
B(-5,-10,-2,STONE)
B(-5,-10,-1,STONE)
B(-5,-10,0,STONE)
B(-5,-10,1,STONE)
B(-5,-10,2,STONE)
B(-5,-10,3,STONE)
B(-5,-10,4,STONE)
B(-5,-10,5,STONE)
B(-5,-10,6,STONE)
B(-5,-10,7,STONE)
B(-5,-10,8,STONE)
B(-5,-10,9,STONE)
B(-5,-10,10,STONE)
B(-5,-10,11,STONE)
B(-5,-10,12,STONE)
B(-5,-10,13,STONE)
B(-5,-10,14,STONE)
B(-5,-10,15,STONE)
B(-5,-10,16,STONE)
B(-5,-9,-14,STONE)
B(-5,-9,-13,STONE)
B(-5,-9,-12,STONE)
B(-5,-9,-11,STONE)
B(-5,-9,-10,STONE)
B(-5,-9,-9,STONE)
B(-5,-9,-8,STONE)
B(-5,-9,-7,STONE)
B(-5,-9,-6,STONE)
B(-5,-9,-5,STONE)
B(-5,-9,-4,STONE)
B(-5,-9,-3,STONE)
B(-5,-9,-2,STONE)
B(-5,-9,-1,STONE)
B(-5,-9,0,STONE)
B(-5,-9,1,STONE)
B(-5,-9,2,STONE)
B(-5,-9,3,STONE)
B(-5,-9,4,STONE)
B(-5,-9,5,STONE)
B(-5,-9,6,STONE)
B(-5,-9,7,STONE)
B(-5,-9,8,STONE)
B(-5,-9,9,STONE)
B(-5,-9,10,STONE)
B(-5,-9,11,STONE)
B(-5,-9,12,STONE)
B(-5,-9,13,STONE)
B(-5,-9,14,STONE)
B(-5,-8,-12,STONE)
B(-5,-8,-11,STONE)
B(-5,-8,-10,STONE)
B(-5,-8,-9,STONE)
B(-5,-8,-8,STONE)
B(-5,-8,-7,STONE)
B(-5,-8,-6,STONE)
B(-5,-8,-5,STONE)
B(-5,-8,-4,STONE)
B(-5,-8,-3,STONE)
B(-5,-8,-2,STONE)
B(-5,-8,-1,STONE)
B(-5,-8,0,STONE)
B(-5,-8,1,STONE)
B(-5,-8,2,STONE)
B(-5,-8,3,STONE)
B(-5,-8,4,STONE)
B(-5,-8,5,STONE)
B(-5,-8,6,STONE)
B(-5,-8,7,STONE)
B(-5,-8,8,STONE)
B(-5,-8,9,STONE)
B(-5,-8,10,STONE)
B(-5,-8,11,STONE)
B(-5,-8,12,STONE)
B(-5,-8,13,STONE)
B(-5,-8,14,STONE)
B(-5,-7,-12,STONE)
B(-5,-7,-11,STONE)
B(-5,-7,-10,STONE)
B(-5,-7,-9,STONE)
B(-5,-7,-8,STONE)
B(-5,-7,-7,STONE)
B(-5,-7,-6,STONE)
B(-5,-7,-5,STONE)
B(-5,-7,-4,STONE)
B(-5,-7,-3,STONE)
B(-5,-7,-2,STONE)
B(-5,-7,-1,STONE)
B(-5,-7,0,STONE)
B(-5,-7,1,STONE)
B(-5,-7,2,STONE)
B(-5,-7,3,STONE)
B(-5,-7,4,STONE)
B(-5,-7,5,STONE)
B(-5,-7,6,STONE)
B(-5,-7,7,STONE)
B(-5,-7,8,STONE)
B(-5,-7,9,STONE)
B(-5,-7,10,STONE)
B(-5,-7,11,STONE)
B(-5,-7,12,STONE)
B(-5,-7,13,STONE)
B(-5,-6,-12,STONE)
B(-5,-6,-11,STONE)
B(-5,-6,-10,STONE)
B(-5,-6,-9,STONE)
B(-5,-6,-8,STONE)
B(-5,-6,-7,STONE)
B(-5,-6,-6,STONE)
B(-5,-6,-5,STONE)
B(-5,-6,-4,STONE)
B(-5,-6,-3,STONE)
B(-5,-6,-2,STONE)
B(-5,-6,-1,STONE)
B(-5,-6,0,STONE)
B(-5,-6,1,STONE)
B(-5,-6,2,STONE)
B(-5,-6,3,STONE)
B(-5,-6,4,STONE)
B(-5,-6,5,STONE)
B(-5,-6,6,STONE)
B(-5,-6,7,STONE)
B(-5,-6,8,STONE)
B(-5,-6,9,STONE)
B(-5,-6,10,STONE)
B(-5,-6,11,STONE)
B(-5,-6,12,STONE)
B(-5,-6,13,STONE)
B(-5,-5,-11,STONE)
B(-5,-5,-10,STONE)
B(-5,-5,-9,STONE)
B(-5,-5,-8,STONE)
B(-5,-5,-7,STONE)
B(-5,-5,-6,STONE)
B(-5,-5,-5,STONE)
B(-5,-5,-4,STONE)
B(-5,-5,-3,STONE)
B(-5,-5,-2,STONE)
B(-5,-5,-1,STONE)
B(-5,-5,0,STONE)
B(-5,-5,1,STONE)
B(-5,-5,2,STONE)
B(-5,-5,3,STONE)
B(-5,-5,4,STONE)
B(-5,-5,5,STONE)
B(-5,-5,6,STONE)
B(-5,-5,7,STONE)
B(-5,-5,8,STONE)
B(-5,-5,9,STONE)
B(-5,-5,10,STONE)
B(-5,-5,11,STONE)
B(-5,-5,12,STONE)
B(-5,-5,13,STONE)
B(-5,-4,-10,STONE)
B(-5,-4,-9,STONE)
B(-5,-4,-8,STONE)
B(-5,-4,-7,STONE)
B(-5,-4,-6,STONE)
B(-5,-4,-5,STONE)
B(-5,-4,-4,STONE)
B(-5,-4,-3,STONE)
B(-5,-4,-2,STONE)
B(-5,-4,-1,STONE)
B(-5,-4,0,STONE)
B(-5,-4,1,STONE)
B(-5,-4,2,STONE)
B(-5,-4,3,STONE)
B(-5,-4,4,STONE)
B(-5,-4,5,STONE)
B(-5,-4,6,STONE)
B(-5,-4,7,STONE)
B(-5,-4,8,STONE)
B(-5,-4,9,STONE)
B(-5,-4,10,STONE)
B(-5,-4,11,STONE)
B(-5,-3,-10,STONE)
B(-5,-3,-9,STONE)
B(-5,-3,-8,STONE)
B(-5,-3,-7,STONE)
B(-5,-3,-6,STONE)
B(-5,-3,-5,STONE)
B(-5,-3,-4,STONE)
B(-5,-3,-3,STONE)
B(-5,-3,-2,STONE)
B(-5,-3,-1,STONE)
B(-5,-3,0,STONE)
B(-5,-3,1,STONE)
B(-5,-3,2,STONE)
B(-5,-3,3,STONE)
B(-5,-3,4,STONE)
B(-5,-3,5,STONE)
B(-5,-3,6,STONE)
B(-5,-3,7,STONE)
B(-5,-3,8,STONE)
B(-5,-3,9,STONE)
B(-5,-3,10,STONE)
B(-5,-3,11,STONE)
B(-5,-2,-10,STONE)
B(-5,-2,-9,STONE)
B(-5,-2,-8,STONE)
B(-5,-2,-7,STONE)
B(-5,-2,-6,STONE)
B(-5,-2,-5,STONE)
B(-5,-2,-4,STONE)
B(-5,-2,-3,STONE)
B(-5,-2,-2,STONE)
B(-5,-2,-1,STONE)
B(-5,-2,0,STONE)
B(-5,-2,1,STONE)
B(-5,-2,2,STONE)
B(-5,-2,3,STONE)
B(-5,-2,4,STONE)
B(-5,-2,5,STONE)
B(-5,-2,6,STONE)
B(-5,-2,7,STONE)
B(-5,-2,8,STONE)
B(-5,-2,9,STONE)
B(-5,-2,10,STONE)
B(-5,-2,11,STONE)
B(-5,-1,-10,STONE)
B(-5,-1,-9,STONE)
B(-5,-1,-8,STONE)
B(-5,-1,-7,STONE)
B(-5,-1,-6,STONE)
B(-5,-1,-5,STONE)
B(-5,-1,-4,STONE)
B(-5,-1,-3,STONE)
B(-5,-1,-2,STONE)
B(-5,-1,-1,STONE)
B(-5,-1,0,STONE)
B(-5,-1,1,STONE)
B(-5,-1,2,STONE)
B(-5,-1,3,STONE)
B(-5,-1,4,STONE)
B(-5,-1,5,STONE)
B(-5,-1,6,STONE)
B(-5,-1,7,STONE)
B(-5,-1,8,STONE)
B(-5,-1,9,STONE)
B(-5,-1,10,STONE)
B(-5,-1,11,STONE)
B(-5,0,-9,STONE)
B(-5,0,-8,STONE)
B(-5,0,-7,STONE)
B(-5,0,-6,STONE)
B(-5,0,-5,STONE)
B(-5,0,-4,STONE)
B(-5,0,-3,STONE)
B(-5,0,-2,STONE)
B(-5,0,-1,STONE)
B(-5,0,0,STONE)
B(-5,0,1,STONE)
B(-5,0,2,STONE)
B(-5,0,3,STONE)
B(-5,0,4,STONE)
B(-5,0,5,STONE)
B(-5,0,6,STONE)
B(-5,0,7,STONE)
B(-5,0,8,STONE)
B(-5,0,9,STONE)
B(-5,0,10,STONE)
B(-5,1,-9,STONE)
B(-5,1,-8,STONE)
B(-5,1,-7,STONE)
B(-5,1,-6,STONE)
B(-5,1,-5,STONE)
B(-5,1,-4,STONE)
B(-5,1,-3,STONE)
B(-5,1,-2,STONE)
B(-5,1,-1,STONE)
B(-5,1,0,STONE)
B(-5,1,1,STONE)
B(-5,1,2,STONE)
B(-5,1,3,STONE)
B(-5,1,4,STONE)
B(-5,1,5,STONE)
B(-5,1,6,STONE)
B(-5,1,7,STONE)
B(-5,1,8,STONE)
B(-5,1,9,STONE)
B(-5,1,10,STONE)
B(-5,2,-9,STONE)
B(-5,2,-8,STONE)
B(-5,2,-7,STONE)
B(-5,2,-6,STONE)
B(-5,2,-5,STONE)
B(-5,2,-4,STONE)
B(-5,2,-3,STONE)
B(-5,2,-2,STONE)
B(-5,2,-1,STONE)
B(-5,2,0,STONE)
B(-5,2,1,STONE)
B(-5,2,2,STONE)
B(-5,2,3,STONE)
B(-5,2,4,STONE)
B(-5,2,5,STONE)
B(-5,2,6,STONE)
B(-5,2,7,STONE)
B(-5,2,8,STONE)
B(-5,3,-8,STONE)
B(-5,3,-7,STONE)
B(-5,3,-6,STONE)
B(-5,3,-5,STONE)
B(-5,3,-4,STONE)
B(-5,3,-3,STONE)
B(-5,3,-2,STONE)
B(-5,3,-1,STONE)
B(-5,3,0,STONE)
B(-5,3,1,STONE)
B(-5,3,2,STONE)
B(-5,3,3,STONE)
B(-5,3,4,STONE)
B(-5,3,5,STONE)
B(-5,3,6,STONE)
B(-5,3,7,STONE)
B(-5,3,8,STONE)
B(-5,4,-8,STONE)
B(-5,4,-7,STONE)
B(-5,4,-6,STONE)
B(-5,4,-5,STONE)
B(-5,4,-4,STONE)
B(-5,4,-3,STONE)
B(-5,4,-2,STONE)
B(-5,4,-1,STONE)
B(-5,4,0,STONE)
B(-5,4,1,STONE)
B(-5,4,2,STONE)
B(-5,4,3,STONE)
B(-5,4,4,STONE)
B(-5,4,5,STONE)
B(-5,4,6,STONE)
B(-5,5,-7,STONE)
B(-5,5,-6,STONE)
B(-5,5,-5,STONE)
B(-5,5,-4,STONE)
B(-5,5,-3,STONE)
B(-5,5,-2,STONE)
B(-5,5,-1,STONE)
B(-5,5,0,STONE)
B(-5,5,1,STONE)
B(-5,5,2,STONE)
B(-5,5,3,STONE)
B(-5,5,4,STONE)
B(-5,5,5,STONE)
B(-5,5,6,STONE)
B(-5,6,-7,STONE)
B(-5,6,-6,STONE)
B(-5,6,-5,STONE)
B(-5,6,-4,STONE)
B(-5,6,-3,STONE)
B(-5,6,-2,STONE)
B(-5,6,-1,STONE)
B(-5,6,0,STONE)
B(-5,6,1,STONE)
B(-5,6,2,STONE)
B(-5,6,3,STONE)
B(-5,6,4,STONE)
B(-5,6,5,STONE)
B(-5,6,6,STONE)
B(-5,7,-6,STONE)
B(-5,7,-5,STONE)
B(-5,7,-4,STONE)
B(-5,7,-3,STONE)
B(-5,7,-2,STONE)
B(-5,7,-1,STONE)
B(-5,7,0,STONE)
B(-5,7,1,STONE)
B(-5,7,2,STONE)
B(-5,7,3,STONE)
B(-5,7,4,STONE)
B(-5,7,5,STONE)
B(-5,8,-6,STONE)
B(-5,8,-5,STONE)
B(-5,8,-4,STONE)
B(-5,8,-3,STONE)
B(-5,8,-2,STONE)
B(-5,8,-1,STONE)
B(-5,8,0,STONE)
B(-5,8,1,STONE)
B(-5,8,2,STONE)
B(-5,8,3,STONE)
B(-5,8,4,STONE)
B(-5,8,5,STONE)
B(-5,9,-5,STONE)
B(-5,9,-4,STONE)
B(-5,9,-3,STONE)
B(-5,9,-2,STONE)
B(-5,9,-1,STONE)
B(-5,9,0,STONE)
B(-5,9,1,STONE)
B(-5,9,2,STONE)
B(-5,9,3,STONE)
B(-5,9,4,STONE)
B(-5,9,5,STONE)
B(-5,10,-5,STONE)
B(-5,10,-4,STONE)
B(-5,10,-3,STONE)
B(-5,10,-2,STONE)
B(-5,10,-1,STONE)
B(-5,10,0,STONE)
B(-5,10,1,STONE)
B(-5,10,2,STONE)
B(-5,10,3,STONE)
B(-5,10,4,STONE)
B(-5,10,5,STONE)
B(-5,11,-5,STONE)
B(-5,11,-4,STONE)
B(-5,11,-3,STONE)
B(-5,11,-2,STONE)
B(-5,11,-1,STONE)
B(-5,11,0,STONE)
B(-5,11,1,STONE)
B(-5,11,2,STONE)
B(-5,11,3,STONE)
B(-5,11,4,STONE)
B(-5,12,-4,STONE)
B(-5,12,-3,SMOOTH_BRICK)
B(-5,12,-2,SMOOTH_BRICK)
B(-5,12,2,SMOOTH_BRICK)
B(-5,12,3,SMOOTH_BRICK)
B(-5,13,-3,SMOOTH_BRICK)
B(-5,13,-2,SMOOTH_BRICK)
B(-5,13,2,SMOOTH_BRICK)
B(-5,13,3,SMOOTH_BRICK)
B(-5,14,-3,SMOOTH_BRICK)
B(-5,14,-2,SMOOTH_BRICK)
B(-5,14,-1,SMOOTH_BRICK)
B(-5,14,0,SMOOTH_BRICK)
B(-5,14,1,SMOOTH_BRICK)
B(-5,14,2,SMOOTH_BRICK)
B(-5,14,3,SMOOTH_BRICK)
B(-5,15,-3,SMOOTH_BRICK)
B(-5,15,-1,SMOOTH_BRICK)
B(-5,15,1,SMOOTH_BRICK)
B(-5,15,3,SMOOTH_BRICK)
B(-5,16,-3,SMOOTH_BRICK)
B(-5,16,-1,SMOOTH_BRICK)
B(-5,16,1,SMOOTH_BRICK)
B(-5,16,3,SMOOTH_BRICK)
B(-5,17,-3,SMOOTH_BRICK)
B(-5,17,-1,SMOOTH_BRICK)
B(-5,17,1,SMOOTH_BRICK)
B(-5,17,3,SMOOTH_BRICK)
B(-5,18,-3,SMOOTH_BRICK)
B(-5,18,-1,SMOOTH_BRICK)
B(-5,18,1,SMOOTH_BRICK)
B(-5,18,3,SMOOTH_BRICK)
B(-5,19,-4,SMOOTH_BRICK)
B(-5,19,-3,SMOOTH_BRICK)
B(-5,19,-1,SMOOTH_BRICK)
B(-5,19,1,SMOOTH_BRICK)
B(-5,19,3,SMOOTH_BRICK)
B(-5,19,4,SMOOTH_BRICK)
B(-5,20,-7,WOOD_STEP:12)
B(-5,20,-6,WOOD_STEP:12)
B(-5,20,-5,SMOOTH_BRICK)
B(-5,20,-4,SMOOTH_BRICK)
B(-5,20,-3,SMOOTH_BRICK)
B(-5,20,-1,SMOOTH_BRICK)
B(-5,20,1,SMOOTH_BRICK)
B(-5,20,3,SMOOTH_BRICK)
B(-5,20,4,SMOOTH_BRICK)
B(-5,20,5,SMOOTH_BRICK)
B(-5,20,6,WOOD_STEP:12)
B(-5,21,-5,ACACIA_STAIRS:2)
B(-5,21,-4,ACACIA_STAIRS:0)
B(-5,21,-3,WOOD:4)
B(-5,21,-2,SMOOTH_BRICK)
B(-5,21,-1,SMOOTH_BRICK)
B(-5,21,0,SMOOTH_BRICK)
B(-5,21,1,SMOOTH_BRICK)
B(-5,21,2,SMOOTH_BRICK)
B(-5,21,3,WOOD:4)
B(-5,21,4,ACACIA_STAIRS)
B(-5,21,5,ACACIA_STAIRS:0)
B(-5,22,-3,WOOD_STEP:4)
B(-5,22,-2,SMOOTH_BRICK)
B(-5,22,-1,SMOOTH_BRICK)
B(-5,22,0,SMOOTH_BRICK)
B(-5,22,1,SMOOTH_BRICK)
B(-5,22,2,SMOOTH_BRICK)
B(-5,22,3,WOOD_STEP:4)
B(-5,23,-2,SMOOTH_BRICK)
B(-5,23,-1,SMOOTH_BRICK)
B(-5,23,0,SMOOTH_BRICK)
B(-5,23,1,SMOOTH_BRICK)
B(-5,23,2,SMOOTH_BRICK)
B(-5,24,-2,SMOOTH_BRICK)
B(-5,24,-1,SMOOTH_BRICK)
B(-5,24,0,SMOOTH_BRICK)
B(-5,24,1,SMOOTH_BRICK)
B(-5,24,2,SMOOTH_BRICK)
B(-5,25,-2,SMOOTH_BRICK)
B(-5,25,-1,SMOOTH_BRICK)
B(-5,25,0,SMOOTH_BRICK)
B(-5,25,1,SMOOTH_BRICK)
B(-5,25,2,SMOOTH_BRICK)
B(-5,26,-2,SMOOTH_BRICK)
B(-5,26,-1,SMOOTH_BRICK)
B(-5,26,0,SMOOTH_BRICK)
B(-5,26,1,SMOOTH_BRICK)
B(-5,26,2,SMOOTH_BRICK)
B(-5,27,-2,SMOOTH_BRICK)
B(-5,27,-1,SMOOTH_BRICK)
B(-5,27,1,SMOOTH_BRICK)
B(-5,27,2,SMOOTH_BRICK)
B(-5,28,-2,SMOOTH_BRICK)
B(-5,28,-1,SMOOTH_BRICK)
B(-5,28,1,SMOOTH_BRICK)
B(-5,28,2,SMOOTH_BRICK)
B(-5,29,-2,SMOOTH_BRICK)
B(-5,29,-1,SMOOTH_BRICK)
B(-5,29,1,SMOOTH_BRICK)
B(-5,29,2,SMOOTH_BRICK)
B(-5,30,-2,SMOOTH_BRICK)
B(-5,30,-1,SMOOTH_BRICK)
B(-5,30,1,SMOOTH_BRICK)
B(-5,30,2,SMOOTH_BRICK)
B(-5,31,-2,SMOOTH_BRICK)
B(-5,31,-1,SMOOTH_BRICK)
B(-5,31,0,SMOOTH_BRICK)
B(-5,31,1,SMOOTH_BRICK)
B(-5,31,2,SMOOTH_BRICK)
B(-5,32,-2,SMOOTH_BRICK)
B(-5,32,-1,SMOOTH_BRICK)
B(-5,32,0,SMOOTH_BRICK)
B(-5,32,1,SMOOTH_BRICK)
B(-5,32,2,SMOOTH_BRICK)
B(-5,33,-2,SMOOTH_BRICK)
B(-5,33,-1,SMOOTH_BRICK)
B(-5,33,0,SMOOTH_BRICK)
B(-5,33,1,SMOOTH_BRICK)
B(-5,33,2,SMOOTH_BRICK)
B(-5,34,-3,SMOOTH_BRICK)
B(-5,34,-2,SMOOTH_BRICK)
B(-5,34,-1,SMOOTH_BRICK)
B(-5,34,0,SMOOTH_BRICK)
B(-5,34,1,SMOOTH_BRICK)
B(-5,34,2,SMOOTH_BRICK)
B(-5,34,3,SMOOTH_BRICK)
B(-5,35,-3,SMOOTH_BRICK)
B(-5,35,-2,SMOOTH_BRICK)
B(-5,35,-1,SMOOTH_BRICK)
B(-5,35,0,SMOOTH_BRICK)
B(-5,35,1,SMOOTH_BRICK)
B(-5,35,2,SMOOTH_BRICK)
B(-5,35,3,SMOOTH_BRICK)
B(-5,36,-3,SMOOTH_BRICK)
B(-5,36,-2,SMOOTH_BRICK)
B(-5,36,-1,SMOOTH_BRICK)
B(-5,36,0,SMOOTH_BRICK)
B(-5,36,1,SMOOTH_BRICK)
B(-5,36,2,SMOOTH_BRICK)
B(-5,36,3,SMOOTH_BRICK)
B(-5,37,-3,SMOOTH_BRICK)
B(-5,37,3,SMOOTH_BRICK)
B(-5,38,-3,SMOOTH_BRICK)
B(-5,38,3,SMOOTH_BRICK)
B(-5,39,-3,SMOOTH_BRICK)
B(-5,39,3,SMOOTH_BRICK)
B(-5,40,-3,SMOOTH_BRICK)
B(-5,40,-2,WEB)
B(-5,40,3,SMOOTH_BRICK)
B(-5,41,-5,WOOD_STEP:12)
B(-5,41,-4,WOOD_STEP:12)
B(-5,41,-3,SMOOTH_BRICK)
B(-5,41,3,SMOOTH_BRICK)
B(-5,41,4,WOOD_STEP:12)
B(-5,41,5,WOOD_STEP:12)
B(-5,42,-6,ACACIA_STAIRS:6)
B(-5,42,-5,WOOD:4)
B(-5,42,-4,WOOD:4)
B(-5,42,-3,SMOOTH_BRICK)
B(-5,42,-2,WOOD_STEP:12)
B(-5,42,-1,WEB)
B(-5,42,0,WOOD_STEP:12)
B(-5,42,2,WOOD_STEP:12)
B(-5,42,3,SMOOTH_BRICK)
B(-5,42,4,WOOD:4)
B(-5,42,5,WOOD:4)
B(-5,42,6,ACACIA_STAIRS:4)
B(-5,43,-3,WOOD:4)
B(-5,43,-2,WOOD:4)
B(-5,43,2,WOOD:4)
B(-5,43,3,WOOD:4)
B(-5,43,4,ACACIA_STAIRS)
B(-5,44,-2,ACACIA_STAIRS:0)
B(-5,44,-1,WOOD:4)
B(-5,44,1,WOOD:4)
B(-5,44,2,ACACIA_STAIRS:0)
B(-5,45,-1,WOOD:4)
B(-5,45,0,WOOD_STEP:12)
B(-5,45,1,WOOD:4)
B(-5,46,-1,ACACIA_STAIRS:0)
B(-5,46,0,WOOD:4)
B(-5,46,1,ACACIA_STAIRS:0)
B(-4,-10,-15,STONE)
B(-4,-10,-14,STONE)
B(-4,-10,-13,STONE)
B(-4,-10,-12,STONE)
B(-4,-10,-11,STONE)
B(-4,-10,-10,STONE)
B(-4,-10,-9,STONE)
B(-4,-10,-8,STONE)
B(-4,-10,-7,STONE)
B(-4,-10,-6,STONE)
B(-4,-10,-5,STONE)
B(-4,-10,-4,STONE)
B(-4,-10,-3,STONE)
B(-4,-10,-2,STONE)
B(-4,-10,-1,STONE)
B(-4,-10,0,STONE)
B(-4,-10,1,STONE)
B(-4,-10,2,STONE)
B(-4,-10,3,STONE)
B(-4,-10,4,STONE)
B(-4,-10,5,STONE)
B(-4,-10,6,STONE)
B(-4,-10,7,STONE)
B(-4,-10,8,STONE)
B(-4,-10,9,STONE)
B(-4,-10,10,STONE)
B(-4,-10,11,STONE)
B(-4,-10,12,STONE)
B(-4,-10,13,STONE)
B(-4,-10,14,STONE)
B(-4,-10,15,STONE)
B(-4,-9,-14,STONE)
B(-4,-9,-13,STONE)
B(-4,-9,-12,STONE)
B(-4,-9,-11,STONE)
B(-4,-9,-10,STONE)
B(-4,-9,-9,STONE)
B(-4,-9,-8,STONE)
B(-4,-9,-7,STONE)
B(-4,-9,-6,STONE)
B(-4,-9,-5,STONE)
B(-4,-9,-4,STONE)
B(-4,-9,-3,STONE)
B(-4,-9,-2,STONE)
B(-4,-9,-1,STONE)
B(-4,-9,0,STONE)
B(-4,-9,1,STONE)
B(-4,-9,2,STONE)
B(-4,-9,3,STONE)
B(-4,-9,4,STONE)
B(-4,-9,5,STONE)
B(-4,-9,6,STONE)
B(-4,-9,7,STONE)
B(-4,-9,8,STONE)
B(-4,-9,9,STONE)
B(-4,-9,10,STONE)
B(-4,-9,11,STONE)
B(-4,-9,12,STONE)
B(-4,-9,13,STONE)
B(-4,-9,14,STONE)
B(-4,-9,15,STONE)
B(-4,-8,-13,STONE)
B(-4,-8,-12,STONE)
B(-4,-8,-11,STONE)
B(-4,-8,-10,STONE)
B(-4,-8,-9,STONE)
B(-4,-8,-8,STONE)
B(-4,-8,-7,STONE)
B(-4,-8,-6,STONE)
B(-4,-8,-5,STONE)
B(-4,-8,-4,STONE)
B(-4,-8,-3,STONE)
B(-4,-8,-2,STONE)
B(-4,-8,-1,STONE)
B(-4,-8,0,STONE)
B(-4,-8,1,STONE)
B(-4,-8,2,STONE)
B(-4,-8,3,STONE)
B(-4,-8,4,STONE)
B(-4,-8,5,STONE)
B(-4,-8,6,STONE)
B(-4,-8,7,STONE)
B(-4,-8,8,STONE)
B(-4,-8,9,STONE)
B(-4,-8,10,STONE)
B(-4,-8,11,STONE)
B(-4,-8,12,STONE)
B(-4,-8,13,STONE)
B(-4,-8,14,STONE)
B(-4,-7,-12,STONE)
B(-4,-7,-11,STONE)
B(-4,-7,-10,STONE)
B(-4,-7,-9,STONE)
B(-4,-7,-8,STONE)
B(-4,-7,-7,STONE)
B(-4,-7,-6,STONE)
B(-4,-7,-5,STONE)
B(-4,-7,-4,STONE)
B(-4,-7,-3,STONE)
B(-4,-7,-2,STONE)
B(-4,-7,-1,STONE)
B(-4,-7,0,STONE)
B(-4,-7,1,STONE)
B(-4,-7,2,STONE)
B(-4,-7,3,STONE)
B(-4,-7,4,STONE)
B(-4,-7,5,STONE)
B(-4,-7,6,STONE)
B(-4,-7,7,STONE)
B(-4,-7,8,STONE)
B(-4,-7,9,STONE)
B(-4,-7,10,STONE)
B(-4,-7,11,STONE)
B(-4,-7,12,STONE)
B(-4,-7,13,STONE)
B(-4,-7,14,STONE)
B(-4,-6,-11,STONE)
B(-4,-6,-10,STONE)
B(-4,-6,-9,STONE)
B(-4,-6,-8,STONE)
B(-4,-6,-7,STONE)
B(-4,-6,-6,STONE)
B(-4,-6,-5,STONE)
B(-4,-6,-4,STONE)
B(-4,-6,-3,STONE)
B(-4,-6,-2,STONE)
B(-4,-6,-1,STONE)
B(-4,-6,0,STONE)
B(-4,-6,1,STONE)
B(-4,-6,2,STONE)
B(-4,-6,3,STONE)
B(-4,-6,4,STONE)
B(-4,-6,5,STONE)
B(-4,-6,6,STONE)
B(-4,-6,7,STONE)
B(-4,-6,8,STONE)
B(-4,-6,9,STONE)
B(-4,-6,10,STONE)
B(-4,-6,11,STONE)
B(-4,-6,12,STONE)
B(-4,-6,13,STONE)
B(-4,-5,-11,STONE)
B(-4,-5,-10,STONE)
B(-4,-5,-9,STONE)
B(-4,-5,-8,STONE)
B(-4,-5,-7,STONE)
B(-4,-5,-6,STONE)
B(-4,-5,-5,STONE)
B(-4,-5,-4,STONE)
B(-4,-5,-3,STONE)
B(-4,-5,-2,STONE)
B(-4,-5,-1,STONE)
B(-4,-5,0,STONE)
B(-4,-5,1,STONE)
B(-4,-5,2,STONE)
B(-4,-5,3,STONE)
B(-4,-5,4,STONE)
B(-4,-5,5,STONE)
B(-4,-5,6,STONE)
B(-4,-5,7,STONE)
B(-4,-5,8,STONE)
B(-4,-5,9,STONE)
B(-4,-5,10,STONE)
B(-4,-5,11,STONE)
B(-4,-5,12,STONE)
B(-4,-4,-11,STONE)
B(-4,-4,-10,STONE)
B(-4,-4,-9,STONE)
B(-4,-4,-8,STONE)
B(-4,-4,-7,STONE)
B(-4,-4,-6,STONE)
B(-4,-4,-5,STONE)
B(-4,-4,-4,STONE)
B(-4,-4,-3,STONE)
B(-4,-4,-2,STONE)
B(-4,-4,-1,STONE)
B(-4,-4,0,STONE)
B(-4,-4,1,STONE)
B(-4,-4,2,STONE)
B(-4,-4,3,STONE)
B(-4,-4,4,STONE)
B(-4,-4,5,STONE)
B(-4,-4,6,STONE)
B(-4,-4,7,STONE)
B(-4,-4,8,STONE)
B(-4,-4,9,STONE)
B(-4,-4,10,STONE)
B(-4,-4,11,STONE)
B(-4,-3,-11,STONE)
B(-4,-3,-10,STONE)
B(-4,-3,-9,STONE)
B(-4,-3,-8,STONE)
B(-4,-3,-7,STONE)
B(-4,-3,-6,STONE)
B(-4,-3,-5,STONE)
B(-4,-3,-4,STONE)
B(-4,-3,-3,STONE)
B(-4,-3,-2,STONE)
B(-4,-3,-1,STONE)
B(-4,-3,0,STONE)
B(-4,-3,1,STONE)
B(-4,-3,2,STONE)
B(-4,-3,3,STONE)
B(-4,-3,4,STONE)
B(-4,-3,5,STONE)
B(-4,-3,6,STONE)
B(-4,-3,7,STONE)
B(-4,-3,8,STONE)
B(-4,-3,9,STONE)
B(-4,-3,10,STONE)
B(-4,-3,11,STONE)
B(-4,-2,-11,STONE)
B(-4,-2,-10,STONE)
B(-4,-2,-9,STONE)
B(-4,-2,-8,STONE)
B(-4,-2,-7,STONE)
B(-4,-2,-6,STONE)
B(-4,-2,-5,STONE)
B(-4,-2,-4,STONE)
B(-4,-2,-3,STONE)
B(-4,-2,-2,STONE)
B(-4,-2,-1,STONE)
B(-4,-2,0,STONE)
B(-4,-2,1,STONE)
B(-4,-2,2,STONE)
B(-4,-2,3,STONE)
B(-4,-2,4,STONE)
B(-4,-2,5,STONE)
B(-4,-2,6,STONE)
B(-4,-2,7,STONE)
B(-4,-2,8,STONE)
B(-4,-2,9,STONE)
B(-4,-2,10,STONE)
B(-4,-2,11,STONE)
B(-4,-1,-10,STONE)
B(-4,-1,-9,STONE)
B(-4,-1,-8,STONE)
B(-4,-1,-7,STONE)
B(-4,-1,-6,STONE)
B(-4,-1,-5,STONE)
B(-4,-1,-4,STONE)
B(-4,-1,-3,STONE)
B(-4,-1,-2,STONE)
B(-4,-1,-1,STONE)
B(-4,-1,0,STONE)
B(-4,-1,1,STONE)
B(-4,-1,2,STONE)
B(-4,-1,3,STONE)
B(-4,-1,4,STONE)
B(-4,-1,5,STONE)
B(-4,-1,6,STONE)
B(-4,-1,7,STONE)
B(-4,-1,8,STONE)
B(-4,-1,9,STONE)
B(-4,-1,10,STONE)
B(-4,-1,11,STONE)
B(-4,0,-10,STONE)
B(-4,0,-9,STONE)
B(-4,0,-8,STONE)
B(-4,0,-7,STONE)
B(-4,0,-6,STONE)
B(-4,0,-5,STONE)
B(-4,0,-4,STONE)
B(-4,0,-3,STONE)
B(-4,0,-2,STONE)
B(-4,0,-1,STONE)
B(-4,0,0,STONE)
B(-4,0,1,STONE)
B(-4,0,2,STONE)
B(-4,0,3,STONE)
B(-4,0,4,STONE)
B(-4,0,5,STONE)
B(-4,0,6,STONE)
B(-4,0,7,STONE)
B(-4,0,8,STONE)
B(-4,0,9,STONE)
B(-4,0,10,STONE)
B(-4,0,11,STONE)
B(-4,1,-10,STONE)
B(-4,1,-9,STONE)
B(-4,1,-8,STONE)
B(-4,1,-7,STONE)
B(-4,1,-6,STONE)
B(-4,1,-5,STONE)
B(-4,1,-4,STONE)
B(-4,1,-3,STONE)
B(-4,1,-2,STONE)
B(-4,1,-1,STONE)
B(-4,1,0,STONE)
B(-4,1,1,STONE)
B(-4,1,2,STONE)
B(-4,1,3,STONE)
B(-4,1,4,STONE)
B(-4,1,5,STONE)
B(-4,1,6,STONE)
B(-4,1,7,STONE)
B(-4,1,8,STONE)
B(-4,1,9,STONE)
B(-4,1,10,STONE)
B(-4,2,-9,STONE)
B(-4,2,-8,STONE)
B(-4,2,-7,STONE)
B(-4,2,-6,STONE)
B(-4,2,-5,STONE)
B(-4,2,-4,STONE)
B(-4,2,-3,STONE)
B(-4,2,-2,STONE)
B(-4,2,-1,STONE)
B(-4,2,0,STONE)
B(-4,2,1,STONE)
B(-4,2,2,STONE)
B(-4,2,3,STONE)
B(-4,2,4,STONE)
B(-4,2,5,STONE)
B(-4,2,6,STONE)
B(-4,2,7,STONE)
B(-4,2,8,STONE)
B(-4,2,9,STONE)
B(-4,2,10,STONE)
B(-4,3,-8,STONE)
B(-4,3,-7,STONE)
B(-4,3,-6,STONE)
B(-4,3,-5,STONE)
B(-4,3,-4,STONE)
B(-4,3,-3,STONE)
B(-4,3,-2,STONE)
B(-4,3,-1,STONE)
B(-4,3,0,STONE)
B(-4,3,1,STONE)
B(-4,3,2,STONE)
B(-4,3,3,STONE)
B(-4,3,4,STONE)
B(-4,3,5,STONE)
B(-4,3,6,STONE)
B(-4,3,7,STONE)
B(-4,3,8,STONE)
B(-4,3,9,STONE)
B(-4,3,10,STONE)
B(-4,4,-8,STONE)
B(-4,4,-7,STONE)
B(-4,4,-6,STONE)
B(-4,4,-5,STONE)
B(-4,4,-4,STONE)
B(-4,4,-3,STONE)
B(-4,4,-2,STONE)
B(-4,4,-1,STONE)
B(-4,4,0,STONE)
B(-4,4,1,STONE)
B(-4,4,2,STONE)
B(-4,4,3,STONE)
B(-4,4,4,STONE)
B(-4,4,5,STONE)
B(-4,4,6,STONE)
B(-4,4,7,STONE)
B(-4,4,8,STONE)
B(-4,5,-8,STONE)
B(-4,5,-7,STONE)
B(-4,5,-6,STONE)
B(-4,5,-5,STONE)
B(-4,5,-4,STONE)
B(-4,5,-3,STONE)
B(-4,5,-2,STONE)
B(-4,5,-1,STONE)
B(-4,5,0,STONE)
B(-4,5,1,STONE)
B(-4,5,2,STONE)
B(-4,5,3,STONE)
B(-4,5,4,STONE)
B(-4,5,5,STONE)
B(-4,5,6,STONE)
B(-4,5,7,STONE)
B(-4,6,-7,STONE)
B(-4,6,-6,STONE)
B(-4,6,-5,STONE)
B(-4,6,-4,STONE)
B(-4,6,-3,STONE)
B(-4,6,-2,STONE)
B(-4,6,-1,STONE)
B(-4,6,0,STONE)
B(-4,6,1,STONE)
B(-4,6,2,STONE)
B(-4,6,3,STONE)
B(-4,6,4,STONE)
B(-4,6,5,STONE)
B(-4,6,6,STONE)
B(-4,7,-7,STONE)
B(-4,7,-6,STONE)
B(-4,7,-5,STONE)
B(-4,7,-4,STONE)
B(-4,7,-3,STONE)
B(-4,7,-2,STONE)
B(-4,7,-1,STONE)
B(-4,7,0,STONE)
B(-4,7,1,STONE)
B(-4,7,2,STONE)
B(-4,7,3,STONE)
B(-4,7,4,STONE)
B(-4,7,5,STONE)
B(-4,7,6,STONE)
B(-4,8,-7,STONE)
B(-4,8,-6,STONE)
B(-4,8,-5,STONE)
B(-4,8,-4,STONE)
B(-4,8,-3,STONE)
B(-4,8,-2,STONE)
B(-4,8,-1,STONE)
B(-4,8,0,STONE)
B(-4,8,1,STONE)
B(-4,8,2,STONE)
B(-4,8,3,STONE)
B(-4,8,4,STONE)
B(-4,8,5,STONE)
B(-4,9,-6,STONE)
B(-4,9,-5,STONE)
B(-4,9,-4,STONE)
B(-4,9,-3,STONE)
B(-4,9,-2,STONE)
B(-4,9,-1,STONE)
B(-4,9,0,STONE)
B(-4,9,1,STONE)
B(-4,9,2,STONE)
B(-4,9,3,STONE)
B(-4,9,4,STONE)
B(-4,9,5,STONE)
B(-4,10,-6,STONE)
B(-4,10,-5,STONE)
B(-4,10,-4,STONE)
B(-4,10,-3,STONE)
B(-4,10,-2,STONE)
B(-4,10,-1,STONE)
B(-4,10,0,STONE)
B(-4,10,1,STONE)
B(-4,10,2,STONE)
B(-4,10,3,STONE)
B(-4,10,4,STONE)
B(-4,10,5,STONE)
B(-4,11,-6,STONE)
B(-4,11,-5,STONE)
B(-4,11,-4,STONE)
B(-4,11,-3,STONE)
B(-4,11,-2,STONE)
B(-4,11,-1,STONE)
B(-4,11,0,STONE)
B(-4,11,1,STONE)
B(-4,11,2,STONE)
B(-4,11,3,STONE)
B(-4,11,4,STONE)
B(-4,11,5,STONE)
B(-4,12,-5,STONE)
B(-4,12,-4,SMOOTH_BRICK)
B(-4,12,-3,SMOOTH_BRICK)
B(-4,12,-2,SMOOTH_BRICK)
B(-4,12,-1,SMOOTH_BRICK)
B(-4,12,1,SMOOTH_BRICK)
B(-4,12,2,SMOOTH_BRICK)
B(-4,12,3,SMOOTH_BRICK)
B(-4,12,4,SMOOTH_BRICK)
B(-4,13,-5,STONE)
B(-4,13,-4,SMOOTH_BRICK)
B(-4,13,-3,SMOOTH_BRICK)
B(-4,13,-2,SMOOTH_BRICK)
B(-4,13,-1,SMOOTH_BRICK)
B(-4,13,1,SMOOTH_BRICK)
B(-4,13,2,SMOOTH_BRICK)
B(-4,13,3,SMOOTH_BRICK)
B(-4,13,4,SMOOTH_BRICK)
B(-4,14,-4,SMOOTH_BRICK)
B(-4,14,-3,SMOOTH_BRICK)
B(-4,14,-2,SMOOTH_BRICK)
B(-4,14,-1,SMOOTH_BRICK)
B(-4,14,0,SMOOTH_BRICK)
B(-4,14,1,SMOOTH_BRICK)
B(-4,14,2,SMOOTH_BRICK)
B(-4,14,3,SMOOTH_BRICK)
B(-4,14,4,SMOOTH_BRICK)
B(-4,15,-4,SMOOTH_BRICK)
B(-4,15,-1,SMOOTH_BRICK)
B(-4,15,1,SMOOTH_BRICK)
B(-4,15,4,SMOOTH_BRICK)
B(-4,16,-4,SMOOTH_BRICK)
B(-4,16,-1,SMOOTH_BRICK)
B(-4,16,1,SMOOTH_BRICK)
B(-4,16,4,SMOOTH_BRICK)
B(-4,17,-4,SMOOTH_BRICK)
B(-4,17,-1,SMOOTH_BRICK)
B(-4,17,1,SMOOTH_BRICK)
B(-4,17,4,SMOOTH_BRICK)
B(-4,18,-4,SMOOTH_BRICK)
B(-4,18,-1,SMOOTH_BRICK)
B(-4,18,1,SMOOTH_BRICK)
B(-4,18,4,SMOOTH_BRICK)
B(-4,19,-5,SMOOTH_BRICK)
B(-4,19,-4,SMOOTH_BRICK)
B(-4,19,-1,SMOOTH_BRICK)
B(-4,19,1,SMOOTH_BRICK)
B(-4,19,4,SMOOTH_BRICK)
B(-4,19,5,SMOOTH_BRICK)
B(-4,20,-8,WOOD_STEP:12)
B(-4,20,-7,WOOD_STEP:12)
B(-4,20,-6,SMOOTH_BRICK)
B(-4,20,-5,SMOOTH_BRICK)
B(-4,20,-4,SMOOTH_BRICK)
B(-4,20,-1,SMOOTH_BRICK)
B(-4,20,1,SMOOTH_BRICK)
B(-4,20,4,SMOOTH_BRICK)
B(-4,20,5,SMOOTH_BRICK)
B(-4,20,6,SMOOTH_BRICK)
B(-4,20,7,WOOD_STEP:12)
B(-4,21,-8,ACACIA_STAIRS:2)
B(-4,21,-7,ACACIA_STAIRS:0)
B(-4,21,-6,ACACIA_STAIRS:0)
B(-4,21,-5,ACACIA_STAIRS:0)
B(-4,21,-4,WOOD:4)
B(-4,21,-3,SMOOTH_BRICK)
B(-4,21,-2,SMOOTH_BRICK)
B(-4,21,-1,SMOOTH_BRICK)
B(-4,21,0,SMOOTH_BRICK)
B(-4,21,1,SMOOTH_BRICK)
B(-4,21,2,SMOOTH_BRICK)
B(-4,21,3,SMOOTH_BRICK)
B(-4,21,4,WOOD:4)
B(-4,21,5,ACACIA_STAIRS)
B(-4,21,6,ACACIA_STAIRS:0)
B(-4,22,-3,SMOOTH_BRICK)
B(-4,22,3,SMOOTH_BRICK)
B(-4,22,4,WOOD_STEP:4)
B(-4,23,-3,SMOOTH_BRICK)
B(-4,23,3,SMOOTH_BRICK)
B(-4,24,-3,SMOOTH_BRICK)
B(-4,24,3,SMOOTH_BRICK)
B(-4,25,-6,ACACIA_STAIRS:4)
B(-4,25,-5,ACACIA_STAIRS:4)
B(-4,25,-4,ACACIA_STAIRS:4)
B(-4,25,-3,SMOOTH_BRICK)
B(-4,25,3,SMOOTH_BRICK)
B(-4,26,-3,SMOOTH_BRICK)
B(-4,26,3,SMOOTH_BRICK)
B(-4,27,-3,SMOOTH_BRICK)
B(-4,27,3,SMOOTH_BRICK)
B(-4,28,-3,SMOOTH_BRICK)
B(-4,28,-2,WEB)
B(-4,28,3,SMOOTH_BRICK)
B(-4,29,-3,SMOOTH_BRICK)
B(-4,29,3,SMOOTH_BRICK)
B(-4,30,-3,SMOOTH_BRICK)
B(-4,30,3,SMOOTH_BRICK)
B(-4,31,-3,SMOOTH_BRICK)
B(-4,31,2,WEB)
B(-4,31,3,SMOOTH_BRICK)
B(-4,32,-3,SMOOTH_BRICK)
B(-4,32,3,SMOOTH_BRICK)
B(-4,33,-3,SMOOTH_BRICK)
B(-4,33,3,SMOOTH_BRICK)
B(-4,34,-4,SMOOTH_BRICK)
B(-4,34,-3,SMOOTH_BRICK)
B(-4,34,3,SMOOTH_BRICK)
B(-4,34,4,SMOOTH_BRICK)
B(-4,35,-4,SMOOTH_BRICK)
B(-4,35,-3,SMOOTH_BRICK)
B(-4,35,3,SMOOTH_BRICK)
B(-4,35,4,SMOOTH_BRICK)
B(-4,36,-4,SMOOTH_BRICK)
B(-4,36,-3,SMOOTH_BRICK)
B(-4,36,-2,SMOOTH_BRICK)
B(-4,36,-1,SMOOTH_BRICK)
B(-4,36,0,SMOOTH_BRICK)
B(-4,36,1,SMOOTH_BRICK)
B(-4,36,2,SMOOTH_BRICK)
B(-4,36,3,SMOOTH_BRICK)
B(-4,36,4,SMOOTH_BRICK)
B(-4,37,-4,SMOOTH_BRICK)
E(-4,37,0,Witch,1,Witch.txt)
B(-4,37,4,SMOOTH_BRICK)
B(-4,38,-4,SMOOTH_BRICK)
B(-4,38,4,SMOOTH_BRICK)
B(-4,39,-4,SMOOTH_BRICK)
B(-4,39,4,SMOOTH_BRICK)
B(-4,40,-4,SMOOTH_BRICK)
B(-4,40,4,SMOOTH_BRICK)
B(-4,41,-6,WOOD_STEP:12)
B(-4,41,-5,WOOD_STEP:12)
B(-4,41,-4,SMOOTH_BRICK)
B(-4,41,-3,WEB)
B(-4,41,4,SMOOTH_BRICK)
B(-4,41,5,WOOD_STEP:12)
B(-4,41,6,WOOD_STEP:12)
B(-4,42,-7,ACACIA_STAIRS:6)
B(-4,42,-6,WOOD:4)
B(-4,42,-5,WOOD:4)
B(-4,42,-4,SMOOTH_BRICK)
B(-4,42,-3,WOOD_DOUBLE_STEP:4)
B(-4,42,0,WOOD_STEP:12)
B(-4,42,3,WOOD_DOUBLE_STEP:4)
B(-4,42,4,SMOOTH_BRICK)
B(-4,42,5,WOOD:4)
B(-4,42,6,WOOD:4)
B(-4,42,7,ACACIA_STAIRS:4)
B(-4,43,-5,ACACIA_STAIRS:2)
B(-4,43,-4,WOOD:4)
B(-4,43,-3,WOOD:4)
B(-4,43,3,WOOD:4)
B(-4,43,4,WOOD:4)
B(-4,43,5,ACACIA_STAIRS)
B(-4,44,-3,WOOD:4)
B(-4,44,-2,WOOD:4)
B(-4,44,2,WOOD:4)
B(-4,44,3,WOOD:4)
B(-4,45,-2,WOOD:4)
B(-4,45,-1,WOOD_STEP:12)
B(-4,45,0,WEB)
B(-4,45,1,WOOD_STEP:12)
B(-4,45,2,WOOD:4)
B(-4,46,-2,ACACIA_STAIRS:0)
B(-4,46,-1,WOOD:4)
B(-4,46,0,WOOD:4)
B(-4,46,1,WOOD:4)
B(-4,46,2,ACACIA_STAIRS:0)
B(-4,47,0,ACACIA_STAIRS:0)
B(-3,-10,-15,STONE)
B(-3,-10,-14,STONE)
B(-3,-10,-13,STONE)
B(-3,-10,-12,STONE)
B(-3,-10,-11,STONE)
B(-3,-10,-10,STONE)
B(-3,-10,-9,STONE)
B(-3,-10,-8,STONE)
B(-3,-10,-7,STONE)
B(-3,-10,-6,STONE)
B(-3,-10,-5,STONE)
B(-3,-10,-4,STONE)
B(-3,-10,-3,STONE)
B(-3,-10,-2,STONE)
B(-3,-10,-1,STONE)
B(-3,-10,0,STONE)
B(-3,-10,1,STONE)
B(-3,-10,2,STONE)
B(-3,-10,3,STONE)
B(-3,-10,4,STONE)
B(-3,-10,5,STONE)
B(-3,-10,6,STONE)
B(-3,-10,7,STONE)
B(-3,-10,8,STONE)
B(-3,-10,9,STONE)
B(-3,-10,10,STONE)
B(-3,-10,11,STONE)
B(-3,-10,12,STONE)
B(-3,-10,13,STONE)
B(-3,-10,14,STONE)
B(-3,-10,15,STONE)
B(-3,-10,16,STONE)
B(-3,-9,-15,STONE)
B(-3,-9,-14,STONE)
B(-3,-9,-13,STONE)
B(-3,-9,-12,STONE)
B(-3,-9,-11,STONE)
B(-3,-9,-10,STONE)
B(-3,-9,-9,STONE)
B(-3,-9,-8,STONE)
B(-3,-9,-7,STONE)
B(-3,-9,-6,STONE)
B(-3,-9,-5,STONE)
B(-3,-9,-4,STONE)
B(-3,-9,-3,STONE)
B(-3,-9,-2,STONE)
B(-3,-9,-1,STONE)
B(-3,-9,0,STONE)
B(-3,-9,1,STONE)
B(-3,-9,2,STONE)
B(-3,-9,3,STONE)
B(-3,-9,4,STONE)
B(-3,-9,5,STONE)
B(-3,-9,6,STONE)
B(-3,-9,7,STONE)
B(-3,-9,8,STONE)
B(-3,-9,9,STONE)
B(-3,-9,10,STONE)
B(-3,-9,11,STONE)
B(-3,-9,12,STONE)
B(-3,-9,13,STONE)
B(-3,-9,14,STONE)
B(-3,-9,15,STONE)
B(-3,-9,16,STONE)
B(-3,-8,-13,STONE)
B(-3,-8,-12,STONE)
B(-3,-8,-11,STONE)
B(-3,-8,-10,STONE)
B(-3,-8,-9,STONE)
B(-3,-8,-8,STONE)
B(-3,-8,-7,STONE)
B(-3,-8,-6,STONE)
B(-3,-8,-5,STONE)
B(-3,-8,-4,STONE)
B(-3,-8,-3,STONE)
B(-3,-8,-2,STONE)
B(-3,-8,-1,STONE)
B(-3,-8,0,STONE)
B(-3,-8,1,STONE)
B(-3,-8,2,STONE)
B(-3,-8,3,STONE)
B(-3,-8,4,STONE)
B(-3,-8,5,STONE)
B(-3,-8,6,STONE)
B(-3,-8,7,STONE)
B(-3,-8,8,STONE)
B(-3,-8,9,STONE)
B(-3,-8,10,STONE)
B(-3,-8,11,STONE)
B(-3,-8,12,STONE)
B(-3,-8,13,STONE)
B(-3,-8,14,STONE)
B(-3,-8,15,STONE)
B(-3,-7,-12,STONE)
B(-3,-7,-11,STONE)
B(-3,-7,-10,STONE)
B(-3,-7,-9,STONE)
B(-3,-7,-8,STONE)
B(-3,-7,-7,STONE)
B(-3,-7,-6,STONE)
B(-3,-7,-5,STONE)
B(-3,-7,-4,STONE)
B(-3,-7,-3,STONE)
B(-3,-7,-2,STONE)
B(-3,-7,-1,STONE)
B(-3,-7,0,STONE)
B(-3,-7,1,STONE)
B(-3,-7,2,STONE)
B(-3,-7,3,STONE)
B(-3,-7,4,STONE)
B(-3,-7,5,STONE)
B(-3,-7,6,STONE)
B(-3,-7,7,STONE)
B(-3,-7,8,STONE)
B(-3,-7,9,STONE)
B(-3,-7,10,STONE)
B(-3,-7,11,STONE)
B(-3,-7,12,STONE)
B(-3,-7,13,STONE)
B(-3,-7,14,STONE)
B(-3,-6,-12,STONE)
B(-3,-6,-11,STONE)
B(-3,-6,-10,STONE)
B(-3,-6,-9,STONE)
B(-3,-6,-8,STONE)
B(-3,-6,-7,STONE)
B(-3,-6,-6,STONE)
B(-3,-6,-5,STONE)
B(-3,-6,-4,STONE)
B(-3,-6,-3,STONE)
B(-3,-6,-2,STONE)
B(-3,-6,-1,STONE)
B(-3,-6,0,STONE)
B(-3,-6,1,STONE)
B(-3,-6,2,STONE)
B(-3,-6,3,STONE)
B(-3,-6,4,STONE)
B(-3,-6,5,STONE)
B(-3,-6,6,STONE)
B(-3,-6,7,STONE)
B(-3,-6,8,STONE)
B(-3,-6,9,STONE)
B(-3,-6,10,STONE)
B(-3,-6,11,STONE)
B(-3,-6,12,STONE)
B(-3,-6,13,STONE)
B(-3,-6,14,STONE)
B(-3,-5,-12,STONE)
B(-3,-5,-11,STONE)
B(-3,-5,-10,STONE)
B(-3,-5,-9,STONE)
B(-3,-5,-8,STONE)
B(-3,-5,-7,STONE)
B(-3,-5,-6,STONE)
B(-3,-5,-5,STONE)
B(-3,-5,-4,STONE)
B(-3,-5,-3,STONE)
B(-3,-5,-2,STONE)
B(-3,-5,-1,STONE)
B(-3,-5,0,STONE)
B(-3,-5,1,STONE)
B(-3,-5,2,STONE)
B(-3,-5,3,STONE)
B(-3,-5,4,STONE)
B(-3,-5,5,STONE)
B(-3,-5,6,STONE)
B(-3,-5,7,STONE)
B(-3,-5,8,STONE)
B(-3,-5,9,STONE)
B(-3,-5,10,STONE)
B(-3,-5,11,STONE)
B(-3,-5,12,STONE)
B(-3,-5,14,STONE)
B(-3,-4,-12,STONE)
B(-3,-4,-11,STONE)
B(-3,-4,-10,STONE)
B(-3,-4,-9,STONE)
B(-3,-4,-8,STONE)
B(-3,-4,-7,STONE)
B(-3,-4,-6,STONE)
B(-3,-4,-5,STONE)
B(-3,-4,-4,STONE)
B(-3,-4,-3,STONE)
B(-3,-4,-2,STONE)
B(-3,-4,-1,STONE)
B(-3,-4,0,STONE)
B(-3,-4,1,STONE)
B(-3,-4,2,STONE)
B(-3,-4,3,STONE)
B(-3,-4,4,STONE)
B(-3,-4,5,STONE)
B(-3,-4,6,STONE)
B(-3,-4,7,STONE)
B(-3,-4,8,STONE)
B(-3,-4,9,STONE)
B(-3,-4,10,STONE)
B(-3,-4,11,STONE)
B(-3,-3,-11,STONE)
B(-3,-3,-10,STONE)
B(-3,-3,-9,STONE)
B(-3,-3,-8,STONE)
B(-3,-3,-7,STONE)
B(-3,-3,-6,STONE)
B(-3,-3,-5,STONE)
B(-3,-3,-4,STONE)
B(-3,-3,-3,STONE)
B(-3,-3,-2,STONE)
B(-3,-3,-1,STONE)
B(-3,-3,0,STONE)
B(-3,-3,1,STONE)
B(-3,-3,2,STONE)
B(-3,-3,3,STONE)
B(-3,-3,4,STONE)
B(-3,-3,5,STONE)
B(-3,-3,6,STONE)
B(-3,-3,7,STONE)
B(-3,-3,8,STONE)
B(-3,-3,9,STONE)
B(-3,-3,10,STONE)
B(-3,-3,11,STONE)
B(-3,-2,-10,STONE)
B(-3,-2,-9,STONE)
B(-3,-2,-8,STONE)
B(-3,-2,-7,STONE)
B(-3,-2,-6,STONE)
B(-3,-2,-5,STONE)
B(-3,-2,-4,STONE)
B(-3,-2,-3,STONE)
B(-3,-2,-2,STONE)
B(-3,-2,-1,STONE)
B(-3,-2,0,STONE)
B(-3,-2,1,STONE)
B(-3,-2,2,STONE)
B(-3,-2,3,STONE)
B(-3,-2,4,STONE)
B(-3,-2,5,STONE)
B(-3,-2,6,STONE)
B(-3,-2,7,STONE)
B(-3,-2,8,STONE)
B(-3,-2,9,STONE)
B(-3,-2,10,STONE)
B(-3,-2,11,STONE)
B(-3,-1,-10,STONE)
B(-3,-1,-9,STONE)
B(-3,-1,-8,STONE)
B(-3,-1,-7,STONE)
B(-3,-1,-6,STONE)
B(-3,-1,-5,STONE)
B(-3,-1,-4,STONE)
B(-3,-1,-3,STONE)
B(-3,-1,-2,STONE)
B(-3,-1,-1,STONE)
B(-3,-1,0,STONE)
B(-3,-1,1,STONE)
B(-3,-1,2,STONE)
B(-3,-1,3,STONE)
B(-3,-1,4,STONE)
B(-3,-1,5,STONE)
B(-3,-1,6,STONE)
B(-3,-1,7,STONE)
B(-3,-1,8,STONE)
B(-3,-1,9,STONE)
B(-3,-1,10,STONE)
B(-3,0,-10,STONE)
B(-3,0,-9,STONE)
B(-3,0,-8,STONE)
B(-3,0,-7,STONE)
B(-3,0,-6,STONE)
B(-3,0,-5,STONE)
B(-3,0,-4,STONE)
B(-3,0,-3,STONE)
B(-3,0,-2,STONE)
B(-3,0,-1,STONE)
B(-3,0,0,STONE)
B(-3,0,1,STONE)
B(-3,0,2,STONE)
B(-3,0,3,STONE)
B(-3,0,4,STONE)
B(-3,0,5,STONE)
B(-3,0,6,STONE)
B(-3,0,7,STONE)
B(-3,0,8,STONE)
B(-3,0,9,STONE)
B(-3,0,10,STONE)
B(-3,1,-9,STONE)
B(-3,1,-8,STONE)
B(-3,1,-7,STONE)
B(-3,1,-6,STONE)
B(-3,1,-5,STONE)
B(-3,1,-4,STONE)
B(-3,1,-3,STONE)
B(-3,1,-2,STONE)
B(-3,1,-1,STONE)
B(-3,1,0,STONE)
B(-3,1,1,STONE)
B(-3,1,2,STONE)
B(-3,1,3,STONE)
B(-3,1,4,STONE)
B(-3,1,5,STONE)
B(-3,1,6,STONE)
B(-3,1,7,STONE)
B(-3,1,8,STONE)
B(-3,1,9,STONE)
B(-3,1,10,STONE)
B(-3,2,-8,STONE)
B(-3,2,-7,STONE)
B(-3,2,-6,STONE)
B(-3,2,-5,STONE)
B(-3,2,-4,STONE)
B(-3,2,-3,STONE)
B(-3,2,-2,STONE)
B(-3,2,-1,STONE)
B(-3,2,0,STONE)
B(-3,2,1,STONE)
B(-3,2,2,STONE)
B(-3,2,3,STONE)
B(-3,2,4,STONE)
B(-3,2,5,STONE)
B(-3,2,6,STONE)
B(-3,2,7,STONE)
B(-3,2,8,STONE)
B(-3,2,9,STONE)
B(-3,2,10,STONE)
B(-3,3,-8,STONE)
B(-3,3,-7,STONE)
B(-3,3,-6,STONE)
B(-3,3,-5,STONE)
B(-3,3,-4,STONE)
B(-3,3,-3,STONE)
B(-3,3,-2,STONE)
B(-3,3,-1,STONE)
B(-3,3,0,STONE)
B(-3,3,1,STONE)
B(-3,3,2,STONE)
B(-3,3,3,STONE)
B(-3,3,4,STONE)
B(-3,3,5,STONE)
B(-3,3,6,STONE)
B(-3,3,7,STONE)
B(-3,3,8,STONE)
B(-3,3,9,STONE)
B(-3,3,10,STONE)
B(-3,4,-8,STONE)
B(-3,4,-7,STONE)
B(-3,4,-6,STONE)
B(-3,4,-5,STONE)
B(-3,4,-4,STONE)
B(-3,4,-3,STONE)
B(-3,4,-2,STONE)
B(-3,4,-1,STONE)
B(-3,4,0,STONE)
B(-3,4,1,STONE)
B(-3,4,2,STONE)
B(-3,4,3,STONE)
B(-3,4,4,STONE)
B(-3,4,5,STONE)
B(-3,4,6,STONE)
B(-3,4,7,STONE)
B(-3,4,8,STONE)
B(-3,5,-8,STONE)
B(-3,5,-7,STONE)
B(-3,5,-6,STONE)
B(-3,5,-5,STONE)
B(-3,5,-4,STONE)
B(-3,5,-3,STONE)
B(-3,5,-2,STONE)
B(-3,5,-1,STONE)
B(-3,5,0,STONE)
B(-3,5,1,STONE)
B(-3,5,2,STONE)
B(-3,5,3,STONE)
B(-3,5,4,STONE)
B(-3,5,5,STONE)
B(-3,5,6,STONE)
B(-3,5,7,STONE)
B(-3,6,-7,STONE)
B(-3,6,-6,STONE)
B(-3,6,-5,STONE)
B(-3,6,-4,STONE)
B(-3,6,-3,STONE)
B(-3,6,-2,STONE)
B(-3,6,-1,STONE)
B(-3,6,0,STONE)
B(-3,6,1,STONE)
B(-3,6,2,STONE)
B(-3,6,3,STONE)
B(-3,6,4,STONE)
B(-3,6,5,STONE)
B(-3,6,6,STONE)
B(-3,6,7,STONE)
B(-3,7,-7,STONE)
B(-3,7,-6,STONE)
B(-3,7,-5,STONE)
B(-3,7,-4,STONE)
B(-3,7,-3,STONE)
B(-3,7,-2,STONE)
B(-3,7,-1,STONE)
B(-3,7,0,STONE)
B(-3,7,1,STONE)
B(-3,7,2,STONE)
B(-3,7,3,STONE)
B(-3,7,4,STONE)
B(-3,7,5,STONE)
B(-3,7,6,STONE)
B(-3,8,-7,STONE)
B(-3,8,-6,STONE)
B(-3,8,-5,STONE)
B(-3,8,-4,STONE)
B(-3,8,-3,STONE)
B(-3,8,-2,STONE)
B(-3,8,-1,STONE)
B(-3,8,0,STONE)
B(-3,8,1,STONE)
B(-3,8,2,STONE)
B(-3,8,3,STONE)
B(-3,8,4,STONE)
B(-3,8,5,STONE)
B(-3,8,6,STONE)
B(-3,9,-7,STONE)
B(-3,9,-6,STONE)
B(-3,9,-5,STONE)
B(-3,9,-4,STONE)
B(-3,9,-3,STONE)
B(-3,9,-2,STONE)
B(-3,9,-1,STONE)
B(-3,9,0,STONE)
B(-3,9,1,STONE)
B(-3,9,2,STONE)
B(-3,9,3,STONE)
B(-3,9,4,STONE)
B(-3,9,5,STONE)
B(-3,9,6,STONE)
B(-3,10,-6,STONE)
B(-3,10,-5,STONE)
B(-3,10,-4,STONE)
B(-3,10,-3,STONE)
B(-3,10,-2,STONE)
B(-3,10,-1,STONE)
B(-3,10,0,STONE)
B(-3,10,1,STONE)
B(-3,10,2,STONE)
B(-3,10,3,STONE)
B(-3,10,4,STONE)
B(-3,10,5,STONE)
B(-3,11,-6,STONE)
B(-3,11,-5,STONE)
B(-3,11,-4,COBBLESTONE)
B(-3,11,-3,COBBLESTONE)
B(-3,11,-2,STONE)
B(-3,11,-1,COBBLESTONE)
B(-3,11,0,COBBLESTONE)
B(-3,11,1,STONE)
B(-3,11,2,STONE)
B(-3,11,3,MOSSY_COBBLESTONE)
B(-3,11,4,STONE)
B(-3,11,5,STONE)
B(-3,12,-6,STONE)
B(-3,12,-5,SMOOTH_BRICK)
B(-3,12,-1,LADDER:5)
B(-3,12,1,LADDER:5)
B(-3,12,5,SMOOTH_BRICK)
B(-3,13,-5,SMOOTH_BRICK)
B(-3,13,-1,LADDER:5)
B(-3,13,1,LADDER:5)
B(-3,13,5,SMOOTH_BRICK)
B(-3,14,-5,SMOOTH_BRICK)
B(-3,14,-1,LADDER:5)
B(-3,14,1,LADDER:5)
B(-3,14,5,SMOOTH_BRICK)
B(-3,15,-5,SMOOTH_BRICK)
B(-3,15,-4,WOOD_STEP:12)
B(-3,15,-1,LADDER:5)
B(-3,15,1,LADDER:5)
B(-3,15,4,WOOD_STEP:12)
B(-3,15,5,SMOOTH_BRICK)
B(-3,16,-5,SMOOTH_BRICK)
B(-3,16,-1,LADDER:5)
B(-3,16,1,LADDER:5)
B(-3,16,4,BOOKSHELF)
B(-3,16,5,SMOOTH_BRICK)
B(-3,17,-5,SMOOTH_BRICK)
B(-3,17,-4,WOOD_STEP:12)
B(-3,17,-1,LADDER:5)
B(-3,17,1,LADDER:5)
B(-3,17,5,SMOOTH_BRICK)
B(-3,18,-5,SMOOTH_BRICK)
B(-3,18,-4,PUMPKIN:0)
B(-3,18,-1,LADDER:5)
B(-3,18,1,LADDER:5)
B(-3,18,5,SMOOTH_BRICK)
B(-3,19,-6,SMOOTH_BRICK)
B(-3,19,-5,SMOOTH_BRICK)
B(-3,19,-4,WOOD_STEP:12)
B(-3,19,-1,LADDER:5)
B(-3,19,1,LADDER:5)
B(-3,19,5,SMOOTH_BRICK)
B(-3,19,6,SMOOTH_BRICK)
B(-3,20,-9,WOOD_STEP:12)
B(-3,20,-8,SMOOTH_BRICK)
B(-3,20,-7,SMOOTH_BRICK)
B(-3,20,-6,SMOOTH_BRICK)
B(-3,20,-5,SMOOTH_BRICK)
B(-3,20,-1,LADDER:5)
B(-3,20,1,LADDER:5)
B(-3,20,5,SMOOTH_BRICK)
B(-3,20,6,SMOOTH_BRICK)
B(-3,20,7,SMOOTH_BRICK)
B(-3,20,8,WOOD_STEP:12)
B(-3,21,-8,WOOD:4)
B(-3,21,-7,SMOOTH_BRICK)
B(-3,21,-6,SMOOTH_BRICK)
B(-3,21,-5,SMOOTH_BRICK)
B(-3,21,-4,SMOOTH_BRICK)
B(-3,21,-3,SMOOTH_BRICK)
B(-3,21,-2,SMOOTH_BRICK)
B(-3,21,-1,TRAP_DOOR:11)
B(-3,21,0,SMOOTH_BRICK)
B(-3,21,1,TRAP_DOOR:11)
B(-3,21,2,SMOOTH_BRICK)
B(-3,21,3,SMOOTH_BRICK)
B(-3,21,4,SMOOTH_BRICK)
B(-3,21,5,WOOD:4)
B(-3,21,6,ACACIA_STAIRS)
B(-3,21,7,ACACIA_STAIRS:0)
B(-3,22,-8,ACACIA_FENCE)
B(-3,22,-7,WOOD:4)
B(-3,22,-6,SMOOTH_BRICK)
B(-3,22,-5,SMOOTH_BRICK)
B(-3,22,-4,SMOOTH_BRICK)
B(-3,22,4,SMOOTH_BRICK)
B(-3,22,5,WOOD_STEP:4)
B(-3,23,-7,WOOD:4)
B(-3,23,-6,SMOOTH_BRICK)
B(-3,23,-5,SMOOTH_BRICK)
B(-3,23,-4,SMOOTH_BRICK)
B(-3,23,4,SMOOTH_BRICK)
B(-3,24,-7,ACACIA_STAIRS:2)
B(-3,24,-6,SMOOTH_BRICK)
B(-3,24,-5,SMOOTH_BRICK)
B(-3,24,-4,SMOOTH_BRICK)
B(-3,24,4,SMOOTH_BRICK)
B(-3,25,-7,ACACIA_STAIRS:6)
B(-3,25,-6,SMOOTH_BRICK)
B(-3,25,-5,SMOOTH_BRICK)
B(-3,25,-4,SMOOTH_BRICK)
B(-3,25,4,SMOOTH_BRICK)
B(-3,26,-6,ACACIA_STAIRS:0)
B(-3,26,-5,ACACIA_STAIRS:0)
B(-3,26,-4,SMOOTH_BRICK)
B(-3,26,4,SMOOTH_BRICK)
B(-3,26,5,ACACIA_STAIRS:0)
B(-3,26,6,WOOD_STEP:4)
B(-3,27,-4,SMOOTH_BRICK)
B(-3,27,4,SMOOTH_BRICK)
B(-3,28,-4,SMOOTH_BRICK)
B(-3,28,4,SMOOTH_BRICK)
B(-3,29,-4,SMOOTH_BRICK)
B(-3,29,3,WEB)
B(-3,29,4,SMOOTH_BRICK)
B(-3,30,-4,SMOOTH_BRICK)
B(-3,30,4,SMOOTH_BRICK)
B(-3,31,-4,SMOOTH_BRICK)
B(-3,31,4,SMOOTH_BRICK)
B(-3,32,-4,SMOOTH_BRICK)
B(-3,32,4,SMOOTH_BRICK)
B(-3,33,-4,SMOOTH_BRICK)
B(-3,33,4,SMOOTH_BRICK)
B(-3,34,-4,SMOOTH_BRICK)
B(-3,34,4,SMOOTH_BRICK)
B(-3,35,-5,SMOOTH_BRICK)
B(-3,35,-4,SMOOTH_BRICK)
B(-3,35,4,SMOOTH_BRICK)
B(-3,35,5,SMOOTH_BRICK)
B(-3,36,-5,SMOOTH_BRICK)
B(-3,36,-4,SMOOTH_BRICK)
B(-3,36,-3,SMOOTH_BRICK)
B(-3,36,-2,WOOD:4)
B(-3,36,-1,WOOD:4)
B(-3,36,0,WOOD:4)
B(-3,36,1,WOOD:4)
B(-3,36,2,WOOD:4)
B(-3,36,3,SMOOTH_BRICK)
B(-3,36,4,SMOOTH_BRICK)
B(-3,36,5,SMOOTH_BRICK)
B(-3,37,-5,SMOOTH_BRICK)
B(-3,37,5,SMOOTH_BRICK)
B(-3,38,-5,SMOOTH_BRICK)
B(-3,38,5,SMOOTH_BRICK)
B(-3,39,-5,SMOOTH_BRICK)
B(-3,39,5,SMOOTH_BRICK)
B(-3,40,-5,SMOOTH_BRICK)
B(-3,40,5,SMOOTH_BRICK)
B(-3,41,-7,WOOD_STEP:12)
B(-3,41,-6,WOOD_STEP:12)
B(-3,41,-5,SMOOTH_BRICK)
B(-3,41,4,WEB)
B(-3,41,5,SMOOTH_BRICK)
B(-3,41,6,WOOD_STEP:12)
B(-3,42,-8,ACACIA_STAIRS:6)
B(-3,42,-7,WOOD:4)
B(-3,42,-6,WOOD:4)
B(-3,42,-5,SMOOTH_BRICK)
B(-3,42,-4,WOOD_STEP:12)
B(-3,42,0,WOOD_STEP:12)
B(-3,42,4,WOOD_STEP:12)
B(-3,42,5,SMOOTH_BRICK)
B(-3,42,6,WOOD:4)
B(-3,42,7,WOOD:4)
B(-3,42,8,ACACIA_STAIRS:7)
B(-3,43,-6,ACACIA_STAIRS:2)
B(-3,43,-5,WOOD:4)
B(-3,43,-4,WOOD:4)
B(-3,43,4,WOOD:4)
B(-3,43,5,WOOD:4)
B(-3,43,6,ACACIA_STAIRS)
B(-3,44,-4,ACACIA_STAIRS:2)
B(-3,44,-3,WOOD:4)
B(-3,44,3,WOOD:4)
B(-3,44,4,ACACIA_STAIRS)
B(-3,45,-3,WOOD:4)
B(-3,45,-2,WOOD_STEP:12)
B(-3,45,2,WOOD_STEP:12)
B(-3,45,3,WOOD:4)
B(-3,46,-3,ACACIA_STAIRS:2)
B(-3,46,-2,WOOD:4)
B(-3,46,-1,WOOD:4)
B(-3,46,1,WOOD:4)
B(-3,46,2,WOOD:4)
B(-3,46,3,ACACIA_STAIRS)
B(-3,47,-1,ACACIA_STAIRS:0)
B(-3,47,0,WOOD:4)
B(-3,47,1,ACACIA_STAIRS:0)
B(-3,48,0,ACACIA_STAIRS:0)
B(-2,-10,-15,STONE)
B(-2,-10,-14,STONE)
B(-2,-10,-13,STONE)
B(-2,-10,-12,STONE)
B(-2,-10,-11,STONE)
B(-2,-10,-10,STONE)
B(-2,-10,-9,STONE)
B(-2,-10,-8,STONE)
B(-2,-10,-7,STONE)
B(-2,-10,-6,STONE)
B(-2,-10,-5,STONE)
B(-2,-10,-4,STONE)
B(-2,-10,-3,STONE)
B(-2,-10,-2,STONE)
B(-2,-10,-1,STONE)
B(-2,-10,0,STONE)
B(-2,-10,1,STONE)
B(-2,-10,2,STONE)
B(-2,-10,3,STONE)
B(-2,-10,4,STONE)
B(-2,-10,5,STONE)
B(-2,-10,6,STONE)
B(-2,-10,7,STONE)
B(-2,-10,8,STONE)
B(-2,-10,9,STONE)
B(-2,-10,10,STONE)
B(-2,-10,11,STONE)
B(-2,-10,12,STONE)
B(-2,-10,13,STONE)
B(-2,-10,14,STONE)
B(-2,-10,15,STONE)
B(-2,-10,16,STONE)
B(-2,-9,-14,STONE)
B(-2,-9,-13,STONE)
B(-2,-9,-12,STONE)
B(-2,-9,-11,STONE)
B(-2,-9,-10,STONE)
B(-2,-9,-9,STONE)
B(-2,-9,-8,STONE)
B(-2,-9,-7,STONE)
B(-2,-9,-6,STONE)
B(-2,-9,-5,STONE)
B(-2,-9,-4,STONE)
B(-2,-9,-3,STONE)
B(-2,-9,-2,STONE)
B(-2,-9,-1,STONE)
B(-2,-9,0,STONE)
B(-2,-9,1,STONE)
B(-2,-9,2,STONE)
B(-2,-9,3,STONE)
B(-2,-9,4,STONE)
B(-2,-9,5,STONE)
B(-2,-9,6,STONE)
B(-2,-9,7,STONE)
B(-2,-9,8,STONE)
B(-2,-9,9,STONE)
B(-2,-9,10,STONE)
B(-2,-9,11,STONE)
B(-2,-9,12,STONE)
B(-2,-9,13,STONE)
B(-2,-9,14,STONE)
B(-2,-9,15,STONE)
B(-2,-9,16,STONE)
B(-2,-8,-12,STONE)
B(-2,-8,-11,STONE)
B(-2,-8,-10,STONE)
B(-2,-8,-9,STONE)
B(-2,-8,-8,STONE)
B(-2,-8,-7,STONE)
B(-2,-8,-6,STONE)
B(-2,-8,-5,STONE)
B(-2,-8,-4,STONE)
B(-2,-8,-3,STONE)
B(-2,-8,-2,STONE)
B(-2,-8,-1,STONE)
B(-2,-8,0,STONE)
B(-2,-8,1,STONE)
B(-2,-8,2,STONE)
B(-2,-8,3,STONE)
B(-2,-8,4,STONE)
B(-2,-8,5,STONE)
B(-2,-8,6,STONE)
B(-2,-8,7,STONE)
B(-2,-8,8,STONE)
B(-2,-8,9,STONE)
B(-2,-8,10,STONE)
B(-2,-8,11,STONE)
B(-2,-8,12,STONE)
B(-2,-8,13,STONE)
B(-2,-8,14,STONE)
B(-2,-8,15,STONE)
B(-2,-7,-12,STONE)
B(-2,-7,-11,STONE)
B(-2,-7,-10,STONE)
B(-2,-7,-9,STONE)
B(-2,-7,-8,STONE)
B(-2,-7,-7,STONE)
B(-2,-7,-6,STONE)
B(-2,-7,-5,STONE)
B(-2,-7,-4,STONE)
B(-2,-7,-3,STONE)
B(-2,-7,-2,STONE)
B(-2,-7,-1,STONE)
B(-2,-7,0,STONE)
B(-2,-7,1,STONE)
B(-2,-7,2,STONE)
B(-2,-7,3,STONE)
B(-2,-7,4,STONE)
B(-2,-7,5,STONE)
B(-2,-7,6,STONE)
B(-2,-7,7,STONE)
B(-2,-7,8,STONE)
B(-2,-7,9,STONE)
B(-2,-7,10,STONE)
B(-2,-7,11,STONE)
B(-2,-7,12,STONE)
B(-2,-7,13,STONE)
B(-2,-7,14,STONE)
B(-2,-6,-12,STONE)
B(-2,-6,-11,STONE)
B(-2,-6,-10,STONE)
B(-2,-6,-9,STONE)
B(-2,-6,-8,STONE)
B(-2,-6,-7,STONE)
B(-2,-6,-6,STONE)
B(-2,-6,-5,STONE)
B(-2,-6,-4,STONE)
B(-2,-6,-3,STONE)
B(-2,-6,-2,STONE)
B(-2,-6,-1,STONE)
B(-2,-6,0,STONE)
B(-2,-6,1,STONE)
B(-2,-6,2,STONE)
B(-2,-6,3,STONE)
B(-2,-6,4,STONE)
B(-2,-6,5,STONE)
B(-2,-6,6,STONE)
B(-2,-6,7,STONE)
B(-2,-6,8,STONE)
B(-2,-6,9,STONE)
B(-2,-6,10,STONE)
B(-2,-6,11,STONE)
B(-2,-6,12,STONE)
B(-2,-6,13,STONE)
B(-2,-5,-12,STONE)
B(-2,-5,-10,STONE)
B(-2,-5,-9,STONE)
B(-2,-5,-8,STONE)
B(-2,-5,-7,STONE)
B(-2,-5,-6,STONE)
B(-2,-5,-5,STONE)
B(-2,-5,-4,STONE)
B(-2,-5,-3,STONE)
B(-2,-5,-2,STONE)
B(-2,-5,-1,STONE)
B(-2,-5,0,STONE)
B(-2,-5,1,STONE)
B(-2,-5,2,STONE)
B(-2,-5,3,STONE)
B(-2,-5,4,STONE)
B(-2,-5,5,STONE)
B(-2,-5,6,STONE)
B(-2,-5,7,STONE)
B(-2,-5,8,STONE)
B(-2,-5,9,STONE)
B(-2,-5,10,STONE)
B(-2,-5,11,STONE)
B(-2,-5,12,STONE)
B(-2,-4,-10,STONE)
B(-2,-4,-9,STONE)
B(-2,-4,-8,STONE)
B(-2,-4,-7,STONE)
B(-2,-4,-6,STONE)
B(-2,-4,-5,STONE)
B(-2,-4,-4,STONE)
B(-2,-4,-3,STONE)
B(-2,-4,-2,STONE)
B(-2,-4,-1,STONE)
B(-2,-4,0,STONE)
B(-2,-4,1,STONE)
B(-2,-4,2,STONE)
B(-2,-4,3,STONE)
B(-2,-4,4,STONE)
B(-2,-4,5,STONE)
B(-2,-4,6,STONE)
B(-2,-4,7,STONE)
B(-2,-4,8,STONE)
B(-2,-4,9,STONE)
B(-2,-4,10,STONE)
B(-2,-4,11,STONE)
B(-2,-4,12,STONE)
B(-2,-3,-10,STONE)
B(-2,-3,-9,STONE)
B(-2,-3,-8,STONE)
B(-2,-3,-7,STONE)
B(-2,-3,-6,STONE)
B(-2,-3,-5,STONE)
B(-2,-3,-4,STONE)
B(-2,-3,-3,STONE)
B(-2,-3,-2,STONE)
B(-2,-3,-1,STONE)
B(-2,-3,0,STONE)
B(-2,-3,1,STONE)
B(-2,-3,2,STONE)
B(-2,-3,3,STONE)
B(-2,-3,4,STONE)
B(-2,-3,5,STONE)
B(-2,-3,6,STONE)
B(-2,-3,7,STONE)
B(-2,-3,8,STONE)
B(-2,-3,9,STONE)
B(-2,-3,10,STONE)
B(-2,-3,11,STONE)
B(-2,-2,-10,STONE)
B(-2,-2,-9,STONE)
B(-2,-2,-8,STONE)
B(-2,-2,-7,STONE)
B(-2,-2,-6,STONE)
B(-2,-2,-5,STONE)
B(-2,-2,-4,STONE)
B(-2,-2,-3,STONE)
B(-2,-2,-2,STONE)
B(-2,-2,-1,STONE)
B(-2,-2,0,STONE)
B(-2,-2,1,STONE)
B(-2,-2,2,STONE)
B(-2,-2,3,STONE)
B(-2,-2,4,STONE)
B(-2,-2,5,STONE)
B(-2,-2,6,STONE)
B(-2,-2,7,STONE)
B(-2,-2,8,STONE)
B(-2,-2,9,STONE)
B(-2,-2,10,STONE)
B(-2,-2,11,STONE)
B(-2,-1,-10,STONE)
B(-2,-1,-9,STONE)
B(-2,-1,-8,STONE)
B(-2,-1,-7,STONE)
B(-2,-1,-6,STONE)
B(-2,-1,-5,STONE)
B(-2,-1,-4,STONE)
B(-2,-1,-3,STONE)
B(-2,-1,-2,STONE)
B(-2,-1,-1,STONE)
B(-2,-1,0,STONE)
B(-2,-1,1,STONE)
B(-2,-1,2,STONE)
B(-2,-1,3,STONE)
B(-2,-1,4,STONE)
B(-2,-1,5,STONE)
B(-2,-1,6,STONE)
B(-2,-1,7,STONE)
B(-2,-1,8,STONE)
B(-2,-1,9,STONE)
B(-2,-1,10,STONE)
B(-2,-1,11,STONE)
B(-2,0,-10,STONE)
B(-2,0,-9,STONE)
B(-2,0,-8,STONE)
B(-2,0,-7,STONE)
B(-2,0,-6,STONE)
B(-2,0,-5,STONE)
B(-2,0,-4,STONE)
B(-2,0,-3,STONE)
B(-2,0,-2,STONE)
B(-2,0,-1,STONE)
B(-2,0,0,STONE)
B(-2,0,1,STONE)
B(-2,0,2,STONE)
B(-2,0,3,STONE)
B(-2,0,4,STONE)
B(-2,0,5,STONE)
B(-2,0,6,STONE)
B(-2,0,7,STONE)
B(-2,0,8,STONE)
B(-2,0,9,STONE)
B(-2,0,10,STONE)
B(-2,1,-9,STONE)
B(-2,1,-8,STONE)
B(-2,1,-7,STONE)
B(-2,1,-6,STONE)
B(-2,1,-5,STONE)
B(-2,1,-4,STONE)
B(-2,1,-3,STONE)
B(-2,1,-2,STONE)
B(-2,1,-1,STONE)
B(-2,1,0,STONE)
B(-2,1,1,STONE)
B(-2,1,2,STONE)
B(-2,1,3,STONE)
B(-2,1,4,STONE)
B(-2,1,5,STONE)
B(-2,1,6,STONE)
B(-2,1,7,STONE)
B(-2,1,8,STONE)
B(-2,1,9,STONE)
B(-2,1,10,STONE)
B(-2,2,-9,STONE)
B(-2,2,-8,STONE)
B(-2,2,-7,STONE)
B(-2,2,-6,STONE)
B(-2,2,-5,STONE)
B(-2,2,-4,STONE)
B(-2,2,-3,STONE)
B(-2,2,-2,STONE)
B(-2,2,-1,STONE)
B(-2,2,0,STONE)
B(-2,2,1,STONE)
B(-2,2,2,STONE)
B(-2,2,3,STONE)
B(-2,2,4,STONE)
B(-2,2,5,STONE)
B(-2,2,6,STONE)
B(-2,2,7,STONE)
B(-2,2,8,STONE)
B(-2,2,9,STONE)
B(-2,3,-9,STONE)
B(-2,3,-8,STONE)
B(-2,3,-7,STONE)
B(-2,3,-6,STONE)
B(-2,3,-5,STONE)
B(-2,3,-4,STONE)
B(-2,3,-3,STONE)
B(-2,3,-2,STONE)
B(-2,3,-1,STONE)
B(-2,3,0,STONE)
B(-2,3,1,STONE)
B(-2,3,2,STONE)
B(-2,3,3,STONE)
B(-2,3,4,STONE)
B(-2,3,5,STONE)
B(-2,3,6,STONE)
B(-2,3,7,STONE)
B(-2,3,8,STONE)
B(-2,3,9,STONE)
B(-2,4,-9,STONE)
B(-2,4,-8,STONE)
B(-2,4,-7,STONE)
B(-2,4,-6,STONE)
B(-2,4,-5,STONE)
B(-2,4,-4,STONE)
B(-2,4,-3,STONE)
B(-2,4,-2,STONE)
B(-2,4,-1,STONE)
B(-2,4,0,STONE)
B(-2,4,1,STONE)
B(-2,4,2,STONE)
B(-2,4,3,STONE)
B(-2,4,4,STONE)
B(-2,4,5,STONE)
B(-2,4,6,STONE)
B(-2,4,7,STONE)
B(-2,4,8,STONE)
B(-2,4,9,STONE)
B(-2,5,-9,STONE)
B(-2,5,-8,STONE)
B(-2,5,-7,STONE)
B(-2,5,-6,STONE)
B(-2,5,-5,STONE)
B(-2,5,-4,STONE)
B(-2,5,-3,STONE)
B(-2,5,-2,STONE)
B(-2,5,-1,STONE)
B(-2,5,0,STONE)
B(-2,5,1,STONE)
B(-2,5,2,STONE)
B(-2,5,3,STONE)
B(-2,5,4,STONE)
B(-2,5,5,STONE)
B(-2,5,6,STONE)
B(-2,5,7,STONE)
B(-2,5,8,STONE)
B(-2,6,-8,STONE)
B(-2,6,-7,STONE)
B(-2,6,-6,STONE)
B(-2,6,-5,STONE)
B(-2,6,-4,STONE)
B(-2,6,-3,STONE)
B(-2,6,-2,STONE)
B(-2,6,-1,STONE)
B(-2,6,0,STONE)
B(-2,6,1,STONE)
B(-2,6,2,STONE)
B(-2,6,3,STONE)
B(-2,6,4,STONE)
B(-2,6,5,STONE)
B(-2,6,6,STONE)
B(-2,6,7,STONE)
B(-2,7,-8,STONE)
B(-2,7,-7,STONE)
B(-2,7,-6,STONE)
B(-2,7,-5,STONE)
B(-2,7,-4,STONE)
B(-2,7,-3,STONE)
B(-2,7,-2,STONE)
B(-2,7,-1,STONE)
B(-2,7,0,STONE)
B(-2,7,1,STONE)
B(-2,7,2,STONE)
B(-2,7,3,STONE)
B(-2,7,4,STONE)
B(-2,7,5,STONE)
B(-2,7,6,STONE)
B(-2,7,7,STONE)
B(-2,8,-7,STONE)
B(-2,8,-6,STONE)
B(-2,8,-5,STONE)
B(-2,8,-4,STONE)
B(-2,8,-3,STONE)
B(-2,8,-2,STONE)
B(-2,8,-1,STONE)
B(-2,8,0,STONE)
B(-2,8,1,STONE)
B(-2,8,2,STONE)
B(-2,8,3,STONE)
B(-2,8,4,STONE)
B(-2,8,5,STONE)
B(-2,8,6,STONE)
B(-2,9,-7,STONE)
B(-2,9,-6,STONE)
B(-2,9,-5,STONE)
B(-2,9,-4,STONE)
B(-2,9,-3,STONE)
B(-2,9,-2,STONE)
B(-2,9,-1,STONE)
B(-2,9,0,STONE)
B(-2,9,1,STONE)
B(-2,9,2,STONE)
B(-2,9,3,STONE)
B(-2,9,4,STONE)
B(-2,9,5,STONE)
B(-2,9,6,STONE)
B(-2,10,-7,STONE)
B(-2,10,-6,STONE)
B(-2,10,-5,STONE)
B(-2,10,-4,STONE)
B(-2,10,-3,STONE)
B(-2,10,-2,STONE)
B(-2,10,-1,STONE)
B(-2,10,0,STONE)
B(-2,10,1,STONE)
B(-2,10,2,STONE)
B(-2,10,3,STONE)
B(-2,10,4,STONE)
B(-2,10,5,STONE)
B(-2,10,6,STONE)
B(-2,11,-7,STONE)
B(-2,11,-6,STONE)
B(-2,11,-5,STONE)
B(-2,11,-4,COBBLESTONE)
B(-2,11,-3,STONE)
B(-2,11,-2,STONE)
B(-2,11,-1,COBBLESTONE)
B(-2,11,0,MOSSY_COBBLESTONE)
B(-2,11,1,STONE)
B(-2,11,2,COBBLESTONE)
B(-2,11,3,STONE)
B(-2,11,4,STONE)
B(-2,11,5,STONE)
B(-2,12,-7,STONE)
B(-2,12,-6,SMOOTH_BRICK)
B(-2,12,-5,SMOOTH_BRICK)
B(-2,12,5,SMOOTH_BRICK)
B(-2,13,-6,SMOOTH_BRICK)
B(-2,13,-5,SMOOTH_BRICK)
B(-2,13,5,SMOOTH_BRICK)
B(-2,14,-6,SMOOTH_BRICK)
B(-2,14,-5,SMOOTH_BRICK)
B(-2,14,5,SMOOTH_BRICK)
B(-2,15,-6,SMOOTH_BRICK)
B(-2,15,-5,SMOOTH_BRICK)
B(-2,15,-4,WOOD_STEP:12)
B(-2,15,-3,WALL_BANNER:3)
B(-2,15,3,WALL_BANNER)
B(-2,15,4,WOOD_STEP:12)
B(-2,15,5,SMOOTH_BRICK)
B(-2,16,-7,SMOOTH_BRICK)
B(-2,16,-6,SMOOTH_BRICK)
B(-2,16,-5,SMOOTH_BRICK)
RB(-2,16,-4,CHEST,../../nbt/VanillaLoot/simple_dungeon.nbt,50,CHEST,../../nbt/VanillaLoot/abandoned_mineshaft.nbt,30,CHEST,../../nbt/VanillaLoot/stronghold_corridor.nbt,100)
B(-2,16,4,BOOKSHELF)
B(-2,16,5,SMOOTH_BRICK)
B(-2,17,-7,SMOOTH_BRICK)
B(-2,17,-6,SMOOTH_BRICK)
B(-2,17,-5,SMOOTH_BRICK)
B(-2,17,-4,WOOD_STEP:12)
B(-2,17,5,SMOOTH_BRICK)
B(-2,18,-8,SMOOTH_BRICK)
B(-2,18,-7,SMOOTH_BRICK)
B(-2,18,-6,SMOOTH_BRICK)
B(-2,18,-5,SMOOTH_BRICK)
B(-2,18,-4,FLOWER_POT)
B(-2,18,5,SMOOTH_BRICK)
B(-2,19,-8,SMOOTH_BRICK)
B(-2,19,-7,SMOOTH_BRICK)
B(-2,19,-6,SMOOTH_BRICK)
B(-2,19,-5,SMOOTH_BRICK)
B(-2,19,-4,WOOD_STEP:12)
B(-2,19,5,SMOOTH_BRICK)
B(-2,19,6,SMOOTH_BRICK)
B(-2,20,-9,WOOD_STEP:12)
B(-2,20,-8,SMOOTH_BRICK)
B(-2,20,-7,SMOOTH_BRICK)
B(-2,20,-6,SMOOTH_BRICK)
B(-2,20,-5,SMOOTH_BRICK)
B(-2,20,5,SMOOTH_BRICK)
B(-2,20,6,SMOOTH_BRICK)
B(-2,20,7,SMOOTH_BRICK)
B(-2,20,8,WOOD_STEP:12)
B(-2,21,-9,ACACIA_STAIRS:0)
B(-2,21,-8,WOOD:4)
B(-2,21,-7,SMOOTH_BRICK)
B(-2,21,-6,SMOOTH_BRICK)
B(-2,21,-5,SMOOTH_BRICK)
B(-2,21,-4,SMOOTH_BRICK)
B(-2,21,-3,SMOOTH_BRICK)
B(-2,21,-2,SMOOTH_BRICK)
B(-2,21,-1,SMOOTH_BRICK)
B(-2,21,0,SMOOTH_BRICK)
B(-2,21,1,SMOOTH_BRICK)
B(-2,21,2,SMOOTH_BRICK)
B(-2,21,3,SMOOTH_BRICK)
B(-2,21,4,SMOOTH_BRICK)
B(-2,21,5,WOOD:4)
B(-2,21,6,WOOD:4)
B(-2,21,7,ACACIA_STAIRS)
B(-2,22,-8,ACACIA_FENCE)
B(-2,22,0,ACACIA_FENCE)
B(-2,22,1,ACACIA_FENCE)
B(-2,22,4,SMOOTH_BRICK)
B(-2,22,5,SMOOTH_BRICK)
B(-2,22,6,WOOD_STEP:4)
B(-2,23,1,ACACIA_FENCE)
B(-2,23,4,SMOOTH_BRICK)
B(-2,23,5,SMOOTH_BRICK)
B(-2,24,0,ACACIA_STAIRS:6)
B(-2,24,1,WOOD:4)
B(-2,24,4,SMOOTH_BRICK)
B(-2,24,5,SMOOTH_BRICK)
B(-2,25,-6,WOOD_STEP:12)
B(-2,25,-1,ACACIA_STAIRS:6)
B(-2,25,0,ACACIA_STAIRS)
B(-2,25,4,SMOOTH_BRICK)
B(-2,25,5,SMOOTH_BRICK)
B(-2,26,-7,ACACIA_STAIRS:6)
B(-2,26,-6,SMOOTH_BRICK)
B(-2,26,-5,SMOOTH_BRICK)
B(-2,26,-4,SMOOTH_BRICK)
B(-2,26,4,SMOOTH_BRICK)
B(-2,26,5,SMOOTH_BRICK)
B(-2,26,6,ACACIA_STAIRS)
B(-2,27,-6,ACACIA_STAIRS:0)
B(-2,27,-5,ACACIA_STAIRS:2)
B(-2,27,-4,SMOOTH_BRICK)
B(-2,27,4,SMOOTH_BRICK)
B(-2,27,5,ACACIA_STAIRS)
B(-2,28,-4,SMOOTH_BRICK)
B(-2,28,0,WOOD:4)
B(-2,28,1,WOOD:4)
B(-2,28,4,SMOOTH_BRICK)
B(-2,29,-4,SMOOTH_BRICK)
B(-2,29,-1,ACACIA_STAIRS:6)
B(-2,29,0,ACACIA_STAIRS)
B(-2,29,4,SMOOTH_BRICK)
B(-2,30,-4,SMOOTH_BRICK)
B(-2,30,4,SMOOTH_BRICK)
B(-2,31,-4,SMOOTH_BRICK)
B(-2,31,4,SMOOTH_BRICK)
B(-2,32,-4,SMOOTH_BRICK)
B(-2,32,0,ACACIA_STAIRS:6)
B(-2,32,1,ACACIA_STAIRS:4)
B(-2,32,4,SMOOTH_BRICK)
B(-2,33,-5,ACACIA_STAIRS:6)
B(-2,33,-4,SMOOTH_BRICK)
B(-2,33,-1,ACACIA_STAIRS:4)
B(-2,33,0,ACACIA_STAIRS)
B(-2,33,4,SMOOTH_BRICK)
B(-2,33,5,ACACIA_STAIRS:7)
B(-2,34,-5,SMOOTH_BRICK)
B(-2,34,-4,SMOOTH_BRICK)
B(-2,34,4,SMOOTH_BRICK)
B(-2,34,5,SMOOTH_BRICK)
B(-2,35,-5,SMOOTH_BRICK)
B(-2,35,-4,SMOOTH_BRICK)
B(-2,35,4,SMOOTH_BRICK)
B(-2,35,5,SMOOTH_BRICK)
B(-2,36,-6,ACACIA_STAIRS:6)
B(-2,36,-5,SMOOTH_BRICK)
B(-2,36,-4,SMOOTH_BRICK)
B(-2,36,-3,SMOOTH_BRICK)
B(-2,36,-2,WOOD:4)
B(-2,36,1,WEB)
B(-2,36,2,WOOD:4)
B(-2,36,3,SMOOTH_BRICK)
B(-2,36,4,SMOOTH_BRICK)
B(-2,36,5,SMOOTH_BRICK)
B(-2,36,6,ACACIA_STAIRS:7)
B(-2,37,-6,SMOOTH_BRICK)
B(-2,37,-5,SMOOTH_BRICK)
E(-2,37,3,Witch,1,Witch.txt)
B(-2,37,5,SMOOTH_BRICK)
B(-2,37,6,SMOOTH_BRICK)
B(-2,38,-6,SMOOTH_BRICK)
B(-2,38,6,SMOOTH_BRICK)
B(-2,39,-6,SMOOTH_BRICK)
B(-2,39,6,SMOOTH_BRICK)
B(-2,40,-6,SMOOTH_BRICK)
B(-2,40,6,SMOOTH_BRICK)
B(-2,41,-7,WOOD_STEP:12)
B(-2,41,-6,SMOOTH_BRICK)
B(-2,41,6,SMOOTH_BRICK)
B(-2,41,7,WOOD_STEP:12)
B(-2,42,-8,ACACIA_STAIRS:6)
B(-2,42,-7,WOOD:4)
B(-2,42,-6,SMOOTH_BRICK)
B(-2,42,-5,WOOD_DOUBLE_STEP:4)
B(-2,42,-4,WEB)
B(-2,42,0,WOOD_STEP:12)
B(-2,42,1,WEB)
B(-2,42,5,WOOD_DOUBLE_STEP:4)
B(-2,42,6,SMOOTH_BRICK)
B(-2,42,7,WOOD:4)
B(-2,42,8,ACACIA_STAIRS:7)
B(-2,43,-7,ACACIA_STAIRS:2)
B(-2,43,-6,WOOD:4)
B(-2,43,-5,WOOD:4)
B(-2,43,5,WOOD:4)
B(-2,43,6,WOOD:4)
B(-2,43,7,ACACIA_STAIRS)
B(-2,44,-5,ACACIA_STAIRS:2)
B(-2,44,-4,WOOD:4)
B(-2,44,4,WOOD:4)
B(-2,44,5,ACACIA_STAIRS)
B(-2,45,-4,WOOD:4)
B(-2,45,-3,WOOD_STEP:12)
B(-2,45,3,WOOD_STEP:12)
B(-2,45,4,WOOD:4)
B(-2,46,-4,ACACIA_STAIRS:2)
B(-2,46,-3,WOOD:4)
B(-2,46,-2,WOOD:4)
B(-2,46,2,WOOD:4)
B(-2,46,3,WOOD:4)
B(-2,46,4,ACACIA_STAIRS)
B(-2,47,-2,ACACIA_STAIRS:2)
B(-2,47,-1,WOOD:4)
B(-2,47,0,WOOD:4)
B(-2,47,1,WOOD:4)
B(-2,47,2,ACACIA_STAIRS)
B(-2,48,-1,WOOD:4)
B(-2,48,0,WOOD:4)
B(-2,48,1,WOOD:4)
B(-2,49,0,ACACIA_STAIRS:0)
B(-1,-10,-15,STONE)
B(-1,-10,-14,STONE)
B(-1,-10,-13,STONE)
B(-1,-10,-12,STONE)
B(-1,-10,-11,STONE)
B(-1,-10,-10,STONE)
B(-1,-10,-9,STONE)
B(-1,-10,-8,STONE)
B(-1,-10,-7,STONE)
B(-1,-10,-6,STONE)
B(-1,-10,-5,STONE)
B(-1,-10,-4,STONE)
B(-1,-10,-3,STONE)
B(-1,-10,-2,STONE)
B(-1,-10,-1,STONE)
B(-1,-10,0,STONE)
B(-1,-10,1,STONE)
B(-1,-10,2,STONE)
B(-1,-10,3,STONE)
B(-1,-10,4,STONE)
B(-1,-10,5,STONE)
B(-1,-10,6,STONE)
B(-1,-10,7,STONE)
B(-1,-10,8,STONE)
B(-1,-10,9,STONE)
B(-1,-10,10,STONE)
B(-1,-10,11,STONE)
B(-1,-10,12,STONE)
B(-1,-10,13,STONE)
B(-1,-10,14,STONE)
B(-1,-10,15,STONE)
B(-1,-10,16,STONE)
B(-1,-9,-15,STONE)
B(-1,-9,-14,STONE)
B(-1,-9,-13,STONE)
B(-1,-9,-12,STONE)
B(-1,-9,-11,STONE)
B(-1,-9,-10,STONE)
B(-1,-9,-9,STONE)
B(-1,-9,-8,STONE)
B(-1,-9,-7,STONE)
B(-1,-9,-6,STONE)
B(-1,-9,-5,STONE)
B(-1,-9,-4,STONE)
B(-1,-9,-3,STONE)
B(-1,-9,-2,STONE)
B(-1,-9,-1,STONE)
B(-1,-9,0,STONE)
B(-1,-9,1,STONE)
B(-1,-9,2,STONE)
B(-1,-9,3,STONE)
B(-1,-9,4,STONE)
B(-1,-9,5,STONE)
B(-1,-9,6,STONE)
B(-1,-9,7,STONE)
B(-1,-9,8,STONE)
B(-1,-9,9,STONE)
B(-1,-9,10,STONE)
B(-1,-9,11,STONE)
B(-1,-9,12,STONE)
B(-1,-9,13,STONE)
B(-1,-9,14,STONE)
B(-1,-9,15,STONE)
B(-1,-8,-13,STONE)
B(-1,-8,-12,STONE)
B(-1,-8,-11,STONE)
B(-1,-8,-10,STONE)
B(-1,-8,-9,STONE)
B(-1,-8,-8,STONE)
B(-1,-8,-7,STONE)
B(-1,-8,-6,STONE)
B(-1,-8,-5,STONE)
B(-1,-8,-4,STONE)
B(-1,-8,-3,STONE)
B(-1,-8,-2,STONE)
B(-1,-8,-1,STONE)
B(-1,-8,0,STONE)
B(-1,-8,1,STONE)
B(-1,-8,2,STONE)
B(-1,-8,3,STONE)
B(-1,-8,4,STONE)
B(-1,-8,5,STONE)
B(-1,-8,6,STONE)
B(-1,-8,7,STONE)
B(-1,-8,8,STONE)
B(-1,-8,9,STONE)
B(-1,-8,10,STONE)
B(-1,-8,11,STONE)
B(-1,-8,12,STONE)
B(-1,-8,13,STONE)
B(-1,-8,14,STONE)
B(-1,-8,15,STONE)
B(-1,-7,-12,STONE)
B(-1,-7,-11,STONE)
B(-1,-7,-10,STONE)
B(-1,-7,-9,STONE)
B(-1,-7,-8,STONE)
B(-1,-7,-7,STONE)
B(-1,-7,-6,STONE)
B(-1,-7,-5,STONE)
B(-1,-7,-4,STONE)
B(-1,-7,-3,STONE)
B(-1,-7,-2,STONE)
B(-1,-7,-1,STONE)
B(-1,-7,0,STONE)
B(-1,-7,1,STONE)
B(-1,-7,2,STONE)
B(-1,-7,3,STONE)
B(-1,-7,4,STONE)
B(-1,-7,5,STONE)
B(-1,-7,6,STONE)
B(-1,-7,7,STONE)
B(-1,-7,8,STONE)
B(-1,-7,9,STONE)
B(-1,-7,10,STONE)
B(-1,-7,11,STONE)
B(-1,-7,12,STONE)
B(-1,-7,13,STONE)
B(-1,-7,14,STONE)
B(-1,-6,-12,STONE)
B(-1,-6,-11,STONE)
B(-1,-6,-10,STONE)
B(-1,-6,-9,STONE)
B(-1,-6,-8,STONE)
B(-1,-6,-7,STONE)
B(-1,-6,-6,STONE)
B(-1,-6,-5,STONE)
B(-1,-6,-4,STONE)
B(-1,-6,-3,STONE)
B(-1,-6,-2,STONE)
B(-1,-6,-1,STONE)
B(-1,-6,0,STONE)
B(-1,-6,1,STONE)
B(-1,-6,2,STONE)
B(-1,-6,3,STONE)
B(-1,-6,4,STONE)
B(-1,-6,5,STONE)
B(-1,-6,6,STONE)
