
#######################################################################
# +-----------------------------------------------------------------+ #
# |                            BO3 object                           | #
# +-----------------------------------------------------------------+ #
#######################################################################

# This is the config file of a custom object.
# If you add this object correctly to your BiomeConfigs, it will spawn in the world.

# This is the creator of this BO3 object
Author: Piginabag

# A short description of this BO3 object
Description: No description given

# The BO3 version, don't change this! It can be used by external applications to do a version check.
Version: 3

# The settings mode, WriteAll, WriteWithoutComments or WriteDisable. See WorldConfig.
SettingsMode: WriteDisable


#######################################################################
# +-----------------------------------------------------------------+ #
# |                          Main settings                          | #
# +-----------------------------------------------------------------+ #
#######################################################################

# This needs to be set to true to spawn the object in the Tree and Sapling resources.
Tree: false

# The frequency of the BO3 from 1 to 200. Tries this many times to spawn this BO3 when using the CustomObject(...) resource.
# Ignored by Tree(..), Sapling(..) and CustomStructure(..)
Frequency: 1

# The rarity of the BO3 from 0 to 100. Each spawn attempt has rarity% chance to succeed when using the CustomObject(...) resource.
# Ignored by Tree(..), Sapling(..) and CustomStructure(..)
Rarity: 100.0

# If you set this to true, the BO3 will be placed with a random rotation.
RotateRandomly: false

# The spawn height of the BO3 - randomY, highestBlock or highestSolidBlock.
SpawnHeight: highestSolidBlock

# The height limits for the BO3.
MinHeight: 0

MaxHeight: 256

# Objects can have other objects attacthed to it: branches. Branches can also
# have branches attached to it, which can also have branches, etc. This is the
# maximum branch depth for this objects.
MaxBranchDepth: 10

# When spawned with the UseWorld keyword, this BO3 should NOT spawn in the following biomes.
# If you writer.write the BO3 name directly in the BiomeConfigs, this will be ignored.
ExcludedBiomes: All


#######################################################################
# +-----------------------------------------------------------------+ #
# |                      Source block settings                      | #
# +-----------------------------------------------------------------+ #
#######################################################################

# The B(s) the BO3 should spawn in.
SourceBlocks: AIR

# The maximum percentage of the BO3 that can be outside the SourceBlock.
# The BO3 won't be placed on a location with more blocks outside the SourceBlock than this percentage.
MaxPercentageOutsideSourceBlock: 100

# What to do when a block is about to be placed outside the SourceBlock? (dontPlace, placeAnyway)
OutsideSourceBlock: placeAnyway


#######################################################################
# +-----------------------------------------------------------------+ #
# |                              Blocks                             | #
# +-----------------------------------------------------------------+ #
#######################################################################

# All the blocks used in the BO3 are listed here. Possible blocks:
# B(x,y,z,id[.data][,nbtfile.nbt)
# RB(x,y,z,id[:data][,nbtfile.nbt],chance[,id[:data][,nbtfile.nbt],chance[,...]])
# So RB(0,0,0,CHEST,chest.nbt,50,CHEST,anotherchest.nbt,100) will spawn a chest at
# the BO3 origin, and give it a 50% chance to have the contents of chest.nbt, or, if that
# fails, a 100% percent chance to have the contents of anotherchest.nbt.
B(-12,-6,-9,STONE)
B(-12,-6,-8,STONE)
B(-12,-5,-11,STONE)
B(-12,-5,-10,STONE)
B(-12,-5,-9,STONE)
B(-12,-5,-8,STONE)
B(-12,-4,-12,STONE)
B(-12,-4,-11,STONE)
B(-12,-4,-10,STONE)
B(-12,-4,-9,STONE)
B(-12,-4,-8,STONE)
B(-12,-3,-11,STONE)
B(-12,-3,-10,STONE)
B(-12,-2,-11,STONE)
B(-11,-8,-8,STONE)
B(-11,-8,-7,STONE)
B(-11,-7,-9,STONE)
B(-11,-7,-8,STONE)
B(-11,-7,-7,STONE)
B(-11,-7,-6,STONE)
B(-11,-6,-10,STONE)
B(-11,-6,-9,STONE)
B(-11,-6,-8,STONE)
B(-11,-6,-7,STONE)
B(-11,-6,-6,STONE)
B(-11,-5,-12,STONE)
B(-11,-5,-11,STONE)
B(-11,-5,-10,STONE)
B(-11,-5,-9,STONE)
B(-11,-5,-8,STONE)
B(-11,-5,-7,STONE)
B(-11,-5,-6,STONE)
B(-11,-4,-13,STONE)
B(-11,-4,-12,STONE)
B(-11,-4,-11,STONE)
B(-11,-4,-10,STONE)
B(-11,-4,-9,STONE)
B(-11,-4,-8,STONE)
B(-11,-4,-6,STONE)
B(-11,-3,-15,STONE)
B(-11,-3,-14,STONE)
B(-11,-3,-13,STONE)
B(-11,-3,-12,STONE)
B(-11,-3,-11,STONE)
B(-11,-3,-10,STONE)
B(-11,-3,-9,STONE)
B(-11,-3,-8,STONE)
B(-11,-2,-14,STONE)
B(-11,-2,-13,STONE)
B(-11,-2,-12,STONE)
B(-11,-2,-11,STONE)
B(-11,-2,-10,STONE)
B(-11,-2,-9,STONE)
B(-11,-1,-13,STONE)
B(-11,-1,-12,STONE)
B(-11,-1,-11,STONE)
B(-11,-1,-10,STONE)
B(-11,0,-12,STONE)
B(-11,0,-11,STONE)
B(-11,1,-12,STONE)
B(-10,-10,-8,STONE)
B(-10,-10,-7,STONE)
B(-10,-9,-9,STONE)
B(-10,-9,-8,STONE)
B(-10,-9,-7,STONE)
B(-10,-9,-6,STONE)
B(-10,-8,-11,STONE)
B(-10,-8,-10,STONE)
B(-10,-8,-9,STONE)
B(-10,-8,-8,STONE)
B(-10,-8,-7,STATIONARY_WATER)
B(-10,-8,-6,STONE)
B(-10,-8,-5,STONE)
B(-10,-7,-11,STONE)
B(-10,-7,-10,STONE)
B(-10,-7,-9,STONE)
B(-10,-7,-8,MOSSY_COBBLESTONE)
B(-10,-7,-7,STONE)
B(-10,-7,-6,STONE)
B(-10,-7,-5,STONE)
B(-10,-7,-4,STONE)
B(-10,-6,-13,STONE)
B(-10,-6,-12,STONE)
B(-10,-6,-11,STONE)
B(-10,-6,-10,STONE)
B(-10,-6,-9,STONE)
B(-10,-6,-8,STONE)
B(-10,-6,-7,STONE)
B(-10,-6,-6,STONE)
B(-10,-6,-5,STONE)
B(-10,-6,-4,STONE)
B(-10,-5,-14,STONE)
B(-10,-5,-13,STONE)
B(-10,-5,-12,STONE)
B(-10,-5,-11,STATIONARY_WATER:8)
B(-10,-5,-10,STATIONARY_WATER:8)
B(-10,-5,-9,STATIONARY_WATER:8)
B(-10,-5,-8,STONE)
B(-10,-5,-7,STONE)
B(-10,-5,-6,STONE)
B(-10,-5,-5,STONE)
B(-10,-5,-4,STONE)
B(-10,-4,-17,STONE)
B(-10,-4,-16,STONE)
B(-10,-4,-15,STONE)
B(-10,-4,-14,STONE)
B(-10,-4,-13,STONE)
B(-10,-4,-12,STONE)
B(-10,-4,-11,STATIONARY_WATER)
B(-10,-4,-10,STATIONARY_WATER)
B(-10,-4,-9,STATIONARY_WATER)
B(-10,-4,-8,STONE)
B(-10,-4,-7,STONE)
B(-10,-4,-6,STONE)
B(-10,-4,-5,STONE)
B(-10,-4,-4,STONE)
B(-10,-3,-17,STONE)
B(-10,-3,-16,STONE)
B(-10,-3,-15,STONE)
B(-10,-3,-14,STONE)
B(-10,-3,-13,STONE)
B(-10,-3,-12,STONE)
B(-10,-3,-11,STONE)
B(-10,-3,-10,STONE)
B(-10,-3,-9,STATIONARY_WATER)
B(-10,-3,-8,STONE)
B(-10,-3,-7,STONE)
B(-10,-3,-6,STONE)
B(-10,-3,-5,STONE)
B(-10,-2,-16,STONE)
B(-10,-2,-15,STONE)
B(-10,-2,-14,STONE)
B(-10,-2,-13,STONE)
B(-10,-2,-12,STONE)
B(-10,-2,-11,STONE)
B(-10,-2,-10,STONE)
B(-10,-2,-9,STONE)
B(-10,-2,-6,STONE)
B(-10,-1,-15,STONE)
B(-10,-1,-14,STONE)
B(-10,-1,-13,STONE)
B(-10,-1,-12,STONE)
B(-10,-1,-11,STONE)
B(-10,-1,-10,STONE)
B(-10,0,-15,STONE)
B(-10,0,-14,STONE)
B(-10,0,-13,STONE)
B(-10,0,-12,STONE)
B(-10,0,-11,STONE)
B(-10,0,-10,STONE)
B(-10,1,-14,STONE)
B(-10,1,-13,STONE)
B(-10,1,-12,STONE)
B(-10,1,-11,STONE)
B(-10,1,-10,STONE)
B(-10,2,-14,STONE)
B(-10,2,-13,STONE)
B(-10,2,-12,STONE)
B(-10,2,-11,STONE)
B(-10,3,-13,STONE)
B(-9,-12,-6,STONE)
B(-9,-11,-9,STONE)
B(-9,-11,-8,STONE)
B(-9,-11,-7,STONE)
B(-9,-11,-6,STONE)
B(-9,-10,-9,STONE)
B(-9,-10,-8,STONE)
B(-9,-10,-7,STONE)
B(-9,-10,-6,STONE)
B(-9,-10,-5,STONE)
B(-9,-9,-11,STONE)
B(-9,-9,-10,STONE)
B(-9,-9,-9,STONE)
B(-9,-9,-8,STATIONARY_WATER:8)
B(-9,-9,-7,STATIONARY_WATER:8)
B(-9,-9,-6,STATIONARY_WATER:8)
B(-9,-9,-5,STONE)
B(-9,-9,-4,STONE)
B(-9,-8,-13,STONE)
B(-9,-8,-12,STONE)
B(-9,-8,-11,STATIONARY_WATER:8)
B(-9,-8,-10,STATIONARY_WATER:8)
B(-9,-8,-9,STATIONARY_WATER:8)
B(-9,-8,-8,STATIONARY_WATER:8)
B(-9,-8,-7,STATIONARY_WATER:8)
B(-9,-8,-6,STATIONARY_WATER:8)
B(-9,-8,-5,STATIONARY_WATER:9)
B(-9,-8,-4,STONE)
B(-9,-8,-3,STONE)
B(-9,-7,-14,STONE)
B(-9,-7,-13,STONE)
B(-9,-7,-12,STONE)
B(-9,-7,-11,STATIONARY_WATER:8)
B(-9,-7,-10,STATIONARY_WATER:8)
B(-9,-7,-9,STATIONARY_WATER:8)
B(-9,-7,-8,STATIONARY_WATER:8)
B(-9,-7,-7,STATIONARY_WATER)
B(-9,-7,-6,STATIONARY_WATER)
B(-9,-7,-5,STATIONARY_WATER:1)
B(-9,-7,-4,STONE)
B(-9,-7,-3,STONE)
B(-9,-6,-18,STONE)
B(-9,-6,-17,STONE)
B(-9,-6,-16,STONE)
B(-9,-6,-15,STONE)
B(-9,-6,-14,STONE)
B(-9,-6,-13,STONE)
B(-9,-6,-12,STONE)
B(-9,-6,-11,STATIONARY_WATER)
B(-9,-6,-10,STATIONARY_WATER)
B(-9,-6,-9,STATIONARY_WATER:8)
B(-9,-6,-8,STATIONARY_WATER:8)
B(-9,-6,-7,STATIONARY_WATER)
B(-9,-6,-6,STONE)
B(-9,-6,-5,STONE)
B(-9,-6,-4,STONE)
B(-9,-6,-3,STONE)
B(-9,-5,-18,STONE)
B(-9,-5,-17,STONE)
B(-9,-5,-16,STONE)
B(-9,-5,-15,STONE)
B(-9,-5,-14,STONE)
B(-9,-5,-13,STONE)
B(-9,-5,-12,STATIONARY_WATER:8)
B(-9,-5,-11,STATIONARY_WATER)
B(-9,-5,-10,STATIONARY_WATER)
B(-9,-5,-9,STATIONARY_WATER:8)
B(-9,-5,-8,STATIONARY_WATER)
B(-9,-5,-7,STATIONARY_WATER)
B(-9,-5,-6,STONE)
B(-9,-5,-5,STONE)
B(-9,-5,-4,STONE)
B(-9,-5,-3,STONE)
B(-9,-4,-18,STONE)
B(-9,-4,-17,STONE)
B(-9,-4,-16,STONE)
B(-9,-4,-15,STONE)
B(-9,-4,-14,STONE)
B(-9,-4,-13,STATIONARY_WATER:8)
B(-9,-4,-12,STATIONARY_WATER:8)
B(-9,-4,-11,STATIONARY_WATER)
B(-9,-4,-10,STATIONARY_WATER)
B(-9,-4,-9,STATIONARY_WATER:8)
B(-9,-4,-8,STATIONARY_WATER)
B(-9,-4,-7,STATIONARY_WATER)
B(-9,-4,-6,STONE)
B(-9,-4,-5,STONE)
B(-9,-4,-4,STONE)
B(-9,-4,-3,STONE)
B(-9,-4,-2,STONE)
B(-9,-3,-18,STONE)
B(-9,-3,-17,STONE)
B(-9,-3,-16,STONE)
B(-9,-3,-15,STONE)
B(-9,-3,-14,STONE)
B(-9,-3,-13,STATIONARY_WATER)
B(-9,-3,-12,STATIONARY_WATER)
B(-9,-3,-11,STATIONARY_WATER)
B(-9,-3,-10,STATIONARY_WATER)
B(-9,-3,-9,STATIONARY_WATER)
B(-9,-3,-8,STONE)
B(-9,-3,-7,STONE)
B(-9,-3,-6,STONE)
B(-9,-3,-5,STONE)
B(-9,-3,-4,STONE)
B(-9,-3,-3,STONE)
B(-9,-3,-2,STONE)
B(-9,-2,-17,STONE)
B(-9,-2,-16,STONE)
B(-9,-2,-15,STONE)
B(-9,-2,-14,STATIONARY_WATER)
B(-9,-2,-13,STATIONARY_WATER)
B(-9,-2,-12,STATIONARY_WATER)
B(-9,-2,-11,STATIONARY_WATER)
B(-9,-2,-10,STONE)
B(-9,-2,-9,STONE)
B(-9,-2,-8,STONE)
B(-9,-2,-7,STONE)
B(-9,-2,-6,STONE)
B(-9,-2,-5,STONE)
B(-9,-2,-4,STONE)
B(-9,-2,-3,STONE)
B(-9,-2,-2,STONE)
B(-9,-2,-1,STONE)
B(-9,-1,-16,STONE)
B(-9,-1,-15,STONE)
B(-9,-1,-14,STATIONARY_WATER)
B(-9,-1,-13,STATIONARY_WATER)
B(-9,-1,-12,STATIONARY_WATER)
B(-9,-1,-11,STONE)
B(-9,-1,-10,STONE)
B(-9,-1,-9,STONE)
B(-9,-1,-8,STONE)
B(-9,-1,-4,STONE)
B(-9,-1,-3,STONE)
B(-9,-1,-2,STONE)
B(-9,0,-16,STONE)
B(-9,0,-15,STONE)
B(-9,0,-14,STONE)
B(-9,0,-13,STATIONARY_WATER)
B(-9,0,-12,STATIONARY_WATER)
B(-9,0,-11,STONE)
B(-9,0,-10,STONE)
B(-9,0,-9,STONE)
B(-9,1,-16,STONE)
B(-9,1,-15,STONE)
B(-9,1,-14,STONE)
B(-9,1,-13,STATIONARY_WATER)
B(-9,1,-12,STATIONARY_WATER)
B(-9,1,-11,STONE)
B(-9,1,-10,STONE)
B(-9,2,-15,STONE)
B(-9,2,-14,STATIONARY_WATER)
B(-9,2,-13,STATIONARY_WATER)
B(-9,2,-12,STATIONARY_WATER)
B(-9,2,-11,STONE)
B(-9,2,-10,STONE)
B(-9,3,-11,STONE)
B(-8,-13,-6,STONE)
B(-8,-12,-7,STONE)
B(-8,-12,-6,STONE)
B(-8,-12,-5,STONE)
B(-8,-12,-4,STONE)
B(-8,-11,-8,STONE)
B(-8,-11,-7,STONE)
B(-8,-11,-6,STONE)
B(-8,-11,-5,STONE)
B(-8,-11,-4,STONE)
B(-8,-10,-15,STONE)
B(-8,-10,-13,STONE)
B(-8,-10,-12,STONE)
B(-8,-10,-11,STONE)
B(-8,-10,-10,STONE)
B(-8,-10,-9,STONE)
B(-8,-10,-8,STONE)
B(-8,-10,-7,STATIONARY_WATER:8)
B(-8,-10,-6,STATIONARY_WATER:8)
B(-8,-10,-5,STATIONARY_WATER:8)
B(-8,-10,-4,STONE)
B(-8,-10,-3,STONE)
B(-8,-9,-16,STONE)
B(-8,-9,-15,STONE)
B(-8,-9,-14,STONE)
B(-8,-9,-13,STONE)
B(-8,-9,-12,STONE)
B(-8,-9,-11,STONE)
B(-8,-9,-10,STONE)
B(-8,-9,-9,STATIONARY_WATER:8)
B(-8,-9,-8,STATIONARY_WATER:9)
B(-8,-9,-7,STATIONARY_WATER:8)
B(-8,-9,-6,STATIONARY_WATER:8)
B(-8,-9,-5,STATIONARY_WATER:8)
B(-8,-9,-4,STONE)
B(-8,-9,-3,STONE)
B(-8,-9,-2,STONE)
B(-8,-8,-17,STONE)
B(-8,-8,-16,STONE)
B(-8,-8,-15,STONE)
B(-8,-8,-14,STONE)
B(-8,-8,-13,STONE)
B(-8,-8,-12,STONE)
B(-8,-8,-11,STONE)
B(-8,-8,-10,STATIONARY_WATER:8)
B(-8,-8,-9,STATIONARY_WATER:8)
B(-8,-8,-8,STATIONARY_WATER:9)
B(-8,-8,-7,STATIONARY_WATER:8)
B(-8,-8,-6,STATIONARY_WATER:8)
B(-8,-8,-5,STATIONARY_WATER)
B(-8,-8,-4,STATIONARY_WATER)
B(-8,-8,-3,STONE)
B(-8,-8,-2,STONE)
B(-8,-7,-18,STONE)
B(-8,-7,-17,STONE)
B(-8,-7,-16,STONE)
B(-8,-7,-15,STONE)
B(-8,-7,-14,STONE)
B(-8,-7,-13,STONE)
B(-8,-7,-12,STONE)
B(-8,-7,-11,STATIONARY_WATER:8)
B(-8,-7,-10,STATIONARY_WATER:8)
B(-8,-7,-9,STATIONARY_WATER:8)
B(-8,-7,-8,STATIONARY_WATER:9)
B(-8,-7,-7,STATIONARY_WATER:8)
B(-8,-7,-6,STATIONARY_WATER:8)
B(-8,-7,-5,STATIONARY_WATER)
B(-8,-7,-4,STATIONARY_WATER)
B(-8,-7,-3,STONE)
B(-8,-7,-2,STONE)
B(-8,-6,-19,STONE)
B(-8,-6,-18,STONE)
B(-8,-6,-17,STONE)
B(-8,-6,-16,STONE)
B(-8,-6,-15,STONE)
B(-8,-6,-14,STONE)
B(-8,-6,-13,STONE)
B(-8,-6,-12,STATIONARY_WATER:8)
B(-8,-6,-11,STATIONARY_WATER)
B(-8,-6,-10,STATIONARY_WATER:8)
B(-8,-6,-9,STATIONARY_WATER:8)
B(-8,-6,-8,STATIONARY_WATER:9)
B(-8,-6,-7,STATIONARY_WATER:8)
B(-8,-6,-6,STATIONARY_WATER)
B(-8,-6,-5,STONE)
B(-8,-6,-4,STONE)
B(-8,-6,-3,STONE)
B(-8,-6,-2,STONE)
B(-8,-5,-19,STONE)
B(-8,-5,-18,STONE)
B(-8,-5,-17,STONE)
B(-8,-5,-16,STONE)
B(-8,-5,-15,STONE)
B(-8,-5,-14,STONE)
B(-8,-5,-13,STONE)
B(-8,-5,-12,STATIONARY_WATER:8)
B(-8,-5,-11,STATIONARY_WATER:8)
B(-8,-5,-10,STATIONARY_WATER:8)
B(-8,-5,-9,STATIONARY_WATER:8)
B(-8,-5,-8,STATIONARY_WATER:9)
B(-8,-5,-7,STATIONARY_WATER)
B(-8,-5,-6,STONE)
B(-8,-5,-5,STONE)
B(-8,-5,-4,STONE)
B(-8,-5,-3,STONE)
B(-8,-5,-2,STONE)
B(-8,-5,-1,STONE)
B(-8,-4,-20,STONE)
B(-8,-4,-19,STONE)
B(-8,-4,-18,STONE)
B(-8,-4,-17,STONE)
B(-8,-4,-16,STONE)
B(-8,-4,-15,STONE)
B(-8,-4,-14,STONE)
B(-8,-4,-13,STATIONARY_WATER:8)
B(-8,-4,-12,STATIONARY_WATER:8)
B(-8,-4,-11,STATIONARY_WATER:8)
B(-8,-4,-10,STATIONARY_WATER:8)
B(-8,-4,-9,STATIONARY_WATER:8)
B(-8,-4,-8,STATIONARY_WATER:1)
B(-8,-4,-7,STATIONARY_WATER)
B(-8,-4,-6,STONE)
B(-8,-4,-5,STONE)
B(-8,-4,-4,STONE)
B(-8,-4,-3,STONE)
B(-8,-4,-2,STONE)
B(-8,-4,-1,STONE)
B(-8,-3,-20,STONE)
B(-8,-3,-19,STONE)
B(-8,-3,-18,STONE)
B(-8,-3,-17,STONE)
B(-8,-3,-16,STONE)
B(-8,-3,-15,STONE)
B(-8,-3,-14,STATIONARY_WATER)
B(-8,-3,-13,STATIONARY_WATER)
B(-8,-3,-12,STATIONARY_WATER)
B(-8,-3,-11,STATIONARY_WATER)
B(-8,-3,-10,STATIONARY_WATER)
B(-8,-3,-9,STATIONARY_WATER)
B(-8,-3,-8,STONE)
B(-8,-3,-7,STONE)
B(-8,-3,-6,STONE)
B(-8,-3,-5,STONE)
B(-8,-3,-4,STONE)
B(-8,-3,-3,STONE)
B(-8,-3,-2,STONE)
B(-8,-3,-1,STONE)
B(-8,-2,-19,STONE)
B(-8,-2,-18,STONE)
B(-8,-2,-17,STONE)
B(-8,-2,-16,STONE)
B(-8,-2,-15,STONE)
B(-8,-2,-14,STATIONARY_WATER)
B(-8,-2,-13,STATIONARY_WATER)
B(-8,-2,-12,STATIONARY_WATER)
B(-8,-2,-11,STATIONARY_WATER)
B(-8,-2,-10,STATIONARY_WATER)
B(-8,-2,-9,STONE)
B(-8,-2,-8,STONE)
B(-8,-2,-7,STONE)
B(-8,-2,-6,STONE)
B(-8,-2,-5,STONE)
B(-8,-2,-4,STONE)
B(-8,-2,-3,STONE)
B(-8,-2,-2,STONE)
B(-8,-2,-1,STONE)
B(-8,-2,0,STONE)
B(-8,-1,-18,STONE)
B(-8,-1,-17,STONE)
B(-8,-1,-16,STONE)
B(-8,-1,-15,STONE)
B(-8,-1,-14,STATIONARY_WATER)
B(-8,-1,-13,STATIONARY_WATER)
B(-8,-1,-12,STATIONARY_WATER)
B(-8,-1,-11,STATIONARY_WATER)
B(-8,-1,-10,STONE)
B(-8,-1,-9,STONE)
B(-8,-1,-8,STONE)
B(-8,-1,-7,STONE)
B(-8,-1,-6,STONE)
B(-8,-1,-5,STONE)
B(-8,-1,-4,STONE)
B(-8,-1,-3,STONE)
B(-8,-1,-2,STONE)
B(-8,-1,-1,STONE)
B(-8,0,-18,STONE)
B(-8,0,-17,STONE)
B(-8,0,-16,STONE)
B(-8,0,-15,STATIONARY_WATER)
B(-8,0,-14,STATIONARY_WATER)
B(-8,0,-13,STATIONARY_WATER)
B(-8,0,-12,STATIONARY_WATER)
B(-8,0,-11,STATIONARY_WATER)
B(-8,0,-10,STONE)
B(-8,0,-9,STONE)
B(-8,0,-8,STONE)
B(-8,0,-5,STONE)
B(-8,0,-4,STONE)
B(-8,0,-3,STONE)
B(-8,0,-2,STONE)
B(-8,1,-17,STONE)
B(-8,1,-16,STONE)
B(-8,1,-15,STATIONARY_WATER)
B(-8,1,-14,STATIONARY_WATER)
B(-8,1,-13,STATIONARY_WATER)
B(-8,1,-12,STATIONARY_WATER)
B(-8,1,-11,STATIONARY_WATER)
B(-8,1,-10,STONE)
B(-8,1,-9,STONE)
B(-8,2,-17,STONE)
B(-8,2,-16,STONE)
B(-8,2,-15,STATIONARY_WATER)
B(-8,2,-14,STATIONARY_WATER)
B(-8,2,-13,STATIONARY_WATER)
B(-8,2,-12,STATIONARY_WATER)
B(-8,2,-11,STATIONARY_WATER)
B(-8,2,-10,STONE)
B(-8,3,-16,STONE)
B(-7,-13,-7,STONE)
B(-7,-13,-6,STONE)
B(-7,-13,-5,STONE)
B(-7,-12,-8,STONE)
B(-7,-12,-7,STONE)
B(-7,-12,-6,STATIONARY_WATER:8)
B(-7,-12,-5,STONE)
B(-7,-12,-4,STONE)
B(-7,-11,-8,STONE)
B(-7,-11,-7,STATIONARY_WATER:8)
B(-7,-11,-6,STATIONARY_WATER:8)
B(-7,-11,-5,STATIONARY_WATER:8)
B(-7,-11,-4,STONE)
B(-7,-11,-3,STONE)
B(-7,-10,-16,STONE)
B(-7,-10,-15,STONE)
B(-7,-10,-14,STONE)
B(-7,-10,-13,STONE)
B(-7,-10,-12,STONE)
B(-7,-10,-11,STONE)
B(-7,-10,-10,STONE)
B(-7,-10,-9,STONE)
B(-7,-10,-8,STONE)
B(-7,-10,-7,STATIONARY_WATER:8)
B(-7,-10,-6,STATIONARY_WATER:8)
B(-7,-10,-5,STATIONARY_WATER:8)
B(-7,-10,-4,STATIONARY_WATER:8)
B(-7,-10,-3,STONE)
B(-7,-10,-2,STONE)
B(-7,-9,-18,STONE)
B(-7,-9,-17,STONE)
B(-7,-9,-16,STONE)
B(-7,-9,-15,STONE)
B(-7,-9,-14,STONE)
B(-7,-9,-13,STONE)
B(-7,-9,-12,STONE)
B(-7,-9,-11,STONE)
B(-7,-9,-10,STONE)
B(-7,-9,-9,STATIONARY_WATER:8)
B(-7,-9,-8,STATIONARY_WATER:8)
B(-7,-9,-7,STATIONARY_WATER:8)
B(-7,-9,-6,STATIONARY_WATER:8)
B(-7,-9,-5,STATIONARY_WATER:8)
B(-7,-9,-4,STATIONARY_WATER:8)
B(-7,-9,-3,STONE)
B(-7,-9,-2,STONE)
B(-7,-8,-19,STONE)
B(-7,-8,-18,STONE)
B(-7,-8,-17,STONE)
B(-7,-8,-16,STONE)
B(-7,-8,-15,STONE)
B(-7,-8,-14,STONE)
B(-7,-8,-13,STONE)
B(-7,-8,-12,STONE)
B(-7,-8,-11,STONE)
B(-7,-8,-10,STONE)
B(-7,-8,-9,STATIONARY_WATER)
B(-7,-8,-8,STATIONARY_WATER:8)
B(-7,-8,-7,STATIONARY_WATER:8)
B(-7,-8,-6,STATIONARY_WATER:8)
B(-7,-8,-5,STATIONARY_WATER)
B(-7,-8,-4,STATIONARY_WATER)
B(-7,-8,-3,STONE)
B(-7,-8,-2,STONE)
B(-7,-8,-1,STONE)
B(-7,-7,-19,STONE)
B(-7,-7,-18,STONE)
B(-7,-7,-17,STONE)
B(-7,-7,-16,STONE)
B(-7,-7,-15,STONE)
B(-7,-7,-14,STONE)
B(-7,-7,-13,STONE)
B(-7,-7,-12,STONE)
B(-7,-7,-11,STONE)
B(-7,-7,-10,STATIONARY_WATER:8)
B(-7,-7,-9,STATIONARY_WATER:8)
B(-7,-7,-8,STATIONARY_WATER:8)
B(-7,-7,-7,STATIONARY_WATER:8)
B(-7,-7,-6,STATIONARY_WATER)
B(-7,-7,-5,STONE)
B(-7,-7,-4,STONE)
B(-7,-7,-3,STONE)
B(-7,-7,-2,STONE)
B(-7,-6,-19,STONE)
B(-7,-6,-18,STONE)
B(-7,-6,-17,STONE)
B(-7,-6,-16,STONE)
B(-7,-6,-15,STONE)
B(-7,-6,-14,STONE)
B(-7,-6,-13,STONE)
B(-7,-6,-12,STONE)
B(-7,-6,-11,STATIONARY_WATER)
B(-7,-6,-10,STATIONARY_WATER:8)
B(-7,-6,-9,STATIONARY_WATER:8)
B(-7,-6,-8,STATIONARY_WATER:8)
B(-7,-6,-7,STATIONARY_WATER)
B(-7,-6,-6,STONE)
B(-7,-6,-5,STONE)
B(-7,-6,-4,STONE)
B(-7,-6,-3,STONE)
B(-7,-6,-2,STONE)
B(-7,-6,-1,STONE)
B(-7,-5,-22,STONE)
B(-7,-5,-21,STONE)
B(-7,-5,-20,STONE)
B(-7,-5,-19,STONE)
B(-7,-5,-18,STONE)
B(-7,-5,-17,STONE)
B(-7,-5,-16,STONE)
B(-7,-5,-15,STONE)
B(-7,-5,-14,STONE)
B(-7,-5,-13,STONE)
B(-7,-5,-12,STONE)
B(-7,-5,-11,STATIONARY_WATER:8)
B(-7,-5,-10,STATIONARY_WATER)
B(-7,-5,-9,STATIONARY_WATER:8)
B(-7,-5,-8,STATIONARY_WATER)
B(-7,-5,-7,STONE)
B(-7,-5,-6,STONE)
B(-7,-5,-5,STONE)
B(-7,-5,-4,STONE)
B(-7,-5,-3,STONE)
B(-7,-5,-2,STONE)
B(-7,-5,-1,STONE)
B(-7,-4,-22,STONE)
B(-7,-4,-21,STONE)
B(-7,-4,-20,STONE)
B(-7,-4,-19,STONE)
B(-7,-4,-18,STONE)
B(-7,-4,-17,STONE)
B(-7,-4,-16,STONE)
B(-7,-4,-15,STONE)
B(-7,-4,-14,STONE)
B(-7,-4,-13,STATIONARY_WATER:8)
B(-7,-4,-12,STATIONARY_WATER:8)
B(-7,-4,-11,STATIONARY_WATER:8)
B(-7,-4,-10,STATIONARY_WATER)
B(-7,-4,-9,STATIONARY_WATER)
B(-7,-4,-8,STONE)
B(-7,-4,-7,STONE)
B(-7,-4,-6,STONE)
B(-7,-4,-5,STONE)
B(-7,-4,-4,STONE)
B(-7,-4,-3,STONE)
B(-7,-4,-2,STONE)
B(-7,-4,-1,STONE)
B(-7,-4,0,STONE)
B(-7,-3,-22,STONE)
B(-7,-3,-21,STONE)
B(-7,-3,-20,STONE)
B(-7,-3,-19,STONE)
B(-7,-3,-18,STONE)
B(-7,-3,-17,STONE)
B(-7,-3,-16,STONE)
B(-7,-3,-15,STONE)
B(-7,-3,-14,STATIONARY_WATER)
B(-7,-3,-13,STATIONARY_WATER)
B(-7,-3,-12,STATIONARY_WATER)
B(-7,-3,-11,STATIONARY_WATER:8)
B(-7,-3,-10,STATIONARY_WATER)
B(-7,-3,-9,STATIONARY_WATER)
B(-7,-3,-8,STONE)
B(-7,-3,-7,STONE)
B(-7,-3,-6,STONE)
B(-7,-3,-5,STONE)
B(-7,-3,-4,STONE)
B(-7,-3,-3,STONE)
B(-7,-3,-2,STONE)
B(-7,-3,-1,STONE)
B(-7,-3,0,STONE)
B(-7,-2,-21,STONE)
B(-7,-2,-20,STONE)
B(-7,-2,-19,STONE)
B(-7,-2,-18,STONE)
B(-7,-2,-17,STONE)
B(-7,-2,-16,STONE)
B(-7,-2,-15,STATIONARY_WATER)
B(-7,-2,-14,STATIONARY_WATER)
B(-7,-2,-13,STATIONARY_WATER)
B(-7,-2,-12,STATIONARY_WATER)
B(-7,-2,-11,STATIONARY_WATER)
B(-7,-2,-10,STATIONARY_WATER)
B(-7,-2,-9,STATIONARY_WATER:1)
B(-7,-2,-8,STONE)
B(-7,-2,-7,STONE)
B(-7,-2,-6,STONE)
B(-7,-2,-5,STONE)
B(-7,-2,-4,STONE)
B(-7,-2,-3,STONE)
B(-7,-2,-2,STONE)
B(-7,-2,-1,STONE)
B(-7,-2,0,STONE)
B(-7,-1,-19,STONE)
B(-7,-1,-18,STONE)
B(-7,-1,-17,STONE)
B(-7,-1,-16,STONE)
B(-7,-1,-15,STATIONARY_WATER)
B(-7,-1,-14,STATIONARY_WATER)
B(-7,-1,-13,STATIONARY_WATER)
B(-7,-1,-12,STATIONARY_WATER)
B(-7,-1,-11,STATIONARY_WATER)
B(-7,-1,-10,STATIONARY_WATER)
B(-7,-1,-9,STONE)
B(-7,-1,-8,STONE)
B(-7,-1,-7,STONE)
B(-7,-1,-6,STONE)
B(-7,-1,-5,STONE)
B(-7,-1,-4,STONE)
B(-7,-1,-3,STONE)
B(-7,-1,-2,STONE)
B(-7,-1,-1,STONE)
B(-7,-1,0,STONE)
B(-7,0,-18,STONE)
B(-7,0,-17,STONE)
B(-7,0,-16,STATIONARY_WATER)
B(-7,0,-15,STATIONARY_WATER)
B(-7,0,-14,STATIONARY_WATER)
B(-7,0,-13,STATIONARY_WATER)
B(-7,0,-12,STATIONARY_WATER)
B(-7,0,-11,STATIONARY_WATER)
B(-7,0,-10,STONE)
B(-7,0,-9,STONE)
B(-7,0,-8,STONE)
B(-7,0,-7,STONE)
B(-7,0,-6,STONE)
B(-7,0,-5,STONE)
B(-7,0,-4,STONE)
B(-7,0,-3,STONE)
B(-7,0,-2,STONE)
B(-7,0,-1,STONE)
B(-7,1,-18,STONE)
B(-7,1,-17,STONE)
B(-7,1,-16,STATIONARY_WATER)
B(-7,1,-15,STATIONARY_WATER)
B(-7,1,-14,STATIONARY_WATER)
B(-7,1,-13,STATIONARY_WATER)
B(-7,1,-12,STATIONARY_WATER)
B(-7,1,-11,STATIONARY_WATER)
B(-7,1,-10,STONE)
B(-7,1,-9,STONE)
B(-7,1,-8,STONE)
B(-7,1,-7,STONE)
B(-7,1,-6,STONE)
B(-7,1,-5,STONE)
B(-7,1,-4,STONE)
B(-7,1,-3,STONE)
B(-7,2,-17,STONE)
B(-7,2,-16,STATIONARY_WATER)
B(-7,2,-15,STATIONARY_WATER)
B(-7,2,-14,STATIONARY_WATER)
B(-7,2,-13,STATIONARY_WATER)
B(-7,2,-12,STATIONARY_WATER)
B(-7,2,-11,STATIONARY_WATER)
B(-7,2,-10,STONE)
B(-7,3,-17,STONE)
B(-6,-14,-6,STONE)
B(-6,-13,-8,STONE)
B(-6,-13,-7,STONE)
B(-6,-13,-6,STATIONARY_WATER:8)
B(-6,-13,-5,MOSSY_COBBLESTONE)
B(-6,-13,-4,STONE)
B(-6,-12,-9,STONE)
B(-6,-12,-8,STONE)
B(-6,-12,-7,STONE)
B(-6,-12,-6,STATIONARY_WATER:8)
B(-6,-12,-5,STATIONARY_WATER:8)
B(-6,-12,-4,STONE)
B(-6,-12,-3,STONE)
B(-6,-11,-15,STONE)
B(-6,-11,-14,STONE)
B(-6,-11,-13,STONE)
B(-6,-11,-12,STONE)
B(-6,-11,-9,STONE)
B(-6,-11,-8,STONE)
B(-6,-11,-7,STATIONARY_WATER:9)
B(-6,-11,-6,STATIONARY_WATER:8)
B(-6,-11,-5,STATIONARY_WATER:8)
B(-6,-11,-4,STATIONARY_WATER:8)
B(-6,-11,-3,STONE)
B(-6,-11,-2,STONE)
B(-6,-10,-17,STONE)
B(-6,-10,-16,STONE)
B(-6,-10,-15,STONE)
B(-6,-10,-14,STONE)
B(-6,-10,-13,STONE)
B(-6,-10,-12,STONE)
B(-6,-10,-11,STONE)
B(-6,-10,-10,STONE)
B(-6,-10,-9,STONE)
B(-6,-10,-8,STONE)
B(-6,-10,-7,STATIONARY_WATER:9)
B(-6,-10,-6,STATIONARY_WATER:8)
B(-6,-10,-5,STATIONARY_WATER:8)
B(-6,-10,-4,STATIONARY_WATER:8)
B(-6,-10,-3,STATIONARY_WATER)
B(-6,-10,-2,STONE)
B(-6,-9,-19,STONE)
B(-6,-9,-18,STONE)
B(-6,-9,-17,STONE)
B(-6,-9,-16,STONE)
B(-6,-9,-15,STONE)
B(-6,-9,-14,STONE)
B(-6,-9,-13,STONE)
B(-6,-9,-12,STONE)
B(-6,-9,-11,STONE)
B(-6,-9,-10,STONE)
B(-6,-9,-9,STONE)
B(-6,-9,-8,STONE)
B(-6,-9,-7,STATIONARY_WATER:1)
B(-6,-9,-6,STATIONARY_WATER)
B(-6,-9,-5,STATIONARY_WATER)
B(-6,-9,-4,STATIONARY_WATER:8)
B(-6,-9,-3,STONE)
B(-6,-9,-2,STONE)
B(-6,-9,-1,STONE)
B(-6,-8,-19,STONE)
B(-6,-8,-18,STONE)
B(-6,-8,-17,STONE)
B(-6,-8,-16,STONE)
B(-6,-8,-15,STONE)
B(-6,-8,-14,STONE)
B(-6,-8,-13,STONE)
B(-6,-8,-12,STONE)
B(-6,-8,-11,STONE)
B(-6,-8,-10,STONE)
B(-6,-8,-9,STONE)
B(-6,-8,-8,STATIONARY_WATER)
B(-6,-8,-7,STONE)
B(-6,-8,-6,STATIONARY_WATER)
B(-6,-8,-5,STATIONARY_WATER)
B(-6,-8,-4,STATIONARY_WATER)
B(-6,-8,-3,STONE)
B(-6,-8,-2,STONE)
B(-6,-8,-1,STONE)
B(-6,-7,-20,STONE)
B(-6,-7,-19,STONE)
B(-6,-7,-18,STONE)
B(-6,-7,-17,STONE)
B(-6,-7,-16,STONE)
B(-6,-7,-15,STONE)
B(-6,-7,-14,STONE)
B(-6,-7,-13,STONE)
B(-6,-7,-12,STONE)
B(-6,-7,-11,STONE)
B(-6,-7,-10,STONE)
B(-6,-7,-9,STATIONARY_WATER)
B(-6,-7,-8,STATIONARY_WATER)
B(-6,-7,-7,STONE)
B(-6,-7,-6,STONE)
B(-6,-7,-5,STONE)
B(-6,-7,-4,STONE)
B(-6,-7,-3,STONE)
B(-6,-7,-2,STONE)
B(-6,-7,-1,STONE)
B(-6,-6,-21,STONE)
B(-6,-6,-20,STONE)
B(-6,-6,-19,STONE)
B(-6,-6,-18,STONE)
B(-6,-6,-17,STONE)
B(-6,-6,-16,STONE)
B(-6,-6,-15,STONE)
B(-6,-6,-14,STONE)
B(-6,-6,-13,STONE)
B(-6,-6,-12,STONE)
B(-6,-6,-11,STONE)
B(-6,-6,-10,STONE)
B(-6,-6,-9,STATIONARY_WATER)
B(-6,-6,-8,STATIONARY_WATER:1)
B(-6,-6,-7,STONE)
B(-6,-6,-6,STONE)
B(-6,-6,-5,STONE)
B(-6,-6,-4,STONE)
B(-6,-6,-3,STONE)
B(-6,-6,-2,STONE)
B(-6,-6,-1,STONE)
B(-6,-5,-23,STONE)
B(-6,-5,-22,STONE)
B(-6,-5,-21,STONE)
B(-6,-5,-20,STONE)
B(-6,-5,-19,STONE)
B(-6,-5,-18,STONE)
B(-6,-5,-17,STONE)
B(-6,-5,-16,STONE)
B(-6,-5,-15,STONE)
B(-6,-5,-14,STONE)
B(-6,-5,-13,STONE)
B(-6,-5,-12,STONE)
B(-6,-5,-11,STONE)
B(-6,-5,-10,STONE)
B(-6,-5,-9,STONE)
B(-6,-5,-8,STONE)
B(-6,-5,-7,STONE)
B(-6,-5,-6,STONE)
B(-6,-5,-5,STONE)
B(-6,-5,-4,STONE)
B(-6,-5,-3,STONE)
B(-6,-5,-2,STONE)
B(-6,-5,-1,STONE)
B(-6,-5,0,STONE)
B(-6,-4,-23,STONE)
B(-6,-4,-22,STONE)
B(-6,-4,-21,STONE)
B(-6,-4,-20,STONE)
B(-6,-4,-19,STONE)
B(-6,-4,-18,STONE)
B(-6,-4,-17,STONE)
B(-6,-4,-16,STONE)
B(-6,-4,-15,STONE)
B(-6,-4,-14,STONE)
B(-6,-4,-13,STONE)
B(-6,-4,-12,STONE)
B(-6,-4,-11,COAL_ORE)
B(-6,-4,-10,STONE)
B(-6,-4,-9,STONE)
B(-6,-4,-8,STONE)
B(-6,-4,-7,STONE)
B(-6,-4,-6,STONE)
B(-6,-4,-5,STONE)
B(-6,-4,-4,STONE)
B(-6,-4,-3,STONE)
B(-6,-4,-2,STONE)
B(-6,-4,-1,STONE)
B(-6,-4,0,STONE)
B(-6,-3,-23,STONE)
B(-6,-3,-22,STONE)
B(-6,-3,-21,STONE)
B(-6,-3,-20,STONE)
B(-6,-3,-19,STONE)
B(-6,-3,-18,STONE)
B(-6,-3,-17,STONE)
B(-6,-3,-16,STONE)
B(-6,-3,-15,STONE)
B(-6,-3,-14,STATIONARY_WATER)
B(-6,-3,-13,STATIONARY_WATER)
B(-6,-3,-12,STATIONARY_WATER)
B(-6,-3,-11,STONE)
B(-6,-3,-10,STONE)
B(-6,-3,-9,STONE)
B(-6,-3,-8,STONE)
B(-6,-3,-7,STONE)
B(-6,-3,-6,STONE)
B(-6,-3,-5,STONE)
B(-6,-3,-4,STONE)
B(-6,-3,-3,STONE)
B(-6,-3,-2,STONE)
B(-6,-3,-1,STONE)
B(-6,-3,0,STONE)
B(-6,-3,1,STONE)
B(-6,-2,-22,STONE)
B(-6,-2,-21,STONE)
B(-6,-2,-20,STONE)
B(-6,-2,-19,STONE)
B(-6,-2,-18,STONE)
B(-6,-2,-17,STONE)
B(-6,-2,-16,STONE)
B(-6,-2,-15,STATIONARY_WATER)
B(-6,-2,-14,STATIONARY_WATER)
B(-6,-2,-13,STATIONARY_WATER)
B(-6,-2,-12,STATIONARY_WATER)
B(-6,-2,-11,STATIONARY_WATER)
B(-6,-2,-10,STONE)
B(-6,-2,-9,STONE)
B(-6,-2,-8,STONE)
B(-6,-2,-7,STONE)
B(-6,-2,-6,STONE)
B(-6,-2,-5,STONE)
B(-6,-2,-4,STONE)
B(-6,-2,-3,STONE)
B(-6,-2,-2,STONE)
B(-6,-2,-1,STONE)
B(-6,-2,0,STONE)
B(-6,-1,-21,STONE)
B(-6,-1,-20,STONE)
B(-6,-1,-19,STONE)
B(-6,-1,-18,STONE)
B(-6,-1,-17,STONE)
B(-6,-1,-16,STONE)
B(-6,-1,-15,STATIONARY_WATER)
B(-6,-1,-14,STATIONARY_WATER)
B(-6,-1,-13,STATIONARY_WATER)
B(-6,-1,-12,STATIONARY_WATER)
B(-6,-1,-11,STONE)
B(-6,-1,-10,STONE)
B(-6,-1,-9,STONE)
B(-6,-1,-8,STONE)
B(-6,-1,-7,STONE)
B(-6,-1,-6,STONE)
B(-6,-1,-5,STONE)
B(-6,-1,-4,STONE)
B(-6,-1,-3,STONE)
B(-6,-1,-2,STONE)
B(-6,-1,-1,STONE)
B(-6,-1,0,STONE)
B(-6,0,-19,STONE)
B(-6,0,-18,STONE)
B(-6,0,-17,STONE)
B(-6,0,-16,STONE)
B(-6,0,-15,STATIONARY_WATER)
B(-6,0,-14,STATIONARY_WATER)
B(-6,0,-13,STATIONARY_WATER)
B(-6,0,-12,STATIONARY_WATER)
B(-6,0,-11,STONE)
B(-6,0,-10,STONE)
B(-6,0,-9,STONE)
B(-6,0,-8,STONE)
B(-6,0,-7,STONE)
B(-6,0,-6,STONE)
B(-6,0,-5,STONE)
B(-6,0,-4,STONE)
B(-6,0,-3,STONE)
B(-6,0,-2,STONE)
B(-6,0,-1,STONE)
B(-6,1,-18,STONE)
B(-6,1,-17,STONE)
B(-6,1,-16,STONE)
B(-6,1,-15,STATIONARY_WATER)
B(-6,1,-14,STATIONARY_WATER)
B(-6,1,-13,STATIONARY_WATER)
B(-6,1,-12,STATIONARY_WATER)
B(-6,1,-11,STATIONARY_WATER)
B(-6,1,-10,STONE)
B(-6,1,-9,STONE)
B(-6,1,-8,STONE)
B(-6,1,-7,STONE)
B(-6,1,-6,STONE)
B(-6,1,-5,STONE)
B(-6,1,-4,STONE)
B(-6,1,-3,STONE)
B(-6,1,-2,STONE)
B(-6,2,-18,STONE)
B(-6,2,-17,STONE)
B(-6,2,-16,STATIONARY_WATER)
B(-6,2,-15,STATIONARY_WATER)
B(-6,2,-14,STATIONARY_WATER)
B(-6,2,-13,STATIONARY_WATER)
B(-6,2,-12,STATIONARY_WATER)
B(-6,2,-11,STATIONARY_WATER)
B(-6,2,-10,STONE)
B(-6,2,-9,STONE)
B(-6,2,-8,STONE)
B(-6,2,-7,STONE)
B(-6,2,-6,STONE)
B(-6,2,-5,STONE)
B(-6,3,-17,STONE)
B(-6,3,-10,STONE)
B(-5,-14,-9,STONE)
B(-5,-14,-8,STONE)
B(-5,-14,-7,STONE)
B(-5,-14,-6,STONE)
B(-5,-14,-5,STONE)
B(-5,-13,-10,STONE)
B(-5,-13,-9,STONE)
B(-5,-13,-8,STONE)
B(-5,-13,-7,STONE)
B(-5,-13,-6,STATIONARY_WATER:8)
B(-5,-13,-5,STATIONARY_WATER:8)
B(-5,-13,-4,STONE)
B(-5,-13,-3,STONE)
B(-5,-12,-14,STONE)
B(-5,-12,-13,STONE)
B(-5,-12,-12,STONE)
B(-5,-12,-11,STONE)
B(-5,-12,-10,STONE)
B(-5,-12,-9,STONE)
B(-5,-12,-8,STONE)
B(-5,-12,-7,STATIONARY_WATER:8)
B(-5,-12,-6,STATIONARY_WATER:8)
B(-5,-12,-5,STATIONARY_WATER:8)
B(-5,-12,-4,STATIONARY_WATER:8)
B(-5,-12,-3,STONE)
B(-5,-12,-2,STONE)
B(-5,-11,-16,STONE)
B(-5,-11,-15,STONE)
B(-5,-11,-14,STONE)
B(-5,-11,-13,STONE)
B(-5,-11,-12,STONE)
B(-5,-11,-11,STONE)
B(-5,-11,-10,STONE)
B(-5,-11,-9,STONE)
B(-5,-11,-8,STONE)
B(-5,-11,-7,STATIONARY_WATER:8)
B(-5,-11,-6,STATIONARY_WATER:8)
B(-5,-11,-5,STATIONARY_WATER:8)
B(-5,-11,-4,STATIONARY_WATER:8)
B(-5,-11,-3,STATIONARY_WATER:8)
B(-5,-11,-2,STONE)
B(-5,-10,-19,STONE)
B(-5,-10,-18,STONE)
B(-5,-10,-17,STONE)
B(-5,-10,-16,STONE)
B(-5,-10,-15,STONE)
B(-5,-10,-14,STONE)
B(-5,-10,-13,STONE)
B(-5,-10,-12,STONE)
B(-5,-10,-11,STONE)
B(-5,-10,-10,STONE)
B(-5,-10,-9,STONE)
B(-5,-10,-8,STONE)
B(-5,-10,-7,STATIONARY_WATER:8)
B(-5,-10,-6,STATIONARY_WATER:8)
B(-5,-10,-5,STATIONARY_WATER:8)
B(-5,-10,-4,STATIONARY_WATER:8)
B(-5,-10,-3,STATIONARY_WATER:8)
B(-5,-10,-2,COAL_ORE)
B(-5,-9,-20,STONE)
B(-5,-9,-19,STONE)
B(-5,-9,-18,STONE)
B(-5,-9,-17,STONE)
B(-5,-9,-16,STONE)
B(-5,-9,-15,STONE)
B(-5,-9,-14,STONE)
B(-5,-9,-13,STONE)
B(-5,-9,-12,STONE)
B(-5,-9,-11,STONE)
B(-5,-9,-10,STONE)
B(-5,-9,-9,STONE)
B(-5,-9,-8,STONE)
B(-5,-9,-7,STATIONARY_WATER:8)
B(-5,-9,-6,STATIONARY_WATER)
B(-5,-9,-5,STATIONARY_WATER)
B(-5,-9,-4,STATIONARY_WATER:8)
B(-5,-9,-3,STATIONARY_WATER)
B(-5,-9,-2,STONE)
B(-5,-9,-1,STONE)
B(-5,-8,-20,STONE)
B(-5,-8,-19,STONE)
B(-5,-8,-18,STONE)
B(-5,-8,-17,STONE)
B(-5,-8,-16,STONE)
B(-5,-8,-15,STONE)
B(-5,-8,-14,STONE)
B(-5,-8,-13,STONE)
B(-5,-8,-12,STONE)
B(-5,-8,-11,STONE)
B(-5,-8,-10,STONE)
B(-5,-8,-9,STONE)
B(-5,-8,-8,STONE)
B(-5,-8,-7,STATIONARY_WATER)
B(-5,-8,-6,STATIONARY_WATER)
B(-5,-8,-5,STATIONARY_WATER)
B(-5,-8,-4,STATIONARY_WATER)
B(-5,-8,-3,STONE)
B(-5,-8,-2,STONE)
B(-5,-8,-1,STONE)
B(-5,-7,-21,STONE)
B(-5,-7,-20,STONE)
B(-5,-7,-19,STONE)
B(-5,-7,-18,STONE)
B(-5,-7,-17,STONE)
B(-5,-7,-16,STONE)
B(-5,-7,-15,STONE)
B(-5,-7,-14,STONE)
B(-5,-7,-13,STONE)
B(-5,-7,-12,STONE)
B(-5,-7,-11,STONE)
B(-5,-7,-10,STONE)
B(-5,-7,-9,STONE)
B(-5,-7,-8,STONE)
B(-5,-7,-7,AIR)
B(-5,-7,-6,AIR)
B(-5,-7,-5,STONE)
B(-5,-7,-4,STONE)
B(-5,-7,-3,STONE)
B(-5,-7,-2,STONE)
B(-5,-7,-1,STONE)
B(-5,-6,-22,STONE)
B(-5,-6,-21,STONE)
B(-5,-6,-20,STONE)
B(-5,-6,-19,STONE)
B(-5,-6,-18,STONE)
B(-5,-6,-17,STONE)
B(-5,-6,-16,STONE)
B(-5,-6,-15,STONE)
B(-5,-6,-14,STONE)
B(-5,-6,-13,STONE)
B(-5,-6,-12,STONE)
B(-5,-6,-11,STONE)
B(-5,-6,-10,STONE)
B(-5,-6,-9,STONE)
B(-5,-6,-8,STONE)
B(-5,-6,-7,STONE)
B(-5,-6,-6,MOSSY_COBBLESTONE)
B(-5,-6,-5,STONE)
B(-5,-6,-4,STONE)
B(-5,-6,-3,STONE)
B(-5,-6,-2,STONE)
B(-5,-6,-1,STONE)
B(-5,-5,-23,STONE)
B(-5,-5,-22,STONE)
B(-5,-5,-21,STONE)
B(-5,-5,-20,STONE)
B(-5,-5,-19,STONE)
B(-5,-5,-18,STONE)
B(-5,-5,-17,STONE)
B(-5,-5,-16,STONE)
B(-5,-5,-15,STONE)
B(-5,-5,-14,STONE)
B(-5,-5,-13,STONE)
B(-5,-5,-12,STONE)
B(-5,-5,-11,STONE)
B(-5,-5,-10,STONE)
B(-5,-5,-9,STONE)
B(-5,-5,-8,STONE)
B(-5,-5,-7,STONE)
B(-5,-5,-6,AIR)
B(-5,-5,-5,STONE)
B(-5,-5,-4,STONE)
B(-5,-5,-3,STONE)
B(-5,-5,-2,STONE)
B(-5,-5,-1,STONE)
B(-5,-5,0,STONE)
B(-5,-4,-23,STONE)
B(-5,-4,-22,STONE)
B(-5,-4,-21,STONE)
B(-5,-4,-20,STONE)
B(-5,-4,-19,STONE)
B(-5,-4,-18,STONE)
B(-5,-4,-17,STONE)
B(-5,-4,-16,STONE)
B(-5,-4,-15,STONE)
B(-5,-4,-14,STONE)
B(-5,-4,-13,STONE)
B(-5,-4,-12,STONE)
B(-5,-4,-11,STONE)
B(-5,-4,-10,MOSSY_COBBLESTONE)
B(-5,-4,-9,STONE)
B(-5,-4,-8,STONE)
B(-5,-4,-7,STONE)
B(-5,-4,-6,STONE)
B(-5,-4,-5,AIR)
B(-5,-4,-4,STONE)
B(-5,-4,-3,STONE)
B(-5,-4,-2,STONE)
B(-5,-4,-1,STONE)
B(-5,-4,0,STONE)
B(-5,-4,1,STONE)
B(-5,-3,-23,STONE)
B(-5,-3,-22,STONE)
B(-5,-3,-21,STONE)
B(-5,-3,-20,STONE)
B(-5,-3,-19,STONE)
B(-5,-3,-18,STONE)
B(-5,-3,-17,STONE)
B(-5,-3,-16,STONE)
B(-5,-3,-15,STONE)
B(-5,-3,-14,STONE)
B(-5,-3,-13,STONE)
B(-5,-3,-12,STONE)
B(-5,-3,-11,STONE)
B(-5,-3,-10,STONE)
B(-5,-3,-9,STONE)
B(-5,-3,-8,STONE)
B(-5,-3,-7,STONE)
B(-5,-3,-6,STONE)
B(-5,-3,-5,STONE)
B(-5,-3,-4,STONE)
B(-5,-3,-3,STONE)
B(-5,-3,-2,STONE)
B(-5,-3,-1,STONE)
B(-5,-3,0,STONE)
B(-5,-3,1,STONE)
B(-5,-2,-23,STONE)
B(-5,-2,-22,STONE)
B(-5,-2,-21,STONE)
B(-5,-2,-20,STONE)
B(-5,-2,-19,STONE)
B(-5,-2,-18,STONE)
B(-5,-2,-17,STONE)
B(-5,-2,-16,STONE)
B(-5,-2,-15,STONE)
B(-5,-2,-14,STONE)
B(-5,-2,-13,STONE)
B(-5,-2,-12,STONE)
B(-5,-2,-11,STONE)
B(-5,-2,-10,STONE)
B(-5,-2,-9,STONE)
B(-5,-2,-8,STONE)
B(-5,-2,-7,STONE)
B(-5,-2,-6,STONE)
B(-5,-2,-5,STONE)
B(-5,-2,-4,STONE)
B(-5,-2,-3,STONE)
B(-5,-2,-2,STONE)
B(-5,-2,-1,STONE)
B(-5,-2,0,STONE)
B(-5,-2,1,STONE)
B(-5,-1,-22,STONE)
B(-5,-1,-21,STONE)
B(-5,-1,-20,STONE)
B(-5,-1,-19,STONE)
B(-5,-1,-18,STONE)
B(-5,-1,-17,STONE)
B(-5,-1,-16,STONE)
B(-5,-1,-15,STATIONARY_WATER)
B(-5,-1,-14,STATIONARY_WATER)
B(-5,-1,-13,STATIONARY_WATER)
B(-5,-1,-12,STONE)
B(-5,-1,-11,STONE)
B(-5,-1,-10,STONE)
B(-5,-1,-9,STONE)
B(-5,-1,-8,STONE)
B(-5,-1,-7,STONE)
B(-5,-1,-6,STONE)
B(-5,-1,-5,STONE)
B(-5,-1,-4,STONE)
B(-5,-1,-3,STONE)
B(-5,-1,-2,STONE)
B(-5,-1,-1,STONE)
B(-5,-1,0,STONE)
B(-5,0,-20,STONE)
B(-5,0,-19,STONE)
B(-5,0,-18,STONE)
B(-5,0,-17,STONE)
B(-5,0,-16,STATIONARY_WATER)
B(-5,0,-15,STATIONARY_WATER)
B(-5,0,-14,STATIONARY_WATER)
B(-5,0,-13,STATIONARY_WATER)
B(-5,0,-12,STATIONARY_WATER)
B(-5,0,-11,STONE)
B(-5,0,-10,STONE)
B(-5,0,-9,STONE)
B(-5,0,-8,STONE)
B(-5,0,-7,STONE)
B(-5,0,-6,STONE)
B(-5,0,-5,STONE)
B(-5,0,-4,STONE)
B(-5,0,-3,STONE)
B(-5,0,-2,STONE)
B(-5,0,-1,STONE)
B(-5,1,-19,STONE)
B(-5,1,-18,STONE)
B(-5,1,-17,STONE)
B(-5,1,-16,STATIONARY_WATER)
B(-5,1,-15,STATIONARY_WATER)
B(-5,1,-14,STATIONARY_WATER)
B(-5,1,-13,STATIONARY_WATER)
B(-5,1,-12,STATIONARY_WATER)
B(-5,1,-11,STONE)
B(-5,1,-10,STONE)
B(-5,1,-9,STONE)
B(-5,1,-8,STONE)
B(-5,1,-7,STONE)
B(-5,1,-6,STONE)
B(-5,1,-5,STONE)
B(-5,1,-4,STONE)
B(-5,1,-3,STONE)
B(-5,1,-2,STONE)
B(-5,1,-1,STONE)
B(-5,2,-18,STONE)
B(-5,2,-17,STONE)
B(-5,2,-16,STATIONARY_WATER)
B(-5,2,-15,STATIONARY_WATER)
B(-5,2,-14,STATIONARY_WATER)
B(-5,2,-13,STATIONARY_WATER)
B(-5,2,-12,STATIONARY_WATER)
B(-5,2,-11,STONE)
B(-5,2,-10,STONE)
B(-5,2,-9,STONE)
B(-5,2,-8,STONE)
B(-5,2,-7,STONE)
B(-5,2,-6,STONE)
B(-5,2,-5,STONE)
B(-5,2,-4,STONE)
B(-5,2,-3,STONE)
B(-5,3,-10,STONE)
B(-5,3,-9,STONE)
B(-5,3,-8,STONE)
B(-5,3,-7,STONE)
B(-5,3,-6,STONE)
B(-4,-14,-10,STONE)
B(-4,-14,-9,STONE)
B(-4,-14,-8,STONE)
B(-4,-14,-7,STONE)
B(-4,-14,-6,MOSSY_COBBLESTONE)
B(-4,-14,-5,STONE)
B(-4,-14,-4,STONE)
B(-4,-13,-13,STONE)
B(-4,-13,-12,STONE)
B(-4,-13,-11,STONE)
B(-4,-13,-10,STONE)
B(-4,-13,-9,STONE)
B(-4,-13,-8,STONE)
B(-4,-13,-7,STATIONARY_WATER:8)
B(-4,-13,-6,STATIONARY_WATER:8)
B(-4,-13,-5,STATIONARY_WATER:8)
B(-4,-13,-4,STONE)
B(-4,-13,-3,STONE)
B(-4,-12,-16,STONE)
B(-4,-12,-15,STONE)
B(-4,-12,-14,STONE)
B(-4,-12,-13,STONE)
B(-4,-12,-12,STONE)
B(-4,-12,-11,STONE)
B(-4,-12,-10,STONE)
B(-4,-12,-9,STONE)
B(-4,-12,-8,STONE)
B(-4,-12,-7,STATIONARY_WATER:8)
B(-4,-12,-6,STATIONARY_WATER:8)
B(-4,-12,-5,STATIONARY_WATER:8)
B(-4,-12,-4,STONE)
B(-4,-12,-3,STONE)
B(-4,-12,-2,STONE)
B(-4,-11,-17,STONE)
B(-4,-11,-16,STONE)
B(-4,-11,-15,STONE)
B(-4,-11,-14,STONE)
B(-4,-11,-13,STONE)
B(-4,-11,-12,STONE)
B(-4,-11,-11,STONE)
B(-4,-11,-10,STONE)
B(-4,-11,-9,STONE)
B(-4,-11,-8,STONE)
B(-4,-11,-7,STATIONARY_WATER:8)
B(-4,-11,-6,STATIONARY_WATER:8)
B(-4,-11,-5,STATIONARY_WATER:8)
B(-4,-11,-4,STATIONARY_WATER:8)
B(-4,-11,-3,STONE)
B(-4,-11,-2,STONE)
B(-4,-10,-19,STONE)
B(-4,-10,-18,STONE)
B(-4,-10,-17,STONE)
B(-4,-10,-16,STONE)
B(-4,-10,-15,STONE)
B(-4,-10,-14,STONE)
B(-4,-10,-13,STONE)
B(-4,-10,-12,STONE)
B(-4,-10,-11,STONE)
B(-4,-10,-10,STONE)
B(-4,-10,-9,STONE)
B(-4,-10,-8,STATIONARY_WATER:8)
B(-4,-10,-7,STATIONARY_WATER)
B(-4,-10,-6,STATIONARY_WATER)
B(-4,-10,-5,STATIONARY_WATER:8)
B(-4,-10,-4,STATIONARY_WATER:8)
B(-4,-10,-3,STONE)
B(-4,-10,-2,STONE)
B(-4,-9,-20,STONE)
B(-4,-9,-19,STONE)
B(-4,-9,-18,STONE)
B(-4,-9,-17,STONE)
B(-4,-9,-16,STONE)
B(-4,-9,-15,STONE)
B(-4,-9,-14,STONE)
B(-4,-9,-13,STONE)
B(-4,-9,-12,STONE)
B(-4,-9,-11,STONE)
B(-4,-9,-10,STONE)
B(-4,-9,-9,STONE)
B(-4,-9,-8,STATIONARY_WATER)
B(-4,-9,-7,STATIONARY_WATER)
B(-4,-9,-6,STATIONARY_WATER)
B(-4,-9,-5,STATIONARY_WATER)
B(-4,-9,-4,STATIONARY_WATER:8)
B(-4,-9,-3,STONE)
B(-4,-9,-2,STONE)
B(-4,-9,-1,STONE)
B(-4,-8,-21,STONE)
B(-4,-8,-20,STONE)
B(-4,-8,-19,STONE)
B(-4,-8,-18,STONE)
B(-4,-8,-17,STONE)
B(-4,-8,-16,STONE)
B(-4,-8,-15,STONE)
B(-4,-8,-14,STONE)
B(-4,-8,-13,STONE)
B(-4,-8,-12,STONE)
B(-4,-8,-11,STONE)
B(-4,-8,-10,STONE)
B(-4,-8,-9,STONE)
B(-4,-8,-8,STATIONARY_WATER)
B(-4,-8,-7,STATIONARY_WATER)
B(-4,-8,-6,STATIONARY_WATER)
B(-4,-8,-5,STATIONARY_WATER)
B(-4,-8,-4,STATIONARY_WATER)
B(-4,-8,-3,STONE)
B(-4,-8,-2,STONE)
B(-4,-8,-1,STONE)
B(-4,-7,-22,STONE)
B(-4,-7,-21,STONE)
B(-4,-7,-20,STONE)
B(-4,-7,-19,STONE)
B(-4,-7,-18,STONE)
B(-4,-7,-17,STONE)
B(-4,-7,-16,STONE)
B(-4,-7,-15,STONE)
B(-4,-7,-14,STONE)
B(-4,-7,-13,STONE)
B(-4,-7,-12,STONE)
B(-4,-7,-11,STONE)
B(-4,-7,-10,STONE)
B(-4,-7,-9,STONE)
B(-4,-7,-8,AIR)
B(-4,-7,-7,AIR)
B(-4,-7,-6,AIR)
B(-4,-7,-5,VINE:3)
B(-4,-7,-4,STONE)
B(-4,-7,-3,STONE)
B(-4,-7,-2,STONE)
B(-4,-7,-1,STONE)
B(-4,-6,-22,STONE)
B(-4,-6,-21,STONE)
B(-4,-6,-20,STONE)
B(-4,-6,-19,STONE)
B(-4,-6,-18,STONE)
B(-4,-6,-17,STONE)
B(-4,-6,-16,STONE)
B(-4,-6,-15,STONE)
B(-4,-6,-14,STONE)
B(-4,-6,-13,STONE)
B(-4,-6,-12,VINE:2)
B(-4,-6,-11,AIR)
B(-4,-6,-10,STONE)
B(-4,-6,-9,STONE)
B(-4,-6,-8,AIR)
B(-4,-6,-7,AIR)
B(-4,-6,-6,AIR)
B(-4,-6,-5,VINE:2)
B(-4,-6,-4,VINE:2)
B(-4,-6,-3,STONE)
B(-4,-6,-2,STONE)
B(-4,-6,-1,STONE)
B(-4,-6,0,STONE)
B(-4,-5,-23,STONE)
B(-4,-5,-22,STONE)
B(-4,-5,-21,STONE)
B(-4,-5,-20,STONE)
B(-4,-5,-19,STONE)
B(-4,-5,-18,STONE)
B(-4,-5,-17,STONE)
B(-4,-5,-16,STONE)
B(-4,-5,-15,STONE)
B(-4,-5,-14,STONE)
B(-4,-5,-13,AIR)
B(-4,-5,-12,AIR)
B(-4,-5,-11,AIR)
B(-4,-5,-10,BROWN_MUSHROOM)
B(-4,-5,-9,AIR)
B(-4,-5,-8,VINE:2)
B(-4,-5,-7,AIR)
B(-4,-5,-6,AIR)
B(-4,-5,-5,AIR)
B(-4,-5,-4,STONE)
B(-4,-5,-3,STONE)
B(-4,-5,-2,STONE)
B(-4,-5,-1,STONE)
B(-4,-5,0,STONE)
B(-4,-5,1,STONE)
B(-4,-4,-23,STONE)
B(-4,-4,-22,STONE)
B(-4,-4,-21,STONE)
B(-4,-4,-20,STONE)
B(-4,-4,-19,STONE)
B(-4,-4,-18,STONE)
B(-4,-4,-17,STONE)
B(-4,-4,-16,STONE)
B(-4,-4,-15,STONE)
B(-4,-4,-14,STONE)
B(-4,-4,-13,STONE)
B(-4,-4,-12,AIR)
B(-4,-4,-11,AIR)
B(-4,-4,-10,AIR)
B(-4,-4,-9,AIR)
B(-4,-4,-8,VINE:2)
B(-4,-4,-7,AIR)
B(-4,-4,-6,AIR)
B(-4,-4,-5,AIR)
B(-4,-4,-4,STONE)
B(-4,-4,-3,STONE)
B(-4,-4,-2,STONE)
B(-4,-4,-1,STONE)
B(-4,-4,0,STONE)
B(-4,-4,1,STONE)
B(-4,-3,-23,STONE)
B(-4,-3,-22,STONE)
B(-4,-3,-21,STONE)
B(-4,-3,-20,STONE)
B(-4,-3,-19,STONE)
B(-4,-3,-18,STONE)
B(-4,-3,-17,STONE)
B(-4,-3,-16,STONE)
B(-4,-3,-15,STONE)
B(-4,-3,-14,MOSSY_COBBLESTONE)
B(-4,-3,-13,STONE)
B(-4,-3,-12,STONE)
B(-4,-3,-11,AIR)
B(-4,-3,-10,AIR)
B(-4,-3,-9,VINE:2)
B(-4,-3,-8,AIR)
B(-4,-3,-7,STONE)
B(-4,-3,-6,AIR)
B(-4,-3,-5,AIR)
B(-4,-3,-4,STONE)
B(-4,-3,-3,STONE)
B(-4,-3,-2,STONE)
B(-4,-3,-1,STONE)
B(-4,-3,0,STONE)
B(-4,-3,1,STONE)
B(-4,-3,2,STONE)
B(-4,-2,-23,STONE)
B(-4,-2,-22,STONE)
B(-4,-2,-21,STONE)
B(-4,-2,-20,STONE)
B(-4,-2,-19,STONE)
B(-4,-2,-18,STONE)
B(-4,-2,-17,STONE)
B(-4,-2,-16,STONE)
B(-4,-2,-15,STONE)
B(-4,-2,-14,STONE)
B(-4,-2,-13,STONE)
B(-4,-2,-12,STONE)
B(-4,-2,-11,STONE)
B(-4,-2,-10,STONE)
B(-4,-2,-9,STONE)
B(-4,-2,-8,STONE)
B(-4,-2,-7,STONE)
B(-4,-2,-6,STONE)
B(-4,-2,-5,STONE)
B(-4,-2,-4,STONE)
B(-4,-2,-3,STONE)
B(-4,-2,-2,STONE)
B(-4,-2,-1,STONE)
B(-4,-2,0,STONE)
B(-4,-2,1,STONE)
B(-4,-2,2,STONE)
B(-4,-1,-22,STONE)
B(-4,-1,-21,STONE)
B(-4,-1,-20,STONE)
B(-4,-1,-19,STONE)
B(-4,-1,-18,STONE)
B(-4,-1,-17,STONE)
B(-4,-1,-16,STONE)
B(-4,-1,-15,COAL_ORE)
B(-4,-1,-14,STONE)
B(-4,-1,-13,STONE)
B(-4,-1,-12,STONE)
B(-4,-1,-11,STONE)
B(-4,-1,-10,STONE)
B(-4,-1,-9,STONE)
B(-4,-1,-8,STONE)
B(-4,-1,-7,STONE)
B(-4,-1,-6,STONE)
B(-4,-1,-5,STONE)
B(-4,-1,-4,STONE)
B(-4,-1,-3,STONE)
B(-4,-1,-2,STONE)
B(-4,-1,-1,STONE)
B(-4,-1,0,STONE)
B(-4,-1,1,STONE)
B(-4,0,-21,STONE)
B(-4,0,-20,STONE)
B(-4,0,-19,STONE)
B(-4,0,-18,STONE)
B(-4,0,-17,STONE)
B(-4,0,-16,STONE)
B(-4,0,-15,STATIONARY_WATER)
B(-4,0,-14,STONE)
B(-4,0,-13,STONE)
B(-4,0,-12,STONE)
B(-4,0,-11,STONE)
B(-4,0,-10,STONE)
B(-4,0,-9,STONE)
B(-4,0,-8,STONE)
B(-4,0,-7,STONE)
B(-4,0,-6,STONE)
B(-4,0,-5,STONE)
B(-4,0,-4,STONE)
B(-4,0,-3,STONE)
B(-4,0,-2,STONE)
B(-4,0,-1,STONE)
B(-4,0,0,STONE)
B(-4,1,-19,STONE)
B(-4,1,-18,STONE)
B(-4,1,-17,STONE)
B(-4,1,-16,STONE)
B(-4,1,-15,STATIONARY_WATER)
B(-4,1,-14,STONE)
B(-4,1,-13,STATIONARY_WATER)
B(-4,1,-12,STONE)
B(-4,1,-11,STONE)
B(-4,1,-10,STONE)
B(-4,1,-9,STONE)
B(-4,1,-8,STONE)
B(-4,1,-7,STONE)
B(-4,1,-6,STONE)
B(-4,1,-5,STONE)
B(-4,1,-4,STONE)
B(-4,1,-3,STONE)
B(-4,1,-2,STONE)
B(-4,1,-1,STONE)
B(-4,2,-18,STONE)
B(-4,2,-17,STONE)
B(-4,2,-16,STONE)
B(-4,2,-15,STATIONARY_WATER)
B(-4,2,-14,STATIONARY_WATER)
B(-4,2,-13,STATIONARY_WATER)
B(-4,2,-12,STONE)
B(-4,2,-11,STONE)
B(-4,2,-10,STONE)
B(-4,2,-9,STONE)
B(-4,2,-8,STONE)
B(-4,2,-7,STONE)
B(-4,2,-6,STONE)
B(-4,2,-5,STONE)
B(-4,2,-4,STONE)
B(-4,2,-3,STONE)
B(-4,2,-2,STONE)
B(-4,3,-11,STONE)
B(-4,3,-10,STONE)
B(-4,3,-9,STONE)
B(-4,3,-8,STONE)
B(-4,3,-7,STONE)
B(-4,3,-6,STONE)
B(-4,3,-5,STONE)
B(-4,3,-4,STONE)
B(-4,4,-11,STONE)
B(-4,4,-10,STONE)
B(-4,4,-9,STONE)
B(-4,4,-8,STONE)
B(-4,4,-7,STONE)
B(-3,-14,-13,STONE)
B(-3,-14,-12,STONE)
B(-3,-14,-11,STONE)
B(-3,-14,-10,STONE)
B(-3,-14,-9,STONE)
B(-3,-14,-8,STONE)
B(-3,-14,-7,STONE)
B(-3,-14,-6,STONE)
B(-3,-14,-5,STONE)
B(-3,-14,-4,STONE)
B(-3,-13,-16,STONE)
B(-3,-13,-15,STONE)
B(-3,-13,-14,STONE)
B(-3,-13,-13,STONE)
B(-3,-13,-12,STONE)
B(-3,-13,-11,STONE)
B(-3,-13,-10,STONE)
B(-3,-13,-9,STONE)
B(-3,-13,-8,STONE)
B(-3,-13,-7,STONE)
B(-3,-13,-6,STONE)
B(-3,-13,-5,STONE)
B(-3,-13,-4,STONE)
B(-3,-13,-3,STONE)
B(-3,-12,-17,STONE)
B(-3,-12,-16,STONE)
B(-3,-12,-15,STONE)
B(-3,-12,-14,STONE)
B(-3,-12,-13,STONE)
B(-3,-12,-12,STONE)
B(-3,-12,-11,STONE)
B(-3,-12,-10,STONE)
B(-3,-12,-9,STONE)
B(-3,-12,-8,STONE)
B(-3,-12,-7,STONE)
B(-3,-12,-6,STATIONARY_WATER:8)
B(-3,-12,-5,STONE)
B(-3,-12,-4,STONE)
B(-3,-12,-3,STONE)
B(-3,-12,-2,STONE)
B(-3,-11,-18,STONE)
B(-3,-11,-17,STONE)
B(-3,-11,-16,STONE)
B(-3,-11,-15,STONE)
B(-3,-11,-14,STONE)
B(-3,-11,-13,STONE)
B(-3,-11,-12,STONE)
B(-3,-11,-11,STONE)
B(-3,-11,-10,STONE)
B(-3,-11,-9,STONE)
B(-3,-11,-8,STONE)
B(-3,-11,-7,STATIONARY_WATER:8)
B(-3,-11,-6,STATIONARY_WATER:8)
B(-3,-11,-5,STONE)
B(-3,-11,-4,STONE)
B(-3,-11,-3,STONE)
B(-3,-11,-2,STONE)
B(-3,-10,-19,STONE)
B(-3,-10,-18,STONE)
B(-3,-10,-17,STONE)
B(-3,-10,-16,STONE)
B(-3,-10,-15,STONE)
B(-3,-10,-14,STONE)
B(-3,-10,-13,STONE)
B(-3,-10,-12,STONE)
B(-3,-10,-11,STONE)
B(-3,-10,-10,STONE)
B(-3,-10,-9,STONE)
B(-3,-10,-8,STONE)
B(-3,-10,-7,STATIONARY_WATER)
B(-3,-10,-6,STATIONARY_WATER)
B(-3,-10,-5,STATIONARY_WATER:8)
B(-3,-10,-4,STATIONARY_WATER:8)
B(-3,-10,-3,STONE)
B(-3,-10,-2,STONE)
B(-3,-10,-1,STONE)
B(-3,-9,-21,STONE)
B(-3,-9,-20,STONE)
B(-3,-9,-19,STONE)
B(-3,-9,-18,STONE)
B(-3,-9,-17,STONE)
B(-3,-9,-16,STONE)
B(-3,-9,-15,STONE)
B(-3,-9,-14,STONE)
B(-3,-9,-13,STONE)
B(-3,-9,-12,STONE)
B(-3,-9,-11,STONE)
B(-3,-9,-10,STONE)
B(-3,-9,-9,STONE)
B(-3,-9,-8,STATIONARY_WATER)
B(-3,-9,-7,STATIONARY_WATER)
B(-3,-9,-6,STATIONARY_WATER)
B(-3,-9,-5,STATIONARY_WATER:8)
B(-3,-9,-4,STATIONARY_WATER:8)
B(-3,-9,-3,STONE)
B(-3,-9,-2,STONE)
B(-3,-9,-1,STONE)
B(-3,-8,-21,STONE)
B(-3,-8,-20,STONE)
B(-3,-8,-19,STONE)
B(-3,-8,-18,STONE)
B(-3,-8,-17,STONE)
B(-3,-8,-16,STONE)
B(-3,-8,-15,STONE)
B(-3,-8,-14,STONE)
B(-3,-8,-13,STONE)
B(-3,-8,-12,STONE)
B(-3,-8,-11,STONE)
B(-3,-8,-10,STONE)
B(-3,-8,-9,STONE)
B(-3,-8,-8,STATIONARY_WATER)
B(-3,-8,-7,STATIONARY_WATER)
B(-3,-8,-6,STATIONARY_WATER)
B(-3,-8,-5,STATIONARY_WATER)
B(-3,-8,-4,STATIONARY_WATER)
B(-3,-8,-3,STONE)
B(-3,-8,-2,STONE)
B(-3,-8,-1,STONE)
B(-3,-7,-22,STONE)
B(-3,-7,-21,STONE)
B(-3,-7,-20,STONE)
B(-3,-7,-19,STONE)
B(-3,-7,-18,STONE)
B(-3,-7,-17,STONE)
B(-3,-7,-16,STONE)
B(-3,-7,-15,STONE)
B(-3,-7,-14,AIR)
B(-3,-7,-13,VINE:2)
B(-3,-7,-12,AIR)
B(-3,-7,-11,AIR)
B(-3,-7,-10,AIR)
B(-3,-7,-9,AIR)
B(-3,-7,-8,AIR)
B(-3,-7,-7,AIR)
B(-3,-7,-6,AIR)
B(-3,-7,-5,AIR)
B(-3,-7,-4,STONE)
B(-3,-7,-3,STONE)
B(-3,-7,-2,STONE)
B(-3,-7,-1,STONE)
B(-3,-7,0,STONE)
B(-3,-6,-22,STONE)
B(-3,-6,-21,STONE)
B(-3,-6,-20,STONE)
B(-3,-6,-19,STONE)
B(-3,-6,-18,STONE)
B(-3,-6,-17,STONE)
B(-3,-6,-16,STONE)
B(-3,-6,-15,RED_MUSHROOM)
B(-3,-6,-14,AIR)
B(-3,-6,-13,VINE:2)
B(-3,-6,-12,AIR)
B(-3,-6,-11,AIR)
B(-3,-6,-10,AIR)
B(-3,-6,-9,AIR)
B(-3,-6,-8,AIR)
B(-3,-6,-7,AIR)
B(-3,-6,-6,AIR)
B(-3,-6,-5,AIR)
B(-3,-6,-4,AIR)
B(-3,-6,-3,STONE)
B(-3,-6,-2,STONE)
B(-3,-6,-1,STONE)
B(-3,-6,0,STONE)
B(-3,-5,-23,STONE)
B(-3,-5,-22,STONE)
B(-3,-5,-21,STONE)
B(-3,-5,-20,STONE)
B(-3,-5,-19,STONE)
B(-3,-5,-18,STONE)
B(-3,-5,-17,AIR)
B(-3,-5,-16,AIR)
B(-3,-5,-15,AIR)
B(-3,-5,-14,VINE:2)
B(-3,-5,-13,AIR)
B(-3,-5,-12,AIR)
B(-3,-5,-11,AIR)
B(-3,-5,-10,AIR)
B(-3,-5,-9,AIR)
B(-3,-5,-8,AIR)
B(-3,-5,-7,AIR)
B(-3,-5,-6,AIR)
B(-3,-5,-5,AIR)
B(-3,-5,-4,AIR)
B(-3,-5,-3,STONE)
B(-3,-5,-2,STONE)
B(-3,-5,-1,STONE)
B(-3,-5,0,STONE)
B(-3,-5,1,STONE)
B(-3,-4,-23,STONE)
B(-3,-4,-22,STONE)
B(-3,-4,-21,STONE)
B(-3,-4,-20,STONE)
B(-3,-4,-19,STONE)
B(-3,-4,-18,STONE)
B(-3,-4,-17,AIR)
B(-3,-4,-16,AIR)
B(-3,-4,-15,AIR)
B(-3,-4,-14,AIR)
B(-3,-4,-13,AIR)
B(-3,-4,-12,AIR)
B(-3,-4,-11,AIR)
B(-3,-4,-10,AIR)
B(-3,-4,-9,AIR)
B(-3,-4,-8,AIR)
B(-3,-4,-7,AIR)
B(-3,-4,-6,AIR)
B(-3,-4,-5,AIR)
B(-3,-4,-4,AIR)
B(-3,-4,-3,STONE)
B(-3,-4,-2,STONE)
B(-3,-4,-1,STONE)
B(-3,-4,0,STONE)
B(-3,-4,1,STONE)
B(-3,-4,2,STONE)
B(-3,-3,-23,STONE)
B(-3,-3,-22,STONE)
B(-3,-3,-21,STONE)
B(-3,-3,-20,STONE)
B(-3,-3,-19,STONE)
B(-3,-3,-18,STONE)
B(-3,-3,-17,STONE)
B(-3,-3,-16,STONE)
B(-3,-3,-15,STONE)
B(-3,-3,-14,AIR)
B(-3,-3,-13,AIR)
B(-3,-3,-12,AIR)
B(-3,-3,-11,AIR)
B(-3,-3,-10,AIR)
B(-3,-3,-9,AIR)
B(-3,-3,-8,AIR)
B(-3,-3,-7,AIR)
B(-3,-3,-6,AIR)
B(-3,-3,-5,AIR)
B(-3,-3,-4,STONE)
B(-3,-3,-3,STONE)
B(-3,-3,-2,STONE)
B(-3,-3,-1,STONE)
B(-3,-3,0,STONE)
B(-3,-3,1,STONE)
B(-3,-3,2,STONE)
B(-3,-2,-23,STONE)
B(-3,-2,-22,STONE)
B(-3,-2,-21,STONE)
B(-3,-2,-20,STONE)
B(-3,-2,-19,STONE)
B(-3,-2,-18,STONE)
B(-3,-2,-17,STONE)
B(-3,-2,-16,STONE)
B(-3,-2,-15,STONE)
B(-3,-2,-14,STONE)
B(-3,-2,-13,STONE)
B(-3,-2,-12,STONE)
B(-3,-2,-11,STONE)
B(-3,-2,-10,AIR)
B(-3,-2,-9,STONE)
B(-3,-2,-8,STONE)
B(-3,-2,-7,STONE)
B(-3,-2,-6,STONE)
B(-3,-2,-5,STONE)
B(-3,-2,-4,STONE)
B(-3,-2,-3,STONE)
B(-3,-2,-2,STONE)
B(-3,-2,-1,STONE)
B(-3,-2,0,STONE)
B(-3,-2,1,STONE)
B(-3,-2,2,STONE)
B(-3,-1,-22,STONE)
B(-3,-1,-21,STONE)
B(-3,-1,-20,STONE)
B(-3,-1,-19,STONE)
B(-3,-1,-18,STONE)
B(-3,-1,-17,STONE)
B(-3,-1,-16,STONE)
B(-3,-1,-15,STONE)
B(-3,-1,-14,STONE)
B(-3,-1,-13,STONE)
B(-3,-1,-12,STONE)
B(-3,-1,-11,STONE)
B(-3,-1,-10,STONE)
B(-3,-1,-9,STONE)
B(-3,-1,-8,STONE)
B(-3,-1,-7,STONE)
B(-3,-1,-6,STONE)
B(-3,-1,-5,STONE)
B(-3,-1,-4,STONE)
B(-3,-1,-3,STONE)
B(-3,-1,-2,STONE)
B(-3,-1,-1,STONE)
B(-3,-1,0,STONE)
B(-3,-1,1,STONE)
B(-3,0,-21,STONE)
B(-3,0,-20,STONE)
B(-3,0,-19,STONE)
B(-3,0,-18,STONE)
B(-3,0,-17,STONE)
B(-3,0,-16,STONE)
B(-3,0,-15,STONE)
B(-3,0,-14,STONE)
B(-3,0,-13,STONE)
B(-3,0,-12,STONE)
B(-3,0,-11,STONE)
B(-3,0,-10,STONE)
B(-3,0,-9,STONE)
B(-3,0,-8,STONE)
B(-3,0,-7,STONE)
B(-3,0,-6,STONE)
B(-3,0,-5,STONE)
B(-3,0,-4,STONE)
B(-3,0,-3,STONE)
B(-3,0,-2,STONE)
B(-3,0,-1,STONE)
B(-3,0,0,STONE)
B(-3,1,-19,STONE)
B(-3,1,-18,STONE)
B(-3,1,-17,STONE)
B(-3,1,-16,STONE)
B(-3,1,-15,STONE)
B(-3,1,-14,STONE)
B(-3,1,-13,STONE)
B(-3,1,-12,STONE)
B(-3,1,-11,STONE)
B(-3,1,-10,STONE)
B(-3,1,-9,STONE)
B(-3,1,-8,STONE)
B(-3,1,-7,STONE)
B(-3,1,-6,STONE)
B(-3,1,-5,STONE)
B(-3,1,-4,STONE)
B(-3,1,-3,STONE)
B(-3,1,-2,STONE)
B(-3,1,-1,STONE)
B(-3,2,-17,STONE)
B(-3,2,-16,STONE)
B(-3,2,-15,STONE)
B(-3,2,-14,STONE)
B(-3,2,-13,STONE)
B(-3,2,-12,STONE)
B(-3,2,-11,STONE)
B(-3,2,-10,STONE)
B(-3,2,-9,STONE)
B(-3,2,-8,STONE)
B(-3,2,-7,STONE)
B(-3,2,-6,STONE)
B(-3,2,-5,STONE)
B(-3,2,-4,STONE)
B(-3,2,-3,STONE)
B(-3,2,-2,STONE)
B(-3,3,-13,STONE)
B(-3,3,-12,STONE)
B(-3,3,-11,STONE)
B(-3,3,-10,STONE)
B(-3,3,-9,STONE)
B(-3,3,-8,STONE)
B(-3,3,-7,STONE)
B(-3,3,-6,STONE)
B(-3,3,-5,STONE)
B(-3,3,-4,STONE)
B(-3,3,-3,STONE)
B(-3,4,-12,STONE)
B(-3,4,-11,STONE)
B(-3,4,-10,STONE)
B(-3,4,-9,STONE)
B(-3,4,-8,STONE)
B(-3,4,-7,STONE)
B(-3,4,-6,STONE)
B(-3,5,-11,STONE)
B(-3,5,-10,STONE)
B(-3,5,-9,STONE)
B(-3,5,-8,STONE)
B(-2,-14,-17,STONE)
B(-2,-14,-16,STONE)
B(-2,-14,-15,STONE)
B(-2,-14,-14,STONE)
B(-2,-14,-13,STONE)
B(-2,-14,-12,STONE)
B(-2,-14,-11,STONE)
B(-2,-14,-10,STONE)
B(-2,-14,-9,STONE)
B(-2,-14,-8,STONE)
B(-2,-14,-7,STONE)
B(-2,-14,-6,STONE)
B(-2,-14,-5,STONE)
B(-2,-14,-4,STONE)
B(-2,-13,-17,STONE)
B(-2,-13,-16,STONE)
B(-2,-13,-15,STONE)
B(-2,-13,-14,STONE)
B(-2,-13,-13,STONE)
B(-2,-13,-12,STONE)
B(-2,-13,-11,STONE)
B(-2,-13,-10,STONE)
B(-2,-13,-9,STONE)
B(-2,-13,-8,STONE)
B(-2,-13,-7,STONE)
B(-2,-13,-6,STONE)
B(-2,-13,-5,STONE)
B(-2,-13,-4,STONE)
B(-2,-13,-3,STONE)
B(-2,-12,-18,STONE)
B(-2,-12,-17,STONE)
B(-2,-12,-16,STONE)
B(-2,-12,-15,STONE)
B(-2,-12,-14,STONE)
B(-2,-12,-13,STONE)
B(-2,-12,-12,STONE)
B(-2,-12,-11,STONE)
B(-2,-12,-10,STONE)
B(-2,-12,-9,STONE)
B(-2,-12,-8,STONE)
B(-2,-12,-7,STONE)
B(-2,-12,-6,STONE)
B(-2,-12,-5,STONE)
B(-2,-12,-4,STONE)
B(-2,-12,-3,STONE)
B(-2,-12,-2,STONE)
B(-2,-11,-19,STONE)
B(-2,-11,-18,STONE)
B(-2,-11,-17,STONE)
B(-2,-11,-16,STONE)
B(-2,-11,-15,STONE)
B(-2,-11,-14,STONE)
B(-2,-11,-13,STONE)
B(-2,-11,-12,STONE)
B(-2,-11,-11,STONE)
B(-2,-11,-10,STONE)
B(-2,-11,-9,STONE)
B(-2,-11,-8,STONE)
B(-2,-11,-7,STONE)
B(-2,-11,-6,STONE)
B(-2,-11,-5,STONE)
B(-2,-11,-4,STONE)
B(-2,-11,-3,STONE)
B(-2,-11,-2,STONE)
B(-2,-10,-20,STONE)
B(-2,-10,-19,STONE)
B(-2,-10,-18,STONE)
B(-2,-10,-17,STONE)
B(-2,-10,-16,STONE)
B(-2,-10,-15,STONE)
B(-2,-10,-14,STONE)
B(-2,-10,-13,STONE)
B(-2,-10,-12,STONE)
B(-2,-10,-11,STONE)
B(-2,-10,-10,STONE)
B(-2,-10,-9,STONE)
B(-2,-10,-8,STONE)
B(-2,-10,-7,STONE)
B(-2,-10,-6,STATIONARY_WATER)
B(-2,-10,-5,STONE)
B(-2,-10,-4,MOSSY_COBBLESTONE)
B(-2,-10,-3,STONE)
B(-2,-10,-2,STONE)
B(-2,-10,-1,STONE)
B(-2,-9,-21,STONE)
B(-2,-9,-20,STONE)
B(-2,-9,-19,STONE)
B(-2,-9,-18,STONE)
B(-2,-9,-17,STONE)
B(-2,-9,-16,STONE)
B(-2,-9,-15,STONE)
B(-2,-9,-14,STONE)
B(-2,-9,-13,STONE)
B(-2,-9,-12,STONE)
B(-2,-9,-11,STONE)
B(-2,-9,-10,STONE)
B(-2,-9,-9,STONE)
B(-2,-9,-8,STONE)
B(-2,-9,-7,STATIONARY_WATER)
B(-2,-9,-6,STATIONARY_WATER)
B(-2,-9,-5,STATIONARY_WATER:8)
B(-2,-9,-4,STONE)
B(-2,-9,-3,STONE)
B(-2,-9,-2,STONE)
B(-2,-9,-1,STONE)
B(-2,-8,-22,STONE)
B(-2,-8,-21,STONE)
B(-2,-8,-20,STONE)
B(-2,-8,-19,STONE)
B(-2,-8,-18,STONE)
B(-2,-8,-17,STONE)
B(-2,-8,-16,STONE)
B(-2,-8,-15,STONE)
B(-2,-8,-14,STONE)
B(-2,-8,-13,STONE)
B(-2,-8,-12,STONE)
B(-2,-8,-11,STONE)
B(-2,-8,-10,STONE)
B(-2,-8,-9,STONE)
B(-2,-8,-8,STATIONARY_WATER)
B(-2,-8,-7,STATIONARY_WATER)
B(-2,-8,-6,STATIONARY_WATER)
B(-2,-8,-5,STATIONARY_WATER)
B(-2,-8,-4,STONE)
B(-2,-8,-3,STONE)
B(-2,-8,-2,STONE)
B(-2,-8,-1,STONE)
B(-2,-7,-22,STONE)
B(-2,-7,-21,STONE)
B(-2,-7,-20,STONE)
B(-2,-7,-19,STONE)
B(-2,-7,-18,STONE)
B(-2,-7,-17,STONE)
B(-2,-7,-16,STONE)
B(-2,-7,-15,AIR)
B(-2,-7,-14,AIR)
B(-2,-7,-13,AIR)
B(-2,-7,-12,AIR)
B(-2,-7,-11,AIR)
RB(-2,-7,-10,CHEST,../../nbt/VanillaLoot/simple_dungeon.nbt,50,CHEST,../../nbt/VanillaLoot/stronghold_crossing.nbt,100)
B(-2,-7,-9,AIR)
B(-2,-7,-8,AIR)
B(-2,-7,-7,AIR)
B(-2,-7,-6,AIR)
B(-2,-7,-5,STONE)
B(-2,-7,-4,STONE)
B(-2,-7,-3,STONE)
B(-2,-7,-2,STONE)
B(-2,-7,-1,STONE)
B(-2,-7,0,STONE)
B(-2,-6,-23,STONE)
B(-2,-6,-22,STONE)
B(-2,-6,-21,STONE)
B(-2,-6,-20,STONE)
B(-2,-6,-19,STONE)
B(-2,-6,-18,STONE)
B(-2,-6,-17,STONE)
B(-2,-6,-16,BROWN_MUSHROOM)
B(-2,-6,-15,AIR)
B(-2,-6,-14,AIR)
B(-2,-6,-13,AIR)
B(-2,-6,-12,AIR)
B(-2,-6,-11,AIR)
B(-2,-6,-10,AIR)
B(-2,-6,-9,AIR)
B(-2,-6,-8,AIR)
B(-2,-6,-7,AIR)
B(-2,-6,-6,AIR)
B(-2,-6,-5,BROWN_MUSHROOM)
B(-2,-6,-4,STONE)
B(-2,-6,-3,STONE)
B(-2,-6,-2,STONE)
B(-2,-6,-1,STONE)
B(-2,-6,0,STONE)
B(-2,-6,1,STONE)
B(-2,-5,-23,STONE)
B(-2,-5,-22,STONE)
B(-2,-5,-21,STONE)
B(-2,-5,-20,STONE)
B(-2,-5,-19,STONE)
B(-2,-5,-18,STONE)
B(-2,-5,-17,BROWN_MUSHROOM)
B(-2,-5,-16,AIR)
B(-2,-5,-15,AIR)
B(-2,-5,-14,AIR)
B(-2,-5,-13,AIR)
B(-2,-5,-12,AIR)
B(-2,-5,-11,AIR)
B(-2,-5,-10,AIR)
B(-2,-5,-9,AIR)
B(-2,-5,-8,AIR)
B(-2,-5,-7,AIR)
B(-2,-5,-6,AIR)
B(-2,-5,-5,AIR)
B(-2,-5,-4,AIR)
B(-2,-5,-3,STONE)
B(-2,-5,-2,STONE)
B(-2,-5,-1,STONE)
B(-2,-5,0,STONE)
B(-2,-5,1,STONE)
B(-2,-5,2,STONE)
B(-2,-4,-23,STONE)
B(-2,-4,-22,STONE)
B(-2,-4,-21,STONE)
B(-2,-4,-20,STONE)
B(-2,-4,-19,STONE)
B(-2,-4,-18,STONE)
B(-2,-4,-17,AIR)
B(-2,-4,-16,AIR)
B(-2,-4,-15,VINE:6)
B(-2,-4,-14,AIR)
B(-2,-4,-13,AIR)
B(-2,-4,-12,AIR)
B(-2,-4,-11,AIR)
B(-2,-4,-10,AIR)
B(-2,-4,-9,AIR)
B(-2,-4,-8,AIR)
B(-2,-4,-7,AIR)
B(-2,-4,-6,AIR)
B(-2,-4,-5,AIR)
B(-2,-4,-4,STONE)
B(-2,-4,-3,STONE)
B(-2,-4,-2,STONE)
B(-2,-4,-1,STONE)
B(-2,-4,0,STONE)
B(-2,-4,1,STONE)
B(-2,-4,2,STONE)
B(-2,-3,-23,STONE)
B(-2,-3,-22,STONE)
B(-2,-3,-21,STONE)
B(-2,-3,-20,STONE)
B(-2,-3,-19,STONE)
B(-2,-3,-18,STONE)
B(-2,-3,-17,STONE)
B(-2,-3,-16,STONE)
B(-2,-3,-15,VINE:6)
B(-2,-3,-14,AIR)
B(-2,-3,-13,AIR)
B(-2,-3,-12,AIR)
B(-2,-3,-11,AIR)
B(-2,-3,-10,AIR)
B(-2,-3,-9,AIR)
B(-2,-3,-8,AIR)
B(-2,-3,-7,AIR)
B(-2,-3,-6,AIR)
B(-2,-3,-5,AIR)
B(-2,-3,-4,STONE)
B(-2,-3,-3,STONE)
B(-2,-3,-2,STONE)
B(-2,-3,-1,STONE)
B(-2,-3,0,STONE)
B(-2,-3,1,STONE)
B(-2,-3,2,STONE)
B(-2,-2,-23,STONE)
B(-2,-2,-22,STONE)
B(-2,-2,-21,STONE)
B(-2,-2,-20,STONE)
B(-2,-2,-19,STONE)
B(-2,-2,-18,STONE)
B(-2,-2,-17,STONE)
B(-2,-2,-16,STONE)
B(-2,-2,-15,STONE)
B(-2,-2,-14,AIR)
B(-2,-2,-13,AIR)
B(-2,-2,-12,AIR)
B(-2,-2,-11,AIR)
B(-2,-2,-10,AIR)
B(-2,-2,-9,AIR)
B(-2,-2,-8,STONE)
B(-2,-2,-7,AIR)
B(-2,-2,-6,STONE)
B(-2,-2,-5,STONE)
B(-2,-2,-4,STONE)
B(-2,-2,-3,STONE)
B(-2,-2,-2,STONE)
B(-2,-2,-1,STONE)
B(-2,-2,0,STONE)
B(-2,-2,1,STONE)
B(-2,-2,2,STONE)
B(-2,-1,-22,STONE)
B(-2,-1,-21,STONE)
B(-2,-1,-20,STONE)
B(-2,-1,-19,STONE)
B(-2,-1,-18,STONE)
B(-2,-1,-17,STONE)
B(-2,-1,-16,STONE)
B(-2,-1,-15,STONE)
B(-2,-1,-14,STONE)
B(-2,-1,-13,STONE)
B(-2,-1,-12,STONE)
B(-2,-1,-11,STONE)
B(-2,-1,-10,STONE)
B(-2,-1,-9,STONE)
B(-2,-1,-8,STONE)
B(-2,-1,-7,STONE)
B(-2,-1,-6,STONE)
B(-2,-1,-5,STONE)
B(-2,-1,-4,STONE)
B(-2,-1,-3,STONE)
B(-2,-1,-2,STONE)
B(-2,-1,-1,STONE)
B(-2,-1,0,STONE)
B(-2,-1,1,STONE)
B(-2,-1,2,STONE)
B(-2,0,-21,STONE)
B(-2,0,-20,STONE)
B(-2,0,-19,STONE)
B(-2,0,-18,STONE)
B(-2,0,-17,STONE)
B(-2,0,-16,STONE)
B(-2,0,-15,STONE)
B(-2,0,-14,STONE)
B(-2,0,-13,STONE)
B(-2,0,-12,STONE)
B(-2,0,-11,STONE)
B(-2,0,-10,STONE)
B(-2,0,-9,STONE)
B(-2,0,-8,STONE)
B(-2,0,-7,STONE)
B(-2,0,-6,STONE)
B(-2,0,-5,STONE)
B(-2,0,-4,STONE)
B(-2,0,-3,STONE)
B(-2,0,-2,STONE)
B(-2,0,-1,STONE)
B(-2,0,0,STONE)
B(-2,0,1,STONE)
B(-2,1,-20,STONE)
B(-2,1,-19,STONE)
B(-2,1,-18,STONE)
B(-2,1,-17,STONE)
B(-2,1,-16,STONE)
B(-2,1,-15,STONE)
B(-2,1,-14,STONE)
B(-2,1,-13,STONE)
B(-2,1,-12,STONE)
B(-2,1,-11,STONE)
B(-2,1,-10,STONE)
B(-2,1,-9,STONE)
B(-2,1,-8,STONE)
B(-2,1,-7,STONE)
B(-2,1,-6,STONE)
B(-2,1,-5,STONE)
B(-2,1,-4,STONE)
B(-2,1,-3,STONE)
B(-2,1,-2,STONE)
B(-2,1,-1,STONE)
B(-2,1,0,STONE)
B(-2,2,-17,STONE)
B(-2,2,-16,STONE)
B(-2,2,-15,STONE)
B(-2,2,-14,STONE)
B(-2,2,-13,STONE)
B(-2,2,-12,STONE)
B(-2,2,-11,STONE)
B(-2,2,-10,STONE)
B(-2,2,-9,STONE)
B(-2,2,-8,STONE)
B(-2,2,-7,STONE)
B(-2,2,-6,STONE)
B(-2,2,-5,STONE)
B(-2,2,-4,STONE)
B(-2,2,-3,STONE)
B(-2,2,-2,STONE)
B(-2,3,-15,STONE)
B(-2,3,-14,STONE)
B(-2,3,-13,STONE)
B(-2,3,-12,STONE)
B(-2,3,-11,STONE)
B(-2,3,-10,STONE)
B(-2,3,-9,STONE)
B(-2,3,-8,STONE)
B(-2,3,-7,STONE)
B(-2,3,-6,STONE)
B(-2,3,-5,STONE)
B(-2,3,-4,STONE)
B(-2,3,-3,STONE)
B(-2,4,-13,STONE)
B(-2,4,-12,STONE)
B(-2,4,-11,STONE)
B(-2,4,-10,STONE)
B(-2,4,-9,STONE)
B(-2,4,-8,STONE)
B(-2,4,-7,STONE)
B(-2,4,-6,STONE)
B(-2,4,-5,STONE)
B(-2,5,-12,STONE)
B(-2,5,-11,STONE)
B(-2,5,-10,STONE)
B(-2,5,-9,STONE)
B(-2,5,-8,STONE)
B(-2,5,-7,STONE)
B(-1,-14,-17,STONE)
B(-1,-14,-16,STONE)
B(-1,-14,-15,STONE)
B(-1,-14,-14,STONE)
B(-1,-14,-13,STONE)
B(-1,-14,-12,STONE)
B(-1,-14,-11,STONE)
B(-1,-14,-10,STONE)
B(-1,-14,-9,STONE)
B(-1,-14,-8,STONE)
B(-1,-14,-7,STONE)
B(-1,-14,-6,STONE)
B(-1,-14,-5,STONE)
B(-1,-14,-4,STONE)
B(-1,-14,-3,STONE)
B(-1,-13,-18,STONE)
B(-1,-13,-17,STONE)
B(-1,-13,-16,STONE)
B(-1,-13,-15,STONE)
B(-1,-13,-14,STONE)
B(-1,-13,-13,STONE)
B(-1,-13,-12,STONE)
B(-1,-13,-11,STONE)
B(-1,-13,-10,STONE)
B(-1,-13,-9,STONE)
B(-1,-13,-8,STONE)
B(-1,-13,-7,STONE)
B(-1,-13,-6,STONE)
B(-1,-13,-5,STONE)
B(-1,-13,-4,STONE)
B(-1,-13,-3,STONE)
B(-1,-13,-2,STONE)
B(-1,-12,-19,STONE)
B(-1,-12,-18,STONE)
B(-1,-12,-17,STONE)
B(-1,-12,-16,STONE)
B(-1,-12,-15,STONE)
B(-1,-12,-14,STONE)
B(-1,-12,-13,STONE)
B(-1,-12,-12,STONE)
B(-1,-12,-11,STONE)
B(-1,-12,-10,STONE)
B(-1,-12,-9,STONE)
B(-1,-12,-8,STONE)
B(-1,-12,-7,STONE)
B(-1,-12,-6,STONE)
B(-1,-12,-5,STONE)
B(-1,-12,-4,STONE)
B(-1,-12,-3,STONE)
B(-1,-12,-2,STONE)
B(-1,-11,-20,STONE)
B(-1,-11,-19,STONE)
B(-1,-11,-18,STONE)
B(-1,-11,-17,STONE)
B(-1,-11,-16,STONE)
B(-1,-11,-15,STONE)
B(-1,-11,-14,STONE)
B(-1,-11,-13,STONE)
B(-1,-11,-12,STONE)
B(-1,-11,-11,STONE)
B(-1,-11,-10,STONE)
B(-1,-11,-9,STONE)
B(-1,-11,-8,STONE)
B(-1,-11,-7,STONE)
B(-1,-11,-6,STONE)
B(-1,-11,-5,STONE)
B(-1,-11,-4,STONE)
B(-1,-11,-3,STONE)
B(-1,-11,-2,STONE)
B(-1,-10,-22,STONE)
B(-1,-10,-21,STONE)
B(-1,-10,-20,STONE)
B(-1,-10,-19,STONE)
B(-1,-10,-18,STONE)
B(-1,-10,-17,STONE)
B(-1,-10,-16,STONE)
B(-1,-10,-15,STONE)
B(-1,-10,-14,STONE)
B(-1,-10,-13,STONE)
B(-1,-10,-12,STONE)
B(-1,-10,-11,STONE)
B(-1,-10,-10,STONE)
B(-1,-10,-9,STONE)
B(-1,-10,-8,STONE)
B(-1,-10,-7,STONE)
B(-1,-10,-6,STONE)
B(-1,-10,-5,STONE)
B(-1,-10,-4,STONE)
B(-1,-10,-3,STONE)
B(-1,-10,-2,STONE)
B(-1,-10,-1,STONE)
B(-1,-9,-21,STONE)
B(-1,-9,-20,STONE)
B(-1,-9,-19,STONE)
B(-1,-9,-18,STONE)
B(-1,-9,-17,STONE)
B(-1,-9,-16,STONE)
B(-1,-9,-15,STONE)
B(-1,-9,-14,STONE)
B(-1,-9,-13,STATIONARY_WATER)
B(-1,-9,-12,STATIONARY_WATER)
B(-1,-9,-11,STONE)
B(-1,-9,-10,STONE)
B(-1,-9,-9,STONE)
B(-1,-9,-8,STONE)
B(-1,-9,-7,STONE)
B(-1,-9,-6,STONE)
B(-1,-9,-5,STONE)
B(-1,-9,-4,STONE)
B(-1,-9,-3,STONE)
B(-1,-9,-2,STONE)
B(-1,-9,-1,STONE)
B(-1,-8,-22,STONE)
B(-1,-8,-21,STONE)
B(-1,-8,-20,STONE)
B(-1,-8,-19,STONE)
B(-1,-8,-18,STONE)
B(-1,-8,-17,STONE)
B(-1,-8,-16,STONE)
B(-1,-8,-15,STATIONARY_WATER)
B(-1,-8,-14,STATIONARY_WATER)
B(-1,-8,-13,STATIONARY_WATER)
B(-1,-8,-12,STATIONARY_WATER)
B(-1,-8,-11,STATIONARY_WATER)
B(-1,-8,-10,STONE)
B(-1,-8,-9,STONE)
B(-1,-8,-8,STONE)
B(-1,-8,-7,STONE)
B(-1,-8,-6,MOSSY_COBBLESTONE)
B(-1,-8,-5,STONE)
B(-1,-8,-4,STONE)
B(-1,-8,-3,STONE)
B(-1,-8,-2,STONE)
B(-1,-8,-1,STONE)
B(-1,-7,-22,STONE)
B(-1,-7,-21,STONE)
B(-1,-7,-20,STONE)
B(-1,-7,-19,STONE)
B(-1,-7,-18,STONE)
B(-1,-7,-17,AIR)
B(-1,-7,-16,AIR)
B(-1,-7,-15,AIR)
B(-1,-7,-14,AIR)
B(-1,-7,-13,AIR)
B(-1,-7,-12,AIR)
B(-1,-7,-11,AIR)
B(-1,-7,-10,RED_MUSHROOM)
B(-1,-7,-9,AIR)
B(-1,-7,-8,AIR)
B(-1,-7,-7,AIR)
B(-1,-7,-6,AIR)
B(-1,-7,-5,STONE)
B(-1,-7,-4,STONE)
B(-1,-7,-3,STONE)
B(-1,-7,-2,STONE)
B(-1,-7,-1,STONE)
B(-1,-7,0,STONE)
B(-1,-6,-23,STONE)
B(-1,-6,-22,STONE)
B(-1,-6,-21,STONE)
B(-1,-6,-20,STONE)
B(-1,-6,-19,STONE)
B(-1,-6,-18,STONE)
B(-1,-6,-17,AIR)
B(-1,-6,-16,AIR)
B(-1,-6,-15,AIR)
B(-1,-6,-14,AIR)
B(-1,-6,-13,AIR)
B(-1,-6,-12,AIR)
B(-1,-6,-11,AIR)
B(-1,-6,-10,AIR)
B(-1,-6,-9,AIR)
B(-1,-6,-8,AIR)
B(-1,-6,-7,AIR)
B(-1,-6,-6,AIR)
B(-1,-6,-5,VINE:1)
B(-1,-6,-4,STONE)
B(-1,-6,-3,STONE)
B(-1,-6,-2,STONE)
B(-1,-6,-1,STONE)
B(-1,-6,0,STONE)
B(-1,-5,-23,STONE)
B(-1,-5,-22,STONE)
B(-1,-5,-21,STONE)
B(-1,-5,-20,STONE)
B(-1,-5,-19,STONE)
B(-1,-5,-18,STONE)
B(-1,-5,-17,AIR)
B(-1,-5,-16,AIR)
B(-1,-5,-15,AIR)
B(-1,-5,-14,AIR)
B(-1,-5,-13,AIR)
B(-1,-5,-12,AIR)
B(-1,-5,-11,AIR)
B(-1,-5,-10,AIR)
B(-1,-5,-9,AIR)
B(-1,-5,-8,AIR)
B(-1,-5,-7,AIR)
B(-1,-5,-6,AIR)
B(-1,-5,-5,VINE:1)
B(-1,-5,-4,STONE)
B(-1,-5,-3,STONE)
B(-1,-5,-2,STONE)
B(-1,-5,-1,STONE)
B(-1,-5,0,STONE)
B(-1,-5,1,STONE)
B(-1,-4,-23,STONE)
B(-1,-4,-22,STONE)
B(-1,-4,-21,STONE)
B(-1,-4,-20,STONE)
B(-1,-4,-19,STONE)
B(-1,-4,-18,STONE)
B(-1,-4,-17,AIR)
B(-1,-4,-16,AIR)
B(-1,-4,-15,AIR)
B(-1,-4,-14,AIR)
B(-1,-4,-13,AIR)
B(-1,-4,-12,AIR)
B(-1,-4,-11,AIR)
B(-1,-4,-10,AIR)
B(-1,-4,-9,AIR)
B(-1,-4,-8,AIR)
B(-1,-4,-7,AIR)
B(-1,-4,-6,AIR)
B(-1,-4,-5,AIR)
B(-1,-4,-4,STONE)
B(-1,-4,-3,STONE)
B(-1,-4,-2,STONE)
B(-1,-4,-1,STONE)
B(-1,-4,0,STONE)
B(-1,-4,1,STONE)
B(-1,-4,2,STONE)
B(-1,-3,-23,STONE)
B(-1,-3,-22,STONE)
B(-1,-3,-21,STONE)
B(-1,-3,-20,STONE)
B(-1,-3,-19,STONE)
B(-1,-3,-18,STONE)
B(-1,-3,-17,STONE)
B(-1,-3,-16,VINE:6)
B(-1,-3,-15,AIR)
B(-1,-3,-14,AIR)
B(-1,-3,-13,AIR)
B(-1,-3,-12,AIR)
B(-1,-3,-11,AIR)
B(-1,-3,-10,AIR)
B(-1,-3,-9,AIR)
B(-1,-3,-8,AIR)
B(-1,-3,-7,AIR)
B(-1,-3,-6,VINE:1)
B(-1,-3,-5,STONE)
B(-1,-3,-4,STONE)
B(-1,-3,-3,STONE)
B(-1,-3,-2,STONE)
B(-1,-3,-1,STONE)
B(-1,-3,0,STONE)
B(-1,-3,1,STONE)
B(-1,-3,2,STONE)
B(-1,-2,-23,STONE)
B(-1,-2,-22,STONE)
B(-1,-2,-21,STONE)
B(-1,-2,-20,STONE)
B(-1,-2,-19,STONE)
B(-1,-2,-18,STONE)
B(-1,-2,-17,STONE)
B(-1,-2,-16,STONE)
B(-1,-2,-15,STONE)
B(-1,-2,-14,AIR)
B(-1,-2,-13,AIR)
B(-1,-2,-12,AIR)
B(-1,-2,-11,AIR)
B(-1,-2,-10,AIR)
B(-1,-2,-9,AIR)
B(-1,-2,-8,AIR)
B(-1,-2,-7,AIR)
B(-1,-2,-6,STONE)
B(-1,-2,-5,STONE)
B(-1,-2,-4,STONE)
B(-1,-2,-3,STONE)
B(-1,-2,-2,STONE)
B(-1,-2,-1,STONE)
B(-1,-2,0,STONE)
B(-1,-2,1,STONE)
B(-1,-2,2,STONE)
B(-1,-1,-22,STONE)
B(-1,-1,-21,STONE)
B(-1,-1,-20,STONE)
B(-1,-1,-19,STONE)
B(-1,-1,-18,STONE)
B(-1,-1,-17,STONE)
B(-1,-1,-16,STONE)
B(-1,-1,-15,STONE)
B(-1,-1,-14,STONE)
B(-1,-1,-13,STONE)
B(-1,-1,-12,AIR)
B(-1,-1,-11,AIR)
B(-1,-1,-10,AIR)
B(-1,-1,-9,AIR)
B(-1,-1,-8,STONE)
B(-1,-1,-7,STONE)
B(-1,-1,-6,STONE)
B(-1,-1,-5,STONE)
B(-1,-1,-4,STONE)
B(-1,-1,-3,STONE)
B(-1,-1,-2,STONE)
B(-1,-1,-1,STONE)
B(-1,-1,0,STONE)
B(-1,-1,1,STONE)
B(-1,0,-21,STONE)
B(-1,0,-20,STONE)
B(-1,0,-19,STONE)
B(-1,0,-18,STONE)
B(-1,0,-17,STONE)
B(-1,0,-16,STONE)
B(-1,0,-15,STONE)
B(-1,0,-14,STONE)
B(-1,0,-13,STONE)
B(-1,0,-12,STONE)
B(-1,0,-11,STONE)
B(-1,0,-10,STONE)
B(-1,0,-9,STONE)
B(-1,0,-8,STONE)
B(-1,0,-7,STONE)
B(-1,0,-6,STONE)
B(-1,0,-5,STONE)
B(-1,0,-4,STONE)
B(-1,0,-3,STONE)
B(-1,0,-2,STONE)
B(-1,0,-1,STONE)
B(-1,0,0,STONE)
B(-1,0,1,STONE)
B(-1,1,-20,STONE)
B(-1,1,-19,STONE)
B(-1,1,-18,STONE)
B(-1,1,-17,STONE)
B(-1,1,-16,STONE)
B(-1,1,-15,STONE)
B(-1,1,-14,STONE)
B(-1,1,-13,STONE)
B(-1,1,-12,STONE)
B(-1,1,-11,STONE)
B(-1,1,-10,STONE)
B(-1,1,-9,STONE)
B(-1,1,-8,STONE)
B(-1,1,-7,STONE)
B(-1,1,-6,STONE)
B(-1,1,-5,STONE)
B(-1,1,-4,STONE)
B(-1,1,-3,STONE)
B(-1,1,-2,STONE)
B(-1,1,-1,STONE)
B(-1,1,0,STONE)
B(-1,2,-18,STONE)
B(-1,2,-17,STONE)
B(-1,2,-16,STONE)
B(-1,2,-15,STONE)
B(-1,2,-14,STONE)
B(-1,2,-13,STONE)
B(-1,2,-12,STONE)
B(-1,2,-11,STONE)
B(-1,2,-10,STONE)
B(-1,2,-9,STONE)
B(-1,2,-8,STONE)
B(-1,2,-7,STONE)
B(-1,2,-6,STONE)
B(-1,2,-5,STONE)
B(-1,2,-4,STONE)
B(-1,2,-3,STONE)
B(-1,2,-2,STONE)
B(-1,2,-1,STONE)
B(-1,3,-16,STONE)
B(-1,3,-15,STONE)
B(-1,3,-14,STONE)
B(-1,3,-13,STONE)
B(-1,3,-12,STONE)
B(-1,3,-11,STONE)
B(-1,3,-10,STONE)
B(-1,3,-9,STONE)
B(-1,3,-8,STONE)
B(-1,3,-7,STONE)
B(-1,3,-6,STONE)
B(-1,3,-5,STONE)
B(-1,3,-4,STONE)
B(-1,3,-3,STONE)
B(-1,4,-15,STONE)
B(-1,4,-14,STONE)
B(-1,4,-13,STONE)
B(-1,4,-12,STONE)
B(-1,4,-11,STONE)
B(-1,4,-10,STONE)
B(-1,4,-9,STONE)
B(-1,4,-8,STONE)
B(-1,4,-7,STONE)
B(-1,4,-6,STONE)
B(-1,4,-5,STONE)
B(-1,4,-4,STONE)
B(-1,5,-14,STONE)
B(-1,5,-13,STONE)
B(-1,5,-12,STONE)
B(-1,5,-11,STONE)
B(-1,5,-10,STONE)
B(-1,5,-9,STONE)
B(-1,5,-8,STONE)
B(-1,5,-7,STONE)
B(-1,5,-6,STONE)
B(-1,6,-11,STONE)
B(-1,6,-10,STONE)
B(-1,6,-9,STONE)
B(-1,6,-8,STONE)
B(0,-14,-18,STONE)
B(0,-14,-17,STONE)
B(0,-14,-16,STONE)
B(0,-14,-15,STONE)
B(0,-14,-14,STONE)
B(0,-14,-13,STONE)
B(0,-14,-12,STONE)
B(0,-14,-11,STONE)
B(0,-14,-10,STONE)
B(0,-14,-9,STONE)
B(0,-14,-8,STONE)
B(0,-14,-7,STONE)
B(0,-14,-6,STONE)
B(0,-14,-5,STONE)
B(0,-14,-4,STONE)
B(0,-14,-3,STONE)
B(0,-13,-19,STONE)
B(0,-13,-18,STONE)
B(0,-13,-17,STONE)
B(0,-13,-16,STONE)
B(0,-13,-15,STONE)
B(0,-13,-14,STONE)
B(0,-13,-13,STONE)
B(0,-13,-12,STONE)
B(0,-13,-11,STONE)
B(0,-13,-10,STONE)
B(0,-13,-9,STONE)
B(0,-13,-8,STONE)
B(0,-13,-7,STONE)
B(0,-13,-6,STONE)
B(0,-13,-5,STONE)
B(0,-13,-4,STONE)
B(0,-13,-3,STONE)
B(0,-13,-2,STONE)
B(0,-12,-19,STONE)
B(0,-12,-18,STONE)
B(0,-12,-17,STONE)
B(0,-12,-16,STONE)
B(0,-12,-15,STONE)
B(0,-12,-14,STONE)
B(0,-12,-13,STONE)
B(0,-12,-12,STONE)
B(0,-12,-11,STONE)
B(0,-12,-10,STONE)
B(0,-12,-9,STONE)
B(0,-12,-8,STONE)
B(0,-12,-7,STONE)
B(0,-12,-6,STONE)
B(0,-12,-5,STONE)
B(0,-12,-4,STONE)
B(0,-12,-3,STONE)
B(0,-12,-2,STONE)
B(0,-11,-21,STONE)
B(0,-11,-20,STONE)
B(0,-11,-19,STONE)
B(0,-11,-18,STONE)
B(0,-11,-17,STONE)
B(0,-11,-16,STONE)
B(0,-11,-15,STONE)
B(0,-11,-14,STONE)
B(0,-11,-13,STONE)
B(0,-11,-12,STONE)
B(0,-11,-11,STONE)
B(0,-11,-10,STONE)
B(0,-11,-9,STONE)
B(0,-11,-8,STONE)
B(0,-11,-7,STONE)
B(0,-11,-6,STONE)
B(0,-11,-5,STONE)
B(0,-11,-4,STONE)
B(0,-11,-3,STONE)
B(0,-11,-2,STONE)
B(0,-11,-1,STONE)
B(0,-10,-21,STONE)
B(0,-10,-20,STONE)
B(0,-10,-19,STONE)
B(0,-10,-18,STONE)
B(0,-10,-17,STONE)
B(0,-10,-16,STONE)
B(0,-10,-15,STONE)
B(0,-10,-14,STONE)
B(0,-10,-13,STATIONARY_WATER)
B(0,-10,-12,STATIONARY_WATER)
B(0,-10,-11,STATIONARY_WATER)
B(0,-10,-10,STONE)
B(0,-10,-9,STONE)
B(0,-10,-8,STONE)
B(0,-10,-7,STONE)
B(0,-10,-6,STONE)
B(0,-10,-5,STONE)
B(0,-10,-4,STONE)
B(0,-10,-3,STONE)
B(0,-10,-2,STONE)
B(0,-10,-1,STONE)
B(0,-9,-22,STONE)
B(0,-9,-21,STONE)
B(0,-9,-20,STONE)
B(0,-9,-19,STONE)
B(0,-9,-18,STONE)
B(0,-9,-17,STONE)
B(0,-9,-16,STONE)
B(0,-9,-15,STONE)
B(0,-9,-14,STONE)
B(0,-9,-13,STATIONARY_WATER)
B(0,-9,-12,STATIONARY_WATER)
B(0,-9,-11,STATIONARY_WATER)
B(0,-9,-10,STATIONARY_WATER)
B(0,-9,-9,STONE)
B(0,-9,-8,STONE)
B(0,-9,-7,STONE)
B(0,-9,-6,STONE)
B(0,-9,-5,STONE)
B(0,-9,-4,STONE)
B(0,-9,-3,STONE)
B(0,-9,-2,STONE)
B(0,-9,-1,STONE)
B(0,-8,-22,STONE)
B(0,-8,-21,STONE)
B(0,-8,-20,STONE)
B(0,-8,-19,STONE)
B(0,-8,-18,STONE)
B(0,-8,-17,STONE)
B(0,-8,-16,STONE)
B(0,-8,-15,STATIONARY_WATER)
B(0,-8,-14,STATIONARY_WATER)
B(0,-8,-13,STATIONARY_WATER)
B(0,-8,-12,STATIONARY_WATER)
B(0,-8,-11,STATIONARY_WATER)
B(0,-8,-10,STATIONARY_WATER)
B(0,-8,-9,STONE)
B(0,-8,-8,STONE)
B(0,-8,-7,STONE)
B(0,-8,-6,STONE)
B(0,-8,-5,STONE)
B(0,-8,-4,STONE)
B(0,-8,-3,STONE)
B(0,-8,-2,STONE)
B(0,-8,-1,STONE)
B(0,-7,-22,STONE)
B(0,-7,-21,STONE)
B(0,-7,-20,STONE)
B(0,-7,-19,STONE)
B(0,-7,-18,STONE)
B(0,-7,-17,AIR)
B(0,-7,-16,AIR)
B(0,-7,-15,AIR)
B(0,-7,-14,AIR)
B(0,-7,-13,AIR)
B(0,-7,-12,AIR)
B(0,-7,-11,AIR)
B(0,-7,-10,AIR)
B(0,-7,-9,AIR)
B(0,-7,-8,RED_MUSHROOM)
B(0,-7,-7,STONE)
B(0,-7,-6,STONE)
B(0,-7,-5,STONE)
B(0,-7,-4,STONE)
B(0,-7,-3,STONE)
B(0,-7,-2,STONE)
B(0,-7,-1,STONE)
B(0,-6,-23,STONE)
B(0,-6,-22,STONE)
B(0,-6,-21,STONE)
B(0,-6,-20,STONE)
B(0,-6,-19,STONE)
B(0,-6,-18,STONE)
B(0,-6,-17,AIR)
B(0,-6,-16,AIR)
B(0,-6,-15,AIR)
B(0,-6,-14,AIR)
B(0,-6,-13,AIR)
B(0,-6,-12,AIR)
B(0,-6,-11,AIR)
B(0,-6,-10,AIR)
B(0,-6,-9,AIR)
B(0,-6,-8,AIR)
B(0,-6,-7,AIR)
B(0,-6,-6,STONE)
B(0,-6,-5,STONE)
B(0,-6,-4,STONE)
B(0,-6,-3,STONE)
B(0,-6,-2,STONE)
B(0,-6,-1,STONE)
B(0,-6,0,STONE)
B(0,-5,-23,STONE)
B(0,-5,-22,STONE)
B(0,-5,-21,STONE)
B(0,-5,-20,STONE)
B(0,-5,-19,STONE)
B(0,-5,-18,STONE)
B(0,-5,-17,AIR)
B(0,-5,-16,AIR)
B(0,-5,-15,AIR)
B(0,-5,-14,AIR)
B(0,-5,-13,AIR)
B(0,-5,-12,AIR)
B(0,-5,-11,AIR)
B(0,-5,-10,AIR)
B(0,-5,-9,AIR)
B(0,-5,-8,AIR)
B(0,-5,-7,AIR)
B(0,-5,-6,VINE:1)
B(0,-5,-5,STONE)
B(0,-5,-4,STONE)
B(0,-5,-3,STONE)
B(0,-5,-2,STONE)
B(0,-5,-1,STONE)
B(0,-5,0,STONE)
B(0,-5,1,STONE)
B(0,-4,-23,STONE)
B(0,-4,-22,STONE)
B(0,-4,-21,STONE)
B(0,-4,-20,STONE)
B(0,-4,-19,STONE)
B(0,-4,-18,STONE)
B(0,-4,-17,STONE)
B(0,-4,-16,AIR)
B(0,-4,-15,AIR)
B(0,-4,-14,AIR)
B(0,-4,-13,AIR)
B(0,-4,-12,AIR)
B(0,-4,-11,AIR)
B(0,-4,-10,AIR)
B(0,-4,-9,AIR)
B(0,-4,-8,AIR)
B(0,-4,-7,AIR)
B(0,-4,-6,AIR)
B(0,-4,-5,AIR)
B(0,-4,-4,STONE)
B(0,-4,-3,STONE)
B(0,-4,-2,STONE)
B(0,-4,-1,STONE)
B(0,-4,0,STONE)
B(0,-4,1,STONE)
B(0,-3,-23,STONE)
B(0,-3,-22,STONE)
B(0,-3,-21,STONE)
B(0,-3,-20,STONE)
B(0,-3,-19,STONE)
B(0,-3,-18,STONE)
B(0,-3,-17,STONE)
B(0,-3,-16,VINE:4)
B(0,-3,-15,AIR)
B(0,-3,-14,AIR)
B(0,-3,-13,AIR)
B(0,-3,-12,AIR)
B(0,-3,-11,AIR)
B(0,-3,-10,AIR)
B(0,-3,-9,AIR)
B(0,-3,-8,AIR)
B(0,-3,-7,AIR)
B(0,-3,-6,AIR)
B(0,-3,-5,AIR)
B(0,-3,-4,STONE)
B(0,-3,-3,STONE)
B(0,-3,-2,STONE)
B(0,-3,-1,STONE)
B(0,-3,0,STONE)
B(0,-3,1,STONE)
B(0,-2,-23,STONE)
B(0,-2,-22,STONE)
B(0,-2,-21,STONE)
B(0,-2,-20,STONE)
B(0,-2,-19,STONE)
B(0,-2,-18,STONE)
B(0,-2,-17,STONE)
B(0,-2,-16,STONE)
B(0,-2,-15,AIR)
B(0,-2,-14,AIR)
B(0,-2,-13,AIR)
B(0,-2,-12,AIR)
B(0,-2,-11,AIR)
B(0,-2,-10,AIR)
B(0,-2,-9,AIR)
B(0,-2,-8,AIR)
B(0,-2,-7,AIR)
B(0,-2,-6,AIR)
B(0,-2,-5,STONE)
B(0,-2,-4,STONE)
B(0,-2,-3,STONE)
B(0,-2,-2,STONE)
B(0,-2,-1,STONE)
B(0,-2,0,STONE)
B(0,-2,1,STONE)
B(0,-1,-22,STONE)
B(0,-1,-21,STONE)
B(0,-1,-20,STONE)
B(0,-1,-19,STONE)
B(0,-1,-18,STONE)
B(0,-1,-17,STONE)
B(0,-1,-16,STONE)
B(0,-1,-15,STONE)
B(0,-1,-14,STONE)
B(0,-1,-13,AIR)
B(0,-1,-12,AIR)
B(0,-1,-11,AIR)
B(0,-1,-10,AIR)
B(0,-1,-9,AIR)
B(0,-1,-8,AIR)
B(0,-1,-7,STONE)
B(0,-1,-6,STONE)
B(0,-1,-5,STONE)
B(0,-1,-4,STONE)
B(0,-1,-3,STONE)
B(0,-1,-2,STONE)
B(0,-1,-1,STONE)
B(0,-1,0,STONE)
B(0,-1,1,STONE)
B(0,0,-21,STONE)
B(0,0,-20,STONE)
B(0,0,-19,STONE)
B(0,0,-18,STONE)
B(0,0,-17,STONE)
B(0,0,-16,STONE)
B(0,0,-15,STONE)
B(0,0,-14,STONE)
B(0,0,-13,STONE)
B(0,0,-12,STONE)
B(0,0,-11,STONE)
B(0,0,-10,STONE)
B(0,0,-9,STONE)
B(0,0,-8,STONE)
B(0,0,-7,STONE)
B(0,0,-6,STONE)
B(0,0,-5,STONE)
B(0,0,-4,STONE)
B(0,0,-3,STONE)
B(0,0,-2,STONE)
B(0,0,-1,STONE)
B(0,0,0,STONE)
B(0,1,-21,STONE)
B(0,1,-20,STONE)
B(0,1,-19,STONE)
B(0,1,-18,STONE)
B(0,1,-17,STONE)
B(0,1,-16,STONE)
B(0,1,-15,STONE)
B(0,1,-14,STONE)
B(0,1,-13,STONE)
B(0,1,-12,STONE)
B(0,1,-11,STONE)
B(0,1,-10,STONE)
B(0,1,-9,STONE)
B(0,1,-8,STONE)
B(0,1,-7,STONE)
B(0,1,-6,STONE)
B(0,1,-5,STONE)
B(0,1,-4,STONE)
B(0,1,-3,STONE)
B(0,1,-2,STONE)
B(0,1,-1,STONE)
B(0,1,0,STONE)
B(0,2,-18,STONE)
B(0,2,-17,STONE)
B(0,2,-16,STONE)
B(0,2,-15,STONE)
B(0,2,-14,STONE)
B(0,2,-13,STONE)
B(0,2,-12,STONE)
B(0,2,-11,STONE)
B(0,2,-10,STONE)
B(0,2,-9,STONE)
B(0,2,-8,STONE)
B(0,2,-7,STONE)
B(0,2,-6,STONE)
B(0,2,-5,STONE)
B(0,2,-4,STONE)
B(0,2,-3,STONE)
B(0,2,-2,STONE)
B(0,2,-1,STONE)
B(0,3,-17,STONE)
B(0,3,-16,STONE)
B(0,3,-15,STONE)
B(0,3,-14,STONE)
B(0,3,-13,STONE)
B(0,3,-12,STONE)
B(0,3,-11,STONE)
B(0,3,-10,STONE)
B(0,3,-9,STONE)
B(0,3,-8,STONE)
B(0,3,-7,STONE)
B(0,3,-6,STONE)
B(0,3,-5,STONE)
B(0,3,-4,STONE)
B(0,3,-3,STONE)
B(0,3,-2,STONE)
B(0,4,-16,STONE)
B(0,4,-15,STONE)
B(0,4,-14,STONE)
B(0,4,-13,STONE)
B(0,4,-12,STONE)
B(0,4,-11,STONE)
B(0,4,-10,STONE)
B(0,4,-9,STONE)
B(0,4,-8,STONE)
B(0,4,-7,STONE)
B(0,4,-6,STONE)
B(0,4,-5,STONE)
B(0,4,-4,STONE)
B(0,4,-3,STONE)
B(0,5,-14,STONE)
B(0,5,-13,STONE)
B(0,5,-12,STONE)
B(0,5,-11,STONE)
B(0,5,-10,STONE)
B(0,5,-9,STONE)
B(0,5,-8,STONE)
B(0,5,-7,STONE)
B(0,5,-6,STONE)
B(0,5,-5,STONE)
B(0,6,-13,STONE)
B(0,6,-12,STONE)
B(0,6,-11,STONE)
B(0,6,-10,STONE)
B(0,6,-9,STONE)
B(0,6,-8,STONE)
B(0,6,-7,STONE)
B(1,-14,-18,STONE)
B(1,-14,-17,STONE)
B(1,-14,-16,STONE)
B(1,-14,-15,STONE)
B(1,-14,-14,STONE)
B(1,-14,-13,STONE)
B(1,-14,-12,STONE)
B(1,-14,-11,STONE)
B(1,-14,-10,STONE)
B(1,-14,-9,STONE)
B(1,-14,-8,STONE)
B(1,-14,-7,STONE)
B(1,-14,-6,STONE)
B(1,-14,-5,STONE)
B(1,-14,-4,STONE)
B(1,-14,-3,STONE)
B(1,-13,-19,STONE)
B(1,-13,-18,STONE)
B(1,-13,-17,STONE)
B(1,-13,-16,STONE)
B(1,-13,-15,STONE)
B(1,-13,-14,STONE)
B(1,-13,-13,STONE)
B(1,-13,-12,STONE)
B(1,-13,-11,STONE)
B(1,-13,-10,STONE)
B(1,-13,-9,STONE)
B(1,-13,-8,STONE)
B(1,-13,-7,STONE)
B(1,-13,-6,STONE)
B(1,-13,-5,STONE)
B(1,-13,-4,STONE)
B(1,-13,-3,STONE)
B(1,-13,-2,STONE)
B(1,-12,-19,STONE)
B(1,-12,-18,STONE)
B(1,-12,-17,STONE)
B(1,-12,-16,STONE)
B(1,-12,-15,STONE)
B(1,-12,-14,STONE)
B(1,-12,-13,STONE)
B(1,-12,-12,STONE)
B(1,-12,-11,STONE)
B(1,-12,-10,STONE)
B(1,-12,-9,STONE)
B(1,-12,-8,STONE)
B(1,-12,-7,STONE)
B(1,-12,-6,STONE)
B(1,-12,-5,STONE)
B(1,-12,-4,STONE)
B(1,-12,-3,STONE)
B(1,-12,-2,STONE)
B(1,-11,-20,STONE)
B(1,-11,-19,STONE)
B(1,-11,-18,STONE)
B(1,-11,-17,STONE)
B(1,-11,-16,STONE)
B(1,-11,-15,STONE)
B(1,-11,-14,STONE)
B(1,-11,-13,STONE)
B(1,-11,-12,STATIONARY_WATER)
B(1,-11,-11,STATIONARY_WATER)
B(1,-11,-10,COAL_ORE)
B(1,-11,-9,STONE)
B(1,-11,-8,STONE)
B(1,-11,-7,STONE)
B(1,-11,-6,STONE)
B(1,-11,-5,STONE)
B(1,-11,-4,STONE)
B(1,-11,-3,STONE)
B(1,-11,-2,STONE)
B(1,-11,-1,STONE)
B(1,-10,-21,STONE)
B(1,-10,-20,STONE)
B(1,-10,-19,STONE)
B(1,-10,-18,STONE)
B(1,-10,-17,STONE)
B(1,-10,-16,STONE)
B(1,-10,-15,STONE)
B(1,-10,-14,STONE)
B(1,-10,-13,STATIONARY_WATER)
B(1,-10,-12,STATIONARY_WATER)
B(1,-10,-11,STATIONARY_WATER)
B(1,-10,-10,STATIONARY_WATER)
B(1,-10,-9,STONE)
B(1,-10,-8,STONE)
B(1,-10,-7,STONE)
B(1,-10,-6,STONE)
B(1,-10,-5,STONE)
B(1,-10,-4,STONE)
B(1,-10,-3,STONE)
B(1,-10,-2,STONE)
B(1,-10,-1,STONE)
B(1,-9,-21,STONE)
B(1,-9,-20,STONE)
B(1,-9,-19,STONE)
B(1,-9,-18,STONE)
B(1,-9,-17,STONE)
B(1,-9,-16,STONE)
B(1,-9,-15,STONE)
B(1,-9,-14,STATIONARY_WATER)
B(1,-9,-13,STATIONARY_WATER)
B(1,-9,-12,STATIONARY_WATER)
B(1,-9,-11,STATIONARY_WATER)
B(1,-9,-10,STATIONARY_WATER)
B(1,-9,-9,STATIONARY_WATER)
B(1,-9,-8,STONE)
B(1,-9,-7,STONE)
B(1,-9,-6,STONE)
B(1,-9,-5,STONE)
B(1,-9,-4,STONE)
B(1,-9,-3,STONE)
B(1,-9,-2,STONE)
B(1,-9,-1,STONE)
B(1,-8,-22,STONE)
B(1,-8,-21,STONE)
B(1,-8,-20,STONE)
B(1,-8,-19,STONE)
B(1,-8,-18,STONE)
B(1,-8,-17,STONE)
B(1,-8,-16,STONE)
B(1,-8,-15,STATIONARY_WATER)
B(1,-8,-14,STATIONARY_WATER)
B(1,-8,-13,STATIONARY_WATER)
B(1,-8,-12,STATIONARY_WATER)
B(1,-8,-11,STATIONARY_WATER)
B(1,-8,-10,STATIONARY_WATER)
B(1,-8,-9,STATIONARY_WATER)
B(1,-8,-8,STONE)
B(1,-8,-7,STONE)
B(1,-8,-6,STONE)
B(1,-8,-5,STONE)
B(1,-8,-4,STONE)
B(1,-8,-3,STONE)
B(1,-8,-2,STONE)
B(1,-8,-1,STONE)
B(1,-7,-22,STONE)
B(1,-7,-21,STONE)
B(1,-7,-20,STONE)
B(1,-7,-19,STONE)
B(1,-7,-18,MOSSY_COBBLESTONE)
B(1,-7,-17,AIR)
B(1,-7,-16,AIR)
B(1,-7,-15,AIR)
B(1,-7,-14,AIR)
B(1,-7,-13,AIR)
B(1,-7,-12,AIR)
B(1,-7,-11,AIR)
B(1,-7,-10,AIR)
B(1,-7,-9,AIR)
B(1,-7,-8,AIR)
B(1,-7,-7,AIR)
B(1,-7,-6,STONE)
B(1,-7,-5,STONE)
B(1,-7,-4,STONE)
B(1,-7,-3,STONE)
B(1,-7,-2,STONE)
B(1,-7,-1,STONE)
B(1,-6,-23,STONE)
B(1,-6,-22,STONE)
B(1,-6,-21,STONE)
B(1,-6,-20,STONE)
B(1,-6,-19,STONE)
B(1,-6,-18,STONE)
B(1,-6,-17,AIR)
B(1,-6,-16,AIR)
B(1,-6,-15,AIR)
B(1,-6,-14,AIR)
B(1,-6,-13,AIR)
B(1,-6,-12,AIR)
B(1,-6,-11,AIR)
B(1,-6,-10,AIR)
B(1,-6,-9,AIR)
B(1,-6,-8,AIR)
B(1,-6,-7,AIR)
B(1,-6,-6,AIR)
B(1,-6,-5,STONE)
B(1,-6,-4,STONE)
B(1,-6,-3,STONE)
B(1,-6,-2,STONE)
B(1,-6,-1,STONE)
B(1,-6,0,STONE)
B(1,-5,-23,STONE)
B(1,-5,-22,STONE)
B(1,-5,-21,STONE)
B(1,-5,-20,STONE)
B(1,-5,-19,STONE)
B(1,-5,-18,STONE)
B(1,-5,-17,AIR)
B(1,-5,-16,AIR)
B(1,-5,-15,AIR)
B(1,-5,-14,AIR)
B(1,-5,-13,AIR)
B(1,-5,-12,AIR)
B(1,-5,-11,AIR)
B(1,-5,-10,AIR)
B(1,-5,-9,AIR)
B(1,-5,-8,AIR)
B(1,-5,-7,AIR)
B(1,-5,-6,AIR)
B(1,-5,-5,STONE)
B(1,-5,-4,STONE)
B(1,-5,-3,STONE)
B(1,-5,-2,STONE)
B(1,-5,-1,STONE)
B(1,-5,0,STONE)
B(1,-4,-23,STONE)
B(1,-4,-22,STONE)
B(1,-4,-21,STONE)
B(1,-4,-20,STONE)
B(1,-4,-19,STONE)
B(1,-4,-18,STONE)
B(1,-4,-17,STONE)
B(1,-4,-16,VINE:4)
B(1,-4,-15,AIR)
B(1,-4,-14,AIR)
B(1,-4,-13,AIR)
B(1,-4,-12,AIR)
B(1,-4,-11,AIR)
B(1,-4,-10,AIR)
B(1,-4,-9,AIR)
B(1,-4,-8,AIR)
B(1,-4,-7,AIR)
B(1,-4,-6,AIR)
B(1,-4,-5,AIR)
B(1,-4,-4,STONE)
B(1,-4,-3,STONE)
B(1,-4,-2,STONE)
B(1,-4,-1,STONE)
B(1,-4,0,STONE)
B(1,-4,1,STONE)
B(1,-3,-23,STONE)
B(1,-3,-22,STONE)
B(1,-3,-21,STONE)
B(1,-3,-20,STONE)
B(1,-3,-19,STONE)
B(1,-3,-18,STONE)
B(1,-3,-17,STONE)
B(1,-3,-16,STONE)
B(1,-3,-15,AIR)
B(1,-3,-14,AIR)
B(1,-3,-13,AIR)
B(1,-3,-12,AIR)
B(1,-3,-11,AIR)
B(1,-3,-10,AIR)
B(1,-3,-9,AIR)
B(1,-3,-8,AIR)
B(1,-3,-7,AIR)
B(1,-3,-6,AIR)
B(1,-3,-5,STONE)
B(1,-3,-4,STONE)
B(1,-3,-3,STONE)
B(1,-3,-2,STONE)
B(1,-3,-1,STONE)
B(1,-3,0,STONE)
B(1,-3,1,STONE)
B(1,-2,-23,STONE)
B(1,-2,-22,STONE)
B(1,-2,-21,STONE)
B(1,-2,-20,STONE)
B(1,-2,-19,STONE)
B(1,-2,-18,STONE)
B(1,-2,-17,STONE)
B(1,-2,-16,STONE)
B(1,-2,-15,AIR)
B(1,-2,-14,AIR)
B(1,-2,-13,AIR)
B(1,-2,-12,AIR)
B(1,-2,-11,AIR)
B(1,-2,-10,AIR)
B(1,-2,-9,AIR)
B(1,-2,-8,AIR)
B(1,-2,-7,AIR)
B(1,-2,-6,STONE)
B(1,-2,-5,STONE)
B(1,-2,-4,STONE)
B(1,-2,-3,STONE)
B(1,-2,-2,STONE)
B(1,-2,-1,STONE)
B(1,-2,0,STONE)
B(1,-2,1,STONE)
B(1,-1,-23,STONE)
B(1,-1,-22,STONE)
B(1,-1,-21,STONE)
B(1,-1,-20,STONE)
B(1,-1,-19,STONE)
B(1,-1,-18,STONE)
B(1,-1,-17,STONE)
B(1,-1,-16,STONE)
B(1,-1,-15,STONE)
B(1,-1,-14,AIR)
B(1,-1,-13,AIR)
B(1,-1,-12,AIR)
B(1,-1,-11,AIR)
B(1,-1,-10,AIR)
B(1,-1,-9,AIR)
B(1,-1,-8,AIR)
B(1,-1,-7,STONE)
B(1,-1,-6,STONE)
B(1,-1,-5,STONE)
B(1,-1,-4,STONE)
B(1,-1,-3,STONE)
B(1,-1,-2,STONE)
B(1,-1,-1,STONE)
B(1,-1,0,STONE)
B(1,-1,1,STONE)
B(1,0,-22,STONE)
B(1,0,-21,STONE)
B(1,0,-20,STONE)
B(1,0,-19,STONE)
B(1,0,-18,STONE)
B(1,0,-17,STONE)
B(1,0,-16,STONE)
B(1,0,-15,STONE)
B(1,0,-14,STONE)
B(1,0,-13,STONE)
B(1,0,-12,AIR)
B(1,0,-11,AIR)
B(1,0,-10,AIR)
B(1,0,-9,STONE)
B(1,0,-8,STONE)
B(1,0,-7,STONE)
B(1,0,-6,STONE)
B(1,0,-5,STONE)
B(1,0,-4,STONE)
B(1,0,-3,STONE)
B(1,0,-2,STONE)
B(1,0,-1,STONE)
B(1,0,0,STONE)
B(1,1,-20,STONE)
B(1,1,-19,STONE)
B(1,1,-18,STONE)
B(1,1,-17,STONE)
B(1,1,-16,STONE)
B(1,1,-15,STONE)
B(1,1,-14,STONE)
B(1,1,-13,STONE)
B(1,1,-12,STONE)
B(1,1,-11,STONE)
B(1,1,-10,STONE)
B(1,1,-9,STONE)
B(1,1,-8,STONE)
B(1,1,-7,STONE)
B(1,1,-6,STONE)
B(1,1,-5,STONE)
B(1,1,-4,STONE)
B(1,1,-3,STONE)
B(1,1,-2,STONE)
B(1,1,-1,STONE)
B(1,1,0,STONE)
B(1,2,-19,STONE)
B(1,2,-18,STONE)
B(1,2,-17,STONE)
B(1,2,-16,STONE)
B(1,2,-15,STONE)
B(1,2,-14,STONE)
B(1,2,-13,STONE)
B(1,2,-12,STONE)
B(1,2,-11,STONE)
B(1,2,-10,STONE)
B(1,2,-9,STONE)
B(1,2,-8,STONE)
B(1,2,-7,STONE)
B(1,2,-6,STONE)
B(1,2,-5,STONE)
B(1,2,-4,STONE)
B(1,2,-3,STONE)
B(1,2,-2,STONE)
B(1,2,-1,STONE)
B(1,3,-18,STONE)
B(1,3,-17,STONE)
B(1,3,-16,STONE)
B(1,3,-15,STONE)
B(1,3,-14,STONE)
B(1,3,-13,STONE)
B(1,3,-12,STONE)
B(1,3,-11,STONE)
B(1,3,-10,STONE)
B(1,3,-9,STONE)
B(1,3,-8,STONE)
B(1,3,-7,STONE)
B(1,3,-6,STONE)
B(1,3,-5,STONE)
B(1,3,-4,STONE)
B(1,3,-3,STONE)
B(1,3,-2,STONE)
B(1,4,-17,STONE)
B(1,4,-16,STONE)
B(1,4,-15,STONE)
B(1,4,-14,STONE)
B(1,4,-13,STONE)
B(1,4,-12,STONE)
B(1,4,-11,STONE)
B(1,4,-10,STONE)
B(1,4,-9,STONE)
B(1,4,-8,STONE)
B(1,4,-7,STONE)
B(1,4,-6,STONE)
B(1,4,-5,STONE)
B(1,4,-4,STONE)
B(1,4,-3,STONE)
B(1,5,-15,STONE)
B(1,5,-14,STONE)
B(1,5,-13,STONE)
B(1,5,-12,STONE)
B(1,5,-11,STONE)
B(1,5,-10,STONE)
B(1,5,-9,STONE)
B(1,5,-8,STONE)
B(1,5,-7,STONE)
B(1,5,-6,STONE)
B(1,5,-5,STONE)
B(1,6,-13,STONE)
B(1,6,-12,STONE)
B(1,6,-11,STONE)
B(1,6,-10,STONE)
B(1,6,-9,STONE)
B(1,6,-8,STONE)
B(1,6,-7,STONE)
B(1,7,-10,STONE)
B(1,7,-9,STONE)
B(2,-14,-18,STONE)
B(2,-14,-17,STONE)
B(2,-14,-16,STONE)
B(2,-14,-15,STONE)
B(2,-14,-14,STONE)
B(2,-14,-13,STONE)
B(2,-14,-12,STONE)
B(2,-14,-11,STONE)
B(2,-14,-10,STONE)
B(2,-14,-9,STONE)
B(2,-14,-8,STONE)
B(2,-14,-7,STONE)
B(2,-14,-6,STONE)
B(2,-14,-5,STONE)
B(2,-14,-4,STONE)
B(2,-13,-19,STONE)
B(2,-13,-18,STONE)
B(2,-13,-17,STONE)
B(2,-13,-16,STONE)
B(2,-13,-15,STONE)
B(2,-13,-14,STONE)
B(2,-13,-13,STONE)
B(2,-13,-12,STONE)
B(2,-13,-11,STONE)
B(2,-13,-10,STONE)
B(2,-13,-9,STONE)
B(2,-13,-8,STONE)
B(2,-13,-7,STONE)
B(2,-13,-6,STONE)
B(2,-13,-5,STONE)
B(2,-13,-4,STONE)
B(2,-13,-3,STONE)
B(2,-12,-19,STONE)
B(2,-12,-18,STONE)
B(2,-12,-17,STONE)
B(2,-12,-16,STONE)
B(2,-12,-15,STONE)
B(2,-12,-14,STONE)
B(2,-12,-13,STONE)
B(2,-12,-12,STONE)
B(2,-12,-11,STONE)
B(2,-12,-10,STONE)
B(2,-12,-9,STONE)
B(2,-12,-8,STONE)
B(2,-12,-7,STONE)
B(2,-12,-6,STONE)
B(2,-12,-5,STONE)
B(2,-12,-4,STONE)
B(2,-12,-3,STONE)
B(2,-12,-2,STONE)
B(2,-11,-20,STONE)
B(2,-11,-19,STONE)
B(2,-11,-18,STONE)
B(2,-11,-17,STONE)
B(2,-11,-16,STONE)
B(2,-11,-15,STONE)
B(2,-11,-14,STONE)
B(2,-11,-13,STATIONARY_WATER)
B(2,-11,-12,STATIONARY_WATER)
B(2,-11,-11,STATIONARY_WATER)
B(2,-11,-10,STONE)
B(2,-11,-9,STONE)
B(2,-11,-8,STONE)
B(2,-11,-7,STONE)
B(2,-11,-6,STONE)
B(2,-11,-5,STONE)
B(2,-11,-4,STONE)
B(2,-11,-3,STONE)
B(2,-11,-2,STONE)
B(2,-10,-21,STONE)
B(2,-10,-20,STONE)
B(2,-10,-19,STONE)
B(2,-10,-18,STONE)
B(2,-10,-17,STONE)
B(2,-10,-16,STONE)
B(2,-10,-15,STONE)
B(2,-10,-14,STATIONARY_WATER)
B(2,-10,-13,STATIONARY_WATER)
B(2,-10,-12,STATIONARY_WATER)
B(2,-10,-11,STATIONARY_WATER)
B(2,-10,-10,STATIONARY_WATER)
B(2,-10,-9,STATIONARY_WATER)
B(2,-10,-8,STONE)
B(2,-10,-7,STONE)
B(2,-10,-6,STONE)
B(2,-10,-5,STONE)
B(2,-10,-4,STONE)
B(2,-10,-3,STONE)
B(2,-10,-2,STONE)
B(2,-10,-1,STONE)
B(2,-9,-21,STONE)
B(2,-9,-20,STONE)
B(2,-9,-19,STONE)
B(2,-9,-18,STONE)
B(2,-9,-17,STONE)
B(2,-9,-16,STONE)
B(2,-9,-15,STATIONARY_WATER)
B(2,-9,-14,STATIONARY_WATER)
B(2,-9,-13,STATIONARY_WATER)
B(2,-9,-12,STATIONARY_WATER)
B(2,-9,-11,STATIONARY_WATER)
B(2,-9,-10,STATIONARY_WATER)
B(2,-9,-9,STATIONARY_WATER)
B(2,-9,-8,STONE)
B(2,-9,-7,STONE)
B(2,-9,-6,STONE)
B(2,-9,-5,STONE)
B(2,-9,-4,STONE)
B(2,-9,-3,STONE)
B(2,-9,-2,STONE)
B(2,-9,-1,STONE)
B(2,-8,-22,STONE)
B(2,-8,-21,STONE)
B(2,-8,-20,STONE)
B(2,-8,-19,STONE)
B(2,-8,-18,STONE)
B(2,-8,-17,STONE)
B(2,-8,-16,STATIONARY_WATER)
B(2,-8,-15,STATIONARY_WATER)
B(2,-8,-14,STATIONARY_WATER)
B(2,-8,-13,STATIONARY_WATER)
B(2,-8,-12,STATIONARY_WATER)
B(2,-8,-11,STATIONARY_WATER)
B(2,-8,-10,STATIONARY_WATER)
B(2,-8,-9,STATIONARY_WATER)
B(2,-8,-8,STATIONARY_WATER)
B(2,-8,-7,STONE)
B(2,-8,-6,STONE)
B(2,-8,-5,STONE)
B(2,-8,-4,STONE)
B(2,-8,-3,STONE)
B(2,-8,-2,STONE)
B(2,-8,-1,STONE)
B(2,-7,-22,STONE)
B(2,-7,-21,STONE)
B(2,-7,-20,STONE)
B(2,-7,-19,STONE)
B(2,-7,-18,STONE)
B(2,-7,-17,BROWN_MUSHROOM)
B(2,-7,-16,AIR)
B(2,-7,-15,AIR)
B(2,-7,-14,AIR)
B(2,-7,-13,AIR)
B(2,-7,-12,AIR)
B(2,-7,-11,AIR)
B(2,-7,-10,AIR)
B(2,-7,-9,AIR)
B(2,-7,-8,AIR)
B(2,-7,-7,AIR)
B(2,-7,-6,AIR)
B(2,-7,-5,STONE)
B(2,-7,-4,STONE)
B(2,-7,-3,STONE)
B(2,-7,-2,STONE)
B(2,-7,-1,STONE)
B(2,-6,-22,STONE)
B(2,-6,-21,STONE)
B(2,-6,-20,STONE)
B(2,-6,-19,STONE)
B(2,-6,-18,STONE)
B(2,-6,-17,AIR)
B(2,-6,-16,AIR)
B(2,-6,-15,AIR)
B(2,-6,-14,AIR)
B(2,-6,-13,AIR)
B(2,-6,-12,AIR)
B(2,-6,-11,AIR)
B(2,-6,-10,AIR)
B(2,-6,-9,AIR)
B(2,-6,-8,AIR)
B(2,-6,-7,AIR)
B(2,-6,-6,VINE:1)
B(2,-6,-5,STONE)
B(2,-6,-4,STONE)
B(2,-6,-3,STONE)
B(2,-6,-2,STONE)
B(2,-6,-1,STONE)
B(2,-6,0,STONE)
B(2,-5,-23,STONE)
B(2,-5,-22,STONE)
B(2,-5,-21,STONE)
B(2,-5,-20,STONE)
B(2,-5,-19,STONE)
B(2,-5,-18,STONE)
B(2,-5,-17,STONE)
B(2,-5,-16,AIR)
B(2,-5,-15,AIR)
B(2,-5,-14,AIR)
B(2,-5,-13,AIR)
B(2,-5,-12,AIR)
B(2,-5,-11,AIR)
B(2,-5,-10,AIR)
B(2,-5,-9,AIR)
B(2,-5,-8,AIR)
B(2,-5,-7,AIR)
B(2,-5,-6,VINE:1)
B(2,-5,-5,STONE)
B(2,-5,-4,STONE)
B(2,-5,-3,STONE)
B(2,-5,-2,STONE)
B(2,-5,-1,STONE)
B(2,-5,0,STONE)
B(2,-5,1,STONE)
B(2,-4,-23,STONE)
B(2,-4,-22,STONE)
B(2,-4,-21,STONE)
B(2,-4,-20,STONE)
B(2,-4,-19,STONE)
B(2,-4,-18,STONE)
B(2,-4,-17,STONE)
B(2,-4,-16,AIR)
B(2,-4,-15,AIR)
B(2,-4,-14,AIR)
B(2,-4,-13,AIR)
B(2,-4,-12,AIR)
B(2,-4,-11,AIR)
B(2,-4,-10,AIR)
B(2,-4,-9,AIR)
B(2,-4,-8,AIR)
B(2,-4,-7,AIR)
B(2,-4,-6,VINE:1)
B(2,-4,-5,STONE)
B(2,-4,-4,STONE)
B(2,-4,-3,STONE)
B(2,-4,-2,STONE)
B(2,-4,-1,STONE)
B(2,-4,0,STONE)
B(2,-4,1,STONE)
B(2,-3,-23,STONE)
B(2,-3,-22,STONE)
B(2,-3,-21,STONE)
B(2,-3,-20,STONE)
B(2,-3,-19,STONE)
B(2,-3,-18,STONE)
B(2,-3,-17,STONE)
B(2,-3,-16,STONE)
B(2,-3,-15,AIR)
B(2,-3,-14,AIR)
B(2,-3,-13,AIR)
B(2,-3,-12,AIR)
B(2,-3,-11,AIR)
B(2,-3,-10,AIR)
B(2,-3,-9,AIR)
B(2,-3,-8,AIR)
B(2,-3,-7,AIR)
B(2,-3,-6,VINE:1)
B(2,-3,-5,STONE)
B(2,-3,-4,STONE)
B(2,-3,-3,STONE)
B(2,-3,-2,STONE)
B(2,-3,-1,STONE)
B(2,-3,0,STONE)
B(2,-3,1,STONE)
B(2,-2,-23,STONE)
B(2,-2,-22,STONE)
B(2,-2,-21,STONE)
B(2,-2,-20,STONE)
B(2,-2,-19,STONE)
B(2,-2,-18,STONE)
B(2,-2,-17,STONE)
B(2,-2,-16,STONE)
B(2,-2,-15,STONE)
B(2,-2,-14,AIR)
B(2,-2,-13,AIR)
B(2,-2,-12,AIR)
B(2,-2,-11,AIR)
B(2,-2,-10,AIR)
B(2,-2,-9,AIR)
B(2,-2,-8,AIR)
B(2,-2,-7,AIR)
B(2,-2,-6,STONE)
B(2,-2,-5,STONE)
B(2,-2,-4,STONE)
B(2,-2,-3,STONE)
B(2,-2,-2,STONE)
B(2,-2,-1,STONE)
B(2,-2,0,STONE)
B(2,-2,1,STONE)
B(2,-1,-22,STONE)
B(2,-1,-21,STONE)
B(2,-1,-20,STONE)
B(2,-1,-19,STONE)
B(2,-1,-18,STONE)
B(2,-1,-17,STONE)
B(2,-1,-16,STONE)
B(2,-1,-15,STONE)
B(2,-1,-14,AIR)
B(2,-1,-13,AIR)
B(2,-1,-12,AIR)
B(2,-1,-11,AIR)
B(2,-1,-10,AIR)
B(2,-1,-9,AIR)
B(2,-1,-8,AIR)
B(2,-1,-7,STONE)
B(2,-1,-6,STONE)
B(2,-1,-5,STONE)
B(2,-1,-4,STONE)
B(2,-1,-3,STONE)
B(2,-1,-2,STONE)
B(2,-1,-1,STONE)
B(2,-1,0,STONE)
B(2,-1,1,STONE)
B(2,0,-21,STONE)
B(2,0,-20,STONE)
B(2,0,-19,STONE)
B(2,0,-18,STONE)
B(2,0,-17,STONE)
B(2,0,-16,STONE)
B(2,0,-15,STONE)
B(2,0,-14,STONE)
B(2,0,-13,STONE)
B(2,0,-12,AIR)
B(2,0,-11,AIR)
B(2,0,-10,AIR)
B(2,0,-9,AIR)
B(2,0,-8,STONE)
B(2,0,-7,STONE)
B(2,0,-6,STONE)
B(2,0,-5,STONE)
B(2,0,-4,STONE)
B(2,0,-3,STONE)
B(2,0,-2,STONE)
B(2,0,-1,STONE)
B(2,0,0,STONE)
B(2,1,-20,STONE)
B(2,1,-19,STONE)
B(2,1,-18,STONE)
B(2,1,-17,STONE)
B(2,1,-16,STONE)
B(2,1,-15,STONE)
B(2,1,-14,STONE)
B(2,1,-13,STONE)
B(2,1,-12,STONE)
B(2,1,-11,STONE)
B(2,1,-10,STONE)
B(2,1,-9,STONE)
B(2,1,-8,STONE)
B(2,1,-7,STONE)
B(2,1,-6,STONE)
B(2,1,-5,STONE)
B(2,1,-4,STONE)
B(2,1,-3,STONE)
B(2,1,-2,STONE)
B(2,1,-1,STONE)
B(2,1,0,STONE)
B(2,2,-19,STONE)
B(2,2,-18,STONE)
B(2,2,-17,STONE)
B(2,2,-16,STONE)
B(2,2,-15,STONE)
B(2,2,-14,STONE)
B(2,2,-13,STONE)
B(2,2,-12,STONE)
B(2,2,-11,STONE)
B(2,2,-10,STONE)
B(2,2,-9,STONE)
B(2,2,-8,STONE)
B(2,2,-7,STONE)
B(2,2,-6,STONE)
B(2,2,-5,STONE)
B(2,2,-4,STONE)
B(2,2,-3,STONE)
B(2,2,-2,STONE)
B(2,2,-1,STONE)
B(2,3,-18,STONE)
B(2,3,-17,STONE)
B(2,3,-16,STONE)
B(2,3,-15,STONE)
B(2,3,-14,STONE)
B(2,3,-13,STONE)
B(2,3,-12,STONE)
B(2,3,-11,STONE)
B(2,3,-10,STONE)
B(2,3,-9,STONE)
B(2,3,-8,STONE)
B(2,3,-7,STONE)
B(2,3,-6,STONE)
B(2,3,-5,STONE)
B(2,3,-4,STONE)
B(2,3,-3,STONE)
B(2,3,-2,STONE)
B(2,4,-17,STONE)
B(2,4,-16,STONE)
B(2,4,-15,STONE)
B(2,4,-14,STONE)
B(2,4,-13,STONE)
B(2,4,-12,STONE)
B(2,4,-11,STONE)
B(2,4,-10,STONE)
B(2,4,-9,STONE)
B(2,4,-8,STONE)
B(2,4,-7,STONE)
B(2,4,-6,STONE)
B(2,4,-5,STONE)
B(2,4,-4,STONE)
B(2,5,-16,STONE)
B(2,5,-15,STONE)
B(2,5,-14,STONE)
B(2,5,-13,STONE)
B(2,5,-12,STONE)
B(2,5,-11,STONE)
B(2,5,-10,STONE)
B(2,5,-9,STONE)
B(2,5,-8,STONE)
B(2,5,-7,STONE)
B(2,5,-6,STONE)
B(2,5,-5,STONE)
B(2,6,-14,STONE)
B(2,6,-13,STONE)
B(2,6,-12,STONE)
B(2,6,-11,STONE)
B(2,6,-10,STONE)
B(2,6,-9,STONE)
B(2,6,-8,STONE)
B(2,6,-7,STONE)
B(2,7,-11,STONE)
B(2,7,-10,STONE)
B(3,-14,-18,STONE)
B(3,-14,-17,STONE)
B(3,-14,-16,STONE)
B(3,-14,-15,STONE)
B(3,-14,-14,STONE)
B(3,-14,-13,STONE)
B(3,-14,-12,STONE)
B(3,-14,-11,STONE)
B(3,-14,-10,STONE)
B(3,-14,-9,STONE)
B(3,-14,-8,STONE)
B(3,-14,-7,STONE)
B(3,-14,-6,STONE)
B(3,-14,-5,STONE)
B(3,-13,-19,STONE)
B(3,-13,-18,STONE)
B(3,-13,-17,STONE)
B(3,-13,-16,STONE)
B(3,-13,-15,STONE)
B(3,-13,-14,STONE)
B(3,-13,-13,STONE)
B(3,-13,-12,STONE)
B(3,-13,-11,STONE)
B(3,-13,-10,STONE)
B(3,-13,-9,STONE)
B(3,-13,-8,STONE)
B(3,-13,-7,STONE)
B(3,-13,-6,STONE)
B(3,-13,-5,STONE)
B(3,-13,-4,STONE)
B(3,-12,-19,STONE)
B(3,-12,-18,STONE)
B(3,-12,-17,STONE)
B(3,-12,-16,STONE)
B(3,-12,-15,STONE)
B(3,-12,-14,STONE)
B(3,-12,-13,STONE)
B(3,-12,-12,STONE)
B(3,-12,-11,STONE)
B(3,-12,-10,STONE)
B(3,-12,-9,STONE)
B(3,-12,-8,STONE)
B(3,-12,-7,STONE)
B(3,-12,-6,STONE)
B(3,-12,-5,STONE)
B(3,-12,-4,STONE)
B(3,-12,-3,STONE)
B(3,-11,-20,STONE)
B(3,-11,-19,STONE)
B(3,-11,-18,STONE)
B(3,-11,-17,STONE)
B(3,-11,-16,STONE)
B(3,-11,-15,STONE)
B(3,-11,-14,STONE)
B(3,-11,-13,STATIONARY_WATER)
B(3,-11,-12,STATIONARY_WATER)
B(3,-11,-11,STONE)
B(3,-11,-10,STONE)
B(3,-11,-9,STONE)
B(3,-11,-8,STONE)
B(3,-11,-7,STONE)
B(3,-11,-6,STONE)
B(3,-11,-5,STONE)
B(3,-11,-4,STONE)
B(3,-11,-3,STONE)
B(3,-11,-2,STONE)
B(3,-10,-21,STONE)
B(3,-10,-20,STONE)
B(3,-10,-19,STONE)
B(3,-10,-18,STONE)
B(3,-10,-17,STONE)
B(3,-10,-16,STONE)
B(3,-10,-15,MOSSY_COBBLESTONE)
B(3,-10,-14,STATIONARY_WATER)
B(3,-10,-13,STATIONARY_WATER)
B(3,-10,-12,STATIONARY_WATER)
B(3,-10,-11,STATIONARY_WATER)
B(3,-10,-10,STATIONARY_WATER)
B(3,-10,-9,STONE)
B(3,-10,-8,STONE)
B(3,-10,-7,STONE)
B(3,-10,-6,STONE)
B(3,-10,-5,STONE)
B(3,-10,-4,STONE)
B(3,-10,-3,STONE)
B(3,-10,-2,STONE)
B(3,-9,-21,STONE)
B(3,-9,-20,STONE)
B(3,-9,-19,STONE)
B(3,-9,-18,STONE)
B(3,-9,-17,STONE)
B(3,-9,-16,STONE)
B(3,-9,-15,STATIONARY_WATER)
B(3,-9,-14,STATIONARY_WATER)
B(3,-9,-13,STATIONARY_WATER)
B(3,-9,-12,STATIONARY_WATER)
B(3,-9,-11,STATIONARY_WATER)
B(3,-9,-10,STATIONARY_WATER)
B(3,-9,-9,STATIONARY_WATER)
B(3,-9,-8,STATIONARY_WATER)
B(3,-9,-7,STONE)
B(3,-9,-6,STONE)
B(3,-9,-5,STONE)
B(3,-9,-4,STONE)
B(3,-9,-3,STONE)
B(3,-9,-2,STONE)
B(3,-8,-22,STONE)
B(3,-8,-21,STONE)
B(3,-8,-20,STONE)
B(3,-8,-19,STONE)
B(3,-8,-18,STONE)
B(3,-8,-17,STONE)
B(3,-8,-16,STATIONARY_WATER)
B(3,-8,-15,STATIONARY_WATER)
B(3,-8,-14,STATIONARY_WATER)
B(3,-8,-13,STATIONARY_WATER)
B(3,-8,-12,STATIONARY_WATER)
B(3,-8,-11,STATIONARY_WATER)
B(3,-8,-10,STATIONARY_WATER)
B(3,-8,-9,STATIONARY_WATER)
B(3,-8,-8,STATIONARY_WATER)
B(3,-8,-7,STONE)
B(3,-8,-6,STONE)
B(3,-8,-5,STONE)
B(3,-8,-4,STONE)
B(3,-8,-3,STONE)
B(3,-8,-2,STONE)
B(3,-8,-1,STONE)
B(3,-7,-22,STONE)
B(3,-7,-21,STONE)
B(3,-7,-20,STONE)
B(3,-7,-19,STONE)
B(3,-7,-18,STONE)
B(3,-7,-17,AIR)
B(3,-7,-16,AIR)
B(3,-7,-15,AIR)
B(3,-7,-14,AIR)
B(3,-7,-13,AIR)
B(3,-7,-12,AIR)
B(3,-7,-11,AIR)
B(3,-7,-10,AIR)
B(3,-7,-9,AIR)
B(3,-7,-8,AIR)
B(3,-7,-7,AIR)
B(3,-7,-6,MOSSY_COBBLESTONE)
B(3,-7,-5,STONE)
B(3,-7,-4,STONE)
B(3,-7,-3,STONE)
B(3,-7,-2,STONE)
B(3,-7,-1,STONE)
B(3,-6,-22,STONE)
B(3,-6,-21,STONE)
B(3,-6,-20,STONE)
B(3,-6,-19,STONE)
B(3,-6,-18,STONE)
B(3,-6,-17,STONE)
B(3,-6,-16,AIR)
B(3,-6,-15,AIR)
B(3,-6,-14,AIR)
B(3,-6,-13,AIR)
B(3,-6,-12,AIR)
B(3,-6,-11,AIR)
B(3,-6,-10,AIR)
B(3,-6,-9,AIR)
B(3,-6,-8,AIR)
B(3,-6,-7,AIR)
B(3,-6,-6,STONE)
B(3,-6,-5,STONE)
B(3,-6,-4,STONE)
B(3,-6,-3,STONE)
B(3,-6,-2,STONE)
B(3,-6,-1,STONE)
B(3,-6,0,STONE)
B(3,-5,-22,STONE)
B(3,-5,-21,STONE)
B(3,-5,-20,STONE)
B(3,-5,-19,STONE)
B(3,-5,-18,STONE)
B(3,-5,-17,AIR)
B(3,-5,-16,AIR)
B(3,-5,-15,AIR)
B(3,-5,-14,AIR)
B(3,-5,-13,AIR)
B(3,-5,-12,AIR)
B(3,-5,-11,AIR)
B(3,-5,-10,AIR)
B(3,-5,-9,AIR)
B(3,-5,-8,AIR)
B(3,-5,-7,AIR)
B(3,-5,-6,STONE)
B(3,-5,-5,STONE)
B(3,-5,-4,STONE)
B(3,-5,-3,STONE)
B(3,-5,-2,STONE)
B(3,-5,-1,STONE)
B(3,-5,0,STONE)
B(3,-4,-23,STONE)
B(3,-4,-22,STONE)
B(3,-4,-21,STONE)
B(3,-4,-20,STONE)
B(3,-4,-19,STONE)
B(3,-4,-18,STONE)
B(3,-4,-17,STONE)
B(3,-4,-16,AIR)
B(3,-4,-15,AIR)
B(3,-4,-14,AIR)
B(3,-4,-13,AIR)
B(3,-4,-12,AIR)
B(3,-4,-11,AIR)
B(3,-4,-10,AIR)
B(3,-4,-9,AIR)
B(3,-4,-8,AIR)
B(3,-4,-7,AIR)
B(3,-4,-6,AIR)
B(3,-4,-5,STONE)
B(3,-4,-4,STONE)
B(3,-4,-3,STONE)
B(3,-4,-2,STONE)
B(3,-4,-1,STONE)
B(3,-4,0,STONE)
B(3,-4,1,STONE)
B(3,-3,-23,STONE)
B(3,-3,-22,STONE)
B(3,-3,-21,STONE)
B(3,-3,-20,STONE)
B(3,-3,-19,STONE)
B(3,-3,-18,STONE)
B(3,-3,-17,STONE)
B(3,-3,-16,AIR)
B(3,-3,-15,AIR)
B(3,-3,-14,AIR)
B(3,-3,-13,AIR)
B(3,-3,-12,AIR)
B(3,-3,-11,AIR)
B(3,-3,-10,AIR)
B(3,-3,-9,AIR)
B(3,-3,-8,AIR)
B(3,-3,-7,AIR)
B(3,-3,-6,VINE:1)
B(3,-3,-5,STONE)
B(3,-3,-4,STONE)
B(3,-3,-3,STONE)
B(3,-3,-2,STONE)
B(3,-3,-1,STONE)
B(3,-3,0,STONE)
B(3,-3,1,STONE)
B(3,-2,-22,STONE)
B(3,-2,-21,STONE)
B(3,-2,-20,STONE)
B(3,-2,-19,STONE)
B(3,-2,-18,STONE)
B(3,-2,-17,STONE)
B(3,-2,-16,STONE)
B(3,-2,-15,AIR)
B(3,-2,-14,AIR)
B(3,-2,-13,AIR)
B(3,-2,-12,AIR)
B(3,-2,-11,AIR)
B(3,-2,-10,AIR)
B(3,-2,-9,AIR)
B(3,-2,-8,AIR)
B(3,-2,-7,AIR)
B(3,-2,-6,STONE)
B(3,-2,-5,STONE)
B(3,-2,-4,STONE)
B(3,-2,-3,STONE)
B(3,-2,-2,STONE)
B(3,-2,-1,STONE)
B(3,-2,0,STONE)
B(3,-2,1,STONE)
B(3,-1,-21,STONE)
B(3,-1,-20,STONE)
B(3,-1,-19,STONE)
B(3,-1,-18,STONE)
B(3,-1,-17,STONE)
B(3,-1,-16,STONE)
B(3,-1,-15,STONE)
B(3,-1,-14,AIR)
B(3,-1,-13,AIR)
B(3,-1,-12,AIR)
B(3,-1,-11,AIR)
B(3,-1,-10,AIR)
B(3,-1,-9,AIR)
B(3,-1,-8,STONE)
B(3,-1,-7,STONE)
B(3,-1,-6,STONE)
B(3,-1,-5,STONE)
B(3,-1,-4,STONE)
B(3,-1,-3,STONE)
B(3,-1,-2,STONE)
B(3,-1,-1,STONE)
B(3,-1,0,STONE)
B(3,-1,1,STONE)
B(3,0,-21,STONE)
B(3,0,-20,STONE)
B(3,0,-19,STONE)
B(3,0,-18,STONE)
B(3,0,-17,STONE)
B(3,0,-16,STONE)
B(3,0,-15,STONE)
B(3,0,-14,STONE)
B(3,0,-13,AIR)
B(3,0,-12,AIR)
B(3,0,-11,AIR)
B(3,0,-10,AIR)
B(3,0,-9,STONE)
B(3,0,-8,STONE)
B(3,0,-7,STONE)
B(3,0,-6,STONE)
B(3,0,-5,STONE)
B(3,0,-4,STONE)
B(3,0,-3,STONE)
B(3,0,-2,STONE)
B(3,0,-1,STONE)
B(3,0,0,STONE)
B(3,1,-20,STONE)
B(3,1,-19,STONE)
B(3,1,-18,STONE)
B(3,1,-17,STONE)
B(3,1,-16,STONE)
B(3,1,-15,STONE)
B(3,1,-14,STONE)
B(3,1,-13,STONE)
B(3,1,-12,STONE)
B(3,1,-11,STONE)
B(3,1,-10,STONE)
B(3,1,-9,STONE)
B(3,1,-8,STONE)
B(3,1,-7,STONE)
B(3,1,-6,STONE)
B(3,1,-5,STONE)
B(3,1,-4,STONE)
B(3,1,-3,STONE)
B(3,1,-2,STONE)
B(3,1,-1,STONE)
B(3,2,-19,STONE)
B(3,2,-18,STONE)
B(3,2,-17,STONE)
B(3,2,-16,STONE)
B(3,2,-15,STONE)
B(3,2,-14,STONE)
B(3,2,-13,STONE)
B(3,2,-12,STONE)
B(3,2,-11,STONE)
B(3,2,-10,STONE)
B(3,2,-9,STONE)
B(3,2,-8,STONE)
B(3,2,-7,STONE)
B(3,2,-6,STONE)
B(3,2,-5,STONE)
B(3,2,-4,STONE)
B(3,2,-3,STONE)
B(3,2,-2,STONE)
B(3,2,-1,STONE)
B(3,3,-18,STONE)
B(3,3,-17,STONE)
B(3,3,-16,STONE)
B(3,3,-15,STONE)
B(3,3,-14,STONE)
B(3,3,-13,STONE)
B(3,3,-12,STONE)
B(3,3,-11,STONE)
B(3,3,-10,STONE)
B(3,3,-9,STONE)
B(3,3,-8,STONE)
B(3,3,-7,STONE)
B(3,3,-6,STONE)
B(3,3,-5,STONE)
B(3,3,-4,STONE)
B(3,3,-3,STONE)
B(3,3,-2,STONE)
B(3,4,-17,STONE)
B(3,4,-16,STONE)
B(3,4,-15,STONE)
B(3,4,-14,STONE)
B(3,4,-13,STONE)
B(3,4,-12,STONE)
B(3,4,-11,STONE)
B(3,4,-10,STONE)
B(3,4,-9,STONE)
B(3,4,-8,STONE)
B(3,4,-7,STONE)
B(3,4,-6,STONE)
B(3,4,-5,STONE)
B(3,4,-4,STONE)
B(3,5,-16,STONE)
B(3,5,-15,STONE)
B(3,5,-14,STONE)
B(3,5,-13,STONE)
B(3,5,-12,STONE)
B(3,5,-11,STONE)
B(3,5,-10,STONE)
B(3,5,-9,STONE)
B(3,5,-8,STONE)
B(3,5,-7,STONE)
B(3,5,-6,STONE)
B(3,5,-5,STONE)
B(3,6,-14,STONE)
B(3,6,-13,STONE)
B(3,6,-12,STONE)
B(3,6,-11,STONE)
B(3,6,-10,STONE)
B(3,6,-9,STONE)
B(3,6,-8,STONE)
B(4,-14,-18,STONE)
B(4,-14,-17,STONE)
B(4,-14,-16,STONE)
B(4,-14,-15,STONE)
B(4,-14,-14,STONE)
B(4,-14,-13,STONE)
B(4,-14,-12,STONE)
B(4,-14,-11,STONE)
B(4,-14,-10,STONE)
B(4,-14,-9,STONE)
B(4,-14,-8,STONE)
B(4,-14,-7,STONE)
B(4,-14,-6,STONE)
B(4,-13,-19,STONE)
B(4,-13,-18,STONE)
B(4,-13,-17,STONE)
B(4,-13,-16,STONE)
B(4,-13,-15,STONE)
B(4,-13,-14,STONE)
B(4,-13,-13,STONE)
B(4,-13,-12,STONE)
B(4,-13,-11,STONE)
B(4,-13,-10,STONE)
B(4,-13,-9,STONE)
B(4,-13,-8,STONE)
B(4,-13,-7,STONE)
B(4,-13,-6,STONE)
B(4,-13,-5,STONE)
B(4,-13,-4,STONE)
B(4,-12,-19,STONE)
B(4,-12,-18,STONE)
B(4,-12,-17,STONE)
B(4,-12,-16,STONE)
B(4,-12,-15,STONE)
B(4,-12,-14,STONE)
B(4,-12,-13,STONE)
B(4,-12,-12,STONE)
B(4,-12,-11,STONE)
B(4,-12,-10,STONE)
B(4,-12,-9,STONE)
B(4,-12,-8,STONE)
B(4,-12,-7,STONE)
B(4,-12,-6,STONE)
B(4,-12,-5,STONE)
B(4,-12,-4,STONE)
B(4,-12,-3,STONE)
B(4,-11,-20,STONE)
B(4,-11,-19,STONE)
B(4,-11,-18,STONE)
B(4,-11,-17,STONE)
B(4,-11,-16,STONE)
B(4,-11,-15,STONE)
B(4,-11,-14,STONE)
B(4,-11,-13,STONE)
B(4,-11,-12,MOSSY_COBBLESTONE)
B(4,-11,-11,STONE)
B(4,-11,-10,STONE)
B(4,-11,-9,STONE)
B(4,-11,-8,STONE)
B(4,-11,-7,STONE)
B(4,-11,-6,STONE)
B(4,-11,-5,STONE)
B(4,-11,-4,STONE)
B(4,-11,-3,STONE)
B(4,-10,-21,STONE)
B(4,-10,-20,STONE)
B(4,-10,-19,STONE)
B(4,-10,-18,STONE)
B(4,-10,-17,STONE)
B(4,-10,-16,STONE)
B(4,-10,-15,STONE)
B(4,-10,-14,STATIONARY_WATER)
B(4,-10,-13,STATIONARY_WATER)
B(4,-10,-12,STATIONARY_WATER)
B(4,-10,-11,STATIONARY_WATER)
B(4,-10,-10,STONE)
B(4,-10,-9,STONE)
B(4,-10,-8,STONE)
B(4,-10,-7,STONE)
B(4,-10,-6,STONE)
B(4,-10,-5,STONE)
B(4,-10,-4,STONE)
B(4,-10,-3,STONE)
B(4,-10,-2,STONE)
B(4,-9,-21,STONE)
B(4,-9,-20,STONE)
B(4,-9,-19,STONE)
B(4,-9,-18,STONE)
B(4,-9,-17,STONE)
B(4,-9,-16,STONE)
B(4,-9,-15,STATIONARY_WATER)
B(4,-9,-14,STATIONARY_WATER)
B(4,-9,-13,STATIONARY_WATER)
B(4,-9,-12,STATIONARY_WATER)
B(4,-9,-11,STATIONARY_WATER)
B(4,-9,-10,STATIONARY_WATER)
B(4,-9,-9,STONE)
B(4,-9,-8,STONE)
B(4,-9,-7,STONE)
B(4,-9,-6,STONE)
B(4,-9,-5,STONE)
B(4,-9,-4,STONE)
B(4,-9,-3,STONE)
B(4,-9,-2,STONE)
B(4,-8,-21,STONE)
B(4,-8,-20,STONE)
B(4,-8,-19,STONE)
B(4,-8,-18,STONE)
B(4,-8,-17,STONE)
B(4,-8,-16,STATIONARY_WATER)
B(4,-8,-15,STATIONARY_WATER)
B(4,-8,-14,STATIONARY_WATER)
B(4,-8,-13,STATIONARY_WATER)
B(4,-8,-12,STATIONARY_WATER)
B(4,-8,-11,STATIONARY_WATER)
B(4,-8,-10,STATIONARY_WATER)
B(4,-8,-9,STATIONARY_WATER)
B(4,-8,-8,STONE)
B(4,-8,-7,STONE)
B(4,-8,-6,STONE)
B(4,-8,-5,STONE)
B(4,-8,-4,STONE)
B(4,-8,-3,STONE)
B(4,-8,-2,STONE)
B(4,-7,-21,STONE)
B(4,-7,-20,STONE)
B(4,-7,-19,STONE)
B(4,-7,-18,STONE)
B(4,-7,-17,AIR)
B(4,-7,-16,AIR)
B(4,-7,-15,AIR)
B(4,-7,-14,AIR)
B(4,-7,-13,AIR)
B(4,-7,-12,AIR)
B(4,-7,-11,AIR)
B(4,-7,-10,AIR)
B(4,-7,-9,AIR)
B(4,-7,-8,VINE:8)
B(4,-7,-7,VINE:9)
B(4,-7,-6,STONE)
B(4,-7,-5,STONE)
B(4,-7,-4,STONE)
B(4,-7,-3,STONE)
B(4,-7,-2,STONE)
B(4,-7,-1,STONE)
B(4,-6,-22,STONE)
B(4,-6,-21,STONE)
B(4,-6,-20,STONE)
B(4,-6,-19,STONE)
B(4,-6,-18,STONE)
B(4,-6,-17,AIR)
B(4,-6,-16,AIR)
B(4,-6,-15,AIR)
B(4,-6,-14,AIR)
B(4,-6,-13,AIR)
B(4,-6,-12,AIR)
B(4,-6,-11,AIR)
B(4,-6,-10,AIR)
B(4,-6,-9,AIR)
B(4,-6,-8,AIR)
B(4,-6,-7,AIR)
B(4,-6,-6,STONE)
B(4,-6,-5,STONE)
B(4,-6,-4,STONE)
B(4,-6,-3,STONE)
B(4,-6,-2,STONE)
B(4,-6,-1,STONE)
B(4,-6,0,STONE)
B(4,-5,-22,STONE)
B(4,-5,-21,STONE)
B(4,-5,-20,STONE)
B(4,-5,-19,STONE)
B(4,-5,-18,STONE)
B(4,-5,-17,AIR)
B(4,-5,-16,AIR)
B(4,-5,-15,AIR)
B(4,-5,-14,AIR)
B(4,-5,-13,AIR)
B(4,-5,-12,AIR)
B(4,-5,-11,AIR)
B(4,-5,-10,AIR)
B(4,-5,-9,AIR)
B(4,-5,-8,AIR)
B(4,-5,-7,AIR)
B(4,-5,-6,STONE)
B(4,-5,-5,STONE)
B(4,-5,-4,STONE)
B(4,-5,-3,STONE)
B(4,-5,-2,STONE)
B(4,-5,-1,STONE)
B(4,-5,0,STONE)
B(4,-4,-22,STONE)
B(4,-4,-21,STONE)
B(4,-4,-20,STONE)
B(4,-4,-19,STONE)
B(4,-4,-18,STONE)
B(4,-4,-17,AIR)
B(4,-4,-16,AIR)
B(4,-4,-15,AIR)
B(4,-4,-14,AIR)
B(4,-4,-13,AIR)
B(4,-4,-12,AIR)
B(4,-4,-11,AIR)
B(4,-4,-10,AIR)
B(4,-4,-9,AIR)
B(4,-4,-8,AIR)
B(4,-4,-7,VINE:1)
B(4,-4,-6,STONE)
B(4,-4,-5,STONE)
B(4,-4,-4,STONE)
B(4,-4,-3,STONE)
B(4,-4,-2,STONE)
B(4,-4,-1,STONE)
B(4,-4,0,STONE)
B(4,-4,1,STONE)
B(4,-3,-22,STONE)
B(4,-3,-21,STONE)
B(4,-3,-20,STONE)
B(4,-3,-19,STONE)
B(4,-3,-18,STONE)
B(4,-3,-17,AIR)
B(4,-3,-16,AIR)
B(4,-3,-15,AIR)
B(4,-3,-14,AIR)
B(4,-3,-13,AIR)
B(4,-3,-12,AIR)
B(4,-3,-11,AIR)
B(4,-3,-10,AIR)
B(4,-3,-9,AIR)
B(4,-3,-8,AIR)
B(4,-3,-7,AIR)
B(4,-3,-6,STONE)
B(4,-3,-5,STONE)
B(4,-3,-4,STONE)
B(4,-3,-3,STONE)
B(4,-3,-2,STONE)
B(4,-3,-1,STONE)
B(4,-3,0,STONE)
B(4,-3,1,STONE)
B(4,-2,-22,STONE)
B(4,-2,-21,STONE)
B(4,-2,-20,STONE)
B(4,-2,-19,STONE)
B(4,-2,-18,STONE)
B(4,-2,-17,STONE)
B(4,-2,-16,AIR)
B(4,-2,-15,AIR)
B(4,-2,-14,AIR)
B(4,-2,-13,AIR)
B(4,-2,-12,AIR)
B(4,-2,-11,AIR)
B(4,-2,-10,AIR)
B(4,-2,-9,AIR)
B(4,-2,-8,AIR)
B(4,-2,-7,STONE)
B(4,-2,-6,STONE)
B(4,-2,-5,STONE)
B(4,-2,-4,STONE)
B(4,-2,-3,STONE)
B(4,-2,-2,STONE)
B(4,-2,-1,STONE)
B(4,-2,0,STONE)
B(4,-2,1,STONE)
B(4,-1,-21,STONE)
B(4,-1,-20,STONE)
B(4,-1,-19,STONE)
B(4,-1,-18,STONE)
B(4,-1,-17,STONE)
B(4,-1,-16,STONE)
B(4,-1,-15,AIR)
B(4,-1,-14,AIR)
B(4,-1,-13,AIR)
B(4,-1,-12,AIR)
B(4,-1,-11,AIR)
B(4,-1,-10,AIR)
B(4,-1,-9,AIR)
B(4,-1,-8,STONE)
B(4,-1,-7,STONE)
B(4,-1,-6,STONE)
B(4,-1,-5,STONE)
B(4,-1,-4,STONE)
B(4,-1,-3,STONE)
B(4,-1,-2,STONE)
B(4,-1,-1,STONE)
B(4,-1,0,STONE)
B(4,-1,1,STONE)
B(4,0,-20,STONE)
B(4,0,-19,STONE)
B(4,0,-18,STONE)
B(4,0,-17,STONE)
B(4,0,-16,STONE)
B(4,0,-15,STONE)
B(4,0,-14,STONE)
B(4,0,-13,AIR)
B(4,0,-12,AIR)
B(4,0,-11,AIR)
B(4,0,-10,STONE)
B(4,0,-9,STONE)
B(4,0,-8,STONE)
B(4,0,-7,STONE)
B(4,0,-6,STONE)
B(4,0,-5,STONE)
B(4,0,-4,STONE)
B(4,0,-3,STONE)
B(4,0,-2,STONE)
B(4,0,-1,STONE)
B(4,0,0,STONE)
B(4,1,-20,STONE)
B(4,1,-19,STONE)
B(4,1,-18,STONE)
B(4,1,-17,STONE)
B(4,1,-16,STONE)
B(4,1,-15,STONE)
B(4,1,-14,STONE)
B(4,1,-13,STONE)
B(4,1,-12,STONE)
B(4,1,-11,STONE)
B(4,1,-10,STONE)
B(4,1,-9,STONE)
B(4,1,-8,STONE)
B(4,1,-7,STONE)
B(4,1,-6,STONE)
B(4,1,-5,STONE)
B(4,1,-4,STONE)
B(4,1,-3,STONE)
B(4,1,-2,STONE)
B(4,1,-1,STONE)
B(4,2,-19,STONE)
B(4,2,-18,STONE)
B(4,2,-17,STONE)
B(4,2,-16,STONE)
B(4,2,-15,STONE)
B(4,2,-14,STONE)
B(4,2,-13,STONE)
B(4,2,-12,STONE)
B(4,2,-11,STONE)
B(4,2,-10,STONE)
B(4,2,-9,STONE)
B(4,2,-8,STONE)
B(4,2,-7,STONE)
B(4,2,-6,STONE)
B(4,2,-5,STONE)
B(4,2,-4,STONE)
B(4,2,-3,STONE)
B(4,2,-2,STONE)
B(4,3,-18,STONE)
B(4,3,-17,STONE)
B(4,3,-16,STONE)
B(4,3,-15,STONE)
B(4,3,-14,STONE)
B(4,3,-13,STONE)
B(4,3,-12,STONE)
B(4,3,-11,STONE)
B(4,3,-10,STONE)
B(4,3,-9,STONE)
B(4,3,-8,STONE)
B(4,3,-7,STONE)
B(4,3,-6,STONE)
B(4,3,-5,STONE)
B(4,3,-4,STONE)
B(4,3,-3,STONE)
B(4,4,-16,STONE)
B(4,4,-15,STONE)
B(4,4,-14,STONE)
B(4,4,-13,STONE)
B(4,4,-12,STONE)
B(4,4,-11,STONE)
B(4,4,-10,STONE)
B(4,4,-9,STONE)
B(4,4,-8,STONE)
B(4,4,-7,STONE)
B(4,4,-6,STONE)
B(4,4,-5,STONE)
B(4,4,-4,STONE)
B(4,5,-16,STONE)
B(4,5,-15,STONE)
B(4,5,-14,STONE)
B(4,5,-13,STONE)
B(4,5,-12,STONE)
B(4,5,-11,STONE)
B(4,5,-10,STONE)
B(4,5,-9,STONE)
B(4,5,-8,STONE)
B(4,5,-7,STONE)
B(4,5,-6,STONE)
B(4,6,-15,STONE)
B(4,6,-14,STONE)
B(4,6,-13,STONE)
B(4,6,-12,STONE)
B(4,6,-11,STONE)
B(4,6,-10,STONE)
B(4,6,-9,STONE)
B(5,-14,-17,STONE)
B(5,-14,-16,STONE)
B(5,-14,-15,STONE)
B(5,-14,-14,STONE)
B(5,-14,-13,STONE)
B(5,-14,-12,STONE)
B(5,-14,-11,STONE)
B(5,-14,-10,STONE)
B(5,-14,-9,STONE)
B(5,-14,-8,STONE)
B(5,-14,-7,STONE)
B(5,-13,-19,STONE)
B(5,-13,-18,STONE)
B(5,-13,-17,STONE)
B(5,-13,-16,STONE)
B(5,-13,-15,STONE)
B(5,-13,-14,STONE)
B(5,-13,-13,STONE)
B(5,-13,-12,STONE)
B(5,-13,-11,STONE)
B(5,-13,-10,STONE)
B(5,-13,-9,STONE)
B(5,-13,-8,STONE)
B(5,-13,-7,STONE)
B(5,-13,-6,STONE)
B(5,-12,-19,STONE)
B(5,-12,-18,STONE)
B(5,-12,-17,STONE)
B(5,-12,-16,STONE)
B(5,-12,-15,STONE)
B(5,-12,-14,STONE)
B(5,-12,-13,STONE)
B(5,-12,-12,STONE)
B(5,-12,-11,STONE)
B(5,-12,-10,STONE)
B(5,-12,-9,STONE)
B(5,-12,-8,STONE)
B(5,-12,-7,STONE)
B(5,-12,-6,STONE)
B(5,-12,-5,STONE)
B(5,-12,-4,STONE)
B(5,-11,-20,STONE)
B(5,-11,-19,STONE)
B(5,-11,-18,STONE)
B(5,-11,-17,STONE)
B(5,-11,-16,STONE)
B(5,-11,-15,STONE)
B(5,-11,-14,STONE)
B(5,-11,-13,STONE)
B(5,-11,-12,STONE)
B(5,-11,-11,STONE)
B(5,-11,-10,STONE)
B(5,-11,-9,STONE)
B(5,-11,-8,STONE)
B(5,-11,-7,STONE)
B(5,-11,-6,STONE)
B(5,-11,-5,STONE)
B(5,-11,-4,STONE)
B(5,-11,-3,STONE)
B(5,-10,-21,STONE)
B(5,-10,-20,STONE)
B(5,-10,-19,STONE)
B(5,-10,-18,STONE)
B(5,-10,-17,STONE)
B(5,-10,-16,STONE)
B(5,-10,-15,STONE)
B(5,-10,-14,STONE)
B(5,-10,-13,STONE)
B(5,-10,-12,STONE)
B(5,-10,-11,STONE)
B(5,-10,-10,STONE)
