#######################################################################
# +-----------------------------------------------------------------+ #
# |                            BO3 object                           | #
# +-----------------------------------------------------------------+ #
#######################################################################

# The descriptions in this file are true only for TerrainControl. They are not true for the Minecraft Worlds mod!
# Minecraft Worlds completely reimplemented BO3s, check the MCW documentation on the mc/mctcp forums for how to use BO3s with MCW
# or watch the video's on my YT channel at https://www.youtube.com/user/PeeGee85. You can check out the "Editing and importing schematics & BO3s" 
# series of video's, in part 2 I explain BO3s. 

# This is the config file of a custom object.
# If you add this object correctly to your BiomeConfigs, it will spawn in the world.

# This is the creator of this BO3 object
Author: Unknown

# A short description of this BO3 object
Description: This BO3 was converted from a schematic using the MineCraft Worlds Editor. Unfortunately the author and description information for the schematic could not be found. If you know who the author of the schematic is then please tell the author of this BO3!

# The BO3 version, don't change this! It can be used by external applications to do a version check.
Version: 3

# The settings mode, WriteAll, WriteWithoutComments or WriteDisable. See WorldConfig.
SettingsMode: WriteDisable

#######################################################################
# +-----------------------------------------------------------------+ #
# |                          Main settings                          | #
# +-----------------------------------------------------------------+ #
#######################################################################

# This needs to be set to true to spawn the object in the Tree and Sapling resources.
Tree: false

# The frequency of the BO3 from 1 to 200. Tries this many times to spawn this BO3 when using the CustomObject(...) resource.
# Ignored by Tree(..), Sapling(..) and CustomStructure(..)
Frequency: 40

# The rarity of the BO3 from 0 to 100. Each spawn attempt has rarity% chance to succeed when using the CustomObject(...) resource.
# Ignored by Tree(..), Sapling(..) and CustomStructure(..)
Rarity: 100.0

# If you set this to true, the BO3 will be placed with a random rotation.
RotateRandomly: false

# The spawn height of the BO3 - randomY, highestBlock or highestSolidBlock.
SpawnHeight: highestBlock

# The height limits for the BO3.
MinHeight: 0

MaxHeight: 256

# Objects can have other objects attached to it: branches. Branches can also
# have branches attached to it, which can also have branches, etc. This is the
# maximum branch depth for this objects.
MaxBranchDepth: 10

# When spawned with the UseWorld keyword, this BO3 should NOT spawn in the following biomes.
# If you writer.write the BO3 name directly in the BiomeConfigs, this will be ignored.
ExcludedBiomes: All

#######################################################################
# +-----------------------------------------------------------------+ #
# |                      Source block settings                      | #
# +-----------------------------------------------------------------+ #
#######################################################################

# The B(s) the BO3 should spawn in.
SourceBlocks: AIR

# The maximum percentage of the BO3 that can be outside the SourceBlock.
# The BO3 won't be placed on a location with more blocks outside the SourceBlock than this percentage.
MaxPercentageOutsideSourceBlock: 100

# What to do when a block is about to be placed outside the SourceBlock? (dontPlace, placeAnyway)
OutsideSourceBlock: placeAnyway

#######################################################################
# +-----------------------------------------------------------------+ #
# |                              Blocks                             | #
# +-----------------------------------------------------------------+ #
#######################################################################

# All the blocks used in the BO3 are listed here. Possible blocks:
# B(x,y,z,id[.data][,nbtfile.nbt)
# RB(x,y,z,id[:data][,nbtfile.nbt],chance[,id[:data][,nbtfile.nbt],chance[,...]])
# So RB(0,0,0,CHEST,chest.nbt,50,CHEST,anotherchest.nbt,100) will spawn a chest at
# the BO3 origin, and give it a 50% chance to have the contents of chest.nbt, or, if that
# fails, a 100% percent chance to have the contents of anotherchest.nbt.

B(-8,11,-4,35)
B(-8,11,-3,35)
B(-8,12,-4,35)
B(-8,12,-3,35)
B(-8,12,-2,35)
B(-8,13,-5,35)
B(-8,13,-4,35)
B(-8,13,-3,35)
B(-8,13,-2,35)
B(-8,14,-5,35)
B(-8,14,-4,35)
B(-8,14,-3,35)
B(-8,14,-2,35)
B(-8,15,-5,35)
B(-8,15,-4,35)
B(-8,15,-3,35)
B(-8,16,-4,35)
B(-8,16,-3,35)
B(-8,17,-4,35)
B(-8,18,-4,35)
B(-7,8,-4,35)
B(-7,8,-3,35)
B(-7,8,-2,35)
B(-7,9,-5,35)
B(-7,9,-4,35)
B(-7,9,-3,35)
B(-7,9,-2,35)
B(-7,10,-5,35)
B(-7,10,-4,35)
B(-7,10,-3,35)
B(-7,10,-2,35)
B(-7,10,-1,35)
B(-7,11,-5,35)
B(-7,11,-4,35)
B(-7,11,-3,35)
B(-7,11,-2,35)
B(-7,11,-1,35)
B(-7,12,-5,35)
B(-7,12,-4,35)
B(-7,12,-3,35)
B(-7,12,-2,35)
B(-7,12,-1,35)
B(-7,13,-5,35)
B(-7,13,-4,35)
B(-7,13,-3,35)
B(-7,13,-2,35)
B(-7,13,-1,35)
B(-7,14,-5,35)
B(-7,14,-4,35)
B(-7,14,-3,35)
B(-7,14,-2,35)
B(-7,14,-1,35)
B(-7,15,-5,35)
B(-7,15,-4,35)
B(-7,15,-3,35)
B(-7,15,-2,35)
B(-7,15,-1,35)
B(-7,16,-5,35)
B(-7,16,-4,35)
B(-7,16,-3,35)
B(-7,16,-2,35)
B(-7,17,-5,35)
B(-7,17,-4,35)
B(-7,17,-3,35)
B(-7,17,-2,35)
B(-7,18,-5,35)
B(-7,18,-4,35)
B(-7,18,-3,35)
B(-7,18,-2,35)
B(-7,19,-5,35)
B(-7,19,-4,35)
B(-7,19,-3,35)
B(-7,19,-2,35)
B(-7,20,-4,35)
B(-7,20,-3,35)
B(-7,20,-2,35)
B(-7,21,-5,35)
B(-7,21,-4,35)
B(-7,21,-3,35)
B(-7,21,-2,35)
B(-7,22,-4,35)
B(-7,22,-3,35)
B(-7,22,-2,35)
B(-7,23,-4,35)
B(-7,23,-3,35)
B(-7,23,-2,35)
B(-7,24,-4,35)
B(-7,24,-3,35)
B(-7,24,-2,35)
B(-6,6,-5,35)
B(-6,6,-4,35)
B(-6,6,-3,35)
B(-6,6,-2,35)
B(-6,7,-5,35)
B(-6,7,-4,35)
B(-6,7,-3,35)
B(-6,7,-2,35)
B(-6,8,-5,35)
B(-6,8,-4,35)
B(-6,8,-3,35)
B(-6,8,-2,35)
B(-6,8,-1,35)
B(-6,9,-6,35)
B(-6,9,-5,35)
B(-6,9,-4,35)
B(-6,9,-3,35)
B(-6,9,-2,35)
B(-6,9,-1,35)
B(-6,10,-6,35)
B(-6,10,-5,35)
B(-6,10,-4,35)
B(-6,10,-3,35)
B(-6,10,-2,35)
B(-6,10,-1,35)
B(-6,11,-7,35)
B(-6,11,-6,35)
B(-6,11,-5,35)
B(-6,11,-4,35)
B(-6,11,-3,35)
B(-6,11,-2,35)
B(-6,11,-1,35)
B(-6,12,-7,35)
B(-6,12,-6,35)
B(-6,12,-5,35)
B(-6,12,-4,35)
B(-6,12,-3,35)
B(-6,12,-2,35)
B(-6,12,-1,35)
B(-6,12,0,35)
B(-6,13,-7,35)
B(-6,13,-6,35)
B(-6,13,-5,35)
B(-6,13,-4,35)
B(-6,13,-3,35)
B(-6,13,-2,35)
B(-6,13,-1,35)
B(-6,13,0,35)
B(-6,14,-7,35)
B(-6,14,-6,35)
B(-6,14,-5,35)
B(-6,14,-4,35)
B(-6,14,-3,35)
B(-6,14,-2,35)
B(-6,14,-1,35)
B(-6,14,0,35)
B(-6,15,-7,35)
B(-6,15,-6,35)
B(-6,15,-5,35)
B(-6,15,-4,35)
B(-6,15,-3,35)
B(-6,15,-2,35)
B(-6,15,-1,35)
B(-6,16,-7,35)
B(-6,16,-6,35)
B(-6,16,-5,35)
B(-6,16,-4,35)
B(-6,16,-3,35)
B(-6,16,-2,35)
B(-6,16,-1,35)
B(-6,17,-6,35)
B(-6,17,-5,35)
B(-6,17,-4,35)
B(-6,17,-3,35)
B(-6,17,-2,35)
B(-6,17,-1,35)
B(-6,18,-6,35)
B(-6,18,-5,35)
B(-6,18,-4,35)
B(-6,18,-3,35)
B(-6,18,-2,35)
B(-6,18,-1,35)
B(-6,19,-6,35)
B(-6,19,-5,35)
B(-6,19,-4,35)
B(-6,19,-3,35)
B(-6,19,-2,35)
B(-6,19,-1,35)
B(-6,20,-5,35)
B(-6,20,-4,35)
B(-6,20,-3,35)
B(-6,20,-2,35)
B(-6,20,-1,35)
B(-6,21,-5,35)
B(-6,21,-4,35)
B(-6,21,-3,35)
B(-6,21,-2,35)
B(-6,21,-1,35)
B(-6,22,-5,35)
B(-6,22,-4,35)
B(-6,22,-3,35)
B(-6,22,-2,35)
B(-6,22,-1,35)
B(-6,23,-5,35)
B(-6,23,-4,35)
B(-6,23,-3,35)
B(-6,23,-2,35)
B(-6,23,-1,35)
B(-6,24,-5,35)
B(-6,24,-4,35)
B(-6,24,-3,35)
B(-6,24,-2,35)
B(-6,24,-1,35)
B(-5,5,-5,35)
B(-5,5,-4,35)
B(-5,5,-3,35)
B(-5,5,-2,35)
B(-5,6,-6,35)
B(-5,6,-5,35)
B(-5,6,-4,35)
B(-5,6,-3,35)
B(-5,6,-2,35)
B(-5,6,-1,35)
B(-5,7,-6,35)
B(-5,7,-5,35)
B(-5,7,-4,35)
B(-5,7,-3,35)
B(-5,7,-2,35)
B(-5,7,-1,35)
B(-5,8,-6,35)
B(-5,8,-5,35)
B(-5,8,-4,35)
B(-5,8,-3,35)
B(-5,8,-2,35)
B(-5,8,-1,35)
B(-5,9,-6,35)
B(-5,9,-5,35)
B(-5,9,-4,35)
B(-5,9,-3,35)
B(-5,9,-2,35)
B(-5,9,-1,35)
B(-5,10,-6,35)
B(-5,10,-5,35)
B(-5,10,-4,35)
B(-5,10,-3,35)
B(-5,10,-2,35)
B(-5,10,-1,35)
B(-5,10,0,35)
B(-5,11,-6,35)
B(-5,11,-5,35)
B(-5,11,-4,35)
B(-5,11,-3,35)
B(-5,11,-2,35)
B(-5,11,-1,35)
B(-5,11,0,35)
B(-5,12,-7,35)
B(-5,12,-6,35)
B(-5,12,-5,35)
B(-5,12,-4,35)
B(-5,12,-3,35)
B(-5,12,-2,35)
B(-5,12,-1,35)
B(-5,12,0,35)
B(-5,13,-7,35)
B(-5,13,-6,35)
B(-5,13,-5,35)
B(-5,13,-4,35)
B(-5,13,-3,35)
B(-5,13,-2,35)
B(-5,13,-1,35)
B(-5,13,0,35)
B(-5,14,-7,35)
B(-5,14,-6,35)
B(-5,14,-5,35)
B(-5,14,-4,35)
B(-5,14,-3,35)
B(-5,14,-2,35)
B(-5,14,-1,35)
B(-5,14,0,35)
B(-5,15,-7,35)
B(-5,15,-6,35)
B(-5,15,-5,35)
B(-5,15,-4,35)
B(-5,15,-3,35)
B(-5,15,-2,35)
B(-5,15,-1,35)
B(-5,15,0,35)
B(-5,16,-7,35)
B(-5,16,-6,35)
B(-5,16,-5,35)
B(-5,16,-4,35)
B(-5,16,-3,35)
B(-5,16,-2,35)
B(-5,16,-1,35)
B(-5,16,0,35)
B(-5,17,-7,35)
B(-5,17,-6,35)
B(-5,17,-5,35)
B(-5,17,-4,35)
B(-5,17,-3,35)
B(-5,17,-2,35)
B(-5,17,-1,35)
B(-5,18,-6,35)
B(-5,18,-5,35)
B(-5,18,-4,35)
B(-5,18,-3,35)
B(-5,18,-2,35)
B(-5,18,-1,35)
B(-5,19,-6,35)
B(-5,19,-5,35)
B(-5,19,-4,35)
B(-5,19,-3,35)
B(-5,19,-2,35)
B(-5,19,-1,35)
B(-5,20,-6,35)
B(-5,20,-5,35)
B(-5,20,-4,35)
B(-5,20,-3,35)
B(-5,20,-2,35)
B(-5,20,-1,35)
B(-5,21,-5,35)
B(-5,21,-4,35)
B(-5,21,-3,35)
B(-5,21,-2,35)
B(-5,21,-1,35)
B(-5,22,-5,35)
B(-5,22,-4,35)
B(-5,22,-3,35)
B(-5,22,-2,35)
B(-5,22,-1,35)
B(-5,23,-5,35)
B(-5,23,-4,35)
B(-5,23,-3,35)
B(-5,23,-2,35)
B(-5,23,-1,35)
B(-5,24,-5,35)
B(-5,24,-4,35)
B(-5,24,-3,35)
B(-5,24,-2,35)
B(-5,24,-1,35)
B(-5,25,-1,1)
B(-4,4,-6,35)
B(-4,4,-5,35)
B(-4,4,-4,35)
B(-4,4,-3,35)
B(-4,4,-2,35)
B(-4,5,-6,35)
B(-4,5,-5,35)
B(-4,5,-4,35)
B(-4,5,-3,35)
B(-4,5,-2,35)
B(-4,5,-1,35)
B(-4,6,-6,35)
B(-4,6,-5,35)
B(-4,6,-4,35)
B(-4,6,-3,35)
B(-4,6,-2,35)
B(-4,6,-1,35)
B(-4,7,-6,35)
B(-4,7,-5,35)
B(-4,7,-4,35)
B(-4,7,-3,35)
B(-4,7,-2,35)
B(-4,7,-1,35)
B(-4,8,-6,35)
B(-4,8,-5,35)
B(-4,8,-4,35)
B(-4,8,-3,35)
B(-4,8,-2,35)
B(-4,8,-1,35)
B(-4,9,-6,35)
B(-4,9,-5,35)
B(-4,9,-4,35)
B(-4,9,-3,35)
B(-4,9,-2,35)
B(-4,9,-1,35)
B(-4,10,-6,35)
B(-4,10,-5,35)
B(-4,10,-4,35)
B(-4,10,-3,35)
B(-4,10,-2,35)
B(-4,10,-1,35)
B(-4,11,-6,35)
B(-4,11,-5,35)
B(-4,11,-4,35)
B(-4,11,-3,35)
B(-4,11,-2,35)
B(-4,11,-1,35)
B(-4,12,-6,35)
B(-4,12,-5,35)
B(-4,12,-4,35)
B(-4,12,-3,35)
B(-4,12,-2,35)
B(-4,12,-1,35)
B(-4,13,-6,35)
B(-4,13,-5,35)
B(-4,13,-4,35)
B(-4,13,-3,35)
B(-4,13,-2,35)
B(-4,13,-1,35)
B(-4,13,0,35)
B(-4,14,-6,35)
B(-4,14,-5,35)
B(-4,14,-4,35)
B(-4,14,-3,35)
B(-4,14,-2,35)
B(-4,14,-1,35)
B(-4,14,0,35)
B(-4,15,-6,35)
B(-4,15,-5,35)
B(-4,15,-4,35)
B(-4,15,-3,35)
B(-4,15,-2,35)
B(-4,15,-1,35)
B(-4,16,-5,35)
B(-4,16,-4,35)
B(-4,16,-3,35)
B(-4,16,-2,35)
B(-4,16,-1,35)
B(-4,17,-5,35)
B(-4,17,-4,35)
B(-4,17,-3,35)
B(-4,17,-2,35)
B(-4,17,-1,35)
B(-4,18,-5,35)
B(-4,18,-4,35)
B(-4,18,-3,35)
B(-4,18,-2,35)
B(-4,18,-1,35)
B(-4,19,-5,35)
B(-4,19,-4,35)
B(-4,19,-3,35)
B(-4,19,-2,35)
B(-4,19,-1,35)
B(-4,20,-5,35)
B(-4,20,-4,35)
B(-4,20,-3,35)
B(-4,20,-2,35)
B(-4,20,-1,35)
B(-4,21,-5,35)
B(-4,21,-4,35)
B(-4,21,-3,35)
B(-4,21,-2,35)
B(-4,21,-1,35)
B(-4,22,-5,35)
B(-4,22,-4,35)
B(-4,22,-3,35)
B(-4,22,-2,35)
B(-4,22,-1,35)
B(-4,23,-5,35)
B(-4,23,-4,35)
B(-4,23,-3,35)
B(-4,23,-2,35)
B(-4,24,-5,35)
B(-4,24,-4,35)
B(-4,24,-3,35)
B(-4,24,-2,35)
B(-3,1,-7,35)
B(-3,2,-7,35)
B(-3,2,-6,35)
B(-3,3,-7,35)
B(-3,3,-6,35)
B(-3,3,-5,35)
B(-3,3,-4,35)
B(-3,3,-3,35)
B(-3,4,-7,35)
B(-3,4,-6,35)
B(-3,4,-5,35)
B(-3,4,-4,35)
B(-3,4,-3,35)
B(-3,4,-2,35)
B(-3,5,-7,35)
B(-3,5,-6,35)
B(-3,5,-5,35)
B(-3,5,-4,35)
B(-3,5,-3,35)
B(-3,5,-2,35)
B(-3,5,-1,35)
B(-3,6,-7,35)
B(-3,6,-6,35)
B(-3,6,-5,35)
B(-3,6,-4,35)
B(-3,6,-3,35)
B(-3,6,-2,35)
B(-3,6,-1,35)
B(-3,7,-7,35)
B(-3,7,-6,35)
B(-3,7,-5,35)
B(-3,7,-4,35)
B(-3,7,-3,35)
B(-3,7,-2,35)
B(-3,7,-1,35)
B(-3,8,-6,35)
B(-3,8,-5,35)
B(-3,8,-4,35)
B(-3,8,-3,35)
B(-3,8,-2,35)
B(-3,8,-1,35)
B(-3,9,-6,35)
B(-3,9,-5,35)
B(-3,9,-4,35)
B(-3,9,-3,35)
B(-3,9,-2,35)
B(-3,9,-1,35)
B(-3,10,-6,35)
B(-3,10,-5,35)
B(-3,10,-4,35)
B(-3,10,-3,35)
B(-3,10,-2,35)
B(-3,10,-1,35)
B(-3,11,-6,35)
B(-3,11,-5,35)
B(-3,11,-4,35)
B(-3,11,-3,35)
B(-3,11,-2,35)
B(-3,11,-1,35)
B(-3,12,-5,35)
B(-3,12,-4,35)
B(-3,12,-3,35)
B(-3,12,-2,35)
B(-3,12,-1,35)
B(-3,13,-5,35)
B(-3,13,-4,35)
B(-3,13,-3,35)
B(-3,13,-2,35)
B(-3,13,-1,35)
B(-3,14,-5,35)
B(-3,14,-4,35)
B(-3,14,-3,35)
B(-3,14,-2,35)
B(-3,14,-1,35)
B(-3,15,-5,35)
B(-3,15,-4,35)
B(-3,15,-3,35)
B(-3,15,-2,35)
B(-3,15,-1,35)
B(-3,16,-5,35)
B(-3,16,-4,35)
B(-3,16,-3,35)
B(-3,16,-2,35)
B(-3,16,-1,35)
B(-3,17,-5,35)
B(-3,17,-4,35)
B(-3,17,-3,35)
B(-3,17,-2,35)
B(-3,17,-1,35)
B(-3,18,-5,35)
B(-3,18,-4,35)
B(-3,18,-3,35)
B(-3,18,-2,35)
B(-3,19,-5,35)
B(-3,19,-4,35)
B(-3,19,-3,35)
B(-3,19,-2,35)
B(-3,20,-5,35)
B(-3,20,-4,35)
B(-3,20,-3,35)
B(-3,20,-2,35)
B(-3,21,-5,35)
B(-3,21,-4,35)
B(-3,21,-3,35)
B(-3,21,-2,35)
B(-3,22,-5,35)
B(-3,22,-4,35)
B(-3,22,-3,35)
B(-3,22,-2,35)
B(-3,23,-4,35)
B(-3,23,-3,35)
B(-3,24,-4,35)
B(-3,24,-3,35)
B(-2,1,-7,35)
B(-2,1,-6,35)
B(-2,2,-7,35)
B(-2,2,-6,35)
B(-2,2,-5,35)
B(-2,3,-7,35)
B(-2,3,-6,35)
B(-2,3,-5,35)
B(-2,3,-4,35)
B(-2,3,-3,35)
B(-2,3,-2,35)
B(-2,4,-7,35)
B(-2,4,-6,35)
B(-2,4,-5,35)
B(-2,4,-4,35)
B(-2,4,-3,35)
B(-2,4,-2,35)
B(-2,4,-1,35)
B(-2,5,-7,35)
B(-2,5,-6,35)
B(-2,5,-5,35)
B(-2,5,-4,35)
B(-2,5,-3,35)
B(-2,5,-2,35)
B(-2,5,-1,35)
B(-2,6,-7,35)
B(-2,6,-6,35)
B(-2,6,-5,35)
B(-2,6,-4,35)
B(-2,6,-3,35)
B(-2,6,-2,35)
B(-2,6,-1,35)
B(-2,7,-7,35)
B(-2,7,-6,35)
B(-2,7,-5,35)
B(-2,7,-4,35)
B(-2,7,-3,35)
B(-2,7,-2,35)
B(-2,7,-1,35)
B(-2,8,-6,35)
B(-2,8,-5,35)
B(-2,8,-4,35)
B(-2,8,-3,35)
B(-2,8,-2,35)
B(-2,8,-1,35)
B(-2,9,-6,35)
B(-2,9,-5,35)
B(-2,9,-4,35)
B(-2,9,-3,35)
B(-2,9,-2,35)
B(-2,9,-1,35)
B(-2,10,-5,35)
B(-2,10,-4,35)
B(-2,10,-3,35)
B(-2,10,-2,35)
B(-2,11,-5,35)
B(-2,11,-4,35)
B(-2,11,-3,35)
B(-2,11,-2,35)
B(-2,12,-4,35)
B(-2,12,-3,35)
B(-2,12,-2,35)
B(-2,13,-4,35)
B(-2,13,-3,35)
B(-2,13,-2,35)
B(-2,14,-4,35)
B(-2,14,-3,35)
B(-2,15,-4,35)
B(-2,15,-3,35)
B(-2,16,-4,35)
B(-2,16,-3,35)
B(-2,17,-4,35)
B(-2,17,-3,35)
B(-2,17,-2,35)
B(-2,18,-3,35)
B(-2,19,-3,35)
B(-1,1,-7,35)
B(-1,1,-6,35)
B(-1,2,-7,35)
B(-1,2,-6,35)
B(-1,2,-5,35)
B(-1,2,-4,35)
B(-1,2,-3,35)
B(-1,3,-7,35)
B(-1,3,-6,35)
B(-1,3,-5,35)
B(-1,3,-4,35)
B(-1,3,-3,35)
B(-1,3,-2,35)
B(-1,4,-7,35)
B(-1,4,-6,35)
B(-1,4,-5,35)
B(-1,4,-4,35)
B(-1,4,-3,35)
B(-1,4,-2,35)
B(-1,4,-1,35)
B(-1,5,-7,35)
B(-1,5,-6,35)
B(-1,5,-5,35)
B(-1,5,-4,35)
B(-1,5,-3,35)
B(-1,5,-2,35)
B(-1,5,-1,35)
B(-1,6,-7,35)
B(-1,6,-6,35)
B(-1,6,-5,35)
B(-1,6,-4,35)
B(-1,6,-3,35)
B(-1,6,-2,35)
B(-1,6,-1,35)
B(-1,7,-7,35)
B(-1,7,-6,35)
B(-1,7,-5,35)
B(-1,7,-4,35)
B(-1,7,-3,35)
B(-1,7,-2,35)
B(-1,7,-1,35)
B(-1,8,-6,35)
B(-1,8,-5,35)
B(-1,8,-4,35)
B(-1,8,-3,35)
B(-1,8,-2,35)
B(-1,8,-1,35)
B(-1,9,-5,35)
B(-1,9,-4,35)
B(-1,9,-3,35)
B(-1,9,-2,35)
B(0,1,-7,35)
B(0,1,-6,35)
B(0,1,-4,35)
B(0,1,-3,35)
B(0,1,-2,35)
B(0,2,-7,35)
B(0,2,-6,35)
B(0,2,-5,35)
B(0,2,-4,35)
B(0,2,-3,35)
B(0,2,-2,35)
B(0,3,-7,35)
B(0,3,-6,35)
B(0,3,-5,35)
B(0,3,-4,35)
B(0,3,-3,35)
B(0,3,-2,35)
B(0,4,-7,35)
B(0,4,-6,35)
B(0,4,-5,35)
B(0,4,-4,35)
B(0,4,-3,35)
B(0,4,-2,35)
B(0,5,-7,35)
B(0,5,-6,35)
B(0,5,-5,35)
B(0,5,-4,35)
B(0,5,-3,35)
B(0,5,-2,35)
B(0,6,-7,35)
B(0,6,-6,35)
B(0,6,-5,35)
B(0,6,-4,35)
B(0,6,-3,35)
B(0,6,-2,35)
B(0,6,-1,35)
B(0,7,-7,35)
B(0,7,-6,35)
B(0,7,-5,35)
B(0,7,-4,35)
B(0,7,-3,35)
B(0,7,-2,35)
B(0,8,-5,35)
B(0,8,-4,35)
B(0,8,-3,35)
B(0,8,-2,35)
B(1,1,-4,35)
B(1,1,-3,35)
B(1,1,-2,35)
B(1,1,-1,35)
B(1,2,-7,35)
B(1,2,-6,35)
B(1,2,-5,35)
B(1,2,-4,35)
B(1,2,-3,35)
B(1,2,-2,35)
B(1,2,-1,35)
B(1,3,-7,35)
B(1,3,-6,35)
B(1,3,-5,35)
B(1,3,-4,35)
B(1,3,-3,35)
B(1,3,-2,35)
B(1,3,-1,35)
B(1,4,-7,35)
B(1,4,-6,35)
B(1,4,-5,35)
B(1,4,-4,35)
B(1,4,-3,35)
B(1,4,-2,35)
B(1,5,-7,35)
B(1,5,-6,35)
B(1,5,-5,35)
B(1,5,-4,35)
B(1,5,-3,35)
B(1,5,-2,35)
B(1,6,-7,35)
B(1,6,-6,35)
B(1,6,-5,35)
B(1,6,-4,35)
B(1,6,-3,35)
B(1,6,-2,35)
B(1,7,-6,35)
B(1,7,-5,35)
B(1,7,-4,35)
B(1,7,-3,35)
B(2,1,-5,35)
B(2,1,-4,35)
B(2,1,-3,35)
B(2,1,-2,35)
B(2,1,-1,35)
B(2,1,0,35)
B(2,2,-5,35)
B(2,2,-4,35)
B(2,2,-3,35)
B(2,2,-2,35)
B(2,2,-1,35)
B(2,2,0,35)
B(2,3,-6,35)
B(2,3,-5,35)
B(2,3,-4,35)
B(2,3,-3,35)
B(2,3,-2,35)
B(2,3,-1,35)
B(2,3,0,35)
B(2,4,-7,35)
B(2,4,-6,35)
B(2,4,-5,35)
B(2,4,-4,35)
B(2,4,-3,35)
B(2,4,-2,35)
B(2,4,-1,35)
B(2,5,-7,35)
B(2,5,-6,35)
B(2,5,-5,35)
B(2,5,-4,35)
B(2,5,-3,35)
B(2,5,-2,35)
B(2,6,-6,35)
B(2,6,-5,35)
B(2,6,-4,35)
B(2,6,-3,35)
B(2,7,-5,35)
B(2,7,-4,35)
B(3,1,-4,35)
B(3,1,-3,35)
B(3,1,-2,35)
B(3,1,-1,35)
B(3,1,0,35)
B(3,2,-4,35)
B(3,2,-3,35)
B(3,2,-2,35)
B(3,2,-1,35)
B(3,2,0,35)
B(3,3,-5,35)
B(3,3,-4,35)
B(3,3,-3,35)
B(3,3,-2,35)
B(3,3,-1,35)
B(3,3,0,35)
B(3,4,-5,35)
B(3,4,-4,35)
B(3,4,-3,35)
B(3,4,-2,35)
B(3,4,-1,35)
B(3,5,-5,35)
B(3,5,-4,35)
B(4,1,-3,35)
B(4,1,-2,35)
B(4,1,-1,35)
B(4,1,0,35)
B(4,2,-4,35)
B(4,2,-3,35)
B(4,2,-2,35)
B(4,2,-1,35)
B(4,2,0,35)
B(4,3,-3,35)
B(4,3,-2,35)
B(4,3,-1,35)
B(4,3,0,35)
B(4,4,-2,35)
B(5,0,-3,35)
B(5,0,-2,35)
B(5,0,-1,35)
B(5,0,0,35)
B(5,1,-3,35)
B(5,1,-2,35)
B(5,1,-1,35)
B(5,1,0,35)
B(5,2,-3,35)
B(5,2,-2,35)
B(5,2,-1,35)
B(5,2,0,35)
B(5,3,-3,35)
B(5,3,-2,35)
B(5,3,-1,35)
B(5,3,0,35)
B(6,0,-3,35)
B(6,0,-2,35)
B(6,0,-1,35)
B(6,0,0,35)
B(6,1,-6,35)
B(6,1,-5,35)
B(6,1,-4,35)
B(6,1,-3,35)
B(6,1,-2,35)
B(6,1,-1,35)
B(6,1,0,35)
B(6,2,-7,35)
B(6,2,-6,35)
B(6,2,-5,35)
B(6,2,-4,35)
B(6,2,-3,35)
B(6,2,-2,35)
B(6,2,-1,35)
B(6,2,0,35)
B(6,3,-6,35)
B(6,3,-5,35)
B(6,3,-4,35)
B(6,3,-3,35)
B(6,3,-2,35)
B(6,3,-1,35)
B(6,3,0,35)
B(7,0,-3,35)
B(7,0,-2,35)
B(7,0,-1,35)
B(7,0,0,35)
B(7,1,-7,35)
B(7,1,-6,35)
B(7,1,-5,35)
B(7,1,-4,35)
B(7,1,-3,35)
B(7,1,-2,35)
B(7,1,-1,35)
B(7,1,0,35)
B(7,2,-7,35)
B(7,2,-6,35)
B(7,2,-5,35)
B(7,2,-4,35)
B(7,2,-3,35)
B(7,2,-2,35)
B(7,2,-1,35)
B(7,2,0,35)
B(7,3,-7,35)
B(7,3,-6,35)
B(7,3,-5,35)
B(7,3,-4,35)
B(7,3,-3,35)
B(7,3,-2,35)
B(7,3,-1,35)
B(7,3,0,35)
B(7,4,-6,35)
B(7,4,-5,35)
B(7,4,-4,35)
B(7,4,-3,35)
B(7,4,-2,35)


#######################################################################
# +-----------------------------------------------------------------+ #
# |                            BO3 checks                           | #
# +-----------------------------------------------------------------+ #
#######################################################################

# Require a condition at a certain location in order for the BO3 to be spawned.
# BlockCheck(x,y,z,BlockName[,BlockName[,...]]) - one of the blocks must be at the location
# BlockCheckNot(x,y,z,BlockName[,BlockName[,...]]) - all the blocks must not be at the location
# LightCheck(x,y,z,minLightLevel,maxLightLevel) - light must be between min and max (inclusive)

# You can use "Solid" as a BlockName for matching all solid blocks or "All" to match all blocks that aren't air.

# Examples:
#   BlockCheck(0,-1,0,GRASS,DIRT,biomesoplenty:grass:0,biomesoplenty:grass:1,biomesoplenty:grass:2,biomesoplenty:grass:3,biomesoplenty:grass:4,biomesoplenty:grass:5,biomesoplenty:grass:6,biomesoplenty:grass:7,biomesoplenty:dirt:0,biomesoplenty:dirt:1,biomesoplenty:dirt:2,biomesoplenty:dirt:3,biomesoplenty:dirt:4,biomesoplenty:dirt:5,biomesoplenty:dirt:6,biomesoplenty:dirt:7,biomesoplenty:dirt:8,biomesoplenty:dirt:9,biomesoplenty:dirt:10,biomesoplenty:dried_sand:0,biomesoplenty:hard_ice:0,biomesoplenty:white_sand:0,biomesoplenty:white_sandstone:0,biomesoplenty:mud:0,biomesoplenty:ash_block:0)  Require grass or dirt just below the object
#   BlockCheck(0,-1,0,Solid)       Require any solid block just below the object
#   BlockCheck(0,-1,0,WOOL)        Require any type of wool just below the object
#   BlockCheck(0,-1,0,WOOL:0)      Require white wool just below the object
#   BlockCheckNot(0,-1,0,WOOL:0)   Require that there is no white wool below the object
#   LightCheck(0,0,0,0,1)          Require almost complete darkness just below the object

#######################################################################
# +-----------------------------------------------------------------+ #
# |                             Branches                            | #
# +-----------------------------------------------------------------+ #
#######################################################################

# Branches are objects that will spawn when this object spawns when it is used in
# the CustomStructure resource. Branches can also have branches, making complex
# structures possible. See the wiki for more details.

# Regular Branches spawn each branch with an independent chance of spawning.
# Branch(x,y,z,branchName,rotation,chance[,anotherBranchName,rotation,chance[,...]][IndividualChance])
# branchName - name of the object to spawn.
# rotation - NORTH, SOUTH, EAST or WEST.
# IndividualChance - The chance each branch has to spawn, assumed to be 100 when left blank

# WBR(x,y,z,branchName,rotation,chance[,anotherBranchName,rotation,chance[,...]][MaxChanceOutOf])
# MaxChanceOutOf - The chance all branches have to spawn out of, assumed to be 100 when left blank
Branch(0,0,0,SmallSurfaceCave2C0R0,NORTH,100)
