#######################################################################
# +-----------------------------------------------------------------+ #
# |                            BO3 object                           | #
# +-----------------------------------------------------------------+ #
#######################################################################

# The descriptions in this file are true only for TerrainControl. They are not true for the Minecraft Worlds mod!
# Minecraft Worlds completely reimplemented BO3s, check the MCW documentation on the mc/mctcp forums for how to use BO3s with MCW
# or watch the video's on my YT channel at https://www.youtube.com/user/PeeGee85. You can check out the "Editing and importing schematics & BO3s" 
# series of video's, in part 2 I explain BO3s. 

# This is the config file of a custom object.
# If you add this object correctly to your BiomeConfigs, it will spawn in the world.

# This is the creator of this BO3 object
Author: Unknown

# A short description of this BO3 object
Description: This BO3 was converted from a schematic using the MineCraft Worlds Editor. Unfortunately the author and description information for the schematic could not be found. If you know who the author of the schematic is then please tell the author of this BO3!

# The BO3 version, don't change this! It can be used by external applications to do a version check.
Version: 3

# The settings mode, WriteAll, WriteWithoutComments or WriteDisable. See WorldConfig.
SettingsMode: WriteDisable

#######################################################################
# +-----------------------------------------------------------------+ #
# |                          Main settings                          | #
# +-----------------------------------------------------------------+ #
#######################################################################

# This needs to be set to true to spawn the object in the Tree and Sapling resources.
Tree: false

# The frequency of the BO3 from 1 to 200. Tries this many times to spawn this BO3 when using the CustomObject(...) resource.
# Ignored by Tree(..), Sapling(..) and CustomStructure(..)
Frequency: 40

# The rarity of the BO3 from 0 to 100. Each spawn attempt has rarity% chance to succeed when using the CustomObject(...) resource.
# Ignored by Tree(..), Sapling(..) and CustomStructure(..)
Rarity: 100.0

# If you set this to true, the BO3 will be placed with a random rotation.
RotateRandomly: false

# The spawn height of the BO3 - randomY, highestBlock or highestSolidBlock.
SpawnHeight: randomY

# The height limits for the BO3.
MinHeight: 0

MaxHeight: 256

# Objects can have other objects attached to it: branches. Branches can also
# have branches attached to it, which can also have branches, etc. This is the
# maximum branch depth for this objects.
MaxBranchDepth: 10

# When spawned with the UseWorld keyword, this BO3 should NOT spawn in the following biomes.
# If you writer.write the BO3 name directly in the BiomeConfigs, this will be ignored.
ExcludedBiomes: All

#######################################################################
# +-----------------------------------------------------------------+ #
# |                      Source block settings                      | #
# +-----------------------------------------------------------------+ #
#######################################################################

# The block(s) the BO3 should spawn in.
SourceBlocks: AIR

# The maximum percentage of the BO3 that can be outside the SourceBlock.
# The BO3 won't be placed on a location with more blocks outside the SourceBlock than this percentage.
MaxPercentageOutsideSourceBlock: 100

# What to do when a block is about to be placed outside the SourceBlock? (dontPlace, placeAnyway)
OutsideSourceBlock: placeAnyway

#######################################################################
# +-----------------------------------------------------------------+ #
# |                              Blocks                             | #
# +-----------------------------------------------------------------+ #
#######################################################################

# All the blocks used in the BO3 are listed here. Possible blocks:
# Block(x,y,z,id[.data][,nbtfile.nbt)
# RandomBlock(x,y,z,id[:data][,nbtfile.nbt],chance[,id[:data][,nbtfile.nbt],chance[,...]])
# So RandomBlock(0,0,0,CHEST,chest.nbt,50,CHEST,anotherchest.nbt,100) will spawn a chest at
# the BO3 origin, and give it a 50% chance to have the contents of chest.nbt, or, if that
# fails, a 100% percent chance to have the contents of anotherchest.nbt.

Block(-8,13,-7,5:1)
Block(-8,13,-6,5:1)
Block(-8,13,-5,5:1)
Block(-8,13,-4,5:1)
Block(-8,13,-3,5:1)
Block(-8,13,-2,5:1)
Block(-8,13,-1,5:1)
Block(-8,13,0,5:1)
Block(-8,13,1,17:5)
Block(-8,14,-7,AIR)
Block(-8,14,-6,AIR)
Block(-8,14,-5,AIR)
Block(-8,14,-4,AIR)
Block(-8,14,-3,AIR)
Block(-8,14,-2,AIR)
Block(-8,14,-1,AIR)
Block(-8,14,0,134:6)
Block(-8,14,1,134:7)
Block(-8,15,-7,AIR)
Block(-8,15,-6,AIR)
Block(-8,15,-5,AIR)
Block(-8,15,-4,AIR)
Block(-8,15,-3,AIR)
Block(-8,15,-2,AIR)
Block(-8,15,-1,AIR)
Block(-8,15,0,160:9)
Block(-8,15,1,AIR)
Block(-8,16,-7,AIR)
Block(-8,16,-6,AIR)
Block(-8,16,-5,AIR)
Block(-8,16,-4,AIR)
Block(-8,16,-3,AIR)
Block(-8,16,-2,AIR)
Block(-8,16,-1,AIR)
Block(-8,16,0,134:2)
Block(-8,16,1,134:7)
Block(-8,17,-7,AIR)
Block(-8,17,-6,AIR)
Block(-8,17,-5,126:9)
Block(-8,17,-4,AIR)
Block(-8,17,-3,AIR)
Block(-8,17,-2,126:9)
Block(-8,17,-1,AIR)
Block(-8,17,0,AIR)
Block(-8,17,1,134:7)
Block(-8,18,-7,5:1)
Block(-8,18,-6,5:1)
Block(-8,18,-5,5:1)
Block(-8,18,-4,5:1)
Block(-8,18,-3,5:1)
Block(-8,18,-2,5:1)
Block(-8,18,-1,5:1)
Block(-8,18,0,5:1)
Block(-8,18,1,17:5)
Block(-8,19,-7,AIR)
Block(-8,19,-6,AIR)
Block(-8,19,-5,AIR)
Block(-8,19,-4,AIR)
Block(-8,19,-3,AIR)
Block(-8,19,-2,AIR)
Block(-8,19,-1,AIR)
Block(-8,19,0,134:6)
Block(-8,19,1,134:7)
Block(-8,20,-7,AIR)
Block(-8,20,-6,AIR)
Block(-8,20,-5,AIR)
Block(-8,20,-4,AIR)
Block(-8,20,-3,AIR)
Block(-8,20,-2,AIR)
Block(-8,20,-1,AIR)
Block(-8,20,0,160:9)
Block(-8,20,1,AIR)
Block(-8,21,-7,AIR)
Block(-8,21,-6,AIR)
Block(-8,21,-5,AIR)
Block(-8,21,-4,AIR)
Block(-8,21,-3,AIR)
Block(-8,21,-2,AIR)
Block(-8,21,-1,AIR)
Block(-8,21,0,134:2)
Block(-8,21,1,134:7)
Block(-8,22,-7,5:1)
Block(-8,22,-6,5:1)
Block(-8,22,-5,5:1)
Block(-8,22,-4,5:1)
Block(-8,22,-3,5:1)
Block(-8,22,-2,5:1)
Block(-8,22,-1,5:1)
Block(-8,22,0,5:1)
Block(-8,22,1,17:5)
Block(-8,23,-7,AIR)
Block(-8,23,-6,AIR)
Block(-8,23,-5,AIR)
Block(-8,23,-4,AIR)
Block(-8,23,-3,AIR)
Block(-8,23,-2,AIR)
Block(-8,23,-1,AIR)
Block(-8,23,0,AIR)
Block(-8,23,1,159:13)
Block(-8,23,2,126:13)
Block(-8,24,-7,AIR)
Block(-8,24,-6,AIR)
Block(-8,24,-5,AIR)
Block(-8,24,-4,AIR)
Block(-8,24,-3,AIR)
Block(-8,24,-2,AIR)
Block(-8,24,-1,AIR)
Block(-8,24,0,159:13)
Block(-8,24,1,AIR)
Block(-8,24,2,5:5)
Block(-8,25,-7,AIR)
Block(-8,25,-6,AIR)
Block(-8,25,-5,AIR)
Block(-8,25,-4,AIR)
Block(-8,25,-3,AIR)
Block(-8,25,-2,AIR)
Block(-8,25,-1,159:13)
Block(-8,25,0,AIR)
Block(-8,25,1,AIR)
Block(-8,26,-7,159:13)
Block(-8,26,-6,AIR)
Block(-8,26,-5,AIR)
Block(-8,26,-4,AIR)
Block(-8,26,-3,159:13)
Block(-8,26,-2,159:13)
Block(-8,26,-1,AIR)
Block(-8,26,0,AIR)
Block(-8,26,1,AIR)
Block(-8,27,-6,159:13)
Block(-8,27,-4,159:13)
Block(-8,27,-2,191)
Block(-8,28,-5,5:5)
Block(-8,28,-2,191)
Block(-8,29,-5,126:5)
Block(-8,29,-2,191)
Block(-8,30,-6,216)
Block(-8,30,-5,216)
Block(-8,30,-4,216)
Block(-8,30,-2,35:15)
Block(-8,31,-7,35:15)
Block(-8,31,-6,216)
Block(-8,31,-5,216)
Block(-8,31,-4,216)
Block(-8,31,-3,35:15)
Block(-8,31,-2,191)
Block(-8,32,-7,191)
Block(-8,32,-6,35:15)
Block(-8,32,-5,216)
Block(-8,32,-4,35:15)
Block(-8,32,-3,191)
Block(-8,33,-6,191)
Block(-8,33,-5,35:15)
Block(-8,33,-4,191)
Block(-8,34,-5,191)
Block(-7,13,-7,5:1)
Block(-7,13,-6,5:1)
Block(-7,13,-5,5:1)
Block(-7,13,-4,5:1)
Block(-7,13,-3,5:1)
Block(-7,13,-2,5:1)
Block(-7,13,-1,5:1)
Block(-7,13,0,5:1)
Block(-7,13,1,17:5)
Block(-7,14,-7,191)
Block(-7,14,-6,134:4)
Block(-7,14,-5,134:4)
Block(-7,14,-4,134:4)
Block(-7,14,-3,191)
Block(-7,14,-2,134:4)
Block(-7,14,-1,134:4)
Block(-7,14,0,134:4)
Block(-7,14,1,134:7)
Block(-7,15,-7,191)
Block(-7,15,-6,5:1)
Block(-7,15,-5,160:9)
Block(-7,15,-4,5:1)
Block(-7,15,-3,191)
Block(-7,15,-2,5:1)
Block(-7,15,-1,160:9)
Block(-7,15,0,5:1)
Block(-7,15,1,134)
Block(-7,16,-7,56)
Block(-7,16,-6,134)
Block(-7,16,-5,134)
Block(-7,16,-4,134)
Block(-7,16,-3,56)
Block(-7,16,-2,134)
Block(-7,16,-1,134)
Block(-7,16,0,134:2)
Block(-7,16,1,134:7)
Block(-7,17,-7,AIR)
Block(-7,17,-6,AIR)
Block(-7,17,-5,126:9)
Block(-7,17,-4,AIR)
Block(-7,17,-3,AIR)
Block(-7,17,-2,126:9)
Block(-7,17,-1,AIR)
Block(-7,17,0,AIR)
Block(-7,17,1,134:7)
Block(-7,18,-7,5:1)
Block(-7,18,-6,5:1)
Block(-7,18,-5,5:1)
Block(-7,18,-4,5:1)
Block(-7,18,-3,5:1)
Block(-7,18,-2,5:1)
Block(-7,18,-1,5:1)
Block(-7,18,0,5:1)
Block(-7,18,1,17:5)
Block(-7,19,-7,AIR)
Block(-7,19,-6,136:4)
Block(-7,19,-5,61:4)
Block(-7,19,-4,118:3)
Block(-7,19,-3,AIR)
Block(-7,19,-2,134:4)
Block(-7,19,-1,134:4)
Block(-7,19,0,134:4)
Block(-7,19,1,134:7)
Block(-7,20,-7,AIR)
Block(-7,20,-6,AIR)
Block(-7,20,-5,AIR)
Block(-7,20,-4,AIR)
Block(-7,20,-3,AIR)
Block(-7,20,-2,5:1)
Block(-7,20,-1,160:9)
Block(-7,20,0,5:1)
Block(-7,20,1,134)
Block(-7,21,-7,AIR)
Block(-7,21,-6,AIR)
Block(-7,21,-5,AIR)
Block(-7,21,-4,AIR)
Block(-7,21,-3,AIR)
Block(-7,21,-2,134)
Block(-7,21,-1,134)
Block(-7,21,0,134:2)
Block(-7,21,1,134:7)
Block(-7,22,-7,5:1)
Block(-7,22,-6,5:1)
Block(-7,22,-5,5:1)
Block(-7,22,-4,5:1)
Block(-7,22,-3,5:1)
Block(-7,22,-2,5:1)
Block(-7,22,-1,5:1)
Block(-7,22,0,5:1)
Block(-7,22,1,17:5)
Block(-7,23,-7,AIR)
Block(-7,23,-6,AIR)
Block(-7,23,-5,AIR)
Block(-7,23,-4,AIR)
Block(-7,23,-3,AIR)
Block(-7,23,-2,AIR)
Block(-7,23,-1,AIR)
Block(-7,23,0,AIR)
Block(-7,23,1,159:13)
Block(-7,23,2,126:13)
Block(-7,24,-7,AIR)
Block(-7,24,-6,AIR)
Block(-7,24,-5,AIR)
Block(-7,24,-4,AIR)
Block(-7,24,-3,AIR)
Block(-7,24,-2,AIR)
Block(-7,24,-1,AIR)
Block(-7,24,0,159:13)
Block(-7,24,1,AIR)
Block(-7,24,2,5:5)
Block(-7,25,-7,AIR)
Block(-7,25,-6,AIR)
Block(-7,25,-5,AIR)
Block(-7,25,-4,AIR)
Block(-7,25,-3,AIR)
Block(-7,25,-2,AIR)
Block(-7,25,-1,159:13)
Block(-7,25,0,AIR)
Block(-7,25,1,AIR)
Block(-7,26,-7,AIR)
Block(-7,26,-6,AIR)
Block(-7,26,-5,AIR)
Block(-7,26,-4,AIR)
Block(-7,26,-3,AIR)
Block(-7,26,-2,159:13)
Block(-7,26,-1,AIR)
Block(-7,26,0,AIR)
Block(-7,26,1,AIR)
Block(-7,27,-7,159:13)
Block(-7,27,-6,159:13)
Block(-7,27,-5,50:2)
Block(-7,27,-4,159:13)
Block(-7,27,-3,159:13)
Block(-7,28,-5,5:5)
Block(-7,29,-5,126:5)
Block(-7,30,-5,216)
Block(-7,31,-6,216)
Block(-7,31,-5,216)
Block(-7,31,-4,216)
Block(-7,32,-5,216)
Block(-6,0,-7,17:1)
Block(-6,0,1,17:1)
Block(-6,1,-7,17:1)
Block(-6,1,1,17:1)
Block(-6,2,-7,17:1)
Block(-6,2,1,17:1)
Block(-6,3,-7,17:1)
Block(-6,3,1,17:1)
Block(-6,4,-7,17:1)
Block(-6,4,1,17:1)
Block(-6,5,-7,17:1)
Block(-6,5,1,17:1)
Block(-6,6,-7,17:1)
Block(-6,6,1,17:1)
Block(-6,7,-7,17:1)
Block(-6,7,1,17:1)
Block(-6,8,-7,17:1)
Block(-6,8,1,17:1)
Block(-6,9,-7,17:1)
Block(-6,9,1,17:1)
Block(-6,10,-7,17:1)
Block(-6,10,1,17:1)
Block(-6,11,-7,17:1)
Block(-6,11,1,17:1)
Block(-6,12,-7,17:1)
Block(-6,12,1,17:1)
Block(-6,13,-7,17:9)
Block(-6,13,-6,17:9)
Block(-6,13,-5,17:9)
Block(-6,13,-4,17:9)
Block(-6,13,-3,17:9)
Block(-6,13,-2,17:9)
Block(-6,13,-1,17:9)
Block(-6,13,0,17:9)
Block(-6,13,1,17:5)
Block(-6,14,-7,17:1)
Block(-6,14,-6,134:5)
Block(-6,14,-5,134:5)
Block(-6,14,-4,134:5)
Block(-6,14,-3,17:1)
Block(-6,14,-2,134:5)
Block(-6,14,-1,134:5)
Block(-6,14,0,134:5)
Block(-6,14,1,17:1)
Block(-6,15,-7,17:1)
Block(-6,15,-6,134:1)
Block(-6,15,-5,AIR)
Block(-6,15,-4,134:1)
Block(-6,15,-3,17:1)
Block(-6,15,-2,134:1)
Block(-6,15,-1,AIR)
Block(-6,15,0,134:1)
Block(-6,15,1,17:1)
Block(-6,16,-7,17:1)
Block(-6,16,-6,134:5)
Block(-6,16,-5,134:5)
Block(-6,16,-4,134:5)
Block(-6,16,-3,17:1)
Block(-6,16,-2,134:5)
Block(-6,16,-1,134:5)
Block(-6,16,0,134:5)
Block(-6,16,1,17:1)
Block(-6,17,-7,17:1)
Block(-6,17,-6,134:5)
Block(-6,17,-5,134:5)
Block(-6,17,-4,134:5)
Block(-6,17,-3,17:1)
Block(-6,17,-2,134:5)
Block(-6,17,-1,134:5)
Block(-6,17,0,134:5)
Block(-6,17,1,17:1)
Block(-6,18,-7,17:9)
Block(-6,18,-6,17:9)
Block(-6,18,-5,17:9)
Block(-6,18,-4,17:9)
Block(-6,18,-3,17:9)
Block(-6,18,-2,17:9)
Block(-6,18,-1,17:9)
Block(-6,18,0,17:9)
Block(-6,18,1,17:1)
Block(-6,19,-7,17:1)
Block(-6,19,-6,134:5)
Block(-6,19,-5,134:5)
Block(-6,19,-4,134:5)
Block(-6,19,-3,17:1)
Block(-6,19,-2,134:5)
Block(-6,19,-1,134:5)
Block(-6,19,0,134:5)
Block(-6,19,1,17:1)
Block(-6,20,-7,17:1)
Block(-6,20,-6,134:1)
Block(-6,20,-5,134:1)
Block(-6,20,-4,134:1)
Block(-6,20,-3,17:1)
Block(-6,20,-2,134:1)
Block(-6,20,-1,AIR)
Block(-6,20,0,134:1)
Block(-6,20,1,17:1)
Block(-6,21,-7,17:1)
Block(-6,21,-6,134:5)
Block(-6,21,-5,134:5)
Block(-6,21,-4,134:5)
Block(-6,21,-3,17:1)
Block(-6,21,-2,134:5)
Block(-6,21,-1,134:5)
Block(-6,21,0,134:5)
Block(-6,21,1,17:1)
Block(-6,22,-7,17:9)
Block(-6,22,-6,17:9)
Block(-6,22,-5,17:9)
Block(-6,22,-4,17:9)
Block(-6,22,-3,17:9)
Block(-6,22,-2,17:9)
Block(-6,22,-1,17:9)
Block(-6,22,0,17:9)
Block(-6,22,1,17:5)
Block(-6,23,-7,134:5)
Block(-6,23,-6,134:5)
Block(-6,23,-5,134:5)
Block(-6,23,-4,134:5)
Block(-6,23,-3,134:5)
Block(-6,23,-2,134:5)
Block(-6,23,-1,134:5)
Block(-6,23,0,134:5)
Block(-6,23,1,159:13)
Block(-6,24,-7,5:1)
Block(-6,24,-6,134)
Block(-6,24,-5,AIR)
Block(-6,24,-4,134:2)
Block(-6,24,-3,5:1)
Block(-6,24,-2,5:1)
Block(-6,24,-1,5:1)
Block(-6,24,0,159:13)
Block(-6,24,1,AIR)
Block(-6,24,2,5:5)
Block(-6,25,-7,5:1)
Block(-6,25,-6,134:7)
Block(-6,25,-5,AIR)
Block(-6,25,-4,134:6)
Block(-6,25,-3,5:1)
Block(-6,25,-2,5:1)
Block(-6,25,-1,159:13)
Block(-6,25,0,AIR)
Block(-6,25,1,AIR)
Block(-6,25,2,126:5)
Block(-6,26,-7,5:1)
Block(-6,26,-6,5:1)
Block(-6,26,-5,5:1)
Block(-6,26,-4,5:1)
Block(-6,26,-3,5:1)
Block(-6,26,-2,159:13)
Block(-6,26,-1,AIR)
Block(-6,26,0,AIR)
Block(-6,26,1,AIR)
Block(-6,27,-7,159:13)
Block(-6,27,-6,5:1)
Block(-6,27,-5,5:1)
Block(-6,27,-4,5:1)
Block(-6,27,-3,159:13)
Block(-6,28,-6,159:13)
Block(-6,28,-5,5:1)
Block(-6,28,-4,159:13)
Block(-6,29,-5,5:5)
Block(-6,30,-5,216)
Block(-6,31,-6,216)
Block(-6,31,-5,216)
Block(-6,31,-4,216)
Block(-6,32,-6,216)
Block(-6,32,-5,216)
Block(-6,32,-4,216)
Block(-5,13,-3,17:5)
Block(-5,13,1,17:5)
Block(-5,18,-7,5:1)
Block(-5,18,-6,5:1)
Block(-5,18,-5,5:1)
Block(-5,18,-4,5:1)
Block(-5,18,-3,17:5)
Block(-5,19,-3,134:4)
Block(-5,22,1,17:5)
Block(-5,24,0,159:13)
Block(-5,24,2,126:13)
Block(-5,25,-1,159:13)
Block(-5,25,2,5:5)
Block(-5,26,-2,159:13)
Block(-5,27,-7,159:13)
Block(-5,27,-3,159:13)
Block(-5,28,-6,159:13)
Block(-5,28,-5,126:13)
Block(-5,28,-4,159:13)
Block(-5,29,-5,5:5)
Block(-5,31,-5,216)
Block(-5,32,-6,216)
Block(-5,32,-5,216)
Block(-5,32,-4,216)
Block(-5,33,-5,216)
Block(-4,0,-3,17:1)
Block(-4,1,-3,17:1)
Block(-4,2,-3,17:1)
Block(-4,3,-3,17:1)
Block(-4,4,-3,17:1)
Block(-4,5,-3,17:1)
Block(-4,6,-3,17:1)
Block(-4,7,-3,17:1)
Block(-4,8,-3,17:1)
Block(-4,9,-3,17:1)
Block(-4,10,-3,17:1)
Block(-4,11,-3,17:1)
Block(-4,12,-3,17:1)
Block(-4,13,-3,17:1)
Block(-4,14,-3,17:1)
Block(-4,15,-3,17:1)
Block(-4,16,-3,17:1)
Block(-4,17,-3,17:1)
Block(-4,18,-7,5:1)
Block(-4,18,-6,5:1)
Block(-4,18,-5,5:1)
Block(-4,18,-4,5:1)
Block(-4,18,-3,17:5)
Block(-4,19,-7,191)
Block(-4,19,-3,126:9)
Block(-4,20,-7,191)
Block(-4,21,-7,191)
Block(-4,22,-7,56)
Block(-4,25,-1,159:13)
Block(-4,25,2,5:5)
Block(-4,26,-2,159:13)
Block(-4,27,-7,159:13)
Block(-4,27,-3,159:13)
Block(-4,28,-6,159:13)
Block(-4,28,-5,126:13)
Block(-4,28,-4,159:13)
Block(-4,29,-5,5:5)
Block(-4,30,-5,126:5)
Block(-4,31,-5,216)
Block(-4,32,-6,216)
Block(-4,32,-5,216)
Block(-4,32,-4,216)
Block(-4,33,-5,216)
Block(-4,34,-5,216)
Block(-3,16,-3,134:5)
Block(-3,17,-3,134)
Block(-3,18,-7,5:1)
Block(-3,18,-6,5:1)
Block(-3,18,-5,5:1)
Block(-3,18,-4,5:1)
Block(-3,18,-3,17:5)
Block(-3,19,-3,134:5)
Block(-3,26,-2,159:13)
Block(-3,27,-7,159:13)
Block(-3,27,-3,159:13)
Block(-3,28,-6,159:13)
Block(-3,28,-4,159:13)
Block(-3,29,-5,5:5)
Block(-3,30,-5,126:5)
Block(-3,32,-6,216)
Block(-3,32,-5,216)
Block(-3,32,-4,216)
Block(-3,33,-6,216)
Block(-3,33,-5,216)
Block(-3,33,-4,216)
Block(-3,34,-5,216)
Block(-2,17,-3,134:5)
Block(-2,18,-7,17:9)
Block(-2,18,-6,17:9)
Block(-2,18,-5,17:9)
Block(-2,18,-4,17:9)
Block(-2,18,-3,17:5)
Block(-2,19,-7,126:9)
Block(-2,19,-6,126:9)
Block(-2,19,-5,126:9)
Block(-2,19,-4,134:7)
Block(-2,19,-3,17:1)
Block(-2,27,-7,159:13)
Block(-2,27,-3,159:13)
Block(-2,28,-6,159:13)
Block(-2,28,-4,159:13)
Block(-2,29,-5,5:5)
Block(-2,30,-5,5:5)
Block(-2,32,-5,216)
Block(-2,33,-6,216)
Block(-2,33,-5,216)
Block(-2,33,-4,216)
Block(-2,34,-6,216)
Block(-2,34,-5,216)
Block(-2,34,-4,216)
Block(-1,18,-3,17:5)
Block(-1,28,-6,159:13)
Block(-1,28,-4,159:13)
Block(-1,29,-5,5:5)
Block(-1,30,-5,5:5)
Block(-1,31,-5,164:4)
Block(-1,33,-5,216)
Block(-1,34,-6,216)
Block(-1,34,-5,216)
Block(-1,34,-4,216)
Block(-1,35,-5,216)
Block(0,29,-5,164:5)
Block(0,30,-5,5:5)
Block(0,31,-5,164:1)
Block(0,34,-5,216)
Block(0,35,-5,216)
Block(0,36,-5,216)


#######################################################################
# +-----------------------------------------------------------------+ #
# |                            BO3 checks                           | #
# +-----------------------------------------------------------------+ #
#######################################################################

# Require a condition at a certain location in order for the BO3 to be spawned.
# BlockCheck(x,y,z,BlockName[,BlockName[,...]]) - one of the blocks must be at the location
# BlockCheckNot(x,y,z,BlockName[,BlockName[,...]]) - all the blocks must not be at the location
# LightCheck(x,y,z,minLightLevel,maxLightLevel) - light must be between min and max (inclusive)

# You can use "Solid" as a BlockName for matching all solid blocks or "All" to match all blocks that aren't air.

# Examples:
#   BlockCheck(0,-1,0,GRASS,DIRT,biomesoplenty:grass:0,biomesoplenty:grass:1,biomesoplenty:grass:2,biomesoplenty:grass:3,biomesoplenty:grass:4,biomesoplenty:grass:5,biomesoplenty:grass:6,biomesoplenty:grass:7,biomesoplenty:dirt:0,biomesoplenty:dirt:1,biomesoplenty:dirt:2,biomesoplenty:dirt:3,biomesoplenty:dirt:4,biomesoplenty:dirt:5,biomesoplenty:dirt:6,biomesoplenty:dirt:7,biomesoplenty:dirt:8,biomesoplenty:dirt:9,biomesoplenty:dirt:10,biomesoplenty:dried_sand:0,biomesoplenty:hard_ice:0,biomesoplenty:white_sand:0,biomesoplenty:white_sandstone:0,biomesoplenty:mud:0,biomesoplenty:ash_block:0)  Require grass or dirt just below the object
#   BlockCheck(0,-1,0,Solid)       Require any solid block just below the object
#   BlockCheck(0,-1,0,WOOL)        Require any type of wool just below the object
#   BlockCheck(0,-1,0,WOOL:0)      Require white wool just below the object
#   BlockCheckNot(0,-1,0,WOOL:0)   Require that there is no white wool below the object
#   LightCheck(0,0,0,0,1)          Require almost complete darkness just below the object

#######################################################################
# +-----------------------------------------------------------------+ #
# |                             Branches                            | #
# +-----------------------------------------------------------------+ #
#######################################################################

# Branches are objects that will spawn when this object spawns when it is used in
# the CustomStructure resource. Branches can also have branches, making complex
# structures possible. See the wiki for more details.

# Regular Branches spawn each branch with an independent chance of spawning.
# Branch(x,y,z,branchName,rotation,chance[,anotherBranchName,rotation,chance[,...]][IndividualChance])
# branchName - name of the object to spawn.
# rotation - NORTH, SOUTH, EAST or WEST.
# IndividualChance - The chance each branch has to spawn, assumed to be 100 when left blank

# WeightedBranch(x,y,z,branchName,rotation,chance[,anotherBranchName,rotation,chance[,...]][MaxChanceOutOf])
# MaxChanceOutOf - The chance all branches have to spawn out of, assumed to be 100 when left blank
