[META]
version=2.0
spawnOnBlockType=1
spawnSunlight=True
spawnDarkness=True
spawnWater=False
spawnLava=False
underFill=True
randomRotation=True
dig=True
tree=False
branch=False
needsFoundation=True
rarity=25
collisionPercentage=2
spawnElevationMin=80
spawnElevationMax=250
spawnInBiome=Custom
[DATA]
0,0,0:1
0,1,0:1
1,1,0:1
1,0,0:1
0,0,1:1
1,0,1:1
1,1,1:1
0,0,2:1
1,0,2:1
1,1,-1:1
0,1,-1:1
0,0,-1:1
1,0,-1:1
0,-1,-1:1
-1,0,-1:1
1,-1,-1:1
0,1,-2:1
0,0,-2:1
0,-1,-2:1
-1,-1,-2:1
-1,0,-2:1
1,0,-2:1
1,1,-2:1
0,1,-3:1
0,0,-3:1
0,-1,-3:1
-1,-1,-3:1
-1,0,-3:1
1,0,-3:1
1,1,-3:1
1,1,-4:1
0,1,-4:1
0,0,-4:1
1,0,-4:1
-1,0,-4:1
-1,-1,-4:1
0,-1,-4:1
-1,0,-5:1
0,0,-5:1
0,1,-5:1
1,0,-5:1
1,1,-5:1
1,2,-5:1
0,2,-5:1
-1,1,-5:1
-1,-1,-5:1
0,-1,-5:1
1,-1,-5:1
-1,0,-6:1
-1,1,-6:1
-1,-1,-6:1
0,-1,-6:1
1,-1,-6:1
1,0,-6:1
1,1,-6:1
0,1,-6:1
0,0,-6:1
0,2,-6:1
2,1,-6:1
0,1,-7:1
-1,1,-7:1
-1,2,-7:1
-1,0,-7:1
-1,-1,-7:1
0,-1,-7:1
1,-1,-7:1
1,0,-7:1
1,1,-7:1
2,1,-7:1
2,0,-7:1
0,0,-7:1
0,-2,-7:1
-1,-2,-7:1
-2,1,-7:1
-2,0,-7:1
0,2,-7:1
1,2,-7:1
-1,1,-8:1
-1,2,-8:1
0,2,-8:1
0,1,-8:1
0,0,-8:1
-1,0,-8:1
-2,0,-8:1
-1,-1,-8:1
-1,-2,-8:1
0,-2,-8:1
0,-1,-8:1
1,0,-8:1
2,0,-8:1
2,1,-8:1
1,1,-8:1
1,-1,-8:1
-1,0,-9:1
-2,0,-9:1
-2,1,-9:1
-1,-1,-9:1
-1,-2,-9:1
-2,-1,-9:1
0,0,-9:1
0,1,-9:1
0,-1,-9:1
0,-2,-9:1
-1,1,-9:1
1,1,-9:1
1,0,-9:1
1,-1,-9:1
1,-2,-9:1
2,0,-9:1
2,-1,-9:1
2,1,-9:1
0,2,-9:1
1,-3,-10:1
1,-2,-10:1
2,-1,-10:1
2,-2,-10:1
2,0,-10:1
1,0,-10:1
0,0,-10:1
0,-1,-10:1
0,-2,-10:1
1,-1,-10:1
0,-3,-10:1
-1,-1,-10:1
-1,-2,-10:1
-2,-2,-10:1
-2,-1,-10:1
-3,0,-10:1
-2,0,-10:1
-1,0,-10:1
-1,1,-10:1
0,1,-10:1
1,1,-10:1
1,2,-10:1
0,2,-10:1
-1,2,-10:1
-2,1,-10:1
2,1,-10:1
0,0,-11:1
-1,0,-11:1
-1,-1,-11:1
-2,-1,-11:1
-2,-2,-11:1
-1,-2,-11:1
0,-2,-11:1
1,-2,-11:1
1,-1,-11:1
1,0,-11:1
0,-1,-11:1
0,-3,-11:1
-1,-3,-11:1
1,-3,-11:1
2,-2,-11:1
2,-1,-11:1
2,0,-11:1
1,1,-11:1
0,1,-11:1
-1,1,-11:1
1,2,-11:1
2,2,-11:1
2,1,-11:1
-2,0,-11:1
-1,-1,-12:1
-1,0,-12:1
-1,-2,-12:1
-1,-3,-12:1
-2,-1,-12:1
-2,-2,-12:1
-2,0,-12:1
-1,1,-12:1
0,1,-12:1
1,1,-12:1
1,0,-12:1
1,-1,-12:1
0,-1,-12:1
0,0,-12:1
0,-2,-12:1
1,-2,-12:1
1,-3,-12:1
0,-3,-12:1
2,-2,-12:1
2,-1,-12:1
2,0,-12:1
2,1,-12:1
2,2,-12:1
1,2,-12:1
0,2,-12:1
0,-1,-13:1
-1,-1,-13:1
-1,-2,-13:1
-2,-1,-13:1
-2,0,-13:1
-1,0,-13:1
0,0,-13:1
0,1,-13:1
-1,1,-13:1
1,0,-13:1
1,-1,-13:1
2,-1,-13:1
2,-2,-13:1
1,-2,-13:1
0,-2,-13:1
0,-3,-13:1
1,-3,-13:1
-1,-3,-13:1
2,0,-13:1
-1,-1,-14:1
-1,-2,-14:1
0,-2,-14:1
0,-3,-14:1
0,-1,-14:1
0,0,-14:1
1,0,-14:1
1,-1,-14:1
2,-1,-14:1
2,-2,-14:1
2,-3,-14:1
1,-3,-14:1
1,-2,-14:1
0,1,-14:1
-1,0,-14:1
-2,-1,-14:1
-2,-2,-14:1
-1,-3,-14:1
-1,1,-14:1
2,0,-14:1
0,-1,-15:1
-1,0,-15:1
-1,1,-15:1
-1,-1,-15:1
-1,-2,-15:1
0,-2,-15:1
-2,-1,-15:1
-2,-2,-15:1
0,-3,-15:1
-1,-3,-15:1
1,-2,-15:1
1,-1,-15:1
1,-3,-15:1
2,-2,-15:1
2,-1,-15:1
2,0,-15:1
1,0,-15:1
1,1,-15:1
0,1,-15:1
0,0,-15:1
2,-3,-15:1
1,-1,-16:1
1,0,-16:1
0,0,-16:1
0,-1,-16:1
-1,0,-16:1
1,-2,-16:1
-1,1,-16:1
0,1,-16:1
1,1,-16:1
-1,-1,-16:1
-1,-2,-16:1
-2,-1,-16:1
0,-2,-16:1
1,-3,-16:1
2,-3,-16:1
2,-2,-16:1
2,-1,-16:1
2,0,-16:1
0,-1,-17:1
-1,-1,-17:1
-1,0,-17:1
0,0,-17:1
1,0,-17:1
1,-1,-17:1
2,-2,-17:1
1,-2,-17:1
0,-2,-17:1
2,-1,-17:1
2,0,-17:1
0,1,-17:1
-1,1,-17:1
-1,-2,-17:1
-2,-2,-17:1
-2,-1,-17:1
-2,0,-17:1
-2,1,-17:1
1,1,-17:1
2,1,-17:1
1,-3,-17:1
2,-3,-17:1
0,2,-17:1
0,0,-18:1
-1,0,-18:1
-1,-1,-18:1
-1,1,-18:1
-1,2,-18:1
0,2,-18:1
0,1,-18:1
1,0,-18:1
1,-1,-18:1
0,-1,-18:1
1,-2,-18:1
0,-2,-18:1
-2,-1,-18:1
-2,0,-18:1
-2,1,-18:1
-1,-2,-18:1
-2,-2,-18:1
1,1,-18:1
2,1,-18:1
2,0,-18:1
2,-1,-18:1
2,-2,-18:1
2,-3,-18:1
1,-3,-18:1
0,-1,-19:1
0,0,-19:1
-1,0,-19:1
-1,1,-19:1
0,1,-19:1
1,1,-19:1
1,0,-19:1
0,0,-20:1