
#######################################################################
# +-----------------------------------------------------------------+ #
# |                            BO3 object                           | #
# +-----------------------------------------------------------------+ #
#######################################################################

Author: LordSmellyPants

Description: No description given

Version: 3

SettingsMode: WriteWithoutComments


#######################################################################
# +-----------------------------------------------------------------+ #
# |                          Main settings                          | #
# +-----------------------------------------------------------------+ #
#######################################################################

Tree: false

Frequency: 1

Rarity: 4.0

RotateRandomly: true

SpawnHeight: randomY

SpawnHeightOffset: 0

SpawnHeightVariance: 0

##############################
# Height Limits for the BO3. #
##############################

MinHeight: 53

MaxHeight: 67

######################
# Extrusion settings #
######################

ExtrudeMode: None

ExtrudeThroughBlocks: AIR

MaxBranchDepth: 10

ExcludedBiomes: All


#######################################################################
# +-----------------------------------------------------------------+ #
# |                      Source block settings                      | #
# +-----------------------------------------------------------------+ #
#######################################################################

SourceBlocks: GRASS,DIRT,GRAVEL,SAND,SAND:1,SANDSTONE,STONE,STONE:1,STONE:3,STONE:5,DIRT:1,CLAY,HARD_CLAY,STAINED_CLAY,RED_ROSE,RED_ROSE:1,RED_ROSE:2,RED_ROSE:3,RED_ROSE:4,RED_ROSE:5,RED_ROSE:6,RED_ROSE:7,RED_ROSE:8,BROWN_MUSHROOM,RED_MUSHROOM,DOUBLE_PLANT,DOUBLE_PLANT:1,DOUBLE_PLANT:2,DOUBLE_PLANT:3,DOUBLE_PLANT:4,DOUBLE_PLANT:5,LONG_GRASS,LONG_GRASS:1,LONG_GRASS:2,DEAD_BUSH,COAL_ORE,IRON_ORE,GOLD_ORE,REDSTONE_ORE,DIAMOND_ORE,LAPIS_ORE,EMERALD_ORE,VINE,AIR,STATIONARY_WATER

MaxPercentageOutsideSourceBlock: 20

OutsideSourceBlock: placeAnyway

DoReplaceBlocks: true

IsOTGPlus: false


#######################################################################
# +-----------------------------------------------------------------+ #
# |                              Blocks                             | #
# +-----------------------------------------------------------------+ #
#######################################################################

Block(-5,-2,0,STAINED_CLAY:1)
Block(-5,-1,-1,STAINED_CLAY:1)
Block(-5,-1,0,STAINED_CLAY:1)
Block(-5,-1,1,STAINED_CLAY:1)
Block(-5,0,-2,STAINED_CLAY:1)
Block(-5,0,-1,STAINED_CLAY:1)
Block(-5,0,0,STAINED_CLAY:1)
Block(-5,0,1,STAINED_CLAY:1)
Block(-5,1,-2,STAINED_CLAY:1)
Block(-5,1,-1,STAINED_CLAY:1)
Block(-5,1,0,STAINED_CLAY:1)
Block(-5,1,1,STAINED_CLAY:1)
Block(-5,2,-2,STAINED_CLAY:1)
Block(-5,2,-1,STAINED_CLAY:1)
Block(-5,2,0,STAINED_CLAY:1)
Block(-5,2,1,STAINED_CLAY:1)
Block(-5,3,0,STAINED_CLAY:1)
Block(-5,4,0,STAINED_CLAY:4)
Block(-4,-3,1,STAINED_CLAY:1)
Block(-4,-2,-1,STAINED_CLAY:1)
Block(-4,-2,0,STAINED_CLAY:1)
Block(-4,-2,1,STAINED_CLAY:1)
Block(-4,-2,2,STAINED_CLAY:1)
Block(-4,-1,-2,STAINED_CLAY:1)
Block(-4,-1,-1,STAINED_CLAY:1)
Block(-4,-1,0,STAINED_CLAY:1)
Block(-4,-1,1,STAINED_CLAY:1)
Block(-4,-1,2,STAINED_CLAY:1)
Block(-4,0,-2,STAINED_CLAY:1)
Block(-4,0,-1,STAINED_CLAY:1)
Block(-4,0,0,STAINED_CLAY:1)
Block(-4,0,1,STAINED_CLAY:1)
Block(-4,0,2,STAINED_CLAY:1)
Block(-4,1,-2,STAINED_CLAY:1)
Block(-4,1,-1,STAINED_CLAY:1)
Block(-4,1,0,STAINED_CLAY:1)
Block(-4,1,1,STAINED_CLAY:1)
Block(-4,1,2,STAINED_CLAY:1)
Block(-4,2,-2,STAINED_CLAY:1)
Block(-4,2,-1,STAINED_CLAY:1)
Block(-4,2,0,STAINED_CLAY:1)
Block(-4,2,1,STAINED_CLAY:1)
Block(-4,2,2,STAINED_CLAY:1)
Block(-4,3,-2,STAINED_CLAY:1)
Block(-4,3,-1,STAINED_CLAY:1)
Block(-4,3,0,STAINED_CLAY:1)
Block(-4,3,1,STAINED_CLAY:1)
Block(-4,3,2,STAINED_CLAY:1)
Block(-4,4,-2,HARD_CLAY)
Block(-4,4,-1,STAINED_CLAY:4)
Block(-4,4,0,STAINED_CLAY:4)
Block(-4,4,1,HARD_CLAY)
Block(-4,4,2,HARD_CLAY)
Block(-4,5,-1,STAINED_CLAY:4)
Block(-4,5,0,STAINED_CLAY:4)
Block(-4,5,1,STAINED_CLAY:4)
Block(-4,5,2,HARD_CLAY)
Block(-4,6,-1,HARD_CLAY)
Block(-4,6,0,HARD_CLAY)
Block(-4,6,1,HARD_CLAY)
Block(-4,6,2,HARD_CLAY)
Block(-4,7,-1,HARD_CLAY)
Block(-4,7,0,HARD_CLAY)
Block(-4,7,1,HARD_CLAY)
Block(-4,7,2,HARD_CLAY)
Block(-4,8,-1,HARD_CLAY)
Block(-4,8,0,HARD_CLAY)
Block(-4,8,1,HARD_CLAY)
Block(-4,9,-1,HARD_CLAY)
Block(-3,-4,1,STAINED_CLAY:1)
Block(-3,-3,0,STAINED_CLAY:1)
Block(-3,-3,1,STAINED_CLAY:1)
Block(-3,-3,2,STAINED_CLAY:1)
Block(-3,-2,-2,STAINED_CLAY:1)
Block(-3,-2,-1,STAINED_CLAY:1)
Block(-3,-2,0,STAINED_CLAY:1)
Block(-3,-2,1,STAINED_CLAY:1)
Block(-3,-2,2,STAINED_CLAY:1)
Block(-3,-1,-2,STAINED_CLAY:1)
Block(-3,-1,-1,STAINED_CLAY:1)
Block(-3,-1,0,STAINED_CLAY:1)
Block(-3,-1,1,STAINED_CLAY:1)
Block(-3,-1,2,STAINED_CLAY:1)
Block(-3,-1,3,STAINED_CLAY:1)
Block(-3,0,-2,STAINED_CLAY:1)
Block(-3,0,-1,STAINED_CLAY:1)
Block(-3,0,0,STAINED_CLAY:1)
Block(-3,0,1,STAINED_CLAY:1)
Block(-3,0,2,STAINED_CLAY:1)
Block(-3,0,3,STAINED_CLAY:1)
Block(-3,1,-2,STAINED_CLAY:1)
Block(-3,1,-1,STAINED_CLAY:1)
Block(-3,1,0,STAINED_CLAY:1)
Block(-3,1,1,STAINED_CLAY:1)
Block(-3,1,2,STAINED_CLAY:1)
Block(-3,1,3,STAINED_CLAY:1)
Block(-3,2,-2,STAINED_CLAY:1)
Block(-3,2,-1,STAINED_CLAY:1)
Block(-3,2,0,STAINED_CLAY:1)
Block(-3,2,1,STAINED_CLAY:1)
Block(-3,2,2,STAINED_CLAY:1)
Block(-3,2,3,STAINED_CLAY:1)
Block(-3,3,-2,STAINED_CLAY:1)
Block(-3,3,-1,STAINED_CLAY:1)
Block(-3,3,0,STAINED_CLAY:1)
Block(-3,3,1,STAINED_CLAY:1)
Block(-3,3,2,STAINED_CLAY:1)
Block(-3,3,3,STAINED_CLAY:1)
Block(-3,4,-2,STAINED_CLAY:4)
Block(-3,4,-1,HARD_CLAY)
Block(-3,4,0,HARD_CLAY)
Block(-3,4,1,HARD_CLAY)
Block(-3,4,2,HARD_CLAY)
Block(-3,4,3,STAINED_CLAY:4)
Block(-3,5,-2,STAINED_CLAY:4)
Block(-3,5,-1,HARD_CLAY)
Block(-3,5,0,HARD_CLAY)
Block(-3,5,1,STAINED_CLAY:4)
Block(-3,5,2,STAINED_CLAY:4)
Block(-3,5,3,STAINED_CLAY:4)
Block(-3,6,-2,HARD_CLAY)
Block(-3,6,-1,HARD_CLAY)
Block(-3,6,0,HARD_CLAY)
Block(-3,6,1,HARD_CLAY)
Block(-3,6,2,HARD_CLAY)
Block(-3,6,3,HARD_CLAY)
Block(-3,7,-1,HARD_CLAY)
Block(-3,7,0,HARD_CLAY)
Block(-3,7,1,HARD_CLAY)
Block(-3,7,2,HARD_CLAY)
Block(-3,7,3,HARD_CLAY)
Block(-3,8,-1,HARD_CLAY)
Block(-3,8,0,HARD_CLAY)
Block(-3,8,1,HARD_CLAY)
Block(-3,8,2,HARD_CLAY)
Block(-3,9,-1,STAINED_CLAY:1)
Block(-3,9,0,STAINED_CLAY:1)
Block(-3,9,1,STAINED_CLAY:1)
Block(-3,9,2,STAINED_CLAY:1)
Block(-3,10,-1,HARD_CLAY)
Block(-3,10,0,HARD_CLAY)
Block(-3,10,1,HARD_CLAY)
Block(-3,10,2,HARD_CLAY)
Block(-3,11,0,HARD_CLAY)
Block(-3,11,1,HARD_CLAY)
Block(-3,11,2,HARD_CLAY)
Block(-3,12,0,STAINED_CLAY:1)
Block(-3,12,1,STAINED_CLAY:1)
Block(-3,12,2,STAINED_CLAY:1)
Block(-3,13,0,HARD_CLAY)
Block(-3,13,1,HARD_CLAY)
Block(-3,13,2,HARD_CLAY)
Block(-3,14,0,HARD_CLAY)
Block(-3,14,1,HARD_CLAY)
Block(-3,14,2,HARD_CLAY)
Block(-3,15,0,STAINED_CLAY:14)
Block(-3,15,1,STAINED_CLAY:14)
Block(-3,15,2,STAINED_CLAY:14)
Block(-3,16,0,STAINED_CLAY:14)
Block(-3,16,1,STAINED_CLAY:14)
Block(-3,16,2,STAINED_CLAY:14)
Block(-3,17,0,STAINED_CLAY:12)
Block(-3,17,1,STAINED_CLAY:12)
Block(-3,17,2,STAINED_CLAY:12)
Block(-3,18,0,STAINED_CLAY:12)
Block(-3,18,1,STAINED_CLAY:12)
Block(-3,18,2,STAINED_CLAY:12)
Block(-3,19,0,HARD_CLAY)
Block(-3,19,1,HARD_CLAY)
Block(-3,19,2,HARD_CLAY)
Block(-2,-4,0,STAINED_CLAY:1)
Block(-2,-4,1,STAINED_CLAY:1)
Block(-2,-4,2,STAINED_CLAY:1)
Block(-2,-3,-1,STAINED_CLAY:1)
Block(-2,-3,0,STAINED_CLAY:1)
Block(-2,-3,1,STAINED_CLAY:1)
Block(-2,-3,2,STAINED_CLAY:1)
Block(-2,-3,3,STAINED_CLAY:1)
Block(-2,-2,-2,STAINED_CLAY:1)
Block(-2,-2,-1,STAINED_CLAY:1)
Block(-2,-2,0,STAINED_CLAY:1)
Block(-2,-2,1,STAINED_CLAY:1)
Block(-2,-2,2,STAINED_CLAY:1)
Block(-2,-2,3,STAINED_CLAY:1)
Block(-2,-1,-2,STAINED_CLAY:1)
Block(-2,-1,-1,STAINED_CLAY:1)
Block(-2,-1,0,STAINED_CLAY:1)
Block(-2,-1,1,STAINED_CLAY:1)
Block(-2,-1,2,STAINED_CLAY:1)
Block(-2,-1,3,STAINED_CLAY:1)
Block(-2,-1,4,STAINED_CLAY:1)
Block(-2,0,-2,STAINED_CLAY:1)
Block(-2,0,-1,STAINED_CLAY:1)
Block(-2,0,0,STAINED_CLAY:1)
Block(-2,0,1,STAINED_CLAY:1)
Block(-2,0,2,STAINED_CLAY:1)
Block(-2,0,3,STAINED_CLAY:1)
Block(-2,0,4,STAINED_CLAY:1)
Block(-2,1,-2,STAINED_CLAY:1)
Block(-2,1,-1,STAINED_CLAY:1)
Block(-2,1,0,STAINED_CLAY:1)
Block(-2,1,1,STAINED_CLAY:1)
Block(-2,1,2,STAINED_CLAY:1)
Block(-2,1,3,STAINED_CLAY:1)
Block(-2,1,4,STAINED_CLAY:1)
Block(-2,2,-2,STAINED_CLAY:1)
Block(-2,2,-1,STAINED_CLAY:1)
Block(-2,2,0,STAINED_CLAY:1)
Block(-2,2,1,STAINED_CLAY:1)
Block(-2,2,2,STAINED_CLAY:1)
Block(-2,2,3,STAINED_CLAY:1)
Block(-2,2,4,STAINED_CLAY:1)
Block(-2,3,-2,STAINED_CLAY:1)
Block(-2,3,-1,STAINED_CLAY:1)
Block(-2,3,0,STAINED_CLAY:1)
Block(-2,3,1,STAINED_CLAY:1)
Block(-2,3,2,STAINED_CLAY:1)
Block(-2,3,3,STAINED_CLAY:1)
Block(-2,3,4,STAINED_CLAY:1)
Block(-2,4,-2,STAINED_CLAY:4)
Block(-2,4,-1,HARD_CLAY)
Block(-2,4,0,HARD_CLAY)
Block(-2,4,1,HARD_CLAY)
Block(-2,4,2,HARD_CLAY)
Block(-2,4,3,HARD_CLAY)
Block(-2,4,4,STAINED_CLAY:4)
Block(-2,5,-2,STAINED_CLAY:4)
Block(-2,5,-1,HARD_CLAY)
Block(-2,5,0,HARD_CLAY)
Block(-2,5,1,HARD_CLAY)
Block(-2,5,2,STAINED_CLAY:4)
Block(-2,5,3,STAINED_CLAY:4)
Block(-2,5,4,STAINED_CLAY:4)
Block(-2,6,-2,HARD_CLAY)
Block(-2,6,-1,HARD_CLAY)
Block(-2,6,0,HARD_CLAY)
Block(-2,6,1,HARD_CLAY)
Block(-2,6,2,HARD_CLAY)
Block(-2,6,3,HARD_CLAY)
Block(-2,6,4,HARD_CLAY)
Block(-2,7,-2,HARD_CLAY)
Block(-2,7,-1,HARD_CLAY)
Block(-2,7,0,HARD_CLAY)
Block(-2,7,1,HARD_CLAY)
Block(-2,7,2,HARD_CLAY)
Block(-2,7,3,HARD_CLAY)
Block(-2,8,-2,HARD_CLAY)
Block(-2,8,-1,HARD_CLAY)
Block(-2,8,0,HARD_CLAY)
Block(-2,8,1,HARD_CLAY)
Block(-2,8,2,HARD_CLAY)
Block(-2,8,3,HARD_CLAY)
Block(-2,9,-2,STAINED_CLAY:1)
Block(-2,9,-1,STAINED_CLAY:1)
Block(-2,9,0,HARD_CLAY)
Block(-2,9,1,STAINED_CLAY:1)
Block(-2,9,2,STAINED_CLAY:1)
Block(-2,9,3,STAINED_CLAY:1)
Block(-2,10,-1,HARD_CLAY)
Block(-2,10,0,HARD_CLAY)
Block(-2,10,1,HARD_CLAY)
Block(-2,10,2,HARD_CLAY)
Block(-2,11,-1,HARD_CLAY)
Block(-2,11,0,HARD_CLAY)
Block(-2,11,1,HARD_CLAY)
Block(-2,11,2,HARD_CLAY)
Block(-2,12,-1,STAINED_CLAY:1)
Block(-2,12,0,HARD_CLAY)
Block(-2,12,1,HARD_CLAY)
Block(-2,12,2,STAINED_CLAY:1)
Block(-2,13,-1,HARD_CLAY)
Block(-2,13,0,HARD_CLAY)
Block(-2,13,1,HARD_CLAY)
Block(-2,13,2,HARD_CLAY)
Block(-2,14,-1,HARD_CLAY)
Block(-2,14,0,HARD_CLAY)
Block(-2,14,1,HARD_CLAY)
Block(-2,14,2,HARD_CLAY)
Block(-2,15,-1,HARD_CLAY)
Block(-2,15,0,STAINED_CLAY:14)
Block(-2,15,1,STAINED_CLAY:14)
Block(-2,15,2,STAINED_CLAY:14)
Block(-2,16,0,STAINED_CLAY:14)
Block(-2,16,1,STAINED_CLAY:14)
Block(-2,16,2,STAINED_CLAY:14)
Block(-2,17,0,STAINED_CLAY:12)
Block(-2,17,1,STAINED_CLAY:12)
Block(-2,17,2,STAINED_CLAY:12)
Block(-2,18,0,HARD_CLAY)
Block(-2,18,1,STAINED_CLAY:12)
Block(-2,18,2,STAINED_CLAY:12)
Block(-2,19,0,HARD_CLAY)
Block(-2,19,1,HARD_CLAY)
Block(-2,19,2,HARD_CLAY)
Block(-1,-4,-1,STAINED_CLAY:1)
Block(-1,-4,0,STAINED_CLAY:1)
Block(-1,-4,1,STAINED_CLAY:1)
Block(-1,-4,2,STAINED_CLAY:1)
Block(-1,-4,3,STAINED_CLAY:1)
Block(-1,-3,-1,STAINED_CLAY:1)
Block(-1,-3,0,STAINED_CLAY:1)
Block(-1,-3,1,STAINED_CLAY:1)
Block(-1,-3,2,STAINED_CLAY:1)
Block(-1,-3,3,STAINED_CLAY:1)
Block(-1,-2,-3,STAINED_CLAY:1)
Block(-1,-2,-2,STAINED_CLAY:1)
Block(-1,-2,-1,STAINED_CLAY:1)
Block(-1,-2,0,STAINED_CLAY:1)
Block(-1,-2,1,STAINED_CLAY:1)
Block(-1,-2,2,STAINED_CLAY:1)
Block(-1,-2,3,STAINED_CLAY:1)
Block(-1,-2,4,STAINED_CLAY:1)
Block(-1,-1,-3,STAINED_CLAY:1)
Block(-1,-1,-2,STAINED_CLAY:1)
Block(-1,-1,-1,STAINED_CLAY:1)
Block(-1,-1,0,STAINED_CLAY:1)
Block(-1,-1,1,STAINED_CLAY:1)
Block(-1,-1,2,STAINED_CLAY:1)
Block(-1,-1,3,STAINED_CLAY:1)
Block(-1,-1,4,STAINED_CLAY:1)
Block(-1,0,-3,STAINED_CLAY:1)
Block(-1,0,-2,STAINED_CLAY:1)
Block(-1,0,-1,STAINED_CLAY:1)
Block(-1,0,0,STAINED_CLAY:1)
Block(-1,0,1,STAINED_CLAY:1)
Block(-1,0,2,STAINED_CLAY:1)
Block(-1,0,3,STAINED_CLAY:1)
Block(-1,0,4,STAINED_CLAY:1)
Block(-1,1,-3,STAINED_CLAY:1)
Block(-1,1,-2,STAINED_CLAY:1)
Block(-1,1,-1,STAINED_CLAY:1)
Block(-1,1,0,STAINED_CLAY:1)
Block(-1,1,1,STAINED_CLAY:1)
Block(-1,1,2,STAINED_CLAY:1)
Block(-1,1,3,STAINED_CLAY:1)
Block(-1,1,4,STAINED_CLAY:1)
Block(-1,2,-3,STAINED_CLAY:1)
Block(-1,2,-2,STAINED_CLAY:1)
Block(-1,2,-1,STAINED_CLAY:1)
Block(-1,2,0,STAINED_CLAY:1)
Block(-1,2,1,STAINED_CLAY:1)
Block(-1,2,2,STAINED_CLAY:1)
Block(-1,2,3,STAINED_CLAY:1)
Block(-1,2,4,STAINED_CLAY:1)
Block(-1,3,-2,STAINED_CLAY:1)
Block(-1,3,-1,STAINED_CLAY:1)
Block(-1,3,0,STAINED_CLAY:1)
Block(-1,3,1,STAINED_CLAY:1)
Block(-1,3,2,STAINED_CLAY:1)
Block(-1,3,3,STAINED_CLAY:1)
Block(-1,3,4,STAINED_CLAY:1)
Block(-1,4,-2,STAINED_CLAY:4)
Block(-1,4,-1,HARD_CLAY)
Block(-1,4,0,HARD_CLAY)
Block(-1,4,1,HARD_CLAY)
Block(-1,4,2,HARD_CLAY)
Block(-1,4,3,STAINED_CLAY:4)
Block(-1,4,4,STAINED_CLAY:4)
Block(-1,5,-2,STAINED_CLAY:4)
Block(-1,5,-1,HARD_CLAY)
Block(-1,5,0,HARD_CLAY)
Block(-1,5,1,HARD_CLAY)
Block(-1,5,2,HARD_CLAY)
Block(-1,5,3,HARD_CLAY)
Block(-1,5,4,STAINED_CLAY:4)
Block(-1,6,-2,HARD_CLAY)
Block(-1,6,-1,HARD_CLAY)
Block(-1,6,0,HARD_CLAY)
Block(-1,6,1,HARD_CLAY)
Block(-1,6,2,HARD_CLAY)
Block(-1,6,3,HARD_CLAY)
Block(-1,6,4,HARD_CLAY)
Block(-1,7,-2,HARD_CLAY)
Block(-1,7,-1,HARD_CLAY)
Block(-1,7,0,HARD_CLAY)
Block(-1,7,1,HARD_CLAY)
Block(-1,7,2,HARD_CLAY)
Block(-1,7,3,HARD_CLAY)
Block(-1,7,4,HARD_CLAY)
Block(-1,8,-1,HARD_CLAY)
Block(-1,8,0,HARD_CLAY)
Block(-1,8,1,HARD_CLAY)
Block(-1,8,2,HARD_CLAY)
Block(-1,8,3,HARD_CLAY)
Block(-1,8,4,HARD_CLAY)
Block(-1,9,-1,STAINED_CLAY:1)
Block(-1,9,0,HARD_CLAY)
Block(-1,9,1,STAINED_CLAY:1)
Block(-1,9,2,STAINED_CLAY:1)
Block(-1,9,3,STAINED_CLAY:1)
Block(-1,10,-1,HARD_CLAY)
Block(-1,10,0,HARD_CLAY)
Block(-1,10,1,HARD_CLAY)
Block(-1,10,2,HARD_CLAY)
Block(-1,10,3,HARD_CLAY)
Block(-1,11,-1,HARD_CLAY)
Block(-1,11,0,HARD_CLAY)
Block(-1,11,1,HARD_CLAY)
Block(-1,11,2,HARD_CLAY)
Block(-1,11,3,HARD_CLAY)
Block(-1,12,0,STAINED_CLAY:1)
Block(-1,12,1,STAINED_CLAY:1)
Block(-1,12,2,STAINED_CLAY:1)
Block(-1,13,0,HARD_CLAY)
Block(-1,13,1,HARD_CLAY)
Block(-1,13,2,HARD_CLAY)
Block(-1,14,0,HARD_CLAY)
Block(-1,14,1,HARD_CLAY)
Block(-1,14,2,HARD_CLAY)
Block(-1,15,0,STAINED_CLAY:14)
Block(-1,15,1,STAINED_CLAY:14)
Block(-1,15,2,STAINED_CLAY:14)
Block(-1,16,0,HARD_CLAY)
Block(-1,16,1,STAINED_CLAY:14)
Block(-1,17,0,HARD_CLAY)
Block(-1,17,1,STAINED_CLAY:12)
Block(-1,18,0,HARD_CLAY)
Block(-1,18,1,STAINED_CLAY:12)
Block(-1,19,0,HARD_CLAY)
Block(-1,19,1,HARD_CLAY)
Block(0,-4,-1,STAINED_CLAY:1)
Block(0,-4,0,STAINED_CLAY:1)
Block(0,-4,1,STAINED_CLAY:1)
Block(0,-4,2,STAINED_CLAY:1)
Block(0,-4,3,STAINED_CLAY:1)
Block(0,-3,-2,STAINED_CLAY:1)
Block(0,-3,-1,STAINED_CLAY:1)
Block(0,-3,0,STAINED_CLAY:1)
Block(0,-3,1,STAINED_CLAY:1)
Block(0,-3,2,STAINED_CLAY:1)
Block(0,-3,3,STAINED_CLAY:1)
Block(0,-3,4,STAINED_CLAY:1)
Block(0,-2,-3,STAINED_CLAY:1)
Block(0,-2,-2,STAINED_CLAY:1)
Block(0,-2,-1,STAINED_CLAY:1)
Block(0,-2,0,STAINED_CLAY:1)
Block(0,-2,1,STAINED_CLAY:1)
Block(0,-2,2,STAINED_CLAY:1)
Block(0,-2,3,STAINED_CLAY:1)
Block(0,-2,4,STAINED_CLAY:1)
Block(0,-1,-3,STAINED_CLAY:1)
Block(0,-1,-2,STAINED_CLAY:1)
Block(0,-1,-1,STAINED_CLAY:1)
Block(0,-1,0,STAINED_CLAY:1)
Block(0,-1,1,STAINED_CLAY:1)
Block(0,-1,2,STAINED_CLAY:1)
Block(0,-1,3,STAINED_CLAY:1)
Block(0,-1,4,STAINED_CLAY:1)
Block(0,0,-3,STAINED_CLAY:1)
Block(0,0,-2,STAINED_CLAY:1)
Block(0,0,-1,STAINED_CLAY:1)
Block(0,0,0,STAINED_CLAY:1)
Block(0,0,1,STAINED_CLAY:1)
Block(0,0,2,STAINED_CLAY:1)
Block(0,0,3,STAINED_CLAY:1)
Block(0,0,4,STAINED_CLAY:1)
Block(0,1,-3,STAINED_CLAY:1)
Block(0,1,-2,STAINED_CLAY:1)
Block(0,1,-1,STAINED_CLAY:1)
Block(0,1,0,STAINED_CLAY:1)
Block(0,1,1,STAINED_CLAY:1)
Block(0,1,2,STAINED_CLAY:1)
Block(0,1,3,STAINED_CLAY:1)
Block(0,1,4,STAINED_CLAY:1)
Block(0,2,-3,STAINED_CLAY:1)
Block(0,2,-2,STAINED_CLAY:1)
Block(0,2,-1,STAINED_CLAY:1)
Block(0,2,0,STAINED_CLAY:1)
Block(0,2,1,STAINED_CLAY:1)
Block(0,2,2,STAINED_CLAY:1)
Block(0,2,3,STAINED_CLAY:1)
Block(0,2,4,STAINED_CLAY:1)
Block(0,3,-3,STAINED_CLAY:1)
Block(0,3,-2,STAINED_CLAY:1)
Block(0,3,-1,STAINED_CLAY:1)
Block(0,3,0,STAINED_CLAY:1)
Block(0,3,1,STAINED_CLAY:1)
Block(0,3,2,STAINED_CLAY:1)
Block(0,3,3,STAINED_CLAY:1)
Block(0,3,4,STAINED_CLAY:1)
Block(0,4,-2,STAINED_CLAY:4)
Block(0,4,-1,HARD_CLAY)
Block(0,4,0,HARD_CLAY)
Block(0,4,1,HARD_CLAY)
Block(0,4,2,HARD_CLAY)
Block(0,4,3,HARD_CLAY)
Block(0,4,4,STAINED_CLAY:4)
Block(0,5,-2,STAINED_CLAY:4)
Block(0,5,-1,HARD_CLAY)
Block(0,5,0,HARD_CLAY)
Block(0,5,1,HARD_CLAY)
Block(0,5,2,HARD_CLAY)
Block(0,5,3,HARD_CLAY)
Block(0,5,4,STAINED_CLAY:4)
Block(0,6,-2,HARD_CLAY)
Block(0,6,-1,HARD_CLAY)
Block(0,6,0,HARD_CLAY)
Block(0,6,1,HARD_CLAY)
Block(0,6,2,HARD_CLAY)
Block(0,6,3,HARD_CLAY)
Block(0,6,4,HARD_CLAY)
Block(0,7,-1,HARD_CLAY)
Block(0,7,0,HARD_CLAY)
Block(0,7,1,HARD_CLAY)
Block(0,7,2,HARD_CLAY)
Block(0,7,3,HARD_CLAY)
Block(0,8,-1,HARD_CLAY)
Block(0,8,0,HARD_CLAY)
Block(0,8,1,HARD_CLAY)
Block(0,8,2,HARD_CLAY)
Block(0,9,-1,STAINED_CLAY:1)
Block(0,9,0,HARD_CLAY)
Block(0,9,1,STAINED_CLAY:1)
Block(0,10,-1,HARD_CLAY)
Block(0,10,0,HARD_CLAY)
Block(0,10,1,HARD_CLAY)
Block(0,11,-1,HARD_CLAY)
Block(0,11,0,HARD_CLAY)
Block(1,-4,0,STAINED_CLAY:1)
Block(1,-4,1,STAINED_CLAY:1)
Block(1,-3,-1,STAINED_CLAY:1)
Block(1,-3,0,STAINED_CLAY:1)
Block(1,-3,1,STAINED_CLAY:1)
Block(1,-3,2,STAINED_CLAY:1)
Block(1,-3,3,STAINED_CLAY:1)
Block(1,-2,-3,STAINED_CLAY:1)
Block(1,-2,-2,STAINED_CLAY:1)
Block(1,-2,-1,STAINED_CLAY:1)
Block(1,-2,0,STAINED_CLAY:1)
Block(1,-2,1,STAINED_CLAY:1)
Block(1,-2,2,STAINED_CLAY:1)
Block(1,-2,3,STAINED_CLAY:1)
Block(1,-2,4,STAINED_CLAY:1)
Block(1,-1,-3,STAINED_CLAY:1)
Block(1,-1,-2,STAINED_CLAY:1)
Block(1,-1,-1,STAINED_CLAY:1)
Block(1,-1,0,STAINED_CLAY:1)
Block(1,-1,1,STAINED_CLAY:1)
Block(1,-1,2,STAINED_CLAY:1)
Block(1,-1,3,STAINED_CLAY:1)
Block(1,-1,4,STAINED_CLAY:1)
Block(1,0,-3,STAINED_CLAY:1)
Block(1,0,-2,STAINED_CLAY:1)
Block(1,0,-1,STAINED_CLAY:1)
Block(1,0,0,STAINED_CLAY:1)
Block(1,0,1,STAINED_CLAY:1)
Block(1,0,2,STAINED_CLAY:1)
Block(1,0,3,STAINED_CLAY:1)
Block(1,0,4,STAINED_CLAY:1)
Block(1,1,-3,STAINED_CLAY:1)
Block(1,1,-2,STAINED_CLAY:1)
Block(1,1,-1,STAINED_CLAY:1)
Block(1,1,0,STAINED_CLAY:1)
Block(1,1,1,STAINED_CLAY:1)
Block(1,1,2,STAINED_CLAY:1)
Block(1,1,3,STAINED_CLAY:1)
Block(1,1,4,STAINED_CLAY:1)
Block(1,2,-3,STAINED_CLAY:1)
Block(1,2,-2,STAINED_CLAY:1)
Block(1,2,-1,STAINED_CLAY:1)
Block(1,2,0,STAINED_CLAY:1)
Block(1,2,1,STAINED_CLAY:1)
Block(1,2,2,STAINED_CLAY:1)
Block(1,2,3,STAINED_CLAY:1)
Block(1,2,4,STAINED_CLAY:1)
Block(1,3,-3,STAINED_CLAY:1)
Block(1,3,-2,STAINED_CLAY:1)
Block(1,3,-1,STAINED_CLAY:1)
Block(1,3,0,STAINED_CLAY:1)
Block(1,3,1,STAINED_CLAY:1)
Block(1,3,2,STAINED_CLAY:1)
Block(1,3,3,STAINED_CLAY:1)
Block(1,3,4,STAINED_CLAY:1)
Block(1,4,-3,STAINED_CLAY:4)
Block(1,4,-2,HARD_CLAY)
Block(1,4,-1,HARD_CLAY)
Block(1,4,0,HARD_CLAY)
Block(1,4,1,HARD_CLAY)
Block(1,4,2,HARD_CLAY)
Block(1,4,3,HARD_CLAY)
Block(1,4,4,STAINED_CLAY:4)
Block(1,5,-2,STAINED_CLAY:4)
Block(1,5,-1,HARD_CLAY)
Block(1,5,0,HARD_CLAY)
Block(1,5,1,HARD_CLAY)
Block(1,5,2,HARD_CLAY)
Block(1,5,3,HARD_CLAY)
Block(1,5,4,STAINED_CLAY:4)
Block(1,6,-2,HARD_CLAY)
Block(1,6,-1,HARD_CLAY)
Block(1,6,0,HARD_CLAY)
Block(1,6,1,HARD_CLAY)
Block(1,6,2,HARD_CLAY)
Block(1,6,3,HARD_CLAY)
Block(1,7,-1,HARD_CLAY)
Block(1,7,0,HARD_CLAY)
Block(1,7,1,HARD_CLAY)
Block(1,7,2,HARD_CLAY)
Block(1,8,0,HARD_CLAY)
Block(1,8,1,HARD_CLAY)
Block(1,9,0,STAINED_CLAY:1)
Block(1,10,0,HARD_CLAY)
Block(2,-3,-1,STAINED_CLAY:1)
Block(2,-3,0,STAINED_CLAY:1)
Block(2,-2,-2,STAINED_CLAY:1)
Block(2,-2,-1,STAINED_CLAY:1)
Block(2,-2,0,STAINED_CLAY:1)
Block(2,-1,-3,STAINED_CLAY:1)
Block(2,-1,-2,STAINED_CLAY:1)
Block(2,-1,-1,STAINED_CLAY:1)
Block(2,-1,0,STAINED_CLAY:1)
Block(2,-1,1,STAINED_CLAY:1)
Block(2,-1,2,STAINED_CLAY:1)
Block(2,0,-3,STAINED_CLAY:1)
Block(2,0,-2,STAINED_CLAY:1)
Block(2,0,-1,STAINED_CLAY:1)
Block(2,0,0,STAINED_CLAY:1)
Block(2,0,1,STAINED_CLAY:1)
Block(2,0,2,STAINED_CLAY:1)
Block(2,0,3,STAINED_CLAY:1)
Block(2,1,-3,STAINED_CLAY:1)
Block(2,1,-2,STAINED_CLAY:1)
Block(2,1,-1,STAINED_CLAY:1)
Block(2,1,0,STAINED_CLAY:1)
Block(2,1,1,STAINED_CLAY:1)
Block(2,1,2,STAINED_CLAY:1)
Block(2,1,3,STAINED_CLAY:1)
Block(2,2,-3,STAINED_CLAY:1)
Block(2,2,-2,STAINED_CLAY:1)
Block(2,2,-1,STAINED_CLAY:1)
Block(2,2,0,STAINED_CLAY:1)
Block(2,2,1,STAINED_CLAY:1)
Block(2,2,2,STAINED_CLAY:1)
Block(2,2,3,STAINED_CLAY:1)
Block(2,3,-2,STAINED_CLAY:1)
Block(2,3,-1,STAINED_CLAY:1)
Block(2,3,0,STAINED_CLAY:1)
Block(2,3,1,STAINED_CLAY:1)
Block(2,3,2,STAINED_CLAY:1)
Block(2,3,3,STAINED_CLAY:1)
Block(2,4,-2,STAINED_CLAY:4)
Block(2,4,-1,STAINED_CLAY:4)
Block(2,4,0,HARD_CLAY)
Block(2,4,1,HARD_CLAY)
Block(2,4,2,HARD_CLAY)
Block(2,4,3,STAINED_CLAY:4)
Block(2,5,-1,STAINED_CLAY:4)
Block(2,5,0,HARD_CLAY)
Block(2,5,1,HARD_CLAY)
Block(2,5,2,HARD_CLAY)
Block(2,5,3,STAINED_CLAY:4)
Block(2,6,-1,HARD_CLAY)
Block(2,6,0,HARD_CLAY)
Block(2,6,1,HARD_CLAY)
Block(2,6,2,HARD_CLAY)
Block(2,7,0,HARD_CLAY)
Block(2,7,1,HARD_CLAY)
Block(2,8,0,HARD_CLAY)
Block(3,-3,0,STAINED_CLAY:1)
Block(3,-2,0,STAINED_CLAY:1)
Block(3,-1,-2,STAINED_CLAY:1)
Block(3,-1,-1,STAINED_CLAY:1)
Block(3,-1,0,STAINED_CLAY:1)
Block(3,-1,1,STAINED_CLAY:1)
Block(3,0,-2,STAINED_CLAY:1)
Block(3,0,-1,STAINED_CLAY:1)
Block(3,0,0,STAINED_CLAY:1)
Block(3,0,1,STAINED_CLAY:1)
Block(3,0,2,STAINED_CLAY:1)
Block(3,1,-2,STAINED_CLAY:1)
Block(3,1,-1,STAINED_CLAY:1)
Block(3,1,0,STAINED_CLAY:1)
Block(3,1,1,STAINED_CLAY:1)
Block(3,1,2,STAINED_CLAY:1)
Block(3,2,-2,STAINED_CLAY:1)
Block(3,2,-1,STAINED_CLAY:1)
Block(3,2,0,STAINED_CLAY:1)
Block(3,2,1,STAINED_CLAY:1)
Block(3,2,2,STAINED_CLAY:1)
Block(3,3,0,STAINED_CLAY:1)
Block(3,3,1,STAINED_CLAY:1)
Block(3,3,2,STAINED_CLAY:1)
Block(3,4,0,HARD_CLAY)
Block(3,4,1,STAINED_CLAY:4)
Block(3,4,2,STAINED_CLAY:4)
Block(3,5,0,HARD_CLAY)
Block(3,5,1,STAINED_CLAY:4)
Block(3,5,2,HARD_CLAY)
Block(3,6,0,HARD_CLAY)
Block(3,6,1,HARD_CLAY)

#######################################################################
# +-----------------------------------------------------------------+ #
# |                            BO3 checks                           | #
# +-----------------------------------------------------------------+ #
#######################################################################


#######################################################################
# +-----------------------------------------------------------------+ #
# |                             Branches                            | #
# +-----------------------------------------------------------------+ #
#######################################################################


#######################################################################
# +-----------------------------------------------------------------+ #
# |                             Entities                            | #
# +-----------------------------------------------------------------+ #
#######################################################################


#######################################################################
# +-----------------------------------------------------------------+ #
# |                            Particles                            | #
# +-----------------------------------------------------------------+ #
#######################################################################


#######################################################################
# +-----------------------------------------------------------------+ #
# |                             Spawners                            | #
# +-----------------------------------------------------------------+ #
#######################################################################


#######################################################################
# +-----------------------------------------------------------------+ #
# |                             ModData                             | #
# +-----------------------------------------------------------------+ #
#######################################################################

