[META]
version=2.0
spawnOnBlockType=2
spawnSunlight=True
spawnDarkness=True
spawnWater=False
spawnLava=False
underFill=False
spawnUnderground=True
randomRotation=True
dig=True
tree=True
branch=False
needsFoundation=True
rarity=20
collisionPercentage=20
spawnElevationMin=30
spawnElevationMax=200
spawnInBiome=CustomFloatingPlains
[DATA]
0,-2,-1:162.1
0,-1,-1:162.1
1,-1,-1:30.0
-2,0,-1:162.1
-1,0,-1:162.1
1,0,-1:162.1
2,0,-1:162.1
0,1,-1:162.1
1,1,-1:162.1
-1,2,-1:162.1
0,2,-1:162.1
0,-3,0:161.1
-2,-2,0:161.1
-1,-2,0:161.1
0,-2,0:86.2
1,-2,0:161.1
-2,-1,0:161.1
-1,-1,0:161.1
0,-1,0:86.0
1,-1,0:161.1
2,-1,0:161.1
-3,0,0:161.1
-2,0,0:162.1
-1,0,0:86.3
0,0,0:162.1
1,0,0:86.1
2,0,0:162.5
3,0,0:18.1
-2,1,0:161.1
-1,1,0:161.1
0,1,0:162.1
1,1,0:162.1
2,1,0:161.1
-2,2,0:161.1
-1,2,0:162.1
0,2,0:86.3
1,2,0:161.1
-1,3,0:161.1
-1,-2,1:161.1
0,-2,1:86.0
-2,-1,1:30.0
-1,-1,1:86.3
0,-1,1:86.3
1,-1,1:86.0
-3,0,1:18.1
-2,0,1:86.3
-1,0,1:86.2
0,0,1:162.1
1,0,1:86.2
2,0,1:161.1
-2,1,1:18.1
-1,1,1:86.2
0,1,1:86.0
1,1,1:86.2
-1,2,1:161.1
0,2,1:86.2
1,2,1:30.0
-1,-1,2:86.3
0,-1,2:86.0
1,-1,2:86.0
-2,0,2:18.1
-1,0,2:86.3
0,0,2:162.5
1,0,2:91.0
-1,1,2:86.2
0,1,2:86.2
1,1,2:86.1
0,-1,3:30.0
0,0,3:161.1
0,-1,4:161.1
0,0,4:161.1
2,1,1:40.0
-2,2,1:40.0
0,-2,2:39.0
0,2,2:39.0
-2,0,3:39.0
1,-2,1:39.0
