#######################################################################
# +-----------------------------------------------------------------+ #
# |                            BO3 object                           | #
# +-----------------------------------------------------------------+ #
#######################################################################

# The descriptions in this file are true only for TerrainControl. They are not true for the Minecraft Worlds mod!
# Minecraft Worlds completely reimplemented BO3s, check the MCW documentation on the mc/mctcp forums for how to use BO3s with MCW
# or watch the video's on my YT channel at https://www.youtube.com/user/PeeGee85. You can check out the "Editing and importing schematics & BO3s" 
# series of video's, in part 2 I explain BO3s. 

# This is the config file of a custom object.
# If you add this object correctly to your BiomeConfigs, it will spawn in the world.

# This is the creator of this BO3 object
Author: Unknown

# A short description of this BO3 object
Description: This BO3 was converted from a schematic using the MineCraft Worlds Editor. Unfortunately the author and description information for the schematic could not be found. If you know who the author of the schematic is then please tell the author of this BO3!

# The BO3 version, don't change this! It can be used by external applications to do a version check.
Version: 3

# The settings mode, WriteAll, WriteWithoutComments or WriteDisable. See WorldConfig.
SettingsMode: WriteDisable

#######################################################################
# +-----------------------------------------------------------------+ #
# |                          Main settings                          | #
# +-----------------------------------------------------------------+ #
#######################################################################

# This needs to be set to true to spawn the object in the Tree and Sapling resources.
Tree: false

# The frequency of the BO3 from 1 to 200. Tries this many times to spawn this BO3 when using the CustomObject(...) resource.
# Ignored by Tree(..), Sapling(..) and CustomStructure(..)
Frequency: 40

# The rarity of the BO3 from 0 to 100. Each spawn attempt has rarity% chance to succeed when using the CustomObject(...) resource.
# Ignored by Tree(..), Sapling(..) and CustomStructure(..)
Rarity: 100.0

# If you set this to true, the BO3 will be placed with a random rotation.
RotateRandomly: false

# The spawn height of the BO3 - randomY, highestBlock or highestSolidBlock.
SpawnHeight: randomY

# The height limits for the BO3.
MinHeight: 23

MaxHeight: 37

# Objects can have other objects attached to it: branches. Branches can also
# have branches attached to it, which can also have branches, etc. This is the
# maximum branch depth for this objects.
MaxBranchDepth: 10

# When spawned with the UseWorld keyword, this BO3 should NOT spawn in the following biomes.
# If you writer.write the BO3 name directly in the BiomeConfigs, this will be ignored.
ExcludedBiomes: All

#######################################################################
# +-----------------------------------------------------------------+ #
# |                      Source block settings                      | #
# +-----------------------------------------------------------------+ #
#######################################################################

# The B(s) the BO3 should spawn in.
SourceBlocks: AIR

# The maximum percentage of the BO3 that can be outside the SourceBlock.
# The BO3 won't be placed on a location with more blocks outside the SourceBlock than this percentage.
MaxPercentageOutsideSourceBlock: 100

# What to do when a block is about to be placed outside the SourceBlock? (dontPlace, placeAnyway)
OutsideSourceBlock: placeAnyway

#######################################################################
# +-----------------------------------------------------------------+ #
# |                              Blocks                             | #
# +-----------------------------------------------------------------+ #
#######################################################################

# All the blocks used in the BO3 are listed here. Possible blocks:
# B(x,y,z,id[.data][,nbtfile.nbt)
# RB(x,y,z,id[:data][,nbtfile.nbt],chance[,id[:data][,nbtfile.nbt],chance[,...]])
# So RB(0,0,0,CHEST,chest.nbt,50,CHEST,anotherchest.nbt,100) will spawn a chest at
# the BO3 origin, and give it a 50% chance to have the contents of chest.nbt, or, if that
# fails, a 100% percent chance to have the contents of anotherchest.nbt.

B(-6,11,-7,4)
B(-6,12,-7,4)
B(-6,13,-7,4)
B(-5,2,-7,3)
B(-5,3,-7,4)
B(-5,4,-7,4)
B(-5,11,-7,4)
B(-5,12,-7,4)
B(-5,13,-7,4)
B(-4,2,-7,4)
B(-4,3,-7,4)
B(-4,4,-7,2)
B(-4,11,-7,4)
B(-4,12,-7,4)
B(-4,13,-7,4)
B(-3,2,-7,3)
B(-3,3,-7,4)
B(-3,4,-7,4)
B(-2,9,-7,4)
B(-2,9,-6,4)
B(-2,10,-7,4)
B(-2,10,-6,4)
B(-2,11,-7,4)
B(-2,11,-6,4)
B(-2,12,-7,3)
B(-2,12,-6,3)
B(-2,13,-7,3)
B(-2,13,-6,3)
B(-2,14,-7,2)
B(-2,14,-6,3)
B(-2,15,-7,31:1)
B(-2,16,-7,AIR)
B(-2,17,-7,AIR)
B(-1,8,-7,4)
B(-1,8,-6,4)
B(-1,9,-7,4)
B(-1,9,-6,4)
B(-1,9,-5,4)
B(-1,10,-7,4)
B(-1,10,-6,4)
B(-1,10,-5,4)
B(-1,11,-7,3)
B(-1,11,-6,3)
B(-1,11,-5,4)
B(-1,12,-7,3)
B(-1,12,-6,4)
B(-1,12,-5,3)
B(-1,13,-7,2)
B(-1,13,-6,2)
B(-1,13,-5,3)
B(-1,14,-7,31:1)
B(-1,14,-6,31:1)
B(-1,14,-5,3)
B(-1,15,-7,AIR)
B(-1,15,-6,AIR)
B(-1,15,-5,AIR)
B(-1,16,-7,AIR)
B(-1,16,-6,AIR)
B(-1,16,-5,AIR)
B(-1,17,-7,AIR)
RB(-1,17,-6,COBBLESTONE,50,AIR,100)
B(-1,18,-7,AIR)
B(0,7,-7,4)
B(0,7,-6,4)
B(0,8,-7,4)
B(0,8,-6,4)
B(0,9,-7,106:2)
B(0,9,-6,4)
B(0,9,-5,4)
B(0,10,-7,106:2)
B(0,10,-6,4)
B(0,10,-5,4)
B(0,11,-7,AIR)
B(0,11,-6,3)
B(0,11,-5,4)
B(0,12,-7,3)
B(0,12,-6,3)
B(0,12,-5,3)
B(0,13,-7,2)
B(0,13,-6,2)
B(0,13,-5,3)
B(0,14,-7,175:2)
B(0,14,-6,31:1)
B(0,14,-5,AIR)
B(0,15,-7,175:10)
B(0,15,-6,AIR)
B(0,15,-5,AIR)
B(0,15,-4,AIR)
B(0,16,-7,AIR)
B(0,16,-6,AIR)
B(0,16,-5,AIR)
B(0,16,-4,AIR)
B(0,17,-7,AIR)
B(0,17,-6,AIR)
B(0,17,-5,AIR)
B(0,18,-7,AIR)
B(0,18,-6,AIR)
RB(0,19,-6,COBBLESTONE,50,AIR,100)
B(1,6,-7,4)
B(1,6,-6,4)
B(1,7,-7,4)
B(1,7,-6,4)
B(1,7,-5,4)
B(1,8,-7,4)
B(1,8,-6,4)
B(1,8,-5,4)
B(1,9,-7,106:1)
B(1,9,-6,4)
B(1,9,-5,4)
B(1,10,-7,AIR)
B(1,10,-6,4)
B(1,10,-5,4)
B(1,11,-7,AIR)
B(1,11,-6,AIR)
B(1,11,-5,4)
B(1,12,-7,98)
B(1,12,-6,2)
B(1,12,-5,3)
B(1,12,-4,3)
B(1,12,-3,3)
B(1,13,-7,AIR)
B(1,13,-6,39)
B(1,13,-5,2)
B(1,13,-4,3)
B(1,13,-3,3)
B(1,14,-7,AIR)
B(1,14,-6,AIR)
B(1,14,-5,31:1)
B(1,14,-4,AIR)
B(1,14,-3,3)
B(1,15,-7,AIR)
B(1,15,-6,AIR)
B(1,15,-5,AIR)
B(1,15,-4,AIR)
B(1,16,-7,AIR)
B(1,16,-6,AIR)
B(1,16,-5,AIR)
B(1,16,-4,AIR)
B(1,17,-7,AIR)
B(1,17,-6,AIR)
B(1,17,-5,AIR)
B(1,17,-4,AIR)
B(1,17,-3,3)
B(1,17,-2,3)
B(1,18,-7,AIR)
B(1,18,-6,AIR)
RB(1,18,-5,COBBLESTONE,50,AIR,100)
B(1,18,-4,3)
B(1,18,-3,3)
B(1,18,-2,3)
RB(1,19,-7,COBBLESTONE,50,AIR,100)
RB(1,19,-6,COBBLESTONE,50,AIR,100)
B(2,6,-7,4)
B(2,6,-6,4)
B(2,7,-7,4)
B(2,7,-6,4)
B(2,7,-5,4)
B(2,8,-7,4)
B(2,8,-6,4)
B(2,8,-5,4)
B(2,9,-7,106:1)
B(2,9,-6,4)
B(2,9,-5,4)
B(2,10,-7,AIR)
B(2,10,-6,AIR)
B(2,11,-7,AIR)
B(2,11,-6,AIR)
B(2,11,-5,3)
B(2,11,-4,3)
B(2,11,-3,3)
B(2,12,-7,98)
B(2,12,-6,98)
B(2,12,-5,3)
B(2,12,-4,3)
B(2,12,-3,3)
B(2,12,-2,3)
B(2,13,-7,AIR)
B(2,13,-6,AIR)
B(2,13,-5,2)
B(2,13,-4,3)
B(2,13,-3,3)
B(2,13,-2,3)
B(2,14,-7,AIR)
B(2,14,-6,AIR)
B(2,14,-5,175:3)
B(2,14,-4,AIR)
B(2,14,-3,3)
B(2,14,-2,3)
B(2,15,-7,AIR)
B(2,15,-6,AIR)
B(2,15,-5,175:10)
B(2,15,-4,AIR)
B(2,15,-3,3)
B(2,16,-7,AIR)
B(2,16,-6,AIR)
B(2,16,-5,AIR)
B(2,16,-4,AIR)
B(2,16,-3,3)
B(2,17,-7,AIR)
B(2,17,-6,AIR)
B(2,17,-5,AIR)
B(2,17,-4,AIR)
B(2,17,-3,3)
B(2,17,-2,3)
B(2,18,-7,AIR)
B(2,18,-6,AIR)
B(2,18,-5,AIR)
B(2,18,-4,3)
B(2,18,-3,3)
B(2,18,-2,3)
RB(2,19,-7,COBBLESTONE,50,AIR,100)
RB(2,19,-6,COBBLESTONE,50,AIR,100)
B(2,19,-3,3)
B(2,19,-2,3)
B(3,6,-7,4)
B(3,6,-6,4)
B(3,7,-7,4)
B(3,7,-6,4)
B(3,7,-5,4)
B(3,8,-7,AIR)
B(3,8,-6,4)
B(3,8,-5,4)
B(3,9,-7,AIR)
B(3,9,-6,106:2)
B(3,9,-5,4)
B(3,10,-7,AIR)
B(3,10,-6,AIR)
B(3,11,-7,AIR)
B(3,11,-6,AIR)
B(3,11,-5,AIR)
B(3,11,-4,3)
B(3,11,-3,3)
B(3,12,-7,98)
B(3,12,-6,98)
B(3,12,-5,98)
B(3,12,-4,3)
B(3,12,-3,3)
B(3,12,-2,3)
B(3,13,-7,AIR)
B(3,13,-6,AIR)
B(3,13,-5,AIR)
RB(3,13,-4,CHEST,../../nbt/VanillaLoot/simple_dungeon.nbt,50,CHEST,../../nbt/VanillaLoot/desert_pyramid.nbt,100)
B(3,13,-3,3)
B(3,13,-2,3)
B(3,14,-7,AIR)
B(3,14,-6,AIR)
B(3,14,-5,AIR)
B(3,14,-4,AIR)
B(3,14,-3,3)
B(3,14,-2,3)
B(3,15,-7,AIR)
B(3,15,-6,AIR)
B(3,15,-5,AIR)
B(3,15,-4,AIR)
RB(3,15,-3,COBBLESTONE,50,AIR,100)
B(3,16,-7,AIR)
B(3,16,-6,AIR)
B(3,16,-5,AIR)
B(3,16,-4,AIR)
B(3,16,-3,AIR)
B(3,17,-7,AIR)
B(3,17,-6,AIR)
B(3,17,-5,AIR)
B(3,17,-4,AIR)
B(3,17,-3,3)
B(3,18,-7,AIR)
B(3,18,-6,AIR)
B(3,18,-5,AIR)
B(3,18,-4,AIR)
B(3,18,-3,3)
B(3,18,-2,3)
RB(3,19,-6,COBBLESTONE,50,AIR,100)
B(3,19,-3,3)
B(4,6,-7,98)
B(4,7,-7,106:3)
B(4,7,-6,4)
B(4,8,-7,AIR)
B(4,8,-6,AIR)
B(4,9,-7,106:1)
B(4,9,-6,AIR)
B(4,10,-7,106:1)
B(4,10,-6,AIR)
B(4,10,-5,AIR)
B(4,11,-7,106:1)
B(4,11,-6,AIR)
B(4,11,-5,AIR)
B(4,11,-4,3)
B(4,11,-3,3)
B(4,12,-7,106:1)
B(4,12,-6,98)
B(4,12,-5,98)
B(4,12,-4,3)
B(4,12,-3,3)
B(4,12,-2,3)
B(4,13,-7,AIR)
B(4,13,-6,AIR)
B(4,13,-5,AIR)
B(4,13,-4,3)
B(4,13,-3,3)
B(4,13,-2,3)
B(4,14,-7,AIR)
B(4,14,-6,AIR)
B(4,14,-5,AIR)
B(4,14,-4,AIR)
RB(4,14,-3,COBBLESTONE,50,AIR,100)
B(4,14,-2,3)
B(4,15,-7,AIR)
B(4,15,-6,AIR)
B(4,15,-5,AIR)
B(4,15,-4,AIR)
RB(4,15,-3,COBBLESTONE,50,AIR,100)
B(4,16,-7,AIR)
B(4,16,-6,AIR)
B(4,16,-5,AIR)
B(4,16,-4,AIR)
RB(4,16,-3,COBBLESTONE,50,AIR,100)
B(4,17,-7,AIR)
B(4,17,-6,AIR)
B(4,17,-5,AIR)
B(4,17,-4,AIR)
B(4,17,-3,AIR)
B(4,18,-7,AIR)
B(4,18,-6,AIR)
B(4,18,-5,AIR)
B(4,18,-4,AIR)
B(5,4,-7,AIR)
B(5,5,-7,AIR)
B(5,6,-7,98)
B(5,7,-7,106:9)
B(5,7,-6,AIR)
B(5,8,-7,106:9)
B(5,8,-6,AIR)
B(5,9,-7,106:9)
B(5,9,-6,AIR)
B(5,9,-5,AIR)
B(5,10,-7,106:9)
B(5,10,-6,AIR)
B(5,10,-5,AIR)
B(5,11,-7,106:9)
B(5,11,-6,AIR)
B(5,11,-5,AIR)
B(5,12,-7,106:9)
B(5,12,-6,98)
B(5,12,-5,98)
B(5,12,-4,3)
B(5,12,-3,3)
B(5,13,-7,AIR)
B(5,13,-6,AIR)
B(5,13,-5,AIR)
B(5,13,-4,2)
B(5,13,-3,3)
B(5,14,-7,AIR)
B(5,14,-6,AIR)
B(5,14,-5,AIR)
B(5,14,-4,AIR)
B(5,14,-3,AIR)
B(5,15,-7,AIR)
B(5,15,-6,AIR)
B(5,15,-5,AIR)
B(5,15,-4,AIR)
RB(5,15,-3,COBBLESTONE,50,AIR,100)
B(5,16,-7,AIR)
B(5,16,-6,AIR)
B(5,16,-5,AIR)
B(5,16,-4,AIR)
RB(5,16,-3,COBBLESTONE,50,AIR,100)
B(5,17,-7,AIR)
B(5,17,-6,AIR)
B(5,17,-5,AIR)
B(5,17,-4,AIR)
B(5,18,-7,AIR)
B(5,18,-6,AIR)
B(5,18,-5,AIR)
B(6,4,-7,AIR)
B(6,5,-7,AIR)
B(6,6,-7,98)
B(6,6,-6,98)
B(6,7,-7,AIR)
B(6,7,-6,AIR)
B(6,7,-5,AIR)
B(6,8,-7,AIR)
B(6,8,-6,AIR)
B(6,8,-5,AIR)
B(6,9,-7,AIR)
B(6,9,-6,AIR)
B(6,9,-5,AIR)
B(6,10,-7,AIR)
B(6,10,-6,AIR)
B(6,10,-5,AIR)
B(6,11,-7,AIR)
B(6,11,-6,AIR)
B(6,11,-5,AIR)
B(6,11,-4,3)
B(6,12,-7,98)
B(6,12,-6,98)
B(6,12,-5,2)
B(6,12,-4,3)
B(6,12,-3,3)
B(6,13,-7,AIR)
B(6,13,-6,AIR)
B(6,13,-5,175:2)
B(6,13,-4,2)
B(6,13,-3,3)
B(6,14,-7,AIR)
B(6,14,-6,AIR)
B(6,14,-5,175:10)
B(6,14,-4,175:2)
B(6,14,-3,AIR)
B(6,15,-7,AIR)
B(6,15,-6,AIR)
B(6,15,-5,AIR)
B(6,15,-4,175:10)
B(6,15,-3,AIR)
B(6,16,-7,AIR)
B(6,16,-6,AIR)
B(6,16,-5,AIR)
B(6,16,-4,AIR)
B(6,16,-3,AIR)
B(6,17,-7,AIR)
B(6,17,-6,AIR)
B(6,17,-5,AIR)
B(6,17,-4,AIR)
B(6,18,-7,AIR)
B(6,18,-6,AIR)
B(6,18,-5,AIR)
B(7,4,-7,AIR)
B(7,5,-7,AIR)
B(7,6,-7,98)
B(7,6,-6,98)
B(7,7,-7,AIR)
B(7,7,-6,AIR)
B(7,7,-5,AIR)
B(7,8,-7,AIR)
B(7,8,-6,AIR)
B(7,8,-5,AIR)
B(7,9,-7,AIR)
B(7,9,-6,AIR)
B(7,9,-5,AIR)
B(7,10,-7,AIR)
B(7,10,-6,AIR)
B(7,10,-5,AIR)
B(7,11,-7,AIR)
B(7,11,-6,AIR)
B(7,11,-5,3)
B(7,11,-4,3)
B(7,12,-7,98)
B(7,12,-6,98)
B(7,12,-5,3)
B(7,12,-4,3)
B(7,12,-3,3)
B(7,13,-7,AIR)
B(7,13,-6,AIR)
B(7,13,-5,2)
B(7,13,-4,3)
B(7,13,-3,3)
B(7,14,-7,AIR)
B(7,14,-6,AIR)
B(7,14,-5,175:2)
B(7,14,-4,AIR)
B(7,14,-3,3)
B(7,15,-7,AIR)
B(7,15,-6,AIR)
B(7,15,-5,175:10)
B(7,15,-4,AIR)
B(7,15,-3,AIR)
B(7,16,-7,AIR)
B(7,16,-6,AIR)
B(7,16,-5,AIR)
B(7,16,-4,AIR)
B(7,17,-7,AIR)
B(7,17,-6,AIR)
B(7,17,-5,AIR)
B(7,17,-4,AIR)
B(7,18,-7,AIR)
B(7,18,-6,AIR)


#######################################################################
# +-----------------------------------------------------------------+ #
# |                            BO3 checks                           | #
# +-----------------------------------------------------------------+ #
#######################################################################

# Require a condition at a certain location in order for the BO3 to be spawned.
# BlockCheck(x,y,z,BlockName[,BlockName[,...]]) - one of the blocks must be at the location
# BlockCheckNot(x,y,z,BlockName[,BlockName[,...]]) - all the blocks must not be at the location
# LightCheck(x,y,z,minLightLevel,maxLightLevel) - light must be between min and max (inclusive)

# You can use "Solid" as a BlockName for matching all solid blocks or "All" to match all blocks that aren't air.

# Examples:
#   BlockCheck(0,-1,0,GRASS,DIRT,biomesoplenty:grass:0,biomesoplenty:grass:1,biomesoplenty:grass:2,biomesoplenty:grass:3,biomesoplenty:grass:4,biomesoplenty:grass:5,biomesoplenty:grass:6,biomesoplenty:grass:7,biomesoplenty:dirt:0,biomesoplenty:dirt:1,biomesoplenty:dirt:2,biomesoplenty:dirt:3,biomesoplenty:dirt:4,biomesoplenty:dirt:5,biomesoplenty:dirt:6,biomesoplenty:dirt:7,biomesoplenty:dirt:8,biomesoplenty:dirt:9,biomesoplenty:dirt:10,biomesoplenty:dried_sand:0,biomesoplenty:hard_ice:0,biomesoplenty:white_sand:0,biomesoplenty:white_sandstone:0,biomesoplenty:mud:0,biomesoplenty:ash_block:0)  Require grass or dirt just below the object
#   BlockCheck(0,-1,0,Solid)       Require any solid block just below the object
#   BlockCheck(0,-1,0,WOOL)        Require any type of wool just below the object
#   BlockCheck(0,-1,0,WOOL:0)      Require white wool just below the object
#   BlockCheckNot(0,-1,0,WOOL:0)   Require that there is no white wool below the object
#   LightCheck(0,0,0,0,1)          Require almost complete darkness just below the object

#######################################################################
# +-----------------------------------------------------------------+ #
# |                             Branches                            | #
# +-----------------------------------------------------------------+ #
#######################################################################

# Branches are objects that will spawn when this object spawns when it is used in
# the CustomStructure resource. Branches can also have branches, making complex
# structures possible. See the wiki for more details.

# Regular Branches spawn each branch with an independent chance of spawning.
# Branch(x,y,z,branchName,rotation,chance[,anotherBranchName,rotation,chance[,...]][IndividualChance])
# branchName - name of the object to spawn.
# rotation - NORTH, SOUTH, EAST or WEST.
# IndividualChance - The chance each branch has to spawn, assumed to be 100 when left blank

# WBR(x,y,z,branchName,rotation,chance[,anotherBranchName,rotation,chance[,...]][MaxChanceOutOf])
# MaxChanceOutOf - The chance all branches have to spawn out of, assumed to be 100 when left blank
Branch(16,0,0,PigsUndergroundCaveC3R1,NORTH,100)
