#######################################################################
# +-----------------------------------------------------------------+ #
# |                            BO3 object                           | #
# +-----------------------------------------------------------------+ #
#######################################################################

# The descriptions in this file are true only for TerrainControl. They are not true for the Minecraft Worlds mod!
# Minecraft Worlds completely reimplemented BO3s, check the MCW documentation on the mc/mctcp forums for how to use BO3s with MCW
# or watch the video's on my YT channel at https://www.youtube.com/user/PeeGee85. You can check out the "Editing and importing schematics & BO3s" 
# series of video's, in part 2 I explain BO3s. 

# This is the config file of a custom object.
# If you add this object correctly to your BiomeConfigs, it will spawn in the world.

# This is the creator of this BO3 object
Author: Unknown

# A short description of this BO3 object
Description: This BO3 was converted from a schematic using the MineCraft Worlds Editor. Unfortunately the author and description information for the schematic could not be found. If you know who the author of the schematic is then please tell the author of this BO3!

# The BO3 version, don't change this! It can be used by external applications to do a version check.
Version: 3

# The settings mode, WriteAll, WriteWithoutComments or WriteDisable. See WorldConfig.
SettingsMode: WriteDisable

#######################################################################
# +-----------------------------------------------------------------+ #
# |                          Main settings                          | #
# +-----------------------------------------------------------------+ #
#######################################################################

# This needs to be set to true to spawn the object in the Tree and Sapling resources.
Tree: false

# The frequency of the BO3 from 1 to 200. Tries this many times to spawn this BO3 when using the CustomObject(...) resource.
# Ignored by Tree(..), Sapling(..) and CustomStructure(..)
Frequency: 40

# The rarity of the BO3 from 0 to 100. Each spawn attempt has rarity% chance to succeed when using the CustomObject(...) resource.
# Ignored by Tree(..), Sapling(..) and CustomStructure(..)
Rarity: 100.0

# If you set this to true, the BO3 will be placed with a random rotation.
RotateRandomly: false

# The spawn height of the BO3 - randomY, highestBlock or highestSolidBlock.
SpawnHeight: randomY

# The height limits for the BO3.
MinHeight: 0

MaxHeight: 256

# Objects can have other objects attached to it: branches. Branches can also
# have branches attached to it, which can also have branches, etc. This is the
# maximum branch depth for this objects.
MaxBranchDepth: 10

# When spawned with the UseWorld keyword, this BO3 should NOT spawn in the following biomes.
# If you writer.write the BO3 name directly in the BiomeConfigs, this will be ignored.
ExcludedBiomes: All

#######################################################################
# +-----------------------------------------------------------------+ #
# |                      Source block settings                      | #
# +-----------------------------------------------------------------+ #
#######################################################################

# The block(s) the BO3 should spawn in.
SourceBlocks: AIR

# The maximum percentage of the BO3 that can be outside the SourceBlock.
# The BO3 won't be placed on a location with more blocks outside the SourceBlock than this percentage.
MaxPercentageOutsideSourceBlock: 100

# What to do when a block is about to be placed outside the SourceBlock? (dontPlace, placeAnyway)
OutsideSourceBlock: placeAnyway

#######################################################################
# +-----------------------------------------------------------------+ #
# |                              Blocks                             | #
# +-----------------------------------------------------------------+ #
#######################################################################

# All the blocks used in the BO3 are listed here. Possible blocks:
# Block(x,y,z,id[.data][,nbtfile.nbt)
# RandomBlock(x,y,z,id[:data][,nbtfile.nbt],chance[,id[:data][,nbtfile.nbt],chance[,...]])
# So RandomBlock(0,0,0,CHEST,chest.nbt,50,CHEST,anotherchest.nbt,100) will spawn a chest at
# the BO3 origin, and give it a 50% chance to have the contents of chest.nbt, or, if that
# fails, a 100% percent chance to have the contents of anotherchest.nbt.

Block(-8,15,-6,17:5)
Block(-8,15,-5,5:1)
Block(-8,15,-4,5:1)
Block(-8,15,-3,5:1)
Block(-8,15,-2,5:1)
Block(-8,15,-1,5:1)
Block(-8,15,0,5:1)
Block(-8,15,1,5:1)
Block(-8,15,2,5:1)
Block(-8,15,3,17:5)
Block(-8,15,4,125:1)
Block(-8,16,-6,134:6)
Block(-8,16,-5,134:7)
Block(-8,16,-4,AIR)
Block(-8,16,-3,AIR)
Block(-8,16,-2,126:11)
Block(-8,16,-1,126:11)
Block(-8,16,0,53:2)
Block(-8,16,1,AIR)
Block(-8,16,2,AIR)
Block(-8,16,3,5:1)
Block(-8,16,4,AIR)
Block(-8,16,5,AIR)
Block(-8,16,6,AIR)
Block(-8,16,7,AIR)
Block(-8,16,8,AIR)
Block(-8,17,-6,134:2)
Block(-8,17,-5,5:1)
Block(-8,17,-4,AIR)
Block(-8,17,-3,AIR)
Block(-8,17,-2,AIR)
Block(-8,17,-1,AIR)
Block(-8,17,0,AIR)
Block(-8,17,1,AIR)
Block(-8,17,2,AIR)
Block(-8,17,3,5:1)
Block(-8,17,4,AIR)
Block(-8,17,5,AIR)
Block(-8,17,6,AIR)
Block(-8,17,7,AIR)
Block(-8,17,8,AIR)
Block(-8,18,-6,134:6)
Block(-8,18,-5,134:3)
Block(-8,18,-4,AIR)
Block(-8,18,-3,AIR)
Block(-8,18,-2,AIR)
Block(-8,18,-1,AIR)
Block(-8,18,0,AIR)
Block(-8,18,1,AIR)
Block(-8,18,2,AIR)
Block(-8,18,3,5:1)
Block(-8,18,4,AIR)
Block(-8,18,5,AIR)
Block(-8,18,6,AIR)
Block(-8,18,7,AIR)
Block(-8,18,8,AIR)
Block(-8,19,-6,134:6)
Block(-8,19,-5,AIR)
Block(-8,19,-4,AIR)
Block(-8,19,-3,AIR)
Block(-8,19,-2,AIR)
Block(-8,19,-1,AIR)
Block(-8,19,0,AIR)
Block(-8,19,1,AIR)
Block(-8,19,2,AIR)
Block(-8,19,3,134:7)
Block(-8,19,4,AIR)
Block(-8,19,5,AIR)
Block(-8,19,6,AIR)
Block(-8,19,7,AIR)
Block(-8,19,8,AIR)
Block(-8,20,-7,5:5)
Block(-8,20,-6,17:5)
Block(-8,20,-5,5:1)
Block(-8,20,-4,5:1)
Block(-8,20,-3,5:1)
Block(-8,20,-2,5:1)
Block(-8,20,-1,5:1)
Block(-8,20,0,5:1)
Block(-8,20,1,5:1)
Block(-8,20,2,5:1)
Block(-8,20,3,17:5)
Block(-8,20,4,AIR)
Block(-8,20,5,AIR)
Block(-8,20,6,AIR)
Block(-8,20,7,AIR)
Block(-8,20,8,AIR)
Block(-8,21,-6,159:13)
Block(-8,21,-5,159:13)
Block(-8,21,-4,159:13)
Block(-8,21,-3,171:12)
Block(-8,21,-2,171:12)
Block(-8,21,-1,171:12)
Block(-8,21,0,134:2)
Block(-8,21,1,55)
Block(-8,21,2,159:13)
Block(-8,21,3,159:13)
Block(-8,21,4,159:13)
Block(-8,21,5,AIR)
Block(-8,21,6,AIR)
Block(-8,21,7,AIR)
Block(-8,21,8,AIR)
Block(-8,22,-6,AIR)
Block(-8,22,-5,AIR)
Block(-8,22,-4,134:6)
Block(-8,22,-3,134:7)
Block(-8,22,-2,AIR)
Block(-8,22,-1,AIR)
Block(-8,22,0,AIR)
Block(-8,22,1,134:2)
Block(-8,22,2,134:7)
Block(-8,22,3,AIR)
Block(-8,22,4,AIR)
Block(-8,22,5,AIR)
Block(-8,22,6,AIR)
Block(-8,22,7,AIR)
Block(-8,22,8,AIR)
Block(-8,23,-6,AIR)
Block(-8,23,-5,AIR)
Block(-8,23,-4,5:1)
Block(-8,23,-3,5:1)
Block(-8,23,-2,AIR)
Block(-8,23,-1,AIR)
Block(-8,23,0,AIR)
Block(-8,23,1,5:1)
Block(-8,23,2,5:1)
Block(-8,23,3,AIR)
Block(-8,23,4,AIR)
Block(-8,23,5,AIR)
Block(-8,23,6,AIR)
Block(-8,23,7,AIR)
Block(-8,23,8,AIR)
Block(-8,24,-6,AIR)
Block(-8,24,-5,164:4)
Block(-8,24,-4,5:1)
Block(-8,24,-3,159:13)
Block(-8,24,-2,AIR)
Block(-8,24,-1,AIR)
Block(-8,24,0,AIR)
Block(-8,24,1,159:13)
Block(-8,24,2,5:1)
Block(-8,24,3,164:4)
Block(-8,24,4,AIR)
Block(-8,24,5,AIR)
Block(-8,24,6,AIR)
Block(-8,24,7,AIR)
Block(-8,24,8,AIR)
Block(-8,25,-6,AIR)
Block(-8,25,-5,164:3)
Block(-8,25,-4,164:3)
Block(-8,25,-3,164:3)
Block(-8,25,-2,159:13)
Block(-8,25,-1,AIR)
Block(-8,25,0,159:13)
Block(-8,25,1,164:3)
Block(-8,25,2,164:3)
Block(-8,25,3,164:3)
Block(-8,25,4,AIR)
Block(-8,25,5,AIR)
Block(-8,25,6,AIR)
Block(-8,25,7,AIR)
Block(-8,25,8,AIR)
Block(-8,26,-6,AIR)
Block(-8,26,-5,164)
Block(-8,26,-4,164)
Block(-8,26,-3,164)
Block(-8,26,-2,AIR)
Block(-8,26,-1,5:5)
Block(-8,26,0,AIR)
Block(-8,26,1,164)
Block(-8,26,2,164)
Block(-8,26,3,164)
Block(-8,26,4,AIR)
Block(-8,26,5,AIR)
Block(-8,26,6,AIR)
Block(-8,26,7,AIR)
Block(-8,26,8,AIR)
Block(-8,27,-2,216:8)
Block(-8,27,-1,216:8)
Block(-8,27,0,216:8)
Block(-8,28,-2,216:8)
Block(-8,28,-1,216:8)
Block(-8,28,0,216:8)
Block(-7,0,5,17:1)
Block(-7,1,5,17:1)
Block(-7,2,5,17:1)
Block(-7,3,5,17:1)
Block(-7,4,5,17:1)
Block(-7,5,5,17:1)
Block(-7,6,5,17:1)
Block(-7,7,5,17:1)
Block(-7,8,5,17:1)
Block(-7,9,5,17:1)
Block(-7,10,5,17:1)
Block(-7,11,5,17:1)
Block(-7,12,5,17:1)
Block(-7,13,5,17:1)
Block(-7,14,5,17:1)
Block(-7,15,-6,17:5)
Block(-7,15,-5,5:1)
Block(-7,15,-4,5:1)
Block(-7,15,-3,5:1)
Block(-7,15,-2,5:1)
Block(-7,15,-1,5:1)
Block(-7,15,0,5:1)
Block(-7,15,1,5:1)
Block(-7,15,2,5:1)
Block(-7,15,3,17:5)
Block(-7,15,4,17:9)
Block(-7,15,5,17:9)
Block(-7,15,6,17:9)
Block(-7,16,-6,134:6)
Block(-7,16,-5,134:7)
Block(-7,16,-4,AIR)
Block(-7,16,-3,53:3)
Block(-7,16,-2,136:4)
Block(-7,16,-1,136:4)
Block(-7,16,0,AIR)
Block(-7,16,1,AIR)
Block(-7,16,2,191)
Block(-7,16,3,17:1)
Block(-7,16,4,AIR)
Block(-7,16,5,AIR)
Block(-7,16,6,AIR)
Block(-7,16,7,AIR)
Block(-7,16,8,AIR)
Block(-7,17,-6,AIR)
Block(-7,17,-5,160:9)
Block(-7,17,-4,AIR)
Block(-7,17,-3,AIR)
Block(-7,17,-2,AIR)
Block(-7,17,-1,AIR)
Block(-7,17,0,AIR)
Block(-7,17,1,AIR)
Block(-7,17,2,191)
Block(-7,17,3,17:1)
Block(-7,17,4,AIR)
Block(-7,17,5,AIR)
Block(-7,17,6,AIR)
Block(-7,17,7,AIR)
Block(-7,17,8,AIR)
Block(-7,18,-6,134:6)
Block(-7,18,-5,134:3)
Block(-7,18,-4,AIR)
Block(-7,18,-3,AIR)
Block(-7,18,-2,AIR)
Block(-7,18,-1,AIR)
Block(-7,18,0,AIR)
Block(-7,18,1,AIR)
Block(-7,18,2,56)
Block(-7,18,3,17:1)
Block(-7,18,4,AIR)
Block(-7,18,5,AIR)
Block(-7,18,6,AIR)
Block(-7,18,7,AIR)
Block(-7,18,8,AIR)
Block(-7,19,-6,134:6)
Block(-7,19,-5,AIR)
Block(-7,19,-4,AIR)
Block(-7,19,-3,AIR)
Block(-7,19,-2,AIR)
Block(-7,19,-1,AIR)
Block(-7,19,0,AIR)
Block(-7,19,1,AIR)
Block(-7,19,2,AIR)
Block(-7,19,3,17:1)
Block(-7,19,4,AIR)
Block(-7,19,5,AIR)
Block(-7,19,6,AIR)
Block(-7,19,7,AIR)
Block(-7,19,8,AIR)
Block(-7,20,-7,5:5)
Block(-7,20,-6,17:5)
Block(-7,20,-5,5:1)
Block(-7,20,-4,5:1)
Block(-7,20,-3,5:1)
Block(-7,20,-2,5:1)
Block(-7,20,-1,5:1)
Block(-7,20,0,5:1)
Block(-7,20,1,5:1)
Block(-7,20,2,5:1)
Block(-7,20,3,17:5)
Block(-7,20,4,AIR)
Block(-7,20,5,AIR)
Block(-7,20,6,AIR)
Block(-7,20,7,AIR)
Block(-7,20,8,AIR)
Block(-7,21,-6,159:13)
Block(-7,21,-5,159:13)
Block(-7,21,-4,159:13)
Block(-7,21,-3,171:12)
Block(-7,21,-2,171:12)
Block(-7,21,-1,171:12)
Block(-7,21,0,134:2)
Block(-7,21,1,55)
Block(-7,21,2,159:13)
Block(-7,21,3,159:13)
Block(-7,21,4,159:13)
Block(-7,21,5,AIR)
Block(-7,21,6,AIR)
Block(-7,21,7,AIR)
Block(-7,21,8,AIR)
Block(-7,22,-6,159:13)
Block(-7,22,-5,159:13)
Block(-7,22,-4,159:13)
Block(-7,22,-3,AIR)
Block(-7,22,-2,AIR)
Block(-7,22,-1,AIR)
Block(-7,22,0,AIR)
Block(-7,22,1,134:2)
Block(-7,22,2,159:13)
Block(-7,22,3,159:13)
Block(-7,22,4,159:13)
Block(-7,22,5,AIR)
Block(-7,22,6,AIR)
Block(-7,22,7,AIR)
Block(-7,22,8,AIR)
Block(-7,23,-6,AIR)
Block(-7,23,-5,164:4)
Block(-7,23,-4,5:1)
Block(-7,23,-3,AIR)
Block(-7,23,-2,AIR)
Block(-7,23,-1,AIR)
Block(-7,23,0,AIR)
Block(-7,23,1,134:6)
Block(-7,23,2,5:1)
Block(-7,23,3,164:4)
Block(-7,23,4,AIR)
Block(-7,23,5,AIR)
Block(-7,23,6,AIR)
Block(-7,23,7,AIR)
Block(-7,23,8,AIR)
Block(-7,24,-6,AIR)
Block(-7,24,-5,164:3)
Block(-7,24,-4,164:3)
Block(-7,24,-3,159:13)
Block(-7,24,-2,AIR)
Block(-7,24,-1,AIR)
Block(-7,24,0,AIR)
Block(-7,24,1,159:13)
Block(-7,24,2,164:3)
Block(-7,24,3,164:3)
Block(-7,24,4,AIR)
Block(-7,24,5,AIR)
Block(-7,24,6,AIR)
Block(-7,24,7,AIR)
Block(-7,24,8,AIR)
Block(-7,25,-6,AIR)
Block(-7,25,-5,AIR)
Block(-7,25,-4,AIR)
Block(-7,25,-3,AIR)
Block(-7,25,-2,159:13)
Block(-7,25,-1,AIR)
Block(-7,25,0,159:13)
Block(-7,25,1,AIR)
Block(-7,25,2,AIR)
Block(-7,25,3,AIR)
Block(-7,25,4,AIR)
Block(-7,25,5,AIR)
Block(-7,25,6,AIR)
Block(-7,25,7,AIR)
Block(-7,25,8,AIR)
Block(-7,26,-6,AIR)
Block(-7,26,-5,AIR)
Block(-7,26,-4,AIR)
Block(-7,26,-3,AIR)
Block(-7,26,-2,AIR)
Block(-7,26,-1,5:5)
Block(-7,26,0,AIR)
Block(-7,26,1,AIR)
Block(-7,26,2,AIR)
Block(-7,26,3,AIR)
Block(-7,26,4,AIR)
Block(-7,26,5,AIR)
Block(-7,26,6,AIR)
Block(-7,26,7,AIR)
Block(-7,26,8,AIR)
Block(-7,27,-2,216:8)
Block(-7,27,-1,216:8)
Block(-7,27,0,216:8)
Block(-7,28,-2,216:8)
Block(-7,28,-1,216:8)
Block(-7,28,0,216:8)
Block(-7,29,-1,216:8)
Block(-6,15,-6,17:5)
Block(-6,15,-5,5:1)
Block(-6,15,-4,5:1)
Block(-6,15,-3,5:1)
Block(-6,15,-2,5:1)
Block(-6,15,-1,5:1)
Block(-6,15,0,5:1)
Block(-6,15,1,5:1)
Block(-6,15,2,5:1)
Block(-6,15,3,17:5)
Block(-6,15,4,126:9)
Block(-6,15,5,17:5)
Block(-6,16,-6,134:6)
Block(-6,16,-5,134:7)
Block(-6,16,-4,AIR)
Block(-6,16,-3,AIR)
Block(-6,16,-2,AIR)
Block(-6,16,-1,AIR)
Block(-6,16,0,AIR)
Block(-6,16,1,AIR)
Block(-6,16,2,134:6)
Block(-6,16,3,134:7)
Block(-6,16,4,AIR)
Block(-6,16,5,AIR)
Block(-6,16,6,AIR)
Block(-6,16,7,AIR)
Block(-6,16,8,AIR)
Block(-6,17,-6,134:2)
Block(-6,17,-5,5:1)
Block(-6,17,-4,AIR)
Block(-6,17,-3,AIR)
Block(-6,17,-2,AIR)
Block(-6,17,-1,AIR)
Block(-6,17,0,AIR)
Block(-6,17,1,AIR)
Block(-6,17,2,5:1)
Block(-6,17,3,134:3)
Block(-6,17,4,AIR)
Block(-6,17,5,AIR)
Block(-6,17,6,AIR)
Block(-6,17,7,AIR)
Block(-6,17,8,AIR)
Block(-6,18,-6,134:6)
Block(-6,18,-5,134:3)
Block(-6,18,-4,AIR)
Block(-6,18,-3,AIR)
Block(-6,18,-2,AIR)
Block(-6,18,-1,AIR)
Block(-6,18,0,AIR)
Block(-6,18,1,AIR)
Block(-6,18,2,134:2)
Block(-6,18,3,134:7)
Block(-6,18,4,AIR)
Block(-6,18,5,AIR)
Block(-6,18,6,AIR)
Block(-6,18,7,AIR)
Block(-6,18,8,AIR)
Block(-6,19,-6,134:6)
Block(-6,19,-5,AIR)
Block(-6,19,-4,AIR)
Block(-6,19,-3,AIR)
Block(-6,19,-2,AIR)
Block(-6,19,-1,AIR)
Block(-6,19,0,AIR)
Block(-6,19,1,AIR)
Block(-6,19,2,AIR)
Block(-6,19,3,134:7)
Block(-6,19,4,AIR)
Block(-6,19,5,AIR)
Block(-6,19,6,AIR)
Block(-6,19,7,AIR)
Block(-6,19,8,AIR)
Block(-6,20,-7,5:5)
Block(-6,20,-6,17:5)
Block(-6,20,-5,5:1)
Block(-6,20,-4,5:1)
Block(-6,20,-3,5:1)
Block(-6,20,-2,5:1)
Block(-6,20,-1,5:1)
Block(-6,20,0,5:1)
Block(-6,20,1,5:1)
Block(-6,20,2,5:1)
Block(-6,20,3,17:5)
Block(-6,20,4,AIR)
Block(-6,20,5,AIR)
Block(-6,20,6,AIR)
Block(-6,20,7,AIR)
Block(-6,20,8,AIR)
Block(-6,21,-7,126:5)
Block(-6,21,-6,159:13)
Block(-6,21,-5,159:13)
Block(-6,21,-4,AIR)
Block(-6,21,-3,171:12)
Block(-6,21,-2,171:12)
Block(-6,21,-1,171:12)
Block(-6,21,0,134:2)
Block(-6,21,1,55)
Block(-6,21,2,159:13)
Block(-6,21,3,159:13)
Block(-6,21,4,159:13)
Block(-6,21,5,AIR)
Block(-6,21,6,AIR)
Block(-6,21,7,AIR)
Block(-6,21,8,AIR)
Block(-6,22,-6,159:13)
Block(-6,22,-5,159:13)
Block(-6,22,-4,AIR)
Block(-6,22,-3,AIR)
Block(-6,22,-2,AIR)
Block(-6,22,-1,AIR)
Block(-6,22,0,AIR)
Block(-6,22,1,134:2)
Block(-6,22,2,159:13)
Block(-6,22,3,159:13)
Block(-6,22,4,159:13)
Block(-6,22,5,AIR)
Block(-6,22,6,AIR)
Block(-6,22,7,AIR)
Block(-6,22,8,AIR)
Block(-6,23,-6,AIR)
Block(-6,23,-5,164:3)
Block(-6,23,-4,159:13)
Block(-6,23,-3,AIR)
Block(-6,23,-2,AIR)
Block(-6,23,-1,AIR)
Block(-6,23,0,AIR)
Block(-6,23,1,134:6)
Block(-6,23,2,159:13)
Block(-6,23,3,164:3)
Block(-6,23,4,AIR)
Block(-6,23,5,AIR)
Block(-6,23,6,AIR)
Block(-6,23,7,AIR)
Block(-6,23,8,AIR)
Block(-6,24,-6,AIR)
Block(-6,24,-5,AIR)
Block(-6,24,-4,AIR)
Block(-6,24,-3,159:13)
Block(-6,24,-2,AIR)
Block(-6,24,-1,AIR)
Block(-6,24,0,AIR)
Block(-6,24,1,159:13)
Block(-6,24,2,AIR)
Block(-6,24,3,AIR)
Block(-6,24,4,AIR)
Block(-6,24,5,AIR)
Block(-6,24,6,AIR)
Block(-6,24,7,AIR)
Block(-6,24,8,AIR)
Block(-6,25,-6,AIR)
Block(-6,25,-5,AIR)
Block(-6,25,-4,AIR)
Block(-6,25,-3,AIR)
Block(-6,25,-2,159:13)
Block(-6,25,-1,AIR)
Block(-6,25,0,159:13)
Block(-6,25,1,AIR)
Block(-6,25,2,AIR)
Block(-6,25,3,AIR)
Block(-6,25,4,AIR)
Block(-6,25,5,AIR)
Block(-6,25,6,AIR)
Block(-6,25,7,AIR)
Block(-6,25,8,AIR)
Block(-6,26,-6,AIR)
Block(-6,26,-5,AIR)
Block(-6,26,-4,AIR)
Block(-6,26,-3,AIR)
Block(-6,26,-2,AIR)
Block(-6,26,-1,5:5)
Block(-6,26,0,AIR)
Block(-6,26,1,AIR)
Block(-6,26,2,AIR)
Block(-6,26,3,AIR)
Block(-6,26,4,AIR)
Block(-6,26,5,AIR)
Block(-6,26,6,AIR)
Block(-6,26,7,AIR)
Block(-6,26,8,AIR)
Block(-6,27,-1,216:8)
Block(-6,28,-2,216:8)
Block(-6,28,-1,216:8)
Block(-6,28,0,216:8)
Block(-6,29,-2,216:8)
Block(-6,29,-1,216:8)
Block(-6,29,0,216:8)
Block(-5,0,-6,17:1)
Block(-5,1,-6,17:1)
Block(-5,2,-6,17:1)
Block(-5,3,-6,17:1)
Block(-5,4,-6,17:1)
Block(-5,5,-6,17:1)
Block(-5,6,-6,17:1)
Block(-5,7,-6,17:1)
Block(-5,8,-6,17:1)
Block(-5,9,-6,17:1)
Block(-5,10,-6,17:1)
Block(-5,11,-6,17:1)
Block(-5,12,-6,17:1)
Block(-5,13,-6,17:1)
Block(-5,14,-6,17:1)
Block(-5,15,-6,17:1)
Block(-5,15,-5,5:1)
Block(-5,15,-4,5:1)
Block(-5,15,-3,5:1)
Block(-5,15,-2,5:1)
Block(-5,15,-1,5:1)
Block(-5,15,0,5:1)
Block(-5,15,1,5:1)
Block(-5,15,2,5:1)
Block(-5,15,3,17:5)
Block(-5,15,4,126:9)
Block(-5,15,5,17:5)
Block(-5,16,-6,17:1)
Block(-5,16,-5,191)
Block(-5,16,-4,AIR)
Block(-5,16,-3,AIR)
Block(-5,16,-2,AIR)
Block(-5,16,-1,AIR)
Block(-5,16,0,191)
Block(-5,16,1,AIR)
Block(-5,16,2,134:6)
Block(-5,16,3,134:7)
Block(-5,16,4,AIR)
Block(-5,16,5,AIR)
Block(-5,16,6,AIR)
Block(-5,16,7,AIR)
Block(-5,16,8,AIR)
Block(-5,17,-6,17:1)
Block(-5,17,-5,191)
Block(-5,17,-4,AIR)
Block(-5,17,-3,AIR)
Block(-5,17,-2,AIR)
Block(-5,17,-1,AIR)
Block(-5,17,0,191)
Block(-5,17,1,AIR)
Block(-5,17,2,160:9)
Block(-5,17,3,AIR)
Block(-5,17,4,AIR)
Block(-5,17,5,AIR)
Block(-5,17,6,AIR)
Block(-5,17,7,AIR)
Block(-5,17,8,AIR)
Block(-5,18,-6,17:1)
Block(-5,18,-5,191)
Block(-5,18,-4,AIR)
Block(-5,18,-3,AIR)
Block(-5,18,-2,AIR)
Block(-5,18,-1,AIR)
Block(-5,18,0,191)
Block(-5,18,1,AIR)
Block(-5,18,2,134:2)
Block(-5,18,3,134:7)
Block(-5,18,4,AIR)
Block(-5,18,5,AIR)
Block(-5,18,6,AIR)
Block(-5,18,7,AIR)
Block(-5,18,8,AIR)
Block(-5,19,-6,17:1)
Block(-5,19,-5,56)
Block(-5,19,-4,AIR)
Block(-5,19,-3,AIR)
Block(-5,19,-2,AIR)
Block(-5,19,-1,AIR)
Block(-5,19,0,124)
Block(-5,19,1,69)
Block(-5,19,2,AIR)
Block(-5,19,3,134:7)
Block(-5,19,4,AIR)
Block(-5,19,5,AIR)
Block(-5,19,6,AIR)
Block(-5,19,7,AIR)
Block(-5,19,8,AIR)
Block(-5,20,-7,5:5)
Block(-5,20,-6,17:1)
Block(-5,20,-5,5:1)
Block(-5,20,-4,5:1)
Block(-5,20,-3,5:1)
Block(-5,20,-2,5:1)
Block(-5,20,-1,5:1)
Block(-5,20,0,5:1)
Block(-5,20,1,5:1)
Block(-5,20,2,5:1)
Block(-5,20,3,17:5)
Block(-5,20,4,AIR)
Block(-5,20,5,AIR)
Block(-5,20,6,AIR)
Block(-5,20,7,AIR)
Block(-5,20,8,AIR)
Block(-5,21,-7,126:5)
Block(-5,21,-6,159:13)
Block(-5,21,-5,159:13)
Block(-5,21,-4,47)
Block(-5,21,-3,171:12)
Block(-5,21,-2,171:12)
Block(-5,21,-1,171:12)
Block(-5,21,0,134:2)
Block(-5,21,1,55)
Block(-5,21,2,159:13)
Block(-5,21,3,159:13)
Block(-5,21,4,159:13)
Block(-5,21,5,AIR)
Block(-5,21,6,AIR)
Block(-5,21,7,AIR)
Block(-5,21,8,AIR)
Block(-5,22,-6,159:13)
Block(-5,22,-5,159:13)
Block(-5,22,-4,47)
Block(-5,22,-3,AIR)
Block(-5,22,-2,AIR)
Block(-5,22,-1,AIR)
Block(-5,22,0,AIR)
Block(-5,22,1,134:2)
Block(-5,22,2,159:13)
Block(-5,22,3,159:13)
Block(-5,22,4,159:13)
Block(-5,22,5,AIR)
Block(-5,22,6,AIR)
Block(-5,22,7,AIR)
Block(-5,22,8,AIR)
Block(-5,23,-6,AIR)
Block(-5,23,-5,AIR)
Block(-5,23,-4,159:13)
Block(-5,23,-3,AIR)
Block(-5,23,-2,AIR)
Block(-5,23,-1,AIR)
Block(-5,23,0,AIR)
Block(-5,23,1,134:6)
Block(-5,23,2,159:13)
Block(-5,23,3,AIR)
Block(-5,23,4,AIR)
Block(-5,23,5,AIR)
Block(-5,23,6,AIR)
Block(-5,23,7,AIR)
Block(-5,23,8,AIR)
Block(-5,24,-6,AIR)
Block(-5,24,-5,AIR)
Block(-5,24,-4,AIR)
Block(-5,24,-3,159:13)
Block(-5,24,-2,AIR)
Block(-5,24,-1,AIR)
Block(-5,24,0,AIR)
Block(-5,24,1,159:13)
Block(-5,24,2,AIR)
Block(-5,24,3,AIR)
Block(-5,24,4,AIR)
Block(-5,24,5,AIR)
Block(-5,24,6,AIR)
Block(-5,24,7,AIR)
Block(-5,24,8,AIR)
Block(-5,25,-6,AIR)
Block(-5,25,-5,AIR)
Block(-5,25,-4,AIR)
Block(-5,25,-3,AIR)
Block(-5,25,-2,159:13)
Block(-5,25,-1,AIR)
Block(-5,25,0,159:13)
Block(-5,25,1,AIR)
Block(-5,25,2,AIR)
Block(-5,25,3,AIR)
Block(-5,25,4,AIR)
Block(-5,25,5,AIR)
Block(-5,25,6,AIR)
Block(-5,25,7,AIR)
Block(-5,25,8,AIR)
Block(-5,26,-6,AIR)
Block(-5,26,-5,AIR)
Block(-5,26,-4,AIR)
Block(-5,26,-3,AIR)
Block(-5,26,-2,AIR)
Block(-5,26,-1,5:5)
Block(-5,26,0,AIR)
Block(-5,26,1,AIR)
Block(-5,26,2,AIR)
Block(-5,26,3,AIR)
Block(-5,26,4,AIR)
Block(-5,26,5,AIR)
Block(-5,26,6,AIR)
Block(-5,26,7,AIR)
Block(-5,26,8,AIR)
Block(-5,28,-2,216:8)
Block(-5,28,-1,216:8)
Block(-5,28,0,216:8)
Block(-5,29,-2,216:8)
Block(-5,29,-1,216:8)
Block(-5,29,0,216:8)
Block(-5,30,-1,216:8)
Block(-4,15,-6,17:5)
Block(-4,15,-5,5:1)
Block(-4,15,-4,5:1)
Block(-4,15,-3,5:1)
Block(-4,15,-2,5:1)
Block(-4,15,-1,5:1)
Block(-4,15,0,5:1)
Block(-4,15,1,5:1)
Block(-4,15,2,5:1)
Block(-4,15,3,17:5)
Block(-4,15,4,126:9)
Block(-4,15,5,17:5)
Block(-4,16,-6,134:6)
Block(-4,16,-5,AIR)
Block(-4,16,-4,AIR)
Block(-4,16,-3,AIR)
Block(-4,16,-2,AIR)
Block(-4,16,-1,AIR)
Block(-4,16,0,AIR)
Block(-4,16,1,AIR)
Block(-4,16,2,134:6)
Block(-4,16,3,134:7)
Block(-4,16,4,AIR)
Block(-4,16,5,AIR)
Block(-4,16,6,AIR)
Block(-4,16,7,AIR)
Block(-4,16,8,AIR)
Block(-4,17,-6,134:2)
Block(-4,17,-5,AIR)
Block(-4,17,-4,AIR)
Block(-4,17,-3,AIR)
Block(-4,17,-2,AIR)
Block(-4,17,-1,AIR)
Block(-4,17,0,AIR)
Block(-4,17,1,AIR)
Block(-4,17,2,5:1)
Block(-4,17,3,134:3)
Block(-4,17,4,AIR)
Block(-4,17,5,AIR)
Block(-4,17,6,AIR)
Block(-4,17,7,AIR)
Block(-4,17,8,AIR)
Block(-4,18,-6,134:6)
Block(-4,18,-5,AIR)
Block(-4,18,-4,AIR)
Block(-4,18,-3,AIR)
Block(-4,18,-2,AIR)
Block(-4,18,-1,AIR)
Block(-4,18,0,AIR)
Block(-4,18,1,AIR)
Block(-4,18,2,134:2)
Block(-4,18,3,134:7)
Block(-4,18,4,AIR)
Block(-4,18,5,AIR)
Block(-4,18,6,AIR)
Block(-4,18,7,AIR)
Block(-4,18,8,AIR)
Block(-4,19,-6,134:6)
Block(-4,19,-5,AIR)
Block(-4,19,-4,AIR)
Block(-4,19,-3,AIR)
Block(-4,19,-2,AIR)
Block(-4,19,-1,AIR)
Block(-4,19,0,AIR)
Block(-4,19,1,AIR)
Block(-4,19,2,AIR)
Block(-4,19,3,134:7)
Block(-4,19,4,AIR)
Block(-4,19,5,AIR)
Block(-4,19,6,AIR)
Block(-4,19,7,AIR)
Block(-4,19,8,AIR)
Block(-4,20,-7,5:5)
Block(-4,20,-6,17:5)
Block(-4,20,-5,5:1)
Block(-4,20,-4,5:1)
Block(-4,20,-3,5:1)
Block(-4,20,-2,5:1)
Block(-4,20,-1,5:1)
Block(-4,20,0,5:1)
Block(-4,20,1,5:1)
Block(-4,20,2,5:1)
Block(-4,20,3,17:5)
Block(-4,20,4,159:13)
Block(-4,20,5,159:13)
Block(-4,20,6,AIR)
Block(-4,20,7,AIR)
Block(-4,20,8,164)
Block(-4,21,-7,126:5)
Block(-4,21,-6,159:13)
Block(-4,21,-5,159:13)
Block(-4,21,-4,47)
Block(-4,21,-3,171:12)
Block(-4,21,-2,171:12)
Block(-4,21,-1,171:12)
Block(-4,21,0,134:2)
Block(-4,21,1,124)
Block(-4,21,2,159:13)
Block(-4,21,3,159:13)
Block(-4,21,4,159:13)
Block(-4,21,5,AIR)
Block(-4,21,6,AIR)
Block(-4,21,7,AIR)
Block(-4,21,8,AIR)
Block(-4,22,-6,AIR)
Block(-4,22,-5,159:13)
Block(-4,22,-4,AIR)
Block(-4,22,-3,AIR)
Block(-4,22,-2,AIR)
Block(-4,22,-1,AIR)
Block(-4,22,0,AIR)
Block(-4,22,1,AIR)
Block(-4,22,2,159:13)
Block(-4,22,3,159:13)
Block(-4,22,4,AIR)
Block(-4,22,5,AIR)
Block(-4,22,6,AIR)
Block(-4,22,7,AIR)
Block(-4,22,8,AIR)
Block(-4,23,-6,AIR)
Block(-4,23,-5,AIR)
Block(-4,23,-4,159:13)
Block(-4,23,-3,AIR)
Block(-4,23,-2,AIR)
Block(-4,23,-1,AIR)
Block(-4,23,0,AIR)
Block(-4,23,1,AIR)
Block(-4,23,2,159:13)
Block(-4,23,3,AIR)
Block(-4,23,4,AIR)
Block(-4,23,5,AIR)
Block(-4,23,6,AIR)
Block(-4,23,7,AIR)
Block(-4,23,8,AIR)
Block(-4,24,-6,AIR)
Block(-4,24,-5,AIR)
Block(-4,24,-4,159:13)
Block(-4,24,-3,159:13)
Block(-4,24,-2,AIR)
Block(-4,24,-1,AIR)
Block(-4,24,0,AIR)
Block(-4,24,1,159:13)
Block(-4,24,2,159:13)
Block(-4,24,3,AIR)
Block(-4,24,4,AIR)
Block(-4,24,5,AIR)
Block(-4,24,6,AIR)
Block(-4,24,7,AIR)
Block(-4,24,8,AIR)
Block(-4,25,-6,AIR)
Block(-4,25,-5,AIR)
Block(-4,25,-4,AIR)
Block(-4,25,-3,AIR)
Block(-4,25,-2,159:13)
Block(-4,25,-1,AIR)
Block(-4,25,0,159:13)
Block(-4,25,1,AIR)
Block(-4,25,2,AIR)
Block(-4,25,3,AIR)
Block(-4,25,4,AIR)
Block(-4,25,5,AIR)
Block(-4,25,6,AIR)
Block(-4,25,7,AIR)
Block(-4,25,8,AIR)
Block(-4,26,-6,AIR)
Block(-4,26,-5,AIR)
Block(-4,26,-4,AIR)
Block(-4,26,-3,AIR)
Block(-4,26,-2,AIR)
Block(-4,26,-1,5:5)
Block(-4,26,0,AIR)
Block(-4,26,1,AIR)
Block(-4,26,2,AIR)
Block(-4,26,3,AIR)
Block(-4,26,4,AIR)
Block(-4,26,5,AIR)
Block(-4,26,6,AIR)
Block(-4,26,7,AIR)
Block(-4,26,8,AIR)
Block(-4,27,-1,126:5)
Block(-4,28,-2,216:8)
Block(-4,28,-1,216:8)
Block(-4,28,0,216:8)
Block(-4,29,-2,216:8)
Block(-4,29,-1,216:8)
Block(-4,29,0,216:8)
Block(-4,30,-1,216:8)
Block(-3,0,8,17:1)
Block(-3,1,8,17:1)
Block(-3,2,8,17:1)
Block(-3,3,8,17:1)
Block(-3,4,8,17:1)
Block(-3,5,8,17:1)
Block(-3,6,8,17:1)
Block(-3,7,8,17:1)
Block(-3,8,8,17:1)
Block(-3,9,8,17:1)
Block(-3,10,8,17:1)
Block(-3,11,8,17:1)
Block(-3,12,8,17:1)
Block(-3,13,8,17:1)
Block(-3,14,8,17:1)
Block(-3,15,-6,17:5)
Block(-3,15,-5,5:1)
Block(-3,15,-4,5:1)
Block(-3,15,-3,5:1)
Block(-3,15,-2,5:1)
Block(-3,15,-1,5:1)
Block(-3,15,0,5:1)
Block(-3,15,1,5:1)
Block(-3,15,2,5:1)
Block(-3,15,3,17:5)
Block(-3,15,4,17:9)
Block(-3,15,5,17:9)
Block(-3,15,6,17:9)
Block(-3,15,7,17:9)
Block(-3,15,8,17:1)
Block(-3,16,-6,134:6)
Block(-3,16,-5,134:7)
Block(-3,16,-4,AIR)
Block(-3,16,-3,AIR)
Block(-3,16,-2,AIR)
Block(-3,16,-1,AIR)
Block(-3,16,0,AIR)
Block(-3,16,1,AIR)
Block(-3,16,2,191)
Block(-3,16,3,17:1)
Block(-3,16,4,134:4)
Block(-3,16,5,134:4)
Block(-3,16,6,134:4)
Block(-3,16,7,134:4)
Block(-3,16,8,17:1)
Block(-3,17,-6,134:2)
Block(-3,17,-5,5:1)
Block(-3,17,-4,AIR)
Block(-3,17,-3,AIR)
Block(-3,17,-2,AIR)
Block(-3,17,-1,AIR)
Block(-3,17,0,AIR)
Block(-3,17,1,AIR)
Block(-3,17,2,191)
Block(-3,17,3,17:1)
Block(-3,17,4,134)
Block(-3,17,5,134)
Block(-3,17,6,134)
Block(-3,17,7,134)
Block(-3,17,8,17:1)
Block(-3,18,-6,134:6)
Block(-3,18,-5,134:3)
Block(-3,18,-4,AIR)
Block(-3,18,-3,AIR)
Block(-3,18,-2,AIR)
Block(-3,18,-1,AIR)
Block(-3,18,0,AIR)
Block(-3,18,1,AIR)
Block(-3,18,2,56)
Block(-3,18,3,17:1)
Block(-3,18,4,134:4)
Block(-3,18,5,134:4)
Block(-3,18,6,134:4)
Block(-3,18,7,134:4)
Block(-3,18,8,17:1)
Block(-3,19,-6,134:6)
Block(-3,19,-5,AIR)
Block(-3,19,-4,AIR)
Block(-3,19,-3,AIR)
Block(-3,19,-2,AIR)
Block(-3,19,-1,AIR)
Block(-3,19,0,AIR)
Block(-3,19,1,AIR)
Block(-3,19,2,AIR)
Block(-3,19,3,17:1)
Block(-3,19,4,134:4)
Block(-3,19,5,134:4)
Block(-3,19,6,134:4)
Block(-3,19,7,134:4)
Block(-3,19,8,17:1)
Block(-3,20,-7,126:13)
Block(-3,20,-6,17:5)
Block(-3,20,-5,5:1)
Block(-3,20,-4,5:1)
Block(-3,20,-3,5:1)
Block(-3,20,-2,5:1)
Block(-3,20,-1,5:1)
Block(-3,20,0,5:1)
Block(-3,20,1,5:1)
Block(-3,20,2,5:1)
Block(-3,20,3,5:1)
Block(-3,20,4,159:13)
Block(-3,20,5,159:13)
Block(-3,20,6,159:13)
Block(-3,20,7,159:13)
Block(-3,20,8,17:1)
Block(-3,21,-7,5:5)
Block(-3,21,-6,159:13)
Block(-3,21,-5,159:13)
Block(-3,21,-4,54:3)
Block(-3,21,-3,171:12)
Block(-3,21,-2,171:12)
Block(-3,21,-1,171:12)
Block(-3,21,0,134:2)
Block(-3,21,1,5:1)
Block(-3,21,2,159:13)
Block(-3,21,3,159:13)
Block(-3,21,4,159:13)
Block(-3,21,5,AIR)
Block(-3,21,6,AIR)
Block(-3,21,7,AIR)
Block(-3,21,8,164)
Block(-3,22,-6,AIR)
Block(-3,22,-5,159:13)
Block(-3,22,-4,AIR)
Block(-3,22,-3,AIR)
Block(-3,22,-2,AIR)
Block(-3,22,-1,AIR)
Block(-3,22,0,AIR)
Block(-3,22,1,134:2)
Block(-3,22,2,159:13)
Block(-3,22,3,159:13)
Block(-3,22,4,AIR)
Block(-3,22,5,AIR)
Block(-3,22,6,AIR)
Block(-3,22,7,AIR)
Block(-3,22,8,AIR)
Block(-3,23,-6,AIR)
Block(-3,23,-5,191)
Block(-3,23,-4,159:13)
Block(-3,23,-3,AIR)
Block(-3,23,-2,AIR)
Block(-3,23,-1,AIR)
Block(-3,23,0,AIR)
Block(-3,23,1,134:6)
Block(-3,23,2,159:13)
Block(-3,23,3,191)
Block(-3,23,4,AIR)
Block(-3,23,5,AIR)
Block(-3,23,6,AIR)
Block(-3,23,7,AIR)
Block(-3,23,8,AIR)
Block(-3,24,-6,AIR)
Block(-3,24,-5,191)
Block(-3,24,-4,159:13)
Block(-3,24,-3,159:13)
Block(-3,24,-2,AIR)
Block(-3,24,-1,AIR)
Block(-3,24,0,AIR)
Block(-3,24,1,159:13)
Block(-3,24,2,159:13)
Block(-3,24,3,191)
Block(-3,24,4,AIR)
Block(-3,24,5,AIR)
Block(-3,24,6,AIR)
Block(-3,24,7,AIR)
Block(-3,24,8,AIR)
Block(-3,25,-6,AIR)
Block(-3,25,-5,191)
Block(-3,25,-4,191)
Block(-3,25,-3,AIR)
Block(-3,25,-2,159:13)
Block(-3,25,-1,AIR)
Block(-3,25,0,159:13)
Block(-3,25,1,AIR)
Block(-3,25,2,AIR)
Block(-3,25,3,191)
Block(-3,25,4,AIR)
Block(-3,25,5,AIR)
Block(-3,25,6,AIR)
Block(-3,25,7,AIR)
Block(-3,25,8,AIR)
Block(-3,26,-6,AIR)
Block(-3,26,-5,191)
Block(-3,26,-4,AIR)
Block(-3,26,-3,AIR)
Block(-3,26,-2,AIR)
Block(-3,26,-1,5:5)
Block(-3,26,0,AIR)
Block(-3,26,1,AIR)
Block(-3,26,2,AIR)
Block(-3,26,3,191)
Block(-3,26,4,AIR)
Block(-3,26,5,AIR)
Block(-3,26,6,AIR)
Block(-3,26,7,AIR)
Block(-3,26,8,AIR)
Block(-3,27,-5,35:15)
Block(-3,27,-1,126:5)
Block(-3,27,3,35:15)
Block(-3,28,-5,191)
Block(-3,28,-4,35:15)
Block(-3,28,-2,216:8)
Block(-3,28,-1,216:8)
Block(-3,28,0,216:8)
Block(-3,28,2,35:15)
Block(-3,28,3,191)
Block(-3,29,-4,191)
Block(-3,29,-3,35:15)
Block(-3,29,-2,216:8)
Block(-3,29,-1,216:8)
Block(-3,29,0,216:8)
Block(-3,29,1,35:15)
Block(-3,29,2,191)
Block(-3,30,-3,191)
Block(-3,30,-2,35:15)
Block(-3,30,-1,216:8)
Block(-3,30,0,35:15)
Block(-3,30,1,191)
Block(-3,31,-2,191)
Block(-3,31,-1,35:15)
Block(-3,31,0,191)
Block(-3,32,-1,191)
Block(-2,0,3,17:1)
Block(-2,1,3,17:1)
Block(-2,2,3,17:1)
Block(-2,3,3,17:1)
Block(-2,4,3,17:1)
Block(-2,5,3,17:1)
Block(-2,6,3,17:1)
Block(-2,7,3,17:1)
Block(-2,8,3,17:1)
Block(-2,9,3,17:1)
Block(-2,10,3,17:1)
Block(-2,11,3,17:1)
Block(-2,12,3,17:1)
Block(-2,13,3,17:1)
Block(-2,14,3,17:1)
Block(-2,15,-6,17:5)
Block(-2,15,-5,5:1)
Block(-2,15,-4,5:1)
Block(-2,15,-3,5:1)
Block(-2,15,-2,5:1)
Block(-2,15,-1,5:1)
Block(-2,15,0,5:1)
Block(-2,15,1,5:1)
Block(-2,15,2,5:1)
Block(-2,15,3,17:5)
Block(-2,15,4,5:1)
Block(-2,15,5,5:1)
Block(-2,15,6,5:1)
Block(-2,15,7,5:1)
Block(-2,15,8,17:5)
Block(-2,16,-6,134:6)
Block(-2,16,-5,134:7)
Block(-2,16,-4,AIR)
Block(-2,16,-3,AIR)
Block(-2,16,-2,AIR)
Block(-2,16,-1,AIR)
Block(-2,16,0,AIR)
Block(-2,16,1,AIR)
Block(-2,16,2,134:2)
Block(-2,16,3,AIR)
Block(-2,16,4,AIR)
Block(-2,16,5,AIR)
Block(-2,16,6,AIR)
Block(-2,16,7,191)
Block(-2,16,8,134:7)
Block(-2,17,-6,AIR)
Block(-2,17,-5,160:9)
Block(-2,17,-4,AIR)
Block(-2,17,-3,AIR)
Block(-2,17,-2,AIR)
Block(-2,17,-1,AIR)
Block(-2,17,0,AIR)
Block(-2,17,1,AIR)
Block(-2,17,2,134:6)
Block(-2,17,3,AIR)
Block(-2,17,4,AIR)
Block(-2,17,5,AIR)
Block(-2,17,6,AIR)
Block(-2,17,7,191)
Block(-2,17,8,134:3)
Block(-2,18,-6,134:6)
Block(-2,18,-5,134:3)
Block(-2,18,-4,AIR)
Block(-2,18,-3,AIR)
Block(-2,18,-2,AIR)
Block(-2,18,-1,AIR)
Block(-2,18,0,AIR)
Block(-2,18,1,AIR)
Block(-2,18,2,134:2)
Block(-2,18,3,AIR)
Block(-2,18,4,AIR)
Block(-2,18,5,AIR)
Block(-2,18,6,AIR)
Block(-2,18,7,56)
Block(-2,18,8,134:7)
Block(-2,19,-6,134:6)
Block(-2,19,-5,AIR)
Block(-2,19,-4,AIR)
Block(-2,19,-3,AIR)
Block(-2,19,-2,AIR)
Block(-2,19,-1,AIR)
Block(-2,19,0,AIR)
Block(-2,19,1,AIR)
Block(-2,19,2,AIR)
Block(-2,19,3,5:1)
Block(-2,19,4,AIR)
Block(-2,19,5,AIR)
Block(-2,19,6,AIR)
Block(-2,19,7,AIR)
Block(-2,19,8,134:7)
Block(-2,20,-7,126:13)
Block(-2,20,-6,17:5)
Block(-2,20,-5,5:1)
Block(-2,20,-4,5:1)
Block(-2,20,-3,5:1)
Block(-2,20,-2,5:1)
Block(-2,20,-1,5:1)
Block(-2,20,0,5:1)
Block(-2,20,1,5:1)
Block(-2,20,2,5:1)
Block(-2,20,3,5:1)
Block(-2,20,4,5:1)
Block(-2,20,5,5:1)
Block(-2,20,6,5:1)
Block(-2,20,7,5:1)
Block(-2,20,8,17:5)
Block(-2,21,-7,5:5)
Block(-2,21,-6,159:13)
Block(-2,21,-5,159:13)
Block(-2,21,-4,AIR)
Block(-2,21,-3,171:12)
Block(-2,21,-2,171:12)
Block(-2,21,-1,171:12)
Block(-2,21,0,134:2)
Block(-2,21,1,5:1)
Block(-2,21,2,159:13)
Block(-2,21,3,159:13)
Block(-2,21,4,159:13)
Block(-2,21,5,159:13)
Block(-2,21,6,159:13)
Block(-2,21,7,159:13)
Block(-2,21,8,164:7)
Block(-2,22,-6,AIR)
Block(-2,22,-5,159:13)
Block(-2,22,-4,AIR)
Block(-2,22,-3,AIR)
Block(-2,22,-2,AIR)
Block(-2,22,-1,AIR)
Block(-2,22,0,AIR)
Block(-2,22,1,134:2)
Block(-2,22,2,159:13)
Block(-2,22,3,159:13)
Block(-2,22,4,159:13)
Block(-2,22,5,AIR)
Block(-2,22,6,AIR)
Block(-2,22,7,AIR)
Block(-2,22,8,164)
Block(-2,23,-6,AIR)
Block(-2,23,-5,159:13)
Block(-2,23,-4,159:13)
Block(-2,23,-3,AIR)
Block(-2,23,-2,AIR)
Block(-2,23,-1,AIR)
Block(-2,23,0,AIR)
Block(-2,23,1,134:6)
Block(-2,23,2,159:13)
Block(-2,23,3,159:13)
Block(-2,23,4,AIR)
Block(-2,23,5,AIR)
Block(-2,23,6,AIR)
Block(-2,23,7,AIR)
Block(-2,23,8,AIR)
Block(-2,24,-6,AIR)
Block(-2,24,-5,AIR)
Block(-2,24,-4,159:13)
Block(-2,24,-3,159:13)
Block(-2,24,-2,AIR)
Block(-2,24,-1,AIR)
Block(-2,24,0,AIR)
Block(-2,24,1,159:13)
Block(-2,24,2,159:13)
Block(-2,24,3,AIR)
Block(-2,24,4,AIR)
Block(-2,24,5,AIR)
Block(-2,24,6,AIR)
Block(-2,24,7,AIR)
Block(-2,24,8,AIR)
Block(-2,25,-6,AIR)
Block(-2,25,-5,AIR)
Block(-2,25,-4,AIR)
Block(-2,25,-3,AIR)
Block(-2,25,-2,159:13)
Block(-2,25,-1,AIR)
Block(-2,25,0,159:13)
Block(-2,25,1,AIR)
Block(-2,25,2,AIR)
Block(-2,25,3,AIR)
Block(-2,25,4,AIR)
Block(-2,25,5,AIR)
Block(-2,25,6,AIR)
Block(-2,25,7,AIR)
Block(-2,25,8,AIR)
Block(-2,26,-6,AIR)
Block(-2,26,-5,AIR)
Block(-2,26,-4,AIR)
Block(-2,26,-3,AIR)
Block(-2,26,-2,AIR)
Block(-2,26,-1,5:5)
Block(-2,26,0,AIR)
Block(-2,26,1,AIR)
Block(-2,26,2,AIR)
Block(-2,26,3,AIR)
Block(-2,26,4,AIR)
Block(-2,26,5,AIR)
Block(-2,26,6,AIR)
Block(-2,26,7,AIR)
Block(-2,26,8,AIR)
Block(-2,27,-1,5:5)
Block(-2,28,-2,216:8)
Block(-2,28,-1,216:8)
Block(-2,28,0,216:8)
Block(-2,29,-2,216:8)
Block(-2,29,-1,216:8)
Block(-2,29,0,216:8)
Block(-2,30,-1,216:8)
Block(-1,15,-6,17:5)
Block(-1,15,-5,5:1)
Block(-1,15,-4,5:1)
Block(-1,15,-3,5:1)
Block(-1,15,-2,5:1)
Block(-1,15,-1,5:1)
Block(-1,15,0,5:1)
Block(-1,15,1,5:1)
Block(-1,15,2,5:1)
Block(-1,15,3,17:5)
Block(-1,15,4,5:1)
Block(-1,15,5,5:1)
Block(-1,15,6,5:1)
Block(-1,15,7,5:1)
Block(-1,15,8,17:5)
Block(-1,16,-6,134:6)
Block(-1,16,-5,134:7)
Block(-1,16,-4,AIR)
Block(-1,16,-3,AIR)
Block(-1,16,-2,133)
Block(-1,16,-1,AIR)
Block(-1,16,0,133)
Block(-1,16,1,AIR)
Block(-1,16,2,AIR)
Block(-1,16,3,AIR)
Block(-1,16,4,AIR)
Block(-1,16,5,AIR)
Block(-1,16,6,AIR)
Block(-1,16,7,134:6)
Block(-1,16,8,134:7)
Block(-1,17,-6,AIR)
Block(-1,17,-5,160:9)
Block(-1,17,-4,AIR)
Block(-1,17,-3,AIR)
Block(-1,17,-2,AIR)
Block(-1,17,-1,AIR)
Block(-1,17,0,AIR)
Block(-1,17,1,AIR)
Block(-1,17,2,AIR)
Block(-1,17,3,AIR)
Block(-1,17,4,AIR)
Block(-1,17,5,AIR)
Block(-1,17,6,AIR)
Block(-1,17,7,5:1)
Block(-1,17,8,134:3)
Block(-1,18,-6,134:6)
Block(-1,18,-5,134:3)
Block(-1,18,-4,AIR)
Block(-1,18,-3,AIR)
Block(-1,18,-2,AIR)
Block(-1,18,-1,AIR)
Block(-1,18,0,AIR)
Block(-1,18,1,AIR)
Block(-1,18,2,134:2)
Block(-1,18,3,AIR)
Block(-1,18,4,AIR)
Block(-1,18,5,AIR)
Block(-1,18,6,AIR)
Block(-1,18,7,134:2)
Block(-1,18,8,134:7)
Block(-1,19,-6,134:6)
Block(-1,19,-5,AIR)
Block(-1,19,-4,AIR)
Block(-1,19,-3,AIR)
Block(-1,19,-2,AIR)
Block(-1,19,-1,AIR)
Block(-1,19,0,AIR)
Block(-1,19,1,AIR)
Block(-1,19,2,AIR)
Block(-1,19,3,5:1)
Block(-1,19,4,AIR)
Block(-1,19,5,AIR)
Block(-1,19,6,AIR)
Block(-1,19,7,AIR)
Block(-1,19,8,134:7)
Block(-1,20,-6,17:5)
Block(-1,20,-5,5:1)
Block(-1,20,-4,5:1)
Block(-1,20,-3,5:1)
Block(-1,20,-2,5:1)
Block(-1,20,-1,5:1)
Block(-1,20,0,5:1)
Block(-1,20,1,5:1)
Block(-1,20,2,5:1)
Block(-1,20,3,5:1)
Block(-1,20,4,5:1)
Block(-1,20,5,5:1)
Block(-1,20,6,5:1)
Block(-1,20,7,5:1)
Block(-1,20,8,17:5)
Block(-1,21,-7,5:5)
Block(-1,21,-6,159:13)
Block(-1,21,-5,159:13)
Block(-1,21,-4,AIR)
Block(-1,21,-3,171:12)
Block(-1,21,-2,171:12)
Block(-1,21,-1,171:12)
Block(-1,21,0,134:2)
Block(-1,21,1,5:1)
Block(-1,21,2,159:13)
Block(-1,21,3,159:13)
Block(-1,21,4,159:13)
Block(-1,21,5,159:13)
Block(-1,21,6,159:13)
Block(-1,21,7,5:1)
Block(-1,21,8,AIR)
Block(-1,22,-6,AIR)
Block(-1,22,-5,159:13)
Block(-1,22,-4,AIR)
Block(-1,22,-3,AIR)
Block(-1,22,-2,AIR)
Block(-1,22,-1,AIR)
Block(-1,22,0,AIR)
Block(-1,22,1,134:2)
Block(-1,22,2,159:13)
Block(-1,22,3,159:13)
Block(-1,22,4,159:13)
Block(-1,22,5,159:13)
Block(-1,22,6,159:13)
Block(-1,22,7,159:13)
Block(-1,22,8,164:7)
Block(-1,23,-6,AIR)
Block(-1,23,-5,159:13)
Block(-1,23,-4,159:13)
Block(-1,23,-3,AIR)
Block(-1,23,-2,AIR)
Block(-1,23,-1,AIR)
Block(-1,23,0,AIR)
Block(-1,23,1,134:6)
Block(-1,23,2,159:13)
Block(-1,23,3,159:13)
Block(-1,23,4,AIR)
Block(-1,23,5,AIR)
Block(-1,23,6,AIR)
Block(-1,23,7,AIR)
Block(-1,23,8,164)
Block(-1,24,-6,AIR)
Block(-1,24,-5,AIR)
Block(-1,24,-4,159:13)
Block(-1,24,-3,159:13)
Block(-1,24,-2,AIR)
Block(-1,24,-1,AIR)
Block(-1,24,0,AIR)
Block(-1,24,1,159:13)
Block(-1,24,2,159:13)
Block(-1,24,3,AIR)
Block(-1,24,4,AIR)
Block(-1,24,5,AIR)
Block(-1,24,6,AIR)
Block(-1,24,7,AIR)
Block(-1,24,8,164:3)
Block(-1,25,-6,AIR)
Block(-1,25,-5,AIR)
Block(-1,25,-4,AIR)
Block(-1,25,-3,AIR)
Block(-1,25,-2,159:13)
Block(-1,25,-1,AIR)
Block(-1,25,0,159:13)
Block(-1,25,1,AIR)
Block(-1,25,2,AIR)
Block(-1,25,3,AIR)
Block(-1,25,4,AIR)
Block(-1,25,5,AIR)
Block(-1,25,6,AIR)
Block(-1,25,7,AIR)
Block(-1,25,8,AIR)
Block(-1,26,-6,AIR)
Block(-1,26,-5,AIR)
Block(-1,26,-4,AIR)
Block(-1,26,-3,AIR)
Block(-1,26,-2,AIR)
Block(-1,26,-1,5:5)
Block(-1,26,0,AIR)
Block(-1,26,1,AIR)
Block(-1,26,2,AIR)
Block(-1,26,3,AIR)
Block(-1,26,4,AIR)
Block(-1,26,5,AIR)
Block(-1,26,6,AIR)
Block(-1,26,7,AIR)
Block(-1,26,8,AIR)
Block(-1,27,-1,5:5)
Block(-1,28,-2,216:8)
Block(-1,28,-1,216:8)
Block(-1,28,0,216:8)
Block(-1,29,-2,216:8)
Block(-1,29,-1,216:8)
Block(-1,29,0,216:8)
Block(-1,30,-1,216:8)
Block(0,15,-6,17:5)
Block(0,15,-5,5:1)
Block(0,15,-4,5:1)
Block(0,15,-3,5:1)
Block(0,15,-2,5:1)
Block(0,15,-1,5:1)
Block(0,15,0,5:1)
Block(0,15,1,5:1)
Block(0,15,2,5:1)
Block(0,15,3,17:5)
Block(0,15,4,5:1)
Block(0,15,5,5:1)
Block(0,15,6,5:1)
Block(0,15,7,5:1)
Block(0,15,8,17:5)
Block(0,16,-6,134:6)
Block(0,16,-5,134:7)
Block(0,16,-4,AIR)
Block(0,16,-3,AIR)
Block(0,16,-2,AIR)
Block(0,16,-1,AIR)
Block(0,16,0,AIR)
Block(0,16,1,AIR)
Block(0,16,2,134:2)
Block(0,16,3,AIR)
Block(0,16,4,AIR)
Block(0,16,5,AIR)
Block(0,16,6,AIR)
Block(0,16,7,134:6)
Block(0,16,8,134:7)
Block(0,17,-6,AIR)
Block(0,17,-5,160:9)
Block(0,17,-4,AIR)
Block(0,17,-3,AIR)
Block(0,17,-2,AIR)
Block(0,17,-1,AIR)
Block(0,17,0,AIR)
Block(0,17,1,AIR)
Block(0,17,2,134:6)
Block(0,17,3,AIR)
Block(0,17,4,AIR)
Block(0,17,5,AIR)
Block(0,17,6,AIR)
Block(0,17,7,160:9)
Block(0,17,8,AIR)
Block(0,18,-6,134:6)
Block(0,18,-5,134:3)
Block(0,18,-4,AIR)
Block(0,18,-3,AIR)
Block(0,18,-2,AIR)
Block(0,18,-1,AIR)
Block(0,18,0,AIR)
Block(0,18,1,AIR)
Block(0,18,2,134:2)
Block(0,18,3,AIR)
Block(0,18,4,AIR)
Block(0,18,5,AIR)
Block(0,18,6,AIR)
Block(0,18,7,134:2)
Block(0,18,8,134:7)
Block(0,19,-6,134:6)
Block(0,19,-5,AIR)
Block(0,19,-4,AIR)
Block(0,19,-3,AIR)
Block(0,19,-2,AIR)
Block(0,19,-1,AIR)
Block(0,19,0,AIR)
Block(0,19,1,AIR)
Block(0,19,2,AIR)
Block(0,19,3,5:1)
Block(0,19,4,AIR)
Block(0,19,5,AIR)
Block(0,19,6,AIR)
Block(0,19,7,AIR)
Block(0,19,8,134:7)
Block(0,20,-6,17:5)
Block(0,20,-5,5:1)
Block(0,20,-4,5:1)
Block(0,20,-3,5:1)
Block(0,20,-2,5:1)
Block(0,20,-1,5:1)
Block(0,20,0,5:1)
Block(0,20,1,5:1)
Block(0,20,2,5:1)
Block(0,20,3,5:1)
Block(0,20,4,5:1)
Block(0,20,5,5:1)
Block(0,20,6,5:1)
Block(0,20,7,5:1)
Block(0,20,8,17:5)
Block(0,21,-7,5:5)
Block(0,21,-6,159:13)
Block(0,21,-5,159:13)
Block(0,21,-4,159:13)
Block(0,21,-3,171:12)
Block(0,21,-2,41)
Block(0,21,-1,171:12)
Block(0,21,0,171:12)
Block(0,21,1,171:12)
Block(0,21,2,171:12)
Block(0,21,3,171:12)
Block(0,21,4,171:12)
Block(0,21,5,171:12)
Block(0,21,6,171:12)
Block(0,21,7,126:1)
Block(0,21,8,AIR)
Block(0,22,-7,126:5)
Block(0,22,-6,159:13)
Block(0,22,-5,159:13)
Block(0,22,-4,159:13)
Block(0,22,-3,AIR)
Block(0,22,-2,AIR)
Block(0,22,-1,AIR)
Block(0,22,0,AIR)
Block(0,22,1,AIR)
Block(0,22,2,AIR)
Block(0,22,3,AIR)
Block(0,22,4,AIR)
Block(0,22,5,AIR)
Block(0,22,6,AIR)
Block(0,22,7,5:1)
Block(0,22,8,AIR)
Block(0,23,-6,AIR)
Block(0,23,-5,159:13)
Block(0,23,-4,159:13)
Block(0,23,-3,AIR)
Block(0,23,-2,AIR)
Block(0,23,-1,AIR)
Block(0,23,0,AIR)
Block(0,23,1,134:6)
Block(0,23,2,159:13)
Block(0,23,3,159:13)
Block(0,23,4,159:13)
Block(0,23,5,159:13)
Block(0,23,6,159:13)
Block(0,23,7,159:13)
Block(0,23,8,5:5)
Block(0,24,-6,AIR)
Block(0,24,-5,AIR)
Block(0,24,-4,159:13)
Block(0,24,-3,159:13)
Block(0,24,-2,AIR)
Block(0,24,-1,AIR)
Block(0,24,0,AIR)
Block(0,24,1,159:13)
Block(0,24,2,159:13)
Block(0,24,3,AIR)
Block(0,24,4,AIR)
Block(0,24,5,AIR)
Block(0,24,6,AIR)
Block(0,24,7,AIR)
Block(0,24,8,AIR)
Block(0,25,-6,AIR)
Block(0,25,-5,AIR)
Block(0,25,-4,AIR)
Block(0,25,-3,159:13)
Block(0,25,-2,159:13)
Block(0,25,-1,50:2)
Block(0,25,0,159:13)
Block(0,25,1,159:13)
Block(0,25,2,AIR)
Block(0,25,3,AIR)
Block(0,25,4,AIR)
Block(0,25,5,AIR)
Block(0,25,6,AIR)
Block(0,25,7,AIR)
Block(0,25,8,AIR)
Block(0,26,-6,AIR)
Block(0,26,-5,AIR)
Block(0,26,-4,AIR)
Block(0,26,-3,AIR)
Block(0,26,-2,AIR)
Block(0,26,-1,5:5)
Block(0,26,0,AIR)
Block(0,26,1,AIR)
Block(0,26,2,AIR)
Block(0,26,3,AIR)
Block(0,26,4,AIR)
Block(0,26,5,AIR)
Block(0,26,6,AIR)
Block(0,26,7,AIR)
Block(0,26,8,AIR)
Block(0,27,-1,5:5)
Block(0,28,-1,216:8)
Block(0,29,-2,216:8)
Block(0,29,-1,216:8)
Block(0,29,0,216:8)
Block(0,30,-2,216:8)
Block(0,30,-1,216:8)
Block(0,30,0,216:8)
Block(0,31,-1,216:8)
Block(1,15,-6,17:5)
Block(1,15,-5,5:1)
Block(1,15,-4,5:1)
Block(1,15,-3,5:1)
Block(1,15,-2,5:1)
Block(1,15,-1,5:1)
Block(1,15,0,5:1)
Block(1,15,1,5:1)
Block(1,15,2,5:1)
Block(1,15,3,17:5)
Block(1,15,4,5:1)
Block(1,15,5,5:1)
Block(1,15,6,5:1)
Block(1,15,7,5:1)
Block(1,15,8,17:5)
Block(1,16,-6,134:6)
Block(1,16,-5,134:7)
Block(1,16,-4,AIR)
Block(1,16,-3,AIR)
Block(1,16,-2,AIR)
Block(1,16,-1,AIR)
Block(1,16,0,AIR)
Block(1,16,1,AIR)
Block(1,16,2,134:2)
Block(1,16,3,AIR)
Block(1,16,4,26:3)
Block(1,16,5,26:3)
Block(1,16,6,AIR)
Block(1,16,7,134:6)
Block(1,16,8,134:7)
Block(1,17,-6,134:2)
Block(1,17,-5,5:1)
Block(1,17,-4,AIR)
Block(1,17,-3,AIR)
Block(1,17,-2,AIR)
Block(1,17,-1,AIR)
Block(1,17,0,AIR)
Block(1,17,1,AIR)
Block(1,17,2,134:6)
Block(1,17,3,AIR)
Block(1,17,4,AIR)
Block(1,17,5,AIR)
Block(1,17,6,AIR)
Block(1,17,7,5:1)
Block(1,17,8,134:3)
Block(1,18,-6,134:6)
Block(1,18,-5,134:3)
Block(1,18,-4,AIR)
Block(1,18,-3,AIR)
Block(1,18,-2,AIR)
Block(1,18,-1,AIR)
Block(1,18,0,AIR)
Block(1,18,1,AIR)
Block(1,18,2,134:2)
Block(1,18,3,AIR)
Block(1,18,4,AIR)
Block(1,18,5,AIR)
Block(1,18,6,AIR)
Block(1,18,7,134:2)
Block(1,18,8,134:7)
Block(1,19,-6,134:6)
Block(1,19,-5,AIR)
Block(1,19,-4,AIR)
Block(1,19,-3,AIR)
Block(1,19,-2,AIR)
Block(1,19,-1,AIR)
Block(1,19,0,AIR)
Block(1,19,1,AIR)
Block(1,19,2,AIR)
Block(1,19,3,5:1)
Block(1,19,4,AIR)
Block(1,19,5,AIR)
Block(1,19,6,AIR)
Block(1,19,7,AIR)
Block(1,19,8,134:7)
Block(1,20,-6,17:5)
Block(1,20,-5,5:1)
Block(1,20,-4,5:1)
Block(1,20,-3,5:1)
Block(1,20,-2,5:1)
Block(1,20,-1,5:1)
Block(1,20,0,5:1)
Block(1,20,1,5:1)
Block(1,20,2,5:1)
Block(1,20,3,5:1)
Block(1,20,4,5:1)
Block(1,20,5,5:1)
Block(1,20,6,5:1)
Block(1,20,7,5:1)
Block(1,20,8,17:5)
Block(1,21,-7,126:13)
Block(1,21,-6,159:13)
Block(1,21,-5,159:13)
Block(1,21,-4,159:13)
Block(1,21,-3,159:13)
Block(1,21,-2,159:13)
Block(1,21,-1,159:13)
Block(1,21,0,159:13)
Block(1,21,1,159:13)
Block(1,21,2,159:13)
Block(1,21,3,159:13)
Block(1,21,4,159:13)
Block(1,21,5,159:13)
Block(1,21,6,159:13)
Block(1,21,7,5:1)
Block(1,21,8,AIR)
Block(1,22,-7,126:5)
Block(1,22,-6,159:13)
Block(1,22,-5,159:13)
Block(1,22,-4,134:5)
Block(1,22,-3,134:5)
Block(1,22,-2,134:5)
Block(1,22,-1,134:5)
Block(1,22,0,134:5)
Block(1,22,1,134:5)
Block(1,22,2,134:5)
Block(1,22,3,159:13)
Block(1,22,4,159:13)
Block(1,22,5,159:13)
Block(1,22,6,159:13)
Block(1,22,7,159:13)
Block(1,22,8,164:7)
Block(1,23,-6,AIR)
Block(1,23,-5,159:13)
Block(1,23,-4,5:1)
Block(1,23,-3,5:1)
Block(1,23,-2,134:3)
Block(1,23,-1,AIR)
Block(1,23,0,134:2)
Block(1,23,1,5:1)
Block(1,23,2,5:1)
Block(1,23,3,159:13)
Block(1,23,4,AIR)
Block(1,23,5,AIR)
Block(1,23,6,AIR)
Block(1,23,7,AIR)
Block(1,23,8,164:3)
Block(1,24,-6,AIR)
Block(1,24,-5,AIR)
Block(1,24,-4,159:13)
Block(1,24,-3,5:1)
Block(1,24,-2,134:7)
Block(1,24,-1,AIR)
Block(1,24,0,134:6)
Block(1,24,1,5:1)
Block(1,24,2,159:13)
Block(1,24,3,AIR)
Block(1,24,4,AIR)
Block(1,24,5,AIR)
Block(1,24,6,AIR)
Block(1,24,7,AIR)
Block(1,24,8,164)
Block(1,25,-6,AIR)
Block(1,25,-5,AIR)
Block(1,25,-4,AIR)
Block(1,25,-3,159:13)
Block(1,25,-2,159:13)
Block(1,25,-1,5:1)
Block(1,25,0,159:13)
Block(1,25,1,159:13)
Block(1,25,2,AIR)
Block(1,25,3,AIR)
Block(1,25,4,AIR)
Block(1,25,5,AIR)
Block(1,25,6,AIR)
Block(1,25,7,AIR)
Block(1,25,8,AIR)
Block(1,26,-6,AIR)
Block(1,26,-5,AIR)
Block(1,26,-4,AIR)
Block(1,26,-3,AIR)
Block(1,26,-2,AIR)
Block(1,26,-1,5:5)
Block(1,26,0,AIR)
Block(1,26,1,AIR)
Block(1,26,2,AIR)
Block(1,26,3,AIR)
Block(1,26,4,AIR)
Block(1,26,5,AIR)
Block(1,26,6,AIR)
Block(1,26,7,AIR)
Block(1,26,8,AIR)
Block(1,27,-1,5:5)
Block(1,29,-1,216:8)
Block(1,30,-2,216:8)
Block(1,30,-1,216:8)
Block(1,30,0,216:8)
Block(1,31,-1,216:8)
Block(2,15,-6,17:5)
Block(2,15,-5,5:1)
Block(2,15,-4,5:1)
Block(2,15,-3,5:1)
Block(2,15,-2,5:1)
Block(2,15,-1,5:1)
Block(2,15,0,5:1)
Block(2,15,1,5:1)
Block(2,15,2,5:1)
Block(2,15,3,17:5)
Block(2,15,4,5:1)
Block(2,15,5,5:1)
Block(2,15,6,5:1)
Block(2,15,7,5:1)
Block(2,15,8,17:5)
Block(2,16,-6,134:6)
Block(2,16,-5,AIR)
Block(2,16,-4,191)
Block(2,16,-3,134:4)
Block(2,16,-2,134:4)
Block(2,16,-1,134:4)
Block(2,16,0,191)
Block(2,16,1,AIR)
Block(2,16,2,134:2)
Block(2,16,3,AIR)
Block(2,16,4,26:11)
Block(2,16,5,26:11)
Block(2,16,6,AIR)
Block(2,16,7,AIR)
Block(2,16,8,134:7)
Block(2,17,-6,134:2)
Block(2,17,-5,AIR)
Block(2,17,-4,191)
Block(2,17,-3,5:1)
Block(2,17,-2,160:9)
Block(2,17,-1,5:1)
Block(2,17,0,191)
Block(2,17,1,AIR)
Block(2,17,2,134:6)
Block(2,17,3,AIR)
Block(2,17,4,AIR)
Block(2,17,5,AIR)
Block(2,17,6,AIR)
Block(2,17,7,AIR)
Block(2,17,8,134:3)
Block(2,18,-6,134:6)
Block(2,18,-5,AIR)
Block(2,18,-4,191)
Block(2,18,-3,134)
Block(2,18,-2,134)
Block(2,18,-1,134)
Block(2,18,0,191)
Block(2,18,1,AIR)
Block(2,18,2,134:2)
Block(2,18,3,AIR)
Block(2,18,4,AIR)
Block(2,18,5,AIR)
Block(2,18,6,AIR)
Block(2,18,7,AIR)
Block(2,18,8,134:7)
Block(2,19,-6,134:6)
Block(2,19,-5,AIR)
Block(2,19,-4,56)
Block(2,19,-3,AIR)
Block(2,19,-2,AIR)
Block(2,19,-1,AIR)
Block(2,19,0,56)
Block(2,19,1,AIR)
Block(2,19,2,AIR)
Block(2,19,3,5:1)
Block(2,19,4,AIR)
Block(2,19,5,AIR)
Block(2,19,6,AIR)
Block(2,19,7,AIR)
Block(2,19,8,134:7)
Block(2,20,-6,17:5)
Block(2,20,-5,5:1)
Block(2,20,-4,5:1)
Block(2,20,-3,5:1)
Block(2,20,-2,5:1)
Block(2,20,-1,5:1)
Block(2,20,0,5:1)
Block(2,20,1,5:1)
Block(2,20,2,5:1)
Block(2,20,3,5:1)
Block(2,20,4,5:1)
Block(2,20,5,5:1)
Block(2,20,6,5:1)
Block(2,20,7,5:1)
Block(2,20,8,17:5)
Block(2,21,-7,126:13)
Block(2,21,-6,159:13)
Block(2,21,-5,159:13)
Block(2,21,-4,159:13)
Block(2,21,-3,159:13)
Block(2,21,-2,159:13)
Block(2,21,-1,159:13)
Block(2,21,0,159:13)
Block(2,21,1,159:13)
Block(2,21,2,159:13)
Block(2,21,3,159:13)
Block(2,21,4,159:13)
Block(2,21,5,159:13)
Block(2,21,6,159:13)
Block(2,21,7,159:13)
Block(2,21,8,164:7)
Block(2,22,-7,5:5)
Block(2,22,-6,159:13)
Block(2,22,-5,AIR)
Block(2,22,-4,AIR)
Block(2,22,-3,AIR)
Block(2,22,-2,AIR)
Block(2,22,-1,AIR)
Block(2,22,0,AIR)
Block(2,22,1,AIR)
Block(2,22,2,AIR)
Block(2,22,3,AIR)
Block(2,22,4,159:13)
Block(2,22,5,AIR)
Block(2,22,6,AIR)
Block(2,22,7,AIR)
Block(2,22,8,164:3)
Block(2,23,-6,AIR)
Block(2,23,-5,159:13)
Block(2,23,-4,AIR)
Block(2,23,-3,AIR)
Block(2,23,-2,AIR)
Block(2,23,-1,AIR)
Block(2,23,0,AIR)
Block(2,23,1,AIR)
Block(2,23,2,AIR)
Block(2,23,3,159:13)
Block(2,23,4,AIR)
Block(2,23,5,AIR)
Block(2,23,6,AIR)
Block(2,23,7,AIR)
Block(2,23,8,AIR)
Block(2,24,-6,AIR)
Block(2,24,-5,AIR)
Block(2,24,-4,159:13)
Block(2,24,-3,AIR)
Block(2,24,-2,AIR)
Block(2,24,-1,AIR)
Block(2,24,0,AIR)
Block(2,24,1,AIR)
Block(2,24,2,159:13)
Block(2,24,3,AIR)
Block(2,24,4,AIR)
Block(2,24,5,AIR)
Block(2,24,6,AIR)
Block(2,24,7,AIR)
Block(2,24,8,AIR)
Block(2,25,-6,AIR)
Block(2,25,-5,AIR)
Block(2,25,-4,AIR)
Block(2,25,-3,159:13)
Block(2,25,-2,159:13)
Block(2,25,-1,AIR)
Block(2,25,0,159:13)
Block(2,25,1,159:13)
Block(2,25,2,AIR)
Block(2,25,3,AIR)
Block(2,25,4,AIR)
Block(2,25,5,AIR)
Block(2,25,6,AIR)
Block(2,25,7,AIR)
Block(2,25,8,AIR)
Block(2,26,-6,AIR)
Block(2,26,-5,AIR)
Block(2,26,-4,AIR)
Block(2,26,-3,AIR)
Block(2,26,-2,159:13)
Block(2,26,-1,5:5)
Block(2,26,0,159:13)
Block(2,26,1,AIR)
Block(2,26,2,AIR)
Block(2,26,3,AIR)
Block(2,26,4,AIR)
Block(2,26,5,AIR)
Block(2,26,6,AIR)
Block(2,26,7,AIR)
Block(2,26,8,AIR)
Block(2,27,-1,5:5)
Block(2,29,-1,216:8)
Block(2,30,-2,216:8)
Block(2,30,-1,216:8)
Block(2,30,0,216:8)
Block(2,31,-1,216:8)
Block(3,0,-6,17:1)
Block(3,0,0,17:1)
Block(3,0,3,17:1)
Block(3,0,8,17:1)
Block(3,1,-6,17:1)
Block(3,1,0,17:1)
Block(3,1,3,17:1)
Block(3,1,8,17:1)
Block(3,2,-6,17:1)
Block(3,2,0,17:1)
Block(3,2,3,17:1)
Block(3,2,8,17:1)
Block(3,3,-6,17:1)
Block(3,3,0,17:1)
Block(3,3,3,17:1)
Block(3,3,8,17:1)
Block(3,4,-6,17:1)
Block(3,4,0,17:1)
Block(3,4,3,17:1)
Block(3,4,8,17:1)
Block(3,5,-6,17:1)
Block(3,5,0,17:1)
Block(3,5,3,17:1)
Block(3,5,8,17:1)
Block(3,6,-6,17:1)
Block(3,6,0,17:1)
Block(3,6,3,17:1)
Block(3,6,8,17:1)
Block(3,7,-6,17:1)
Block(3,7,0,17:1)
Block(3,7,3,17:1)
Block(3,7,8,17:1)
Block(3,8,-6,17:1)
Block(3,8,0,17:1)
Block(3,8,3,17:1)
Block(3,8,8,17:1)
Block(3,9,-6,17:1)
Block(3,9,0,17:1)
Block(3,9,3,17:1)
Block(3,9,8,17:1)
Block(3,10,-6,17:1)
Block(3,10,0,17:1)
Block(3,10,3,17:1)
Block(3,10,8,17:1)
Block(3,11,-6,17:1)
Block(3,11,0,17:1)
Block(3,11,3,17:1)
Block(3,11,8,17:1)
Block(3,12,-6,17:1)
Block(3,12,0,17:1)
Block(3,12,3,17:1)
Block(3,12,8,17:1)
Block(3,13,-6,17:1)
Block(3,13,0,17:1)
Block(3,13,3,17:1)
Block(3,13,8,17:1)
Block(3,14,-6,17:1)
Block(3,14,0,17:1)
Block(3,14,3,17:1)
Block(3,14,8,17:1)
Block(3,15,-6,17:1)
Block(3,15,-5,17:9)
Block(3,15,-4,17:9)
Block(3,15,-3,17:9)
Block(3,15,-2,17:9)
Block(3,15,-1,17:9)
Block(3,15,0,17:1)
Block(3,15,1,17:9)
Block(3,15,2,17:9)
Block(3,15,3,17:9)
Block(3,15,4,17:9)
Block(3,15,5,17:9)
Block(3,15,6,17:9)
Block(3,15,7,17:9)
Block(3,15,8,17:1)
Block(3,16,-6,17:1)
Block(3,16,-5,134:5)
Block(3,16,-4,134:5)
Block(3,16,-3,134:5)
Block(3,16,-2,134:5)
Block(3,16,-1,134:5)
Block(3,16,0,17:1)
Block(3,16,1,134:5)
Block(3,16,2,134:5)
Block(3,16,3,17:1)
Block(3,16,4,134:5)
Block(3,16,5,134:5)
Block(3,16,6,134:5)
Block(3,16,7,134:5)
Block(3,16,8,17:1)
Block(3,17,-6,17:1)
Block(3,17,-5,134:3)
Block(3,17,-4,134:3)
Block(3,17,-3,134:3)
Block(3,17,-2,AIR)
Block(3,17,-1,134:3)
Block(3,17,0,17:1)
Block(3,17,1,134:3)
Block(3,17,2,134:3)
Block(3,17,3,17:1)
Block(3,17,4,134:3)
Block(3,17,5,134:3)
Block(3,17,6,134:3)
Block(3,17,7,134:3)
Block(3,17,8,17:1)
Block(3,18,-6,17:1)
Block(3,18,-5,134:5)
Block(3,18,-4,134:5)
Block(3,18,-3,134:5)
Block(3,18,-2,134:5)
Block(3,18,-1,134:5)
Block(3,18,0,17:1)
Block(3,18,1,134:5)
Block(3,18,2,134:5)
Block(3,18,3,17:1)
Block(3,18,4,134:5)
Block(3,18,5,134:5)
Block(3,18,6,134:5)
Block(3,18,7,134:5)
Block(3,18,8,17:1)
Block(3,19,-6,17:1)
Block(3,19,-5,134:5)
Block(3,19,-4,134:5)
Block(3,19,-3,134:5)
Block(3,19,-2,134:5)
Block(3,19,-1,134:5)
Block(3,19,0,17:1)
Block(3,19,1,134:5)
Block(3,19,2,134:5)
Block(3,19,3,17:1)
Block(3,19,4,134:5)
Block(3,19,5,134:5)
Block(3,19,6,134:5)
Block(3,19,7,134:5)
Block(3,19,8,17:1)
Block(3,20,-7,164:4)
Block(3,20,-6,159:13)
Block(3,20,-5,159:13)
Block(3,20,-4,159:13)
Block(3,20,-3,159:13)
Block(3,20,-2,159:13)
Block(3,20,-1,159:13)
Block(3,20,0,159:13)
Block(3,20,1,159:13)
Block(3,20,2,159:13)
Block(3,20,3,159:13)
Block(3,20,4,159:13)
Block(3,20,5,159:13)
Block(3,20,6,159:13)
Block(3,20,7,159:13)
Block(3,20,8,17:1)
Block(3,21,-7,164:3)
Block(3,21,-6,AIR)
Block(3,21,-5,AIR)
Block(3,21,-4,AIR)
Block(3,21,-3,AIR)
Block(3,21,-2,AIR)
Block(3,21,-1,AIR)
Block(3,21,0,AIR)
Block(3,21,1,AIR)
Block(3,21,2,AIR)
Block(3,21,3,AIR)
Block(3,21,4,AIR)
Block(3,21,5,AIR)
Block(3,21,6,AIR)
Block(3,21,7,AIR)
Block(3,21,8,164:3)
Block(3,22,-7,5:5)
Block(3,22,-6,AIR)
Block(3,22,-5,AIR)
Block(3,22,-4,AIR)
Block(3,22,-3,AIR)
Block(3,22,-2,AIR)
Block(3,22,-1,AIR)
Block(3,22,0,AIR)
Block(3,22,1,AIR)
Block(3,22,2,AIR)
Block(3,22,3,AIR)
Block(3,22,4,AIR)
Block(3,22,5,AIR)
Block(3,22,6,AIR)
Block(3,22,7,AIR)
Block(3,22,8,AIR)
Block(3,23,-7,126:5)
Block(3,23,-6,AIR)
Block(3,23,-5,AIR)
Block(3,23,-4,AIR)
Block(3,23,-3,AIR)
Block(3,23,-2,AIR)
Block(3,23,-1,AIR)
Block(3,23,0,AIR)
Block(3,23,1,AIR)
Block(3,23,2,AIR)
Block(3,23,3,AIR)
Block(3,23,4,AIR)
Block(3,23,5,AIR)
Block(3,23,6,AIR)
Block(3,23,7,AIR)
Block(3,23,8,AIR)
Block(3,24,-6,AIR)
Block(3,24,-5,AIR)
Block(3,24,-4,159:13)
Block(3,24,-3,AIR)
Block(3,24,-2,AIR)
Block(3,24,-1,AIR)
Block(3,24,0,AIR)
Block(3,24,1,AIR)
Block(3,24,2,159:13)
Block(3,24,3,AIR)
Block(3,24,4,AIR)
Block(3,24,5,AIR)
Block(3,24,6,AIR)
Block(3,24,7,AIR)
Block(3,24,8,AIR)
Block(3,25,-6,AIR)
Block(3,25,-5,AIR)
Block(3,25,-4,AIR)
Block(3,25,-3,159:13)
Block(3,25,-2,159:13)
Block(3,25,-1,AIR)
Block(3,25,0,159:13)
Block(3,25,1,159:13)
Block(3,25,2,AIR)
Block(3,25,3,AIR)
Block(3,25,4,AIR)
Block(3,25,5,AIR)
Block(3,25,6,AIR)
Block(3,25,7,AIR)
Block(3,25,8,AIR)
Block(3,26,-6,AIR)
Block(3,26,-5,AIR)
Block(3,26,-4,AIR)
Block(3,26,-3,AIR)
Block(3,26,-2,159:13)
Block(3,26,-1,5:5)
Block(3,26,0,159:13)
Block(3,26,1,AIR)
Block(3,26,2,AIR)
Block(3,26,3,AIR)
Block(3,26,4,AIR)
Block(3,26,5,AIR)
Block(3,26,6,AIR)
Block(3,26,7,AIR)
Block(3,26,8,AIR)
Block(3,27,-1,5:5)
Block(3,28,-1,126:5)
Block(3,30,-2,216:8)
Block(3,30,-1,216:8)
Block(3,30,0,216:8)
Block(3,31,-2,216)
Block(3,31,-1,216:8)
Block(3,31,0,216)
Block(3,32,-1,216)
Block(4,15,-6,17:5)
Block(4,15,0,17:5)
Block(4,15,3,17:5)
Block(4,15,8,17:5)
Block(4,20,-7,164:3)
Block(4,20,-4,159:13)
Block(4,20,-3,159:13)
Block(4,20,-2,159:13)
Block(4,20,-1,159:13)
Block(4,20,0,159:13)
Block(4,20,1,159:13)
Block(4,20,2,159:13)
Block(4,20,8,164:3)
Block(4,25,-3,159:13)
Block(4,25,-2,159:13)
Block(4,25,0,159:13)
Block(4,25,1,159:13)
Block(4,26,-2,159:13)
Block(4,26,-1,5:5)
Block(4,26,0,159:13)
Block(4,27,-1,5:5)
Block(4,28,-1,5:5)
Block(4,30,-1,216:8)
Block(4,31,-2,216)
Block(4,31,-1,216)
Block(4,31,0,216)
Block(4,32,-2,216)
Block(4,32,-1,216:8)
Block(4,32,0,216)
Block(4,33,-1,216)
Block(5,26,-2,159:13)
Block(5,26,-1,5:5)
Block(5,26,0,159:13)
Block(5,27,-1,5:5)
Block(5,28,-1,5:5)
Block(5,29,-1,164:4)
Block(5,31,-1,216:8)
Block(5,32,-2,216)
Block(5,32,-1,216:8)
Block(5,32,0,216)
Block(5,33,-2,216)
Block(5,33,-1,216)
Block(5,33,0,216)
Block(5,34,-1,216)
Block(6,27,-1,164:5)
Block(6,28,-1,5:5)
Block(6,29,-1,164:3)
Block(6,33,-1,216)
Block(6,34,-1,216)
Block(6,35,-1,216)


#######################################################################
# +-----------------------------------------------------------------+ #
# |                            BO3 checks                           | #
# +-----------------------------------------------------------------+ #
#######################################################################

# Require a condition at a certain location in order for the BO3 to be spawned.
# BlockCheck(x,y,z,BlockName[,BlockName[,...]]) - one of the blocks must be at the location
# BlockCheckNot(x,y,z,BlockName[,BlockName[,...]]) - all the blocks must not be at the location
# LightCheck(x,y,z,minLightLevel,maxLightLevel) - light must be between min and max (inclusive)

# You can use "Solid" as a BlockName for matching all solid blocks or "All" to match all blocks that aren't air.

# Examples:
#   BlockCheck(0,-1,0,GRASS,DIRT,biomesoplenty:grass:0,biomesoplenty:grass:1,biomesoplenty:grass:2,biomesoplenty:grass:3,biomesoplenty:grass:4,biomesoplenty:grass:5,biomesoplenty:grass:6,biomesoplenty:grass:7,biomesoplenty:dirt:0,biomesoplenty:dirt:1,biomesoplenty:dirt:2,biomesoplenty:dirt:3,biomesoplenty:dirt:4,biomesoplenty:dirt:5,biomesoplenty:dirt:6,biomesoplenty:dirt:7,biomesoplenty:dirt:8,biomesoplenty:dirt:9,biomesoplenty:dirt:10,biomesoplenty:dried_sand:0,biomesoplenty:hard_ice:0,biomesoplenty:white_sand:0,biomesoplenty:white_sandstone:0,biomesoplenty:mud:0,biomesoplenty:ash_block:0)  Require grass or dirt just below the object
#   BlockCheck(0,-1,0,Solid)       Require any solid block just below the object
#   BlockCheck(0,-1,0,WOOL)        Require any type of wool just below the object
#   BlockCheck(0,-1,0,WOOL:0)      Require white wool just below the object
#   BlockCheckNot(0,-1,0,WOOL:0)   Require that there is no white wool below the object
#   LightCheck(0,0,0,0,1)          Require almost complete darkness just below the object

#######################################################################
# +-----------------------------------------------------------------+ #
# |                             Branches                            | #
# +-----------------------------------------------------------------+ #
#######################################################################

# Branches are objects that will spawn when this object spawns when it is used in
# the CustomStructure resource. Branches can also have branches, making complex
# structures possible. See the wiki for more details.

# Regular Branches spawn each branch with an independent chance of spawning.
# Branch(x,y,z,branchName,rotation,chance[,anotherBranchName,rotation,chance[,...]][IndividualChance])
# branchName - name of the object to spawn.
# rotation - NORTH, SOUTH, EAST or WEST.
# IndividualChance - The chance each branch has to spawn, assumed to be 100 when left blank

# WeightedBranch(x,y,z,branchName,rotation,chance[,anotherBranchName,rotation,chance[,...]][MaxChanceOutOf])
# MaxChanceOutOf - The chance all branches have to spawn out of, assumed to be 100 when left blank
