
#######################################################################
# +-----------------------------------------------------------------+ #
# |                            BO3 object                           | #
# +-----------------------------------------------------------------+ #
#######################################################################

Author: MC_Pitman

Description: No description given

Version: 3

SettingsMode: WriteWithoutComments


#######################################################################
# +-----------------------------------------------------------------+ #
# |                          Main settings                          | #
# +-----------------------------------------------------------------+ #
#######################################################################

Tree: true

Frequency: 1

Rarity: 50.0

RotateRandomly: true

SpawnHeight: highestSolidBlock

SpawnHeightOffset: 0

SpawnHeightVariance: 0

##############################
# Height Limits for the BO3. #
##############################

MinHeight: 62

MaxHeight: 210

######################
# Extrusion settings #
######################

ExtrudeMode: None

ExtrudeThroughBlocks: AIR

MaxBranchDepth: 10

ExcludedBiomes: All


#######################################################################
# +-----------------------------------------------------------------+ #
# |                      Source block settings                      | #
# +-----------------------------------------------------------------+ #
#######################################################################

SourceBlocks: STONE:1,STONE:3,STONE:5,DIRT:1,DIRT,SAND,GRASS,DIRT:2,STATIONARY_WATER,HARD_CLAY,STAINED_CLAY,CLAY,SANDSTONE,SAND:1,AIR,STONE,GRAVEL,LONG_GRASS,LONG_GRASS:1,LONG_GRASS:2,DEAD_BUSH,YELLOW_FLOWER,RED_ROSE,BROWN_MUSHROOM,RED_MUSHROOM,biomesoplenty:plant_0:1,biomesoplenty:plant_0:2,biomesoplenty:plant_0:3,biomesoplenty:plant_0:4,biomesoplenty:plant_0:5,biomesoplenty:plant_0:6,biomesoplenty:plant_0:7,biomesoplenty:plant_0:8,biomesoplenty:plant_0:9,biomesoplenty:plant_0:10,biomesoplenty:plant_0:11,biomesoplenty:plant_0:12,biomesoplenty:plant_0:13,biomesoplenty:plant_0:14,biomesoplenty:flower_0:1,biomesoplenty:flower_0:2,biomesoplenty:flower_0:3,biomesoplenty:flower_0:4,biomesoplenty:flower_0:5,biomesoplenty:flower_0:6,biomesoplenty:flower_0:7,biomesoplenty:flower_0:8,biomesoplenty:flower_0:9,biomesoplenty:flower_0:10,biomesoplenty:flower_0:11,biomesoplenty:flower_0:12,biomesoplenty:flower_0:13,biomesoplenty:flower_0:14,biomesoplenty:plant_1,biomesoplenty:grass:0,biomesoplenty:grass:1,biomesoplenty:grass,biomesoplenty:grass:3,biomesoplenty:grass:4,biomesoplenty:grass:5,biomesoplenty:grass:6,biomesoplenty:grass:7,biomesoplenty:dirt,biomesoplenty:dirt:1,biomesoplenty:dirt:2,biomesoplenty:dirt:8,biomesoplenty:dirt:9,biomesoplenty:dirt:10,biomesoplenty:dried_sand,biomesoplenty:hard_ice,biomesoplenty:white_sand,biomesoplenty:white_sandstone,biomesoplenty:mud,biomesoplenty:ash_block

MaxPercentageOutsideSourceBlock: 0

OutsideSourceBlock: placeAnyway

DoReplaceBlocks: true

IsOTGPlus: false


#######################################################################
# +-----------------------------------------------------------------+ #
# |                              Blocks                             | #
# +-----------------------------------------------------------------+ #
#######################################################################

Block(-8,1,6,biomesoplenty:leaves_4:3)
Block(-8,2,6,biomesoplenty:leaves_4:3)
Block(-8,3,6,biomesoplenty:leaves_4:3)
Block(-8,4,5,biomesoplenty:leaves_4:3)
Block(-8,4,6,biomesoplenty:leaves_4:3)
Block(-8,4,7,biomesoplenty:leaves_4:3)
Block(-8,5,5,biomesoplenty:leaves_4:3)
Block(-8,5,6,biomesoplenty:log_2:5)
Block(-8,5,7,biomesoplenty:leaves_4:3)
Block(-8,6,5,biomesoplenty:leaves_4:3)
Block(-8,6,6,biomesoplenty:log_2:5)
Block(-8,6,7,biomesoplenty:leaves_4:3)
Block(-8,7,5,biomesoplenty:leaves_4:3)
Block(-8,7,6,biomesoplenty:log_2:5)
Block(-8,7,7,biomesoplenty:leaves_4:3)
Block(-8,8,6,biomesoplenty:leaves_4:3)
Block(-7,3,7,biomesoplenty:leaves_4:3)
Block(-7,4,6,biomesoplenty:leaves_4:3)
Block(-7,4,7,biomesoplenty:leaves_4:3)
Block(-7,5,5,biomesoplenty:leaves_4:3)
Block(-7,5,6,biomesoplenty:leaves_4:3)
Block(-7,5,7,biomesoplenty:leaves_4:3)
Block(-7,6,2,biomesoplenty:leaves_4:3)
Block(-7,6,5,biomesoplenty:leaves_4:3)
Block(-7,6,6,biomesoplenty:leaves_4:3)
Block(-7,6,7,biomesoplenty:leaves_4:3)
Block(-7,7,2,biomesoplenty:leaves_4:3)
Block(-7,7,4,biomesoplenty:leaves_4:3)
Block(-7,7,5,biomesoplenty:leaves_4:3)
Block(-7,7,6,biomesoplenty:log_2:5)
Block(-7,7,7,biomesoplenty:leaves_4:3)
Block(-7,8,2,biomesoplenty:leaves_4:3)
Block(-7,8,4,biomesoplenty:leaves_4:3)
Block(-7,8,5,biomesoplenty:leaves_4:3)
Block(-7,8,6,biomesoplenty:leaves_4:3)
Block(-7,9,4,biomesoplenty:leaves_4:3)
Block(-6,3,2,biomesoplenty:leaves_4:3)
Block(-6,3,5,biomesoplenty:leaves_4:3)
Block(-6,4,2,biomesoplenty:leaves_4:3)
Block(-6,4,4,biomesoplenty:leaves_4:3)
Block(-6,4,5,biomesoplenty:leaves_4:3)
Block(-6,5,1,biomesoplenty:leaves_4:3)
Block(-6,5,2,biomesoplenty:leaves_4:3)
Block(-6,5,3,biomesoplenty:leaves_4:3)
Block(-6,5,4,biomesoplenty:leaves_4:3)
Block(-6,5,5,biomesoplenty:leaves_4:3)
Block(-6,5,7,biomesoplenty:leaves_4:3)
Block(-6,6,1,biomesoplenty:leaves_4:3)
Block(-6,6,2,biomesoplenty:log_2:5)
Block(-6,6,3,biomesoplenty:leaves_4:3)
Block(-6,6,4,biomesoplenty:leaves_4:3)
Block(-6,6,5,biomesoplenty:log_2:5)
Block(-6,6,6,biomesoplenty:leaves_4:3)
Block(-6,6,7,biomesoplenty:leaves_4:3)
Block(-6,6,8,biomesoplenty:leaves_4:3)
Block(-6,7,1,biomesoplenty:leaves_4:3)
Block(-6,7,2,biomesoplenty:log_2:5)
Block(-6,7,3,biomesoplenty:leaves_4:3)
Block(-6,7,4,biomesoplenty:leaves_4:3)
Block(-6,7,5,biomesoplenty:log_2:5)
Block(-6,7,6,biomesoplenty:leaves_4:3)
Block(-6,7,7,biomesoplenty:leaves_4:3)
Block(-6,7,8,biomesoplenty:leaves_4:3)
Block(-6,8,1,biomesoplenty:leaves_4:3)
Block(-6,8,2,biomesoplenty:log_2:5)
Block(-6,8,3,biomesoplenty:leaves_4:3)
Block(-6,8,4,biomesoplenty:leaves_4:3)
Block(-6,8,5,biomesoplenty:log_2:5)
Block(-6,8,6,biomesoplenty:leaves_4:3)
Block(-6,8,7,biomesoplenty:leaves_4:3)
Block(-6,8,8,biomesoplenty:leaves_4:3)
Block(-6,9,2,biomesoplenty:leaves_4:3)
Block(-6,9,3,biomesoplenty:leaves_4:3)
Block(-6,9,4,biomesoplenty:leaves_4:3)
Block(-6,9,5,biomesoplenty:leaves_4:3)
Block(-6,10,3,biomesoplenty:leaves_4:3)
Block(-5,4,3,biomesoplenty:leaves_4:3)
Block(-5,4,9,biomesoplenty:leaves_4:3)
Block(-5,5,-1,biomesoplenty:leaves_4:3)
Block(-5,5,1,biomesoplenty:leaves_4:3)
Block(-5,5,3,biomesoplenty:leaves_4:3)
Block(-5,5,4,biomesoplenty:leaves_4:3)
Block(-5,5,9,biomesoplenty:leaves_4:3)
Block(-5,6,-1,biomesoplenty:leaves_4:3)
Block(-5,6,0,biomesoplenty:leaves_4:3)
Block(-5,6,2,biomesoplenty:leaves_4:3)
Block(-5,6,3,biomesoplenty:leaves_4:3)
Block(-5,6,4,biomesoplenty:leaves_4:3)
Block(-5,6,5,biomesoplenty:leaves_4:3)
Block(-5,6,8,biomesoplenty:leaves_4:3)
Block(-5,6,9,biomesoplenty:leaves_4:3)
Block(-5,7,-1,biomesoplenty:leaves_4:3)
Block(-5,7,0,biomesoplenty:leaves_4:3)
Block(-5,7,1,biomesoplenty:leaves_4:3)
Block(-5,7,2,biomesoplenty:leaves_4:3)
Block(-5,7,3,biomesoplenty:leaves_4:3)
Block(-5,7,5,biomesoplenty:leaves_4:3)
Block(-5,7,6,biomesoplenty:leaves_4:3)
Block(-5,7,7,biomesoplenty:leaves_4:3)
Block(-5,7,8,biomesoplenty:leaves_4:3)
Block(-5,7,9,biomesoplenty:leaves_4:3)
Block(-5,8,1,biomesoplenty:leaves_4:3)
Block(-5,8,2,biomesoplenty:log_2:5)
Block(-5,8,3,biomesoplenty:leaves_4:3)
Block(-5,8,5,biomesoplenty:leaves_4:3)
Block(-5,8,6,biomesoplenty:leaves_4:3)
Block(-5,8,7,biomesoplenty:leaves_4:3)
Block(-5,8,8,biomesoplenty:leaves_4:3)
Block(-5,9,2,biomesoplenty:leaves_4:3)
Block(-5,9,3,biomesoplenty:leaves_4:3)
Block(-5,9,4,biomesoplenty:leaves_4:3)
Block(-5,9,5,biomesoplenty:log_2:5)
Block(-5,9,6,biomesoplenty:leaves_4:3)
Block(-5,9,7,biomesoplenty:leaves_4:3)
Block(-5,9,8,biomesoplenty:leaves_4:3)
Block(-5,10,5,biomesoplenty:leaves_4:3)
Block(-5,10,7,biomesoplenty:leaves_4:3)
Block(-4,1,9,biomesoplenty:leaves_4:3)
Block(-4,2,3,biomesoplenty:leaves_4:3)
Block(-4,2,9,biomesoplenty:leaves_4:3)
Block(-4,3,-1,biomesoplenty:leaves_4:3)
Block(-4,3,3,biomesoplenty:leaves_4:3)
Block(-4,3,9,biomesoplenty:leaves_4:3)
Block(-4,3,10,biomesoplenty:leaves_4:3)
Block(-4,4,-2,biomesoplenty:leaves_4:3)
Block(-4,4,-1,biomesoplenty:leaves_4:3)
Block(-4,4,0,biomesoplenty:leaves_4:3)
Block(-4,4,2,biomesoplenty:leaves_4:3)
Block(-4,4,3,biomesoplenty:leaves_4:3)
Block(-4,4,8,biomesoplenty:leaves_4:3)
Block(-4,4,9,biomesoplenty:log_2:5)
Block(-4,4,10,biomesoplenty:leaves_4:3)
Block(-4,5,-2,biomesoplenty:leaves_4:3)
Block(-4,5,-1,biomesoplenty:log_2:5)
Block(-4,5,0,biomesoplenty:leaves_4:3)
Block(-4,5,2,biomesoplenty:leaves_4:3)
Block(-4,5,3,biomesoplenty:leaves_4:3)
Block(-4,5,8,biomesoplenty:leaves_4:3)
Block(-4,5,9,biomesoplenty:log_2:5)
Block(-4,5,10,biomesoplenty:leaves_4:3)
Block(-4,6,-2,biomesoplenty:leaves_4:3)
Block(-4,6,-1,biomesoplenty:log_2:5)
Block(-4,6,0,biomesoplenty:leaves_4:3)
Block(-4,6,1,biomesoplenty:leaves_4:3)
Block(-4,6,2,biomesoplenty:leaves_4:3)
Block(-4,6,3,biomesoplenty:log_2:5)
Block(-4,6,4,biomesoplenty:leaves_4:3)
Block(-4,6,7,biomesoplenty:leaves_4:3)
Block(-4,6,8,biomesoplenty:leaves_4:3)
Block(-4,6,9,biomesoplenty:log_2:5)
Block(-4,6,10,biomesoplenty:leaves_4:3)
Block(-4,7,-2,biomesoplenty:leaves_4:3)
Block(-4,7,-1,biomesoplenty:log_2:5)
Block(-4,7,0,biomesoplenty:leaves_4:3)
Block(-4,7,1,biomesoplenty:leaves_4:3)
Block(-4,7,2,biomesoplenty:leaves_4:3)
Block(-4,7,3,biomesoplenty:log_2:5)
Block(-4,7,4,biomesoplenty:leaves_4:3)
Block(-4,7,5,biomesoplenty:leaves_4:3)
Block(-4,7,6,biomesoplenty:leaves_4:3)
Block(-4,7,7,biomesoplenty:leaves_4:3)
Block(-4,7,8,biomesoplenty:leaves_4:3)
Block(-4,7,9,biomesoplenty:log_2:5)
Block(-4,7,10,biomesoplenty:leaves_4:3)
Block(-4,8,-1,biomesoplenty:leaves_4:3)
Block(-4,8,0,biomesoplenty:leaves_4:3)
Block(-4,8,1,biomesoplenty:leaves_4:3)
Block(-4,8,2,biomesoplenty:leaves_4:3)
Block(-4,8,3,biomesoplenty:log_2:5)
Block(-4,8,4,biomesoplenty:leaves_4:3)
Block(-4,8,5,biomesoplenty:leaves_4:3)
Block(-4,8,6,biomesoplenty:leaves_4:3)
Block(-4,8,7,biomesoplenty:leaves_4:3)
Block(-4,8,8,biomesoplenty:leaves_4:3)
Block(-4,8,9,biomesoplenty:leaves_4:3)
Block(-4,9,1,biomesoplenty:leaves_4:3)
Block(-4,9,2,biomesoplenty:leaves_4:3)
Block(-4,9,3,biomesoplenty:leaves_4:3)
Block(-4,9,4,biomesoplenty:log_2:5)
Block(-4,9,5,biomesoplenty:log_2:5)
Block(-4,9,6,biomesoplenty:leaves_4:3)
Block(-4,10,4,biomesoplenty:leaves_4:3)
Block(-4,10,5,biomesoplenty:leaves_4:3)
Block(-4,14,8,biomesoplenty:leaves_4:3)
Block(-4,15,8,biomesoplenty:leaves_4:3)
Block(-4,16,8,biomesoplenty:leaves_4:3)
Block(-3,4,9,biomesoplenty:leaves_4:3)
Block(-3,5,-1,biomesoplenty:leaves_4:3)
Block(-3,5,1,biomesoplenty:leaves_4:3)
Block(-3,5,4,biomesoplenty:leaves_4:3)
Block(-3,5,9,biomesoplenty:leaves_4:3)
Block(-3,6,-1,biomesoplenty:leaves_4:3)
Block(-3,6,0,biomesoplenty:leaves_4:3)
Block(-3,6,1,biomesoplenty:leaves_4:3)
Block(-3,6,2,biomesoplenty:leaves_4:3)
Block(-3,6,3,biomesoplenty:leaves_4:3)
Block(-3,6,4,biomesoplenty:leaves_4:3)
Block(-3,6,8,biomesoplenty:leaves_4:3)
Block(-3,6,9,biomesoplenty:leaves_4:3)
Block(-3,7,-1,biomesoplenty:leaves_4:3)
Block(-3,7,0,biomesoplenty:leaves_4:3)
Block(-3,7,1,biomesoplenty:log_2:5)
Block(-3,7,2,biomesoplenty:leaves_4:3)
Block(-3,7,3,biomesoplenty:leaves_4:3)
Block(-3,7,4,biomesoplenty:leaves_4:3)
Block(-3,7,5,biomesoplenty:leaves_4:3)
Block(-3,7,8,biomesoplenty:leaves_4:3)
Block(-3,7,9,biomesoplenty:leaves_4:3)
Block(-3,8,-1,biomesoplenty:leaves_4:3)
Block(-3,8,0,biomesoplenty:log_2:5)
Block(-3,8,1,biomesoplenty:log_2:5)
Block(-3,8,2,biomesoplenty:leaves_4:3)
Block(-3,8,3,biomesoplenty:leaves_4:3)
Block(-3,8,4,biomesoplenty:log_2:5)
Block(-3,8,5,biomesoplenty:leaves_4:3)
Block(-3,8,6,biomesoplenty:leaves_4:3)
Block(-3,8,7,biomesoplenty:leaves_4:3)
Block(-3,8,8,biomesoplenty:log_2:5)
Block(-3,8,9,biomesoplenty:leaves_4:3)
Block(-3,9,0,biomesoplenty:leaves_4:3)
Block(-3,9,1,biomesoplenty:log_2:5)
Block(-3,9,2,biomesoplenty:leaves_4:3)
Block(-3,9,3,biomesoplenty:leaves_4:3)
Block(-3,9,4,biomesoplenty:log_2:5)
Block(-3,9,5,biomesoplenty:leaves_4:3)
Block(-3,9,6,biomesoplenty:leaves_4:3)
Block(-3,9,8,biomesoplenty:leaves_4:3)
Block(-3,10,1,biomesoplenty:leaves_4:3)
Block(-3,10,2,biomesoplenty:leaves_4:3)
Block(-3,10,3,biomesoplenty:leaves_4:3)
Block(-3,10,4,biomesoplenty:log_2:5)
Block(-3,10,5,biomesoplenty:log_2:5)
Block(-3,10,6,biomesoplenty:leaves_4:3)
Block(-3,11,2,biomesoplenty:leaves_4:3)
Block(-3,11,4,biomesoplenty:leaves_4:3)
Block(-3,11,5,biomesoplenty:leaves_4:3)
Block(-3,11,8,biomesoplenty:leaves_4:3)
Block(-3,12,7,biomesoplenty:leaves_4:3)
Block(-3,12,8,biomesoplenty:leaves_4:3)
Block(-3,12,10,biomesoplenty:leaves_4:3)
Block(-3,13,5,biomesoplenty:leaves_4:3)
Block(-3,13,7,biomesoplenty:leaves_4:3)
Block(-3,13,8,biomesoplenty:leaves_4:3)
Block(-3,13,10,biomesoplenty:leaves_4:3)
Block(-3,14,5,biomesoplenty:leaves_4:3)
Block(-3,14,7,biomesoplenty:leaves_4:3)
Block(-3,14,8,biomesoplenty:log_2:5)
Block(-3,14,9,biomesoplenty:leaves_4:3)
Block(-3,14,10,biomesoplenty:leaves_4:3)
Block(-3,15,4,biomesoplenty:leaves_4:3)
Block(-3,15,5,biomesoplenty:leaves_4:3)
Block(-3,15,7,biomesoplenty:leaves_4:3)
Block(-3,15,8,biomesoplenty:log_2:5)
Block(-3,15,9,biomesoplenty:leaves_4:3)
Block(-3,15,10,biomesoplenty:leaves_4:3)
Block(-3,16,5,biomesoplenty:leaves_4:3)
Block(-3,16,7,biomesoplenty:leaves_4:3)
Block(-3,16,8,biomesoplenty:log_2:5)
Block(-3,16,9,biomesoplenty:leaves_4:3)
Block(-3,17,8,biomesoplenty:leaves_4:3)
Block(-2,-2,-2,biomesoplenty:log_2:5)
Block(-2,-1,-2,biomesoplenty:log_2:5)
Block(-2,6,7,biomesoplenty:leaves_4:3)
Block(-2,6,8,biomesoplenty:leaves_4:3)
Block(-2,7,1,biomesoplenty:leaves_4:3)
Block(-2,7,3,biomesoplenty:leaves_4:3)
Block(-2,7,4,biomesoplenty:leaves_4:3)
Block(-2,7,6,biomesoplenty:leaves_4:3)
Block(-2,7,7,biomesoplenty:leaves_4:3)
Block(-2,7,8,biomesoplenty:leaves_4:3)
Block(-2,8,0,biomesoplenty:leaves_4:3)
Block(-2,8,1,biomesoplenty:leaves_4:3)
Block(-2,8,2,biomesoplenty:leaves_4:3)
Block(-2,8,3,biomesoplenty:leaves_4:3)
Block(-2,8,4,biomesoplenty:leaves_4:3)
Block(-2,8,5,biomesoplenty:leaves_4:3)
Block(-2,8,6,biomesoplenty:leaves_4:3)
Block(-2,8,7,biomesoplenty:log_2:5)
Block(-2,8,8,biomesoplenty:leaves_4:3)
Block(-2,8,9,biomesoplenty:leaves_4:3)
Block(-2,9,0,biomesoplenty:leaves_4:3)
Block(-2,9,1,biomesoplenty:log_2:5)
Block(-2,9,2,biomesoplenty:leaves_4:3)
Block(-2,9,3,biomesoplenty:leaves_4:3)
Block(-2,9,4,biomesoplenty:leaves_4:3)
Block(-2,9,5,biomesoplenty:leaves_4:3)
Block(-2,9,6,biomesoplenty:log_2:5)
Block(-2,9,7,biomesoplenty:leaves_4:3)
Block(-2,9,8,biomesoplenty:leaves_4:3)
Block(-2,9,9,biomesoplenty:leaves_4:3)
Block(-2,10,1,biomesoplenty:leaves_4:3)
Block(-2,10,2,biomesoplenty:leaves_4:3)
Block(-2,10,3,biomesoplenty:leaves_4:3)
Block(-2,10,4,biomesoplenty:log_2:5)
Block(-2,10,5,biomesoplenty:log_2:5)
Block(-2,10,6,biomesoplenty:leaves_4:3)
Block(-2,11,4,biomesoplenty:leaves_4:3)
Block(-2,11,5,biomesoplenty:leaves_4:3)
Block(-2,12,5,biomesoplenty:leaves_4:3)
Block(-2,13,2,biomesoplenty:leaves_4:3)
Block(-2,13,5,biomesoplenty:log_2:5)
Block(-2,13,6,biomesoplenty:leaves_4:3)
Block(-2,13,8,biomesoplenty:leaves_4:3)
Block(-2,13,11,biomesoplenty:leaves_4:3)
Block(-2,14,2,biomesoplenty:leaves_4:3)
Block(-2,14,4,biomesoplenty:leaves_4:3)
Block(-2,14,5,biomesoplenty:log_2:5)
Block(-2,14,6,biomesoplenty:leaves_4:3)
Block(-2,14,8,biomesoplenty:leaves_4:3)
Block(-2,14,9,biomesoplenty:leaves_4:3)
Block(-2,14,11,biomesoplenty:leaves_4:3)
Block(-2,15,2,biomesoplenty:leaves_4:3)
Block(-2,15,4,biomesoplenty:leaves_4:3)
Block(-2,15,5,biomesoplenty:log_2:5)
Block(-2,15,6,biomesoplenty:leaves_4:3)
Block(-2,15,7,biomesoplenty:leaves_4:3)
Block(-2,15,8,biomesoplenty:leaves_4:3)
Block(-2,15,9,biomesoplenty:leaves_4:3)
Block(-2,15,10,biomesoplenty:leaves_4:3)
Block(-2,15,11,biomesoplenty:leaves_4:3)
Block(-2,16,2,biomesoplenty:leaves_4:3)
Block(-2,16,4,biomesoplenty:leaves_4:3)
Block(-2,16,5,biomesoplenty:log_2:5)
Block(-2,16,6,biomesoplenty:leaves_4:3)
Block(-2,16,7,biomesoplenty:log_2:5)
Block(-2,16,8,biomesoplenty:leaves_4:3)
Block(-2,16,9,biomesoplenty:leaves_4:3)
Block(-2,16,10,biomesoplenty:leaves_4:3)
Block(-2,16,11,biomesoplenty:leaves_4:3)
Block(-2,17,4,biomesoplenty:leaves_4:3)
Block(-2,17,5,biomesoplenty:leaves_4:3)
Block(-2,17,7,biomesoplenty:leaves_4:3)
Block(-2,17,9,biomesoplenty:leaves_4:3)
Block(-2,17,10,biomesoplenty:leaves_4:3)
Block(-1,-1,-1,biomesoplenty:log_2:5)
Block(-1,0,-1,biomesoplenty:log_2:5)
Block(-1,3,7,biomesoplenty:leaves_4:3)
Block(-1,4,7,biomesoplenty:leaves_4:3)
Block(-1,5,3,biomesoplenty:leaves_4:3)
Block(-1,5,7,biomesoplenty:leaves_4:3)
Block(-1,5,8,biomesoplenty:leaves_4:3)
Block(-1,6,3,biomesoplenty:leaves_4:3)
Block(-1,6,5,biomesoplenty:leaves_4:3)
Block(-1,6,6,biomesoplenty:leaves_4:3)
Block(-1,6,7,biomesoplenty:log_2:5)
Block(-1,6,8,biomesoplenty:leaves_4:3)
Block(-1,7,2,biomesoplenty:leaves_4:3)
Block(-1,7,3,biomesoplenty:leaves_4:3)
Block(-1,7,4,biomesoplenty:leaves_4:3)
Block(-1,7,5,biomesoplenty:leaves_4:3)
Block(-1,7,6,biomesoplenty:leaves_4:3)
Block(-1,7,7,biomesoplenty:log_2:5)
Block(-1,7,8,biomesoplenty:leaves_4:3)
Block(-1,8,2,biomesoplenty:leaves_4:3)
Block(-1,8,3,biomesoplenty:log_2:5)
Block(-1,8,4,biomesoplenty:leaves_4:3)
Block(-1,8,5,biomesoplenty:leaves_4:3)
Block(-1,8,6,biomesoplenty:leaves_4:3)
Block(-1,8,7,biomesoplenty:log_2:5)
Block(-1,8,8,biomesoplenty:leaves_4:3)
Block(-1,9,1,biomesoplenty:leaves_4:3)
Block(-1,9,2,biomesoplenty:log_2:5)
Block(-1,9,3,biomesoplenty:log_2:5)
Block(-1,9,4,biomesoplenty:leaves_4:3)
Block(-1,9,5,biomesoplenty:leaves_4:3)
Block(-1,9,6,biomesoplenty:leaves_4:3)
Block(-1,9,7,biomesoplenty:log_2:5)
Block(-1,9,8,biomesoplenty:leaves_4:3)
Block(-1,10,2,biomesoplenty:leaves_4:3)
Block(-1,10,3,biomesoplenty:log_2:5)
Block(-1,10,4,biomesoplenty:leaves_4:3)
Block(-1,10,5,biomesoplenty:leaves_4:3)
Block(-1,10,6,biomesoplenty:leaves_4:3)
Block(-1,10,7,biomesoplenty:leaves_4:3)
Block(-1,11,2,biomesoplenty:leaves_4:3)
Block(-1,11,3,biomesoplenty:leaves_4:3)
Block(-1,11,4,biomesoplenty:log_2:5)
Block(-1,11,5,biomesoplenty:leaves_4:3)
Block(-1,11,11,biomesoplenty:leaves_4:3)
Block(-1,12,2,biomesoplenty:leaves_4:3)
Block(-1,12,4,biomesoplenty:leaves_4:3)
Block(-1,12,5,biomesoplenty:leaves_4:3)
Block(-1,12,11,biomesoplenty:leaves_4:3)
Block(-1,13,2,biomesoplenty:leaves_4:3)
Block(-1,13,5,biomesoplenty:leaves_4:3)
Block(-1,13,10,biomesoplenty:leaves_4:3)
Block(-1,13,11,biomesoplenty:log_2:5)
Block(-1,13,12,biomesoplenty:leaves_4:3)
Block(-1,14,1,biomesoplenty:leaves_4:3)
Block(-1,14,2,biomesoplenty:log_2:5)
Block(-1,14,3,biomesoplenty:leaves_4:3)
Block(-1,14,5,biomesoplenty:leaves_4:3)
Block(-1,14,10,biomesoplenty:leaves_4:3)
Block(-1,14,11,biomesoplenty:log_2:5)
Block(-1,14,12,biomesoplenty:leaves_4:3)
Block(-1,15,1,biomesoplenty:leaves_4:3)
Block(-1,15,2,biomesoplenty:log_2:5)
Block(-1,15,3,biomesoplenty:leaves_4:3)
Block(-1,15,5,biomesoplenty:leaves_4:3)
Block(-1,15,10,biomesoplenty:leaves_4:3)
Block(-1,15,11,biomesoplenty:log_2:5)
Block(-1,15,12,biomesoplenty:leaves_4:3)
Block(-1,16,1,biomesoplenty:leaves_4:3)
Block(-1,16,2,biomesoplenty:log_2:5)
Block(-1,16,3,biomesoplenty:leaves_4:3)
Block(-1,16,4,biomesoplenty:leaves_4:3)
Block(-1,16,5,biomesoplenty:leaves_4:3)
Block(-1,16,6,biomesoplenty:leaves_4:3)
Block(-1,16,7,biomesoplenty:leaves_4:3)
Block(-1,16,8,biomesoplenty:leaves_4:3)
Block(-1,16,9,biomesoplenty:leaves_4:3)
Block(-1,16,10,biomesoplenty:leaves_4:3)
Block(-1,16,11,biomesoplenty:log_2:5)
Block(-1,16,12,biomesoplenty:leaves_4:3)
Block(-1,17,2,biomesoplenty:leaves_4:3)
Block(-1,17,3,biomesoplenty:leaves_4:3)
Block(-1,17,4,biomesoplenty:log_2:5)
Block(-1,17,5,biomesoplenty:leaves_4:3)
Block(-1,17,6,biomesoplenty:leaves_4:3)
Block(-1,17,7,biomesoplenty:log_2:5)
Block(-1,17,8,biomesoplenty:leaves_4:3)
Block(-1,17,9,biomesoplenty:log_2:5)
Block(-1,17,10,biomesoplenty:log_2:5)
Block(-1,17,11,biomesoplenty:leaves_4:3)
Block(-1,18,4,biomesoplenty:leaves_4:3)
Block(-1,18,7,biomesoplenty:leaves_4:3)
Block(-1,18,8,biomesoplenty:leaves_4:3)
Block(-1,18,9,biomesoplenty:leaves_4:3)
Block(-1,18,10,biomesoplenty:leaves_4:3)
Block(0,-2,-2,biomesoplenty:log_2:5)
Block(0,-2,-1,biomesoplenty:log_2:5)
Block(0,-1,-2,biomesoplenty:log_2:5)
Block(0,-1,-1,biomesoplenty:log_2:5)
Block(0,-1,0,biomesoplenty:log_2:5)
Block(0,0,-2,biomesoplenty:log_2:5)
Block(0,0,-1,biomesoplenty:log_2:5)
Block(0,0,0,biomesoplenty:log_2:5)
Block(0,1,-1,biomesoplenty:log_2:5)
Block(0,1,0,biomesoplenty:log_2:5)
Block(0,2,-1,biomesoplenty:log_2:5)
Block(0,2,0,biomesoplenty:log_2:5)
Block(0,3,-1,biomesoplenty:log_2:5)
Block(0,3,0,biomesoplenty:log_2:5)
Block(0,4,0,biomesoplenty:log_2:5)
Block(0,4,9,biomesoplenty:leaves_4:3)
Block(0,5,0,biomesoplenty:log_2:5)
Block(0,5,9,biomesoplenty:leaves_4:3)
Block(0,6,0,biomesoplenty:log_2:5)
Block(0,6,7,biomesoplenty:leaves_4:3)
Block(0,6,8,biomesoplenty:leaves_4:3)
Block(0,6,9,biomesoplenty:leaves_4:3)
Block(0,7,0,biomesoplenty:log_2:5)
Block(0,7,4,biomesoplenty:leaves_4:3)
Block(0,7,7,biomesoplenty:leaves_4:3)
Block(0,7,8,biomesoplenty:leaves_4:3)
Block(0,7,9,biomesoplenty:leaves_4:3)
Block(0,8,0,biomesoplenty:log_2:5)
Block(0,8,1,biomesoplenty:log_2:5)
Block(0,8,3,biomesoplenty:leaves_4:3)
Block(0,8,4,biomesoplenty:leaves_4:3)
Block(0,8,5,biomesoplenty:leaves_4:3)
Block(0,8,6,biomesoplenty:leaves_4:3)
Block(0,8,7,biomesoplenty:leaves_4:3)
Block(0,8,8,biomesoplenty:log_2:5)
Block(0,8,9,biomesoplenty:leaves_4:3)
Block(0,9,1,biomesoplenty:log_2:5)
Block(0,9,2,biomesoplenty:leaves_4:3)
Block(0,9,3,biomesoplenty:leaves_4:3)
Block(0,9,4,biomesoplenty:leaves_4:3)
Block(0,9,5,biomesoplenty:leaves_4:3)
Block(0,9,6,biomesoplenty:leaves_4:3)
Block(0,9,7,biomesoplenty:leaves_4:3)
Block(0,9,8,biomesoplenty:leaves_4:3)
Block(0,10,3,biomesoplenty:leaves_4:3)
Block(0,10,4,biomesoplenty:leaves_4:3)
Block(0,10,5,biomesoplenty:leaves_4:3)
Block(0,10,6,biomesoplenty:leaves_4:3)
Block(0,11,4,biomesoplenty:leaves_4:3)
Block(0,11,5,biomesoplenty:log_2:5)
Block(0,11,6,biomesoplenty:leaves_4:3)
Block(0,12,5,biomesoplenty:leaves_4:3)
Block(0,13,2,biomesoplenty:leaves_4:3)
Block(0,13,11,biomesoplenty:leaves_4:3)
Block(0,14,2,biomesoplenty:leaves_4:3)
Block(0,14,4,biomesoplenty:leaves_4:3)
Block(0,14,9,biomesoplenty:leaves_4:3)
Block(0,14,11,biomesoplenty:leaves_4:3)
Block(0,15,2,biomesoplenty:leaves_4:3)
Block(0,15,3,biomesoplenty:leaves_4:3)
Block(0,15,4,biomesoplenty:leaves_4:3)
Block(0,15,9,biomesoplenty:leaves_4:3)
Block(0,15,10,biomesoplenty:leaves_4:3)
Block(0,15,11,biomesoplenty:leaves_4:3)
Block(0,15,12,biomesoplenty:leaves_4:3)
Block(0,15,13,biomesoplenty:leaves_4:3)
Block(0,16,2,biomesoplenty:leaves_4:3)
Block(0,16,3,biomesoplenty:log_2:5)
Block(0,16,4,biomesoplenty:leaves_4:3)
Block(0,16,5,biomesoplenty:leaves_4:3)
Block(0,16,6,biomesoplenty:leaves_4:3)
Block(0,16,8,biomesoplenty:leaves_4:3)
Block(0,16,9,biomesoplenty:log_2:5)
Block(0,16,10,biomesoplenty:leaves_4:3)
Block(0,16,11,biomesoplenty:leaves_4:3)
Block(0,16,12,biomesoplenty:leaves_4:3)
Block(0,16,13,biomesoplenty:leaves_4:3)
Block(0,17,3,biomesoplenty:leaves_4:3)
Block(0,17,4,biomesoplenty:log_2:5)
Block(0,17,5,biomesoplenty:leaves_4:3)
Block(0,17,6,biomesoplenty:leaves_4:3)
Block(0,17,7,biomesoplenty:leaves_4:3)
Block(0,17,8,biomesoplenty:leaves_4:3)
Block(0,17,9,biomesoplenty:log_2:5)
Block(0,17,10,biomesoplenty:leaves_4:3)
Block(0,17,12,biomesoplenty:leaves_4:3)
Block(0,17,13,biomesoplenty:leaves_4:3)
Block(0,18,4,biomesoplenty:leaves_4:3)
Block(0,18,7,biomesoplenty:leaves_4:3)
Block(0,18,8,biomesoplenty:log_2:5)
Block(0,18,9,biomesoplenty:log_2:5)
Block(0,18,10,biomesoplenty:leaves_4:3)
Block(0,18,13,biomesoplenty:leaves_4:3)
Block(0,19,7,biomesoplenty:leaves_4:3)
Block(0,19,8,biomesoplenty:leaves_4:3)
Block(0,19,9,biomesoplenty:leaves_4:3)
Block(1,-2,-3,biomesoplenty:log_2:5)
Block(1,-1,-3,biomesoplenty:log_2:5)
Block(1,-1,-1,biomesoplenty:log_2:5)
Block(1,0,-1,biomesoplenty:log_2:5)
Block(1,2,9,biomesoplenty:leaves_4:3)
Block(1,3,9,biomesoplenty:leaves_4:3)
Block(1,3,10,biomesoplenty:leaves_4:3)
Block(1,4,9,biomesoplenty:leaves_4:3)
Block(1,4,10,biomesoplenty:leaves_4:3)
Block(1,5,8,biomesoplenty:leaves_4:3)
Block(1,5,9,biomesoplenty:log_2:5)
Block(1,5,10,biomesoplenty:leaves_4:3)
Block(1,6,0,biomesoplenty:log_2:5)
Block(1,6,5,biomesoplenty:leaves_4:3)
Block(1,6,8,biomesoplenty:leaves_4:3)
Block(1,6,9,biomesoplenty:log_2:5)
Block(1,6,10,biomesoplenty:leaves_4:3)
Block(1,7,0,biomesoplenty:log_2:5)
Block(1,7,5,biomesoplenty:leaves_4:3)
Block(1,7,7,biomesoplenty:leaves_4:3)
Block(1,7,8,biomesoplenty:leaves_4:3)
Block(1,7,9,biomesoplenty:log_2:5)
Block(1,7,10,biomesoplenty:leaves_4:3)
Block(1,8,0,biomesoplenty:log_2:5)
Block(1,8,4,biomesoplenty:leaves_4:3)
Block(1,8,5,biomesoplenty:leaves_4:3)
Block(1,8,6,biomesoplenty:leaves_4:3)
Block(1,8,8,biomesoplenty:leaves_4:3)
Block(1,8,9,biomesoplenty:leaves_4:3)
Block(1,9,0,biomesoplenty:log_2:5)
Block(1,9,4,biomesoplenty:leaves_4:3)
Block(1,9,5,biomesoplenty:log_2:5)
Block(1,9,6,biomesoplenty:leaves_4:3)
Block(1,10,0,biomesoplenty:log_2:5)
Block(1,10,4,biomesoplenty:leaves_4:3)
Block(1,10,5,biomesoplenty:log_2:5)
Block(1,10,6,biomesoplenty:leaves_4:3)
Block(1,11,0,biomesoplenty:log_2:5)
Block(1,11,4,biomesoplenty:leaves_4:3)
Block(1,11,5,biomesoplenty:log_2:5)
Block(1,11,6,biomesoplenty:leaves_4:3)
Block(1,11,11,biomesoplenty:leaves_4:3)
Block(1,12,0,biomesoplenty:log_2:5)
Block(1,12,5,biomesoplenty:leaves_4:3)
Block(1,12,11,biomesoplenty:leaves_4:3)
Block(1,13,11,biomesoplenty:leaves_4:3)
Block(1,13,13,biomesoplenty:leaves_4:3)
Block(1,14,3,biomesoplenty:leaves_4:3)
Block(1,14,10,biomesoplenty:leaves_4:3)
Block(1,14,11,biomesoplenty:leaves_4:3)
Block(1,14,12,biomesoplenty:leaves_4:3)
Block(1,14,13,biomesoplenty:leaves_4:3)
Block(1,15,3,biomesoplenty:leaves_4:3)
Block(1,15,10,biomesoplenty:leaves_4:3)
Block(1,15,11,biomesoplenty:leaves_4:3)
Block(1,15,12,biomesoplenty:leaves_4:3)
Block(1,15,13,biomesoplenty:leaves_4:3)
Block(1,15,14,biomesoplenty:leaves_4:3)
Block(1,16,3,biomesoplenty:leaves_4:3)
Block(1,16,6,biomesoplenty:leaves_4:3)
Block(1,16,7,biomesoplenty:leaves_4:3)
Block(1,16,9,biomesoplenty:leaves_4:3)
Block(1,16,10,biomesoplenty:leaves_4:3)
Block(1,16,11,biomesoplenty:leaves_4:3)
Block(1,16,12,biomesoplenty:leaves_4:3)
Block(1,16,13,biomesoplenty:log_2:5)
Block(1,16,14,biomesoplenty:leaves_4:3)
Block(1,17,3,biomesoplenty:leaves_4:3)
Block(1,17,4,biomesoplenty:leaves_4:3)
Block(1,17,6,biomesoplenty:leaves_4:3)
Block(1,17,7,biomesoplenty:leaves_4:3)
Block(1,17,8,biomesoplenty:leaves_4:3)
Block(1,17,9,biomesoplenty:leaves_4:3)
Block(1,17,10,biomesoplenty:leaves_4:3)
Block(1,17,12,biomesoplenty:leaves_4:3)
Block(1,17,13,biomesoplenty:log_2:5)
Block(1,17,14,biomesoplenty:leaves_4:3)
Block(1,18,3,biomesoplenty:leaves_4:3)
Block(1,18,4,biomesoplenty:log_2:5)
Block(1,18,5,biomesoplenty:leaves_4:3)
Block(1,18,6,biomesoplenty:leaves_4:3)
Block(1,18,7,biomesoplenty:leaves_4:3)
Block(1,18,8,biomesoplenty:leaves_4:3)
Block(1,18,9,biomesoplenty:leaves_4:3)
Block(1,18,12,biomesoplenty:leaves_4:3)
Block(1,18,13,biomesoplenty:log_2:5)
Block(1,18,14,biomesoplenty:leaves_4:3)
Block(1,19,4,biomesoplenty:leaves_4:3)
Block(1,19,6,biomesoplenty:leaves_4:3)
Block(1,19,7,biomesoplenty:log_2:5)
Block(1,19,8,biomesoplenty:leaves_4:3)
Block(1,19,12,biomesoplenty:leaves_4:3)
Block(1,19,13,biomesoplenty:leaves_4:3)
Block(1,20,7,biomesoplenty:leaves_4:3)
Block(2,-2,-1,biomesoplenty:log_2:5)
Block(2,-1,-1,biomesoplenty:log_2:5)
Block(2,4,4,biomesoplenty:leaves_4:3)
Block(2,4,9,biomesoplenty:leaves_4:3)
Block(2,5,4,biomesoplenty:leaves_4:3)
Block(2,5,9,biomesoplenty:leaves_4:3)
Block(2,6,4,biomesoplenty:leaves_4:3)
Block(2,6,9,biomesoplenty:leaves_4:3)
Block(2,7,3,biomesoplenty:leaves_4:3)
Block(2,7,4,biomesoplenty:leaves_4:3)
Block(2,7,6,biomesoplenty:leaves_4:3)
Block(2,7,7,biomesoplenty:leaves_4:3)
Block(2,7,9,biomesoplenty:leaves_4:3)
Block(2,8,3,biomesoplenty:leaves_4:3)
Block(2,8,4,biomesoplenty:log_2:5)
Block(2,8,5,biomesoplenty:leaves_4:3)
Block(2,8,6,biomesoplenty:leaves_4:3)
Block(2,9,3,biomesoplenty:leaves_4:3)
Block(2,9,4,biomesoplenty:log_2:5)
Block(2,9,5,biomesoplenty:leaves_4:3)
Block(2,9,6,biomesoplenty:leaves_4:3)
Block(2,10,3,biomesoplenty:leaves_4:3)
Block(2,10,4,biomesoplenty:log_2:5)
Block(2,10,5,biomesoplenty:log_2:5)
Block(2,10,6,biomesoplenty:leaves_4:3)
Block(2,11,4,biomesoplenty:leaves_4:3)
Block(2,11,5,biomesoplenty:leaves_4:3)
Block(2,12,1,biomesoplenty:log_2:5)
Block(2,12,11,biomesoplenty:leaves_4:3)
Block(2,13,1,biomesoplenty:log_2:5)
Block(2,13,6,biomesoplenty:leaves_4:3)
Block(2,13,11,biomesoplenty:leaves_4:3)
Block(2,14,1,biomesoplenty:log_2:5)
Block(2,14,6,biomesoplenty:leaves_4:3)
Block(2,14,7,biomesoplenty:leaves_4:3)
Block(2,14,8,biomesoplenty:leaves_4:3)
Block(2,14,11,biomesoplenty:leaves_4:3)
Block(2,15,1,biomesoplenty:log_2:5)
Block(2,15,5,biomesoplenty:leaves_4:3)
Block(2,15,6,biomesoplenty:leaves_4:3)
Block(2,15,7,biomesoplenty:leaves_4:3)
Block(2,15,8,biomesoplenty:leaves_4:3)
Block(2,15,11,biomesoplenty:leaves_4:3)
Block(2,15,12,biomesoplenty:leaves_4:3)
Block(2,16,3,biomesoplenty:leaves_4:3)
Block(2,16,4,biomesoplenty:leaves_4:3)
Block(2,16,5,biomesoplenty:leaves_4:3)
Block(2,16,6,biomesoplenty:log_2:5)
Block(2,16,7,biomesoplenty:leaves_4:3)
Block(2,16,8,biomesoplenty:leaves_4:3)
Block(2,16,9,biomesoplenty:leaves_4:3)
Block(2,16,10,biomesoplenty:leaves_4:3)
Block(2,16,11,biomesoplenty:leaves_4:3)
Block(2,16,12,biomesoplenty:leaves_4:3)
Block(2,16,13,biomesoplenty:leaves_4:3)
Block(2,17,2,biomesoplenty:leaves_4:3)
Block(2,17,3,biomesoplenty:log_2:5)
Block(2,17,4,biomesoplenty:leaves_4:3)
Block(2,17,5,biomesoplenty:leaves_4:3)
Block(2,17,6,biomesoplenty:log_2:5)
Block(2,17,7,biomesoplenty:leaves_4:3)
Block(2,17,8,biomesoplenty:leaves_4:3)
Block(2,17,11,biomesoplenty:leaves_4:3)
Block(2,17,12,biomesoplenty:leaves_4:3)
Block(2,17,13,biomesoplenty:leaves_4:3)
Block(2,18,3,biomesoplenty:leaves_4:3)
Block(2,18,4,biomesoplenty:log_2:5)
Block(2,18,5,biomesoplenty:log_2:5)
Block(2,18,6,biomesoplenty:log_2:5)
Block(2,18,7,biomesoplenty:leaves_4:3)
Block(2,18,11,biomesoplenty:leaves_4:3)
Block(2,18,12,biomesoplenty:leaves_4:3)
Block(2,18,13,biomesoplenty:leaves_4:3)
Block(2,19,4,biomesoplenty:leaves_4:3)
Block(2,19,5,biomesoplenty:leaves_4:3)
Block(2,19,6,biomesoplenty:log_2:5)
Block(2,19,7,biomesoplenty:leaves_4:3)
Block(2,19,11,biomesoplenty:leaves_4:3)
Block(2,19,12,biomesoplenty:log_2:5)
Block(2,19,13,biomesoplenty:leaves_4:3)
Block(2,20,6,biomesoplenty:leaves_4:3)
Block(2,20,11,biomesoplenty:leaves_4:3)
Block(2,20,12,biomesoplenty:leaves_4:3)
Block(3,3,6,biomesoplenty:leaves_4:3)
Block(3,4,6,biomesoplenty:leaves_4:3)
Block(3,5,6,biomesoplenty:leaves_4:3)
Block(3,5,7,biomesoplenty:leaves_4:3)
Block(3,6,6,biomesoplenty:leaves_4:3)
Block(3,6,7,biomesoplenty:leaves_4:3)
Block(3,7,4,biomesoplenty:leaves_4:3)
Block(3,7,5,biomesoplenty:leaves_4:3)
Block(3,7,6,biomesoplenty:log_2:5)
Block(3,7,7,biomesoplenty:leaves_4:3)
Block(3,8,4,biomesoplenty:leaves_4:3)
Block(3,8,5,biomesoplenty:leaves_4:3)
Block(3,8,6,biomesoplenty:log_2:5)
Block(3,8,7,biomesoplenty:leaves_4:3)
Block(3,9,4,biomesoplenty:leaves_4:3)
Block(3,9,5,biomesoplenty:log_2:5)
Block(3,9,6,biomesoplenty:log_2:5)
Block(3,9,7,biomesoplenty:leaves_4:3)
Block(3,9,11,biomesoplenty:leaves_4:3)
Block(3,10,4,biomesoplenty:leaves_4:3)
Block(3,10,5,biomesoplenty:leaves_4:3)
Block(3,10,6,biomesoplenty:leaves_4:3)
Block(3,10,11,biomesoplenty:leaves_4:3)
Block(3,11,11,biomesoplenty:leaves_4:3)
Block(3,12,8,biomesoplenty:leaves_4:3)
Block(3,12,11,biomesoplenty:leaves_4:3)
Block(3,12,12,biomesoplenty:leaves_4:3)
Block(3,13,8,biomesoplenty:leaves_4:3)
Block(3,13,10,biomesoplenty:leaves_4:3)
Block(3,13,11,biomesoplenty:log_2:5)
Block(3,13,12,biomesoplenty:leaves_4:3)
Block(3,14,8,biomesoplenty:leaves_4:3)
Block(3,14,10,biomesoplenty:leaves_4:3)
Block(3,14,11,biomesoplenty:log_2:5)
Block(3,14,12,biomesoplenty:leaves_4:3)
Block(3,15,2,biomesoplenty:log_2:5)
Block(3,15,7,biomesoplenty:leaves_4:3)
Block(3,15,8,biomesoplenty:log_2:5)
Block(3,15,9,biomesoplenty:leaves_4:3)
Block(3,15,10,biomesoplenty:leaves_4:3)
Block(3,15,11,biomesoplenty:log_2:5)
Block(3,15,12,biomesoplenty:leaves_4:3)
Block(3,16,2,biomesoplenty:log_2:5)
Block(3,16,3,biomesoplenty:leaves_4:3)
Block(3,16,6,biomesoplenty:leaves_4:3)
Block(3,16,7,biomesoplenty:leaves_4:3)
Block(3,16,8,biomesoplenty:log_2:5)
Block(3,16,9,biomesoplenty:log_2:5)
Block(3,16,10,biomesoplenty:log_2:5)
Block(3,16,11,biomesoplenty:leaves_4:3)
Block(3,16,12,biomesoplenty:leaves_4:3)
Block(3,17,2,biomesoplenty:log_2:5)
Block(3,17,3,biomesoplenty:leaves_4:3)
Block(3,17,4,biomesoplenty:leaves_4:3)
Block(3,17,5,biomesoplenty:leaves_4:3)
Block(3,17,6,biomesoplenty:leaves_4:3)
Block(3,17,7,biomesoplenty:leaves_4:3)
Block(3,17,8,biomesoplenty:log_2:5)
Block(3,17,9,biomesoplenty:leaves_4:3)
Block(3,17,10,biomesoplenty:leaves_4:3)
Block(3,17,11,biomesoplenty:leaves_4:3)
Block(3,17,12,biomesoplenty:leaves_4:3)
Block(3,18,4,biomesoplenty:leaves_4:3)
Block(3,18,5,biomesoplenty:leaves_4:3)
Block(3,18,6,biomesoplenty:leaves_4:3)
Block(3,18,8,biomesoplenty:leaves_4:3)
Block(3,18,10,biomesoplenty:leaves_4:3)
Block(3,18,11,biomesoplenty:log_2:5)
Block(3,18,12,biomesoplenty:leaves_4:3)
Block(3,19,6,biomesoplenty:leaves_4:3)
Block(3,19,7,biomesoplenty:log_2:5)
Block(3,19,8,biomesoplenty:leaves_4:3)
Block(3,19,10,biomesoplenty:leaves_4:3)
Block(3,19,11,biomesoplenty:log_2:5)
Block(3,19,12,biomesoplenty:leaves_4:3)
Block(3,20,7,biomesoplenty:leaves_4:3)
Block(3,20,10,biomesoplenty:leaves_4:3)
Block(3,20,11,biomesoplenty:log_2:5)
Block(3,20,12,biomesoplenty:leaves_4:3)
Block(3,21,11,biomesoplenty:leaves_4:3)
Block(4,6,6,biomesoplenty:leaves_4:3)
Block(4,7,6,biomesoplenty:leaves_4:3)
Block(4,8,5,biomesoplenty:leaves_4:3)
Block(4,8,6,biomesoplenty:leaves_4:3)
Block(4,9,5,biomesoplenty:leaves_4:3)
Block(4,9,6,biomesoplenty:leaves_4:3)
Block(4,11,11,biomesoplenty:leaves_4:3)
Block(4,12,11,biomesoplenty:leaves_4:3)
Block(4,13,11,biomesoplenty:leaves_4:3)
Block(4,14,10,biomesoplenty:leaves_4:3)
Block(4,14,11,biomesoplenty:leaves_4:3)
Block(4,14,12,biomesoplenty:leaves_4:3)
Block(4,14,13,biomesoplenty:leaves_4:3)
Block(4,15,8,biomesoplenty:leaves_4:3)
Block(4,15,10,biomesoplenty:leaves_4:3)
Block(4,15,11,biomesoplenty:leaves_4:3)
Block(4,15,12,biomesoplenty:leaves_4:3)
Block(4,15,13,biomesoplenty:leaves_4:3)
Block(4,16,6,biomesoplenty:leaves_4:3)
Block(4,16,7,biomesoplenty:leaves_4:3)
Block(4,16,8,biomesoplenty:leaves_4:3)
Block(4,16,9,biomesoplenty:leaves_4:3)
Block(4,16,10,biomesoplenty:leaves_4:3)
Block(4,16,11,biomesoplenty:leaves_4:3)
Block(4,16,12,biomesoplenty:leaves_4:3)
Block(4,16,13,biomesoplenty:leaves_4:3)
Block(4,17,3,biomesoplenty:log_2:5)
Block(4,17,4,biomesoplenty:leaves_4:3)
Block(4,17,5,biomesoplenty:leaves_4:3)
Block(4,17,6,biomesoplenty:leaves_4:3)
Block(4,17,7,biomesoplenty:leaves_4:3)
Block(4,17,8,biomesoplenty:leaves_4:3)
Block(4,17,9,biomesoplenty:leaves_4:3)
Block(4,17,10,biomesoplenty:leaves_4:3)
Block(4,17,11,biomesoplenty:leaves_4:3)
Block(4,17,12,biomesoplenty:leaves_4:3)
Block(4,18,3,biomesoplenty:log_2:5)
Block(4,18,4,biomesoplenty:leaves_4:3)
Block(4,18,5,biomesoplenty:leaves_4:3)
Block(4,18,6,biomesoplenty:leaves_4:3)
Block(4,18,7,biomesoplenty:leaves_4:3)
Block(4,18,8,biomesoplenty:log_2:5)
Block(4,18,9,biomesoplenty:leaves_4:3)
Block(4,18,10,biomesoplenty:leaves_4:3)
Block(4,18,11,biomesoplenty:leaves_4:3)
Block(4,19,3,biomesoplenty:leaves_4:3)
Block(4,19,4,biomesoplenty:leaves_4:3)
Block(4,19,7,biomesoplenty:leaves_4:3)
Block(4,19,8,biomesoplenty:leaves_4:3)
Block(4,19,9,biomesoplenty:leaves_4:3)
Block(4,19,10,biomesoplenty:leaves_4:3)
Block(4,19,11,biomesoplenty:leaves_4:3)
Block(4,20,9,biomesoplenty:leaves_4:3)
Block(4,20,10,biomesoplenty:log_2:5)
Block(4,20,11,biomesoplenty:leaves_4:3)
Block(4,21,9,biomesoplenty:leaves_4:3)
Block(4,21,10,biomesoplenty:leaves_4:3)
Block(5,14,2,biomesoplenty:leaves_4:3)
Block(5,14,11,biomesoplenty:leaves_4:3)
Block(5,14,12,biomesoplenty:leaves_4:3)
Block(5,15,2,biomesoplenty:leaves_4:3)
Block(5,15,10,biomesoplenty:leaves_4:3)
Block(5,15,11,biomesoplenty:leaves_4:3)
Block(5,15,12,biomesoplenty:leaves_4:3)
Block(5,16,2,biomesoplenty:leaves_4:3)
Block(5,16,3,biomesoplenty:leaves_4:3)
Block(5,16,4,biomesoplenty:leaves_4:3)
Block(5,16,6,biomesoplenty:leaves_4:3)
Block(5,16,7,biomesoplenty:leaves_4:3)
Block(5,16,8,biomesoplenty:leaves_4:3)
Block(5,16,9,biomesoplenty:leaves_4:3)
Block(5,16,10,biomesoplenty:leaves_4:3)
Block(5,16,11,biomesoplenty:leaves_4:3)
Block(5,16,12,biomesoplenty:leaves_4:3)
Block(5,16,13,biomesoplenty:leaves_4:3)
Block(5,17,2,biomesoplenty:leaves_4:3)
Block(5,17,3,biomesoplenty:leaves_4:3)
Block(5,17,4,biomesoplenty:leaves_4:3)
Block(5,17,5,biomesoplenty:leaves_4:3)
Block(5,17,6,biomesoplenty:leaves_4:3)
Block(5,17,7,biomesoplenty:leaves_4:3)
Block(5,17,8,biomesoplenty:log_2:5)
Block(5,17,9,biomesoplenty:leaves_4:3)
Block(5,17,10,biomesoplenty:leaves_4:3)
Block(5,17,11,biomesoplenty:leaves_4:3)
Block(5,17,12,biomesoplenty:leaves_4:3)
Block(5,17,13,biomesoplenty:leaves_4:3)
Block(5,18,2,biomesoplenty:leaves_4:3)
Block(5,18,3,biomesoplenty:log_2:5)
Block(5,18,4,biomesoplenty:log_2:5)
Block(5,18,5,biomesoplenty:leaves_4:3)
Block(5,18,6,biomesoplenty:leaves_4:3)
Block(5,18,7,biomesoplenty:leaves_4:3)
Block(5,18,8,biomesoplenty:leaves_4:3)
Block(5,18,9,biomesoplenty:leaves_4:3)
Block(5,18,10,biomesoplenty:leaves_4:3)
Block(5,18,11,biomesoplenty:leaves_4:3)
Block(5,18,12,biomesoplenty:leaves_4:3)
Block(5,19,2,biomesoplenty:leaves_4:3)
Block(5,19,3,biomesoplenty:leaves_4:3)
Block(5,19,4,biomesoplenty:log_2:5)
Block(5,19,5,biomesoplenty:leaves_4:3)
Block(5,19,7,biomesoplenty:leaves_4:3)
Block(5,19,8,biomesoplenty:leaves_4:3)
Block(5,19,9,biomesoplenty:leaves_4:3)
Block(5,19,10,biomesoplenty:leaves_4:3)
Block(5,19,11,biomesoplenty:leaves_4:3)
Block(5,19,12,biomesoplenty:leaves_4:3)
Block(5,20,4,biomesoplenty:leaves_4:3)
Block(5,20,8,biomesoplenty:leaves_4:3)
Block(5,20,9,biomesoplenty:leaves_4:3)
Block(5,20,10,biomesoplenty:log_2:5)
Block(5,20,11,biomesoplenty:leaves_4:3)
Block(5,21,8,biomesoplenty:leaves_4:3)
Block(5,21,9,biomesoplenty:log_2:5)
Block(5,21,10,biomesoplenty:log_2:5)
Block(5,21,11,biomesoplenty:leaves_4:3)
Block(5,22,9,biomesoplenty:leaves_4:3)
Block(5,22,10,biomesoplenty:leaves_4:3)
Block(6,11,10,biomesoplenty:leaves_4:3)
Block(6,12,2,biomesoplenty:leaves_4:3)
Block(6,12,10,biomesoplenty:leaves_4:3)
Block(6,13,-2,biomesoplenty:leaves_4:3)
Block(6,13,2,biomesoplenty:leaves_4:3)
Block(6,13,10,biomesoplenty:leaves_4:3)
Block(6,13,11,biomesoplenty:leaves_4:3)
Block(6,13,13,biomesoplenty:leaves_4:3)
Block(6,13,15,biomesoplenty:leaves_4:3)
Block(6,14,-2,biomesoplenty:leaves_4:3)
Block(6,14,2,biomesoplenty:leaves_4:3)
Block(6,14,3,biomesoplenty:leaves_4:3)
Block(6,14,9,biomesoplenty:leaves_4:3)
Block(6,14,10,biomesoplenty:leaves_4:3)
Block(6,14,11,biomesoplenty:leaves_4:3)
Block(6,14,12,biomesoplenty:leaves_4:3)
Block(6,14,13,biomesoplenty:leaves_4:3)
Block(6,14,15,biomesoplenty:leaves_4:3)
Block(6,15,-2,biomesoplenty:leaves_4:3)
Block(6,15,0,biomesoplenty:leaves_4:3)
Block(6,15,1,biomesoplenty:leaves_4:3)
Block(6,15,2,biomesoplenty:log_2:5)
Block(6,15,3,biomesoplenty:leaves_4:3)
Block(6,15,7,biomesoplenty:leaves_4:3)
Block(6,15,8,biomesoplenty:leaves_4:3)
Block(6,15,9,biomesoplenty:leaves_4:3)
Block(6,15,10,biomesoplenty:log_2:5)
Block(6,15,11,biomesoplenty:leaves_4:3)
Block(6,15,12,biomesoplenty:leaves_4:3)
Block(6,15,13,biomesoplenty:leaves_4:3)
Block(6,16,0,biomesoplenty:leaves_4:3)
Block(6,16,1,biomesoplenty:leaves_4:3)
Block(6,16,2,biomesoplenty:log_2:5)
Block(6,16,3,biomesoplenty:leaves_4:3)
Block(6,16,4,biomesoplenty:leaves_4:3)
Block(6,16,7,biomesoplenty:leaves_4:3)
Block(6,16,8,biomesoplenty:leaves_4:3)
Block(6,16,9,biomesoplenty:leaves_4:3)
Block(6,16,10,biomesoplenty:log_2:5)
Block(6,16,11,biomesoplenty:leaves_4:3)
Block(6,16,12,biomesoplenty:log_2:5)
Block(6,16,13,biomesoplenty:leaves_4:3)
Block(6,17,0,biomesoplenty:leaves_4:3)
Block(6,17,1,biomesoplenty:leaves_4:3)
Block(6,17,2,biomesoplenty:log_2:5)
Block(6,17,3,biomesoplenty:leaves_4:3)
Block(6,17,4,biomesoplenty:leaves_4:3)
Block(6,17,5,biomesoplenty:leaves_4:3)
Block(6,17,6,biomesoplenty:leaves_4:3)
Block(6,17,8,biomesoplenty:leaves_4:3)
Block(6,17,9,biomesoplenty:log_2:5)
Block(6,17,10,biomesoplenty:log_2:5)
Block(6,17,11,biomesoplenty:leaves_4:3)
Block(6,17,12,biomesoplenty:log_2:5)
Block(6,17,13,biomesoplenty:leaves_4:3)
Block(6,18,0,biomesoplenty:leaves_4:3)
Block(6,18,1,biomesoplenty:leaves_4:3)
Block(6,18,2,biomesoplenty:log_2:5)
Block(6,18,3,biomesoplenty:leaves_4:3)
Block(6,18,4,biomesoplenty:leaves_4:3)
Block(6,18,5,biomesoplenty:leaves_4:3)
Block(6,18,6,biomesoplenty:leaves_4:3)
Block(6,18,7,biomesoplenty:leaves_4:3)
Block(6,18,8,biomesoplenty:leaves_4:3)
Block(6,18,9,biomesoplenty:leaves_4:3)
Block(6,18,10,biomesoplenty:leaves_4:3)
Block(6,18,11,biomesoplenty:leaves_4:3)
Block(6,18,12,biomesoplenty:log_2:5)
Block(6,18,13,biomesoplenty:leaves_4:3)
Block(6,19,1,biomesoplenty:leaves_4:3)
Block(6,19,2,biomesoplenty:log_2:5)
Block(6,19,3,biomesoplenty:leaves_4:3)
Block(6,19,4,biomesoplenty:leaves_4:3)
Block(6,19,5,biomesoplenty:log_2:5)
Block(6,19,6,biomesoplenty:leaves_4:3)
Block(6,19,7,biomesoplenty:leaves_4:3)
Block(6,19,8,biomesoplenty:log_2:5)
Block(6,19,9,biomesoplenty:leaves_4:3)
Block(6,19,10,biomesoplenty:leaves_4:3)
Block(6,19,11,biomesoplenty:leaves_4:3)
Block(6,19,12,biomesoplenty:log_2:5)
Block(6,19,13,biomesoplenty:leaves_4:3)
Block(6,20,2,biomesoplenty:leaves_4:3)
Block(6,20,5,biomesoplenty:leaves_4:3)
Block(6,20,6,biomesoplenty:leaves_4:3)
Block(6,20,7,biomesoplenty:leaves_4:3)
Block(6,20,8,biomesoplenty:log_2:5)
Block(6,20,9,biomesoplenty:leaves_4:3)
Block(6,20,10,biomesoplenty:leaves_4:3)
Block(6,20,11,biomesoplenty:log_2:5)
Block(6,20,12,biomesoplenty:leaves_4:3)
Block(6,21,8,biomesoplenty:leaves_4:3)
Block(6,21,9,biomesoplenty:log_2:5)
Block(6,21,10,biomesoplenty:log_2:5)
Block(6,21,11,biomesoplenty:leaves_4:3)
Block(6,22,9,biomesoplenty:leaves_4:3)
Block(6,22,10,biomesoplenty:leaves_4:3)
Block(7,11,8,biomesoplenty:leaves_4:3)
Block(7,12,-3,biomesoplenty:leaves_4:3)
Block(7,12,0,biomesoplenty:leaves_4:3)
Block(7,12,3,biomesoplenty:leaves_4:3)
Block(7,12,8,biomesoplenty:leaves_4:3)
Block(7,13,-3,biomesoplenty:leaves_4:3)
Block(7,13,0,biomesoplenty:leaves_4:3)
Block(7,13,2,biomesoplenty:leaves_4:3)
Block(7,13,3,biomesoplenty:leaves_4:3)
Block(7,13,7,biomesoplenty:leaves_4:3)
Block(7,13,8,biomesoplenty:leaves_4:3)
Block(7,13,9,biomesoplenty:leaves_4:3)
Block(7,14,-3,biomesoplenty:leaves_4:3)
Block(7,14,-2,biomesoplenty:leaves_4:3)
Block(7,14,0,biomesoplenty:leaves_4:3)
Block(7,14,1,biomesoplenty:leaves_4:3)
Block(7,14,2,biomesoplenty:leaves_4:3)
Block(7,14,3,biomesoplenty:leaves_4:3)
Block(7,14,6,biomesoplenty:leaves_4:3)
Block(7,14,7,biomesoplenty:leaves_4:3)
Block(7,14,8,biomesoplenty:leaves_4:3)
Block(7,14,9,biomesoplenty:leaves_4:3)
Block(7,14,10,biomesoplenty:leaves_4:3)
Block(7,14,11,biomesoplenty:leaves_4:3)
Block(7,14,12,biomesoplenty:leaves_4:3)
Block(7,14,13,biomesoplenty:leaves_4:3)
Block(7,14,14,biomesoplenty:leaves_4:3)
Block(7,14,15,biomesoplenty:leaves_4:3)
Block(7,15,-3,biomesoplenty:leaves_4:3)
Block(7,15,-2,biomesoplenty:leaves_4:3)
Block(7,15,-1,biomesoplenty:leaves_4:3)
Block(7,15,0,biomesoplenty:leaves_4:3)
Block(7,15,1,biomesoplenty:leaves_4:3)
Block(7,15,2,biomesoplenty:leaves_4:3)
Block(7,15,3,biomesoplenty:leaves_4:3)
Block(7,15,4,biomesoplenty:leaves_4:3)
Block(7,15,6,biomesoplenty:leaves_4:3)
Block(7,15,7,biomesoplenty:leaves_4:3)
Block(7,15,8,biomesoplenty:log_2:5)
Block(7,15,9,biomesoplenty:leaves_4:3)
Block(7,15,10,biomesoplenty:leaves_4:3)
Block(7,15,11,biomesoplenty:leaves_4:3)
Block(7,15,12,biomesoplenty:leaves_4:3)
Block(7,15,13,biomesoplenty:leaves_4:3)
Block(7,15,14,biomesoplenty:leaves_4:3)
Block(7,15,15,biomesoplenty:leaves_4:3)
Block(7,16,-3,biomesoplenty:leaves_4:3)
Block(7,16,-2,biomesoplenty:leaves_4:3)
Block(7,16,-1,biomesoplenty:leaves_4:3)
Block(7,16,0,biomesoplenty:log_2:5)
Block(7,16,1,biomesoplenty:leaves_4:3)
Block(7,16,2,biomesoplenty:leaves_4:3)
Block(7,16,3,biomesoplenty:leaves_4:3)
Block(7,16,4,biomesoplenty:leaves_4:3)
Block(7,16,5,biomesoplenty:leaves_4:3)
Block(7,16,6,biomesoplenty:leaves_4:3)
Block(7,16,7,biomesoplenty:log_2:5)
Block(7,16,8,biomesoplenty:log_2:5)
Block(7,16,9,biomesoplenty:leaves_4:3)
Block(7,16,10,biomesoplenty:leaves_4:3)
Block(7,16,11,biomesoplenty:leaves_4:3)
Block(7,16,12,biomesoplenty:leaves_4:3)
Block(7,16,13,biomesoplenty:leaves_4:3)
Block(7,16,14,biomesoplenty:leaves_4:3)
Block(7,16,15,biomesoplenty:leaves_4:3)
Block(7,17,-2,biomesoplenty:leaves_4:3)
Block(7,17,-1,biomesoplenty:leaves_4:3)
Block(7,17,0,biomesoplenty:log_2:5)
Block(7,17,1,biomesoplenty:leaves_4:3)
Block(7,17,2,biomesoplenty:leaves_4:3)
Block(7,17,3,biomesoplenty:leaves_4:3)
Block(7,17,4,biomesoplenty:leaves_4:3)
Block(7,17,5,biomesoplenty:leaves_4:3)
Block(7,17,6,biomesoplenty:leaves_4:3)
Block(7,17,7,biomesoplenty:leaves_4:3)
Block(7,17,8,biomesoplenty:leaves_4:3)
Block(7,17,9,biomesoplenty:leaves_4:3)
Block(7,17,10,biomesoplenty:leaves_4:3)
Block(7,17,11,biomesoplenty:leaves_4:3)
Block(7,17,12,biomesoplenty:leaves_4:3)
Block(7,17,14,biomesoplenty:leaves_4:3)
Block(7,18,-1,biomesoplenty:leaves_4:3)
Block(7,18,0,biomesoplenty:log_2:5)
Block(7,18,1,biomesoplenty:leaves_4:3)
Block(7,18,2,biomesoplenty:leaves_4:3)
Block(7,18,3,biomesoplenty:leaves_4:3)
Block(7,18,4,biomesoplenty:leaves_4:3)
Block(7,18,6,biomesoplenty:log_2:5)
Block(7,18,7,biomesoplenty:leaves_4:3)
Block(7,18,8,biomesoplenty:leaves_4:3)
Block(7,18,9,biomesoplenty:leaves_4:3)
Block(7,18,10,biomesoplenty:leaves_4:3)
Block(7,18,11,biomesoplenty:leaves_4:3)
Block(7,18,12,biomesoplenty:leaves_4:3)
Block(7,18,13,biomesoplenty:leaves_4:3)
Block(7,18,14,biomesoplenty:leaves_4:3)
Block(7,19,0,biomesoplenty:leaves_4:3)
Block(7,19,1,biomesoplenty:log_2:5)
Block(7,19,2,biomesoplenty:leaves_4:3)
Block(7,19,3,biomesoplenty:leaves_4:3)
Block(7,19,5,biomesoplenty:leaves_4:3)
Block(7,19,6,biomesoplenty:log_2:5)
Block(7,19,7,biomesoplenty:leaves_4:3)
Block(7,19,8,biomesoplenty:leaves_4:3)
Block(7,19,9,biomesoplenty:leaves_4:3)
Block(7,19,10,biomesoplenty:leaves_4:3)
Block(7,19,11,biomesoplenty:leaves_4:3)
Block(7,19,12,biomesoplenty:leaves_4:3)
Block(7,19,13,biomesoplenty:log_2:5)
Block(7,19,14,biomesoplenty:leaves_4:3)
Block(7,20,1,biomesoplenty:leaves_4:3)
Block(7,20,5,biomesoplenty:leaves_4:3)
Block(7,20,6,biomesoplenty:log_2:5)
Block(7,20,7,biomesoplenty:leaves_4:3)
Block(7,20,8,biomesoplenty:log_2:5)
Block(7,20,9,biomesoplenty:leaves_4:3)
Block(7,20,10,biomesoplenty:leaves_4:3)
Block(7,20,11,biomesoplenty:leaves_4:3)
Block(7,20,13,biomesoplenty:leaves_4:3)
Block(7,21,6,biomesoplenty:leaves_4:3)
Block(7,21,8,biomesoplenty:leaves_4:3)
Block(7,21,9,biomesoplenty:leaves_4:3)
Block(7,21,10,biomesoplenty:leaves_4:3)
Block(8,9,-4,biomesoplenty:leaves_4:3)
Block(8,9,6,biomesoplenty:leaves_4:3)
Block(8,10,-4,biomesoplenty:leaves_4:3)
Block(8,10,-3,biomesoplenty:leaves_4:3)
Block(8,10,6,biomesoplenty:leaves_4:3)
Block(8,11,-4,biomesoplenty:leaves_4:3)
Block(8,11,-3,biomesoplenty:leaves_4:3)
Block(8,11,6,biomesoplenty:leaves_4:3)
Block(8,11,13,biomesoplenty:leaves_4:3)
Block(8,12,-4,biomesoplenty:leaves_4:3)
Block(8,12,-3,biomesoplenty:leaves_4:3)
Block(8,12,6,biomesoplenty:leaves_4:3)
Block(8,12,13,biomesoplenty:leaves_4:3)
Block(8,12,16,biomesoplenty:leaves_4:3)
Block(8,13,-4,biomesoplenty:leaves_4:3)
Block(8,13,-3,biomesoplenty:leaves_4:3)
Block(8,13,-2,biomesoplenty:leaves_4:3)
Block(8,13,0,biomesoplenty:leaves_4:3)
Block(8,13,3,biomesoplenty:leaves_4:3)
Block(8,13,5,biomesoplenty:leaves_4:3)
Block(8,13,6,biomesoplenty:leaves_4:3)
Block(8,13,7,biomesoplenty:leaves_4:3)
Block(8,13,8,biomesoplenty:leaves_4:3)
Block(8,13,9,biomesoplenty:leaves_4:3)
Block(8,13,10,biomesoplenty:leaves_4:3)
Block(8,13,12,biomesoplenty:leaves_4:3)
Block(8,13,13,biomesoplenty:leaves_4:3)
Block(8,13,14,biomesoplenty:leaves_4:3)
Block(8,13,16,biomesoplenty:leaves_4:3)
Block(8,14,-4,biomesoplenty:leaves_4:3)
Block(8,14,-3,biomesoplenty:log_2:5)
Block(8,14,-2,biomesoplenty:leaves_4:3)
Block(8,14,-1,biomesoplenty:leaves_4:3)
Block(8,14,0,biomesoplenty:leaves_4:3)
Block(8,14,2,biomesoplenty:leaves_4:3)
Block(8,14,3,biomesoplenty:leaves_4:3)
Block(8,14,5,biomesoplenty:leaves_4:3)
Block(8,14,6,biomesoplenty:log_2:5)
Block(8,14,7,biomesoplenty:leaves_4:3)
Block(8,14,8,biomesoplenty:leaves_4:3)
Block(8,14,9,biomesoplenty:leaves_4:3)
Block(8,14,10,biomesoplenty:leaves_4:3)
Block(8,14,11,biomesoplenty:leaves_4:3)
Block(8,14,12,biomesoplenty:leaves_4:3)
Block(8,14,13,biomesoplenty:log_2:5)
Block(8,14,14,biomesoplenty:leaves_4:3)
Block(8,14,15,biomesoplenty:leaves_4:3)
Block(8,14,16,biomesoplenty:leaves_4:3)
Block(8,15,-4,biomesoplenty:leaves_4:3)
Block(8,15,-3,biomesoplenty:log_2:5)
Block(8,15,-2,biomesoplenty:leaves_4:3)
Block(8,15,-1,biomesoplenty:leaves_4:3)
Block(8,15,0,biomesoplenty:leaves_4:3)
Block(8,15,1,biomesoplenty:leaves_4:3)
Block(8,15,2,biomesoplenty:leaves_4:3)
Block(8,15,3,biomesoplenty:leaves_4:3)
Block(8,15,4,biomesoplenty:leaves_4:3)
Block(8,15,5,biomesoplenty:leaves_4:3)
Block(8,15,6,biomesoplenty:log_2:5)
Block(8,15,7,biomesoplenty:leaves_4:3)
Block(8,15,8,biomesoplenty:leaves_4:3)
Block(8,15,9,biomesoplenty:leaves_4:3)
Block(8,15,10,biomesoplenty:leaves_4:3)
Block(8,15,11,biomesoplenty:leaves_4:3)
Block(8,15,12,biomesoplenty:leaves_4:3)
Block(8,15,13,biomesoplenty:log_2:5)
Block(8,15,14,biomesoplenty:leaves_4:3)
Block(8,15,15,biomesoplenty:leaves_4:3)
Block(8,15,16,biomesoplenty:leaves_4:3)
Block(8,16,-4,biomesoplenty:leaves_4:3)
Block(8,16,-3,biomesoplenty:log_2:5)
Block(8,16,-2,biomesoplenty:leaves_4:3)
Block(8,16,-1,biomesoplenty:leaves_4:3)
Block(8,16,0,biomesoplenty:leaves_4:3)
Block(8,16,1,biomesoplenty:leaves_4:3)
Block(8,16,2,biomesoplenty:leaves_4:3)
Block(8,16,3,biomesoplenty:leaves_4:3)
Block(8,16,4,biomesoplenty:leaves_4:3)
Block(8,16,5,biomesoplenty:leaves_4:3)
Block(8,16,6,biomesoplenty:log_2:5)
Block(8,16,7,biomesoplenty:leaves_4:3)
Block(8,16,8,biomesoplenty:leaves_4:3)
Block(8,16,9,biomesoplenty:leaves_4:3)
Block(8,16,10,biomesoplenty:leaves_4:3)
Block(8,16,11,biomesoplenty:leaves_4:3)
Block(8,16,12,biomesoplenty:leaves_4:3)
Block(8,16,13,biomesoplenty:log_2:5)
Block(8,16,14,biomesoplenty:leaves_4:3)
Block(8,17,-3,biomesoplenty:leaves_4:3)
Block(8,17,-2,biomesoplenty:log_2:5)
Block(8,17,-1,biomesoplenty:leaves_4:3)
Block(8,17,0,biomesoplenty:leaves_4:3)
Block(8,17,1,biomesoplenty:leaves_4:3)
Block(8,17,2,biomesoplenty:leaves_4:3)
Block(8,17,3,biomesoplenty:leaves_4:3)
Block(8,17,4,biomesoplenty:log_2:5)
Block(8,17,5,biomesoplenty:log_2:5)
Block(8,17,6,biomesoplenty:leaves_4:3)
Block(8,17,7,biomesoplenty:leaves_4:3)
Block(8,17,8,biomesoplenty:leaves_4:3)
Block(8,17,9,biomesoplenty:leaves_4:3)
Block(8,17,10,biomesoplenty:leaves_4:3)
Block(8,17,11,biomesoplenty:leaves_4:3)
Block(8,17,12,biomesoplenty:leaves_4:3)
Block(8,17,13,biomesoplenty:leaves_4:3)
Block(8,18,-2,biomesoplenty:leaves_4:3)
Block(8,18,-1,biomesoplenty:log_2:5)
Block(8,18,0,biomesoplenty:log_2:5)
Block(8,18,1,biomesoplenty:leaves_4:3)
Block(8,18,2,biomesoplenty:leaves_4:3)
Block(8,18,3,biomesoplenty:leaves_4:3)
Block(8,18,4,biomesoplenty:leaves_4:3)
Block(8,18,5,biomesoplenty:leaves_4:3)
Block(8,18,6,biomesoplenty:leaves_4:3)
Block(8,18,7,biomesoplenty:leaves_4:3)
Block(8,18,8,biomesoplenty:leaves_4:3)
Block(8,18,9,biomesoplenty:leaves_4:3)
Block(8,18,10,biomesoplenty:leaves_4:3)
Block(8,18,11,biomesoplenty:leaves_4:3)
Block(8,18,12,biomesoplenty:leaves_4:3)
Block(8,18,13,biomesoplenty:leaves_4:3)
Block(8,19,-1,biomesoplenty:leaves_4:3)
Block(8,19,0,biomesoplenty:leaves_4:3)
Block(8,19,1,biomesoplenty:leaves_4:3)
Block(8,19,2,biomesoplenty:log_2:5)
Block(8,19,3,biomesoplenty:leaves_4:3)
Block(8,19,5,biomesoplenty:leaves_4:3)
Block(8,19,6,biomesoplenty:leaves_4:3)
Block(8,19,7,biomesoplenty:leaves_4:3)
Block(8,19,8,biomesoplenty:leaves_4:3)
Block(8,19,9,biomesoplenty:leaves_4:3)
Block(8,19,10,biomesoplenty:leaves_4:3)
Block(8,19,13,biomesoplenty:leaves_4:3)
Block(8,20,2,biomesoplenty:leaves_4:3)
Block(8,20,6,biomesoplenty:leaves_4:3)
Block(8,20,7,biomesoplenty:log_2:5)
Block(8,20,8,biomesoplenty:leaves_4:3)
Block(8,21,7,biomesoplenty:leaves_4:3)
Block(9,8,16,biomesoplenty:leaves_4:3)
Block(9,9,3,biomesoplenty:leaves_4:3)
Block(9,9,16,biomesoplenty:leaves_4:3)
Block(9,10,3,biomesoplenty:leaves_4:3)
Block(9,10,4,biomesoplenty:leaves_4:3)
Block(9,10,6,biomesoplenty:leaves_4:3)
Block(9,10,10,biomesoplenty:leaves_4:3)
Block(9,10,16,biomesoplenty:leaves_4:3)
Block(9,11,0,biomesoplenty:leaves_4:3)
Block(9,11,3,biomesoplenty:leaves_4:3)
Block(9,11,4,biomesoplenty:leaves_4:3)
Block(9,11,6,biomesoplenty:leaves_4:3)
Block(9,11,10,biomesoplenty:leaves_4:3)
Block(9,11,15,biomesoplenty:leaves_4:3)
Block(9,11,16,biomesoplenty:leaves_4:3)
Block(9,12,-4,biomesoplenty:leaves_4:3)
Block(9,12,0,biomesoplenty:leaves_4:3)
Block(9,12,2,biomesoplenty:leaves_4:3)
Block(9,12,3,biomesoplenty:leaves_4:3)
Block(9,12,4,biomesoplenty:leaves_4:3)
Block(9,12,6,biomesoplenty:leaves_4:3)
Block(9,12,7,biomesoplenty:leaves_4:3)
Block(9,12,10,biomesoplenty:leaves_4:3)
Block(9,12,15,biomesoplenty:leaves_4:3)
Block(9,12,16,biomesoplenty:log_2:5)
Block(9,12,17,biomesoplenty:leaves_4:3)
Block(9,13,-3,biomesoplenty:leaves_4:3)
Block(9,13,-2,biomesoplenty:leaves_4:3)
Block(9,13,-1,biomesoplenty:leaves_4:3)
Block(9,13,0,biomesoplenty:leaves_4:3)
Block(9,13,1,biomesoplenty:leaves_4:3)
Block(9,13,2,biomesoplenty:leaves_4:3)
Block(9,13,3,biomesoplenty:leaves_4:3)
Block(9,13,4,biomesoplenty:leaves_4:3)
Block(9,13,5,biomesoplenty:leaves_4:3)
Block(9,13,6,biomesoplenty:leaves_4:3)
Block(9,13,7,biomesoplenty:leaves_4:3)
Block(9,13,10,biomesoplenty:leaves_4:3)
Block(9,13,13,biomesoplenty:leaves_4:3)
Block(9,13,14,biomesoplenty:leaves_4:3)
Block(9,13,15,biomesoplenty:leaves_4:3)
Block(9,13,16,biomesoplenty:log_2:5)
Block(9,13,17,biomesoplenty:leaves_4:3)
Block(9,14,-3,biomesoplenty:leaves_4:3)
Block(9,14,-2,biomesoplenty:leaves_4:3)
Block(9,14,-1,biomesoplenty:leaves_4:3)
Block(9,14,0,biomesoplenty:log_2:5)
Block(9,14,1,biomesoplenty:leaves_4:3)
Block(9,14,2,biomesoplenty:leaves_4:3)
Block(9,14,3,biomesoplenty:leaves_4:3)
Block(9,14,4,biomesoplenty:leaves_4:3)
Block(9,14,5,biomesoplenty:leaves_4:3)
Block(9,14,6,biomesoplenty:leaves_4:3)
Block(9,14,7,biomesoplenty:leaves_4:3)
Block(9,14,8,biomesoplenty:leaves_4:3)
Block(9,14,9,biomesoplenty:leaves_4:3)
Block(9,14,10,biomesoplenty:log_2:5)
Block(9,14,11,biomesoplenty:leaves_4:3)
Block(9,14,12,biomesoplenty:leaves_4:3)
Block(9,14,13,biomesoplenty:leaves_4:3)
Block(9,14,14,biomesoplenty:leaves_4:3)
Block(9,14,15,biomesoplenty:leaves_4:3)
Block(9,14,16,biomesoplenty:log_2:5)
Block(9,14,17,biomesoplenty:leaves_4:3)
Block(9,15,-3,biomesoplenty:leaves_4:3)
Block(9,15,-2,biomesoplenty:leaves_4:3)
Block(9,15,-1,biomesoplenty:leaves_4:3)
Block(9,15,0,biomesoplenty:log_2:5)
Block(9,15,1,biomesoplenty:leaves_4:3)
Block(9,15,2,biomesoplenty:leaves_4:3)
Block(9,15,3,biomesoplenty:log_2:5)
Block(9,15,4,biomesoplenty:leaves_4:3)
Block(9,15,5,biomesoplenty:leaves_4:3)
Block(9,15,6,biomesoplenty:leaves_4:3)
Block(9,15,7,biomesoplenty:leaves_4:3)
Block(9,15,8,biomesoplenty:leaves_4:3)
Block(9,15,9,biomesoplenty:leaves_4:3)
Block(9,15,10,biomesoplenty:log_2:5)
Block(9,15,11,biomesoplenty:leaves_4:3)
Block(9,15,12,biomesoplenty:leaves_4:3)
Block(9,15,13,biomesoplenty:leaves_4:3)
Block(9,15,14,biomesoplenty:leaves_4:3)
Block(9,15,15,biomesoplenty:log_2:5)
Block(9,15,16,biomesoplenty:log_2:5)
Block(9,15,17,biomesoplenty:leaves_4:3)
Block(9,16,-3,biomesoplenty:leaves_4:3)
Block(9,16,-2,biomesoplenty:leaves_4:3)
Block(9,16,-1,biomesoplenty:leaves_4:3)
Block(9,16,0,biomesoplenty:log_2:5)
Block(9,16,1,biomesoplenty:leaves_4:3)
Block(9,16,2,biomesoplenty:leaves_4:3)
Block(9,16,3,biomesoplenty:log_2:5)
Block(9,16,4,biomesoplenty:leaves_4:3)
Block(9,16,5,biomesoplenty:leaves_4:3)
Block(9,16,6,biomesoplenty:leaves_4:3)
Block(9,16,7,biomesoplenty:leaves_4:3)
Block(9,16,8,biomesoplenty:leaves_4:3)
Block(9,16,9,biomesoplenty:leaves_4:3)
Block(9,16,10,biomesoplenty:log_2:5)
Block(9,16,11,biomesoplenty:leaves_4:3)
Block(9,16,12,biomesoplenty:leaves_4:3)
Block(9,16,13,biomesoplenty:log_2:5)
Block(9,16,14,biomesoplenty:log_2:5)
Block(9,16,15,biomesoplenty:leaves_4:3)
Block(9,16,16,biomesoplenty:leaves_4:3)
Block(9,17,-2,biomesoplenty:leaves_4:3)
Block(9,17,-1,biomesoplenty:leaves_4:3)
Block(9,17,0,biomesoplenty:log_2:5)
Block(9,17,1,biomesoplenty:leaves_4:3)
Block(9,17,3,biomesoplenty:log_2:5)
Block(9,17,4,biomesoplenty:leaves_4:3)
Block(9,17,5,biomesoplenty:leaves_4:3)
Block(9,17,6,biomesoplenty:leaves_4:3)
Block(9,17,7,biomesoplenty:leaves_4:3)
Block(9,17,8,biomesoplenty:leaves_4:3)
Block(9,17,9,biomesoplenty:leaves_4:3)
Block(9,17,10,biomesoplenty:log_2:5)
Block(9,17,11,biomesoplenty:leaves_4:3)
Block(9,17,12,biomesoplenty:log_2:5)
Block(9,17,13,biomesoplenty:leaves_4:3)
Block(9,17,14,biomesoplenty:leaves_4:3)
Block(9,18,-1,biomesoplenty:leaves_4:3)
Block(9,18,0,biomesoplenty:leaves_4:3)
Block(9,18,2,biomesoplenty:leaves_4:3)
Block(9,18,3,biomesoplenty:log_2:5)
Block(9,18,4,biomesoplenty:leaves_4:3)
Block(9,18,5,biomesoplenty:leaves_4:3)
Block(9,18,6,biomesoplenty:leaves_4:3)
Block(9,18,7,biomesoplenty:leaves_4:3)
Block(9,18,8,biomesoplenty:leaves_4:3)
Block(9,18,9,biomesoplenty:leaves_4:3)
Block(9,18,10,biomesoplenty:log_2:5)
Block(9,18,11,biomesoplenty:log_2:5)
Block(9,18,12,biomesoplenty:leaves_4:3)
Block(9,19,2,biomesoplenty:leaves_4:3)
Block(9,19,3,biomesoplenty:leaves_4:3)
Block(9,19,6,biomesoplenty:leaves_4:3)
Block(9,19,7,biomesoplenty:leaves_4:3)
Block(9,19,8,biomesoplenty:log_2:5)
Block(9,19,9,biomesoplenty:log_2:5)
Block(9,19,10,biomesoplenty:leaves_4:3)
Block(9,19,11,biomesoplenty:leaves_4:3)
Block(9,20,7,biomesoplenty:leaves_4:3)
Block(9,20,8,biomesoplenty:leaves_4:3)
Block(9,20,9,biomesoplenty:leaves_4:3)
Block(10,11,-2,biomesoplenty:leaves_4:3)
Block(10,11,14,biomesoplenty:leaves_4:3)
Block(10,12,-2,biomesoplenty:leaves_4:3)
Block(10,12,4,biomesoplenty:leaves_4:3)
Block(10,12,5,biomesoplenty:leaves_4:3)
Block(10,12,6,biomesoplenty:leaves_4:3)
Block(10,12,14,biomesoplenty:leaves_4:3)
Block(10,12,15,biomesoplenty:leaves_4:3)
Block(10,12,16,biomesoplenty:leaves_4:3)
Block(10,13,-2,biomesoplenty:leaves_4:3)
Block(10,13,-1,biomesoplenty:leaves_4:3)
Block(10,13,0,biomesoplenty:leaves_4:3)
Block(10,13,1,biomesoplenty:leaves_4:3)
Block(10,13,2,biomesoplenty:leaves_4:3)
Block(10,13,3,biomesoplenty:leaves_4:3)
Block(10,13,4,biomesoplenty:leaves_4:3)
Block(10,13,5,biomesoplenty:leaves_4:3)
Block(10,13,6,biomesoplenty:leaves_4:3)
Block(10,13,12,biomesoplenty:leaves_4:3)
Block(10,13,13,biomesoplenty:leaves_4:3)
Block(10,13,14,biomesoplenty:leaves_4:3)
Block(10,13,15,biomesoplenty:leaves_4:3)
Block(10,13,16,biomesoplenty:leaves_4:3)
Block(10,14,-2,biomesoplenty:leaves_4:3)
Block(10,14,-1,biomesoplenty:leaves_4:3)
Block(10,14,0,biomesoplenty:leaves_4:3)
Block(10,14,1,biomesoplenty:leaves_4:3)
Block(10,14,2,biomesoplenty:leaves_4:3)
Block(10,14,3,biomesoplenty:leaves_4:3)
Block(10,14,4,biomesoplenty:leaves_4:3)
Block(10,14,5,biomesoplenty:leaves_4:3)
Block(10,14,6,biomesoplenty:leaves_4:3)
Block(10,14,7,biomesoplenty:leaves_4:3)
Block(10,14,8,biomesoplenty:leaves_4:3)
Block(10,14,9,biomesoplenty:leaves_4:3)
Block(10,14,10,biomesoplenty:leaves_4:3)
Block(10,14,11,biomesoplenty:leaves_4:3)
Block(10,14,12,biomesoplenty:leaves_4:3)
Block(10,14,13,biomesoplenty:leaves_4:3)
Block(10,14,14,biomesoplenty:leaves_4:3)
Block(10,14,15,biomesoplenty:leaves_4:3)
Block(10,14,16,biomesoplenty:leaves_4:3)
Block(10,15,-2,biomesoplenty:leaves_4:3)
Block(10,15,-1,biomesoplenty:leaves_4:3)
Block(10,15,0,biomesoplenty:leaves_4:3)
Block(10,15,1,biomesoplenty:leaves_4:3)
Block(10,15,2,biomesoplenty:leaves_4:3)
Block(10,15,3,biomesoplenty:leaves_4:3)
Block(10,15,4,biomesoplenty:leaves_4:3)
Block(10,15,5,biomesoplenty:leaves_4:3)
Block(10,15,6,biomesoplenty:leaves_4:3)
Block(10,15,7,biomesoplenty:leaves_4:3)
Block(10,15,8,biomesoplenty:leaves_4:3)
Block(10,15,9,biomesoplenty:leaves_4:3)
Block(10,15,10,biomesoplenty:leaves_4:3)
Block(10,15,12,biomesoplenty:leaves_4:3)
Block(10,15,13,biomesoplenty:leaves_4:3)
Block(10,15,14,biomesoplenty:leaves_4:3)
Block(10,15,15,biomesoplenty:leaves_4:3)
Block(10,15,16,biomesoplenty:leaves_4:3)
Block(10,16,-2,biomesoplenty:leaves_4:3)
Block(10,16,-1,biomesoplenty:leaves_4:3)
Block(10,16,0,biomesoplenty:leaves_4:3)
Block(10,16,1,biomesoplenty:leaves_4:3)
Block(10,16,2,biomesoplenty:leaves_4:3)
Block(10,16,3,biomesoplenty:leaves_4:3)
Block(10,16,4,biomesoplenty:leaves_4:3)
Block(10,16,5,biomesoplenty:leaves_4:3)
Block(10,16,6,biomesoplenty:leaves_4:3)
Block(10,16,7,biomesoplenty:leaves_4:3)
Block(10,16,8,biomesoplenty:leaves_4:3)
Block(10,16,9,biomesoplenty:leaves_4:3)
Block(10,16,10,biomesoplenty:leaves_4:3)
Block(10,16,11,biomesoplenty:leaves_4:3)
Block(10,16,12,biomesoplenty:log_2:5)
Block(10,16,13,biomesoplenty:leaves_4:3)
Block(10,16,14,biomesoplenty:leaves_4:3)
Block(10,17,-1,biomesoplenty:leaves_4:3)
Block(10,17,0,biomesoplenty:log_2:5)
Block(10,17,1,biomesoplenty:leaves_4:3)
Block(10,17,2,biomesoplenty:leaves_4:3)
Block(10,17,3,biomesoplenty:log_2:5)
Block(10,17,4,biomesoplenty:leaves_4:3)
Block(10,17,5,biomesoplenty:leaves_4:3)
Block(10,17,6,biomesoplenty:leaves_4:3)
Block(10,17,7,biomesoplenty:leaves_4:3)
Block(10,17,8,biomesoplenty:leaves_4:3)
Block(10,17,9,biomesoplenty:leaves_4:3)
Block(10,17,10,biomesoplenty:leaves_4:3)
Block(10,17,11,biomesoplenty:leaves_4:3)
Block(10,17,12,biomesoplenty:leaves_4:3)
Block(10,18,0,biomesoplenty:leaves_4:3)
Block(10,18,3,biomesoplenty:leaves_4:3)
Block(10,18,6,biomesoplenty:leaves_4:3)
Block(10,18,7,biomesoplenty:leaves_4:3)
Block(10,18,8,biomesoplenty:leaves_4:3)
Block(10,18,9,biomesoplenty:leaves_4:3)
Block(10,18,10,biomesoplenty:leaves_4:3)
Block(10,18,11,biomesoplenty:leaves_4:3)
Block(10,19,7,biomesoplenty:leaves_4:3)
Block(10,19,8,biomesoplenty:leaves_4:3)
Block(10,19,9,biomesoplenty:log_2:5)
Block(10,19,10,biomesoplenty:leaves_4:3)
Block(10,20,9,biomesoplenty:leaves_4:3)
Block(11,9,14,biomesoplenty:leaves_4:3)
Block(11,10,0,biomesoplenty:leaves_4:3)
Block(11,10,14,biomesoplenty:leaves_4:3)
Block(11,11,0,biomesoplenty:leaves_4:3)
Block(11,11,12,biomesoplenty:leaves_4:3)
Block(11,11,14,biomesoplenty:leaves_4:3)
Block(11,12,0,biomesoplenty:leaves_4:3)
Block(11,12,5,biomesoplenty:leaves_4:3)
Block(11,12,11,biomesoplenty:leaves_4:3)
Block(11,12,12,biomesoplenty:leaves_4:3)
Block(11,12,13,biomesoplenty:leaves_4:3)
Block(11,12,14,biomesoplenty:leaves_4:3)
Block(11,13,-2,biomesoplenty:leaves_4:3)
Block(11,13,-1,biomesoplenty:leaves_4:3)
Block(11,13,0,biomesoplenty:leaves_4:3)
Block(11,13,1,biomesoplenty:leaves_4:3)
Block(11,13,2,biomesoplenty:leaves_4:3)
Block(11,13,3,biomesoplenty:leaves_4:3)
Block(11,13,4,biomesoplenty:leaves_4:3)
Block(11,13,5,biomesoplenty:leaves_4:3)
Block(11,13,8,biomesoplenty:leaves_4:3)
Block(11,13,11,biomesoplenty:leaves_4:3)
Block(11,13,12,biomesoplenty:leaves_4:3)
Block(11,13,13,biomesoplenty:leaves_4:3)
Block(11,13,14,biomesoplenty:leaves_4:3)
Block(11,14,-2,biomesoplenty:leaves_4:3)
Block(11,14,-1,biomesoplenty:leaves_4:3)
Block(11,14,0,biomesoplenty:log_2:5)
Block(11,14,1,biomesoplenty:leaves_4:3)
Block(11,14,2,biomesoplenty:leaves_4:3)
Block(11,14,3,biomesoplenty:leaves_4:3)
Block(11,14,4,biomesoplenty:leaves_4:3)
Block(11,14,5,biomesoplenty:leaves_4:3)
Block(11,14,6,biomesoplenty:leaves_4:3)
Block(11,14,7,biomesoplenty:leaves_4:3)
Block(11,14,8,biomesoplenty:leaves_4:3)
Block(11,14,9,biomesoplenty:leaves_4:3)
Block(11,14,10,biomesoplenty:leaves_4:3)
Block(11,14,11,biomesoplenty:leaves_4:3)
Block(11,14,12,biomesoplenty:log_2:5)
Block(11,14,13,biomesoplenty:leaves_4:3)
Block(11,14,14,biomesoplenty:leaves_4:3)
Block(11,15,-2,biomesoplenty:leaves_4:3)
Block(11,15,-1,biomesoplenty:leaves_4:3)
Block(11,15,0,biomesoplenty:log_2:5)
Block(11,15,1,biomesoplenty:leaves_4:3)
Block(11,15,2,biomesoplenty:leaves_4:3)
Block(11,15,3,biomesoplenty:leaves_4:3)
Block(11,15,4,biomesoplenty:leaves_4:3)
Block(11,15,5,biomesoplenty:leaves_4:3)
Block(11,15,6,biomesoplenty:leaves_4:3)
Block(11,15,7,biomesoplenty:leaves_4:3)
Block(11,15,8,biomesoplenty:leaves_4:3)
Block(11,15,9,biomesoplenty:leaves_4:3)
Block(11,15,10,biomesoplenty:leaves_4:3)
Block(11,15,11,biomesoplenty:leaves_4:3)
Block(11,15,12,biomesoplenty:log_2:5)
Block(11,15,13,biomesoplenty:leaves_4:3)
Block(11,15,14,biomesoplenty:leaves_4:3)
Block(11,16,-2,biomesoplenty:leaves_4:3)
Block(11,16,-1,biomesoplenty:log_2:5)
Block(11,16,0,biomesoplenty:log_2:5)
Block(11,16,1,biomesoplenty:leaves_4:3)
Block(11,16,2,biomesoplenty:leaves_4:3)
Block(11,16,3,biomesoplenty:leaves_4:3)
Block(11,16,4,biomesoplenty:leaves_4:3)
Block(11,16,5,biomesoplenty:leaves_4:3)
Block(11,16,6,biomesoplenty:leaves_4:3)
Block(11,16,7,biomesoplenty:leaves_4:3)
Block(11,16,8,biomesoplenty:leaves_4:3)
Block(11,16,9,biomesoplenty:leaves_4:3)
Block(11,16,10,biomesoplenty:leaves_4:3)
Block(11,16,11,biomesoplenty:leaves_4:3)
Block(11,16,12,biomesoplenty:log_2:5)
Block(11,16,13,biomesoplenty:leaves_4:3)
Block(11,17,-1,biomesoplenty:leaves_4:3)
Block(11,17,0,biomesoplenty:leaves_4:3)
Block(11,17,2,biomesoplenty:leaves_4:3)
Block(11,17,3,biomesoplenty:log_2:5)
Block(11,17,4,biomesoplenty:leaves_4:3)
Block(11,17,5,biomesoplenty:leaves_4:3)
Block(11,17,6,biomesoplenty:leaves_4:3)
Block(11,17,7,biomesoplenty:leaves_4:3)
Block(11,17,8,biomesoplenty:leaves_4:3)
Block(11,17,9,biomesoplenty:leaves_4:3)
Block(11,17,10,biomesoplenty:leaves_4:3)
Block(11,17,11,biomesoplenty:leaves_4:3)
Block(11,17,12,biomesoplenty:leaves_4:3)
Block(11,18,3,biomesoplenty:leaves_4:3)
Block(11,18,7,biomesoplenty:leaves_4:3)
Block(11,18,8,biomesoplenty:leaves_4:3)
Block(11,18,9,biomesoplenty:log_2:5)
Block(11,18,10,biomesoplenty:leaves_4:3)
Block(11,19,9,biomesoplenty:leaves_4:3)
Block(12,7,14,biomesoplenty:leaves_4:3)
Block(12,8,5,biomesoplenty:leaves_4:3)
Block(12,8,14,biomesoplenty:leaves_4:3)
Block(12,9,-2,biomesoplenty:leaves_4:3)
Block(12,9,5,biomesoplenty:leaves_4:3)
Block(12,9,14,biomesoplenty:leaves_4:3)
Block(12,10,-2,biomesoplenty:leaves_4:3)
Block(12,10,5,biomesoplenty:leaves_4:3)
Block(12,10,13,biomesoplenty:leaves_4:3)
Block(12,10,14,biomesoplenty:log_2:5)
Block(12,10,15,biomesoplenty:leaves_4:3)
Block(12,11,-3,biomesoplenty:leaves_4:3)
Block(12,11,-2,biomesoplenty:leaves_4:3)
Block(12,11,3,biomesoplenty:leaves_4:3)
Block(12,11,5,biomesoplenty:leaves_4:3)
Block(12,11,13,biomesoplenty:leaves_4:3)
Block(12,11,14,biomesoplenty:log_2:5)
Block(12,11,15,biomesoplenty:leaves_4:3)
Block(12,12,-3,biomesoplenty:leaves_4:3)
Block(12,12,-2,biomesoplenty:leaves_4:3)
Block(12,12,-1,biomesoplenty:leaves_4:3)
Block(12,12,3,biomesoplenty:leaves_4:3)
Block(12,12,4,biomesoplenty:leaves_4:3)
Block(12,12,5,biomesoplenty:leaves_4:3)
Block(12,12,13,biomesoplenty:leaves_4:3)
Block(12,12,14,biomesoplenty:log_2:5)
Block(12,12,15,biomesoplenty:leaves_4:3)
Block(12,13,-3,biomesoplenty:leaves_4:3)
Block(12,13,-2,biomesoplenty:log_2:5)
Block(12,13,-1,biomesoplenty:leaves_4:3)
Block(12,13,0,biomesoplenty:leaves_4:3)
Block(12,13,2,biomesoplenty:leaves_4:3)
Block(12,13,3,biomesoplenty:leaves_4:3)
Block(12,13,4,biomesoplenty:leaves_4:3)
Block(12,13,5,biomesoplenty:log_2:5)
Block(12,13,6,biomesoplenty:leaves_4:3)
Block(12,13,8,biomesoplenty:leaves_4:3)
Block(12,13,11,biomesoplenty:leaves_4:3)
Block(12,13,12,biomesoplenty:leaves_4:3)
Block(12,13,13,biomesoplenty:leaves_4:3)
Block(12,13,14,biomesoplenty:log_2:5)
Block(12,13,15,biomesoplenty:leaves_4:3)
Block(12,14,-3,biomesoplenty:leaves_4:3)
Block(12,14,-2,biomesoplenty:log_2:5)
Block(12,14,-1,biomesoplenty:leaves_4:3)
Block(12,14,0,biomesoplenty:leaves_4:3)
Block(12,14,2,biomesoplenty:leaves_4:3)
Block(12,14,3,biomesoplenty:log_2:5)
Block(12,14,4,biomesoplenty:leaves_4:3)
Block(12,14,5,biomesoplenty:log_2:5)
Block(12,14,6,biomesoplenty:leaves_4:3)
Block(12,14,7,biomesoplenty:leaves_4:3)
Block(12,14,8,biomesoplenty:leaves_4:3)
Block(12,14,9,biomesoplenty:leaves_4:3)
Block(12,14,10,biomesoplenty:leaves_4:3)
Block(12,14,11,biomesoplenty:leaves_4:3)
Block(12,14,12,biomesoplenty:leaves_4:3)
Block(12,14,13,biomesoplenty:leaves_4:3)
Block(12,14,14,biomesoplenty:log_2:5)
Block(12,14,15,biomesoplenty:leaves_4:3)
Block(12,15,-3,biomesoplenty:leaves_4:3)
Block(12,15,-2,biomesoplenty:log_2:5)
Block(12,15,-1,biomesoplenty:log_2:5)
Block(12,15,0,biomesoplenty:leaves_4:3)
Block(12,15,2,biomesoplenty:leaves_4:3)
Block(12,15,3,biomesoplenty:log_2:5)
Block(12,15,4,biomesoplenty:leaves_4:3)
Block(12,15,5,biomesoplenty:log_2:5)
Block(12,15,6,biomesoplenty:leaves_4:3)
Block(12,15,7,biomesoplenty:leaves_4:3)
Block(12,15,8,biomesoplenty:leaves_4:3)
Block(12,15,9,biomesoplenty:leaves_4:3)
Block(12,15,10,biomesoplenty:leaves_4:3)
Block(12,15,11,biomesoplenty:leaves_4:3)
Block(12,15,12,biomesoplenty:leaves_4:3)
Block(12,15,13,biomesoplenty:log_2:5)
Block(12,15,14,biomesoplenty:leaves_4:3)
Block(12,16,-2,biomesoplenty:leaves_4:3)
Block(12,16,-1,biomesoplenty:leaves_4:3)
Block(12,16,0,biomesoplenty:leaves_4:3)
Block(12,16,2,biomesoplenty:leaves_4:3)
Block(12,16,3,biomesoplenty:log_2:5)
Block(12,16,4,biomesoplenty:leaves_4:3)
Block(12,16,5,biomesoplenty:log_2:5)
Block(12,16,6,biomesoplenty:leaves_4:3)
Block(12,16,7,biomesoplenty:leaves_4:3)
Block(12,16,8,biomesoplenty:leaves_4:3)
Block(12,16,9,biomesoplenty:leaves_4:3)
Block(12,16,10,biomesoplenty:leaves_4:3)
Block(12,16,11,biomesoplenty:leaves_4:3)
Block(12,16,12,biomesoplenty:leaves_4:3)
Block(12,16,13,biomesoplenty:leaves_4:3)
Block(12,16,14,biomesoplenty:leaves_4:3)
Block(12,17,3,biomesoplenty:leaves_4:3)
Block(12,17,5,biomesoplenty:leaves_4:3)
Block(12,17,6,biomesoplenty:log_2:5)
Block(12,17,7,biomesoplenty:log_2:5)
Block(12,17,8,biomesoplenty:leaves_4:3)
Block(12,17,9,biomesoplenty:leaves_4:3)
Block(12,17,10,biomesoplenty:leaves_4:3)
Block(12,17,11,biomesoplenty:leaves_4:3)
Block(12,17,14,biomesoplenty:leaves_4:3)
Block(12,18,6,biomesoplenty:leaves_4:3)
Block(12,18,7,biomesoplenty:leaves_4:3)
Block(12,18,8,biomesoplenty:log_2:5)
Block(12,18,9,biomesoplenty:leaves_4:3)
Block(12,18,10,biomesoplenty:leaves_4:3)
Block(12,19,8,biomesoplenty:leaves_4:3)
Block(12,19,10,biomesoplenty:leaves_4:3)
Block(13,10,14,biomesoplenty:leaves_4:3)
Block(13,11,-1,biomesoplenty:leaves_4:3)
Block(13,11,6,biomesoplenty:leaves_4:3)
Block(13,11,14,biomesoplenty:leaves_4:3)
Block(13,12,-1,biomesoplenty:leaves_4:3)
Block(13,12,6,biomesoplenty:leaves_4:3)
Block(13,12,8,biomesoplenty:leaves_4:3)
Block(13,12,13,biomesoplenty:leaves_4:3)
Block(13,12,14,biomesoplenty:leaves_4:3)
Block(13,13,-2,biomesoplenty:leaves_4:3)
Block(13,13,-1,biomesoplenty:leaves_4:3)
Block(13,13,5,biomesoplenty:leaves_4:3)
Block(13,13,6,biomesoplenty:leaves_4:3)
Block(13,13,7,biomesoplenty:leaves_4:3)
Block(13,13,8,biomesoplenty:leaves_4:3)
Block(13,13,9,biomesoplenty:leaves_4:3)
Block(13,13,11,biomesoplenty:leaves_4:3)
Block(13,13,12,biomesoplenty:leaves_4:3)
Block(13,13,13,biomesoplenty:leaves_4:3)
Block(13,13,14,biomesoplenty:leaves_4:3)
Block(13,14,-2,biomesoplenty:leaves_4:3)
Block(13,14,-1,biomesoplenty:leaves_4:3)
Block(13,14,3,biomesoplenty:leaves_4:3)
Block(13,14,5,biomesoplenty:leaves_4:3)
Block(13,14,6,biomesoplenty:leaves_4:3)
Block(13,14,7,biomesoplenty:leaves_4:3)
Block(13,14,8,biomesoplenty:leaves_4:3)
Block(13,14,9,biomesoplenty:leaves_4:3)
Block(13,14,10,biomesoplenty:leaves_4:3)
Block(13,14,11,biomesoplenty:leaves_4:3)
Block(13,14,12,biomesoplenty:leaves_4:3)
Block(13,14,13,biomesoplenty:leaves_4:3)
Block(13,14,14,biomesoplenty:leaves_4:3)
Block(13,15,-2,biomesoplenty:leaves_4:3)
Block(13,15,-1,biomesoplenty:leaves_4:3)
Block(13,15,3,biomesoplenty:leaves_4:3)
Block(13,15,5,biomesoplenty:leaves_4:3)
Block(13,15,6,biomesoplenty:log_2:5)
Block(13,15,7,biomesoplenty:leaves_4:3)
Block(13,15,8,biomesoplenty:leaves_4:3)
Block(13,15,9,biomesoplenty:leaves_4:3)
Block(13,15,10,biomesoplenty:leaves_4:3)
Block(13,15,11,biomesoplenty:leaves_4:3)
Block(13,15,12,biomesoplenty:leaves_4:3)
Block(13,15,13,biomesoplenty:leaves_4:3)
Block(13,15,14,biomesoplenty:leaves_4:3)
Block(13,16,3,biomesoplenty:leaves_4:3)
Block(13,16,5,biomesoplenty:leaves_4:3)
Block(13,16,6,biomesoplenty:log_2:5)
Block(13,16,7,biomesoplenty:leaves_4:3)
Block(13,16,8,biomesoplenty:log_2:5)
Block(13,16,9,biomesoplenty:leaves_4:3)
Block(13,16,10,biomesoplenty:leaves_4:3)
Block(13,16,11,biomesoplenty:log_2:5)
Block(13,16,12,biomesoplenty:log_2:5)
Block(13,16,13,biomesoplenty:leaves_4:3)
Block(13,17,5,biomesoplenty:leaves_4:3)
Block(13,17,6,biomesoplenty:log_2:5)
Block(13,17,7,biomesoplenty:leaves_4:3)
Block(13,17,8,biomesoplenty:log_2:5)
Block(13,17,9,biomesoplenty:log_2:5)
Block(13,17,10,biomesoplenty:leaves_4:3)
Block(13,17,11,biomesoplenty:leaves_4:3)
Block(13,17,12,biomesoplenty:leaves_4:3)
Block(13,18,6,biomesoplenty:leaves_4:3)
Block(13,18,8,biomesoplenty:leaves_4:3)
Block(13,18,9,biomesoplenty:leaves_4:3)
Block(14,9,14,biomesoplenty:leaves_4:3)
Block(14,10,6,biomesoplenty:leaves_4:3)
Block(14,10,11,biomesoplenty:leaves_4:3)
Block(14,10,14,biomesoplenty:leaves_4:3)
Block(14,10,15,biomesoplenty:leaves_4:3)
Block(14,11,6,biomesoplenty:leaves_4:3)
Block(14,11,11,biomesoplenty:leaves_4:3)
Block(14,11,13,biomesoplenty:leaves_4:3)
Block(14,11,14,biomesoplenty:leaves_4:3)
Block(14,11,15,biomesoplenty:leaves_4:3)
Block(14,11,16,biomesoplenty:leaves_4:3)
Block(14,12,6,biomesoplenty:leaves_4:3)
Block(14,12,7,biomesoplenty:leaves_4:3)
Block(14,12,10,biomesoplenty:leaves_4:3)
Block(14,12,11,biomesoplenty:leaves_4:3)
Block(14,12,12,biomesoplenty:leaves_4:3)
Block(14,12,13,biomesoplenty:leaves_4:3)
Block(14,12,14,biomesoplenty:leaves_4:3)
Block(14,12,15,biomesoplenty:leaves_4:3)
Block(14,12,16,biomesoplenty:leaves_4:3)
Block(14,13,6,biomesoplenty:leaves_4:3)
Block(14,13,7,biomesoplenty:leaves_4:3)
Block(14,13,8,biomesoplenty:leaves_4:3)
Block(14,13,9,biomesoplenty:leaves_4:3)
Block(14,13,10,biomesoplenty:leaves_4:3)
Block(14,13,11,biomesoplenty:log_2:5)
Block(14,13,12,biomesoplenty:leaves_4:3)
Block(14,13,13,biomesoplenty:leaves_4:3)
Block(14,13,14,biomesoplenty:leaves_4:3)
Block(14,13,15,biomesoplenty:leaves_4:3)
Block(14,14,6,biomesoplenty:leaves_4:3)
Block(14,14,7,biomesoplenty:leaves_4:3)
Block(14,14,8,biomesoplenty:leaves_4:3)
Block(14,14,9,biomesoplenty:leaves_4:3)
Block(14,14,10,biomesoplenty:leaves_4:3)
Block(14,14,11,biomesoplenty:log_2:5)
Block(14,14,12,biomesoplenty:leaves_4:3)
Block(14,14,13,biomesoplenty:leaves_4:3)
Block(14,14,14,biomesoplenty:log_2:5)
Block(14,14,15,biomesoplenty:leaves_4:3)
Block(14,15,6,biomesoplenty:leaves_4:3)
Block(14,15,7,biomesoplenty:leaves_4:3)
Block(14,15,8,biomesoplenty:leaves_4:3)
Block(14,15,9,biomesoplenty:leaves_4:3)
Block(14,15,10,biomesoplenty:leaves_4:3)
Block(14,15,11,biomesoplenty:log_2:5)
Block(14,15,12,biomesoplenty:leaves_4:3)
Block(14,15,13,biomesoplenty:log_2:5)
Block(14,15,14,biomesoplenty:log_2:5)
Block(14,15,15,biomesoplenty:leaves_4:3)
Block(14,16,6,biomesoplenty:leaves_4:3)
Block(14,16,8,biomesoplenty:leaves_4:3)
Block(14,16,9,biomesoplenty:leaves_4:3)
Block(14,16,10,biomesoplenty:leaves_4:3)
Block(14,16,11,biomesoplenty:log_2:5)
Block(14,16,12,biomesoplenty:leaves_4:3)
Block(14,16,13,biomesoplenty:leaves_4:3)
Block(14,16,14,biomesoplenty:leaves_4:3)
Block(14,17,6,biomesoplenty:leaves_4:3)
Block(14,17,8,biomesoplenty:leaves_4:3)
Block(14,17,9,biomesoplenty:leaves_4:3)
Block(14,17,10,biomesoplenty:log_2:5)
Block(14,17,11,biomesoplenty:leaves_4:3)
Block(14,18,10,biomesoplenty:leaves_4:3)
Block(15,10,9,biomesoplenty:leaves_4:3)
Block(15,11,9,biomesoplenty:leaves_4:3)
Block(15,11,14,biomesoplenty:leaves_4:3)
Block(15,12,9,biomesoplenty:leaves_4:3)
Block(15,12,14,biomesoplenty:leaves_4:3)
Block(15,12,15,biomesoplenty:leaves_4:3)
Block(15,13,8,biomesoplenty:leaves_4:3)
Block(15,13,9,biomesoplenty:leaves_4:3)
Block(15,13,10,biomesoplenty:leaves_4:3)
Block(15,13,11,biomesoplenty:leaves_4:3)
Block(15,13,12,biomesoplenty:leaves_4:3)
Block(15,13,13,biomesoplenty:leaves_4:3)
Block(15,13,14,biomesoplenty:leaves_4:3)
Block(15,13,15,biomesoplenty:leaves_4:3)
Block(15,14,8,biomesoplenty:leaves_4:3)
Block(15,14,9,biomesoplenty:log_2:5)
Block(15,14,10,biomesoplenty:leaves_4:3)
Block(15,14,11,biomesoplenty:leaves_4:3)
Block(15,14,12,biomesoplenty:leaves_4:3)
Block(15,14,13,biomesoplenty:leaves_4:3)
Block(15,14,14,biomesoplenty:leaves_4:3)
Block(15,14,15,biomesoplenty:leaves_4:3)
Block(15,15,8,biomesoplenty:leaves_4:3)
Block(15,15,9,biomesoplenty:log_2:5)
Block(15,15,10,biomesoplenty:leaves_4:3)
Block(15,15,11,biomesoplenty:leaves_4:3)
Block(15,15,12,biomesoplenty:leaves_4:3)
Block(15,15,13,biomesoplenty:leaves_4:3)
Block(15,15,14,biomesoplenty:log_2:5)
Block(15,15,15,biomesoplenty:leaves_4:3)
Block(15,16,8,biomesoplenty:leaves_4:3)
Block(15,16,9,biomesoplenty:log_2:5)
Block(15,16,10,biomesoplenty:log_2:5)
Block(15,16,11,biomesoplenty:leaves_4:3)
Block(15,16,12,biomesoplenty:leaves_4:3)
Block(15,16,13,biomesoplenty:leaves_4:3)
Block(15,16,14,biomesoplenty:leaves_4:3)
Block(15,16,15,biomesoplenty:leaves_4:3)
Block(15,17,9,biomesoplenty:leaves_4:3)
Block(15,17,10,biomesoplenty:leaves_4:3)
Block(15,17,13,biomesoplenty:leaves_4:3)
Block(16,9,14,biomesoplenty:leaves_4:3)
Block(16,10,14,biomesoplenty:leaves_4:3)
Block(16,11,14,biomesoplenty:leaves_4:3)
Block(16,11,15,biomesoplenty:leaves_4:3)
Block(16,12,10,biomesoplenty:leaves_4:3)
Block(16,12,11,biomesoplenty:leaves_4:3)
Block(16,12,12,biomesoplenty:leaves_4:3)
Block(16,12,14,biomesoplenty:leaves_4:3)
Block(16,12,15,biomesoplenty:leaves_4:3)
Block(16,13,9,biomesoplenty:leaves_4:3)
Block(16,13,10,biomesoplenty:leaves_4:3)
Block(16,13,11,biomesoplenty:leaves_4:3)
Block(16,13,12,biomesoplenty:leaves_4:3)
Block(16,13,13,biomesoplenty:leaves_4:3)
Block(16,13,14,biomesoplenty:log_2:5)
Block(16,13,15,biomesoplenty:leaves_4:3)
Block(16,14,9,biomesoplenty:leaves_4:3)
Block(16,14,10,biomesoplenty:leaves_4:3)
Block(16,14,11,biomesoplenty:leaves_4:3)
Block(16,14,12,biomesoplenty:leaves_4:3)
Block(16,14,13,biomesoplenty:leaves_4:3)
Block(16,14,14,biomesoplenty:log_2:5)
Block(16,14,15,biomesoplenty:leaves_4:3)
Block(16,15,9,biomesoplenty:leaves_4:3)
Block(16,15,10,biomesoplenty:leaves_4:3)
Block(16,15,11,biomesoplenty:log_2:5)
Block(16,15,12,biomesoplenty:leaves_4:3)
Block(16,15,13,biomesoplenty:leaves_4:3)
Block(16,15,14,biomesoplenty:log_2:5)
Block(16,15,15,biomesoplenty:leaves_4:3)
Block(16,16,9,biomesoplenty:leaves_4:3)
Block(16,16,10,biomesoplenty:log_2:5)
Block(16,16,11,biomesoplenty:log_2:5)
Block(16,16,12,biomesoplenty:leaves_4:3)
Block(16,16,14,biomesoplenty:leaves_4:3)
Block(16,17,10,biomesoplenty:leaves_4:3)
Block(16,17,11,biomesoplenty:leaves_4:3)
Block(17,9,10,biomesoplenty:leaves_4:3)
Block(17,10,10,biomesoplenty:leaves_4:3)
Block(17,11,10,biomesoplenty:leaves_4:3)
Block(17,11,11,biomesoplenty:leaves_4:3)
Block(17,12,9,biomesoplenty:leaves_4:3)
Block(17,12,10,biomesoplenty:log_2:5)
Block(17,12,11,biomesoplenty:leaves_4:3)
Block(17,12,14,biomesoplenty:leaves_4:3)
Block(17,13,9,biomesoplenty:leaves_4:3)
Block(17,13,10,biomesoplenty:log_2:5)
Block(17,13,11,biomesoplenty:leaves_4:3)
Block(17,13,14,biomesoplenty:leaves_4:3)
Block(17,14,9,biomesoplenty:leaves_4:3)
Block(17,14,10,biomesoplenty:log_2:5)
Block(17,14,11,biomesoplenty:leaves_4:3)
Block(17,14,14,biomesoplenty:leaves_4:3)
Block(17,15,9,biomesoplenty:leaves_4:3)
Block(17,15,10,biomesoplenty:log_2:5)
Block(17,15,11,biomesoplenty:leaves_4:3)
Block(17,15,14,biomesoplenty:leaves_4:3)
Block(17,16,10,biomesoplenty:leaves_4:3)
Block(17,16,11,biomesoplenty:leaves_4:3)
Block(18,12,10,biomesoplenty:leaves_4:3)
Block(18,13,10,biomesoplenty:leaves_4:3)
Block(18,14,10,biomesoplenty:leaves_4:3)
Block(18,15,10,biomesoplenty:leaves_4:3)

#######################################################################
# +-----------------------------------------------------------------+ #
# |                            BO3 checks                           | #
# +-----------------------------------------------------------------+ #
#######################################################################


#######################################################################
# +-----------------------------------------------------------------+ #
# |                             Branches                            | #
# +-----------------------------------------------------------------+ #
#######################################################################


#######################################################################
# +-----------------------------------------------------------------+ #
# |                             Entities                            | #
# +-----------------------------------------------------------------+ #
#######################################################################


#######################################################################
# +-----------------------------------------------------------------+ #
# |                            Particles                            | #
# +-----------------------------------------------------------------+ #
#######################################################################


#######################################################################
# +-----------------------------------------------------------------+ #
# |                             Spawners                            | #
# +-----------------------------------------------------------------+ #
#######################################################################


#######################################################################
# +-----------------------------------------------------------------+ #
# |                             ModData                             | #
# +-----------------------------------------------------------------+ #
#######################################################################

