[META]
version=2.0
spawnOnBlockType=2,1,110
spawnSunlight=True
spawnDarkness=True
spawnWater=False
spawnLava=False
underFill=False
randomRotation=True
dig=True
tree=False
branch=False
needsFoundation=True
rarity=2
collisionPercentage=5
spawnElevationMin=0
spawnElevationMax=200
spawnInBiome=Custom
[DATA]
1,0,-4:1.0
0,-1,-3:1.0
1,-1,-3:1.0
-1,0,-3:1.0
0,0,-3:1.0
1,0,-3:1.0
2,0,-3:1.0
-1,1,-3:1.0
0,1,-3:1.0
1,1,-3:1.0
2,1,-3:1.0
0,2,-3:1.0
1,-3,-2:1.0
-1,-2,-2:1.0
0,-2,-2:1.0
1,-2,-2:1.0
2,-2,-2:1.0
-2,-1,-2:1.0
-1,-1,-2:1.0
0,-1,-2:1.0
1,-1,-2:1.0
2,-1,-2:1.0
3,-1,-2:1.0
-3,0,-2:1.0
-2,0,-2:1.0
-1,0,-2:1.0
0,0,-2:1.0
1,0,-2:1.0
2,0,-2:1.0
3,0,-2:1.0
4,0,-2:1.0
-2,1,-2:1.0
-1,1,-2:1.0
0,1,-2:1.0
1,1,-2:1.0
2,1,-2:1.0
3,1,-2:1.0
-2,2,-2:1.0
-1,2,-2:1.0
0,2,-2:1.0
1,2,-2:1.0
2,2,-2:1.0
-1,3,-2:1.0
0,3,-2:1.0
1,3,-2:1.0
0,-4,-1:1.0
1,-4,-1:1.0
-1,-3,-1:1.0
0,-3,-1:1.0
1,-3,-1:1.0
2,-3,-1:1.0
-1,-2,-1:1.0
0,-2,-1:1.0
1,-2,-1:1.0
2,-2,-1:1.0
3,-2,-1:1.0
-3,-1,-1:1.0
-2,-1,-1:1.0
-1,-1,-1:1.0
0,-1,-1:1.0
1,-1,-1:1.0
2,-1,-1:1.0
3,-1,-1:1.0
4,-1,-1:1.0
-4,0,-1:1.0
-3,0,-1:1.0
-2,0,-1:1.0
-1,0,-1:1.0
0,0,-1:1.0
1,0,-1:1.0
2,0,-1:1.0
3,0,-1:1.0
4,0,-1:1.0
-3,1,-1:1.0
-2,1,-1:1.0
-1,1,-1:1.0
0,1,-1:1.0
1,1,-1:1.0
2,1,-1:1.0
3,1,-1:1.0
4,1,-1:1.0
-3,2,-1:1.0
-2,2,-1:1.0
-1,2,-1:1.0
0,2,-1:1.0
1,2,-1:1.0
2,2,-1:1.0
3,2,-1:1.0
-2,3,-1:1.0
-1,3,-1:1.0
0,3,-1:1.0
1,3,-1:1.0
2,3,-1:1.0
-1,4,-1:1.0
0,-4,0:1.0
1,-4,0:1.0
-2,-3,0:1.0
-1,-3,0:1.0
0,-3,0:1.0
1,-3,0:1.0
2,-3,0:1.0
-2,-2,0:1.0
-1,-2,0:1.0
0,-2,0:1.0
1,-2,0:1.0
2,-2,0:1.0
3,-2,0:1.0
-3,-1,0:1.0
-2,-1,0:1.0
-1,-1,0:11.0
0,-1,0:11.0
1,-1,0:11.0
2,-1,0:1.0
3,-1,0:1.0
4,-1,0:1.0
-4,0,0:1.0
-3,0,0:1.0
-2,0,0:1.0
-1,0,0:11.0
0,0,0:11.0
1,0,0:11.0
2,0,0:1.0
3,0,0:1.0
4,0,0:1.0
-4,1,0:1.0
-3,1,0:1.0
-2,1,0:1.0
-1,1,0:1.0
0,1,0:1.0
1,1,0:1.0
2,1,0:1.0
3,1,0:1.0
4,1,0:1.0
-2,2,0:1.0
-1,2,0:1.0
0,2,0:1.0
1,2,0:1.0
2,2,0:1.0
-2,3,0:1.0
-1,3,0:1.0
0,3,0:1.0
1,3,0:1.0
2,3,0:1.0
-1,4,0:1.0
0,4,0:1.0
1,4,0:1.0
0,-4,1:1.0
-1,-3,1:1.0
0,-3,1:1.0
1,-3,1:1.0
-2,-2,1:1.0
-1,-2,1:1.0
0,-2,1:11.0
1,-2,1:11.0
2,-2,1:1.0
-3,-1,1:1.0
-2,-1,1:1.0
-1,-1,1:11.0
0,-1,1:11.0
1,-1,1:11.0
2,-1,1:11.0
3,-1,1:1.0
-3,0,1:1.0
-2,0,1:1.0
-1,0,1:11.0
0,0,1:11.0
1,0,1:11.0
2,0,1:11.0
3,0,1:1.0
-3,1,1:1.0
-2,1,1:1.0
-1,1,1:11.0
0,1,1:11.0
1,1,1:1.0
2,1,1:1.0
3,1,1:1.0
-2,2,1:1.0
-1,2,1:1.0
0,2,1:1.0
1,2,1:1.0
2,2,1:1.0
-1,3,1:1.0
0,3,1:1.0
1,3,1:1.0
2,3,1:1.0
0,4,1:1.0
0,-3,2:1.0
-2,-2,2:1.0
-1,-2,2:1.0
0,-2,2:1.0
1,-2,2:1.0
-2,-1,2:1.0
-1,-1,2:11.0
0,-1,2:11.0
1,-1,2:11.0
2,-1,2:1.0
-3,0,2:1.0
-2,0,2:1.0
-1,0,2:11.0
0,0,2:11.0
1,0,2:11.0
2,0,2:1.0
3,0,2:1.0
-2,1,2:1.0
-1,1,2:11.0
0,1,2:11.0
1,1,2:1.0
2,1,2:1.0
-1,2,2:1.0
0,2,2:1.0
1,2,2:1.0
0,3,2:1.0
2,3,2:1.0
-2,-2,3:1.0
0,-2,3:1.0
-1,-1,3:1.0
0,-1,3:11.0
1,-1,3:1.0
-2,0,3:1.0
-1,0,3:1.0
0,0,3:11.0
1,0,3:11.0
2,0,3:1.0
-1,1,3:1.0
0,1,3:11.0
1,1,3:1.0
-1,2,3:1.0
0,2,3:1.0
0,-1,4:1.0
1,-1,4:1.0
2,0,4:1.0
0,1,4:1.0
1,1,4:1.0
-1,2,4:1.0
1,-1,5:1.0
2,0,5:1.0
1,1,5:1.0
1,-1,6:1.0
2,0,6:1.0
2,0,7:1.0
