
#######################################################################
# +-----------------------------------------------------------------+ #
# |                            BO3 object                           | #
# +-----------------------------------------------------------------+ #
#######################################################################

# This is the config file of a custom object.
# If you add this object correctly to your BiomeConfigs, it will spawn in the world.

# This is the creator of this BO3 object
Author: LordSmellyPants

# A short description of this BO3 object
Description: No description given

# The BO3 version, don't change this! It can be used by external applications to do a version check.
Version: 3

# The settings mode, WriteAll, WriteWithoutComments or WriteDisable. See WorldConfig.
SettingsMode: WriteDisable


#######################################################################
# +-----------------------------------------------------------------+ #
# |                          Main settings                          | #
# +-----------------------------------------------------------------+ #
#######################################################################

# This needs to be set to true to spawn the object in the Tree and Sapling resources.
Tree: false

# The frequency of the BO3 from 1 to 200. Tries this many times to spawn this BO3 when using the CustomObject(...) resource.
# Ignored by Tree(..), Sapling(..) and CustomStructure(..)
Frequency: 1

# The rarity of the BO3 from 0 to 100. Each spawn attempt has rarity% chance to succeed when using the CustomObject(...) resource.
# Ignored by Tree(..), Sapling(..) and CustomStructure(..)
Rarity: 0.1

# If you set this to true, the BO3 will be placed with a random rotation.
RotateRandomly: true

# The spawn height of the BO3 - atMinY, randomY, highestBlock or highestSolidBlock.
SpawnHeight: highestSolidBlock

# The offset from the spawn height to spawn this BO3
# Ex. SpawnHeight = highestSolidBlock, SpawnHeightOffset = 3; This object will spawn 3 blocks above the highest solid block
SpawnHeightOffset: 0

# A random amount to offset the spawn location from the spawn offset height
# Ex. SpawnHeightOffset = 3, SpawnHeightVariance = 3; This object will spawn 3 to 6 blocks above the original spot it would have spawned
SpawnHeightVariance: 0

##############################
# Height Limits for the BO3. #
##############################

# When in randomY mode used as the minimum Y or in atMinY mode as the actual Y to spawn this BO3 at.
MinHeight: 0

# When in randomY mode used as the maximum Y to spawn this BO3 at.
MaxHeight: 91

######################
# Extrusion settings #
######################

# The style of extrusion you wish to use - BottomDown, TopUp, None (Default)
ExtrudeMode: None

# The blocks to extrude your BO3 through
ExtrudeThroughBlocks: AIR

# Objects can have other objects attacthed to it: branches. Branches can also
# have branches attached to it, which can also have branches, etc. This is the
# maximum branch depth for this objects.
MaxBranchDepth: 10

# When spawned with the UseWorld keyword, this BO3 should NOT spawn in the following biomes.
# If you write the BO3 name directly in the BiomeConfigs, this will be ignored.
ExcludedBiomes: All


#######################################################################
# +-----------------------------------------------------------------+ #
# |                      Source block settings                      | #
# +-----------------------------------------------------------------+ #
#######################################################################

# The B(s) the BO3 should spawn in.
SourceBlocks: AIR,GRASS,DIRT,GRAVEL,SAND,STONE,STONE:1,STONE:3,STONE:5,DIRT:1,CLAY,HARD_CLAY,38,38:1,38:2,38:3,38:4,38:5,38:6,38:7,38:8,39,40,175,175:1,175:2,175:3,175:4,175:5,31,31:1,31:2,32,STAINED_CLAY:14,STAINED_CLAY

# The maximum percentage of the BO3 that can be outside the SourceBlock.
# The BO3 won't be placed on a location with more blocks outside the SourceBlock than this percentage.
MaxPercentageOutsideSourceBlock: 5

# What to do when a block is about to be placed outside the SourceBlock? (dontPlace, placeAnyway)
OutsideSourceBlock: placeAnyway


#######################################################################
# +-----------------------------------------------------------------+ #
# |                              Blocks                             | #
# +-----------------------------------------------------------------+ #
#######################################################################

# All the blocks used in the BO3 are listed here. Possible blocks:
# B(x,y,z,id[.data][,nbtfile.nbt)
# RB(x,y,z,id[:data][,nbtfile.nbt],chance[,id[:data][,nbtfile.nbt],chance[,...]])
#  So RB(0,0,0,CHEST,chest.nbt,50,CHEST,anotherchest.nbt,100) will spawn a chest at
#  the BO3 origin, and give it a 50% chance to have the contents of chest.nbt, or, if that
#  fails, a 100% percent chance to have the contents of anotherchest.nbt.
# MinecraftObject(x,y,z,name)
#  Spawns an object in the Mojang NBT structure format. For example, 
#  MinecraftObject(0,0,0,minecraft:igloo/igloo_bottom)
#  spawns the bottom part of an igloo.
B(-11,-4,-9,STONE)
B(-11,-4,-8,STONE)
B(-11,-3,-12,STONE)
B(-11,-3,-11,STONE)
B(-11,-3,-10,STONE)
B(-11,-3,-9,STONE)
B(-11,-3,-8,STONE)
B(-11,-3,-7,STONE)
B(-11,-2,-13,STONE)
B(-11,-2,-12,STONE)
B(-11,-2,-11,STONE)
B(-11,-2,-10,STONE)
B(-11,-2,-9,STONE)
B(-11,-2,-8,STONE)
B(-11,-2,-7,STONE)
B(-11,-2,-6,STONE)
B(-11,-1,-13,STONE)
B(-11,-1,-12,STONE)
B(-11,-1,-11,STONE)
B(-11,-1,-10,STONE)
B(-11,-1,-9,STONE)
B(-11,-1,-8,STONE)
B(-11,-1,-7,STONE)
B(-11,-1,-6,STONE)
B(-11,0,-12,STONE)
B(-11,0,-11,STONE)
B(-11,0,-10,STONE)
B(-11,0,-9,STONE)
B(-11,0,-8,STONE)
B(-11,0,-7,STONE)
B(-11,1,-9,STONE)
B(-11,1,-8,STONE)
B(-10,-5,-9,STONE)
B(-10,-4,-11,STONE)
B(-10,-4,-10,STONE)
B(-10,-4,-9,STONE)
B(-10,-4,-8,STONE)
B(-10,-4,-7,STONE)
B(-10,-4,-6,STONE)
B(-10,-4,8,STONE)
B(-10,-3,-14,STONE)
B(-10,-3,-13,STONE)
B(-10,-3,-12,STONE)
B(-10,-3,-11,STONE)
B(-10,-3,-10,STONE)
B(-10,-3,-9,STONE)
B(-10,-3,-8,STONE)
B(-10,-3,-7,STONE)
B(-10,-3,-6,STONE)
B(-10,-3,-5,STONE)
B(-10,-3,6,STONE)
B(-10,-3,7,STONE)
B(-10,-3,8,STONE)
B(-10,-3,9,STONE)
B(-10,-2,-15,STONE)
B(-10,-2,-14,STONE)
B(-10,-2,-13,STONE)
B(-10,-2,-12,STONE)
B(-10,-2,-11,STONE)
B(-10,-2,-10,STONE)
B(-10,-2,-9,STONE)
B(-10,-2,-8,STONE)
B(-10,-2,-7,STONE)
B(-10,-2,-6,STONE)
B(-10,-2,-5,STONE)
B(-10,-2,-4,STONE)
B(-10,-2,6,STONE)
B(-10,-2,7,STONE)
B(-10,-2,8,STONE)
B(-10,-2,9,STONE)
B(-10,-2,10,STONE)
B(-10,-1,-15,STONE)
B(-10,-1,-14,STONE)
B(-10,-1,-13,STONE)
B(-10,-1,-12,STONE)
B(-10,-1,-11,STONE)
B(-10,-1,-10,STONE)
B(-10,-1,-9,STONE)
B(-10,-1,-8,STONE)
B(-10,-1,-7,STONE)
B(-10,-1,-6,STONE)
B(-10,-1,-5,STONE)
B(-10,-1,-4,STONE)
B(-10,-1,6,STONE)
B(-10,-1,7,STONE)
B(-10,-1,8,STONE)
B(-10,-1,9,STONE)
B(-10,-1,10,STONE)
B(-10,0,-14,STONE)
B(-10,0,-13,STONE)
B(-10,0,-12,STONE)
B(-10,0,-11,STONE)
B(-10,0,-10,STONE)
B(-10,0,-9,STONE)
B(-10,0,-8,STONE)
B(-10,0,-7,STONE)
B(-10,0,-6,STONE)
B(-10,0,-5,STONE)
B(-10,0,6,STONE)
B(-10,0,7,STONE)
B(-10,0,8,STONE)
B(-10,0,9,STONE)
B(-10,1,-11,STONE)
B(-10,1,-10,STONE)
B(-10,1,-9,STONE)
B(-10,1,-8,STONE)
B(-10,1,-7,STONE)
B(-10,1,-6,STONE)
B(-10,1,8,STONE)
B(-10,2,-9,STONE)
B(-9,-6,-9,STONE)
B(-9,-6,-8,STONE)
B(-9,-5,-12,STONE)
B(-9,-5,-11,STONE)
B(-9,-5,-10,STONE)
B(-9,-5,-9,STONE)
B(-9,-5,-8,STONE)
B(-9,-5,-7,STONE)
B(-9,-5,-6,STONE)
B(-9,-4,-14,STONE)
B(-9,-4,-13,STONE)
B(-9,-4,-12,STONE)
B(-9,-4,-11,STONE)
B(-9,-4,-10,STONE)
B(-9,-4,-9,STONE)
B(-9,-4,-8,STONE)
B(-9,-4,-7,STONE)
B(-9,-4,-6,STONE)
B(-9,-4,-5,STONE)
B(-9,-4,-4,STONE)
B(-9,-4,6,STONE)
B(-9,-4,7,STONE)
B(-9,-4,8,STONE)
B(-9,-4,9,STONE)
B(-9,-3,-15,STONE)
B(-9,-3,-14,STONE)
B(-9,-3,-13,STONE)
B(-9,-3,-12,STONE)
B(-9,-3,-11,STONE)
B(-9,-3,-10,STONE)
B(-9,-3,-9,STONE)
B(-9,-3,-8,STONE)
B(-9,-3,-7,STONE)
B(-9,-3,-6,STONE)
B(-9,-3,-5,STONE)
B(-9,-3,-4,STONE)
B(-9,-3,-3,STONE)
B(-9,-3,5,STONE)
B(-9,-3,6,STONE)
B(-9,-3,7,STONE)
B(-9,-3,8,STONE)
B(-9,-3,9,STONE)
B(-9,-3,10,STONE)
B(-9,-2,-15,STONE)
B(-9,-2,-14,STONE)
B(-9,-2,-13,STONE)
B(-9,-2,-12,STONE)
B(-9,-2,-11,STONE)
B(-9,-2,-10,STONE)
B(-9,-2,-9,STONE)
B(-9,-2,-8,STONE)
B(-9,-2,-7,STONE)
B(-9,-2,-6,STONE)
B(-9,-2,-5,STONE)
B(-9,-2,-4,STONE)
B(-9,-2,-3,STONE)
B(-9,-2,-2,STONE)
B(-9,-2,-1,STONE)
B(-9,-2,2,STONE)
B(-9,-2,3,STONE)
B(-9,-2,4,STONE)
B(-9,-2,5,STONE)
B(-9,-2,6,STONE)
B(-9,-2,7,STONE)
B(-9,-2,8,STONE)
B(-9,-2,9,STONE)
B(-9,-2,10,STONE)
B(-9,-2,11,STONE)
B(-9,-1,-15,STONE)
B(-9,-1,-14,STONE)
B(-9,-1,-13,STONE)
B(-9,-1,-12,STONE)
B(-9,-1,-11,STONE)
B(-9,-1,-10,STONE)
B(-9,-1,-9,STONE)
B(-9,-1,-8,STONE)
B(-9,-1,-7,STONE)
B(-9,-1,-6,STONE)
B(-9,-1,-5,STONE)
B(-9,-1,-4,STONE)
B(-9,-1,-3,STONE)
B(-9,-1,-2,STONE)
B(-9,-1,-1,STONE)
B(-9,-1,2,STONE)
B(-9,-1,3,STONE)
B(-9,-1,4,STONE)
B(-9,-1,5,STONE)
B(-9,-1,6,STONE)
B(-9,-1,7,STONE)
B(-9,-1,8,STONE)
B(-9,-1,9,STONE)
B(-9,-1,10,STONE)
B(-9,-1,11,STONE)
B(-9,0,-15,STONE)
B(-9,0,-14,STONE)
B(-9,0,-13,STONE)
B(-9,0,-12,STONE)
B(-9,0,-11,STONE)
B(-9,0,-10,STONE)
B(-9,0,-9,STONE)
B(-9,0,-8,STONE)
B(-9,0,-7,STONE)
B(-9,0,-6,STONE)
B(-9,0,-5,STONE)
B(-9,0,-4,STONE)
B(-9,0,-3,STONE)
B(-9,0,5,STONE)
B(-9,0,6,STONE)
B(-9,0,7,STONE)
B(-9,0,8,STONE)
B(-9,0,9,STONE)
B(-9,0,10,STONE)
B(-9,1,-14,STONE)
B(-9,1,-13,STONE)
B(-9,1,-12,STONE)
B(-9,1,-11,STONE)
B(-9,1,-10,STONE)
B(-9,1,-9,STONE)
B(-9,1,-8,STONE)
B(-9,1,-7,STONE)
B(-9,1,-6,STONE)
B(-9,1,-5,STONE)
B(-9,1,-4,STONE)
B(-9,1,6,STONE)
B(-9,1,7,STONE)
B(-9,1,8,STONE)
B(-9,1,9,STONE)
B(-9,2,-12,STONE)
B(-9,2,-11,STONE)
B(-9,2,-10,STONE)
B(-9,2,-9,STONE)
B(-9,2,-8,STONE)
B(-9,2,-7,STONE)
B(-9,2,-6,STONE)
B(-9,3,-9,STONE)
B(-9,3,-8,STONE)
B(-8,-7,-9,STONE)
B(-8,-7,-8,STONE)
B(-8,-7,-7,STONE)
B(-8,-6,-12,STONE)
B(-8,-6,-11,STONE)
B(-8,-6,-10,STONE)
B(-8,-6,-9,STONE)
B(-8,-6,-8,STONE)
B(-8,-6,-7,STONE)
B(-8,-6,-6,STONE)
B(-8,-6,-5,STONE)
B(-8,-5,-13,STONE)
B(-8,-5,-12,STONE)
B(-8,-5,-11,STONE)
B(-8,-5,-10,STONE)
B(-8,-5,-9,STONE)
B(-8,-5,-8,STONE)
B(-8,-5,-7,STONE)
B(-8,-5,-6,STONE)
B(-8,-5,-5,STONE)
B(-8,-5,-4,STONE)
B(-8,-5,7,STONE)
B(-8,-5,8,STONE)
B(-8,-5,9,STONE)
B(-8,-4,-15,STONE)
B(-8,-4,-14,STONE)
B(-8,-4,-13,STONE)
B(-8,-4,-12,STONE)
B(-8,-4,-11,STONE)
B(-8,-4,-10,STONE)
B(-8,-4,-9,STONE)
B(-8,-4,-8,STONE)
B(-8,-4,-7,STONE)
B(-8,-4,-6,STONE)
B(-8,-4,-5,STONE)
B(-8,-4,-4,STONE)
B(-8,-4,-3,STONE)
B(-8,-4,-2,STONE)
B(-8,-4,3,STONE)
B(-8,-4,4,STONE)
B(-8,-4,5,STONE)
B(-8,-4,6,STONE)
B(-8,-4,7,STONE)
B(-8,-4,8,STONE)
B(-8,-4,9,STONE)
B(-8,-4,10,STONE)
B(-8,-3,-15,STONE)
B(-8,-3,-14,STONE)
B(-8,-3,-13,STONE)
B(-8,-3,-12,STONE)
B(-8,-3,-11,STONE)
B(-8,-3,-10,STONE)
B(-8,-3,-9,STONE)
B(-8,-3,-8,STONE)
B(-8,-3,-7,STONE)
B(-8,-3,-6,STONE)
B(-8,-3,-5,STONE)
B(-8,-3,-4,STONE)
B(-8,-3,-3,STONE)
B(-8,-3,-2,STONE)
B(-8,-3,1,STONE)
B(-8,-3,2,STONE)
B(-8,-3,3,STONE)
B(-8,-3,4,STONE)
B(-8,-3,5,STONE)
B(-8,-3,6,STONE)
B(-8,-3,7,STONE)
B(-8,-3,8,STONE)
B(-8,-3,9,STONE)
B(-8,-3,10,STONE)
B(-8,-3,11,STONE)
B(-8,-2,-15,STONE)
B(-8,-2,-14,STONE)
B(-8,-2,-13,STONE)
B(-8,-2,-12,STONE)
B(-8,-2,-11,STONE)
B(-8,-2,-10,STONE)
B(-8,-2,-9,STONE)
B(-8,-2,-8,STONE)
B(-8,-2,-7,STONE)
B(-8,-2,-6,STONE)
B(-8,-2,-5,STONE)
B(-8,-2,-4,STONE)
B(-8,-2,-3,STONE)
B(-8,-2,-2,STONE)
B(-8,-2,-1,STONE)
B(-8,-2,0,STONE)
B(-8,-2,1,STONE)
B(-8,-2,2,STONE)
B(-8,-2,3,STONE)
B(-8,-2,4,STONE)
B(-8,-2,5,STONE)
B(-8,-2,6,STONE)
B(-8,-2,7,STONE)
B(-8,-2,8,STONE)
B(-8,-2,9,STONE)
B(-8,-2,10,STONE)
B(-8,-2,11,STONE)
B(-8,-2,12,STONE)
B(-8,-1,-15,STONE)
B(-8,-1,-14,STONE)
B(-8,-1,-13,STONE)
B(-8,-1,-12,STONE)
B(-8,-1,-11,STONE)
B(-8,-1,-10,STONE)
B(-8,-1,-9,STONE)
B(-8,-1,-8,STONE)
B(-8,-1,-7,STONE)
B(-8,-1,-6,STONE)
B(-8,-1,-5,STONE)
B(-8,-1,-4,STONE)
B(-8,-1,-3,STONE)
B(-8,-1,-2,STONE)
B(-8,-1,-1,STONE)
B(-8,-1,0,STONE)
B(-8,-1,1,STONE)
B(-8,-1,2,STONE)
B(-8,-1,3,STONE)
B(-8,-1,4,STONE)
B(-8,-1,5,STONE)
B(-8,-1,6,STONE)
B(-8,-1,7,STONE)
B(-8,-1,8,STONE)
B(-8,-1,9,STONE)
B(-8,-1,10,STONE)
B(-8,-1,11,STONE)
B(-8,-1,12,STONE)
B(-8,0,-15,STONE)
B(-8,0,-14,STONE)
B(-8,0,-13,STONE)
B(-8,0,-12,STONE)
B(-8,0,-11,STONE)
B(-8,0,-10,STONE)
B(-8,0,-9,STONE)
B(-8,0,-8,STONE)
B(-8,0,-7,STONE)
B(-8,0,-6,STONE)
B(-8,0,-5,STONE)
B(-8,0,-4,STONE)
B(-8,0,-3,STONE)
B(-8,0,-2,STONE)
B(-8,0,1,STONE)
B(-8,0,2,STONE)
B(-8,0,3,STONE)
B(-8,0,4,STONE)
B(-8,0,5,STONE)
B(-8,0,6,STONE)
B(-8,0,7,STONE)
B(-8,0,8,STONE)
B(-8,0,9,STONE)
B(-8,0,10,STONE)
B(-8,0,11,STONE)
B(-8,1,-15,STONE)
B(-8,1,-14,STONE)
B(-8,1,-13,STONE)
B(-8,1,-12,STONE)
B(-8,1,-11,STONE)
B(-8,1,-10,STONE)
B(-8,1,-9,STONE)
B(-8,1,-8,STONE)
B(-8,1,-7,STONE)
B(-8,1,-6,STONE)
B(-8,1,-5,STONE)
B(-8,1,-4,STONE)
B(-8,1,-3,STONE)
B(-8,1,-2,STONE)
B(-8,1,3,STONE)
B(-8,1,4,STONE)
B(-8,1,5,STONE)
B(-8,1,6,STONE)
B(-8,1,7,STONE)
B(-8,1,8,STONE)
B(-8,1,9,STONE)
B(-8,1,10,STONE)
B(-8,2,-13,STONE)
B(-8,2,-12,STONE)
B(-8,2,-11,STONE)
B(-8,2,-10,STONE)
B(-8,2,-9,STONE)
B(-8,2,-8,STONE)
B(-8,2,-7,STONE)
B(-8,2,-6,STONE)
B(-8,2,-5,STONE)
B(-8,2,-4,STONE)
B(-8,2,7,STONE)
B(-8,2,8,STONE)
B(-8,2,9,STONE)
B(-8,3,-12,STONE)
B(-8,3,-11,STONE)
B(-8,3,-10,STONE)
B(-8,3,-9,STONE)
B(-8,3,-8,STONE)
B(-8,3,-7,STONE)
B(-8,3,-6,STONE)
B(-8,3,-5,STONE)
B(-8,4,-9,STONE)
B(-8,4,-8,STONE)
B(-8,4,-7,STONE)
B(-7,-8,-10,STONE)
B(-7,-8,-9,STONE)
B(-7,-8,-8,STONE)
B(-7,-8,-7,STONE)
B(-7,-8,-6,STONE)
B(-7,-8,-5,STONE)
B(-7,-7,-11,STONE)
B(-7,-7,-10,STONE)
B(-7,-7,-9,STONE)
B(-7,-7,-8,STONE)
B(-7,-7,-7,STONE)
B(-7,-7,-6,STONE)
B(-7,-7,-5,STONE)
B(-7,-7,-4,STONE)
B(-7,-7,8,STONE)
B(-7,-6,-12,STONE)
B(-7,-6,-11,STONE)
B(-7,-6,-10,STONE)
B(-7,-6,-9,STONE)
B(-7,-6,-8,STONE)
B(-7,-6,-7,STONE)
B(-7,-6,-6,STONE)
B(-7,-6,-5,STONE)
B(-7,-6,-4,STONE)
B(-7,-6,-3,STONE)
B(-7,-6,6,STONE)
B(-7,-6,7,STONE)
B(-7,-6,8,STONE)
B(-7,-6,9,STONE)
B(-7,-5,-13,STONE)
B(-7,-5,-12,STONE)
B(-7,-5,-11,STONE)
B(-7,-5,-10,STONE)
B(-7,-5,-9,STONE)
B(-7,-5,-8,STONE)
B(-7,-5,-7,STONE)
B(-7,-5,-6,STONE)
B(-7,-5,-5,STONE)
B(-7,-5,-4,STONE)
B(-7,-5,-3,STONE)
B(-7,-5,-2,STONE)
B(-7,-5,4,STONE)
B(-7,-5,5,STONE)
B(-7,-5,6,STONE)
B(-7,-5,7,STONE)
B(-7,-5,8,STONE)
B(-7,-5,9,STONE)
B(-7,-5,10,STONE)
B(-7,-4,-15,STONE)
B(-7,-4,-14,STONE)
B(-7,-4,-13,STONE)
B(-7,-4,-12,STONE)
B(-7,-4,-11,STONE)
B(-7,-4,-10,STONE)
B(-7,-4,-9,STONE)
B(-7,-4,-8,STONE)
B(-7,-4,-7,STONE)
B(-7,-4,-6,STONE)
B(-7,-4,-5,STONE)
B(-7,-4,-4,STONE)
B(-7,-4,-3,STONE)
B(-7,-4,-2,STONE)
B(-7,-4,-1,STONE)
B(-7,-4,0,STONE)
B(-7,-4,1,STONE)
B(-7,-4,2,STONE)
B(-7,-4,3,STONE)
B(-7,-4,4,STONE)
B(-7,-4,5,STONE)
B(-7,-4,6,STONE)
B(-7,-4,7,STONE)
B(-7,-4,8,STONE)
B(-7,-4,9,STONE)
B(-7,-4,10,STONE)
B(-7,-4,11,STONE)
B(-7,-3,-15,STONE)
B(-7,-3,-14,STONE)
B(-7,-3,-13,STONE)
B(-7,-3,-12,STONE)
B(-7,-3,-11,STONE)
B(-7,-3,-10,STONE)
B(-7,-3,-9,STONE)
B(-7,-3,-8,STONE)
B(-7,-3,-7,STONE)
B(-7,-3,-6,STONE)
B(-7,-3,-5,STONE)
B(-7,-3,-4,STONE)
B(-7,-3,-3,STONE)
B(-7,-3,-2,STONE)
B(-7,-3,-1,STONE)
B(-7,-3,0,STONE)
B(-7,-3,1,STONE)
B(-7,-3,2,STONE)
B(-7,-3,3,STONE)
B(-7,-3,4,STONE)
B(-7,-3,5,STONE)
B(-7,-3,6,STONE)
B(-7,-3,7,STONE)
B(-7,-3,8,STONE)
B(-7,-3,9,STONE)
B(-7,-3,10,STONE)
B(-7,-3,11,STONE)
B(-7,-3,12,STONE)
B(-7,-2,-15,STONE)
B(-7,-2,-14,STONE)
B(-7,-2,-13,STONE)
B(-7,-2,-12,STONE)
B(-7,-2,-11,STONE)
B(-7,-2,-10,STONE)
B(-7,-2,-9,STONE)
B(-7,-2,-8,STONE)
B(-7,-2,-7,STONE)
B(-7,-2,-6,STONE)
B(-7,-2,-5,STONE)
B(-7,-2,-4,STONE)
B(-7,-2,-3,STONE)
B(-7,-2,-2,STONE)
B(-7,-2,-1,STONE)
B(-7,-2,0,STONE)
B(-7,-2,1,STONE)
B(-7,-2,2,STONE)
B(-7,-2,3,STONE)
B(-7,-2,4,STONE)
B(-7,-2,5,STONE)
B(-7,-2,6,STONE)
B(-7,-2,7,STONE)
B(-7,-2,8,STONE)
B(-7,-2,9,STONE)
B(-7,-2,10,STONE)
B(-7,-2,11,STONE)
B(-7,-2,12,STONE)
B(-7,-2,13,STONE)
B(-7,-1,-15,STONE)
B(-7,-1,-14,STONE)
B(-7,-1,-13,STONE)
B(-7,-1,-12,STONE)
B(-7,-1,-11,STONE)
B(-7,-1,-10,STONE)
B(-7,-1,-9,STONE)
B(-7,-1,-8,STONE)
B(-7,-1,-7,STONE)
B(-7,-1,-6,STONE)
B(-7,-1,-5,STONE)
B(-7,-1,-4,STONE)
B(-7,-1,-3,STONE)
B(-7,-1,-2,STONE)
B(-7,-1,-1,STONE)
B(-7,-1,0,STONE)
B(-7,-1,1,STONE)
B(-7,-1,2,STONE)
B(-7,-1,3,STONE)
B(-7,-1,4,STONE)
B(-7,-1,5,STONE)
B(-7,-1,6,STONE)
B(-7,-1,7,STONE)
B(-7,-1,8,STONE)
B(-7,-1,9,STONE)
B(-7,-1,10,STONE)
B(-7,-1,11,STONE)
B(-7,-1,12,STONE)
B(-7,-1,13,STONE)
B(-7,0,-15,STONE)
B(-7,0,-14,STONE)
B(-7,0,-13,STONE)
B(-7,0,-12,STONE)
B(-7,0,-11,STONE)
B(-7,0,-10,STONE)
B(-7,0,-9,STONE)
B(-7,0,-8,STONE)
B(-7,0,-7,STONE)
B(-7,0,-6,STONE)
B(-7,0,-5,STONE)
B(-7,0,-4,STONE)
B(-7,0,-3,STONE)
B(-7,0,-2,STONE)
B(-7,0,-1,STONE)
B(-7,0,0,STONE)
B(-7,0,1,STONE)
B(-7,0,2,STONE)
B(-7,0,3,STONE)
B(-7,0,4,STONE)
B(-7,0,5,STONE)
B(-7,0,6,STONE)
B(-7,0,7,STONE)
B(-7,0,8,STONE)
B(-7,0,9,STONE)
B(-7,0,10,STONE)
B(-7,0,11,STONE)
B(-7,0,12,STONE)
B(-7,1,-15,STONE)
B(-7,1,-14,STONE)
B(-7,1,-13,STONE)
B(-7,1,-12,STONE)
B(-7,1,-11,STONE)
B(-7,1,-10,STONE)
B(-7,1,-9,STONE)
B(-7,1,-8,STONE)
B(-7,1,-7,STONE)
B(-7,1,-6,STONE)
B(-7,1,-5,STONE)
B(-7,1,-4,STONE)
B(-7,1,-3,STONE)
B(-7,1,-2,STONE)
B(-7,1,-1,STONE)
B(-7,1,0,STONE)
B(-7,1,1,STONE)
B(-7,1,2,STONE)
B(-7,1,3,STONE)
B(-7,1,4,STONE)
B(-7,1,5,STONE)
B(-7,1,6,STONE)
B(-7,1,7,STONE)
B(-7,1,8,STONE)
B(-7,1,9,STONE)
B(-7,1,10,STONE)
B(-7,1,11,STONE)
B(-7,2,-13,STONE)
B(-7,2,-12,STONE)
B(-7,2,-11,STONE)
B(-7,2,-10,STONE)
B(-7,2,-9,STONE)
B(-7,2,-8,STONE)
B(-7,2,-7,STONE)
B(-7,2,-6,STONE)
B(-7,2,-5,STONE)
B(-7,2,-4,STONE)
B(-7,2,-3,STONE)
B(-7,2,-2,STONE)
B(-7,2,4,STONE)
B(-7,2,5,STONE)
B(-7,2,6,STONE)
B(-7,2,7,STONE)
B(-7,2,8,STONE)
B(-7,2,9,STONE)
B(-7,2,10,STONE)
B(-7,3,-12,STONE)
B(-7,3,-11,STONE)
B(-7,3,-10,STONE)
B(-7,3,-9,STONE)
B(-7,3,-8,STONE)
B(-7,3,-7,STONE)
B(-7,3,-6,STONE)
B(-7,3,-5,STONE)
B(-7,3,-4,STONE)
B(-7,3,-3,STONE)
B(-7,3,6,STONE)
B(-7,3,7,STONE)
B(-7,3,8,STONE)
B(-7,3,9,STONE)
B(-7,4,-11,STONE)
B(-7,4,-10,STONE)
B(-7,4,-9,STONE)
B(-7,4,-8,STONE)
B(-7,4,-7,STONE)
B(-7,4,-6,STONE)
B(-7,4,-5,STONE)
B(-7,4,-4,STONE)
B(-7,4,8,STONE)
B(-7,5,-10,STONE)
B(-7,5,-9,STONE)
B(-7,5,-8,STONE)
B(-7,5,-7,STONE)
B(-7,5,-6,STONE)
B(-7,5,-5,STONE)
B(-6,-9,-9,STONE)
B(-6,-9,-8,STONE)
B(-6,-9,-7,STONE)
B(-6,-9,-6,STONE)
B(-6,-9,-5,STONE)
B(-6,-8,-11,STONE)
B(-6,-8,-10,STONE)
B(-6,-8,-9,STONE)
B(-6,-8,-8,STONE)
B(-6,-8,-7,STONE)
B(-6,-8,-6,STONE)
B(-6,-8,-5,STONE)
B(-6,-8,-4,STONE)
B(-6,-8,6,STONE)
B(-6,-8,7,STONE)
B(-6,-8,8,STONE)
B(-6,-7,-12,STONE)
B(-6,-7,-11,STONE)
B(-6,-7,-10,STONE)
B(-6,-7,-9,STONE)
B(-6,-7,-8,STONE)
B(-6,-7,-7,STONE)
B(-6,-7,-6,STONE)
B(-6,-7,-5,STONE)
B(-6,-7,-4,STONE)
B(-6,-7,-3,STONE)
B(-6,-7,5,STONE)
B(-6,-7,6,STONE)
B(-6,-7,7,STONE)
B(-6,-7,8,STONE)
B(-6,-7,9,STONE)
B(-6,-7,10,STONE)
B(-6,-6,-13,STONE)
B(-6,-6,-12,STONE)
B(-6,-6,-11,STONE)
B(-6,-6,-10,STONE)
B(-6,-6,-9,STONE)
B(-6,-6,-8,STONE)
B(-6,-6,-7,STONE)
B(-6,-6,-6,STONE)
B(-6,-6,-5,STONE)
B(-6,-6,-4,STONE)
B(-6,-6,-3,STONE)
B(-6,-6,-2,STONE)
B(-6,-6,-1,STONE)
B(-6,-6,4,STONE)
B(-6,-6,5,STONE)
B(-6,-6,6,STONE)
B(-6,-6,7,STONE)
B(-6,-6,8,STONE)
B(-6,-6,9,STONE)
B(-6,-6,10,STONE)
B(-6,-6,11,STONE)
B(-6,-5,-13,STONE)
B(-6,-5,-12,STONE)
B(-6,-5,-11,STONE)
B(-6,-5,-10,STONE)
B(-6,-5,-9,STONE)
B(-6,-5,-8,STONE)
B(-6,-5,-7,STONE)
B(-6,-5,-6,STONE)
B(-6,-5,-5,STONE)
B(-6,-5,-4,STONE)
B(-6,-5,-3,STONE)
B(-6,-5,-2,STONE)
B(-6,-5,-1,STONE)
B(-6,-5,0,STONE)
B(-6,-5,1,STONE)
B(-6,-5,2,STONE)
B(-6,-5,3,STONE)
B(-6,-5,4,STONE)
B(-6,-5,5,STONE)
B(-6,-5,6,STONE)
B(-6,-5,7,STONE)
B(-6,-5,8,STONE)
B(-6,-5,9,STONE)
B(-6,-5,10,STONE)
B(-6,-5,11,STONE)
B(-6,-4,-14,STONE)
B(-6,-4,-13,STONE)
B(-6,-4,-12,STONE)
B(-6,-4,-11,STONE)
B(-6,-4,-10,STONE)
B(-6,-4,-9,STONE)
B(-6,-4,-8,STONE)
B(-6,-4,-7,STONE)
B(-6,-4,-6,STONE)
B(-6,-4,-5,STONE)
B(-6,-4,-4,STONE)
B(-6,-4,-3,STONE)
B(-6,-4,-2,STONE)
B(-6,-4,-1,STONE)
B(-6,-4,0,STONE)
B(-6,-4,1,STONE)
B(-6,-4,2,STONE)
B(-6,-4,3,STONE)
B(-6,-4,4,STONE)
B(-6,-4,5,STONE)
B(-6,-4,6,STONE)
B(-6,-4,7,STONE)
B(-6,-4,8,STONE)
B(-6,-4,9,STONE)
B(-6,-4,10,STONE)
B(-6,-4,11,STONE)
B(-6,-4,12,STONE)
B(-6,-3,-15,STONE)
B(-6,-3,-14,STONE)
B(-6,-3,-13,STONE)
B(-6,-3,-12,STONE)
B(-6,-3,-11,STONE)
B(-6,-3,-10,STONE)
B(-6,-3,-9,STONE)
B(-6,-3,-8,STONE)
B(-6,-3,-7,STONE)
B(-6,-3,-6,STONE)
B(-6,-3,-5,STONE)
B(-6,-3,-4,STONE)
B(-6,-3,-3,STONE)
B(-6,-3,-2,STONE)
B(-6,-3,-1,STONE)
B(-6,-3,0,STONE)
B(-6,-3,1,STONE)
B(-6,-3,2,STONE)
B(-6,-3,3,STONE)
B(-6,-3,4,STONE)
B(-6,-3,5,STONE)
B(-6,-3,6,STONE)
B(-6,-3,7,STONE)
B(-6,-3,8,STONE)
B(-6,-3,9,STONE)
B(-6,-3,10,STONE)
B(-6,-3,11,STONE)
B(-6,-3,12,STONE)
B(-6,-3,13,STONE)
B(-6,-2,-15,STONE)
B(-6,-2,-14,STONE)
B(-6,-2,-13,STONE)
B(-6,-2,-12,STONE)
B(-6,-2,-11,STONE)
B(-6,-2,-10,STONE)
B(-6,-2,-9,STONE)
B(-6,-2,-8,STONE)
B(-6,-2,-7,STONE)
B(-6,-2,-6,STONE)
B(-6,-2,-5,STONE)
B(-6,-2,-4,STONE)
B(-6,-2,-3,STONE)
B(-6,-2,-2,STONE)
B(-6,-2,-1,STONE)
B(-6,-2,0,STONE)
B(-6,-2,1,STONE)
B(-6,-2,2,STONE)
B(-6,-2,3,STONE)
B(-6,-2,4,STONE)
B(-6,-2,5,STONE)
B(-6,-2,6,STONE)
B(-6,-2,7,STONE)
B(-6,-2,8,STONE)
B(-6,-2,9,STONE)
B(-6,-2,10,STONE)
B(-6,-2,11,STONE)
B(-6,-2,12,STONE)
B(-6,-2,13,STONE)
B(-6,-1,-15,STONE)
B(-6,-1,-14,STONE)
B(-6,-1,-13,STONE)
B(-6,-1,-12,STONE)
B(-6,-1,-11,STONE)
B(-6,-1,-10,STONE)
B(-6,-1,-9,STONE)
B(-6,-1,-8,STONE)
B(-6,-1,-7,STONE)
B(-6,-1,-6,STONE)
B(-6,-1,-5,STONE)
B(-6,-1,-4,STONE)
B(-6,-1,-3,STONE)
B(-6,-1,-2,STONE)
B(-6,-1,-1,STONE)
B(-6,-1,0,STONE)
B(-6,-1,1,STONE)
B(-6,-1,2,STONE)
B(-6,-1,3,STONE)
B(-6,-1,4,STONE)
B(-6,-1,5,STONE)
B(-6,-1,6,STONE)
B(-6,-1,7,STONE)
B(-6,-1,8,STONE)
B(-6,-1,9,STONE)
B(-6,-1,10,STONE)
B(-6,-1,11,STONE)
B(-6,-1,12,STONE)
B(-6,-1,13,STONE)
B(-6,0,-15,STONE)
B(-6,0,-14,STONE)
B(-6,0,-13,STONE)
B(-6,0,-12,STONE)
B(-6,0,-11,STONE)
B(-6,0,-10,STONE)
B(-6,0,-9,STONE)
B(-6,0,-8,STONE)
B(-6,0,-7,STONE)
B(-6,0,-6,STONE)
B(-6,0,-5,STONE)
B(-6,0,-4,STONE)
B(-6,0,-3,STONE)
B(-6,0,-2,STONE)
B(-6,0,-1,STONE)
B(-6,0,0,STONE)
B(-6,0,1,STONE)
B(-6,0,2,STONE)
B(-6,0,3,STONE)
B(-6,0,4,STONE)
B(-6,0,5,STONE)
B(-6,0,6,STONE)
B(-6,0,7,STONE)
B(-6,0,8,STONE)
B(-6,0,9,STONE)
B(-6,0,10,STONE)
B(-6,0,11,STONE)
B(-6,0,12,STONE)
B(-6,0,13,STONE)
B(-6,1,-14,STONE)
B(-6,1,-13,STONE)
B(-6,1,-12,STONE)
B(-6,1,-11,STONE)
B(-6,1,-10,STONE)
B(-6,1,-9,STONE)
B(-6,1,-8,STONE)
B(-6,1,-7,STONE)
B(-6,1,-6,STONE)
B(-6,1,-5,STONE)
B(-6,1,-4,STONE)
B(-6,1,-3,STONE)
B(-6,1,-2,STONE)
B(-6,1,-1,STONE)
B(-6,1,0,STONE)
B(-6,1,1,STONE)
B(-6,1,2,STONE)
B(-6,1,3,STONE)
B(-6,1,4,STONE)
B(-6,1,5,STONE)
B(-6,1,6,STONE)
B(-6,1,7,STONE)
B(-6,1,8,STONE)
B(-6,1,9,STONE)
B(-6,1,10,STONE)
B(-6,1,11,STONE)
B(-6,1,12,STONE)
B(-6,2,-13,STONE)
B(-6,2,-12,STONE)
B(-6,2,-11,STONE)
B(-6,2,-10,STONE)
B(-6,2,-9,STONE)
B(-6,2,-8,STONE)
B(-6,2,-7,STONE)
B(-6,2,-6,STONE)
B(-6,2,-5,STONE)
B(-6,2,-4,STONE)
B(-6,2,-3,STONE)
B(-6,2,-2,STONE)
B(-6,2,-1,STONE)
B(-6,2,0,STONE)
B(-6,2,1,STONE)
B(-6,2,2,STONE)
B(-6,2,3,STONE)
B(-6,2,4,STONE)
B(-6,2,5,STONE)
B(-6,2,6,STONE)
B(-6,2,7,STONE)
B(-6,2,8,STONE)
B(-6,2,9,STONE)
B(-6,2,10,STONE)
B(-6,2,11,STONE)
B(-6,3,-13,STONE)
B(-6,3,-12,STONE)
B(-6,3,-11,STONE)
B(-6,3,-10,STONE)
B(-6,3,-9,STONE)
B(-6,3,-8,STONE)
B(-6,3,-7,STONE)
B(-6,3,-6,STONE)
B(-6,3,-5,STONE)
B(-6,3,-4,STONE)
B(-6,3,-3,STONE)
B(-6,3,-2,STONE)
B(-6,3,-1,STONE)
B(-6,3,4,STONE)
B(-6,3,5,STONE)
B(-6,3,6,STONE)
B(-6,3,7,STONE)
B(-6,3,8,STONE)
B(-6,3,9,STONE)
B(-6,3,10,STONE)
B(-6,3,11,STONE)
B(-6,4,-12,STONE)
B(-6,4,-11,STONE)
B(-6,4,-10,STONE)
B(-6,4,-9,STONE)
B(-6,4,-8,STONE)
B(-6,4,-7,STONE)
B(-6,4,-6,STONE)
B(-6,4,-5,STONE)
B(-6,4,-4,STONE)
B(-6,4,-3,STONE)
B(-6,4,5,STONE)
B(-6,4,6,STONE)
B(-6,4,7,STONE)
B(-6,4,8,STONE)
B(-6,4,9,STONE)
B(-6,4,10,STONE)
B(-6,5,-11,STONE)
B(-6,5,-10,STONE)
B(-6,5,-9,STONE)
B(-6,5,-8,STONE)
B(-6,5,-7,STONE)
B(-6,5,-6,STONE)
B(-6,5,-5,STONE)
B(-6,5,-4,STONE)
B(-6,5,6,STONE)
B(-6,5,7,STONE)
B(-6,5,8,STONE)
B(-6,6,-9,STONE)
B(-6,6,-8,STONE)
B(-6,6,-7,STONE)
B(-6,6,-6,STONE)
B(-6,6,-5,STONE)
B(-5,-10,-8,STONE)
B(-5,-10,-7,STONE)
B(-5,-10,-6,STONE)
B(-5,-10,-5,STONE)
B(-5,-10,-4,STONE)
B(-5,-9,-10,STONE)
B(-5,-9,-9,STONE)
B(-5,-9,-8,STONE)
B(-5,-9,-7,STONE)
B(-5,-9,-6,STONE)
B(-5,-9,-5,STONE)
B(-5,-9,-4,STONE)
B(-5,-9,-3,STONE)
B(-5,-9,5,STONE)
B(-5,-9,6,STONE)
B(-5,-9,7,STONE)
B(-5,-9,8,STONE)
B(-5,-9,9,STONE)
B(-5,-8,-11,STONE)
B(-5,-8,-10,STONE)
B(-5,-8,-9,STONE)
B(-5,-8,-8,STONE)
B(-5,-8,-7,STONE)
B(-5,-8,-6,STONE)
B(-5,-8,-5,STONE)
B(-5,-8,-4,STONE)
B(-5,-8,-3,STONE)
B(-5,-8,-2,STONE)
B(-5,-8,4,STONE)
B(-5,-8,5,STONE)
B(-5,-8,6,STONE)
B(-5,-8,7,STONE)
B(-5,-8,8,STONE)
B(-5,-8,9,STONE)
B(-5,-8,10,STONE)
B(-5,-7,-12,STONE)
B(-5,-7,-11,STONE)
B(-5,-7,-10,STONE)
B(-5,-7,-9,STONE)
B(-5,-7,-8,STONE)
B(-5,-7,-7,STONE)
B(-5,-7,-6,STONE)
B(-5,-7,-5,STONE)
B(-5,-7,-4,STONE)
B(-5,-7,-3,STONE)
B(-5,-7,-2,STONE)
B(-5,-7,-1,STONE)
B(-5,-7,0,STONE)
B(-5,-7,1,STONE)
B(-5,-7,2,STONE)
B(-5,-7,3,STONE)
B(-5,-7,4,STONE)
B(-5,-7,5,STONE)
B(-5,-7,6,STONE)
B(-5,-7,7,STONE)
B(-5,-7,8,STONE)
B(-5,-7,9,STONE)
B(-5,-7,10,STONE)
B(-5,-7,11,STONE)
B(-5,-6,-13,STONE)
B(-5,-6,-12,STONE)
B(-5,-6,-11,STONE)
B(-5,-6,-10,STONE)
B(-5,-6,-9,STONE)
B(-5,-6,-8,STONE)
B(-5,-6,-7,STONE)
B(-5,-6,-6,STONE)
B(-5,-6,-5,STONE)
B(-5,-6,-4,STONE)
B(-5,-6,-3,STONE)
B(-5,-6,-2,STONE)
B(-5,-6,-1,STONE)
B(-5,-6,0,STONE)
B(-5,-6,1,STONE)
B(-5,-6,2,STONE)
B(-5,-6,3,STONE)
B(-5,-6,4,STONE)
B(-5,-6,5,STONE)
B(-5,-6,6,STONE)
B(-5,-6,7,STONE)
B(-5,-6,8,STONE)
B(-5,-6,9,STONE)
B(-5,-6,10,STONE)
B(-5,-6,11,STONE)
B(-5,-5,-13,STONE)
B(-5,-5,-12,STONE)
B(-5,-5,-11,STONE)
B(-5,-5,-10,STONE)
B(-5,-5,-9,STONE)
B(-5,-5,-8,STONE)
B(-5,-5,-7,STONE)
B(-5,-5,-6,STONE)
B(-5,-5,-5,STONE)
B(-5,-5,-4,STONE)
B(-5,-5,-3,STONE)
B(-5,-5,-2,STONE)
B(-5,-5,-1,STONE)
B(-5,-5,0,STONE)
B(-5,-5,1,STONE)
B(-5,-5,2,STONE)
B(-5,-5,3,STONE)
B(-5,-5,4,STONE)
B(-5,-5,5,STONE)
B(-5,-5,6,STONE)
B(-5,-5,7,STONE)
B(-5,-5,8,STONE)
B(-5,-5,9,STONE)
B(-5,-5,10,STONE)
B(-5,-5,11,STONE)
B(-5,-5,12,STONE)
B(-5,-4,-14,STONE)
B(-5,-4,-13,STONE)
B(-5,-4,-12,STONE)
B(-5,-4,-11,STONE)
B(-5,-4,-10,STONE)
B(-5,-4,-9,STONE)
B(-5,-4,-8,STONE)
B(-5,-4,-7,STONE)
B(-5,-4,-6,STONE)
B(-5,-4,-5,STONE)
B(-5,-4,-4,STONE)
B(-5,-4,-3,STONE)
B(-5,-4,-2,STONE)
B(-5,-4,-1,STONE)
B(-5,-4,0,STONE)
B(-5,-4,1,STONE)
B(-5,-4,2,STONE)
B(-5,-4,3,STONE)
B(-5,-4,4,STONE)
B(-5,-4,5,STONE)
B(-5,-4,6,STONE)
B(-5,-4,7,STONE)
B(-5,-4,8,STONE)
B(-5,-4,9,STONE)
B(-5,-4,10,STONE)
B(-5,-4,11,STONE)
B(-5,-4,12,STONE)
B(-5,-4,13,STONE)
B(-5,-3,-14,STONE)
B(-5,-3,-13,STONE)
B(-5,-3,-12,STONE)
B(-5,-3,-11,STONE)
B(-5,-3,-10,STONE)
B(-5,-3,-9,STONE)
B(-5,-3,-8,STONE)
B(-5,-3,-7,STONE)
B(-5,-3,-6,STONE)
B(-5,-3,-5,STONE)
B(-5,-3,-4,STONE)
B(-5,-3,-3,STONE)
B(-5,-3,-2,STONE)
B(-5,-3,-1,STONE)
B(-5,-3,0,STONE)
B(-5,-3,1,STONE)
B(-5,-3,2,STONE)
B(-5,-3,3,STONE)
B(-5,-3,4,STONE)
B(-5,-3,5,STONE)
B(-5,-3,6,STONE)
B(-5,-3,7,STONE)
B(-5,-3,8,STONE)
B(-5,-3,9,STONE)
B(-5,-3,10,STONE)
B(-5,-3,11,STONE)
B(-5,-3,12,STONE)
B(-5,-3,13,STONE)
B(-5,-2,-15,STONE)
B(-5,-2,-14,STONE)
B(-5,-2,-13,STONE)
B(-5,-2,-12,STONE)
B(-5,-2,-11,STONE)
B(-5,-2,-10,STONE)
B(-5,-2,-9,STONE)
B(-5,-2,-8,STONE)
B(-5,-2,-7,STONE)
B(-5,-2,-6,STONE)
B(-5,-2,-5,STONE)
B(-5,-2,-4,STONE)
B(-5,-2,-3,STONE)
B(-5,-2,-2,STONE)
B(-5,-2,-1,STONE)
B(-5,-2,0,STONE)
B(-5,-2,1,STONE)
B(-5,-2,2,STONE)
B(-5,-2,3,STONE)
B(-5,-2,4,STONE)
B(-5,-2,5,STONE)
B(-5,-2,6,STONE)
B(-5,-2,7,STONE)
B(-5,-2,8,STONE)
B(-5,-2,9,STONE)
B(-5,-2,10,STONE)
B(-5,-2,11,STONE)
B(-5,-2,12,STONE)
B(-5,-2,13,STONE)
B(-5,-2,14,STONE)
B(-5,-1,-15,STONE)
B(-5,-1,-14,STONE)
B(-5,-1,-13,STONE)
B(-5,-1,-12,STONE)
B(-5,-1,-11,STONE)
B(-5,-1,-10,STONE)
B(-5,-1,-9,STONE)
B(-5,-1,-8,STONE)
B(-5,-1,-7,STONE)
B(-5,-1,-6,STONE)
B(-5,-1,-5,STONE)
B(-5,-1,-4,STONE)
B(-5,-1,-3,STONE)
B(-5,-1,-2,STONE)
B(-5,-1,-1,STONE)
B(-5,-1,0,STONE)
B(-5,-1,1,STONE)
B(-5,-1,2,STONE)
B(-5,-1,3,STONE)
B(-5,-1,4,STONE)
B(-5,-1,5,STONE)
B(-5,-1,6,STONE)
B(-5,-1,7,STONE)
B(-5,-1,8,STONE)
B(-5,-1,9,STONE)
B(-5,-1,10,STONE)
B(-5,-1,11,STONE)
B(-5,-1,12,STONE)
B(-5,-1,13,STONE)
B(-5,-1,14,STONE)
B(-5,0,-14,STONE)
B(-5,0,-13,STONE)
B(-5,0,-12,STONE)
B(-5,0,-11,STONE)
B(-5,0,-10,STONE)
B(-5,0,-9,STONE)
B(-5,0,-8,STONE)
B(-5,0,-7,STONE)
B(-5,0,-6,STONE)
B(-5,0,-5,STONE)
B(-5,0,-4,STONE)
B(-5,0,-3,STONE)
B(-5,0,-2,STONE)
B(-5,0,-1,STONE)
B(-5,0,0,STONE)
B(-5,0,1,STONE)
B(-5,0,2,STONE)
B(-5,0,3,STONE)
B(-5,0,4,STONE)
B(-5,0,5,STONE)
B(-5,0,6,STONE)
B(-5,0,7,STONE)
B(-5,0,8,STONE)
B(-5,0,9,STONE)
B(-5,0,10,STONE)
B(-5,0,11,STONE)
B(-5,0,12,STONE)
B(-5,0,13,STONE)
B(-5,1,-14,STONE)
B(-5,1,-13,STONE)
B(-5,1,-12,STONE)
B(-5,1,-11,STONE)
B(-5,1,-10,STONE)
B(-5,1,-9,STONE)
B(-5,1,-8,STONE)
B(-5,1,-7,STONE)
B(-5,1,-6,STONE)
B(-5,1,-5,STONE)
B(-5,1,-4,STONE)
B(-5,1,-3,STONE)
B(-5,1,-2,STONE)
B(-5,1,-1,STONE)
B(-5,1,0,STONE)
B(-5,1,1,STONE)
B(-5,1,2,STONE)
B(-5,1,3,STONE)
B(-5,1,4,STONE)
B(-5,1,5,STONE)
B(-5,1,6,STONE)
B(-5,1,7,STONE)
B(-5,1,8,STONE)
B(-5,1,9,STONE)
B(-5,1,10,STONE)
B(-5,1,11,STONE)
B(-5,1,12,STONE)
B(-5,1,13,STONE)
B(-5,2,-13,STONE)
B(-5,2,-12,STONE)
B(-5,2,-11,STONE)
B(-5,2,-10,STONE)
B(-5,2,-9,STONE)
B(-5,2,-8,STONE)
B(-5,2,-7,STONE)
B(-5,2,-6,STONE)
B(-5,2,-5,STONE)
B(-5,2,-4,STONE)
B(-5,2,-3,STONE)
B(-5,2,-2,STONE)
B(-5,2,-1,STONE)
B(-5,2,0,STONE)
B(-5,2,1,STONE)
B(-5,2,2,STONE)
B(-5,2,3,STONE)
B(-5,2,4,STONE)
B(-5,2,5,STONE)
B(-5,2,6,STONE)
B(-5,2,7,STONE)
B(-5,2,8,STONE)
B(-5,2,9,STONE)
B(-5,2,10,STONE)
B(-5,2,11,STONE)
B(-5,2,12,STONE)
B(-5,3,-13,STONE)
B(-5,3,-12,STONE)
B(-5,3,-11,STONE)
B(-5,3,-10,STONE)
B(-5,3,-9,STONE)
B(-5,3,-8,STONE)
B(-5,3,-7,STONE)
B(-5,3,-6,STONE)
B(-5,3,-5,STONE)
B(-5,3,-4,STONE)
B(-5,3,-3,STONE)
B(-5,3,-2,STONE)
B(-5,3,-1,STONE)
B(-5,3,0,STONE)
B(-5,3,1,STONE)
B(-5,3,2,STONE)
B(-5,3,3,STONE)
B(-5,3,4,STONE)
B(-5,3,5,STONE)
B(-5,3,6,STONE)
B(-5,3,7,STONE)
B(-5,3,8,STONE)
B(-5,3,9,STONE)
B(-5,3,10,STONE)
B(-5,3,11,STONE)
B(-5,4,-12,STONE)
B(-5,4,-11,STONE)
B(-5,4,-10,STONE)
B(-5,4,-9,STONE)
B(-5,4,-8,STONE)
B(-5,4,-7,STONE)
B(-5,4,-6,STONE)
B(-5,4,-5,STONE)
B(-5,4,-4,STONE)
B(-5,4,-3,STONE)
B(-5,4,-2,STONE)
B(-5,4,-1,STONE)
B(-5,4,0,STONE)
B(-5,4,1,STONE)
B(-5,4,2,STONE)
B(-5,4,3,STONE)
B(-5,4,4,STONE)
B(-5,4,5,STONE)
B(-5,4,6,STONE)
B(-5,4,7,STONE)
B(-5,4,8,STONE)
B(-5,4,9,STONE)
B(-5,4,10,STONE)
B(-5,4,11,STONE)
B(-5,5,-11,STONE)
B(-5,5,-10,STONE)
B(-5,5,-9,STONE)
B(-5,5,-8,STONE)
B(-5,5,-7,STONE)
B(-5,5,-6,STONE)
B(-5,5,-5,STONE)
B(-5,5,-4,STONE)
B(-5,5,-3,STONE)
B(-5,5,-2,STONE)
B(-5,5,4,STONE)
B(-5,5,5,STONE)
B(-5,5,6,STONE)
B(-5,5,7,STONE)
B(-5,5,8,STONE)
B(-5,5,9,STONE)
B(-5,5,10,STONE)
B(-5,6,-10,STONE)
B(-5,6,-9,STONE)
B(-5,6,-8,STONE)
B(-5,6,-7,STONE)
B(-5,6,-6,STONE)
B(-5,6,-5,STONE)
B(-5,6,-4,STONE)
B(-5,6,-3,STONE)
B(-5,6,5,STONE)
B(-5,6,6,STONE)
B(-5,6,7,STONE)
B(-5,6,8,STONE)
B(-5,6,9,STONE)
B(-5,7,-8,STONE)
B(-5,7,-7,STONE)
B(-5,7,-6,STONE)
B(-5,7,-5,STONE)
B(-5,7,-4,STONE)
B(-4,-11,-6,STONE)
B(-4,-11,-5,STONE)
B(-4,-11,5,STONE)
B(-4,-11,6,STONE)
B(-4,-11,7,STONE)
B(-4,-10,-8,STONE)
B(-4,-10,-7,STONE)
B(-4,-10,-6,STONE)
B(-4,-10,-5,STONE)
B(-4,-10,-4,STONE)
B(-4,-10,-3,STONE)
B(-4,-10,-2,STONE)
B(-4,-10,3,STONE)
B(-4,-10,4,STONE)
B(-4,-10,5,STONE)
B(-4,-10,6,STONE)
B(-4,-10,7,STONE)
B(-4,-10,8,STONE)
B(-4,-10,9,STONE)
B(-4,-9,-10,STONE)
B(-4,-9,-9,STONE)
B(-4,-9,-8,STONE)
B(-4,-9,-7,STONE)
B(-4,-9,-6,STONE)
B(-4,-9,-5,STONE)
B(-4,-9,-4,STONE)
B(-4,-9,-3,STONE)
B(-4,-9,-2,STONE)
B(-4,-9,-1,STONE)
B(-4,-9,0,STONE)
B(-4,-9,1,STONE)
B(-4,-9,2,STONE)
B(-4,-9,3,STONE)
B(-4,-9,4,STONE)
B(-4,-9,5,STONE)
B(-4,-9,6,STONE)
B(-4,-9,7,STONE)
B(-4,-9,8,STONE)
B(-4,-9,9,STONE)
B(-4,-9,10,STONE)
B(-4,-8,-11,STONE)
B(-4,-8,-10,STONE)
B(-4,-8,-9,STONE)
B(-4,-8,-8,STONE)
B(-4,-8,-7,STONE)
B(-4,-8,-6,STONE)
B(-4,-8,-5,STONE)
B(-4,-8,-4,STONE)
B(-4,-8,-3,STONE)
B(-4,-8,-2,STONE)
B(-4,-8,-1,STONE)
B(-4,-8,0,STONE)
B(-4,-8,1,STONE)
B(-4,-8,2,STONE)
B(-4,-8,3,STONE)
B(-4,-8,4,STONE)
B(-4,-8,5,STONE)
B(-4,-8,6,STONE)
B(-4,-8,7,STONE)
B(-4,-8,8,STONE)
B(-4,-8,9,STONE)
B(-4,-8,10,STONE)
B(-4,-7,-12,STONE)
B(-4,-7,-11,STONE)
B(-4,-7,-10,STONE)
B(-4,-7,-9,STONE)
B(-4,-7,-8,STONE)
B(-4,-7,-7,STONE)
B(-4,-7,-6,STONE)
B(-4,-7,-5,STONE)
B(-4,-7,-4,STONE)
B(-4,-7,-3,STONE)
B(-4,-7,-2,STONE)
B(-4,-7,-1,STONE)
B(-4,-7,0,STONE)
B(-4,-7,1,STONE)
B(-4,-7,2,STONE)
B(-4,-7,3,STONE)
B(-4,-7,4,STONE)
B(-4,-7,5,STONE)
B(-4,-7,6,STONE)
B(-4,-7,7,STONE)
B(-4,-7,8,STONE)
B(-4,-7,9,STONE)
B(-4,-7,10,STONE)
B(-4,-7,11,STONE)
B(-4,-6,-12,STONE)
B(-4,-6,-11,STONE)
B(-4,-6,-10,STONE)
B(-4,-6,-9,STONE)
B(-4,-6,-8,STONE)
B(-4,-6,-7,STONE)
B(-4,-6,-6,STONE)
B(-4,-6,-5,STONE)
B(-4,-6,-4,STONE)
B(-4,-6,-3,STONE)
B(-4,-6,-2,STONE)
B(-4,-6,-1,STONE)
B(-4,-6,0,STONE)
B(-4,-6,1,STONE)
B(-4,-6,2,STONE)
B(-4,-6,3,STONE)
B(-4,-6,4,STONE)
B(-4,-6,5,STONE)
B(-4,-6,6,STONE)
B(-4,-6,7,STONE)
B(-4,-6,8,STONE)
B(-4,-6,9,STONE)
B(-4,-6,10,STONE)
B(-4,-6,11,STONE)
B(-4,-5,-13,STONE)
B(-4,-5,-12,STONE)
B(-4,-5,-11,STONE)
B(-4,-5,-10,STONE)
B(-4,-5,-9,STONE)
B(-4,-5,-8,STONE)
B(-4,-5,-7,STONE)
B(-4,-5,-6,STONE)
B(-4,-5,-5,STONE)
B(-4,-5,-4,STONE)
B(-4,-5,-3,STONE)
B(-4,-5,-2,STONE)
B(-4,-5,-1,STONE)
B(-4,-5,0,STONE)
B(-4,-5,1,STONE)
B(-4,-5,2,STONE)
B(-4,-5,3,STONE)
B(-4,-5,4,STONE)
B(-4,-5,5,STONE)
B(-4,-5,6,STONE)
B(-4,-5,7,STONE)
B(-4,-5,8,STONE)
B(-4,-5,9,STONE)
B(-4,-5,10,STONE)
B(-4,-5,11,STONE)
B(-4,-5,12,STONE)
B(-4,-4,-14,STONE)
B(-4,-4,-13,STONE)
B(-4,-4,-12,STONE)
B(-4,-4,-11,STONE)
B(-4,-4,-10,STONE)
B(-4,-4,-9,STONE)
B(-4,-4,-8,STONE)
B(-4,-4,-7,STONE)
B(-4,-4,-6,STONE)
B(-4,-4,-5,STONE)
B(-4,-4,-4,STONE)
B(-4,-4,-3,STONE)
B(-4,-4,-2,STONE)
B(-4,-4,-1,STONE)
B(-4,-4,0,STONE)
B(-4,-4,1,STONE)
B(-4,-4,2,STONE)
B(-4,-4,3,STONE)
B(-4,-4,4,STONE)
B(-4,-4,5,STONE)
B(-4,-4,6,STONE)
B(-4,-4,7,STONE)
B(-4,-4,8,STONE)
B(-4,-4,9,STONE)
B(-4,-4,10,STONE)
B(-4,-4,11,STONE)
B(-4,-4,12,STONE)
B(-4,-4,13,STONE)
B(-4,-3,-14,STONE)
B(-4,-3,-13,STONE)
B(-4,-3,-12,STONE)
B(-4,-3,-11,STONE)
B(-4,-3,-10,STONE)
B(-4,-3,-9,STONE)
B(-4,-3,-8,STONE)
B(-4,-3,-7,STONE)
B(-4,-3,-6,STONE)
B(-4,-3,-5,STONE)
B(-4,-3,-4,STONE)
B(-4,-3,-3,STONE)
B(-4,-3,-2,STONE)
B(-4,-3,-1,STONE)
B(-4,-3,0,STONE)
B(-4,-3,1,STONE)
B(-4,-3,2,STONE)
B(-4,-3,3,STONE)
B(-4,-3,4,STONE)
B(-4,-3,5,STONE)
B(-4,-3,6,STONE)
B(-4,-3,7,STONE)
B(-4,-3,8,STONE)
B(-4,-3,9,STONE)
B(-4,-3,10,STONE)
B(-4,-3,11,STONE)
B(-4,-3,12,STONE)
B(-4,-3,13,STONE)
B(-4,-3,14,STONE)
B(-4,-2,-15,STONE)
B(-4,-2,-14,STONE)
B(-4,-2,-13,STONE)
B(-4,-2,-12,STONE)
B(-4,-2,-11,STONE)
B(-4,-2,-10,STONE)
B(-4,-2,-9,STONE)
B(-4,-2,-8,STONE)
B(-4,-2,-7,STONE)
B(-4,-2,-6,STONE)
B(-4,-2,-5,STONE)
B(-4,-2,-4,STONE)
B(-4,-2,-3,STONE)
B(-4,-2,-2,STONE)
B(-4,-2,-1,STONE)
B(-4,-2,0,STONE)
B(-4,-2,1,STONE)
B(-4,-2,2,STONE)
B(-4,-2,3,STONE)
B(-4,-2,4,STONE)
B(-4,-2,5,STONE)
B(-4,-2,6,STONE)
B(-4,-2,7,STONE)
B(-4,-2,8,STONE)
B(-4,-2,9,STONE)
B(-4,-2,10,STONE)
B(-4,-2,11,STONE)
B(-4,-2,12,STONE)
B(-4,-2,13,STONE)
B(-4,-2,14,STONE)
B(-4,-1,-15,STONE)
B(-4,-1,-14,STONE)
B(-4,-1,-13,STONE)
B(-4,-1,-12,STONE)
B(-4,-1,-11,STONE)
B(-4,-1,-10,STONE)
B(-4,-1,-9,STONE)
B(-4,-1,-8,STONE)
B(-4,-1,-7,STONE)
B(-4,-1,-6,STONE)
B(-4,-1,-5,STONE)
B(-4,-1,-4,STONE)
B(-4,-1,-3,STONE)
B(-4,-1,-2,STONE)
B(-4,-1,-1,STONE)
B(-4,-1,0,STONE)
B(-4,-1,1,STONE)
B(-4,-1,2,STONE)
B(-4,-1,3,STONE)
B(-4,-1,4,STONE)
B(-4,-1,5,STONE)
B(-4,-1,6,STONE)
B(-4,-1,7,STONE)
B(-4,-1,8,STONE)
B(-4,-1,9,STONE)
B(-4,-1,10,STONE)
B(-4,-1,11,STONE)
B(-4,-1,12,STONE)
B(-4,-1,13,STONE)
B(-4,-1,14,STONE)
B(-4,0,-14,STONE)
B(-4,0,-13,STONE)
B(-4,0,-12,STONE)
B(-4,0,-11,STONE)
B(-4,0,-10,STONE)
B(-4,0,-9,STONE)
B(-4,0,-8,STONE)
B(-4,0,-7,STONE)
B(-4,0,-6,STONE)
B(-4,0,-5,STONE)
B(-4,0,-4,STONE)
B(-4,0,-3,STONE)
B(-4,0,-2,STONE)
B(-4,0,-1,STONE)
B(-4,0,0,STONE)
B(-4,0,1,STONE)
B(-4,0,2,STONE)
B(-4,0,3,STONE)
B(-4,0,4,STONE)
B(-4,0,5,STONE)
B(-4,0,6,STONE)
B(-4,0,7,STONE)
B(-4,0,8,STONE)
B(-4,0,9,STONE)
B(-4,0,10,STONE)
B(-4,0,11,STONE)
B(-4,0,12,STONE)
B(-4,0,13,STONE)
B(-4,0,14,STONE)
B(-4,1,-14,STONE)
B(-4,1,-13,STONE)
B(-4,1,-12,STONE)
B(-4,1,-11,STONE)
B(-4,1,-10,STONE)
B(-4,1,-9,STONE)
B(-4,1,-8,STONE)
B(-4,1,-7,STONE)
B(-4,1,-6,STONE)
B(-4,1,-5,STONE)
B(-4,1,-4,STONE)
B(-4,1,-3,STONE)
B(-4,1,-2,STONE)
B(-4,1,-1,STONE)
B(-4,1,0,STONE)
B(-4,1,1,STONE)
B(-4,1,2,STONE)
B(-4,1,3,STONE)
B(-4,1,4,STONE)
B(-4,1,5,STONE)
B(-4,1,6,STONE)
B(-4,1,7,STONE)
B(-4,1,8,STONE)
B(-4,1,9,STONE)
B(-4,1,10,STONE)
B(-4,1,11,STONE)
B(-4,1,12,STONE)
B(-4,1,13,STONE)
B(-4,2,-13,STONE)
B(-4,2,-12,STONE)
B(-4,2,-11,STONE)
B(-4,2,-10,STONE)
B(-4,2,-9,STONE)
B(-4,2,-8,STONE)
B(-4,2,-7,STONE)
B(-4,2,-6,STONE)
B(-4,2,-5,STONE)
B(-4,2,-4,STONE)
B(-4,2,-3,STONE)
B(-4,2,-2,STONE)
B(-4,2,-1,STONE)
B(-4,2,0,STONE)
B(-4,2,1,STONE)
B(-4,2,2,STONE)
B(-4,2,3,STONE)
B(-4,2,4,STONE)
B(-4,2,5,STONE)
B(-4,2,6,STONE)
B(-4,2,7,STONE)
B(-4,2,8,STONE)
B(-4,2,9,STONE)
B(-4,2,10,STONE)
B(-4,2,11,STONE)
B(-4,2,12,STONE)
B(-4,3,-12,STONE)
B(-4,3,-11,STONE)
B(-4,3,-10,STONE)
B(-4,3,-9,STONE)
B(-4,3,-8,STONE)
B(-4,3,-7,STONE)
B(-4,3,-6,STONE)
B(-4,3,-5,STONE)
B(-4,3,-4,STONE)
B(-4,3,-3,STONE)
B(-4,3,-2,STONE)
B(-4,3,-1,STONE)
B(-4,3,0,STONE)
B(-4,3,1,STONE)
B(-4,3,2,STONE)
B(-4,3,3,STONE)
B(-4,3,4,STONE)
B(-4,3,5,STONE)
B(-4,3,6,STONE)
B(-4,3,7,STONE)
B(-4,3,8,STONE)
B(-4,3,9,STONE)
B(-4,3,10,STONE)
B(-4,3,11,STONE)
B(-4,4,-12,STONE)
B(-4,4,-11,STONE)
B(-4,4,-10,STONE)
B(-4,4,-9,STONE)
B(-4,4,-8,STONE)
B(-4,4,-7,STONE)
B(-4,4,-6,STONE)
B(-4,4,-5,STONE)
B(-4,4,-4,STONE)
B(-4,4,-3,STONE)
B(-4,4,-2,STONE)
B(-4,4,-1,STONE)
B(-4,4,0,STONE)
B(-4,4,1,STONE)
B(-4,4,2,STONE)
B(-4,4,3,STONE)
B(-4,4,4,STONE)
B(-4,4,5,STONE)
B(-4,4,6,STONE)
B(-4,4,7,STONE)
B(-4,4,8,STONE)
B(-4,4,9,STONE)
B(-4,4,10,STONE)
B(-4,4,11,STONE)
B(-4,5,-11,STONE)
B(-4,5,-10,STONE)
B(-4,5,-9,STONE)
B(-4,5,-8,STONE)
B(-4,5,-7,STONE)
B(-4,5,-6,STONE)
B(-4,5,-5,STONE)
B(-4,5,-4,STONE)
B(-4,5,-3,STONE)
B(-4,5,-2,STONE)
B(-4,5,-1,STONE)
B(-4,5,0,STONE)
B(-4,5,1,STONE)
B(-4,5,2,STONE)
B(-4,5,3,STONE)
B(-4,5,4,STONE)
B(-4,5,5,STONE)
B(-4,5,6,STONE)
B(-4,5,7,STONE)
B(-4,5,8,STONE)
B(-4,5,9,STONE)
B(-4,5,10,STONE)
B(-4,6,-10,STONE)
B(-4,6,-9,STONE)
B(-4,6,-8,STONE)
B(-4,6,-7,STONE)
B(-4,6,-6,STONE)
B(-4,6,-5,STONE)
B(-4,6,-4,STONE)
B(-4,6,-3,STONE)
B(-4,6,-2,STONE)
B(-4,6,-1,STONE)
B(-4,6,0,STONE)
B(-4,6,1,STONE)
B(-4,6,2,STONE)
B(-4,6,3,STONE)
B(-4,6,4,STONE)
B(-4,6,5,STONE)
B(-4,6,6,STONE)
B(-4,6,7,STONE)
B(-4,6,8,STONE)
B(-4,6,9,STONE)
B(-4,6,10,STONE)
B(-4,7,-8,STONE)
B(-4,7,-7,STONE)
B(-4,7,-6,STONE)
B(-4,7,-5,STONE)
B(-4,7,-4,STONE)
B(-4,7,-3,STONE)
B(-4,7,-2,STONE)
B(-4,7,3,STONE)
B(-4,7,4,STONE)
B(-4,7,5,STONE)
B(-4,7,6,STONE)
B(-4,7,7,STONE)
B(-4,7,8,STONE)
B(-4,7,9,STONE)
B(-4,8,-6,STONE)
B(-4,8,-5,STONE)
B(-4,8,5,STONE)
B(-4,8,6,STONE)
B(-4,8,7,STONE)
B(-3,-12,2,STONE)
B(-3,-12,3,STONE)
B(-3,-12,4,STONE)
B(-3,-12,5,STONE)
B(-3,-12,6,STONE)
B(-3,-11,-7,STONE)
B(-3,-11,-6,STONE)
B(-3,-11,-5,STONE)
B(-3,-11,-4,STONE)
B(-3,-11,-3,STONE)
B(-3,-11,-2,STONE)
B(-3,-11,-1,STONE)
B(-3,-11,0,STONE)
B(-3,-11,1,STONE)
B(-3,-11,2,STONE)
B(-3,-11,3,STONE)
B(-3,-11,4,STONE)
B(-3,-11,5,STONE)
B(-3,-11,6,STONE)
B(-3,-11,7,STONE)
B(-3,-11,8,STONE)
B(-3,-10,-8,STONE)
B(-3,-10,-7,STONE)
B(-3,-10,-6,STONE)
B(-3,-10,-5,STONE)
B(-3,-10,-4,STONE)
B(-3,-10,-3,STONE)
B(-3,-10,-2,STONE)
B(-3,-10,-1,STONE)
B(-3,-10,0,STONE)
B(-3,-10,1,STONE)
B(-3,-10,2,STONE)
B(-3,-10,3,STONE)
B(-3,-10,4,STONE)
B(-3,-10,5,STONE)
B(-3,-10,6,STONE)
B(-3,-10,7,STONE)
B(-3,-10,8,STONE)
B(-3,-10,9,STONE)
B(-3,-9,-9,STONE)
B(-3,-9,-8,STONE)
B(-3,-9,-7,STONE)
B(-3,-9,-6,STONE)
B(-3,-9,-5,STONE)
B(-3,-9,-4,STONE)
B(-3,-9,-3,STONE)
B(-3,-9,-2,STONE)
B(-3,-9,-1,STONE)
B(-3,-9,0,STONE)
B(-3,-9,1,STONE)
B(-3,-9,2,STONE)
B(-3,-9,3,STONE)
B(-3,-9,4,STONE)
B(-3,-9,5,STONE)
B(-3,-9,6,STONE)
B(-3,-9,7,STONE)
B(-3,-9,8,STONE)
B(-3,-9,9,STONE)
B(-3,-9,10,STONE)
B(-3,-8,-10,STONE)
B(-3,-8,-9,STONE)
B(-3,-8,-8,STONE)
B(-3,-8,-7,STONE)
B(-3,-8,-6,STONE)
B(-3,-8,-5,STONE)
B(-3,-8,-4,STONE)
B(-3,-8,-3,STONE)
B(-3,-8,-2,STONE)
B(-3,-8,-1,STONE)
B(-3,-8,0,STONE)
B(-3,-8,1,STONE)
B(-3,-8,2,STONE)
B(-3,-8,3,STONE)
B(-3,-8,4,STONE)
B(-3,-8,5,STONE)
B(-3,-8,6,STONE)
B(-3,-8,7,STONE)
B(-3,-8,8,STONE)
B(-3,-8,9,STONE)
B(-3,-8,10,STONE)
B(-3,-7,-11,STONE)
B(-3,-7,-10,STONE)
B(-3,-7,-9,STONE)
B(-3,-7,-8,STONE)
B(-3,-7,-7,STONE)
B(-3,-7,-6,STONE)
B(-3,-7,-5,STONE)
B(-3,-7,-4,STONE)
B(-3,-7,-3,STONE)
B(-3,-7,-2,STONE)
B(-3,-7,-1,STONE)
B(-3,-7,0,STONE)
B(-3,-7,1,STONE)
B(-3,-7,2,STONE)
B(-3,-7,3,STONE)
B(-3,-7,4,STONE)
B(-3,-7,5,STONE)
B(-3,-7,6,STONE)
B(-3,-7,7,STONE)
B(-3,-7,8,STONE)
B(-3,-7,9,STONE)
B(-3,-7,10,STONE)
B(-3,-7,11,STONE)
B(-3,-6,-11,STONE)
B(-3,-6,-10,STONE)
B(-3,-6,-9,STONE)
B(-3,-6,-8,STONE)
B(-3,-6,-7,STONE)
B(-3,-6,-6,STONE)
B(-3,-6,-5,STONE)
B(-3,-6,-4,STONE)
B(-3,-6,-3,STONE)
B(-3,-6,-2,STONE)
B(-3,-6,-1,STONE)
B(-3,-6,0,STONE)
B(-3,-6,1,STONE)
B(-3,-6,2,STONE)
B(-3,-6,3,STONE)
B(-3,-6,4,STONE)
B(-3,-6,5,STONE)
B(-3,-6,6,STONE)
B(-3,-6,7,STONE)
B(-3,-6,8,STONE)
B(-3,-6,9,STONE)
B(-3,-6,10,STONE)
B(-3,-6,11,STONE)
B(-3,-5,-12,STONE)
B(-3,-5,-11,STONE)
B(-3,-5,-10,STONE)
B(-3,-5,-9,STONE)
B(-3,-5,-8,STONE)
B(-3,-5,-7,STONE)
B(-3,-5,-6,STONE)
B(-3,-5,-5,STONE)
B(-3,-5,-4,STONE)
B(-3,-5,-3,STONE)
B(-3,-5,-2,STONE)
B(-3,-5,-1,STONE)
B(-3,-5,0,STONE)
B(-3,-5,1,STONE)
B(-3,-5,2,STONE)
B(-3,-5,3,STONE)
B(-3,-5,4,STONE)
B(-3,-5,5,STONE)
B(-3,-5,6,STONE)
B(-3,-5,7,STONE)
B(-3,-5,8,STONE)
B(-3,-5,9,STONE)
B(-3,-5,10,STONE)
B(-3,-5,11,STONE)
B(-3,-5,12,STONE)
B(-3,-4,-13,STONE)
B(-3,-4,-12,STONE)
B(-3,-4,-11,STONE)
B(-3,-4,-10,STONE)
B(-3,-4,-9,STONE)
B(-3,-4,-8,STONE)
B(-3,-4,-7,STONE)
B(-3,-4,-6,STONE)
B(-3,-4,-5,STONE)
B(-3,-4,-4,STONE)
B(-3,-4,-3,STONE)
B(-3,-4,-2,STONE)
B(-3,-4,-1,STONE)
B(-3,-4,0,STONE)
B(-3,-4,1,STONE)
B(-3,-4,2,STONE)
B(-3,-4,3,STONE)
B(-3,-4,4,STONE)
B(-3,-4,5,STONE)
B(-3,-4,6,STONE)
B(-3,-4,7,STONE)
B(-3,-4,8,STONE)
B(-3,-4,9,STONE)
B(-3,-4,10,STONE)
B(-3,-4,11,STONE)
B(-3,-4,12,STONE)
B(-3,-4,13,STONE)
B(-3,-3,-14,STONE)
B(-3,-3,-13,STONE)
B(-3,-3,-12,STONE)
B(-3,-3,-11,STONE)
B(-3,-3,-10,STONE)
B(-3,-3,-9,STONE)
B(-3,-3,-8,STONE)
B(-3,-3,-7,STONE)
B(-3,-3,-6,STONE)
B(-3,-3,-5,STONE)
B(-3,-3,-4,STONE)
B(-3,-3,-3,STONE)
B(-3,-3,-2,STONE)
B(-3,-3,-1,STONE)
B(-3,-3,0,STONE)
B(-3,-3,1,STONE)
B(-3,-3,2,STONE)
B(-3,-3,3,STONE)
B(-3,-3,4,STONE)
B(-3,-3,5,STONE)
B(-3,-3,6,STONE)
B(-3,-3,7,STONE)
B(-3,-3,8,STONE)
B(-3,-3,9,STONE)
B(-3,-3,10,STONE)
B(-3,-3,11,STONE)
B(-3,-3,12,STONE)
B(-3,-3,13,STONE)
B(-3,-3,14,STONE)
B(-3,-2,-14,STONE)
B(-3,-2,-13,STONE)
B(-3,-2,-12,STONE)
B(-3,-2,-11,STONE)
B(-3,-2,-10,STONE)
B(-3,-2,-9,STONE)
B(-3,-2,-8,STONE)
B(-3,-2,-7,STONE)
B(-3,-2,-6,STONE)
B(-3,-2,-5,STONE)
B(-3,-2,-4,STONE)
B(-3,-2,-3,STONE)
B(-3,-2,-2,STONE)
B(-3,-2,-1,STONE)
B(-3,-2,0,STONE)
B(-3,-2,1,STONE)
B(-3,-2,2,STONE)
B(-3,-2,3,STONE)
B(-3,-2,4,STONE)
B(-3,-2,5,STONE)
B(-3,-2,6,STONE)
B(-3,-2,7,STONE)
B(-3,-2,8,STONE)
B(-3,-2,9,STONE)
B(-3,-2,10,STONE)
B(-3,-2,11,STONE)
B(-3,-2,12,STONE)
B(-3,-2,13,STONE)
B(-3,-2,14,STONE)
B(-3,-1,-14,STONE)
B(-3,-1,-13,STONE)
B(-3,-1,-12,STONE)
B(-3,-1,-11,STONE)
B(-3,-1,-10,STONE)
B(-3,-1,-9,STONE)
B(-3,-1,-8,STONE)
B(-3,-1,-7,STONE)
B(-3,-1,-6,STONE)
B(-3,-1,-5,STONE)
B(-3,-1,-4,STONE)
B(-3,-1,-3,STONE)
B(-3,-1,-2,STONE)
B(-3,-1,-1,STONE)
B(-3,-1,0,STONE)
B(-3,-1,1,STONE)
B(-3,-1,2,STONE)
B(-3,-1,3,STONE)
B(-3,-1,4,STONE)
B(-3,-1,5,STONE)
B(-3,-1,6,STONE)
B(-3,-1,7,STONE)
B(-3,-1,8,STONE)
B(-3,-1,9,STONE)
B(-3,-1,10,STONE)
B(-3,-1,11,STONE)
B(-3,-1,12,STONE)
B(-3,-1,13,STONE)
B(-3,-1,14,STONE)
B(-3,0,-14,STONE)
B(-3,0,-13,STONE)
B(-3,0,-12,STONE)
B(-3,0,-11,STONE)
B(-3,0,-10,STONE)
B(-3,0,-9,STONE)
B(-3,0,-8,STONE)
B(-3,0,-7,STONE)
B(-3,0,-6,STONE)
B(-3,0,-5,STONE)
B(-3,0,-4,STONE)
B(-3,0,-3,STONE)
B(-3,0,-2,STONE)
B(-3,0,-1,STONE)
B(-3,0,0,STONE)
B(-3,0,1,STONE)
B(-3,0,2,STONE)
B(-3,0,3,STONE)
B(-3,0,4,STONE)
B(-3,0,5,STONE)
B(-3,0,6,STONE)
B(-3,0,7,STONE)
B(-3,0,8,STONE)
B(-3,0,9,STONE)
B(-3,0,10,STONE)
B(-3,0,11,STONE)
B(-3,0,12,STONE)
B(-3,0,13,STONE)
B(-3,0,14,STONE)
B(-3,1,-13,STONE)
B(-3,1,-12,STONE)
B(-3,1,-11,STONE)
B(-3,1,-10,STONE)
B(-3,1,-9,STONE)
B(-3,1,-8,STONE)
B(-3,1,-7,STONE)
B(-3,1,-6,STONE)
B(-3,1,-5,STONE)
B(-3,1,-4,STONE)
B(-3,1,-3,STONE)
B(-3,1,-2,STONE)
B(-3,1,-1,STONE)
B(-3,1,0,STONE)
B(-3,1,1,STONE)
B(-3,1,2,STONE)
B(-3,1,3,STONE)
B(-3,1,4,STONE)
B(-3,1,5,STONE)
B(-3,1,6,STONE)
B(-3,1,7,STONE)
B(-3,1,8,STONE)
B(-3,1,9,STONE)
B(-3,1,10,STONE)
B(-3,1,11,STONE)
B(-3,1,12,STONE)
B(-3,1,13,STONE)
B(-3,2,-12,STONE)
B(-3,2,-11,STONE)
B(-3,2,-10,STONE)
B(-3,2,-9,STONE)
B(-3,2,-8,STONE)
B(-3,2,-7,STONE)
B(-3,2,-6,STONE)
B(-3,2,-5,STONE)
B(-3,2,-4,STONE)
B(-3,2,-3,STONE)
B(-3,2,-2,STONE)
B(-3,2,-1,STONE)
B(-3,2,0,STONE)
B(-3,2,1,STONE)
B(-3,2,2,STONE)
B(-3,2,3,STONE)
B(-3,2,4,STONE)
B(-3,2,5,STONE)
B(-3,2,6,STONE)
B(-3,2,7,STONE)
B(-3,2,8,STONE)
B(-3,2,9,STONE)
B(-3,2,10,STONE)
B(-3,2,11,STONE)
B(-3,2,12,STONE)
B(-3,3,-11,STONE)
B(-3,3,-10,STONE)
B(-3,3,-9,STONE)
B(-3,3,-8,STONE)
B(-3,3,-7,STONE)
B(-3,3,-6,STONE)
B(-3,3,-5,STONE)
B(-3,3,-4,STONE)
B(-3,3,-3,STONE)
B(-3,3,-2,STONE)
B(-3,3,-1,STONE)
B(-3,3,0,STONE)
B(-3,3,1,STONE)
B(-3,3,2,STONE)
B(-3,3,3,STONE)
B(-3,3,4,STONE)
B(-3,3,5,STONE)
B(-3,3,6,STONE)
B(-3,3,7,STONE)
B(-3,3,8,STONE)
B(-3,3,9,STONE)
B(-3,3,10,STONE)
B(-3,3,11,STONE)
B(-3,4,-11,STONE)
B(-3,4,-10,STONE)
B(-3,4,-9,STONE)
B(-3,4,-8,STONE)
B(-3,4,-7,STONE)
B(-3,4,-6,STONE)
B(-3,4,-5,STONE)
B(-3,4,-4,STONE)
B(-3,4,-3,STONE)
B(-3,4,-2,STONE)
B(-3,4,-1,STONE)
B(-3,4,0,STONE)
B(-3,4,1,STONE)
B(-3,4,2,STONE)
B(-3,4,3,STONE)
B(-3,4,4,STONE)
B(-3,4,5,STONE)
B(-3,4,6,STONE)
B(-3,4,7,STONE)
B(-3,4,8,STONE)
B(-3,4,9,STONE)
B(-3,4,10,STONE)
B(-3,4,11,STONE)
B(-3,5,-10,STONE)
B(-3,5,-9,STONE)
B(-3,5,-8,STONE)
B(-3,5,-7,STONE)
B(-3,5,-6,STONE)
B(-3,5,-5,STONE)
B(-3,5,-4,STONE)
B(-3,5,-3,STONE)
B(-3,5,-2,STONE)
B(-3,5,-1,STONE)
B(-3,5,0,STONE)
B(-3,5,1,STONE)
B(-3,5,2,STONE)
B(-3,5,3,STONE)
B(-3,5,4,STONE)
B(-3,5,5,STONE)
B(-3,5,6,STONE)
B(-3,5,7,STONE)
B(-3,5,8,STONE)
B(-3,5,9,STONE)
B(-3,5,10,STONE)
B(-3,6,-9,STONE)
B(-3,6,-8,STONE)
B(-3,6,-7,STONE)
B(-3,6,-6,STONE)
B(-3,6,-5,STONE)
B(-3,6,-4,STONE)
B(-3,6,-3,STONE)
B(-3,6,-2,STONE)
B(-3,6,-1,STONE)
B(-3,6,0,STONE)
B(-3,6,1,STONE)
B(-3,6,2,STONE)
B(-3,6,3,STONE)
B(-3,6,4,STONE)
B(-3,6,5,STONE)
B(-3,6,6,STONE)
B(-3,6,7,STONE)
B(-3,6,8,STONE)
B(-3,6,9,STONE)
B(-3,6,10,STONE)
B(-3,7,-8,STONE)
B(-3,7,-7,STONE)
B(-3,7,-6,STONE)
B(-3,7,-5,STONE)
B(-3,7,-4,STONE)
B(-3,7,-3,STONE)
B(-3,7,-2,STONE)
B(-3,7,-1,STONE)
B(-3,7,0,STONE)
B(-3,7,1,STONE)
B(-3,7,2,STONE)
B(-3,7,3,STONE)
B(-3,7,4,STONE)
B(-3,7,5,STONE)
B(-3,7,6,STONE)
B(-3,7,7,STONE)
B(-3,7,8,STONE)
B(-3,7,9,STONE)
B(-3,8,-7,STONE)
B(-3,8,-6,STONE)
B(-3,8,-5,STONE)
B(-3,8,-4,STONE)
B(-3,8,-3,STONE)
B(-3,8,-2,STONE)
B(-3,8,-1,STONE)
B(-3,8,0,STONE)
B(-3,8,1,STONE)
B(-3,8,2,STONE)
B(-3,8,3,STONE)
B(-3,8,4,STONE)
B(-3,8,5,STONE)
B(-3,8,6,STONE)
B(-3,8,7,STONE)
B(-3,8,8,STONE)
B(-3,9,2,STONE)
B(-3,9,3,STONE)
B(-3,9,4,STONE)
B(-3,9,5,STONE)
B(-3,9,6,STONE)
B(-2,-12,-4,STONE)
B(-2,-12,-3,STONE)
B(-2,-12,-2,STONE)
B(-2,-12,-1,STONE)
B(-2,-12,0,STONE)
B(-2,-12,1,STONE)
B(-2,-12,2,STONE)
B(-2,-12,3,STONE)
B(-2,-12,4,STONE)
B(-2,-12,5,STONE)
B(-2,-12,6,STONE)
B(-2,-12,7,STONE)
B(-2,-11,-7,STONE)
B(-2,-11,-6,STONE)
B(-2,-11,-5,STONE)
B(-2,-11,-4,STONE)
B(-2,-11,-3,STONE)
B(-2,-11,-2,STONE)
B(-2,-11,-1,STONE)
B(-2,-11,0,STONE)
B(-2,-11,1,STONE)
B(-2,-11,2,STONE)
B(-2,-11,3,STONE)
B(-2,-11,4,STONE)
B(-2,-11,5,STONE)
B(-2,-11,6,STONE)
B(-2,-11,7,STONE)
B(-2,-11,8,STONE)
B(-2,-10,-8,STONE)
B(-2,-10,-7,STONE)
B(-2,-10,-6,STONE)
B(-2,-10,-5,STONE)
B(-2,-10,-4,STONE)
B(-2,-10,-3,STONE)
B(-2,-10,-2,STONE)
B(-2,-10,-1,STONE)
B(-2,-10,0,STONE)
B(-2,-10,1,STONE)
B(-2,-10,2,STONE)
B(-2,-10,3,STONE)
B(-2,-10,4,STONE)
B(-2,-10,5,STONE)
B(-2,-10,6,STONE)
B(-2,-10,7,STONE)
B(-2,-10,8,STONE)
B(-2,-10,9,STONE)
B(-2,-9,-9,STONE)
B(-2,-9,-8,STONE)
B(-2,-9,-7,STONE)
B(-2,-9,-6,STONE)
B(-2,-9,-5,STONE)
B(-2,-9,-4,STONE)
B(-2,-9,-3,STONE)
B(-2,-9,-2,STONE)
B(-2,-9,-1,STONE)
B(-2,-9,0,STONE)
B(-2,-9,1,STONE)
B(-2,-9,2,STONE)
B(-2,-9,3,STONE)
B(-2,-9,4,STONE)
B(-2,-9,5,STONE)
B(-2,-9,6,STONE)
B(-2,-9,7,STONE)
B(-2,-9,8,STONE)
B(-2,-9,9,STONE)
B(-2,-9,10,STONE)
B(-2,-8,-9,STONE)
B(-2,-8,-8,STONE)
B(-2,-8,-7,STONE)
B(-2,-8,-6,STONE)
B(-2,-8,-5,STONE)
B(-2,-8,-4,STONE)
B(-2,-8,-3,STONE)
B(-2,-8,-2,STONE)
B(-2,-8,-1,STONE)
B(-2,-8,0,STONE)
B(-2,-8,1,STONE)
B(-2,-8,2,STONE)
B(-2,-8,3,STONE)
B(-2,-8,4,STONE)
B(-2,-8,5,STONE)
B(-2,-8,6,STONE)
B(-2,-8,7,STONE)
B(-2,-8,8,STONE)
B(-2,-8,9,STONE)
B(-2,-8,10,STONE)
B(-2,-7,-10,STONE)
B(-2,-7,-9,STONE)
B(-2,-7,-8,STONE)
B(-2,-7,-7,STONE)
B(-2,-7,-6,STONE)
B(-2,-7,-5,STONE)
B(-2,-7,-4,STONE)
B(-2,-7,-3,STONE)
B(-2,-7,-2,STONE)
B(-2,-7,-1,STONE)
B(-2,-7,0,STONE)
B(-2,-7,1,STONE)
B(-2,-7,2,STONE)
B(-2,-7,3,STONE)
B(-2,-7,4,STONE)
B(-2,-7,5,STONE)
B(-2,-7,6,STONE)
B(-2,-7,7,STONE)
B(-2,-7,8,STONE)
B(-2,-7,9,STONE)
B(-2,-7,10,STONE)
B(-2,-7,11,STONE)
B(-2,-6,-11,STONE)
B(-2,-6,-10,STONE)
B(-2,-6,-9,STONE)
B(-2,-6,-8,STONE)
B(-2,-6,-7,STONE)
B(-2,-6,-6,STONE)
B(-2,-6,-5,STONE)
B(-2,-6,-4,STONE)
B(-2,-6,-3,STONE)
B(-2,-6,-2,STONE)
B(-2,-6,-1,STONE)
B(-2,-6,0,STONE)
B(-2,-6,1,STONE)
B(-2,-6,2,STONE)
B(-2,-6,3,STONE)
B(-2,-6,4,STONE)
B(-2,-6,5,STONE)
B(-2,-6,6,STONE)
B(-2,-6,7,STONE)
B(-2,-6,8,STONE)
B(-2,-6,9,STONE)
B(-2,-6,10,STONE)
B(-2,-6,11,STONE)
B(-2,-5,-11,STONE)
B(-2,-5,-10,STONE)
B(-2,-5,-9,STONE)
B(-2,-5,-8,STONE)
B(-2,-5,-7,STONE)
B(-2,-5,-6,STONE)
B(-2,-5,-5,STONE)
B(-2,-5,-4,STONE)
B(-2,-5,-3,STONE)
B(-2,-5,-2,STONE)
B(-2,-5,-1,STONE)
B(-2,-5,0,STONE)
B(-2,-5,1,STONE)
B(-2,-5,2,STONE)
B(-2,-5,3,STONE)
B(-2,-5,4,STONE)
B(-2,-5,5,STONE)
B(-2,-5,6,STONE)
B(-2,-5,7,STONE)
B(-2,-5,8,STONE)
B(-2,-5,9,STONE)
B(-2,-5,10,STONE)
B(-2,-5,11,STONE)
B(-2,-5,12,STONE)
B(-2,-4,-12,STONE)
B(-2,-4,-11,STONE)
B(-2,-4,-10,STONE)
B(-2,-4,-9,STONE)
B(-2,-4,-8,STONE)
B(-2,-4,-7,STONE)
B(-2,-4,-6,STONE)
B(-2,-4,-5,STONE)
B(-2,-4,-4,STONE)
B(-2,-4,-3,STONE)
B(-2,-4,-2,STONE)
B(-2,-4,-1,STONE)
B(-2,-4,0,STONE)
B(-2,-4,1,STONE)
B(-2,-4,2,STONE)
B(-2,-4,3,STONE)
B(-2,-4,4,STONE)
B(-2,-4,5,STONE)
B(-2,-4,6,STONE)
B(-2,-4,7,STONE)
B(-2,-4,8,STONE)
B(-2,-4,9,STONE)
B(-2,-4,10,STONE)
B(-2,-4,11,STONE)
B(-2,-4,12,STONE)
B(-2,-4,13,STONE)
B(-2,-3,-13,STONE)
B(-2,-3,-12,STONE)
B(-2,-3,-11,STONE)
B(-2,-3,-10,STONE)
B(-2,-3,-9,STONE)
B(-2,-3,-8,STONE)
B(-2,-3,-7,STONE)
B(-2,-3,-6,STONE)
B(-2,-3,-5,STONE)
B(-2,-3,-4,STONE)
B(-2,-3,-3,STONE)
B(-2,-3,-2,STONE)
B(-2,-3,-1,STONE)
B(-2,-3,0,STONE)
B(-2,-3,1,STONE)
B(-2,-3,2,STONE)
B(-2,-3,3,STONE)
B(-2,-3,4,STONE)
B(-2,-3,5,STONE)
B(-2,-3,6,STONE)
B(-2,-3,7,STONE)
B(-2,-3,8,STONE)
B(-2,-3,9,STONE)
B(-2,-3,10,STONE)
B(-2,-3,11,STONE)
B(-2,-3,12,STONE)
B(-2,-3,13,STONE)
B(-2,-3,14,STONE)
B(-2,-2,-14,STONE)
B(-2,-2,-13,STONE)
B(-2,-2,-12,STONE)
B(-2,-2,-11,STONE)
B(-2,-2,-10,STONE)
B(-2,-2,-9,STONE)
B(-2,-2,-8,STONE)
B(-2,-2,-7,STONE)
B(-2,-2,-6,STONE)
B(-2,-2,-5,STONE)
B(-2,-2,-4,STONE)
B(-2,-2,-3,STONE)
B(-2,-2,-2,STONE)
B(-2,-2,-1,STONE)
B(-2,-2,0,STONE)
B(-2,-2,1,STONE)
B(-2,-2,2,STONE)
B(-2,-2,3,STONE)
B(-2,-2,4,STONE)
B(-2,-2,5,STONE)
B(-2,-2,6,STONE)
B(-2,-2,7,STONE)
B(-2,-2,8,STONE)
B(-2,-2,9,STONE)
B(-2,-2,10,STONE)
B(-2,-2,11,STONE)
B(-2,-2,12,STONE)
B(-2,-2,13,STONE)
B(-2,-2,14,STONE)
B(-2,-1,-14,STONE)
B(-2,-1,-13,STONE)
B(-2,-1,-12,STONE)
B(-2,-1,-11,STONE)
B(-2,-1,-10,STONE)
B(-2,-1,-9,STONE)
B(-2,-1,-8,STONE)
B(-2,-1,-7,STONE)
B(-2,-1,-6,STONE)
B(-2,-1,-5,STONE)
B(-2,-1,-4,STONE)
B(-2,-1,-3,STONE)
B(-2,-1,-2,STONE)
B(-2,-1,-1,STONE)
B(-2,-1,0,STONE)
B(-2,-1,1,STONE)
B(-2,-1,2,STONE)
B(-2,-1,3,STONE)
B(-2,-1,4,STONE)
B(-2,-1,5,STONE)
B(-2,-1,6,STONE)
B(-2,-1,7,STONE)
B(-2,-1,8,STONE)
B(-2,-1,9,STONE)
B(-2,-1,10,STONE)
B(-2,-1,11,STONE)
B(-2,-1,12,STONE)
B(-2,-1,13,STONE)
B(-2,-1,14,STONE)
B(-2,0,-13,STONE)
B(-2,0,-12,STONE)
B(-2,0,-11,STONE)
B(-2,0,-10,STONE)
B(-2,0,-9,STONE)
B(-2,0,-8,STONE)
B(-2,0,-7,STONE)
B(-2,0,-6,STONE)
B(-2,0,-5,STONE)
B(-2,0,-4,STONE)
B(-2,0,-3,STONE)
B(-2,0,-2,STONE)
B(-2,0,-1,STONE)
B(-2,0,0,STONE)
B(-2,0,1,STONE)
B(-2,0,2,STONE)
B(-2,0,3,STONE)
B(-2,0,4,STONE)
B(-2,0,5,STONE)
B(-2,0,6,STONE)
B(-2,0,7,STONE)
B(-2,0,8,STONE)
B(-2,0,9,STONE)
B(-2,0,10,STONE)
B(-2,0,11,STONE)
B(-2,0,12,STONE)
B(-2,0,13,STONE)
B(-2,0,14,STONE)
B(-2,1,-12,STONE)
B(-2,1,-11,STONE)
B(-2,1,-10,STONE)
B(-2,1,-9,STONE)
B(-2,1,-8,STONE)
B(-2,1,-7,STONE)
B(-2,1,-6,STONE)
B(-2,1,-5,STONE)
B(-2,1,-4,STONE)
B(-2,1,-3,STONE)
B(-2,1,-2,STONE)
B(-2,1,-1,STONE)
B(-2,1,0,STONE)
B(-2,1,1,STONE)
B(-2,1,2,STONE)
B(-2,1,3,STONE)
B(-2,1,4,STONE)
B(-2,1,5,STONE)
B(-2,1,6,STONE)
B(-2,1,7,STONE)
B(-2,1,8,STONE)
B(-2,1,9,STONE)
B(-2,1,10,STONE)
B(-2,1,11,STONE)
B(-2,1,12,STONE)
B(-2,1,13,STONE)
B(-2,2,-11,STONE)
B(-2,2,-10,STONE)
B(-2,2,-9,STONE)
B(-2,2,-8,STONE)
B(-2,2,-7,STONE)
B(-2,2,-6,STONE)
B(-2,2,-5,STONE)
B(-2,2,-4,STONE)
B(-2,2,-3,STONE)
B(-2,2,-2,STONE)
B(-2,2,-1,STONE)
B(-2,2,0,STONE)
B(-2,2,1,STONE)
B(-2,2,2,STONE)
B(-2,2,3,STONE)
B(-2,2,4,STONE)
B(-2,2,5,STONE)
B(-2,2,6,STONE)
B(-2,2,7,STONE)
B(-2,2,8,STONE)
B(-2,2,9,STONE)
B(-2,2,10,STONE)
B(-2,2,11,STONE)
B(-2,2,12,STONE)
B(-2,3,-11,STONE)
B(-2,3,-10,STONE)
B(-2,3,-9,STONE)
B(-2,3,-8,STONE)
B(-2,3,-7,STONE)
B(-2,3,-6,STONE)
B(-2,3,-5,STONE)
B(-2,3,-4,STONE)
B(-2,3,-3,STONE)
B(-2,3,-2,STONE)
B(-2,3,-1,STONE)
B(-2,3,0,STONE)
B(-2,3,1,STONE)
B(-2,3,2,STONE)
B(-2,3,3,STONE)
B(-2,3,4,STONE)
B(-2,3,5,STONE)
B(-2,3,6,STONE)
B(-2,3,7,STONE)
B(-2,3,8,STONE)
B(-2,3,9,STONE)
B(-2,3,10,STONE)
B(-2,3,11,STONE)
B(-2,4,-10,STONE)
B(-2,4,-9,STONE)
B(-2,4,-8,STONE)
B(-2,4,-7,STONE)
B(-2,4,-6,STONE)
B(-2,4,-5,STONE)
B(-2,4,-4,STONE)
B(-2,4,-3,STONE)
B(-2,4,-2,STONE)
B(-2,4,-1,STONE)
B(-2,4,0,STONE)
B(-2,4,1,STONE)
B(-2,4,2,STONE)
B(-2,4,3,STONE)
B(-2,4,4,STONE)
B(-2,4,5,STONE)
B(-2,4,6,STONE)
B(-2,4,7,STONE)
B(-2,4,8,STONE)
B(-2,4,9,STONE)
B(-2,4,10,STONE)
B(-2,4,11,STONE)
B(-2,5,-9,STONE)
B(-2,5,-8,STONE)
B(-2,5,-7,STONE)
B(-2,5,-6,STONE)
B(-2,5,-5,STONE)
B(-2,5,-4,STONE)
B(-2,5,-3,STONE)
B(-2,5,-2,STONE)
B(-2,5,-1,STONE)
B(-2,5,0,STONE)
B(-2,5,1,STONE)
B(-2,5,2,STONE)
B(-2,5,3,STONE)
B(-2,5,4,STONE)
B(-2,5,5,STONE)
B(-2,5,6,STONE)
B(-2,5,7,STONE)
B(-2,5,8,STONE)
B(-2,5,9,STONE)
B(-2,5,10,STONE)
B(-2,6,-9,STONE)
B(-2,6,-8,STONE)
B(-2,6,-7,STONE)
B(-2,6,-6,STONE)
B(-2,6,-5,STONE)
B(-2,6,-4,STONE)
B(-2,6,-3,STONE)
B(-2,6,-2,STONE)
B(-2,6,-1,STONE)
B(-2,6,0,STONE)
B(-2,6,1,STONE)
B(-2,6,2,STONE)
B(-2,6,3,STONE)
B(-2,6,4,STONE)
B(-2,6,5,STONE)
B(-2,6,6,STONE)
B(-2,6,7,STONE)
B(-2,6,8,STONE)
B(-2,6,9,STONE)
B(-2,6,10,STONE)
B(-2,7,-8,STONE)
B(-2,7,-7,STONE)
B(-2,7,-6,STONE)
B(-2,7,-5,STONE)
B(-2,7,-4,STONE)
B(-2,7,-3,STONE)
B(-2,7,-2,STONE)
B(-2,7,-1,STONE)
B(-2,7,0,STONE)
B(-2,7,1,STONE)
B(-2,7,2,STONE)
B(-2,7,3,STONE)
B(-2,7,4,STONE)
B(-2,7,5,STONE)
B(-2,7,6,STONE)
B(-2,7,7,STONE)
B(-2,7,8,STONE)
B(-2,7,9,STONE)
B(-2,8,-7,STONE)
B(-2,8,-6,STONE)
B(-2,8,-5,STONE)
B(-2,8,-4,STONE)
B(-2,8,-3,STONE)
B(-2,8,-2,STONE)
B(-2,8,-1,STONE)
B(-2,8,0,STONE)
B(-2,8,1,STONE)
B(-2,8,2,STONE)
B(-2,8,3,STONE)
B(-2,8,4,STONE)
B(-2,8,5,STONE)
B(-2,8,6,STONE)
B(-2,8,7,STONE)
B(-2,8,8,STONE)
B(-2,9,-4,STONE)
B(-2,9,-3,STONE)
B(-2,9,-2,STONE)
B(-2,9,-1,STONE)
B(-2,9,0,STONE)
B(-2,9,1,STONE)
B(-2,9,2,STONE)
B(-2,9,3,STONE)
B(-2,9,4,STONE)
B(-2,9,5,STONE)
B(-2,9,6,STONE)
B(-2,9,7,STONE)
B(-2,10,0,STONE)
B(-2,10,1,STONE)
B(-2,10,2,STONE)
B(-2,10,3,STONE)
B(-2,10,4,STONE)
B(-2,10,5,STONE)
B(-2,10,6,STONE)
B(-1,-12,-6,STONE)
B(-1,-12,-5,STONE)
B(-1,-12,-4,STONE)
B(-1,-12,-3,STONE)
B(-1,-12,-2,STONE)
B(-1,-12,-1,STONE)
B(-1,-12,0,STONE)
B(-1,-12,1,STONE)
B(-1,-12,2,STONE)
B(-1,-12,3,STONE)
B(-1,-12,4,STONE)
B(-1,-12,5,STONE)
B(-1,-12,6,STONE)
B(-1,-12,7,STONE)
B(-1,-12,8,STONE)
B(-1,-11,-7,STONE)
B(-1,-11,-6,STONE)
B(-1,-11,-5,STONE)
B(-1,-11,-4,STONE)
B(-1,-11,-3,STONE)
B(-1,-11,-2,STONE)
B(-1,-11,-1,STONE)
B(-1,-11,0,STONE)
B(-1,-11,1,STONE)
B(-1,-11,2,STONE)
B(-1,-11,3,STONE)
B(-1,-11,4,STONE)
B(-1,-11,5,STONE)
B(-1,-11,6,STONE)
B(-1,-11,7,STONE)
B(-1,-11,8,STONE)
B(-1,-11,9,STONE)
B(-1,-10,-7,STONE)
B(-1,-10,-6,STONE)
B(-1,-10,-5,STONE)
B(-1,-10,-4,STONE)
B(-1,-10,-3,STONE)
B(-1,-10,-2,STONE)
B(-1,-10,-1,STONE)
B(-1,-10,0,STONE)
B(-1,-10,1,STONE)
B(-1,-10,2,STONE)
B(-1,-10,3,STONE)
B(-1,-10,4,STONE)
B(-1,-10,5,STONE)
B(-1,-10,6,STONE)
B(-1,-10,7,STONE)
B(-1,-10,8,STONE)
B(-1,-10,9,STONE)
B(-1,-9,-8,STONE)
B(-1,-9,-7,STONE)
B(-1,-9,-6,STONE)
B(-1,-9,-5,STONE)
B(-1,-9,-4,STONE)
B(-1,-9,-3,STONE)
B(-1,-9,-2,STONE)
B(-1,-9,-1,STONE)
B(-1,-9,0,STONE)
B(-1,-9,1,STONE)
B(-1,-9,2,STONE)
B(-1,-9,3,STONE)
B(-1,-9,4,STONE)
B(-1,-9,5,STONE)
B(-1,-9,6,STONE)
B(-1,-9,7,STONE)
B(-1,-9,8,STONE)
B(-1,-9,9,STONE)
B(-1,-9,10,STONE)
B(-1,-8,-9,STONE)
B(-1,-8,-8,STONE)
B(-1,-8,-7,STONE)
B(-1,-8,-6,STONE)
B(-1,-8,-5,STONE)
B(-1,-8,-4,STONE)
B(-1,-8,-3,STONE)
B(-1,-8,-2,STONE)
B(-1,-8,-1,STONE)
B(-1,-8,0,STONE)
B(-1,-8,1,STONE)
B(-1,-8,2,STONE)
B(-1,-8,3,STONE)
B(-1,-8,4,STONE)
B(-1,-8,5,STONE)
B(-1,-8,6,STONE)
B(-1,-8,7,STONE)
B(-1,-8,8,STONE)
B(-1,-8,9,STONE)
B(-1,-8,10,STONE)
B(-1,-7,-10,STONE)
B(-1,-7,-9,STONE)
B(-1,-7,-8,STONE)
B(-1,-7,-7,STONE)
B(-1,-7,-6,STONE)
B(-1,-7,-5,STONE)
B(-1,-7,-4,STONE)
B(-1,-7,-3,STONE)
B(-1,-7,-2,STONE)
B(-1,-7,-1,STONE)
B(-1,-7,0,STONE)
B(-1,-7,1,STONE)
B(-1,-7,2,STONE)
B(-1,-7,3,STONE)
B(-1,-7,4,STONE)
B(-1,-7,5,STONE)
B(-1,-7,6,STONE)
B(-1,-7,7,STONE)
B(-1,-7,8,STONE)
B(-1,-7,9,STONE)
B(-1,-7,10,STONE)
B(-1,-6,-10,STONE)
B(-1,-6,-9,STONE)
B(-1,-6,-8,STONE)
B(-1,-6,-7,STONE)
B(-1,-6,-6,STONE)
B(-1,-6,-5,STONE)
B(-1,-6,-4,STONE)
B(-1,-6,-3,STONE)
B(-1,-6,-2,STONE)
B(-1,-6,-1,STONE)
B(-1,-6,0,STONE)
B(-1,-6,1,STONE)
B(-1,-6,2,STONE)
B(-1,-6,3,STONE)
B(-1,-6,4,STONE)
B(-1,-6,5,STONE)
B(-1,-6,6,STONE)
B(-1,-6,7,STONE)
B(-1,-6,8,STONE)
B(-1,-6,9,STONE)
B(-1,-6,10,STONE)
B(-1,-6,11,STONE)
B(-1,-5,-11,STONE)
B(-1,-5,-10,STONE)
B(-1,-5,-9,STONE)
B(-1,-5,-8,STONE)
B(-1,-5,-7,STONE)
B(-1,-5,-6,STONE)
B(-1,-5,-5,STONE)
B(-1,-5,-4,STONE)
B(-1,-5,-3,STONE)
B(-1,-5,-2,STONE)
B(-1,-5,-1,STONE)
B(-1,-5,0,STONE)
B(-1,-5,1,STONE)
B(-1,-5,2,STONE)
B(-1,-5,3,STONE)
B(-1,-5,4,STONE)
B(-1,-5,5,STONE)
B(-1,-5,6,STONE)
B(-1,-5,7,STONE)
B(-1,-5,8,STONE)
B(-1,-5,9,STONE)
B(-1,-5,10,STONE)
B(-1,-5,11,STONE)
B(-1,-5,12,STONE)
B(-1,-4,-12,STONE)
B(-1,-4,-11,STONE)
B(-1,-4,-10,STONE)
B(-1,-4,-9,STONE)
B(-1,-4,-8,STONE)
B(-1,-4,-7,STONE)
B(-1,-4,-6,STONE)
B(-1,-4,-5,STONE)
B(-1,-4,-4,STONE)
B(-1,-4,-3,STONE)
B(-1,-4,-2,STONE)
B(-1,-4,-1,STONE)
B(-1,-4,0,STONE)
B(-1,-4,1,STONE)
B(-1,-4,2,STONE)
B(-1,-4,3,STONE)
B(-1,-4,4,STONE)
B(-1,-4,5,STONE)
B(-1,-4,6,STONE)
B(-1,-4,7,STONE)
B(-1,-4,8,STONE)
B(-1,-4,9,STONE)
B(-1,-4,10,STONE)
B(-1,-4,11,STONE)
B(-1,-4,12,STONE)
B(-1,-4,13,STONE)
B(-1,-3,-13,STONE)
B(-1,-3,-12,STONE)
B(-1,-3,-11,STONE)
B(-1,-3,-10,STONE)
B(-1,-3,-9,STONE)
B(-1,-3,-8,STONE)
B(-1,-3,-7,STONE)
B(-1,-3,-6,STONE)
B(-1,-3,-5,STONE)
B(-1,-3,-4,STONE)
B(-1,-3,-3,STONE)
B(-1,-3,-2,STONE)
B(-1,-3,-1,STONE)
B(-1,-3,0,STONE)
B(-1,-3,1,STONE)
B(-1,-3,2,STONE)
B(-1,-3,3,STONE)
B(-1,-3,4,STONE)
B(-1,-3,5,STONE)
B(-1,-3,6,STONE)
B(-1,-3,7,STONE)
B(-1,-3,8,STONE)
B(-1,-3,9,STONE)
B(-1,-3,10,STONE)
B(-1,-3,11,STONE)
B(-1,-3,12,STONE)
B(-1,-3,13,STONE)
B(-1,-2,-14,STONE)
B(-1,-2,-13,STONE)
B(-1,-2,-12,STONE)
B(-1,-2,-11,STONE)
B(-1,-2,-10,STONE)
B(-1,-2,-9,STONE)
B(-1,-2,-8,STONE)
B(-1,-2,-7,STONE)
B(-1,-2,-6,STONE)
B(-1,-2,-5,STONE)
B(-1,-2,-4,STONE)
B(-1,-2,-3,STONE)
B(-1,-2,-2,STONE)
B(-1,-2,-1,STONE)
B(-1,-2,0,STONE)
B(-1,-2,1,STONE)
B(-1,-2,2,STONE)
B(-1,-2,3,STONE)
B(-1,-2,4,STONE)
B(-1,-2,5,STONE)
B(-1,-2,6,STONE)
B(-1,-2,7,STONE)
B(-1,-2,8,STONE)
B(-1,-2,9,STONE)
B(-1,-2,10,STONE)
B(-1,-2,11,STONE)
B(-1,-2,12,STONE)
B(-1,-2,13,STONE)
B(-1,-2,14,STONE)
B(-1,-1,-14,STONE)
B(-1,-1,-13,STONE)
B(-1,-1,-12,STONE)
B(-1,-1,-11,STONE)
B(-1,-1,-10,STONE)
B(-1,-1,-9,STONE)
B(-1,-1,-8,STONE)
B(-1,-1,-7,STONE)
B(-1,-1,-6,STONE)
B(-1,-1,-5,STONE)
B(-1,-1,-4,STONE)
B(-1,-1,-3,STONE)
B(-1,-1,-2,STONE)
B(-1,-1,-1,STONE)
B(-1,-1,0,STONE)
B(-1,-1,1,STONE)
B(-1,-1,2,STONE)
B(-1,-1,3,STONE)
B(-1,-1,4,STONE)
B(-1,-1,5,STONE)
B(-1,-1,6,STONE)
B(-1,-1,7,STONE)
B(-1,-1,8,STONE)
B(-1,-1,9,STONE)
B(-1,-1,10,STONE)
B(-1,-1,11,STONE)
B(-1,-1,12,STONE)
B(-1,-1,13,STONE)
B(-1,-1,14,STONE)
B(-1,0,-13,STONE)
B(-1,0,-12,STONE)
B(-1,0,-11,STONE)
B(-1,0,-10,STONE)
B(-1,0,-9,STONE)
B(-1,0,-8,STONE)
B(-1,0,-7,STONE)
B(-1,0,-6,STONE)
B(-1,0,-5,STONE)
B(-1,0,-4,STONE)
B(-1,0,-3,STONE)
B(-1,0,-2,STONE)
B(-1,0,-1,STONE)
B(-1,0,0,STONE)
B(-1,0,1,STONE)
B(-1,0,2,STONE)
B(-1,0,3,STONE)
B(-1,0,4,STONE)
B(-1,0,5,STONE)
B(-1,0,6,STONE)
B(-1,0,7,STONE)
B(-1,0,8,STONE)
B(-1,0,9,STONE)
B(-1,0,10,STONE)
B(-1,0,11,STONE)
B(-1,0,12,STONE)
B(-1,0,13,STONE)
B(-1,1,-12,STONE)
B(-1,1,-11,STONE)
B(-1,1,-10,STONE)
B(-1,1,-9,STONE)
B(-1,1,-8,STONE)
B(-1,1,-7,STONE)
B(-1,1,-6,STONE)
B(-1,1,-5,STONE)
B(-1,1,-4,STONE)
B(-1,1,-3,STONE)
B(-1,1,-2,STONE)
B(-1,1,-1,STONE)
B(-1,1,0,STONE)
B(-1,1,1,STONE)
B(-1,1,2,STONE)
B(-1,1,3,STONE)
B(-1,1,4,STONE)
B(-1,1,5,STONE)
B(-1,1,6,STONE)
B(-1,1,7,STONE)
B(-1,1,8,STONE)
B(-1,1,9,STONE)
B(-1,1,10,STONE)
B(-1,1,11,STONE)
B(-1,1,12,STONE)
B(-1,1,13,STONE)
B(-1,2,-11,STONE)
B(-1,2,-10,STONE)
B(-1,2,-9,STONE)
B(-1,2,-8,STONE)
B(-1,2,-7,STONE)
B(-1,2,-6,STONE)
B(-1,2,-5,STONE)
B(-1,2,-4,STONE)
B(-1,2,-3,STONE)
B(-1,2,-2,STONE)
B(-1,2,-1,STONE)
B(-1,2,0,STONE)
B(-1,2,1,STONE)
B(-1,2,2,STONE)
B(-1,2,3,STONE)
B(-1,2,4,STONE)
B(-1,2,5,STONE)
B(-1,2,6,STONE)
B(-1,2,7,STONE)
B(-1,2,8,STONE)
B(-1,2,9,STONE)
B(-1,2,10,STONE)
B(-1,2,11,STONE)
B(-1,2,12,STONE)
B(-1,3,-10,STONE)
B(-1,3,-9,STONE)
B(-1,3,-8,STONE)
B(-1,3,-7,STONE)
B(-1,3,-6,STONE)
B(-1,3,-5,STONE)
B(-1,3,-4,STONE)
B(-1,3,-3,STONE)
B(-1,3,-2,STONE)
B(-1,3,-1,STONE)
B(-1,3,0,STONE)
B(-1,3,1,STONE)
B(-1,3,2,STONE)
B(-1,3,3,STONE)
B(-1,3,4,STONE)
B(-1,3,5,STONE)
B(-1,3,6,STONE)
B(-1,3,7,STONE)
B(-1,3,8,STONE)
B(-1,3,9,STONE)
B(-1,3,10,STONE)
B(-1,3,11,STONE)
B(-1,4,-10,STONE)
B(-1,4,-9,STONE)
B(-1,4,-8,STONE)
B(-1,4,-7,STONE)
B(-1,4,-6,STONE)
B(-1,4,-5,STONE)
B(-1,4,-4,STONE)
B(-1,4,-3,STONE)
B(-1,4,-2,STONE)
B(-1,4,-1,STONE)
B(-1,4,0,STONE)
B(-1,4,1,STONE)
B(-1,4,2,STONE)
B(-1,4,3,STONE)
B(-1,4,4,STONE)
B(-1,4,5,STONE)
B(-1,4,6,STONE)
B(-1,4,7,STONE)
B(-1,4,8,STONE)
B(-1,4,9,STONE)
B(-1,4,10,STONE)
B(-1,5,-9,STONE)
B(-1,5,-8,STONE)
B(-1,5,-7,STONE)
B(-1,5,-6,STONE)
B(-1,5,-5,STONE)
B(-1,5,-4,STONE)
B(-1,5,-3,STONE)
B(-1,5,-2,STONE)
B(-1,5,-1,STONE)
B(-1,5,0,STONE)
B(-1,5,1,STONE)
B(-1,5,2,STONE)
B(-1,5,3,STONE)
B(-1,5,4,STONE)
B(-1,5,5,STONE)
B(-1,5,6,STONE)
B(-1,5,7,STONE)
B(-1,5,8,STONE)
B(-1,5,9,STONE)
B(-1,5,10,STONE)
B(-1,6,-8,STONE)
B(-1,6,-7,STONE)
B(-1,6,-6,STONE)
B(-1,6,-5,STONE)
B(-1,6,-4,STONE)
B(-1,6,-3,STONE)
B(-1,6,-2,STONE)
B(-1,6,-1,STONE)
B(-1,6,0,STONE)
B(-1,6,1,STONE)
B(-1,6,2,STONE)
B(-1,6,3,STONE)
B(-1,6,4,STONE)
B(-1,6,5,STONE)
B(-1,6,6,STONE)
B(-1,6,7,STONE)
B(-1,6,8,STONE)
B(-1,6,9,STONE)
B(-1,6,10,STONE)
B(-1,7,-7,STONE)
B(-1,7,-6,STONE)
B(-1,7,-5,STONE)
B(-1,7,-4,STONE)
B(-1,7,-3,STONE)
B(-1,7,-2,STONE)
B(-1,7,-1,STONE)
B(-1,7,0,STONE)
B(-1,7,1,STONE)
B(-1,7,2,STONE)
B(-1,7,3,STONE)
B(-1,7,4,STONE)
B(-1,7,5,STONE)
B(-1,7,6,STONE)
B(-1,7,7,STONE)
B(-1,7,8,STONE)
B(-1,7,9,STONE)
B(-1,8,-7,STONE)
B(-1,8,-6,STONE)
B(-1,8,-5,STONE)
B(-1,8,-4,STONE)
B(-1,8,-3,STONE)
B(-1,8,-2,STONE)
B(-1,8,-1,STONE)
B(-1,8,0,STONE)
B(-1,8,1,STONE)
B(-1,8,2,STONE)
B(-1,8,3,STONE)
B(-1,8,4,STONE)
B(-1,8,5,STONE)
B(-1,8,6,STONE)
B(-1,8,7,STONE)
B(-1,8,8,STONE)
B(-1,8,9,STONE)
B(-1,9,-6,STONE)
B(-1,9,-5,STONE)
B(-1,9,-4,STONE)
B(-1,9,-3,STONE)
B(-1,9,-2,STONE)
B(-1,9,-1,STONE)
B(-1,9,0,STONE)
B(-1,9,1,STONE)
B(-1,9,2,STONE)
B(-1,9,3,STONE)
B(-1,9,4,STONE)
B(-1,9,5,STONE)
B(-1,9,6,STONE)
B(-1,9,7,STONE)
B(-1,9,8,STONE)
B(-1,10,-3,STONE)
B(-1,10,0,STONE)
B(-1,10,1,STONE)
B(-1,10,2,STONE)
B(-1,10,3,STONE)
B(-1,10,4,STONE)
B(-1,10,5,STONE)
B(-1,10,6,STONE)
B(-1,10,7,STONE)
B(-1,11,2,STONE)
B(-1,11,3,STONE)
B(-1,11,4,STONE)
B(0,-12,-6,STONE)
B(0,-12,-5,STONE)
B(0,-12,-4,STONE)
B(0,-12,-3,STONE)
B(0,-12,-2,STONE)
B(0,-12,-1,STONE)
B(0,-12,0,STONE)
B(0,-12,1,STONE)
B(0,-12,2,STONE)
B(0,-12,3,STONE)
B(0,-12,4,STONE)
B(0,-12,5,STONE)
B(0,-12,6,STONE)
B(0,-12,7,STONE)
B(0,-12,8,STONE)
B(0,-11,-7,STONE)
B(0,-11,-6,STONE)
B(0,-11,-5,STONE)
B(0,-11,-4,STONE)
B(0,-11,-3,STONE)
B(0,-11,-2,STONE)
B(0,-11,-1,STONE)
B(0,-11,0,STONE)
B(0,-11,1,STONE)
B(0,-11,2,STONE)
B(0,-11,3,STONE)
B(0,-11,4,STONE)
B(0,-11,5,STONE)
B(0,-11,6,STONE)
B(0,-11,7,STONE)
B(0,-11,8,STONE)
B(0,-10,-7,STONE)
B(0,-10,-6,STONE)
B(0,-10,-5,STONE)
B(0,-10,-4,STONE)
B(0,-10,-3,STONE)
B(0,-10,-2,STONE)
B(0,-10,-1,STONE)
B(0,-10,0,STONE)
B(0,-10,1,STONE)
B(0,-10,2,STONE)
B(0,-10,3,STONE)
B(0,-10,4,STONE)
B(0,-10,5,STONE)
B(0,-10,6,STONE)
B(0,-10,7,STONE)
B(0,-10,8,STONE)
B(0,-10,9,STONE)
B(0,-9,-8,STONE)
B(0,-9,-7,STONE)
B(0,-9,-6,STONE)
B(0,-9,-5,STONE)
B(0,-9,-4,STONE)
B(0,-9,-3,STONE)
B(0,-9,-2,STONE)
B(0,-9,-1,STONE)
B(0,-9,0,STONE)
B(0,-9,1,STONE)
B(0,-9,2,STONE)
B(0,-9,3,STONE)
B(0,-9,4,STONE)
B(0,-9,5,STONE)
B(0,-9,6,STONE)
B(0,-9,7,STONE)
B(0,-9,8,STONE)
B(0,-9,9,STONE)
B(0,-8,-9,STONE)
B(0,-8,-8,STONE)
B(0,-8,-7,STONE)
B(0,-8,-6,STONE)
B(0,-8,-5,STONE)
B(0,-8,-4,STONE)
B(0,-8,-3,STONE)
B(0,-8,-2,STONE)
B(0,-8,-1,STONE)
B(0,-8,0,STONE)
B(0,-8,1,STONE)
B(0,-8,2,STONE)
B(0,-8,3,STONE)
B(0,-8,4,STONE)
B(0,-8,5,STONE)
B(0,-8,6,STONE)
B(0,-8,7,STONE)
B(0,-8,8,STONE)
B(0,-8,9,STONE)
B(0,-8,10,STONE)
B(0,-7,-9,STONE)
B(0,-7,-8,STONE)
B(0,-7,-7,STONE)
B(0,-7,-6,STONE)
B(0,-7,-5,STONE)
B(0,-7,-4,STONE)
B(0,-7,-3,STONE)
B(0,-7,-2,STONE)
B(0,-7,-1,STONE)
B(0,-7,0,STONE)
B(0,-7,1,STONE)
B(0,-7,2,STONE)
B(0,-7,3,STONE)
B(0,-7,4,STONE)
B(0,-7,5,STONE)
B(0,-7,6,STONE)
B(0,-7,7,STONE)
B(0,-7,8,STONE)
B(0,-7,9,STONE)
B(0,-7,10,STONE)
B(0,-6,-10,STONE)
B(0,-6,-9,STONE)
B(0,-6,-8,STONE)
B(0,-6,-7,STONE)
B(0,-6,-6,STONE)
B(0,-6,-5,STONE)
B(0,-6,-4,STONE)
B(0,-6,-3,STONE)
B(0,-6,-2,STONE)
B(0,-6,-1,STONE)
B(0,-6,0,STONE)
B(0,-6,1,STONE)
B(0,-6,2,STONE)
B(0,-6,3,STONE)
B(0,-6,4,STONE)
B(0,-6,5,STONE)
B(0,-6,6,STONE)
B(0,-6,7,STONE)
B(0,-6,8,STONE)
B(0,-6,9,STONE)
B(0,-6,10,STONE)
B(0,-6,11,STONE)
B(0,-5,-11,STONE)
B(0,-5,-10,STONE)
B(0,-5,-9,STONE)
B(0,-5,-8,STONE)
B(0,-5,-7,STONE)
B(0,-5,-6,STONE)
B(0,-5,-5,STONE)
B(0,-5,-4,STONE)
B(0,-5,-3,STONE)
B(0,-5,-2,STONE)
B(0,-5,-1,STONE)
B(0,-5,0,STONE)
B(0,-5,1,STONE)
B(0,-5,2,STONE)
B(0,-5,3,STONE)
B(0,-5,4,STONE)
B(0,-5,5,STONE)
B(0,-5,6,STONE)
B(0,-5,7,STONE)
B(0,-5,8,STONE)
B(0,-5,9,STONE)
B(0,-5,10,STONE)
B(0,-5,11,STONE)
B(0,-5,12,STONE)
B(0,-4,-12,STONE)
B(0,-4,-11,STONE)
B(0,-4,-10,STONE)
B(0,-4,-9,STONE)
B(0,-4,-8,STONE)
B(0,-4,-7,STONE)
B(0,-4,-6,STONE)
B(0,-4,-5,STONE)
B(0,-4,-4,STONE)
B(0,-4,-3,STONE)
B(0,-4,-2,STONE)
B(0,-4,-1,STONE)
B(0,-4,0,STONE)
B(0,-4,1,STONE)
B(0,-4,2,STONE)
B(0,-4,3,STONE)
B(0,-4,4,STONE)
B(0,-4,5,STONE)
B(0,-4,6,STONE)
B(0,-4,7,STONE)
B(0,-4,8,STONE)
B(0,-4,9,STONE)
B(0,-4,10,STONE)
B(0,-4,11,STONE)
B(0,-4,12,STONE)
B(0,-4,13,STONE)
B(0,-3,-13,STONE)
B(0,-3,-12,STONE)
B(0,-3,-11,STONE)
B(0,-3,-10,STONE)
B(0,-3,-9,STONE)
B(0,-3,-8,STONE)
B(0,-3,-7,STONE)
B(0,-3,-6,STONE)
B(0,-3,-5,STONE)
B(0,-3,-4,STONE)
B(0,-3,-3,STONE)
B(0,-3,-2,STONE)
B(0,-3,-1,STONE)
B(0,-3,0,STONE)
B(0,-3,1,STONE)
B(0,-3,2,STONE)
B(0,-3,3,STONE)
B(0,-3,4,STONE)
B(0,-3,5,STONE)
B(0,-3,6,STONE)
B(0,-3,7,STONE)
B(0,-3,8,STONE)
B(0,-3,9,STONE)
B(0,-3,10,STONE)
B(0,-3,11,STONE)
B(0,-3,12,STONE)
B(0,-3,13,STONE)
B(0,-2,-13,STONE)
B(0,-2,-12,STONE)
B(0,-2,-11,STONE)
B(0,-2,-10,STONE)
B(0,-2,-9,STONE)
B(0,-2,-8,STONE)
B(0,-2,-7,STONE)
B(0,-2,-6,STONE)
B(0,-2,-5,STONE)
B(0,-2,-4,STONE)
B(0,-2,-3,STONE)
B(0,-2,-2,STONE)
B(0,-2,-1,STONE)
B(0,-2,0,STONE)
B(0,-2,1,STONE)
B(0,-2,2,STONE)
B(0,-2,3,STONE)
B(0,-2,4,STONE)
B(0,-2,5,STONE)
B(0,-2,6,STONE)
B(0,-2,7,STONE)
B(0,-2,8,STONE)
B(0,-2,9,STONE)
B(0,-2,10,STONE)
B(0,-2,11,STONE)
B(0,-2,12,STONE)
B(0,-2,13,STONE)
B(0,-2,14,STONE)
B(0,-1,-13,STONE)
B(0,-1,-12,STONE)
B(0,-1,-11,STONE)
B(0,-1,-10,STONE)
B(0,-1,-9,STONE)
B(0,-1,-8,STONE)
B(0,-1,-7,STONE)
B(0,-1,-6,STONE)
B(0,-1,-5,STONE)
B(0,-1,-4,STONE)
B(0,-1,-3,STONE)
B(0,-1,-2,STONE)
B(0,-1,-1,STONE)
B(0,-1,0,STONE)
B(0,-1,1,STONE)
B(0,-1,2,STONE)
B(0,-1,3,STONE)
B(0,-1,4,STONE)
B(0,-1,5,STONE)
B(0,-1,6,STONE)
B(0,-1,7,STONE)
B(0,-1,8,STONE)
B(0,-1,9,STONE)
B(0,-1,10,STONE)
B(0,-1,11,STONE)
B(0,-1,12,STONE)
B(0,-1,13,STONE)
B(0,-1,14,STONE)
B(0,0,-13,STONE)
B(0,0,-12,STONE)
B(0,0,-11,STONE)
B(0,0,-10,STONE)
B(0,0,-9,STONE)
B(0,0,-8,STONE)
B(0,0,-7,STONE)
B(0,0,-6,STONE)
B(0,0,-5,STONE)
B(0,0,-4,STONE)
B(0,0,-3,STONE)
B(0,0,-2,STONE)
B(0,0,-1,STONE)
B(0,0,0,STONE)
B(0,0,1,STONE)
B(0,0,2,STONE)
B(0,0,3,STONE)
B(0,0,4,STONE)
B(0,0,5,STONE)
B(0,0,6,STONE)
B(0,0,7,STONE)
B(0,0,8,STONE)
B(0,0,9,STONE)
B(0,0,10,STONE)
B(0,0,11,STONE)
B(0,0,12,STONE)
B(0,0,13,STONE)
B(0,1,-12,STONE)
B(0,1,-11,STONE)
B(0,1,-10,STONE)
B(0,1,-9,STONE)
B(0,1,-8,STONE)
B(0,1,-7,STONE)
B(0,1,-6,STONE)
B(0,1,-5,STONE)
B(0,1,-4,STONE)
B(0,1,-3,STONE)
B(0,1,-2,STONE)
B(0,1,-1,STONE)
B(0,1,0,STONE)
B(0,1,1,STONE)
B(0,1,2,STONE)
B(0,1,3,STONE)
B(0,1,4,STONE)
B(0,1,5,STONE)
B(0,1,6,STONE)
B(0,1,7,STONE)
B(0,1,8,STONE)
B(0,1,9,STONE)
B(0,1,10,STONE)
B(0,1,11,STONE)
B(0,1,12,STONE)
B(0,1,13,STONE)
B(0,2,-11,STONE)
B(0,2,-10,STONE)
B(0,2,-9,STONE)
B(0,2,-8,STONE)
B(0,2,-7,STONE)
B(0,2,-6,STONE)
B(0,2,-5,STONE)
B(0,2,-4,STONE)
B(0,2,-3,STONE)
B(0,2,-2,STONE)
B(0,2,-1,STONE)
B(0,2,0,STONE)
B(0,2,1,STONE)
B(0,2,2,STONE)
B(0,2,3,STONE)
B(0,2,4,STONE)
B(0,2,5,STONE)
B(0,2,6,STONE)
B(0,2,7,STONE)
B(0,2,8,STONE)
B(0,2,9,STONE)
B(0,2,10,STONE)
B(0,2,11,STONE)
B(0,2,12,STONE)
B(0,3,-10,STONE)
B(0,3,-9,STONE)
B(0,3,-8,STONE)
B(0,3,-7,STONE)
B(0,3,-6,STONE)
B(0,3,-5,STONE)
B(0,3,-4,STONE)
B(0,3,-3,STONE)
B(0,3,-2,STONE)
B(0,3,-1,STONE)
B(0,3,0,STONE)
B(0,3,1,STONE)
B(0,3,2,STONE)
B(0,3,3,STONE)
B(0,3,4,STONE)
B(0,3,5,STONE)
B(0,3,6,STONE)
B(0,3,7,STONE)
B(0,3,8,STONE)
B(0,3,9,STONE)
B(0,3,10,STONE)
B(0,3,11,STONE)
B(0,4,-9,STONE)
B(0,4,-8,STONE)
B(0,4,-7,STONE)
B(0,4,-6,STONE)
B(0,4,-5,STONE)
B(0,4,-4,STONE)
B(0,4,-3,STONE)
B(0,4,-2,STONE)
B(0,4,-1,STONE)
B(0,4,0,STONE)
B(0,4,1,STONE)
B(0,4,2,STONE)
B(0,4,3,STONE)
B(0,4,4,STONE)
B(0,4,5,STONE)
B(0,4,6,STONE)
B(0,4,7,STONE)
B(0,4,8,STONE)
B(0,4,9,STONE)
B(0,4,10,STONE)
B(0,5,-9,STONE)
B(0,5,-8,STONE)
B(0,5,-7,STONE)
B(0,5,-6,STONE)
B(0,5,-5,STONE)
B(0,5,-4,STONE)
B(0,5,-3,STONE)
B(0,5,-2,STONE)
B(0,5,-1,STONE)
B(0,5,0,STONE)
B(0,5,1,STONE)
B(0,5,2,STONE)
B(0,5,3,STONE)
B(0,5,4,STONE)
B(0,5,5,STONE)
B(0,5,6,STONE)
B(0,5,7,STONE)
B(0,5,8,STONE)
B(0,5,9,STONE)
B(0,5,10,STONE)
B(0,6,-8,STONE)
B(0,6,-7,STONE)
B(0,6,-6,STONE)
B(0,6,-5,STONE)
B(0,6,-4,STONE)
B(0,6,-3,STONE)
B(0,6,-2,STONE)
B(0,6,-1,STONE)
B(0,6,0,STONE)
B(0,6,1,STONE)
B(0,6,2,STONE)
B(0,6,3,STONE)
B(0,6,4,STONE)
B(0,6,5,STONE)
B(0,6,6,STONE)
B(0,6,7,STONE)
B(0,6,8,STONE)
B(0,6,9,STONE)
B(0,7,-7,STONE)
B(0,7,-6,STONE)
B(0,7,-5,STONE)
B(0,7,-4,STONE)
B(0,7,-3,STONE)
B(0,7,-2,STONE)
B(0,7,-1,STONE)
B(0,7,0,STONE)
B(0,7,1,STONE)
B(0,7,2,STONE)
B(0,7,3,STONE)
B(0,7,4,STONE)
B(0,7,5,STONE)
B(0,7,6,STONE)
B(0,7,7,STONE)
B(0,7,8,STONE)
B(0,7,9,STONE)
B(0,8,-7,STONE)
B(0,8,-6,STONE)
B(0,8,-5,STONE)
B(0,8,-4,STONE)
B(0,8,-3,STONE)
B(0,8,-2,LAVA)
B(0,8,-1,STONE)
B(0,8,0,STONE)
B(0,8,1,STONE)
B(0,8,2,STONE)
B(0,8,3,STONE)
B(0,8,4,STONE)
B(0,8,5,STONE)
B(0,8,6,STONE)
B(0,8,7,STONE)
B(0,8,8,STONE)
B(0,9,-6,STONE)
B(0,9,-5,STONE)
B(0,9,-4,STONE)
B(0,9,-3,LAVA)
B(0,9,-2,LAVA)
B(0,9,-1,LAVA)
B(0,9,0,LAVA)
B(0,9,1,STONE)
B(0,9,2,STONE)
B(0,9,3,STONE)
B(0,9,4,STONE)
B(0,9,5,STONE)
B(0,9,6,STONE)
B(0,9,7,STONE)
B(0,9,8,STONE)
B(0,10,2,STONE)
B(0,10,3,STONE)
B(0,10,4,STONE)
B(0,10,5,STONE)
B(0,10,6,STONE)
B(0,10,7,STONE)
B(0,11,2,STONE)
B(0,11,3,STONE)
B(0,11,4,STONE)
B(0,11,5,STONE)
B(1,-12,-6,STONE)
B(1,-12,-5,STONE)
B(1,-12,-4,STONE)
B(1,-12,-3,STONE)
B(1,-12,-2,STONE)
B(1,-12,-1,STONE)
B(1,-12,0,STONE)
B(1,-12,1,STONE)
B(1,-12,2,STONE)
B(1,-12,3,STONE)
B(1,-12,4,STONE)
B(1,-12,5,STONE)
B(1,-12,6,STONE)
B(1,-12,7,STONE)
B(1,-12,8,STONE)
B(1,-11,-7,STONE)
B(1,-11,-6,STONE)
B(1,-11,-5,STONE)
B(1,-11,-4,STONE)
B(1,-11,-3,STONE)
B(1,-11,-2,STONE)
B(1,-11,-1,STONE)
B(1,-11,0,STONE)
B(1,-11,1,STONE)
B(1,-11,2,STONE)
B(1,-11,3,STONE)
B(1,-11,4,STONE)
B(1,-11,5,STONE)
B(1,-11,6,STONE)
B(1,-11,7,STONE)
B(1,-11,8,STONE)
B(1,-10,-8,STONE)
B(1,-10,-7,STONE)
B(1,-10,-6,STONE)
B(1,-10,-5,STONE)
B(1,-10,-4,STONE)
B(1,-10,-3,STONE)
B(1,-10,-2,STONE)
B(1,-10,-1,STONE)
B(1,-10,0,STONE)
B(1,-10,1,STONE)
B(1,-10,2,STONE)
B(1,-10,3,STONE)
B(1,-10,4,STONE)
B(1,-10,5,STONE)
B(1,-10,6,STONE)
B(1,-10,7,STONE)
B(1,-10,8,STONE)
B(1,-10,9,STONE)
B(1,-9,-8,STONE)
B(1,-9,-7,STONE)
B(1,-9,-6,STONE)
B(1,-9,-5,STONE)
B(1,-9,-4,STONE)
B(1,-9,-3,STONE)
B(1,-9,-2,STONE)
B(1,-9,-1,STONE)
B(1,-9,0,STONE)
B(1,-9,1,STONE)
B(1,-9,2,STONE)
B(1,-9,3,STONE)
B(1,-9,4,STONE)
B(1,-9,5,STONE)
B(1,-9,6,STONE)
B(1,-9,7,STONE)
B(1,-9,8,STONE)
B(1,-9,9,STONE)
B(1,-8,-9,STONE)
B(1,-8,-8,STONE)
B(1,-8,-7,STONE)
B(1,-8,-6,STONE)
B(1,-8,-5,STONE)
B(1,-8,-4,STONE)
B(1,-8,-3,STONE)
B(1,-8,-2,STONE)
B(1,-8,-1,STONE)
B(1,-8,0,STONE)
B(1,-8,1,STONE)
B(1,-8,2,STONE)
B(1,-8,3,STONE)
B(1,-8,4,STONE)
B(1,-8,5,STONE)
B(1,-8,6,STONE)
B(1,-8,7,STONE)
B(1,-8,8,STONE)
B(1,-8,9,STONE)
B(1,-8,10,STONE)
B(1,-7,-9,STONE)
B(1,-7,-8,STONE)
B(1,-7,-7,STONE)
B(1,-7,-6,STONE)
B(1,-7,-5,STONE)
B(1,-7,-4,STONE)
B(1,-7,-3,STONE)
B(1,-7,-2,STONE)
B(1,-7,-1,STONE)
B(1,-7,0,STONE)
B(1,-7,1,STONE)
B(1,-7,2,STONE)
B(1,-7,3,STONE)
B(1,-7,4,STONE)
B(1,-7,5,STONE)
B(1,-7,6,STONE)
B(1,-7,7,STONE)
B(1,-7,8,STONE)
B(1,-7,9,STONE)
B(1,-7,10,STONE)
B(1,-6,-10,STONE)
B(1,-6,-9,STONE)
B(1,-6,-8,STONE)
B(1,-6,-7,STONE)
B(1,-6,-6,STONE)
B(1,-6,-5,STONE)
B(1,-6,-4,STONE)
B(1,-6,-3,STONE)
B(1,-6,-2,STONE)
B(1,-6,-1,STONE)
B(1,-6,0,STONE)
B(1,-6,1,STONE)
B(1,-6,2,STONE)
B(1,-6,3,STONE)
B(1,-6,4,STONE)
B(1,-6,5,STONE)
B(1,-6,6,STONE)
B(1,-6,7,STONE)
B(1,-6,8,STONE)
B(1,-6,9,STONE)
B(1,-6,10,STONE)
B(1,-6,11,STONE)
B(1,-5,-11,STONE)
B(1,-5,-10,STONE)
B(1,-5,-9,STONE)
B(1,-5,-8,STONE)
B(1,-5,-7,STONE)
B(1,-5,-6,STONE)
B(1,-5,-5,STONE)
B(1,-5,-4,STONE)
B(1,-5,-3,STONE)
B(1,-5,-2,STONE)
B(1,-5,-1,STONE)
B(1,-5,0,STONE)
B(1,-5,1,STONE)
B(1,-5,2,STONE)
B(1,-5,3,STONE)
B(1,-5,4,STONE)
B(1,-5,5,STONE)
B(1,-5,6,STONE)
B(1,-5,7,STONE)
B(1,-5,8,STONE)
B(1,-5,9,STONE)
B(1,-5,10,STONE)
B(1,-5,11,STONE)
B(1,-5,12,STONE)
B(1,-4,-12,STONE)
B(1,-4,-11,STONE)
B(1,-4,-10,STONE)
B(1,-4,-9,STONE)
B(1,-4,-8,STONE)
B(1,-4,-7,STONE)
B(1,-4,-6,STONE)
B(1,-4,-5,STONE)
B(1,-4,-4,STONE)
B(1,-4,-3,STONE)
B(1,-4,-2,STONE)
B(1,-4,-1,STONE)
B(1,-4,0,STONE)
B(1,-4,1,STONE)
B(1,-4,2,STONE)
B(1,-4,3,STONE)
B(1,-4,4,STONE)
B(1,-4,5,STONE)
B(1,-4,6,STONE)
B(1,-4,7,STONE)
B(1,-4,8,STONE)
B(1,-4,9,STONE)
B(1,-4,10,STONE)
B(1,-4,11,STONE)
B(1,-4,12,STONE)
B(1,-4,13,STONE)
B(1,-3,-12,STONE)
B(1,-3,-11,STONE)
B(1,-3,-10,STONE)
B(1,-3,-9,STONE)
B(1,-3,-8,STONE)
B(1,-3,-7,STONE)
B(1,-3,-6,STONE)
B(1,-3,-5,STONE)
B(1,-3,-4,STONE)
B(1,-3,-3,STONE)
B(1,-3,-2,STONE)
B(1,-3,-1,STONE)
B(1,-3,0,STONE)
B(1,-3,1,STONE)
B(1,-3,2,STONE)
B(1,-3,3,STONE)
B(1,-3,4,STONE)
B(1,-3,5,STONE)
B(1,-3,6,STONE)
B(1,-3,7,STONE)
B(1,-3,8,STONE)
B(1,-3,9,STONE)
B(1,-3,10,STONE)
B(1,-3,11,STONE)
B(1,-3,12,STONE)
B(1,-3,13,STONE)
B(1,-3,14,STONE)
B(1,-2,-13,STONE)
B(1,-2,-12,STONE)
B(1,-2,-11,STONE)
B(1,-2,-10,STONE)
B(1,-2,-9,STONE)
B(1,-2,-8,STONE)
B(1,-2,-7,STONE)
B(1,-2,-6,STONE)
B(1,-2,-5,STONE)
B(1,-2,-4,STONE)
B(1,-2,-3,STONE)
B(1,-2,-2,STONE)
B(1,-2,-1,STONE)
B(1,-2,0,STONE)
B(1,-2,1,STONE)
B(1,-2,2,STONE)
B(1,-2,3,STONE)
B(1,-2,4,STONE)
B(1,-2,5,STONE)
B(1,-2,6,STONE)
B(1,-2,7,STONE)
B(1,-2,8,STONE)
B(1,-2,9,STONE)
B(1,-2,10,STONE)
B(1,-2,11,STONE)
B(1,-2,12,STONE)
B(1,-2,13,STONE)
B(1,-2,14,STONE)
B(1,-1,-13,STONE)
B(1,-1,-12,STONE)
B(1,-1,-11,STONE)
B(1,-1,-10,STONE)
B(1,-1,-9,STONE)
B(1,-1,-8,STONE)
B(1,-1,-7,STONE)
B(1,-1,-6,STONE)
B(1,-1,-5,STONE)
B(1,-1,-4,STONE)
B(1,-1,-3,STONE)
B(1,-1,-2,STONE)
B(1,-1,-1,STONE)
B(1,-1,0,STONE)
B(1,-1,1,STONE)
B(1,-1,2,STONE)
B(1,-1,3,STONE)
B(1,-1,4,STONE)
B(1,-1,5,STONE)
B(1,-1,6,STONE)
B(1,-1,7,STONE)
B(1,-1,8,STONE)
B(1,-1,9,STONE)
B(1,-1,10,STONE)
B(1,-1,11,STONE)
B(1,-1,12,STONE)
B(1,-1,13,STONE)
B(1,-1,14,STONE)
B(1,0,-12,STONE)
B(1,0,-11,STONE)
B(1,0,-10,STONE)
B(1,0,-9,STONE)
B(1,0,-8,STONE)
B(1,0,-7,STONE)
B(1,0,-6,STONE)
B(1,0,-5,STONE)
B(1,0,-4,STONE)
B(1,0,-3,STONE)
B(1,0,-2,STONE)
B(1,0,-1,STONE)
B(1,0,0,STONE)
B(1,0,1,STONE)
B(1,0,2,STONE)
B(1,0,3,STONE)
B(1,0,4,STONE)
B(1,0,5,STONE)
B(1,0,6,STONE)
B(1,0,7,STONE)
B(1,0,8,STONE)
B(1,0,9,STONE)
B(1,0,10,STONE)
B(1,0,11,STONE)
B(1,0,12,STONE)
B(1,0,13,STONE)
B(1,0,14,STONE)
B(1,1,-12,STONE)
B(1,1,-11,STONE)
B(1,1,-10,STONE)
B(1,1,-9,STONE)
B(1,1,-8,STONE)
B(1,1,-7,STONE)
B(1,1,-6,STONE)
B(1,1,-5,STONE)
B(1,1,-4,STONE)
B(1,1,-3,STONE)
B(1,1,-2,STONE)
B(1,1,-1,STONE)
B(1,1,0,STONE)
B(1,1,1,STONE)
B(1,1,2,STONE)
B(1,1,3,STONE)
B(1,1,4,STONE)
B(1,1,5,STONE)
B(1,1,6,STONE)
B(1,1,7,STONE)
B(1,1,8,STONE)
B(1,1,9,STONE)
B(1,1,10,STONE)
B(1,1,11,STONE)
B(1,1,12,STONE)
B(1,1,13,STONE)
B(1,2,-11,STONE)
B(1,2,-10,STONE)
B(1,2,-9,STONE)
B(1,2,-8,STONE)
B(1,2,-7,STONE)
B(1,2,-6,STONE)
B(1,2,-5,STONE)
B(1,2,-4,STONE)
B(1,2,-3,STONE)
B(1,2,-2,STONE)
B(1,2,-1,STONE)
B(1,2,0,STONE)
B(1,2,1,STONE)
B(1,2,2,STONE)
B(1,2,3,STONE)
B(1,2,4,STONE)
B(1,2,5,STONE)
B(1,2,6,STONE)
B(1,2,7,STONE)
B(1,2,8,STONE)
B(1,2,9,STONE)
B(1,2,10,STONE)
B(1,2,11,STONE)
B(1,2,12,STONE)
B(1,3,-10,STONE)
B(1,3,-9,STONE)
B(1,3,-8,STONE)
B(1,3,-7,STONE)
B(1,3,-6,STONE)
B(1,3,-5,STONE)
B(1,3,-4,STONE)
B(1,3,-3,STONE)
B(1,3,-2,STONE)
B(1,3,-1,STONE)
B(1,3,0,STONE)
B(1,3,1,STONE)
B(1,3,2,STONE)
B(1,3,3,STONE)
B(1,3,4,STONE)
B(1,3,5,STONE)
B(1,3,6,STONE)
B(1,3,7,STONE)
B(1,3,8,STONE)
B(1,3,9,STONE)
B(1,3,10,STONE)
B(1,3,11,STONE)
B(1,4,-9,STONE)
B(1,4,-8,STONE)
B(1,4,-7,STONE)
B(1,4,-6,STONE)
B(1,4,-5,STONE)
B(1,4,-4,STONE)
B(1,4,-3,STONE)
B(1,4,-2,STONE)
B(1,4,-1,STONE)
B(1,4,0,STONE)
B(1,4,1,STONE)
B(1,4,2,STONE)
B(1,4,3,STONE)
B(1,4,4,STONE)
B(1,4,5,STONE)
B(1,4,6,STONE)
B(1,4,7,STONE)
B(1,4,8,STONE)
B(1,4,9,STONE)
B(1,4,10,STONE)
B(1,5,-9,STONE)
B(1,5,-8,STONE)
B(1,5,-7,STONE)
B(1,5,-6,STONE)
B(1,5,-5,STONE)
B(1,5,-4,STONE)
B(1,5,-3,STONE)
B(1,5,-2,STONE)
B(1,5,-1,STONE)
B(1,5,0,STONE)
B(1,5,1,STONE)
B(1,5,2,STONE)
B(1,5,3,STONE)
B(1,5,4,STONE)
B(1,5,5,STONE)
B(1,5,6,STONE)
B(1,5,7,STONE)
B(1,5,8,STONE)
B(1,5,9,STONE)
B(1,5,10,STONE)
B(1,6,-8,STONE)
B(1,6,-7,STONE)
B(1,6,-6,STONE)
B(1,6,-5,STONE)
B(1,6,-4,STONE)
B(1,6,-3,STONE)
B(1,6,-2,STONE)
B(1,6,-1,STONE)
B(1,6,0,STONE)
B(1,6,1,STONE)
B(1,6,2,STONE)
B(1,6,3,STONE)
B(1,6,4,STONE)
B(1,6,5,STONE)
B(1,6,6,STONE)
B(1,6,7,STONE)
B(1,6,8,STONE)
B(1,6,9,STONE)
B(1,7,-8,STONE)
B(1,7,-7,STONE)
B(1,7,-6,STONE)
B(1,7,-5,STONE)
B(1,7,-4,STONE)
B(1,7,-3,STONE)
B(1,7,-2,STONE)
B(1,7,-1,LAVA)
B(1,7,0,STONE)
B(1,7,1,STONE)
B(1,7,2,STONE)
B(1,7,3,STONE)
B(1,7,4,STONE)
B(1,7,5,STONE)
B(1,7,6,STONE)
B(1,7,7,STONE)
B(1,7,8,STONE)
B(1,7,9,STONE)
B(1,8,-7,STONE)
B(1,8,-6,STONE)
B(1,8,-5,STONE)
B(1,8,-4,STONE)
B(1,8,-3,STONE)
B(1,8,-2,LAVA)
B(1,8,-1,LAVA)
B(1,8,0,LAVA)
B(1,8,1,STONE)
B(1,8,2,STONE)
B(1,8,3,STONE)
B(1,8,4,STONE)
B(1,8,5,STONE)
B(1,8,6,STONE)
B(1,8,7,STONE)
B(1,8,8,STONE)
B(1,9,-6,STONE)
B(1,9,-5,STONE)
B(1,9,-4,STONE)
B(1,9,-3,LAVA)
B(1,9,-2,LAVA)
B(1,9,-1,LAVA)
B(1,9,0,LAVA)
B(1,9,1,STONE)
B(1,9,2,STONE)
B(1,9,3,STONE)
B(1,9,4,STONE)
B(1,9,5,STONE)
B(1,9,6,STONE)
B(1,9,7,STONE)
B(1,9,8,STONE)
B(1,10,3,STONE)
B(1,10,4,STONE)
B(1,10,5,STONE)
B(1,10,6,STONE)
B(1,10,7,STONE)
B(1,11,3,STONE)
B(1,11,4,STONE)
B(1,11,5,STONE)
B(1,11,6,STONE)
B(2,-12,-7,STONE)
B(2,-12,-6,STONE)
B(2,-12,-5,STONE)
B(2,-12,-4,STONE)
B(2,-12,-3,STONE)
B(2,-12,-2,STONE)
B(2,-12,-1,STONE)
B(2,-12,0,STONE)
B(2,-12,1,STONE)
B(2,-12,2,STONE)
B(2,-12,3,STONE)
B(2,-12,4,STONE)
B(2,-12,5,STONE)
B(2,-12,6,STONE)
B(2,-12,7,STONE)
B(2,-12,8,STONE)
B(2,-11,-7,STONE)
B(2,-11,-6,STONE)
B(2,-11,-5,STONE)
B(2,-11,-4,STONE)
B(2,-11,-3,STONE)
B(2,-11,-2,STONE)
B(2,-11,-1,STONE)
B(2,-11,0,STONE)
B(2,-11,1,STONE)
B(2,-11,2,STONE)
B(2,-11,3,STONE)
B(2,-11,4,STONE)
B(2,-11,5,STONE)
B(2,-11,6,STONE)
B(2,-11,7,STONE)
B(2,-11,8,STONE)
B(2,-10,-8,STONE)
B(2,-10,-7,STONE)
B(2,-10,-6,STONE)
B(2,-10,-5,STONE)
B(2,-10,-4,STONE)
B(2,-10,-3,STONE)
B(2,-10,-2,STONE)
B(2,-10,-1,STONE)
B(2,-10,0,STONE)
B(2,-10,1,STONE)
B(2,-10,2,STONE)
B(2,-10,3,STONE)
B(2,-10,4,STONE)
B(2,-10,5,STONE)
B(2,-10,6,STONE)
B(2,-10,7,STONE)
B(2,-10,8,STONE)
B(2,-10,9,STONE)
B(2,-9,-8,STONE)
B(2,-9,-7,STONE)
B(2,-9,-6,STONE)
B(2,-9,-5,STONE)
B(2,-9,-4,STONE)
B(2,-9,-3,STONE)
B(2,-9,-2,STONE)
B(2,-9,-1,STONE)
B(2,-9,0,STONE)
B(2,-9,1,STONE)
B(2,-9,2,STONE)
B(2,-9,3,STONE)
B(2,-9,4,STONE)
B(2,-9,5,STONE)
B(2,-9,6,STONE)
B(2,-9,7,STONE)
B(2,-9,8,STONE)
B(2,-9,9,STONE)
B(2,-8,-9,STONE)
B(2,-8,-8,STONE)
B(2,-8,-7,STONE)
B(2,-8,-6,STONE)
B(2,-8,-5,STONE)
B(2,-8,-4,STONE)
B(2,-8,-3,STONE)
B(2,-8,-2,STONE)
B(2,-8,-1,STONE)
B(2,-8,0,STONE)
B(2,-8,1,STONE)
B(2,-8,2,STONE)
B(2,-8,3,STONE)
B(2,-8,4,STONE)
B(2,-8,5,STONE)
B(2,-8,6,STONE)
B(2,-8,7,STONE)
B(2,-8,8,STONE)
B(2,-8,9,STONE)
B(2,-8,10,STONE)
B(2,-7,-9,STONE)
B(2,-7,-8,STONE)
B(2,-7,-7,STONE)
B(2,-7,-6,STONE)
B(2,-7,-5,STONE)
B(2,-7,-4,STONE)
B(2,-7,-3,STONE)
B(2,-7,-2,STONE)
B(2,-7,-1,STONE)
B(2,-7,0,STONE)
B(2,-7,1,STONE)
B(2,-7,2,STONE)
B(2,-7,3,STONE)
B(2,-7,4,STONE)
B(2,-7,5,STONE)
B(2,-7,6,STONE)
B(2,-7,7,STONE)
B(2,-7,8,STONE)
B(2,-7,9,STONE)
B(2,-7,10,STONE)
B(2,-6,-10,STONE)
B(2,-6,-9,STONE)
B(2,-6,-8,STONE)
B(2,-6,-7,STONE)
B(2,-6,-6,STONE)
B(2,-6,-5,STONE)
B(2,-6,-4,STONE)
B(2,-6,-3,STONE)
B(2,-6,-2,STONE)
B(2,-6,-1,STONE)
B(2,-6,0,STONE)
B(2,-6,1,STONE)
B(2,-6,2,STONE)
B(2,-6,3,STONE)
B(2,-6,4,STONE)
B(2,-6,5,STONE)
B(2,-6,6,STONE)
B(2,-6,7,STONE)
B(2,-6,8,STONE)
B(2,-6,9,STONE)
B(2,-6,10,STONE)
B(2,-6,11,STONE)
B(2,-5,-11,STONE)
B(2,-5,-10,STONE)
B(2,-5,-9,STONE)
B(2,-5,-8,STONE)
B(2,-5,-7,STONE)
B(2,-5,-6,STONE)
B(2,-5,-5,STONE)
B(2,-5,-4,STONE)
B(2,-5,-3,STONE)
B(2,-5,-2,STONE)
B(2,-5,-1,STONE)
B(2,-5,0,STONE)
B(2,-5,1,STONE)
B(2,-5,2,STONE)
B(2,-5,3,STONE)
B(2,-5,4,STONE)
B(2,-5,5,STONE)
B(2,-5,6,STONE)
B(2,-5,7,STONE)
B(2,-5,8,STONE)
B(2,-5,9,STONE)
B(2,-5,10,STONE)
B(2,-5,11,STONE)
B(2,-5,12,STONE)
B(2,-4,-12,STONE)
B(2,-4,-11,STONE)
B(2,-4,-10,STONE)
B(2,-4,-9,STONE)
B(2,-4,-8,STONE)
B(2,-4,-7,STONE)
B(2,-4,-6,STONE)
B(2,-4,-5,STONE)
B(2,-4,-4,STONE)
B(2,-4,-3,STONE)
B(2,-4,-2,STONE)
B(2,-4,-1,STONE)
B(2,-4,0,STONE)
B(2,-4,1,STONE)
B(2,-4,2,STONE)
B(2,-4,3,STONE)
B(2,-4,4,STONE)
B(2,-4,5,STONE)
B(2,-4,6,STONE)
B(2,-4,7,STONE)
B(2,-4,8,STONE)
B(2,-4,9,STONE)
B(2,-4,10,STONE)
B(2,-4,11,STONE)
B(2,-4,12,STONE)
B(2,-4,13,STONE)
B(2,-4,14,STONE)
B(2,-3,-13,STONE)
B(2,-3,-12,STONE)
B(2,-3,-11,STONE)
B(2,-3,-10,STONE)
B(2,-3,-9,STONE)
B(2,-3,-8,STONE)
B(2,-3,-7,STONE)
B(2,-3,-6,STONE)
B(2,-3,-5,STONE)
B(2,-3,-4,STONE)
B(2,-3,-3,STONE)
B(2,-3,-2,STONE)
B(2,-3,-1,STONE)
B(2,-3,0,STONE)
B(2,-3,1,STONE)
B(2,-3,2,STONE)
B(2,-3,3,STONE)
B(2,-3,4,STONE)
B(2,-3,5,STONE)
B(2,-3,6,STONE)
B(2,-3,7,STONE)
B(2,-3,8,STONE)
B(2,-3,9,STONE)
B(2,-3,10,STONE)
B(2,-3,11,STONE)
B(2,-3,12,STONE)
B(2,-3,13,STONE)
B(2,-3,14,STONE)
B(2,-3,15,STONE)
B(2,-2,-13,STONE)
B(2,-2,-12,STONE)
B(2,-2,-11,STONE)
B(2,-2,-10,STONE)
B(2,-2,-9,STONE)
B(2,-2,-8,STONE)
B(2,-2,-7,STONE)
B(2,-2,-6,STONE)
B(2,-2,-5,STONE)
B(2,-2,-4,STONE)
B(2,-2,-3,STONE)
B(2,-2,-2,STONE)
B(2,-2,-1,STONE)
B(2,-2,0,STONE)
B(2,-2,1,STONE)
B(2,-2,2,STONE)
B(2,-2,3,STONE)
B(2,-2,4,STONE)
B(2,-2,5,STONE)
B(2,-2,6,STONE)
B(2,-2,7,STONE)
B(2,-2,8,STONE)
B(2,-2,9,STONE)
B(2,-2,10,STONE)
B(2,-2,11,STONE)
B(2,-2,12,STONE)
B(2,-2,13,STONE)
B(2,-2,14,STONE)
B(2,-2,15,STONE)
B(2,-1,-13,STONE)
B(2,-1,-12,STONE)
B(2,-1,-11,STONE)
B(2,-1,-10,STONE)
B(2,-1,-9,STONE)
B(2,-1,-8,STONE)
B(2,-1,-7,STONE)
B(2,-1,-6,STONE)
B(2,-1,-5,STONE)
B(2,-1,-4,STONE)
B(2,-1,-3,STONE)
B(2,-1,-2,STONE)
B(2,-1,-1,STONE)
B(2,-1,0,STONE)
B(2,-1,1,STONE)
B(2,-1,2,STONE)
B(2,-1,3,STONE)
B(2,-1,4,STONE)
B(2,-1,5,STONE)
B(2,-1,6,STONE)
B(2,-1,7,STONE)
B(2,-1,8,STONE)
B(2,-1,9,STONE)
B(2,-1,10,STONE)
B(2,-1,11,STONE)
B(2,-1,12,STONE)
B(2,-1,13,STONE)
B(2,-1,14,STONE)
B(2,-1,15,STONE)
B(2,0,-13,STONE)
B(2,0,-12,STONE)
B(2,0,-11,STONE)
B(2,0,-10,STONE)
B(2,0,-9,STONE)
B(2,0,-8,STONE)
B(2,0,-7,STONE)
B(2,0,-6,STONE)
B(2,0,-5,STONE)
B(2,0,-4,STONE)
B(2,0,-3,STONE)
B(2,0,-2,STONE)
B(2,0,-1,STONE)
B(2,0,0,STONE)
B(2,0,1,STONE)
B(2,0,2,STONE)
B(2,0,3,STONE)
B(2,0,4,STONE)
B(2,0,5,STONE)
B(2,0,6,STONE)
B(2,0,7,STONE)
B(2,0,8,STONE)
B(2,0,9,STONE)
B(2,0,10,STONE)
B(2,0,11,STONE)
B(2,0,12,STONE)
B(2,0,13,STONE)
B(2,0,14,STONE)
B(2,0,15,STONE)
B(2,1,-12,STONE)
B(2,1,-11,STONE)
B(2,1,-10,STONE)
B(2,1,-9,STONE)
B(2,1,-8,STONE)
B(2,1,-7,STONE)
B(2,1,-6,STONE)
B(2,1,-5,STONE)
B(2,1,-4,STONE)
B(2,1,-3,STONE)
B(2,1,-2,STONE)
B(2,1,-1,STONE)
B(2,1,0,STONE)
B(2,1,1,STONE)
B(2,1,2,STONE)
B(2,1,3,STONE)
B(2,1,4,STONE)
B(2,1,5,STONE)
B(2,1,6,STONE)
B(2,1,7,STONE)
B(2,1,8,STONE)
B(2,1,9,STONE)
B(2,1,10,STONE)
B(2,1,11,STONE)
B(2,1,12,STONE)
B(2,1,13,STONE)
B(2,1,14,STONE)
B(2,2,-11,STONE)
B(2,2,-10,STONE)
B(2,2,-9,STONE)
B(2,2,-8,STONE)
B(2,2,-7,STONE)
B(2,2,-6,STONE)
B(2,2,-5,STONE)
B(2,2,-4,STONE)
B(2,2,-3,STONE)
B(2,2,-2,STONE)
B(2,2,-1,STONE)
B(2,2,0,STONE)
B(2,2,1,STONE)
B(2,2,2,STONE)
B(2,2,3,STONE)
B(2,2,4,STONE)
B(2,2,5,STONE)
B(2,2,6,STONE)
B(2,2,7,STONE)
B(2,2,8,STONE)
B(2,2,9,STONE)
B(2,2,10,STONE)
B(2,2,11,STONE)
B(2,2,12,STONE)
B(2,3,-10,STONE)
B(2,3,-9,STONE)
B(2,3,-8,STONE)
B(2,3,-7,STONE)
B(2,3,-6,STONE)
B(2,3,-5,STONE)
B(2,3,-4,STONE)
B(2,3,-3,STONE)
B(2,3,-2,STONE)
B(2,3,-1,STONE)
B(2,3,0,STONE)
B(2,3,1,STONE)
B(2,3,2,STONE)
B(2,3,3,STONE)
B(2,3,4,STONE)
B(2,3,5,STONE)
B(2,3,6,STONE)
B(2,3,7,STONE)
B(2,3,8,STONE)
B(2,3,9,STONE)
B(2,3,10,STONE)
B(2,3,11,STONE)
B(2,4,-9,STONE)
B(2,4,-8,STONE)
B(2,4,-7,STONE)
B(2,4,-6,STONE)
B(2,4,-5,STONE)
B(2,4,-4,STONE)
B(2,4,-3,STONE)
B(2,4,-2,STONE)
B(2,4,-1,STONE)
B(2,4,0,STONE)
B(2,4,1,STONE)
B(2,4,2,STONE)
B(2,4,3,STONE)
B(2,4,4,STONE)
B(2,4,5,STONE)
B(2,4,6,STONE)
B(2,4,7,STONE)
B(2,4,8,STONE)
B(2,4,9,STONE)
B(2,4,10,STONE)
B(2,5,-9,STONE)
B(2,5,-8,STONE)
B(2,5,-7,STONE)
B(2,5,-6,STONE)
B(2,5,-5,STONE)
B(2,5,-4,STONE)
B(2,5,-3,STONE)
B(2,5,-2,STONE)
B(2,5,-1,STONE)
B(2,5,0,STONE)
B(2,5,1,STONE)
B(2,5,2,STONE)
B(2,5,3,STONE)
B(2,5,4,STONE)
B(2,5,5,STONE)
B(2,5,6,STONE)
B(2,5,7,STONE)
B(2,5,8,STONE)
B(2,5,9,STONE)
B(2,5,10,STONE)
B(2,6,-8,STONE)
B(2,6,-7,STONE)
B(2,6,-6,STONE)
B(2,6,-5,STONE)
B(2,6,-4,STONE)
B(2,6,-3,STONE)
B(2,6,-2,STONE)
B(2,6,-1,STONE)
B(2,6,0,STONE)
B(2,6,1,STONE)
B(2,6,2,STONE)
B(2,6,3,STONE)
B(2,6,4,STONE)
B(2,6,5,STONE)
B(2,6,6,STONE)
B(2,6,7,STONE)
B(2,6,8,STONE)
B(2,6,9,STONE)
B(2,7,-8,STONE)
B(2,7,-7,STONE)
B(2,7,-6,STONE)
B(2,7,-5,STONE)
B(2,7,-4,STONE)
B(2,7,-3,STONE)
B(2,7,-2,LAVA)
B(2,7,-1,LAVA)
B(2,7,0,LAVA)
B(2,7,1,LAVA)
B(2,7,2,STONE)
B(2,7,3,STONE)
B(2,7,4,STONE)
B(2,7,5,STONE)
B(2,7,6,STONE)
B(2,7,7,STONE)
B(2,7,8,STONE)
B(2,7,9,STONE)
B(2,8,-7,STONE)
B(2,8,-6,STONE)
B(2,8,-5,STONE)
B(2,8,-4,LAVA)
B(2,8,-3,LAVA)
B(2,8,-2,LAVA)
B(2,8,-1,LAVA)
B(2,8,0,LAVA)
B(2,8,1,LAVA)
B(2,8,2,STONE)
B(2,8,3,STONE)
B(2,8,4,STONE)
B(2,8,5,STONE)
B(2,8,6,STONE)
B(2,8,7,STONE)
B(2,8,8,STONE)
B(2,9,-7,STONE)
B(2,9,-6,STONE)
B(2,9,-5,LAVA)
B(2,9,-4,LAVA)
B(2,9,-3,LAVA)
B(2,9,-2,LAVA)
B(2,9,-1,LAVA)
B(2,9,0,LAVA)
B(2,9,1,LAVA)
B(2,9,2,STONE)
B(2,9,3,LAVA)
B(2,9,4,STONE)
B(2,9,5,STONE)
B(2,9,6,STONE)
B(2,9,7,STONE)
B(2,9,8,STONE)
B(2,10,4,STONE)
B(2,10,5,STONE)
B(2,10,6,STONE)
B(2,10,7,STONE)
B(2,11,4,STONE)
B(2,11,5,STONE)
B(2,11,6,STONE)
B(3,-12,-7,STONE)
B(3,-12,-6,STONE)
B(3,-12,-5,STONE)
B(3,-12,-4,STONE)
B(3,-12,-3,STONE)
B(3,-12,-2,STONE)
B(3,-12,-1,STONE)
B(3,-12,0,STONE)
B(3,-12,1,STONE)
B(3,-12,2,STONE)
B(3,-12,3,STONE)
B(3,-12,4,STONE)
B(3,-12,5,STONE)
B(3,-12,6,STONE)
B(3,-12,7,STONE)
B(3,-11,-8,STONE)
B(3,-11,-7,STONE)
B(3,-11,-6,STONE)
B(3,-11,-5,STONE)
B(3,-11,-4,STONE)
B(3,-11,-3,STONE)
B(3,-11,-2,STONE)
B(3,-11,-1,STONE)
B(3,-11,0,STONE)
B(3,-11,1,STONE)
B(3,-11,2,STONE)
B(3,-11,3,STONE)
B(3,-11,4,STONE)
B(3,-11,5,STONE)
B(3,-11,6,STONE)
B(3,-11,7,STONE)
B(3,-11,8,STONE)
B(3,-10,-8,STONE)
B(3,-10,-7,STONE)
B(3,-10,-6,STONE)
B(3,-10,-5,STONE)
B(3,-10,-4,STONE)
B(3,-10,-3,STONE)
B(3,-10,-2,STONE)
B(3,-10,-1,STONE)
B(3,-10,0,STONE)
B(3,-10,1,STONE)
B(3,-10,2,STONE)
B(3,-10,3,STONE)
B(3,-10,4,STONE)
B(3,-10,5,STONE)
B(3,-10,6,STONE)
B(3,-10,7,STONE)
B(3,-10,8,STONE)
B(3,-9,-9,STONE)
B(3,-9,-8,STONE)
B(3,-9,-7,STONE)
B(3,-9,-6,STONE)
B(3,-9,-5,STONE)
B(3,-9,-4,STONE)
B(3,-9,-3,STONE)
B(3,-9,-2,STONE)
B(3,-9,-1,STONE)
B(3,-9,0,STONE)
B(3,-9,1,STONE)
B(3,-9,2,STONE)
B(3,-9,3,STONE)
B(3,-9,4,STONE)
B(3,-9,5,STONE)
B(3,-9,6,STONE)
B(3,-9,7,STONE)
B(3,-9,8,STONE)
B(3,-9,9,STONE)
B(3,-8,-9,STONE)
B(3,-8,-8,STONE)
B(3,-8,-7,STONE)
B(3,-8,-6,STONE)
B(3,-8,-5,STONE)
B(3,-8,-4,STONE)
B(3,-8,-3,STONE)
B(3,-8,-2,STONE)
B(3,-8,-1,STONE)
B(3,-8,0,STONE)
B(3,-8,1,STONE)
B(3,-8,2,STONE)
B(3,-8,3,STONE)
B(3,-8,4,STONE)
B(3,-8,5,STONE)
B(3,-8,6,STONE)
B(3,-8,7,STONE)
B(3,-8,8,STONE)
B(3,-8,9,STONE)
B(3,-8,10,STONE)
B(3,-7,-10,STONE)
B(3,-7,-9,STONE)
B(3,-7,-8,STONE)
B(3,-7,-7,STONE)
B(3,-7,-6,STONE)
B(3,-7,-5,STONE)
B(3,-7,-4,STONE)
B(3,-7,-3,STONE)
B(3,-7,-2,STONE)
B(3,-7,-1,STONE)
B(3,-7,0,STONE)
B(3,-7,1,STONE)
B(3,-7,2,STONE)
B(3,-7,3,STONE)
B(3,-7,4,STONE)
B(3,-7,5,STONE)
B(3,-7,6,STONE)
B(3,-7,7,STONE)
B(3,-7,8,STONE)
B(3,-7,9,STONE)
B(3,-7,10,STONE)
B(3,-7,11,STONE)
B(3,-6,-10,STONE)
B(3,-6,-9,STONE)
B(3,-6,-8,STONE)
B(3,-6,-7,STONE)
B(3,-6,-6,STONE)
B(3,-6,-5,STONE)
B(3,-6,-4,STONE)
B(3,-6,-3,STONE)
B(3,-6,-2,STONE)
B(3,-6,-1,STONE)
B(3,-6,0,STONE)
B(3,-6,1,STONE)
B(3,-6,2,STONE)
B(3,-6,3,STONE)
B(3,-6,4,STONE)
B(3,-6,5,STONE)
B(3,-6,6,STONE)
B(3,-6,7,STONE)
B(3,-6,8,STONE)
B(3,-6,9,STONE)
B(3,-6,10,STONE)
B(3,-6,11,STONE)
B(3,-5,-11,STONE)
B(3,-5,-10,STONE)
B(3,-5,-9,STONE)
B(3,-5,-8,STONE)
B(3,-5,-7,STONE)
B(3,-5,-6,STONE)
B(3,-5,-5,STONE)
B(3,-5,-4,STONE)
B(3,-5,-3,STONE)
B(3,-5,-2,STONE)
B(3,-5,-1,STONE)
B(3,-5,0,STONE)
B(3,-5,1,STONE)
B(3,-5,2,STONE)
B(3,-5,3,STONE)
B(3,-5,4,STONE)
B(3,-5,5,STONE)
B(3,-5,6,STONE)
B(3,-5,7,STONE)
B(3,-5,8,STONE)
B(3,-5,9,STONE)
B(3,-5,10,STONE)
B(3,-5,11,STONE)
B(3,-5,12,STONE)
B(3,-4,-13,STONE)
B(3,-4,-12,STONE)
B(3,-4,-11,STONE)
B(3,-4,-10,STONE)
B(3,-4,-9,STONE)
B(3,-4,-8,STONE)
B(3,-4,-7,STONE)
B(3,-4,-6,STONE)
B(3,-4,-5,STONE)
B(3,-4,-4,STONE)
B(3,-4,-3,STONE)
B(3,-4,-2,STONE)
B(3,-4,-1,STONE)
B(3,-4,0,STONE)
B(3,-4,1,STONE)
B(3,-4,2,STONE)
B(3,-4,3,STONE)
B(3,-4,4,STONE)
B(3,-4,5,STONE)
B(3,-4,6,STONE)
B(3,-4,7,STONE)
B(3,-4,8,STONE)
B(3,-4,9,STONE)
B(3,-4,10,STONE)
B(3,-4,11,STONE)
B(3,-4,12,STONE)
B(3,-4,13,STONE)
B(3,-4,14,STONE)
B(3,-3,-13,STONE)
B(3,-3,-12,STONE)
B(3,-3,-11,STONE)
B(3,-3,-10,STONE)
B(3,-3,-9,STONE)
B(3,-3,-8,STONE)
B(3,-3,-7,STONE)
B(3,-3,-6,STONE)
B(3,-3,-5,STONE)
B(3,-3,-4,STONE)
B(3,-3,-3,STONE)
B(3,-3,-2,STONE)
B(3,-3,-1,STONE)
B(3,-3,0,STONE)
B(3,-3,1,STONE)
B(3,-3,2,STONE)
B(3,-3,3,STONE)
B(3,-3,4,STONE)
B(3,-3,5,STONE)
B(3,-3,6,STONE)
B(3,-3,7,STONE)
B(3,-3,8,STONE)
B(3,-3,9,STONE)
B(3,-3,10,STONE)
B(3,-3,11,STONE)
B(3,-3,12,STONE)
B(3,-3,13,STONE)
B(3,-3,14,STONE)
B(3,-3,15,STONE)
B(3,-2,-14,STONE)
B(3,-2,-13,STONE)
B(3,-2,-12,STONE)
B(3,-2,-11,STONE)
B(3,-2,-10,STONE)
B(3,-2,-9,STONE)
B(3,-2,-8,STONE)
B(3,-2,-7,STONE)
B(3,-2,-6,STONE)
B(3,-2,-5,STONE)
B(3,-2,-4,STONE)
B(3,-2,-3,STONE)
B(3,-2,-2,STONE)
B(3,-2,-1,STONE)
B(3,-2,0,STONE)
B(3,-2,1,STONE)
B(3,-2,2,STONE)
B(3,-2,3,STONE)
B(3,-2,4,STONE)
B(3,-2,5,STONE)
B(3,-2,6,STONE)
B(3,-2,7,STONE)
B(3,-2,8,STONE)
B(3,-2,9,STONE)
B(3,-2,10,STONE)
B(3,-2,11,STONE)
B(3,-2,12,STONE)
B(3,-2,13,STONE)
B(3,-2,14,STONE)
B(3,-2,15,STONE)
B(3,-1,-14,STONE)
B(3,-1,-13,STONE)
B(3,-1,-12,STONE)
B(3,-1,-11,STONE)
B(3,-1,-10,STONE)
B(3,-1,-9,STONE)
B(3,-1,-8,STONE)
B(3,-1,-7,STONE)
B(3,-1,-6,STONE)
B(3,-1,-5,STONE)
B(3,-1,-4,STONE)
B(3,-1,-3,STONE)
B(3,-1,-2,STONE)
B(3,-1,-1,STONE)
B(3,-1,0,STONE)
B(3,-1,1,STONE)
B(3,-1,2,STONE)
B(3,-1,3,STONE)
B(3,-1,4,STONE)
B(3,-1,5,STONE)
B(3,-1,6,STONE)
B(3,-1,7,STONE)
B(3,-1,8,STONE)
B(3,-1,9,STONE)
B(3,-1,10,STONE)
B(3,-1,11,STONE)
B(3,-1,12,STONE)
B(3,-1,13,STONE)
B(3,-1,14,STONE)
B(3,-1,15,STONE)
B(3,0,-13,STONE)
B(3,0,-12,STONE)
B(3,0,-11,STONE)
B(3,0,-10,STONE)
B(3,0,-9,STONE)
B(3,0,-8,STONE)
B(3,0,-7,STONE)
B(3,0,-6,STONE)
B(3,0,-5,STONE)
B(3,0,-4,STONE)
B(3,0,-3,STONE)
B(3,0,-2,STONE)
B(3,0,-1,STONE)
B(3,0,0,STONE)
B(3,0,1,STONE)
B(3,0,2,STONE)
B(3,0,3,STONE)
B(3,0,4,STONE)
B(3,0,5,STONE)
B(3,0,6,STONE)
B(3,0,7,STONE)
B(3,0,8,STONE)
B(3,0,9,STONE)
B(3,0,10,STONE)
B(3,0,11,STONE)
B(3,0,12,STONE)
B(3,0,13,STONE)
B(3,0,14,STONE)
B(3,0,15,STONE)
B(3,1,-13,STONE)
B(3,1,-12,STONE)
B(3,1,-11,STONE)
B(3,1,-10,STONE)
B(3,1,-9,STONE)
B(3,1,-8,STONE)
B(3,1,-7,STONE)
B(3,1,-6,STONE)
B(3,1,-5,STONE)
B(3,1,-4,STONE)
B(3,1,-3,STONE)
B(3,1,-2,STONE)
B(3,1,-1,STONE)
B(3,1,0,STONE)
B(3,1,1,STONE)
B(3,1,2,STONE)
B(3,1,3,STONE)
B(3,1,4,STONE)
B(3,1,5,STONE)
B(3,1,6,STONE)
B(3,1,7,STONE)
B(3,1,8,STONE)
B(3,1,9,STONE)
B(3,1,10,STONE)
B(3,1,11,STONE)
B(3,1,12,STONE)
B(3,1,13,STONE)
B(3,1,14,STONE)
B(3,2,-11,STONE)
B(3,2,-10,STONE)
B(3,2,-9,STONE)
B(3,2,-8,STONE)
B(3,2,-7,STONE)
B(3,2,-6,STONE)
B(3,2,-5,STONE)
B(3,2,-4,STONE)
B(3,2,-3,STONE)
B(3,2,-2,STONE)
B(3,2,-1,STONE)
B(3,2,0,STONE)
B(3,2,1,STONE)
B(3,2,2,STONE)
B(3,2,3,STONE)
B(3,2,4,STONE)
B(3,2,5,STONE)
B(3,2,6,STONE)
B(3,2,7,STONE)
B(3,2,8,STONE)
B(3,2,9,STONE)
B(3,2,10,STONE)
B(3,2,11,STONE)
B(3,2,12,STONE)
B(3,3,-10,STONE)
B(3,3,-9,STONE)
B(3,3,-8,STONE)
B(3,3,-7,STONE)
B(3,3,-6,STONE)
B(3,3,-5,STONE)
B(3,3,-4,STONE)
B(3,3,-3,STONE)
B(3,3,-2,STONE)
B(3,3,-1,STONE)
B(3,3,0,STONE)
B(3,3,1,STONE)
B(3,3,2,STONE)
B(3,3,3,STONE)
B(3,3,4,STONE)
B(3,3,5,STONE)
B(3,3,6,STONE)
B(3,3,7,STONE)
B(3,3,8,STONE)
B(3,3,9,STONE)
B(3,3,10,STONE)
B(3,3,11,STONE)
B(3,4,-10,STONE)
B(3,4,-9,STONE)
B(3,4,-8,STONE)
B(3,4,-7,STONE)
B(3,4,-6,STONE)
B(3,4,-5,STONE)
B(3,4,-4,STONE)
B(3,4,-3,STONE)
B(3,4,-2,STONE)
B(3,4,-1,STONE)
B(3,4,0,STONE)
B(3,4,1,STONE)
B(3,4,2,STONE)
B(3,4,3,STONE)
B(3,4,4,STONE)
B(3,4,5,STONE)
B(3,4,6,STONE)
B(3,4,7,STONE)
B(3,4,8,STONE)
B(3,4,9,STONE)
B(3,4,10,STONE)
B(3,4,11,STONE)
B(3,5,-9,STONE)
B(3,5,-8,STONE)
B(3,5,-7,STONE)
B(3,5,-6,STONE)
B(3,5,-5,STONE)
B(3,5,-4,STONE)
B(3,5,-3,STONE)
B(3,5,-2,LAVA)
B(3,5,-1,LAVA)
B(3,5,0,STONE)
B(3,5,1,STONE)
B(3,5,2,STONE)
B(3,5,3,STONE)
B(3,5,4,STONE)
B(3,5,5,STONE)
B(3,5,6,STONE)
B(3,5,7,STONE)
B(3,5,8,STONE)
B(3,5,9,STONE)
B(3,5,10,STONE)
B(3,6,-9,STONE)
B(3,6,-8,STONE)
B(3,6,-7,STONE)
B(3,6,-6,STONE)
B(3,6,-5,STONE)
B(3,6,-4,STONE)
B(3,6,-3,LAVA)
B(3,6,-2,LAVA)
B(3,6,-1,LAVA)
B(3,6,0,LAVA)
B(3,6,1,LAVA)
B(3,6,2,STONE)
B(3,6,3,STONE)
B(3,6,4,STONE)
B(3,6,5,STONE)
B(3,6,6,STONE)
B(3,6,7,STONE)
B(3,6,8,STONE)
B(3,6,9,STONE)
B(3,7,-8,STONE)
B(3,7,-7,STONE)
B(3,7,-6,STONE)
B(3,7,-5,STONE)
B(3,7,-4,LAVA)
B(3,7,-3,LAVA)
B(3,7,-2,LAVA)
B(3,7,-1,LAVA)
B(3,7,0,LAVA)
B(3,7,1,LAVA)
B(3,7,2,STONE)
B(3,7,3,STONE)
B(3,7,4,STONE)
B(3,7,5,STONE)
B(3,7,6,STONE)
B(3,7,7,STONE)
B(3,7,8,STONE)
B(3,8,-8,STONE)
B(3,8,-7,STONE)
B(3,8,-6,STONE)
B(3,8,-5,STONE)
B(3,8,-4,LAVA)
B(3,8,-3,LAVA)
B(3,8,-2,LAVA)
B(3,8,-1,LAVA)
B(3,8,0,LAVA)
B(3,8,1,LAVA)
B(3,8,2,LAVA)
B(3,8,3,STONE)
B(3,8,4,STONE)
B(3,8,5,STONE)
B(3,8,6,STONE)
B(3,8,7,STONE)
B(3,8,8,STONE)
B(3,9,-7,STONE)
B(3,9,-6,STONE)
B(3,9,-5,LAVA)
B(3,9,-4,LAVA)
B(3,9,-3,LAVA)
B(3,9,-2,LAVA)
B(3,9,-1,LAVA)
B(3,9,0,LAVA)
B(3,9,1,LAVA)
B(3,9,2,LAVA)
B(3,9,3,LAVA)
B(3,9,4,STONE)
B(3,9,5,STONE)
B(3,9,6,STONE)
B(3,9,7,STONE)
B(3,10,-7,STONE)
B(3,10,-6,STONE)
B(3,10,4,STONE)
B(3,10,5,STONE)
B(3,10,6,STONE)
B(3,11,-6,STONE)
B(3,11,4,STONE)
B(3,11,5,STONE)
B(4,-12,-8,STONE)
B(4,-12,-7,STONE)
B(4,-12,-6,STONE)
B(4,-12,-5,STONE)
B(4,-12,-4,STONE)
B(4,-12,-3,STONE)
B(4,-12,-2,STONE)
B(4,-12,-1,STONE)
B(4,-12,0,STONE)
B(4,-12,1,STONE)
B(4,-12,2,STONE)
B(4,-12,3,STONE)
B(4,-12,4,STONE)
B(4,-12,5,STONE)
B(4,-12,6,STONE)
B(4,-12,7,STONE)
B(4,-11,-8,STONE)
B(4,-11,-7,STONE)
B(4,-11,-6,STONE)
B(4,-11,-5,STONE)
B(4,-11,-4,STONE)
B(4,-11,-3,STONE)
B(4,-11,-2,STONE)
B(4,-11,-1,STONE)
B(4,-11,0,STONE)
B(4,-11,1,STONE)
B(4,-11,2,STONE)
B(4,-11,3,STONE)
B(4,-11,4,STONE)
B(4,-11,5,STONE)
B(4,-11,6,STONE)
B(4,-11,7,STONE)
B(4,-11,8,STONE)
B(4,-10,-8,STONE)
B(4,-10,-7,STONE)
B(4,-10,-6,STONE)
B(4,-10,-5,STONE)
B(4,-10,-4,STONE)
B(4,-10,-3,STONE)
B(4,-10,-2,STONE)
B(4,-10,-1,STONE)
B(4,-10,0,STONE)
B(4,-10,1,STONE)
B(4,-10,2,STONE)
B(4,-10,3,STONE)
B(4,-10,4,STONE)
B(4,-10,5,STONE)
B(4,-10,6,STONE)
B(4,-10,7,STONE)
B(4,-10,8,STONE)
B(4,-9,-9,STONE)
B(4,-9,-8,STONE)
B(4,-9,-7,STONE)
B(4,-9,-6,STONE)
B(4,-9,-5,STONE)
B(4,-9,-4,STONE)
B(4,-9,-3,STONE)
B(4,-9,-2,STONE)
B(4,-9,-1,STONE)
B(4,-9,0,STONE)
B(4,-9,1,STONE)
B(4,-9,2,STONE)
B(4,-9,3,STONE)
B(4,-9,4,STONE)
B(4,-9,5,STONE)
B(4,-9,6,STONE)
B(4,-9,7,STONE)
B(4,-9,8,STONE)
B(4,-9,9,STONE)
B(4,-8,-9,STONE)
B(4,-8,-8,STONE)
B(4,-8,-7,STONE)
B(4,-8,-6,STONE)
B(4,-8,-5,STONE)
B(4,-8,-4,STONE)
B(4,-8,-3,STONE)
B(4,-8,-2,STONE)
B(4,-8,-1,STONE)
B(4,-8,0,STONE)
B(4,-8,1,STONE)
B(4,-8,2,STONE)
B(4,-8,3,STONE)
B(4,-8,4,STONE)
B(4,-8,5,STONE)
B(4,-8,6,STONE)
B(4,-8,7,STONE)
B(4,-8,8,STONE)
B(4,-8,9,STONE)
B(4,-8,10,STONE)
B(4,-7,-10,STONE)
B(4,-7,-9,STONE)
B(4,-7,-8,STONE)
B(4,-7,-7,STONE)
B(4,-7,-6,STONE)
B(4,-7,-5,STONE)
B(4,-7,-4,STONE)
B(4,-7,-3,STONE)
B(4,-7,-2,STONE)
B(4,-7,-1,STONE)
B(4,-7,0,STONE)
B(4,-7,1,STONE)
B(4,-7,2,STONE)
B(4,-7,3,STONE)
B(4,-7,4,STONE)
B(4,-7,5,STONE)
B(4,-7,6,STONE)
B(4,-7,7,STONE)
B(4,-7,8,STONE)
B(4,-7,9,STONE)
B(4,-7,10,STONE)
B(4,-7,11,STONE)
B(4,-6,-10,STONE)
B(4,-6,-9,STONE)
B(4,-6,-8,STONE)
B(4,-6,-7,STONE)
B(4,-6,-6,STONE)
B(4,-6,-5,STONE)
B(4,-6,-4,STONE)
B(4,-6,-3,STONE)
B(4,-6,-2,STONE)
B(4,-6,-1,STONE)
B(4,-6,0,STONE)
B(4,-6,1,STONE)
B(4,-6,2,STONE)
B(4,-6,3,STONE)
B(4,-6,4,STONE)
B(4,-6,5,STONE)
B(4,-6,6,STONE)
B(4,-6,7,STONE)
B(4,-6,8,STONE)
B(4,-6,9,STONE)
B(4,-6,10,STONE)
B(4,-6,11,STONE)
B(4,-5,-11,STONE)
B(4,-5,-10,STONE)
B(4,-5,-9,STONE)
B(4,-5,-8,STONE)
B(4,-5,-7,STONE)
B(4,-5,-6,STONE)
B(4,-5,-5,STONE)
B(4,-5,-4,STONE)
B(4,-5,-3,STONE)
B(4,-5,-2,STONE)
B(4,-5,-1,STONE)
B(4,-5,0,STONE)
B(4,-5,1,STONE)
B(4,-5,2,STONE)
B(4,-5,3,STONE)
B(4,-5,4,STONE)
B(4,-5,5,STONE)
B(4,-5,6,STONE)
B(4,-5,7,STONE)
B(4,-5,8,STONE)
B(4,-5,9,STONE)
B(4,-5,10,STONE)
B(4,-5,11,STONE)
B(4,-5,12,STONE)
B(4,-4,-12,STONE)
B(4,-4,-11,STONE)
B(4,-4,-10,STONE)
B(4,-4,-9,STONE)
B(4,-4,-8,STONE)
B(4,-4,-7,STONE)
B(4,-4,-5,STONE)
B(4,-4,-4,STONE)
B(4,-4,-3,STONE)
B(4,-4,-2,STONE)
B(4,-4,-1,STONE)
B(4,-4,2,STONE)
B(4,-4,3,STONE)
B(4,-4,4,STONE)
B(4,-4,5,STONE)
B(4,-4,6,STONE)
B(4,-4,7,STONE)
B(4,-4,8,STONE)
B(4,-4,9,STONE)
B(4,-4,10,STONE)
B(4,-4,11,STONE)
B(4,-4,12,STONE)
B(4,-4,13,STONE)
B(4,-4,14,STONE)
B(4,-3,-13,STONE)
B(4,-3,-12,STONE)
B(4,-3,-11,STONE)
B(4,-3,-10,STONE)
B(4,-3,-9,STONE)
B(4,-3,-8,STONE)
B(4,-3,-7,STONE)
B(4,-3,-5,STONE)
B(4,-3,-4,STONE)
B(4,-3,-3,STONE)
B(4,-3,-2,STONE)
B(4,-3,-1,STONE)
B(4,-3,2,STONE)
B(4,-3,3,STONE)
B(4,-3,4,STONE)
B(4,-3,5,STONE)
B(4,-3,6,STONE)
B(4,-3,7,STONE)
B(4,-3,8,STONE)
B(4,-3,9,STONE)
B(4,-3,10,STONE)
B(4,-3,11,STONE)
B(4,-3,12,STONE)
B(4,-3,13,STONE)
B(4,-3,14,STONE)
B(4,-3,15,STONE)
B(4,-2,-14,STONE)
B(4,-2,-13,STONE)
B(4,-2,-12,STONE)
B(4,-2,-11,STONE)
B(4,-2,-10,STONE)
B(4,-2,-9,STONE)
B(4,-2,-8,STONE)
B(4,-2,-7,STONE)
B(4,-2,-5,STONE)
B(4,-2,-4,STONE)
B(4,-2,-3,STONE)
B(4,-2,-2,STONE)
B(4,-2,-1,STONE)
B(4,-2,2,STONE)
B(4,-2,3,STONE)
B(4,-2,4,STONE)
B(4,-2,5,STONE)
B(4,-2,6,STONE)
B(4,-2,7,STONE)
B(4,-2,8,STONE)
B(4,-2,9,STONE)
B(4,-2,10,STONE)
B(4,-2,11,STONE)
B(4,-2,12,STONE)
B(4,-2,13,STONE)
B(4,-2,14,STONE)
B(4,-2,15,STONE)
B(4,-1,-14,STONE)
B(4,-1,-13,STONE)
B(4,-1,-12,STONE)
B(4,-1,-11,STONE)
B(4,-1,-10,STONE)
B(4,-1,-9,STONE)
B(4,-1,-8,STONE)
B(4,-1,-7,STONE)
B(4,-1,-5,STONE)
B(4,-1,-4,STONE)
B(4,-1,-3,STONE)
B(4,-1,-2,STONE)
B(4,-1,-1,STONE)
B(4,-1,2,STONE)
B(4,-1,3,STONE)
B(4,-1,4,STONE)
B(4,-1,5,STONE)
B(4,-1,6,STONE)
B(4,-1,7,STONE)
B(4,-1,8,STONE)
B(4,-1,9,STONE)
B(4,-1,10,STONE)
B(4,-1,11,STONE)
B(4,-1,12,STONE)
B(4,-1,13,STONE)
B(4,-1,14,STONE)
B(4,-1,15,STONE)
B(4,0,-13,STONE)
B(4,0,-12,STONE)
B(4,0,-11,STONE)
B(4,0,-10,STONE)
B(4,0,-9,STONE)
B(4,0,-8,STONE)
B(4,0,-7,STONE)
B(4,0,-5,STONE)
B(4,0,-4,STONE)
B(4,0,-3,STONE)
B(4,0,-2,STONE)
B(4,0,-1,STONE)
B(4,0,2,STONE)
B(4,0,3,STONE)
B(4,0,4,STONE)
B(4,0,5,STONE)
B(4,0,6,STONE)
B(4,0,7,STONE)
B(4,0,8,STONE)
B(4,0,9,STONE)
B(4,0,10,STONE)
B(4,0,11,STONE)
B(4,0,12,STONE)
B(4,0,13,STONE)
B(4,0,14,STONE)
B(4,0,15,STONE)
B(4,1,-12,STONE)
B(4,1,-11,STONE)
B(4,1,-10,STONE)
B(4,1,-9,STONE)
B(4,1,-8,STONE)
B(4,1,-7,STONE)
B(4,1,-5,STONE)
B(4,1,-4,STONE)
B(4,1,-3,STONE)
B(4,1,-2,STONE)
B(4,1,-1,STONE)
B(4,1,2,STONE)
B(4,1,3,STONE)
B(4,1,4,STONE)
B(4,1,5,STONE)
B(4,1,6,STONE)
B(4,1,7,STONE)
B(4,1,8,STONE)
B(4,1,9,STONE)
B(4,1,10,STONE)
B(4,1,11,STONE)
B(4,1,12,STONE)
B(4,1,13,STONE)
B(4,1,14,STONE)
B(4,2,-11,STONE)
B(4,2,-10,STONE)
B(4,2,-9,STONE)
B(4,2,-8,STONE)
B(4,2,-7,STONE)
B(4,2,-6,STONE)
B(4,2,-5,STONE)
B(4,2,-4,STONE)
B(4,2,-3,STONE)
B(4,2,-2,STONE)
B(4,2,-1,STONE)
B(4,2,0,STONE)
B(4,2,1,STONE)
B(4,2,2,STONE)
B(4,2,3,STONE)
B(4,2,4,STONE)
B(4,2,5,STONE)
B(4,2,6,STONE)
B(4,2,7,STONE)
B(4,2,8,STONE)
B(4,2,9,STONE)
B(4,2,10,STONE)
B(4,2,11,STONE)
B(4,2,12,STONE)
B(4,3,-10,STONE)
B(4,3,-9,STONE)
B(4,3,-8,STONE)
B(4,3,-7,STONE)
