[META]
version=2.0
spawnOnBlockType=12
spawnSunlight=True
spawnDarkness=True
spawnWater=False
spawnLava=False
underFill=False
randomRotation=True
dig=True
tree=False
branch=False
needsFoundation=True
rarity=3
collisionPercentage=20
spawnElevationMin=0
spawnElevationMax=200
spawnInBiome=Custom
[DATA]
1,-2,-3:24.0
1,-1,-3:24.0
0,0,-3:24.0
1,0,-3:24.0
2,0,-3:24.0
1,1,-3:24.0
1,-2,-2:24.0
0,-1,-2:24.0
1,-1,-2:24.0
2,-1,-2:24.0
-1,0,-2:24.0
0,0,-2:24.0
1,0,-2:24.0
2,0,-2:24.0
1,1,-2:24.0
1,-2,-1:24.0
-1,-1,-1:24.0
0,-1,-1:24.0
1,-1,-1:24.0
2,-1,-1:24.0
-2,0,-1:24.0
-1,0,-1:24.0
0,0,-1:24.0
1,0,-1:24.0
2,0,-1:24.0
0,1,-1:24.0
1,1,-1:24.0
0,-1,0:24.0
1,-1,0:24.0
-1,0,0:24.0
0,0,0:24.0
1,0,0:24.0
0,1,0:24.0
0,-1,1:24.0
1,-1,1:24.0
-1,0,1:24.0
0,0,1:24.0
0,1,1:24.0
0,0,2:12.0
0,1,2:24.0
