[META]
version=2.0
spawnOnBlockType=12
spawnSunlight=True
spawnDarkness=True
spawnWater=False
spawnLava=False
underFill=False
randomRotation=True
dig=True
tree=False
branch=False
needsFoundation=True
rarity=3
collisionPercentage=2
spawnElevationMin=0
spawnElevationMax=128
spawnInBiome=Custom
[DATA]
-1,-2,0:12
0,-2,0:12
1,-2,0:24.0
-2,-1,0:24.0
-1,-1,0:12
0,-1,0:24.0
1,-1,0:24.0
2,-1,0:24.0
-2,0,0:12
-1,0,0:24.0
0,0,0:24.0
1,0,0:24.0
2,0,0:24.0
3,0,0:24.0
-2,1,0:24.0
-1,1,0:24.0
0,1,0:24.0
1,1,0:24.0
2,1,0:24.0
3,1,0:24.0
-2,2,0:24.0
-1,2,0:24.0
0,2,0:24.0
1,2,0:24.0
2,2,0:24.0
3,2,0:24.0
-1,3,0:24.0
0,3,0:24.0
1,3,0:24.0
2,3,0:24.0
-4,-4,-6:24.0
-5,-3,-6:24.0
-4,-3,-6:24.0
-3,-3,-6:24.0
-5,-2,-6:24.0
-4,-2,-6:24.0
-3,-2,-6:24.0
-2,-2,-6:24.0
-4,-1,-6:24.0
-3,-1,-6:24.0
-2,-1,-6:24.0
-1,-1,-6:24.0
-1,0,-6:24.0
-4,-5,-5:24.0
-5,-4,-5:24.0
-4,-4,-5:24.0
-3,-4,-5:24.0
-5,-3,-5:24.0
-4,-3,-5:24.0
-3,-3,-5:24.0
-2,-3,-5:24.0
-1,-3,-5:24.0
-5,-2,-5:24.0
-4,-2,-5:24.0
-3,-2,-5:24.0
-2,-2,-5:24.0
-1,-2,-5:24.0
0,-2,-5:24.0
-5,-1,-5:24.0
-4,-1,-5:24.0
-3,-1,-5:24.0
-2,-1,-5:24.0
-1,-1,-5:24.0
0,-1,-5:24.0
1,-1,-5:24.0
-4,0,-5:24.0
-3,0,-5:24.0
-2,0,-5:24.0
-1,0,-5:24.0
0,0,-5:24.0
1,0,-5:24.0
-3,1,-5:24.0
-1,1,-5:24.0
0,1,-5:24.0
-4,-5,-4:24.0
-3,-5,-4:24.0
-4,-4,-4:24.0
-3,-4,-4:24.0
-2,-4,-4:24.0
-5,-3,-4:24.0
-4,-3,-4:24.0
-3,-3,-4:24.0
-2,-3,-4:24.0
-1,-3,-4:24.0
0,-3,-4:24.0
-5,-2,-4:24.0
-4,-2,-4:24.0
-3,-2,-4:24.0
-2,-2,-4:24.0
-1,-2,-4:24.0
0,-2,-4:24.0
-5,-1,-4:24.0
-4,-1,-4:24.0
-3,-1,-4:24.0
-2,-1,-4:24.0
-1,-1,-4:24.0
0,-1,-4:24.0
1,-1,-4:24.0
-4,0,-4:24.0
-3,0,-4:24.0
-2,0,-4:24.0
-1,0,-4:24.0
0,0,-4:24.0
1,0,-4:24.0
2,0,-4:24.0
-4,1,-4:24.0
-3,1,-4:24.0
-2,1,-4:24.0
-1,1,-4:24.0
0,1,-4:24.0
1,1,-4:24.0
-1,2,-4:24.0
0,2,-4:24.0
-3,-5,-3:24.0
-4,-4,-3:24.0
-3,-4,-3:24.0
-2,-4,-3:24.0
-1,-4,-3:24.0
-4,-3,-3:24.0
-3,-3,-3:24.0
-2,-3,-3:24.0
-1,-3,-3:24.0
0,-3,-3:24.0
-5,-2,-3:24.0
-4,-2,-3:24.0
-3,-2,-3:24.0
-2,-2,-3:24.0
-1,-2,-3:24.0
0,-2,-3:24.0
1,-2,-3:24.0
-5,-1,-3:24.0
-4,-1,-3:24.0
-3,-1,-3:24.0
-2,-1,-3:24.0
-1,-1,-3:24.0
0,-1,-3:24.0
1,-1,-3:24.0
-5,0,-3:24.0
-4,0,-3:24.0
-3,0,-3:24.0
-2,0,-3:24.0
-1,0,-3:24.0
0,0,-3:24.0
1,0,-3:24.0
2,0,-3:24.0
-4,1,-3:24.0
-3,1,-3:24.0
-2,1,-3:24.0
-1,1,-3:24.0
0,1,-3:24.0
1,1,-3:24.0
2,1,-3:24.0
-3,2,-3:24.0
-2,2,-3:24.0
-1,2,-3:24.0
0,2,-3:24.0
1,2,-3:24.0
-1,3,-3:24.0
-3,-4,-2:24.0
-2,-4,-2:24.0
-1,-4,-2:24.0
0,-4,-2:24.0
-3,-3,-2:24.0
-2,-3,-2:24.0
-1,-3,-2:24.0
0,-3,-2:24.0
-4,-2,-2:24.0
-3,-2,-2:24.0
-2,-2,-2:24.0
-1,-2,-2:24.0
0,-2,-2:24.0
1,-2,-2:24.0
-4,-1,-2:24.0
-3,-1,-2:24.0
-2,-1,-2:24.0
0,-1,-2:24.0
1,-1,-2:24.0
2,-1,-2:24.0
-4,0,-2:24.0
-3,0,-2:24.0
-2,0,-2:24.0
-1,0,-2:24.0
0,0,-2:24.0
1,0,-2:24.0
2,0,-2:24.0
3,0,-2:24.0
-4,1,-2:24.0
-3,1,-2:24.0
-2,1,-2:24.0
-1,1,-2:24.0
0,1,-2:24.0
1,1,-2:24.0
2,1,-2:24.0
3,1,-2:24.0
-3,2,-2:24.0
-2,2,-2:24.0
-1,2,-2:24.0
0,2,-2:24.0
1,2,-2:24.0
2,2,-2:24.0
-2,3,-2:24.0
-1,3,-2:24.0
0,3,-2:24.0
-2,-3,-1:24.0
-1,-3,-1:12
0,-3,-1:24.0
-3,-2,-1:12
-2,-2,-1:12
-1,-2,-1:24.0
0,-2,-1:24.0
1,-2,-1:24.0
-3,-1,-1:24.0
-2,-1,-1:24.0
-1,-1,-1:24.0
0,-1,-1:24.0
1,-1,-1:24.0
2,-1,-1:24.0
-3,0,-1:12
-2,0,-1:24.0
-1,0,-1:24.0
0,0,-1:24.0
1,0,-1:24.0
2,0,-1:24.0
3,0,-1:24.0
-3,1,-1:24.0
-2,1,-1:24.0
-1,1,-1:24.0
0,1,-1:24.0
1,1,-1:24.0
2,1,-1:24.0
3,1,-1:24.0
-2,2,-1:24.0
-1,2,-1:24.0
0,2,-1:24.0
1,2,-1:24.0
2,2,-1:24.0
-2,3,-1:12
-1,3,-1:24.0
0,3,-1:24.0
1,3,-1:24.0
0,-1,1:12
1,-1,1:24.0
2,-1,1:24.0
3,-1,1:24.0
-1,0,1:12
0,0,1:12
1,0,1:24.0
2,0,1:24.0
3,0,1:24.0
4,0,1:24.0
-1,1,1:24.0
0,1,1:12
1,1,1:24.0
2,1,1:24.0
3,1,1:24.0
4,1,1:24.0
-1,2,1:24.0
0,2,1:24.0
1,2,1:24.0
2,2,1:24.0
3,2,1:24.0
0,3,1:24.0
1,3,1:24.0
2,3,1:24.0
3,3,1:24.0
1,4,1:24.0
2,4,1:24.0
3,-1,2:24.0
1,0,2:24.0
2,0,2:24.0
3,0,2:24.0
4,0,2:24.0
1,1,2:12
2,1,2:24.0
3,1,2:24.0
4,1,2:24.0
5,1,2:24.0
0,2,2:24.0
1,2,2:24.0
2,2,2:24.0
3,2,2:24.0
4,2,2:24.0
5,2,2:24.0
2,3,2:24.0
3,3,2:24.0
4,3,2:24.0
2,4,2:24.0
3,4,2:24.0
2,1,3:24.0
3,1,3:24.0
4,1,3:24.0
3,2,3:24.0
4,2,3:12
5,2,3:24.0
3,3,3:24.0
4,3,3:24.0
5,3,3:24.0
