
#######################################################################
# +-----------------------------------------------------------------+ #
# |                            BO3 object                           | #
# +-----------------------------------------------------------------+ #
#######################################################################

Author: Unknown

Description: This BO3 was converted from a schematic using OTGEdit. The author and description information of the schematic could not be found. If you know who the author of the schematic is then please add this information.

Version: 3

SettingsMode: WriteWithoutComments


#######################################################################
# +-----------------------------------------------------------------+ #
# |                          Main settings                          | #
# +-----------------------------------------------------------------+ #
#######################################################################

Tree: true

Frequency: 1

Rarity: 100.0

RotateRandomly: true

SpawnHeight: highestSolidBlock

SpawnHeightOffset: 0

SpawnHeightVariance: 0

##############################
# Height Limits for the BO3. #
##############################

MinHeight: 20

MaxHeight: 255

######################
# Extrusion settings #
######################

ExtrudeMode: None

ExtrudeThroughBlocks: AIR

MaxBranchDepth: 10

ExcludedBiomes: All


#######################################################################
# +-----------------------------------------------------------------+ #
# |                      Source block settings                      | #
# +-----------------------------------------------------------------+ #
#######################################################################

SourceBlocks: AIR

MaxPercentageOutsideSourceBlock: 100

OutsideSourceBlock: dontPlace

DoReplaceBlocks: true

IsOTGPlus: false


#######################################################################
# +-----------------------------------------------------------------+ #
# |                              Blocks                             | #
# +-----------------------------------------------------------------+ #
#######################################################################

Block(-12,32,2,LEAVES:3)
Block(-11,32,1,LEAVES:3)
Block(-11,32,2,LEAVES:3)
Block(-11,32,3,LEAVES:3)
Block(-11,33,2,LEAVES:3)
Block(-10,30,2,LEAVES:3)
Block(-10,31,1,LEAVES:3)
Block(-10,31,2,LEAVES:3)
Block(-10,31,3,LEAVES:3)
Block(-10,32,0,LEAVES:3)
Block(-10,32,1,LEAVES:3)
Block(-10,32,2,LEAVES:3)
Block(-10,32,3,LEAVES:3)
Block(-10,32,4,LEAVES:3)
Block(-10,33,1,LEAVES:3)
Block(-10,33,2,LEAVES:3)
Block(-10,33,3,LEAVES:3)
Block(-9,30,1,LEAVES:3)
Block(-9,30,2,LEAVES:3)
Block(-9,30,3,LEAVES:3)
Block(-9,31,0,LEAVES:3)
Block(-9,31,1,LEAVES:3)
Block(-9,31,2,LEAVES:3)
Block(-9,31,3,LEAVES:3)
Block(-9,31,4,LEAVES:3)
Block(-9,32,-1,LEAVES:3)
Block(-9,32,0,LEAVES:3)
Block(-9,32,1,LEAVES:3)
Block(-9,32,2,LEAVES:3)
Block(-9,32,3,LEAVES:3)
Block(-9,32,4,LEAVES:3)
Block(-9,32,5,LEAVES:3)
Block(-9,33,0,LEAVES:3)
Block(-9,33,1,LEAVES:3)
Block(-9,33,2,LEAVES:3)
Block(-9,33,3,LEAVES:3)
Block(-9,33,4,LEAVES:3)
Block(-9,34,2,LEAVES:3)
Block(-9,34,3,LEAVES:3)
Block(-8,30,0,LEAVES:3)
Block(-8,30,1,LEAVES:3)
Block(-8,30,2,LEAVES:3)
Block(-8,31,0,LEAVES:3)
Block(-8,31,1,LEAVES:3)
Block(-8,31,2,LEAVES:3)
Block(-8,31,3,LEAVES:3)
Block(-8,31,4,LEAVES:3)
Block(-8,31,5,LEAVES:3)
Block(-8,32,-1,LEAVES:3)
Block(-8,32,0,LEAVES:3)
Block(-8,32,1,LEAVES:3)
Block(-8,32,2,LOG:15)
Block(-8,32,3,LEAVES:3)
Block(-8,32,4,LEAVES:3)
Block(-8,32,5,LEAVES:3)
Block(-8,33,-1,LEAVES:3)
Block(-8,33,0,LEAVES:3)
Block(-8,33,1,LEAVES:3)
Block(-8,33,2,LEAVES:3)
Block(-8,33,3,LEAVES:3)
Block(-8,33,4,LEAVES:3)
Block(-8,33,5,LEAVES:3)
Block(-8,34,0,LEAVES:3)
Block(-8,34,1,LEAVES:3)
Block(-8,34,2,LEAVES:3)
Block(-8,34,3,LEAVES:3)
Block(-7,15,-1,LEAVES:3)
Block(-7,16,-2,LEAVES:3)
Block(-7,16,-1,LEAVES:3)
Block(-7,16,0,LEAVES:3)
Block(-7,17,-1,LEAVES:3)
Block(-7,30,0,LEAVES:3)
Block(-7,30,1,LEAVES:3)
Block(-7,30,2,LEAVES:3)
Block(-7,30,3,LEAVES:3)
Block(-7,31,-1,LEAVES:3)
Block(-7,31,0,LEAVES:3)
Block(-7,31,1,LEAVES:3)
Block(-7,31,2,LEAVES:3)
Block(-7,31,3,LEAVES:3)
Block(-7,31,4,LEAVES:3)
Block(-7,32,-2,LEAVES:3)
Block(-7,32,-1,LEAVES:3)
Block(-7,32,0,LEAVES:3)
Block(-7,32,1,LOG:7)
Block(-7,32,2,LEAVES:3)
Block(-7,32,3,LEAVES:3)
Block(-7,32,4,LEAVES:3)
Block(-7,32,5,LEAVES:3)
Block(-7,33,-1,LEAVES:3)
Block(-7,33,0,LEAVES:3)
Block(-7,33,1,LEAVES:3)
Block(-7,33,2,LEAVES:3)
Block(-7,33,3,LEAVES:3)
Block(-7,33,4,LEAVES:3)
Block(-7,34,0,LEAVES:3)
Block(-7,34,1,LEAVES:3)
Block(-7,34,2,LEAVES:3)
Block(-7,34,3,LEAVES:3)
Block(-6,10,1,LEAVES:3)
Block(-6,15,-2,LEAVES:3)
Block(-6,15,-1,LEAVES:3)
Block(-6,15,0,LEAVES:3)
Block(-6,16,-3,LEAVES:3)
Block(-6,16,-2,LEAVES:3)
Block(-6,16,-1,LEAVES:3)
Block(-6,16,0,LEAVES:3)
Block(-6,16,1,LEAVES:3)
Block(-6,17,-2,LEAVES:3)
Block(-6,17,-1,LEAVES:3)
Block(-6,17,0,LEAVES:3)
Block(-6,18,-1,LEAVES:3)
Block(-6,30,-1,LEAVES:3)
Block(-6,30,0,LEAVES:3)
Block(-6,30,1,LEAVES:3)
Block(-6,30,2,LEAVES:3)
Block(-6,31,-1,LEAVES:3)
Block(-6,31,0,LEAVES:3)
Block(-6,31,1,LEAVES:3)
Block(-6,31,2,LEAVES:3)
Block(-6,31,3,LEAVES:3)
Block(-6,32,-3,LEAVES:3)
Block(-6,32,-2,LEAVES:3)
Block(-6,32,-1,LEAVES:3)
Block(-6,32,0,LEAVES:3)
Block(-6,32,1,LOG:7)
Block(-6,32,2,LEAVES:3)
Block(-6,32,3,LEAVES:3)
Block(-6,32,4,LEAVES:3)
Block(-6,33,-2,LEAVES:3)
Block(-6,33,-1,LEAVES:3)
Block(-6,33,0,LEAVES:3)
Block(-6,33,1,LEAVES:3)
Block(-6,33,2,LEAVES:3)
Block(-6,33,3,LEAVES:3)
Block(-6,34,-1,LEAVES:3)
Block(-6,34,0,LEAVES:3)
Block(-6,34,1,LEAVES:3)
Block(-6,34,2,LEAVES:3)
Block(-5,9,1,LEAVES:3)
Block(-5,10,0,LEAVES:3)
Block(-5,10,1,LEAVES:3)
Block(-5,10,2,LEAVES:3)
Block(-5,11,1,LEAVES:3)
Block(-5,14,-1,LEAVES:3)
Block(-5,15,-3,LEAVES:3)
Block(-5,15,-2,LEAVES:3)
Block(-5,15,-1,LEAVES:3)
Block(-5,15,0,LEAVES:3)
Block(-5,15,1,LEAVES:3)
Block(-5,16,-4,LEAVES:3)
Block(-5,16,-3,LEAVES:3)
Block(-5,16,-2,LEAVES:3)
Block(-5,16,-1,LEAVES:3)
Block(-5,16,0,LEAVES:3)
Block(-5,16,1,LEAVES:3)
Block(-5,16,2,LEAVES:3)
Block(-5,17,-3,LEAVES:3)
Block(-5,17,-2,LEAVES:3)
Block(-5,17,-1,LEAVES:3)
Block(-5,17,0,LEAVES:3)
Block(-5,17,1,LEAVES:3)
Block(-5,18,-2,LEAVES:3)
Block(-5,18,-1,LEAVES:3)
Block(-5,18,0,LEAVES:3)
Block(-5,30,0,LEAVES:3)
Block(-5,30,2,LEAVES:3)
Block(-5,31,-1,LEAVES:3)
Block(-5,31,0,LEAVES:3)
Block(-5,31,1,LEAVES:3)
Block(-5,31,2,LEAVES:3)
Block(-5,31,3,LEAVES:3)
Block(-5,32,-2,LEAVES:3)
Block(-5,32,-1,LEAVES:3)
Block(-5,32,0,LEAVES:3)
Block(-5,32,1,LEAVES:3)
Block(-5,32,2,LEAVES:3)
Block(-5,32,3,LEAVES:3)
Block(-5,32,4,LEAVES:3)
Block(-5,33,-1,LEAVES:3)
Block(-5,33,0,LEAVES:3)
Block(-5,33,1,LOG:7)
Block(-5,33,2,LEAVES:3)
Block(-5,33,3,LEAVES:3)
Block(-5,33,4,VINE:4)
Block(-5,34,-2,LEAVES:3)
Block(-5,34,-1,LEAVES:3)
Block(-5,34,0,LEAVES:3)
Block(-5,34,1,LEAVES:3)
Block(-5,34,2,LEAVES:3)
Block(-5,35,-2,VINE:9)
Block(-5,35,-1,LEAVES:3)
Block(-5,35,0,LEAVES:3)
Block(-5,35,1,LEAVES:3)
Block(-4,6,1,VINE:8)
Block(-4,6,2,VINE:8)
Block(-4,7,1,VINE:8)
Block(-4,7,2,VINE:8)
Block(-4,8,1,VINE:8)
Block(-4,8,2,VINE:8)
Block(-4,9,0,LEAVES:3)
Block(-4,9,1,LEAVES:3)
Block(-4,9,2,LEAVES:3)
Block(-4,10,-1,LEAVES:3)
Block(-4,10,0,LEAVES:3)
Block(-4,10,1,LEAVES:3)
Block(-4,10,2,LEAVES:3)
Block(-4,10,3,LEAVES:3)
Block(-4,11,0,LEAVES:3)
Block(-4,11,1,LEAVES:3)
Block(-4,11,2,LEAVES:3)
Block(-4,11,3,VINE:8)
Block(-4,12,1,LEAVES:3)
Block(-4,12,3,VINE:8)
Block(-4,13,3,VINE:8)
Block(-4,14,-3,LEAVES:3)
Block(-4,14,-2,LEAVES:3)
Block(-4,14,-1,LEAVES:3)
Block(-4,14,0,LEAVES:3)
Block(-4,14,1,LEAVES:3)
Block(-4,14,3,VINE:8)
Block(-4,15,-3,LEAVES:3)
Block(-4,15,-2,LEAVES:3)
Block(-4,15,-1,LEAVES:3)
Block(-4,15,0,LEAVES:3)
Block(-4,15,1,LEAVES:3)
Block(-4,15,2,LEAVES:3)
Block(-4,15,3,VINE:8)
Block(-4,16,-5,LEAVES:3)
Block(-4,16,-4,LEAVES:3)
Block(-4,16,-3,LEAVES:3)
Block(-4,16,-2,LEAVES:3)
Block(-4,16,-1,LOG:15)
Block(-4,16,0,LEAVES:3)
Block(-4,16,1,LEAVES:3)
Block(-4,16,2,LEAVES:3)
Block(-4,16,3,VINE:8)
Block(-4,17,-4,LEAVES:3)
Block(-4,17,-3,LEAVES:3)
Block(-4,17,-2,LEAVES:3)
Block(-4,17,-1,LEAVES:3)
Block(-4,17,0,LEAVES:3)
Block(-4,17,1,LEAVES:3)
Block(-4,17,2,LEAVES:3)
Block(-4,17,3,VINE:8)
Block(-4,18,-3,LEAVES:3)
Block(-4,18,-2,LEAVES:3)
Block(-4,18,-1,LEAVES:3)
Block(-4,18,0,LEAVES:3)
Block(-4,18,1,LEAVES:3)
Block(-4,18,2,VINE:2)
Block(-4,19,-2,LEAVES:3)
Block(-4,19,-1,VINE:8)
Block(-4,19,2,VINE:2)
Block(-4,20,2,VINE:2)
Block(-4,21,2,VINE:2)
Block(-4,22,2,VINE:2)
Block(-4,23,2,VINE:2)
Block(-4,23,4,VINE:4)
Block(-4,24,2,VINE:2)
Block(-4,24,4,VINE:4)
Block(-4,25,2,VINE:2)
Block(-4,25,4,VINE:6)
Block(-4,26,2,VINE:2)
Block(-4,26,4,VINE:6)
Block(-4,27,2,VINE:2)
Block(-4,27,4,VINE:6)
Block(-4,28,2,VINE:2)
Block(-4,28,4,VINE:6)
Block(-4,29,2,VINE:2)
Block(-4,29,4,VINE:6)
Block(-4,30,2,VINE:2)
Block(-4,30,4,VINE:6)
Block(-4,31,0,LEAVES:3)
Block(-4,31,1,LEAVES:3)
Block(-4,31,2,LEAVES:3)
Block(-4,31,4,VINE:6)
Block(-4,32,-1,LEAVES:3)
Block(-4,32,0,LEAVES:3)
Block(-4,32,1,LEAVES:3)
Block(-4,32,2,LEAVES:3)
Block(-4,32,3,LEAVES:3)
Block(-4,32,4,VINE:6)
Block(-4,33,-2,LEAVES:3)
Block(-4,33,-1,LEAVES:3)
Block(-4,33,0,LOG:7)
Block(-4,33,1,LEAVES:3)
Block(-4,33,2,LEAVES:3)
Block(-4,33,3,VINE:14)
Block(-4,34,-3,LEAVES:3)
Block(-4,34,-2,LEAVES:3)
Block(-4,34,-1,LEAVES:3)
Block(-4,34,0,LEAVES:3)
Block(-4,34,1,LEAVES:3)
Block(-4,34,2,LEAVES:3)
Block(-4,34,3,LEAVES:3)
Block(-4,35,-3,VINE:9)
Block(-4,35,-2,LEAVES:3)
Block(-4,35,-1,LEAVES:3)
Block(-4,35,0,LEAVES:3)
Block(-4,35,1,LEAVES:3)
Block(-4,35,2,LEAVES:3)
Block(-4,36,2,VINE:8)
Block(-3,6,3,VINE:4)
Block(-3,7,3,VINE:4)
Block(-3,8,0,LEAVES:3)
Block(-3,8,1,LEAVES:3)
Block(-3,8,2,LEAVES:3)
Block(-3,8,3,VINE:4)
Block(-3,9,-1,LEAVES:3)
Block(-3,9,0,LEAVES:3)
Block(-3,9,1,LEAVES:3)
Block(-3,9,2,LEAVES:3)
Block(-3,9,3,LEAVES:3)
Block(-3,10,-2,LEAVES:3)
Block(-3,10,-1,LEAVES:3)
Block(-3,10,0,LEAVES:3)
Block(-3,10,1,LEAVES:3)
Block(-3,10,2,LEAVES:3)
Block(-3,10,3,LEAVES:3)
Block(-3,10,4,LEAVES:3)
Block(-3,11,-1,LEAVES:3)
Block(-3,11,0,LEAVES:3)
Block(-3,11,1,LEAVES:3)
Block(-3,11,2,LEAVES:3)
Block(-3,11,3,LEAVES:3)
Block(-3,12,0,LEAVES:3)
Block(-3,12,1,LEAVES:3)
Block(-3,12,2,LEAVES:3)
Block(-3,14,-1,LEAVES:3)
Block(-3,15,-3,LEAVES:3)
Block(-3,15,-2,LEAVES:3)
Block(-3,15,-1,LEAVES:3)
Block(-3,15,0,LEAVES:3)
Block(-3,15,1,LEAVES:3)
Block(-3,16,-4,LEAVES:3)
Block(-3,16,-3,LEAVES:3)
Block(-3,16,-2,LEAVES:3)
Block(-3,16,-1,LEAVES:3)
Block(-3,16,0,LEAVES:3)
Block(-3,16,1,LEAVES:3)
Block(-3,16,2,LEAVES:3)
Block(-3,17,-4,LEAVES:3)
Block(-3,17,-3,LEAVES:3)
Block(-3,17,-2,LEAVES:3)
Block(-3,17,-1,LOG:7)
Block(-3,17,0,LEAVES:3)
Block(-3,17,1,LEAVES:3)
Block(-3,17,2,LEAVES:3)
Block(-3,17,3,LEAVES:3)
Block(-3,18,-4,LEAVES:3)
Block(-3,18,-3,LEAVES:3)
Block(-3,18,-2,LEAVES:3)
Block(-3,18,-1,LEAVES:3)
Block(-3,18,0,LEAVES:3)
Block(-3,18,1,LEAVES:3)
Block(-3,19,-3,LEAVES:3)
Block(-3,19,-2,LEAVES:3)
Block(-3,19,-1,LEAVES:3)
Block(-3,19,0,VINE:4)
Block(-3,19,1,LEAVES:3)
Block(-3,20,3,VINE:4)
Block(-3,21,3,VINE:4)
Block(-3,22,3,VINE:4)
Block(-3,23,3,VINE:4)
Block(-3,24,3,VINE:4)
Block(-3,25,3,VINE:4)
Block(-3,26,3,VINE:6)
Block(-3,27,3,VINE:6)
Block(-3,28,-4,VINE:1)
Block(-3,28,3,VINE:6)
Block(-3,29,-4,VINE:1)
Block(-3,29,3,VINE:6)
Block(-3,30,-4,VINE:9)
Block(-3,30,3,VINE:6)
Block(-3,31,-4,VINE:9)
Block(-3,31,1,LEAVES:3)
Block(-3,31,3,VINE:6)
Block(-3,32,-4,VINE:9)
Block(-3,32,0,LEAVES:3)
Block(-3,32,1,LEAVES:3)
Block(-3,32,2,LEAVES:3)
Block(-3,32,3,VINE:6)
Block(-3,32,4,VINE:4)
Block(-3,32,6,LEAVES:3)
Block(-3,33,-4,VINE:9)
Block(-3,33,-2,LEAVES:3)
Block(-3,33,-1,LEAVES:3)
Block(-3,33,0,LEAVES:3)
Block(-3,33,1,LEAVES:3)
Block(-3,33,2,LEAVES:3)
Block(-3,33,3,LEAVES:3)
Block(-3,33,4,VINE:12)
Block(-3,34,-4,VINE:9)
Block(-3,34,-3,LEAVES:3)
Block(-3,34,-2,LEAVES:3)
Block(-3,34,-1,LEAVES:3)
Block(-3,34,0,LOG:7)
Block(-3,34,1,LEAVES:3)
Block(-3,34,2,LEAVES:3)
Block(-3,34,3,LEAVES:3)
Block(-3,34,4,VINE:12)
Block(-3,35,-4,VINE:9)
Block(-3,35,-3,LEAVES:3)
Block(-3,35,-2,LEAVES:3)
Block(-3,35,-1,LEAVES:3)
Block(-3,35,0,LEAVES:3)
Block(-3,35,1,LEAVES:3)
Block(-3,35,2,LEAVES:3)
Block(-3,35,3,LEAVES:3)
Block(-3,35,4,VINE:4)
Block(-3,36,-2,LEAVES:3)
Block(-3,36,-1,LEAVES:3)
Block(-3,36,0,LEAVES:3)
Block(-3,36,1,VINE:12)
Block(-3,36,2,LEAVES:3)
Block(-3,36,3,VINE:4)
Block(-3,37,-1,LEAVES:3)
Block(-2,5,0,VINE:8)
Block(-2,6,0,VINE:8)
Block(-2,7,0,VINE:8)
Block(-2,8,-1,LEAVES:3)
Block(-2,8,0,VINE:8)
Block(-2,8,1,LEAVES:3)
Block(-2,8,2,LEAVES:3)
Block(-2,9,-4,VINE:1)
Block(-2,9,-1,LEAVES:3)
Block(-2,9,0,LEAVES:3)
Block(-2,9,1,LEAVES:3)
Block(-2,9,2,LEAVES:3)
Block(-2,9,3,LEAVES:3)
Block(-2,9,4,LEAVES:3)
Block(-2,10,-4,VINE:1)
Block(-2,10,-3,LEAVES:3)
Block(-2,10,-2,LEAVES:3)
Block(-2,10,-1,LEAVES:3)
Block(-2,10,0,LEAVES:3)
Block(-2,10,1,LOG:15)
Block(-2,10,2,LEAVES:3)
Block(-2,10,3,LEAVES:3)
Block(-2,10,4,LEAVES:3)
Block(-2,11,-4,VINE:1)
Block(-2,11,-3,VINE:1)
Block(-2,11,-2,LEAVES:3)
Block(-2,11,-1,LEAVES:3)
Block(-2,11,0,LEAVES:3)
Block(-2,11,1,LEAVES:3)
Block(-2,11,2,LEAVES:3)
Block(-2,11,3,LEAVES:3)
Block(-2,12,-4,VINE:1)
Block(-2,12,-1,LEAVES:3)
Block(-2,12,0,VINE:4)
Block(-2,12,1,LEAVES:3)
Block(-2,12,2,LEAVES:3)
Block(-2,12,3,LEAVES:3)
Block(-2,13,-4,VINE:1)
Block(-2,13,0,VINE:4)
Block(-2,14,-4,VINE:1)
Block(-2,14,-1,LEAVES:3)
Block(-2,14,0,VINE:4)
Block(-2,15,-4,VINE:1)
Block(-2,15,-2,LEAVES:3)
Block(-2,15,-1,LEAVES:3)
Block(-2,15,0,LEAVES:3)
Block(-2,16,-4,VINE:1)
Block(-2,16,-3,LEAVES:3)
Block(-2,16,-2,LEAVES:3)
Block(-2,16,-1,LEAVES:3)
Block(-2,16,0,LEAVES:3)
Block(-2,16,1,LEAVES:3)
Block(-2,17,-4,LEAVES:3)
Block(-2,17,-3,LEAVES:3)
Block(-2,17,-2,LEAVES:3)
Block(-2,17,-1,LOG:7)
Block(-2,17,0,LEAVES:3)
Block(-2,17,1,LEAVES:3)
Block(-2,17,2,LEAVES:3)
Block(-2,18,-4,VINE:1)
Block(-2,18,-3,LEAVES:3)
Block(-2,18,-2,LEAVES:3)
Block(-2,18,-1,LEAVES:3)
Block(-2,18,0,LEAVES:3)
Block(-2,18,1,LEAVES:3)
Block(-2,19,-2,LEAVES:3)
Block(-2,19,-1,LEAVES:3)
Block(-2,20,-1,VINE:8)
Block(-2,21,-1,VINE:8)
Block(-2,29,-5,VINE:1)
Block(-2,30,-5,VINE:1)
Block(-2,30,8,LEAVES:3)
Block(-2,31,-5,VINE:1)
Block(-2,31,6,LEAVES:3)
Block(-2,31,7,LEAVES:3)
Block(-2,31,8,LEAVES:3)
Block(-2,31,9,LEAVES:3)
Block(-2,32,-5,VINE:1)
Block(-2,32,0,LEAVES:3)
Block(-2,32,1,LEAVES:3)
Block(-2,32,5,LEAVES:3)
Block(-2,32,6,LEAVES:3)
Block(-2,32,7,LEAVES:3)
Block(-2,32,8,LEAVES:3)
Block(-2,33,-5,VINE:1)
Block(-2,33,-2,LEAVES:3)
Block(-2,33,-1,LEAVES:3)
Block(-2,33,0,LEAVES:3)
Block(-2,33,1,LEAVES:3)
Block(-2,33,2,LEAVES:3)
Block(-2,33,5,VINE:4)
Block(-2,33,6,LEAVES:3)
Block(-2,34,-5,VINE:1)
Block(-2,34,-3,LEAVES:3)
Block(-2,34,-2,LEAVES:3)
Block(-2,34,-1,LEAVES:3)
Block(-2,34,0,LOG:7)
Block(-2,34,1,LEAVES:3)
Block(-2,34,2,LEAVES:3)
Block(-2,34,3,LEAVES:3)
Block(-2,34,4,LEAVES:3)
Block(-2,34,5,VINE:4)
Block(-2,35,-5,VINE:1)
Block(-2,35,-4,LEAVES:3)
Block(-2,35,-3,LEAVES:3)
Block(-2,35,-2,LEAVES:3)
Block(-2,35,-1,LEAVES:3)
Block(-2,35,0,LEAVES:3)
Block(-2,35,1,LEAVES:3)
Block(-2,35,2,LEAVES:3)
Block(-2,35,3,LEAVES:3)
Block(-2,36,-3,LEAVES:3)
Block(-2,36,-2,LEAVES:3)
Block(-2,36,-1,LEAVES:3)
Block(-2,36,0,LEAVES:3)
Block(-2,36,1,LEAVES:3)
Block(-2,36,2,LEAVES:3)
Block(-2,36,3,VINE:12)
Block(-2,37,-2,LEAVES:3)
Block(-2,37,-1,LEAVES:3)
Block(-2,37,0,LEAVES:3)
Block(-1,0,-1,LOG:3)
Block(-1,0,0,LOG:3)
Block(-1,1,-1,LOG:3)
Block(-1,1,0,LOG:3)
Block(-1,2,-1,LOG:3)
Block(-1,2,0,LOG:3)
Block(-1,3,-1,LOG:3)
Block(-1,3,0,LOG:3)
Block(-1,4,-2,LEAVES:3)
Block(-1,4,-1,LOG:3)
Block(-1,4,0,LOG:3)
Block(-1,5,-3,LEAVES:3)
Block(-1,5,-2,LEAVES:3)
Block(-1,5,-1,LOG:3)
Block(-1,5,0,LOG:3)
Block(-1,6,-1,LOG:3)
Block(-1,6,0,LOG:3)
Block(-1,6,1,VINE:8)
Block(-1,7,-1,LOG:3)
Block(-1,7,0,LOG:3)
Block(-1,8,-1,LOG:3)
Block(-1,8,0,LOG:3)
Block(-1,8,1,LEAVES:3)
Block(-1,9,-1,LOG:3)
Block(-1,9,0,LOG:3)
Block(-1,9,1,LEAVES:3)
Block(-1,9,2,LEAVES:3)
Block(-1,9,3,LEAVES:3)
Block(-1,10,-2,LEAVES:3)
Block(-1,10,-1,LOG:3)
Block(-1,10,0,LOG:3)
Block(-1,10,1,LOG:7)
Block(-1,10,2,LEAVES:3)
Block(-1,10,3,LEAVES:3)
Block(-1,10,4,LEAVES:3)
Block(-1,11,-1,LOG:3)
Block(-1,11,0,LOG:3)
Block(-1,11,1,LEAVES:3)
Block(-1,11,2,LEAVES:3)
Block(-1,11,3,LEAVES:3)
Block(-1,12,-1,LOG:3)
Block(-1,12,0,LOG:3)
Block(-1,12,1,VINE:14)
Block(-1,12,2,LEAVES:3)
Block(-1,13,-1,LOG:3)
Block(-1,13,0,LOG:3)
Block(-1,13,1,VINE:14)
Block(-1,13,2,VINE:2)
Block(-1,14,-1,LOG:3)
Block(-1,14,0,LOG:3)
Block(-1,14,1,VINE:14)
Block(-1,14,2,VINE:2)
Block(-1,15,-1,LOG:3)
Block(-1,15,0,LOG:3)
Block(-1,15,1,VINE:14)
Block(-1,15,2,VINE:2)
Block(-1,16,-2,LEAVES:3)
Block(-1,16,-1,LOG:3)
Block(-1,16,0,LOG:3)
Block(-1,16,1,VINE:14)
Block(-1,16,2,VINE:2)
Block(-1,17,-3,LEAVES:3)
Block(-1,17,-2,LEAVES:3)
Block(-1,17,-1,LOG:3)
Block(-1,17,0,LOG:3)
Block(-1,17,1,LEAVES:3)
Block(-1,17,2,VINE:2)
Block(-1,18,-3,VINE:2)
Block(-1,18,-2,LEAVES:3)
Block(-1,18,-1,LOG:3)
Block(-1,18,0,LOG:3)
Block(-1,18,1,VINE:14)
Block(-1,19,-2,VINE:9)
Block(-1,19,-1,LOG:3)
Block(-1,19,0,LOG:3)
Block(-1,19,1,VINE:12)
Block(-1,20,-2,VINE:9)
Block(-1,20,-1,LOG:3)
Block(-1,20,0,LOG:3)
Block(-1,20,1,VINE:12)
Block(-1,21,-2,VINE:9)
Block(-1,21,-1,LOG:3)
Block(-1,21,0,LOG:3)
Block(-1,21,1,VINE:12)
Block(-1,22,-2,VINE:1)
Block(-1,22,-1,LOG:3)
Block(-1,22,0,LOG:3)
Block(-1,22,1,VINE:12)
Block(-1,23,-2,VINE:1)
Block(-1,23,-1,LOG:3)
Block(-1,23,0,LOG:3)
Block(-1,23,1,VINE:12)
Block(-1,24,-2,VINE:1)
Block(-1,24,-1,LOG:3)
Block(-1,24,0,LOG:3)
Block(-1,24,1,VINE:12)
Block(-1,25,-2,VINE:1)
Block(-1,25,-1,LOG:3)
Block(-1,25,0,LOG:3)
Block(-1,25,1,VINE:12)
Block(-1,26,-2,VINE:1)
Block(-1,26,-1,LOG:3)
Block(-1,26,0,LOG:3)
Block(-1,26,1,VINE:12)
Block(-1,27,-2,VINE:1)
Block(-1,27,-1,LOG:3)
Block(-1,27,0,LOG:3)
Block(-1,28,-2,VINE:1)
Block(-1,28,-1,LOG:3)
Block(-1,28,0,LOG:3)
Block(-1,29,-2,VINE:1)
Block(-1,29,-1,LOG:3)
Block(-1,29,0,LOG:3)
Block(-1,30,-2,VINE:1)
Block(-1,30,-1,LOG:3)
Block(-1,30,0,LOG:3)
Block(-1,30,7,LEAVES:3)
Block(-1,30,8,LEAVES:3)
Block(-1,30,9,LEAVES:3)
Block(-1,31,-2,VINE:1)
Block(-1,31,-1,LOG:3)
Block(-1,31,0,LOG:3)
Block(-1,31,5,LEAVES:3)
Block(-1,31,6,LEAVES:3)
Block(-1,31,7,LEAVES:3)
Block(-1,31,8,LEAVES:3)
Block(-1,31,9,LEAVES:3)
Block(-1,31,10,LEAVES:3)
Block(-1,32,-6,LEAVES:3)
Block(-1,32,-2,VINE:1)
Block(-1,32,-1,LOG:3)
Block(-1,32,0,LOG:3)
Block(-1,32,4,LEAVES:3)
Block(-1,32,5,LEAVES:3)
Block(-1,32,6,LEAVES:3)
Block(-1,32,7,LEAVES:3)
Block(-1,32,8,LEAVES:3)
Block(-1,32,9,LEAVES:3)
Block(-1,33,-3,LEAVES:3)
Block(-1,33,-2,LEAVES:3)
Block(-1,33,-1,LOG:3)
Block(-1,33,0,LOG:3)
Block(-1,33,1,LEAVES:3)
Block(-1,33,2,LEAVES:3)
Block(-1,33,3,LEAVES:3)
Block(-1,33,4,LEAVES:3)
Block(-1,33,5,LEAVES:3)
Block(-1,33,6,LEAVES:3)
Block(-1,33,7,LEAVES:3)
Block(-1,33,8,LEAVES:3)
Block(-1,34,-5,LEAVES:3)
Block(-1,34,-4,LEAVES:3)
Block(-1,34,-3,LEAVES:3)
Block(-1,34,-2,LEAVES:3)
Block(-1,34,-1,LOG:3)
Block(-1,34,0,LOG:3)
Block(-1,34,1,LEAVES:3)
Block(-1,34,2,LEAVES:3)
Block(-1,34,3,LEAVES:3)
Block(-1,34,4,LEAVES:3)
Block(-1,34,5,LEAVES:3)
Block(-1,35,-4,LEAVES:3)
Block(-1,35,-3,LEAVES:3)
Block(-1,35,-2,LEAVES:3)
Block(-1,35,-1,LOG:15)
Block(-1,35,0,LOG:7)
Block(-1,35,1,LEAVES:3)
Block(-1,35,2,LEAVES:3)
Block(-1,35,3,LEAVES:3)
Block(-1,35,4,LEAVES:3)
Block(-1,36,-4,LEAVES:3)
Block(-1,36,-3,LEAVES:3)
Block(-1,36,-2,LEAVES:3)
Block(-1,36,-1,LEAVES:3)
Block(-1,36,0,LEAVES:3)
Block(-1,36,1,LEAVES:3)
Block(-1,36,2,LEAVES:3)
Block(-1,36,3,LEAVES:3)
Block(-1,36,4,VINE:4)
Block(-1,37,-2,LEAVES:3)
Block(-1,37,-1,LEAVES:3)
Block(-1,37,0,LEAVES:3)
Block(-1,37,1,LEAVES:3)
Block(0,0,-2,LOG:3)
Block(0,0,-1,LOG:3)
Block(0,0,0,LOG:3)
Block(0,0,1,LOG:3)
Block(0,1,-2,LOG:3)
Block(0,1,-1,LOG:3)
Block(0,1,0,LOG:3)
Block(0,1,1,LOG:3)
Block(0,2,-2,LOG:3)
Block(0,2,-1,LOG:3)
Block(0,2,0,LOG:3)
Block(0,2,1,LOG:3)
Block(0,3,-2,LOG:3)
Block(0,3,-1,LOG:3)
Block(0,3,0,LOG:3)
Block(0,3,1,LOG:3)
Block(0,4,-3,LEAVES:3)
Block(0,4,-2,LOG:3)
Block(0,4,-1,LOG:3)
Block(0,4,0,LOG:3)
Block(0,4,1,LOG:3)
Block(0,5,-4,LEAVES:3)
Block(0,5,-3,LEAVES:3)
Block(0,5,-2,LOG:3)
Block(0,5,-1,LOG:3)
Block(0,5,0,LOG:3)
Block(0,5,1,LOG:3)
Block(0,6,-3,LEAVES:3)
Block(0,6,-2,LOG:3)
Block(0,6,-1,LOG:3)
Block(0,6,0,LOG:3)
Block(0,6,1,LOG:3)
Block(0,6,2,VINE:4)
Block(0,7,-3,VINE:9)
Block(0,7,-2,LOG:3)
Block(0,7,-1,LOG:3)
Block(0,7,0,LOG:3)
Block(0,7,1,LOG:3)
Block(0,7,2,VINE:8)
Block(0,8,-3,VINE:1)
Block(0,8,-2,LOG:3)
Block(0,8,-1,LOG:3)
Block(0,8,0,LOG:3)
Block(0,8,1,LOG:3)
Block(0,8,2,LEAVES:3)
Block(0,9,-3,VINE:1)
Block(0,9,-2,LOG:3)
Block(0,9,-1,LOG:3)
Block(0,9,0,LOG:3)
Block(0,9,1,LOG:3)
Block(0,9,2,LEAVES:3)
Block(0,10,-3,VINE:1)
Block(0,10,-2,LOG:3)
Block(0,10,-1,LOG:3)
Block(0,10,0,LOG:3)
Block(0,10,1,LOG:3)
Block(0,10,2,LEAVES:3)
Block(0,10,3,LEAVES:3)
Block(0,11,-3,VINE:1)
Block(0,11,-2,LOG:3)
Block(0,11,-1,LOG:3)
Block(0,11,0,LOG:3)
Block(0,11,1,LOG:3)
Block(0,11,2,LEAVES:3)
Block(0,11,3,VINE:2)
Block(0,12,-3,VINE:1)
Block(0,12,-2,LOG:3)
Block(0,12,-1,LOG:3)
Block(0,12,0,LOG:3)
Block(0,12,1,LOG:3)
Block(0,12,2,VINE:4)
Block(0,13,-3,VINE:1)
Block(0,13,-2,LOG:3)
Block(0,13,-1,LOG:3)
Block(0,13,0,LOG:3)
Block(0,13,1,LOG:3)
Block(0,13,2,VINE:4)
Block(0,14,-3,VINE:1)
Block(0,14,-2,LOG:3)
Block(0,14,-1,LOG:3)
Block(0,14,0,LOG:3)
Block(0,14,1,LOG:3)
Block(0,14,2,VINE:4)
Block(0,15,-3,VINE:1)
Block(0,15,-2,LOG:3)
Block(0,15,-1,LOG:3)
Block(0,15,0,LOG:3)
Block(0,15,1,LOG:3)
Block(0,15,2,VINE:4)
Block(0,16,-3,VINE:1)
Block(0,16,-2,LOG:3)
Block(0,16,-1,LOG:3)
Block(0,16,0,LOG:3)
Block(0,16,1,LOG:3)
Block(0,16,2,VINE:4)
Block(0,17,-3,VINE:1)
Block(0,17,-2,LOG:3)
Block(0,17,-1,LOG:3)
Block(0,17,0,LOG:3)
Block(0,17,1,LOG:3)
Block(0,17,2,VINE:4)
Block(0,18,-3,VINE:1)
Block(0,18,-2,LOG:3)
Block(0,18,-1,LOG:3)
Block(0,18,0,LOG:3)
Block(0,18,1,LOG:3)
Block(0,19,-3,VINE:1)
Block(0,19,-2,LOG:3)
Block(0,19,-1,LOG:3)
Block(0,19,0,LOG:3)
Block(0,19,1,LOG:3)
Block(0,20,-3,VINE:1)
Block(0,20,-2,LOG:3)
Block(0,20,-1,LOG:3)
Block(0,20,0,LOG:3)
Block(0,20,1,LOG:3)
Block(0,21,-5,VINE:8)
Block(0,21,-3,VINE:1)
Block(0,21,-2,LOG:3)
Block(0,21,-1,LOG:3)
Block(0,21,0,LOG:3)
Block(0,21,1,LOG:3)
Block(0,22,-5,VINE:8)
Block(0,22,-3,VINE:1)
Block(0,22,-2,LOG:3)
Block(0,22,-1,LOG:3)
Block(0,22,0,LOG:3)
Block(0,22,1,LOG:3)
Block(0,23,-5,VINE:8)
Block(0,23,-3,VINE:13)
Block(0,23,-2,LOG:3)
Block(0,23,-1,LOG:3)
Block(0,23,0,LOG:3)
Block(0,23,1,LOG:3)
Block(0,24,-5,VINE:8)
Block(0,24,-3,VINE:13)
Block(0,24,-2,LOG:3)
Block(0,24,-1,LOG:3)
Block(0,24,0,LOG:3)
Block(0,24,1,LOG:3)
Block(0,25,-5,VINE:8)
Block(0,25,-3,VINE:13)
Block(0,25,-2,LOG:3)
Block(0,25,-1,LOG:3)
Block(0,25,0,LOG:3)
Block(0,25,1,LOG:3)
Block(0,26,-5,VINE:8)
Block(0,26,-3,VINE:13)
Block(0,26,-2,LOG:3)
Block(0,26,-1,LOG:3)
Block(0,26,0,LOG:3)
Block(0,26,1,LOG:3)
Block(0,27,-5,VINE:8)
Block(0,27,-3,VINE:13)
Block(0,27,-2,LOG:3)
Block(0,27,-1,LOG:3)
Block(0,27,0,LOG:3)
Block(0,27,1,LOG:3)
Block(0,28,-5,VINE:8)
Block(0,28,-3,VINE:13)
Block(0,28,-2,LOG:3)
Block(0,28,-1,LOG:3)
Block(0,28,0,LOG:3)
Block(0,28,1,LOG:3)
Block(0,29,-5,VINE:8)
Block(0,29,-3,VINE:13)
Block(0,29,-2,LOG:3)
Block(0,29,-1,LOG:3)
Block(0,29,0,LOG:3)
Block(0,29,1,LOG:3)
Block(0,30,-5,VINE:8)
Block(0,30,-3,VINE:13)
Block(0,30,-2,LOG:3)
Block(0,30,-1,LOG:3)
Block(0,30,0,LOG:3)
Block(0,30,1,LOG:3)
Block(0,30,6,LEAVES:3)
Block(0,30,7,LEAVES:3)
Block(0,30,8,LEAVES:3)
Block(0,30,9,LEAVES:3)
Block(0,30,10,LEAVES:3)
Block(0,31,-8,LEAVES:3)
Block(0,31,-5,VINE:8)
Block(0,31,-3,VINE:13)
Block(0,31,-2,LOG:3)
Block(0,31,-1,LOG:3)
Block(0,31,0,LOG:3)
Block(0,31,1,LOG:3)
Block(0,31,4,LEAVES:3)
Block(0,31,5,LEAVES:3)
Block(0,31,6,LEAVES:3)
Block(0,31,7,LEAVES:3)
Block(0,31,8,LEAVES:3)
Block(0,31,9,LEAVES:3)
Block(0,31,10,LEAVES:3)
Block(0,31,11,LEAVES:3)
Block(0,32,-7,LEAVES:3)
Block(0,32,-6,LEAVES:3)
Block(0,32,-5,LEAVES:3)
Block(0,32,-4,LEAVES:3)
Block(0,32,-3,VINE:12)
Block(0,32,-2,LOG:3)
Block(0,32,-1,LOG:3)
Block(0,32,0,LOG:3)
Block(0,32,1,LOG:3)
Block(0,32,3,LEAVES:3)
Block(0,32,4,LEAVES:3)
Block(0,32,5,LEAVES:3)
Block(0,32,6,LEAVES:3)
Block(0,32,7,LEAVES:3)
Block(0,32,8,LEAVES:3)
Block(0,32,9,LEAVES:3)
Block(0,32,10,LEAVES:3)
Block(0,33,-6,LEAVES:3)
Block(0,33,-5,LEAVES:3)
Block(0,33,-4,LEAVES:3)
Block(0,33,-3,LEAVES:3)
Block(0,33,-2,LOG:3)
Block(0,33,-1,LOG:3)
Block(0,33,0,LOG:3)
Block(0,33,1,LOG:3)
Block(0,33,2,LEAVES:3)
Block(0,33,3,LEAVES:3)
Block(0,33,4,LEAVES:3)
Block(0,33,5,LEAVES:3)
Block(0,33,6,LEAVES:3)
Block(0,33,7,LEAVES:3)
Block(0,33,8,LEAVES:3)
Block(0,34,-6,LEAVES:3)
Block(0,34,-5,LEAVES:3)
Block(0,34,-4,LEAVES:3)
Block(0,34,-3,LEAVES:3)
Block(0,34,-2,LOG:3)
Block(0,34,-1,LOG:3)
Block(0,34,0,LOG:3)
Block(0,34,1,LOG:3)
Block(0,34,2,LOG:11)
Block(0,34,3,LEAVES:3)
Block(0,34,4,LEAVES:3)
Block(0,34,5,LEAVES:3)
Block(0,34,6,LEAVES:3)
Block(0,35,-5,LEAVES:3)
Block(0,35,-4,LEAVES:3)
Block(0,35,-3,LEAVES:3)
Block(0,35,-2,LOG:15)
Block(0,35,-1,LOG:7)
Block(0,35,0,LOG:11)
Block(0,35,1,LOG:11)
Block(0,35,2,LEAVES:3)
Block(0,35,3,LEAVES:3)
Block(0,35,4,LEAVES:3)
Block(0,35,5,LEAVES:3)
Block(0,36,-4,LEAVES:3)
Block(0,36,-3,LEAVES:3)
Block(0,36,-2,LEAVES:3)
Block(0,36,-1,LEAVES:3)
Block(0,36,0,LEAVES:3)
Block(0,36,1,LEAVES:3)
Block(0,36,2,LEAVES:3)
Block(0,36,3,LEAVES:3)
Block(0,37,-3,LEAVES:3)
Block(0,37,-2,LEAVES:3)
Block(0,37,-1,LEAVES:3)
Block(0,37,0,LEAVES:3)
Block(0,37,1,LEAVES:3)
Block(0,37,2,LEAVES:3)
Block(1,0,-2,LOG:3)
Block(1,0,-1,LOG:3)
Block(1,0,0,LOG:3)
Block(1,0,1,LOG:3)
Block(1,1,-2,LOG:3)
Block(1,1,-1,LOG:3)
Block(1,1,0,LOG:3)
Block(1,1,1,LOG:3)
Block(1,2,-2,LOG:3)
Block(1,2,-1,LOG:3)
Block(1,2,0,LOG:3)
Block(1,2,1,LOG:3)
Block(1,3,-3,LEAVES:3)
Block(1,3,-2,LOG:3)
Block(1,3,-1,LOG:3)
Block(1,3,0,LOG:3)
Block(1,3,1,LOG:3)
Block(1,4,-4,LEAVES:3)
Block(1,4,-3,LEAVES:3)
Block(1,4,-2,LOG:3)
Block(1,4,-1,LOG:3)
Block(1,4,0,LOG:3)
Block(1,4,1,LOG:3)
Block(1,5,-5,LEAVES:3)
Block(1,5,-4,LEAVES:3)
Block(1,5,-3,LEAVES:3)
Block(1,5,-2,LOG:3)
Block(1,5,-1,LOG:3)
Block(1,5,0,LOG:3)
Block(1,5,1,LOG:3)
Block(1,6,-4,LEAVES:3)
Block(1,6,-3,LEAVES:3)
Block(1,6,-2,LOG:3)
Block(1,6,-1,LOG:3)
Block(1,6,0,LOG:3)
Block(1,6,1,LOG:3)
Block(1,6,2,VINE:4)
Block(1,7,-4,VINE:8)
Block(1,7,-3,LEAVES:3)
Block(1,7,-2,LOG:3)
Block(1,7,-1,LOG:3)
Block(1,7,0,LOG:3)
Block(1,7,1,LOG:3)
Block(1,7,2,LEAVES:3)
Block(1,8,-3,VINE:1)
Block(1,8,-2,LOG:3)
Block(1,8,-1,LOG:3)
Block(1,8,0,LOG:3)
Block(1,8,1,LOG:3)
Block(1,8,2,LEAVES:3)
Block(1,8,3,LEAVES:3)
Block(1,9,-3,VINE:1)
Block(1,9,-2,LOG:3)
Block(1,9,-1,LOG:3)
Block(1,9,0,LOG:3)
Block(1,9,1,LOG:3)
Block(1,9,2,LEAVES:3)
Block(1,9,3,VINE:12)
Block(1,10,-3,VINE:1)
Block(1,10,-2,LOG:3)
Block(1,10,-1,LOG:3)
Block(1,10,0,LOG:3)
Block(1,10,1,LOG:3)
Block(1,10,2,LEAVES:3)
Block(1,10,3,VINE:4)
Block(1,11,-3,VINE:1)
Block(1,11,-2,LOG:3)
Block(1,11,-1,LOG:3)
Block(1,11,0,LOG:3)
Block(1,11,1,LOG:3)
Block(1,11,2,VINE:6)
Block(1,12,-3,VINE:1)
Block(1,12,-2,LOG:3)
Block(1,12,-1,LOG:3)
Block(1,12,0,LOG:3)
Block(1,12,1,LOG:3)
Block(1,12,2,VINE:4)
Block(1,13,-3,VINE:1)
Block(1,13,-2,LOG:3)
Block(1,13,-1,LOG:3)
Block(1,13,0,LOG:3)
Block(1,13,1,LOG:3)
Block(1,13,2,VINE:4)
Block(1,14,-4,VINE:8)
Block(1,14,-3,VINE:1)
Block(1,14,-2,LOG:3)
Block(1,14,-1,LOG:3)
Block(1,14,0,LOG:3)
Block(1,14,1,LOG:3)
Block(1,14,2,VINE:4)
Block(1,15,-4,VINE:8)
Block(1,15,-3,VINE:1)
Block(1,15,-2,LOG:3)
Block(1,15,-1,LOG:3)
Block(1,15,0,LOG:3)
Block(1,15,1,LOG:3)
Block(1,15,2,VINE:4)
Block(1,16,-4,VINE:8)
Block(1,16,-3,VINE:1)
Block(1,16,-2,LOG:3)
Block(1,16,-1,LOG:3)
Block(1,16,0,LOG:3)
Block(1,16,1,LOG:3)
Block(1,16,2,VINE:4)
Block(1,17,-4,VINE:8)
Block(1,17,-3,VINE:1)
Block(1,17,-2,LOG:3)
Block(1,17,-1,LOG:3)
Block(1,17,0,LOG:3)
Block(1,17,1,LOG:3)
Block(1,17,2,VINE:4)
Block(1,18,-4,VINE:8)
Block(1,18,-3,VINE:1)
Block(1,18,-2,LOG:3)
Block(1,18,-1,LOG:3)
Block(1,18,0,LOG:3)
Block(1,18,1,LOG:3)
Block(1,18,2,VINE:4)
Block(1,19,-4,VINE:8)
Block(1,19,-3,VINE:1)
Block(1,19,-2,LOG:3)
Block(1,19,-1,LOG:3)
Block(1,19,0,LOG:3)
Block(1,19,1,LOG:3)
Block(1,19,2,VINE:4)
Block(1,20,-4,VINE:8)
Block(1,20,-3,VINE:1)
Block(1,20,-2,LOG:3)
Block(1,20,-1,LOG:3)
Block(1,20,0,LOG:3)
Block(1,20,1,LOG:3)
Block(1,20,2,VINE:4)
Block(1,21,-4,VINE:8)
Block(1,21,-2,LOG:3)
Block(1,21,-1,LOG:3)
Block(1,21,0,LOG:3)
Block(1,21,1,LOG:3)
Block(1,21,2,VINE:4)
Block(1,22,-4,VINE:8)
Block(1,22,-2,LOG:3)
Block(1,22,-1,LOG:3)
Block(1,22,0,LOG:3)
Block(1,22,1,LOG:3)
Block(1,22,2,VINE:4)
Block(1,23,-4,VINE:8)
Block(1,23,-2,LOG:3)
Block(1,23,-1,LOG:3)
Block(1,23,0,LOG:3)
Block(1,23,1,LOG:3)
Block(1,23,2,VINE:4)
Block(1,24,-4,VINE:8)
Block(1,24,-2,LOG:3)
Block(1,24,-1,LOG:3)
Block(1,24,0,LOG:3)
Block(1,24,1,LOG:3)
Block(1,24,2,VINE:4)
Block(1,25,-4,VINE:8)
Block(1,25,-2,LOG:3)
Block(1,25,-1,LOG:3)
Block(1,25,0,LOG:3)
Block(1,25,1,LOG:3)
Block(1,25,2,VINE:4)
Block(1,26,-4,VINE:8)
Block(1,26,-2,LOG:3)
Block(1,26,-1,LOG:3)
Block(1,26,0,LOG:3)
Block(1,26,1,LOG:3)
Block(1,26,2,VINE:4)
Block(1,27,-4,VINE:8)
Block(1,27,-2,LOG:3)
Block(1,27,-1,LOG:3)
Block(1,27,0,LOG:3)
Block(1,27,1,LOG:3)
Block(1,27,2,VINE:4)
Block(1,28,-4,VINE:8)
Block(1,28,-2,LOG:3)
Block(1,28,-1,LOG:3)
Block(1,28,0,LOG:3)
Block(1,28,1,LOG:3)
Block(1,28,2,VINE:4)
Block(1,29,-4,VINE:8)
Block(1,29,-2,LOG:3)
Block(1,29,-1,LOG:3)
Block(1,29,0,LOG:3)
Block(1,29,1,LOG:3)
Block(1,29,2,VINE:4)
Block(1,29,6,LEAVES:3)
Block(1,29,8,LEAVES:3)
Block(1,29,10,LEAVES:3)
Block(1,30,-6,LEAVES:3)
Block(1,30,-4,VINE:8)
Block(1,30,-2,LOG:3)
Block(1,30,-1,LOG:3)
Block(1,30,0,LOG:3)
Block(1,30,1,LOG:3)
Block(1,30,2,VINE:4)
Block(1,30,4,LEAVES:3)
Block(1,30,5,LEAVES:3)
Block(1,30,6,LEAVES:3)
Block(1,30,7,LEAVES:3)
Block(1,30,8,LEAVES:3)
Block(1,30,9,LEAVES:3)
Block(1,30,10,LEAVES:3)
Block(1,30,11,LEAVES:3)
Block(1,31,-9,LEAVES:3)
Block(1,31,-8,LEAVES:3)
Block(1,31,-7,LEAVES:3)
Block(1,31,-6,LEAVES:3)
Block(1,31,-5,LEAVES:3)
Block(1,31,-4,VINE:8)
Block(1,31,-2,LOG:3)
Block(1,31,-1,LOG:3)
Block(1,31,0,LOG:3)
Block(1,31,1,LOG:3)
Block(1,31,2,VINE:4)
Block(1,31,4,LEAVES:3)
Block(1,31,5,LEAVES:3)
Block(1,31,6,LEAVES:3)
Block(1,31,7,LEAVES:3)
Block(1,31,8,LOG:15)
Block(1,31,9,LEAVES:3)
Block(1,31,10,LEAVES:3)
Block(1,31,11,LEAVES:3)
Block(1,32,-8,LEAVES:3)
Block(1,32,-7,LEAVES:3)
Block(1,32,-6,LEAVES:3)
Block(1,32,-5,LEAVES:3)
Block(1,32,-4,LEAVES:3)
Block(1,32,-3,LEAVES:3)
Block(1,32,-2,LOG:3)
Block(1,32,-1,LOG:3)
Block(1,32,0,LOG:3)
Block(1,32,1,LOG:3)
Block(1,32,2,LEAVES:3)
Block(1,32,3,LEAVES:3)
Block(1,32,4,LEAVES:3)
Block(1,32,5,LEAVES:3)
Block(1,32,6,LOG:11)
Block(1,32,7,LOG:11)
Block(1,32,8,LEAVES:3)
Block(1,32,9,LEAVES:3)
Block(1,32,10,LEAVES:3)
Block(1,33,-7,LEAVES:3)
Block(1,33,-6,LEAVES:3)
Block(1,33,-5,LEAVES:3)
Block(1,33,-4,LEAVES:3)
Block(1,33,-3,LEAVES:3)
Block(1,33,-2,LOG:3)
Block(1,33,-1,LOG:3)
Block(1,33,0,LOG:3)
Block(1,33,1,LOG:3)
Block(1,33,2,LEAVES:3)
Block(1,33,3,LEAVES:3)
Block(1,33,4,LOG:11)
Block(1,33,5,LOG:11)
Block(1,33,6,LEAVES:3)
Block(1,33,7,LEAVES:3)
Block(1,33,8,LEAVES:3)
Block(1,33,9,LEAVES:3)
Block(1,33,10,LEAVES:3)
Block(1,34,-7,LEAVES:3)
Block(1,34,-6,LEAVES:3)
Block(1,34,-5,LEAVES:3)
Block(1,34,-4,LEAVES:3)
Block(1,34,-3,LOG:11)
Block(1,34,-2,LOG:3)
Block(1,34,-1,LOG:3)
Block(1,34,0,LOG:3)
Block(1,34,1,LOG:3)
Block(1,34,2,LOG:11)
Block(1,34,3,LOG:11)
Block(1,34,4,LEAVES:3)
Block(1,34,5,LEAVES:3)
Block(1,34,6,LEAVES:3)
Block(1,34,7,LEAVES:3)
Block(1,34,8,LEAVES:3)
Block(1,35,-6,LEAVES:3)
Block(1,35,-5,LEAVES:3)
Block(1,35,-4,LEAVES:3)
Block(1,35,-3,LEAVES:3)
Block(1,35,-2,LOG:11)
Block(1,35,-1,LOG:15)
Block(1,35,0,LOG:7)
Block(1,35,1,LOG:11)
Block(1,35,2,LEAVES:3)
Block(1,35,3,LEAVES:3)
Block(1,35,4,LEAVES:3)
Block(1,35,5,LEAVES:3)
Block(1,35,6,LEAVES:3)
Block(1,36,-6,VINE:8)
Block(1,36,-4,LEAVES:3)
Block(1,36,-3,LEAVES:3)
Block(1,36,-2,LEAVES:3)
Block(1,36,-1,LEAVES:3)
Block(1,36,0,LEAVES:3)
Block(1,36,1,LEAVES:3)
Block(1,36,2,LEAVES:3)
Block(1,36,3,LEAVES:3)
Block(1,36,4,LEAVES:3)
Block(1,37,-2,LEAVES:3)
Block(1,37,-1,LEAVES:3)
Block(1,37,0,LEAVES:3)
Block(1,37,1,LEAVES:3)
Block(1,37,2,LEAVES:3)
Block(2,0,-1,LOG:3)
Block(2,0,0,LOG:3)
Block(2,1,-1,LOG:3)
Block(2,1,0,LOG:3)
Block(2,2,-1,LOG:3)
Block(2,2,0,LOG:3)
Block(2,3,-4,LEAVES:3)
Block(2,3,-3,LEAVES:3)
Block(2,3,-2,LEAVES:3)
Block(2,3,-1,LOG:3)
Block(2,3,0,LOG:3)
Block(2,4,-4,LEAVES:3)
Block(2,4,-3,LEAVES:3)
Block(2,4,-2,LEAVES:3)
Block(2,4,-1,LOG:3)
Block(2,4,0,LOG:3)
Block(2,5,-6,LEAVES:3)
Block(2,5,-5,LEAVES:3)
Block(2,5,-4,LEAVES:3)
Block(2,5,-3,LEAVES:3)
Block(2,5,-2,LOG:15)
Block(2,5,-1,LOG:3)
Block(2,5,0,LOG:3)
Block(2,5,1,LEAVES:3)
Block(2,5,2,LEAVES:3)
Block(2,6,-5,LEAVES:3)
Block(2,6,-4,LEAVES:3)
Block(2,6,-3,LEAVES:3)
Block(2,6,-2,LEAVES:3)
Block(2,6,-1,LOG:3)
Block(2,6,0,LOG:3)
Block(2,6,1,LEAVES:3)
Block(2,6,2,LEAVES:3)
Block(2,7,-5,VINE:1)
Block(2,7,-4,LEAVES:3)
Block(2,7,-3,LEAVES:3)
Block(2,7,-2,LEAVES:3)
Block(2,7,-1,LOG:3)
Block(2,7,0,LOG:3)
Block(2,7,1,LEAVES:3)
Block(2,7,2,LEAVES:3)
Block(2,7,3,LEAVES:3)
Block(2,8,-3,LEAVES:3)
Block(2,8,-2,LEAVES:3)
Block(2,8,-1,LOG:3)
Block(2,8,0,LOG:3)
Block(2,8,1,LOG:7)
Block(2,8,2,LEAVES:3)
Block(2,8,3,LEAVES:3)
Block(2,8,4,LEAVES:3)
Block(2,9,-2,LEAVES:3)
Block(2,9,-1,LOG:3)
Block(2,9,0,LOG:3)
Block(2,9,1,LEAVES:3)
Block(2,9,2,LEAVES:3)
Block(2,9,3,LEAVES:3)
Block(2,10,-2,VINE:8)
Block(2,10,-1,LOG:3)
Block(2,10,0,LOG:3)
Block(2,10,1,LEAVES:3)
Block(2,10,2,LEAVES:3)
Block(2,10,3,VINE:8)
Block(2,11,-2,VINE:8)
Block(2,11,-1,LOG:3)
Block(2,11,0,LOG:3)
Block(2,12,-2,LEAVES:3)
Block(2,12,-1,LOG:3)
Block(2,12,0,LOG:3)
Block(2,13,-3,LEAVES:3)
Block(2,13,-2,LEAVES:3)
Block(2,13,-1,LOG:3)
Block(2,13,0,LOG:3)
Block(2,13,1,LEAVES:3)
Block(2,14,-2,LEAVES:3)
Block(2,14,-1,LOG:3)
Block(2,14,0,LOG:3)
Block(2,14,1,VINE:14)
Block(2,15,-2,VINE:2)
Block(2,15,-1,LOG:3)
Block(2,15,0,LOG:3)
Block(2,15,1,VINE:14)
Block(2,16,-2,VINE:3)
Block(2,16,-1,LOG:3)
Block(2,16,0,LOG:3)
Block(2,16,1,VINE:14)
Block(2,17,-2,VINE:3)
Block(2,17,-1,LOG:3)
Block(2,17,0,LOG:3)
Block(2,17,1,VINE:14)
Block(2,18,-2,VINE:3)
Block(2,18,-1,LOG:3)
Block(2,18,0,LOG:3)
Block(2,18,1,VINE:14)
Block(2,19,-1,LOG:3)
Block(2,19,0,LOG:3)
Block(2,19,1,VINE:14)
Block(2,20,-1,LOG:3)
Block(2,20,0,LOG:3)
Block(2,20,1,VINE:14)
Block(2,21,-1,LOG:3)
Block(2,21,0,LOG:3)
Block(2,21,1,VINE:14)
Block(2,22,-1,LOG:3)
Block(2,22,0,LOG:3)
Block(2,22,1,VINE:14)
Block(2,23,-2,LEAVES:3)
Block(2,23,-1,LOG:3)
Block(2,23,0,LOG:3)
Block(2,23,1,VINE:12)
Block(2,24,-3,LEAVES:3)
Block(2,24,-2,LEAVES:3)
Block(2,24,-1,LOG:3)
Block(2,24,0,LOG:3)
Block(2,24,1,LEAVES:3)
Block(2,25,-3,VINE:8)
Block(2,25,-2,LEAVES:3)
Block(2,25,-1,LOG:3)
Block(2,25,0,LOG:3)
Block(2,25,1,VINE:10)
Block(2,26,-3,VINE:8)
Block(2,26,-2,VINE:2)
Block(2,26,-1,LOG:3)
Block(2,26,0,LOG:3)
Block(2,26,1,VINE:2)
Block(2,27,-3,VINE:8)
Block(2,27,-2,VINE:2)
Block(2,27,-1,LOG:3)
Block(2,27,0,LOG:3)
Block(2,27,1,VINE:2)
Block(2,28,-3,VINE:8)
Block(2,28,-2,VINE:2)
Block(2,28,-1,LOG:3)
Block(2,28,0,LOG:3)
Block(2,28,1,VINE:2)
Block(2,29,-3,VINE:8)
Block(2,29,-2,VINE:2)
Block(2,29,-1,LOG:3)
Block(2,29,0,LOG:3)
Block(2,29,1,VINE:2)
Block(2,30,-9,LEAVES:3)
Block(2,30,-8,LEAVES:3)
Block(2,30,-7,LEAVES:3)
Block(2,30,-6,LEAVES:3)
Block(2,30,-5,LEAVES:3)
Block(2,30,-3,VINE:8)
Block(2,30,-2,VINE:2)
Block(2,30,-1,LOG:3)
Block(2,30,0,LOG:3)
Block(2,30,1,VINE:2)
Block(2,30,4,LEAVES:3)
Block(2,30,5,LEAVES:3)
Block(2,30,6,LEAVES:3)
Block(2,30,7,LEAVES:3)
Block(2,30,8,LEAVES:3)
Block(2,30,9,LEAVES:3)
Block(2,30,10,LEAVES:3)
Block(2,31,-10,LEAVES:3)
Block(2,31,-9,LEAVES:3)
Block(2,31,-8,LEAVES:3)
Block(2,31,-7,LEAVES:3)
Block(2,31,-6,LEAVES:3)
Block(2,31,-5,LEAVES:3)
Block(2,31,-4,LEAVES:3)
Block(2,31,-3,VINE:8)
Block(2,31,-2,VINE:2)
Block(2,31,-1,LOG:3)
Block(2,31,0,LOG:3)
Block(2,31,1,VINE:2)
Block(2,31,3,LEAVES:3)
Block(2,31,4,LEAVES:3)
Block(2,31,5,LEAVES:3)
Block(2,31,6,LEAVES:3)
Block(2,31,7,LEAVES:3)
Block(2,31,8,LEAVES:3)
Block(2,31,9,LEAVES:3)
Block(2,31,10,LEAVES:3)
Block(2,31,11,LEAVES:3)
Block(2,32,-9,LEAVES:3)
Block(2,32,-8,LEAVES:3)
Block(2,32,-7,LEAVES:3)
Block(2,32,-6,LEAVES:3)
Block(2,32,-5,LEAVES:3)
Block(2,32,-4,LEAVES:3)
Block(2,32,-3,LEAVES:3)
Block(2,32,-2,LEAVES:3)
Block(2,32,-1,LOG:3)
Block(2,32,0,LOG:3)
Block(2,32,1,VINE:2)
Block(2,32,2,LEAVES:3)
Block(2,32,3,LEAVES:3)
Block(2,32,4,LEAVES:3)
Block(2,32,5,LEAVES:3)
Block(2,32,6,LEAVES:3)
Block(2,32,7,LEAVES:3)
Block(2,32,8,LEAVES:3)
Block(2,32,9,LEAVES:3)
Block(2,32,10,LEAVES:3)
Block(2,33,-8,LEAVES:3)
Block(2,33,-7,LEAVES:3)
Block(2,33,-6,LEAVES:3)
Block(2,33,-5,LEAVES:3)
Block(2,33,-4,LEAVES:3)
Block(2,33,-3,LEAVES:3)
Block(2,33,-2,LEAVES:3)
Block(2,33,-1,LOG:3)
Block(2,33,0,LOG:3)
Block(2,33,1,LEAVES:3)
Block(2,33,2,LEAVES:3)
Block(2,33,3,LEAVES:3)
Block(2,33,4,LEAVES:3)
Block(2,33,5,LEAVES:3)
Block(2,33,6,LEAVES:3)
Block(2,33,7,LEAVES:3)
Block(2,33,8,LEAVES:3)
Block(2,33,9,LEAVES:3)
Block(2,34,-7,LEAVES:3)
Block(2,34,-6,LEAVES:3)
Block(2,34,-5,LEAVES:3)
Block(2,34,-4,LOG:11)
Block(2,34,-3,LEAVES:3)
Block(2,34,-2,LEAVES:3)
Block(2,34,-1,LOG:3)
Block(2,34,0,LOG:3)
Block(2,34,1,LOG:7)
Block(2,34,2,LEAVES:3)
Block(2,34,3,LOG:11)
Block(2,34,4,LEAVES:3)
Block(2,34,5,LEAVES:3)
Block(2,34,6,LEAVES:3)
Block(2,34,7,LEAVES:3)
Block(2,35,-7,VINE:1)
Block(2,35,-6,LEAVES:3)
Block(2,35,-5,LEAVES:3)
Block(2,35,-4,LEAVES:3)
Block(2,35,-3,LEAVES:3)
Block(2,35,-2,LEAVES:3)
Block(2,35,-1,LOG:15)
Block(2,35,0,LOG:7)
Block(2,35,1,LEAVES:3)
Block(2,35,2,LEAVES:3)
Block(2,35,3,LEAVES:3)
Block(2,35,4,LEAVES:3)
Block(2,35,5,LEAVES:3)
Block(2,35,6,LEAVES:3)
Block(2,36,-7,VINE:1)
Block(2,36,-6,LEAVES:3)
Block(2,36,-5,LEAVES:3)
Block(2,36,-4,LEAVES:3)
Block(2,36,-3,LEAVES:3)
Block(2,36,-2,LEAVES:3)
Block(2,36,-1,LEAVES:3)
Block(2,36,0,LEAVES:3)
Block(2,36,1,LEAVES:3)
Block(2,36,2,LEAVES:3)
Block(2,36,3,LEAVES:3)
Block(2,36,4,LEAVES:3)
Block(2,36,5,LEAVES:3)
Block(2,37,-2,LEAVES:3)
Block(2,37,-1,LEAVES:3)
Block(2,37,0,LEAVES:3)
Block(2,37,1,LEAVES:3)
Block(3,3,-3,LEAVES:3)
Block(3,3,-2,LEAVES:3)
Block(3,4,-4,LEAVES:3)
Block(3,4,-3,LEAVES:3)
Block(3,4,-2,LEAVES:3)
Block(3,4,-1,LEAVES:3)
Block(3,4,0,LEAVES:3)
Block(3,5,-5,LEAVES:3)
Block(3,5,-4,LEAVES:3)
Block(3,5,-3,LEAVES:3)
Block(3,5,-2,LEAVES:3)
Block(3,5,-1,LEAVES:3)
Block(3,5,0,LEAVES:3)
Block(3,5,1,LEAVES:3)
Block(3,6,-4,LEAVES:3)
Block(3,6,-3,LEAVES:3)
Block(3,6,-2,LEAVES:3)
Block(3,6,-1,LEAVES:3)
Block(3,6,0,LEAVES:3)
Block(3,6,1,LEAVES:3)
Block(3,6,2,VINE:8)
Block(3,6,3,LEAVES:3)
Block(3,7,-5,LEAVES:3)
Block(3,7,-4,LEAVES:3)
Block(3,7,-3,LEAVES:3)
Block(3,7,-2,LEAVES:3)
Block(3,7,-1,LOG:15)
Block(3,7,0,LEAVES:3)
Block(3,7,1,LEAVES:3)
Block(3,7,2,LEAVES:3)
Block(3,7,3,LEAVES:3)
Block(3,7,4,LEAVES:3)
Block(3,8,-3,LEAVES:3)
Block(3,8,-2,LEAVES:3)
Block(3,8,-1,LEAVES:3)
Block(3,8,0,LEAVES:3)
Block(3,8,1,LOG:15)
Block(3,8,2,LEAVES:3)
Block(3,8,3,LEAVES:3)
Block(3,8,4,LEAVES:3)
Block(3,9,-1,LEAVES:3)
Block(3,9,0,LEAVES:3)
Block(3,9,1,LEAVES:3)
Block(3,9,2,LEAVES:3)
Block(3,9,3,LEAVES:3)
Block(3,9,4,LEAVES:3)
Block(3,10,-1,LEAVES:3)
Block(3,10,0,VINE:2)
Block(3,10,1,LEAVES:3)
Block(3,10,2,LEAVES:3)
Block(3,10,3,LEAVES:3)
Block(3,11,-2,LEAVES:3)
Block(3,11,-1,LEAVES:3)
Block(3,11,0,LEAVES:3)
Block(3,11,3,VINE:4)
Block(3,12,-3,LEAVES:3)
Block(3,12,-2,LEAVES:3)
Block(3,12,-1,LEAVES:3)
Block(3,12,0,LEAVES:3)
Block(3,12,1,LEAVES:3)
Block(3,12,3,VINE:4)
Block(3,13,-4,LEAVES:3)
Block(3,13,-3,LEAVES:3)
Block(3,13,-2,LEAVES:3)
Block(3,13,-1,LOG:7)
Block(3,13,0,LEAVES:3)
Block(3,13,1,LEAVES:3)
Block(3,13,2,LEAVES:3)
Block(3,13,3,VINE:4)
Block(3,14,-3,LEAVES:3)
Block(3,14,-2,LEAVES:3)
Block(3,14,-1,LEAVES:3)
Block(3,14,0,LEAVES:3)
Block(3,14,1,LEAVES:3)
Block(3,14,2,VINE:4)
Block(3,14,3,VINE:4)
Block(3,15,-3,VINE:1)
Block(3,15,-1,VINE:2)
Block(3,15,1,VINE:8)
Block(3,15,3,VINE:4)
Block(3,16,-3,VINE:1)
Block(3,16,-1,VINE:2)
Block(3,16,3,VINE:4)
Block(3,17,-3,VINE:1)
Block(3,17,-1,VINE:2)
Block(3,17,3,VINE:4)
Block(3,18,-3,VINE:1)
Block(3,18,-1,VINE:2)
Block(3,18,3,VINE:4)
Block(3,19,-3,VINE:1)
Block(3,19,-1,VINE:2)
Block(3,19,3,VINE:4)
Block(3,20,-3,VINE:1)
Block(3,20,-1,VINE:2)
Block(3,20,3,VINE:4)
Block(3,21,-3,VINE:1)
Block(3,21,3,VINE:4)
Block(3,22,-3,VINE:1)
Block(3,22,-2,LEAVES:3)
Block(3,22,3,VINE:4)
Block(3,23,-3,LEAVES:3)
Block(3,23,-2,LEAVES:3)
Block(3,23,-1,LEAVES:3)
Block(3,23,0,LEAVES:3)
Block(3,23,1,LEAVES:3)
Block(3,23,3,VINE:4)
Block(3,24,-4,LEAVES:3)
Block(3,24,-3,LEAVES:3)
Block(3,24,-2,LEAVES:3)
Block(3,24,-1,LOG:7)
Block(3,24,0,LEAVES:3)
Block(3,24,1,LEAVES:3)
Block(3,24,2,LEAVES:3)
Block(3,24,3,VINE:4)
Block(3,25,-3,LEAVES:3)
Block(3,25,-2,LEAVES:3)
Block(3,25,-1,LEAVES:3)
Block(3,25,0,LEAVES:3)
Block(3,25,1,LEAVES:3)
Block(3,26,-2,LEAVES:3)
Block(3,26,-1,LEAVES:3)
Block(3,26,0,VINE:2)
Block(3,27,-1,VINE:2)
Block(3,27,0,VINE:2)
Block(3,28,-1,VINE:2)
Block(3,28,0,VINE:2)
Block(3,29,0,VINE:2)
Block(3,29,8,LEAVES:3)
Block(3,30,-10,LEAVES:3)
Block(3,30,-9,LEAVES:3)
Block(3,30,-8,LEAVES:3)
Block(3,30,-7,LEAVES:3)
Block(3,30,-6,LEAVES:3)
Block(3,30,5,LEAVES:3)
Block(3,30,6,LEAVES:3)
Block(3,30,7,LEAVES:3)
Block(3,30,8,LEAVES:3)
Block(3,30,9,LEAVES:3)
Block(3,31,-11,LEAVES:3)
Block(3,31,-10,LEAVES:3)
Block(3,31,-9,LEAVES:3)
Block(3,31,-8,LEAVES:3)
Block(3,31,-7,LEAVES:3)
Block(3,31,-6,LEAVES:3)
Block(3,31,-5,LEAVES:3)
Block(3,31,-4,LEAVES:3)
Block(3,31,-3,LEAVES:3)
Block(3,31,3,LEAVES:3)
Block(3,31,4,LEAVES:3)
Block(3,31,5,LEAVES:3)
Block(3,31,6,LEAVES:3)
Block(3,31,7,LEAVES:3)
Block(3,31,8,LEAVES:3)
Block(3,31,9,LEAVES:3)
Block(3,31,10,LEAVES:3)
Block(3,32,-10,LEAVES:3)
Block(3,32,-9,LEAVES:3)
Block(3,32,-8,LEAVES:3)
Block(3,32,-7,LEAVES:3)
Block(3,32,-6,LOG:11)
Block(3,32,-5,LEAVES:3)
Block(3,32,-4,LEAVES:3)
Block(3,32,-3,LEAVES:3)
Block(3,32,-2,LEAVES:3)
Block(3,32,0,LEAVES:3)
Block(3,32,1,LEAVES:3)
Block(3,32,2,LEAVES:3)
Block(3,32,3,LEAVES:3)
Block(3,32,4,LEAVES:3)
Block(3,32,5,LOG:11)
Block(3,32,6,LEAVES:3)
Block(3,32,7,LEAVES:3)
Block(3,32,8,LEAVES:3)
Block(3,32,9,LEAVES:3)
Block(3,32,10,LEAVES:3)
Block(3,33,-9,LEAVES:3)
Block(3,33,-8,LEAVES:3)
Block(3,33,-7,LEAVES:3)
Block(3,33,-6,LEAVES:3)
Block(3,33,-5,LOG:11)
Block(3,33,-4,LEAVES:3)
Block(3,33,-3,LEAVES:3)
Block(3,33,-2,LEAVES:3)
Block(3,33,-1,LEAVES:3)
Block(3,33,0,LEAVES:3)
Block(3,33,1,LEAVES:3)
Block(3,33,2,LEAVES:3)
Block(3,33,3,LEAVES:3)
Block(3,33,4,LOG:11)
Block(3,33,5,LEAVES:3)
Block(3,33,6,LEAVES:3)
Block(3,33,7,LEAVES:3)
Block(3,33,8,LEAVES:3)
Block(3,33,9,LEAVES:3)
Block(3,34,-7,LEAVES:3)
Block(3,34,-6,LEAVES:3)
Block(3,34,-5,LEAVES:3)
Block(3,34,-4,LEAVES:3)
Block(3,34,-3,LEAVES:3)
Block(3,34,-2,LEAVES:3)
Block(3,34,-1,LEAVES:3)
Block(3,34,0,LEAVES:3)
Block(3,34,1,LEAVES:3)
Block(3,34,2,LOG:7)
Block(3,34,3,LEAVES:3)
Block(3,34,4,LEAVES:3)
Block(3,34,5,LEAVES:3)
Block(3,34,6,LEAVES:3)
Block(3,34,7,LEAVES:3)
Block(3,35,-6,LEAVES:3)
Block(3,35,-5,LEAVES:3)
Block(3,35,-4,LEAVES:3)
Block(3,35,-3,LEAVES:3)
Block(3,35,-2,LEAVES:3)
Block(3,35,-1,LEAVES:3)
Block(3,35,0,LEAVES:3)
Block(3,35,1,LEAVES:3)
Block(3,35,2,LEAVES:3)
Block(3,35,3,LEAVES:3)
Block(3,35,4,LEAVES:3)
Block(3,35,5,LEAVES:3)
Block(3,36,-6,VINE:2)
Block(3,36,-5,VINE:2)
Block(3,36,-3,LEAVES:3)
Block(3,36,-2,LEAVES:3)
Block(3,36,-1,LEAVES:3)
Block(3,36,0,LEAVES:3)
Block(3,36,1,LEAVES:3)
Block(3,36,2,LEAVES:3)
Block(3,36,3,LEAVES:3)
Block(3,37,-2,LEAVES:3)
Block(3,37,-1,LEAVES:3)
Block(4,4,-3,LEAVES:3)
Block(4,4,-2,LEAVES:3)
Block(4,4,-1,LEAVES:3)
Block(4,5,-4,LEAVES:3)
Block(4,5,-3,LEAVES:3)
Block(4,5,-2,LEAVES:3)
Block(4,5,-1,LEAVES:3)
Block(4,5,0,LEAVES:3)
Block(4,6,-3,LEAVES:3)
Block(4,6,-2,LEAVES:3)
Block(4,6,-1,LEAVES:3)
Block(4,6,0,LEAVES:3)
Block(4,6,1,LEAVES:3)
Block(4,6,2,LEAVES:3)
Block(4,7,-4,LEAVES:3)
Block(4,7,-3,LEAVES:3)
Block(4,7,-2,LEAVES:3)
Block(4,7,-1,LEAVES:3)
Block(4,7,0,LEAVES:3)
Block(4,7,1,LEAVES:3)
Block(4,7,2,LEAVES:3)
Block(4,7,3,LEAVES:3)
Block(4,8,-3,LEAVES:3)
Block(4,8,-2,LEAVES:3)
Block(4,8,-1,LEAVES:3)
Block(4,8,0,LEAVES:3)
Block(4,8,1,LEAVES:3)
Block(4,8,2,LEAVES:3)
Block(4,8,3,LEAVES:3)
Block(4,8,4,LEAVES:3)
Block(4,9,-1,LEAVES:3)
Block(4,9,0,LEAVES:3)
Block(4,9,1,LEAVES:3)
Block(4,9,2,LEAVES:3)
Block(4,9,3,LEAVES:3)
Block(4,10,-5,VINE:1)
Block(4,10,0,LEAVES:3)
Block(4,10,1,LEAVES:3)
Block(4,10,2,LEAVES:3)
Block(4,11,-5,VINE:1)
Block(4,11,-3,LEAVES:3)
Block(4,11,-2,LEAVES:3)
Block(4,11,-1,LEAVES:3)
Block(4,11,0,LEAVES:3)
Block(4,11,1,LEAVES:3)
Block(4,12,-5,VINE:1)
Block(4,12,-4,LEAVES:3)
Block(4,12,-3,LEAVES:3)
Block(4,12,-2,LEAVES:3)
Block(4,12,-1,LEAVES:3)
Block(4,12,0,LEAVES:3)
Block(4,12,1,LEAVES:3)
Block(4,12,2,LEAVES:3)
Block(4,13,-5,VINE:5)
Block(4,13,-4,LEAVES:3)
Block(4,13,-3,LEAVES:3)
Block(4,13,-2,LEAVES:3)
Block(4,13,-1,LOG:7)
Block(4,13,0,LEAVES:3)
Block(4,13,1,LEAVES:3)
Block(4,13,2,LEAVES:3)
Block(4,13,3,LEAVES:3)
Block(4,14,-5,VINE:5)
Block(4,14,-4,LEAVES:3)
Block(4,14,-3,LEAVES:3)
Block(4,14,-2,LEAVES:3)
Block(4,14,-1,LEAVES:3)
Block(4,14,0,LEAVES:3)
Block(4,14,1,LEAVES:3)
Block(4,15,-5,VINE:5)
Block(4,15,-3,LEAVES:3)
Block(4,15,-2,LEAVES:3)
Block(4,15,1,LEAVES:3)
Block(4,16,-5,VINE:5)
Block(4,16,1,VINE:8)
Block(4,17,-5,VINE:5)
Block(4,17,1,VINE:8)
Block(4,18,-5,VINE:5)
Block(4,18,1,VINE:8)
Block(4,19,-5,VINE:5)
Block(4,19,1,VINE:8)
Block(4,20,-5,VINE:5)
Block(4,20,1,VINE:8)
Block(4,21,-5,VINE:5)
Block(4,21,1,VINE:8)
Block(4,22,-5,VINE:5)
Block(4,22,-2,LEAVES:3)
Block(4,22,-1,LEAVES:3)
Block(4,22,0,LEAVES:3)
Block(4,22,1,VINE:8)
Block(4,23,-5,VINE:5)
Block(4,23,-4,LEAVES:3)
Block(4,23,-3,LEAVES:3)
Block(4,23,-2,LEAVES:3)
Block(4,23,-1,LEAVES:3)
Block(4,23,0,LEAVES:3)
Block(4,23,1,LEAVES:3)
Block(4,24,-5,VINE:5)
Block(4,24,-4,LEAVES:3)
Block(4,24,-3,LEAVES:3)
Block(4,24,-2,LEAVES:3)
Block(4,24,-1,LOG:7)
Block(4,24,0,LEAVES:3)
Block(4,24,1,LEAVES:3)
Block(4,24,2,LEAVES:3)
Block(4,25,-5,VINE:4)
Block(4,25,-4,LEAVES:3)
Block(4,25,-3,LEAVES:3)
Block(4,25,-2,LEAVES:3)
Block(4,25,-1,LEAVES:3)
Block(4,25,0,LEAVES:3)
Block(4,25,1,LEAVES:3)
Block(4,25,2,LEAVES:3)
Block(4,26,-5,VINE:4)
Block(4,26,-3,LEAVES:3)
Block(4,26,-2,LEAVES:3)
Block(4,26,-1,LEAVES:3)
Block(4,26,0,LEAVES:3)
Block(4,27,-5,VINE:4)
Block(4,27,0,VINE:2)
Block(4,28,-5,VINE:4)
Block(4,28,0,VINE:2)
Block(4,29,-10,LEAVES:3)
Block(4,29,-9,LEAVES:3)
Block(4,29,-8,LEAVES:3)
Block(4,29,-5,VINE:4)
Block(4,29,0,VINE:2)
Block(4,30,-11,LEAVES:3)
Block(4,30,-10,LEAVES:3)
Block(4,30,-9,LEAVES:3)
Block(4,30,-8,LEAVES:3)
Block(4,30,-7,LEAVES:3)
Block(4,30,-6,LEAVES:3)
Block(4,30,-5,VINE:4)
Block(4,30,0,VINE:2)
Block(4,30,6,LEAVES:3)
Block(4,30,7,LEAVES:3)
Block(4,30,8,LEAVES:3)
Block(4,30,9,LEAVES:3)
Block(4,31,-11,LEAVES:3)
Block(4,31,-10,LEAVES:3)
Block(4,31,-9,LEAVES:3)
Block(4,31,-8,LOG:15)
Block(4,31,-7,LEAVES:3)
Block(4,31,-6,LEAVES:3)
Block(4,31,-5,LEAVES:3)
Block(4,31,-4,LEAVES:3)
Block(4,31,0,VINE:2)
Block(4,31,2,LEAVES:3)
Block(4,31,3,LEAVES:3)
Block(4,31,4,LEAVES:3)
Block(4,31,5,LEAVES:3)
Block(4,31,6,LEAVES:3)
Block(4,31,7,LEAVES:3)
Block(4,31,8,LEAVES:3)
Block(4,31,9,LEAVES:3)
Block(4,32,-11,LEAVES:3)
Block(4,32,-10,LEAVES:3)
Block(4,32,-9,LEAVES:3)
Block(4,32,-8,LEAVES:3)
Block(4,32,-7,LOG:11)
Block(4,32,-6,LEAVES:3)
Block(4,32,-5,LEAVES:3)
Block(4,32,-4,LEAVES:3)
Block(4,32,-3,LEAVES:3)
Block(4,32,0,VINE:2)
Block(4,32,1,LEAVES:3)
Block(4,32,2,LEAVES:3)
Block(4,32,3,LEAVES:3)
Block(4,32,4,LEAVES:3)
Block(4,32,5,LEAVES:3)
Block(4,32,6,LOG:11)
Block(4,32,7,LOG:15)
Block(4,32,8,LEAVES:3)
Block(4,32,9,LEAVES:3)
Block(4,32,10,LEAVES:3)
Block(4,33,-10,LEAVES:3)
Block(4,33,-8,LEAVES:3)
Block(4,33,-7,LEAVES:3)
Block(4,33,-6,LEAVES:3)
Block(4,33,-5,LEAVES:3)
Block(4,33,-4,LEAVES:3)
Block(4,33,-3,LEAVES:3)
Block(4,33,0,LEAVES:3)
Block(4,33,1,LEAVES:3)
Block(4,33,2,LOG:7)
Block(4,33,3,LEAVES:3)
Block(4,33,4,LEAVES:3)
Block(4,33,5,LEAVES:3)
Block(4,33,6,LEAVES:3)
Block(4,33,7,LEAVES:3)
Block(4,33,8,LEAVES:3)
Block(4,33,9,LEAVES:3)
Block(4,33,10,LEAVES:3)
Block(4,34,-7,LEAVES:3)
Block(4,34,-6,LEAVES:3)
Block(4,34,-5,LEAVES:3)
Block(4,34,-4,LEAVES:3)
Block(4,34,-3,LEAVES:3)
Block(4,34,-2,LEAVES:3)
Block(4,34,-1,LEAVES:3)
Block(4,34,0,LEAVES:3)
Block(4,34,1,LEAVES:3)
Block(4,34,2,LEAVES:3)
Block(4,34,3,LEAVES:3)
Block(4,34,4,LEAVES:3)
Block(4,34,5,LEAVES:3)
Block(4,34,6,LEAVES:3)
Block(4,34,7,LEAVES:3)
Block(4,34,8,LEAVES:3)
Block(4,35,-5,LEAVES:3)
Block(4,35,-4,LEAVES:3)
Block(4,35,-3,LEAVES:3)
Block(4,35,-2,LEAVES:3)
Block(4,35,-1,LEAVES:3)
Block(4,35,0,LEAVES:3)
Block(4,35,1,LEAVES:3)
Block(4,35,2,LEAVES:3)
Block(4,35,3,LEAVES:3)
Block(4,35,4,LEAVES:3)
Block(4,36,-2,VINE:3)
Block(4,36,-1,LEAVES:3)
Block(4,36,0,LEAVES:3)
Block(4,36,1,LEAVES:3)
Block(4,36,2,LEAVES:3)
Block(4,36,3,LEAVES:3)
Block(4,37,-2,VINE:2)
Block(5,5,-3,LEAVES:3)
Block(5,5,-2,LEAVES:3)
Block(5,5,-1,LEAVES:3)
Block(5,6,-2,LEAVES:3)
Block(5,6,-1,LEAVES:3)
Block(5,6,0,LEAVES:3)
Block(5,7,-3,LEAVES:3)
Block(5,7,-2,LEAVES:3)
Block(5,7,-1,LEAVES:3)
Block(5,7,0,LEAVES:3)
Block(5,7,1,LEAVES:3)
Block(5,7,2,LEAVES:3)
Block(5,8,-2,LEAVES:3)
Block(5,8,-1,LEAVES:3)
Block(5,8,0,LEAVES:3)
Block(5,8,1,LEAVES:3)
Block(5,8,2,LEAVES:3)
Block(5,8,3,LEAVES:3)
Block(5,9,-1,LEAVES:3)
Block(5,9,0,LEAVES:3)
Block(5,9,1,LEAVES:3)
Block(5,9,2,LEAVES:3)
Block(5,10,-3,LEAVES:3)
Block(5,10,-2,LEAVES:3)
Block(5,10,-1,LEAVES:3)
Block(5,10,1,LEAVES:3)
Block(5,11,-3,LEAVES:3)
Block(5,11,-2,LEAVES:3)
Block(5,11,-1,LEAVES:3)
Block(5,11,0,LEAVES:3)
Block(5,11,1,LEAVES:3)
Block(5,11,2,LEAVES:3)
Block(5,12,-4,LEAVES:3)
Block(5,12,-3,LEAVES:3)
Block(5,12,-2,LEAVES:3)
Block(5,12,-1,LOG:15)
Block(5,12,0,LEAVES:3)
Block(5,12,1,LEAVES:3)
Block(5,12,2,LEAVES:3)
Block(5,13,-5,LEAVES:3)
Block(5,13,-4,LEAVES:3)
Block(5,13,-3,LEAVES:3)
Block(5,13,-2,LEAVES:3)
Block(5,13,-1,LOG:7)
Block(5,13,0,LEAVES:3)
Block(5,13,1,LEAVES:3)
Block(5,13,2,LEAVES:3)
Block(5,14,-4,LEAVES:3)
Block(5,14,-3,LEAVES:3)
Block(5,14,-2,LEAVES:3)
Block(5,14,-1,LEAVES:3)
Block(5,14,0,LEAVES:3)
Block(5,14,1,LEAVES:3)
Block(5,15,-2,LEAVES:3)
Block(5,15,-1,LEAVES:3)
Block(5,20,-1,LEAVES:3)
Block(5,21,-2,LEAVES:3)
Block(5,21,-1,LEAVES:3)
Block(5,21,0,LEAVES:3)
Block(5,22,-3,LEAVES:3)
Block(5,22,-2,LEAVES:3)
Block(5,22,-1,LEAVES:3)
Block(5,22,0,LEAVES:3)
Block(5,22,1,LEAVES:3)
Block(5,23,-3,LEAVES:3)
Block(5,23,-2,LEAVES:3)
Block(5,23,-1,LOG:7)
Block(5,23,0,LEAVES:3)
Block(5,23,1,LEAVES:3)
Block(5,24,-4,LEAVES:3)
Block(5,24,-3,LEAVES:3)
Block(5,24,-2,LEAVES:3)
Block(5,24,-1,LEAVES:3)
Block(5,24,0,LEAVES:3)
Block(5,24,1,LEAVES:3)
Block(5,24,2,LEAVES:3)
Block(5,25,-3,LEAVES:3)
Block(5,25,-2,LEAVES:3)
Block(5,25,-1,LEAVES:3)
Block(5,25,0,LEAVES:3)
Block(5,25,1,LEAVES:3)
Block(5,26,-2,LEAVES:3)
Block(5,26,-1,LEAVES:3)
Block(5,29,-8,LEAVES:3)
Block(5,30,-10,LEAVES:3)
Block(5,30,-9,LEAVES:3)
Block(5,30,-8,LEAVES:3)
Block(5,30,-7,LEAVES:3)
Block(5,30,-6,LEAVES:3)
Block(5,30,7,LEAVES:3)
Block(5,30,8,LEAVES:3)
Block(5,31,-11,LEAVES:3)
Block(5,31,-10,LEAVES:3)
Block(5,31,-9,LEAVES:3)
Block(5,31,-8,LEAVES:3)
Block(5,31,-7,LEAVES:3)
Block(5,31,-6,LEAVES:3)
Block(5,31,-5,LEAVES:3)
Block(5,31,1,LEAVES:3)
Block(5,31,2,LEAVES:3)
Block(5,31,3,LEAVES:3)
Block(5,31,4,LEAVES:3)
Block(5,31,5,LEAVES:3)
Block(5,31,6,LEAVES:3)
Block(5,31,7,LEAVES:3)
Block(5,31,8,LEAVES:3)
Block(5,31,9,LEAVES:3)
Block(5,32,-10,LEAVES:3)
Block(5,32,-9,LEAVES:3)
Block(5,32,-8,LEAVES:3)
Block(5,32,-7,LEAVES:3)
Block(5,32,-6,LEAVES:3)
Block(5,32,-5,LEAVES:3)
Block(5,32,-4,LEAVES:3)
Block(5,32,1,LEAVES:3)
Block(5,32,2,LEAVES:3)
Block(5,32,3,LEAVES:3)
Block(5,32,4,LEAVES:3)
Block(5,32,5,LEAVES:3)
Block(5,32,6,LEAVES:3)
Block(5,32,7,LEAVES:3)
Block(5,32,8,LEAVES:3)
Block(5,32,9,LEAVES:3)
Block(5,32,10,LEAVES:3)
Block(5,33,-9,LEAVES:3)
Block(5,33,-7,LEAVES:3)
Block(5,33,-6,LEAVES:3)
Block(5,33,-5,LEAVES:3)
Block(5,33,-4,LEAVES:3)
Block(5,33,-1,LEAVES:3)
Block(5,33,0,LEAVES:3)
Block(5,33,1,LEAVES:3)
Block(5,33,2,LEAVES:3)
Block(5,33,3,LOG:7)
Block(5,33,4,LEAVES:3)
Block(5,33,5,LEAVES:3)
Block(5,33,6,LEAVES:3)
Block(5,33,7,LEAVES:3)
Block(5,33,8,LEAVES:3)
Block(5,33,9,LEAVES:3)
Block(5,34,-5,LEAVES:3)
Block(5,34,-4,LEAVES:3)
Block(5,34,-3,LEAVES:3)
Block(5,34,0,LEAVES:3)
Block(5,34,1,LEAVES:3)
Block(5,34,2,LEAVES:3)
Block(5,34,3,LEAVES:3)
Block(5,34,4,LEAVES:3)
Block(5,34,5,LEAVES:3)
Block(5,34,6,LEAVES:3)
Block(5,35,-1,LEAVES:3)
Block(5,35,0,LEAVES:3)
Block(5,35,1,LEAVES:3)
Block(5,35,2,LEAVES:3)
Block(5,35,3,LEAVES:3)
Block(5,36,-1,VINE:2)
Block(5,36,0,VINE:2)
Block(5,36,1,VINE:2)
Block(5,36,2,LEAVES:3)
Block(6,6,-1,LEAVES:3)
Block(6,7,-2,LEAVES:3)
Block(6,7,-1,LEAVES:3)
Block(6,7,0,LEAVES:3)
Block(6,7,1,LEAVES:3)
Block(6,8,0,LEAVES:3)
Block(6,8,1,LEAVES:3)
Block(6,8,2,LEAVES:3)
Block(6,10,-1,LEAVES:3)
Block(6,11,-3,LEAVES:3)
Block(6,11,-2,LEAVES:3)
Block(6,11,-1,LEAVES:3)
Block(6,11,0,LEAVES:3)
Block(6,11,1,LEAVES:3)
Block(6,12,-4,LEAVES:3)
Block(6,12,-3,LEAVES:3)
Block(6,12,-2,LEAVES:3)
Block(6,12,-1,LEAVES:3)
Block(6,12,0,LEAVES:3)
Block(6,12,1,LEAVES:3)
Block(6,12,2,LEAVES:3)
Block(6,13,-5,LEAVES:3)
Block(6,13,-4,LEAVES:3)
Block(6,13,-3,LEAVES:3)
Block(6,13,-2,LEAVES:3)
Block(6,13,-1,LOG:7)
Block(6,13,0,LEAVES:3)
Block(6,13,1,LEAVES:3)
Block(6,14,-4,LEAVES:3)
Block(6,14,-3,LEAVES:3)
Block(6,14,-2,LEAVES:3)
Block(6,14,-1,LEAVES:3)
Block(6,14,0,LEAVES:3)
Block(6,15,-2,LEAVES:3)
Block(6,20,-1,LEAVES:3)
Block(6,21,-3,LEAVES:3)
Block(6,21,-2,LEAVES:3)
Block(6,21,-1,LEAVES:3)
Block(6,21,0,LEAVES:3)
Block(6,21,1,LEAVES:3)
Block(6,22,-4,LEAVES:3)
Block(6,22,-3,LEAVES:3)
Block(6,22,-2,LEAVES:3)
Block(6,22,-1,LEAVES:3)
Block(6,22,0,LEAVES:3)
Block(6,22,1,LEAVES:3)
Block(6,22,2,LEAVES:3)
Block(6,23,-3,LEAVES:3)
Block(6,23,-2,LEAVES:3)
Block(6,23,-1,LOG:7)
Block(6,23,0,LEAVES:3)
Block(6,23,1,LEAVES:3)
Block(6,24,-3,LEAVES:3)
Block(6,24,-2,LEAVES:3)
Block(6,24,-1,LEAVES:3)
Block(6,24,0,LEAVES:3)
Block(6,24,1,LEAVES:3)
Block(6,25,-2,LEAVES:3)
Block(6,25,-1,LEAVES:3)
Block(6,25,0,LEAVES:3)
Block(6,29,-8,LEAVES:3)
Block(6,30,-9,LEAVES:3)
Block(6,30,-8,LEAVES:3)
Block(6,30,-7,LEAVES:3)
Block(6,30,4,LEAVES:3)
Block(6,30,5,LEAVES:3)
Block(6,30,6,LEAVES:3)
Block(6,30,7,LEAVES:3)
Block(6,31,-10,LEAVES:3)
Block(6,31,-9,LEAVES:3)
Block(6,31,-8,LEAVES:3)
Block(6,31,-7,LEAVES:3)
Block(6,31,-6,LEAVES:3)
Block(6,31,3,LEAVES:3)
Block(6,31,4,LEAVES:3)
Block(6,31,5,LEAVES:3)
Block(6,31,6,LEAVES:3)
Block(6,31,7,LEAVES:3)
Block(6,31,8,LEAVES:3)
Block(6,32,-9,LEAVES:3)
Block(6,32,-8,LEAVES:3)
Block(6,32,-7,LEAVES:3)
Block(6,32,-6,LEAVES:3)
Block(6,32,-5,LEAVES:3)
Block(6,32,1,LEAVES:3)
Block(6,32,2,LEAVES:3)
Block(6,32,3,LEAVES:3)
Block(6,32,4,LOG:7)
Block(6,32,5,LEAVES:3)
Block(6,32,6,LEAVES:3)
Block(6,32,7,LEAVES:3)
Block(6,32,8,LEAVES:3)
Block(6,32,9,LEAVES:3)
Block(6,33,0,LEAVES:3)
Block(6,33,1,LEAVES:3)
Block(6,33,2,LEAVES:3)
Block(6,33,3,LEAVES:3)
Block(6,33,4,LEAVES:3)
Block(6,33,5,LEAVES:3)
Block(6,33,6,LEAVES:3)
Block(6,33,7,LEAVES:3)
Block(6,33,8,LEAVES:3)
Block(6,34,1,LEAVES:3)
Block(6,34,2,LEAVES:3)
Block(6,34,3,LEAVES:3)
Block(6,34,4,LEAVES:3)
Block(6,34,5,LEAVES:3)
Block(6,34,6,LEAVES:3)
Block(6,35,0,LEAVES:3)
Block(6,35,4,LEAVES:3)
Block(7,8,1,LEAVES:3)
Block(7,11,-2,LEAVES:3)
Block(7,11,-1,LEAVES:3)
Block(7,11,0,LEAVES:3)
Block(7,12,-3,LEAVES:3)
Block(7,12,-2,LEAVES:3)
Block(7,12,-1,LEAVES:3)
Block(7,12,0,LEAVES:3)
Block(7,12,1,LEAVES:3)
Block(7,13,-4,LEAVES:3)
Block(7,13,-3,LEAVES:3)
Block(7,13,-2,LEAVES:3)
Block(7,13,-1,LEAVES:3)
Block(7,13,0,LEAVES:3)
Block(7,14,-3,LEAVES:3)
Block(7,14,-2,LEAVES:3)
Block(7,14,-1,LEAVES:3)
Block(7,20,-3,LEAVES:3)
Block(7,20,-1,LEAVES:3)
Block(7,20,1,LEAVES:3)
Block(7,21,-4,LEAVES:3)
Block(7,21,-3,LEAVES:3)
Block(7,21,-2,LEAVES:3)
Block(7,21,-1,LEAVES:3)
Block(7,21,0,LEAVES:3)
Block(7,21,1,LEAVES:3)
Block(7,21,2,LEAVES:3)
Block(7,22,-4,LEAVES:3)
Block(7,22,-3,LEAVES:3)
Block(7,22,-2,LEAVES:3)
Block(7,22,-1,LOG:15)
Block(7,22,0,LEAVES:3)
Block(7,22,1,LEAVES:3)
Block(7,22,2,LEAVES:3)
Block(7,23,-3,LEAVES:3)
Block(7,23,-2,LEAVES:3)
Block(7,23,-1,LEAVES:3)
Block(7,23,0,LEAVES:3)
Block(7,23,1,LEAVES:3)
Block(7,23,2,LEAVES:3)
Block(7,24,-2,LEAVES:3)
Block(7,24,-1,LEAVES:3)
Block(7,24,0,LEAVES:3)
Block(7,24,1,LEAVES:3)
Block(7,30,4,LEAVES:3)
Block(7,30,5,LEAVES:3)
Block(7,30,6,LEAVES:3)
Block(7,30,7,LEAVES:3)
Block(7,31,-9,LEAVES:3)
Block(7,31,-8,LEAVES:3)
Block(7,31,-7,LEAVES:3)
Block(7,31,2,LEAVES:3)
Block(7,31,3,LEAVES:3)
Block(7,31,4,LEAVES:3)
Block(7,31,5,LEAVES:3)
Block(7,31,6,LEAVES:3)
Block(7,31,7,LEAVES:3)
Block(7,31,8,LEAVES:3)
Block(7,32,-8,LEAVES:3)
Block(7,32,1,LEAVES:3)
Block(7,32,2,LEAVES:3)
Block(7,32,3,LEAVES:3)
Block(7,32,4,LEAVES:3)
Block(7,32,5,LOG:15)
Block(7,32,6,LEAVES:3)
Block(7,32,7,LEAVES:3)
Block(7,32,8,LEAVES:3)
Block(7,33,1,LEAVES:3)
Block(7,33,2,LEAVES:3)
Block(7,33,3,LEAVES:3)
Block(7,33,4,LEAVES:3)
Block(7,33,5,LEAVES:3)
Block(7,33,6,LEAVES:3)
Block(7,33,7,LEAVES:3)
Block(7,33,8,LEAVES:3)
Block(7,34,2,LEAVES:3)
Block(7,34,3,LEAVES:3)
Block(7,34,4,LEAVES:3)
Block(7,34,5,LEAVES:3)
Block(7,34,7,LEAVES:3)
Block(8,10,-4,VINE:1)
Block(8,11,-4,VINE:1)
Block(8,11,-1,LEAVES:3)
Block(8,12,-4,VINE:1)
Block(8,12,-2,LEAVES:3)
Block(8,12,-1,LEAVES:3)
Block(8,12,0,LEAVES:3)
Block(8,13,-4,VINE:1)
Block(8,13,-3,LEAVES:3)
Block(8,13,-2,LEAVES:3)
Block(8,13,-1,LEAVES:3)
Block(8,13,0,LEAVES:3)
Block(8,14,-4,VINE:1)
Block(8,14,-2,LEAVES:3)
Block(8,14,-1,LEAVES:3)
Block(8,15,-4,VINE:1)
Block(8,16,-4,VINE:1)
Block(8,17,-4,VINE:1)
Block(8,18,-4,VINE:1)
Block(8,19,-4,VINE:1)
Block(8,20,-4,VINE:1)
Block(8,20,-2,LEAVES:3)
Block(8,20,-1,LEAVES:3)
Block(8,21,-4,VINE:1)
Block(8,21,-3,LEAVES:3)
Block(8,21,-2,LEAVES:3)
Block(8,21,-1,LEAVES:3)
Block(8,21,0,LEAVES:3)
Block(8,21,1,LEAVES:3)
Block(8,22,-4,LEAVES:3)
Block(8,22,-3,LEAVES:3)
Block(8,22,-2,LEAVES:3)
Block(8,22,-1,LEAVES:3)
Block(8,22,0,LEAVES:3)
Block(8,22,1,LEAVES:3)
Block(8,22,2,LEAVES:3)
Block(8,23,-3,LEAVES:3)
Block(8,23,-2,LEAVES:3)
Block(8,23,-1,LEAVES:3)
Block(8,23,0,LEAVES:3)
Block(8,23,1,LEAVES:3)
Block(8,24,-1,LEAVES:3)
Block(8,24,0,LEAVES:3)
Block(8,30,5,LEAVES:3)
Block(8,31,-8,LEAVES:3)
Block(8,31,3,LEAVES:3)
Block(8,31,4,LEAVES:3)
Block(8,31,5,LEAVES:3)
Block(8,31,6,LEAVES:3)
Block(8,31,7,LEAVES:3)
Block(8,32,2,LEAVES:3)
Block(8,32,3,LEAVES:3)
Block(8,32,4,LEAVES:3)
Block(8,32,5,LEAVES:3)
Block(8,32,6,LEAVES:3)
Block(8,32,7,LEAVES:3)
Block(8,32,8,LEAVES:3)
Block(8,33,2,LEAVES:3)
Block(8,33,3,LEAVES:3)
Block(8,33,4,LEAVES:3)
Block(8,33,5,LEAVES:3)
Block(8,33,6,LEAVES:3)
Block(8,33,7,LEAVES:3)
Block(8,34,3,LEAVES:3)
Block(8,34,6,LEAVES:3)
Block(9,12,-3,VINE:3)
Block(9,13,-3,VINE:3)
Block(9,13,-2,LEAVES:3)
Block(9,13,-1,LEAVES:3)
Block(9,14,-3,VINE:3)
Block(9,14,-2,VINE:1)
Block(9,15,-3,VINE:3)
Block(9,15,-2,VINE:1)
Block(9,16,-3,VINE:3)
Block(9,16,-2,VINE:1)
Block(9,17,-3,VINE:3)
Block(9,17,-2,VINE:1)
Block(9,18,-3,VINE:3)
Block(9,18,-2,VINE:1)
Block(9,19,-3,VINE:3)
Block(9,19,-2,VINE:1)
Block(9,20,-3,VINE:3)
Block(9,20,-2,VINE:1)
Block(9,20,-1,LEAVES:3)
Block(9,21,-3,VINE:3)
Block(9,21,-2,LEAVES:3)
Block(9,21,-1,LEAVES:3)
Block(9,21,0,LEAVES:3)
Block(9,22,-3,LEAVES:3)
Block(9,22,-2,LEAVES:3)
Block(9,22,-1,LEAVES:3)
Block(9,22,0,LEAVES:3)
Block(9,22,1,LEAVES:3)
Block(9,23,-2,LEAVES:3)
Block(9,23,-1,LEAVES:3)
Block(9,23,0,LEAVES:3)
Block(9,24,-1,LEAVES:3)
Block(9,30,5,LEAVES:3)
Block(9,31,4,LEAVES:3)
Block(9,31,5,LEAVES:3)
Block(9,31,6,LEAVES:3)
Block(9,32,3,LEAVES:3)
Block(9,32,4,LEAVES:3)
Block(9,32,5,LEAVES:3)
Block(9,32,6,LEAVES:3)
Block(9,32,7,LEAVES:3)
Block(9,33,4,LEAVES:3)
Block(9,33,5,LEAVES:3)
Block(9,33,6,LEAVES:3)
Block(9,34,5,LEAVES:3)
Block(10,18,-2,VINE:2)
Block(10,19,-2,VINE:2)
Block(10,20,-2,VINE:2)
Block(10,21,-2,VINE:2)
Block(10,21,-1,LEAVES:3)
Block(10,22,-2,LEAVES:3)
Block(10,22,-1,LEAVES:3)
Block(10,22,0,LEAVES:3)
Block(10,31,5,LEAVES:3)
Block(10,32,4,LEAVES:3)
Block(10,32,5,LEAVES:3)
Block(10,32,6,LEAVES:3)
Block(10,33,5,LEAVES:3)
Block(11,32,5,LEAVES:3)

#######################################################################
# +-----------------------------------------------------------------+ #
# |                            BO3 checks                           | #
# +-----------------------------------------------------------------+ #
#######################################################################

BlockCheck(0,-1,0,GRASS:0,DIRT:0)
BlockCheck(1,-1,0,GRASS:0,DIRT:0)
BlockCheck(0,-1,1,GRASS:0,DIRT:0)
BlockCheck(1,-1,1,GRASS:0,DIRT:0)

#######################################################################
# +-----------------------------------------------------------------+ #
# |                             Branches                            | #
# +-----------------------------------------------------------------+ #
#######################################################################


#######################################################################
# +-----------------------------------------------------------------+ #
# |                             Entities                            | #
# +-----------------------------------------------------------------+ #
#######################################################################


#######################################################################
# +-----------------------------------------------------------------+ #
# |                            Particles                            | #
# +-----------------------------------------------------------------+ #
#######################################################################


#######################################################################
# +-----------------------------------------------------------------+ #
# |                             Spawners                            | #
# +-----------------------------------------------------------------+ #
#######################################################################


#######################################################################
# +-----------------------------------------------------------------+ #
# |                             ModData                             | #
# +-----------------------------------------------------------------+ #
#######################################################################

