
#######################################################################
# +-----------------------------------------------------------------+ #
# |                            BO3 object                           | #
# +-----------------------------------------------------------------+ #
#######################################################################

Author: Unknown

Description: This BO3 was converted from a schematic using OTGEdit. The author and description information of the schematic could not be found. If you know who the author of the schematic is then please add this information.

Version: 3

SettingsMode: WriteWithoutComments


#######################################################################
# +-----------------------------------------------------------------+ #
# |                          Main settings                          | #
# +-----------------------------------------------------------------+ #
#######################################################################

Tree: true

Frequency: 1

Rarity: 100.0

RotateRandomly: true

SpawnHeight: highestSolidBlock

SpawnHeightOffset: 0

SpawnHeightVariance: 0

##############################
# Height Limits for the BO3. #
##############################

MinHeight: 20

MaxHeight: 255

######################
# Extrusion settings #
######################

ExtrudeMode: None

ExtrudeThroughBlocks: AIR

MaxBranchDepth: 10

ExcludedBiomes: All


#######################################################################
# +-----------------------------------------------------------------+ #
# |                      Source block settings                      | #
# +-----------------------------------------------------------------+ #
#######################################################################

SourceBlocks: AIR

MaxPercentageOutsideSourceBlock: 100

OutsideSourceBlock: dontPlace

DoReplaceBlocks: true

IsOTGPlus: false


#######################################################################
# +-----------------------------------------------------------------+ #
# |                              Blocks                             | #
# +-----------------------------------------------------------------+ #
#######################################################################

Block(-8,30,0,LEAVES:3)
Block(-8,30,1,LEAVES:3)
Block(-8,30,2,LEAVES:3)
Block(-7,20,-2,LEAVES:3)
Block(-7,20,0,LEAVES:3)
Block(-7,29,1,LEAVES:3)
Block(-7,29,2,LEAVES:3)
Block(-7,30,-1,LEAVES:3)
Block(-7,30,0,LEAVES:3)
Block(-7,30,1,LEAVES:3)
Block(-7,30,2,LEAVES:3)
Block(-7,30,3,LEAVES:3)
Block(-7,31,0,LEAVES:3)
Block(-7,31,1,LEAVES:3)
Block(-7,31,2,LEAVES:3)
Block(-6,19,0,LEAVES:3)
Block(-6,20,-3,LEAVES:3)
Block(-6,20,-2,LEAVES:3)
Block(-6,20,-1,LEAVES:3)
Block(-6,20,0,LEAVES:3)
Block(-6,20,1,LEAVES:3)
Block(-6,21,-2,LEAVES:3)
Block(-6,21,-1,LEAVES:3)
Block(-6,21,0,LEAVES:3)
Block(-6,21,1,VINE:4)
Block(-6,22,0,VINE:8)
Block(-6,28,1,LEAVES:3)
Block(-6,28,2,LEAVES:3)
Block(-6,29,-1,LEAVES:3)
Block(-6,29,0,LEAVES:3)
Block(-6,29,1,LEAVES:3)
Block(-6,29,2,LEAVES:3)
Block(-6,29,3,LEAVES:3)
Block(-6,30,-2,LEAVES:3)
Block(-6,30,-1,LEAVES:3)
Block(-6,30,0,LEAVES:3)
Block(-6,30,1,LEAVES:3)
Block(-6,30,2,LEAVES:3)
Block(-6,30,3,LEAVES:3)
Block(-6,30,4,LEAVES:3)
Block(-6,31,-1,LEAVES:3)
Block(-6,31,0,LEAVES:3)
Block(-6,31,1,LEAVES:3)
Block(-6,31,2,LEAVES:3)
Block(-6,31,3,LEAVES:3)
Block(-6,32,0,LEAVES:3)
Block(-6,32,1,LEAVES:3)
Block(-6,32,2,LEAVES:3)
Block(-6,33,1,LEAVES:3)
Block(-5,15,-2,VINE:1)
Block(-5,16,-2,VINE:1)
Block(-5,17,-2,VINE:1)
Block(-5,18,-2,VINE:1)
Block(-5,18,-1,LEAVES:3)
Block(-5,18,0,LEAVES:3)
Block(-5,19,-3,LEAVES:3)
Block(-5,19,-2,LEAVES:3)
Block(-5,19,-1,LEAVES:3)
Block(-5,19,0,LEAVES:3)
Block(-5,19,1,LEAVES:3)
Block(-5,20,-4,LEAVES:3)
Block(-5,20,-3,LEAVES:3)
Block(-5,20,-2,LEAVES:3)
Block(-5,20,-1,LEAVES:3)
Block(-5,20,0,LEAVES:3)
Block(-5,20,1,LEAVES:3)
Block(-5,20,2,LEAVES:3)
Block(-5,21,-3,LEAVES:3)
Block(-5,21,-2,LEAVES:3)
Block(-5,21,-1,LEAVES:3)
Block(-5,21,0,LEAVES:3)
Block(-5,21,1,LEAVES:3)
Block(-5,22,-2,VINE:8)
Block(-5,22,-1,VINE:8)
Block(-5,22,0,LEAVES:3)
Block(-5,25,0,VINE:1)
Block(-5,26,0,VINE:1)
Block(-5,27,0,VINE:1)
Block(-5,28,-1,LEAVES:3)
Block(-5,28,0,VINE:1)
Block(-5,28,1,LEAVES:3)
Block(-5,28,2,LEAVES:3)
Block(-5,29,-2,LEAVES:3)
Block(-5,29,-1,LEAVES:3)
Block(-5,29,0,LEAVES:3)
Block(-5,29,1,LEAVES:3)
Block(-5,29,2,LEAVES:3)
Block(-5,29,3,LEAVES:3)
Block(-5,29,4,LEAVES:3)
Block(-5,30,-3,LEAVES:3)
Block(-5,30,-2,LEAVES:3)
Block(-5,30,-1,LEAVES:3)
Block(-5,30,0,LEAVES:3)
Block(-5,30,1,LOG:15)
Block(-5,30,2,LEAVES:3)
Block(-5,30,3,LEAVES:3)
Block(-5,30,4,LEAVES:3)
Block(-5,30,5,LEAVES:3)
Block(-5,31,-3,VINE:8)
Block(-5,31,-2,LEAVES:3)
Block(-5,31,-1,LEAVES:3)
Block(-5,31,0,LEAVES:3)
Block(-5,31,1,LEAVES:3)
Block(-5,31,2,LEAVES:3)
Block(-5,31,3,LEAVES:3)
Block(-5,31,4,LEAVES:3)
Block(-5,32,-3,VINE:8)
Block(-5,32,-1,LEAVES:3)
Block(-5,32,0,LEAVES:3)
Block(-5,32,1,LEAVES:3)
Block(-5,32,2,LEAVES:3)
Block(-5,32,3,LEAVES:3)
Block(-5,33,-3,VINE:8)
Block(-5,33,0,LEAVES:3)
Block(-5,33,1,LEAVES:3)
Block(-5,35,-6,LEAVES:3)
Block(-5,42,-1,LEAVES:3)
Block(-5,43,-2,LEAVES:3)
Block(-5,43,-1,LEAVES:3)
Block(-5,43,0,LEAVES:3)
Block(-5,43,1,LEAVES:3)
Block(-4,16,2,VINE:4)
Block(-4,17,2,VINE:4)
Block(-4,18,-3,LEAVES:3)
Block(-4,18,-1,LEAVES:3)
Block(-4,18,0,LEAVES:3)
Block(-4,18,1,LEAVES:3)
Block(-4,18,2,VINE:4)
Block(-4,19,-4,LEAVES:3)
Block(-4,19,-3,LEAVES:3)
Block(-4,19,-2,LEAVES:3)
Block(-4,19,-1,LEAVES:3)
Block(-4,19,0,LEAVES:3)
Block(-4,19,1,LEAVES:3)
Block(-4,19,2,LEAVES:3)
Block(-4,19,3,VINE:4)
Block(-4,20,-5,LEAVES:3)
Block(-4,20,-4,LEAVES:3)
Block(-4,20,-3,LEAVES:3)
Block(-4,20,-2,LEAVES:3)
Block(-4,20,-1,LEAVES:3)
Block(-4,20,0,LEAVES:3)
Block(-4,20,1,LEAVES:3)
Block(-4,20,2,LEAVES:3)
Block(-4,20,3,LEAVES:3)
Block(-4,20,4,VINE:4)
Block(-4,21,-4,LEAVES:3)
Block(-4,21,-3,LEAVES:3)
Block(-4,21,-2,LEAVES:3)
Block(-4,21,-1,LEAVES:3)
Block(-4,21,0,LEAVES:3)
Block(-4,21,1,LEAVES:3)
Block(-4,21,2,LEAVES:3)
Block(-4,22,-3,LEAVES:3)
Block(-4,22,-2,LEAVES:3)
Block(-4,22,-1,LEAVES:3)
Block(-4,22,0,LEAVES:3)
Block(-4,22,1,LEAVES:3)
Block(-4,26,-4,VINE:8)
Block(-4,27,-4,VINE:8)
Block(-4,28,-4,VINE:8)
Block(-4,28,0,LEAVES:3)
Block(-4,28,2,LEAVES:3)
Block(-4,29,-4,VINE:8)
Block(-4,29,-1,LEAVES:3)
Block(-4,29,0,LEAVES:3)
Block(-4,29,1,LEAVES:3)
Block(-4,29,2,LEAVES:3)
Block(-4,29,3,LEAVES:3)
Block(-4,30,-4,VINE:8)
Block(-4,30,-2,LEAVES:3)
Block(-4,30,-1,LEAVES:3)
Block(-4,30,0,LEAVES:3)
Block(-4,30,1,LEAVES:3)
Block(-4,30,2,LEAVES:3)
Block(-4,30,3,LEAVES:3)
Block(-4,30,4,LEAVES:3)
Block(-4,31,-4,VINE:8)
Block(-4,31,-2,LEAVES:3)
Block(-4,31,-1,LEAVES:3)
Block(-4,31,0,LEAVES:3)
Block(-4,31,1,LOG:7)
Block(-4,31,2,LEAVES:3)
Block(-4,31,3,LEAVES:3)
Block(-4,31,4,LEAVES:3)
Block(-4,31,5,LEAVES:3)
Block(-4,32,-6,LEAVES:3)
Block(-4,32,-5,LEAVES:3)
Block(-4,32,-4,LEAVES:3)
Block(-4,32,-2,VINE:8)
Block(-4,32,-1,LEAVES:3)
Block(-4,32,0,LEAVES:3)
Block(-4,32,1,LEAVES:3)
Block(-4,32,2,LEAVES:3)
Block(-4,32,3,LEAVES:3)
Block(-4,33,-5,LEAVES:3)
Block(-4,33,-4,LEAVES:3)
Block(-4,33,-3,LEAVES:3)
Block(-4,33,-2,VINE:8)
Block(-4,33,0,LEAVES:3)
Block(-4,33,1,LEAVES:3)
Block(-4,33,3,LEAVES:3)
Block(-4,34,-6,LEAVES:3)
Block(-4,34,-4,LEAVES:3)
Block(-4,34,-3,VINE:4)
Block(-4,34,-2,VINE:8)
Block(-4,35,-7,LEAVES:3)
Block(-4,35,-6,LEAVES:3)
Block(-4,35,-5,LEAVES:3)
Block(-4,35,-4,LEAVES:3)
Block(-4,35,-3,VINE:4)
Block(-4,35,-2,VINE:8)
Block(-4,36,-6,LEAVES:3)
Block(-4,36,-5,LEAVES:3)
Block(-4,36,-4,LEAVES:3)
Block(-4,36,-3,LEAVES:3)
Block(-4,36,-2,VINE:8)
Block(-4,37,-4,LEAVES:3)
Block(-4,39,3,LEAVES:3)
Block(-4,40,-7,LEAVES:3)
Block(-4,42,-4,LEAVES:3)
Block(-4,42,-2,LEAVES:3)
Block(-4,42,-1,LEAVES:3)
Block(-4,42,0,LEAVES:3)
Block(-4,42,1,LEAVES:3)
Block(-4,43,-3,LEAVES:3)
Block(-4,43,-2,LEAVES:3)
Block(-4,43,-1,LEAVES:3)
Block(-4,43,0,LEAVES:3)
Block(-4,43,1,LEAVES:3)
Block(-4,43,2,LEAVES:3)
Block(-4,44,-2,LEAVES:3)
Block(-4,44,-1,LEAVES:3)
Block(-4,44,0,LEAVES:3)
Block(-4,44,1,LEAVES:3)
Block(-4,45,-1,LEAVES:3)
Block(-3,6,0,VINE:8)
Block(-3,7,0,VINE:8)
Block(-3,8,-1,VINE:8)
Block(-3,8,0,VINE:8)
Block(-3,9,-1,VINE:8)
Block(-3,9,0,VINE:8)
Block(-3,10,-1,VINE:8)
Block(-3,10,0,VINE:8)
Block(-3,11,0,VINE:8)
Block(-3,12,0,VINE:8)
Block(-3,14,-4,VINE:1)
Block(-3,15,-4,VINE:1)
Block(-3,16,-4,VINE:1)
Block(-3,17,-4,VINE:1)
Block(-3,18,-4,VINE:1)
Block(-3,18,-3,LEAVES:3)
Block(-3,18,-2,LEAVES:3)
Block(-3,18,-1,LEAVES:3)
Block(-3,18,0,LEAVES:3)
Block(-3,18,1,VINE:2)
Block(-3,18,2,LEAVES:3)
Block(-3,19,-4,LEAVES:3)
Block(-3,19,-3,LEAVES:3)
Block(-3,19,-2,LEAVES:3)
Block(-3,19,-1,LEAVES:3)
Block(-3,19,0,LEAVES:3)
Block(-3,19,1,LEAVES:3)
Block(-3,19,2,LEAVES:3)
Block(-3,19,3,LEAVES:3)
Block(-3,20,-5,LEAVES:3)
Block(-3,20,-4,LEAVES:3)
Block(-3,20,-3,LEAVES:3)
Block(-3,20,-2,LEAVES:3)
Block(-3,20,-1,LOG:7)
Block(-3,20,0,LOG:7)
Block(-3,20,1,LEAVES:3)
Block(-3,20,2,LEAVES:3)
Block(-3,20,3,LEAVES:3)
Block(-3,20,4,LEAVES:3)
Block(-3,21,-5,LEAVES:3)
Block(-3,21,-4,LEAVES:3)
Block(-3,21,-3,LEAVES:3)
Block(-3,21,-2,LEAVES:3)
Block(-3,21,-1,LEAVES:3)
Block(-3,21,0,LEAVES:3)
Block(-3,21,1,LEAVES:3)
Block(-3,21,2,LEAVES:3)
Block(-3,21,3,LEAVES:3)
Block(-3,22,-3,VINE:8)
Block(-3,22,-2,LEAVES:3)
Block(-3,22,-1,LEAVES:3)
Block(-3,22,0,LEAVES:3)
Block(-3,22,1,LEAVES:3)
Block(-3,22,2,LEAVES:3)
Block(-3,23,-1,VINE:8)
Block(-3,24,-1,VINE:8)
Block(-3,25,-3,VINE:8)
Block(-3,25,-1,VINE:8)
Block(-3,26,-3,VINE:8)
Block(-3,26,-1,VINE:9)
Block(-3,27,-3,VINE:8)
Block(-3,27,-1,VINE:9)
Block(-3,28,-3,VINE:8)
Block(-3,28,-1,VINE:9)
Block(-3,29,-3,VINE:8)
Block(-3,29,-1,VINE:1)
Block(-3,29,0,LEAVES:3)
Block(-3,29,1,LEAVES:3)
Block(-3,29,2,LEAVES:3)
Block(-3,30,-3,VINE:8)
Block(-3,30,-1,LEAVES:3)
Block(-3,30,0,LEAVES:3)
Block(-3,30,1,LEAVES:3)
Block(-3,30,2,LEAVES:3)
Block(-3,30,3,LEAVES:3)
Block(-3,31,-6,LEAVES:3)
Block(-3,31,-5,LEAVES:3)
Block(-3,31,-4,LEAVES:3)
Block(-3,31,-3,VINE:8)
Block(-3,31,-2,LEAVES:3)
Block(-3,31,-1,LEAVES:3)
Block(-3,31,0,LOG:7)
Block(-3,31,1,LEAVES:3)
Block(-3,31,2,LEAVES:3)
Block(-3,31,3,LEAVES:3)
Block(-3,31,4,LEAVES:3)
Block(-3,32,-7,LEAVES:3)
Block(-3,32,-6,LEAVES:3)
Block(-3,32,-5,LEAVES:3)
Block(-3,32,-4,LEAVES:3)
Block(-3,32,-3,LEAVES:3)
Block(-3,32,-1,LEAVES:3)
Block(-3,32,0,LEAVES:3)
Block(-3,32,1,LEAVES:3)
Block(-3,32,2,LEAVES:3)
Block(-3,32,3,LEAVES:3)
Block(-3,33,-6,LEAVES:3)
Block(-3,33,-5,LEAVES:3)
Block(-3,33,-4,LEAVES:3)
Block(-3,33,-3,LEAVES:3)
Block(-3,33,-2,LEAVES:3)
Block(-3,33,-1,VINE:12)
Block(-3,33,1,VINE:2)
Block(-3,34,-7,LEAVES:3)
Block(-3,34,-6,LEAVES:3)
Block(-3,34,-5,LEAVES:3)
Block(-3,34,-4,LEAVES:3)
Block(-3,34,-3,LEAVES:3)
Block(-3,34,-2,VINE:8)
Block(-3,34,-1,VINE:12)
Block(-3,35,-8,LEAVES:3)
Block(-3,35,-7,LEAVES:3)
Block(-3,35,-6,LEAVES:3)
Block(-3,35,-5,LEAVES:3)
Block(-3,35,-4,LEAVES:3)
Block(-3,35,-3,LEAVES:3)
Block(-3,35,-2,VINE:8)
Block(-3,35,-1,VINE:12)
Block(-3,36,-7,LEAVES:3)
Block(-3,36,-6,LEAVES:3)
Block(-3,36,-5,LEAVES:3)
Block(-3,36,-4,LEAVES:3)
Block(-3,36,-3,LEAVES:3)
Block(-3,36,-2,LEAVES:3)
Block(-3,36,-1,VINE:12)
Block(-3,37,-6,LEAVES:3)
Block(-3,37,-5,LEAVES:3)
Block(-3,37,-4,LEAVES:3)
Block(-3,37,-3,LEAVES:3)
Block(-3,37,-1,VINE:8)
Block(-3,38,-1,VINE:8)
Block(-3,38,4,LEAVES:3)
Block(-3,39,-7,LEAVES:3)
Block(-3,39,-1,VINE:8)
Block(-3,39,2,LEAVES:3)
Block(-3,39,3,LEAVES:3)
Block(-3,39,4,LEAVES:3)
Block(-3,40,-8,LEAVES:3)
Block(-3,40,-7,LEAVES:3)
Block(-3,40,-6,LEAVES:3)
Block(-3,40,-1,VINE:8)
Block(-3,40,2,VINE:8)
Block(-3,40,3,LEAVES:3)
Block(-3,41,-1,LEAVES:3)
Block(-3,41,0,LEAVES:3)
Block(-3,42,-5,LEAVES:3)
Block(-3,42,-4,LEAVES:3)
Block(-3,42,-3,LEAVES:3)
Block(-3,42,-2,LEAVES:3)
Block(-3,42,-1,LEAVES:3)
Block(-3,42,0,LEAVES:3)
Block(-3,42,1,LEAVES:3)
Block(-3,42,2,LEAVES:3)
Block(-3,43,-4,LEAVES:3)
Block(-3,43,-3,LEAVES:3)
Block(-3,43,-2,LEAVES:3)
Block(-3,43,-1,LEAVES:3)
Block(-3,43,0,LEAVES:3)
Block(-3,43,1,LEAVES:3)
Block(-3,43,2,LEAVES:3)
Block(-3,43,3,LEAVES:3)
Block(-3,44,-4,VINE:8)
Block(-3,44,-3,LEAVES:3)
Block(-3,44,-2,LEAVES:3)
Block(-3,44,-1,LEAVES:3)
Block(-3,44,0,LEAVES:3)
Block(-3,44,1,LEAVES:3)
Block(-3,44,2,LEAVES:3)
Block(-3,45,-1,LEAVES:3)
Block(-3,45,0,LEAVES:3)
Block(-3,45,1,LEAVES:3)
Block(-2,0,-1,LOG:3)
Block(-2,0,0,LOG:3)
Block(-2,1,-1,LOG:3)
Block(-2,1,0,LOG:3)
Block(-2,2,-1,LOG:3)
Block(-2,2,0,LOG:3)
Block(-2,3,-1,LOG:3)
Block(-2,3,0,LOG:3)
Block(-2,4,-1,LOG:3)
Block(-2,4,0,LOG:3)
Block(-2,5,-1,LOG:3)
Block(-2,5,0,LOG:3)
Block(-2,6,-1,LOG:3)
Block(-2,6,0,LOG:3)
Block(-2,7,-1,LOG:3)
Block(-2,7,0,LOG:3)
Block(-2,8,-1,LOG:3)
Block(-2,8,0,LOG:3)
Block(-2,8,1,LEAVES:3)
Block(-2,8,2,LEAVES:3)
Block(-2,8,3,LEAVES:3)
Block(-2,9,-1,LOG:3)
Block(-2,9,0,LOG:3)
Block(-2,10,-1,LOG:3)
Block(-2,10,0,LOG:3)
Block(-2,11,-1,LOG:3)
Block(-2,11,0,LOG:3)
Block(-2,12,-1,LOG:3)
Block(-2,12,0,LOG:3)
Block(-2,13,-1,LOG:3)
Block(-2,13,0,LOG:3)
Block(-2,14,-1,LOG:3)
Block(-2,14,0,LOG:3)
Block(-2,15,-1,LOG:3)
Block(-2,15,0,LOG:3)
Block(-2,16,-1,LOG:3)
Block(-2,16,0,LOG:3)
Block(-2,17,-1,LOG:3)
Block(-2,17,0,LOG:3)
Block(-2,18,-4,LEAVES:3)
Block(-2,18,-3,LEAVES:3)
Block(-2,18,-2,LEAVES:3)
Block(-2,18,-1,LOG:3)
Block(-2,18,0,LOG:3)
Block(-2,18,1,LEAVES:3)
Block(-2,19,-5,LEAVES:3)
Block(-2,19,-4,LEAVES:3)
Block(-2,19,-3,LEAVES:3)
Block(-2,19,-2,LEAVES:3)
Block(-2,19,-1,LOG:3)
Block(-2,19,0,LOG:3)
Block(-2,19,1,LEAVES:3)
Block(-2,19,2,LEAVES:3)
Block(-2,20,-5,LEAVES:3)
Block(-2,20,-4,LEAVES:3)
Block(-2,20,-3,LEAVES:3)
Block(-2,20,-2,LEAVES:3)
Block(-2,20,-1,LOG:3)
Block(-2,20,0,LOG:3)
Block(-2,20,1,LEAVES:3)
Block(-2,20,2,LEAVES:3)
Block(-2,20,3,LEAVES:3)
Block(-2,21,-4,LEAVES:3)
Block(-2,21,-3,LEAVES:3)
Block(-2,21,-2,LEAVES:3)
Block(-2,21,-1,LOG:3)
Block(-2,21,0,LOG:3)
Block(-2,21,1,LEAVES:3)
Block(-2,21,2,LEAVES:3)
Block(-2,22,-3,LEAVES:3)
Block(-2,22,-2,LEAVES:3)
Block(-2,22,-1,LOG:3)
Block(-2,22,0,LOG:3)
Block(-2,22,1,LEAVES:3)
Block(-2,23,-1,LOG:3)
Block(-2,23,0,LOG:3)
Block(-2,24,-1,LOG:3)
Block(-2,24,0,LOG:3)
Block(-2,25,-1,LOG:3)
Block(-2,25,0,LOG:3)
Block(-2,25,1,VINE:12)
Block(-2,26,-1,LOG:3)
Block(-2,26,0,LOG:3)
Block(-2,26,1,VINE:12)
Block(-2,27,-1,LOG:3)
Block(-2,27,0,LOG:3)
Block(-2,27,1,VINE:12)
Block(-2,28,-1,LOG:3)
Block(-2,28,0,LOG:3)
Block(-2,28,1,VINE:12)
Block(-2,29,-1,LOG:3)
Block(-2,29,0,LOG:3)
Block(-2,29,1,LEAVES:3)
Block(-2,30,-5,LEAVES:3)
Block(-2,30,-3,LEAVES:3)
Block(-2,30,-1,LOG:3)
Block(-2,30,0,LOG:3)
Block(-2,30,1,LEAVES:3)
Block(-2,30,2,LEAVES:3)
Block(-2,31,-7,LEAVES:3)
Block(-2,31,-6,LEAVES:3)
Block(-2,31,-5,LEAVES:3)
Block(-2,31,-4,LEAVES:3)
Block(-2,31,-3,LEAVES:3)
Block(-2,31,-1,LOG:3)
Block(-2,31,0,LOG:3)
Block(-2,31,1,LEAVES:3)
Block(-2,31,2,LEAVES:3)
Block(-2,31,3,LEAVES:3)
Block(-2,32,-8,LEAVES:3)
Block(-2,32,-7,LEAVES:3)
Block(-2,32,-6,LEAVES:3)
Block(-2,32,-5,LEAVES:3)
Block(-2,32,-4,LEAVES:3)
Block(-2,32,-3,LEAVES:3)
Block(-2,32,-2,LEAVES:3)
Block(-2,32,-1,LOG:3)
Block(-2,32,0,LOG:3)
Block(-2,32,1,LEAVES:3)
Block(-2,32,2,LEAVES:3)
Block(-2,33,-7,LEAVES:3)
Block(-2,33,-6,LEAVES:3)
Block(-2,33,-5,LEAVES:3)
Block(-2,33,-4,LEAVES:3)
Block(-2,33,-3,LEAVES:3)
Block(-2,33,-2,LEAVES:3)
Block(-2,33,-1,LOG:3)
Block(-2,33,0,LOG:3)
Block(-2,33,1,LEAVES:3)
Block(-2,33,2,VINE:4)
Block(-2,34,-8,LEAVES:3)
Block(-2,34,-7,LEAVES:3)
Block(-2,34,-6,LEAVES:3)
Block(-2,34,-5,LEAVES:3)
Block(-2,34,-4,LEAVES:3)
Block(-2,34,-3,LEAVES:3)
Block(-2,34,-2,LEAVES:3)
Block(-2,34,-1,LOG:3)
Block(-2,34,0,LOG:3)
Block(-2,34,1,VINE:13)
Block(-2,35,-9,LEAVES:3)
Block(-2,35,-8,LEAVES:3)
Block(-2,35,-7,LEAVES:3)
Block(-2,35,-6,LEAVES:3)
Block(-2,35,-5,LEAVES:3)
Block(-2,35,-4,LEAVES:3)
Block(-2,35,-3,LEAVES:3)
Block(-2,35,-2,LEAVES:3)
Block(-2,35,-1,LOG:3)
Block(-2,35,0,LOG:3)
Block(-2,35,1,VINE:13)
Block(-2,36,-8,LEAVES:3)
Block(-2,36,-7,LEAVES:3)
Block(-2,36,-6,LEAVES:3)
Block(-2,36,-5,LEAVES:3)
Block(-2,36,-4,LEAVES:3)
Block(-2,36,-3,LEAVES:3)
Block(-2,36,-2,LEAVES:3)
Block(-2,36,-1,LOG:3)
Block(-2,36,0,LOG:3)
Block(-2,36,1,VINE:13)
Block(-2,37,-7,LEAVES:3)
Block(-2,37,-6,LEAVES:3)
Block(-2,37,-5,LEAVES:3)
Block(-2,37,-4,LEAVES:3)
Block(-2,37,-3,LEAVES:3)
Block(-2,37,-2,LEAVES:3)
Block(-2,37,-1,LOG:3)
Block(-2,37,0,LOG:3)
Block(-2,37,1,VINE:13)
Block(-2,38,-7,LEAVES:3)
Block(-2,38,-5,LEAVES:3)
Block(-2,38,-4,LEAVES:3)
Block(-2,38,-3,VINE:4)
Block(-2,38,-2,VINE:8)
Block(-2,38,-1,LOG:3)
Block(-2,38,0,LOG:3)
Block(-2,38,1,VINE:13)
Block(-2,38,2,LEAVES:3)
Block(-2,38,3,LEAVES:3)
Block(-2,38,4,LEAVES:3)
Block(-2,38,5,LEAVES:3)
Block(-2,38,6,LEAVES:3)
Block(-2,39,-8,LEAVES:3)
Block(-2,39,-7,LEAVES:3)
Block(-2,39,-6,LEAVES:3)
Block(-2,39,-2,VINE:8)
Block(-2,39,-1,LOG:3)
Block(-2,39,0,LOG:3)
Block(-2,39,1,LEAVES:3)
Block(-2,39,2,LEAVES:3)
Block(-2,39,3,LEAVES:3)
Block(-2,39,4,LEAVES:3)
Block(-2,39,5,LEAVES:3)
Block(-2,40,-9,LEAVES:3)
Block(-2,40,-8,LEAVES:3)
Block(-2,40,-7,LEAVES:3)
Block(-2,40,-6,LEAVES:3)
Block(-2,40,-5,LEAVES:3)
Block(-2,40,-4,LEAVES:3)
Block(-2,40,-2,VINE:8)
Block(-2,40,-1,LOG:3)
Block(-2,40,0,LOG:3)
Block(-2,40,1,VINE:1)
Block(-2,40,2,LEAVES:3)
Block(-2,40,3,LEAVES:3)
Block(-2,40,4,LEAVES:3)
Block(-2,41,-8,LEAVES:3)
Block(-2,41,-7,LEAVES:3)
Block(-2,41,-6,LEAVES:3)
Block(-2,41,-5,LEAVES:3)
Block(-2,41,-4,LEAVES:3)
Block(-2,41,-3,LEAVES:3)
Block(-2,41,-2,VINE:8)
Block(-2,41,-1,LOG:3)
Block(-2,41,0,LOG:3)
Block(-2,41,1,LEAVES:3)
Block(-2,41,2,VINE:8)
Block(-2,41,3,VINE:8)
Block(-2,42,-7,LEAVES:3)
Block(-2,42,-6,LEAVES:3)
Block(-2,42,-5,LEAVES:3)
Block(-2,42,-4,LEAVES:3)
Block(-2,42,-3,LEAVES:3)
Block(-2,42,-2,LEAVES:3)
Block(-2,42,-1,LOG:3)
Block(-2,42,0,LOG:3)
Block(-2,42,1,LEAVES:3)
Block(-2,42,2,LEAVES:3)
Block(-2,42,3,LEAVES:3)
Block(-2,43,-5,LEAVES:3)
Block(-2,43,-4,LEAVES:3)
Block(-2,43,-3,LEAVES:3)
Block(-2,43,-2,LEAVES:3)
Block(-2,43,-1,LOG:15)
Block(-2,43,0,LOG:15)
Block(-2,43,1,LEAVES:3)
Block(-2,43,2,LEAVES:3)
Block(-2,43,3,LEAVES:3)
Block(-2,43,4,LEAVES:3)
Block(-2,44,-5,VINE:1)
Block(-2,44,-4,LEAVES:3)
Block(-2,44,-3,LEAVES:3)
Block(-2,44,-2,LEAVES:3)
Block(-2,44,-1,LEAVES:3)
Block(-2,44,0,LEAVES:3)
Block(-2,44,1,LEAVES:3)
Block(-2,44,2,LEAVES:3)
Block(-2,44,3,LEAVES:3)
Block(-2,45,-3,LEAVES:3)
Block(-2,45,-2,LEAVES:3)
Block(-2,45,-1,LEAVES:3)
Block(-2,45,0,LEAVES:3)
Block(-2,45,1,LEAVES:3)
Block(-2,45,2,LEAVES:3)
Block(-1,0,-2,LOG:3)
Block(-1,0,-1,LOG:3)
Block(-1,0,0,LOG:3)
Block(-1,0,1,LOG:3)
Block(-1,1,-2,LOG:3)
Block(-1,1,-1,LOG:3)
Block(-1,1,0,LOG:3)
Block(-1,1,1,LOG:3)
Block(-1,2,-2,LOG:3)
Block(-1,2,-1,LOG:3)
Block(-1,2,0,LOG:3)
Block(-1,2,1,LOG:3)
Block(-1,3,-2,LOG:3)
Block(-1,3,-1,LOG:3)
Block(-1,3,0,LOG:3)
Block(-1,3,1,LOG:3)
Block(-1,4,-2,LOG:3)
Block(-1,4,-1,LOG:3)
Block(-1,4,0,LOG:3)
Block(-1,4,1,LOG:3)
Block(-1,5,-2,LOG:3)
Block(-1,5,-1,LOG:3)
Block(-1,5,0,LOG:3)
Block(-1,5,1,LOG:3)
Block(-1,6,-2,LOG:3)
Block(-1,6,-1,LOG:3)
Block(-1,6,0,LOG:3)
Block(-1,6,1,LOG:3)
Block(-1,7,-2,LOG:3)
Block(-1,7,-1,LOG:3)
Block(-1,7,0,LOG:3)
Block(-1,7,1,LOG:3)
Block(-1,7,2,LEAVES:3)
Block(-1,7,3,LEAVES:3)
Block(-1,8,-2,LOG:3)
Block(-1,8,-1,LOG:3)
Block(-1,8,0,LOG:3)
Block(-1,8,1,LOG:3)
Block(-1,8,2,LEAVES:3)
Block(-1,8,3,LEAVES:3)
Block(-1,8,4,LEAVES:3)
Block(-1,9,-2,LOG:3)
Block(-1,9,-1,LOG:3)
Block(-1,9,0,LOG:3)
Block(-1,9,1,LOG:3)
Block(-1,9,2,LEAVES:3)
Block(-1,9,3,LEAVES:3)
Block(-1,9,4,VINE:4)
Block(-1,10,-2,LOG:3)
Block(-1,10,-1,LOG:3)
Block(-1,10,0,LOG:3)
Block(-1,10,1,LOG:3)
Block(-1,10,3,VINE:8)
Block(-1,11,-2,LOG:3)
Block(-1,11,-1,LOG:3)
Block(-1,11,0,LOG:3)
Block(-1,11,1,LOG:3)
Block(-1,12,-2,LOG:3)
Block(-1,12,-1,LOG:3)
Block(-1,12,0,LOG:3)
Block(-1,12,1,LOG:3)
Block(-1,13,-2,LOG:3)
Block(-1,13,-1,LOG:3)
Block(-1,13,0,LOG:3)
Block(-1,13,1,LOG:3)
Block(-1,14,-2,LOG:3)
Block(-1,14,-1,LOG:3)
Block(-1,14,0,LOG:3)
Block(-1,14,1,LOG:3)
Block(-1,15,-2,LOG:3)
Block(-1,15,-1,LOG:3)
Block(-1,15,0,LOG:3)
Block(-1,15,1,LOG:3)
Block(-1,16,-2,LOG:3)
Block(-1,16,-1,LOG:3)
Block(-1,16,0,LOG:3)
Block(-1,16,1,LOG:3)
Block(-1,17,-2,LOG:3)
Block(-1,17,-1,LOG:3)
Block(-1,17,0,LOG:3)
Block(-1,17,1,LOG:3)
Block(-1,18,-4,VINE:2)
Block(-1,18,-3,LEAVES:3)
Block(-1,18,-2,LOG:3)
Block(-1,18,-1,LOG:3)
Block(-1,18,0,LOG:3)
Block(-1,18,1,LOG:3)
Block(-1,19,-4,LEAVES:3)
Block(-1,19,-3,LEAVES:3)
Block(-1,19,-2,LOG:3)
Block(-1,19,-1,LOG:3)
Block(-1,19,0,LOG:3)
Block(-1,19,1,LOG:3)
Block(-1,20,-5,LEAVES:3)
Block(-1,20,-4,LEAVES:3)
Block(-1,20,-3,LEAVES:3)
Block(-1,20,-2,LOG:3)
Block(-1,20,-1,LOG:3)
Block(-1,20,0,LOG:3)
Block(-1,20,1,LOG:3)
Block(-1,20,2,LEAVES:3)
Block(-1,21,-4,LEAVES:3)
Block(-1,21,-3,LEAVES:3)
Block(-1,21,-2,LOG:3)
Block(-1,21,-1,LOG:3)
Block(-1,21,0,LOG:3)
Block(-1,21,1,LOG:3)
Block(-1,22,-2,LOG:3)
Block(-1,22,-1,LOG:3)
Block(-1,22,0,LOG:3)
Block(-1,22,1,LOG:3)
Block(-1,23,-2,LOG:3)
Block(-1,23,-1,LOG:3)
Block(-1,23,0,LOG:3)
Block(-1,23,1,LOG:3)
Block(-1,24,-2,LOG:3)
Block(-1,24,-1,LOG:3)
Block(-1,24,0,LOG:3)
Block(-1,24,1,LOG:3)
Block(-1,25,-3,VINE:1)
Block(-1,25,-2,LOG:3)
Block(-1,25,-1,LOG:3)
Block(-1,25,0,LOG:3)
Block(-1,25,1,LOG:3)
Block(-1,26,-3,VINE:1)
Block(-1,26,-2,LOG:3)
Block(-1,26,-1,LOG:3)
Block(-1,26,0,LOG:3)
Block(-1,26,1,LOG:3)
Block(-1,26,2,VINE:2)
Block(-1,27,-3,VINE:1)
Block(-1,27,-2,LOG:3)
Block(-1,27,-1,LOG:3)
Block(-1,27,0,LOG:3)
Block(-1,27,1,LOG:3)
Block(-1,27,2,VINE:2)
Block(-1,28,-2,LOG:3)
Block(-1,28,-1,LOG:3)
Block(-1,28,0,LOG:3)
Block(-1,28,1,LOG:3)
Block(-1,28,2,VINE:2)
Block(-1,28,3,VINE:1)
Block(-1,29,-3,LEAVES:3)
Block(-1,29,-2,LOG:3)
Block(-1,29,-1,LOG:3)
Block(-1,29,0,LOG:3)
Block(-1,29,1,LOG:3)
Block(-1,29,2,VINE:2)
Block(-1,29,3,VINE:1)
Block(-1,30,-6,LEAVES:3)
Block(-1,30,-5,LEAVES:3)
Block(-1,30,-4,LEAVES:3)
Block(-1,30,-3,LEAVES:3)
Block(-1,30,-2,LOG:3)
Block(-1,30,-1,LOG:3)
Block(-1,30,0,LOG:3)
Block(-1,30,1,LOG:3)
Block(-1,30,2,VINE:2)
Block(-1,30,3,VINE:1)
Block(-1,31,-7,LEAVES:3)
Block(-1,31,-6,LEAVES:3)
Block(-1,31,-5,LEAVES:3)
Block(-1,31,-4,LEAVES:3)
Block(-1,31,-3,LEAVES:3)
Block(-1,31,-2,LOG:3)
Block(-1,31,-1,LOG:3)
Block(-1,31,0,LOG:3)
Block(-1,31,1,LOG:3)
Block(-1,31,2,LEAVES:3)
Block(-1,31,3,VINE:1)
Block(-1,32,-8,LEAVES:3)
Block(-1,32,-7,LEAVES:3)
Block(-1,32,-6,LEAVES:3)
Block(-1,32,-5,LOG:15)
Block(-1,32,-4,LEAVES:3)
Block(-1,32,-3,LEAVES:3)
Block(-1,32,-2,LOG:3)
Block(-1,32,-1,LOG:3)
Block(-1,32,0,LOG:3)
Block(-1,32,1,LOG:3)
Block(-1,32,3,VINE:1)
Block(-1,33,-8,LEAVES:3)
Block(-1,33,-7,LEAVES:3)
Block(-1,33,-6,LEAVES:3)
Block(-1,33,-5,LEAVES:3)
Block(-1,33,-4,LOG:11)
Block(-1,33,-3,LOG:11)
Block(-1,33,-2,LOG:3)
Block(-1,33,-1,LOG:3)
Block(-1,33,0,LOG:3)
Block(-1,33,1,LOG:3)
Block(-1,33,3,VINE:1)
Block(-1,34,-8,LEAVES:3)
Block(-1,34,-7,LEAVES:3)
Block(-1,34,-6,LEAVES:3)
Block(-1,34,-5,LEAVES:3)
Block(-1,34,-4,LEAVES:3)
Block(-1,34,-3,LEAVES:3)
Block(-1,34,-2,LOG:3)
Block(-1,34,-1,LOG:3)
Block(-1,34,0,LOG:3)
Block(-1,34,1,LOG:3)
Block(-1,34,3,VINE:1)
Block(-1,35,-9,LEAVES:3)
Block(-1,35,-8,LEAVES:3)
Block(-1,35,-7,LEAVES:3)
Block(-1,35,-6,LOG:15)
Block(-1,35,-5,LOG:11)
Block(-1,35,-4,LEAVES:3)
Block(-1,35,-3,LEAVES:3)
Block(-1,35,-2,LOG:3)
Block(-1,35,-1,LOG:3)
Block(-1,35,0,LOG:3)
Block(-1,35,1,LOG:3)
Block(-1,35,3,VINE:1)
Block(-1,36,-9,LEAVES:3)
Block(-1,36,-8,LEAVES:3)
Block(-1,36,-7,LEAVES:3)
Block(-1,36,-6,LEAVES:3)
Block(-1,36,-5,LEAVES:3)
Block(-1,36,-4,LOG:11)
Block(-1,36,-3,LOG:11)
Block(-1,36,-2,LOG:3)
Block(-1,36,-1,LOG:3)
Block(-1,36,0,LOG:3)
Block(-1,36,1,LOG:3)
Block(-1,36,3,VINE:1)
Block(-1,36,5,LEAVES:3)
Block(-1,37,-8,LEAVES:3)
Block(-1,37,-7,LEAVES:3)
Block(-1,37,-6,LEAVES:3)
Block(-1,37,-5,LEAVES:3)
Block(-1,37,-4,LEAVES:3)
Block(-1,37,-3,LEAVES:3)
Block(-1,37,-2,LOG:3)
Block(-1,37,-1,LOG:3)
Block(-1,37,0,LOG:3)
Block(-1,37,1,LOG:3)
Block(-1,37,2,LEAVES:3)
Block(-1,37,3,VINE:1)
Block(-1,37,4,LEAVES:3)
Block(-1,37,5,LEAVES:3)
Block(-1,37,6,LEAVES:3)
Block(-1,38,-8,LEAVES:3)
Block(-1,38,-4,LEAVES:3)
Block(-1,38,-3,VINE:1)
Block(-1,38,-2,LOG:3)
Block(-1,38,-1,LOG:3)
Block(-1,38,0,LOG:3)
Block(-1,38,1,LOG:3)
Block(-1,38,2,LEAVES:3)
Block(-1,38,3,LEAVES:3)
Block(-1,38,4,LEAVES:3)
Block(-1,38,5,LEAVES:3)
Block(-1,38,6,LEAVES:3)
Block(-1,38,7,LEAVES:3)
Block(-1,39,-9,LEAVES:3)
Block(-1,39,-8,LEAVES:3)
Block(-1,39,-7,LEAVES:3)
Block(-1,39,-6,LEAVES:3)
Block(-1,39,-5,LEAVES:3)
Block(-1,39,-3,VINE:1)
Block(-1,39,-2,LOG:3)
Block(-1,39,-1,LOG:3)
Block(-1,39,0,LOG:3)
Block(-1,39,1,LOG:3)
Block(-1,39,2,LEAVES:3)
Block(-1,39,3,LEAVES:3)
Block(-1,39,4,LEAVES:3)
Block(-1,39,5,LEAVES:3)
Block(-1,39,6,LEAVES:3)
Block(-1,40,-10,LEAVES:3)
Block(-1,40,-9,LEAVES:3)
Block(-1,40,-8,LEAVES:3)
Block(-1,40,-7,LEAVES:3)
Block(-1,40,-6,LEAVES:3)
Block(-1,40,-5,LEAVES:3)
Block(-1,40,-4,LEAVES:3)
Block(-1,40,-3,VINE:1)
Block(-1,40,-2,LOG:3)
Block(-1,40,-1,LOG:3)
Block(-1,40,0,LOG:3)
Block(-1,40,1,LOG:3)
Block(-1,40,2,LEAVES:3)
Block(-1,40,3,LEAVES:3)
Block(-1,40,4,LEAVES:3)
Block(-1,40,5,LEAVES:3)
Block(-1,41,-9,LEAVES:3)
Block(-1,41,-8,LEAVES:3)
Block(-1,41,-7,LEAVES:3)
Block(-1,41,-6,LEAVES:3)
Block(-1,41,-5,LEAVES:3)
Block(-1,41,-4,LEAVES:3)
Block(-1,41,-3,LEAVES:3)
Block(-1,41,-2,LOG:3)
Block(-1,41,-1,LOG:3)
Block(-1,41,0,LOG:3)
Block(-1,41,1,LOG:3)
Block(-1,41,2,LEAVES:3)
Block(-1,41,3,LEAVES:3)
Block(-1,41,4,VINE:4)
Block(-1,42,-8,LEAVES:3)
Block(-1,42,-7,LEAVES:3)
Block(-1,42,-6,LEAVES:3)
Block(-1,42,-5,LEAVES:3)
Block(-1,42,-4,LEAVES:3)
Block(-1,42,-3,LOG:11)
Block(-1,42,-2,LOG:3)
Block(-1,42,-1,LOG:3)
Block(-1,42,0,LOG:3)
Block(-1,42,1,LOG:3)
Block(-1,42,2,LEAVES:3)
Block(-1,42,3,LEAVES:3)
Block(-1,42,4,LEAVES:3)
Block(-1,43,-6,LEAVES:3)
Block(-1,43,-5,LEAVES:3)
Block(-1,43,-4,LEAVES:3)
Block(-1,43,-3,LEAVES:3)
Block(-1,43,-2,LOG:11)
Block(-1,43,-1,LOG:11)
Block(-1,43,0,LOG:15)
Block(-1,43,1,LOG:15)
Block(-1,43,2,LEAVES:3)
Block(-1,43,3,LEAVES:3)
Block(-1,43,4,LEAVES:3)
Block(-1,44,-5,VINE:9)
Block(-1,44,-4,LEAVES:3)
Block(-1,44,-3,LEAVES:3)
Block(-1,44,-2,LEAVES:3)
Block(-1,44,-1,LEAVES:3)
Block(-1,44,0,LEAVES:3)
Block(-1,44,1,LEAVES:3)
Block(-1,44,2,LEAVES:3)
Block(-1,44,3,LEAVES:3)
Block(-1,45,-3,LEAVES:3)
Block(-1,45,-2,LEAVES:3)
Block(-1,45,-1,LEAVES:3)
Block(-1,45,0,LEAVES:3)
Block(-1,45,1,LEAVES:3)
Block(-1,45,2,LEAVES:3)
Block(0,0,-2,LOG:3)
Block(0,0,-1,LOG:3)
Block(0,0,0,LOG:3)
Block(0,0,1,LOG:3)
Block(0,1,-2,LOG:3)
Block(0,1,-1,LOG:3)
Block(0,1,0,LOG:3)
Block(0,1,1,LOG:3)
Block(0,2,-2,LOG:3)
Block(0,2,-1,LOG:3)
Block(0,2,0,LOG:3)
Block(0,2,1,LOG:3)
Block(0,3,-2,LOG:3)
Block(0,3,-1,LOG:3)
Block(0,3,0,LOG:3)
Block(0,3,1,LOG:3)
Block(0,4,-2,LOG:3)
Block(0,4,-1,LOG:3)
Block(0,4,0,LOG:3)
Block(0,4,1,LOG:3)
Block(0,5,-3,VINE:1)
Block(0,5,-2,LOG:3)
Block(0,5,-1,LOG:3)
Block(0,5,0,LOG:3)
Block(0,5,1,LOG:3)
Block(0,6,-3,VINE:1)
Block(0,6,-2,LOG:3)
Block(0,6,-1,LOG:3)
Block(0,6,0,LOG:3)
Block(0,6,1,LOG:3)
Block(0,6,2,LEAVES:3)
Block(0,6,3,LEAVES:3)
Block(0,7,-3,VINE:1)
Block(0,7,-2,LOG:3)
Block(0,7,-1,LOG:3)
Block(0,7,0,LOG:3)
Block(0,7,1,LOG:3)
Block(0,7,2,LEAVES:3)
Block(0,7,3,LEAVES:3)
Block(0,7,4,LEAVES:3)
Block(0,8,-3,VINE:1)
Block(0,8,-2,LOG:3)
Block(0,8,-1,LOG:3)
Block(0,8,0,LOG:3)
Block(0,8,1,LOG:3)
Block(0,8,2,LEAVES:3)
Block(0,8,3,LEAVES:3)
Block(0,8,4,LEAVES:3)
Block(0,8,5,LEAVES:3)
Block(0,9,-3,VINE:1)
Block(0,9,-2,LOG:3)
Block(0,9,-1,LOG:3)
Block(0,9,0,LOG:3)
Block(0,9,1,LOG:3)
Block(0,9,2,LEAVES:3)
Block(0,9,3,LEAVES:3)
Block(0,9,4,LEAVES:3)
Block(0,10,-2,LOG:3)
Block(0,10,-1,LOG:3)
Block(0,10,0,LOG:3)
Block(0,10,1,LOG:3)
Block(0,10,2,VINE:8)
Block(0,10,3,LEAVES:3)
Block(0,11,-2,LOG:3)
Block(0,11,-1,LOG:3)
Block(0,11,0,LOG:3)
Block(0,11,1,LOG:3)
Block(0,12,-2,LOG:3)
Block(0,12,-1,LOG:3)
Block(0,12,0,LOG:3)
Block(0,12,1,LOG:3)
Block(0,13,-2,LOG:3)
Block(0,13,-1,LOG:3)
Block(0,13,0,LOG:3)
Block(0,13,1,LOG:3)
Block(0,14,-2,LOG:3)
Block(0,14,-1,LOG:3)
Block(0,14,0,LOG:3)
Block(0,14,1,LOG:3)
Block(0,15,-2,LOG:3)
Block(0,15,-1,LOG:3)
Block(0,15,0,LOG:3)
Block(0,15,1,LOG:3)
Block(0,16,-2,LOG:3)
Block(0,16,-1,LOG:3)
Block(0,16,0,LOG:3)
Block(0,16,1,LOG:3)
Block(0,17,-2,LOG:3)
Block(0,17,-1,LOG:3)
Block(0,17,0,LOG:3)
Block(0,17,1,LOG:3)
Block(0,18,-2,LOG:3)
Block(0,18,-1,LOG:3)
Block(0,18,0,LOG:3)
Block(0,18,1,LOG:3)
Block(0,19,-3,LEAVES:3)
Block(0,19,-2,LOG:3)
Block(0,19,-1,LOG:3)
Block(0,19,0,LOG:3)
Block(0,19,1,LOG:3)
Block(0,20,-4,LEAVES:3)
Block(0,20,-3,LEAVES:3)
Block(0,20,-2,LOG:3)
Block(0,20,-1,LOG:3)
Block(0,20,0,LOG:3)
Block(0,20,1,LOG:3)
Block(0,21,-3,LEAVES:3)
Block(0,21,-2,LOG:3)
Block(0,21,-1,LOG:3)
Block(0,21,0,LOG:3)
Block(0,21,1,LOG:3)
Block(0,22,-2,LOG:3)
Block(0,22,-1,LOG:3)
Block(0,22,0,LOG:3)
Block(0,22,1,LOG:3)
Block(0,23,-3,VINE:1)
Block(0,23,-2,LOG:3)
Block(0,23,-1,LOG:3)
Block(0,23,0,LOG:3)
Block(0,23,1,LOG:3)
Block(0,24,-3,VINE:1)
Block(0,24,-2,LOG:3)
Block(0,24,-1,LOG:3)
Block(0,24,0,LOG:3)
Block(0,24,1,LOG:3)
Block(0,24,2,VINE:4)
Block(0,25,-3,VINE:1)
Block(0,25,-2,LOG:3)
Block(0,25,-1,LOG:3)
Block(0,25,0,LOG:3)
Block(0,25,1,LOG:3)
Block(0,25,2,VINE:4)
Block(0,26,-2,LOG:3)
Block(0,26,-1,LOG:3)
Block(0,26,0,LOG:3)
Block(0,26,1,LOG:3)
Block(0,26,2,VINE:4)
Block(0,27,-2,LOG:3)
Block(0,27,-1,LOG:3)
Block(0,27,0,LOG:3)
Block(0,27,1,LOG:3)
Block(0,27,2,VINE:4)
Block(0,28,-2,LOG:3)
Block(0,28,-1,LOG:3)
Block(0,28,0,LOG:3)
Block(0,28,1,LOG:3)
Block(0,28,2,VINE:4)
Block(0,29,-4,LEAVES:3)
Block(0,29,-3,LEAVES:3)
Block(0,29,-2,LOG:3)
Block(0,29,-1,LOG:3)
Block(0,29,0,LOG:3)
Block(0,29,1,LOG:3)
Block(0,29,2,VINE:4)
Block(0,30,-5,LEAVES:3)
Block(0,30,-4,LEAVES:3)
Block(0,30,-3,LEAVES:3)
Block(0,30,-2,LOG:3)
Block(0,30,-1,LOG:3)
Block(0,30,0,LOG:3)
Block(0,30,1,LOG:3)
Block(0,30,2,VINE:4)
Block(0,31,-7,LEAVES:3)
Block(0,31,-6,LEAVES:3)
Block(0,31,-5,LEAVES:3)
Block(0,31,-4,LEAVES:3)
Block(0,31,-3,LEAVES:3)
Block(0,31,-2,LOG:3)
Block(0,31,-1,LOG:3)
Block(0,31,0,LOG:3)
Block(0,31,1,LOG:3)
Block(0,31,2,VINE:4)
Block(0,32,-8,LEAVES:3)
Block(0,32,-7,LEAVES:3)
Block(0,32,-6,LEAVES:3)
Block(0,32,-5,LEAVES:3)
Block(0,32,-4,LEAVES:3)
Block(0,32,-3,LEAVES:3)
Block(0,32,-2,LOG:3)
Block(0,32,-1,LOG:3)
Block(0,32,0,LOG:3)
Block(0,32,1,LOG:3)
Block(0,32,2,VINE:4)
Block(0,33,-7,LEAVES:3)
Block(0,33,-6,LEAVES:3)
Block(0,33,-5,LEAVES:3)
Block(0,33,-4,LEAVES:3)
Block(0,33,-3,LEAVES:3)
Block(0,33,-2,LOG:3)
Block(0,33,-1,LOG:3)
Block(0,33,0,LOG:3)
Block(0,33,1,LOG:3)
Block(0,33,2,VINE:4)
Block(0,34,-8,LEAVES:3)
Block(0,34,-7,LEAVES:3)
Block(0,34,-6,LEAVES:3)
Block(0,34,-5,LEAVES:3)
Block(0,34,-4,LEAVES:3)
Block(0,34,-3,LEAVES:3)
Block(0,34,-2,LOG:3)
Block(0,34,-1,LOG:3)
Block(0,34,0,LOG:3)
Block(0,34,1,LOG:3)
Block(0,34,2,VINE:4)
Block(0,35,-9,LEAVES:3)
Block(0,35,-8,LEAVES:3)
Block(0,35,-7,LEAVES:3)
Block(0,35,-6,LEAVES:3)
Block(0,35,-5,LEAVES:3)
Block(0,35,-4,LEAVES:3)
Block(0,35,-3,LEAVES:3)
Block(0,35,-2,LOG:3)
Block(0,35,-1,LOG:3)
Block(0,35,0,LOG:3)
Block(0,35,1,LOG:3)
Block(0,35,2,VINE:4)
Block(0,36,-8,LEAVES:3)
Block(0,36,-7,LEAVES:3)
Block(0,36,-6,LEAVES:3)
Block(0,36,-5,LEAVES:3)
Block(0,36,-4,LEAVES:3)
Block(0,36,-3,LEAVES:3)
Block(0,36,-2,LOG:3)
Block(0,36,-1,LOG:3)
Block(0,36,0,LOG:3)
Block(0,36,1,LOG:3)
Block(0,36,2,VINE:4)
Block(0,36,6,LEAVES:3)
Block(0,37,-7,LEAVES:3)
Block(0,37,-6,LEAVES:3)
Block(0,37,-5,LEAVES:3)
Block(0,37,-4,LEAVES:3)
Block(0,37,-3,LEAVES:3)
Block(0,37,-2,LOG:3)
Block(0,37,-1,LOG:3)
Block(0,37,0,LOG:3)
Block(0,37,1,LOG:3)
Block(0,37,2,LEAVES:3)
Block(0,37,3,LEAVES:3)
Block(0,37,4,LEAVES:3)
Block(0,37,5,LEAVES:3)
Block(0,37,6,LEAVES:3)
Block(0,37,7,LEAVES:3)
Block(0,38,-7,LEAVES:3)
Block(0,38,-6,LEAVES:3)
Block(0,38,-5,LEAVES:3)
Block(0,38,-4,LEAVES:3)
Block(0,38,-2,LOG:3)
Block(0,38,-1,LOG:3)
Block(0,38,0,LOG:3)
Block(0,38,1,LOG:3)
Block(0,38,2,LEAVES:3)
Block(0,38,3,LEAVES:3)
Block(0,38,4,LEAVES:3)
Block(0,38,5,LEAVES:3)
Block(0,38,6,LEAVES:3)
Block(0,38,7,LEAVES:3)
Block(0,38,8,LEAVES:3)
Block(0,39,-10,LEAVES:3)
Block(0,39,-9,LEAVES:3)
Block(0,39,-8,LEAVES:3)
Block(0,39,-7,LEAVES:3)
Block(0,39,-6,LEAVES:3)
Block(0,39,-5,LEAVES:3)
Block(0,39,-2,LOG:3)
Block(0,39,-1,LOG:3)
Block(0,39,0,LOG:3)
Block(0,39,1,LOG:3)
Block(0,39,2,LOG:11)
Block(0,39,3,LOG:11)
Block(0,39,4,LEAVES:3)
Block(0,39,5,LEAVES:3)
Block(0,39,6,LEAVES:3)
Block(0,39,7,LEAVES:3)
Block(0,40,-11,LEAVES:3)
Block(0,40,-10,LEAVES:3)
Block(0,40,-9,LEAVES:3)
Block(0,40,-8,LEAVES:3)
Block(0,40,-7,LOG:15)
Block(0,40,-6,LEAVES:3)
Block(0,40,-5,LEAVES:3)
Block(0,40,-4,LEAVES:3)
Block(0,40,-3,LEAVES:3)
Block(0,40,-2,LOG:3)
Block(0,40,-1,LOG:3)
Block(0,40,0,LOG:3)
Block(0,40,1,LOG:3)
Block(0,40,2,LEAVES:3)
Block(0,40,3,LEAVES:3)
Block(0,40,4,LEAVES:3)
Block(0,40,5,LEAVES:3)
Block(0,40,6,LEAVES:3)
Block(0,41,-9,LEAVES:3)
Block(0,41,-8,LEAVES:3)
Block(0,41,-7,LEAVES:3)
Block(0,41,-6,LOG:11)
Block(0,41,-5,LOG:11)
Block(0,41,-4,LEAVES:3)
Block(0,41,-3,LEAVES:3)
Block(0,41,-2,LOG:3)
Block(0,41,-1,LOG:3)
Block(0,41,0,LOG:3)
Block(0,41,1,LOG:3)
Block(0,41,2,LEAVES:3)
Block(0,41,3,LEAVES:3)
Block(0,42,-8,LEAVES:3)
Block(0,42,-7,LEAVES:3)
Block(0,42,-6,LEAVES:3)
Block(0,42,-5,LEAVES:3)
Block(0,42,-4,LOG:11)
Block(0,42,-3,LEAVES:3)
Block(0,42,-2,LOG:3)
Block(0,42,-1,LOG:3)
Block(0,42,0,LOG:3)
Block(0,42,1,LOG:3)
Block(0,42,2,LEAVES:3)
Block(0,42,3,LEAVES:3)
Block(0,42,4,LEAVES:3)
Block(0,43,-7,LEAVES:3)
Block(0,43,-6,LEAVES:3)
Block(0,43,-5,LEAVES:3)
Block(0,43,-4,LEAVES:3)
Block(0,43,-3,LEAVES:3)
Block(0,43,-2,LOG:15)
Block(0,43,-1,LOG:7)
Block(0,43,0,LOG:15)
Block(0,43,1,LOG:15)
Block(0,43,2,LEAVES:3)
Block(0,43,3,LEAVES:3)
Block(0,43,4,LEAVES:3)
Block(0,44,-6,VINE:1)
Block(0,44,-5,LEAVES:3)
Block(0,44,-4,LEAVES:3)
Block(0,44,-3,LEAVES:3)
Block(0,44,-2,LEAVES:3)
Block(0,44,-1,LEAVES:3)
Block(0,44,0,LEAVES:3)
Block(0,44,1,LEAVES:3)
Block(0,44,2,LEAVES:3)
Block(0,44,3,LEAVES:3)
Block(0,45,-3,LEAVES:3)
Block(0,45,-2,LEAVES:3)
Block(0,45,-1,LEAVES:3)
Block(0,45,0,LEAVES:3)
Block(0,45,1,LEAVES:3)
Block(0,45,2,LEAVES:3)
Block(1,0,-1,LOG:3)
Block(1,0,0,LOG:3)
Block(1,1,-1,LOG:3)
Block(1,1,0,LOG:3)
Block(1,2,-1,LOG:3)
Block(1,2,0,LOG:3)
Block(1,3,-1,LOG:3)
Block(1,3,0,LOG:3)
Block(1,4,-1,LOG:3)
Block(1,4,0,LOG:3)
Block(1,5,-1,LOG:3)
Block(1,5,0,LOG:3)
Block(1,6,-1,LOG:3)
Block(1,6,0,LOG:3)
Block(1,6,1,LEAVES:3)
Block(1,6,2,LEAVES:3)
Block(1,6,3,LEAVES:3)
Block(1,6,4,LEAVES:3)
Block(1,7,-1,LOG:3)
Block(1,7,0,LOG:3)
Block(1,7,1,LEAVES:3)
Block(1,7,2,LEAVES:3)
Block(1,7,3,LEAVES:3)
Block(1,7,4,LEAVES:3)
Block(1,7,5,LEAVES:3)
Block(1,8,-1,LOG:3)
Block(1,8,0,LOG:3)
Block(1,8,1,LEAVES:3)
Block(1,8,2,LEAVES:3)
Block(1,8,3,LEAVES:3)
Block(1,8,4,LEAVES:3)
Block(1,8,5,LEAVES:3)
Block(1,8,6,LEAVES:3)
Block(1,9,-1,LOG:3)
Block(1,9,0,LOG:3)
Block(1,9,1,LEAVES:3)
Block(1,9,2,LEAVES:3)
Block(1,9,3,LEAVES:3)
Block(1,9,4,LEAVES:3)
Block(1,9,5,LEAVES:3)
Block(1,10,-1,LOG:3)
Block(1,10,0,LOG:3)
Block(1,10,1,LEAVES:3)
Block(1,10,2,LEAVES:3)
Block(1,10,3,LEAVES:3)
Block(1,10,4,LEAVES:3)
Block(1,11,-1,LOG:3)
Block(1,11,0,LOG:3)
Block(1,12,-1,LOG:3)
Block(1,12,0,LOG:3)
Block(1,13,-1,LOG:3)
Block(1,13,0,LOG:3)
Block(1,14,-1,LOG:3)
Block(1,14,0,LOG:3)
Block(1,15,-1,LOG:3)
Block(1,15,0,LOG:3)
Block(1,16,-1,LOG:3)
Block(1,16,0,LOG:3)
Block(1,17,-1,LOG:3)
Block(1,17,0,LOG:3)
Block(1,18,-1,LOG:3)
Block(1,18,0,LOG:3)
Block(1,19,-1,LOG:3)
Block(1,19,0,LOG:3)
Block(1,20,-3,LEAVES:3)
Block(1,20,-2,LEAVES:3)
Block(1,20,-1,LOG:3)
Block(1,20,0,LOG:3)
Block(1,21,-2,LEAVES:3)
Block(1,21,-1,LOG:3)
Block(1,21,0,LOG:3)
Block(1,22,-2,VINE:2)
Block(1,22,-1,LOG:3)
Block(1,22,0,LOG:3)
Block(1,23,-2,VINE:15)
Block(1,23,-1,LOG:3)
Block(1,23,0,LOG:3)
Block(1,24,-2,VINE:15)
Block(1,24,-1,LOG:3)
Block(1,24,0,LOG:3)
Block(1,25,-2,VINE:15)
Block(1,25,-1,LOG:3)
Block(1,25,0,LOG:3)
Block(1,25,1,VINE:4)
Block(1,26,-2,VINE:15)
Block(1,26,-1,LOG:3)
Block(1,26,0,LOG:3)
Block(1,26,1,VINE:5)
Block(1,27,-3,LEAVES:3)
Block(1,27,-2,VINE:15)
Block(1,27,-1,LOG:3)
Block(1,27,0,LOG:3)
Block(1,27,1,VINE:5)
Block(1,28,-4,LEAVES:3)
Block(1,28,-3,LEAVES:3)
Block(1,28,-2,LEAVES:3)
Block(1,28,-1,LOG:3)
Block(1,28,0,LOG:3)
Block(1,28,1,VINE:5)
Block(1,29,-5,LEAVES:3)
Block(1,29,-4,LEAVES:3)
Block(1,29,-3,LEAVES:3)
Block(1,29,-2,LEAVES:3)
Block(1,29,-1,LOG:3)
Block(1,29,0,LOG:3)
Block(1,29,1,VINE:7)
Block(1,30,-6,LEAVES:3)
Block(1,30,-5,LEAVES:3)
Block(1,30,-4,LEAVES:3)
Block(1,30,-3,LEAVES:3)
Block(1,30,-2,LOG:7)
Block(1,30,-1,LOG:3)
Block(1,30,0,LOG:3)
Block(1,30,1,VINE:7)
Block(1,31,-6,LEAVES:3)
Block(1,31,-5,LEAVES:3)
Block(1,31,-4,LEAVES:3)
Block(1,31,-3,LEAVES:3)
Block(1,31,-2,LEAVES:3)
Block(1,31,-1,LOG:3)
Block(1,31,0,LOG:3)
Block(1,31,1,VINE:7)
Block(1,32,-7,LEAVES:3)
Block(1,32,-6,LEAVES:3)
Block(1,32,-5,LEAVES:3)
Block(1,32,-4,LEAVES:3)
Block(1,32,-3,LEAVES:3)
Block(1,32,-1,LOG:3)
Block(1,32,0,LOG:3)
Block(1,32,1,VINE:7)
Block(1,33,-6,LEAVES:3)
Block(1,33,-5,LEAVES:3)
Block(1,33,-4,LEAVES:3)
Block(1,33,-3,LEAVES:3)
Block(1,33,-2,LEAVES:3)
Block(1,33,-1,LOG:3)
Block(1,33,0,LOG:3)
Block(1,33,1,VINE:7)
Block(1,34,-7,LEAVES:3)
Block(1,34,-6,LEAVES:3)
Block(1,34,-5,LEAVES:3)
Block(1,34,-4,LEAVES:3)
Block(1,34,-3,LEAVES:3)
Block(1,34,-1,LOG:3)
Block(1,34,0,LOG:3)
Block(1,34,1,VINE:7)
Block(1,35,-8,LEAVES:3)
Block(1,35,-7,LEAVES:3)
Block(1,35,-6,LEAVES:3)
Block(1,35,-5,LEAVES:3)
Block(1,35,-4,LEAVES:3)
Block(1,35,-3,LEAVES:3)
Block(1,35,-1,LOG:3)
Block(1,35,0,LOG:3)
Block(1,35,1,VINE:7)
Block(1,36,-7,LEAVES:3)
Block(1,36,-6,LEAVES:3)
Block(1,36,-5,LEAVES:3)
Block(1,36,-4,LEAVES:3)
Block(1,36,-3,LEAVES:3)
Block(1,36,-2,LEAVES:3)
Block(1,36,-1,LOG:3)
Block(1,36,0,LOG:3)
Block(1,36,1,VINE:7)
Block(1,36,5,LEAVES:3)
Block(1,36,6,LEAVES:3)
Block(1,36,7,LEAVES:3)
Block(1,37,-6,LEAVES:3)
Block(1,37,-5,LEAVES:3)
Block(1,37,-4,LEAVES:3)
Block(1,37,-3,LEAVES:3)
Block(1,37,-1,LOG:3)
Block(1,37,0,LOG:3)
Block(1,37,1,VINE:7)
Block(1,37,2,LEAVES:3)
Block(1,37,3,LEAVES:3)
Block(1,37,4,LEAVES:3)
Block(1,37,5,LEAVES:3)
Block(1,37,6,LEAVES:3)
Block(1,37,7,LEAVES:3)
Block(1,38,-7,LEAVES:3)
Block(1,38,-6,LEAVES:3)
Block(1,38,-4,VINE:6)
Block(1,38,-1,LOG:3)
Block(1,38,0,LOG:3)
Block(1,38,1,LEAVES:3)
Block(1,38,2,LEAVES:3)
Block(1,38,3,LEAVES:3)
Block(1,38,4,LOG:11)
Block(1,38,5,LOG:15)
Block(1,38,6,LEAVES:3)
Block(1,38,7,LEAVES:3)
Block(1,38,8,LEAVES:3)
Block(1,39,-9,LEAVES:3)
Block(1,39,-8,LEAVES:3)
Block(1,39,-7,LEAVES:3)
Block(1,39,-6,LEAVES:3)
Block(1,39,-5,LEAVES:3)
Block(1,39,-4,VINE:4)
Block(1,39,-1,LOG:3)
Block(1,39,0,LOG:3)
Block(1,39,1,LEAVES:3)
Block(1,39,2,LEAVES:3)
Block(1,39,3,LEAVES:3)
Block(1,39,4,LEAVES:3)
Block(1,39,5,LEAVES:3)
Block(1,39,6,LEAVES:3)
Block(1,39,7,LEAVES:3)
Block(1,40,-10,LEAVES:3)
Block(1,40,-9,LEAVES:3)
Block(1,40,-8,LEAVES:3)
Block(1,40,-7,LEAVES:3)
Block(1,40,-6,LEAVES:3)
Block(1,40,-5,LEAVES:3)
Block(1,40,-4,LEAVES:3)
Block(1,40,-3,LEAVES:3)
Block(1,40,-2,LEAVES:3)
Block(1,40,-1,LOG:3)
Block(1,40,0,LOG:3)
Block(1,40,1,LEAVES:3)
Block(1,40,2,LEAVES:3)
Block(1,40,3,LEAVES:3)
Block(1,40,4,LEAVES:3)
Block(1,40,5,LEAVES:3)
Block(1,41,-9,LEAVES:3)
Block(1,41,-8,LEAVES:3)
Block(1,41,-7,LEAVES:3)
Block(1,41,-6,LEAVES:3)
Block(1,41,-5,LEAVES:3)
Block(1,41,-4,LEAVES:3)
Block(1,41,-3,LEAVES:3)
Block(1,41,-2,LEAVES:3)
Block(1,41,-1,LOG:3)
Block(1,41,0,LOG:3)
Block(1,41,1,LEAVES:3)
Block(1,41,2,LEAVES:3)
Block(1,42,-7,LEAVES:3)
Block(1,42,-6,LEAVES:3)
Block(1,42,-5,LEAVES:3)
Block(1,42,-4,LEAVES:3)
Block(1,42,-3,LEAVES:3)
Block(1,42,-2,LOG:7)
Block(1,42,-1,LOG:3)
Block(1,42,0,LOG:3)
Block(1,42,1,LEAVES:3)
Block(1,42,2,LEAVES:3)
Block(1,42,3,LEAVES:3)
Block(1,43,-6,LEAVES:3)
Block(1,43,-5,LEAVES:3)
Block(1,43,-4,LEAVES:3)
Block(1,43,-3,LEAVES:3)
Block(1,43,-2,LEAVES:3)
Block(1,43,-1,LOG:7)
Block(1,43,0,LOG:15)
Block(1,43,1,LEAVES:3)
Block(1,43,2,LEAVES:3)
Block(1,43,3,LEAVES:3)
Block(1,43,4,LEAVES:3)
Block(1,44,-6,VINE:1)
Block(1,44,-5,LEAVES:3)
Block(1,44,-4,LEAVES:3)
Block(1,44,-3,LEAVES:3)
Block(1,44,-2,LEAVES:3)
Block(1,44,-1,LEAVES:3)
Block(1,44,0,LEAVES:3)
Block(1,44,1,LEAVES:3)
Block(1,44,2,LEAVES:3)
Block(1,45,-2,LEAVES:3)
Block(1,45,-1,LEAVES:3)
Block(1,45,0,LEAVES:3)
Block(1,45,1,LEAVES:3)
Block(1,45,2,LEAVES:3)
Block(2,4,4,VINE:2)
Block(2,5,4,VINE:2)
Block(2,6,-1,VINE:1)
Block(2,6,0,LEAVES:3)
Block(2,6,1,LEAVES:3)
Block(2,6,2,LEAVES:3)
Block(2,6,3,LEAVES:3)
Block(2,6,4,VINE:2)
Block(2,6,5,LEAVES:3)
Block(2,7,-1,LEAVES:3)
Block(2,7,0,LEAVES:3)
Block(2,7,1,LOG:3)
Block(2,7,2,LEAVES:3)
Block(2,7,3,LEAVES:3)
Block(2,7,4,LEAVES:3)
Block(2,7,5,LEAVES:3)
Block(2,7,6,LEAVES:3)
Block(2,8,-2,LEAVES:3)
Block(2,8,-1,LEAVES:3)
Block(2,8,0,LEAVES:3)
Block(2,8,1,LEAVES:3)
Block(2,8,2,LEAVES:3)
Block(2,8,3,LEAVES:3)
Block(2,8,4,LEAVES:3)
Block(2,8,5,LEAVES:3)
Block(2,8,6,LEAVES:3)
Block(2,8,7,LEAVES:3)
Block(2,9,-1,LEAVES:3)
Block(2,9,0,LEAVES:3)
Block(2,9,1,LEAVES:3)
Block(2,9,2,LEAVES:3)
Block(2,9,3,LEAVES:3)
Block(2,9,4,LEAVES:3)
Block(2,9,5,LEAVES:3)
Block(2,9,6,LEAVES:3)
Block(2,10,0,VINE:8)
Block(2,10,1,LEAVES:3)
Block(2,10,2,LEAVES:3)
Block(2,10,3,LEAVES:3)
Block(2,10,4,LEAVES:3)
Block(2,10,5,LEAVES:3)
Block(2,24,-3,VINE:1)
Block(2,25,-3,VINE:1)
Block(2,26,-3,VINE:1)
Block(2,26,-1,VINE:8)
Block(2,26,1,VINE:4)
Block(2,27,-3,VINE:1)
Block(2,27,-2,LEAVES:3)
Block(2,27,-1,VINE:8)
Block(2,27,1,VINE:4)
Block(2,28,-5,LEAVES:3)
Block(2,28,-4,LEAVES:3)
Block(2,28,-3,LEAVES:3)
Block(2,28,-2,LEAVES:3)
Block(2,28,-1,LEAVES:3)
Block(2,28,1,VINE:4)
Block(2,29,-6,LEAVES:3)
Block(2,29,-5,LEAVES:3)
Block(2,29,-4,LEAVES:3)
Block(2,29,-3,LEAVES:3)
Block(2,29,-2,LEAVES:3)
Block(2,29,-1,LEAVES:3)
Block(2,29,0,LEAVES:3)
Block(2,29,1,VINE:4)
Block(2,30,-7,LEAVES:3)
Block(2,30,-6,LEAVES:3)
Block(2,30,-5,LEAVES:3)
Block(2,30,-4,LEAVES:3)
Block(2,30,-3,LOG:7)
Block(2,30,-2,LEAVES:3)
Block(2,30,-1,LEAVES:3)
Block(2,30,0,LEAVES:3)
Block(2,30,1,LEAVES:3)
Block(2,31,-6,LEAVES:3)
Block(2,31,-5,LEAVES:3)
Block(2,31,-4,LEAVES:3)
Block(2,31,-3,LEAVES:3)
Block(2,31,-2,LEAVES:3)
Block(2,31,-1,LEAVES:3)
Block(2,31,0,LEAVES:3)
Block(2,32,-6,LEAVES:3)
Block(2,32,-5,LEAVES:3)
Block(2,32,-4,LEAVES:3)
Block(2,32,-3,LEAVES:3)
Block(2,32,-2,LEAVES:3)
Block(2,32,0,VINE:2)
Block(2,33,-5,LEAVES:3)
Block(2,33,-4,LEAVES:3)
Block(2,33,-3,LEAVES:3)
Block(2,33,-2,VINE:4)
Block(2,33,0,VINE:2)
Block(2,34,-2,VINE:4)
Block(2,34,0,VINE:2)
Block(2,35,-7,LEAVES:3)
Block(2,35,-6,LEAVES:3)
Block(2,35,-5,LEAVES:3)
Block(2,35,-4,LEAVES:3)
Block(2,35,-2,VINE:4)
Block(2,35,0,VINE:2)
Block(2,36,-6,VINE:11)
Block(2,36,-5,LEAVES:3)
Block(2,36,-4,LEAVES:3)
Block(2,36,-3,LEAVES:3)
Block(2,36,-2,VINE:4)
Block(2,36,0,VINE:2)
Block(2,36,5,LEAVES:3)
Block(2,36,6,LEAVES:3)
Block(2,37,-6,VINE:10)
Block(2,37,0,VINE:2)
Block(2,37,3,LEAVES:3)
Block(2,37,4,LEAVES:3)
Block(2,37,5,LEAVES:3)
Block(2,37,6,LEAVES:3)
Block(2,37,7,LEAVES:3)
Block(2,38,-6,VINE:8)
Block(2,38,0,VINE:2)
Block(2,38,2,LEAVES:3)
Block(2,38,3,LEAVES:3)
Block(2,38,4,LEAVES:3)
Block(2,38,5,LEAVES:3)
Block(2,38,6,LEAVES:3)
Block(2,38,7,LEAVES:3)
Block(2,38,8,LEAVES:3)
Block(2,39,-8,LEAVES:3)
Block(2,39,-7,LEAVES:3)
Block(2,39,-6,LEAVES:3)
Block(2,39,-5,LEAVES:3)
Block(2,39,-4,LEAVES:3)
Block(2,39,0,VINE:2)
Block(2,39,1,LEAVES:3)
Block(2,39,2,LEAVES:3)
Block(2,39,3,LEAVES:3)
Block(2,39,4,LEAVES:3)
Block(2,39,5,LEAVES:3)
Block(2,39,6,LEAVES:3)
Block(2,39,7,LEAVES:3)
Block(2,40,-9,LEAVES:3)
Block(2,40,-8,LEAVES:3)
Block(2,40,-7,LEAVES:3)
Block(2,40,-6,LEAVES:3)
Block(2,40,-5,LEAVES:3)
Block(2,40,-4,LEAVES:3)
Block(2,40,-3,LEAVES:3)
Block(2,40,-2,LEAVES:3)
Block(2,40,-1,LEAVES:3)
Block(2,40,0,LEAVES:3)
Block(2,40,2,LEAVES:3)
Block(2,40,3,LEAVES:3)
Block(2,40,4,LEAVES:3)
Block(2,40,5,LEAVES:3)
Block(2,40,6,LEAVES:3)
Block(2,41,-8,LEAVES:3)
Block(2,41,-7,LEAVES:3)
Block(2,41,-6,LEAVES:3)
Block(2,41,-5,LEAVES:3)
Block(2,41,-4,LEAVES:3)
Block(2,41,-3,LEAVES:3)
Block(2,41,-2,LEAVES:3)
Block(2,41,-1,LEAVES:3)
Block(2,41,0,LEAVES:3)
Block(2,41,1,LEAVES:3)
Block(2,42,-7,LEAVES:3)
Block(2,42,-6,LEAVES:3)
Block(2,42,-5,LEAVES:3)
Block(2,42,-4,LEAVES:3)
Block(2,42,-3,LOG:7)
Block(2,42,-2,LOG:7)
Block(2,42,-1,LOG:7)
Block(2,42,0,LEAVES:3)
Block(2,42,1,LEAVES:3)
Block(2,42,2,LEAVES:3)
Block(2,43,-6,LEAVES:3)
Block(2,43,-5,LEAVES:3)
Block(2,43,-4,LEAVES:3)
Block(2,43,-3,LEAVES:3)
Block(2,43,-2,LEAVES:3)
Block(2,43,-1,LEAVES:3)
Block(2,43,0,LEAVES:3)
Block(2,43,1,LEAVES:3)
Block(2,43,2,LEAVES:3)
Block(2,43,3,LEAVES:3)
Block(2,44,-5,LEAVES:3)
Block(2,44,-4,LEAVES:3)
Block(2,44,-3,LEAVES:3)
Block(2,44,-2,LEAVES:3)
Block(2,44,-1,LEAVES:3)
Block(2,44,0,LEAVES:3)
Block(2,44,1,LEAVES:3)
Block(2,44,2,LEAVES:3)
Block(2,44,3,VINE:4)
Block(2,45,-1,LEAVES:3)
Block(2,45,0,VINE:2)
Block(2,45,1,VINE:2)
Block(3,6,-1,LEAVES:3)
Block(3,6,0,LEAVES:3)
Block(3,6,1,LEAVES:3)
Block(3,6,2,LEAVES:3)
Block(3,6,3,LEAVES:3)
Block(3,6,4,LEAVES:3)
Block(3,7,-2,LEAVES:3)
Block(3,7,-1,LEAVES:3)
Block(3,7,0,LEAVES:3)
Block(3,7,1,LEAVES:3)
Block(3,7,2,LOG:3)
Block(3,7,3,LEAVES:3)
Block(3,7,4,LEAVES:3)
Block(3,7,5,LEAVES:3)
Block(3,8,-2,LEAVES:3)
Block(3,8,-1,LEAVES:3)
Block(3,8,0,LEAVES:3)
Block(3,8,1,LEAVES:3)
Block(3,8,2,LEAVES:3)
Block(3,8,3,LEAVES:3)
Block(3,8,4,LEAVES:3)
Block(3,8,5,LEAVES:3)
Block(3,8,6,LEAVES:3)
Block(3,9,-1,LEAVES:3)
Block(3,9,0,LEAVES:3)
Block(3,9,1,LEAVES:3)
Block(3,9,2,LEAVES:3)
Block(3,9,3,LEAVES:3)
Block(3,9,4,LEAVES:3)
Block(3,9,5,LEAVES:3)
Block(3,10,0,LEAVES:3)
Block(3,10,1,LEAVES:3)
Block(3,10,2,LEAVES:3)
Block(3,10,3,LEAVES:3)
Block(3,10,4,LEAVES:3)
Block(3,25,-2,VINE:4)
Block(3,26,-2,VINE:4)
Block(3,27,-5,LEAVES:3)
Block(3,27,-3,LEAVES:3)
Block(3,27,-2,VINE:4)
Block(3,27,-1,LEAVES:3)
Block(3,28,-6,LEAVES:3)
Block(3,28,-5,LEAVES:3)
Block(3,28,-4,LEAVES:3)
Block(3,28,-3,LEAVES:3)
Block(3,28,-2,LEAVES:3)
Block(3,28,-1,LEAVES:3)
Block(3,29,-6,LEAVES:3)
Block(3,29,-5,LEAVES:3)
Block(3,29,-4,LEAVES:3)
Block(3,29,-3,LOG:15)
Block(3,29,-2,LEAVES:3)
Block(3,29,-1,LEAVES:3)
Block(3,29,0,LEAVES:3)
Block(3,29,1,LEAVES:3)
Block(3,30,-6,LEAVES:3)
Block(3,30,-5,LEAVES:3)
Block(3,30,-4,LEAVES:3)
Block(3,30,-3,LEAVES:3)
Block(3,30,-2,LEAVES:3)
Block(3,30,-1,LEAVES:3)
Block(3,30,0,LEAVES:3)
Block(3,31,-5,LEAVES:3)
Block(3,31,-4,LEAVES:3)
Block(3,31,-3,LEAVES:3)
Block(3,31,-2,LEAVES:3)
Block(3,31,-1,LEAVES:3)
Block(3,32,-5,VINE:7)
Block(3,32,-4,VINE:2)
Block(3,32,-3,LEAVES:3)
Block(3,33,-5,VINE:7)
Block(3,33,-4,LEAVES:3)
Block(3,34,-5,VINE:7)
Block(3,35,-6,LEAVES:3)
Block(3,35,-5,VINE:7)
Block(3,36,-5,VINE:3)
Block(3,36,-4,LEAVES:3)
Block(3,37,4,LEAVES:3)
Block(3,37,5,LEAVES:3)
Block(3,37,6,LEAVES:3)
Block(3,38,-6,LEAVES:3)
Block(3,38,-4,LEAVES:3)
Block(3,38,3,LEAVES:3)
Block(3,38,4,LEAVES:3)
Block(3,38,5,LEAVES:3)
Block(3,38,6,LEAVES:3)
Block(3,38,7,LEAVES:3)
Block(3,39,-7,LEAVES:3)
Block(3,39,-6,LEAVES:3)
Block(3,39,-5,LEAVES:3)
Block(3,39,-4,LEAVES:3)
Block(3,39,-3,LEAVES:3)
Block(3,39,-2,LEAVES:3)
Block(3,39,-1,LEAVES:3)
Block(3,39,2,LEAVES:3)
Block(3,39,3,LEAVES:3)
Block(3,39,4,LEAVES:3)
Block(3,39,5,LEAVES:3)
Block(3,39,6,LEAVES:3)
Block(3,40,-8,LEAVES:3)
Block(3,40,-7,LEAVES:3)
Block(3,40,-6,LEAVES:3)
Block(3,40,-5,LEAVES:3)
Block(3,40,-4,LEAVES:3)
Block(3,40,-3,LEAVES:3)
Block(3,40,-2,LEAVES:3)
Block(3,40,-1,LEAVES:3)
Block(3,40,0,LEAVES:3)
Block(3,40,1,LEAVES:3)
Block(3,40,5,LEAVES:3)
Block(3,41,-7,LEAVES:3)
Block(3,41,-6,LEAVES:3)
Block(3,41,-5,LEAVES:3)
Block(3,41,-4,LOG:7)
Block(3,41,-3,LOG:7)
Block(3,41,-2,LEAVES:3)
Block(3,41,-1,LEAVES:3)
Block(3,41,0,LEAVES:3)
Block(3,41,1,LEAVES:3)
Block(3,42,-6,LEAVES:3)
Block(3,42,-5,LEAVES:3)
Block(3,42,-4,LEAVES:3)
Block(3,42,-3,LEAVES:3)
Block(3,42,-2,LEAVES:3)
Block(3,42,-1,LOG:7)
Block(3,42,0,LEAVES:3)
Block(3,42,1,LEAVES:3)
Block(3,42,2,LEAVES:3)
Block(3,43,-5,LEAVES:3)
Block(3,43,-4,LEAVES:3)
Block(3,43,-3,LEAVES:3)
Block(3,43,-2,LEAVES:3)
Block(3,43,-1,LEAVES:3)
Block(3,43,0,LEAVES:3)
Block(3,43,1,LEAVES:3)
Block(3,43,2,LEAVES:3)
Block(3,44,-3,LEAVES:3)
Block(3,44,-2,LEAVES:3)
Block(3,44,-1,LEAVES:3)
Block(3,44,0,LEAVES:3)
Block(3,44,1,LEAVES:3)
Block(3,44,2,VINE:6)
Block(4,3,-1,VINE:2)
Block(4,4,-1,VINE:2)
Block(4,5,-1,VINE:2)
Block(4,6,-1,VINE:2)
Block(4,6,0,LEAVES:3)
Block(4,6,1,LEAVES:3)
Block(4,6,2,LEAVES:3)
Block(4,6,3,LEAVES:3)
Block(4,7,-1,LEAVES:3)
Block(4,7,0,LEAVES:3)
Block(4,7,1,LEAVES:3)
Block(4,7,2,LEAVES:3)
Block(4,7,3,LEAVES:3)
Block(4,7,4,LEAVES:3)
Block(4,8,-2,LEAVES:3)
Block(4,8,-1,LEAVES:3)
Block(4,8,0,LEAVES:3)
Block(4,8,1,LEAVES:3)
Block(4,8,2,LEAVES:3)
Block(4,8,3,LEAVES:3)
Block(4,8,4,LEAVES:3)
Block(4,8,5,LEAVES:3)
Block(4,9,-1,LEAVES:3)
Block(4,9,0,LEAVES:3)
Block(4,9,1,LEAVES:3)
Block(4,9,2,LEAVES:3)
Block(4,9,3,LEAVES:3)
Block(4,9,4,LEAVES:3)
Block(4,10,1,LEAVES:3)
Block(4,10,2,LEAVES:3)
Block(4,10,3,LEAVES:3)
Block(4,10,4,VINE:4)
Block(4,27,-2,LEAVES:3)
Block(4,28,-5,LEAVES:3)
Block(4,28,-4,LEAVES:3)
Block(4,28,-3,LEAVES:3)
Block(4,28,-2,LEAVES:3)
Block(4,28,-1,LEAVES:3)
Block(4,29,-6,LEAVES:3)
Block(4,29,-5,LEAVES:3)
Block(4,29,-4,LEAVES:3)
Block(4,29,-3,LEAVES:3)
Block(4,29,-2,LEAVES:3)
Block(4,29,-1,LEAVES:3)
Block(4,29,0,LEAVES:3)
Block(4,30,-5,LEAVES:3)
Block(4,30,-4,LEAVES:3)
Block(4,30,-3,LEAVES:3)
Block(4,30,-2,LEAVES:3)
Block(4,30,-1,LEAVES:3)
Block(4,31,-4,LEAVES:3)
Block(4,31,-3,LEAVES:3)
Block(4,31,-2,LEAVES:3)
Block(4,38,-7,LEAVES:3)
Block(4,38,-6,LEAVES:3)
Block(4,38,-5,LEAVES:3)
Block(4,38,-4,LEAVES:3)
Block(4,38,-3,LEAVES:3)
Block(4,38,-2,LEAVES:3)
Block(4,38,-1,LEAVES:3)
Block(4,38,4,LEAVES:3)
Block(4,38,5,LEAVES:3)
Block(4,38,6,LEAVES:3)
Block(4,39,-8,LEAVES:3)
Block(4,39,-7,LEAVES:3)
Block(4,39,-6,LEAVES:3)
Block(4,39,-5,LEAVES:3)
Block(4,39,-4,LEAVES:3)
Block(4,39,-3,LEAVES:3)
Block(4,39,-2,LEAVES:3)
Block(4,39,-1,LEAVES:3)
Block(4,39,0,LEAVES:3)
Block(4,40,-9,LEAVES:3)
Block(4,40,-8,LEAVES:3)
Block(4,40,-7,LEAVES:3)
Block(4,40,-6,LEAVES:3)
Block(4,40,-5,LOG:15)
Block(4,40,-4,LEAVES:3)
Block(4,40,-3,LEAVES:3)
Block(4,40,-2,LEAVES:3)
Block(4,40,-1,LEAVES:3)
Block(4,40,0,LEAVES:3)
Block(4,40,1,LEAVES:3)
Block(4,41,-7,LEAVES:3)
Block(4,41,-6,LEAVES:3)
Block(4,41,-5,LEAVES:3)
Block(4,41,-4,LOG:7)
Block(4,41,-3,LOG:7)
Block(4,41,-2,LEAVES:3)
Block(4,41,-1,LOG:7)
Block(4,41,0,LEAVES:3)
Block(4,41,1,LEAVES:3)
Block(4,42,-7,LEAVES:3)
Block(4,42,-6,LEAVES:3)
Block(4,42,-5,LEAVES:3)
Block(4,42,-4,LEAVES:3)
Block(4,42,-3,LEAVES:3)
Block(4,42,-2,LEAVES:3)
Block(4,42,-1,LEAVES:3)
Block(4,42,0,LEAVES:3)
Block(4,42,1,LEAVES:3)
Block(4,43,-4,LEAVES:3)
Block(4,43,-3,LEAVES:3)
Block(4,43,-2,LEAVES:3)
Block(4,43,-1,LEAVES:3)
Block(4,43,0,LEAVES:3)
Block(4,43,1,LEAVES:3)
Block(4,44,-3,LEAVES:3)
Block(4,44,-2,LEAVES:3)
Block(4,44,0,LEAVES:3)
Block(4,44,1,VINE:6)
Block(5,6,1,LEAVES:3)
Block(5,7,0,LEAVES:3)
Block(5,7,1,LEAVES:3)
Block(5,7,2,LEAVES:3)
Block(5,7,3,LEAVES:3)
Block(5,8,-1,LEAVES:3)
Block(5,8,0,LEAVES:3)
Block(5,8,1,LEAVES:3)
Block(5,8,2,LEAVES:3)
Block(5,8,3,LEAVES:3)
Block(5,8,4,LEAVES:3)
Block(5,9,0,LEAVES:3)
Block(5,9,1,LEAVES:3)
Block(5,9,2,LEAVES:3)
Block(5,9,3,LEAVES:3)
Block(5,10,1,LEAVES:3)
Block(5,10,2,VINE:4)
Block(5,10,3,VINE:2)
Block(5,28,-4,LEAVES:3)
Block(5,28,-3,LEAVES:3)
Block(5,28,-2,LEAVES:3)
Block(5,29,-5,LEAVES:3)
Block(5,29,-4,LEAVES:3)
Block(5,29,-3,LEAVES:3)
Block(5,29,-2,LEAVES:3)
Block(5,29,-1,LEAVES:3)
Block(5,30,-4,LEAVES:3)
Block(5,30,-3,LEAVES:3)
Block(5,30,-2,LEAVES:3)
Block(5,31,-3,LEAVES:3)
Block(5,38,-6,LEAVES:3)
Block(5,38,-5,LEAVES:3)
Block(5,38,-4,LEAVES:3)
Block(5,38,-3,LEAVES:3)
Block(5,38,-2,LEAVES:3)
Block(5,38,-1,LEAVES:3)
Block(5,38,0,LEAVES:3)
Block(5,39,-7,LEAVES:3)
Block(5,39,-6,LEAVES:3)
Block(5,39,-5,LEAVES:3)
Block(5,39,-4,LEAVES:3)
Block(5,39,-3,LEAVES:3)
Block(5,39,-2,LEAVES:3)
Block(5,39,-1,LEAVES:3)
Block(5,39,0,LEAVES:3)
Block(5,39,1,LEAVES:3)
Block(5,40,-8,LEAVES:3)
Block(5,40,-7,LEAVES:3)
Block(5,40,-6,LEAVES:3)
Block(5,40,-5,LEAVES:3)
Block(5,40,-4,LOG:15)
Block(5,40,-3,LEAVES:3)
Block(5,40,-2,LEAVES:3)
Block(5,40,-1,LEAVES:3)
Block(5,40,0,LEAVES:3)
Block(5,40,1,LEAVES:3)
Block(5,40,2,LEAVES:3)
Block(5,41,-8,LEAVES:3)
Block(5,41,-7,LEAVES:3)
Block(5,41,-6,LEAVES:3)
Block(5,41,-5,LEAVES:3)
Block(5,41,-4,LOG:15)
Block(5,41,-3,LEAVES:3)
Block(5,41,-2,LEAVES:3)
Block(5,41,-1,LOG:7)
Block(5,41,0,LEAVES:3)
Block(5,41,1,LEAVES:3)
Block(5,42,-7,LEAVES:3)
Block(5,42,-6,LEAVES:3)
Block(5,42,-5,LEAVES:3)
Block(5,42,-4,LEAVES:3)
Block(5,42,-3,LEAVES:3)
Block(5,42,-2,LEAVES:3)
Block(5,42,-1,LEAVES:3)
Block(5,42,0,LEAVES:3)
Block(5,42,1,LEAVES:3)
Block(5,43,-5,LEAVES:3)
Block(5,43,-4,LEAVES:3)
Block(5,43,-3,LEAVES:3)
Block(5,43,-2,LEAVES:3)
Block(5,43,-1,LEAVES:3)
Block(5,43,0,LEAVES:3)
Block(6,7,2,LEAVES:3)
Block(6,8,0,LEAVES:3)
Block(6,8,1,LEAVES:3)
Block(6,8,2,LEAVES:3)
Block(6,8,3,LEAVES:3)
Block(6,9,1,LEAVES:3)
Block(6,10,1,VINE:2)
Block(6,29,-4,LEAVES:3)
Block(6,29,-3,LEAVES:3)
Block(6,29,-2,LEAVES:3)
Block(6,30,-3,LEAVES:3)
Block(6,38,-5,LEAVES:3)
Block(6,38,-2,LEAVES:3)
Block(6,38,-1,LEAVES:3)
Block(6,38,0,LEAVES:3)
Block(6,38,1,LEAVES:3)
Block(6,39,-6,LEAVES:3)
Block(6,39,-5,LEAVES:3)
Block(6,39,-4,LEAVES:3)
Block(6,39,-3,LEAVES:3)
Block(6,39,-2,LEAVES:3)
Block(6,39,-1,LEAVES:3)
Block(6,39,0,LEAVES:3)
Block(6,39,1,LEAVES:3)
Block(6,39,2,LEAVES:3)
Block(6,40,-7,LEAVES:3)
Block(6,40,-6,LEAVES:3)
Block(6,40,-5,LEAVES:3)
Block(6,40,-4,LEAVES:3)
Block(6,40,-3,LEAVES:3)
Block(6,40,-2,LEAVES:3)
Block(6,40,-1,LOG:15)
Block(6,40,0,LEAVES:3)
Block(6,40,1,LEAVES:3)
Block(6,40,2,LEAVES:3)
Block(6,41,-7,LEAVES:3)
Block(6,41,-6,LEAVES:3)
Block(6,41,-5,LEAVES:3)
Block(6,41,-4,LEAVES:3)
Block(6,41,-3,LEAVES:3)
Block(6,41,-2,LEAVES:3)
Block(6,41,-1,LEAVES:3)
Block(6,41,0,LEAVES:3)
Block(6,41,1,LEAVES:3)
Block(6,41,2,LEAVES:3)
Block(6,42,-6,LEAVES:3)
Block(6,42,-5,LEAVES:3)
Block(6,42,-4,LEAVES:3)
Block(6,42,-3,LEAVES:3)
Block(6,42,-2,LEAVES:3)
Block(6,42,-1,LEAVES:3)
Block(6,42,0,LEAVES:3)
Block(6,43,-3,LEAVES:3)
Block(7,29,-3,LEAVES:3)
Block(7,38,-4,LEAVES:3)
Block(7,38,-1,LEAVES:3)
Block(7,39,-5,LEAVES:3)
Block(7,39,-4,LEAVES:3)
Block(7,39,-3,LEAVES:3)
Block(7,39,-2,LEAVES:3)
Block(7,39,-1,LEAVES:3)
Block(7,39,0,LEAVES:3)
Block(7,39,1,LEAVES:3)
Block(7,40,-6,LEAVES:3)
Block(7,40,-5,LEAVES:3)
Block(7,40,-4,LEAVES:3)
Block(7,40,-3,LEAVES:3)
Block(7,40,-2,LEAVES:3)
Block(7,40,-1,LEAVES:3)
Block(7,40,0,LEAVES:3)
Block(7,40,1,LEAVES:3)
Block(7,40,2,LEAVES:3)
Block(7,41,-6,LEAVES:3)
Block(7,41,-5,LEAVES:3)
Block(7,41,-4,LEAVES:3)
Block(7,41,-3,LEAVES:3)
Block(7,41,-2,LEAVES:3)
Block(7,41,-1,LEAVES:3)
Block(7,41,0,LEAVES:3)
Block(7,41,1,LEAVES:3)
Block(7,42,-5,LEAVES:3)
Block(7,42,-4,LEAVES:3)
Block(7,42,-3,LEAVES:3)
Block(7,42,-2,LEAVES:3)
Block(7,42,-1,LEAVES:3)
Block(7,43,-4,LEAVES:3)
Block(8,39,-2,LEAVES:3)
Block(8,39,-1,LEAVES:3)
Block(8,39,0,LEAVES:3)
Block(8,40,-5,LEAVES:3)
Block(8,40,-4,LEAVES:3)
Block(8,40,-3,LEAVES:3)
Block(8,40,-2,LEAVES:3)
Block(8,40,-1,LEAVES:3)
Block(8,40,0,LEAVES:3)
Block(8,40,1,LEAVES:3)
Block(8,41,-5,LEAVES:3)
Block(8,41,-4,LEAVES:3)
Block(8,41,-3,LEAVES:3)
Block(8,41,-2,LEAVES:3)
Block(8,41,-1,LEAVES:3)
Block(8,41,0,LEAVES:3)
Block(8,42,-1,LEAVES:3)
Block(9,39,-1,LEAVES:3)
Block(9,40,-2,LEAVES:3)
Block(9,40,-1,LEAVES:3)
Block(9,40,0,LEAVES:3)
Block(9,41,-4,LEAVES:3)
Block(9,41,-1,LEAVES:3)
Block(10,40,-1,LEAVES:3)

#######################################################################
# +-----------------------------------------------------------------+ #
# |                            BO3 checks                           | #
# +-----------------------------------------------------------------+ #
#######################################################################

BlockCheck(0,-1,0,GRASS:0,DIRT:0)
BlockCheck(1,-1,0,GRASS:0,DIRT:0)
BlockCheck(0,-1,1,GRASS:0,DIRT:0)
BlockCheck(1,-1,1,GRASS:0,DIRT:0)
BlockCheck(2,-1,0,GRASS:0,DIRT:0)
BlockCheck(2,-1,1,GRASS:0,DIRT:0)
BlockCheck(2,-1,2,GRASS:0,DIRT:0)
BlockCheck(2,-1,-1,GRASS:0,DIRT:0)
BlockCheck(2,-1,-2,GRASS:0,DIRT:0)
BlockCheck(-2,-1,0,GRASS:0,DIRT:0)
BlockCheck(-2,-1,1,GRASS:0,DIRT:0)
BlockCheck(-2,-1,2,GRASS:0,DIRT:0)
BlockCheck(-2,-1,-1,GRASS:0,DIRT:0)
BlockCheck(-2,-1,-2,GRASS:0,DIRT:0)

#######################################################################
# +-----------------------------------------------------------------+ #
# |                             Branches                            | #
# +-----------------------------------------------------------------+ #
#######################################################################


#######################################################################
# +-----------------------------------------------------------------+ #
# |                             Entities                            | #
# +-----------------------------------------------------------------+ #
#######################################################################


#######################################################################
# +-----------------------------------------------------------------+ #
# |                            Particles                            | #
# +-----------------------------------------------------------------+ #
#######################################################################


#######################################################################
# +-----------------------------------------------------------------+ #
# |                             Spawners                            | #
# +-----------------------------------------------------------------+ #
#######################################################################


#######################################################################
# +-----------------------------------------------------------------+ #
# |                             ModData                             | #
# +-----------------------------------------------------------------+ #
#######################################################################

