
#######################################################################
# +-----------------------------------------------------------------+ #
# |                            BO3 object                           | #
# +-----------------------------------------------------------------+ #
#######################################################################

Author: Unknown

Description: This BO3 was converted from a schematic using OTGEdit. The author and description information of the schematic could not be found. If you know who the author of the schematic is then please add this information.

Version: 3

SettingsMode: WriteWithoutComments


#######################################################################
# +-----------------------------------------------------------------+ #
# |                          Main settings                          | #
# +-----------------------------------------------------------------+ #
#######################################################################

Tree: true

Frequency: 1

Rarity: 100.0

RotateRandomly: true

SpawnHeight: highestSolidBlock

SpawnHeightOffset: 0

SpawnHeightVariance: 0

##############################
# Height Limits for the BO3. #
##############################

MinHeight: 20

MaxHeight: 255

######################
# Extrusion settings #
######################

ExtrudeMode: None

ExtrudeThroughBlocks: AIR

MaxBranchDepth: 10

ExcludedBiomes: All


#######################################################################
# +-----------------------------------------------------------------+ #
# |                      Source block settings                      | #
# +-----------------------------------------------------------------+ #
#######################################################################

SourceBlocks: AIR

MaxPercentageOutsideSourceBlock: 100

OutsideSourceBlock: dontPlace

DoReplaceBlocks: true

IsOTGPlus: false


#######################################################################
# +-----------------------------------------------------------------+ #
# |                              Blocks                             | #
# +-----------------------------------------------------------------+ #
#######################################################################

Block(-12,37,-3,VINE:8)
Block(-12,38,-3,VINE:8)
Block(-12,39,-3,VINE:8)
Block(-12,40,-3,VINE:8)
Block(-12,41,-3,VINE:8)
Block(-12,41,-2,LEAVES:3)
Block(-12,42,-1,LEAVES:3)
Block(-11,40,-2,LEAVES:3)
Block(-11,41,-3,LEAVES:3)
Block(-11,41,-2,LEAVES:3)
Block(-11,41,-1,LEAVES:3)
Block(-11,42,-2,LEAVES:3)
Block(-11,42,-1,LEAVES:3)
Block(-11,42,0,LEAVES:3)
Block(-11,43,-1,LEAVES:3)
Block(-10,39,-2,LEAVES:3)
Block(-10,40,-3,LEAVES:3)
Block(-10,40,-2,LEAVES:3)
Block(-10,40,-1,LEAVES:3)
Block(-10,40,4,LEAVES:3)
Block(-10,41,-4,LEAVES:3)
Block(-10,41,-3,LEAVES:3)
Block(-10,41,-2,LEAVES:3)
Block(-10,41,-1,LEAVES:3)
Block(-10,41,0,LEAVES:3)
Block(-10,41,3,LEAVES:3)
Block(-10,41,4,LEAVES:3)
Block(-10,41,5,LEAVES:3)
Block(-10,42,-3,LEAVES:3)
Block(-10,42,-2,LEAVES:3)
Block(-10,42,-1,LEAVES:3)
Block(-10,42,0,LEAVES:3)
Block(-10,42,1,LEAVES:3)
Block(-10,42,4,LEAVES:3)
Block(-10,43,-2,LEAVES:3)
Block(-10,43,-1,LEAVES:3)
Block(-10,43,0,LEAVES:3)
Block(-9,39,-2,LEAVES:3)
Block(-9,39,-1,LEAVES:3)
Block(-9,39,4,LEAVES:3)
Block(-9,40,-4,LEAVES:3)
Block(-9,40,-3,LEAVES:3)
Block(-9,40,-2,LEAVES:3)
Block(-9,40,-1,LEAVES:3)
Block(-9,40,0,LEAVES:3)
Block(-9,40,3,LEAVES:3)
Block(-9,40,4,LEAVES:3)
Block(-9,40,5,LEAVES:3)
Block(-9,41,-5,LEAVES:3)
Block(-9,41,-4,LEAVES:3)
Block(-9,41,-3,LEAVES:3)
Block(-9,41,-2,LEAVES:3)
Block(-9,41,-1,LEAVES:3)
Block(-9,41,0,LEAVES:3)
Block(-9,41,1,LEAVES:3)
Block(-9,41,2,LEAVES:3)
Block(-9,41,3,LEAVES:3)
Block(-9,41,4,LEAVES:3)
Block(-9,41,5,LEAVES:3)
Block(-9,41,6,LEAVES:3)
Block(-9,42,-4,LEAVES:3)
Block(-9,42,-3,LEAVES:3)
Block(-9,42,-2,LEAVES:3)
Block(-9,42,-1,LEAVES:3)
Block(-9,42,0,LEAVES:3)
Block(-9,42,1,LEAVES:3)
Block(-9,42,2,LEAVES:3)
Block(-9,42,3,LEAVES:3)
Block(-9,42,4,LEAVES:3)
Block(-9,42,5,LEAVES:3)
Block(-9,43,-3,LEAVES:3)
Block(-9,43,-2,LEAVES:3)
Block(-9,43,-1,LEAVES:3)
Block(-9,43,0,LEAVES:3)
Block(-9,43,1,LEAVES:3)
Block(-9,44,0,LEAVES:3)
Block(-8,37,7,VINE:4)
Block(-8,38,7,VINE:4)
Block(-8,39,-3,LEAVES:3)
Block(-8,39,-2,LEAVES:3)
Block(-8,39,-1,LEAVES:3)
Block(-8,39,0,LEAVES:3)
Block(-8,39,3,LEAVES:3)
Block(-8,39,4,LEAVES:3)
Block(-8,39,5,LEAVES:3)
Block(-8,39,7,VINE:4)
Block(-8,40,-5,LEAVES:3)
Block(-8,40,-4,LEAVES:3)
Block(-8,40,-3,LEAVES:3)
Block(-8,40,-2,LEAVES:3)
Block(-8,40,-1,LEAVES:3)
Block(-8,40,0,LEAVES:3)
Block(-8,40,1,LEAVES:3)
Block(-8,40,2,LEAVES:3)
Block(-8,40,3,LEAVES:3)
Block(-8,40,4,LEAVES:3)
Block(-8,40,5,LEAVES:3)
Block(-8,40,6,LEAVES:3)
Block(-8,40,7,VINE:4)
Block(-8,41,-6,LEAVES:3)
Block(-8,41,-5,LEAVES:3)
Block(-8,41,-4,LEAVES:3)
Block(-8,41,-3,LEAVES:3)
Block(-8,41,-2,LOG:15)
Block(-8,41,-1,LEAVES:3)
Block(-8,41,0,LEAVES:3)
Block(-8,41,1,LEAVES:3)
Block(-8,41,2,LEAVES:3)
Block(-8,41,3,LEAVES:3)
Block(-8,41,4,LEAVES:3)
Block(-8,41,5,LEAVES:3)
Block(-8,41,6,LEAVES:3)
Block(-8,41,7,LEAVES:3)
Block(-8,42,-4,LEAVES:3)
Block(-8,42,-3,LEAVES:3)
Block(-8,42,-2,LEAVES:3)
Block(-8,42,-1,LOG:15)
Block(-8,42,0,LEAVES:3)
Block(-8,42,1,LEAVES:3)
Block(-8,42,2,LEAVES:3)
Block(-8,42,3,LEAVES:3)
Block(-8,42,4,LEAVES:3)
Block(-8,42,5,LEAVES:3)
Block(-8,42,6,LEAVES:3)
Block(-8,43,-4,LEAVES:3)
Block(-8,43,-3,LEAVES:3)
Block(-8,43,-2,LEAVES:3)
Block(-8,43,-1,LEAVES:3)
Block(-8,43,0,LEAVES:3)
Block(-8,43,1,LEAVES:3)
Block(-8,43,2,LEAVES:3)
Block(-8,43,4,LEAVES:3)
Block(-8,43,5,LEAVES:3)
Block(-8,44,-2,LEAVES:3)
Block(-8,44,-1,LEAVES:3)
Block(-8,44,0,LEAVES:3)
Block(-7,39,-2,LEAVES:3)
Block(-7,39,-1,LEAVES:3)
Block(-7,39,3,LEAVES:3)
Block(-7,39,4,LEAVES:3)
Block(-7,40,-4,LEAVES:3)
Block(-7,40,-3,LEAVES:3)
Block(-7,40,-2,LEAVES:3)
Block(-7,40,-1,LEAVES:3)
Block(-7,40,0,LEAVES:3)
Block(-7,40,1,LEAVES:3)
Block(-7,40,2,LEAVES:3)
Block(-7,40,3,LEAVES:3)
Block(-7,40,4,LEAVES:3)
Block(-7,40,5,LEAVES:3)
Block(-7,40,6,LEAVES:3)
Block(-7,40,7,LEAVES:3)
Block(-7,41,-5,LEAVES:3)
Block(-7,41,-4,LEAVES:3)
Block(-7,41,-3,LEAVES:3)
Block(-7,41,-2,LEAVES:3)
Block(-7,41,-1,LEAVES:3)
Block(-7,41,0,LEAVES:3)
Block(-7,41,1,LEAVES:3)
Block(-7,41,2,LEAVES:3)
Block(-7,41,3,LEAVES:3)
Block(-7,41,4,LOG:15)
Block(-7,41,5,LEAVES:3)
Block(-7,41,6,LEAVES:3)
Block(-7,41,7,LEAVES:3)
Block(-7,41,8,LEAVES:3)
Block(-7,42,-5,LEAVES:3)
Block(-7,42,-4,LEAVES:3)
Block(-7,42,-3,LEAVES:3)
Block(-7,42,-2,LOG:7)
Block(-7,42,-1,LOG:7)
Block(-7,42,0,LEAVES:3)
Block(-7,42,1,LEAVES:3)
Block(-7,42,2,LEAVES:3)
Block(-7,42,3,LEAVES:3)
Block(-7,42,4,LEAVES:3)
Block(-7,42,5,LEAVES:3)
Block(-7,42,6,LEAVES:3)
Block(-7,42,7,LEAVES:3)
Block(-7,43,-4,LEAVES:3)
Block(-7,43,-3,LEAVES:3)
Block(-7,43,-2,LEAVES:3)
Block(-7,43,-1,LEAVES:3)
Block(-7,43,0,LEAVES:3)
Block(-7,43,1,LEAVES:3)
Block(-7,43,2,LEAVES:3)
Block(-7,43,3,LEAVES:3)
Block(-7,43,4,LEAVES:3)
Block(-7,43,5,LEAVES:3)
Block(-7,43,6,LEAVES:3)
Block(-7,44,-3,LEAVES:3)
Block(-7,44,-2,LEAVES:3)
Block(-7,44,-1,LEAVES:3)
Block(-7,44,0,LEAVES:3)
Block(-6,39,-2,LEAVES:3)
Block(-6,39,4,LEAVES:3)
Block(-6,40,-4,LEAVES:3)
Block(-6,40,-3,LEAVES:3)
Block(-6,40,-2,LEAVES:3)
Block(-6,40,-1,LEAVES:3)
Block(-6,40,0,LEAVES:3)
Block(-6,40,2,LEAVES:3)
Block(-6,40,3,LEAVES:3)
Block(-6,40,4,LEAVES:3)
Block(-6,40,5,LEAVES:3)
Block(-6,40,6,LEAVES:3)
Block(-6,41,-5,LEAVES:3)
Block(-6,41,-4,LEAVES:3)
Block(-6,41,-3,LEAVES:3)
Block(-6,41,-2,LEAVES:3)
Block(-6,41,-1,LEAVES:3)
Block(-6,41,0,LEAVES:3)
Block(-6,41,1,LEAVES:3)
Block(-6,41,2,LEAVES:3)
Block(-6,41,3,LEAVES:3)
Block(-6,41,4,LEAVES:3)
Block(-6,41,5,LEAVES:3)
Block(-6,41,6,LEAVES:3)
Block(-6,41,7,LEAVES:3)
Block(-6,42,-6,LEAVES:3)
Block(-6,42,-5,LEAVES:3)
Block(-6,42,-4,LEAVES:3)
Block(-6,42,-3,LEAVES:3)
Block(-6,42,-2,LOG:7)
Block(-6,42,-1,LOG:7)
Block(-6,42,0,LEAVES:3)
Block(-6,42,1,LEAVES:3)
Block(-6,42,2,LEAVES:3)
Block(-6,42,3,LOG:7)
Block(-6,42,4,LEAVES:3)
Block(-6,42,5,LEAVES:3)
Block(-6,42,6,LEAVES:3)
Block(-6,43,-4,LEAVES:3)
Block(-6,43,-3,LEAVES:3)
Block(-6,43,-2,LEAVES:3)
Block(-6,43,-1,LEAVES:3)
Block(-6,43,0,LEAVES:3)
Block(-6,43,1,LEAVES:3)
Block(-6,43,2,LEAVES:3)
Block(-6,43,3,LEAVES:3)
Block(-6,43,4,LEAVES:3)
Block(-6,43,5,LEAVES:3)
Block(-6,44,-4,LEAVES:3)
Block(-6,44,-3,LEAVES:3)
Block(-6,44,-2,LEAVES:3)
Block(-6,44,-1,LEAVES:3)
Block(-6,44,0,LEAVES:3)
Block(-6,44,1,LEAVES:3)
Block(-6,45,-1,LEAVES:3)
Block(-5,39,4,LEAVES:3)
Block(-5,40,-3,LEAVES:3)
Block(-5,40,-2,LEAVES:3)
Block(-5,40,-1,LEAVES:3)
Block(-5,40,0,LEAVES:3)
Block(-5,40,2,LEAVES:3)
Block(-5,40,3,LEAVES:3)
Block(-5,40,4,LEAVES:3)
Block(-5,40,5,LEAVES:3)
Block(-5,41,-4,LEAVES:3)
Block(-5,41,-3,LEAVES:3)
Block(-5,41,-2,LEAVES:3)
Block(-5,41,-1,LEAVES:3)
Block(-5,41,0,LEAVES:3)
Block(-5,41,1,LEAVES:3)
Block(-5,41,2,LEAVES:3)
Block(-5,41,3,LEAVES:3)
Block(-5,41,4,LEAVES:3)
Block(-5,41,5,LEAVES:3)
Block(-5,41,6,LEAVES:3)
Block(-5,42,-5,LEAVES:3)
Block(-5,42,-4,LEAVES:3)
Block(-5,42,-3,LEAVES:3)
Block(-5,42,-2,LEAVES:3)
Block(-5,42,-1,LEAVES:3)
Block(-5,42,0,LEAVES:3)
Block(-5,42,1,LEAVES:3)
Block(-5,42,2,LEAVES:3)
Block(-5,42,3,LOG:7)
Block(-5,42,4,LEAVES:3)
Block(-5,42,5,LEAVES:3)
Block(-5,42,6,LEAVES:3)
Block(-5,43,-4,LEAVES:3)
Block(-5,43,-3,LEAVES:3)
Block(-5,43,-2,LEAVES:3)
Block(-5,43,-1,LOG:7)
Block(-5,43,0,LEAVES:3)
Block(-5,43,1,LEAVES:3)
Block(-5,43,2,LEAVES:3)
Block(-5,43,3,LEAVES:3)
Block(-5,43,4,LEAVES:3)
Block(-5,43,5,LEAVES:3)
Block(-5,44,-3,LEAVES:3)
Block(-5,44,-2,LEAVES:3)
Block(-5,44,-1,LEAVES:3)
Block(-5,44,0,LEAVES:3)
Block(-5,44,1,LEAVES:3)
Block(-5,44,2,LEAVES:3)
Block(-5,44,3,LEAVES:3)
Block(-5,45,-2,LEAVES:3)
Block(-5,45,-1,LEAVES:3)
Block(-5,45,0,LEAVES:3)
Block(-5,45,1,LEAVES:3)
Block(-4,27,-6,LEAVES:3)
Block(-4,32,6,LEAVES:3)
Block(-4,34,3,LEAVES:3)
Block(-4,40,2,LEAVES:3)
Block(-4,40,3,LEAVES:3)
Block(-4,40,4,LEAVES:3)
Block(-4,41,-3,LEAVES:3)
Block(-4,41,-2,LEAVES:3)
Block(-4,41,-1,LEAVES:3)
Block(-4,41,0,LEAVES:3)
Block(-4,41,1,LEAVES:3)
Block(-4,41,2,LEAVES:3)
Block(-4,41,3,LEAVES:3)
Block(-4,41,4,LEAVES:3)
Block(-4,41,5,LEAVES:3)
Block(-4,42,-4,LEAVES:3)
Block(-4,42,-3,LEAVES:3)
Block(-4,42,-2,LEAVES:3)
Block(-4,42,-1,LEAVES:3)
Block(-4,42,0,LEAVES:3)
Block(-4,42,1,LEAVES:3)
Block(-4,42,2,LEAVES:3)
Block(-4,42,3,LEAVES:3)
Block(-4,42,4,LEAVES:3)
Block(-4,42,5,LEAVES:3)
Block(-4,42,6,LEAVES:3)
Block(-4,43,-3,LEAVES:3)
Block(-4,43,-2,LEAVES:3)
Block(-4,43,-1,LOG:7)
Block(-4,43,0,LEAVES:3)
Block(-4,43,1,LEAVES:3)
Block(-4,43,2,LOG:7)
Block(-4,43,3,LEAVES:3)
Block(-4,43,4,LEAVES:3)
Block(-4,43,5,LEAVES:3)
Block(-4,44,-4,LEAVES:3)
Block(-4,44,-3,LEAVES:3)
Block(-4,44,-2,LEAVES:3)
Block(-4,44,-1,LEAVES:3)
Block(-4,44,0,LEAVES:3)
Block(-4,44,1,LEAVES:3)
Block(-4,44,2,LEAVES:3)
Block(-4,44,3,LEAVES:3)
Block(-4,45,-3,LEAVES:3)
Block(-4,45,-2,LEAVES:3)
Block(-4,45,-1,LEAVES:3)
Block(-4,45,0,LEAVES:3)
Block(-4,45,1,LEAVES:3)
Block(-4,45,2,LEAVES:3)
Block(-4,46,-2,LEAVES:3)
Block(-4,46,-1,LEAVES:3)
Block(-4,46,0,LEAVES:3)
Block(-4,46,1,LEAVES:3)
Block(-3,21,-8,VINE:8)
Block(-3,22,-8,VINE:8)
Block(-3,23,-8,VINE:8)
Block(-3,24,-8,VINE:8)
Block(-3,25,-8,VINE:8)
Block(-3,26,-8,VINE:8)
Block(-3,26,-6,LEAVES:3)
Block(-3,27,-8,VINE:8)
Block(-3,27,-7,LEAVES:3)
Block(-3,27,-6,LEAVES:3)
Block(-3,27,-5,LEAVES:3)
Block(-3,27,-4,LEAVES:3)
Block(-3,27,7,VINE:8)
Block(-3,28,-5,LEAVES:3)
Block(-3,28,-4,LEAVES:3)
Block(-3,28,-3,LEAVES:3)
Block(-3,28,7,VINE:8)
Block(-3,29,7,VINE:8)
Block(-3,30,7,VINE:8)
Block(-3,31,7,VINE:8)
Block(-3,32,5,LEAVES:3)
Block(-3,32,6,LEAVES:3)
Block(-3,32,7,LEAVES:3)
Block(-3,32,8,LEAVES:3)
Block(-3,33,3,LEAVES:3)
Block(-3,34,2,LEAVES:3)
Block(-3,34,3,LEAVES:3)
Block(-3,34,4,LEAVES:3)
Block(-3,35,3,LEAVES:3)
Block(-3,40,3,LEAVES:3)
Block(-3,41,-2,LEAVES:3)
Block(-3,41,2,LEAVES:3)
Block(-3,41,3,LEAVES:3)
Block(-3,41,4,LEAVES:3)
Block(-3,42,-3,LEAVES:3)
Block(-3,42,-2,LEAVES:3)
Block(-3,42,-1,LEAVES:3)
Block(-3,42,0,LEAVES:3)
Block(-3,42,1,LEAVES:3)
Block(-3,42,2,LEAVES:3)
Block(-3,42,3,LEAVES:3)
Block(-3,42,4,LEAVES:3)
Block(-3,42,5,LEAVES:3)
Block(-3,43,-4,LEAVES:3)
Block(-3,43,-3,LEAVES:3)
Block(-3,43,-2,LEAVES:3)
Block(-3,43,-1,LEAVES:3)
Block(-3,43,0,LEAVES:3)
Block(-3,43,1,LEAVES:3)
Block(-3,43,2,LOG:7)
Block(-3,43,3,LEAVES:3)
Block(-3,43,4,LEAVES:3)
Block(-3,44,-5,LEAVES:3)
Block(-3,44,-4,LEAVES:3)
Block(-3,44,-3,LEAVES:3)
Block(-3,44,-2,LEAVES:3)
Block(-3,44,-1,LOG:7)
Block(-3,44,0,LEAVES:3)
Block(-3,44,1,LEAVES:3)
Block(-3,44,2,LEAVES:3)
Block(-3,44,3,LEAVES:3)
Block(-3,44,4,LEAVES:3)
Block(-3,45,-4,LEAVES:3)
Block(-3,45,-3,LEAVES:3)
Block(-3,45,-2,LEAVES:3)
Block(-3,45,-1,LEAVES:3)
Block(-3,45,0,LEAVES:3)
Block(-3,45,1,LEAVES:3)
Block(-3,45,2,LEAVES:3)
Block(-3,45,3,LEAVES:3)
Block(-3,46,-3,LEAVES:3)
Block(-3,46,-2,LEAVES:3)
Block(-3,46,-1,LEAVES:3)
Block(-3,46,0,LEAVES:3)
Block(-3,46,1,LEAVES:3)
Block(-3,47,-1,LEAVES:3)
Block(-3,47,0,LEAVES:3)
Block(-2,26,-7,LEAVES:3)
Block(-2,26,-6,LEAVES:3)
Block(-2,26,-5,LEAVES:3)
Block(-2,26,-4,LEAVES:3)
Block(-2,26,0,VINE:8)
Block(-2,27,-8,LEAVES:3)
Block(-2,27,-7,LEAVES:3)
Block(-2,27,-6,LEAVES:3)
Block(-2,27,-5,LEAVES:3)
Block(-2,27,-4,LEAVES:3)
Block(-2,27,-3,LEAVES:3)
Block(-2,27,0,VINE:8)
Block(-2,28,-7,LEAVES:3)
Block(-2,28,-6,LEAVES:3)
Block(-2,28,-5,LEAVES:3)
Block(-2,28,-4,LEAVES:3)
Block(-2,28,-3,LEAVES:3)
Block(-2,28,-2,LEAVES:3)
Block(-2,28,0,VINE:8)
Block(-2,29,-6,LEAVES:3)
Block(-2,29,-5,LEAVES:3)
Block(-2,29,-4,LEAVES:3)
Block(-2,29,-3,LEAVES:3)
Block(-2,29,0,VINE:8)
Block(-2,30,-4,LEAVES:3)
Block(-2,30,0,VINE:8)
Block(-2,30,7,LEAVES:3)
Block(-2,31,-1,VINE:8)
Block(-2,31,0,VINE:8)
Block(-2,31,5,LEAVES:3)
Block(-2,31,6,LEAVES:3)
Block(-2,31,7,LEAVES:3)
Block(-2,31,8,LEAVES:3)
Block(-2,32,-1,VINE:8)
Block(-2,32,0,VINE:8)
Block(-2,32,4,LEAVES:3)
Block(-2,32,5,LEAVES:3)
Block(-2,32,6,LEAVES:3)
Block(-2,32,7,LEAVES:3)
Block(-2,32,8,LEAVES:3)
Block(-2,32,9,LEAVES:3)
Block(-2,33,-1,VINE:8)
Block(-2,33,0,VINE:8)
Block(-2,33,2,LEAVES:3)
Block(-2,33,3,LEAVES:3)
Block(-2,33,4,LEAVES:3)
Block(-2,33,5,LEAVES:3)
Block(-2,33,6,LEAVES:3)
Block(-2,33,7,LEAVES:3)
Block(-2,33,8,LEAVES:3)
Block(-2,34,-1,VINE:8)
Block(-2,34,0,VINE:8)
Block(-2,34,1,LEAVES:3)
Block(-2,34,2,LEAVES:3)
Block(-2,34,3,LEAVES:3)
Block(-2,34,4,LEAVES:3)
Block(-2,34,5,LEAVES:3)
Block(-2,35,-1,VINE:8)
Block(-2,35,0,VINE:8)
Block(-2,35,2,LEAVES:3)
Block(-2,35,3,LEAVES:3)
Block(-2,35,4,LEAVES:3)
Block(-2,36,-1,VINE:8)
Block(-2,36,0,VINE:8)
Block(-2,37,-1,VINE:8)
Block(-2,37,0,VINE:8)
Block(-2,38,0,VINE:8)
Block(-2,39,0,VINE:8)
Block(-2,40,0,VINE:8)
Block(-2,41,0,VINE:8)
Block(-2,41,3,LEAVES:3)
Block(-2,42,-2,LEAVES:3)
Block(-2,42,-1,LEAVES:3)
Block(-2,42,0,LEAVES:3)
Block(-2,42,1,LEAVES:3)
Block(-2,42,2,LEAVES:3)
Block(-2,42,3,LEAVES:3)
Block(-2,42,4,LEAVES:3)
Block(-2,43,-3,LEAVES:3)
Block(-2,43,-2,LEAVES:3)
Block(-2,43,-1,LEAVES:3)
Block(-2,43,0,LEAVES:3)
Block(-2,43,1,LEAVES:3)
Block(-2,43,2,LEAVES:3)
Block(-2,43,3,LEAVES:3)
Block(-2,43,4,LEAVES:3)
Block(-2,44,-4,LEAVES:3)
Block(-2,44,-3,LEAVES:3)
Block(-2,44,-2,LEAVES:3)
Block(-2,44,-1,LOG:7)
Block(-2,44,0,LEAVES:3)
Block(-2,44,1,LOG:7)
Block(-2,44,2,LEAVES:3)
Block(-2,44,3,LEAVES:3)
Block(-2,44,4,LEAVES:3)
Block(-2,44,5,LEAVES:3)
Block(-2,45,-4,LEAVES:3)
Block(-2,45,-3,LEAVES:3)
Block(-2,45,-2,LEAVES:3)
Block(-2,45,-1,LEAVES:3)
Block(-2,45,0,LEAVES:3)
Block(-2,45,1,LEAVES:3)
Block(-2,45,2,LEAVES:3)
Block(-2,45,3,LEAVES:3)
Block(-2,46,-3,LEAVES:3)
Block(-2,46,-2,LEAVES:3)
Block(-2,46,-1,LEAVES:3)
Block(-2,46,0,LEAVES:3)
Block(-2,46,1,LEAVES:3)
Block(-2,46,2,LEAVES:3)
Block(-2,46,3,LEAVES:3)
Block(-2,47,-2,LEAVES:3)
Block(-2,47,-1,LEAVES:3)
Block(-2,47,0,LEAVES:3)
Block(-2,47,1,LEAVES:3)
Block(-1,0,-1,LOG:3)
Block(-1,0,0,LOG:3)
Block(-1,1,-1,LOG:3)
Block(-1,1,0,LOG:3)
Block(-1,2,-1,LOG:3)
Block(-1,2,0,LOG:3)
Block(-1,3,-1,LOG:3)
Block(-1,3,0,LOG:3)
Block(-1,4,-1,LOG:3)
Block(-1,4,0,LOG:3)
Block(-1,5,-1,LOG:3)
Block(-1,5,0,LOG:3)
Block(-1,6,-1,LOG:3)
Block(-1,6,0,LOG:3)
Block(-1,7,-1,LOG:3)
Block(-1,7,0,LOG:3)
Block(-1,8,-1,LOG:3)
Block(-1,8,0,LOG:3)
Block(-1,9,-1,LOG:3)
Block(-1,9,0,LOG:3)
Block(-1,10,-1,LOG:3)
Block(-1,10,0,LOG:3)
Block(-1,11,-1,LOG:3)
Block(-1,11,0,LOG:3)
Block(-1,12,-1,LOG:3)
Block(-1,12,0,LOG:3)
Block(-1,13,-2,VINE:1)
Block(-1,13,-1,LOG:3)
Block(-1,13,0,LOG:3)
Block(-1,14,-2,VINE:1)
Block(-1,14,-1,LOG:3)
Block(-1,14,0,LOG:3)
Block(-1,15,-2,VINE:1)
Block(-1,15,-1,LOG:3)
Block(-1,15,0,LOG:3)
Block(-1,16,-2,VINE:1)
Block(-1,16,-1,LOG:3)
Block(-1,16,0,LOG:3)
Block(-1,17,-2,VINE:1)
Block(-1,17,-1,LOG:3)
Block(-1,17,0,LOG:3)
Block(-1,18,-2,VINE:1)
Block(-1,18,-1,LOG:3)
Block(-1,18,0,LOG:3)
Block(-1,19,-2,VINE:1)
Block(-1,19,-1,LOG:3)
Block(-1,19,0,LOG:3)
Block(-1,20,-2,VINE:1)
Block(-1,20,-1,LOG:3)
Block(-1,20,0,LOG:3)
Block(-1,21,-2,VINE:1)
Block(-1,21,-1,LOG:3)
Block(-1,21,0,LOG:3)
Block(-1,22,-2,VINE:1)
Block(-1,22,-1,LOG:3)
Block(-1,22,0,LOG:3)
Block(-1,23,-2,VINE:1)
Block(-1,23,-1,LOG:3)
Block(-1,23,0,LOG:3)
Block(-1,24,-2,VINE:1)
Block(-1,24,-1,LOG:3)
Block(-1,24,0,LOG:3)
Block(-1,25,-6,LEAVES:3)
Block(-1,25,-5,LEAVES:3)
Block(-1,25,-2,VINE:1)
Block(-1,25,-1,LOG:3)
Block(-1,25,0,LOG:3)
Block(-1,26,-8,LEAVES:3)
Block(-1,26,-7,LEAVES:3)
Block(-1,26,-6,LEAVES:3)
Block(-1,26,-5,LEAVES:3)
Block(-1,26,-4,LEAVES:3)
Block(-1,26,-3,LEAVES:3)
Block(-1,26,-2,VINE:1)
Block(-1,26,-1,LOG:3)
Block(-1,26,0,LOG:3)
Block(-1,27,-9,LEAVES:3)
Block(-1,27,-8,LEAVES:3)
Block(-1,27,-7,LEAVES:3)
Block(-1,27,-6,LEAVES:3)
Block(-1,27,-5,LEAVES:3)
Block(-1,27,-4,LEAVES:3)
Block(-1,27,-3,LEAVES:3)
Block(-1,27,-2,LEAVES:3)
Block(-1,27,-1,LOG:3)
Block(-1,27,0,LOG:3)
Block(-1,28,-8,LEAVES:3)
Block(-1,28,-7,LEAVES:3)
Block(-1,28,-6,LEAVES:3)
Block(-1,28,-5,LEAVES:3)
Block(-1,28,-4,LEAVES:3)
Block(-1,28,-3,LEAVES:3)
Block(-1,28,-2,LEAVES:3)
Block(-1,28,-1,LOG:3)
Block(-1,28,0,LOG:3)
Block(-1,29,-6,LEAVES:3)
Block(-1,29,-5,LEAVES:3)
Block(-1,29,-4,LEAVES:3)
Block(-1,29,-3,LEAVES:3)
Block(-1,29,-2,LEAVES:3)
Block(-1,29,-1,LOG:3)
Block(-1,29,0,LOG:3)
Block(-1,30,-3,LEAVES:3)
Block(-1,30,-1,LOG:3)
Block(-1,30,0,LOG:3)
Block(-1,30,5,LEAVES:3)
Block(-1,30,6,LEAVES:3)
Block(-1,30,7,LEAVES:3)
Block(-1,31,-1,LOG:3)
Block(-1,31,0,LOG:3)
Block(-1,31,4,LEAVES:3)
Block(-1,31,5,LEAVES:3)
Block(-1,31,6,LEAVES:3)
Block(-1,31,7,LEAVES:3)
Block(-1,31,8,LEAVES:3)
Block(-1,31,9,LEAVES:3)
Block(-1,32,-1,LOG:3)
Block(-1,32,0,LOG:3)
Block(-1,32,2,LEAVES:3)
Block(-1,32,3,LEAVES:3)
Block(-1,32,4,LEAVES:3)
Block(-1,32,5,LEAVES:3)
Block(-1,32,6,LEAVES:3)
Block(-1,32,7,LEAVES:3)
Block(-1,32,8,LEAVES:3)
Block(-1,32,9,LEAVES:3)
Block(-1,32,10,LEAVES:3)
Block(-1,33,-2,VINE:1)
Block(-1,33,-1,LOG:3)
Block(-1,33,0,LOG:3)
Block(-1,33,1,LEAVES:3)
Block(-1,33,2,LEAVES:3)
Block(-1,33,3,LEAVES:3)
Block(-1,33,4,LEAVES:3)
Block(-1,33,5,LEAVES:3)
Block(-1,33,6,LEAVES:3)
Block(-1,33,7,LEAVES:3)
Block(-1,33,8,LEAVES:3)
Block(-1,33,9,LEAVES:3)
Block(-1,34,-2,VINE:1)
Block(-1,34,-1,LOG:3)
Block(-1,34,0,LOG:3)
Block(-1,34,1,LEAVES:3)
Block(-1,34,2,LEAVES:3)
Block(-1,34,3,LEAVES:3)
Block(-1,34,4,LEAVES:3)
Block(-1,34,5,LEAVES:3)
Block(-1,34,6,LEAVES:3)
Block(-1,35,-2,VINE:1)
Block(-1,35,-1,LOG:3)
Block(-1,35,0,LOG:3)
Block(-1,35,1,LEAVES:3)
Block(-1,35,2,LEAVES:3)
Block(-1,35,3,LEAVES:3)
Block(-1,35,4,LEAVES:3)
Block(-1,35,5,LEAVES:3)
Block(-1,36,-1,LOG:3)
Block(-1,36,0,LOG:3)
Block(-1,37,-1,LOG:3)
Block(-1,37,0,LOG:3)
Block(-1,38,-1,LOG:3)
Block(-1,38,0,LOG:3)
Block(-1,39,-1,LOG:3)
Block(-1,39,0,LOG:3)
Block(-1,40,-1,LOG:3)
Block(-1,40,0,LOG:3)
Block(-1,41,-1,LOG:3)
Block(-1,41,0,LOG:3)
Block(-1,42,-1,LOG:3)
Block(-1,42,0,LOG:3)
Block(-1,42,3,LEAVES:3)
Block(-1,43,-2,LEAVES:3)
Block(-1,43,-1,LOG:3)
Block(-1,43,0,LOG:3)
Block(-1,43,1,LEAVES:3)
Block(-1,43,2,LEAVES:3)
Block(-1,43,3,LEAVES:3)
Block(-1,43,4,LEAVES:3)
Block(-1,44,-4,LEAVES:3)
Block(-1,44,-3,LEAVES:3)
Block(-1,44,-2,LEAVES:3)
Block(-1,44,-1,LOG:3)
Block(-1,44,0,LOG:3)
Block(-1,44,1,LEAVES:3)
Block(-1,44,2,LEAVES:3)
Block(-1,44,3,LEAVES:3)
Block(-1,44,4,LEAVES:3)
Block(-1,45,-5,LEAVES:3)
Block(-1,45,-4,LEAVES:3)
Block(-1,45,-3,LEAVES:3)
Block(-1,45,-2,LEAVES:3)
Block(-1,45,-1,LOG:7)
Block(-1,45,0,LOG:7)
Block(-1,45,1,LEAVES:3)
Block(-1,45,2,LEAVES:3)
Block(-1,45,3,LEAVES:3)
Block(-1,45,4,LEAVES:3)
Block(-1,46,-4,LEAVES:3)
Block(-1,46,-3,LEAVES:3)
Block(-1,46,-2,LEAVES:3)
Block(-1,46,-1,LEAVES:3)
Block(-1,46,0,LEAVES:3)
Block(-1,46,1,LEAVES:3)
Block(-1,46,2,LEAVES:3)
Block(-1,46,3,LEAVES:3)
Block(-1,47,-3,LEAVES:3)
Block(-1,47,-2,LEAVES:3)
Block(-1,47,-1,LEAVES:3)
Block(-1,47,0,LEAVES:3)
Block(0,0,-2,LOG:3)
Block(0,0,-1,LOG:3)
Block(0,0,0,LOG:3)
Block(0,0,1,LOG:3)
Block(0,1,-2,LOG:3)
Block(0,1,-1,LOG:3)
Block(0,1,0,LOG:3)
Block(0,1,1,LOG:15)
Block(0,2,-2,LOG:3)
Block(0,2,-1,LOG:15)
Block(0,2,0,LOG:15)
Block(0,2,1,LOG:3)
Block(0,3,-2,LOG:3)
Block(0,3,-1,LOG:3)
Block(0,3,0,LOG:3)
Block(0,3,1,LOG:3)
Block(0,4,-2,LOG:3)
Block(0,4,-1,LOG:3)
Block(0,4,0,LOG:3)
Block(0,4,1,LOG:3)
Block(0,5,-2,LOG:3)
Block(0,5,-1,LOG:3)
Block(0,5,0,LOG:3)
Block(0,5,1,LOG:3)
Block(0,6,-2,LOG:3)
Block(0,6,-1,LOG:3)
Block(0,6,0,LOG:3)
Block(0,6,1,LOG:3)
Block(0,7,-2,LOG:3)
Block(0,7,-1,LOG:3)
Block(0,7,0,LOG:3)
Block(0,7,1,LOG:3)
Block(0,8,-2,LOG:3)
Block(0,8,-1,LOG:3)
Block(0,8,0,LOG:3)
Block(0,8,1,LOG:3)
Block(0,9,-2,LOG:3)
Block(0,9,-1,LOG:3)
Block(0,9,0,LOG:3)
Block(0,9,1,LOG:3)
Block(0,10,-2,LOG:3)
Block(0,10,-1,LOG:3)
Block(0,10,0,LOG:3)
Block(0,10,1,LOG:3)
Block(0,11,-3,VINE:1)
Block(0,11,-2,LOG:3)
Block(0,11,-1,LOG:3)
Block(0,11,0,LOG:3)
Block(0,11,1,LOG:3)
Block(0,12,-3,VINE:1)
Block(0,12,-2,LOG:3)
Block(0,12,-1,LOG:3)
Block(0,12,0,LOG:3)
Block(0,12,1,LOG:3)
Block(0,13,-3,VINE:1)
Block(0,13,-2,LOG:3)
Block(0,13,-1,LOG:3)
Block(0,13,0,LOG:3)
Block(0,13,1,LOG:3)
Block(0,14,-3,VINE:1)
Block(0,14,-2,LOG:3)
Block(0,14,-1,LOG:3)
Block(0,14,0,LOG:3)
Block(0,14,1,LOG:3)
Block(0,15,-3,VINE:1)
Block(0,15,-2,LOG:3)
Block(0,15,-1,LOG:3)
Block(0,15,0,LOG:3)
Block(0,15,1,LOG:3)
Block(0,16,-3,VINE:1)
Block(0,16,-2,LOG:3)
Block(0,16,-1,LOG:3)
Block(0,16,0,LOG:3)
Block(0,16,1,LOG:3)
Block(0,17,-3,VINE:1)
Block(0,17,-2,LOG:3)
Block(0,17,-1,LOG:3)
Block(0,17,0,LOG:3)
Block(0,17,1,LOG:3)
Block(0,18,-3,VINE:1)
Block(0,18,-2,LOG:3)
Block(0,18,-1,LOG:3)
Block(0,18,0,LOG:3)
Block(0,18,1,LOG:3)
Block(0,19,-3,VINE:1)
Block(0,19,-2,LOG:3)
Block(0,19,-1,LOG:3)
Block(0,19,0,LOG:3)
Block(0,19,1,LOG:3)
Block(0,20,-3,VINE:1)
Block(0,20,-2,LOG:3)
Block(0,20,-1,LOG:3)
Block(0,20,0,LOG:3)
Block(0,20,1,LOG:3)
Block(0,21,-3,VINE:1)
Block(0,21,-2,LOG:3)
Block(0,21,-1,LOG:3)
Block(0,21,0,LOG:3)
Block(0,21,1,LOG:3)
Block(0,22,-2,LOG:3)
Block(0,22,-1,LOG:3)
Block(0,22,0,LOG:3)
Block(0,22,1,LOG:3)
Block(0,23,-2,LOG:3)
Block(0,23,-1,LOG:3)
Block(0,23,0,LOG:3)
Block(0,23,1,LOG:3)
Block(0,24,-2,LOG:3)
Block(0,24,-1,LOG:3)
Block(0,24,0,LOG:3)
Block(0,24,1,LOG:3)
Block(0,25,-6,LEAVES:3)
Block(0,25,-2,LOG:3)
Block(0,25,-1,LOG:3)
Block(0,25,0,LOG:3)
Block(0,25,1,LOG:3)
Block(0,25,2,VINE:4)
Block(0,26,-9,LEAVES:3)
Block(0,26,-8,LEAVES:3)
Block(0,26,-7,LEAVES:3)
Block(0,26,-6,LEAVES:3)
Block(0,26,-5,LEAVES:3)
Block(0,26,-4,LEAVES:3)
Block(0,26,-3,LEAVES:3)
Block(0,26,-2,LOG:3)
Block(0,26,-1,LOG:3)
Block(0,26,0,LOG:3)
Block(0,26,1,LOG:3)
Block(0,26,2,VINE:4)
Block(0,27,-9,LEAVES:3)
Block(0,27,-8,LEAVES:3)
Block(0,27,-7,LEAVES:3)
Block(0,27,-6,LOG:15)
Block(0,27,-5,LOG:11)
Block(0,27,-4,LEAVES:3)
Block(0,27,-3,LEAVES:3)
Block(0,27,-2,LOG:3)
Block(0,27,-1,LOG:3)
Block(0,27,0,LOG:3)
Block(0,27,1,LOG:3)
Block(0,27,2,VINE:4)
Block(0,28,-9,LEAVES:3)
Block(0,28,-8,LEAVES:3)
Block(0,28,-7,LEAVES:3)
Block(0,28,-6,LEAVES:3)
Block(0,28,-5,LEAVES:3)
Block(0,28,-4,LOG:11)
Block(0,28,-3,LOG:11)
Block(0,28,-2,LOG:3)
Block(0,28,-1,LOG:3)
Block(0,28,0,LOG:3)
Block(0,28,1,LOG:3)
Block(0,28,2,VINE:4)
Block(0,29,-8,LEAVES:3)
Block(0,29,-6,LEAVES:3)
Block(0,29,-5,LEAVES:3)
Block(0,29,-4,LEAVES:3)
Block(0,29,-3,LEAVES:3)
Block(0,29,-2,LOG:3)
Block(0,29,-1,LOG:3)
Block(0,29,0,LOG:3)
Block(0,29,1,LOG:3)
Block(0,29,2,VINE:4)
Block(0,30,-6,LEAVES:3)
Block(0,30,-4,LEAVES:3)
Block(0,30,-3,LEAVES:3)
Block(0,30,-2,LOG:3)
Block(0,30,-1,LOG:3)
Block(0,30,0,LOG:3)
Block(0,30,1,LOG:3)
Block(0,30,2,VINE:4)
Block(0,30,5,LEAVES:3)
Block(0,30,6,LEAVES:3)
Block(0,30,7,LEAVES:3)
Block(0,31,-3,LEAVES:3)
Block(0,31,-2,LOG:3)
Block(0,31,-1,LOG:3)
Block(0,31,0,LOG:3)
Block(0,31,1,LOG:3)
Block(0,31,2,VINE:4)
Block(0,31,4,LEAVES:3)
Block(0,31,5,LEAVES:3)
Block(0,31,6,LEAVES:3)
Block(0,31,7,LEAVES:3)
Block(0,31,8,LEAVES:3)
Block(0,31,9,LEAVES:3)
Block(0,31,10,LEAVES:3)
Block(0,32,-2,LOG:3)
Block(0,32,-1,LOG:3)
Block(0,32,0,LOG:3)
Block(0,32,1,LOG:3)
Block(0,32,2,LEAVES:3)
Block(0,32,3,LEAVES:3)
Block(0,32,4,LEAVES:3)
Block(0,32,5,LEAVES:3)
Block(0,32,6,LOG:11)
Block(0,32,7,LOG:15)
Block(0,32,8,LEAVES:3)
Block(0,32,9,LEAVES:3)
Block(0,32,10,LEAVES:3)
Block(0,33,-2,LOG:3)
Block(0,33,-1,LOG:3)
Block(0,33,0,LOG:3)
Block(0,33,1,LOG:3)
Block(0,33,2,LEAVES:3)
Block(0,33,3,LEAVES:3)
Block(0,33,4,LOG:11)
Block(0,33,5,LOG:11)
Block(0,33,6,LEAVES:3)
Block(0,33,7,LEAVES:3)
Block(0,33,8,LEAVES:3)
Block(0,33,9,LEAVES:3)
Block(0,34,-2,LOG:3)
Block(0,34,-1,LOG:3)
Block(0,34,0,LOG:3)
Block(0,34,1,LOG:3)
Block(0,34,2,LOG:11)
Block(0,34,3,LOG:11)
Block(0,34,4,LEAVES:3)
Block(0,34,5,LEAVES:3)
Block(0,34,6,LEAVES:3)
Block(0,34,7,LEAVES:3)
Block(0,34,8,LEAVES:3)
Block(0,35,-2,LOG:3)
Block(0,35,-1,LOG:3)
Block(0,35,0,LOG:3)
Block(0,35,1,LOG:3)
Block(0,35,2,LEAVES:3)
Block(0,35,3,LEAVES:3)
Block(0,35,4,LEAVES:3)
Block(0,35,5,LEAVES:3)
Block(0,36,-2,LOG:3)
Block(0,36,-1,LOG:3)
Block(0,36,0,LOG:3)
Block(0,36,1,LOG:3)
Block(0,37,-2,LOG:3)
Block(0,37,-1,LOG:3)
Block(0,37,0,LOG:3)
Block(0,37,1,LOG:3)
Block(0,38,-2,LOG:3)
Block(0,38,-1,LOG:3)
Block(0,38,0,LOG:3)
Block(0,38,1,LOG:3)
Block(0,39,-2,LOG:3)
Block(0,39,-1,LOG:3)
Block(0,39,0,LOG:3)
Block(0,39,1,LOG:3)
Block(0,40,-2,LOG:3)
Block(0,40,-1,LOG:3)
Block(0,40,0,LOG:3)
Block(0,40,1,LOG:3)
Block(0,41,-2,LOG:3)
Block(0,41,-1,LOG:3)
Block(0,41,0,LOG:3)
Block(0,41,1,LOG:3)
Block(0,42,-2,LOG:3)
Block(0,42,-1,LOG:3)
Block(0,42,0,LOG:3)
Block(0,42,1,LOG:3)
Block(0,43,-2,LOG:3)
Block(0,43,-1,LOG:3)
Block(0,43,0,LOG:3)
Block(0,43,1,LOG:3)
Block(0,43,2,LEAVES:3)
Block(0,43,3,LEAVES:3)
Block(0,44,-4,LEAVES:3)
Block(0,44,-3,LEAVES:3)
Block(0,44,-2,LOG:3)
Block(0,44,-1,LOG:3)
Block(0,44,0,LOG:3)
Block(0,44,1,LOG:3)
Block(0,44,2,LEAVES:3)
Block(0,44,3,LEAVES:3)
Block(0,44,4,LEAVES:3)
Block(0,45,-5,LEAVES:3)
Block(0,45,-4,LEAVES:3)
Block(0,45,-3,LEAVES:3)
Block(0,45,-2,LOG:15)
Block(0,45,-1,LOG:7)
Block(0,45,0,LOG:7)
Block(0,45,1,LOG:15)
Block(0,45,2,LEAVES:3)
Block(0,45,3,LEAVES:3)
Block(0,45,4,LEAVES:3)
Block(0,46,-4,LEAVES:3)
Block(0,46,-3,LEAVES:3)
Block(0,46,-2,LEAVES:3)
Block(0,46,-1,LEAVES:3)
Block(0,46,0,LEAVES:3)
Block(0,46,1,LEAVES:3)
Block(0,46,2,LEAVES:3)
Block(0,46,3,LEAVES:3)
Block(0,46,4,LEAVES:3)
Block(0,47,-3,LEAVES:3)
Block(0,47,-2,LEAVES:3)
Block(0,47,-1,LEAVES:3)
Block(0,47,0,LEAVES:3)
Block(0,47,1,LEAVES:3)
Block(0,47,2,LEAVES:3)
Block(0,47,3,LEAVES:3)
Block(1,0,-2,LOG:3)
Block(1,0,-1,LOG:3)
Block(1,0,0,LOG:3)
Block(1,0,1,LOG:3)
Block(1,1,-2,LOG:3)
Block(1,1,-1,LOG:3)
Block(1,1,0,LOG:3)
Block(1,1,1,LOG:3)
Block(1,2,-2,LOG:3)
Block(1,2,-1,LOG:15)
Block(1,2,0,LOG:3)
Block(1,2,1,LOG:3)
Block(1,3,-2,LOG:3)
Block(1,3,-1,LOG:3)
Block(1,3,0,LOG:3)
Block(1,3,1,LOG:3)
Block(1,4,-2,LOG:3)
Block(1,4,-1,LOG:3)
Block(1,4,0,LOG:3)
Block(1,4,1,LOG:3)
Block(1,5,-2,LOG:3)
Block(1,5,-1,LOG:3)
Block(1,5,0,LOG:3)
Block(1,5,1,LOG:3)
Block(1,6,-2,LOG:3)
Block(1,6,-1,LOG:3)
Block(1,6,0,LOG:3)
Block(1,6,1,LOG:3)
Block(1,7,-2,LOG:3)
Block(1,7,-1,LOG:3)
Block(1,7,0,LOG:3)
Block(1,7,1,LOG:3)
Block(1,8,-2,LOG:3)
Block(1,8,-1,LOG:3)
Block(1,8,0,LOG:3)
Block(1,8,1,LOG:3)
Block(1,9,-2,LOG:3)
Block(1,9,-1,LOG:3)
Block(1,9,0,LOG:3)
Block(1,9,1,LOG:3)
Block(1,10,-2,LOG:3)
Block(1,10,-1,LOG:3)
Block(1,10,0,LOG:3)
Block(1,10,1,LOG:3)
Block(1,11,-2,LOG:3)
Block(1,11,-1,LOG:3)
Block(1,11,0,LOG:3)
Block(1,11,1,LOG:3)
Block(1,12,-2,LOG:3)
Block(1,12,-1,LOG:3)
Block(1,12,0,LOG:3)
Block(1,12,1,LOG:3)
Block(1,13,-2,LOG:3)
Block(1,13,-1,LOG:3)
Block(1,13,0,LOG:3)
Block(1,13,1,LOG:3)
Block(1,14,-2,LOG:3)
Block(1,14,-1,LOG:3)
Block(1,14,0,LOG:3)
Block(1,14,1,LOG:3)
Block(1,15,-2,LOG:3)
Block(1,15,-1,LOG:3)
Block(1,15,0,LOG:3)
Block(1,15,1,LOG:3)
Block(1,16,-2,LOG:3)
Block(1,16,-1,LOG:3)
Block(1,16,0,LOG:3)
Block(1,16,1,LOG:3)
Block(1,17,-2,LOG:3)
Block(1,17,-1,LOG:3)
Block(1,17,0,LOG:3)
Block(1,17,1,LOG:3)
Block(1,18,-2,LOG:3)
Block(1,18,-1,LOG:3)
Block(1,18,0,LOG:3)
Block(1,18,1,LOG:3)
Block(1,19,-2,LOG:3)
Block(1,19,-1,LOG:3)
Block(1,19,0,LOG:3)
Block(1,19,1,LOG:3)
Block(1,20,-2,LOG:3)
Block(1,20,-1,LOG:3)
Block(1,20,0,LOG:3)
Block(1,20,1,LOG:3)
Block(1,21,-2,LOG:3)
Block(1,21,-1,LOG:3)
Block(1,21,0,LOG:3)
Block(1,21,1,LOG:3)
Block(1,21,2,VINE:4)
Block(1,22,-2,LOG:3)
Block(1,22,-1,LOG:3)
Block(1,22,0,LOG:3)
Block(1,22,1,LOG:3)
Block(1,22,2,VINE:4)
Block(1,23,-2,LOG:3)
Block(1,23,-1,LOG:3)
Block(1,23,0,LOG:3)
Block(1,23,1,LOG:3)
Block(1,23,2,VINE:4)
Block(1,24,-2,LOG:3)
Block(1,24,-1,LOG:3)
Block(1,24,0,LOG:3)
Block(1,24,1,LOG:3)
Block(1,24,2,VINE:4)
Block(1,25,-6,LEAVES:3)
Block(1,25,-5,LEAVES:3)
Block(1,25,-2,LOG:3)
Block(1,25,-1,LOG:3)
Block(1,25,0,LOG:3)
Block(1,25,1,LOG:3)
Block(1,25,2,VINE:4)
Block(1,26,-8,LEAVES:3)
Block(1,26,-7,LEAVES:3)
Block(1,26,-6,LEAVES:3)
Block(1,26,-5,LEAVES:3)
Block(1,26,-4,LEAVES:3)
Block(1,26,-3,LEAVES:3)
Block(1,26,-2,LOG:3)
Block(1,26,-1,LOG:3)
Block(1,26,0,LOG:3)
Block(1,26,1,LOG:3)
Block(1,26,2,VINE:4)
Block(1,27,-9,LEAVES:3)
Block(1,27,-8,LEAVES:3)
Block(1,27,-7,LEAVES:3)
Block(1,27,-6,LEAVES:3)
Block(1,27,-5,LEAVES:3)
Block(1,27,-4,LEAVES:3)
Block(1,27,-3,LEAVES:3)
Block(1,27,-2,LOG:3)
Block(1,27,-1,LOG:3)
Block(1,27,0,LOG:3)
Block(1,27,1,LOG:3)
Block(1,27,2,VINE:4)
Block(1,28,-8,LEAVES:3)
Block(1,28,-7,LEAVES:3)
Block(1,28,-6,LEAVES:3)
Block(1,28,-5,LEAVES:3)
Block(1,28,-4,LEAVES:3)
Block(1,28,-3,LEAVES:3)
Block(1,28,-2,LOG:3)
Block(1,28,-1,LOG:3)
Block(1,28,0,LOG:3)
Block(1,28,1,LOG:3)
Block(1,28,2,VINE:4)
Block(1,29,-7,LEAVES:3)
Block(1,29,-6,LEAVES:3)
Block(1,29,-5,LEAVES:3)
Block(1,29,-4,LEAVES:3)
Block(1,29,-3,LEAVES:3)
Block(1,29,-2,LOG:3)
Block(1,29,-1,LOG:3)
Block(1,29,0,LOG:3)
Block(1,29,1,LOG:3)
Block(1,29,2,VINE:4)
Block(1,29,10,VINE:4)
Block(1,30,-5,LEAVES:3)
Block(1,30,-4,LEAVES:3)
Block(1,30,-3,LEAVES:3)
Block(1,30,-2,LOG:3)
Block(1,30,-1,LOG:3)
Block(1,30,0,LOG:3)
Block(1,30,1,LOG:3)
Block(1,30,6,LEAVES:3)
Block(1,30,7,LEAVES:3)
Block(1,30,10,VINE:4)
Block(1,31,-4,LEAVES:3)
Block(1,31,-3,LEAVES:3)
Block(1,31,-2,LOG:3)
Block(1,31,-1,LOG:3)
Block(1,31,0,LOG:3)
Block(1,31,1,LOG:3)
Block(1,31,4,LEAVES:3)
Block(1,31,5,LEAVES:3)
Block(1,31,6,LEAVES:3)
Block(1,31,7,LEAVES:3)
Block(1,31,8,LEAVES:3)
Block(1,31,9,LEAVES:3)
Block(1,31,10,VINE:4)
Block(1,32,-3,VINE:1)
Block(1,32,-2,LOG:3)
Block(1,32,-1,LOG:3)
Block(1,32,0,LOG:3)
Block(1,32,1,LOG:3)
Block(1,32,3,LEAVES:3)
Block(1,32,4,LEAVES:3)
Block(1,32,5,LEAVES:3)
Block(1,32,6,LEAVES:3)
Block(1,32,7,LEAVES:3)
Block(1,32,8,LEAVES:3)
Block(1,32,9,LEAVES:3)
Block(1,32,10,LEAVES:3)
Block(1,33,-3,VINE:1)
Block(1,33,-2,LOG:3)
Block(1,33,-1,LOG:3)
Block(1,33,0,LOG:3)
Block(1,33,1,LOG:3)
Block(1,33,2,LEAVES:3)
Block(1,33,3,LEAVES:3)
Block(1,33,4,LEAVES:3)
Block(1,33,5,LEAVES:3)
Block(1,33,6,LEAVES:3)
Block(1,33,7,LEAVES:3)
Block(1,33,8,LEAVES:3)
Block(1,33,9,LEAVES:3)
Block(1,34,-3,VINE:1)
Block(1,34,-2,LOG:3)
Block(1,34,-1,LOG:3)
Block(1,34,0,LOG:3)
Block(1,34,1,LOG:3)
Block(1,34,2,LEAVES:3)
Block(1,34,3,LEAVES:3)
Block(1,34,4,LEAVES:3)
Block(1,34,5,LEAVES:3)
Block(1,34,6,LEAVES:3)
Block(1,34,7,LEAVES:3)
Block(1,35,-3,VINE:1)
Block(1,35,-2,LOG:3)
Block(1,35,-1,LOG:3)
Block(1,35,0,LOG:3)
Block(1,35,1,LOG:3)
Block(1,35,2,LEAVES:3)
Block(1,35,3,LEAVES:3)
Block(1,35,4,LEAVES:3)
Block(1,35,5,LEAVES:3)
Block(1,36,-3,VINE:1)
Block(1,36,-2,LOG:3)
Block(1,36,-1,LOG:3)
Block(1,36,0,LOG:3)
Block(1,36,1,LOG:3)
Block(1,37,-3,VINE:1)
Block(1,37,-2,LOG:3)
Block(1,37,-1,LOG:3)
Block(1,37,0,LOG:3)
Block(1,37,1,LOG:3)
Block(1,38,-3,VINE:1)
Block(1,38,-2,LOG:3)
Block(1,38,-1,LOG:3)
Block(1,38,0,LOG:3)
Block(1,38,1,LOG:3)
Block(1,39,-3,VINE:1)
Block(1,39,-2,LOG:3)
Block(1,39,-1,LOG:3)
Block(1,39,0,LOG:3)
Block(1,39,1,LOG:3)
Block(1,40,-3,VINE:1)
Block(1,40,-2,LOG:3)
Block(1,40,-1,LOG:3)
Block(1,40,0,LOG:3)
Block(1,40,1,LOG:3)
Block(1,41,-3,VINE:1)
Block(1,41,-2,LOG:3)
Block(1,41,-1,LOG:3)
Block(1,41,0,LOG:3)
Block(1,41,1,LOG:3)
Block(1,42,-3,VINE:1)
Block(1,42,-2,LOG:3)
Block(1,42,-1,LOG:3)
Block(1,42,0,LOG:3)
Block(1,42,1,LOG:3)
Block(1,43,-4,LEAVES:3)
Block(1,43,-3,VINE:1)
Block(1,43,-2,LOG:3)
Block(1,43,-1,LOG:3)
Block(1,43,0,LOG:3)
Block(1,43,1,LOG:3)
Block(1,43,2,LEAVES:3)
Block(1,43,3,LEAVES:3)
Block(1,44,-5,LEAVES:3)
Block(1,44,-4,LEAVES:3)
Block(1,44,-3,LEAVES:3)
Block(1,44,-2,LOG:3)
Block(1,44,-1,LOG:3)
Block(1,44,0,LOG:3)
Block(1,44,1,LOG:3)
Block(1,44,2,LEAVES:3)
Block(1,44,3,LEAVES:3)
Block(1,44,4,LEAVES:3)
Block(1,45,-6,LEAVES:3)
Block(1,45,-5,LEAVES:3)
Block(1,45,-4,LEAVES:3)
Block(1,45,-3,LEAVES:3)
Block(1,45,-2,LOG:15)
Block(1,45,-1,LOG:7)
Block(1,45,0,LOG:11)
Block(1,45,1,LOG:15)
Block(1,45,2,LEAVES:3)
Block(1,45,3,LEAVES:3)
Block(1,45,4,LEAVES:3)
Block(1,46,-5,LEAVES:3)
Block(1,46,-4,LEAVES:3)
Block(1,46,-3,LEAVES:3)
Block(1,46,-2,LEAVES:3)
Block(1,46,-1,LEAVES:3)
Block(1,46,0,LEAVES:3)
Block(1,46,1,LEAVES:3)
Block(1,46,2,LEAVES:3)
Block(1,46,3,LEAVES:3)
Block(1,47,-2,LEAVES:3)
Block(1,47,-1,LEAVES:3)
Block(1,47,0,LEAVES:3)
Block(1,47,1,LEAVES:3)
Block(2,0,-1,LOG:3)
Block(2,0,0,LOG:3)
Block(2,1,-1,LOG:15)
Block(2,1,0,LOG:15)
Block(2,2,-1,LOG:3)
Block(2,2,0,LOG:3)
Block(2,3,-1,LOG:3)
Block(2,3,0,LOG:3)
Block(2,4,-1,LOG:3)
Block(2,4,0,LOG:3)
Block(2,5,-1,LOG:3)
Block(2,5,0,LOG:3)
Block(2,6,-1,LOG:3)
Block(2,6,0,LOG:3)
Block(2,7,-1,LOG:3)
Block(2,7,0,LOG:3)
Block(2,8,-1,LOG:3)
Block(2,8,0,LOG:3)
Block(2,9,-1,LOG:3)
Block(2,9,0,LOG:3)
Block(2,10,-1,LOG:3)
Block(2,10,0,LOG:3)
Block(2,11,-1,LOG:3)
Block(2,11,0,LOG:3)
Block(2,12,-1,LOG:3)
Block(2,12,0,LOG:3)
Block(2,13,-1,LOG:3)
Block(2,13,0,LOG:3)
Block(2,14,-1,LOG:3)
Block(2,14,0,LOG:3)
Block(2,15,-1,LOG:3)
Block(2,15,0,LOG:3)
Block(2,16,-1,LOG:3)
Block(2,16,0,LOG:3)
Block(2,17,-1,LOG:3)
Block(2,17,0,LOG:3)
Block(2,18,-1,LOG:3)
Block(2,18,0,LOG:3)
Block(2,19,-1,LOG:3)
Block(2,19,0,LOG:3)
Block(2,20,-1,LOG:3)
Block(2,20,0,LOG:3)
Block(2,21,-1,LOG:3)
Block(2,21,0,LOG:3)
Block(2,22,-1,LOG:3)
Block(2,22,0,LOG:3)
Block(2,23,-8,VINE:1)
Block(2,23,-1,LOG:3)
Block(2,23,0,LOG:3)
Block(2,24,-8,VINE:1)
Block(2,24,-1,LOG:3)
Block(2,24,0,LOG:3)
Block(2,25,-8,VINE:1)
Block(2,25,-1,LOG:3)
Block(2,25,0,LOG:3)
Block(2,26,-8,VINE:1)
Block(2,26,-7,LEAVES:3)
Block(2,26,-6,LEAVES:3)
Block(2,26,-5,LEAVES:3)
Block(2,26,-4,LEAVES:3)
Block(2,26,-1,LOG:3)
Block(2,26,0,LOG:3)
Block(2,27,-8,LEAVES:3)
Block(2,27,-7,LEAVES:3)
Block(2,27,-6,LEAVES:3)
Block(2,27,-5,LEAVES:3)
Block(2,27,-4,LEAVES:3)
Block(2,27,-3,LEAVES:3)
Block(2,27,-1,LOG:3)
Block(2,27,0,LOG:3)
Block(2,28,-7,LEAVES:3)
Block(2,28,-6,LEAVES:3)
Block(2,28,-5,LEAVES:3)
Block(2,28,-4,LEAVES:3)
Block(2,28,-3,LEAVES:3)
Block(2,28,-2,LEAVES:3)
Block(2,28,-1,LOG:3)
Block(2,28,0,LOG:3)
Block(2,29,-6,LEAVES:3)
Block(2,29,-5,LEAVES:3)
Block(2,29,-4,LEAVES:3)
Block(2,29,-3,LEAVES:3)
Block(2,29,-2,LEAVES:3)
Block(2,29,-1,LOG:3)
Block(2,29,0,LOG:3)
Block(2,30,-6,LEAVES:3)
Block(2,30,-5,LEAVES:3)
Block(2,30,-4,LEAVES:3)
Block(2,30,-3,LEAVES:3)
Block(2,30,-2,LOG:11)
Block(2,30,-1,LOG:3)
Block(2,30,0,LOG:3)
Block(2,30,6,LEAVES:3)
Block(2,31,-5,LEAVES:3)
Block(2,31,-4,LEAVES:3)
Block(2,31,-3,LEAVES:3)
Block(2,31,-2,LEAVES:3)
Block(2,31,-1,LOG:3)
Block(2,31,0,LOG:3)
Block(2,31,5,LEAVES:3)
Block(2,31,6,LEAVES:3)
Block(2,31,7,LEAVES:3)
Block(2,31,8,LEAVES:3)
Block(2,32,-4,LEAVES:3)
Block(2,32,-3,LEAVES:3)
Block(2,32,-2,LEAVES:3)
Block(2,32,-1,LOG:3)
Block(2,32,0,LOG:3)
Block(2,32,3,LEAVES:3)
Block(2,32,4,LEAVES:3)
Block(2,32,5,LEAVES:3)
Block(2,32,6,LEAVES:3)
Block(2,32,7,LEAVES:3)
Block(2,32,8,LEAVES:3)
Block(2,32,9,LEAVES:3)
Block(2,33,-1,LOG:3)
Block(2,33,0,LOG:3)
Block(2,33,2,LEAVES:3)
Block(2,33,3,LEAVES:3)
Block(2,33,4,LEAVES:3)
Block(2,33,5,LEAVES:3)
Block(2,33,6,LEAVES:3)
Block(2,33,7,LEAVES:3)
Block(2,33,8,LEAVES:3)
Block(2,34,-1,LOG:3)
Block(2,34,0,LOG:3)
Block(2,34,1,LEAVES:3)
Block(2,34,2,LEAVES:3)
Block(2,34,3,LEAVES:3)
Block(2,34,4,LEAVES:3)
Block(2,34,5,LEAVES:3)
Block(2,35,-1,LOG:3)
Block(2,35,0,LOG:3)
Block(2,35,2,LEAVES:3)
Block(2,35,3,LEAVES:3)
Block(2,35,4,LEAVES:3)
Block(2,36,-1,LOG:3)
Block(2,36,0,LOG:3)
Block(2,37,-1,LOG:3)
Block(2,37,0,LOG:3)
Block(2,38,-1,LOG:3)
Block(2,38,0,LOG:3)
Block(2,39,-1,LOG:3)
Block(2,39,0,LOG:3)
Block(2,40,-1,LOG:3)
Block(2,40,0,LOG:3)
Block(2,41,-1,LOG:3)
Block(2,41,0,LOG:3)
Block(2,42,-3,LEAVES:3)
Block(2,42,-2,LEAVES:3)
Block(2,42,-1,LOG:3)
Block(2,42,0,LOG:3)
Block(2,42,1,LEAVES:3)
Block(2,42,2,LEAVES:3)
Block(2,42,3,LEAVES:3)
Block(2,42,4,LEAVES:3)
Block(2,43,-3,LEAVES:3)
Block(2,43,-2,LEAVES:3)
Block(2,43,-1,LOG:3)
Block(2,43,0,LOG:3)
Block(2,43,1,LEAVES:3)
Block(2,43,2,LEAVES:3)
Block(2,43,3,LEAVES:3)
Block(2,43,4,LEAVES:3)
Block(2,43,5,LEAVES:3)
Block(2,44,-4,LEAVES:3)
Block(2,44,-3,LEAVES:3)
Block(2,44,-2,LEAVES:3)
Block(2,44,-1,LOG:3)
Block(2,44,0,LOG:3)
Block(2,44,1,LOG:11)
Block(2,44,2,LEAVES:3)
Block(2,44,3,LEAVES:3)
Block(2,44,4,LEAVES:3)
Block(2,44,5,LEAVES:3)
Block(2,45,-5,LEAVES:3)
Block(2,45,-4,LEAVES:3)
Block(2,45,-3,LEAVES:3)
Block(2,45,-2,LEAVES:3)
Block(2,45,-1,LOG:7)
Block(2,45,0,LOG:15)
Block(2,45,1,LEAVES:3)
Block(2,45,2,LEAVES:3)
Block(2,45,3,LEAVES:3)
Block(2,45,4,LEAVES:3)
Block(2,46,-4,LEAVES:3)
Block(2,46,-3,LEAVES:3)
Block(2,46,-2,LEAVES:3)
Block(2,46,-1,LEAVES:3)
Block(2,46,0,LEAVES:3)
Block(2,46,1,LEAVES:3)
Block(2,46,2,LEAVES:3)
Block(2,46,3,LEAVES:3)
Block(2,47,-2,LEAVES:3)
Block(2,47,-1,LEAVES:3)
Block(2,47,0,LEAVES:3)
Block(2,47,1,LEAVES:3)
Block(3,10,-1,VINE:2)
Block(3,11,-1,VINE:2)
Block(3,12,-1,VINE:2)
Block(3,13,-1,VINE:2)
Block(3,13,0,VINE:2)
Block(3,14,-1,VINE:2)
Block(3,14,0,VINE:2)
Block(3,15,-1,VINE:2)
Block(3,15,0,VINE:2)
Block(3,16,-1,VINE:2)
Block(3,16,0,VINE:2)
Block(3,17,0,VINE:2)
Block(3,18,0,VINE:2)
Block(3,19,0,VINE:2)
Block(3,20,0,VINE:2)
Block(3,21,0,VINE:2)
Block(3,26,-5,LEAVES:3)
Block(3,27,-7,LEAVES:3)
Block(3,27,-6,LEAVES:3)
Block(3,27,-5,LEAVES:3)
Block(3,27,-4,LEAVES:3)
Block(3,28,-7,LEAVES:3)
Block(3,28,-6,LEAVES:3)
Block(3,28,-5,LEAVES:3)
Block(3,28,-4,LEAVES:3)
Block(3,28,-3,LEAVES:3)
Block(3,28,-2,LEAVES:3)
Block(3,29,-6,LEAVES:3)
Block(3,29,-5,LEAVES:3)
Block(3,29,-4,LOG:11)
Block(3,29,-3,LEAVES:3)
Block(3,29,-2,LEAVES:3)
Block(3,29,-1,LEAVES:3)
Block(3,30,-7,LEAVES:3)
Block(3,30,-6,LEAVES:3)
Block(3,30,-5,LEAVES:3)
Block(3,30,-4,LEAVES:3)
Block(3,30,-3,LOG:11)
Block(3,30,-2,LEAVES:3)
Block(3,30,-1,LEAVES:3)
Block(3,30,0,LEAVES:3)
Block(3,31,-6,LEAVES:3)
Block(3,31,-5,LEAVES:3)
Block(3,31,-4,LEAVES:3)
Block(3,31,-3,LEAVES:3)
Block(3,31,-2,LEAVES:3)
Block(3,31,-1,LEAVES:3)
Block(3,31,0,VINE:2)
Block(3,31,7,LEAVES:3)
Block(3,32,-5,LEAVES:3)
Block(3,32,-4,LEAVES:3)
Block(3,32,-3,LEAVES:3)
Block(3,32,0,VINE:2)
Block(3,32,5,LEAVES:3)
Block(3,32,6,LEAVES:3)
Block(3,32,7,LEAVES:3)
Block(3,32,8,LEAVES:3)
Block(3,33,0,VINE:2)
Block(3,34,0,VINE:2)
Block(3,34,2,LEAVES:3)
Block(3,34,3,LEAVES:3)
Block(3,34,4,LEAVES:3)
Block(3,35,0,VINE:2)
Block(3,36,0,VINE:2)
Block(3,37,0,VINE:2)
Block(3,38,0,VINE:2)
Block(3,39,0,VINE:2)
Block(3,40,0,VINE:2)
Block(3,41,0,VINE:2)
Block(3,41,3,LEAVES:3)
Block(3,41,4,LEAVES:3)
Block(3,41,5,LEAVES:3)
Block(3,42,-4,LEAVES:3)
Block(3,42,-3,LEAVES:3)
Block(3,42,-2,LEAVES:3)
Block(3,42,-1,LEAVES:3)
Block(3,42,0,VINE:2)
Block(3,42,1,LEAVES:3)
Block(3,42,2,LEAVES:3)
Block(3,42,3,LEAVES:3)
Block(3,42,4,LEAVES:3)
Block(3,42,5,LEAVES:3)
Block(3,42,6,LEAVES:3)
Block(3,43,-4,LEAVES:3)
Block(3,43,-3,LEAVES:3)
Block(3,43,-2,LEAVES:3)
Block(3,43,-1,LEAVES:3)
Block(3,43,0,LEAVES:3)
Block(3,43,1,LEAVES:3)
Block(3,43,2,LEAVES:3)
Block(3,43,3,LOG:11)
Block(3,43,4,LEAVES:3)
Block(3,43,5,LEAVES:3)
Block(3,44,-5,LEAVES:3)
Block(3,44,-4,LEAVES:3)
Block(3,44,-3,LEAVES:3)
Block(3,44,-2,LEAVES:3)
Block(3,44,-1,LOG:7)
Block(3,44,0,LEAVES:3)
Block(3,44,1,LEAVES:3)
Block(3,44,2,LOG:11)
Block(3,44,3,LEAVES:3)
Block(3,44,4,LEAVES:3)
Block(3,44,5,LEAVES:3)
Block(3,45,-4,LEAVES:3)
Block(3,45,-3,LEAVES:3)
Block(3,45,-2,LEAVES:3)
Block(3,45,-1,LEAVES:3)
Block(3,45,0,LEAVES:3)
Block(3,45,1,LEAVES:3)
Block(3,45,2,LEAVES:3)
Block(3,45,3,LEAVES:3)
Block(3,45,4,LEAVES:3)
Block(3,45,5,LEAVES:3)
Block(3,46,-3,LEAVES:3)
Block(3,46,-2,LEAVES:3)
Block(3,46,-1,LEAVES:3)
Block(3,46,0,LEAVES:3)
Block(3,46,1,LEAVES:3)
Block(3,46,2,LEAVES:3)
Block(3,46,3,LEAVES:3)
Block(3,46,4,LEAVES:3)
Block(3,47,0,LEAVES:3)
Block(3,47,1,LEAVES:3)
Block(4,26,-6,LEAVES:3)
Block(4,26,-5,LEAVES:3)
Block(4,26,-4,LEAVES:3)
Block(4,27,-7,LEAVES:3)
Block(4,27,-6,LEAVES:3)
Block(4,27,-5,LEAVES:3)
Block(4,27,-4,LEAVES:3)
Block(4,27,-3,LEAVES:3)
Block(4,28,-8,LEAVES:3)
Block(4,28,-7,LEAVES:3)
Block(4,28,-6,LEAVES:3)
Block(4,28,-5,LEAVES:3)
Block(4,28,-4,LEAVES:3)
Block(4,28,-3,LEAVES:3)
Block(4,28,-2,LEAVES:3)
Block(4,29,-7,LEAVES:3)
Block(4,29,-6,LEAVES:3)
Block(4,29,-5,LEAVES:3)
Block(4,29,-4,LOG:11)
Block(4,29,-3,LEAVES:3)
Block(4,29,-2,LEAVES:3)
Block(4,29,-1,LEAVES:3)
Block(4,30,-6,LEAVES:3)
Block(4,30,-5,LEAVES:3)
Block(4,30,-4,LEAVES:3)
Block(4,30,-3,LEAVES:3)
Block(4,30,-2,LEAVES:3)
Block(4,30,-1,LEAVES:3)
Block(4,30,0,LEAVES:3)
Block(4,31,-5,LEAVES:3)
Block(4,31,-4,LEAVES:3)
Block(4,31,-3,LEAVES:3)
Block(4,31,-2,LEAVES:3)
Block(4,31,-1,LEAVES:3)
Block(4,32,-4,LEAVES:3)
Block(4,32,-3,LEAVES:3)
Block(4,32,6,LEAVES:3)
Block(4,40,3,LEAVES:3)
Block(4,40,4,LEAVES:3)
Block(4,41,-4,LEAVES:3)
Block(4,41,-3,LEAVES:3)
Block(4,41,-2,LEAVES:3)
Block(4,41,2,LEAVES:3)
Block(4,41,3,LEAVES:3)
Block(4,41,4,LEAVES:3)
Block(4,41,5,LEAVES:3)
Block(4,41,6,LEAVES:3)
Block(4,42,-5,LEAVES:3)
Block(4,42,-4,LEAVES:3)
Block(4,42,-3,LEAVES:3)
Block(4,42,-2,LEAVES:3)
Block(4,42,-1,LEAVES:3)
Block(4,42,0,LEAVES:3)
Block(4,42,1,LEAVES:3)
Block(4,42,2,LEAVES:3)
Block(4,42,3,LEAVES:3)
Block(4,42,4,LEAVES:3)
Block(4,42,5,LEAVES:3)
Block(4,42,6,LEAVES:3)
Block(4,42,7,LEAVES:3)
Block(4,43,-5,LEAVES:3)
Block(4,43,-4,LEAVES:3)
Block(4,43,-3,LEAVES:3)
Block(4,43,-2,LEAVES:3)
Block(4,43,-1,LEAVES:3)
Block(4,43,0,LEAVES:3)
Block(4,43,1,LEAVES:3)
Block(4,43,2,LEAVES:3)
Block(4,43,3,LOG:11)
Block(4,43,4,LEAVES:3)
Block(4,43,5,LEAVES:3)
Block(4,43,6,LEAVES:3)
Block(4,44,-6,LEAVES:3)
Block(4,44,-5,LEAVES:3)
Block(4,44,-4,LEAVES:3)
Block(4,44,-3,LEAVES:3)
Block(4,44,-2,LOG:7)
Block(4,44,-1,LEAVES:3)
Block(4,44,0,LEAVES:3)
Block(4,44,1,LEAVES:3)
Block(4,44,2,LEAVES:3)
Block(4,44,3,LEAVES:3)
Block(4,44,4,LEAVES:3)
Block(4,44,5,LEAVES:3)
Block(4,45,-4,LEAVES:3)
Block(4,45,-3,LEAVES:3)
Block(4,45,-2,LEAVES:3)
Block(4,45,-1,LEAVES:3)
Block(4,45,0,LEAVES:3)
Block(4,45,1,LEAVES:3)
Block(4,45,2,LEAVES:3)
Block(4,45,3,LEAVES:3)
Block(4,45,4,LEAVES:3)
Block(4,46,-4,LEAVES:3)
Block(4,46,-2,LEAVES:3)
Block(4,46,-1,LEAVES:3)
Block(4,46,0,LEAVES:3)
Block(4,46,1,LEAVES:3)
Block(4,46,2,LEAVES:3)
Block(4,46,3,LEAVES:3)
Block(5,26,-6,LEAVES:3)
Block(5,26,-5,LEAVES:3)
Block(5,27,-8,LEAVES:3)
Block(5,27,-7,LEAVES:3)
Block(5,27,-6,LEAVES:3)
Block(5,27,-5,LEAVES:3)
Block(5,27,-4,LEAVES:3)
Block(5,27,-3,LEAVES:3)
Block(5,27,-2,LEAVES:3)
Block(5,28,-8,LEAVES:3)
Block(5,28,-7,LEAVES:3)
Block(5,28,-6,LEAVES:3)
Block(5,28,-5,LOG:15)
Block(5,28,-4,LEAVES:3)
Block(5,28,-3,LEAVES:3)
Block(5,28,-2,LEAVES:3)
Block(5,28,-1,LEAVES:3)
Block(5,29,-8,LEAVES:3)
Block(5,29,-7,LEAVES:3)
Block(5,29,-6,LEAVES:3)
Block(5,29,-5,LEAVES:3)
Block(5,29,-4,LEAVES:3)
Block(5,29,-3,LEAVES:3)
Block(5,29,-2,LEAVES:3)
Block(5,29,-1,LEAVES:3)
Block(5,30,-5,LEAVES:3)
Block(5,30,-4,LEAVES:3)
Block(5,30,-3,LEAVES:3)
Block(5,30,-2,LEAVES:3)
Block(5,30,-1,LEAVES:3)
Block(5,31,-4,LEAVES:3)
Block(5,31,-3,LEAVES:3)
Block(5,31,-2,LEAVES:3)
Block(5,40,2,LEAVES:3)
Block(5,40,3,LEAVES:3)
Block(5,40,4,LEAVES:3)
Block(5,40,5,LEAVES:3)
Block(5,40,6,LEAVES:3)
Block(5,41,-5,LEAVES:3)
Block(5,41,-4,LEAVES:3)
Block(5,41,-3,LEAVES:3)
Block(5,41,-2,LEAVES:3)
Block(5,41,-1,LEAVES:3)
Block(5,41,1,LEAVES:3)
Block(5,41,2,LEAVES:3)
Block(5,41,3,LEAVES:3)
Block(5,41,4,LEAVES:3)
Block(5,41,5,LEAVES:3)
Block(5,41,6,LEAVES:3)
Block(5,41,7,LEAVES:3)
Block(5,42,-6,LEAVES:3)
Block(5,42,-5,LEAVES:3)
Block(5,42,-4,LEAVES:3)
Block(5,42,-3,LEAVES:3)
Block(5,42,-2,LEAVES:3)
Block(5,42,-1,LEAVES:3)
Block(5,42,0,LEAVES:3)
Block(5,42,1,LEAVES:3)
Block(5,42,2,LEAVES:3)
Block(5,42,3,LEAVES:3)
Block(5,42,4,LOG:11)
Block(5,42,5,LEAVES:3)
Block(5,42,6,LEAVES:3)
Block(5,42,7,LEAVES:3)
Block(5,42,8,LEAVES:3)
Block(5,43,-5,LEAVES:3)
Block(5,43,-4,LEAVES:3)
Block(5,43,-3,LEAVES:3)
Block(5,43,-2,LOG:7)
Block(5,43,-1,LEAVES:3)
Block(5,43,0,LEAVES:3)
Block(5,43,1,LEAVES:3)
Block(5,43,2,LEAVES:3)
Block(5,43,3,LEAVES:3)
Block(5,43,4,LEAVES:3)
Block(5,43,5,LEAVES:3)
Block(5,43,6,LEAVES:3)
Block(5,43,7,LEAVES:3)
Block(5,44,-5,LEAVES:3)
Block(5,44,-4,LEAVES:3)
Block(5,44,-3,LEAVES:3)
Block(5,44,-2,LEAVES:3)
Block(5,44,-1,LEAVES:3)
Block(5,44,0,LEAVES:3)
Block(5,44,1,LEAVES:3)
Block(5,44,2,LEAVES:3)
Block(5,44,3,LEAVES:3)
Block(5,44,4,LEAVES:3)
Block(5,44,5,LEAVES:3)
Block(5,44,6,LEAVES:3)
Block(5,45,-4,LEAVES:3)
Block(5,45,-3,LEAVES:3)
Block(5,45,-2,LEAVES:3)
Block(5,45,-1,LEAVES:3)
Block(5,45,0,LEAVES:3)
Block(5,45,1,LEAVES:3)
Block(5,45,2,LEAVES:3)
Block(5,45,3,LEAVES:3)
Block(5,46,2,LEAVES:3)
Block(6,27,-7,LEAVES:3)
Block(6,27,-6,LEAVES:3)
Block(6,27,-5,LEAVES:3)
Block(6,27,-4,LEAVES:3)
Block(6,27,-3,LEAVES:3)
Block(6,28,-8,LEAVES:3)
Block(6,28,-7,LEAVES:3)
Block(6,28,-6,LEAVES:3)
Block(6,28,-5,LEAVES:3)
Block(6,28,-4,LEAVES:3)
Block(6,28,-3,LEAVES:3)
Block(6,28,-2,LEAVES:3)
Block(6,29,-7,LEAVES:3)
Block(6,29,-6,LEAVES:3)
Block(6,29,-5,LEAVES:3)
Block(6,29,-4,LEAVES:3)
Block(6,29,-3,LEAVES:3)
Block(6,29,-2,LEAVES:3)
Block(6,29,-1,LEAVES:3)
Block(6,30,-5,LEAVES:3)
Block(6,30,-4,LEAVES:3)
Block(6,30,-3,LEAVES:3)
Block(6,30,-2,LEAVES:3)
Block(6,39,-4,LEAVES:3)
Block(6,40,-5,LEAVES:3)
Block(6,40,-4,LEAVES:3)
Block(6,40,-3,LEAVES:3)
Block(6,40,-1,LEAVES:3)
Block(6,40,3,LEAVES:3)
Block(6,40,4,LEAVES:3)
Block(6,40,5,LEAVES:3)
Block(6,40,6,LEAVES:3)
Block(6,41,-6,LEAVES:3)
Block(6,41,-5,LEAVES:3)
Block(6,41,-4,LEAVES:3)
Block(6,41,-3,LEAVES:3)
Block(6,41,-2,LEAVES:3)
Block(6,41,-1,LEAVES:3)
Block(6,41,2,LEAVES:3)
Block(6,41,3,LEAVES:3)
Block(6,41,4,LEAVES:3)
Block(6,41,5,LEAVES:3)
Block(6,41,6,LEAVES:3)
Block(6,41,7,LEAVES:3)
Block(6,41,8,LEAVES:3)
Block(6,41,10,VINE:4)
Block(6,42,-6,LEAVES:3)
Block(6,42,-5,LEAVES:3)
Block(6,42,-4,LEAVES:3)
Block(6,42,-3,LOG:7)
Block(6,42,-2,LEAVES:3)
Block(6,42,-1,LEAVES:3)
Block(6,42,0,LEAVES:3)
Block(6,42,1,LEAVES:3)
Block(6,42,2,LEAVES:3)
Block(6,42,3,LEAVES:3)
Block(6,42,4,LEAVES:3)
Block(6,42,5,LOG:15)
Block(6,42,6,LEAVES:3)
Block(6,42,7,LEAVES:3)
Block(6,42,8,LEAVES:3)
Block(6,42,9,LEAVES:3)
Block(6,42,10,VINE:4)
Block(6,43,-5,LEAVES:3)
Block(6,43,-4,LEAVES:3)
Block(6,43,-3,LEAVES:3)
Block(6,43,-2,LEAVES:3)
Block(6,43,-1,LEAVES:3)
Block(6,43,2,LEAVES:3)
Block(6,43,3,LEAVES:3)
Block(6,43,4,LEAVES:3)
Block(6,43,5,LEAVES:3)
Block(6,43,6,LEAVES:3)
Block(6,43,7,LEAVES:3)
Block(6,44,-4,LEAVES:3)
Block(6,44,-3,LEAVES:3)
Block(6,44,-2,LEAVES:3)
Block(6,44,-1,LEAVES:3)
Block(6,44,0,LEAVES:3)
Block(6,44,1,LEAVES:3)
Block(6,44,2,LEAVES:3)
Block(6,44,3,LEAVES:3)
Block(6,44,4,LEAVES:3)
Block(6,44,5,LEAVES:3)
Block(6,44,6,LEAVES:3)
Block(6,44,7,LEAVES:3)
Block(6,45,-3,LEAVES:3)
Block(6,45,-2,LEAVES:3)
Block(6,45,-1,LEAVES:3)
Block(6,45,0,LEAVES:3)
Block(7,26,-5,LEAVES:3)
Block(7,27,-6,LEAVES:3)
Block(7,27,-5,LEAVES:3)
Block(7,27,-4,LEAVES:3)
Block(7,28,-7,LEAVES:3)
Block(7,28,-6,LEAVES:3)
Block(7,28,-5,LEAVES:3)
Block(7,28,-4,LEAVES:3)
Block(7,28,-3,LEAVES:3)
Block(7,29,-6,LEAVES:3)
Block(7,29,-5,LEAVES:3)
Block(7,29,-4,LEAVES:3)
Block(7,30,-5,LEAVES:3)
Block(7,39,-4,LEAVES:3)
Block(7,39,-3,LEAVES:3)
Block(7,40,-6,LEAVES:3)
Block(7,40,-5,LEAVES:3)
Block(7,40,-4,LEAVES:3)
Block(7,40,-3,LEAVES:3)
Block(7,40,-2,LEAVES:3)
Block(7,40,4,LEAVES:3)
Block(7,40,5,LEAVES:3)
Block(7,41,-7,LEAVES:3)
Block(7,41,-6,LEAVES:3)
Block(7,41,-5,LEAVES:3)
Block(7,41,-4,LEAVES:3)
Block(7,41,-3,LEAVES:3)
Block(7,41,-2,LEAVES:3)
Block(7,41,-1,LEAVES:3)
Block(7,41,3,LEAVES:3)
Block(7,41,4,LEAVES:3)
Block(7,41,5,LEAVES:3)
Block(7,41,6,LEAVES:3)
Block(7,41,7,LEAVES:3)
Block(7,42,-6,LEAVES:3)
Block(7,42,-5,LEAVES:3)
Block(7,42,-4,LEAVES:3)
Block(7,42,-3,LOG:7)
Block(7,42,-2,LEAVES:3)
Block(7,42,-1,LEAVES:3)
Block(7,42,0,LEAVES:3)
Block(7,42,2,LEAVES:3)
Block(7,42,3,LEAVES:3)
Block(7,42,4,LEAVES:3)
Block(7,42,5,LEAVES:3)
Block(7,42,6,LEAVES:3)
Block(7,42,7,LEAVES:3)
Block(7,42,8,LEAVES:3)
Block(7,43,-5,LEAVES:3)
Block(7,43,-4,LEAVES:3)
Block(7,43,-3,LEAVES:3)
Block(7,43,-2,LEAVES:3)
Block(7,43,-1,LEAVES:3)
Block(7,43,3,LEAVES:3)
Block(7,43,4,LEAVES:3)
Block(7,43,5,LEAVES:3)
Block(7,43,6,LEAVES:3)
Block(7,43,7,LEAVES:3)
Block(7,44,-4,LEAVES:3)
Block(7,44,-3,LEAVES:3)
Block(7,44,-2,LEAVES:3)
Block(7,44,-1,LEAVES:3)
Block(7,44,4,LEAVES:3)
Block(7,44,5,LEAVES:3)
Block(7,44,6,LEAVES:3)
Block(8,22,-4,VINE:2)
Block(8,23,-4,VINE:2)
Block(8,24,-4,VINE:2)
Block(8,25,-4,VINE:2)
Block(8,26,-4,VINE:2)
Block(8,27,-5,LEAVES:3)
Block(8,27,-4,VINE:2)
Block(8,28,-6,LEAVES:3)
Block(8,28,-5,LEAVES:3)
Block(8,28,-4,LEAVES:3)
Block(8,39,-5,LEAVES:3)
Block(8,39,-4,LEAVES:3)
Block(8,39,-3,LEAVES:3)
Block(8,39,-2,LEAVES:3)
Block(8,40,-6,LEAVES:3)
Block(8,40,-5,LEAVES:3)
Block(8,40,-4,LEAVES:3)
Block(8,40,-3,LEAVES:3)
Block(8,40,-2,LEAVES:3)
Block(8,40,5,LEAVES:3)
Block(8,41,-7,LEAVES:3)
Block(8,41,-6,LEAVES:3)
Block(8,41,-5,LEAVES:3)
Block(8,41,-4,LOG:15)
Block(8,41,-3,LEAVES:3)
Block(8,41,-2,LEAVES:3)
Block(8,41,-1,LEAVES:3)
Block(8,41,0,LEAVES:3)
Block(8,41,4,LEAVES:3)
Block(8,41,5,LEAVES:3)
Block(8,41,6,LEAVES:3)
Block(8,42,-6,LEAVES:3)
Block(8,42,-5,LEAVES:3)
Block(8,42,-4,LEAVES:3)
Block(8,42,-3,LEAVES:3)
Block(8,42,-2,LEAVES:3)
Block(8,42,-1,LEAVES:3)
Block(8,42,3,LEAVES:3)
Block(8,42,4,LEAVES:3)
Block(8,42,5,LEAVES:3)
Block(8,42,6,LEAVES:3)
Block(8,42,7,LEAVES:3)
Block(8,43,-4,LEAVES:3)
Block(8,43,-3,LEAVES:3)
Block(8,43,-2,LEAVES:3)
Block(8,43,4,LEAVES:3)
Block(8,43,5,LEAVES:3)
Block(8,43,6,LEAVES:3)
Block(8,44,-3,LEAVES:3)
Block(8,44,-2,LEAVES:3)
Block(8,44,5,LEAVES:3)
Block(9,39,-5,LEAVES:3)
Block(9,39,-4,LEAVES:3)
Block(9,39,-3,LEAVES:3)
Block(9,40,-6,LEAVES:3)
Block(9,40,-5,LEAVES:3)
Block(9,40,-4,LEAVES:3)
Block(9,40,-3,LEAVES:3)
Block(9,40,-2,LEAVES:3)
Block(9,41,-7,LEAVES:3)
Block(9,41,-6,LEAVES:3)
Block(9,41,-5,LEAVES:3)
Block(9,41,-4,LEAVES:3)
Block(9,41,-3,LEAVES:3)
Block(9,41,-2,LEAVES:3)
Block(9,41,-1,LEAVES:3)
Block(9,42,-6,LEAVES:3)
Block(9,42,-5,LEAVES:3)
Block(9,42,-4,LEAVES:3)
Block(9,42,-3,LEAVES:3)
Block(9,42,-2,LEAVES:3)
Block(9,42,4,LEAVES:3)
Block(9,42,5,LEAVES:3)
Block(9,42,6,LEAVES:3)
Block(9,43,-4,LEAVES:3)
Block(9,43,-3,LEAVES:3)
Block(10,40,-5,LEAVES:3)
Block(10,41,-5,LEAVES:3)
Block(10,41,-4,LEAVES:3)
Block(10,41,-3,LEAVES:3)
Block(10,42,-4,LEAVES:3)
Block(10,42,-3,LEAVES:3)

#######################################################################
# +-----------------------------------------------------------------+ #
# |                            BO3 checks                           | #
# +-----------------------------------------------------------------+ #
#######################################################################

BlockCheck(0,-1,0,GRASS:0,DIRT:0)
BlockCheck(1,-1,0,GRASS:0,DIRT:0)
BlockCheck(0,-1,1,GRASS:0,DIRT:0)
BlockCheck(1,-1,1,GRASS:0,DIRT:0)

#######################################################################
# +-----------------------------------------------------------------+ #
# |                             Branches                            | #
# +-----------------------------------------------------------------+ #
#######################################################################


#######################################################################
# +-----------------------------------------------------------------+ #
# |                             Entities                            | #
# +-----------------------------------------------------------------+ #
#######################################################################


#######################################################################
# +-----------------------------------------------------------------+ #
# |                            Particles                            | #
# +-----------------------------------------------------------------+ #
#######################################################################


#######################################################################
# +-----------------------------------------------------------------+ #
# |                             Spawners                            | #
# +-----------------------------------------------------------------+ #
#######################################################################


#######################################################################
# +-----------------------------------------------------------------+ #
# |                             ModData                             | #
# +-----------------------------------------------------------------+ #
#######################################################################

