
#######################################################################
# +-----------------------------------------------------------------+ #
# |                            BO3 object                           | #
# +-----------------------------------------------------------------+ #
#######################################################################

Author: Unknown

Description: This BO3 was converted from a schematic using OTGEdit. The author and description information of the schematic could not be found. If you know who the author of the schematic is then please add this information.

Version: 3

SettingsMode: WriteWithoutComments


#######################################################################
# +-----------------------------------------------------------------+ #
# |                          Main settings                          | #
# +-----------------------------------------------------------------+ #
#######################################################################

Tree: true

Frequency: 1

Rarity: 100.0

RotateRandomly: true

SpawnHeight: highestSolidBlock

SpawnHeightOffset: 0

SpawnHeightVariance: 0

##############################
# Height Limits for the BO3. #
##############################

MinHeight: 20

MaxHeight: 255

######################
# Extrusion settings #
######################

ExtrudeMode: None

ExtrudeThroughBlocks: AIR

MaxBranchDepth: 10

ExcludedBiomes: All


#######################################################################
# +-----------------------------------------------------------------+ #
# |                      Source block settings                      | #
# +-----------------------------------------------------------------+ #
#######################################################################

SourceBlocks: AIR

MaxPercentageOutsideSourceBlock: 100

OutsideSourceBlock: dontPlace

DoReplaceBlocks: true

IsOTGPlus: false


#######################################################################
# +-----------------------------------------------------------------+ #
# |                              Blocks                             | #
# +-----------------------------------------------------------------+ #
#######################################################################

Block(-15,50,-1,LEAVES:3)
Block(-14,49,-1,LEAVES:3)
Block(-14,50,-2,LEAVES:3)
Block(-14,50,-1,LEAVES:3)
Block(-14,50,0,LEAVES:3)
Block(-14,51,-1,LEAVES:3)
Block(-13,49,-2,LEAVES:3)
Block(-13,49,-1,LEAVES:3)
Block(-13,49,0,LEAVES:3)
Block(-13,50,-3,LEAVES:3)
Block(-13,50,-2,LEAVES:3)
Block(-13,50,-1,LEAVES:3)
Block(-13,50,0,LEAVES:3)
Block(-13,50,1,LEAVES:3)
Block(-13,51,-2,LEAVES:3)
Block(-13,51,-1,LEAVES:3)
Block(-13,51,0,LEAVES:3)
Block(-12,44,4,LEAVES:3)
Block(-12,45,3,LEAVES:3)
Block(-12,45,4,LEAVES:3)
Block(-12,45,5,LEAVES:3)
Block(-12,46,4,LEAVES:3)
Block(-12,48,-1,LEAVES:3)
Block(-12,48,0,LEAVES:3)
Block(-12,49,-3,LEAVES:3)
Block(-12,49,-2,LEAVES:3)
Block(-12,49,-1,LEAVES:3)
Block(-12,49,0,LEAVES:3)
Block(-12,49,1,LEAVES:3)
Block(-12,50,-4,LEAVES:3)
Block(-12,50,-3,LEAVES:3)
Block(-12,50,-2,LEAVES:3)
Block(-12,50,-1,LEAVES:3)
Block(-12,50,0,LEAVES:3)
Block(-12,50,1,LEAVES:3)
Block(-12,50,2,LEAVES:3)
Block(-12,51,-3,LEAVES:3)
Block(-12,51,-2,LEAVES:3)
Block(-12,51,-1,LEAVES:3)
Block(-12,51,0,LEAVES:3)
Block(-12,51,1,LEAVES:3)
Block(-12,52,-1,LEAVES:3)
Block(-12,52,0,LEAVES:3)
Block(-11,43,4,LEAVES:3)
Block(-11,44,3,LEAVES:3)
Block(-11,44,4,LEAVES:3)
Block(-11,44,5,LEAVES:3)
Block(-11,45,2,LEAVES:3)
Block(-11,45,3,LEAVES:3)
Block(-11,45,4,LEAVES:3)
Block(-11,45,5,LEAVES:3)
Block(-11,45,6,LEAVES:3)
Block(-11,46,3,LEAVES:3)
Block(-11,46,4,LEAVES:3)
Block(-11,46,5,LEAVES:3)
Block(-11,47,4,LEAVES:3)
Block(-11,48,-3,LEAVES:3)
Block(-11,48,-2,LEAVES:3)
Block(-11,48,-1,LEAVES:3)
Block(-11,48,0,LEAVES:3)
Block(-11,48,1,LEAVES:3)
Block(-11,49,-4,LEAVES:3)
Block(-11,49,-3,LEAVES:3)
Block(-11,49,-2,LEAVES:3)
Block(-11,49,-1,LEAVES:3)
Block(-11,49,0,LEAVES:3)
Block(-11,49,1,LEAVES:3)
Block(-11,49,2,LEAVES:3)
Block(-11,50,-5,LEAVES:3)
Block(-11,50,-4,LEAVES:3)
Block(-11,50,-3,LEAVES:3)
Block(-11,50,-2,LEAVES:3)
Block(-11,50,-1,LOG:15)
Block(-11,50,0,LEAVES:3)
Block(-11,50,1,LEAVES:3)
Block(-11,50,2,LEAVES:3)
Block(-11,51,-4,LEAVES:3)
Block(-11,51,-3,LEAVES:3)
Block(-11,51,-2,LEAVES:3)
Block(-11,51,-1,LEAVES:3)
Block(-11,51,0,LEAVES:3)
Block(-11,51,1,LEAVES:3)
Block(-11,51,2,LEAVES:3)
Block(-11,52,-3,LEAVES:3)
Block(-11,52,-1,LEAVES:3)
Block(-11,52,0,LEAVES:3)
Block(-11,52,1,LEAVES:3)
Block(-10,43,3,LEAVES:3)
Block(-10,44,2,LEAVES:3)
Block(-10,44,3,LEAVES:3)
Block(-10,44,4,LEAVES:3)
Block(-10,44,5,LEAVES:3)
Block(-10,44,6,LEAVES:3)
Block(-10,45,1,LEAVES:3)
Block(-10,45,2,LEAVES:3)
Block(-10,45,3,LEAVES:3)
Block(-10,45,4,LEAVES:3)
Block(-10,45,5,LEAVES:3)
Block(-10,45,6,LEAVES:3)
Block(-10,45,7,LEAVES:3)
Block(-10,46,2,LEAVES:3)
Block(-10,46,3,LEAVES:3)
Block(-10,46,4,LEAVES:3)
Block(-10,46,5,LEAVES:3)
Block(-10,46,6,LEAVES:3)
Block(-10,47,3,LEAVES:3)
Block(-10,48,-2,LEAVES:3)
Block(-10,48,-1,LEAVES:3)
Block(-10,48,0,LEAVES:3)
Block(-10,49,-3,LEAVES:3)
Block(-10,49,-2,LEAVES:3)
Block(-10,49,-1,LEAVES:3)
Block(-10,49,0,LEAVES:3)
Block(-10,49,1,LEAVES:3)
Block(-10,50,-4,LEAVES:3)
Block(-10,50,-3,LEAVES:3)
Block(-10,50,-2,LEAVES:3)
Block(-10,50,-1,LEAVES:3)
Block(-10,50,0,LEAVES:3)
Block(-10,50,1,LEAVES:3)
Block(-10,50,2,LEAVES:3)
Block(-10,51,-3,LEAVES:3)
Block(-10,51,-2,LEAVES:3)
Block(-10,51,-1,LEAVES:3)
Block(-10,51,0,LOG:7)
Block(-10,51,1,LEAVES:3)
Block(-10,52,-2,LEAVES:3)
Block(-10,52,-1,LEAVES:3)
Block(-10,52,0,LEAVES:3)
Block(-10,52,1,LEAVES:3)
Block(-10,52,2,LEAVES:3)
Block(-10,53,-1,LEAVES:3)
Block(-10,53,0,LEAVES:3)
Block(-10,53,1,LEAVES:3)
Block(-9,43,4,LEAVES:3)
Block(-9,43,6,LEAVES:3)
Block(-9,44,2,LEAVES:3)
Block(-9,44,3,LEAVES:3)
Block(-9,44,4,LEAVES:3)
Block(-9,44,5,LEAVES:3)
Block(-9,44,6,LEAVES:3)
Block(-9,44,7,LEAVES:3)
Block(-9,45,1,LEAVES:3)
Block(-9,45,2,LEAVES:3)
Block(-9,45,3,LEAVES:3)
Block(-9,45,4,LOG:15)
Block(-9,45,5,LEAVES:3)
Block(-9,45,6,LEAVES:3)
Block(-9,45,7,LEAVES:3)
Block(-9,46,1,LEAVES:3)
Block(-9,46,2,LEAVES:3)
Block(-9,46,3,LEAVES:3)
Block(-9,46,4,LEAVES:3)
Block(-9,46,5,LEAVES:3)
Block(-9,46,6,LEAVES:3)
Block(-9,46,7,LEAVES:3)
Block(-9,47,2,LEAVES:3)
Block(-9,47,3,LEAVES:3)
Block(-9,47,4,LEAVES:3)
Block(-9,47,5,LEAVES:3)
Block(-9,47,6,LEAVES:3)
Block(-9,48,-1,LEAVES:3)
Block(-9,48,3,LEAVES:3)
Block(-9,49,-2,LEAVES:3)
Block(-9,49,-1,LEAVES:3)
Block(-9,49,0,LEAVES:3)
Block(-9,50,-3,LEAVES:3)
Block(-9,50,-2,LEAVES:3)
Block(-9,50,-1,LEAVES:3)
Block(-9,50,0,LEAVES:3)
Block(-9,50,1,LEAVES:3)
Block(-9,51,-2,LEAVES:3)
Block(-9,51,-1,LEAVES:3)
Block(-9,51,0,LOG:7)
Block(-9,51,1,LEAVES:3)
Block(-9,51,2,LEAVES:3)
Block(-9,52,-3,LEAVES:3)
Block(-9,52,-2,LEAVES:3)
Block(-9,52,-1,LEAVES:3)
Block(-9,52,0,LEAVES:3)
Block(-9,52,1,LEAVES:3)
Block(-9,52,2,LEAVES:3)
Block(-9,52,3,LEAVES:3)
Block(-9,53,-2,LEAVES:3)
Block(-9,53,-1,LEAVES:3)
Block(-9,53,0,LEAVES:3)
Block(-9,53,1,LEAVES:3)
Block(-9,53,2,LEAVES:3)
Block(-9,54,0,LEAVES:3)
Block(-8,44,2,LEAVES:3)
Block(-8,44,3,LEAVES:3)
Block(-8,44,4,LEAVES:3)
Block(-8,44,5,LEAVES:3)
Block(-8,44,6,LEAVES:3)
Block(-8,45,1,LEAVES:3)
Block(-8,45,2,LEAVES:3)
Block(-8,45,3,LEAVES:3)
Block(-8,45,4,LEAVES:3)
Block(-8,45,5,LEAVES:3)
Block(-8,45,6,LEAVES:3)
Block(-8,45,7,LEAVES:3)
Block(-8,46,0,LEAVES:3)
Block(-8,46,1,LEAVES:3)
Block(-8,46,2,LEAVES:3)
Block(-8,46,3,LOG:7)
Block(-8,46,4,LEAVES:3)
Block(-8,46,5,LEAVES:3)
Block(-8,46,6,LEAVES:3)
Block(-8,47,1,LEAVES:3)
Block(-8,47,2,LEAVES:3)
Block(-8,47,3,LEAVES:3)
Block(-8,47,4,LEAVES:3)
Block(-8,47,5,LEAVES:3)
Block(-8,48,1,LEAVES:3)
Block(-8,48,2,LEAVES:3)
Block(-8,48,3,LEAVES:3)
Block(-8,49,2,LEAVES:3)
Block(-8,50,-2,LEAVES:3)
Block(-8,50,-1,LEAVES:3)
Block(-8,50,0,LEAVES:3)
Block(-8,50,1,LEAVES:3)
Block(-8,51,-2,LEAVES:3)
Block(-8,51,-1,LEAVES:3)
Block(-8,51,0,LEAVES:3)
Block(-8,51,1,LEAVES:3)
Block(-8,51,2,LEAVES:3)
Block(-8,51,3,LEAVES:3)
Block(-8,52,-4,LEAVES:3)
Block(-8,52,-3,LEAVES:3)
Block(-8,52,-2,LEAVES:3)
Block(-8,52,-1,LEAVES:3)
Block(-8,52,0,LOG:7)
Block(-8,52,1,LEAVES:3)
Block(-8,52,2,LEAVES:3)
Block(-8,52,3,LEAVES:3)
Block(-8,52,4,LEAVES:3)
Block(-8,53,-3,LEAVES:3)
Block(-8,53,-2,LEAVES:3)
Block(-8,53,-1,LEAVES:3)
Block(-8,53,0,LEAVES:3)
Block(-8,53,1,LEAVES:3)
Block(-8,53,2,LEAVES:3)
Block(-8,54,-2,LEAVES:3)
Block(-8,54,-1,LEAVES:3)
Block(-8,54,0,LEAVES:3)
Block(-8,54,1,LEAVES:3)
Block(-7,43,4,LEAVES:3)
Block(-7,44,2,LEAVES:3)
Block(-7,44,3,LEAVES:3)
Block(-7,44,4,LEAVES:3)
Block(-7,44,5,LEAVES:3)
Block(-7,45,0,LEAVES:3)
Block(-7,45,1,LEAVES:3)
Block(-7,45,2,LEAVES:3)
Block(-7,45,3,LEAVES:3)
Block(-7,45,4,LEAVES:3)
Block(-7,45,5,LEAVES:3)
Block(-7,45,6,LEAVES:3)
Block(-7,46,-1,LEAVES:3)
Block(-7,46,0,LEAVES:3)
Block(-7,46,1,LEAVES:3)
Block(-7,46,2,LEAVES:3)
Block(-7,46,3,LOG:7)
Block(-7,46,4,LEAVES:3)
Block(-7,46,5,LEAVES:3)
Block(-7,46,6,LEAVES:3)
Block(-7,46,7,LEAVES:3)
Block(-7,47,0,LEAVES:3)
Block(-7,47,1,LEAVES:3)
Block(-7,47,2,LEAVES:3)
Block(-7,47,3,LEAVES:3)
Block(-7,47,4,LEAVES:3)
Block(-7,47,5,LEAVES:3)
Block(-7,48,0,LEAVES:3)
Block(-7,48,1,LEAVES:3)
Block(-7,48,2,LEAVES:3)
Block(-7,48,3,LEAVES:3)
Block(-7,48,4,LEAVES:3)
Block(-7,48,5,LEAVES:3)
Block(-7,49,1,LEAVES:3)
Block(-7,49,2,LEAVES:3)
Block(-7,49,3,LEAVES:3)
Block(-7,51,-2,LEAVES:3)
Block(-7,51,-1,LEAVES:3)
Block(-7,51,0,LEAVES:3)
Block(-7,51,1,LEAVES:3)
Block(-7,51,2,LEAVES:3)
Block(-7,52,-3,LEAVES:3)
Block(-7,52,-2,LEAVES:3)
Block(-7,52,-1,LEAVES:3)
Block(-7,52,0,LOG:7)
Block(-7,52,1,LEAVES:3)
Block(-7,52,2,LEAVES:3)
Block(-7,52,3,LEAVES:3)
Block(-7,53,-2,LEAVES:3)
Block(-7,53,-1,LEAVES:3)
Block(-7,53,0,LEAVES:3)
Block(-7,53,1,LEAVES:3)
Block(-7,53,2,LEAVES:3)
Block(-7,54,-1,LEAVES:3)
Block(-7,54,0,LEAVES:3)
Block(-7,54,1,LEAVES:3)
Block(-7,55,0,LEAVES:3)
Block(-7,55,1,VINE:12)
Block(-6,29,-5,LEAVES:3)
Block(-6,30,-3,LEAVES:3)
Block(-6,44,-4,VINE:1)
Block(-6,44,3,LEAVES:3)
Block(-6,44,4,LEAVES:3)
Block(-6,45,-4,VINE:1)
Block(-6,45,1,LEAVES:3)
Block(-6,45,2,LEAVES:3)
Block(-6,45,3,LEAVES:3)
Block(-6,45,4,LEAVES:3)
Block(-6,45,5,LEAVES:3)
Block(-6,46,-4,VINE:1)
Block(-6,46,0,LEAVES:3)
Block(-6,46,1,LEAVES:3)
Block(-6,46,2,LEAVES:3)
Block(-6,46,3,LEAVES:3)
Block(-6,46,4,LEAVES:3)
Block(-6,46,5,LEAVES:3)
Block(-6,46,6,LEAVES:3)
Block(-6,47,-4,VINE:1)
Block(-6,47,0,LEAVES:3)
Block(-6,47,1,LEAVES:3)
Block(-6,47,2,LOG:7)
Block(-6,47,3,LOG:7)
Block(-6,47,4,LEAVES:3)
Block(-6,47,5,LEAVES:3)
Block(-6,48,-4,VINE:1)
Block(-6,48,-1,LEAVES:3)
Block(-6,48,0,LEAVES:3)
Block(-6,48,1,LEAVES:3)
Block(-6,48,2,LEAVES:3)
Block(-6,48,3,LEAVES:3)
Block(-6,48,4,LEAVES:3)
Block(-6,48,5,LEAVES:3)
Block(-6,49,-4,VINE:1)
Block(-6,49,0,LEAVES:3)
Block(-6,49,1,LEAVES:3)
Block(-6,49,2,LEAVES:3)
Block(-6,49,3,LEAVES:3)
Block(-6,49,4,LEAVES:3)
Block(-6,50,-4,VINE:1)
Block(-6,50,1,LEAVES:3)
Block(-6,50,2,LEAVES:3)
Block(-6,51,-4,VINE:1)
Block(-6,51,-1,LEAVES:3)
Block(-6,51,0,LEAVES:3)
Block(-6,51,1,LEAVES:3)
Block(-6,52,-4,VINE:1)
Block(-6,52,-2,LEAVES:3)
Block(-6,52,-1,LEAVES:3)
Block(-6,52,0,LOG:7)
Block(-6,52,1,LEAVES:3)
Block(-6,52,2,LEAVES:3)
Block(-6,53,-4,VINE:1)
Block(-6,53,-3,LEAVES:3)
Block(-6,53,-2,LEAVES:3)
Block(-6,53,-1,LEAVES:3)
Block(-6,53,0,LEAVES:3)
Block(-6,53,1,LEAVES:3)
Block(-6,53,2,LEAVES:3)
Block(-6,53,3,LEAVES:3)
Block(-6,54,-2,LEAVES:3)
Block(-6,54,-1,LEAVES:3)
Block(-6,54,0,LEAVES:3)
Block(-6,54,1,LEAVES:3)
Block(-6,54,2,LEAVES:3)
Block(-6,55,1,LEAVES:3)
Block(-6,55,2,VINE:12)
Block(-5,11,4,VINE:4)
Block(-5,12,-2,VINE:8)
Block(-5,12,4,VINE:4)
Block(-5,13,-2,VINE:8)
Block(-5,13,4,VINE:4)
Block(-5,14,-2,VINE:8)
Block(-5,14,4,VINE:4)
Block(-5,15,-2,VINE:8)
Block(-5,15,3,LEAVES:3)
Block(-5,15,4,VINE:4)
Block(-5,16,-2,VINE:8)
Block(-5,17,-2,VINE:8)
Block(-5,18,-2,VINE:8)
Block(-5,19,-2,VINE:8)
Block(-5,20,-2,VINE:8)
Block(-5,21,-2,VINE:8)
Block(-5,28,-5,LEAVES:3)
Block(-5,29,-6,LEAVES:3)
Block(-5,29,-5,LEAVES:3)
Block(-5,29,-4,LEAVES:3)
Block(-5,30,-5,LEAVES:3)
Block(-5,30,-4,LEAVES:3)
Block(-5,30,-3,LEAVES:3)
Block(-5,30,-2,LEAVES:3)
Block(-5,41,-3,VINE:1)
Block(-5,42,-3,VINE:1)
Block(-5,43,-3,VINE:1)
Block(-5,44,-3,VINE:1)
Block(-5,45,-3,VINE:1)
Block(-5,45,2,LEAVES:3)
Block(-5,45,3,LEAVES:3)
Block(-5,45,4,LEAVES:3)
Block(-5,46,-3,VINE:1)
Block(-5,46,1,LEAVES:3)
Block(-5,46,2,LEAVES:3)
Block(-5,46,3,LEAVES:3)
Block(-5,46,4,LEAVES:3)
Block(-5,46,5,LEAVES:3)
Block(-5,47,-3,VINE:1)
Block(-5,47,0,LEAVES:3)
Block(-5,47,1,LEAVES:3)
Block(-5,47,2,LEAVES:3)
Block(-5,47,3,LEAVES:3)
Block(-5,47,4,LEAVES:3)
Block(-5,47,5,LEAVES:3)
Block(-5,48,-4,VINE:9)
Block(-5,48,-3,VINE:1)
Block(-5,48,-2,LEAVES:3)
Block(-5,48,-1,LEAVES:3)
Block(-5,48,0,LEAVES:3)
Block(-5,48,1,LEAVES:3)
Block(-5,48,2,LOG:7)
Block(-5,48,3,LEAVES:3)
Block(-5,48,4,LEAVES:3)
Block(-5,48,5,LEAVES:3)
Block(-5,48,6,LEAVES:3)
Block(-5,49,-4,VINE:9)
Block(-5,49,0,LEAVES:3)
Block(-5,49,1,LEAVES:3)
Block(-5,49,2,LEAVES:3)
Block(-5,49,3,LEAVES:3)
Block(-5,49,4,LEAVES:3)
Block(-5,50,-4,VINE:9)
Block(-5,50,0,LEAVES:3)
Block(-5,50,1,LEAVES:3)
Block(-5,50,2,LEAVES:3)
Block(-5,50,3,LEAVES:3)
Block(-5,51,-4,VINE:9)
Block(-5,51,-2,LEAVES:3)
Block(-5,51,-1,LEAVES:3)
Block(-5,51,0,LEAVES:3)
Block(-5,51,1,LEAVES:3)
Block(-5,52,-4,VINE:9)
Block(-5,52,-3,LEAVES:3)
Block(-5,52,-2,LEAVES:3)
Block(-5,52,-1,LEAVES:3)
Block(-5,52,0,LEAVES:3)
Block(-5,52,1,LEAVES:3)
Block(-5,52,2,LEAVES:3)
Block(-5,53,-4,VINE:9)
Block(-5,53,-3,LEAVES:3)
Block(-5,53,-2,LEAVES:3)
Block(-5,53,-1,LEAVES:3)
Block(-5,53,0,LOG:7)
Block(-5,53,1,LEAVES:3)
Block(-5,53,2,LEAVES:3)
Block(-5,53,3,LEAVES:3)
Block(-5,53,4,LEAVES:3)
Block(-5,54,-2,LEAVES:3)
Block(-5,54,-1,LEAVES:3)
Block(-5,54,0,LEAVES:3)
Block(-5,54,1,LEAVES:3)
Block(-5,54,2,LEAVES:3)
Block(-5,54,3,LEAVES:3)
Block(-5,55,-1,LEAVES:3)
Block(-5,55,0,LEAVES:3)
Block(-5,55,1,LEAVES:3)
Block(-5,55,2,LEAVES:3)
Block(-5,55,3,VINE:4)
Block(-5,56,0,LEAVES:3)
Block(-4,0,1,LOG:3)
Block(-4,1,1,LOG:3)
Block(-4,2,1,LOG:3)
Block(-4,3,1,LOG:3)
Block(-4,4,1,LOG:3)
Block(-4,5,1,LOG:3)
Block(-4,6,0,VINE:8)
Block(-4,6,1,LOG:15)
Block(-4,7,0,VINE:8)
Block(-4,7,1,VINE:8)
Block(-4,8,-2,VINE:8)
Block(-4,8,0,VINE:8)
Block(-4,8,1,VINE:8)
Block(-4,9,-2,VINE:8)
Block(-4,9,0,VINE:8)
Block(-4,9,1,VINE:8)
Block(-4,10,-2,VINE:8)
Block(-4,10,0,VINE:8)
Block(-4,10,1,VINE:8)
Block(-4,11,-2,VINE:8)
Block(-4,11,0,VINE:8)
Block(-4,11,1,VINE:8)
Block(-4,12,-2,VINE:8)
Block(-4,12,1,VINE:8)
Block(-4,12,4,VINE:4)
Block(-4,13,-2,VINE:8)
Block(-4,13,1,VINE:8)
Block(-4,13,4,VINE:4)
Block(-4,14,-2,VINE:8)
Block(-4,14,1,VINE:8)
Block(-4,14,3,LEAVES:3)
Block(-4,14,4,VINE:4)
Block(-4,15,-2,VINE:8)
Block(-4,15,1,VINE:8)
Block(-4,15,2,LEAVES:3)
Block(-4,15,3,LEAVES:3)
Block(-4,15,4,LEAVES:3)
Block(-4,16,-2,VINE:8)
Block(-4,16,1,VINE:8)
Block(-4,17,-2,VINE:8)
Block(-4,17,1,VINE:8)
Block(-4,18,-2,VINE:8)
Block(-4,19,-2,VINE:8)
Block(-4,20,-2,VINE:8)
Block(-4,21,-4,LEAVES:3)
Block(-4,21,-3,LEAVES:3)
Block(-4,21,-2,LEAVES:3)
Block(-4,22,-3,LEAVES:3)
Block(-4,22,-2,VINE:4)
Block(-4,23,-2,VINE:4)
Block(-4,23,1,VINE:8)
Block(-4,24,-2,VINE:4)
Block(-4,24,1,VINE:8)
Block(-4,25,-2,VINE:4)
Block(-4,25,1,VINE:8)
Block(-4,26,-2,VINE:4)
Block(-4,26,1,VINE:8)
Block(-4,27,-5,LEAVES:3)
Block(-4,27,-2,VINE:4)
Block(-4,27,1,VINE:8)
Block(-4,28,-6,LEAVES:3)
Block(-4,28,-5,LEAVES:3)
Block(-4,28,-4,LEAVES:3)
Block(-4,28,-3,LEAVES:3)
Block(-4,28,-2,VINE:4)
Block(-4,28,1,VINE:8)
Block(-4,29,-7,LEAVES:3)
Block(-4,29,-6,LEAVES:3)
Block(-4,29,-5,LEAVES:3)
Block(-4,29,-4,LEAVES:3)
Block(-4,29,-3,LEAVES:3)
Block(-4,29,-2,LEAVES:3)
Block(-4,29,1,VINE:8)
Block(-4,30,-6,LEAVES:3)
Block(-4,30,-5,LEAVES:3)
Block(-4,30,-4,LEAVES:3)
Block(-4,30,-3,LEAVES:3)
Block(-4,30,-2,LEAVES:3)
Block(-4,30,-1,LEAVES:3)
Block(-4,30,1,VINE:8)
Block(-4,31,-5,LEAVES:3)
Block(-4,31,-4,LEAVES:3)
Block(-4,31,-3,LEAVES:3)
Block(-4,31,-2,LEAVES:3)
Block(-4,31,-1,VINE:4)
Block(-4,31,1,VINE:8)
Block(-4,32,1,VINE:8)
Block(-4,33,1,VINE:8)
Block(-4,34,1,VINE:8)
Block(-4,35,1,VINE:8)
Block(-4,39,-2,VINE:2)
Block(-4,40,-2,VINE:2)
Block(-4,41,-2,VINE:2)
Block(-4,42,-2,VINE:2)
Block(-4,43,-2,VINE:2)
Block(-4,44,-2,VINE:2)
Block(-4,45,-2,VINE:2)
Block(-4,45,3,LEAVES:3)
Block(-4,46,-2,VINE:2)
Block(-4,46,1,LEAVES:3)
Block(-4,46,2,LEAVES:3)
Block(-4,46,3,LEAVES:3)
Block(-4,46,4,LEAVES:3)
Block(-4,47,-2,VINE:2)
Block(-4,47,0,LEAVES:3)
Block(-4,47,1,LEAVES:3)
Block(-4,47,2,LEAVES:3)
Block(-4,47,3,LEAVES:3)
Block(-4,47,4,LEAVES:3)
Block(-4,48,-2,VINE:2)
Block(-4,48,-1,LEAVES:3)
Block(-4,48,0,LEAVES:3)
Block(-4,48,1,LOG:7)
Block(-4,48,2,LEAVES:3)
Block(-4,48,3,LEAVES:3)
Block(-4,48,4,LEAVES:3)
Block(-4,48,5,LEAVES:3)
Block(-4,49,0,LEAVES:3)
Block(-4,49,1,LEAVES:3)
Block(-4,49,2,LEAVES:3)
Block(-4,49,3,LEAVES:3)
Block(-4,49,4,LEAVES:3)
Block(-4,50,-5,VINE:1)
Block(-4,50,0,LEAVES:3)
Block(-4,50,1,LEAVES:3)
Block(-4,50,2,LEAVES:3)
Block(-4,50,3,LEAVES:3)
Block(-4,51,-5,VINE:1)
Block(-4,51,-1,LEAVES:3)
Block(-4,51,1,LEAVES:3)
Block(-4,51,2,LEAVES:3)
Block(-4,52,-5,VINE:1)
Block(-4,52,-3,LEAVES:3)
Block(-4,52,-2,LEAVES:3)
Block(-4,52,-1,LEAVES:3)
Block(-4,52,0,LEAVES:3)
Block(-4,52,1,LEAVES:3)
Block(-4,52,2,LEAVES:3)
Block(-4,53,-5,VINE:1)
Block(-4,53,-4,LEAVES:3)
Block(-4,53,-3,LEAVES:3)
Block(-4,53,-2,LEAVES:3)
Block(-4,53,-1,LEAVES:3)
Block(-4,53,0,LOG:7)
Block(-4,53,1,LEAVES:3)
Block(-4,53,2,LEAVES:3)
Block(-4,53,3,LEAVES:3)
Block(-4,54,-3,LEAVES:3)
Block(-4,54,-2,LEAVES:3)
Block(-4,54,-1,LEAVES:3)
Block(-4,54,0,LEAVES:3)
Block(-4,54,1,LEAVES:3)
Block(-4,54,2,LEAVES:3)
Block(-4,54,3,LEAVES:3)
Block(-4,54,4,LEAVES:3)
Block(-4,55,-3,VINE:8)
Block(-4,55,-2,LEAVES:3)
Block(-4,55,-1,LEAVES:3)
Block(-4,55,0,LEAVES:3)
Block(-4,55,1,LEAVES:3)
Block(-4,55,2,LEAVES:3)
Block(-4,55,3,LEAVES:3)
Block(-4,56,-1,LEAVES:3)
Block(-4,56,0,LEAVES:3)
Block(-4,56,1,LEAVES:3)
Block(-4,56,2,LEAVES:3)
Block(-3,0,-2,LOG:3)
Block(-3,0,-1,LOG:3)
Block(-3,0,0,LOG:3)
Block(-3,0,1,LOG:3)
Block(-3,0,2,LOG:3)
Block(-3,1,-2,LOG:3)
Block(-3,1,-1,LOG:3)
Block(-3,1,0,LOG:3)
Block(-3,1,1,LOG:3)
Block(-3,1,2,LOG:3)
Block(-3,2,-2,LOG:3)
Block(-3,2,-1,LOG:3)
Block(-3,2,0,LOG:3)
Block(-3,2,1,LOG:3)
Block(-3,2,2,LOG:3)
Block(-3,3,-2,LOG:15)
Block(-3,3,-1,LOG:3)
Block(-3,3,0,LOG:3)
Block(-3,3,1,LOG:3)
Block(-3,3,2,LOG:3)
Block(-3,4,-1,LOG:3)
Block(-3,4,0,LOG:3)
Block(-3,4,1,LOG:3)
Block(-3,4,2,LOG:15)
Block(-3,5,-1,LOG:15)
Block(-3,5,0,LOG:3)
Block(-3,5,1,LOG:3)
Block(-3,6,-1,VINE:1)
Block(-3,6,0,LOG:3)
Block(-3,6,1,LOG:15)
Block(-3,6,2,VINE:8)
Block(-3,7,-1,VINE:1)
Block(-3,7,0,LOG:3)
Block(-3,7,1,LOG:15)
Block(-3,7,2,VINE:8)
Block(-3,8,-1,VINE:9)
Block(-3,8,0,LOG:3)
Block(-3,8,1,LOG:3)
Block(-3,9,-1,VINE:9)
Block(-3,9,0,LOG:3)
Block(-3,9,1,LOG:3)
Block(-3,10,-2,LEAVES:3)
Block(-3,10,0,LOG:3)
Block(-3,10,1,LOG:3)
Block(-3,11,0,LOG:3)
Block(-3,11,1,LOG:3)
Block(-3,12,0,LOG:3)
Block(-3,12,1,LOG:3)
Block(-3,13,0,LOG:3)
Block(-3,13,1,LOG:3)
Block(-3,13,3,LEAVES:3)
Block(-3,14,0,LOG:3)
Block(-3,14,1,LOG:3)
Block(-3,14,2,LEAVES:3)
Block(-3,14,3,LEAVES:3)
Block(-3,14,4,LEAVES:3)
Block(-3,15,0,LOG:3)
Block(-3,15,1,LOG:3)
Block(-3,15,2,LEAVES:3)
Block(-3,15,3,LEAVES:3)
Block(-3,15,4,LEAVES:3)
Block(-3,15,5,LEAVES:3)
Block(-3,16,-2,LEAVES:3)
Block(-3,16,-1,LEAVES:3)
Block(-3,16,0,LOG:3)
Block(-3,16,1,LOG:3)
Block(-3,16,2,LEAVES:3)
Block(-3,16,3,LEAVES:3)
Block(-3,16,4,LEAVES:3)
Block(-3,17,-1,LEAVES:3)
Block(-3,17,0,LOG:3)
Block(-3,17,1,LOG:3)
Block(-3,17,2,VINE:8)
Block(-3,18,-1,VINE:8)
Block(-3,18,0,LOG:3)
Block(-3,18,1,LOG:3)
Block(-3,18,2,VINE:8)
Block(-3,19,-3,LEAVES:3)
Block(-3,19,-1,VINE:12)
Block(-3,19,0,LOG:3)
Block(-3,19,1,LOG:3)
Block(-3,19,2,VINE:12)
Block(-3,20,-4,LEAVES:3)
Block(-3,20,-3,LEAVES:3)
Block(-3,20,-2,LEAVES:3)
Block(-3,20,-1,VINE:4)
Block(-3,20,0,LOG:3)
Block(-3,20,1,LOG:3)
Block(-3,20,2,VINE:12)
Block(-3,21,-5,LEAVES:3)
Block(-3,21,-4,LEAVES:3)
Block(-3,21,-3,LEAVES:3)
Block(-3,21,-2,LEAVES:3)
Block(-3,21,-1,LEAVES:3)
Block(-3,21,0,LOG:3)
Block(-3,21,1,LOG:3)
Block(-3,21,2,VINE:12)
Block(-3,22,-4,LEAVES:3)
Block(-3,22,-3,LEAVES:3)
Block(-3,22,-2,LEAVES:3)
Block(-3,22,-1,VINE:1)
Block(-3,22,0,LOG:3)
Block(-3,22,1,LOG:3)
Block(-3,22,2,VINE:12)
Block(-3,23,-1,VINE:1)
Block(-3,23,0,LOG:3)
Block(-3,23,1,LOG:3)
Block(-3,23,2,VINE:12)
Block(-3,24,-1,VINE:1)
Block(-3,24,0,LOG:3)
Block(-3,24,1,LOG:3)
Block(-3,24,2,VINE:4)
Block(-3,25,0,LOG:3)
Block(-3,25,1,LOG:3)
Block(-3,25,2,VINE:4)
Block(-3,26,0,LOG:3)
Block(-3,26,1,LOG:3)
Block(-3,26,2,VINE:4)
Block(-3,27,-4,LEAVES:3)
Block(-3,27,0,LOG:3)
Block(-3,27,1,LOG:3)
Block(-3,27,2,VINE:12)
Block(-3,28,-7,LEAVES:3)
Block(-3,28,-6,LEAVES:3)
Block(-3,28,-5,LEAVES:3)
Block(-3,28,-4,LEAVES:3)
Block(-3,28,-3,LEAVES:3)
Block(-3,28,-2,LEAVES:3)
Block(-3,28,0,LOG:3)
Block(-3,28,1,LOG:3)
Block(-3,28,2,VINE:12)
Block(-3,29,-8,LEAVES:3)
Block(-3,29,-7,LEAVES:3)
Block(-3,29,-6,LEAVES:3)
Block(-3,29,-5,LEAVES:3)
Block(-3,29,-4,LEAVES:3)
Block(-3,29,-3,LEAVES:3)
Block(-3,29,-2,LEAVES:3)
Block(-3,29,-1,LEAVES:3)
Block(-3,29,0,LOG:3)
Block(-3,29,1,LOG:3)
Block(-3,29,2,VINE:12)
Block(-3,30,-7,LEAVES:3)
Block(-3,30,-6,LEAVES:3)
Block(-3,30,-5,LEAVES:3)
Block(-3,30,-4,LEAVES:3)
Block(-3,30,-3,LEAVES:3)
Block(-3,30,-2,LEAVES:3)
Block(-3,30,-1,LEAVES:3)
Block(-3,30,0,LOG:3)
Block(-3,30,1,LOG:3)
Block(-3,30,2,VINE:12)
Block(-3,31,-5,LEAVES:3)
Block(-3,31,-4,LEAVES:3)
Block(-3,31,-3,LEAVES:3)
Block(-3,31,-2,LEAVES:3)
Block(-3,31,-1,LEAVES:3)
Block(-3,31,0,LOG:3)
Block(-3,31,1,LOG:3)
Block(-3,31,2,VINE:12)
Block(-3,32,-3,LEAVES:3)
Block(-3,32,-2,LEAVES:3)
Block(-3,32,-1,VINE:8)
Block(-3,32,0,LOG:3)
Block(-3,32,1,LOG:3)
Block(-3,32,2,VINE:12)
Block(-3,33,-1,VINE:8)
Block(-3,33,0,LOG:3)
Block(-3,33,1,LOG:3)
Block(-3,33,2,VINE:13)
Block(-3,34,-1,VINE:8)
Block(-3,34,0,LOG:3)
Block(-3,34,1,LOG:3)
Block(-3,34,2,VINE:13)
Block(-3,35,-1,VINE:8)
Block(-3,35,0,LOG:3)
Block(-3,35,1,LOG:3)
Block(-3,35,2,VINE:13)
Block(-3,36,-1,VINE:8)
Block(-3,36,0,LOG:3)
Block(-3,36,1,LOG:3)
Block(-3,36,2,VINE:13)
Block(-3,37,-1,VINE:8)
Block(-3,37,0,LOG:3)
Block(-3,37,1,LOG:3)
Block(-3,37,2,VINE:13)
Block(-3,38,-1,VINE:8)
Block(-3,38,0,LOG:3)
Block(-3,38,1,LOG:3)
Block(-3,38,2,VINE:13)
Block(-3,39,0,LOG:3)
Block(-3,39,1,LOG:3)
Block(-3,39,2,VINE:13)
Block(-3,40,0,LOG:3)
Block(-3,40,1,LOG:3)
Block(-3,40,2,VINE:13)
Block(-3,41,0,LOG:3)
Block(-3,41,1,LOG:3)
Block(-3,41,2,VINE:5)
Block(-3,42,0,LOG:3)
Block(-3,42,1,LOG:3)
Block(-3,42,2,VINE:5)
Block(-3,43,-1,VINE:8)
Block(-3,43,0,LOG:3)
Block(-3,43,1,LOG:3)
Block(-3,43,2,VINE:5)
Block(-3,44,-1,VINE:8)
Block(-3,44,0,LOG:3)
Block(-3,44,1,LOG:3)
Block(-3,44,2,VINE:5)
Block(-3,45,-1,VINE:8)
Block(-3,45,0,LOG:3)
Block(-3,45,1,LOG:3)
Block(-3,45,2,VINE:5)
Block(-3,46,-1,VINE:8)
Block(-3,46,0,LOG:3)
Block(-3,46,1,LOG:3)
Block(-3,46,2,VINE:1)
Block(-3,46,3,LEAVES:3)
Block(-3,47,-1,VINE:8)
Block(-3,47,0,LOG:3)
Block(-3,47,1,LOG:3)
Block(-3,47,2,LEAVES:3)
Block(-3,47,3,LEAVES:3)
Block(-3,48,-1,VINE:8)
Block(-3,48,0,LOG:3)
Block(-3,48,1,LOG:3)
Block(-3,48,2,LEAVES:3)
Block(-3,48,3,LEAVES:3)
Block(-3,48,4,LEAVES:3)
Block(-3,48,6,LEAVES:3)
Block(-3,49,-1,VINE:8)
Block(-3,49,0,LOG:3)
Block(-3,49,1,LOG:3)
Block(-3,49,2,LEAVES:3)
Block(-3,49,3,LEAVES:3)
Block(-3,49,4,LEAVES:3)
Block(-3,50,-1,VINE:8)
Block(-3,50,0,LOG:3)
Block(-3,50,1,LOG:3)
Block(-3,50,2,LEAVES:3)
Block(-3,50,3,LEAVES:3)
Block(-3,50,4,LEAVES:3)
Block(-3,50,5,LEAVES:3)
Block(-3,51,-3,LEAVES:3)
Block(-3,51,-1,VINE:8)
Block(-3,51,0,LOG:3)
Block(-3,51,1,LOG:3)
Block(-3,51,2,LEAVES:3)
Block(-3,51,3,LEAVES:3)
Block(-3,51,4,LEAVES:3)
Block(-3,52,-7,LEAVES:3)
Block(-3,52,-6,LEAVES:3)
Block(-3,52,-5,LEAVES:3)
Block(-3,52,-4,LEAVES:3)
Block(-3,52,-3,LEAVES:3)
Block(-3,52,-2,LEAVES:3)
Block(-3,52,-1,LEAVES:3)
Block(-3,52,0,LOG:3)
Block(-3,52,1,LOG:3)
Block(-3,52,2,LEAVES:3)
Block(-3,52,3,LEAVES:3)
Block(-3,53,-5,LEAVES:3)
Block(-3,53,-4,LEAVES:3)
Block(-3,53,-3,LEAVES:3)
Block(-3,53,-2,LEAVES:3)
Block(-3,53,-1,LEAVES:3)
Block(-3,53,0,LOG:3)
Block(-3,53,1,LOG:3)
Block(-3,53,2,LEAVES:3)
Block(-3,53,3,LEAVES:3)
Block(-3,53,4,LEAVES:3)
Block(-3,54,-4,LEAVES:3)
Block(-3,54,-3,LEAVES:3)
Block(-3,54,-2,LEAVES:3)
Block(-3,54,-1,LEAVES:3)
Block(-3,54,0,LOG:7)
Block(-3,54,1,LOG:15)
Block(-3,54,2,LEAVES:3)
Block(-3,54,3,LEAVES:3)
Block(-3,54,4,LEAVES:3)
Block(-3,54,5,LEAVES:3)
Block(-3,55,-3,LEAVES:3)
Block(-3,55,-2,LEAVES:3)
Block(-3,55,-1,LEAVES:3)
Block(-3,55,0,LEAVES:3)
Block(-3,55,1,LEAVES:3)
Block(-3,55,2,LEAVES:3)
Block(-3,55,3,LEAVES:3)
Block(-3,55,4,LEAVES:3)
Block(-3,56,-3,VINE:1)
Block(-3,56,-2,LEAVES:3)
Block(-3,56,-1,LEAVES:3)
Block(-3,56,0,LEAVES:3)
Block(-3,56,1,LEAVES:3)
Block(-3,56,2,LEAVES:3)
Block(-2,0,-1,LOG:3)
Block(-2,0,0,LOG:3)
Block(-2,0,1,LOG:3)
Block(-2,0,2,LOG:3)
Block(-2,1,-1,LOG:3)
Block(-2,1,0,LOG:3)
Block(-2,1,1,LOG:3)
Block(-2,1,2,LOG:3)
Block(-2,2,-1,LOG:3)
Block(-2,2,0,LOG:3)
Block(-2,2,1,LOG:3)
Block(-2,2,2,LOG:3)
Block(-2,3,-1,LOG:3)
Block(-2,3,0,LOG:3)
Block(-2,3,1,LOG:3)
Block(-2,3,2,LOG:3)
Block(-2,4,-1,LOG:3)
Block(-2,4,0,LOG:3)
Block(-2,4,1,LOG:3)
Block(-2,4,2,LOG:3)
Block(-2,5,-1,LOG:3)
Block(-2,5,0,LOG:3)
Block(-2,5,1,LOG:3)
Block(-2,5,2,LOG:3)
Block(-2,5,3,VINE:4)
Block(-2,6,-1,LOG:15)
Block(-2,6,0,LOG:3)
Block(-2,6,1,LOG:3)
Block(-2,6,2,LOG:3)
Block(-2,6,3,VINE:4)
Block(-2,7,-1,LOG:3)
Block(-2,7,0,LOG:3)
Block(-2,7,1,LOG:3)
Block(-2,7,2,LOG:3)
Block(-2,7,3,VINE:4)
Block(-2,8,-1,LOG:3)
Block(-2,8,0,LOG:15)
Block(-2,8,1,LOG:15)
Block(-2,8,2,LOG:3)
Block(-2,8,3,VINE:4)
Block(-2,9,-3,LEAVES:3)
Block(-2,9,-2,LEAVES:3)
Block(-2,9,-1,LOG:3)
Block(-2,9,0,LOG:3)
Block(-2,9,1,BROWN_MUSHROOM)
Block(-2,9,2,LOG:3)
Block(-2,9,3,VINE:4)
Block(-2,10,-4,LEAVES:3)
Block(-2,10,-3,LEAVES:3)
Block(-2,10,-2,LEAVES:3)
Block(-2,10,-1,LOG:3)
Block(-2,10,0,LOG:3)
Block(-2,10,1,LOG:3)
Block(-2,10,2,LOG:3)
Block(-2,10,3,VINE:4)
Block(-2,11,-2,LEAVES:3)
Block(-2,11,-1,LOG:3)
Block(-2,11,0,LOG:3)
Block(-2,11,1,LOG:3)
Block(-2,11,2,LOG:3)
Block(-2,11,3,VINE:4)
Block(-2,12,-1,LOG:3)
Block(-2,12,0,LOG:3)
Block(-2,12,1,LOG:3)
Block(-2,12,2,LOG:3)
Block(-2,12,3,VINE:4)
Block(-2,13,-1,LOG:3)
Block(-2,13,0,LOG:3)
Block(-2,13,1,LOG:3)
Block(-2,13,2,LOG:3)
Block(-2,13,3,LEAVES:3)
Block(-2,14,-1,LOG:3)
Block(-2,14,0,LOG:3)
Block(-2,14,1,LOG:3)
Block(-2,14,2,LOG:3)
Block(-2,14,3,LEAVES:3)
Block(-2,14,4,LEAVES:3)
Block(-2,14,5,LEAVES:3)
Block(-2,15,-2,LEAVES:3)
Block(-2,15,-1,LOG:3)
Block(-2,15,0,LOG:3)
Block(-2,15,1,LOG:3)
Block(-2,15,2,LOG:3)
Block(-2,15,3,LEAVES:3)
Block(-2,15,4,LEAVES:3)
Block(-2,15,5,LEAVES:3)
Block(-2,15,6,LEAVES:3)
Block(-2,16,-3,LEAVES:3)
Block(-2,16,-2,LEAVES:3)
Block(-2,16,-1,LOG:3)
Block(-2,16,0,LOG:3)
Block(-2,16,1,LOG:3)
Block(-2,16,2,LOG:3)
Block(-2,16,3,LEAVES:3)
Block(-2,16,4,LEAVES:3)
Block(-2,16,5,LEAVES:3)
Block(-2,17,-2,LEAVES:3)
Block(-2,17,-1,LOG:3)
Block(-2,17,0,LOG:3)
Block(-2,17,1,LOG:3)
Block(-2,17,2,LOG:3)
Block(-2,17,3,VINE:4)
Block(-2,17,4,LEAVES:3)
Block(-2,18,-1,LOG:3)
Block(-2,18,0,LOG:3)
Block(-2,18,1,LOG:3)
Block(-2,18,2,LOG:3)
Block(-2,18,3,VINE:4)
Block(-2,19,-3,LEAVES:3)
Block(-2,19,-1,LOG:3)
Block(-2,19,0,LOG:3)
Block(-2,19,1,LOG:3)
Block(-2,19,2,LOG:3)
Block(-2,19,3,VINE:4)
Block(-2,20,-5,LEAVES:3)
Block(-2,20,-4,LEAVES:3)
Block(-2,20,-3,LEAVES:3)
Block(-2,20,-2,LEAVES:3)
Block(-2,20,-1,LOG:3)
Block(-2,20,0,LOG:3)
Block(-2,20,1,LOG:3)
Block(-2,20,2,LOG:3)
Block(-2,20,3,VINE:4)
Block(-2,21,-6,LEAVES:3)
Block(-2,21,-5,LEAVES:3)
Block(-2,21,-4,LEAVES:3)
Block(-2,21,-3,LEAVES:3)
Block(-2,21,-2,LEAVES:3)
Block(-2,21,-1,LOG:3)
Block(-2,21,0,LOG:3)
Block(-2,21,1,LOG:3)
Block(-2,21,2,LOG:3)
Block(-2,21,3,VINE:4)
Block(-2,22,-5,LEAVES:3)
Block(-2,22,-4,LEAVES:3)
Block(-2,22,-3,LEAVES:3)
Block(-2,22,-2,LEAVES:3)
Block(-2,22,-1,LOG:3)
Block(-2,22,0,LOG:3)
Block(-2,22,1,LOG:3)
Block(-2,22,2,LOG:3)
Block(-2,22,3,VINE:4)
Block(-2,23,-4,LEAVES:3)
Block(-2,23,-2,VINE:9)
Block(-2,23,-1,LOG:3)
Block(-2,23,0,LOG:3)
Block(-2,23,1,LOG:3)
Block(-2,23,2,LOG:3)
Block(-2,23,3,VINE:4)
Block(-2,24,-2,VINE:1)
Block(-2,24,-1,LOG:3)
Block(-2,24,0,LOG:3)
Block(-2,24,1,LOG:3)
Block(-2,24,2,LOG:3)
Block(-2,24,3,VINE:4)
Block(-2,25,-1,LOG:3)
Block(-2,25,0,LOG:3)
Block(-2,25,1,LOG:3)
Block(-2,25,2,LOG:3)
Block(-2,25,3,VINE:4)
Block(-2,26,-1,LOG:3)
Block(-2,26,0,LOG:3)
Block(-2,26,1,LOG:3)
Block(-2,26,2,LOG:3)
Block(-2,26,3,VINE:4)
Block(-2,27,-7,LEAVES:3)
Block(-2,27,-6,LEAVES:3)
Block(-2,27,-5,LEAVES:3)
Block(-2,27,-4,LEAVES:3)
Block(-2,27,-3,LEAVES:3)
Block(-2,27,-2,LEAVES:3)
Block(-2,27,-1,LOG:3)
Block(-2,27,0,LOG:3)
Block(-2,27,1,LOG:3)
Block(-2,27,2,LOG:3)
Block(-2,27,3,VINE:4)
Block(-2,28,-7,LEAVES:3)
Block(-2,28,-6,LEAVES:3)
Block(-2,28,-5,LEAVES:3)
Block(-2,28,-4,LEAVES:3)
Block(-2,28,-3,LEAVES:3)
Block(-2,28,-2,LEAVES:3)
Block(-2,28,-1,LOG:3)
Block(-2,28,0,LOG:3)
Block(-2,28,1,LOG:3)
Block(-2,28,2,LOG:3)
Block(-2,28,3,VINE:4)
Block(-2,29,-8,LEAVES:3)
Block(-2,29,-7,LEAVES:3)
Block(-2,29,-6,LEAVES:3)
Block(-2,29,-5,LOG:15)
Block(-2,29,-4,LOG:11)
Block(-2,29,-3,LEAVES:3)
Block(-2,29,-2,LEAVES:3)
Block(-2,29,-1,LOG:3)
Block(-2,29,0,LOG:3)
Block(-2,29,1,LOG:3)
Block(-2,29,2,LOG:3)
Block(-2,29,3,VINE:4)
Block(-2,30,-7,LEAVES:3)
Block(-2,30,-6,LEAVES:3)
Block(-2,30,-5,LEAVES:3)
Block(-2,30,-4,LEAVES:3)
Block(-2,30,-3,LOG:11)
Block(-2,30,-2,LOG:11)
Block(-2,30,-1,LOG:3)
Block(-2,30,0,LOG:3)
Block(-2,30,1,LOG:3)
Block(-2,30,2,LOG:3)
Block(-2,30,3,VINE:4)
Block(-2,31,-6,LEAVES:3)
Block(-2,31,-5,LEAVES:3)
Block(-2,31,-4,LEAVES:3)
Block(-2,31,-3,LEAVES:3)
Block(-2,31,-2,LEAVES:3)
Block(-2,31,-1,LOG:3)
Block(-2,31,0,LOG:3)
Block(-2,31,1,LOG:3)
Block(-2,31,2,LOG:3)
Block(-2,31,3,VINE:4)
Block(-2,32,-5,LEAVES:3)
Block(-2,32,-4,LEAVES:3)
Block(-2,32,-3,LEAVES:3)
Block(-2,32,-2,VINE:1)
Block(-2,32,-1,LOG:3)
Block(-2,32,0,LOG:3)
Block(-2,32,1,LOG:3)
Block(-2,32,2,LOG:3)
Block(-2,32,3,VINE:4)
Block(-2,33,-2,VINE:1)
Block(-2,33,-1,LOG:3)
Block(-2,33,0,LOG:3)
Block(-2,33,1,LOG:3)
Block(-2,33,2,LOG:3)
Block(-2,33,3,VINE:4)
Block(-2,34,-2,VINE:1)
Block(-2,34,-1,LOG:3)
Block(-2,34,0,LOG:3)
Block(-2,34,1,LOG:3)
Block(-2,34,2,LOG:3)
Block(-2,34,3,VINE:4)
Block(-2,35,-2,VINE:1)
Block(-2,35,-1,LOG:3)
Block(-2,35,0,LOG:3)
Block(-2,35,1,LOG:3)
Block(-2,35,2,LOG:3)
Block(-2,35,3,VINE:4)
Block(-2,36,-2,VINE:1)
Block(-2,36,-1,LOG:3)
Block(-2,36,0,LOG:3)
Block(-2,36,1,LOG:3)
Block(-2,36,2,LOG:3)
Block(-2,36,3,VINE:4)
Block(-2,37,-2,VINE:1)
Block(-2,37,-1,LOG:3)
Block(-2,37,0,LOG:3)
Block(-2,37,1,LOG:3)
Block(-2,37,2,LOG:3)
Block(-2,37,3,VINE:4)
Block(-2,38,-2,VINE:1)
Block(-2,38,-1,LOG:3)
Block(-2,38,0,LOG:3)
Block(-2,38,1,LOG:3)
Block(-2,38,2,LOG:3)
Block(-2,38,3,VINE:4)
Block(-2,39,-4,VINE:1)
Block(-2,39,-2,VINE:1)
Block(-2,39,-1,LOG:3)
Block(-2,39,0,LOG:3)
Block(-2,39,1,LOG:3)
Block(-2,39,2,LOG:3)
Block(-2,39,3,VINE:4)
Block(-2,40,-4,VINE:1)
Block(-2,40,-1,LOG:3)
Block(-2,40,0,LOG:3)
Block(-2,40,1,LOG:3)
Block(-2,40,2,LOG:3)
Block(-2,40,3,VINE:4)
Block(-2,41,-4,VINE:1)
Block(-2,41,-1,LOG:3)
Block(-2,41,0,LOG:3)
Block(-2,41,1,LOG:3)
Block(-2,41,2,LOG:3)
Block(-2,41,3,VINE:6)
Block(-2,42,-4,VINE:1)
Block(-2,42,-1,LOG:3)
Block(-2,42,0,LOG:3)
Block(-2,42,1,LOG:3)
Block(-2,42,2,LOG:3)
Block(-2,42,3,VINE:6)
Block(-2,43,-4,VINE:1)
Block(-2,43,-1,LOG:3)
Block(-2,43,0,LOG:3)
Block(-2,43,1,LOG:3)
Block(-2,43,2,LOG:3)
Block(-2,43,3,VINE:6)
Block(-2,44,-4,VINE:1)
Block(-2,44,-1,LOG:3)
Block(-2,44,0,LOG:3)
Block(-2,44,1,LOG:3)
Block(-2,44,2,LOG:3)
Block(-2,44,3,VINE:6)
Block(-2,45,-4,VINE:1)
Block(-2,45,-1,LOG:3)
Block(-2,45,0,LOG:3)
Block(-2,45,1,LOG:3)
Block(-2,45,2,LOG:3)
Block(-2,45,3,VINE:6)
Block(-2,46,-4,VINE:1)
Block(-2,46,-1,LOG:3)
Block(-2,46,0,LOG:3)
Block(-2,46,1,LOG:3)
Block(-2,46,2,LOG:3)
Block(-2,46,3,VINE:2)
Block(-2,47,-4,VINE:1)
Block(-2,47,-1,LOG:3)
Block(-2,47,0,LOG:3)
Block(-2,47,1,LOG:3)
Block(-2,47,2,LOG:3)
Block(-2,47,9,LEAVES:3)
Block(-2,48,-4,VINE:1)
Block(-2,48,-1,LOG:3)
Block(-2,48,0,LOG:3)
Block(-2,48,1,LOG:3)
Block(-2,48,2,LOG:3)
Block(-2,48,3,LEAVES:3)
Block(-2,48,4,LEAVES:3)
Block(-2,48,5,LEAVES:3)
Block(-2,48,6,LEAVES:3)
Block(-2,48,7,LEAVES:3)
Block(-2,49,-4,VINE:1)
Block(-2,49,-1,LOG:3)
Block(-2,49,0,LOG:3)
Block(-2,49,1,LOG:3)
Block(-2,49,2,LOG:3)
Block(-2,49,3,LEAVES:3)
Block(-2,49,4,LEAVES:3)
Block(-2,49,5,LEAVES:3)
Block(-2,49,6,LEAVES:3)
Block(-2,50,-10,LEAVES:3)
Block(-2,50,-9,LEAVES:3)
Block(-2,50,-8,LEAVES:3)
Block(-2,50,-6,LEAVES:3)
Block(-2,50,-4,VINE:1)
Block(-2,50,-1,LOG:3)
Block(-2,50,0,LOG:3)
Block(-2,50,1,LOG:3)
Block(-2,50,2,LOG:3)
Block(-2,50,3,LEAVES:3)
Block(-2,50,4,LEAVES:3)
Block(-2,50,5,LEAVES:3)
Block(-2,50,6,LEAVES:3)
Block(-2,51,-7,LEAVES:3)
Block(-2,51,-6,LEAVES:3)
Block(-2,51,-5,LEAVES:3)
Block(-2,51,-4,VINE:1)
Block(-2,51,-3,LEAVES:3)
Block(-2,51,-1,LOG:3)
Block(-2,51,0,LOG:3)
Block(-2,51,1,LOG:3)
Block(-2,51,2,LOG:3)
Block(-2,51,3,LEAVES:3)
Block(-2,51,4,LEAVES:3)
Block(-2,51,5,LEAVES:3)
Block(-2,52,-8,LEAVES:3)
Block(-2,52,-7,LEAVES:3)
Block(-2,52,-6,LEAVES:3)
Block(-2,52,-5,LEAVES:3)
Block(-2,52,-4,LEAVES:3)
Block(-2,52,-3,LEAVES:3)
Block(-2,52,-2,LEAVES:3)
Block(-2,52,-1,LOG:3)
Block(-2,52,0,LOG:3)
Block(-2,52,1,LOG:3)
Block(-2,52,2,LOG:3)
Block(-2,52,3,LEAVES:3)
Block(-2,52,4,LEAVES:3)
Block(-2,53,-7,LEAVES:3)
Block(-2,53,-6,LEAVES:3)
Block(-2,53,-5,LEAVES:3)
Block(-2,53,-4,LEAVES:3)
Block(-2,53,-3,LEAVES:3)
Block(-2,53,-2,LEAVES:3)
Block(-2,53,-1,LOG:3)
Block(-2,53,0,LOG:3)
Block(-2,53,1,LOG:3)
Block(-2,53,2,LOG:3)
Block(-2,53,3,LEAVES:3)
Block(-2,53,4,LEAVES:3)
Block(-2,54,-5,LEAVES:3)
Block(-2,54,-4,LEAVES:3)
Block(-2,54,-3,LEAVES:3)
Block(-2,54,-2,LEAVES:3)
Block(-2,54,-1,LOG:15)
Block(-2,54,0,LOG:11)
Block(-2,54,1,LOG:15)
Block(-2,54,2,LOG:15)
Block(-2,54,3,LEAVES:3)
Block(-2,54,4,LEAVES:3)
Block(-2,54,5,LEAVES:3)
Block(-2,54,6,LEAVES:3)
Block(-2,55,-3,LEAVES:3)
Block(-2,55,-2,LEAVES:3)
Block(-2,55,-1,LEAVES:3)
Block(-2,55,0,LEAVES:3)
Block(-2,55,1,LEAVES:3)
Block(-2,55,2,LEAVES:3)
Block(-2,55,3,LEAVES:3)
Block(-2,55,4,LEAVES:3)
Block(-2,56,-3,VINE:8)
Block(-2,56,-2,LEAVES:3)
Block(-2,56,-1,LEAVES:3)
Block(-2,56,0,LEAVES:3)
Block(-2,56,1,LEAVES:3)
Block(-2,56,2,LEAVES:3)
Block(-2,56,3,LEAVES:3)
Block(-2,56,4,LEAVES:3)
Block(-1,0,-1,LOG:3)
Block(-1,0,0,LOG:3)
Block(-1,0,1,LOG:3)
Block(-1,0,2,LOG:3)
Block(-1,1,-1,LOG:3)
Block(-1,1,0,LOG:3)
Block(-1,1,1,LOG:3)
Block(-1,1,2,LOG:3)
Block(-1,2,-1,LOG:3)
Block(-1,2,0,LOG:3)
Block(-1,2,1,LOG:3)
Block(-1,2,2,LOG:3)
Block(-1,3,-1,LOG:3)
Block(-1,3,0,LOG:3)
Block(-1,3,1,LOG:3)
Block(-1,3,2,LOG:3)
Block(-1,4,-1,LOG:3)
Block(-1,4,0,LOG:3)
Block(-1,4,1,LOG:3)
Block(-1,4,2,LOG:3)
Block(-1,5,-1,LOG:3)
Block(-1,5,0,LOG:3)
Block(-1,5,1,LOG:3)
Block(-1,5,2,LOG:3)
Block(-1,6,-1,LOG:3)
Block(-1,6,0,LOG:3)
Block(-1,6,1,LOG:3)
Block(-1,6,2,LOG:3)
Block(-1,7,-1,LOG:3)
Block(-1,7,0,LOG:3)
Block(-1,7,1,LOG:3)
Block(-1,7,2,LOG:3)
Block(-1,8,-3,LEAVES:3)
Block(-1,8,-2,VINE:11)
Block(-1,8,-1,LOG:3)
Block(-1,8,0,LOG:15)
Block(-1,8,1,LOG:3)
Block(-1,8,2,LOG:3)
Block(-1,9,-4,LEAVES:3)
Block(-1,9,-3,VINE:5)
Block(-1,9,-2,VINE:11)
Block(-1,9,-1,LOG:3)
Block(-1,9,0,LOG:3)
Block(-1,9,1,LOG:3)
Block(-1,9,2,LOG:3)
Block(-1,10,-5,LEAVES:3)
Block(-1,10,-4,LEAVES:3)
Block(-1,10,-3,VINE:5)
Block(-1,10,-2,VINE:3)
Block(-1,10,-1,LOG:3)
Block(-1,10,0,LOG:3)
Block(-1,10,1,LOG:3)
Block(-1,10,2,LOG:3)
Block(-1,11,-4,LEAVES:3)
Block(-1,11,-3,VINE:5)
Block(-1,11,-2,VINE:1)
Block(-1,11,-1,LOG:3)
Block(-1,11,0,LOG:3)
Block(-1,11,1,LOG:3)
Block(-1,11,2,LOG:3)
Block(-1,12,-3,VINE:1)
Block(-1,12,-2,VINE:1)
Block(-1,12,-1,LOG:3)
Block(-1,12,0,LOG:3)
Block(-1,12,1,LOG:3)
Block(-1,12,2,LOG:3)
Block(-1,13,-3,VINE:1)
Block(-1,13,-2,VINE:1)
Block(-1,13,-1,LOG:3)
Block(-1,13,0,LOG:3)
Block(-1,13,1,LOG:3)
Block(-1,13,2,LOG:3)
Block(-1,13,3,LEAVES:3)
Block(-1,14,-3,VINE:1)
Block(-1,14,-2,LEAVES:3)
Block(-1,14,-1,LOG:3)
Block(-1,14,0,LOG:3)
Block(-1,14,1,LOG:3)
Block(-1,14,2,LOG:3)
Block(-1,14,3,LEAVES:3)
Block(-1,14,4,LEAVES:3)
Block(-1,14,5,LEAVES:3)
Block(-1,15,-3,LEAVES:3)
Block(-1,15,-2,LEAVES:3)
Block(-1,15,-1,LOG:3)
Block(-1,15,0,LOG:3)
Block(-1,15,1,LOG:3)
Block(-1,15,2,LOG:3)
Block(-1,15,3,LOG:15)
Block(-1,15,4,LEAVES:3)
Block(-1,15,5,LEAVES:3)
Block(-1,15,6,LEAVES:3)
Block(-1,15,7,LEAVES:3)
Block(-1,16,-4,LEAVES:3)
Block(-1,16,-3,LEAVES:3)
Block(-1,16,-2,LEAVES:3)
Block(-1,16,-1,LOG:3)
Block(-1,16,0,LOG:3)
Block(-1,16,1,LOG:3)
Block(-1,16,2,LOG:3)
Block(-1,16,3,LEAVES:3)
Block(-1,16,4,LEAVES:3)
Block(-1,16,5,LEAVES:3)
Block(-1,17,-4,VINE:1)
Block(-1,17,-3,LEAVES:3)
Block(-1,17,-2,LEAVES:3)
Block(-1,17,-1,LOG:3)
Block(-1,17,0,LOG:3)
Block(-1,17,1,LOG:3)
Block(-1,17,2,LOG:3)
Block(-1,17,3,LEAVES:3)
Block(-1,17,4,LEAVES:3)
Block(-1,17,5,LEAVES:3)
Block(-1,18,-2,LEAVES:3)
Block(-1,18,-1,LOG:3)
Block(-1,18,0,LOG:3)
Block(-1,18,1,LOG:3)
Block(-1,18,2,LOG:3)
Block(-1,18,3,VINE:4)
Block(-1,19,-5,LEAVES:3)
Block(-1,19,-4,LEAVES:3)
Block(-1,19,-3,LEAVES:3)
Block(-1,19,-2,LEAVES:3)
Block(-1,19,-1,LOG:3)
Block(-1,19,0,LOG:3)
Block(-1,19,1,LOG:3)
Block(-1,19,2,LOG:3)
Block(-1,19,3,VINE:4)
Block(-1,20,-6,LEAVES:3)
Block(-1,20,-5,LEAVES:3)
Block(-1,20,-4,LEAVES:3)
Block(-1,20,-3,LEAVES:3)
Block(-1,20,-2,LEAVES:3)
Block(-1,20,-1,LOG:3)
Block(-1,20,0,LOG:3)
Block(-1,20,1,LOG:3)
Block(-1,20,2,LOG:3)
Block(-1,20,3,VINE:4)
Block(-1,21,-7,LEAVES:3)
Block(-1,21,-6,LEAVES:3)
Block(-1,21,-5,LEAVES:3)
Block(-1,21,-4,LEAVES:3)
Block(-1,21,-3,LOG:15)
Block(-1,21,-2,LOG:11)
Block(-1,21,-1,LOG:3)
Block(-1,21,0,LOG:3)
Block(-1,21,1,LOG:3)
Block(-1,21,2,LOG:3)
Block(-1,21,3,VINE:4)
Block(-1,22,-5,LEAVES:3)
Block(-1,22,-4,LEAVES:3)
Block(-1,22,-3,LEAVES:3)
Block(-1,22,-2,LEAVES:3)
Block(-1,22,-1,LOG:3)
Block(-1,22,0,LOG:3)
Block(-1,22,1,LOG:3)
Block(-1,22,2,LOG:3)
Block(-1,22,3,VINE:4)
Block(-1,23,-3,LEAVES:3)
Block(-1,23,-2,LEAVES:3)
Block(-1,23,-1,LOG:3)
Block(-1,23,0,LOG:3)
Block(-1,23,1,LOG:3)
Block(-1,23,2,LOG:3)
Block(-1,23,3,VINE:4)
Block(-1,24,-1,LOG:3)
Block(-1,24,0,LOG:3)
Block(-1,24,1,LOG:3)
Block(-1,24,2,LOG:3)
Block(-1,24,3,VINE:4)
Block(-1,25,-1,LOG:3)
Block(-1,25,0,LOG:3)
Block(-1,25,1,LOG:3)
Block(-1,25,2,LOG:3)
Block(-1,25,3,VINE:4)
Block(-1,26,-1,LOG:3)
Block(-1,26,0,LOG:3)
Block(-1,26,1,LOG:3)
Block(-1,26,2,LOG:3)
Block(-1,26,3,VINE:4)
Block(-1,27,-5,LEAVES:3)
Block(-1,27,-4,LEAVES:3)
Block(-1,27,-3,LEAVES:3)
Block(-1,27,-2,LEAVES:3)
Block(-1,27,-1,LOG:3)
Block(-1,27,0,LOG:3)
Block(-1,27,1,LOG:3)
Block(-1,27,2,LOG:3)
Block(-1,27,3,VINE:4)
Block(-1,28,-7,LEAVES:3)
Block(-1,28,-6,LEAVES:3)
Block(-1,28,-5,LEAVES:3)
Block(-1,28,-4,LEAVES:3)
Block(-1,28,-3,LEAVES:3)
Block(-1,28,-2,LEAVES:3)
Block(-1,28,-1,LOG:3)
Block(-1,28,0,LOG:3)
Block(-1,28,1,LOG:3)
Block(-1,28,2,LOG:3)
Block(-1,28,3,VINE:4)
Block(-1,29,-8,LEAVES:3)
Block(-1,29,-7,LEAVES:3)
Block(-1,29,-6,LEAVES:3)
Block(-1,29,-5,LEAVES:3)
Block(-1,29,-4,LEAVES:3)
Block(-1,29,-3,LEAVES:3)
Block(-1,29,-2,LEAVES:3)
Block(-1,29,-1,LOG:3)
Block(-1,29,0,LOG:3)
Block(-1,29,1,LOG:3)
Block(-1,29,2,LOG:3)
Block(-1,29,3,VINE:4)
Block(-1,30,-7,LEAVES:3)
Block(-1,30,-6,LEAVES:3)
Block(-1,30,-5,LEAVES:3)
Block(-1,30,-4,LEAVES:3)
Block(-1,30,-3,LEAVES:3)
Block(-1,30,-2,LEAVES:3)
Block(-1,30,-1,LOG:3)
Block(-1,30,0,LOG:3)
Block(-1,30,1,LOG:3)
Block(-1,30,2,LOG:3)
Block(-1,30,3,VINE:4)
Block(-1,31,-5,LEAVES:3)
Block(-1,31,-4,LEAVES:3)
Block(-1,31,-3,LEAVES:3)
Block(-1,31,-2,LEAVES:3)
Block(-1,31,-1,LOG:3)
Block(-1,31,0,LOG:3)
Block(-1,31,1,LOG:3)
Block(-1,31,2,LOG:3)
Block(-1,32,-3,LEAVES:3)
Block(-1,32,-2,VINE:1)
Block(-1,32,-1,LOG:3)
Block(-1,32,0,LOG:3)
Block(-1,32,1,LOG:3)
Block(-1,32,2,LOG:3)
Block(-1,33,-2,VINE:1)
Block(-1,33,-1,LOG:3)
Block(-1,33,0,LOG:3)
Block(-1,33,1,LOG:3)
Block(-1,33,2,LOG:3)
Block(-1,34,-2,VINE:1)
Block(-1,34,-1,LOG:3)
Block(-1,34,0,LOG:3)
Block(-1,34,1,LOG:3)
Block(-1,34,2,LOG:3)
Block(-1,35,-2,VINE:1)
Block(-1,35,-1,LOG:3)
Block(-1,35,0,LOG:3)
Block(-1,35,1,LOG:3)
Block(-1,35,2,LOG:3)
Block(-1,36,-2,VINE:1)
Block(-1,36,-1,LOG:3)
Block(-1,36,0,LOG:3)
Block(-1,36,1,LOG:3)
Block(-1,36,2,LOG:3)
Block(-1,37,-2,VINE:1)
Block(-1,37,-1,LOG:3)
Block(-1,37,0,LOG:3)
Block(-1,37,1,LOG:3)
Block(-1,37,2,LOG:3)
Block(-1,38,-2,VINE:1)
Block(-1,38,-1,LOG:3)
Block(-1,38,0,LOG:3)
Block(-1,38,1,LOG:3)
Block(-1,38,2,LOG:3)
Block(-1,39,-2,VINE:1)
Block(-1,39,-1,LOG:3)
Block(-1,39,0,LOG:3)
Block(-1,39,1,LOG:3)
Block(-1,39,2,LOG:3)
Block(-1,40,-2,VINE:1)
Block(-1,40,-1,LOG:3)
Block(-1,40,0,LOG:3)
Block(-1,40,1,LOG:3)
Block(-1,40,2,LOG:3)
Block(-1,41,-2,VINE:1)
Block(-1,41,-1,LOG:3)
Block(-1,41,0,LOG:3)
Block(-1,41,1,LOG:3)
Block(-1,41,2,LOG:3)
Block(-1,42,-2,VINE:1)
Block(-1,42,-1,LOG:3)
Block(-1,42,0,LOG:3)
Block(-1,42,1,LOG:3)
Block(-1,42,2,LOG:3)
Block(-1,43,-2,VINE:1)
Block(-1,43,-1,LOG:3)
Block(-1,43,0,LOG:3)
Block(-1,43,1,LOG:3)
Block(-1,43,2,LOG:3)
Block(-1,44,-2,VINE:1)
Block(-1,44,-1,LOG:3)
Block(-1,44,0,LOG:3)
Block(-1,44,1,LOG:3)
Block(-1,44,2,LOG:3)
Block(-1,45,-2,VINE:1)
Block(-1,45,-1,LOG:3)
Block(-1,45,0,LOG:3)
Block(-1,45,1,LOG:3)
Block(-1,45,2,LOG:3)
Block(-1,46,-2,VINE:1)
Block(-1,46,-1,LOG:3)
Block(-1,46,0,LOG:3)
Block(-1,46,1,LOG:3)
Block(-1,46,2,LOG:3)
Block(-1,46,6,LEAVES:3)
Block(-1,47,-2,VINE:1)
Block(-1,47,-1,LOG:3)
Block(-1,47,0,LOG:3)
Block(-1,47,1,LOG:3)
Block(-1,47,2,LOG:3)
Block(-1,47,5,LEAVES:3)
Block(-1,47,6,LEAVES:3)
Block(-1,47,7,LEAVES:3)
Block(-1,47,8,LEAVES:3)
Block(-1,47,9,LEAVES:3)
Block(-1,47,10,LEAVES:3)
Block(-1,48,-2,VINE:1)
Block(-1,48,-1,LOG:3)
Block(-1,48,0,LOG:3)
Block(-1,48,1,LOG:3)
Block(-1,48,2,LOG:3)
Block(-1,48,3,LEAVES:3)
Block(-1,48,4,LEAVES:3)
Block(-1,48,5,LEAVES:3)
Block(-1,48,6,LEAVES:3)
Block(-1,48,7,LEAVES:3)
Block(-1,48,8,LEAVES:3)
Block(-1,48,9,LEAVES:3)
Block(-1,49,-10,LEAVES:3)
Block(-1,49,-9,LEAVES:3)
Block(-1,49,-8,LEAVES:3)
Block(-1,49,-2,VINE:1)
Block(-1,49,-1,LOG:3)
Block(-1,49,0,LOG:3)
Block(-1,49,1,LOG:3)
Block(-1,49,2,LOG:3)
Block(-1,49,3,LEAVES:3)
Block(-1,49,4,LEAVES:3)
Block(-1,49,5,LEAVES:3)
Block(-1,49,6,LEAVES:3)
Block(-1,49,7,LEAVES:3)
Block(-1,50,-11,LEAVES:3)
Block(-1,50,-10,LEAVES:3)
Block(-1,50,-9,LEAVES:3)
Block(-1,50,-8,LEAVES:3)
Block(-1,50,-7,LEAVES:3)
Block(-1,50,-6,LEAVES:3)
Block(-1,50,-5,LEAVES:3)
Block(-1,50,-1,LOG:3)
Block(-1,50,0,LOG:3)
Block(-1,50,1,LOG:3)
Block(-1,50,2,LOG:3)
Block(-1,50,3,LOG:11)
Block(-1,50,4,LEAVES:3)
Block(-1,50,5,LEAVES:3)
Block(-1,50,6,LEAVES:3)
Block(-1,50,7,LEAVES:3)
Block(-1,51,-10,LEAVES:3)
Block(-1,51,-9,LEAVES:3)
Block(-1,51,-8,LEAVES:3)
Block(-1,51,-7,LEAVES:3)
Block(-1,51,-6,LEAVES:3)
Block(-1,51,-5,LEAVES:3)
Block(-1,51,-4,LEAVES:3)
Block(-1,51,-3,LEAVES:3)
Block(-1,51,-2,LEAVES:3)
Block(-1,51,-1,LOG:3)
Block(-1,51,0,LOG:3)
Block(-1,51,1,LOG:3)
Block(-1,51,2,LOG:3)
Block(-1,51,3,LEAVES:3)
Block(-1,51,4,LEAVES:3)
Block(-1,51,5,LEAVES:3)
Block(-1,51,6,LEAVES:3)
Block(-1,52,-9,LEAVES:3)
Block(-1,52,-8,LEAVES:3)
Block(-1,52,-7,LEAVES:3)
Block(-1,52,-6,LEAVES:3)
Block(-1,52,-5,LEAVES:3)
Block(-1,52,-4,LOG:11)
Block(-1,52,-3,LEAVES:3)
Block(-1,52,-2,LEAVES:3)
Block(-1,52,-1,LOG:3)
Block(-1,52,0,LOG:3)
Block(-1,52,1,LOG:3)
Block(-1,52,2,LOG:3)
Block(-1,52,3,LEAVES:3)
Block(-1,52,4,LEAVES:3)
Block(-1,53,-8,LEAVES:3)
Block(-1,53,-7,LEAVES:3)
Block(-1,53,-6,LEAVES:3)
Block(-1,53,-5,LEAVES:3)
Block(-1,53,-4,LEAVES:3)
Block(-1,53,-3,LOG:11)
Block(-1,53,-2,LOG:11)
Block(-1,53,-1,LOG:3)
Block(-1,53,0,LOG:3)
Block(-1,53,1,LOG:3)
Block(-1,53,2,LOG:3)
Block(-1,53,3,LEAVES:3)
Block(-1,53,4,LEAVES:3)
Block(-1,54,-6,LEAVES:3)
Block(-1,54,-5,LEAVES:3)
Block(-1,54,-4,LEAVES:3)
Block(-1,54,-3,LEAVES:3)
Block(-1,54,-2,LEAVES:3)
Block(-1,54,-1,LOG:11)
Block(-1,54,0,LOG:7)
Block(-1,54,1,LOG:15)
Block(-1,54,2,LOG:15)
Block(-1,54,3,LEAVES:3)
Block(-1,54,4,LEAVES:3)
Block(-1,54,5,LEAVES:3)
Block(-1,55,-5,LEAVES:3)
Block(-1,55,-4,VINE:4)
Block(-1,55,-3,LEAVES:3)
Block(-1,55,-2,LEAVES:3)
Block(-1,55,-1,LEAVES:3)
Block(-1,55,0,LEAVES:3)
Block(-1,55,1,LEAVES:3)
Block(-1,55,2,LEAVES:3)
Block(-1,55,3,LEAVES:3)
Block(-1,55,4,LEAVES:3)
Block(-1,56,-4,VINE:1)
Block(-1,56,-3,LEAVES:3)
Block(-1,56,-1,LEAVES:3)
Block(-1,56,0,LEAVES:3)
Block(-1,56,1,LEAVES:3)
Block(-1,56,2,LEAVES:3)
Block(-1,56,3,VINE:14)
Block(0,0,0,LOG:3)
Block(0,0,1,LOG:3)
Block(0,1,0,LOG:3)
Block(0,1,1,LOG:3)
Block(0,2,0,LOG:3)
Block(0,2,1,LOG:3)
Block(0,3,0,LOG:3)
Block(0,3,1,LOG:3)
Block(0,4,0,LOG:3)
Block(0,4,1,LOG:3)
Block(0,5,0,LOG:3)
Block(0,5,1,LOG:3)
Block(0,6,-1,VINE:3)
Block(0,6,0,LOG:3)
Block(0,6,1,LOG:3)
Block(0,6,2,VINE:6)
Block(0,7,-4,VINE:8)
Block(0,7,-1,VINE:3)
Block(0,7,0,LOG:15)
Block(0,7,1,LOG:3)
Block(0,7,2,VINE:6)
Block(0,8,-4,VINE:8)
Block(0,8,-3,LEAVES:3)
Block(0,8,-2,LEAVES:3)
Block(0,8,-1,VINE:3)
Block(0,8,0,LOG:3)
Block(0,8,1,LOG:3)
Block(0,8,2,VINE:6)
Block(0,8,3,VINE:2)
Block(0,9,-5,LEAVES:3)
Block(0,9,-4,LEAVES:3)
Block(0,9,-3,LEAVES:3)
Block(0,9,-2,LEAVES:3)
Block(0,9,-1,VINE:3)
Block(0,9,0,LOG:3)
Block(0,9,1,LOG:3)
Block(0,9,2,VINE:4)
Block(0,9,3,VINE:2)
Block(0,10,-6,LEAVES:3)
Block(0,10,-5,LEAVES:3)
Block(0,10,-4,LEAVES:3)
Block(0,10,-3,LEAVES:3)
Block(0,10,-2,LEAVES:3)
Block(0,10,-1,VINE:3)
Block(0,10,0,LOG:3)
Block(0,10,1,LOG:3)
Block(0,10,2,VINE:4)
Block(0,10,3,VINE:2)
Block(0,11,-6,VINE:8)
Block(0,11,-5,LEAVES:3)
Block(0,11,-4,LEAVES:3)
Block(0,11,-3,LEAVES:3)
Block(0,11,-2,LEAVES:3)
Block(0,11,-1,VINE:3)
Block(0,11,0,LOG:3)
Block(0,11,1,LOG:3)
Block(0,11,2,VINE:4)
Block(0,11,3,VINE:2)
Block(0,12,-3,LEAVES:3)
Block(0,12,-2,LEAVES:3)
Block(0,12,-1,VINE:3)
Block(0,12,0,LOG:3)
Block(0,12,1,LOG:3)
Block(0,12,2,VINE:6)
Block(0,12,3,VINE:2)
Block(0,13,-1,VINE:1)
Block(0,13,0,LOG:3)
Block(0,13,1,LOG:3)
Block(0,13,2,VINE:4)
Block(0,13,3,VINE:2)
Block(0,13,4,LEAVES:3)
Block(0,14,-2,LEAVES:3)
Block(0,14,-1,LEAVES:3)
Block(0,14,0,LOG:3)
Block(0,14,1,LOG:3)
Block(0,14,2,LEAVES:3)
Block(0,14,3,LEAVES:3)
Block(0,14,4,LEAVES:3)
Block(0,14,5,LEAVES:3)
Block(0,15,-3,LEAVES:3)
Block(0,15,-2,LEAVES:3)
Block(0,15,-1,LEAVES:3)
Block(0,15,0,LOG:3)
Block(0,15,1,LOG:3)
Block(0,15,2,LEAVES:3)
Block(0,15,3,LEAVES:3)
Block(0,15,4,LEAVES:3)
Block(0,15,5,LEAVES:3)
Block(0,15,6,LEAVES:3)
Block(0,16,-4,LEAVES:3)
Block(0,16,-3,LEAVES:3)
Block(0,16,-2,LEAVES:3)
Block(0,16,-1,LOG:15)
Block(0,16,0,LOG:3)
Block(0,16,1,LOG:3)
Block(0,16,2,LEAVES:3)
Block(0,16,3,LEAVES:3)
Block(0,16,4,LEAVES:3)
Block(0,16,5,LEAVES:3)
Block(0,17,-3,LEAVES:3)
Block(0,17,-2,LEAVES:3)
Block(0,17,-1,LEAVES:3)
Block(0,17,0,LOG:3)
Block(0,17,1,LOG:3)
Block(0,17,2,LEAVES:3)
Block(0,18,-3,LEAVES:3)
Block(0,18,-1,LEAVES:3)
Block(0,18,0,LOG:3)
Block(0,18,1,LOG:3)
Block(0,18,2,VINE:6)
Block(0,19,-4,LEAVES:3)
Block(0,19,0,LOG:3)
Block(0,19,1,LOG:3)
Block(0,19,2,VINE:6)
Block(0,20,-5,LEAVES:3)
Block(0,20,-4,LEAVES:3)
Block(0,20,-3,LEAVES:3)
Block(0,20,-2,LEAVES:3)
Block(0,20,-1,LEAVES:3)
Block(0,20,0,LOG:3)
Block(0,20,1,LOG:3)
Block(0,20,2,VINE:4)
Block(0,21,-6,LEAVES:3)
Block(0,21,-5,LEAVES:3)
Block(0,21,-4,LEAVES:3)
Block(0,21,-3,LEAVES:3)
Block(0,21,-2,LEAVES:3)
Block(0,21,-1,LEAVES:3)
Block(0,21,0,LOG:3)
Block(0,21,1,LOG:3)
Block(0,21,2,VINE:4)
Block(0,22,-5,LEAVES:3)
Block(0,22,-4,LEAVES:3)
Block(0,22,-3,LEAVES:3)
Block(0,22,-2,LEAVES:3)
Block(0,22,-1,LEAVES:3)
Block(0,22,0,LOG:3)
Block(0,22,1,LOG:3)
Block(0,22,2,VINE:4)
Block(0,23,-4,VINE:1)
Block(0,23,-3,LEAVES:3)
Block(0,23,-2,VINE:2)
Block(0,23,-1,VINE:1)
Block(0,23,0,LOG:3)
Block(0,23,1,LOG:3)
Block(0,23,2,VINE:4)
Block(0,24,-4,VINE:1)
Block(0,24,-1,VINE:1)
Block(0,24,0,LOG:3)
Block(0,24,1,LOG:3)
Block(0,24,2,VINE:4)
Block(0,25,-4,VINE:1)
Block(0,25,0,LOG:3)
Block(0,25,1,LOG:3)
Block(0,25,2,VINE:4)
Block(0,26,-4,VINE:1)
Block(0,26,-3,LEAVES:3)
Block(0,26,-2,LEAVES:3)
Block(0,26,-1,LEAVES:3)
Block(0,26,0,LOG:3)
Block(0,26,1,LOG:3)
Block(0,26,2,VINE:4)
Block(0,27,-5,LEAVES:3)
Block(0,27,-4,LEAVES:3)
Block(0,27,-3,LEAVES:3)
Block(0,27,-2,LEAVES:3)
Block(0,27,-1,LEAVES:3)
Block(0,27,0,LOG:3)
Block(0,27,1,LOG:3)
Block(0,27,2,VINE:4)
Block(0,28,-6,LEAVES:3)
Block(0,28,-5,LEAVES:3)
Block(0,28,-4,LEAVES:3)
Block(0,28,-3,LEAVES:3)
Block(0,28,-2,LEAVES:3)
Block(0,28,-1,LOG:7)
Block(0,28,0,LOG:3)
Block(0,28,1,LOG:3)
Block(0,28,2,LEAVES:3)
Block(0,29,-7,LEAVES:3)
Block(0,29,-6,LEAVES:3)
Block(0,29,-5,LEAVES:3)
Block(0,29,-4,LEAVES:3)
Block(0,29,-3,LEAVES:3)
Block(0,29,-2,LEAVES:3)
Block(0,29,-1,LEAVES:3)
Block(0,29,0,LOG:3)
Block(0,29,1,LOG:3)
Block(0,29,2,VINE:6)
Block(0,30,-6,LEAVES:3)
Block(0,30,-5,LEAVES:3)
Block(0,30,-4,LEAVES:3)
Block(0,30,-3,LEAVES:3)
Block(0,30,-2,LEAVES:3)
Block(0,30,-1,LEAVES:3)
Block(0,30,0,LOG:3)
Block(0,30,1,LOG:3)
Block(0,30,2,VINE:6)
Block(0,31,-5,LEAVES:3)
Block(0,31,-4,LEAVES:3)
Block(0,31,-3,LEAVES:3)
Block(0,31,-2,LEAVES:3)
Block(0,31,-1,VINE:2)
Block(0,31,0,LOG:3)
Block(0,31,1,LOG:3)
Block(0,31,2,VINE:6)
Block(0,32,-1,VINE:2)
Block(0,32,0,LOG:3)
Block(0,32,1,LOG:3)
Block(0,32,2,VINE:6)
Block(0,33,-1,VINE:2)
Block(0,33,0,LOG:3)
Block(0,33,1,LOG:3)
Block(0,33,2,VINE:6)
Block(0,34,-1,VINE:2)
Block(0,34,0,LOG:3)
Block(0,34,1,LOG:3)
Block(0,34,2,VINE:6)
Block(0,35,-1,VINE:2)
Block(0,35,0,LOG:3)
Block(0,35,1,LOG:3)
Block(0,35,2,VINE:2)
Block(0,36,-1,VINE:3)
Block(0,36,0,LOG:3)
Block(0,36,1,LOG:3)
Block(0,36,2,VINE:2)
Block(0,37,-1,VINE:1)
Block(0,37,0,LOG:3)
Block(0,37,1,LOG:3)
Block(0,37,2,VINE:2)
Block(0,38,0,LOG:3)
Block(0,38,1,LOG:3)
Block(0,38,2,VINE:2)
Block(0,39,0,LOG:3)
Block(0,39,1,LOG:3)
Block(0,40,-1,VINE:8)
Block(0,40,0,LOG:3)
Block(0,40,1,LOG:3)
Block(0,41,-1,VINE:8)
Block(0,41,0,LOG:3)
Block(0,41,1,LOG:3)
Block(0,42,-1,VINE:8)
Block(0,42,0,LOG:3)
Block(0,42,1,LOG:3)
Block(0,43,-1,VINE:8)
Block(0,43,0,LOG:3)
Block(0,43,1,LOG:3)
Block(0,44,-1,VINE:8)
Block(0,44,0,LOG:3)
Block(0,44,1,LOG:3)
Block(0,45,-1,VINE:8)
Block(0,45,0,LOG:3)
Block(0,45,1,LOG:3)
Block(0,46,-1,VINE:8)
Block(0,46,0,LOG:3)
Block(0,46,1,LOG:3)
Block(0,46,5,LEAVES:3)
Block(0,46,8,LEAVES:3)
Block(0,46,9,LEAVES:3)
Block(0,46,10,LEAVES:3)
Block(0,47,-1,VINE:8)
Block(0,47,0,LOG:3)
Block(0,47,1,LOG:3)
Block(0,47,4,LEAVES:3)
Block(0,47,5,LEAVES:3)
Block(0,47,6,LEAVES:3)
Block(0,47,7,LEAVES:3)
Block(0,47,8,LEAVES:3)
Block(0,47,9,LEAVES:3)
Block(0,47,10,LEAVES:3)
Block(0,47,11,LEAVES:3)
Block(0,48,-10,LEAVES:3)
Block(0,48,-9,LEAVES:3)
Block(0,48,-8,LEAVES:3)
Block(0,48,-1,VINE:8)
Block(0,48,0,LOG:3)
Block(0,48,1,LOG:3)
Block(0,48,2,LEAVES:3)
Block(0,48,3,LEAVES:3)
Block(0,48,4,LEAVES:3)
Block(0,48,5,LEAVES:3)
Block(0,48,6,LEAVES:3)
Block(0,48,7,LEAVES:3)
Block(0,48,8,LEAVES:3)
Block(0,48,9,LEAVES:3)
Block(0,48,10,LEAVES:3)
Block(0,49,-11,LEAVES:3)
Block(0,49,-10,LEAVES:3)
Block(0,49,-9,LEAVES:3)
Block(0,49,-8,LEAVES:3)
Block(0,49,-7,LEAVES:3)
Block(0,49,-1,VINE:8)
Block(0,49,0,LOG:3)
Block(0,49,1,LOG:3)
Block(0,49,2,LEAVES:3)
Block(0,49,3,LEAVES:3)
Block(0,49,4,LEAVES:3)
Block(0,49,5,LOG:11)
Block(0,49,6,LEAVES:3)
Block(0,49,7,LEAVES:3)
Block(0,49,8,LEAVES:3)
Block(0,49,9,LEAVES:3)
Block(0,50,-12,LEAVES:3)
Block(0,50,-11,LEAVES:3)
Block(0,50,-10,LEAVES:3)
Block(0,50,-9,LEAVES:3)
Block(0,50,-8,LEAVES:3)
Block(0,50,-7,LEAVES:3)
Block(0,50,-6,LEAVES:3)
Block(0,50,-5,LEAVES:3)
Block(0,50,-4,LEAVES:3)
Block(0,50,-1,VINE:8)
Block(0,50,0,LOG:3)
Block(0,50,1,LOG:3)
Block(0,50,2,LEAVES:3)
Block(0,50,3,LEAVES:3)
Block(0,50,4,LOG:11)
Block(0,50,5,LEAVES:3)
Block(0,50,6,LEAVES:3)
Block(0,50,7,LEAVES:3)
Block(0,50,8,LEAVES:3)
Block(0,51,-11,LEAVES:3)
Block(0,51,-10,LEAVES:3)
Block(0,51,-9,LEAVES:3)
Block(0,51,-8,LOG:11)
Block(0,51,-7,LOG:11)
Block(0,51,-6,LEAVES:3)
Block(0,51,-5,LEAVES:3)
Block(0,51,-4,LEAVES:3)
Block(0,51,-3,LEAVES:3)
Block(0,51,-2,LEAVES:3)
Block(0,51,-1,VINE:8)
Block(0,51,0,LOG:3)
Block(0,51,1,LOG:3)
Block(0,51,2,LEAVES:3)
Block(0,51,3,LEAVES:3)
Block(0,51,4,LEAVES:3)
Block(0,51,5,LEAVES:3)
Block(0,51,6,LEAVES:3)
Block(0,52,-10,LEAVES:3)
Block(0,52,-9,LEAVES:3)
Block(0,52,-8,LEAVES:3)
Block(0,52,-7,LEAVES:3)
Block(0,52,-6,LOG:11)
Block(0,52,-5,LOG:11)
Block(0,52,-4,LOG:11)
Block(0,52,-3,LEAVES:3)
Block(0,52,-2,LEAVES:3)
Block(0,52,-1,LEAVES:3)
Block(0,52,0,LOG:3)
Block(0,52,1,LOG:3)
Block(0,52,2,LEAVES:3)
Block(0,52,4,LEAVES:3)
Block(0,52,5,LEAVES:3)
Block(0,53,-8,LEAVES:3)
Block(0,53,-7,LEAVES:3)
Block(0,53,-6,LEAVES:3)
Block(0,53,-5,LEAVES:3)
Block(0,53,-4,RED_MUSHROOM)
Block(0,53,-3,LEAVES:3)
Block(0,53,-2,LEAVES:3)
Block(0,53,-1,LEAVES:3)
Block(0,53,0,LOG:3)
Block(0,53,1,LOG:3)
Block(0,53,2,LEAVES:3)
Block(0,53,3,LEAVES:3)
Block(0,54,-8,LEAVES:3)
Block(0,54,-6,LEAVES:3)
Block(0,54,-5,LEAVES:3)
Block(0,54,-4,LEAVES:3)
Block(0,54,-3,LEAVES:3)
Block(0,54,-2,LEAVES:3)
Block(0,54,-1,LEAVES:3)
Block(0,54,0,LOG:7)
Block(0,54,1,LOG:7)
Block(0,54,2,LEAVES:3)
Block(0,54,3,LEAVES:3)
Block(0,54,4,LEAVES:3)
Block(0,54,5,LEAVES:3)
Block(0,55,-4,LEAVES:3)
Block(0,55,-3,LEAVES:3)
Block(0,55,-2,LEAVES:3)
Block(0,55,-1,LEAVES:3)
Block(0,55,0,LEAVES:3)
Block(0,55,1,LEAVES:3)
Block(0,55,2,LEAVES:3)
Block(0,55,3,LEAVES:3)
Block(0,55,4,LEAVES:3)
Block(0,56,-1,LEAVES:3)
Block(0,56,0,LEAVES:3)
Block(0,56,1,LEAVES:3)
Block(0,56,3,LEAVES:3)
Block(0,56,4,VINE:4)
Block(1,0,-3,LOG:3)
Block(1,0,-2,LOG:3)
Block(1,0,-1,LOG:3)
Block(1,0,0,LOG:3)
Block(1,1,-3,LOG:3)
Block(1,1,-2,LOG:3)
Block(1,1,-1,LOG:3)
Block(1,1,0,LOG:3)
Block(1,2,-3,LOG:3)
Block(1,2,-2,LOG:3)
Block(1,2,-1,LOG:3)
Block(1,2,0,LOG:3)
Block(1,3,-3,LOG:3)
Block(1,3,-2,LOG:3)
Block(1,3,-1,LOG:15)
Block(1,3,0,LOG:3)
Block(1,4,-3,LOG:3)
Block(1,4,-2,LOG:3)
Block(1,4,0,LOG:3)
Block(1,5,-3,LOG:3)
Block(1,5,-2,LOG:3)
Block(1,5,0,LOG:15)
Block(1,6,-6,VINE:1)
Block(1,6,-3,LOG:3)
Block(1,6,-2,LOG:3)
Block(1,7,-7,VINE:1)
Block(1,7,-6,VINE:1)
Block(1,7,-4,VINE:1)
Block(1,7,-3,LOG:3)
Block(1,7,-2,LOG:3)
Block(1,8,-7,VINE:1)
Block(1,8,-6,VINE:1)
Block(1,8,-5,LEAVES:3)
Block(1,8,-4,LEAVES:3)
Block(1,8,-3,LOG:3)
Block(1,8,-2,LOG:3)
Block(1,8,-1,LEAVES:3)
Block(1,8,0,LEAVES:3)
Block(1,9,-7,VINE:1)
Block(1,9,-6,LEAVES:3)
Block(1,9,-5,LEAVES:3)
Block(1,9,-4,LEAVES:3)
Block(1,9,-3,LOG:3)
Block(1,9,-2,LOG:3)
Block(1,9,-1,LEAVES:3)
Block(1,9,0,LEAVES:3)
Block(1,9,1,LEAVES:3)
Block(1,10,-7,LEAVES:3)
Block(1,10,-6,LEAVES:3)
Block(1,10,-5,LEAVES:3)
Block(1,10,-4,LEAVES:3)
Block(1,10,-3,LOG:15)
Block(1,10,-2,LOG:15)
Block(1,10,-1,LEAVES:3)
Block(1,10,0,LEAVES:3)
Block(1,10,1,LEAVES:3)
Block(1,10,2,LEAVES:3)
Block(1,11,-6,LEAVES:3)
Block(1,11,-5,LEAVES:3)
Block(1,11,-4,LEAVES:3)
Block(1,11,-3,LEAVES:3)
Block(1,11,-2,VINE:2)
Block(1,11,-1,LEAVES:3)
Block(1,11,0,LEAVES:3)
Block(1,11,1,LEAVES:3)
Block(1,12,-5,LEAVES:3)
Block(1,12,-4,LEAVES:3)
Block(1,12,-3,LEAVES:3)
Block(1,12,-2,VINE:2)
Block(1,12,-1,LEAVES:3)
Block(1,12,0,LEAVES:3)
Block(1,13,-2,VINE:2)
Block(1,13,3,LEAVES:3)
Block(1,14,-2,VINE:2)
Block(1,14,2,LEAVES:3)
Block(1,14,3,LEAVES:3)
Block(1,14,4,LEAVES:3)
Block(1,15,-3,LEAVES:3)
Block(1,15,-2,LEAVES:3)
Block(1,15,-1,LEAVES:3)
Block(1,15,0,LEAVES:3)
Block(1,15,1,LEAVES:3)
Block(1,15,2,LEAVES:3)
Block(1,15,3,LEAVES:3)
Block(1,15,4,LEAVES:3)
Block(1,15,5,LEAVES:3)
Block(1,16,-4,LEAVES:3)
Block(1,16,-3,LEAVES:3)
Block(1,16,-2,LEAVES:3)
Block(1,16,-1,LEAVES:3)
Block(1,16,0,LEAVES:3)
Block(1,16,1,LEAVES:3)
Block(1,16,2,LEAVES:3)
Block(1,16,3,LEAVES:3)
Block(1,16,4,LEAVES:3)
Block(1,17,-3,LEAVES:3)
Block(1,17,-2,LEAVES:3)
Block(1,17,-1,LEAVES:3)
Block(1,17,0,LEAVES:3)
Block(1,17,1,LEAVES:3)
Block(1,17,3,LEAVES:3)
Block(1,18,-3,VINE:2)
Block(1,18,-2,LEAVES:3)
Block(1,18,-1,LEAVES:3)
Block(1,18,0,LEAVES:3)
Block(1,19,-3,LEAVES:3)
Block(1,20,-4,LEAVES:3)
Block(1,20,-3,LEAVES:3)
Block(1,20,-2,LEAVES:3)
Block(1,20,0,VINE:2)
Block(1,21,-5,LEAVES:3)
Block(1,21,-4,LEAVES:3)
Block(1,21,-3,LEAVES:3)
Block(1,21,-2,LEAVES:3)
Block(1,21,-1,LEAVES:3)
Block(1,21,0,VINE:2)
Block(1,22,-4,LEAVES:3)
Block(1,22,-3,LEAVES:3)
Block(1,22,-2,LEAVES:3)
Block(1,22,0,VINE:2)
Block(1,23,0,VINE:2)
Block(1,24,0,VINE:2)
Block(1,25,0,VINE:2)
Block(1,26,-4,LEAVES:3)
Block(1,26,-3,LEAVES:3)
Block(1,26,-2,LEAVES:3)
Block(1,26,-1,LEAVES:3)
Block(1,26,0,LEAVES:3)
Block(1,26,1,LEAVES:3)
Block(1,27,-5,LEAVES:3)
Block(1,27,-4,LEAVES:3)
Block(1,27,-3,LEAVES:3)
Block(1,27,-2,LEAVES:3)
Block(1,27,-1,LEAVES:3)
Block(1,27,0,LEAVES:3)
Block(1,27,1,LEAVES:3)
Block(1,27,2,LEAVES:3)
Block(1,28,-5,LEAVES:3)
Block(1,28,-4,LEAVES:3)
Block(1,28,-3,LEAVES:3)
Block(1,28,-2,LEAVES:3)
Block(1,28,-1,LOG:7)
Block(1,28,0,LEAVES:3)
Block(1,28,1,LEAVES:3)
Block(1,28,2,LEAVES:3)
Block(1,29,-6,LEAVES:3)
Block(1,29,-5,LEAVES:3)
Block(1,29,-4,LEAVES:3)
Block(1,29,-3,LEAVES:3)
Block(1,29,-2,LEAVES:3)
Block(1,29,-1,LEAVES:3)
Block(1,29,0,LEAVES:3)
Block(1,29,1,LEAVES:3)
Block(1,29,2,LEAVES:3)
Block(1,30,-5,LEAVES:3)
Block(1,30,-4,LEAVES:3)
Block(1,30,-3,LEAVES:3)
Block(1,30,-2,LEAVES:3)
Block(1,30,-1,LEAVES:3)
Block(1,30,0,VINE:2)
Block(1,31,-3,LEAVES:3)
Block(1,31,0,VINE:2)
Block(1,31,1,VINE:2)
Block(1,32,0,VINE:2)
Block(1,32,1,VINE:2)
Block(1,33,0,VINE:2)
Block(1,33,1,VINE:2)
Block(1,34,0,VINE:2)
Block(1,34,1,VINE:2)
Block(1,35,0,VINE:2)
Block(1,35,1,VINE:2)
Block(1,36,0,VINE:2)
Block(1,36,1,VINE:2)
Block(1,37,0,VINE:2)
Block(1,37,1,VINE:2)
Block(1,38,0,VINE:2)
Block(1,38,1,VINE:2)
Block(1,39,0,VINE:2)
Block(1,39,1,VINE:2)
Block(1,40,0,VINE:2)
Block(1,40,1,VINE:2)
Block(1,40,2,VINE:2)
Block(1,41,-4,VINE:2)
Block(1,41,1,VINE:2)
Block(1,41,2,VINE:2)
Block(1,42,-4,VINE:2)
Block(1,42,1,VINE:2)
Block(1,42,2,VINE:2)
Block(1,43,-4,VINE:2)
Block(1,43,2,VINE:2)
Block(1,44,-4,VINE:2)
Block(1,44,2,VINE:2)
Block(1,45,-4,VINE:2)
Block(1,45,2,VINE:2)
Block(1,45,8,LEAVES:3)
Block(1,45,10,LEAVES:3)
Block(1,46,-4,VINE:2)
Block(1,46,2,VINE:2)
Block(1,46,6,LEAVES:3)
Block(1,46,7,LEAVES:3)
Block(1,46,8,LEAVES:3)
Block(1,46,9,LEAVES:3)
Block(1,46,10,LEAVES:3)
Block(1,46,11,LEAVES:3)
Block(1,47,-4,VINE:2)
Block(1,47,2,VINE:2)
Block(1,47,3,LEAVES:3)
Block(1,47,4,LEAVES:3)
Block(1,47,5,LEAVES:3)
Block(1,47,6,LEAVES:3)
Block(1,47,7,LEAVES:3)
Block(1,47,8,LEAVES:3)
Block(1,47,9,LEAVES:3)
Block(1,47,10,LEAVES:3)
Block(1,47,11,LEAVES:3)
Block(1,47,12,LEAVES:3)
Block(1,48,-9,LEAVES:3)
Block(1,48,-8,LEAVES:3)
Block(1,48,-7,LEAVES:3)
Block(1,48,-4,VINE:2)
Block(1,48,2,VINE:2)
Block(1,48,3,LEAVES:3)
Block(1,48,4,LEAVES:3)
Block(1,48,5,LEAVES:3)
Block(1,48,6,LOG:11)
Block(1,48,7,LOG:11)
Block(1,48,8,LEAVES:3)
Block(1,48,9,LEAVES:3)
Block(1,48,10,LEAVES:3)
Block(1,48,11,LEAVES:3)
Block(1,49,-12,LEAVES:3)
Block(1,49,-11,LEAVES:3)
Block(1,49,-10,LEAVES:3)
Block(1,49,-9,LEAVES:3)
Block(1,49,-8,LEAVES:3)
Block(1,49,-7,LEAVES:3)
Block(1,49,-6,LEAVES:3)
Block(1,49,-4,VINE:2)
Block(1,49,2,LEAVES:3)
Block(1,49,3,LEAVES:3)
Block(1,49,4,LEAVES:3)
Block(1,49,5,LEAVES:3)
Block(1,49,6,LEAVES:3)
Block(1,49,7,LEAVES:3)
Block(1,49,8,LEAVES:3)
Block(1,49,9,LEAVES:3)
Block(1,49,10,LEAVES:3)
Block(1,50,-13,LEAVES:3)
Block(1,50,-12,LEAVES:3)
Block(1,50,-11,LEAVES:3)
Block(1,50,-10,LEAVES:3)
Block(1,50,-9,LOG:15)
Block(1,50,-8,LEAVES:3)
Block(1,50,-7,LEAVES:3)
Block(1,50,-6,LEAVES:3)
Block(1,50,-5,LEAVES:3)
Block(1,50,-4,VINE:2)
Block(1,50,1,LEAVES:3)
Block(1,50,2,LEAVES:3)
Block(1,50,3,LEAVES:3)
Block(1,50,4,LEAVES:3)
Block(1,50,5,LEAVES:3)
Block(1,50,6,LEAVES:3)
Block(1,50,7,LEAVES:3)
Block(1,51,-11,LEAVES:3)
Block(1,51,-10,LEAVES:3)
Block(1,51,-9,LEAVES:3)
Block(1,51,-8,LEAVES:3)
Block(1,51,-7,LOG:11)
Block(1,51,-6,LOG:11)
Block(1,51,-5,LEAVES:3)
Block(1,51,-4,LEAVES:3)
Block(1,51,-3,LEAVES:3)
Block(1,51,-2,LEAVES:3)
Block(1,51,-1,LEAVES:3)
Block(1,51,0,LEAVES:3)
Block(1,51,1,LEAVES:3)
Block(1,51,2,LEAVES:3)
Block(1,51,3,LEAVES:3)
Block(1,51,4,LEAVES:3)
Block(1,51,5,LEAVES:3)
Block(1,51,6,LEAVES:3)
Block(1,52,-11,LEAVES:3)
Block(1,52,-9,LEAVES:3)
Block(1,52,-8,LEAVES:3)
Block(1,52,-7,LEAVES:3)
Block(1,52,-6,LEAVES:3)
Block(1,52,-5,LEAVES:3)
Block(1,52,-4,LEAVES:3)
Block(1,52,-3,LEAVES:3)
Block(1,52,-2,LEAVES:3)
Block(1,52,-1,LEAVES:3)
Block(1,52,0,LEAVES:3)
Block(1,52,1,LEAVES:3)
Block(1,52,2,LEAVES:3)
Block(1,52,3,LEAVES:3)
Block(1,52,4,LEAVES:3)
Block(1,53,-8,LEAVES:3)
Block(1,53,-7,LEAVES:3)
Block(1,53,-6,LEAVES:3)
Block(1,53,-5,LEAVES:3)
Block(1,53,-4,LEAVES:3)
Block(1,53,-3,LEAVES:3)
Block(1,53,-2,LEAVES:3)
Block(1,53,-1,LEAVES:3)
Block(1,53,0,LOG:7)
Block(1,53,1,LOG:7)
Block(1,53,2,LEAVES:3)
Block(1,53,3,LEAVES:3)
Block(1,53,4,LEAVES:3)
Block(1,54,-7,LEAVES:3)
Block(1,54,-6,LEAVES:3)
Block(1,54,-5,LEAVES:3)
Block(1,54,-4,LEAVES:3)
Block(1,54,-3,LEAVES:3)
Block(1,54,-2,LEAVES:3)
Block(1,54,-1,LEAVES:3)
Block(1,54,0,LEAVES:3)
Block(1,54,1,LEAVES:3)
Block(1,54,2,LEAVES:3)
Block(1,54,3,LEAVES:3)
Block(1,54,4,LEAVES:3)
Block(1,55,-3,LEAVES:3)
Block(1,55,-2,LEAVES:3)
Block(1,55,-1,LEAVES:3)
Block(1,55,0,LEAVES:3)
Block(1,55,1,LEAVES:3)
Block(1,55,2,LEAVES:3)
Block(1,55,3,LEAVES:3)
Block(1,56,-2,VINE:1)
Block(1,56,-1,LEAVES:3)
Block(1,56,0,LEAVES:3)
Block(1,56,3,VINE:2)
Block(2,0,-3,LOG:3)
Block(2,0,-2,LOG:3)
Block(2,0,-1,LOG:3)
Block(2,0,1,LOG:3)
Block(2,1,-3,LOG:3)
Block(2,1,-2,LOG:3)
Block(2,1,-1,LOG:15)
Block(2,1,1,LOG:3)
Block(2,2,-3,LOG:3)
Block(2,2,-2,LOG:3)
Block(2,2,1,LOG:3)
Block(2,3,-3,LOG:3)
Block(2,3,-2,LOG:3)
Block(2,3,1,LOG:3)
Block(2,4,-3,LOG:3)
Block(2,4,-2,LOG:3)
Block(2,4,1,LOG:15)
Block(2,5,-3,LOG:3)
Block(2,5,-2,LOG:3)
Block(2,6,-4,VINE:1)
Block(2,6,-3,LOG:3)
Block(2,6,-2,LOG:3)
Block(2,6,-1,VINE:4)
Block(2,7,-7,VINE:3)
Block(2,7,-4,VINE:1)
Block(2,7,-3,LOG:3)
Block(2,7,-2,LOG:3)
Block(2,7,-1,VINE:4)
Block(2,8,-7,VINE:3)
Block(2,8,-5,LEAVES:3)
Block(2,8,-4,LEAVES:3)
Block(2,8,-3,LOG:3)
Block(2,8,-2,LOG:3)
Block(2,8,-1,LEAVES:3)
Block(2,8,0,LEAVES:3)
Block(2,9,-7,VINE:3)
Block(2,9,-6,LEAVES:3)
Block(2,9,-5,LEAVES:3)
Block(2,9,-4,LEAVES:3)
Block(2,9,-3,LOG:3)
Block(2,9,-2,LOG:3)
Block(2,9,-1,LEAVES:3)
Block(2,9,0,LEAVES:3)
Block(2,10,-7,VINE:3)
Block(2,10,-6,LEAVES:3)
Block(2,10,-5,LEAVES:3)
Block(2,10,-4,LEAVES:3)
Block(2,10,-3,LOG:15)
Block(2,10,-2,LOG:15)
Block(2,10,-1,LEAVES:3)
Block(2,10,0,LEAVES:3)
Block(2,10,1,LEAVES:3)
Block(2,10,2,LEAVES:3)
Block(2,11,-7,VINE:1)
Block(2,11,-6,LEAVES:3)
Block(2,11,-5,LEAVES:3)
Block(2,11,-4,LEAVES:3)
Block(2,11,-3,LEAVES:3)
Block(2,11,-2,LEAVES:3)
Block(2,11,-1,LEAVES:3)
Block(2,11,0,LEAVES:3)
Block(2,11,1,VINE:4)
Block(2,12,-4,LEAVES:3)
Block(2,12,-3,LEAVES:3)
Block(2,12,-2,LEAVES:3)
Block(2,12,-1,LEAVES:3)
Block(2,12,0,LEAVES:3)
Block(2,12,1,VINE:4)
Block(2,13,1,VINE:4)
Block(2,14,1,VINE:4)
Block(2,15,-2,LEAVES:3)
Block(2,15,-1,LEAVES:3)
Block(2,15,0,LEAVES:3)
Block(2,15,1,VINE:4)
Block(2,15,2,LEAVES:3)
Block(2,15,3,LEAVES:3)
Block(2,15,4,LEAVES:3)
Block(2,16,-3,LEAVES:3)
Block(2,16,-2,LEAVES:3)
Block(2,16,-1,LEAVES:3)
Block(2,16,0,LEAVES:3)
Block(2,16,1,LEAVES:3)
Block(2,17,-2,LEAVES:3)
Block(2,17,-1,LEAVES:3)
Block(2,17,0,LEAVES:3)
Block(2,18,-2,VINE:2)
Block(2,19,-2,VINE:2)
Block(2,20,-3,LEAVES:3)
Block(2,20,-2,VINE:2)
Block(2,21,-4,LEAVES:3)
Block(2,21,-3,LEAVES:3)
Block(2,21,-2,LEAVES:3)
Block(2,22,-3,LEAVES:3)
Block(2,22,-2,VINE:2)
Block(2,25,-2,LEAVES:3)
Block(2,25,0,LEAVES:3)
Block(2,26,-4,LEAVES:3)
Block(2,26,-3,LEAVES:3)
Block(2,26,-2,LEAVES:3)
Block(2,26,-1,LEAVES:3)
Block(2,26,0,LEAVES:3)
Block(2,26,1,LEAVES:3)
Block(2,27,-5,LEAVES:3)
Block(2,27,-4,LEAVES:3)
Block(2,27,-3,LEAVES:3)
Block(2,27,-2,LOG:15)
Block(2,27,-1,LEAVES:3)
Block(2,27,0,LEAVES:3)
Block(2,27,1,LEAVES:3)
Block(2,28,-4,LEAVES:3)
Block(2,28,-3,LEAVES:3)
Block(2,28,-2,LEAVES:3)
Block(2,28,-1,LEAVES:3)
Block(2,28,0,LEAVES:3)
Block(2,28,1,LEAVES:3)
Block(2,28,2,LEAVES:3)
Block(2,29,-4,LEAVES:3)
Block(2,29,-3,LEAVES:3)
Block(2,29,-2,LEAVES:3)
Block(2,29,-1,LEAVES:3)
Block(2,29,0,LEAVES:3)
Block(2,29,1,LEAVES:3)
Block(2,30,-1,LEAVES:3)
Block(2,30,0,LEAVES:3)
Block(2,45,7,LEAVES:3)
Block(2,45,8,LEAVES:3)
Block(2,45,9,LEAVES:3)
Block(2,45,10,LEAVES:3)
Block(2,45,11,LEAVES:3)
Block(2,46,5,LEAVES:3)
Block(2,46,7,LEAVES:3)
Block(2,46,8,LEAVES:3)
Block(2,46,9,LEAVES:3)
Block(2,46,10,LEAVES:3)
Block(2,46,11,LEAVES:3)
Block(2,47,4,LEAVES:3)
Block(2,47,5,LEAVES:3)
Block(2,47,6,LEAVES:3)
Block(2,47,7,LEAVES:3)
Block(2,47,8,LOG:11)
Block(2,47,9,LOG:15)
Block(2,47,10,LEAVES:3)
Block(2,47,11,LEAVES:3)
Block(2,47,12,LEAVES:3)
Block(2,48,-10,LEAVES:3)
Block(2,48,-9,LEAVES:3)
Block(2,48,-8,LEAVES:3)
Block(2,48,-7,LEAVES:3)
Block(2,48,3,LEAVES:3)
Block(2,48,4,LEAVES:3)
Block(2,48,5,LEAVES:3)
Block(2,48,6,LEAVES:3)
Block(2,48,7,LEAVES:3)
Block(2,48,8,LEAVES:3)
Block(2,48,9,LEAVES:3)
Block(2,48,10,LEAVES:3)
Block(2,48,11,LEAVES:3)
Block(2,48,12,LEAVES:3)
Block(2,49,-11,LEAVES:3)
Block(2,49,-10,LEAVES:3)
Block(2,49,-9,LEAVES:3)
Block(2,49,-8,LEAVES:3)
Block(2,49,-7,LEAVES:3)
Block(2,49,-6,LEAVES:3)
Block(2,49,3,LEAVES:3)
Block(2,49,4,LEAVES:3)
Block(2,49,5,LEAVES:3)
Block(2,49,6,LEAVES:3)
Block(2,49,7,LEAVES:3)
Block(2,49,8,LEAVES:3)
Block(2,49,9,LEAVES:3)
Block(2,49,10,LEAVES:3)
Block(2,50,-12,LEAVES:3)
Block(2,50,-11,LEAVES:3)
Block(2,50,-10,LEAVES:3)
Block(2,50,-9,LEAVES:3)
Block(2,50,-8,LOG:15)
Block(2,50,-7,LEAVES:3)
Block(2,50,-6,LEAVES:3)
Block(2,50,-5,LEAVES:3)
Block(2,50,1,LEAVES:3)
Block(2,50,2,LEAVES:3)
Block(2,50,3,LEAVES:3)
Block(2,50,4,LEAVES:3)
Block(2,50,5,LEAVES:3)
Block(2,50,6,LEAVES:3)
Block(2,51,-11,LEAVES:3)
Block(2,51,-10,LEAVES:3)
Block(2,51,-9,LEAVES:3)
Block(2,51,-8,LEAVES:3)
Block(2,51,-7,LEAVES:3)
Block(2,51,-6,LEAVES:3)
Block(2,51,-5,LEAVES:3)
Block(2,51,-2,LEAVES:3)
Block(2,51,-1,LEAVES:3)
Block(2,51,0,LEAVES:3)
Block(2,51,1,LEAVES:3)
Block(2,51,2,LEAVES:3)
Block(2,51,3,LEAVES:3)
Block(2,51,4,LEAVES:3)
Block(2,51,5,LEAVES:3)
Block(2,52,-8,LEAVES:3)
Block(2,52,-7,LEAVES:3)
Block(2,52,-6,LEAVES:3)
Block(2,52,-5,LEAVES:3)
Block(2,52,-4,LEAVES:3)
Block(2,52,-3,LEAVES:3)
Block(2,52,-2,LEAVES:3)
Block(2,52,-1,LEAVES:3)
Block(2,52,0,LEAVES:3)
Block(2,52,1,LEAVES:3)
Block(2,52,2,LEAVES:3)
Block(2,52,3,LEAVES:3)
Block(2,53,-7,LEAVES:3)
Block(2,53,-6,LEAVES:3)
Block(2,53,-5,LEAVES:3)
Block(2,53,-4,LEAVES:3)
Block(2,53,-3,LEAVES:3)
Block(2,53,-2,LEAVES:3)
Block(2,53,-1,LEAVES:3)
Block(2,53,0,LOG:7)
Block(2,53,1,LOG:7)
Block(2,53,2,LEAVES:3)
Block(2,53,3,LEAVES:3)
Block(2,53,4,LEAVES:3)
Block(2,53,5,LEAVES:3)
Block(2,54,-6,VINE:2)
Block(2,54,-5,VINE:2)
Block(2,54,-4,VINE:3)
Block(2,54,-3,LEAVES:3)
Block(2,54,-2,LEAVES:3)
Block(2,54,-1,LEAVES:3)
Block(2,54,0,LEAVES:3)
Block(2,54,1,LEAVES:3)
Block(2,54,2,LEAVES:3)
Block(2,54,3,LEAVES:3)
Block(2,54,4,LEAVES:3)
Block(2,55,-2,LEAVES:3)
Block(2,55,-1,LEAVES:3)
Block(2,55,0,LEAVES:3)
Block(2,55,1,LEAVES:3)
Block(2,55,2,LEAVES:3)
Block(2,55,3,LEAVES:3)
Block(2,56,-1,VINE:2)
Block(3,0,1,LOG:3)
Block(3,1,1,LOG:3)
Block(3,2,1,LOG:3)
Block(3,3,1,LOG:15)
Block(3,8,-3,LEAVES:3)
Block(3,8,-2,LEAVES:3)
Block(3,9,-5,LEAVES:3)
Block(3,9,-4,LEAVES:3)
Block(3,9,-3,LEAVES:3)
Block(3,9,-2,LEAVES:3)
Block(3,9,-1,LEAVES:3)
Block(3,9,0,LEAVES:3)
Block(3,10,-6,LEAVES:3)
Block(3,10,-5,LEAVES:3)
Block(3,10,-4,LEAVES:3)
Block(3,10,-3,LEAVES:3)
Block(3,10,-2,LEAVES:3)
Block(3,10,-1,LEAVES:3)
Block(3,10,0,LEAVES:3)
Block(3,10,1,LEAVES:3)
Block(3,11,-6,VINE:1)
Block(3,11,-5,LEAVES:3)
Block(3,11,-4,LEAVES:3)
Block(3,11,-3,LEAVES:3)
Block(3,11,-2,LEAVES:3)
Block(3,11,-1,LEAVES:3)
Block(3,11,0,LEAVES:3)
Block(3,12,-4,LEAVES:3)
Block(3,12,-3,LEAVES:3)
Block(3,12,-2,LEAVES:3)
Block(3,12,-1,LEAVES:3)
Block(3,12,0,VINE:2)
Block(3,13,0,VINE:2)
Block(3,14,0,VINE:2)
Block(3,15,-1,LEAVES:3)
Block(3,15,0,VINE:2)
Block(3,15,3,LEAVES:3)
Block(3,16,-2,LEAVES:3)
Block(3,16,-1,LEAVES:3)
Block(3,16,0,LEAVES:3)
Block(3,17,-1,LEAVES:3)
Block(3,25,-3,LEAVES:3)
Block(3,26,-4,LEAVES:3)
Block(3,26,-3,LEAVES:3)
Block(3,26,-2,LEAVES:3)
Block(3,26,-1,LEAVES:3)
Block(3,26,0,LEAVES:3)
Block(3,27,-5,LEAVES:3)
Block(3,27,-4,LEAVES:3)
Block(3,27,-3,LEAVES:3)
Block(3,27,-2,LEAVES:3)
Block(3,27,-1,LEAVES:3)
Block(3,27,0,LEAVES:3)
Block(3,27,1,LEAVES:3)
Block(3,28,-4,LEAVES:3)
Block(3,28,-3,LEAVES:3)
Block(3,28,-2,LEAVES:3)
Block(3,28,-1,LEAVES:3)
Block(3,28,0,LEAVES:3)
Block(3,28,1,LEAVES:3)
Block(3,29,-3,LEAVES:3)
Block(3,29,-2,LEAVES:3)
Block(3,29,-1,LEAVES:3)
Block(3,29,0,LEAVES:3)
Block(3,30,-1,LEAVES:3)
Block(3,45,9,LEAVES:3)
Block(3,45,10,LEAVES:3)
Block(3,46,7,LEAVES:3)
Block(3,46,8,LEAVES:3)
Block(3,46,9,LEAVES:3)
Block(3,46,10,LEAVES:3)
Block(3,46,11,LEAVES:3)
Block(3,47,5,LEAVES:3)
Block(3,47,6,LEAVES:3)
Block(3,47,7,LEAVES:3)
Block(3,47,8,LEAVES:3)
Block(3,47,9,LEAVES:3)
Block(3,47,10,LEAVES:3)
Block(3,47,11,LEAVES:3)
Block(3,47,12,LEAVES:3)
Block(3,48,-8,LEAVES:3)
Block(3,48,-7,LEAVES:3)
Block(3,48,4,LEAVES:3)
Block(3,48,5,LEAVES:3)
Block(3,48,6,LEAVES:3)
Block(3,48,7,LEAVES:3)
Block(3,48,8,LEAVES:3)
Block(3,48,9,LEAVES:3)
Block(3,48,10,LEAVES:3)
Block(3,48,11,LEAVES:3)
Block(3,49,-10,LEAVES:3)
Block(3,49,-9,LEAVES:3)
Block(3,49,-8,LEAVES:3)
Block(3,49,-7,LEAVES:3)
Block(3,49,-6,LEAVES:3)
Block(3,49,1,LEAVES:3)
Block(3,49,4,LEAVES:3)
Block(3,49,5,LEAVES:3)
Block(3,49,6,LEAVES:3)
Block(3,49,7,LEAVES:3)
Block(3,49,9,LEAVES:3)
Block(3,49,10,LEAVES:3)
Block(3,50,-11,LEAVES:3)
Block(3,50,-10,LEAVES:3)
Block(3,50,-9,LEAVES:3)
Block(3,50,-8,LEAVES:3)
Block(3,50,-7,LEAVES:3)
Block(3,50,-6,LEAVES:3)
Block(3,50,-5,LEAVES:3)
Block(3,50,0,LEAVES:3)
Block(3,50,1,LEAVES:3)
Block(3,50,2,LEAVES:3)
Block(3,50,3,LEAVES:3)
Block(3,50,4,LEAVES:3)
Block(3,50,5,LEAVES:3)
Block(3,51,-10,LEAVES:3)
Block(3,51,-9,LEAVES:3)
Block(3,51,-8,LEAVES:3)
Block(3,51,-7,LEAVES:3)
Block(3,51,-6,LEAVES:3)
Block(3,51,-1,LEAVES:3)
Block(3,51,0,LEAVES:3)
Block(3,51,1,LEAVES:3)
Block(3,51,2,LEAVES:3)
Block(3,51,3,LEAVES:3)
Block(3,51,4,LEAVES:3)
Block(3,52,-7,LEAVES:3)
Block(3,52,-6,LEAVES:3)
Block(3,52,-5,LEAVES:3)
Block(3,52,-2,LEAVES:3)
Block(3,52,-1,LEAVES:3)
Block(3,52,0,LOG:7)
Block(3,52,1,LOG:7)
Block(3,52,2,LEAVES:3)
Block(3,52,3,LEAVES:3)
Block(3,53,-3,LEAVES:3)
Block(3,53,-2,LEAVES:3)
Block(3,53,-1,LEAVES:3)
Block(3,53,0,LEAVES:3)
Block(3,53,1,LEAVES:3)
Block(3,53,2,LEAVES:3)
Block(3,53,3,LEAVES:3)
Block(3,53,4,LEAVES:3)
Block(3,54,-3,VINE:2)
Block(3,54,-2,LEAVES:3)
Block(3,54,-1,LEAVES:3)
Block(3,54,0,LEAVES:3)
Block(3,54,1,LEAVES:3)
Block(3,54,2,LEAVES:3)
Block(3,54,3,LEAVES:3)
Block(3,55,-1,LEAVES:3)
Block(3,55,0,LEAVES:3)
Block(3,55,1,LEAVES:3)
Block(3,55,2,LEAVES:3)
Block(4,0,1,LOG:3)
Block(4,1,1,LOG:15)
Block(4,6,0,VINE:4)
Block(4,7,0,VINE:4)
Block(4,8,-3,LEAVES:3)
Block(4,8,0,VINE:4)
Block(4,8,1,VINE:4)
Block(4,9,-4,LEAVES:3)
Block(4,9,-3,LEAVES:3)
Block(4,9,-2,LEAVES:3)
Block(4,9,-1,LEAVES:3)
Block(4,9,0,VINE:4)
Block(4,9,1,VINE:4)
Block(4,10,-5,LEAVES:3)
Block(4,10,-4,LEAVES:3)
Block(4,10,-3,LEAVES:3)
Block(4,10,-2,LEAVES:3)
Block(4,10,-1,LEAVES:3)
Block(4,10,0,LEAVES:3)
Block(4,10,1,VINE:4)
Block(4,11,-4,LEAVES:3)
Block(4,11,-3,LEAVES:3)
Block(4,11,-2,LEAVES:3)
Block(4,11,-1,LEAVES:3)
Block(4,12,-4,VINE:1)
Block(4,12,-3,LEAVES:3)
Block(4,26,-3,LEAVES:3)
Block(4,26,-2,LEAVES:3)
Block(4,26,-1,LEAVES:3)
Block(4,27,-4,LEAVES:3)
Block(4,27,-3,LEAVES:3)
Block(4,27,-2,LEAVES:3)
Block(4,27,-1,LEAVES:3)
Block(4,27,0,LEAVES:3)
Block(4,28,-3,LEAVES:3)
Block(4,28,-2,LEAVES:3)
Block(4,28,-1,LEAVES:3)
Block(4,28,0,LEAVES:3)
Block(4,29,-2,LEAVES:3)
Block(4,45,9,LEAVES:3)
Block(4,46,8,LEAVES:3)
Block(4,46,9,LEAVES:3)
Block(4,46,10,LEAVES:3)
Block(4,47,6,LEAVES:3)
Block(4,47,7,LEAVES:3)
Block(4,47,8,LEAVES:3)
Block(4,47,9,LEAVES:3)
Block(4,47,10,LEAVES:3)
Block(4,47,11,LEAVES:3)
Block(4,48,5,LEAVES:3)
Block(4,48,6,LEAVES:3)
Block(4,48,7,LEAVES:3)
Block(4,48,8,LEAVES:3)
Block(4,48,9,LEAVES:3)
Block(4,48,10,LEAVES:3)
Block(4,49,-9,LEAVES:3)
Block(4,49,-8,LEAVES:3)
Block(4,49,-7,LEAVES:3)
Block(4,49,2,LEAVES:3)
Block(4,50,-10,LEAVES:3)
Block(4,50,-9,LEAVES:3)
Block(4,50,-8,LEAVES:3)
Block(4,50,-7,LEAVES:3)
Block(4,50,-6,LEAVES:3)
Block(4,50,-1,LEAVES:3)
Block(4,50,0,LEAVES:3)
Block(4,50,1,LEAVES:3)
Block(4,50,2,LEAVES:3)
Block(4,50,3,LEAVES:3)
Block(4,50,4,LEAVES:3)
Block(4,51,-9,LEAVES:3)
Block(4,51,-8,LEAVES:3)
Block(4,51,-7,LEAVES:3)
Block(4,51,-2,LEAVES:3)
Block(4,51,-1,LEAVES:3)
Block(4,51,0,LEAVES:3)
Block(4,51,1,LEAVES:3)
Block(4,51,2,LEAVES:3)
Block(4,51,3,LEAVES:3)
Block(4,51,4,LEAVES:3)
Block(4,51,5,LEAVES:3)
Block(4,52,-8,LEAVES:3)
Block(4,52,-3,LEAVES:3)
Block(4,52,-2,LEAVES:3)
Block(4,52,-1,LEAVES:3)
Block(4,52,0,LOG:7)
Block(4,52,1,LEAVES:3)
Block(4,52,2,LOG:7)
Block(4,52,3,LEAVES:3)
Block(4,52,4,LEAVES:3)
Block(4,53,-2,LEAVES:3)
Block(4,53,-1,LEAVES:3)
Block(4,53,0,LEAVES:3)
Block(4,53,1,LEAVES:3)
Block(4,53,2,LEAVES:3)
Block(4,53,3,LEAVES:3)
Block(4,54,-1,LEAVES:3)
Block(4,54,0,LEAVES:3)
Block(4,54,1,LEAVES:3)
Block(4,54,2,LEAVES:3)
Block(4,55,0,LEAVES:3)
Block(4,55,1,LEAVES:3)
Block(5,9,-3,LEAVES:3)
Block(5,9,-2,LEAVES:3)
Block(5,10,-4,LEAVES:3)
Block(5,10,-3,LEAVES:3)
Block(5,10,-2,LEAVES:3)
Block(5,10,-1,LEAVES:3)
Block(5,11,-3,LEAVES:3)
Block(5,11,-2,VINE:4)
Block(5,27,-3,LEAVES:3)
Block(5,27,-2,LEAVES:3)
Block(5,27,-1,LEAVES:3)
Block(5,28,-2,LEAVES:3)
Block(5,46,9,LEAVES:3)
Block(5,47,8,LEAVES:3)
Block(5,47,9,LEAVES:3)
Block(5,47,10,LEAVES:3)
Block(5,48,9,LEAVES:3)
Block(5,49,-8,LEAVES:3)
Block(5,49,-1,LEAVES:3)
Block(5,49,0,LEAVES:3)
Block(5,49,1,LEAVES:3)
Block(5,49,2,LEAVES:3)
Block(5,49,3,LEAVES:3)
Block(5,50,-9,LEAVES:3)
Block(5,50,-8,LEAVES:3)
Block(5,50,-7,LEAVES:3)
Block(5,50,-2,LEAVES:3)
Block(5,50,-1,LEAVES:3)
Block(5,50,0,LEAVES:3)
Block(5,50,1,LEAVES:3)
Block(5,50,2,LEAVES:3)
Block(5,50,3,LEAVES:3)
Block(5,50,4,LEAVES:3)
Block(5,51,-3,LEAVES:3)
Block(5,51,-2,LEAVES:3)
Block(5,51,-1,LEAVES:3)
Block(5,51,0,LEAVES:3)
Block(5,51,1,LOG:7)
Block(5,51,2,LOG:7)
Block(5,51,3,LEAVES:3)
Block(5,51,4,LEAVES:3)
Block(5,51,5,LEAVES:3)
Block(5,51,6,LEAVES:3)
Block(5,52,-4,LEAVES:3)
Block(5,52,-3,LEAVES:3)
Block(5,52,-2,LEAVES:3)
Block(5,52,-1,LEAVES:3)
Block(5,52,0,LOG:7)
Block(5,52,1,LEAVES:3)
Block(5,52,2,LEAVES:3)
Block(5,52,3,LEAVES:3)
Block(5,52,4,LEAVES:3)
Block(5,52,5,LEAVES:3)
Block(5,53,-2,LEAVES:3)
Block(5,53,-1,LEAVES:3)
Block(5,53,0,LEAVES:3)
Block(5,53,1,LEAVES:3)
Block(5,53,2,LEAVES:3)
Block(5,53,3,LEAVES:3)
Block(5,53,4,LEAVES:3)
Block(5,54,-2,LEAVES:3)
Block(5,54,-1,LEAVES:3)
Block(5,54,0,LEAVES:3)
Block(5,54,1,LEAVES:3)
Block(5,54,2,LEAVES:3)
Block(6,10,-3,LEAVES:3)
Block(6,10,-2,LEAVES:3)
Block(6,48,0,LEAVES:3)
Block(6,48,3,LEAVES:3)
Block(6,49,-1,LEAVES:3)
Block(6,49,0,LEAVES:3)
Block(6,49,1,LEAVES:3)
Block(6,49,2,LEAVES:3)
Block(6,49,3,LEAVES:3)
Block(6,49,4,LEAVES:3)
Block(6,50,-8,LEAVES:3)
Block(6,50,-2,LEAVES:3)
Block(6,50,-1,LEAVES:3)
Block(6,50,0,LEAVES:3)
Block(6,50,1,LEAVES:3)
Block(6,50,2,LEAVES:3)
Block(6,50,3,LEAVES:3)
Block(6,50,4,LEAVES:3)
Block(6,50,5,LEAVES:3)
Block(6,51,-2,LEAVES:3)
Block(6,51,-1,LEAVES:3)
Block(6,51,0,LOG:7)
Block(6,51,1,LOG:7)
Block(6,51,2,LOG:7)
Block(6,51,3,LEAVES:3)
Block(6,51,4,LEAVES:3)
Block(6,51,5,LEAVES:3)
Block(6,52,-3,LEAVES:3)
Block(6,52,-2,LEAVES:3)
Block(6,52,-1,LEAVES:3)
Block(6,52,0,LEAVES:3)
Block(6,52,1,LEAVES:3)
Block(6,52,2,LEAVES:3)
Block(6,52,3,LEAVES:3)
Block(6,52,4,LEAVES:3)
Block(6,53,-2,LEAVES:3)
Block(6,53,-1,LEAVES:3)
Block(6,53,0,LEAVES:3)
Block(6,53,1,LEAVES:3)
Block(6,53,2,LEAVES:3)
Block(6,53,3,LEAVES:3)
Block(7,48,0,LEAVES:3)
Block(7,48,2,LEAVES:3)
Block(7,48,3,LEAVES:3)
Block(7,49,-2,LEAVES:3)
Block(7,49,-1,LEAVES:3)
Block(7,49,0,LEAVES:3)
Block(7,49,1,LEAVES:3)
Block(7,49,2,LEAVES:3)
Block(7,49,3,LEAVES:3)
Block(7,49,4,LEAVES:3)
Block(7,49,5,LEAVES:3)
Block(7,50,-3,LEAVES:3)
Block(7,50,-2,LEAVES:3)
Block(7,50,-1,LEAVES:3)
Block(7,50,0,LEAVES:3)
Block(7,50,1,LEAVES:3)
Block(7,50,2,LOG:7)
Block(7,50,3,LEAVES:3)
Block(7,50,4,LEAVES:3)
Block(7,50,5,LEAVES:3)
Block(7,50,6,LEAVES:3)
Block(7,51,-2,LEAVES:3)
Block(7,51,-1,LEAVES:3)
Block(7,51,0,LOG:7)
Block(7,51,1,LOG:7)
Block(7,51,2,LEAVES:3)
Block(7,51,3,LEAVES:3)
Block(7,51,4,LEAVES:3)
Block(7,51,5,LEAVES:3)
Block(7,52,-2,LEAVES:3)
Block(7,52,-1,LEAVES:3)
Block(7,52,0,LEAVES:3)
Block(7,52,1,LEAVES:3)
Block(7,52,2,LEAVES:3)
Block(7,52,3,LEAVES:3)
Block(7,53,-1,LEAVES:3)
Block(7,53,0,LEAVES:3)
Block(7,53,1,LEAVES:3)
Block(7,53,2,LEAVES:3)
Block(7,54,0,LEAVES:3)
Block(8,48,-1,LEAVES:3)
Block(8,48,0,LEAVES:3)
Block(8,48,1,LEAVES:3)
Block(8,48,2,LEAVES:3)
Block(8,48,3,LEAVES:3)
Block(8,48,4,LEAVES:3)
Block(8,48,5,LEAVES:3)
Block(8,49,-3,LEAVES:3)
Block(8,49,-2,LEAVES:3)
Block(8,49,-1,LEAVES:3)
Block(8,49,0,LEAVES:3)
Block(8,49,1,LEAVES:3)
Block(8,49,2,LEAVES:3)
Block(8,49,3,LEAVES:3)
Block(8,49,4,LEAVES:3)
Block(8,49,5,LEAVES:3)
Block(8,49,6,LEAVES:3)
Block(8,50,-4,LEAVES:3)
Block(8,50,-3,LEAVES:3)
Block(8,50,-2,LEAVES:3)
Block(8,50,-1,LEAVES:3)
Block(8,50,0,LOG:15)
Block(8,50,1,LOG:15)
Block(8,50,2,LEAVES:3)
Block(8,50,3,LOG:15)
Block(8,50,4,LEAVES:3)
Block(8,50,5,LEAVES:3)
Block(8,50,6,LEAVES:3)
Block(8,51,-3,LEAVES:3)
Block(8,51,-2,LEAVES:3)
Block(8,51,-1,LEAVES:3)
Block(8,51,0,LEAVES:3)
Block(8,51,1,LEAVES:3)
Block(8,51,2,LEAVES:3)
Block(8,51,3,LEAVES:3)
Block(8,51,4,LEAVES:3)
Block(8,51,5,LEAVES:3)
Block(8,52,-1,LEAVES:3)
Block(8,52,0,LEAVES:3)
Block(8,52,1,LEAVES:3)
Block(8,52,3,LEAVES:3)
Block(8,52,4,LEAVES:3)
Block(8,52,5,LEAVES:3)
Block(9,48,-1,LEAVES:3)
Block(9,49,-2,LEAVES:3)
Block(9,49,-1,LEAVES:3)
Block(9,49,0,LEAVES:3)
Block(9,49,1,LEAVES:3)
Block(9,49,2,LEAVES:3)
Block(9,49,3,LEAVES:3)
Block(9,49,4,LEAVES:3)
Block(9,49,5,LEAVES:3)
Block(9,50,-3,LEAVES:3)
Block(9,50,-2,LEAVES:3)
Block(9,50,-1,LEAVES:3)
Block(9,50,0,LEAVES:3)
Block(9,50,1,LEAVES:3)
Block(9,50,2,LEAVES:3)
Block(9,50,3,LEAVES:3)
Block(9,50,4,LEAVES:3)
Block(9,50,5,LEAVES:3)
Block(9,50,6,LEAVES:3)
Block(9,51,-2,LEAVES:3)
Block(9,51,-1,LEAVES:3)
Block(9,51,0,LEAVES:3)
Block(9,51,1,LEAVES:3)
Block(9,51,2,LEAVES:3)
Block(9,51,3,LEAVES:3)
Block(9,51,4,LEAVES:3)
Block(9,51,5,LEAVES:3)
Block(9,52,0,LEAVES:3)
Block(9,52,1,LEAVES:3)
Block(9,52,2,LEAVES:3)
Block(9,52,3,LEAVES:3)
Block(9,52,4,LEAVES:3)
Block(10,48,0,LEAVES:3)
Block(10,48,3,LEAVES:3)
Block(10,49,-1,LEAVES:3)
Block(10,49,0,LEAVES:3)
Block(10,49,1,LEAVES:3)
Block(10,49,2,LEAVES:3)
Block(10,49,3,LEAVES:3)
Block(10,49,4,LEAVES:3)
Block(10,50,-2,LEAVES:3)
Block(10,50,-1,LEAVES:3)
Block(10,50,0,LEAVES:3)
Block(10,50,1,LEAVES:3)
Block(10,50,2,LEAVES:3)
Block(10,50,3,LEAVES:3)
Block(10,50,4,LEAVES:3)
Block(10,50,5,LEAVES:3)
Block(10,51,-1,LEAVES:3)
Block(10,51,0,LEAVES:3)
Block(10,51,1,LEAVES:3)
Block(10,51,2,LEAVES:3)
Block(10,51,3,LEAVES:3)
Block(10,51,4,LEAVES:3)
Block(11,49,0,LEAVES:3)
Block(11,49,1,LEAVES:3)
Block(11,50,-1,LEAVES:3)
Block(11,50,0,LEAVES:3)
Block(11,50,1,LEAVES:3)
Block(11,50,2,LEAVES:3)
Block(11,50,3,LEAVES:3)
Block(11,50,4,LEAVES:3)
Block(11,51,1,LEAVES:3)
Block(11,51,3,LEAVES:3)

#######################################################################
# +-----------------------------------------------------------------+ #
# |                            BO3 checks                           | #
# +-----------------------------------------------------------------+ #
#######################################################################

BlockCheck(0,-1,0,GRASS:0,DIRT:0)
BlockCheck(1,-1,0,GRASS:0,DIRT:0)
BlockCheck(0,-1,1,GRASS:0,DIRT:0)
BlockCheck(1,-1,1,GRASS:0,DIRT:0)
BlockCheck(2,-1,0,GRASS:0,DIRT:0)
BlockCheck(2,-1,1,GRASS:0,DIRT:0)
BlockCheck(2,-1,2,GRASS:0,DIRT:0)
BlockCheck(2,-1,-1,GRASS:0,DIRT:0)
BlockCheck(2,-1,-2,GRASS:0,DIRT:0)
BlockCheck(-2,-1,0,GRASS:0,DIRT:0)
BlockCheck(-2,-1,1,GRASS:0,DIRT:0)
BlockCheck(-2,-1,2,GRASS:0,DIRT:0)
BlockCheck(-2,-1,-1,GRASS:0,DIRT:0)
BlockCheck(-2,-1,-2,GRASS:0,DIRT:0)

#######################################################################
# +-----------------------------------------------------------------+ #
# |                             Branches                            | #
# +-----------------------------------------------------------------+ #
#######################################################################


#######################################################################
# +-----------------------------------------------------------------+ #
# |                             Entities                            | #
# +-----------------------------------------------------------------+ #
#######################################################################


#######################################################################
# +-----------------------------------------------------------------+ #
# |                            Particles                            | #
# +-----------------------------------------------------------------+ #
#######################################################################


#######################################################################
# +-----------------------------------------------------------------+ #
# |                             Spawners                            | #
# +-----------------------------------------------------------------+ #
#######################################################################


#######################################################################
# +-----------------------------------------------------------------+ #
# |                             ModData                             | #
# +-----------------------------------------------------------------+ #
#######################################################################

