
#######################################################################
# +-----------------------------------------------------------------+ #
# |                            BO3 object                           | #
# +-----------------------------------------------------------------+ #
#######################################################################

Author: Unknown

Description: This BO3 was converted from a schematic using OTGEdit. The author and description information of the schematic could not be found. If you know who the author of the schematic is then please add this information.

Version: 3

SettingsMode: WriteWithoutComments


#######################################################################
# +-----------------------------------------------------------------+ #
# |                          Main settings                          | #
# +-----------------------------------------------------------------+ #
#######################################################################

Tree: true

Frequency: 1

Rarity: 100.0

RotateRandomly: true

SpawnHeight: highestSolidBlock

SpawnHeightOffset: 0

SpawnHeightVariance: 0

##############################
# Height Limits for the BO3. #
##############################

MinHeight: 20

MaxHeight: 255

######################
# Extrusion settings #
######################

ExtrudeMode: None

ExtrudeThroughBlocks: AIR

MaxBranchDepth: 10

ExcludedBiomes: All


#######################################################################
# +-----------------------------------------------------------------+ #
# |                      Source block settings                      | #
# +-----------------------------------------------------------------+ #
#######################################################################

SourceBlocks: AIR

MaxPercentageOutsideSourceBlock: 100

OutsideSourceBlock: dontPlace

DoReplaceBlocks: true

IsOTGPlus: false


#######################################################################
# +-----------------------------------------------------------------+ #
# |                              Blocks                             | #
# +-----------------------------------------------------------------+ #
#######################################################################

Block(-10,22,-5,LEAVES:3)
Block(-9,22,-6,LEAVES:3)
Block(-9,22,-5,LEAVES:3)
Block(-9,22,-4,LEAVES:3)
Block(-9,22,-3,LEAVES:3)
Block(-9,22,-2,LEAVES:3)
Block(-9,23,-3,LEAVES:3)
Block(-8,20,-4,LEAVES:3)
Block(-8,21,-6,LEAVES:3)
Block(-8,21,-5,LEAVES:3)
Block(-8,21,-4,LEAVES:3)
Block(-8,21,-3,LEAVES:3)
Block(-8,21,-2,LEAVES:3)
Block(-8,21,5,LEAVES:3)
Block(-8,22,-7,LEAVES:3)
Block(-8,22,-6,LEAVES:3)
Block(-8,22,-5,LEAVES:3)
Block(-8,22,-4,LEAVES:3)
Block(-8,22,-3,LEAVES:3)
Block(-8,22,-2,LEAVES:3)
Block(-8,22,-1,LEAVES:3)
Block(-8,22,4,LEAVES:3)
Block(-8,22,5,LEAVES:3)
Block(-8,22,6,LEAVES:3)
Block(-8,22,7,LEAVES:3)
Block(-8,23,-6,LEAVES:3)
Block(-8,23,-5,LEAVES:3)
Block(-8,23,-4,LEAVES:3)
Block(-8,23,-3,LEAVES:3)
Block(-8,23,-2,LEAVES:3)
Block(-7,20,-6,LEAVES:3)
Block(-7,20,-4,LEAVES:3)
Block(-7,20,-3,LEAVES:3)
Block(-7,20,5,LEAVES:3)
Block(-7,20,6,LEAVES:3)
Block(-7,21,-7,LEAVES:3)
Block(-7,21,-6,LEAVES:3)
Block(-7,21,-5,LEAVES:3)
Block(-7,21,-4,LEAVES:3)
Block(-7,21,-3,LEAVES:3)
Block(-7,21,-2,LEAVES:3)
Block(-7,21,-1,LEAVES:3)
Block(-7,21,4,LEAVES:3)
Block(-7,21,5,LEAVES:3)
Block(-7,21,6,LEAVES:3)
Block(-7,21,7,LEAVES:3)
Block(-7,22,-8,LEAVES:3)
Block(-7,22,-7,LEAVES:3)
Block(-7,22,-6,LEAVES:3)
Block(-7,22,-5,LEAVES:3)
Block(-7,22,-4,LEAVES:3)
Block(-7,22,-3,LEAVES:3)
Block(-7,22,-2,LEAVES:3)
Block(-7,22,-1,LEAVES:3)
Block(-7,22,0,LEAVES:3)
Block(-7,22,3,LEAVES:3)
Block(-7,22,4,LEAVES:3)
Block(-7,22,5,LEAVES:3)
Block(-7,22,6,LEAVES:3)
Block(-7,22,7,LEAVES:3)
Block(-7,22,8,LEAVES:3)
Block(-7,23,-7,LEAVES:3)
Block(-7,23,-6,LEAVES:3)
Block(-7,23,-5,LEAVES:3)
Block(-7,23,-4,LEAVES:3)
Block(-7,23,-3,LEAVES:3)
Block(-7,23,-2,LEAVES:3)
Block(-7,23,-1,LEAVES:3)
Block(-7,23,4,LEAVES:3)
Block(-7,23,5,LEAVES:3)
Block(-7,23,6,LEAVES:3)
Block(-7,23,7,LEAVES:3)
Block(-7,24,-6,LEAVES:3)
Block(-7,24,-5,LEAVES:3)
Block(-7,24,-4,LEAVES:3)
Block(-7,24,-2,LEAVES:3)
Block(-7,24,5,LEAVES:3)
Block(-6,20,-6,LEAVES:3)
Block(-6,20,-5,LEAVES:3)
Block(-6,20,-4,LEAVES:3)
Block(-6,20,-3,LEAVES:3)
Block(-6,20,-2,LEAVES:3)
Block(-6,20,-1,LEAVES:3)
Block(-6,20,4,LEAVES:3)
Block(-6,20,5,LEAVES:3)
Block(-6,21,-7,LEAVES:3)
Block(-6,21,-6,LEAVES:3)
Block(-6,21,-5,LEAVES:3)
Block(-6,21,-4,LEAVES:3)
Block(-6,21,-3,LEAVES:3)
Block(-6,21,-2,LEAVES:3)
Block(-6,21,-1,LEAVES:3)
Block(-6,21,3,LEAVES:3)
Block(-6,21,4,LEAVES:3)
Block(-6,21,5,LEAVES:3)
Block(-6,21,6,LEAVES:3)
Block(-6,21,7,LEAVES:3)
Block(-6,21,8,LEAVES:3)
Block(-6,22,-8,LEAVES:3)
Block(-6,22,-7,LEAVES:3)
Block(-6,22,-6,LEAVES:3)
Block(-6,22,-5,LOG:15)
Block(-6,22,-4,LOG:15)
Block(-6,22,-3,LOG:7)
Block(-6,22,-2,LEAVES:3)
Block(-6,22,-1,LEAVES:3)
Block(-6,22,0,LEAVES:3)
Block(-6,22,1,LEAVES:3)
Block(-6,22,2,LEAVES:3)
Block(-6,22,3,LEAVES:3)
Block(-6,22,4,LEAVES:3)
Block(-6,22,5,LEAVES:3)
Block(-6,22,6,LEAVES:3)
Block(-6,22,7,LEAVES:3)
Block(-6,22,8,LEAVES:3)
Block(-6,22,9,LEAVES:3)
Block(-6,23,-8,LEAVES:3)
Block(-6,23,-7,LEAVES:3)
Block(-6,23,-6,LEAVES:3)
Block(-6,23,-5,LEAVES:3)
Block(-6,23,-4,LEAVES:3)
Block(-6,23,-3,LEAVES:3)
Block(-6,23,-2,LEAVES:3)
Block(-6,23,-1,LEAVES:3)
Block(-6,23,0,LEAVES:3)
Block(-6,23,3,LEAVES:3)
Block(-6,23,4,LEAVES:3)
Block(-6,23,5,LEAVES:3)
Block(-6,23,6,LEAVES:3)
Block(-6,23,7,LEAVES:3)
Block(-6,23,8,LEAVES:3)
Block(-6,24,-6,LEAVES:3)
Block(-6,24,-5,LEAVES:3)
Block(-6,24,-4,LEAVES:3)
Block(-6,24,-3,LEAVES:3)
Block(-6,24,-2,LEAVES:3)
Block(-6,24,-1,LEAVES:3)
Block(-6,24,0,LEAVES:3)
Block(-6,24,2,LEAVES:3)
Block(-6,24,3,LEAVES:3)
Block(-6,24,4,LEAVES:3)
Block(-6,24,6,LEAVES:3)
Block(-6,25,-2,LEAVES:3)
Block(-6,25,-1,LEAVES:3)
Block(-6,25,0,LEAVES:3)
Block(-5,20,-6,LEAVES:3)
Block(-5,20,-5,LEAVES:3)
Block(-5,20,-4,LEAVES:3)
Block(-5,20,-3,LEAVES:3)
Block(-5,20,-2,LEAVES:3)
Block(-5,20,4,LEAVES:3)
Block(-5,20,5,LEAVES:3)
Block(-5,20,6,LEAVES:3)
Block(-5,20,7,LEAVES:3)
Block(-5,21,-7,LEAVES:3)
Block(-5,21,-6,LEAVES:3)
Block(-5,21,-5,LEAVES:3)
Block(-5,21,-4,LEAVES:3)
Block(-5,21,-3,LEAVES:3)
Block(-5,21,-2,LEAVES:3)
Block(-5,21,-1,LEAVES:3)
Block(-5,21,2,LEAVES:3)
Block(-5,21,3,LEAVES:3)
Block(-5,21,4,LEAVES:3)
Block(-5,21,5,LEAVES:3)
Block(-5,21,6,LEAVES:3)
Block(-5,21,7,LEAVES:3)
Block(-5,21,8,LEAVES:3)
Block(-5,22,-8,LEAVES:3)
Block(-5,22,-7,LEAVES:3)
Block(-5,22,-6,LEAVES:3)
Block(-5,22,-5,LEAVES:3)
Block(-5,22,-4,LOG:7)
Block(-5,22,-3,LEAVES:3)
Block(-5,22,-2,LEAVES:3)
Block(-5,22,-1,LEAVES:3)
Block(-5,22,0,LEAVES:3)
Block(-5,22,1,LEAVES:3)
Block(-5,22,2,LEAVES:3)
Block(-5,22,3,LEAVES:3)
Block(-5,22,4,LEAVES:3)
Block(-5,22,5,LOG:11)
Block(-5,22,6,LOG:15)
Block(-5,22,7,LEAVES:3)
Block(-5,22,8,LEAVES:3)
Block(-5,22,9,LEAVES:3)
Block(-5,22,10,LEAVES:3)
Block(-5,23,-7,LEAVES:3)
Block(-5,23,-6,LEAVES:3)
Block(-5,23,-5,LEAVES:3)
Block(-5,23,-4,LEAVES:3)
Block(-5,23,-3,LOG:7)
Block(-5,23,-2,LEAVES:3)
Block(-5,23,-1,LEAVES:3)
Block(-5,23,0,LEAVES:3)
Block(-5,23,2,LEAVES:3)
Block(-5,23,3,LEAVES:3)
Block(-5,23,4,LEAVES:3)
Block(-5,23,5,LEAVES:3)
Block(-5,23,6,LEAVES:3)
Block(-5,23,7,LEAVES:3)
Block(-5,23,8,LEAVES:3)
Block(-5,24,-5,LEAVES:3)
Block(-5,24,-4,LEAVES:3)
Block(-5,24,-3,LEAVES:3)
Block(-5,24,-2,LEAVES:3)
Block(-5,24,-1,LEAVES:3)
Block(-5,24,0,LEAVES:3)
Block(-5,24,1,LEAVES:3)
Block(-5,24,2,LEAVES:3)
Block(-5,24,3,LEAVES:3)
Block(-5,24,4,LEAVES:3)
Block(-5,24,5,LEAVES:3)
Block(-5,24,6,LEAVES:3)
Block(-5,24,7,LEAVES:3)
Block(-5,24,8,LEAVES:3)
Block(-5,25,-3,LEAVES:3)
Block(-5,25,-2,LEAVES:3)
Block(-5,25,-1,LEAVES:3)
Block(-5,25,0,LEAVES:3)
Block(-5,25,1,LEAVES:3)
Block(-5,25,2,LEAVES:3)
Block(-5,25,3,LEAVES:3)
Block(-5,25,4,LEAVES:3)
Block(-5,26,-2,LEAVES:3)
Block(-5,26,-1,LEAVES:3)
Block(-5,26,0,VINE:8)
Block(-5,27,0,VINE:8)
Block(-4,8,4,VINE:2)
Block(-4,9,4,VINE:2)
Block(-4,10,4,VINE:2)
Block(-4,11,1,VINE:4)
Block(-4,11,4,VINE:2)
Block(-4,12,1,VINE:4)
Block(-4,12,4,VINE:2)
Block(-4,13,1,VINE:4)
Block(-4,13,4,VINE:2)
Block(-4,14,1,VINE:4)
Block(-4,14,4,VINE:2)
Block(-4,15,1,VINE:4)
Block(-4,15,4,VINE:2)
Block(-4,16,1,VINE:4)
Block(-4,16,4,VINE:2)
Block(-4,17,1,VINE:4)
Block(-4,17,4,VINE:2)
Block(-4,18,1,VINE:4)
Block(-4,18,4,VINE:2)
Block(-4,19,1,VINE:4)
Block(-4,19,4,VINE:2)
Block(-4,20,-5,LEAVES:3)
Block(-4,20,-4,LEAVES:3)
Block(-4,20,-3,LEAVES:3)
Block(-4,20,1,VINE:4)
Block(-4,20,4,VINE:2)
Block(-4,20,5,LEAVES:3)
Block(-4,21,-6,LEAVES:3)
Block(-4,21,-5,LEAVES:3)
Block(-4,21,-4,LEAVES:3)
Block(-4,21,-3,LEAVES:3)
Block(-4,21,-2,LEAVES:3)
Block(-4,21,1,VINE:4)
Block(-4,21,3,LEAVES:3)
Block(-4,21,4,LEAVES:3)
Block(-4,21,5,LEAVES:3)
Block(-4,21,6,LEAVES:3)
Block(-4,21,7,LEAVES:3)
Block(-4,21,8,LEAVES:3)
Block(-4,22,-7,LEAVES:3)
Block(-4,22,-6,LEAVES:3)
Block(-4,22,-5,LEAVES:3)
Block(-4,22,-4,LEAVES:3)
Block(-4,22,-3,LEAVES:3)
Block(-4,22,-2,LEAVES:3)
Block(-4,22,-1,LEAVES:3)
Block(-4,22,0,LEAVES:3)
Block(-4,22,1,VINE:4)
Block(-4,22,2,LEAVES:3)
Block(-4,22,3,LEAVES:3)
Block(-4,22,4,LEAVES:3)
Block(-4,22,5,LEAVES:3)
Block(-4,22,6,LEAVES:3)
Block(-4,22,7,LEAVES:3)
Block(-4,22,8,LEAVES:3)
Block(-4,22,9,LEAVES:3)
Block(-4,23,-6,LEAVES:3)
Block(-4,23,-5,LEAVES:3)
Block(-4,23,-4,LEAVES:3)
Block(-4,23,-3,LOG:7)
Block(-4,23,-2,LOG:7)
Block(-4,23,-1,LEAVES:3)
Block(-4,23,0,LEAVES:3)
Block(-4,23,1,LEAVES:3)
Block(-4,23,2,LEAVES:3)
Block(-4,23,3,LEAVES:3)
Block(-4,23,4,LOG:11)
Block(-4,23,5,LEAVES:3)
Block(-4,23,6,LEAVES:3)
Block(-4,23,7,LEAVES:3)
Block(-4,23,8,LEAVES:3)
Block(-4,24,-5,LEAVES:3)
Block(-4,24,-4,LEAVES:3)
Block(-4,24,-3,LEAVES:3)
Block(-4,24,-2,LEAVES:3)
Block(-4,24,-1,LEAVES:3)
Block(-4,24,0,LEAVES:3)
Block(-4,24,1,LEAVES:3)
Block(-4,24,2,LEAVES:3)
Block(-4,24,3,LEAVES:3)
Block(-4,24,4,LEAVES:3)
Block(-4,24,5,LEAVES:3)
Block(-4,24,6,LEAVES:3)
Block(-4,24,7,LEAVES:3)
Block(-4,25,-4,LEAVES:3)
Block(-4,25,-3,LEAVES:3)
Block(-4,25,-2,LEAVES:3)
Block(-4,25,-1,LEAVES:3)
Block(-4,25,0,LEAVES:3)
Block(-4,25,1,LEAVES:3)
Block(-4,25,2,LEAVES:3)
Block(-4,25,3,LEAVES:3)
Block(-4,25,4,LEAVES:3)
Block(-4,25,5,LEAVES:3)
Block(-4,26,-4,VINE:1)
Block(-4,26,-3,LEAVES:3)
Block(-4,26,-2,LEAVES:3)
Block(-4,26,-1,LEAVES:3)
Block(-4,26,0,LEAVES:3)
Block(-4,26,1,LEAVES:3)
Block(-4,27,0,LEAVES:3)
Block(-3,9,-1,VINE:8)
Block(-3,9,0,VINE:8)
Block(-3,10,-1,VINE:8)
Block(-3,10,0,VINE:8)
Block(-3,11,-1,VINE:8)
Block(-3,11,0,VINE:8)
Block(-3,12,-1,VINE:8)
Block(-3,12,0,VINE:8)
Block(-3,13,-1,VINE:8)
Block(-3,13,0,VINE:8)
Block(-3,14,-1,VINE:8)
Block(-3,14,0,VINE:8)
Block(-3,15,-1,VINE:8)
Block(-3,15,0,VINE:8)
Block(-3,16,-1,VINE:8)
Block(-3,16,0,VINE:8)
Block(-3,17,-1,VINE:8)
Block(-3,17,0,VINE:8)
Block(-3,18,-1,VINE:8)
Block(-3,18,0,VINE:8)
Block(-3,19,0,VINE:8)
Block(-3,20,-4,LEAVES:3)
Block(-3,20,0,VINE:8)
Block(-3,20,5,LEAVES:3)
Block(-3,21,-5,LEAVES:3)
Block(-3,21,-4,LEAVES:3)
Block(-3,21,-3,LEAVES:3)
Block(-3,21,0,VINE:8)
Block(-3,21,4,LEAVES:3)
Block(-3,21,5,LEAVES:3)
Block(-3,21,6,LEAVES:3)
Block(-3,21,7,LEAVES:3)
Block(-3,22,-6,LEAVES:3)
Block(-3,22,-5,LEAVES:3)
Block(-3,22,-4,LEAVES:3)
Block(-3,22,-3,LEAVES:3)
Block(-3,22,-2,LEAVES:3)
Block(-3,22,-1,LEAVES:3)
Block(-3,22,0,LEAVES:3)
Block(-3,22,1,LEAVES:3)
Block(-3,22,2,LEAVES:3)
Block(-3,22,3,LEAVES:3)
Block(-3,22,4,LEAVES:3)
Block(-3,22,5,LEAVES:3)
Block(-3,22,6,LEAVES:3)
Block(-3,22,7,LEAVES:3)
Block(-3,22,8,LEAVES:3)
Block(-3,23,-5,LEAVES:3)
Block(-3,23,-4,LEAVES:3)
Block(-3,23,-3,LEAVES:3)
Block(-3,23,-2,LEAVES:3)
Block(-3,23,-1,LEAVES:3)
Block(-3,23,0,LEAVES:3)
Block(-3,23,1,LEAVES:3)
Block(-3,23,2,LEAVES:3)
Block(-3,23,3,LEAVES:3)
Block(-3,23,4,LOG:11)
Block(-3,23,5,LEAVES:3)
Block(-3,23,6,LEAVES:3)
Block(-3,23,7,LEAVES:3)
Block(-3,24,-5,LEAVES:3)
Block(-3,24,-4,LEAVES:3)
Block(-3,24,-3,LEAVES:3)
Block(-3,24,-2,LOG:7)
Block(-3,24,-1,LOG:7)
Block(-3,24,0,LEAVES:3)
Block(-3,24,1,LEAVES:3)
Block(-3,24,2,LEAVES:3)
Block(-3,24,3,LOG:11)
Block(-3,24,4,LEAVES:3)
Block(-3,24,5,LEAVES:3)
Block(-3,24,6,LEAVES:3)
Block(-3,24,7,LEAVES:3)
Block(-3,25,-4,LEAVES:3)
Block(-3,25,-3,LEAVES:3)
Block(-3,25,-2,LEAVES:3)
Block(-3,25,-1,LEAVES:3)
Block(-3,25,0,LEAVES:3)
Block(-3,25,1,LEAVES:3)
Block(-3,25,2,LEAVES:3)
Block(-3,25,3,LEAVES:3)
Block(-3,25,4,LEAVES:3)
Block(-3,25,5,LEAVES:3)
Block(-3,25,6,LEAVES:3)
Block(-3,26,-3,LEAVES:3)
Block(-3,26,-2,LEAVES:3)
Block(-3,26,-1,LEAVES:3)
Block(-3,26,0,LEAVES:3)
Block(-3,26,1,LEAVES:3)
Block(-3,26,2,LEAVES:3)
Block(-3,26,3,LEAVES:3)
Block(-3,26,4,VINE:8)
Block(-3,27,0,VINE:8)
Block(-3,27,2,LEAVES:3)
Block(-3,27,3,VINE:4)
Block(-2,0,0,LOG:3)
Block(-2,0,1,LOG:3)
Block(-2,1,0,LOG:3)
Block(-2,1,1,LOG:3)
Block(-2,2,0,LOG:3)
Block(-2,2,1,LOG:3)
Block(-2,3,0,LOG:3)
Block(-2,3,1,LOG:3)
Block(-2,4,0,LOG:3)
Block(-2,4,1,LOG:3)
Block(-2,5,0,LOG:3)
Block(-2,5,1,LOG:3)
Block(-2,6,0,LOG:3)
Block(-2,6,1,LOG:3)
Block(-2,7,-1,VINE:9)
Block(-2,7,0,LOG:3)
Block(-2,7,1,LOG:3)
Block(-2,8,-2,VINE:8)
Block(-2,8,-1,VINE:9)
Block(-2,8,0,LOG:3)
Block(-2,8,1,LOG:3)
Block(-2,8,2,VINE:12)
Block(-2,9,-2,VINE:8)
Block(-2,9,-1,VINE:9)
Block(-2,9,0,LOG:3)
Block(-2,9,1,LOG:3)
Block(-2,9,2,VINE:12)
Block(-2,10,-2,VINE:8)
Block(-2,10,-1,VINE:8)
Block(-2,10,0,LOG:3)
Block(-2,10,1,LOG:3)
Block(-2,10,2,VINE:12)
Block(-2,11,-2,VINE:8)
Block(-2,11,-1,VINE:8)
Block(-2,11,0,LOG:3)
Block(-2,11,1,LOG:3)
Block(-2,11,2,VINE:12)
Block(-2,12,-2,VINE:8)
Block(-2,12,-1,VINE:8)
Block(-2,12,0,LOG:3)
Block(-2,12,1,LOG:3)
Block(-2,12,2,VINE:12)
Block(-2,13,-2,VINE:8)
Block(-2,13,-1,VINE:9)
Block(-2,13,0,LOG:3)
Block(-2,13,1,LOG:3)
Block(-2,13,2,VINE:12)
Block(-2,14,-2,VINE:8)
Block(-2,14,-1,VINE:9)
Block(-2,14,0,LOG:3)
Block(-2,14,1,LOG:3)
Block(-2,14,2,VINE:12)
Block(-2,15,-2,VINE:8)
Block(-2,15,-1,VINE:1)
Block(-2,15,0,LOG:3)
Block(-2,15,1,LOG:3)
Block(-2,15,2,VINE:12)
Block(-2,16,-2,VINE:8)
Block(-2,16,-1,VINE:1)
Block(-2,16,0,LOG:3)
Block(-2,16,1,LOG:3)
Block(-2,16,2,VINE:12)
Block(-2,17,-2,VINE:8)
Block(-2,17,0,LOG:3)
Block(-2,17,1,LOG:3)
Block(-2,17,2,VINE:12)
Block(-2,18,-3,LEAVES:3)
Block(-2,18,-2,LEAVES:3)
Block(-2,18,-1,LEAVES:3)
Block(-2,18,0,LOG:3)
Block(-2,18,1,LOG:3)
Block(-2,18,2,VINE:12)
Block(-2,19,-3,VINE:8)
Block(-2,19,-2,VINE:4)
Block(-2,19,-1,VINE:9)
Block(-2,19,0,LOG:3)
Block(-2,19,1,LOG:3)
Block(-2,19,2,VINE:8)
Block(-2,20,-2,VINE:4)
Block(-2,20,-1,VINE:8)
Block(-2,20,0,LOG:3)
Block(-2,20,1,LOG:3)
Block(-2,20,2,VINE:4)
Block(-2,21,-2,VINE:4)
Block(-2,21,-1,VINE:8)
Block(-2,21,0,LOG:3)
Block(-2,21,1,LOG:3)
Block(-2,22,-5,LEAVES:3)
Block(-2,22,-4,LEAVES:3)
Block(-2,22,-3,LEAVES:3)
Block(-2,22,-2,VINE:4)
Block(-2,22,-1,LEAVES:3)
Block(-2,22,0,LOG:3)
Block(-2,22,1,LOG:3)
Block(-2,22,2,LEAVES:3)
Block(-2,22,3,LEAVES:3)
Block(-2,22,4,LEAVES:3)
Block(-2,22,5,LEAVES:3)
Block(-2,22,6,LEAVES:3)
Block(-2,22,7,LEAVES:3)
Block(-2,23,-4,LEAVES:3)
Block(-2,23,-3,LEAVES:3)
Block(-2,23,-2,LEAVES:3)
Block(-2,23,-1,LEAVES:3)
Block(-2,23,0,LOG:3)
Block(-2,23,1,LOG:3)
Block(-2,23,2,LEAVES:3)
Block(-2,23,3,LEAVES:3)
Block(-2,23,4,LEAVES:3)
Block(-2,23,5,LEAVES:3)
Block(-2,23,6,LEAVES:3)
Block(-2,24,-5,LEAVES:3)
Block(-2,24,-4,LEAVES:3)
Block(-2,24,-3,LEAVES:3)
Block(-2,24,-2,LEAVES:3)
Block(-2,24,-1,LOG:7)
Block(-2,24,0,LOG:3)
Block(-2,24,1,LOG:3)
Block(-2,24,2,LOG:11)
Block(-2,24,3,LEAVES:3)
Block(-2,24,4,LEAVES:3)
Block(-2,24,5,LEAVES:3)
Block(-2,24,6,LEAVES:3)
Block(-2,25,-4,LEAVES:3)
Block(-2,25,-3,LEAVES:3)
Block(-2,25,-2,LEAVES:3)
Block(-2,25,-1,LEAVES:3)
Block(-2,25,0,LOG:7)
Block(-2,25,1,LOG:15)
Block(-2,25,2,LEAVES:3)
Block(-2,25,3,LEAVES:3)
Block(-2,25,4,LEAVES:3)
Block(-2,25,5,LEAVES:3)
Block(-2,26,-3,LEAVES:3)
Block(-2,26,-2,LEAVES:3)
Block(-2,26,-1,LEAVES:3)
Block(-2,26,0,LEAVES:3)
Block(-2,26,1,LEAVES:3)
Block(-2,26,2,LEAVES:3)
Block(-2,26,3,LEAVES:3)
Block(-2,26,4,LEAVES:3)
Block(-2,27,-1,LEAVES:3)
Block(-2,27,0,LEAVES:3)
Block(-2,27,1,LEAVES:3)
Block(-2,27,2,LEAVES:3)
Block(-2,27,3,LEAVES:3)
Block(-1,0,-1,LOG:3)
Block(-1,0,0,LOG:3)
Block(-1,0,1,LOG:3)
Block(-1,0,2,LOG:3)
Block(-1,1,-1,LOG:3)
Block(-1,1,0,LOG:3)
Block(-1,1,1,LOG:3)
Block(-1,1,2,LOG:3)
Block(-1,2,-1,LOG:3)
Block(-1,2,0,LOG:3)
Block(-1,2,1,LOG:3)
Block(-1,2,2,LOG:3)
Block(-1,3,-1,LOG:3)
Block(-1,3,0,LOG:3)
Block(-1,3,1,LOG:3)
Block(-1,3,2,LOG:3)
Block(-1,4,-1,LOG:3)
Block(-1,4,0,LOG:3)
Block(-1,4,1,LOG:3)
Block(-1,4,2,LOG:3)
Block(-1,4,3,VINE:4)
Block(-1,5,-1,LOG:3)
Block(-1,5,0,LOG:3)
Block(-1,5,1,LOG:3)
Block(-1,5,2,LOG:3)
Block(-1,5,3,VINE:4)
Block(-1,6,-2,VINE:1)
Block(-1,6,-1,LOG:3)
Block(-1,6,0,LOG:3)
Block(-1,6,1,LOG:3)
Block(-1,6,2,LOG:3)
Block(-1,6,3,VINE:4)
Block(-1,7,-2,VINE:1)
Block(-1,7,-1,LOG:3)
Block(-1,7,0,LOG:3)
Block(-1,7,1,LOG:3)
Block(-1,7,2,LOG:3)
Block(-1,7,3,VINE:4)
Block(-1,8,-2,VINE:1)
Block(-1,8,-1,LOG:3)
Block(-1,8,0,LOG:3)
Block(-1,8,1,LOG:3)
Block(-1,8,2,LOG:3)
Block(-1,8,3,VINE:4)
Block(-1,9,-2,VINE:1)
Block(-1,9,-1,LOG:3)
Block(-1,9,0,LOG:3)
Block(-1,9,1,LOG:3)
Block(-1,9,2,LOG:3)
Block(-1,9,3,VINE:4)
Block(-1,10,-2,VINE:1)
Block(-1,10,-1,LOG:3)
Block(-1,10,0,LOG:3)
Block(-1,10,1,LOG:3)
Block(-1,10,2,LOG:3)
Block(-1,10,3,VINE:4)
Block(-1,11,-2,VINE:1)
Block(-1,11,-1,LOG:3)
Block(-1,11,0,LOG:3)
Block(-1,11,1,LOG:3)
Block(-1,11,2,LOG:3)
Block(-1,11,3,VINE:4)
Block(-1,12,-2,LEAVES:3)
Block(-1,12,-1,LOG:3)
Block(-1,12,0,LOG:3)
Block(-1,12,1,LOG:3)
Block(-1,12,2,LOG:3)
Block(-1,12,3,VINE:4)
Block(-1,13,-3,LEAVES:3)
Block(-1,13,-2,LEAVES:3)
Block(-1,13,-1,LOG:3)
Block(-1,13,0,LOG:3)
Block(-1,13,1,LOG:3)
Block(-1,13,2,LOG:3)
Block(-1,13,3,VINE:4)
Block(-1,14,-3,VINE:1)
Block(-1,14,-2,LEAVES:3)
Block(-1,14,-1,LOG:3)
Block(-1,14,0,LOG:3)
Block(-1,14,1,LOG:3)
Block(-1,14,2,LOG:3)
Block(-1,15,-2,VINE:1)
Block(-1,15,-1,LOG:3)
Block(-1,15,0,LOG:3)
Block(-1,15,1,LOG:3)
Block(-1,15,2,LOG:3)
Block(-1,16,-5,LEAVES:3)
Block(-1,16,-2,VINE:1)
Block(-1,16,-1,LOG:3)
Block(-1,16,0,LOG:3)
Block(-1,16,1,LOG:3)
Block(-1,16,2,LOG:3)
Block(-1,17,-3,LEAVES:3)
Block(-1,17,-2,LEAVES:3)
Block(-1,17,-1,LOG:3)
Block(-1,17,0,LOG:3)
Block(-1,17,1,LOG:3)
Block(-1,17,2,LOG:3)
Block(-1,18,-4,LEAVES:3)
Block(-1,18,-3,LEAVES:3)
Block(-1,18,-2,LEAVES:3)
Block(-1,18,-1,LOG:3)
Block(-1,18,0,LOG:3)
Block(-1,18,1,LOG:3)
Block(-1,18,2,LOG:3)
Block(-1,19,-3,LEAVES:3)
Block(-1,19,-2,LEAVES:3)
Block(-1,19,-1,LOG:3)
Block(-1,19,0,LOG:3)
Block(-1,19,1,LOG:3)
Block(-1,19,2,LOG:3)
Block(-1,20,-1,LOG:3)
Block(-1,20,0,LOG:3)
Block(-1,20,1,LOG:3)
Block(-1,20,2,LOG:3)
Block(-1,21,-1,LOG:3)
Block(-1,21,0,LOG:3)
Block(-1,21,1,LOG:3)
Block(-1,21,2,LOG:3)
Block(-1,22,-2,LEAVES:3)
Block(-1,22,-1,LOG:3)
Block(-1,22,0,LOG:3)
Block(-1,22,1,LOG:3)
Block(-1,22,2,LOG:3)
Block(-1,22,3,LEAVES:3)
Block(-1,23,-3,LEAVES:3)
Block(-1,23,-2,LEAVES:3)
Block(-1,23,-1,LOG:3)
Block(-1,23,0,LOG:3)
Block(-1,23,1,LOG:3)
Block(-1,23,2,LOG:3)
Block(-1,23,3,LEAVES:3)
Block(-1,23,4,LEAVES:3)
Block(-1,24,-4,LEAVES:3)
Block(-1,24,-3,LEAVES:3)
Block(-1,24,-2,LEAVES:3)
Block(-1,24,-1,LOG:3)
Block(-1,24,0,LOG:3)
Block(-1,24,1,LOG:3)
Block(-1,24,2,LOG:3)
Block(-1,24,3,LEAVES:3)
Block(-1,24,4,LEAVES:3)
Block(-1,24,5,LEAVES:3)
Block(-1,25,-4,LEAVES:3)
Block(-1,25,-3,LEAVES:3)
Block(-1,25,-2,LEAVES:3)
Block(-1,25,-1,LOG:15)
Block(-1,25,0,LOG:7)
Block(-1,25,1,LOG:11)
Block(-1,25,2,LOG:15)
Block(-1,25,3,LEAVES:3)
Block(-1,25,4,LEAVES:3)
Block(-1,25,5,LEAVES:3)
Block(-1,25,6,LEAVES:3)
Block(-1,26,-3,LEAVES:3)
Block(-1,26,-2,LEAVES:3)
Block(-1,26,-1,LEAVES:3)
Block(-1,26,0,LEAVES:3)
Block(-1,26,1,LEAVES:3)
Block(-1,26,2,LEAVES:3)
Block(-1,26,3,LEAVES:3)
Block(-1,26,4,LEAVES:3)
Block(-1,26,5,LEAVES:3)
Block(-1,27,-3,VINE:1)
Block(-1,27,-2,LEAVES:3)
Block(-1,27,-1,LEAVES:3)
Block(-1,27,0,LEAVES:3)
Block(-1,27,1,LEAVES:3)
Block(-1,27,2,LEAVES:3)
Block(-1,27,3,LEAVES:3)
Block(-1,27,4,LEAVES:3)
Block(0,0,-1,LOG:3)
Block(0,0,0,LOG:3)
Block(0,0,1,LOG:3)
Block(0,0,2,LOG:3)
Block(0,1,-1,LOG:3)
Block(0,1,0,LOG:3)
Block(0,1,1,LOG:3)
Block(0,1,2,LOG:3)
Block(0,2,-1,LOG:3)
Block(0,2,0,LOG:3)
Block(0,2,1,LOG:3)
Block(0,2,2,LOG:3)
Block(0,3,-1,LOG:3)
Block(0,3,0,LOG:3)
Block(0,3,1,LOG:3)
Block(0,3,2,LOG:3)
Block(0,4,-1,LOG:3)
Block(0,4,0,LOG:3)
Block(0,4,1,LOG:3)
Block(0,4,2,LOG:3)
Block(0,5,-1,LOG:3)
Block(0,5,0,LOG:3)
Block(0,5,1,LOG:3)
Block(0,5,2,LOG:3)
Block(0,6,-1,LOG:3)
Block(0,6,0,LOG:3)
Block(0,6,1,LOG:3)
Block(0,6,2,LOG:3)
Block(0,7,-3,VINE:8)
Block(0,7,-1,LOG:3)
Block(0,7,0,LOG:3)
Block(0,7,1,LOG:3)
Block(0,7,2,LOG:3)
Block(0,7,3,VINE:6)
Block(0,8,-3,VINE:8)
Block(0,8,-1,LOG:3)
Block(0,8,0,LOG:3)
Block(0,8,1,LOG:3)
Block(0,8,2,LOG:3)
Block(0,8,3,VINE:6)
Block(0,9,-3,VINE:8)
Block(0,9,-1,LOG:3)
Block(0,9,0,LOG:3)
Block(0,9,1,LOG:3)
Block(0,9,2,LOG:3)
Block(0,9,3,VINE:6)
Block(0,10,-3,VINE:8)
Block(0,10,-1,LOG:3)
Block(0,10,0,LOG:3)
Block(0,10,1,LOG:3)
Block(0,10,2,LOG:3)
Block(0,10,3,VINE:6)
Block(0,11,-3,VINE:8)
Block(0,11,-1,LOG:3)
Block(0,11,0,LOG:3)
Block(0,11,1,LOG:3)
Block(0,11,2,LOG:3)
Block(0,11,3,VINE:2)
Block(0,12,-3,LEAVES:3)
Block(0,12,-2,LEAVES:3)
Block(0,12,-1,LOG:3)
Block(0,12,0,LOG:3)
Block(0,12,1,LOG:3)
Block(0,12,2,LOG:3)
Block(0,12,3,VINE:2)
Block(0,13,-4,LEAVES:3)
Block(0,13,-3,LEAVES:3)
Block(0,13,-2,LEAVES:3)
Block(0,13,-1,LOG:3)
Block(0,13,0,LOG:3)
Block(0,13,1,LOG:3)
Block(0,13,2,LOG:3)
Block(0,13,3,VINE:2)
Block(0,14,-4,VINE:12)
Block(0,14,-3,LEAVES:3)
Block(0,14,-2,LEAVES:3)
Block(0,14,-1,LOG:3)
Block(0,14,0,LOG:3)
Block(0,14,1,LOG:3)
Block(0,14,2,LOG:3)
Block(0,14,3,VINE:2)
Block(0,15,-5,LEAVES:3)
Block(0,15,-4,VINE:4)
Block(0,15,-1,LOG:3)
Block(0,15,0,LOG:3)
Block(0,15,1,LOG:3)
Block(0,15,2,LOG:3)
Block(0,15,3,VINE:2)
Block(0,16,-6,LEAVES:3)
Block(0,16,-5,LEAVES:3)
Block(0,16,-4,LEAVES:3)
Block(0,16,-3,LEAVES:3)
Block(0,16,-1,LOG:3)
Block(0,16,0,LOG:3)
Block(0,16,1,LOG:3)
Block(0,16,2,LOG:3)
Block(0,16,3,VINE:2)
Block(0,17,-5,LEAVES:3)
Block(0,17,-4,LEAVES:3)
Block(0,17,-3,LEAVES:3)
Block(0,17,-2,LEAVES:3)
Block(0,17,-1,LOG:3)
Block(0,17,0,LOG:3)
Block(0,17,1,LOG:3)
Block(0,17,2,LOG:3)
Block(0,17,3,VINE:2)
Block(0,18,-5,LEAVES:3)
Block(0,18,-4,LEAVES:3)
Block(0,18,-3,LEAVES:3)
Block(0,18,-2,LEAVES:3)
Block(0,18,-1,LOG:3)
Block(0,18,0,LOG:3)
Block(0,18,1,LOG:3)
Block(0,18,2,LOG:3)
Block(0,18,3,VINE:2)
Block(0,19,-4,LEAVES:3)
Block(0,19,-3,LEAVES:3)
Block(0,19,-2,LEAVES:3)
Block(0,19,-1,LOG:3)
Block(0,19,0,LOG:3)
Block(0,19,1,LOG:3)
Block(0,19,2,LOG:3)
Block(0,19,3,VINE:2)
Block(0,20,-4,VINE:1)
Block(0,20,-3,LEAVES:3)
Block(0,20,-1,LOG:3)
Block(0,20,0,LOG:3)
Block(0,20,1,LOG:3)
Block(0,20,2,LOG:3)
Block(0,20,3,VINE:2)
Block(0,21,-1,LOG:3)
Block(0,21,0,LOG:3)
Block(0,21,1,LOG:3)
Block(0,21,2,LOG:3)
Block(0,21,3,VINE:2)
Block(0,22,-7,LEAVES:3)
Block(0,22,-6,LEAVES:3)
Block(0,22,-5,LEAVES:3)
Block(0,22,-2,LEAVES:3)
Block(0,22,-1,LOG:3)
Block(0,22,0,LOG:3)
Block(0,22,1,LOG:3)
Block(0,22,2,LOG:3)
Block(0,22,3,VINE:2)
Block(0,23,-6,LEAVES:3)
Block(0,23,-5,LEAVES:3)
Block(0,23,-4,LEAVES:3)
Block(0,23,-3,LEAVES:3)
Block(0,23,-2,LEAVES:3)
Block(0,23,-1,LOG:3)
Block(0,23,0,LOG:3)
Block(0,23,1,LOG:3)
Block(0,23,2,LOG:3)
Block(0,23,3,LEAVES:3)
Block(0,24,-5,LEAVES:3)
Block(0,24,-4,LEAVES:3)
Block(0,24,-3,LEAVES:3)
Block(0,24,-2,LEAVES:3)
Block(0,24,-1,LOG:3)
Block(0,24,0,LOG:3)
Block(0,24,1,LOG:3)
Block(0,24,2,LOG:3)
Block(0,24,3,LEAVES:3)
Block(0,24,4,LEAVES:3)
Block(0,25,-4,LEAVES:3)
Block(0,25,-3,LEAVES:3)
Block(0,25,-2,LEAVES:3)
Block(0,25,-1,LOG:11)
Block(0,25,0,LOG:11)
Block(0,25,1,LOG:15)
Block(0,25,2,LOG:15)
Block(0,25,3,LEAVES:3)
Block(0,25,4,LEAVES:3)
Block(0,25,5,LEAVES:3)
Block(0,26,-4,LEAVES:3)
Block(0,26,-3,LEAVES:3)
Block(0,26,-2,LEAVES:3)
Block(0,26,-1,LEAVES:3)
Block(0,26,0,LEAVES:3)
Block(0,26,1,LEAVES:3)
Block(0,26,2,LEAVES:3)
Block(0,26,3,LEAVES:3)
Block(0,26,4,LEAVES:3)
Block(0,27,-3,LEAVES:3)
Block(0,27,-2,LEAVES:3)
Block(0,27,-1,LEAVES:3)
Block(0,27,0,LEAVES:3)
Block(0,27,1,LEAVES:3)
Block(0,27,2,LEAVES:3)
Block(0,27,3,LEAVES:3)
Block(0,27,4,VINE:4)
Block(1,0,0,LOG:3)
Block(1,0,1,LOG:3)
Block(1,1,0,LOG:3)
Block(1,1,1,LOG:3)
Block(1,2,0,LOG:3)
Block(1,2,1,LOG:3)
Block(1,3,0,LOG:3)
Block(1,3,1,LOG:3)
Block(1,4,0,LOG:3)
Block(1,4,1,LOG:3)
Block(1,5,0,LOG:3)
Block(1,5,1,LOG:3)
Block(1,6,0,LOG:3)
Block(1,6,1,LOG:3)
Block(1,7,0,LOG:3)
Block(1,7,1,LOG:3)
Block(1,8,0,LOG:3)
Block(1,8,1,LOG:3)
Block(1,9,0,LOG:3)
Block(1,9,1,LOG:3)
Block(1,10,0,LOG:3)
Block(1,10,1,LOG:3)
Block(1,11,-3,LEAVES:3)
Block(1,11,-2,LEAVES:3)
Block(1,11,-1,LEAVES:3)
Block(1,11,0,LOG:3)
Block(1,11,1,LOG:3)
Block(1,12,-4,LEAVES:3)
Block(1,12,-3,LEAVES:3)
Block(1,12,-2,LEAVES:3)
Block(1,12,-1,LEAVES:3)
Block(1,12,0,LOG:3)
Block(1,12,1,LOG:3)
Block(1,13,-5,LEAVES:3)
Block(1,13,-4,LEAVES:3)
Block(1,13,-3,LEAVES:3)
Block(1,13,-2,LEAVES:3)
Block(1,13,-1,LOG:7)
Block(1,13,0,LOG:3)
Block(1,13,1,LOG:3)
Block(1,14,-4,LEAVES:3)
Block(1,14,-3,LEAVES:3)
Block(1,14,-2,LEAVES:3)
Block(1,14,-1,LEAVES:3)
Block(1,14,0,LOG:3)
Block(1,14,1,LOG:3)
Block(1,15,-6,LEAVES:3)
Block(1,15,-5,LEAVES:3)
Block(1,15,-4,LEAVES:3)
Block(1,15,-3,VINE:4)
Block(1,15,0,LOG:3)
Block(1,15,1,LOG:3)
Block(1,16,-7,LEAVES:3)
Block(1,16,-6,LEAVES:3)
Block(1,16,-5,LEAVES:3)
Block(1,16,-4,LEAVES:3)
Block(1,16,-3,LEAVES:3)
Block(1,16,-2,LEAVES:3)
Block(1,16,0,LOG:3)
Block(1,16,1,LOG:3)
Block(1,17,-6,LEAVES:3)
Block(1,17,-5,LEAVES:3)
Block(1,17,-4,LEAVES:3)
Block(1,17,-3,LEAVES:3)
Block(1,17,-2,LEAVES:3)
Block(1,17,-1,LEAVES:3)
Block(1,17,0,LOG:3)
Block(1,17,1,LOG:3)
Block(1,18,-6,LEAVES:3)
Block(1,18,-5,LEAVES:3)
Block(1,18,-4,LEAVES:3)
Block(1,18,-3,LEAVES:3)
Block(1,18,-2,LOG:11)
Block(1,18,-1,LOG:11)
Block(1,18,0,LOG:3)
Block(1,18,1,LOG:3)
Block(1,18,2,LEAVES:3)
Block(1,19,-5,LEAVES:3)
Block(1,19,-4,LEAVES:3)
Block(1,19,-3,LEAVES:3)
Block(1,19,-2,LEAVES:3)
Block(1,19,-1,LEAVES:3)
Block(1,19,0,LOG:3)
Block(1,19,1,LOG:3)
Block(1,20,-2,LEAVES:3)
Block(1,20,0,LOG:3)
Block(1,20,1,LOG:3)
Block(1,21,-7,LEAVES:3)
Block(1,21,-6,LEAVES:3)
Block(1,21,-5,LEAVES:3)
Block(1,21,0,LOG:3)
Block(1,21,1,LOG:3)
Block(1,22,-8,LEAVES:3)
Block(1,22,-7,LEAVES:3)
Block(1,22,-6,LEAVES:3)
Block(1,22,-5,LEAVES:3)
Block(1,22,-4,LEAVES:3)
Block(1,22,-2,LEAVES:3)
Block(1,22,0,LOG:3)
Block(1,22,1,LOG:3)
Block(1,23,-7,LEAVES:3)
Block(1,23,-6,LEAVES:3)
Block(1,23,-5,LEAVES:3)
Block(1,23,-4,LEAVES:3)
Block(1,23,-3,LEAVES:3)
Block(1,23,-2,LEAVES:3)
Block(1,23,-1,LEAVES:3)
Block(1,23,0,LOG:3)
Block(1,23,1,LOG:3)
Block(1,23,2,LEAVES:3)
Block(1,24,-6,LEAVES:3)
Block(1,24,-5,LEAVES:3)
Block(1,24,-4,LEAVES:3)
Block(1,24,-3,LEAVES:3)
Block(1,24,-2,LOG:11)
Block(1,24,-1,LEAVES:3)
Block(1,24,0,LOG:3)
Block(1,24,1,LOG:3)
Block(1,24,2,LEAVES:3)
Block(1,24,3,LEAVES:3)
Block(1,24,4,LEAVES:3)
Block(1,25,-5,LEAVES:3)
Block(1,25,-4,LEAVES:3)
Block(1,25,-3,LEAVES:3)
Block(1,25,-2,LEAVES:3)
Block(1,25,-1,LEAVES:3)
Block(1,25,0,LOG:7)
Block(1,25,1,LOG:15)
Block(1,25,2,LEAVES:3)
Block(1,25,3,LEAVES:3)
Block(1,25,4,LEAVES:3)
Block(1,26,-3,LEAVES:3)
Block(1,26,-2,LEAVES:3)
Block(1,26,-1,LEAVES:3)
Block(1,26,0,LEAVES:3)
Block(1,26,1,LEAVES:3)
Block(1,26,2,LEAVES:3)
Block(1,26,3,LEAVES:3)
Block(1,26,4,VINE:4)
Block(1,27,-3,VINE:1)
Block(1,27,-2,LEAVES:3)
Block(1,27,-1,LEAVES:3)
Block(1,27,0,LEAVES:3)
Block(1,27,1,LEAVES:3)
Block(1,27,2,LEAVES:3)
Block(1,27,3,LEAVES:3)
Block(1,27,4,VINE:4)
Block(2,6,-3,VINE:8)
Block(2,7,-3,VINE:8)
Block(2,8,-3,VINE:8)
Block(2,9,-3,VINE:8)
Block(2,10,-3,VINE:8)
Block(2,11,-4,LEAVES:3)
Block(2,11,-3,LEAVES:3)
Block(2,11,-2,LEAVES:3)
Block(2,11,0,LEAVES:3)
Block(2,12,-5,LEAVES:3)
Block(2,12,-4,LEAVES:3)
Block(2,12,-3,LEAVES:3)
Block(2,12,-2,LEAVES:3)
Block(2,12,-1,LEAVES:3)
Block(2,12,0,LEAVES:3)
Block(2,12,1,LEAVES:3)
Block(2,13,-6,LEAVES:3)
Block(2,13,-5,LEAVES:3)
Block(2,13,-4,LEAVES:3)
Block(2,13,-3,LEAVES:3)
Block(2,13,-2,LOG:7)
Block(2,13,-1,LEAVES:3)
Block(2,13,0,LEAVES:3)
Block(2,13,1,LEAVES:3)
Block(2,14,-6,LEAVES:3)
Block(2,14,-5,LEAVES:3)
Block(2,14,-4,LEAVES:3)
Block(2,14,-3,LEAVES:3)
Block(2,14,-2,LEAVES:3)
Block(2,14,-1,LEAVES:3)
Block(2,14,0,LEAVES:3)
Block(2,14,1,LEAVES:3)
Block(2,15,-7,LEAVES:3)
Block(2,15,-6,LEAVES:3)
Block(2,15,-5,LEAVES:3)
Block(2,15,-4,LEAVES:3)
Block(2,15,-3,LEAVES:3)
Block(2,15,-2,LEAVES:3)
Block(2,15,-1,LEAVES:3)
Block(2,15,0,LEAVES:3)
Block(2,15,1,VINE:2)
Block(2,16,-8,LEAVES:3)
Block(2,16,-7,LEAVES:3)
Block(2,16,-6,LEAVES:3)
Block(2,16,-5,LEAVES:3)
Block(2,16,-4,LEAVES:3)
Block(2,16,-3,LEAVES:3)
Block(2,16,-2,LEAVES:3)
Block(2,16,1,VINE:2)
Block(2,17,-7,LEAVES:3)
Block(2,17,-6,LEAVES:3)
Block(2,17,-5,LEAVES:3)
Block(2,17,-4,LOG:11)
Block(2,17,-3,LOG:11)
Block(2,17,-2,LEAVES:3)
Block(2,17,-1,LEAVES:3)
Block(2,17,0,LEAVES:3)
Block(2,17,1,VINE:2)
Block(2,18,-6,LEAVES:3)
Block(2,18,-5,LEAVES:3)
Block(2,18,-4,LEAVES:3)
Block(2,18,-3,LEAVES:3)
Block(2,18,-2,LEAVES:3)
Block(2,18,-1,LEAVES:3)
Block(2,18,0,LEAVES:3)
Block(2,18,1,LEAVES:3)
Block(2,19,-4,LEAVES:3)
Block(2,19,-3,LEAVES:3)
Block(2,19,-2,LEAVES:3)
Block(2,19,-1,LEAVES:3)
Block(2,19,0,LEAVES:3)
Block(2,19,1,VINE:2)
Block(2,20,-7,LEAVES:3)
Block(2,20,-6,LEAVES:3)
Block(2,20,-5,LEAVES:3)
Block(2,20,-3,VINE:8)
Block(2,20,-2,VINE:4)
Block(2,20,0,VINE:2)
Block(2,20,1,VINE:2)
Block(2,21,-8,LEAVES:3)
Block(2,21,-7,LEAVES:3)
Block(2,21,-6,LEAVES:3)
Block(2,21,-5,LEAVES:3)
Block(2,21,-4,LEAVES:3)
Block(2,21,-3,VINE:8)
Block(2,21,-2,VINE:4)
Block(2,21,0,VINE:2)
Block(2,21,1,VINE:2)
Block(2,22,-9,LEAVES:3)
Block(2,22,-8,LEAVES:3)
Block(2,22,-7,LEAVES:3)
Block(2,22,-6,LEAVES:3)
Block(2,22,-5,LEAVES:3)
Block(2,22,-4,LEAVES:3)
Block(2,22,-3,LEAVES:3)
Block(2,22,-2,VINE:4)
Block(2,22,-1,LEAVES:3)
Block(2,22,0,LEAVES:3)
Block(2,22,1,VINE:2)
Block(2,23,-8,LEAVES:3)
Block(2,23,-7,LEAVES:3)
Block(2,23,-6,LEAVES:3)
Block(2,23,-5,LEAVES:3)
Block(2,23,-4,LOG:11)
Block(2,23,-3,LOG:11)
Block(2,23,-2,LEAVES:3)
Block(2,23,-1,LEAVES:3)
Block(2,23,0,LEAVES:3)
Block(2,23,1,LEAVES:3)
Block(2,23,2,LEAVES:3)
Block(2,24,-7,LEAVES:3)
Block(2,24,-6,LEAVES:3)
Block(2,24,-5,LEAVES:3)
Block(2,24,-4,LEAVES:3)
Block(2,24,-3,LEAVES:3)
Block(2,24,-2,LEAVES:3)
Block(2,24,-1,LEAVES:3)
Block(2,24,0,LOG:7)
Block(2,24,1,LEAVES:3)
Block(2,24,2,LEAVES:3)
Block(2,24,3,LEAVES:3)
Block(2,25,-4,LEAVES:3)
Block(2,25,-3,LEAVES:3)
Block(2,25,-2,LEAVES:3)
Block(2,25,-1,LEAVES:3)
Block(2,25,0,LEAVES:3)
Block(2,25,1,LEAVES:3)
Block(2,25,2,LEAVES:3)
Block(2,25,3,LEAVES:3)
Block(2,25,4,LEAVES:3)
Block(2,26,-3,LEAVES:3)
Block(2,26,-2,LEAVES:3)
Block(2,26,-1,LEAVES:3)
Block(2,26,0,LEAVES:3)
Block(2,26,1,LEAVES:3)
Block(2,26,2,LEAVES:3)
Block(2,26,3,LEAVES:3)
Block(2,27,-2,VINE:3)
Block(2,27,-1,LEAVES:3)
Block(2,27,0,LEAVES:3)
Block(2,27,1,LEAVES:3)
Block(2,27,2,LEAVES:3)
Block(2,27,3,VINE:6)
Block(3,10,-4,LEAVES:3)
Block(3,10,-3,LEAVES:3)
Block(3,10,-2,LEAVES:3)
Block(3,11,-5,LEAVES:3)
Block(3,11,-4,LEAVES:3)
Block(3,11,-3,LEAVES:3)
Block(3,11,-2,LEAVES:3)
Block(3,11,-1,LEAVES:3)
Block(3,12,-6,LEAVES:3)
Block(3,12,-5,LEAVES:3)
Block(3,12,-4,LEAVES:3)
Block(3,12,-3,LEAVES:3)
Block(3,12,-2,LOG:7)
Block(3,12,-1,LEAVES:3)
Block(3,12,0,LEAVES:3)
Block(3,13,-10,VINE:1)
Block(3,13,-5,LEAVES:3)
Block(3,13,-4,LEAVES:3)
Block(3,13,-3,LEAVES:3)
Block(3,13,-2,LEAVES:3)
Block(3,13,-1,LEAVES:3)
Block(3,13,0,LEAVES:3)
Block(3,13,1,LEAVES:3)
Block(3,14,-10,VINE:1)
Block(3,14,-6,LEAVES:3)
Block(3,14,-5,LEAVES:3)
Block(3,14,-4,LEAVES:3)
Block(3,14,-3,LEAVES:3)
Block(3,14,-2,LEAVES:3)
Block(3,14,-1,LEAVES:3)
Block(3,14,0,LEAVES:3)
Block(3,14,1,VINE:2)
Block(3,15,-10,VINE:1)
Block(3,15,-8,LEAVES:3)
Block(3,15,-7,LEAVES:3)
Block(3,15,-6,LEAVES:3)
Block(3,15,-5,LEAVES:3)
Block(3,15,-4,LEAVES:3)
Block(3,15,-3,LEAVES:3)
Block(3,15,-2,LEAVES:3)
Block(3,16,-10,VINE:1)
Block(3,16,-9,LEAVES:3)
Block(3,16,-8,LEAVES:3)
Block(3,16,-7,LEAVES:3)
Block(3,16,-6,LEAVES:3)
Block(3,16,-5,LOG:15)
Block(3,16,-4,LEAVES:3)
Block(3,16,-3,LEAVES:3)
Block(3,16,-2,LEAVES:3)
Block(3,17,-9,VINE:1)
Block(3,17,-7,LEAVES:3)
Block(3,17,-6,LEAVES:3)
Block(3,17,-5,LEAVES:3)
Block(3,17,-4,LEAVES:3)
Block(3,17,-3,LEAVES:3)
Block(3,17,-2,LEAVES:3)
Block(3,17,-1,LEAVES:3)
Block(3,18,-9,VINE:1)
Block(3,18,-5,LEAVES:3)
Block(3,18,-4,LEAVES:3)
Block(3,18,-3,LEAVES:3)
Block(3,18,-2,LEAVES:3)
Block(3,18,-1,LEAVES:3)
Block(3,18,0,LEAVES:3)
Block(3,19,-9,VINE:1)
Block(3,19,-3,LEAVES:3)
Block(3,19,-2,LEAVES:3)
Block(3,19,-1,LEAVES:3)
Block(3,19,0,VINE:4)
Block(3,20,-9,VINE:1)
Block(3,20,-8,LEAVES:3)
Block(3,20,-7,LEAVES:3)
Block(3,20,-6,LEAVES:3)
Block(3,20,-5,LEAVES:3)
Block(3,20,-4,LEAVES:3)
Block(3,20,-2,LEAVES:3)
Block(3,21,-9,LEAVES:3)
Block(3,21,-8,LEAVES:3)
Block(3,21,-7,LEAVES:3)
Block(3,21,-6,LEAVES:3)
Block(3,21,-5,LEAVES:3)
Block(3,21,-4,LEAVES:3)
Block(3,21,-3,LEAVES:3)
Block(3,22,-10,LEAVES:3)
Block(3,22,-9,LEAVES:3)
Block(3,22,-8,LEAVES:3)
Block(3,22,-7,LEAVES:3)
Block(3,22,-6,LOG:15)
Block(3,22,-5,LEAVES:3)
Block(3,22,-4,LEAVES:3)
Block(3,22,-3,LEAVES:3)
Block(3,22,-2,LEAVES:3)
Block(3,22,-1,LEAVES:3)
Block(3,22,0,LEAVES:3)
Block(3,22,1,LEAVES:3)
Block(3,22,2,LEAVES:3)
Block(3,23,-9,LEAVES:3)
Block(3,23,-8,LEAVES:3)
Block(3,23,-7,LEAVES:3)
Block(3,23,-6,LEAVES:3)
Block(3,23,-5,LOG:11)
Block(3,23,-4,LEAVES:3)
Block(3,23,-3,LEAVES:3)
Block(3,23,-2,LEAVES:3)
Block(3,23,-1,LEAVES:3)
Block(3,23,0,LEAVES:3)
Block(3,23,1,LEAVES:3)
Block(3,23,2,LEAVES:3)
Block(3,23,3,LEAVES:3)
Block(3,24,-8,LEAVES:3)
Block(3,24,-7,LEAVES:3)
Block(3,24,-6,LEAVES:3)
Block(3,24,-5,LEAVES:3)
Block(3,24,-4,LEAVES:3)
Block(3,24,-3,LEAVES:3)
Block(3,24,-2,LEAVES:3)
Block(3,24,-1,LEAVES:3)
Block(3,24,0,LOG:7)
Block(3,24,1,LEAVES:3)
Block(3,24,2,LEAVES:3)
Block(3,24,3,LEAVES:3)
Block(3,25,-7,LEAVES:3)
Block(3,25,-6,LEAVES:3)
Block(3,25,-5,LEAVES:3)
Block(3,25,-4,LEAVES:3)
Block(3,25,-3,LEAVES:3)
Block(3,25,-2,LEAVES:3)
Block(3,25,-1,LEAVES:3)
Block(3,25,0,LEAVES:3)
Block(3,25,1,LEAVES:3)
Block(3,25,2,LEAVES:3)
Block(3,25,3,LEAVES:3)
Block(3,26,-2,LEAVES:3)
Block(3,26,-1,LEAVES:3)
Block(3,26,0,LEAVES:3)
Block(3,26,1,LEAVES:3)
Block(3,26,2,LEAVES:3)
Block(3,27,1,LEAVES:3)
Block(3,27,2,VINE:6)
Block(4,10,-3,LEAVES:3)
Block(4,10,-2,LEAVES:3)
Block(4,11,-5,LEAVES:3)
Block(4,11,-4,LEAVES:3)
Block(4,11,-3,LEAVES:3)
Block(4,11,-2,LEAVES:3)
Block(4,11,-1,LEAVES:3)
Block(4,11,0,LEAVES:3)
Block(4,12,-7,LEAVES:3)
Block(4,12,-6,LEAVES:3)
Block(4,12,-5,LEAVES:3)
Block(4,12,-4,LEAVES:3)
Block(4,12,-3,LOG:15)
Block(4,12,-2,LEAVES:3)
Block(4,12,-1,LEAVES:3)
Block(4,12,0,LEAVES:3)
Block(4,13,-5,LEAVES:3)
Block(4,13,-4,LEAVES:3)
Block(4,13,-3,LEAVES:3)
Block(4,13,-2,LEAVES:3)
Block(4,13,-1,LEAVES:3)
Block(4,13,0,LEAVES:3)
Block(4,14,-6,LEAVES:3)
Block(4,14,-4,LEAVES:3)
Block(4,14,-3,LEAVES:3)
Block(4,14,-2,LEAVES:3)
Block(4,14,-1,LEAVES:3)
Block(4,15,-7,LEAVES:3)
Block(4,15,-6,LEAVES:3)
Block(4,15,-5,LEAVES:3)
Block(4,15,-4,LEAVES:3)
Block(4,15,-3,LEAVES:3)
Block(4,15,-2,LEAVES:3)
Block(4,16,-8,LEAVES:3)
Block(4,16,-7,LEAVES:3)
Block(4,16,-6,LEAVES:3)
Block(4,16,-5,LEAVES:3)
Block(4,16,-4,LEAVES:3)
Block(4,16,-3,LEAVES:3)
Block(4,16,-2,LEAVES:3)
Block(4,17,-7,LEAVES:3)
Block(4,17,-6,LEAVES:3)
Block(4,17,-5,LEAVES:3)
Block(4,17,-4,LEAVES:3)
Block(4,17,-3,LEAVES:3)
Block(4,17,-2,LEAVES:3)
Block(4,18,-7,VINE:1)
Block(4,18,-6,LEAVES:3)
Block(4,18,-3,LEAVES:3)
Block(4,18,-2,LEAVES:3)
Block(4,18,-1,LEAVES:3)
Block(4,19,-7,VINE:1)
Block(4,20,-7,VINE:1)
Block(4,20,-6,LEAVES:3)
Block(4,20,-5,LEAVES:3)
Block(4,21,-8,LEAVES:3)
Block(4,21,-7,LEAVES:3)
Block(4,21,-6,LEAVES:3)
Block(4,21,-5,LEAVES:3)
Block(4,21,-4,LEAVES:3)
Block(4,21,0,LEAVES:3)
Block(4,22,-9,LEAVES:3)
Block(4,22,-8,LEAVES:3)
Block(4,22,-7,LEAVES:3)
Block(4,22,-6,LEAVES:3)
Block(4,22,-5,LEAVES:3)
Block(4,22,-4,LEAVES:3)
Block(4,22,-3,LEAVES:3)
Block(4,22,-2,LEAVES:3)
Block(4,22,-1,LEAVES:3)
Block(4,22,0,LEAVES:3)
Block(4,22,1,LEAVES:3)
Block(4,23,-8,LEAVES:3)
Block(4,23,-7,LEAVES:3)
Block(4,23,-6,LEAVES:3)
Block(4,23,-5,LEAVES:3)
Block(4,23,-4,LEAVES:3)
Block(4,23,-3,LEAVES:3)
Block(4,23,-2,LEAVES:3)
Block(4,23,-1,LEAVES:3)
Block(4,23,0,LOG:7)
Block(4,23,1,LEAVES:3)
Block(4,23,2,LEAVES:3)
Block(4,24,-7,LEAVES:3)
Block(4,24,-6,LEAVES:3)
Block(4,24,-5,LEAVES:3)
Block(4,24,-4,LEAVES:3)
Block(4,24,-3,LEAVES:3)
Block(4,24,-2,LEAVES:3)
Block(4,24,-1,LEAVES:3)
Block(4,24,0,LEAVES:3)
Block(4,24,1,LEAVES:3)
Block(4,24,2,LEAVES:3)
Block(4,24,3,LEAVES:3)
Block(4,25,-5,LEAVES:3)
Block(4,25,-4,LEAVES:3)
Block(4,25,-2,LEAVES:3)
Block(4,25,-1,LEAVES:3)
Block(4,25,0,LEAVES:3)
Block(4,25,1,LEAVES:3)
Block(4,25,2,LEAVES:3)
Block(4,26,0,LEAVES:3)
Block(4,26,1,LEAVES:3)
Block(4,27,1,VINE:2)
Block(5,10,-2,LEAVES:3)
Block(5,11,-5,LEAVES:3)
Block(5,11,-4,LEAVES:3)
Block(5,11,-3,LEAVES:3)
Block(5,11,-2,LEAVES:3)
Block(5,11,-1,LEAVES:3)
Block(5,12,-6,LEAVES:3)
Block(5,12,-5,LEAVES:3)
Block(5,12,-4,LEAVES:3)
Block(5,12,-3,LEAVES:3)
Block(5,12,-2,LEAVES:3)
Block(5,12,-1,LEAVES:3)
Block(5,12,0,LEAVES:3)
Block(5,13,-5,LEAVES:3)
Block(5,13,-4,LEAVES:3)
Block(5,13,-3,LEAVES:3)
Block(5,13,-2,LEAVES:3)
Block(5,13,-1,LEAVES:3)
Block(5,14,-4,LEAVES:3)
Block(5,15,-6,LEAVES:3)
Block(5,15,-5,LEAVES:3)
Block(5,15,-4,LEAVES:3)
Block(5,16,-7,LEAVES:3)
Block(5,16,-6,LEAVES:3)
Block(5,16,-5,LEAVES:3)
Block(5,16,-4,LEAVES:3)
Block(5,16,-3,LEAVES:3)
Block(5,17,-6,LEAVES:3)
Block(5,17,-5,LEAVES:3)
Block(5,17,-4,LEAVES:3)
Block(5,18,-2,LEAVES:3)
Block(5,20,-6,LEAVES:3)
Block(5,20,0,LEAVES:3)
Block(5,21,-7,LEAVES:3)
Block(5,21,-6,LEAVES:3)
Block(5,21,-5,LEAVES:3)
Block(5,21,-1,LEAVES:3)
Block(5,21,0,LEAVES:3)
Block(5,21,1,LEAVES:3)
Block(5,22,-8,LEAVES:3)
Block(5,22,-7,LEAVES:3)
Block(5,22,-6,LEAVES:3)
Block(5,22,-5,LEAVES:3)
Block(5,22,-4,LEAVES:3)
Block(5,22,-3,LEAVES:3)
Block(5,22,-2,LEAVES:3)
Block(5,22,-1,LEAVES:3)
Block(5,22,0,LEAVES:3)
Block(5,22,1,LEAVES:3)
Block(5,22,2,LEAVES:3)
Block(5,23,-7,LEAVES:3)
Block(5,23,-6,LEAVES:3)
Block(5,23,-5,LEAVES:3)
Block(5,23,-4,LEAVES:3)
Block(5,23,-3,LEAVES:3)
Block(5,23,-2,LEAVES:3)
Block(5,23,-1,LEAVES:3)
Block(5,23,0,LOG:7)
Block(5,23,1,LEAVES:3)
Block(5,23,2,LEAVES:3)
Block(5,23,3,LEAVES:3)
Block(5,24,-6,LEAVES:3)
Block(5,24,-5,LEAVES:3)
Block(5,24,-4,LEAVES:3)
Block(5,24,-2,LEAVES:3)
Block(5,24,-1,LEAVES:3)
Block(5,24,0,LEAVES:3)
Block(5,24,1,LEAVES:3)
Block(5,24,2,LEAVES:3)
Block(5,25,-1,LEAVES:3)
Block(5,25,0,LEAVES:3)
Block(5,25,1,LEAVES:3)
Block(5,26,0,LEAVES:3)
Block(6,10,-3,LEAVES:3)
Block(6,11,-4,LEAVES:3)
Block(6,11,-3,LEAVES:3)
Block(6,11,-2,LEAVES:3)
Block(6,12,-5,LEAVES:3)
Block(6,12,-4,LEAVES:3)
Block(6,12,-3,LEAVES:3)
Block(6,12,-2,LEAVES:3)
Block(6,12,-1,LEAVES:3)
Block(6,13,-4,LEAVES:3)
Block(6,13,-3,LEAVES:3)
Block(6,13,-2,LEAVES:3)
Block(6,15,-5,LEAVES:3)
Block(6,16,-6,LEAVES:3)
Block(6,16,-5,LEAVES:3)
Block(6,16,-4,LEAVES:3)
Block(6,17,-5,LEAVES:3)
Block(6,21,-2,LEAVES:3)
Block(6,21,-1,LEAVES:3)
Block(6,21,0,LEAVES:3)
Block(6,21,1,LEAVES:3)
Block(6,21,2,LEAVES:3)
Block(6,22,-7,LEAVES:3)
Block(6,22,-6,LEAVES:3)
Block(6,22,-5,LEAVES:3)
Block(6,22,-4,LEAVES:3)
Block(6,22,-3,LEAVES:3)
Block(6,22,-2,LEAVES:3)
Block(6,22,-1,LEAVES:3)
Block(6,22,0,LEAVES:3)
Block(6,22,1,LEAVES:3)
Block(6,22,2,LEAVES:3)
Block(6,22,3,LEAVES:3)
Block(6,23,-6,LEAVES:3)
Block(6,23,-5,LEAVES:3)
Block(6,23,-4,LEAVES:3)
Block(6,23,-3,LEAVES:3)
Block(6,23,-2,LEAVES:3)
Block(6,23,-1,LEAVES:3)
Block(6,23,0,LOG:7)
Block(6,23,1,LEAVES:3)
Block(6,23,2,LEAVES:3)
Block(6,23,3,LEAVES:3)
Block(6,24,-5,LEAVES:3)
Block(6,24,-2,LEAVES:3)
Block(6,24,-1,LEAVES:3)
Block(6,24,0,LEAVES:3)
Block(6,24,1,LEAVES:3)
Block(6,24,2,LEAVES:3)
Block(6,24,3,LEAVES:3)
Block(6,25,-1,LEAVES:3)
Block(6,25,0,LEAVES:3)
Block(6,25,2,LEAVES:3)
Block(7,9,-1,VINE:2)
Block(7,10,-1,VINE:2)
Block(7,11,-1,VINE:2)
Block(7,12,-4,LEAVES:3)
Block(7,12,-3,LEAVES:3)
Block(7,12,-2,LEAVES:3)
Block(7,12,-1,VINE:2)
Block(7,20,0,LEAVES:3)
Block(7,20,2,LEAVES:3)
Block(7,21,-3,LEAVES:3)
Block(7,21,-2,LEAVES:3)
Block(7,21,-1,LEAVES:3)
Block(7,21,0,LEAVES:3)
Block(7,21,1,LEAVES:3)
Block(7,21,2,LEAVES:3)
Block(7,22,-4,LEAVES:3)
Block(7,22,-3,LEAVES:3)
Block(7,22,-2,LEAVES:3)
Block(7,22,-1,LEAVES:3)
Block(7,22,0,LOG:15)
Block(7,22,1,LEAVES:3)
Block(7,22,2,LEAVES:3)
Block(7,22,3,LEAVES:3)
Block(7,22,4,LEAVES:3)
Block(7,23,-5,LEAVES:3)
Block(7,23,-3,LEAVES:3)
Block(7,23,-2,LEAVES:3)
Block(7,23,-1,LEAVES:3)
Block(7,23,0,LEAVES:3)
Block(7,23,1,LEAVES:3)
Block(7,23,2,LEAVES:3)
Block(7,23,3,LEAVES:3)
Block(7,24,-2,LEAVES:3)
Block(7,24,-1,LEAVES:3)
Block(7,24,0,LEAVES:3)
Block(7,24,1,LEAVES:3)
Block(7,24,2,LEAVES:3)
Block(7,25,-1,LEAVES:3)
Block(7,25,1,LEAVES:3)
Block(8,20,0,LEAVES:3)
Block(8,21,-2,LEAVES:3)
Block(8,21,-1,LEAVES:3)
Block(8,21,0,LEAVES:3)
Block(8,21,1,LEAVES:3)
Block(8,21,2,LEAVES:3)
Block(8,22,-3,LEAVES:3)
Block(8,22,-2,LEAVES:3)
Block(8,22,-1,LEAVES:3)
Block(8,22,0,LEAVES:3)
Block(8,22,1,LEAVES:3)
Block(8,22,2,LEAVES:3)
Block(8,22,3,LEAVES:3)
Block(8,23,-2,LEAVES:3)
Block(8,23,-1,LEAVES:3)
Block(8,23,0,LEAVES:3)
Block(8,23,1,LEAVES:3)
Block(8,23,2,LEAVES:3)
Block(8,24,-1,LEAVES:3)
Block(8,24,0,LEAVES:3)
Block(8,24,1,LEAVES:3)
Block(8,25,0,LEAVES:3)
Block(9,21,-1,LEAVES:3)
Block(9,21,0,LEAVES:3)
Block(9,21,1,LEAVES:3)
Block(9,22,-2,LEAVES:3)
Block(9,22,-1,LEAVES:3)
Block(9,22,0,LEAVES:3)
Block(9,22,1,LEAVES:3)
Block(9,22,2,LEAVES:3)
Block(9,23,-1,LEAVES:3)
Block(9,23,0,LEAVES:3)
Block(9,23,1,LEAVES:3)
Block(9,24,0,LEAVES:3)
Block(10,21,0,LEAVES:3)
Block(10,22,-1,LEAVES:3)
Block(10,22,0,LEAVES:3)
Block(10,22,1,LEAVES:3)
Block(10,23,0,LEAVES:3)
Block(11,22,0,LEAVES:3)

#######################################################################
# +-----------------------------------------------------------------+ #
# |                            BO3 checks                           | #
# +-----------------------------------------------------------------+ #
#######################################################################

BlockCheck(0,-1,0,GRASS:0,DIRT:0)
BlockCheck(1,-1,0,GRASS:0,DIRT:0)
BlockCheck(0,-1,1,GRASS:0,DIRT:0)
BlockCheck(1,-1,1,GRASS:0,DIRT:0)

#######################################################################
# +-----------------------------------------------------------------+ #
# |                             Branches                            | #
# +-----------------------------------------------------------------+ #
#######################################################################


#######################################################################
# +-----------------------------------------------------------------+ #
# |                             Entities                            | #
# +-----------------------------------------------------------------+ #
#######################################################################


#######################################################################
# +-----------------------------------------------------------------+ #
# |                            Particles                            | #
# +-----------------------------------------------------------------+ #
#######################################################################


#######################################################################
# +-----------------------------------------------------------------+ #
# |                             Spawners                            | #
# +-----------------------------------------------------------------+ #
#######################################################################


#######################################################################
# +-----------------------------------------------------------------+ #
# |                             ModData                             | #
# +-----------------------------------------------------------------+ #
#######################################################################

