
#######################################################################
# +-----------------------------------------------------------------+ #
# |                            BO3 object                           | #
# +-----------------------------------------------------------------+ #
#######################################################################

Author: Unknown

Description: This BO3 was converted from a schematic using OTGEdit. The author and description information of the schematic could not be found. If you know who the author of the schematic is then please add this information.

Version: 3

SettingsMode: WriteWithoutComments


#######################################################################
# +-----------------------------------------------------------------+ #
# |                          Main settings                          | #
# +-----------------------------------------------------------------+ #
#######################################################################

Tree: true

Frequency: 1

Rarity: 100.0

RotateRandomly: true

SpawnHeight: highestSolidBlock

SpawnHeightOffset: 0

SpawnHeightVariance: 0

##############################
# Height Limits for the BO3. #
##############################

MinHeight: 20

MaxHeight: 255

######################
# Extrusion settings #
######################

ExtrudeMode: None

ExtrudeThroughBlocks: AIR

MaxBranchDepth: 10

ExcludedBiomes: All


#######################################################################
# +-----------------------------------------------------------------+ #
# |                      Source block settings                      | #
# +-----------------------------------------------------------------+ #
#######################################################################

SourceBlocks: AIR

MaxPercentageOutsideSourceBlock: 100

OutsideSourceBlock: dontPlace

DoReplaceBlocks: true

IsOTGPlus: false


#######################################################################
# +-----------------------------------------------------------------+ #
# |                              Blocks                             | #
# +-----------------------------------------------------------------+ #
#######################################################################

Block(-7,29,4,LEAVES:3)
Block(-6,14,-2,LEAVES:3)
Block(-6,14,-1,LEAVES:3)
Block(-6,14,0,LEAVES:3)
Block(-6,15,-1,LEAVES:3)
Block(-6,29,3,LEAVES:3)
Block(-6,29,4,LEAVES:3)
Block(-6,29,5,LEAVES:3)
Block(-6,30,2,LEAVES:3)
Block(-6,30,4,LEAVES:3)
Block(-5,11,-3,VINE:8)
Block(-5,12,-3,VINE:8)
Block(-5,13,-3,VINE:8)
Block(-5,13,-2,LEAVES:3)
Block(-5,13,-1,LEAVES:3)
Block(-5,13,0,LEAVES:3)
Block(-5,14,-3,LEAVES:3)
Block(-5,14,-2,LEAVES:3)
Block(-5,14,-1,LEAVES:3)
Block(-5,14,0,LEAVES:3)
Block(-5,14,1,LEAVES:3)
Block(-5,15,-3,VINE:8)
Block(-5,15,-2,LEAVES:3)
Block(-5,15,-1,LEAVES:3)
Block(-5,15,0,LEAVES:3)
Block(-5,21,-3,VINE:8)
Block(-5,21,1,VINE:8)
Block(-5,22,-3,VINE:8)
Block(-5,22,1,VINE:8)
Block(-5,23,-3,VINE:8)
Block(-5,23,1,VINE:8)
Block(-5,24,-3,VINE:8)
Block(-5,24,1,VINE:8)
Block(-5,25,-3,VINE:8)
Block(-5,25,1,VINE:8)
Block(-5,26,-3,VINE:8)
Block(-5,26,1,VINE:8)
Block(-5,27,-3,VINE:8)
Block(-5,27,1,VINE:8)
Block(-5,28,-3,VINE:8)
Block(-5,28,1,VINE:8)
Block(-5,28,3,LEAVES:3)
Block(-5,28,4,LEAVES:3)
Block(-5,28,5,LEAVES:3)
Block(-5,29,-3,VINE:8)
Block(-5,29,1,VINE:8)
Block(-5,29,2,LEAVES:3)
Block(-5,29,3,LEAVES:3)
Block(-5,29,4,LEAVES:3)
Block(-5,29,5,LEAVES:3)
Block(-5,29,6,LEAVES:3)
Block(-5,30,-4,LEAVES:3)
Block(-5,30,-3,VINE:9)
Block(-5,30,-1,LEAVES:3)
Block(-5,30,1,LEAVES:3)
Block(-5,30,2,LEAVES:3)
Block(-5,30,3,LEAVES:3)
Block(-5,30,4,LEAVES:3)
Block(-5,30,5,LEAVES:3)
Block(-5,31,-4,VINE:8)
Block(-5,31,-3,VINE:9)
Block(-5,31,-2,LEAVES:3)
Block(-5,31,-1,LEAVES:3)
Block(-5,31,0,LEAVES:3)
Block(-5,31,2,LEAVES:3)
Block(-5,31,4,LEAVES:3)
Block(-5,32,-1,LEAVES:3)
Block(-4,9,-2,VINE:1)
Block(-4,10,-4,VINE:8)
Block(-4,10,-2,VINE:1)
Block(-4,11,-4,VINE:8)
Block(-4,11,-2,VINE:1)
Block(-4,12,-4,VINE:8)
Block(-4,12,-2,VINE:1)
Block(-4,12,-1,LEAVES:3)
Block(-4,12,0,LEAVES:3)
Block(-4,13,-4,VINE:8)
Block(-4,13,-3,LEAVES:3)
Block(-4,13,-2,LEAVES:3)
Block(-4,13,-1,LEAVES:3)
Block(-4,13,0,LEAVES:3)
Block(-4,13,1,LEAVES:3)
Block(-4,14,-4,LEAVES:3)
Block(-4,14,-3,LEAVES:3)
Block(-4,14,-2,LEAVES:3)
Block(-4,14,-1,LEAVES:3)
Block(-4,14,0,LEAVES:3)
Block(-4,14,1,LEAVES:3)
Block(-4,14,2,LEAVES:3)
Block(-4,15,-3,LEAVES:3)
Block(-4,15,-2,LEAVES:3)
Block(-4,15,-1,LEAVES:3)
Block(-4,15,0,LEAVES:3)
Block(-4,15,1,LEAVES:3)
Block(-4,16,-1,LEAVES:3)
Block(-4,20,2,VINE:1)
Block(-4,21,2,VINE:1)
Block(-4,22,0,VINE:8)
Block(-4,22,2,VINE:1)
Block(-4,23,0,VINE:8)
Block(-4,23,2,VINE:1)
Block(-4,24,-5,VINE:8)
Block(-4,24,0,VINE:8)
Block(-4,24,2,VINE:1)
Block(-4,25,-5,VINE:8)
Block(-4,25,0,VINE:8)
Block(-4,25,2,VINE:1)
Block(-4,26,-5,VINE:8)
Block(-4,26,0,VINE:8)
Block(-4,26,2,VINE:1)
Block(-4,27,-5,VINE:8)
Block(-4,27,0,VINE:8)
Block(-4,27,2,VINE:1)
Block(-4,27,3,LEAVES:3)
Block(-4,27,4,LEAVES:3)
Block(-4,27,5,LEAVES:3)
Block(-4,28,-5,VINE:8)
Block(-4,28,0,VINE:8)
Block(-4,28,2,LEAVES:3)
Block(-4,28,3,LEAVES:3)
Block(-4,28,4,LEAVES:3)
Block(-4,28,5,LEAVES:3)
Block(-4,28,6,LEAVES:3)
Block(-4,29,-7,LEAVES:3)
Block(-4,29,-6,LEAVES:3)
Block(-4,29,-5,LEAVES:3)
Block(-4,29,0,VINE:8)
Block(-4,29,1,LEAVES:3)
Block(-4,29,2,LEAVES:3)
Block(-4,29,3,LEAVES:3)
Block(-4,29,4,LEAVES:3)
Block(-4,29,5,LEAVES:3)
Block(-4,29,6,LEAVES:3)
Block(-4,29,7,LEAVES:3)
Block(-4,30,-5,LEAVES:3)
Block(-4,30,-4,LEAVES:3)
Block(-4,30,-3,LEAVES:3)
Block(-4,30,-2,LEAVES:3)
Block(-4,30,-1,LEAVES:3)
Block(-4,30,0,LEAVES:3)
Block(-4,30,1,LEAVES:3)
Block(-4,30,2,LEAVES:3)
Block(-4,30,3,LEAVES:3)
Block(-4,30,4,LEAVES:3)
Block(-4,30,5,LEAVES:3)
Block(-4,30,6,LEAVES:3)
Block(-4,31,-6,VINE:8)
Block(-4,31,-5,VINE:9)
Block(-4,31,-4,LEAVES:3)
Block(-4,31,-3,LEAVES:3)
Block(-4,31,-2,LEAVES:3)
Block(-4,31,-1,LEAVES:3)
Block(-4,31,0,LEAVES:3)
Block(-4,31,1,LEAVES:3)
Block(-4,31,2,LEAVES:3)
Block(-4,31,3,LEAVES:3)
Block(-4,31,4,LEAVES:3)
Block(-4,32,-2,LEAVES:3)
Block(-4,32,-1,LEAVES:3)
Block(-4,32,0,LEAVES:3)
Block(-4,33,-2,VINE:8)
Block(-4,33,-1,VINE:8)
Block(-3,6,0,VINE:8)
Block(-3,7,0,VINE:8)
Block(-3,8,0,VINE:8)
Block(-3,9,0,VINE:8)
Block(-3,10,0,VINE:8)
Block(-3,11,0,VINE:8)
Block(-3,12,-2,LEAVES:3)
Block(-3,12,-1,LEAVES:3)
Block(-3,12,0,VINE:8)
Block(-3,13,-4,LEAVES:3)
Block(-3,13,-3,LEAVES:3)
Block(-3,13,-2,LEAVES:3)
Block(-3,13,-1,LEAVES:3)
Block(-3,13,0,LEAVES:3)
Block(-3,13,1,LEAVES:3)
Block(-3,14,-5,LEAVES:3)
Block(-3,14,-4,LEAVES:3)
Block(-3,14,-3,LEAVES:3)
Block(-3,14,-2,LEAVES:3)
Block(-3,14,-1,LOG:15)
Block(-3,14,0,LEAVES:3)
Block(-3,14,1,LEAVES:3)
Block(-3,14,2,LEAVES:3)
Block(-3,14,3,LEAVES:3)
Block(-3,15,-4,LEAVES:3)
Block(-3,15,-3,LEAVES:3)
Block(-3,15,-2,LEAVES:3)
Block(-3,15,-1,LEAVES:3)
Block(-3,15,0,LEAVES:3)
Block(-3,15,1,LEAVES:3)
Block(-3,16,-3,VINE:8)
Block(-3,16,-2,LEAVES:3)
Block(-3,16,-1,LEAVES:3)
Block(-3,16,0,LEAVES:3)
Block(-3,19,2,VINE:1)
Block(-3,20,2,VINE:1)
Block(-3,21,2,VINE:1)
Block(-3,22,2,VINE:1)
Block(-3,23,2,VINE:1)
Block(-3,24,2,VINE:1)
Block(-3,25,2,VINE:1)
Block(-3,26,2,VINE:1)
Block(-3,27,2,VINE:1)
Block(-3,27,3,LEAVES:3)
Block(-3,27,4,LEAVES:3)
Block(-3,27,6,LEAVES:3)
Block(-3,28,-7,LEAVES:3)
Block(-3,28,-6,LEAVES:3)
Block(-3,28,-5,LEAVES:3)
Block(-3,28,1,LEAVES:3)
Block(-3,28,2,LEAVES:3)
Block(-3,28,3,LEAVES:3)
Block(-3,28,4,LEAVES:3)
Block(-3,28,5,LEAVES:3)
Block(-3,28,6,LEAVES:3)
Block(-3,28,7,LEAVES:3)
Block(-3,29,-8,LEAVES:3)
Block(-3,29,-7,LEAVES:3)
Block(-3,29,-6,LEAVES:3)
Block(-3,29,-5,LEAVES:3)
Block(-3,29,-4,LEAVES:3)
Block(-3,29,-3,LEAVES:3)
Block(-3,29,0,LEAVES:3)
Block(-3,29,1,LEAVES:3)
Block(-3,29,2,LEAVES:3)
Block(-3,29,3,LEAVES:3)
Block(-3,29,4,LOG:15)
Block(-3,29,5,LEAVES:3)
Block(-3,29,6,LEAVES:3)
Block(-3,29,7,LEAVES:3)
Block(-3,29,8,LEAVES:3)
Block(-3,30,-7,LEAVES:3)
Block(-3,30,-6,LEAVES:3)
Block(-3,30,-5,LEAVES:3)
Block(-3,30,-4,LEAVES:3)
Block(-3,30,-3,LEAVES:3)
Block(-3,30,-2,LEAVES:3)
Block(-3,30,-1,LEAVES:3)
Block(-3,30,0,LEAVES:3)
Block(-3,30,1,LEAVES:3)
Block(-3,30,2,LEAVES:3)
Block(-3,30,3,LEAVES:3)
Block(-3,30,4,LEAVES:3)
Block(-3,30,5,LEAVES:3)
Block(-3,30,6,LEAVES:3)
Block(-3,31,-6,LEAVES:3)
Block(-3,31,-5,LEAVES:3)
Block(-3,31,-4,LEAVES:3)
Block(-3,31,-3,LEAVES:3)
Block(-3,31,-2,LEAVES:3)
Block(-3,31,-1,LEAVES:3)
Block(-3,31,0,LEAVES:3)
Block(-3,31,1,LEAVES:3)
Block(-3,31,2,LEAVES:3)
Block(-3,31,3,LEAVES:3)
Block(-3,31,4,LEAVES:3)
Block(-3,31,6,LEAVES:3)
Block(-3,32,-3,LEAVES:3)
Block(-3,32,-2,LEAVES:3)
Block(-3,32,-1,LEAVES:3)
Block(-3,32,0,LEAVES:3)
Block(-3,32,1,LEAVES:3)
Block(-3,32,2,LEAVES:3)
Block(-3,33,-2,LEAVES:3)
Block(-3,33,-1,LEAVES:3)
Block(-3,33,0,VINE:4)
Block(-2,0,-1,LOG:3)
Block(-2,0,0,LOG:3)
Block(-2,1,-1,LOG:3)
Block(-2,1,0,LOG:3)
Block(-2,2,-1,LOG:3)
Block(-2,2,0,LOG:3)
Block(-2,3,-1,LOG:3)
Block(-2,3,0,LOG:3)
Block(-2,4,-1,LOG:3)
Block(-2,4,0,LOG:3)
Block(-2,5,-1,LOG:3)
Block(-2,5,0,LOG:3)
Block(-2,6,-2,VINE:1)
Block(-2,6,-1,LOG:3)
Block(-2,6,0,LOG:3)
Block(-2,7,-2,VINE:1)
Block(-2,7,-1,LOG:3)
Block(-2,7,0,LOG:3)
Block(-2,8,-2,VINE:1)
Block(-2,8,-1,LOG:3)
Block(-2,8,0,LOG:3)
Block(-2,9,-2,VINE:1)
Block(-2,9,-1,LOG:3)
Block(-2,9,0,LOG:3)
Block(-2,10,-2,VINE:1)
Block(-2,10,-1,LOG:3)
Block(-2,10,0,LOG:3)
Block(-2,11,-2,VINE:1)
Block(-2,11,-1,LOG:3)
Block(-2,11,0,LOG:3)
Block(-2,12,-2,VINE:1)
Block(-2,12,-1,LOG:3)
Block(-2,12,0,LOG:3)
Block(-2,13,-3,LEAVES:3)
Block(-2,13,-2,LEAVES:3)
Block(-2,13,-1,LOG:3)
Block(-2,13,0,LOG:3)
Block(-2,13,1,LEAVES:3)
Block(-2,14,-4,LEAVES:3)
Block(-2,14,-3,LEAVES:3)
Block(-2,14,-2,LEAVES:3)
Block(-2,14,-1,LOG:3)
Block(-2,14,0,LOG:3)
Block(-2,14,1,LEAVES:3)
Block(-2,14,2,LEAVES:3)
Block(-2,15,-4,VINE:2)
Block(-2,15,-3,LEAVES:3)
Block(-2,15,-2,LEAVES:3)
Block(-2,15,-1,LOG:3)
Block(-2,15,0,LOG:3)
Block(-2,15,1,LEAVES:3)
Block(-2,16,-3,LEAVES:3)
Block(-2,16,-2,LEAVES:3)
Block(-2,16,-1,LOG:3)
Block(-2,16,0,LOG:3)
Block(-2,17,-3,VINE:8)
Block(-2,17,-2,LEAVES:3)
Block(-2,17,-1,LOG:3)
Block(-2,17,0,LOG:3)
Block(-2,18,-2,VINE:9)
Block(-2,18,-1,LOG:3)
Block(-2,18,0,LOG:3)
Block(-2,19,-2,VINE:9)
Block(-2,19,-1,LOG:3)
Block(-2,19,0,LOG:3)
Block(-2,20,-2,VINE:9)
Block(-2,20,-1,LOG:3)
Block(-2,20,0,LOG:3)
Block(-2,21,-3,VINE:8)
Block(-2,21,-2,VINE:9)
Block(-2,21,-1,LOG:3)
Block(-2,21,0,LOG:3)
Block(-2,22,-3,VINE:8)
Block(-2,22,-2,VINE:9)
Block(-2,22,-1,LOG:3)
Block(-2,22,0,LOG:3)
Block(-2,23,-3,VINE:8)
Block(-2,23,-2,VINE:9)
Block(-2,23,-1,LOG:3)
Block(-2,23,0,LOG:3)
Block(-2,24,-3,VINE:8)
Block(-2,24,-2,VINE:8)
Block(-2,24,-1,LOG:3)
Block(-2,24,0,LOG:3)
Block(-2,25,-3,VINE:8)
Block(-2,25,-2,VINE:8)
Block(-2,25,-1,LOG:3)
Block(-2,25,0,LOG:3)
Block(-2,26,-3,VINE:8)
Block(-2,26,-2,VINE:8)
Block(-2,26,-1,LOG:3)
Block(-2,26,0,LOG:3)
Block(-2,27,-3,VINE:8)
Block(-2,27,-2,VINE:8)
Block(-2,27,-1,LOG:3)
Block(-2,27,0,LOG:3)
Block(-2,27,4,LEAVES:3)
Block(-2,28,-8,LEAVES:3)
Block(-2,28,-7,LEAVES:3)
Block(-2,28,-6,LEAVES:3)
Block(-2,28,-5,LEAVES:3)
Block(-2,28,-4,LEAVES:3)
Block(-2,28,-3,VINE:8)
Block(-2,28,-2,VINE:8)
Block(-2,28,-1,LOG:3)
Block(-2,28,0,LOG:3)
Block(-2,28,2,LEAVES:3)
Block(-2,28,3,LEAVES:3)
Block(-2,28,4,LEAVES:3)
Block(-2,28,5,LEAVES:3)
Block(-2,28,6,LEAVES:3)
Block(-2,29,-9,LEAVES:3)
Block(-2,29,-8,LEAVES:3)
Block(-2,29,-7,LEAVES:3)
Block(-2,29,-6,LEAVES:3)
Block(-2,29,-5,LEAVES:3)
Block(-2,29,-4,LEAVES:3)
Block(-2,29,-3,LEAVES:3)
Block(-2,29,-2,LEAVES:3)
Block(-2,29,-1,LOG:3)
Block(-2,29,0,LOG:3)
Block(-2,29,1,LEAVES:3)
Block(-2,29,2,LEAVES:3)
Block(-2,29,3,LOG:11)
Block(-2,29,4,LEAVES:3)
Block(-2,29,5,LEAVES:3)
Block(-2,29,6,LEAVES:3)
Block(-2,29,7,LEAVES:3)
Block(-2,30,-8,LEAVES:3)
Block(-2,30,-7,LEAVES:3)
Block(-2,30,-6,LEAVES:3)
Block(-2,30,-5,LEAVES:3)
Block(-2,30,-4,LEAVES:3)
Block(-2,30,-3,LEAVES:3)
Block(-2,30,-2,LEAVES:3)
Block(-2,30,-1,LOG:3)
Block(-2,30,0,LOG:3)
Block(-2,30,1,LEAVES:3)
Block(-2,30,2,LOG:11)
Block(-2,30,3,LEAVES:3)
Block(-2,30,4,LEAVES:3)
Block(-2,30,5,LEAVES:3)
Block(-2,30,6,LEAVES:3)
Block(-2,31,-7,LEAVES:3)
Block(-2,31,-6,LEAVES:3)
Block(-2,31,-5,LEAVES:3)
Block(-2,31,-4,LEAVES:3)
Block(-2,31,-3,LEAVES:3)
Block(-2,31,-2,LEAVES:3)
Block(-2,31,-1,LOG:15)
Block(-2,31,0,LOG:15)
Block(-2,31,1,LEAVES:3)
Block(-2,31,2,LEAVES:3)
Block(-2,31,3,LEAVES:3)
Block(-2,31,4,LEAVES:3)
Block(-2,32,-5,LEAVES:3)
Block(-2,32,-4,LEAVES:3)
Block(-2,32,-3,LEAVES:3)
Block(-2,32,-2,LEAVES:3)
Block(-2,32,-1,LEAVES:3)
Block(-2,32,0,LEAVES:3)
Block(-2,32,1,LEAVES:3)
Block(-2,32,2,LEAVES:3)
Block(-2,32,3,LEAVES:3)
Block(-2,32,4,LEAVES:3)
Block(-2,33,-2,LEAVES:3)
Block(-2,33,-1,LEAVES:3)
Block(-2,33,0,VINE:4)
Block(-2,33,1,VINE:8)
Block(-1,0,-2,LOG:3)
Block(-1,0,-1,LOG:3)
Block(-1,0,0,LOG:3)
Block(-1,0,1,LOG:3)
Block(-1,1,-2,LOG:3)
Block(-1,1,-1,LOG:3)
Block(-1,1,0,LOG:3)
Block(-1,1,1,LOG:3)
Block(-1,2,-2,LOG:3)
Block(-1,2,-1,LOG:3)
Block(-1,2,0,LOG:3)
Block(-1,2,1,LOG:3)
Block(-1,3,-2,LOG:3)
Block(-1,3,-1,LOG:3)
Block(-1,3,0,LOG:3)
Block(-1,3,1,LOG:3)
Block(-1,4,-2,LOG:3)
Block(-1,4,-1,LOG:3)
Block(-1,4,0,LOG:3)
Block(-1,4,1,LOG:3)
Block(-1,5,-2,LOG:3)
Block(-1,5,-1,LOG:3)
Block(-1,5,0,LOG:3)
Block(-1,5,1,LOG:3)
Block(-1,6,-2,LOG:3)
Block(-1,6,-1,LOG:3)
Block(-1,6,0,LOG:3)
Block(-1,6,1,LOG:3)
Block(-1,7,-2,LOG:3)
Block(-1,7,-1,LOG:3)
Block(-1,7,0,LOG:3)
Block(-1,7,1,LOG:3)
Block(-1,8,-2,LOG:3)
Block(-1,8,-1,LOG:3)
Block(-1,8,0,LOG:3)
Block(-1,8,1,LOG:3)
Block(-1,9,-2,LOG:3)
Block(-1,9,-1,LOG:3)
Block(-1,9,0,LOG:3)
Block(-1,9,1,LOG:3)
Block(-1,10,-2,LOG:3)
Block(-1,10,-1,LOG:3)
Block(-1,10,0,LOG:3)
Block(-1,10,1,LOG:3)
Block(-1,11,-2,LOG:3)
Block(-1,11,-1,LOG:3)
Block(-1,11,0,LOG:3)
Block(-1,11,1,LOG:3)
Block(-1,12,-5,VINE:1)
Block(-1,12,-2,LOG:3)
Block(-1,12,-1,LOG:3)
Block(-1,12,0,LOG:3)
Block(-1,12,1,LOG:3)
Block(-1,13,-5,VINE:1)
Block(-1,13,-2,LOG:3)
Block(-1,13,-1,LOG:3)
Block(-1,13,0,LOG:3)
Block(-1,13,1,LOG:3)
Block(-1,14,-5,VINE:1)
Block(-1,14,-3,LEAVES:3)
Block(-1,14,-2,LOG:3)
Block(-1,14,-1,LOG:3)
Block(-1,14,0,LOG:3)
Block(-1,14,1,LOG:3)
Block(-1,15,-5,VINE:1)
Block(-1,15,-3,LEAVES:3)
Block(-1,15,-2,LOG:3)
Block(-1,15,-1,LOG:3)
Block(-1,15,0,LOG:3)
Block(-1,15,1,LOG:3)
Block(-1,16,-5,VINE:1)
Block(-1,16,-4,LEAVES:3)
Block(-1,16,-3,LEAVES:3)
Block(-1,16,-2,LOG:3)
Block(-1,16,-1,LOG:3)
Block(-1,16,0,LOG:3)
Block(-1,16,1,LOG:3)
Block(-1,17,-4,VINE:8)
Block(-1,17,-3,LEAVES:3)
Block(-1,17,-2,LOG:3)
Block(-1,17,-1,LOG:3)
Block(-1,17,0,LOG:3)
Block(-1,17,1,LOG:3)
Block(-1,18,-3,VINE:1)
Block(-1,18,-2,LOG:3)
Block(-1,18,-1,LOG:3)
Block(-1,18,0,LOG:3)
Block(-1,18,1,LOG:3)
Block(-1,19,-3,VINE:1)
Block(-1,19,-2,LOG:3)
Block(-1,19,-1,LOG:3)
Block(-1,19,0,LOG:3)
Block(-1,19,1,LOG:3)
Block(-1,20,-3,VINE:1)
Block(-1,20,-2,LOG:3)
Block(-1,20,-1,LOG:3)
Block(-1,20,0,LOG:3)
Block(-1,20,1,LOG:3)
Block(-1,21,-3,VINE:1)
Block(-1,21,-2,LOG:3)
Block(-1,21,-1,LOG:3)
Block(-1,21,0,LOG:3)
Block(-1,21,1,LOG:3)
Block(-1,22,-3,VINE:1)
Block(-1,22,-2,LOG:3)
Block(-1,22,-1,LOG:3)
Block(-1,22,0,LOG:3)
Block(-1,22,1,LOG:3)
Block(-1,23,-3,VINE:1)
Block(-1,23,-2,LOG:3)
Block(-1,23,-1,LOG:3)
Block(-1,23,0,LOG:3)
Block(-1,23,1,LOG:3)
Block(-1,24,-3,VINE:1)
Block(-1,24,-2,LOG:3)
Block(-1,24,-1,LOG:3)
Block(-1,24,0,LOG:3)
Block(-1,24,1,LOG:3)
Block(-1,25,-3,VINE:1)
Block(-1,25,-2,LOG:3)
Block(-1,25,-1,LOG:3)
Block(-1,25,0,LOG:3)
Block(-1,25,1,LOG:3)
Block(-1,26,-3,VINE:1)
Block(-1,26,-2,LOG:3)
Block(-1,26,-1,LOG:3)
Block(-1,26,0,LOG:3)
Block(-1,26,1,LOG:3)
Block(-1,27,-8,LEAVES:3)
Block(-1,27,-6,LEAVES:3)
Block(-1,27,-5,LEAVES:3)
Block(-1,27,-4,LEAVES:3)
Block(-1,27,-3,VINE:1)
Block(-1,27,-2,LOG:3)
Block(-1,27,-1,LOG:3)
Block(-1,27,0,LOG:3)
Block(-1,27,1,LOG:3)
Block(-1,27,4,LEAVES:3)
Block(-1,28,-9,LEAVES:3)
Block(-1,28,-8,LEAVES:3)
Block(-1,28,-7,LEAVES:3)
Block(-1,28,-6,LEAVES:3)
Block(-1,28,-5,LEAVES:3)
Block(-1,28,-4,LEAVES:3)
Block(-1,28,-3,LEAVES:3)
Block(-1,28,-2,LOG:3)
Block(-1,28,-1,LOG:3)
Block(-1,28,0,LOG:3)
Block(-1,28,1,LOG:3)
Block(-1,28,2,LEAVES:3)
Block(-1,28,3,LEAVES:3)
Block(-1,28,4,LEAVES:3)
Block(-1,28,5,LEAVES:3)
Block(-1,29,-9,LEAVES:3)
Block(-1,29,-8,LEAVES:3)
Block(-1,29,-7,LEAVES:3)
Block(-1,29,-6,LOG:15)
Block(-1,29,-5,LOG:11)
Block(-1,29,-4,LEAVES:3)
Block(-1,29,-3,LEAVES:3)
Block(-1,29,-2,LOG:3)
Block(-1,29,-1,LOG:3)
Block(-1,29,0,LOG:3)
Block(-1,29,1,LOG:3)
Block(-1,29,2,LEAVES:3)
Block(-1,29,3,LEAVES:3)
Block(-1,29,4,LEAVES:3)
Block(-1,29,5,LEAVES:3)
Block(-1,29,6,LEAVES:3)
Block(-1,30,-9,LEAVES:3)
Block(-1,30,-8,LEAVES:3)
Block(-1,30,-7,LEAVES:3)
Block(-1,30,-6,LEAVES:3)
Block(-1,30,-5,LEAVES:3)
Block(-1,30,-4,LOG:11)
Block(-1,30,-3,LOG:11)
Block(-1,30,-2,LOG:3)
Block(-1,30,-1,LOG:3)
Block(-1,30,0,LOG:3)
Block(-1,30,1,LOG:3)
Block(-1,30,2,LOG:11)
Block(-1,30,3,LEAVES:3)
Block(-1,30,4,LEAVES:3)
Block(-1,30,5,LEAVES:3)
Block(-1,31,-7,LEAVES:3)
Block(-1,31,-6,LEAVES:3)
Block(-1,31,-5,LEAVES:3)
Block(-1,31,-4,LEAVES:3)
Block(-1,31,-3,LEAVES:3)
Block(-1,31,-2,LOG:11)
Block(-1,31,-1,LOG:11)
Block(-1,31,0,LOG:11)
Block(-1,31,1,LOG:11)
Block(-1,31,2,LEAVES:3)
Block(-1,31,3,LEAVES:3)
Block(-1,31,4,LEAVES:3)
Block(-1,32,-5,LEAVES:3)
Block(-1,32,-4,LEAVES:3)
Block(-1,32,-3,LEAVES:3)
Block(-1,32,-2,LEAVES:3)
Block(-1,32,-1,LEAVES:3)
Block(-1,32,0,LEAVES:3)
Block(-1,32,1,LEAVES:3)
Block(-1,32,2,LEAVES:3)
Block(-1,32,3,LEAVES:3)
Block(-1,33,-3,LEAVES:3)
Block(-1,33,-2,LEAVES:3)
Block(-1,33,-1,LEAVES:3)
Block(-1,33,0,LEAVES:3)
Block(-1,33,1,LEAVES:3)
Block(-1,33,3,LEAVES:3)
Block(0,0,-2,LOG:3)
Block(0,0,-1,LOG:3)
Block(0,0,0,LOG:3)
Block(0,0,1,LOG:3)
Block(0,1,-2,LOG:3)
Block(0,1,-1,LOG:3)
Block(0,1,0,LOG:3)
Block(0,1,1,LOG:3)
Block(0,2,-2,LOG:3)
Block(0,2,-1,LOG:3)
Block(0,2,0,LOG:3)
Block(0,2,1,LOG:3)
Block(0,3,-2,LOG:3)
Block(0,3,-1,LOG:3)
Block(0,3,0,LOG:3)
Block(0,3,1,LOG:3)
Block(0,4,-2,LOG:3)
Block(0,4,-1,LOG:3)
Block(0,4,0,LOG:3)
Block(0,4,1,LOG:3)
Block(0,5,-2,LOG:3)
Block(0,5,-1,LOG:3)
Block(0,5,0,LOG:3)
Block(0,5,1,LOG:3)
Block(0,6,-3,VINE:1)
Block(0,6,-2,LOG:3)
Block(0,6,-1,LOG:3)
Block(0,6,0,LOG:3)
Block(0,6,1,LOG:3)
Block(0,7,-3,VINE:1)
Block(0,7,-2,LOG:3)
Block(0,7,-1,LOG:3)
Block(0,7,0,LOG:3)
Block(0,7,1,LOG:3)
Block(0,8,-3,VINE:1)
Block(0,8,-2,LOG:3)
Block(0,8,-1,LOG:3)
Block(0,8,0,LOG:3)
Block(0,8,1,LOG:3)
Block(0,9,-3,VINE:1)
Block(0,9,-2,LOG:3)
Block(0,9,-1,LOG:3)
Block(0,9,0,LOG:3)
Block(0,9,1,LOG:3)
Block(0,9,2,VINE:4)
Block(0,10,-3,VINE:1)
Block(0,10,-2,LOG:3)
Block(0,10,-1,LOG:3)
Block(0,10,0,LOG:3)
Block(0,10,1,LOG:3)
Block(0,10,2,VINE:4)
Block(0,11,-3,VINE:1)
Block(0,11,-2,LOG:3)
Block(0,11,-1,LOG:3)
Block(0,11,0,LOG:3)
Block(0,11,1,LOG:3)
Block(0,11,2,VINE:4)
Block(0,12,-3,VINE:1)
Block(0,12,-2,LOG:3)
Block(0,12,-1,LOG:3)
Block(0,12,0,LOG:3)
Block(0,12,1,LOG:3)
Block(0,12,2,VINE:4)
Block(0,13,-3,VINE:1)
Block(0,13,-2,LOG:3)
Block(0,13,-1,LOG:3)
Block(0,13,0,LOG:3)
Block(0,13,1,LOG:3)
Block(0,13,2,VINE:4)
Block(0,14,-3,VINE:1)
Block(0,14,-2,LOG:3)
Block(0,14,-1,LOG:3)
Block(0,14,0,LOG:3)
Block(0,14,1,LOG:3)
Block(0,14,2,VINE:4)
Block(0,15,-4,LEAVES:3)
Block(0,15,-3,LEAVES:3)
Block(0,15,-2,LOG:3)
Block(0,15,-1,LOG:3)
Block(0,15,0,LOG:3)
Block(0,15,1,LOG:3)
Block(0,15,2,VINE:4)
Block(0,16,-5,LEAVES:3)
Block(0,16,-4,LEAVES:3)
Block(0,16,-3,LEAVES:3)
Block(0,16,-2,LOG:3)
Block(0,16,-1,LOG:3)
Block(0,16,0,LOG:3)
Block(0,16,1,LOG:3)
Block(0,16,2,VINE:4)
Block(0,17,-4,LEAVES:3)
Block(0,17,-3,LEAVES:3)
Block(0,17,-2,LOG:3)
Block(0,17,-1,LOG:3)
Block(0,17,0,LOG:3)
Block(0,17,1,LOG:3)
Block(0,17,2,VINE:4)
Block(0,18,-3,LEAVES:3)
Block(0,18,-2,LOG:3)
Block(0,18,-1,LOG:3)
Block(0,18,0,LOG:3)
Block(0,18,1,LOG:3)
Block(0,18,2,VINE:4)
Block(0,19,-3,VINE:1)
Block(0,19,-2,LOG:3)
Block(0,19,-1,LOG:3)
Block(0,19,0,LOG:3)
Block(0,19,1,LOG:3)
Block(0,19,2,VINE:4)
Block(0,20,-3,VINE:1)
Block(0,20,-2,LOG:3)
Block(0,20,-1,LOG:3)
Block(0,20,0,LOG:3)
Block(0,20,1,LOG:3)
Block(0,20,2,VINE:4)
Block(0,21,-3,VINE:1)
Block(0,21,-2,LOG:3)
Block(0,21,-1,LOG:3)
Block(0,21,0,LOG:3)
Block(0,21,1,LOG:3)
Block(0,21,2,VINE:4)
Block(0,22,-3,VINE:1)
Block(0,22,-2,LOG:3)
Block(0,22,-1,LOG:3)
Block(0,22,0,LOG:3)
Block(0,22,1,LOG:3)
Block(0,22,2,VINE:4)
Block(0,23,-3,VINE:1)
Block(0,23,-2,LOG:3)
Block(0,23,-1,LOG:3)
Block(0,23,0,LOG:3)
Block(0,23,1,LOG:3)
Block(0,23,2,VINE:4)
Block(0,24,-3,VINE:1)
Block(0,24,-2,LOG:3)
Block(0,24,-1,LOG:3)
Block(0,24,0,LOG:3)
Block(0,24,1,LOG:3)
Block(0,24,2,VINE:4)
Block(0,25,-3,VINE:1)
Block(0,25,-2,LOG:3)
Block(0,25,-1,LOG:3)
Block(0,25,0,LOG:3)
Block(0,25,1,LOG:3)
Block(0,25,2,VINE:4)
Block(0,26,-3,VINE:1)
Block(0,26,-2,LOG:3)
Block(0,26,-1,LOG:3)
Block(0,26,0,LOG:3)
Block(0,26,1,LOG:3)
Block(0,27,-7,LEAVES:3)
Block(0,27,-3,VINE:1)
Block(0,27,-2,LOG:3)
Block(0,27,-1,LOG:3)
Block(0,27,0,LOG:3)
Block(0,27,1,LOG:3)
Block(0,28,-8,LEAVES:3)
Block(0,28,-7,LEAVES:3)
Block(0,28,-6,LEAVES:3)
Block(0,28,-5,LEAVES:3)
Block(0,28,-4,LEAVES:3)
Block(0,28,-3,LEAVES:3)
Block(0,28,-2,LOG:3)
Block(0,28,-1,LOG:3)
Block(0,28,0,LOG:3)
Block(0,28,1,LOG:3)
Block(0,28,2,LEAVES:3)
Block(0,29,-9,LEAVES:3)
Block(0,29,-8,LEAVES:3)
Block(0,29,-7,LEAVES:3)
Block(0,29,-6,LEAVES:3)
Block(0,29,-5,LEAVES:3)
Block(0,29,-4,LEAVES:3)
Block(0,29,-3,LEAVES:3)
Block(0,29,-2,LOG:3)
Block(0,29,-1,LOG:3)
Block(0,29,0,LOG:3)
Block(0,29,1,LOG:3)
Block(0,29,2,LEAVES:3)
Block(0,29,3,LEAVES:3)
Block(0,29,4,LEAVES:3)
Block(0,29,5,LEAVES:3)
Block(0,30,-8,LEAVES:3)
Block(0,30,-7,LEAVES:3)
Block(0,30,-6,LEAVES:3)
Block(0,30,-5,LEAVES:3)
Block(0,30,-4,LEAVES:3)
Block(0,30,-3,LEAVES:3)
Block(0,30,-2,LOG:3)
Block(0,30,-1,LOG:3)
Block(0,30,0,LOG:3)
Block(0,30,1,LOG:3)
Block(0,30,2,LEAVES:3)
Block(0,30,3,LEAVES:3)
Block(0,30,4,LEAVES:3)
Block(0,31,-7,LEAVES:3)
Block(0,31,-6,LEAVES:3)
Block(0,31,-5,LEAVES:3)
Block(0,31,-4,LEAVES:3)
Block(0,31,-3,LEAVES:3)
Block(0,31,-2,LOG:15)
Block(0,31,-1,LOG:7)
Block(0,31,0,LOG:15)
Block(0,31,1,LOG:15)
Block(0,31,2,LEAVES:3)
Block(0,31,3,LEAVES:3)
Block(0,31,4,LEAVES:3)
Block(0,32,-4,LEAVES:3)
Block(0,32,-3,LEAVES:3)
Block(0,32,-2,LEAVES:3)
Block(0,32,-1,LEAVES:3)
Block(0,32,0,LEAVES:3)
Block(0,32,1,LEAVES:3)
Block(0,32,2,LEAVES:3)
Block(0,32,3,LEAVES:3)
Block(0,33,-3,LEAVES:3)
Block(0,33,-2,LEAVES:3)
Block(0,33,-1,LEAVES:3)
Block(0,33,0,LEAVES:3)
Block(0,33,1,LEAVES:3)
Block(0,33,2,LEAVES:3)
Block(1,0,-1,LOG:3)
Block(1,0,0,LOG:3)
Block(1,1,-1,LOG:3)
Block(1,1,0,LOG:3)
Block(1,2,-1,LOG:3)
Block(1,2,0,LOG:3)
Block(1,3,-1,LOG:3)
Block(1,3,0,LOG:3)
Block(1,4,-1,LOG:3)
Block(1,4,0,LOG:3)
Block(1,5,-1,LOG:3)
Block(1,5,0,LOG:3)
Block(1,6,-2,VINE:1)
Block(1,6,-1,LOG:3)
Block(1,6,0,LOG:3)
Block(1,6,1,VINE:4)
Block(1,7,-2,VINE:1)
Block(1,7,-1,LOG:3)
Block(1,7,0,LOG:3)
Block(1,7,1,VINE:4)
Block(1,8,-2,VINE:1)
Block(1,8,-1,LOG:3)
Block(1,8,0,LOG:3)
Block(1,8,1,VINE:4)
Block(1,9,-2,VINE:1)
Block(1,9,-1,LOG:3)
Block(1,9,0,LOG:3)
Block(1,9,1,VINE:4)
Block(1,10,-2,VINE:1)
Block(1,10,-1,LOG:3)
Block(1,10,0,LOG:3)
Block(1,10,1,VINE:4)
Block(1,11,-2,VINE:1)
Block(1,11,-1,LOG:3)
Block(1,11,0,LOG:3)
Block(1,11,1,VINE:4)
Block(1,12,-2,VINE:1)
Block(1,12,-1,LOG:3)
Block(1,12,0,LOG:3)
Block(1,12,1,VINE:4)
Block(1,13,-2,VINE:1)
Block(1,13,-1,LOG:3)
Block(1,13,0,LOG:3)
Block(1,13,1,VINE:4)
Block(1,14,-4,LEAVES:3)
Block(1,14,-2,LEAVES:3)
Block(1,14,-1,LOG:3)
Block(1,14,0,LOG:3)
Block(1,14,1,VINE:4)
Block(1,15,-5,LEAVES:3)
Block(1,15,-4,LEAVES:3)
Block(1,15,-3,LEAVES:3)
Block(1,15,-2,LEAVES:3)
Block(1,15,-1,LOG:3)
Block(1,15,0,LOG:3)
Block(1,15,1,VINE:4)
Block(1,16,-6,LEAVES:3)
Block(1,16,-5,LEAVES:3)
Block(1,16,-4,LEAVES:3)
Block(1,16,-3,LEAVES:3)
Block(1,16,-2,LOG:15)
Block(1,16,-1,LOG:3)
Block(1,16,0,LOG:3)
Block(1,16,1,LEAVES:3)
Block(1,17,-5,LEAVES:3)
Block(1,17,-4,LEAVES:3)
Block(1,17,-3,LEAVES:3)
Block(1,17,-2,LEAVES:3)
Block(1,17,-1,LOG:3)
Block(1,17,0,LOG:3)
Block(1,17,1,LEAVES:3)
Block(1,18,-3,LEAVES:3)
Block(1,18,-2,LEAVES:3)
Block(1,18,-1,LOG:3)
Block(1,18,0,LOG:3)
Block(1,18,1,VINE:6)
Block(1,19,-2,VINE:2)
Block(1,19,-1,LOG:3)
Block(1,19,0,LOG:3)
Block(1,19,1,VINE:6)
Block(1,20,-2,VINE:2)
Block(1,20,-1,LOG:3)
Block(1,20,0,LOG:3)
Block(1,20,1,VINE:6)
Block(1,21,-2,VINE:2)
Block(1,21,-1,LOG:3)
Block(1,21,0,LOG:3)
Block(1,21,1,VINE:6)
Block(1,21,3,VINE:4)
Block(1,22,-2,VINE:2)
Block(1,22,-1,LOG:3)
Block(1,22,0,LOG:3)
Block(1,22,1,VINE:4)
Block(1,22,3,VINE:4)
Block(1,23,-2,VINE:2)
Block(1,23,-1,LOG:3)
Block(1,23,0,LOG:3)
Block(1,23,1,VINE:4)
Block(1,23,3,VINE:4)
Block(1,24,-4,VINE:4)
Block(1,24,-2,VINE:2)
Block(1,24,-1,LOG:3)
Block(1,24,0,LOG:3)
Block(1,24,1,VINE:4)
Block(1,24,3,VINE:4)
Block(1,25,-4,VINE:4)
Block(1,25,-2,VINE:2)
Block(1,25,-1,LOG:3)
Block(1,25,0,LOG:3)
Block(1,25,1,VINE:4)
Block(1,25,3,VINE:4)
Block(1,26,-4,VINE:4)
Block(1,26,-2,VINE:2)
Block(1,26,-1,LOG:3)
Block(1,26,0,LOG:3)
Block(1,26,1,VINE:4)
Block(1,26,3,VINE:4)
Block(1,27,-6,LEAVES:3)
Block(1,27,-4,VINE:4)
Block(1,27,-2,VINE:2)
Block(1,27,-1,LOG:3)
Block(1,27,0,LOG:3)
Block(1,27,1,VINE:4)
Block(1,27,3,VINE:4)
Block(1,28,-7,LEAVES:3)
Block(1,28,-6,LEAVES:3)
Block(1,28,-5,LEAVES:3)
Block(1,28,-4,VINE:4)
Block(1,28,-3,LEAVES:3)
Block(1,28,-2,VINE:2)
Block(1,28,-1,LOG:3)
Block(1,28,0,LOG:3)
Block(1,28,1,VINE:4)
Block(1,28,3,VINE:4)
Block(1,29,-8,LEAVES:3)
Block(1,29,-7,LEAVES:3)
Block(1,29,-6,LEAVES:3)
Block(1,29,-5,LEAVES:3)
Block(1,29,-4,LEAVES:3)
Block(1,29,-3,LEAVES:3)
Block(1,29,-2,LEAVES:3)
Block(1,29,-1,LOG:3)
Block(1,29,0,LOG:3)
Block(1,29,1,LEAVES:3)
Block(1,29,2,LEAVES:3)
Block(1,29,3,VINE:4)
Block(1,29,4,LEAVES:3)
Block(1,30,-7,LEAVES:3)
Block(1,30,-6,LEAVES:3)
Block(1,30,-5,LEAVES:3)
Block(1,30,-4,LEAVES:3)
Block(1,30,-3,LEAVES:3)
Block(1,30,-2,LOG:7)
Block(1,30,-1,LOG:3)
Block(1,30,0,LOG:3)
Block(1,30,1,LEAVES:3)
Block(1,30,2,LEAVES:3)
Block(1,30,3,LEAVES:3)
Block(1,31,-5,LEAVES:3)
Block(1,31,-4,LEAVES:3)
Block(1,31,-3,LEAVES:3)
Block(1,31,-2,LEAVES:3)
Block(1,31,-1,LOG:7)
Block(1,31,0,LOG:15)
Block(1,31,1,LEAVES:3)
Block(1,31,2,LEAVES:3)
Block(1,31,3,LEAVES:3)
Block(1,31,4,LEAVES:3)
Block(1,32,-4,LEAVES:3)
Block(1,32,-3,LEAVES:3)
Block(1,32,-2,LEAVES:3)
Block(1,32,-1,LEAVES:3)
Block(1,32,0,LEAVES:3)
Block(1,32,1,LEAVES:3)
Block(1,32,2,LEAVES:3)
Block(1,32,3,VINE:4)
Block(1,33,-2,LEAVES:3)
Block(1,33,-1,LEAVES:3)
Block(1,33,0,LEAVES:3)
Block(1,33,1,LEAVES:3)
Block(1,33,2,LEAVES:3)
Block(1,33,3,VINE:4)
Block(2,6,0,VINE:2)
Block(2,7,0,VINE:2)
Block(2,8,0,VINE:2)
Block(2,9,0,VINE:2)
Block(2,10,0,VINE:2)
Block(2,11,0,VINE:2)
Block(2,12,0,VINE:2)
Block(2,13,0,VINE:2)
Block(2,14,-3,LEAVES:3)
Block(2,14,0,VINE:2)
Block(2,15,-4,LEAVES:3)
Block(2,15,-3,LEAVES:3)
Block(2,15,-2,LEAVES:3)
Block(2,15,-1,LEAVES:3)
Block(2,15,0,LEAVES:3)
Block(2,16,-5,LEAVES:3)
Block(2,16,-4,LEAVES:3)
Block(2,16,-3,LEAVES:3)
Block(2,16,-2,LEAVES:3)
Block(2,16,-1,LEAVES:3)
Block(2,16,0,LEAVES:3)
Block(2,16,1,LEAVES:3)
Block(2,17,-4,LEAVES:3)
Block(2,17,-3,LEAVES:3)
Block(2,17,-2,LEAVES:3)
Block(2,17,-1,LEAVES:3)
Block(2,17,0,LEAVES:3)
Block(2,18,-3,LEAVES:3)
Block(2,18,-2,LEAVES:3)
Block(2,18,-1,LEAVES:3)
Block(2,18,0,VINE:2)
Block(2,18,3,VINE:2)
Block(2,19,-1,VINE:2)
Block(2,19,0,VINE:2)
Block(2,19,3,VINE:2)
Block(2,20,-1,VINE:2)
Block(2,20,0,VINE:2)
Block(2,20,3,VINE:2)
Block(2,21,-3,VINE:4)
Block(2,21,-1,VINE:2)
Block(2,21,0,VINE:2)
Block(2,21,3,VINE:2)
Block(2,22,-3,VINE:4)
Block(2,22,-1,VINE:2)
Block(2,22,0,VINE:2)
Block(2,22,3,VINE:2)
Block(2,23,-3,VINE:4)
Block(2,23,-1,VINE:2)
Block(2,23,0,VINE:2)
Block(2,23,3,VINE:2)
Block(2,24,-3,VINE:4)
Block(2,24,-1,VINE:2)
Block(2,24,0,VINE:2)
Block(2,24,3,VINE:2)
Block(2,25,-3,VINE:4)
Block(2,25,-1,VINE:2)
Block(2,25,3,VINE:2)
Block(2,26,-3,VINE:4)
Block(2,26,-1,VINE:2)
Block(2,26,3,VINE:2)
Block(2,27,-4,LEAVES:3)
Block(2,27,-3,VINE:4)
Block(2,27,-1,VINE:2)
Block(2,27,3,VINE:2)
Block(2,28,-5,LEAVES:3)
Block(2,28,-4,LEAVES:3)
Block(2,28,-3,LEAVES:3)
Block(2,28,-2,LEAVES:3)
Block(2,28,-1,LEAVES:3)
Block(2,28,0,LEAVES:3)
Block(2,28,3,VINE:2)
Block(2,29,-7,LEAVES:3)
Block(2,29,-6,LEAVES:3)
Block(2,29,-5,LEAVES:3)
Block(2,29,-4,LEAVES:3)
Block(2,29,-3,LEAVES:3)
Block(2,29,-2,LEAVES:3)
Block(2,29,-1,LEAVES:3)
Block(2,29,0,LEAVES:3)
Block(2,29,1,LEAVES:3)
Block(2,29,3,VINE:2)
Block(2,30,-6,LEAVES:3)
Block(2,30,-5,LEAVES:3)
Block(2,30,-4,LEAVES:3)
Block(2,30,-3,LOG:7)
Block(2,30,-2,LOG:7)
Block(2,30,-1,LEAVES:3)
Block(2,30,0,LEAVES:3)
Block(2,30,1,LEAVES:3)
Block(2,30,2,LEAVES:3)
Block(2,30,3,VINE:2)
Block(2,31,-6,LEAVES:3)
Block(2,31,-5,LEAVES:3)
Block(2,31,-4,LEAVES:3)
Block(2,31,-3,LEAVES:3)
Block(2,31,-2,LEAVES:3)
Block(2,31,-1,LEAVES:3)
Block(2,31,0,LEAVES:3)
Block(2,31,1,LEAVES:3)
Block(2,31,2,LEAVES:3)
Block(2,31,3,LEAVES:3)
Block(2,32,-4,LEAVES:3)
Block(2,32,-3,LEAVES:3)
Block(2,32,-2,LEAVES:3)
Block(2,32,-1,LEAVES:3)
Block(2,32,0,LEAVES:3)
Block(2,32,1,LEAVES:3)
Block(2,32,2,LEAVES:3)
Block(2,32,3,VINE:4)
Block(2,33,-1,LEAVES:3)
Block(2,33,0,LEAVES:3)
Block(3,9,-4,VINE:1)
Block(3,10,-4,VINE:1)
Block(3,11,-4,VINE:1)
Block(3,11,1,VINE:2)
Block(3,12,-4,VINE:1)
Block(3,12,1,VINE:2)
Block(3,13,-4,VINE:1)
Block(3,13,1,VINE:2)
Block(3,14,-4,VINE:1)
Block(3,14,-2,LEAVES:3)
Block(3,14,1,VINE:2)
Block(3,15,-4,VINE:1)
Block(3,15,-3,LEAVES:3)
Block(3,15,-2,LEAVES:3)
Block(3,15,-1,LEAVES:3)
Block(3,15,1,VINE:2)
Block(3,16,-4,LEAVES:3)
Block(3,16,-3,LEAVES:3)
Block(3,16,-2,LEAVES:3)
Block(3,16,-1,LEAVES:3)
Block(3,16,0,LEAVES:3)
Block(3,16,1,VINE:2)
Block(3,17,-3,LEAVES:3)
Block(3,17,-2,LEAVES:3)
Block(3,17,-1,LEAVES:3)
Block(3,21,3,VINE:4)
Block(3,22,3,VINE:4)
Block(3,23,3,VINE:4)
Block(3,24,3,VINE:4)
Block(3,25,3,VINE:4)
Block(3,26,3,VINE:4)
Block(3,27,-4,LEAVES:3)
Block(3,27,-3,LEAVES:3)
Block(3,27,-2,LEAVES:3)
Block(3,27,3,VINE:4)
Block(3,28,-6,LEAVES:3)
Block(3,28,-5,LEAVES:3)
Block(3,28,-4,LEAVES:3)
Block(3,28,-3,LEAVES:3)
Block(3,28,-2,LEAVES:3)
Block(3,28,-1,LEAVES:3)
Block(3,28,3,VINE:4)
Block(3,29,-7,LEAVES:3)
Block(3,29,-6,LEAVES:3)
Block(3,29,-5,LEAVES:3)
Block(3,29,-4,LEAVES:3)
Block(3,29,-3,LOG:7)
Block(3,29,-2,LEAVES:3)
Block(3,29,-1,LEAVES:3)
Block(3,29,0,LEAVES:3)
Block(3,29,3,VINE:4)
Block(3,30,-6,LEAVES:3)
Block(3,30,-5,LEAVES:3)
Block(3,30,-4,LEAVES:3)
Block(3,30,-3,LEAVES:3)
Block(3,30,-2,LEAVES:3)
Block(3,30,-1,LEAVES:3)
Block(3,30,0,LEAVES:3)
Block(3,30,1,LEAVES:3)
Block(3,30,3,VINE:4)
Block(3,31,-5,LEAVES:3)
Block(3,31,-4,LEAVES:3)
Block(3,31,-3,LEAVES:3)
Block(3,31,-2,LEAVES:3)
Block(3,31,-1,LEAVES:3)
Block(3,31,0,LEAVES:3)
Block(3,31,1,LEAVES:3)
Block(3,31,2,LEAVES:3)
Block(3,31,3,VINE:4)
Block(3,32,-3,LEAVES:3)
Block(3,32,-2,LEAVES:3)
Block(3,32,-1,LEAVES:3)
Block(3,32,0,LEAVES:3)
Block(3,32,1,LEAVES:3)
Block(3,32,2,VINE:2)
Block(4,16,-3,LEAVES:3)
Block(4,16,-2,LEAVES:3)
Block(4,16,-1,LEAVES:3)
Block(4,27,-5,LEAVES:3)
Block(4,27,-4,LEAVES:3)
Block(4,27,-3,LEAVES:3)
Block(4,27,-2,LEAVES:3)
Block(4,28,-7,LEAVES:3)
Block(4,28,-6,LEAVES:3)
Block(4,28,-5,LEAVES:3)
Block(4,28,-4,LEAVES:3)
Block(4,28,-3,LEAVES:3)
Block(4,28,-2,LEAVES:3)
Block(4,28,-1,LEAVES:3)
Block(4,29,-7,LEAVES:3)
Block(4,29,-6,LEAVES:3)
Block(4,29,-5,LEAVES:3)
Block(4,29,-4,LOG:15)
Block(4,29,-3,LOG:15)
Block(4,29,-2,LEAVES:3)
Block(4,29,-1,LEAVES:3)
Block(4,29,0,LEAVES:3)
Block(4,30,-6,LEAVES:3)
Block(4,30,-5,LEAVES:3)
Block(4,30,-4,LEAVES:3)
Block(4,30,-3,LEAVES:3)
Block(4,30,-2,LEAVES:3)
Block(4,30,-1,LEAVES:3)
Block(4,30,0,LEAVES:3)
Block(4,31,-4,LEAVES:3)
Block(4,31,-3,LEAVES:3)
Block(4,31,-2,LEAVES:3)
Block(4,31,-1,LEAVES:3)
Block(4,31,0,LEAVES:3)
Block(4,31,1,LEAVES:3)
Block(4,32,-3,LEAVES:3)
Block(5,16,-2,LEAVES:3)
Block(5,27,-5,LEAVES:3)
Block(5,27,-3,LEAVES:3)
Block(5,27,-2,LEAVES:3)
Block(5,28,-6,LEAVES:3)
Block(5,28,-5,LEAVES:3)
Block(5,28,-4,LEAVES:3)
Block(5,28,-3,LEAVES:3)
Block(5,28,-2,LEAVES:3)
Block(5,28,-1,LEAVES:3)
Block(5,29,-7,LEAVES:3)
Block(5,29,-6,LEAVES:3)
Block(5,29,-5,LEAVES:3)
Block(5,29,-4,LEAVES:3)
Block(5,29,-3,LEAVES:3)
Block(5,29,-2,LEAVES:3)
Block(5,29,-1,LEAVES:3)
Block(5,29,0,LEAVES:3)
Block(5,30,-6,LEAVES:3)
Block(5,30,-5,LEAVES:3)
Block(5,30,-4,LEAVES:3)
Block(5,30,-3,LEAVES:3)
Block(5,30,-2,LEAVES:3)
Block(5,30,-1,LEAVES:3)
Block(5,31,-4,LEAVES:3)
Block(5,31,-3,LEAVES:3)
Block(5,31,0,LEAVES:3)
Block(6,27,-3,LEAVES:3)
Block(6,28,-5,LEAVES:3)
Block(6,28,-4,LEAVES:3)
Block(6,28,-3,LEAVES:3)
Block(6,28,-2,LEAVES:3)
Block(6,29,-6,LEAVES:3)
Block(6,29,-5,LEAVES:3)
Block(6,29,-4,LEAVES:3)
Block(6,29,-3,LEAVES:3)
Block(6,29,-2,LEAVES:3)
Block(6,29,-1,LEAVES:3)
Block(6,30,-5,LEAVES:3)
Block(6,30,-4,LEAVES:3)
Block(6,30,-3,LEAVES:3)
Block(6,30,-2,LEAVES:3)
Block(6,31,-3,LEAVES:3)
Block(7,28,-4,LEAVES:3)
Block(7,28,-3,LEAVES:3)
Block(7,29,-5,LEAVES:3)
Block(7,29,-4,LEAVES:3)
Block(7,29,-3,LEAVES:3)
Block(7,29,-2,LEAVES:3)
Block(7,30,-4,LEAVES:3)
Block(7,30,-3,LEAVES:3)
Block(8,29,-4,LEAVES:3)

#######################################################################
# +-----------------------------------------------------------------+ #
# |                            BO3 checks                           | #
# +-----------------------------------------------------------------+ #
#######################################################################

BlockCheck(0,-1,0,GRASS:0,DIRT:0)
BlockCheck(1,-1,0,GRASS:0,DIRT:0)
BlockCheck(0,-1,1,GRASS:0,DIRT:0)
BlockCheck(1,-1,1,GRASS:0,DIRT:0)

#######################################################################
# +-----------------------------------------------------------------+ #
# |                             Branches                            | #
# +-----------------------------------------------------------------+ #
#######################################################################


#######################################################################
# +-----------------------------------------------------------------+ #
# |                             Entities                            | #
# +-----------------------------------------------------------------+ #
#######################################################################


#######################################################################
# +-----------------------------------------------------------------+ #
# |                            Particles                            | #
# +-----------------------------------------------------------------+ #
#######################################################################


#######################################################################
# +-----------------------------------------------------------------+ #
# |                             Spawners                            | #
# +-----------------------------------------------------------------+ #
#######################################################################


#######################################################################
# +-----------------------------------------------------------------+ #
# |                             ModData                             | #
# +-----------------------------------------------------------------+ #
#######################################################################

