
#######################################################################
# +-----------------------------------------------------------------+ #
# |                            BO3 object                           | #
# +-----------------------------------------------------------------+ #
#######################################################################

Author: Unknown

Description: Converted version of the BO2 BirchForest3

Version: 3

SettingsMode: WriteWithoutComments


#######################################################################
# +-----------------------------------------------------------------+ #
# |                          Main settings                          | #
# +-----------------------------------------------------------------+ #
#######################################################################

Tree: true

Frequency: 1

Rarity: 10.0

RotateRandomly: true

SpawnHeight: highestSolidBlock

SpawnHeightOffset: 0

SpawnHeightVariance: 0

##############################
# Height Limits for the BO3. #
##############################

MinHeight: 62

MaxHeight: 239

######################
# Extrusion settings #
######################

ExtrudeMode: None

ExtrudeThroughBlocks: AIR

MaxBranchDepth: 10

ExcludedBiomes: All


#######################################################################
# +-----------------------------------------------------------------+ #
# |                      Source block settings                      | #
# +-----------------------------------------------------------------+ #
#######################################################################

SourceBlocks: STONE:1,STONE:3,STONE:5,DIRT:1,DIRT,SAND,GRASS,DIRT:2,STATIONARY_WATER,HARD_CLAY,STAINED_CLAY,CLAY,SANDSTONE,SAND:1,AIR,STONE,GRAVEL,LONG_GRASS,LONG_GRASS:1,LONG_GRASS:2,DEAD_BUSH,YELLOW_FLOWER,RED_ROSE,BROWN_MUSHROOM,RED_MUSHROOM,biomesoplenty:plant_0:1,biomesoplenty:plant_0:2,biomesoplenty:plant_0:3,biomesoplenty:plant_0:4,biomesoplenty:plant_0:5,biomesoplenty:plant_0:6,biomesoplenty:plant_0:7,biomesoplenty:plant_0:8,biomesoplenty:plant_0:9,biomesoplenty:plant_0:10,biomesoplenty:plant_0:11,biomesoplenty:plant_0:12,biomesoplenty:plant_0:13,biomesoplenty:plant_0:14,biomesoplenty:flower_0:1,biomesoplenty:flower_0:2,biomesoplenty:flower_0:3,biomesoplenty:flower_0:4,biomesoplenty:flower_0:5,biomesoplenty:flower_0:6,biomesoplenty:flower_0:7,biomesoplenty:flower_0:8,biomesoplenty:flower_0:9,biomesoplenty:flower_0:10,biomesoplenty:flower_0:11,biomesoplenty:flower_0:12,biomesoplenty:flower_0:13,biomesoplenty:flower_0:14,biomesoplenty:plant_1,biomesoplenty:grass:0,biomesoplenty:grass:1,biomesoplenty:grass,biomesoplenty:grass:3,biomesoplenty:grass:4,biomesoplenty:grass:5,biomesoplenty:grass:6,biomesoplenty:grass:7,biomesoplenty:dirt,biomesoplenty:dirt:1,biomesoplenty:dirt:2,biomesoplenty:dirt:8,biomesoplenty:dirt:9,biomesoplenty:dirt:10,biomesoplenty:dried_sand,biomesoplenty:hard_ice,biomesoplenty:white_sand,biomesoplenty:white_sandstone,biomesoplenty:mud,biomesoplenty:ash_block

MaxPercentageOutsideSourceBlock: 0

OutsideSourceBlock: placeAnyway

DoReplaceBlocks: true

IsOTGPlus: false


#######################################################################
# +-----------------------------------------------------------------+ #
# |                              Blocks                             | #
# +-----------------------------------------------------------------+ #
#######################################################################

Block(-4,9,2,LEAVES:2)
Block(-4,7,2,LEAVES:2)
Block(-4,6,2,LEAVES:2)
Block(1,8,-4,LEAVES:2)
Block(1,9,-4,LEAVES:2)
Block(1,6,-4,LEAVES:2)
Block(-3,7,4,LEAVES:2)
Block(1,5,-4,LEAVES:2)
Block(-3,6,4,LEAVES:2)
Block(-3,8,4,LEAVES:2)
Block(-3,5,4,LEAVES:2)
Block(-3,10,2,LEAVES:2)
Block(-4,10,-1,LEAVES:2)
Block(-3,14,2,LEAVES:2)
Block(-3,13,2,LEAVES:2)
Block(-3,12,2,LEAVES:2)
Block(-2,9,6,LEAVES:2)
Block(-3,11,2,LEAVES:2)
Block(-7,8,-1,LEAVES:2)
Block(-1,11,7,LEAVES:2)
Block(-7,9,-1,LEAVES:2)
Block(-1,10,7,LEAVES:2)
Block(-3,15,2,LEAVES:2)
Block(1,10,1,LEAVES:2)
Block(-3,7,-2,LEAVES:2)
Block(1,11,1,LOG:2)
Block(-3,8,-2,LEAVES:2)
Block(1,12,1,LEAVES:2)
Block(-3,9,-2,LEAVES:2)
Block(1,13,1,LEAVES:2)
Block(1,14,1,LEAVES:2)
Block(-4,9,1,LEAVES:2)
Block(-4,8,1,LEAVES:2)
Block(-4,7,1,LEAVES:2)
Block(-4,6,1,LEAVES:2)
Block(1,9,-3,LEAVES:2)
Block(1,7,-3,LEAVES:2)
Block(1,8,-3,LEAVES:2)
Block(1,5,-3,LEAVES:2)
Block(-3,8,3,LEAVES:2)
Block(1,10,2,LEAVES:2)
Block(1,6,-3,LEAVES:2)
Block(-3,7,3,LEAVES:2)
Block(1,11,2,LEAVES:2)
Block(-5,10,7,LEAVES:2)
Block(1,12,2,LEAVES:2)
Block(-3,9,3,LEAVES:2)
Block(-5,11,7,LEAVES:2)
Block(1,13,2,LEAVES:2)
Block(1,13,-1,LEAVES:2)
Block(1,14,2,LEAVES:2)
Block(1,12,-1,LEAVES:2)
Block(-3,6,3,LEAVES:2)
Block(1,11,-1,LEAVES:2)
Block(-3,5,3,LOG:2)
Block(1,10,-1,LEAVES:2)
Block(-7,9,-2,LEAVES:2)
Block(-4,10,5,LEAVES:2)
Block(-4,12,5,LEAVES:2)
Block(-4,11,5,LEAVES:2)
Block(-2,7,5,LEAVES:2)
Block(-2,6,5,LEAVES:2)
Block(-7,8,-2,LEAVES:2)
Block(-4,13,5,LEAVES:2)
Block(-5,9,0,LEAVES:2)
Block(-5,8,0,LEAVES:2)
Block(-3,7,-1,LEAVES:2)
Block(-3,8,-1,LEAVES:2)
Block(-3,9,-1,LEAVES:2)
Block(-3,11,3,LEAVES:2)
Block(-3,10,3,LEAVES:2)
Block(-5,7,0,LEAVES:2)
Block(-4,7,4,LEAVES:2)
Block(-3,14,3,LEAVES:2)
Block(-4,6,4,LEAVES:2)
Block(-3,13,3,LEAVES:2)
Block(-3,12,3,LEAVES:2)
Block(0,5,0,LEAVES:2)
Block(0,7,0,LEAVES:2)
Block(0,6,0,LEAVES:2)
Block(-2,13,0,LEAVES:2)
Block(-2,14,0,LEAVES:2)
Block(-2,11,0,LEAVES:2)
Block(-2,10,0,LEAVES:2)
Block(-3,9,6,LOG:2)
Block(1,8,-2,LEAVES:2)
Block(1,9,-2,LEAVES:2)
Block(1,6,-2,LEAVES:2)
Block(1,7,-2,LEAVES:2)
Block(1,4,-2,LEAVES:2)
Block(1,5,-2,LEAVES:2)
Block(-4,13,3,LEAVES:2)
Block(-4,14,3,LEAVES:2)
Block(-1,12,5,LEAVES:2)
Block(-1,13,5,LEAVES:2)
Block(-4,8,-1,LEAVES:2)
Block(-4,7,-1,LEAVES:2)
Block(2,12,3,LEAVES:2)
Block(-4,9,-1,LEAVES:2)
Block(2,13,3,LEAVES:2)
Block(-4,10,3,LEAVES:2)
Block(-4,11,3,LEAVES:2)
Block(-4,12,3,LEAVES:2)
Block(-5,8,1,LEAVES:2)
Block(-5,9,1,LEAVES:2)
Block(2,5,-1,LEAVES:2)
Block(0,8,1,LOG:2)
Block(0,7,1,LEAVES:2)
Block(2,7,-1,LEAVES:2)
Block(2,6,-1,LEAVES:2)
Block(0,9,1,LOG:2)
Block(2,12,2,LEAVES:2)
Block(-4,8,3,LEAVES:2)
Block(2,11,2,LEAVES:2)
Block(-4,7,3,LEAVES:2)
Block(-4,6,3,LEAVES:2)
Block(2,13,2,LEAVES:2)
Block(-4,10,4,LEAVES:2)
Block(-1,12,6,LEAVES:2)
Block(-4,11,4,LEAVES:2)
Block(-1,11,6,LEAVES:2)
Block(2,10,2,LEAVES:2)
Block(-1,10,6,LEAVES:2)
Block(-4,12,4,LEAVES:2)
Block(-4,13,4,LEAVES:2)
Block(-6,9,-3,LEAVES:2)
Block(-6,8,-3,LEAVES:2)
Block(-4,5,3,LEAVES:2)
Block(-3,9,5,LOG:2)
Block(1,9,-1,LEAVES:2)
Block(2,12,-4,LEAVES:2)
Block(-3,6,5,LEAVES:2)
Block(1,7,-1,LEAVES:2)
Block(2,11,-4,LEAVES:2)
Block(1,8,-1,LEAVES:2)
Block(1,5,-1,LEAVES:2)
Block(1,6,-1,LEAVES:2)
Block(-3,7,5,LEAVES:2)
Block(-3,12,4,LEAVES:2)
Block(-3,11,4,LEAVES:2)
Block(-3,10,4,LEAVES:2)
Block(-3,14,4,LEAVES:2)
Block(-3,13,4,LEAVES:2)
Block(-6,9,0,LEAVES:2)
Block(-6,8,0,LEAVES:2)
Block(-5,7,2,LEAVES:2)
Block(-5,6,2,LEAVES:2)
Block(1,10,3,LEAVES:2)
Block(1,12,3,LEAVES:2)
Block(1,13,3,LEAVES:2)
Block(2,8,-2,LEAVES:2)
Block(0,9,0,LOG:2)
Block(0,8,0,LEAVES:2)
Block(2,6,-2,LEAVES:2)
Block(2,5,-2,LEAVES:2)
Block(-1,13,6,LEAVES:2)
Block(2,9,-2,LEAVES:2)
Block(0,6,-4,LEAVES:2)
Block(0,5,-4,LEAVES:2)
Block(-4,9,6,LEAVES:2)
Block(0,8,-4,LEAVES:2)
Block(0,7,-4,LEAVES:2)
Block(-4,11,2,LEAVES:2)
Block(-4,10,2,LEAVES:2)
Block(-2,9,-3,LEAVES:2)
Block(0,14,1,LEAVES:2)
Block(2,7,6,LEAVES:2)
Block(-2,8,-3,LEAVES:2)
Block(0,13,1,LEAVES:2)
Block(0,12,1,LEAVES:2)
Block(-5,10,5,LEAVES:2)
Block(-5,11,5,LEAVES:2)
Block(0,9,-4,LEAVES:2)
Block(-2,6,-3,LEAVES:2)
Block(0,11,1,LEAVES:2)
Block(-2,5,-3,LEAVES:2)
Block(2,8,6,LEAVES:2)
Block(0,10,1,LOG:2)
Block(-4,8,-3,LEAVES:2)
Block(3,8,4,LEAVES:2)
Block(3,7,4,LEAVES:2)
Block(-6,9,1,LEAVES:2)
Block(-6,8,1,LEAVES:2)
Block(-4,9,-3,LEAVES:2)
Block(-5,6,3,LEAVES:2)
Block(-5,7,3,LEAVES:2)
Block(-1,11,-2,LEAVES:2)
Block(-3,10,5,LEAVES:2)
Block(2,6,-3,LEAVES:2)
Block(-3,11,5,LEAVES:2)
Block(2,5,-3,LEAVES:2)
Block(-3,12,5,LEAVES:2)
Block(-3,13,5,LEAVES:2)
Block(2,9,-3,LEAVES:2)
Block(2,8,-3,LEAVES:2)
Block(-4,7,5,LEAVES:2)
Block(-4,6,5,LEAVES:2)
Block(-2,10,-1,LEAVES:2)
Block(-3,9,7,LEAVES:2)
Block(-1,10,-1,LEAVES:2)
Block(-2,8,-4,LEAVES:2)
Block(-2,9,-4,LEAVES:2)
Block(0,9,-5,LEAVES:2)
Block(0,8,-5,LEAVES:2)
Block(2,8,7,LEAVES:2)
Block(2,7,7,LEAVES:2)
Block(-7,9,0,LEAVES:2)
Block(-7,8,0,LEAVES:2)
Block(2,11,1,LEAVES:2)
Block(2,10,1,LEAVES:2)
Block(-4,9,-2,LEAVES:2)
Block(2,13,1,LEAVES:2)
Block(-4,8,-2,LEAVES:2)
Block(2,12,1,LEAVES:2)
Block(3,7,5,LEAVES:2)
Block(-5,10,-2,LEAVES:2)
Block(-2,14,1,LEAVES:2)
Block(-2,13,1,LEAVES:2)
Block(3,8,5,LEAVES:2)
Block(-2,15,1,LEAVES:2)
Block(-2,10,1,LEAVES:2)
Block(-1,11,-1,LEAVES:2)
Block(-1,12,-1,LEAVES:2)
Block(2,14,1,LEAVES:2)
Block(-2,12,1,LEAVES:2)
Block(-2,11,1,LEAVES:2)
Block(0,13,0,LEAVES:2)
Block(-5,7,4,LEAVES:2)
Block(0,12,0,LEAVES:2)
Block(-5,6,4,LEAVES:2)
Block(0,11,0,LEAVES:2)
Block(-4,14,2,LEAVES:2)
Block(-4,13,2,LEAVES:2)
Block(-4,12,2,LEAVES:2)
Block(0,10,0,LEAVES:2)
Block(2,9,-4,LEAVES:2)
Block(2,8,-4,LEAVES:2)
Block(0,4,-2,LEAVES:2)
Block(2,10,0,LEAVES:2)
Block(0,6,-2,LOG:2)
Block(2,11,0,LEAVES:2)
Block(0,5,-2,LEAVES:2)
Block(2,12,0,LEAVES:2)
Block(0,8,-2,LEAVES:2)
Block(0,7,-2,LEAVES:2)
Block(0,9,-2,LEAVES:2)
Block(2,13,0,LEAVES:2)
Block(-1,10,-3,LEAVES:2)
Block(-2,10,3,LOG:2)
Block(-1,12,-3,LEAVES:2)
Block(-2,9,-1,LEAVES:2)
Block(-1,11,-3,LEAVES:2)
Block(-3,11,6,LEAVES:2)
Block(-3,12,6,LEAVES:2)
Block(-3,13,6,LEAVES:2)
Block(-2,8,-1,LEAVES:2)
Block(-2,7,-1,LEAVES:2)
Block(-2,6,-1,LEAVES:2)
Block(-2,5,-1,LEAVES:2)
Block(-3,10,6,LEAVES:2)
Block(3,8,6,LEAVES:2)
Block(-2,15,3,LEAVES:2)
Block(3,7,6,LEAVES:2)
Block(-2,13,3,LEAVES:2)
Block(-2,14,3,LEAVES:2)
Block(-2,11,3,LEAVES:2)
Block(-6,10,-1,LEAVES:2)
Block(-2,12,3,LEAVES:2)
Block(-5,11,6,LEAVES:2)
Block(0,13,2,LEAVES:2)
Block(0,14,2,LEAVES:2)
Block(-4,10,0,LEAVES:2)
Block(-5,10,6,LEAVES:2)
Block(-4,11,0,LEAVES:2)
Block(-3,10,-1,LEAVES:2)
Block(0,10,2,LEAVES:2)
Block(0,11,2,LEAVES:2)
Block(0,12,2,LEAVES:2)
Block(0,5,-3,LEAVES:2)
Block(0,4,-3,LEAVES:2)
Block(0,7,-3,LOG:2)
Block(0,6,-3,LEAVES:2)
Block(0,9,-3,LEAVES:2)
Block(-5,10,-1,LEAVES:2)
Block(0,8,-3,LEAVES:2)
Block(-2,14,2,LEAVES:2)
Block(-2,15,2,LEAVES:2)
Block(-1,12,-2,LEAVES:2)
Block(-2,12,2,LOG:2)
Block(-2,13,2,LEAVES:2)
Block(-2,10,2,LOG:2)
Block(-2,11,2,LOG:2)
Block(-2,9,-2,LEAVES:2)
Block(-2,8,-2,LEAVES:2)
Block(-4,14,1,LEAVES:2)
Block(-4,13,1,LEAVES:2)
Block(-4,11,1,LEAVES:2)
Block(-2,7,-2,LEAVES:2)
Block(-2,6,-2,LEAVES:2)
Block(-2,5,-2,LEAVES:2)
Block(-4,10,1,LEAVES:2)
Block(-3,12,7,LEAVES:2)
Block(-3,11,7,LEAVES:2)
Block(-3,10,7,LEAVES:2)
Block(1,9,4,LEAVES:2)
Block(1,8,4,LEAVES:2)
Block(1,7,4,LEAVES:2)
Block(1,6,4,LEAVES:2)
Block(1,5,4,LEAVES:2)
Block(-2,14,4,LEAVES:2)
Block(-2,13,4,LEAVES:2)
Block(-2,12,4,LEAVES:2)
Block(2,9,2,LEAVES:2)
Block(2,5,2,LEAVES:2)
Block(2,4,2,LEAVES:2)
Block(2,7,2,LEAVES:2)
Block(2,6,2,LEAVES:2)
Block(-1,10,1,LEAVES:2)
Block(-1,11,1,LEAVES:2)
Block(-5,9,-2,LEAVES:2)
Block(-1,12,1,LEAVES:2)
Block(-1,13,1,LEAVES:2)
Block(-5,7,-2,LEAVES:2)
Block(-1,14,1,LEAVES:2)
Block(-5,8,-2,LEAVES:2)
Block(-1,5,-3,LEAVES:2)
Block(-1,5,0,LOG:2)
Block(3,7,0,LEAVES:2)
Block(3,6,0,LEAVES:2)
Block(-1,7,0,LEAVES:2)
Block(-1,6,0,LEAVES:2)
Block(-1,9,0,LEAVES:2)
Block(-1,8,0,LEAVES:2)
Block(-1,9,-3,LEAVES:2)
Block(-1,8,-3,LEAVES:2)
Block(-1,7,-3,LEAVES:2)
Block(-1,6,-3,LEAVES:2)
Block(-5,10,2,LEAVES:2)
Block(-5,11,2,LEAVES:2)
Block(0,8,7,LEAVES:2)
Block(3,12,2,LEAVES:2)
Block(0,7,7,LEAVES:2)
Block(3,13,2,LEAVES:2)
Block(0,5,-1,LEAVES:2)
Block(1,9,5,LEAVES:2)
Block(0,4,-1,LEAVES:2)
Block(1,8,5,LEAVES:2)
Block(0,7,-1,LEAVES:2)
Block(1,7,5,LEAVES:2)
Block(0,6,-1,LEAVES:2)
Block(1,6,5,LOG:2)
Block(0,9,-1,LEAVES:2)
Block(0,8,-1,LEAVES:2)
Block(2,8,3,LEAVES:2)
Block(2,7,3,LEAVES:2)
Block(0,14,3,LEAVES:2)
Block(2,6,3,LEAVES:2)
Block(2,5,3,LEAVES:2)
Block(0,10,3,LEAVES:2)
Block(0,12,3,LEAVES:2)
Block(0,13,3,LEAVES:2)
Block(-5,8,-3,LEAVES:2)
Block(-3,10,8,LEAVES:2)
Block(-5,9,-3,LEAVES:2)
Block(-3,11,8,LEAVES:2)
Block(-1,6,-2,LEAVES:2)
Block(3,7,1,LEAVES:2)
Block(-1,5,-2,LEAVES:2)
Block(3,6,1,LEAVES:2)
Block(-1,4,-2,LEAVES:2)
Block(3,5,1,LEAVES:2)
Block(-1,9,-2,LEAVES:2)
Block(-1,8,-2,LEAVES:2)
Block(-1,7,-2,LEAVES:2)
Block(-2,11,4,LOG:2)
Block(-2,10,4,LEAVES:2)
Block(-1,10,2,LOG:2)
Block(0,10,-1,LOG:2)
Block(-1,12,2,LEAVES:2)
Block(-1,11,2,LEAVES:2)
Block(0,7,6,LEAVES:2)
Block(0,12,-1,LEAVES:2)
Block(-1,14,2,LEAVES:2)
Block(0,11,-1,LEAVES:2)
Block(-1,13,2,LEAVES:2)
Block(0,8,6,LEAVES:2)
Block(0,13,-1,LEAVES:2)
Block(-1,15,2,LEAVES:2)
Block(1,8,6,LEAVES:2)
Block(1,7,6,LEAVES:2)
Block(1,6,6,LEAVES:2)
Block(1,9,6,LEAVES:2)
Block(2,7,4,LEAVES:2)
Block(2,6,4,LEAVES:2)
Block(2,8,4,LEAVES:2)
Block(2,5,4,LEAVES:2)
Block(0,13,5,LEAVES:2)
Block(0,12,5,LEAVES:2)
Block(3,6,2,LEAVES:2)
Block(3,5,2,LEAVES:2)
Block(-1,5,2,LEAVES:2)
Block(-1,7,2,LEAVES:2)
Block(-1,6,2,LEAVES:2)
Block(-1,9,2,LEAVES:2)
Block(3,7,2,LEAVES:2)
Block(-1,8,2,LOG:2)
Block(3,11,-3,LEAVES:2)
Block(-2,9,0,LEAVES:2)
Block(-2,8,0,LEAVES:2)
Block(-1,9,-5,LEAVES:2)
Block(-2,7,0,LEAVES:2)
Block(-1,8,-5,LEAVES:2)
Block(3,12,-3,LEAVES:2)
Block(-2,6,0,LOG:2)
Block(-2,13,6,LEAVES:2)
Block(-2,12,6,LEAVES:2)
Block(-2,11,6,LEAVES:2)
Block(1,12,-4,LEAVES:2)
Block(-2,10,6,LEAVES:2)
Block(1,11,-4,LEAVES:2)
Block(-1,10,0,LEAVES:2)
Block(-1,11,0,LEAVES:2)
Block(-1,12,0,LEAVES:2)
Block(-1,13,0,LEAVES:2)
Block(-1,14,0,LEAVES:2)
Block(1,7,7,LEAVES:2)
Block(1,8,7,LEAVES:2)
Block(2,6,5,LEAVES:2)
Block(-5,11,3,LEAVES:2)
Block(-2,12,5,LEAVES:2)
Block(-5,10,3,LEAVES:2)
Block(-2,11,5,LEAVES:2)
Block(2,8,5,LEAVES:2)
Block(-2,10,5,LEAVES:2)
Block(2,7,5,LEAVES:2)
Block(-5,7,-1,LOG:2)
Block(3,13,1,LEAVES:2)
Block(2,9,5,LEAVES:2)
Block(-5,8,-1,LEAVES:2)
Block(3,11,1,LEAVES:2)
Block(-5,9,-1,LEAVES:2)
Block(3,12,1,LEAVES:2)
Block(3,5,3,LEAVES:2)
Block(-1,6,1,LEAVES:2)
Block(-1,5,1,LEAVES:2)
Block(-1,8,1,LEAVES:2)
Block(-1,7,1,LEAVES:2)
Block(3,6,3,LEAVES:2)
Block(-1,9,1,LOG:2)
Block(-1,9,-4,LEAVES:2)
Block(-1,8,-4,LEAVES:2)
Block(-1,6,-4,LEAVES:2)
Block(-2,14,5,LEAVES:2)
Block(-1,5,-4,LEAVES:2)
Block(-2,13,5,LEAVES:2)
Block(0,12,4,LEAVES:2)
Block(0,13,4,LEAVES:2)
Block(1,9,0,LEAVES:2)
Block(0,5,2,LEAVES:2)
Block(1,8,0,LEAVES:2)
Block(0,4,2,LEAVES:2)
Block(1,7,0,LEAVES:2)
Block(-6,9,-2,LEAVES:2)
Block(-6,8,-2,LEAVES:2)
Block(-2,10,7,LEAVES:2)
Block(-2,11,7,LEAVES:2)
Block(2,12,-2,LEAVES:2)
Block(2,13,-2,LEAVES:2)
Block(1,10,-3,LEAVES:2)
Block(2,10,-2,LEAVES:2)
Block(1,11,-3,LEAVES:2)
Block(2,11,-2,LEAVES:2)
Block(1,12,-3,LEAVES:2)
Block(1,13,-3,LEAVES:2)
Block(-3,7,0,LEAVES:2)
Block(0,12,-4,LEAVES:2)
Block(-3,6,0,LEAVES:2)
Block(-3,9,0,LEAVES:2)
Block(0,10,-4,LEAVES:2)
Block(-3,8,0,LEAVES:2)
Block(0,11,-4,LEAVES:2)
Block(-4,11,7,LEAVES:2)
Block(-4,10,7,LEAVES:2)
Block(-1,7,4,LEAVES:2)
Block(-1,6,4,LEAVES:2)
Block(-2,9,2,LOG:2)
Block(-2,8,2,LOG:2)
Block(-2,7,2,LOG:2)
Block(-1,8,4,LEAVES:2)
Block(-2,6,2,LOG:2)
Block(-2,5,2,LOG:2)
Block(-2,4,2,LOG:2)
Block(-2,3,2,LOG:2)
Block(-2,2,2,LOG:2)
Block(-2,1,2,LOG:2)
Block(-2,0,2,LOG:2)
Block(-2,-1,2,LOG:2)
Block(-2,-2,2,LOG:2)
Block(-2,-3,2,LOG:2)
Block(0,6,3,LEAVES:2)
Block(-1,13,4,LEAVES:2)
Block(0,5,3,LEAVES:2)
Block(-1,14,4,LEAVES:2)
Block(0,8,3,LEAVES:2)
Block(-1,11,4,LEAVES:2)
Block(0,7,3,LEAVES:2)
Block(-1,12,4,LEAVES:2)
Block(0,9,3,LEAVES:2)
Block(-4,10,8,LEAVES:2)
Block(-4,11,8,LEAVES:2)
Block(1,9,1,LEAVES:2)
Block(1,8,1,LEAVES:2)
Block(0,6,1,LEAVES:2)
Block(1,7,1,LEAVES:2)
Block(0,5,1,LEAVES:2)
Block(1,6,1,LEAVES:2)
Block(3,11,-2,LEAVES:2)
Block(-6,9,-1,LEAVES:2)
Block(3,12,-2,LEAVES:2)
Block(-6,8,-1,LEAVES:2)
Block(-6,7,-1,LEAVES:2)
Block(-3,11,0,LEAVES:2)
Block(-3,10,0,LEAVES:2)
Block(-1,6,3,LEAVES:2)
Block(-1,10,5,LEAVES:2)
Block(-1,5,3,LOG:2)
Block(-1,11,5,LEAVES:2)
Block(-3,13,0,LEAVES:2)
Block(-1,7,3,LEAVES:2)
Block(-3,14,0,LEAVES:2)
Block(-2,9,1,LEAVES:2)
Block(-2,8,1,LOG:2)
Block(-1,9,3,LEAVES:2)
Block(-2,7,1,LEAVES:2)
Block(-2,6,1,LOG:2)
Block(-2,5,1,LOG:2)
Block(2,11,-3,LEAVES:2)
Block(2,12,-3,LEAVES:2)
Block(1,6,0,LEAVES:2)
Block(0,7,2,LEAVES:2)
Block(1,5,0,LEAVES:2)
Block(0,6,2,LEAVES:2)
Block(0,9,2,LEAVES:2)
Block(0,8,2,LEAVES:2)
Block(3,11,0,LEAVES:2)
Block(3,13,0,LEAVES:2)
Block(3,12,0,LEAVES:2)
Block(-4,11,6,LEAVES:2)
Block(-4,9,0,LEAVES:2)
Block(1,9,2,LEAVES:2)
Block(-4,10,6,LEAVES:2)
Block(1,8,2,LEAVES:2)
Block(1,7,2,LEAVES:2)
Block(-4,12,6,LEAVES:2)
Block(1,6,2,LEAVES:2)
Block(1,5,2,LEAVES:2)
Block(-4,8,0,LEAVES:2)
Block(-4,7,0,LEAVES:2)
Block(-4,6,0,LOG:2)
Block(-5,10,1,LEAVES:2)
Block(-5,11,1,LEAVES:2)
Block(2,7,0,LEAVES:2)
Block(-3,9,2,LOG:2)
Block(2,6,0,LEAVES:2)
Block(-3,8,2,LEAVES:2)
Block(2,9,0,LEAVES:2)
Block(-3,5,2,LEAVES:2)
Block(-3,7,2,LEAVES:2)
Block(-3,6,2,LEAVES:2)
Block(-1,7,-1,LEAVES:2)
Block(-1,6,-1,LOG:2)
Block(-1,5,-1,LEAVES:2)
Block(1,14,0,LEAVES:2)
Block(-2,8,4,LOG:2)
Block(1,13,0,LEAVES:2)
Block(-2,7,4,LEAVES:2)
Block(1,12,0,LEAVES:2)
Block(-2,6,4,LEAVES:2)
Block(-1,7,6,LEAVES:2)
Block(1,11,0,LEAVES:2)
Block(1,10,0,LOG:2)
Block(-1,8,6,LEAVES:2)
Block(2,13,-1,LEAVES:2)
Block(-1,9,-1,LEAVES:2)
Block(-1,8,-1,LEAVES:2)
Block(2,12,-1,LEAVES:2)
Block(2,11,-1,LEAVES:2)
Block(1,5,1,LEAVES:2)
Block(0,11,-3,LEAVES:2)
Block(1,4,1,LEAVES:2)
Block(0,12,-3,LEAVES:2)
Block(0,6,5,LEAVES:2)
Block(0,10,-3,LEAVES:2)
Block(0,8,5,LEAVES:2)
Block(0,7,5,LEAVES:2)
Block(0,9,5,LEAVES:2)
Block(-3,12,1,LEAVES:2)
Block(-3,13,1,LEAVES:2)
Block(1,9,3,LEAVES:2)
Block(-3,10,1,LEAVES:2)
Block(1,8,3,LEAVES:2)
Block(-3,11,1,LEAVES:2)
Block(1,7,3,LEAVES:2)
Block(1,6,3,LEAVES:2)
Block(1,5,3,LEAVES:2)
Block(-3,14,1,LEAVES:2)
Block(1,4,3,LEAVES:2)
Block(1,9,-5,LEAVES:2)
Block(1,8,-5,LEAVES:2)
Block(2,9,1,LEAVES:2)
Block(2,6,1,LEAVES:2)
Block(2,5,1,LEAVES:2)
Block(-3,9,1,LEAVES:2)
Block(2,8,1,LEAVES:2)
Block(2,7,1,LEAVES:2)
Block(-3,6,1,LOG:2)
Block(-1,11,3,LEAVES:2)
Block(-1,10,3,LEAVES:2)
Block(-3,8,1,LEAVES:2)
Block(0,11,-2,LEAVES:2)
Block(-1,13,3,LEAVES:2)
Block(-3,7,1,LEAVES:2)
Block(0,10,-2,LEAVES:2)
Block(-1,12,3,LEAVES:2)
Block(0,13,-2,LEAVES:2)
Block(0,12,-2,LEAVES:2)
Block(-1,14,3,LEAVES:2)
Block(-2,9,3,LEAVES:2)
Block(-2,8,3,LOG:2)
Block(-2,7,3,LEAVES:2)
Block(-1,8,5,LEAVES:2)
Block(-2,6,3,LEAVES:2)
Block(-1,7,5,LEAVES:2)
Block(2,5,0,LEAVES:2)
Block(-2,5,3,LEAVES:2)
Block(-2,10,8,LEAVES:2)
Block(3,11,-1,LEAVES:2)
Block(-2,11,8,LEAVES:2)
Block(1,10,-2,LOG:2)
Block(-5,10,0,LEAVES:2)
Block(1,11,-2,LEAVES:2)
Block(3,12,-1,LEAVES:2)
Block(1,12,-2,LEAVES:2)
Block(1,13,-2,LEAVES:2)
Block(1,4,2,LEAVES:2)
Block(0,5,4,LOG:2)
Block(0,7,4,LEAVES:2)
Block(0,6,4,LEAVES:2)
Block(0,8,4,LEAVES:2)

#######################################################################
# +-----------------------------------------------------------------+ #
# |                            BO3 checks                           | #
# +-----------------------------------------------------------------+ #
#######################################################################

BlockCheck(0,-1,0,GRASS,DIRT:0,DIRT:1,DIRT:2,biomesoplenty:grass:0,biomesoplenty:grass:1,biomesoplenty:grass,biomesoplenty:grass:3,biomesoplenty:grass:4,biomesoplenty:grass:5,biomesoplenty:grass:6,biomesoplenty:grass:7,biomesoplenty:dirt,biomesoplenty:dirt:1,biomesoplenty:dirt:2,biomesoplenty:dirt:8,biomesoplenty:dirt:9,biomesoplenty:dirt:10,biomesoplenty:dried_sand,biomesoplenty:hard_ice,biomesoplenty:white_sand,biomesoplenty:white_sandstone,biomesoplenty:mud,biomesoplenty:ash_block)

#######################################################################
# +-----------------------------------------------------------------+ #
# |                             Branches                            | #
# +-----------------------------------------------------------------+ #
#######################################################################


#######################################################################
# +-----------------------------------------------------------------+ #
# |                             Entities                            | #
# +-----------------------------------------------------------------+ #
#######################################################################


#######################################################################
# +-----------------------------------------------------------------+ #
# |                            Particles                            | #
# +-----------------------------------------------------------------+ #
#######################################################################


#######################################################################
# +-----------------------------------------------------------------+ #
# |                             Spawners                            | #
# +-----------------------------------------------------------------+ #
#######################################################################


#######################################################################
# +-----------------------------------------------------------------+ #
# |                             ModData                             | #
# +-----------------------------------------------------------------+ #
#######################################################################

