
#######################################################################
# +-----------------------------------------------------------------+ #
# |                            BO3 object                           | #
# +-----------------------------------------------------------------+ #
#######################################################################

# This is the config file of a custom object.
# If you add this object correctly to your BiomeConfigs, it will spawn in the world.

# This is the creator of this BO3 object
Author: LordSmellyPants

# A short description of this BO3 object
Description: No description given

# The BO3 version, don't change this! It can be used by external applications to do a version check.
Version: 3

# The settings mode, WriteAll, WriteWithoutComments or WriteDisable. See WorldConfig.
SettingsMode: WriteDisable


#######################################################################
# +-----------------------------------------------------------------+ #
# |                          Main settings                          | #
# +-----------------------------------------------------------------+ #
#######################################################################

# This needs to be set to true to spawn the object in the Tree and Sapling resources.
Tree: false

# The frequency of the BO3 from 1 to 200. Tries this many times to spawn this BO3 when using the CustomObject(...) resource.
# Ignored by Tree(..), Sapling(..) and CustomStructure(..)
Frequency: 1

# The rarity of the BO3 from 0 to 100. Each spawn attempt has rarity% chance to succeed when using the CustomObject(...) resource.
# Ignored by Tree(..), Sapling(..) and CustomStructure(..)
Rarity: 100.0

# If you set this to true, the BO3 will be placed with a random rotation.
RotateRandomly: true

# The spawn height of the BO3 - atMinY, randomY, highestBlock or highestSolidBlock.
SpawnHeight: highestSolidBlock

# The offset from the spawn height to spawn this BO3
# Ex. SpawnHeight = highestSolidBlock, SpawnHeightOffset = 3; This object will spawn 3 blocks above the highest solid block
SpawnHeightOffset: 0

# A random amount to offset the spawn location from the spawn offset height
# Ex. SpawnHeightOffset = 3, SpawnHeightVariance = 3; This object will spawn 3 to 6 blocks above the original spot it would have spawned
SpawnHeightVariance: 0

##############################
# Height Limits for the BO3. #
##############################


MinHeight: 0

MaxHeight: 256

######################
# Extrusion settings #
######################

# The style of extrusion you wish to use - BottomDown, TopUp, None (Default)
ExtrudeMode: None

# The blocks to extrude your BO3 through
ExtrudeThroughBlocks: AIR

# Objects can have other objects attacthed to it: branches. Branches can also
# have branches attached to it, which can also have branches, etc. This is the
# maximum branch depth for this objects.
MaxBranchDepth: 10

# When spawned with the UseWorld keyword, this BO3 should NOT spawn in the following biomes.
# If you write the BO3 name directly in the BiomeConfigs, this will be ignored.
ExcludedBiomes: All


#######################################################################
# +-----------------------------------------------------------------+ #
# |                      Source block settings                      | #
# +-----------------------------------------------------------------+ #
#######################################################################

# The B(s) the BO3 should spawn in.
SourceBlocks: STONE:1,STONE:3,STONE:5,DIRT:1,GRASS,DIRT,STONE,GRAVEL,SAND,CLAY,HARD_CLAY,159:14,159,175,175:1,175:2,175:3,175:4,175:5,31,31:1,31:2,1:1,1:5,1:3,AIR,SANDSTONE

# The maximum percentage of the BO3 that can be outside the SourceBlock.
# The BO3 won't be placed on a location with more blocks outside the SourceBlock than this percentage.
MaxPercentageOutsideSourceBlock: 30

# What to do when a block is about to be placed outside the SourceBlock? (dontPlace, placeAnyway)
OutsideSourceBlock: placeAnyway


#######################################################################
# +-----------------------------------------------------------------+ #
# |                              Blocks                             | #
# +-----------------------------------------------------------------+ #
#######################################################################

# All the blocks used in the BO3 are listed here. Possible blocks:
# B(x,y,z,id[.data][,nbtfile.nbt)
# RB(x,y,z,id[:data][,nbtfile.nbt],chance[,id[:data][,nbtfile.nbt],chance[,...]])
#  So RB(0,0,0,CHEST,chest.nbt,50,CHEST,anotherchest.nbt,100) will spawn a chest at
#  the BO3 origin, and give it a 50% chance to have the contents of chest.nbt, or, if that
#  fails, a 100% percent chance to have the contents of anotherchest.nbt.
# MinecraftObject(x,y,z,name)
#  Spawns an object in the Mojang NBT structure format. For example, 
#  MinecraftObject(0,0,0,minecraft:igloo/igloo_bottom)
#  spawns the bottom part of an igloo.
B(-7,-5,1,DIRT)
B(-7,-5,2,DIRT)
B(-7,-4,0,DIRT)
B(-7,-4,1,DIRT)
B(-7,-4,2,DIRT)
B(-7,-4,3,DIRT)
B(-7,-4,4,DIRT)
B(-7,-3,0,DIRT)
B(-7,-3,1,DIRT)
B(-7,-3,2,DIRT)
B(-7,-3,3,DIRT)
B(-7,-3,4,GRASS)
B(-7,-2,0,GRASS)
B(-7,-2,1,GRASS)
B(-7,-2,2,GRASS)
B(-7,-2,3,GRASS)
B(-6,-5,-1,DIRT)
B(-6,-5,0,DIRT)
B(-6,-5,1,DIRT)
B(-6,-5,2,DIRT)
B(-6,-5,3,DIRT)
B(-6,-5,4,DIRT)
B(-6,-4,-2,DIRT)
B(-6,-4,-1,DIRT)
B(-6,-4,0,DIRT)
B(-6,-4,1,DIRT)
B(-6,-4,2,DIRT)
B(-6,-4,3,DIRT)
B(-6,-4,4,DIRT)
B(-6,-4,5,DIRT)
B(-6,-3,-2,DIRT)
B(-6,-3,-1,DIRT)
B(-6,-3,0,DIRT)
B(-6,-3,1,DIRT)
B(-6,-3,2,DIRT)
B(-6,-3,3,DIRT)
B(-6,-3,4,DIRT)
B(-6,-3,5,DIRT)
B(-6,-2,-2,GRASS)
B(-6,-2,-1,GRASS)
B(-6,-2,0,GRASS)
B(-6,-2,1,GRASS)
B(-6,-2,2,GRASS)
B(-6,-2,3,GRASS)
B(-6,-2,4,GRASS)
B(-6,-2,5,GRASS)
B(-5,-6,3,STONE)
B(-5,-6,4,STONE)
B(-5,-6,5,STONE)
B(-5,-5,-2,DIRT)
B(-5,-5,-1,STONE)
B(-5,-5,0,STONE)
B(-5,-5,1,STONE)
B(-5,-5,2,STONE)
B(-5,-5,3,STONE)
B(-5,-5,4,SMOOTH_BRICK)
B(-5,-5,5,DIRT)
B(-5,-4,-3,DIRT)
B(-5,-4,-2,DIRT)
B(-5,-4,-1,DIRT)
B(-5,-4,0,DIRT)
B(-5,-4,1,DIRT)
B(-5,-4,2,DIRT)
B(-5,-4,3,DIRT)
B(-5,-4,4,DIRT)
B(-5,-4,5,DIRT)
B(-5,-4,6,DIRT)
B(-5,-3,-3,DIRT)
B(-5,-3,-2,DIRT)
B(-5,-3,-1,DIRT)
B(-5,-3,0,AIR)
B(-5,-3,1,DIRT)
B(-5,-3,2,DIRT)
B(-5,-3,3,SMOOTH_BRICK)
B(-5,-3,4,DIRT)
B(-5,-3,5,DIRT)
B(-5,-3,6,DIRT)
B(-5,-2,-3,GRASS)
B(-5,-2,-2,GRASS)
B(-5,-2,-1,DIRT)
B(-5,-2,0,DIRT)
B(-5,-2,1,DIRT)
B(-5,-2,2,DIRT)
B(-5,-2,3,DIRT)
B(-5,-2,4,DIRT)
B(-5,-2,5,GRASS)
B(-5,-2,6,GRASS)
B(-5,-1,-1,GRASS)
B(-5,-1,0,GRASS)
B(-5,-1,1,GRASS)
B(-5,-1,2,GRASS)
B(-5,-1,3,GRASS)
B(-5,-1,4,GRASS)
B(-4,-7,2,STONE)
B(-4,-7,3,STONE)
B(-4,-7,4,STONE)
B(-4,-7,5,STONE)
B(-4,-6,-3,STONE)
B(-4,-6,-2,STONE)
B(-4,-6,-1,STONE)
B(-4,-6,0,STONE)
B(-4,-6,1,STONE)
B(-4,-6,2,STONE)
B(-4,-6,3,STONE)
B(-4,-6,4,STONE)
B(-4,-6,5,STONE)
B(-4,-6,6,STONE)
B(-4,-5,-3,STONE)
B(-4,-5,-2,STONE)
B(-4,-5,-1,SMOOTH_BRICK)
B(-4,-5,0,SMOOTH_BRICK)
B(-4,-5,1,SMOOTH_BRICK)
B(-4,-5,2,SMOOTH_BRICK)
B(-4,-5,3,SMOOTH_BRICK)
B(-4,-5,4,SMOOTH_BRICK)
B(-4,-5,5,SMOOTH_BRICK)
B(-4,-5,6,STONE)
B(-4,-5,7,DIRT)
B(-4,-4,-3,DIRT)
B(-4,-4,-2,DIRT)
B(-4,-4,-1,SMOOTH_BRICK)
B(-4,-4,0,SMOOTH_BRICK)
B(-4,-4,1,SMOOTH_BRICK)
B(-4,-4,2,SMOOTH_BRICK)
B(-4,-4,3,SMOOTH_BRICK)
B(-4,-4,4,SMOOTH_BRICK)
B(-4,-4,5,DIRT)
B(-4,-4,6,DIRT)
B(-4,-4,7,DIRT)
B(-4,-3,-3,DIRT)
B(-4,-3,-2,DIRT)
B(-4,-3,-1,SMOOTH_BRICK)
B(-4,-3,0,SMOOTH_BRICK)
B(-4,-3,1,SMOOTH_BRICK)
B(-4,-3,2,SMOOTH_BRICK)
B(-4,-3,3,SMOOTH_BRICK)
B(-4,-3,4,SMOOTH_BRICK)
B(-4,-3,5,DIRT)
B(-4,-3,6,DIRT)
B(-4,-3,7,DIRT)
B(-4,-3,8,DIRT)
B(-4,-2,-6,GRASS)
B(-4,-2,-5,GRASS)
B(-4,-2,-4,GRASS)
B(-4,-2,-3,DIRT)
B(-4,-2,-2,DIRT)
B(-4,-2,-1,DIRT)
B(-4,-2,0,DIRT)
B(-4,-2,1,DIRT)
B(-4,-2,2,DIRT)
B(-4,-2,3,SMOOTH_BRICK)
B(-4,-2,4,DIRT)
B(-4,-2,5,DIRT)
B(-4,-2,6,DIRT)
B(-4,-2,7,GRASS)
B(-4,-2,8,GRASS)
B(-4,-1,-3,GRASS)
B(-4,-1,-2,GRASS)
B(-4,-1,-1,GRASS)
B(-4,-1,0,GRASS)
B(-4,-1,1,GRASS)
B(-4,-1,2,GRASS)
B(-4,-1,3,DIRT)
B(-4,-1,4,GRASS)
B(-4,-1,5,GRASS)
B(-4,-1,6,GRASS)
B(-4,0,3,GRASS)
B(-3,-8,0,STONE)
B(-3,-8,2,STONE)
B(-3,-8,4,STONE)
B(-3,-8,5,STONE)
B(-3,-8,6,STONE)
B(-3,-7,-2,STONE)
B(-3,-7,-1,STONE)
B(-3,-7,0,STONE)
B(-3,-7,1,STONE)
B(-3,-7,2,STONE)
B(-3,-7,3,STONE)
B(-3,-7,4,STONE)
B(-3,-7,5,STONE)
B(-3,-7,6,STONE)
B(-3,-6,-4,STONE)
B(-3,-6,-3,STONE)
B(-3,-6,-2,STONE)
B(-3,-6,-1,STONE)
B(-3,-6,0,SMOOTH_BRICK)
B(-3,-6,1,SMOOTH_BRICK)
B(-3,-6,2,STONE)
B(-3,-6,3,SMOOTH_BRICK)
B(-3,-6,4,SMOOTH_BRICK)
B(-3,-6,5,STONE)
B(-3,-6,6,STONE)
B(-3,-5,-4,STONE)
B(-3,-5,-3,STONE)
B(-3,-5,-2,SMOOTH_BRICK)
B(-3,-5,-1,WOOD:5)
B(-3,-5,0,WOOD_STEP:13)
B(-3,-5,1,WOOD_STEP:13)
B(-3,-5,2,WOOD:5)
B(-3,-5,3,WOOD_STEP:13)
B(-3,-5,4,WOOD_STEP:13)
B(-3,-5,5,WOOD:5)
B(-3,-5,6,SMOOTH_BRICK)
B(-3,-5,7,STONE)
B(-3,-4,-4,DIRT)
B(-3,-4,-3,DIRT)
B(-3,-4,-2,SMOOTH_BRICK)
B(-3,-4,-1,WOOD:5)
B(-3,-4,0,HAY_BLOCK)
B(-3,-4,1,JACK_O_LANTERN:3)
B(-3,-4,2,WOOD:5)
B(-3,-4,3,MELON_BLOCK)
B(-3,-4,4,HAY_BLOCK)
B(-3,-4,5,WOOD:5)
B(-3,-4,6,SMOOTH_BRICK)
B(-3,-4,7,DIRT)
B(-3,-4,8,DIRT)
B(-3,-3,-6,DIRT)
B(-3,-3,-5,DIRT)
B(-3,-3,-4,DIRT)
B(-3,-3,-3,DIRT)
B(-3,-3,-2,SMOOTH_BRICK)
B(-3,-3,-1,WOOD:5)
B(-3,-3,0,WOOD_STEP:13)
B(-3,-3,1,WOOD_STEP:13)
B(-3,-3,2,WOOD:5)
B(-3,-3,3,WOOD_STEP:13)
B(-3,-3,4,WOOD_STEP:13)
B(-3,-3,5,WOOD:5)
B(-3,-3,6,SMOOTH_BRICK)
B(-3,-3,7,DIRT)
B(-3,-3,8,DIRT)
B(-3,-3,9,DIRT)
B(-3,-2,-8,GRASS)
B(-3,-2,-7,GRASS)
B(-3,-2,-6,GRASS)
B(-3,-2,-5,DIRT)
B(-3,-2,-4,DIRT)
B(-3,-2,-3,DIRT)
B(-3,-2,-2,SMOOTH_BRICK)
B(-3,-2,-1,SMOOTH_BRICK)
B(-3,-2,0,SMOOTH_BRICK)
B(-3,-2,1,SMOOTH_BRICK)
B(-3,-2,2,SMOOTH_BRICK)
B(-3,-2,3,SMOOTH_BRICK)
B(-3,-2,4,SMOOTH_BRICK)
B(-3,-2,5,SMOOTH_BRICK)
B(-3,-2,6,SMOOTH_BRICK)
B(-3,-2,7,DIRT)
B(-3,-2,8,DIRT)
B(-3,-2,9,GRASS)
B(-3,-1,-5,GRASS)
B(-3,-1,-4,GRASS)
B(-3,-1,-3,GRASS)
B(-3,-1,-2,GRASS)
B(-3,-1,-1,GRASS)
B(-3,-1,0,GRASS)
B(-3,-1,1,GRASS)
B(-3,-1,2,GRASS)
B(-3,-1,3,DIRT)
B(-3,-1,4,DIRT)
B(-3,-1,5,DIRT)
B(-3,-1,6,GRASS)
B(-3,-1,7,GRASS)
B(-3,-1,8,GRASS)
B(-3,0,3,GRASS)
B(-3,0,4,GRASS)
B(-3,0,5,GRASS)
B(-2,-9,4,STONE)
B(-2,-8,-2,STONE)
B(-2,-8,-1,STONE)
B(-2,-8,0,STONE)
B(-2,-8,1,STONE)
B(-2,-8,2,STONE)
B(-2,-8,3,STONE)
B(-2,-8,4,STONE)
B(-2,-8,5,STONE)
B(-2,-8,6,STONE)
B(-2,-7,-3,STONE)
B(-2,-7,-2,STONE)
B(-2,-7,-1,STONE)
B(-2,-7,0,STONE)
B(-2,-7,1,STONE)
B(-2,-7,2,STONE)
B(-2,-7,3,STONE)
B(-2,-7,4,STONE)
B(-2,-7,5,STONE)
B(-2,-7,6,STONE)
B(-2,-7,7,STONE)
B(-2,-6,-5,STONE)
B(-2,-6,-4,STONE)
B(-2,-6,-3,STONE)
B(-2,-6,-2,COBBLESTONE)
B(-2,-6,-1,COBBLESTONE)
B(-2,-6,0,COBBLESTONE)
B(-2,-6,1,COBBLESTONE)
B(-2,-6,2,COBBLESTONE)
B(-2,-6,3,COBBLESTONE)
B(-2,-6,4,COBBLESTONE)
B(-2,-6,5,COBBLESTONE)
B(-2,-6,6,COBBLESTONE)
B(-2,-6,7,STONE)
B(-2,-5,-5,STONE)
B(-2,-5,-4,STONE)
B(-2,-5,-3,SMOOTH_BRICK)
B(-2,-5,-2,AIR)
B(-2,-5,-1,AIR)
B(-2,-5,0,AIR)
B(-2,-5,1,AIR)
B(-2,-5,2,AIR)
B(-2,-5,3,AIR)
B(-2,-5,4,AIR)
B(-2,-5,5,AIR)
B(-2,-5,6,LOG:4)
B(-2,-5,7,SMOOTH_BRICK)
B(-2,-5,8,STONE)
B(-2,-5,9,STONE)
B(-2,-4,-6,DIRT)
B(-2,-4,-5,STONE)
B(-2,-4,-4,STONE)
B(-2,-4,-3,SMOOTH_BRICK)
B(-2,-4,-2,AIR)
B(-2,-4,-1,AIR)
B(-2,-4,0,AIR)
B(-2,-4,1,AIR)
B(-2,-4,2,AIR)
B(-2,-4,3,AIR)
B(-2,-4,4,AIR)
B(-2,-4,5,AIR)
B(-2,-4,6,AIR)
B(-2,-4,7,SMOOTH_BRICK)
B(-2,-4,8,DIRT)
B(-2,-4,9,DIRT)
B(-2,-3,-8,DIRT)
B(-2,-3,-7,DIRT)
B(-2,-3,-6,DIRT)
B(-2,-3,-5,DIRT)
B(-2,-3,-4,DIRT)
B(-2,-3,-3,SMOOTH_BRICK)
B(-2,-3,-2,AIR)
B(-2,-3,-1,AIR)
B(-2,-3,0,AIR)
B(-2,-3,1,AIR)
B(-2,-3,2,AIR)
B(-2,-3,3,AIR)
B(-2,-3,4,AIR)
B(-2,-3,5,AIR)
B(-2,-3,6,AIR)
B(-2,-3,7,SMOOTH_BRICK)
B(-2,-3,8,DIRT)
B(-2,-3,9,DIRT)
B(-2,-3,10,DIRT)
B(-2,-3,11,DIRT)
B(-2,-3,12,DIRT)
B(-2,-2,-9,GRASS)
B(-2,-2,-8,DIRT)
B(-2,-2,-7,DIRT)
B(-2,-2,-6,DIRT)
B(-2,-2,-5,DIRT)
B(-2,-2,-4,DIRT)
B(-2,-2,-3,SMOOTH_BRICK)
B(-2,-2,-2,STEP:13)
B(-2,-2,-1,STEP:13)
B(-2,-2,0,STEP:13)
B(-2,-2,1,STEP:13)
B(-2,-2,2,STEP:13)
B(-2,-2,3,STEP:13)
B(-2,-2,4,STEP:13)
B(-2,-2,5,STEP:13)
B(-2,-2,6,STEP:13)
B(-2,-2,7,SMOOTH_BRICK)
B(-2,-2,8,DIRT)
B(-2,-2,9,DIRT)
B(-2,-2,10,GRASS)
B(-2,-2,11,GRASS)
B(-2,-2,12,GRASS)
B(-2,-1,-8,GRASS)
B(-2,-1,-7,GRASS)
B(-2,-1,-6,GRASS)
B(-2,-1,-5,DIRT)
B(-2,-1,-4,DIRT)
B(-2,-1,-3,COBBLESTONE)
B(-2,-1,-2,GRASS)
B(-2,-1,-1,GRASS)
B(-2,-1,0,GRASS)
B(-2,-1,1,GRASS)
B(-2,-1,2,COBBLESTONE)
B(-2,-1,3,DIRT)
B(-2,-1,4,DIRT)
B(-2,-1,5,DIRT)
B(-2,-1,6,DIRT)
B(-2,-1,7,DIRT)
B(-2,-1,8,GRASS)
B(-2,-1,9,GRASS)
B(-2,0,-5,GRASS)
B(-2,0,-4,GRASS)
B(-2,0,3,GRASS)
B(-2,0,4,GRASS)
B(-2,0,5,GRASS)
B(-2,0,6,GRASS)
B(-2,0,7,GRASS)
B(-1,-10,0,STONE)
B(-1,-10,2,STONE)
B(-1,-10,3,STONE)
B(-1,-10,4,STONE)
B(-1,-9,-2,STONE)
B(-1,-9,-1,STONE)
B(-1,-9,0,STONE)
B(-1,-9,1,STONE)
B(-1,-9,2,STONE)
B(-1,-9,3,STONE)
B(-1,-9,4,STONE)
B(-1,-9,5,STONE)
B(-1,-8,-3,STONE)
B(-1,-8,-2,STONE)
B(-1,-8,-1,STONE)
B(-1,-8,0,STONE)
B(-1,-8,1,STONE)
B(-1,-8,2,STONE)
B(-1,-8,3,STONE)
B(-1,-8,4,STONE)
B(-1,-8,5,STONE)
B(-1,-8,6,STONE)
B(-1,-7,-4,STONE)
B(-1,-7,-3,STONE)
B(-1,-7,-2,STONE)
B(-1,-7,-1,STONE)
B(-1,-7,0,STONE)
B(-1,-7,1,STONE)
B(-1,-7,2,STONE)
B(-1,-7,3,STONE)
B(-1,-7,4,STONE)
B(-1,-7,5,STONE)
B(-1,-7,6,STONE)
B(-1,-7,8,STONE)
B(-1,-6,-5,STONE)
B(-1,-6,-4,STONE)
B(-1,-6,-3,STONE)
B(-1,-6,-2,COBBLESTONE)
B(-1,-6,-1,COBBLESTONE)
B(-1,-6,0,COBBLESTONE)
B(-1,-6,1,COBBLESTONE)
B(-1,-6,2,COBBLESTONE)
B(-1,-6,3,COBBLESTONE)
B(-1,-6,4,COBBLESTONE)
B(-1,-6,5,COBBLESTONE)
B(-1,-6,6,COBBLESTONE)
B(-1,-6,7,STONE)
B(-1,-6,8,STONE)
B(-1,-6,9,STONE)
B(-1,-5,-7,STONE)
B(-1,-5,-5,STONE)
B(-1,-5,-4,STONE)
B(-1,-5,-3,WOOD:5)
B(-1,-5,-2,AIR)
B(-1,-5,-1,AIR)
B(-1,-5,0,AIR)
B(-1,-5,1,AIR)
B(-1,-5,2,AIR)
B(-1,-5,3,AIR)
B(-1,-5,4,AIR)
B(-1,-5,5,LOG:4)
B(-1,-5,6,LOG:4)
B(-1,-5,7,SMOOTH_BRICK)
B(-1,-5,8,STONE)
B(-1,-5,9,STONE)
B(-1,-5,10,STONE)
B(-1,-4,-7,STONE)
B(-1,-4,-6,STONE)
B(-1,-4,-5,STONE)
B(-1,-4,-4,STONE)
B(-1,-4,-3,WOOD:5)
B(-1,-4,-2,AIR)
B(-1,-4,-1,AIR)
B(-1,-4,0,AIR)
B(-1,-4,1,AIR)
B(-1,-4,2,AIR)
B(-1,-4,3,AIR)
B(-1,-4,4,AIR)
B(-1,-4,5,AIR)
B(-1,-4,6,LOG:4)
B(-1,-4,7,SMOOTH_BRICK)
B(-1,-4,8,STONE)
B(-1,-4,9,DIRT)
B(-1,-4,10,DIRT)
B(-1,-4,11,DIRT)
B(-1,-3,-9,DIRT)
B(-1,-3,-8,DIRT)
B(-1,-3,-7,DIRT)
B(-1,-3,-6,DIRT)
B(-1,-3,-5,DIRT)
B(-1,-3,-4,DIRT)
B(-1,-3,-3,WOOD:5)
B(-1,-3,-2,AIR)
B(-1,-3,-1,AIR)
B(-1,-3,0,AIR)
B(-1,-3,1,AIR)
B(-1,-3,2,AIR)
B(-1,-3,3,AIR)
B(-1,-3,4,AIR)
B(-1,-3,5,AIR)
B(-1,-3,6,AIR)
B(-1,-3,7,SMOOTH_BRICK)
B(-1,-3,8,DIRT)
B(-1,-3,9,DIRT)
B(-1,-3,10,DIRT)
B(-1,-3,11,DIRT)
B(-1,-3,12,DIRT)
B(-1,-3,13,DIRT)
B(-1,-2,-10,GRASS)
B(-1,-2,-9,DIRT)
B(-1,-2,-8,DIRT)
B(-1,-2,-7,DIRT)
B(-1,-2,-6,DIRT)
B(-1,-2,-5,DIRT)
B(-1,-2,-4,DIRT)
B(-1,-2,-3,SMOOTH_BRICK)
B(-1,-2,-2,STEP:13)
B(-1,-2,-1,STEP:13)
B(-1,-2,0,STEP:13)
B(-1,-2,1,STEP:13)
B(-1,-2,2,STEP:13)
B(-1,-2,3,STEP:13)
B(-1,-2,4,STEP:13)
B(-1,-2,5,STEP:13)
B(-1,-2,6,STEP:13)
B(-1,-2,7,SMOOTH_BRICK)
B(-1,-2,8,DIRT)
B(-1,-2,9,DIRT)
B(-1,-2,10,DIRT)
B(-1,-2,11,DIRT)
B(-1,-2,12,GRASS)
B(-1,-2,13,GRASS)
B(-1,-1,-9,GRASS)
B(-1,-1,-8,GRASS)
B(-1,-1,-7,DIRT)
B(-1,-1,-6,DIRT)
B(-1,-1,-5,DIRT)
B(-1,-1,-4,DIRT)
B(-1,-1,-3,COBBLESTONE)
B(-1,-1,-2,GRASS)
B(-1,-1,-1,GRASS)
B(-1,-1,0,GRASS)
B(-1,-1,1,GRASS)
B(-1,-1,2,GRASS)
B(-1,-1,3,DIRT)
B(-1,-1,4,DIRT)
B(-1,-1,5,DIRT)
B(-1,-1,6,DIRT)
B(-1,-1,7,DIRT)
B(-1,-1,8,DIRT)
B(-1,-1,9,GRASS)
B(-1,-1,10,GRASS)
B(-1,-1,11,GRASS)
B(-1,0,-7,GRASS)
B(-1,0,-6,GRASS)
B(-1,0,-5,GRASS)
B(-1,0,-4,GRASS)
B(-1,0,-3,DARK_OAK_FENCE)
B(-1,0,3,GRASS)
B(-1,0,4,GRASS)
B(-1,0,5,GRASS)
B(-1,0,6,GRASS)
B(-1,0,7,GRASS)
B(-1,0,8,GRASS)
B(0,-10,-2,STONE)
B(0,-10,-1,STONE)
B(0,-10,0,STONE)
B(0,-10,1,STONE)
B(0,-10,2,STONE)
B(0,-10,3,STONE)
B(0,-10,4,STONE)
B(0,-10,5,STONE)
B(0,-9,-3,STONE)
B(0,-9,-2,STONE)
B(0,-9,-1,STONE)
B(0,-9,0,STONE)
B(0,-9,1,STONE)
B(0,-9,2,STONE)
B(0,-9,3,STONE)
B(0,-9,4,STONE)
B(0,-9,5,STONE)
B(0,-8,-4,STONE)
B(0,-8,-3,STONE)
B(0,-8,-2,STONE)
B(0,-8,-1,STONE)
B(0,-8,0,STONE)
B(0,-8,1,STONE)
B(0,-8,2,STONE)
B(0,-8,3,STONE)
B(0,-8,4,STONE)
B(0,-8,5,STONE)
B(0,-8,6,STONE)
B(0,-7,-5,STONE)
B(0,-7,-4,STONE)
B(0,-7,-3,STONE)
B(0,-7,-2,STONE)
B(0,-7,-1,STONE)
B(0,-7,0,STONE)
B(0,-7,1,STONE)
B(0,-7,2,STONE)
B(0,-7,3,STONE)
B(0,-7,4,STONE)
B(0,-7,5,STONE)
B(0,-7,6,STONE)
B(0,-7,7,STONE)
B(0,-7,8,STONE)
B(0,-7,9,STONE)
B(0,-6,-6,STONE)
B(0,-6,-5,STONE)
B(0,-6,-4,STONE)
B(0,-6,-3,SMOOTH_BRICK)
B(0,-6,-2,COBBLESTONE)
B(0,-6,-1,COBBLESTONE)
B(0,-6,0,COBBLESTONE)
B(0,-6,1,COBBLESTONE)
B(0,-6,2,COBBLESTONE)
B(0,-6,3,COBBLESTONE)
B(0,-6,4,COBBLESTONE)
B(0,-6,5,COBBLESTONE)
B(0,-6,6,COBBLESTONE)
B(0,-6,7,STONE)
B(0,-6,8,STONE)
B(0,-6,9,STONE)
B(0,-5,-7,STONE)
B(0,-5,-6,STONE)
B(0,-5,-5,STONE)
B(0,-5,-4,SMOOTH_BRICK)
B(0,-5,-3,WOOD_STEP:13)
B(0,-5,-2,AIR)
B(0,-5,-1,AIR)
B(0,-5,0,AIR)
B(0,-5,1,AIR)
B(0,-5,2,AIR)
B(0,-5,3,AIR)
B(0,-5,4,RAILS:5)
B(0,-5,5,LOG:4)
B(0,-5,6,GOLD_BLOCK)
B(0,-5,7,STONE)
B(0,-5,8,STONE)
B(0,-5,9,STONE)
B(0,-5,10,STONE)
B(0,-4,-9,DIRT)
B(0,-4,-8,STONE)
B(0,-4,-7,STONE)
B(0,-4,-6,STONE)
B(0,-4,-5,AIR)
B(0,-4,-4,SMOOTH_BRICK)
B(0,-4,-3,HAY_BLOCK)
B(0,-4,-2,AIR)
B(0,-4,-1,AIR)
B(0,-4,0,AIR)
B(0,-4,1,AIR)
B(0,-4,2,AIR)
B(0,-4,3,AIR)
B(0,-4,4,AIR)
B(0,-4,5,RAILS:5)
B(0,-4,6,LOG:4)
B(0,-4,7,AIR)
B(0,-4,8,STONE)
B(0,-4,9,STONE)
B(0,-4,10,STONE)
B(0,-4,11,DIRT)
B(0,-4,12,DIRT)
B(0,-4,13,DIRT)
B(0,-3,-10,DIRT)
B(0,-3,-9,DIRT)
B(0,-3,-8,DIRT)
B(0,-3,-7,STONE)
B(0,-3,-6,DIRT)
B(0,-3,-5,AIR)
B(0,-3,-4,SMOOTH_BRICK)
B(0,-3,-3,WOOD_STEP:13)
B(0,-3,-2,AIR)
B(0,-3,-1,AIR)
B(0,-3,0,AIR)
B(0,-3,1,AIR)
B(0,-3,2,AIR)
B(0,-3,3,AIR)
B(0,-3,4,AIR)
B(0,-3,5,AIR)
B(0,-3,6,RAILS)
B(0,-3,7,SMOOTH_BRICK)
B(0,-3,8,DIRT)
B(0,-3,9,DIRT)
B(0,-3,10,DIRT)
B(0,-3,11,DIRT)
B(0,-3,12,DIRT)
B(0,-3,13,DIRT)
B(0,-3,14,DIRT)
B(0,-2,-11,GRASS)
B(0,-2,-10,DIRT)
B(0,-2,-9,DIRT)
B(0,-2,-8,DIRT)
B(0,-2,-7,DIRT)
B(0,-2,-6,DIRT)
B(0,-2,-5,DIRT)
B(0,-2,-4,DIRT)
B(0,-2,-3,SMOOTH_BRICK)
B(0,-2,-2,STEP:13)
B(0,-2,-1,STEP:13)
B(0,-2,0,STEP:13)
B(0,-2,1,STEP:13)
B(0,-2,2,STEP:13)
B(0,-2,3,STEP:13)
B(0,-2,4,STEP:13)
B(0,-2,5,STEP:13)
B(0,-2,6,STEP:13)
B(0,-2,7,SMOOTH_BRICK)
B(0,-2,8,DIRT)
B(0,-2,9,DIRT)
B(0,-2,10,DIRT)
B(0,-2,11,DIRT)
B(0,-2,12,DIRT)
B(0,-2,13,DIRT)
B(0,-2,14,GRASS)
B(0,-1,-10,GRASS)
B(0,-1,-9,GRASS)
B(0,-1,-8,DIRT)
B(0,-1,-7,DIRT)
B(0,-1,-6,DIRT)
B(0,-1,-5,DIRT)
B(0,-1,-4,DIRT)
B(0,-1,-3,DIRT)
B(0,-1,-2,COBBLESTONE)
B(0,-1,-1,DIRT)
B(0,-1,0,DIRT)
B(0,-1,1,GRASS)
B(0,-1,2,COBBLESTONE)
B(0,-1,3,DIRT)
B(0,-1,4,DIRT)
B(0,-1,5,DIRT)
B(0,-1,6,DIRT)
B(0,-1,7,DIRT)
B(0,-1,8,DIRT)
B(0,-1,9,DIRT)
B(0,-1,10,DIRT)
B(0,-1,11,GRASS)
B(0,-1,12,GRASS)
B(0,-1,13,GRASS)
B(0,0,-8,GRASS)
B(0,0,-7,DIRT)
B(0,0,-6,GRASS)
B(0,0,-5,GRASS)
B(0,0,-4,GRASS)
B(0,0,-3,AIR)
B(0,0,-2,AIR)
B(0,0,-1,AIR)
B(0,0,0,AIR)
B(0,0,1,AIR)
B(0,0,2,DARK_OAK_FENCE)
B(0,0,3,GRASS)
B(0,0,4,DIRT)
B(0,0,5,GRASS)
B(0,0,6,DIRT)
B(0,0,7,DIRT)
B(0,0,8,GRASS)
B(0,0,9,GRASS)
B(0,0,10,GRASS)
B(0,1,-7,GRASS)
B(0,1,-6,DARK_OAK_FENCE)
B(0,1,-4,AIR)
B(0,1,-3,AIR)
B(0,1,-2,AIR)
B(0,1,-1,AIR)
B(0,1,0,AIR)
B(0,1,1,AIR)
B(0,1,2,AIR)
B(0,1,3,AIR)
B(0,1,4,AIR)
B(0,1,5,DARK_OAK_FENCE)
B(0,1,6,GRASS)
B(0,1,7,GRASS)
B(0,2,-7,WOOD_STEP:5)
B(0,2,-6,WOOD:5)
B(0,2,-5,WOOD_STEP:13)
B(0,2,-2,AIR)
B(0,2,-1,AIR)
B(0,2,0,AIR)
B(0,2,1,AIR)
B(0,2,2,AIR)
B(0,2,4,WOOD_STEP:13)
B(0,2,5,WOOD_DOUBLE_STEP:5)
B(0,2,6,WOOD_STEP:5)
B(0,3,-6,DARK_OAK_FENCE)
B(0,3,-5,DARK_OAK_STAIRS:2)
B(0,3,-4,DARK_OAK_STAIRS:7)
B(0,3,-2,AIR)
B(0,3,-1,AIR)
B(0,3,0,AIR)
B(0,3,1,DARK_OAK_FENCE)
B(0,3,2,DARK_OAK_FENCE)
B(0,3,3,WOOD:5)
B(0,3,4,DARK_OAK_STAIRS)
B(0,3,5,DARK_OAK_FENCE)
B(0,4,-4,WOOD_DOUBLE_STEP:5)
B(0,4,-3,WOOD:5)
B(0,4,-2,DARK_OAK_FENCE)
B(0,4,-1,AIR)
B(0,4,0,WOOD_STEP:13)
B(0,4,1,WOOD_DOUBLE_STEP:5)
B(0,4,2,WOOD_DOUBLE_STEP:5)
B(0,4,3,WOOD_STEP:5)
B(0,5,-3,DARK_OAK_STAIRS:2)
B(0,5,-2,WOOD_DOUBLE_STEP:5)
B(0,5,-1,WOOD_DOUBLE_STEP:5)
B(0,5,0,DARK_OAK_STAIRS)
B(0,5,1,WOOD_STEP:5)
B(0,6,-2,DARK_OAK_STAIRS:2)
B(0,6,-1,DARK_OAK_STAIRS)
B(0,6,0,WOOD_STEP:5)
B(1,-10,-2,DIRT)
B(1,-10,-1,DIRT)
B(1,-10,0,DIRT)
B(1,-10,1,STONE)
B(1,-10,2,STONE)
B(1,-10,3,STONE)
B(1,-10,4,STONE)
B(1,-10,5,STONE)
B(1,-9,-3,STONE)
B(1,-9,-2,DIRT)
B(1,-9,-1,DIRT)
B(1,-9,0,DIRT)
B(1,-9,1,STONE)
B(1,-9,2,STONE)
B(1,-9,3,STONE)
B(1,-9,4,STONE)
B(1,-9,5,STONE)
B(1,-8,-4,STONE)
B(1,-8,-3,STONE)
B(1,-8,-2,DIRT)
B(1,-8,-1,DIRT)
B(1,-8,0,DIRT)
B(1,-8,1,STONE)
B(1,-8,2,STONE)
B(1,-8,3,STONE)
B(1,-8,4,STONE)
B(1,-8,5,STONE)
B(1,-8,6,STONE)
B(1,-7,-5,STONE)
B(1,-7,-4,STONE)
B(1,-7,-3,STONE)
B(1,-7,-2,DIRT)
B(1,-7,-1,DIRT)
B(1,-7,0,DIRT)
B(1,-7,1,STONE)
B(1,-7,2,STONE)
B(1,-7,3,STONE)
B(1,-7,4,STONE)
B(1,-7,5,STONE)
B(1,-7,6,STONE)
B(1,-7,8,STONE)
B(1,-7,9,STONE)
B(1,-6,-6,STONE)
B(1,-6,-5,STONE)
B(1,-6,-4,STONE)
B(1,-6,-3,SMOOTH_BRICK)
B(1,-6,-2,COBBLESTONE)
B(1,-6,-1,COBBLESTONE)
B(1,-6,0,COBBLESTONE)
B(1,-6,1,COBBLESTONE)
B(1,-6,2,COBBLESTONE)
B(1,-6,3,COBBLESTONE)
B(1,-6,4,COBBLESTONE)
B(1,-6,5,COBBLESTONE)
B(1,-6,6,COBBLESTONE)
B(1,-6,7,STONE)
B(1,-6,8,STONE)
B(1,-6,9,STONE)
B(1,-6,10,STONE)
B(1,-5,-9,STONE)
B(1,-5,-8,STONE)
B(1,-5,-7,STONE)
B(1,-5,-6,STONE)
B(1,-5,-5,STONE)
B(1,-5,-4,SMOOTH_BRICK)
B(1,-5,-3,WOOD_STEP:13)
B(1,-5,-2,AIR)
B(1,-5,-1,AIR)
B(1,-5,0,AIR)
B(1,-5,1,AIR)
B(1,-5,2,AIR)
B(1,-5,3,AIR)
B(1,-5,4,AIR)
B(1,-5,5,LOG:4)
B(1,-5,6,LOG:4)
B(1,-5,7,SMOOTH_BRICK)
B(1,-5,8,STONE)
B(1,-5,9,STONE)
B(1,-5,10,STONE)
B(1,-5,11,STONE)
B(1,-5,12,STONE)
B(1,-4,-9,STONE)
B(1,-4,-8,STONE)
B(1,-4,-7,STONE)
B(1,-4,-6,STONE)
B(1,-4,-5,STONE)
B(1,-4,-4,SMOOTH_BRICK)
B(1,-4,-3,HAY_BLOCK:8)
B(1,-4,-2,AIR)
B(1,-4,-1,AIR)
B(1,-4,0,AIR)
B(1,-4,1,AIR)
B(1,-4,2,AIR)
B(1,-4,3,AIR)
B(1,-4,4,AIR)
B(1,-4,5,AIR)
B(1,-4,6,LOG:4)
B(1,-4,7,SMOOTH_BRICK)
B(1,-4,8,STONE)
B(1,-4,9,STONE)
B(1,-4,10,STONE)
B(1,-4,11,STONE)
B(1,-4,12,STONE)
B(1,-4,13,DIRT)
B(1,-4,14,DIRT)
B(1,-3,-12,DIRT)
B(1,-3,-11,DIRT)
B(1,-3,-10,DIRT)
B(1,-3,-9,DIRT)
B(1,-3,-8,STONE)
B(1,-3,-7,STONE)
B(1,-3,-6,STONE)
B(1,-3,-5,STONE)
B(1,-3,-4,SMOOTH_BRICK)
B(1,-3,-3,WOOD_STEP:13)
B(1,-3,-2,AIR)
B(1,-3,-1,AIR)
B(1,-3,0,AIR)
B(1,-3,1,AIR)
B(1,-3,2,AIR)
B(1,-3,3,AIR)
B(1,-3,4,AIR)
B(1,-3,5,AIR)
B(1,-3,6,AIR)
B(1,-3,7,SMOOTH_BRICK)
B(1,-3,8,STONE)
B(1,-3,9,STONE)
B(1,-3,10,STONE)
B(1,-3,11,DIRT)
B(1,-3,12,DIRT)
B(1,-3,13,DIRT)
B(1,-3,14,DIRT)
B(1,-3,15,DIRT)
B(1,-2,-12,GRASS)
B(1,-2,-11,DIRT)
B(1,-2,-10,DIRT)
B(1,-2,-9,DIRT)
B(1,-2,-8,DIRT)
B(1,-2,-7,STONE)
B(1,-2,-6,STONE)
B(1,-2,-5,STONE)
B(1,-2,-4,DIRT)
B(1,-2,-3,SMOOTH_BRICK)
B(1,-2,-2,STEP:13)
B(1,-2,-1,STEP:13)
B(1,-2,0,STEP:13)
B(1,-2,1,STEP:13)
B(1,-2,2,STEP:13)
B(1,-2,3,STEP:13)
B(1,-2,4,STEP:13)
B(1,-2,5,STEP:13)
B(1,-2,6,STEP:13)
B(1,-2,7,SMOOTH_BRICK)
B(1,-2,8,DIRT)
B(1,-2,9,DIRT)
B(1,-2,10,DIRT)
B(1,-2,11,DIRT)
B(1,-2,12,DIRT)
B(1,-2,13,DIRT)
B(1,-2,14,DIRT)
B(1,-2,15,GRASS)
B(1,-1,-11,GRASS)
B(1,-1,-10,GRASS)
B(1,-1,-9,DIRT)
B(1,-1,-8,DIRT)
B(1,-1,-7,DIRT)
B(1,-1,-6,STONE)
B(1,-1,-5,STONE)
B(1,-1,-4,DIRT)
B(1,-1,-3,DIRT)
B(1,-1,-2,COBBLESTONE)
B(1,-1,-1,COBBLESTONE)
B(1,-1,0,COBBLESTONE)
B(1,-1,1,COBBLESTONE)
B(1,-1,2,DIRT)
B(1,-1,3,DIRT)
B(1,-1,4,DIRT)
B(1,-1,5,DIRT)
B(1,-1,6,DIRT)
B(1,-1,7,DIRT)
B(1,-1,8,DIRT)
B(1,-1,9,DIRT)
B(1,-1,10,DIRT)
B(1,-1,11,DIRT)
B(1,-1,12,DIRT)
B(1,-1,13,GRASS)
B(1,-1,14,GRASS)
B(1,0,-9,GRASS)
B(1,0,-8,DIRT)
B(1,0,-7,DIRT)
B(1,0,-6,DIRT)
B(1,0,-5,STONE)
B(1,0,-4,GRASS)
B(1,0,-3,GRASS)
B(1,0,-2,AIR)
B(1,0,-1,AIR)
B(1,0,0,AIR)
B(1,0,1,AIR)
B(1,0,2,GRASS)
B(1,0,3,DIRT)
B(1,0,4,DIRT)
B(1,0,5,GRASS)
B(1,0,6,DIRT)
B(1,0,7,DIRT)
B(1,0,8,DIRT)
B(1,0,9,DIRT)
B(1,0,10,DIRT)
B(1,0,11,GRASS)
B(1,0,12,GRASS)
B(1,1,-8,GRASS)
B(1,1,-7,DIRT)
B(1,1,-6,WOOD:5)
B(1,1,-4,AIR)
B(1,1,-3,AIR)
B(1,1,-2,AIR)
B(1,1,-1,AIR)
B(1,1,0,AIR)
B(1,1,1,AIR)
B(1,1,2,AIR)
B(1,1,3,AIR)
B(1,1,4,AIR)
B(1,1,5,DARK_OAK_FENCE)
B(1,1,6,GRASS)
B(1,1,7,GRASS)
B(1,1,8,GRASS)
B(1,1,9,GRASS)
B(1,1,10,GRASS)
B(1,2,-7,GRASS)
B(1,2,-6,WOOD:5)
B(1,2,-5,WOOD_STEP:13)
B(1,2,-3,AIR)
B(1,2,-2,AIR)
B(1,2,-1,AIR)
B(1,2,0,AIR)
B(1,2,1,AIR)
B(1,2,2,AIR)
B(1,2,3,AIR)
B(1,2,5,WOOD_DOUBLE_STEP:5)
B(1,2,6,WOOD_STEP:5)
B(1,3,-6,GRASS)
B(1,3,-5,WOOD:5)
B(1,3,-4,DARK_OAK_STAIRS:7)
B(1,3,-3,AIR)
B(1,3,-2,AIR)
B(1,3,-1,AIR)
B(1,3,0,AIR)
B(1,3,4,DARK_OAK_STAIRS)
B(1,3,5,DARK_OAK_FENCE)
B(1,4,-5,GRASS)
B(1,4,-4,WOOD:5)
B(1,4,-3,AIR)
B(1,4,-2,AIR)
B(1,4,-1,AIR)
B(1,4,0,AIR)
B(1,4,1,WOOD_DOUBLE_STEP:5)
B(1,4,2,WOOD_DOUBLE_STEP:5)
B(1,4,3,WOOD_DOUBLE_STEP:5)
B(1,5,-4,WOOD_STEP:5)
B(1,5,-3,DARK_OAK_STAIRS:2)
B(1,5,-2,AIR)
B(1,5,-1,AIR)
B(1,5,0,DARK_OAK_STAIRS)
B(1,5,1,WOOD_STEP:5)
B(1,5,2,WOOD_STEP:5)
B(1,6,-2,DARK_OAK_STAIRS:2)
B(1,6,-1,DARK_OAK_STAIRS)
B(1,6,0,WOOD_STEP:5)
B(2,-10,-3,STONE)
B(2,-10,-2,STONE)
B(2,-10,-1,STONE)
B(2,-10,0,STONE)
B(2,-10,1,STONE)
B(2,-10,2,STONE)
B(2,-10,3,STONE)
B(2,-10,4,STONE)
B(2,-10,5,STONE)
B(2,-10,6,STONE)
B(2,-9,-4,STONE)
B(2,-9,-3,STONE)
B(2,-9,-2,STONE)
B(2,-9,-1,STONE)
B(2,-9,0,STONE)
B(2,-9,1,STONE)
B(2,-9,2,STONE)
B(2,-9,3,STONE)
B(2,-9,4,STONE)
B(2,-9,5,STONE)
B(2,-9,6,STONE)
B(2,-8,-5,STONE)
B(2,-8,-4,STONE)
B(2,-8,-3,STONE)
B(2,-8,-2,STONE)
B(2,-8,-1,STONE)
B(2,-8,0,STONE)
B(2,-8,1,STONE)
B(2,-8,2,STONE)
B(2,-8,3,STONE)
B(2,-8,4,STONE)
B(2,-8,5,STONE)
B(2,-8,6,STONE)
B(2,-8,7,STONE)
B(2,-7,-6,STONE)
B(2,-7,-5,STONE)
B(2,-7,-4,STONE)
B(2,-7,-3,STONE)
B(2,-7,-2,STONE)
B(2,-7,-1,STONE)
B(2,-7,0,STONE)
B(2,-7,1,STONE)
B(2,-7,2,STONE)
B(2,-7,3,STONE)
B(2,-7,4,STONE)
B(2,-7,5,STONE)
B(2,-7,6,STONE)
B(2,-7,7,STONE)
B(2,-7,8,STONE)
B(2,-7,9,STONE)
B(2,-6,-9,STONE)
B(2,-6,-8,STONE)
B(2,-6,-7,STONE)
B(2,-6,-6,STONE)
B(2,-6,-5,STONE)
B(2,-6,-4,STONE)
B(2,-6,-3,SMOOTH_BRICK)
B(2,-6,-2,COBBLESTONE)
B(2,-6,-1,COBBLESTONE)
B(2,-6,0,COBBLESTONE)
B(2,-6,1,COBBLESTONE)
B(2,-6,2,COBBLESTONE)
B(2,-6,3,COBBLESTONE)
B(2,-6,4,COBBLESTONE)
B(2,-6,5,COBBLESTONE)
B(2,-6,6,COBBLESTONE)
B(2,-6,7,STONE)
B(2,-6,8,STONE)
B(2,-6,9,STONE)
B(2,-6,10,STONE)
B(2,-6,11,STONE)
B(2,-5,-10,STONE)
B(2,-5,-9,STONE)
B(2,-5,-8,STONE)
B(2,-5,-7,STONE)
B(2,-5,-6,STONE)
B(2,-5,-5,STONE)
B(2,-5,-4,SMOOTH_BRICK)
B(2,-5,-3,WOOD_STEP:13)
B(2,-5,-2,AIR)
B(2,-5,-1,AIR)
B(2,-5,0,AIR)
B(2,-5,1,AIR)
B(2,-5,2,AIR)
B(2,-5,3,AIR)
B(2,-5,4,RAILS:5)
B(2,-5,5,LOG:4)
B(2,-5,6,LOG:4)
B(2,-5,7,SMOOTH_BRICK)
B(2,-5,8,STONE)
B(2,-5,9,STONE)
B(2,-5,10,STONE)
B(2,-5,11,STONE)
B(2,-5,12,STONE)
B(2,-4,-10,STONE)
B(2,-4,-9,STONE)
B(2,-4,-8,STONE)
B(2,-4,-7,STONE)
B(2,-4,-6,STONE)
B(2,-4,-5,STONE)
B(2,-4,-4,SMOOTH_BRICK)
B(2,-4,-3,PUMPKIN:0)
B(2,-4,-2,AIR)
B(2,-4,-1,AIR)
B(2,-4,0,AIR)
B(2,-4,1,AIR)
B(2,-4,2,AIR)
B(2,-4,3,AIR)
B(2,-4,4,AIR)
B(2,-4,5,RAILS:5)
B(2,-4,6,LOG:4)
B(2,-4,7,SMOOTH_BRICK)
B(2,-4,8,STONE)
B(2,-4,9,STONE)
B(2,-4,10,STONE)
B(2,-4,11,STONE)
B(2,-4,12,STONE)
B(2,-4,13,STONE)
B(2,-4,14,DIRT)
B(2,-3,-11,DIRT)
B(2,-3,-10,DIRT)
B(2,-3,-9,STONE)
B(2,-3,-8,STONE)
B(2,-3,-7,STONE)
B(2,-3,-6,STONE)
B(2,-3,-5,STONE)
B(2,-3,-4,SMOOTH_BRICK)
B(2,-3,-3,WOOD_STEP:13)
B(2,-3,-2,AIR)
B(2,-3,-1,AIR)
B(2,-3,0,AIR)
B(2,-3,1,AIR)
B(2,-3,2,AIR)
B(2,-3,3,AIR)
B(2,-3,4,AIR)
B(2,-3,5,AIR)
B(2,-3,6,RAILS)
B(2,-3,7,SMOOTH_BRICK)
B(2,-3,8,STONE)
B(2,-3,9,STONE)
B(2,-3,10,STONE)
B(2,-3,11,STONE)
B(2,-3,12,DIRT)
B(2,-3,13,DIRT)
B(2,-3,14,DIRT)
B(2,-3,15,DIRT)
B(2,-2,-12,DIRT)
B(2,-2,-11,DIRT)
B(2,-2,-10,DIRT)
B(2,-2,-9,DIRT)
B(2,-2,-8,STONE)
B(2,-2,-7,STONE)
B(2,-2,-6,STONE)
B(2,-2,-5,STONE)
B(2,-2,-4,STONE)
B(2,-2,-3,SMOOTH_BRICK)
B(2,-2,-2,STEP:13)
B(2,-2,-1,STEP:13)
B(2,-2,0,STEP:13)
B(2,-2,1,STEP:13)
B(2,-2,2,STEP:13)
B(2,-2,3,STEP:13)
B(2,-2,4,STEP:13)
B(2,-2,5,STEP:13)
B(2,-2,6,STEP:13)
B(2,-2,7,SMOOTH_BRICK)
B(2,-2,8,STONE)
B(2,-2,9,STONE)
B(2,-2,10,DIRT)
B(2,-2,11,DIRT)
B(2,-2,12,DIRT)
B(2,-2,13,DIRT)
B(2,-2,14,DIRT)
B(2,-2,15,DIRT)
B(2,-1,-12,GRASS)
B(2,-1,-11,GRASS)
B(2,-1,-10,DIRT)
B(2,-1,-9,DIRT)
B(2,-1,-8,DIRT)
B(2,-1,-7,STONE)
B(2,-1,-6,STONE)
B(2,-1,-5,STONE)
B(2,-1,-4,STONE)
B(2,-1,-3,STONE)
B(2,-1,-2,STONE)
B(2,-1,-1,STONE)
B(2,-1,0,STONE)
B(2,-1,1,STONE)
B(2,-1,2,STONE)
B(2,-1,3,STONE)
B(2,-1,4,STONE)
B(2,-1,5,STONE)
B(2,-1,6,STONE)
B(2,-1,7,DIRT)
B(2,-1,8,DIRT)
B(2,-1,9,DIRT)
B(2,-1,10,DIRT)
B(2,-1,11,DIRT)
B(2,-1,12,DIRT)
B(2,-1,13,DIRT)
B(2,-1,14,GRASS)
B(2,-1,15,GRASS)
B(2,0,-10,GRASS)
B(2,0,-9,DIRT)
B(2,0,-8,DIRT)
B(2,0,-7,DIRT)
B(2,0,-6,STONE)
B(2,0,-5,STONE)
B(2,0,-4,STONE)
B(2,0,-3,STONE)
B(2,0,-2,DARK_OAK_STAIRS:0)
B(2,0,-1,DARK_OAK_STAIRS:0)
B(2,0,0,DARK_OAK_STAIRS:0)
B(2,0,1,AIR)
B(2,0,2,STONE)
B(2,0,3,STONE)
B(2,0,4,STONE)
B(2,0,5,GRASS)
B(2,0,6,DIRT)
B(2,0,7,DIRT)
B(2,0,8,DIRT)
B(2,0,9,DIRT)
B(2,0,10,DIRT)
B(2,0,11,DIRT)
B(2,0,12,GRASS)
B(2,0,13,GRASS)
B(2,1,-9,GRASS)
B(2,1,-8,DIRT)
B(2,1,-7,DIRT)
B(2,1,-6,WOOD:5)
B(2,1,-5,STONE)
B(2,1,-4,AIR)
RB(2,1,-3,FLOWER_POT,../../nbt/Misc/FlowerPot1.nbt,20,FLOWER_POT,../../nbt/Misc/FlowerPot2.nbt,20,FLOWER_POT,../../nbt/Misc/FlowerPot3.nbt,20,FLOWER_POT,../../nbt/Misc/FlowerPot8.nbt,20,FLOWER_POT,../../nbt/Misc/FlowerPot4.nbt,20,FLOWER_POT,../../nbt/Misc/FlowerPot5.nbt,20,FLOWER_POT,../../nbt/Misc/FlowerPot6.nbt,20,FLOWER_POT,../../nbt/Misc/FlowerPot7.nbt,20,FLOWER_POT,../../nbt/Misc/FlowerPot8.nbt,100)
B(2,1,-2,AIR)
B(2,1,-1,AIR)
B(2,1,0,AIR)
B(2,1,1,AIR)
B(2,1,2,AIR)
B(2,1,3,AIR)
B(2,1,4,AIR)
B(2,1,5,DARK_OAK_FENCE)
B(2,1,6,DIRT)
B(2,1,7,DIRT)
B(2,1,8,DIRT)
B(2,1,9,DIRT)
B(2,1,10,GRASS)
B(2,1,11,GRASS)
B(2,2,-8,GRASS)
B(2,2,-7,DIRT)
B(2,2,-6,WOOD:5)
B(2,2,-5,WOOD_STEP:13)
B(2,2,-4,AIR)
B(2,2,-3,AIR)
B(2,2,-2,AIR)
B(2,2,-1,AIR)
B(2,2,0,AIR)
B(2,2,1,AIR)
B(2,2,2,AIR)
B(2,2,3,AIR)
B(2,2,5,DARK_OAK_STAIRS:6)
B(2,2,6,DIRT)
B(2,2,7,GRASS)
B(2,2,8,GRASS)
B(2,2,9,GRASS)
B(2,3,-7,GRASS)
B(2,3,-6,DIRT)
B(2,3,-5,AIR)
B(2,3,-4,DARK_OAK_STAIRS:7)
B(2,3,-3,AIR)
B(2,3,-2,AIR)
B(2,3,-1,AIR)
B(2,3,0,AIR)
B(2,3,2,AIR)
B(2,3,3,AIR)
B(2,3,4,DARK_OAK_STAIRS:6)
B(2,3,5,GRASS)
B(2,3,6,GRASS)
B(2,4,-6,GRASS)
B(2,4,-5,DIRT)
B(2,4,-4,DIRT)
B(2,4,-3,DARK_OAK_STAIRS:7)
B(2,4,-2,AIR)
B(2,4,-1,AIR)
B(2,4,0,AIR)
B(2,4,2,WOOD_STEP:13)
B(2,4,3,WOOD_DOUBLE_STEP:5)
B(2,4,4,GRASS)
B(2,5,-5,GRASS)
B(2,5,-4,GRASS)
B(2,5,-3,DIRT)
B(2,5,-2,DARK_OAK_STAIRS:7)
B(2,5,-1,WOOD_STEP:13)
B(2,5,0,WOOD_STEP:13)
B(2,5,1,WOOD:5)
B(2,5,2,GRASS)
B(2,5,3,GRASS)
B(2,6,-3,GRASS)
B(2,6,-2,GRASS)
B(2,6,-1,GRASS)
B(2,6,0,GRASS)
B(2,6,1,GRASS)
B(3,-10,-3,STONE)
B(3,-10,-2,STONE)
B(3,-10,-1,STONE)
B(3,-10,0,STONE)
B(3,-10,1,STONE)
B(3,-10,2,STONE)
B(3,-10,3,STONE)
B(3,-10,4,STONE)
B(3,-10,5,STONE)
B(3,-10,6,STONE)
B(3,-10,7,STONE)
B(3,-9,-4,STONE)
B(3,-9,-3,STONE)
B(3,-9,-2,STONE)
B(3,-9,-1,STONE)
B(3,-9,0,STONE)
B(3,-9,1,STONE)
B(3,-9,2,STONE)
B(3,-9,3,STONE)
B(3,-9,4,STONE)
B(3,-9,5,STONE)
B(3,-9,6,STONE)
B(3,-9,7,STONE)
B(3,-9,8,STONE)
B(3,-8,-8,STONE)
B(3,-8,-6,STONE)
B(3,-8,-5,STONE)
B(3,-8,-4,STONE)
B(3,-8,-3,STONE)
B(3,-8,-2,STONE)
B(3,-8,-1,STONE)
B(3,-8,0,STONE)
B(3,-8,1,STONE)
B(3,-8,2,STONE)
B(3,-8,3,STONE)
B(3,-8,4,STONE)
B(3,-8,5,STONE)
B(3,-8,6,STONE)
B(3,-8,7,STONE)
B(3,-8,8,STONE)
B(3,-8,9,STONE)
B(3,-7,-9,STONE)
B(3,-7,-8,STONE)
B(3,-7,-7,STONE)
B(3,-7,-6,STONE)
B(3,-7,-5,STONE)
B(3,-7,-4,STONE)
B(3,-7,-3,STONE)
B(3,-7,-2,STONE)
B(3,-7,-1,STONE)
B(3,-7,0,STONE)
B(3,-7,1,STONE)
B(3,-7,2,STONE)
B(3,-7,3,STONE)
B(3,-7,4,STONE)
B(3,-7,5,STONE)
B(3,-7,6,STONE)
B(3,-7,7,STONE)
B(3,-7,8,STONE)
B(3,-7,9,STONE)
B(3,-7,10,STONE)
B(3,-6,-10,STONE)
B(3,-6,-9,STONE)
B(3,-6,-8,STONE)
B(3,-6,-7,STONE)
B(3,-6,-6,STONE)
B(3,-6,-5,STONE)
B(3,-6,-4,STONE)
B(3,-6,-3,STONE)
B(3,-6,-2,COBBLESTONE)
B(3,-6,-1,COBBLESTONE)
B(3,-6,0,COBBLESTONE)
B(3,-6,1,COBBLESTONE)
B(3,-6,2,COBBLESTONE)
B(3,-6,3,COBBLESTONE)
B(3,-6,4,COBBLESTONE)
B(3,-6,5,COBBLESTONE)
B(3,-6,6,COBBLESTONE)
B(3,-6,7,STONE)
B(3,-6,8,STONE)
B(3,-6,9,STONE)
B(3,-6,10,STONE)
B(3,-6,11,STONE)
B(3,-5,-11,STONE)
B(3,-5,-10,STONE)
B(3,-5,-9,STONE)
B(3,-5,-8,STONE)
B(3,-5,-7,STONE)
B(3,-5,-6,STONE)
B(3,-5,-5,STONE)
B(3,-5,-4,STONE)
B(3,-5,-3,WOOD:5)
B(3,-5,-2,AIR)
B(3,-5,-1,AIR)
B(3,-5,0,AIR)
B(3,-5,1,AIR)
B(3,-5,2,AIR)
B(3,-5,3,AIR)
B(3,-5,4,AIR)
B(3,-5,5,LOG:4)
B(3,-5,6,AIR)
B(3,-5,7,SMOOTH_BRICK)
B(3,-5,8,STONE)
B(3,-5,9,STONE)
B(3,-5,10,STONE)
B(3,-5,11,STONE)
B(3,-5,12,STONE)
B(3,-5,13,STONE)
B(3,-4,-11,STONE)
B(3,-4,-10,STONE)
B(3,-4,-9,STONE)
B(3,-4,-8,STONE)
B(3,-4,-7,STONE)
B(3,-4,-6,STONE)
B(3,-4,-5,STONE)
B(3,-4,-4,STONE)
B(3,-4,-3,WOOD:5)
B(3,-4,-2,AIR)
B(3,-4,-1,AIR)
B(3,-4,0,AIR)
B(3,-4,1,AIR)
B(3,-4,2,AIR)
B(3,-4,3,AIR)
B(3,-4,4,AIR)
B(3,-4,5,AIR)
B(3,-4,6,AIR)
B(3,-4,7,SMOOTH_BRICK)
B(3,-4,8,STONE)
B(3,-4,9,STONE)
B(3,-4,10,STONE)
B(3,-4,11,STONE)
B(3,-4,12,STONE)
B(3,-4,13,STONE)
B(3,-4,14,STONE)
B(3,-3,-12,DIRT)
B(3,-3,-11,DIRT)
B(3,-3,-10,STONE)
B(3,-3,-9,STONE)
B(3,-3,-8,STONE)
B(3,-3,-7,STONE)
B(3,-3,-6,STONE)
B(3,-3,-5,STONE)
B(3,-3,-4,STONE)
B(3,-3,-3,WOOD:5)
B(3,-3,-2,AIR)
B(3,-3,-1,AIR)
B(3,-3,0,AIR)
B(3,-3,1,AIR)
B(3,-3,2,AIR)
B(3,-3,3,AIR)
B(3,-3,4,AIR)
B(3,-3,5,AIR)
B(3,-3,6,AIR)
B(3,-3,7,SMOOTH_BRICK)
B(3,-3,8,STONE)
B(3,-3,9,STONE)
B(3,-3,10,STONE)
B(3,-3,11,STONE)
B(3,-3,12,STONE)
B(3,-3,13,DIRT)
B(3,-3,14,DIRT)
B(3,-3,15,DIRT)
B(3,-2,-13,GRASS)
B(3,-2,-12,DIRT)
B(3,-2,-11,DIRT)
B(3,-2,-10,DIRT)
B(3,-2,-9,DIRT)
B(3,-2,-8,STONE)
B(3,-2,-7,STONE)
B(3,-2,-6,STONE)
B(3,-2,-5,STONE)
B(3,-2,-4,STONE)
B(3,-2,-3,SMOOTH_BRICK)
B(3,-2,-2,STEP:13)
B(3,-2,-1,STEP:13)
B(3,-2,0,STEP:13)
B(3,-2,1,STEP:13)
B(3,-2,2,STEP:13)
B(3,-2,3,STEP:13)
B(3,-2,4,STEP:13)
B(3,-2,5,STEP:13)
B(3,-2,6,STEP:13)
B(3,-2,7,SMOOTH_BRICK)
B(3,-2,8,STONE)
B(3,-2,9,STONE)
B(3,-2,10,STONE)
B(3,-2,11,DIRT)
B(3,-2,12,DIRT)
B(3,-2,13,DIRT)
B(3,-2,14,DIRT)
B(3,-2,15,DIRT)
B(3,-1,-12,GRASS)
B(3,-1,-11,DIRT)
B(3,-1,-10,DIRT)
B(3,-1,-9,DIRT)
B(3,-1,-8,DIRT)
B(3,-1,-7,STONE)
B(3,-1,-6,STONE)
B(3,-1,-5,STONE)
B(3,-1,-4,STONE)
B(3,-1,-3,STONE)
B(3,-1,-2,STONE)
B(3,-1,-1,STONE)
B(3,-1,0,STONE)
B(3,-1,1,STONE)
B(3,-1,2,STONE)
B(3,-1,3,STONE)
B(3,-1,4,STONE)
B(3,-1,5,STONE)
B(3,-1,6,STONE)
B(3,-1,7,STONE)
B(3,-1,8,STONE)
B(3,-1,9,DIRT)
B(3,-1,10,DIRT)
B(3,-1,11,DIRT)
B(3,-1,12,DIRT)
B(3,-1,13,DIRT)
B(3,-1,14,DIRT)
B(3,-1,15,GRASS)
B(3,0,-11,GRASS)
B(3,0,-10,DIRT)
B(3,0,-9,DIRT)
B(3,0,-8,DIRT)
B(3,0,-7,DIRT)
B(3,0,-6,STONE)
B(3,0,-5,WOOD:2)
B(3,0,-4,WOOD:2)
B(3,0,-3,WOOD:2)
B(3,0,-2,WOOD:5)
B(3,0,-1,WOOD:5)
B(3,0,0,WOOD:5)
B(3,0,1,WOOD:5)
B(3,0,2,WOOD:2)
B(3,0,3,WOOD:2)
B(3,0,4,WOOD:2)
B(3,0,5,STONE)
B(3,0,6,DIRT)
B(3,0,7,DIRT)
B(3,0,8,DIRT)
B(3,0,9,DIRT)
B(3,0,10,DIRT)
B(3,0,11,DIRT)
B(3,0,12,DIRT)
B(3,0,13,GRASS)
B(3,0,14,GRASS)
B(3,1,-10,GRASS)
B(3,1,-9,GRASS)
B(3,1,-8,DIRT)
B(3,1,-7,DIRT)
B(3,1,-6,DIRT)
B(3,1,-5,WOOD:2)
B(3,1,-4,WOOD:2)
B(3,1,-3,WOOD:5)
B(3,1,-2,DARK_OAK_FENCE)
B(3,1,-1,DARK_OAK_FENCE_GATE:1)
B(3,1,0,DARK_OAK_FENCE)
B(3,1,1,WOOD:5)
B(3,1,2,WOOD:2)
B(3,1,3,WOOD:2)
B(3,1,4,WOOD:2)
B(3,1,5,WOOD:2)
B(3,1,6,DIRT)
B(3,1,7,DIRT)
B(3,1,8,DIRT)
B(3,1,9,DIRT)
B(3,1,10,DIRT)
B(3,1,11,GRASS)
B(3,1,12,GRASS)
B(3,2,-8,GRASS)
B(3,2,-7,DIRT)
B(3,2,-6,DIRT)
B(3,2,-5,WOOD:2)
B(3,2,-4,WOOD:2)
B(3,2,-3,WOOD:5)
B(3,2,-2,AIR)
B(3,2,-1,AIR)
B(3,2,0,AIR)
B(3,2,1,WOOD:5)
B(3,2,2,WOOD:2)
B(3,2,3,DARK_OAK_FENCE)
B(3,2,4,WOOD:2)
B(3,2,5,WOOD:2)
B(3,2,6,DIRT)
B(3,2,7,DIRT)
B(3,2,8,DIRT)
B(3,2,9,GRASS)
B(3,2,10,GRASS)
B(3,3,-7,GRASS)
B(3,3,-6,DIRT)
B(3,3,-5,WOOD:2)
B(3,3,-4,WOOD:2)
B(3,3,-3,WOOD:5)
B(3,3,-2,DARK_OAK_FENCE)
B(3,3,-1,DARK_OAK_FENCE)
B(3,3,0,DARK_OAK_FENCE)
B(3,3,1,WOOD:5)
B(3,3,2,WOOD:2)
B(3,3,3,WOOD:2)
B(3,3,4,WOOD:2)
B(3,3,5,WOOD:2)
B(3,3,6,GRASS)
B(3,3,7,GRASS)
B(3,3,8,GRASS)
B(3,4,-6,GRASS)
B(3,4,-5,WOOD:2)
B(3,4,-4,WOOD:2)
B(3,4,-3,WOOD:5)
B(3,4,-2,WOOD:5)
B(3,4,-1,WOOD:5)
B(3,4,0,WOOD:5)
B(3,4,1,WOOD:5)
B(3,4,2,WOOD:2)
B(3,4,3,WOOD:2)
B(3,4,4,WOOD:2)
B(3,4,5,GRASS)
B(3,5,-5,GRASS)
B(3,5,-4,DIRT)
B(3,5,-3,DIRT)
B(3,5,-2,WOOD:5)
B(3,5,-1,WOOD:5)
B(3,5,0,WOOD:5)
B(3,5,1,DIRT)
B(3,5,2,GRASS)
B(3,5,3,GRASS)
B(3,5,4,GRASS)
B(3,6,-4,GRASS)
B(3,6,-3,GRASS)
B(3,6,-2,GRASS)
B(3,6,-1,GRASS)
B(3,6,0,GRASS)
B(3,6,1,GRASS)
B(4,-10,-5,STONE)
B(4,-10,-4,STONE)
B(4,-10,-3,STONE)
B(4,-10,-2,STONE)
B(4,-10,-1,STONE)
B(4,-10,0,STONE)
B(4,-10,1,STONE)
B(4,-10,2,STONE)
B(4,-10,3,STONE)
B(4,-10,4,STONE)
B(4,-10,5,STONE)
B(4,-10,6,STONE)
B(4,-10,7,STONE)
B(4,-9,-7,STONE)
B(4,-9,-6,STONE)
B(4,-9,-5,STONE)
B(4,-9,-4,STONE)
B(4,-9,-3,STONE)
B(4,-9,-2,STONE)
B(4,-9,-1,STONE)
B(4,-9,0,STONE)
B(4,-9,1,STONE)
B(4,-9,2,STONE)
B(4,-9,3,STONE)
B(4,-9,4,STONE)
B(4,-9,5,STONE)
B(4,-9,6,STONE)
B(4,-9,7,STONE)
B(4,-9,8,STONE)
B(4,-8,-8,STONE)
B(4,-8,-7,STONE)
B(4,-8,-6,STONE)
B(4,-8,-5,STONE)
B(4,-8,-4,STONE)
B(4,-8,-3,STONE)
B(4,-8,-2,AIR)
B(4,-8,-1,STONE)
B(4,-8,0,STONE)
B(4,-8,1,STONE)
B(4,-8,2,STONE)
B(4,-8,3,STONE)
B(4,-8,4,STONE)
B(4,-8,5,STONE)
B(4,-8,6,STONE)
B(4,-8,7,STONE)
B(4,-8,8,STONE)
B(4,-7,-9,STONE)
B(4,-7,-8,STONE)
B(4,-7,-7,STONE)
B(4,-7,-6,STONE)
B(4,-7,-5,STONE)
B(4,-7,-4,STONE)
B(4,-7,-3,STONE)
B(4,-7,-2,STONE)
B(4,-7,-1,STONE)
B(4,-7,0,STONE)
B(4,-7,1,STONE)
B(4,-7,2,STONE)
B(4,-7,3,STONE)
B(4,-7,4,STONE)
B(4,-7,5,STONE)
B(4,-7,6,STONE)
B(4,-7,7,STONE)
B(4,-7,8,STONE)
B(4,-7,9,STONE)
B(4,-7,10,STONE)
B(4,-6,-10,STONE)
B(4,-6,-9,STONE)
B(4,-6,-8,STONE)
B(4,-6,-7,STONE)
B(4,-6,-6,STONE)
B(4,-6,-5,STONE)
B(4,-6,-4,STONE)
B(4,-6,-3,STONE)
B(4,-6,-2,COBBLESTONE)
B(4,-6,-1,COBBLESTONE)
B(4,-6,0,COBBLESTONE)
B(4,-6,1,BRICK_STAIRS:1)
B(4,-6,2,BRICK_STAIRS:1)
B(4,-6,3,BRICK_STAIRS:1)
B(4,-6,4,COBBLESTONE)
B(4,-6,5,COBBLESTONE)
B(4,-6,6,COBBLESTONE)
B(4,-6,7,STONE)
B(4,-6,8,STONE)
B(4,-6,9,STONE)
B(4,-6,10,STONE)
B(4,-6,11,STONE)
B(4,-5,-12,STONE)
B(4,-5,-11,STONE)
B(4,-5,-10,STONE)
B(4,-5,-9,STONE)
B(4,-5,-8,STONE)
B(4,-5,-7,STONE)
B(4,-5,-6,STONE)
B(4,-5,-5,STONE)
B(4,-5,-4,STONE)
B(4,-5,-3,SMOOTH_BRICK)
B(4,-5,-2,AIR)
B(4,-5,-1,AIR)
B(4,-5,0,AIR)
B(4,-5,1,AIR)
B(4,-5,2,AIR)
B(4,-5,3,AIR)
B(4,-5,4,AIR)
B(4,-5,5,AIR)
B(4,-5,6,AIR)
B(4,-5,7,SMOOTH_BRICK)
B(4,-5,8,STONE)
B(4,-5,9,STONE)
B(4,-5,10,STONE)
B(4,-5,11,STONE)
B(4,-5,12,STONE)
B(4,-4,-12,DIRT)
B(4,-4,-11,STONE)
B(4,-4,-10,STONE)
B(4,-4,-9,STONE)
B(4,-4,-8,STONE)
B(4,-4,-7,STONE)
B(4,-4,-6,STONE)
B(4,-4,-5,STONE)
B(4,-4,-4,STONE:2)
B(4,-4,-3,SMOOTH_BRICK)
B(4,-4,-2,AIR)
B(4,-4,-1,AIR)
B(4,-4,0,AIR)
B(4,-4,1,AIR)
B(4,-4,2,AIR)
B(4,-4,3,AIR)
B(4,-4,4,AIR)
B(4,-4,5,AIR)
B(4,-4,6,AIR)
B(4,-4,7,SMOOTH_BRICK)
B(4,-4,8,STONE)
B(4,-4,9,STONE)
B(4,-4,10,STONE)
B(4,-4,11,STONE)
B(4,-4,12,STONE)
B(4,-4,13,STONE)
B(4,-4,14,STONE)
B(4,-3,-14,DIRT)
B(4,-3,-13,DIRT)
B(4,-3,-12,AIR)
B(4,-3,-11,DIRT)
B(4,-3,-10,STONE)
B(4,-3,-9,STONE)
B(4,-3,-8,STONE)
B(4,-3,-7,STONE)
B(4,-3,-6,STONE)
B(4,-3,-5,STONE)
B(4,-3,-4,STONE)
B(4,-3,-3,SMOOTH_BRICK)
B(4,-3,-2,AIR)
B(4,-3,-1,AIR)
B(4,-3,0,AIR)
B(4,-3,1,AIR)
B(4,-3,2,AIR)
B(4,-3,3,AIR)
B(4,-3,4,AIR)
B(4,-3,5,AIR)
B(4,-3,6,AIR)
B(4,-3,7,SMOOTH_BRICK)
B(4,-3,8,STONE)
B(4,-3,9,STONE)
B(4,-3,10,STONE)
B(4,-3,11,STONE)
B(4,-3,12,STONE)
B(4,-3,13,STONE)
B(4,-3,14,DIRT)
B(4,-3,15,DIRT)
B(4,-3,16,DIRT)
B(4,-2,-14,GRASS)
B(4,-2,-13,DIRT)
B(4,-2,-12,DIRT)
B(4,-2,-11,DIRT)
B(4,-2,-10,DIRT)
B(4,-2,-9,STONE)
B(4,-2,-8,STONE)
B(4,-2,-7,STONE)
B(4,-2,-6,STONE)
B(4,-2,-5,STONE)
B(4,-2,-4,STONE)
B(4,-2,-3,SMOOTH_BRICK)
B(4,-2,-2,STEP:13)
B(4,-2,-1,STEP:13)
B(4,-2,0,STEP:13)
B(4,-2,1,STEP:13)
B(4,-2,2,STEP:13)
B(4,-2,3,STEP:13)
B(4,-2,4,STEP:13)
B(4,-2,5,STEP:13)
B(4,-2,6,STEP:13)
B(4,-2,7,SMOOTH_BRICK)
B(4,-2,8,STONE)
B(4,-2,9,STONE)
B(4,-2,10,STONE)
B(4,-2,11,STONE)
B(4,-2,12,DIRT)
B(4,-2,13,DIRT)
B(4,-2,14,DIRT)
B(4,-2,15,DIRT)
B(4,-2,16,GRASS)
B(4,-1,-13,GRASS)
B(4,-1,-12,GRASS)
B(4,-1,-11,DIRT)
B(4,-1,-10,DIRT)
B(4,-1,-9,DIRT)
B(4,-1,-8,STONE)
B(4,-1,-7,STONE)
B(4,-1,-6,STONE)
B(4,-1,-5,STONE)
B(4,-1,-4,STONE)
B(4,-1,-3,STONE)
B(4,-1,-2,STONE)
B(4,-1,-1,STONE)
B(4,-1,0,STONE)
B(4,-1,1,STONE)
B(4,-1,2,STONE)
B(4,-1,3,STONE)
B(4,-1,4,STONE)
B(4,-1,5,STONE)
B(4,-1,6,STONE)
B(4,-1,7,STONE)
B(4,-1,8,STONE)
B(4,-1,9,STONE)
B(4,-1,10,DIRT)
B(4,-1,11,DIRT)
B(4,-1,12,DIRT)
B(4,-1,13,DIRT)
B(4,-1,14,DIRT)
B(4,-1,15,GRASS)
B(4,0,-11,GRASS)
B(4,0,-10,DIRT)
B(4,0,-9,DIRT)
B(4,0,-8,DIRT)
B(4,0,-7,DIRT)
B(4,0,-6,STONE)
B(4,0,-5,WOOD:5)
B(4,0,-4,WOOD:5)
B(4,0,-3,WOOD:5)
B(4,0,-2,WOOD:5)
B(4,0,-1,WOOD:5)
B(4,0,0,WOOD:5)
B(4,0,1,WOOD:5)
B(4,0,2,WOOD:5)
B(4,0,3,WOOD:5)
B(4,0,4,WOOD:5)
B(4,0,5,STONE)
B(4,0,6,STONE)
B(4,0,7,DIRT)
B(4,0,8,DIRT)
B(4,0,9,DIRT)
B(4,0,10,DIRT)
B(4,0,11,DIRT)
B(4,0,12,DIRT)
B(4,0,13,DIRT)
B(4,0,14,GRASS)
B(4,1,-10,GRASS)
B(4,1,-9,DIRT)
B(4,1,-8,DIRT)
B(4,1,-7,DIRT)
B(4,1,-6,WOOD:2)
B(4,1,-5,AIR)
B(4,1,-4,AIR)
B(4,1,-3,AIR)
B(4,1,-2,AIR)
B(4,1,-1,AIR)
B(4,1,0,AIR)
B(4,1,1,AIR)
B(4,1,2,AIR)
B(4,1,3,AIR)
B(4,1,4,AIR)
B(4,1,5,WOOD:2)
B(4,1,6,DIRT)
B(4,1,7,DIRT)
B(4,1,8,DIRT)
B(4,1,9,DIRT)
B(4,1,10,DIRT)
B(4,1,11,DIRT)
B(4,1,12,GRASS)
B(4,1,13,GRASS)
B(4,2,-9,GRASS)
B(4,2,-8,DIRT)
B(4,2,-7,DIRT)
B(4,2,-6,WOOD:2)
B(4,2,-5,WOOD_STEP:10)
B(4,2,-4,AIR)
B(4,2,-3,AIR)
B(4,2,-2,AIR)
B(4,2,-1,AIR)
B(4,2,0,AIR)
B(4,2,1,AIR)
B(4,2,2,AIR)
B(4,2,3,AIR)
B(4,2,4,AIR)
B(4,2,5,WOOD:2)
B(4,2,6,DIRT)
B(4,2,7,DIRT)
B(4,2,8,DIRT)
B(4,2,9,DIRT)
B(4,2,10,GRASS)
B(4,2,11,GRASS)
B(4,3,-8,GRASS)
B(4,3,-7,GRASS)
B(4,3,-6,WOOD:2)
B(4,3,-5,WOOD:2)
B(4,3,-4,AIR)
B(4,3,-3,AIR)
B(4,3,-2,AIR)
B(4,3,-1,AIR)
B(4,3,0,AIR)
B(4,3,1,AIR)
B(4,3,2,AIR)
B(4,3,3,AIR)
B(4,3,4,AIR)
B(4,3,5,WOOD:2)
B(4,3,6,DIRT)
B(4,3,7,GRASS)
B(4,3,8,GRASS)
B(4,3,9,GRASS)
B(4,4,-6,GRASS)
B(4,4,-5,WOOD:2)
B(4,4,-4,WOOD_STEP:10)
B(4,4,-3,AIR)
B(4,4,-2,AIR)
B(4,4,-1,AIR)
B(4,4,0,AIR)
B(4,4,1,AIR)
B(4,4,2,AIR)
B(4,4,3,WOOD_STEP:10)
B(4,4,4,WOOD:2)
B(4,4,5,WOOD:2)
B(4,4,6,GRASS)
B(4,5,-5,GRASS)
B(4,5,-4,WOOD:2)
B(4,5,-3,WOOD:2)
B(4,5,-2,WOOD_STEP:10)
B(4,5,-1,WOOD_STEP:10)
B(4,5,0,WOOD_DOUBLE_STEP:2)
B(4,5,1,WOOD:2)
B(4,5,2,WOOD:2)
B(4,5,3,WOOD:2)
B(4,5,4,GRASS)
B(4,5,5,GRASS)
B(4,6,-4,GRASS)
B(4,6,-3,GRASS)
B(4,6,-2,DIRT)
B(4,6,-1,DIRT)
B(4,6,0,GRASS)
B(4,6,1,GRASS)
B(4,6,2,GRASS)
B(4,6,3,GRASS)
B(4,7,-2,GRASS)
B(4,7,-1,GRASS)
B(5,-10,-7,STONE)
B(5,-10,-6,STONE)
B(5,-10,-5,STONE)
B(5,-10,-4,STONE)
B(5,-10,-3,STONE)
B(5,-10,-2,STONE)
B(5,-10,-1,STONE)
B(5,-10,0,STONE)
B(5,-10,1,STONE)
B(5,-10,2,STONE)
B(5,-10,3,STONE)
B(5,-10,4,STONE)
B(5,-10,5,STONE)
B(5,-10,6,STONE)
B(5,-10,7,STONE)
B(5,-10,8,STONE)
B(5,-9,-8,STONE)
B(5,-9,-7,STONE)
B(5,-9,-6,STONE)
B(5,-9,-5,STONE)
B(5,-9,-4,STONE)
B(5,-9,-3,STONE)
B(5,-9,-2,STONE)
B(5,-9,-1,STONE)
B(5,-9,0,STONE)
B(5,-9,1,STONE)
B(5,-9,2,STONE)
B(5,-9,3,STONE)
B(5,-9,4,STONE)
B(5,-9,5,STONE)
B(5,-9,6,STONE)
B(5,-9,7,STONE)
B(5,-9,8,STONE)
B(5,-9,9,STONE)
B(5,-8,-9,STONE)
B(5,-8,-8,STONE)
B(5,-8,-7,STONE)
B(5,-8,-6,STONE)
B(5,-8,-5,STONE)
B(5,-8,-4,STONE)
B(5,-8,-3,STONE)
B(5,-8,-2,STONE)
B(5,-8,-1,STONE)
B(5,-8,0,STONE)
B(5,-8,1,STONE)
B(5,-8,2,STONE)
B(5,-8,3,STONE)
B(5,-8,4,STONE)
B(5,-8,5,STONE)
B(5,-8,6,STONE)
B(5,-8,7,STONE)
B(5,-8,8,STONE)
B(5,-8,9,STONE)
B(5,-8,10,STONE)
B(5,-7,-9,STONE)
B(5,-7,-8,STONE)
B(5,-7,-7,STONE)
B(5,-7,-6,STONE)
B(5,-7,-5,STONE)
B(5,-7,-4,STONE)
B(5,-7,-3,STONE)
B(5,-7,-2,STONE:2)
B(5,-7,-1,BRICK)
B(5,-7,0,BRICK)
B(5,-7,1,BRICK_STAIRS:1)
B(5,-7,2,BRICK_STAIRS:1)
B(5,-7,3,BRICK_STAIRS:1)
B(5,-7,4,BRICK)
B(5,-7,5,BRICK)
B(5,-7,6,STONE:2)
B(5,-7,7,STONE)
B(5,-7,8,STONE)
B(5,-7,9,STONE)
B(5,-7,10,STONE)
B(5,-6,-12,STONE)
B(5,-6,-11,STONE)
B(5,-6,-10,STONE)
B(5,-6,-9,STONE)
B(5,-6,-8,STONE)
B(5,-6,-7,STONE)
B(5,-6,-6,STONE)
B(5,-6,-5,STONE)
B(5,-6,-4,STONE)
B(5,-6,-3,STONE)
B(5,-6,-2,STONE:2)
B(5,-6,-1,STONE:2)
B(5,-6,0,STONE:2)
B(5,-6,1,AIR)
B(5,-6,2,AIR)
B(5,-6,3,AIR)
B(5,-6,4,STONE:2)
B(5,-6,5,STONE:2)
B(5,-6,6,STONE:2)
B(5,-6,7,STONE)
B(5,-6,8,STONE)
B(5,-6,9,STONE)
B(5,-6,10,STONE)
B(5,-6,11,STONE)
B(5,-5,-13,STONE)
B(5,-5,-12,STONE:2)
B(5,-5,-11,STONE:2)
B(5,-5,-10,STONE:2)
B(5,-5,-9,STONE:2)
B(5,-5,-8,STONE:2)
B(5,-5,-7,STONE:2)
B(5,-5,-6,STONE:2)
B(5,-5,-5,STONE:2)
B(5,-5,-4,STONE:2)
B(5,-5,-3,STONE:2)
B(5,-5,-2,STONE:2)
B(5,-5,-1,BRICK)
B(5,-5,0,BRICK)
B(5,-5,1,AIR)
B(5,-5,2,AIR)
B(5,-5,3,AIR)
B(5,-5,4,BRICK)
B(5,-5,5,BRICK)
B(5,-5,6,STONE:2)
B(5,-5,7,STONE:2)
B(5,-5,8,STONE)
B(5,-5,9,STONE)
B(5,-5,10,STONE)
B(5,-5,11,STONE)
B(5,-5,12,STONE)
B(5,-4,-13,DIRT)
B(5,-4,-12,STAINED_CLAY:14)
B(5,-4,-11,STONE:2)
B(5,-4,-10,BRICK)
B(5,-4,-9,BRICK)
B(5,-4,-8,BRICK)
B(5,-4,-7,BRICK)
B(5,-4,-6,BRICK)
B(5,-4,-5,BRICK)
B(5,-4,-4,STONE:2)
B(5,-4,-3,STONE:2)
B(5,-4,-2,STONE:2)
B(5,-4,-1,BRICK)
B(5,-4,0,BRICK)
B(5,-4,1,AIR)
B(5,-4,2,AIR)
B(5,-4,3,AIR)
B(5,-4,4,BRICK)
B(5,-4,5,BRICK)
B(5,-4,6,STONE:2)
B(5,-4,7,STONE:2)
B(5,-4,8,STONE)
B(5,-4,9,STONE)
B(5,-4,10,STONE)
B(5,-4,11,STONE)
B(5,-4,12,STONE)
B(5,-4,13,STONE)
B(5,-4,14,STONE)
B(5,-3,-14,DIRT)
B(5,-3,-13,DIRT)
B(5,-3,-12,STONE:2)
B(5,-3,-11,STONE:2)
B(5,-3,-10,STONE:2)
B(5,-3,-9,STONE:2)
B(5,-3,-8,STONE:2)
B(5,-3,-7,STONE:2)
B(5,-3,-6,STONE:2)
B(5,-3,-5,STONE:2)
B(5,-3,-4,STONE:2)
B(5,-3,-3,STONE:2)
B(5,-3,-2,STONE:2)
B(5,-3,-1,STONE:2)
B(5,-3,0,STONE:2)
B(5,-3,1,STONE:2)
B(5,-3,2,STONE:2)
B(5,-3,3,STONE:2)
B(5,-3,4,STONE:2)
B(5,-3,5,STONE:2)
B(5,-3,6,STONE:2)
B(5,-3,7,STONE:2)
B(5,-3,8,STONE)
B(5,-3,9,STONE)
B(5,-3,10,STONE)
B(5,-3,11,STONE)
B(5,-3,12,STONE)
B(5,-3,13,STONE)
B(5,-3,14,DIRT)
B(5,-3,15,DIRT)
B(5,-3,16,DIRT)
B(5,-2,-14,GRASS)
B(5,-2,-13,DIRT)
B(5,-2,-12,STAINED_CLAY:14)
B(5,-2,-11,STONE:2)
B(5,-2,-10,STAINED_CLAY:14)
B(5,-2,-9,STAINED_CLAY:14)
B(5,-2,-8,STAINED_CLAY:14)
B(5,-2,-7,STAINED_CLAY:14)
B(5,-2,-6,STAINED_CLAY:14)
B(5,-2,-5,STAINED_CLAY:14)
B(5,-2,-4,STONE:2)
B(5,-2,-3,STONE:2)
B(5,-2,-2,STONE:2)
B(5,-2,-1,STAINED_CLAY:14)
B(5,-2,0,STAINED_CLAY:14)
B(5,-2,1,STAINED_CLAY:14)
B(5,-2,2,STAINED_CLAY:14)
B(5,-2,3,STAINED_CLAY:14)
B(5,-2,4,STAINED_CLAY:14)
B(5,-2,5,STAINED_CLAY:14)
B(5,-2,6,STONE:2)
B(5,-2,7,STONE:2)
B(5,-2,8,STONE)
B(5,-2,9,STONE)
B(5,-2,10,STONE)
B(5,-2,11,STONE)
B(5,-2,12,STONE)
B(5,-2,13,DIRT)
B(5,-2,14,DIRT)
B(5,-2,15,DIRT)
B(5,-2,16,GRASS)
B(5,-1,-13,GRASS)
B(5,-1,-12,STONE:2)
B(5,-1,-11,STONE:2)
B(5,-1,-10,STONE:2)
B(5,-1,-9,STONE:2)
B(5,-1,-8,STONE:2)
B(5,-1,-7,STONE:2)
B(5,-1,-6,STONE:2)
B(5,-1,-5,STONE:2)
B(5,-1,-4,STONE:2)
B(5,-1,-3,STONE:2)
B(5,-1,-2,STONE:2)
B(5,-1,-1,STONE:2)
B(5,-1,0,STONE:2)
B(5,-1,1,STONE:2)
B(5,-1,2,STONE:2)
B(5,-1,3,STONE:2)
B(5,-1,4,STONE:2)
B(5,-1,5,STONE:2)
B(5,-1,6,STONE:2)
B(5,-1,7,STONE:2)
B(5,-1,8,STONE)
B(5,-1,9,STONE)
B(5,-1,10,STONE)
B(5,-1,11,DIRT)
B(5,-1,12,DIRT)
B(5,-1,13,DIRT)
B(5,-1,14,DIRT)
B(5,-1,15,GRASS)
B(5,0,-12,GRASS)
B(5,0,-11,GRASS)
B(5,0,-10,DIRT)
B(5,0,-9,DIRT)
B(5,0,-8,DIRT)
B(5,0,-7,STONE)
B(5,0,-6,WOOD:5)
B(5,0,-5,WOOD:5)
B(5,0,-4,WOOD:5)
B(5,0,-3,WOOD:5)
B(5,0,-2,WOOD:5)
B(5,0,-1,WOOD:5)
B(5,0,0,WOOD:5)
B(5,0,1,WOOD:5)
B(5,0,2,WOOD:5)
B(5,0,3,WOOD:5)
B(5,0,4,WOOD:5)
B(5,0,5,WOOD:5)
B(5,0,6,STONE)
B(5,0,7,STONE)
B(5,0,8,DIRT)
B(5,0,9,DIRT)
B(5,0,10,DIRT)
B(5,0,11,DIRT)
B(5,0,12,DIRT)
B(5,0,13,DIRT)
B(5,0,14,GRASS)
B(5,1,-10,GRASS)
B(5,1,-9,DIRT)
B(5,1,-8,DIRT)
B(5,1,-7,WOOD:2)
B(5,1,-6,AIR)
B(5,1,-5,AIR)
B(5,1,-4,AIR)
B(5,1,-3,AIR)
B(5,1,-2,AIR)
B(5,1,-1,AIR)
B(5,1,0,AIR)
B(5,1,1,AIR)
B(5,1,2,AIR)
B(5,1,3,AIR)
B(5,1,4,AIR)
B(5,1,5,AIR)
B(5,1,6,WOOD:2)
B(5,1,7,AIR)
B(5,1,8,DIRT)
B(5,1,9,DIRT)
B(5,1,10,DIRT)
B(5,1,11,DIRT)
B(5,1,12,DIRT)
B(5,1,13,GRASS)
B(5,2,-9,GRASS)
B(5,2,-8,DIRT)
B(5,2,-7,WOOD:2)
B(5,2,-6,AIR)
B(5,2,-5,AIR)
B(5,2,-4,AIR)
B(5,2,-3,AIR)
B(5,2,-2,AIR)
B(5,2,-1,AIR)
B(5,2,0,AIR)
B(5,2,1,AIR)
B(5,2,2,AIR)
B(5,2,3,AIR)
B(5,2,4,AIR)
B(5,2,5,AIR)
B(5,2,6,WOOD:2)
B(5,2,7,AIR)
B(5,2,8,DIRT)
B(5,2,9,DIRT)
B(5,2,10,DIRT)
B(5,2,11,GRASS)
B(5,2,12,GRASS)
B(5,3,-8,GRASS)
B(5,3,-7,WOOD:2)
B(5,3,-6,WOOD_DOUBLE_STEP:2)
B(5,3,-5,AIR)
B(5,3,-4,AIR)
B(5,3,-3,AIR)
B(5,3,-2,AIR)
B(5,3,-1,AIR)
B(5,3,0,AIR)
B(5,3,1,AIR)
B(5,3,2,AIR)
B(5,3,3,AIR)
B(5,3,4,AIR)
B(5,3,5,AIR)
B(5,3,6,WOOD:2)
B(5,3,7,DIRT)
B(5,3,8,GRASS)
B(5,3,9,GRASS)
B(5,3,10,GRASS)
B(5,4,-7,GRASS)
B(5,4,-6,GRASS)
B(5,4,-5,WOOD:2)
B(5,4,-4,WOOD_STEP:10)
B(5,4,-3,AIR)
B(5,4,-2,AIR)
B(5,4,-1,AIR)
B(5,4,0,AIR)
B(5,4,1,AIR)
B(5,4,2,AIR)
B(5,4,3,AIR)
B(5,4,4,WOOD_STEP:10)
B(5,4,5,WOOD:2)
B(5,4,6,WOOD:2)
B(5,4,7,GRASS)
B(5,5,-5,GRASS)
B(5,5,-4,WOOD:2)
B(5,5,-3,WOOD_STEP:10)
B(5,5,-2,WOOD_STEP:10)
B(5,5,-1,WOOD_STEP:10)
B(5,5,0,WOOD_STEP:10)
B(5,5,1,WOOD_DOUBLE_STEP:2)
B(5,5,2,WOOD:2)
B(5,5,3,WOOD:2)
B(5,5,4,GRASS)
B(5,5,5,GRASS)
B(5,5,6,GRASS)
B(5,6,-4,GRASS)
B(5,6,-3,GRASS)
B(5,6,-2,DIRT)
B(5,6,-1,DIRT)
B(5,6,0,GRASS)
B(5,6,1,GRASS)
B(5,6,2,GRASS)
B(5,6,3,GRASS)
B(5,7,-2,GRASS)
B(5,7,-1,GRASS)
B(6,-10,-7,STONE)
B(6,-10,-6,STONE)
B(6,-10,-5,STONE)
B(6,-10,-4,STONE)
B(6,-10,-3,STONE)
B(6,-10,-2,STONE)
B(6,-10,-1,STONE)
B(6,-10,0,STONE)
B(6,-10,1,STONE)
B(6,-10,2,STONE)
B(6,-10,3,STONE)
B(6,-10,4,STONE)
B(6,-10,5,STONE)
B(6,-10,6,STONE)
B(6,-10,7,STONE)
B(6,-10,8,STONE)
B(6,-9,-9,STONE)
B(6,-9,-8,STONE)
B(6,-9,-7,STONE)
B(6,-9,-6,STONE)
B(6,-9,-5,STONE)
B(6,-9,-4,STONE)
B(6,-9,-3,STONE)
B(6,-9,-2,STONE)
B(6,-9,-1,STONE)
B(6,-9,0,STONE)
B(6,-9,1,STONE)
B(6,-9,2,STONE)
B(6,-9,3,STONE)
B(6,-9,4,STONE)
B(6,-9,5,STONE)
B(6,-9,6,STONE)
B(6,-9,7,STONE)
B(6,-9,8,STONE)
B(6,-9,9,STONE)
B(6,-8,-10,STONE)
B(6,-8,-9,STONE)
B(6,-8,-8,STONE)
B(6,-8,-7,STONE)
B(6,-8,-6,STONE)
B(6,-8,-5,STONE)
B(6,-8,-4,STONE)
B(6,-8,-3,STONE)
B(6,-8,-2,SMOOTH_BRICK)
B(6,-8,-1,SMOOTH_BRICK)
B(6,-8,0,SMOOTH_BRICK)
B(6,-8,1,SMOOTH_BRICK)
B(6,-8,2,SMOOTH_BRICK)
B(6,-8,3,SMOOTH_BRICK)
B(6,-8,4,SMOOTH_BRICK)
B(6,-8,5,SMOOTH_BRICK)
B(6,-8,6,SMOOTH_BRICK)
B(6,-8,7,STONE)
B(6,-8,8,STONE)
B(6,-8,9,STONE)
B(6,-8,10,STONE)
B(6,-7,-11,STONE)
B(6,-7,-10,STONE)
B(6,-7,-9,STONE)
B(6,-7,-8,STONE)
B(6,-7,-7,STONE)
B(6,-7,-6,STONE)
B(6,-7,-5,STONE)
B(6,-7,-4,STONE)
B(6,-7,-3,STONE:2)
B(6,-7,-2,AIR)
B(6,-7,-1,AIR)
B(6,-7,0,AIR)
B(6,-7,1,AIR)
B(6,-7,2,AIR)
B(6,-7,3,AIR)
B(6,-7,4,AIR)
B(6,-7,5,AIR)
B(6,-7,6,AIR)
B(6,-7,7,STONE:2)
B(6,-7,8,STONE)
B(6,-7,9,STONE)
B(6,-7,10,STONE)
B(6,-6,-12,STONE)
B(6,-6,-11,SMOOTH_BRICK)
B(6,-6,-10,SMOOTH_BRICK)
B(6,-6,-9,SMOOTH_BRICK)
B(6,-6,-8,SMOOTH_BRICK)
B(6,-6,-7,SMOOTH_BRICK)
B(6,-6,-6,SMOOTH_BRICK)
B(6,-6,-5,SMOOTH_BRICK)
B(6,-6,-4,SMOOTH_BRICK)
B(6,-6,-3,STONE:2)
B(6,-6,-2,AIR)
B(6,-6,-1,AIR)
B(6,-6,0,AIR)
B(6,-6,1,AIR)
B(6,-6,2,AIR)
B(6,-6,3,AIR)
B(6,-6,4,AIR)
B(6,-6,5,AIR)
B(6,-6,6,AIR)
B(6,-6,7,STONE:2)
B(6,-6,8,STONE)
B(6,-6,9,STONE)
B(6,-6,10,STONE)
B(6,-6,11,STONE)
B(6,-5,-13,STONE)
B(6,-5,-12,STONE:2)
B(6,-5,-11,WOOD_STAIRS:7)
B(6,-5,-10,AIR)
B(6,-5,-9,AIR)
B(6,-5,-8,AIR)
RB(6,-5,-7,JUKEBOX:1,../../nbt/Misc/RecordPlayer1.nbt,50,JUKEBOX:1,../../nbt/Misc/RecordPlayer2.nbt,50,JUKEBOX:1,../../nbt/Misc/RecordPlayer3.nbt,50,JUKEBOX:1,../../nbt/Misc/RecordPlayer4.nbt,50,JUKEBOX:1,../../nbt/Misc/RecordPlayer5.nbt,50,JUKEBOX:1,../../nbt/Misc/RecordPlayer6.nbt,50,JUKEBOX:1,../../nbt/Misc/RecordPlayer7.nbt,50,JUKEBOX:1,../../nbt/Misc/RecordPlayer8.nbt,50,JUKEBOX:1,../../nbt/Misc/RecordPlayer9.nbt,50,JUKEBOX:1,../../nbt/Misc/RecordPlayer10.nbt,50,JUKEBOX:1,../../nbt/Misc/RecordPlayer11.nbt,100)
B(6,-5,-6,AIR)
B(6,-5,-5,AIR)
B(6,-5,-4,AIR)
B(6,-5,-3,STONE:2)
B(6,-5,-2,AIR)
B(6,-5,-1,AIR)
B(6,-5,0,AIR)
B(6,-5,1,AIR)
B(6,-5,2,AIR)
B(6,-5,3,AIR)
B(6,-5,4,AIR)
B(6,-5,5,AIR)
B(6,-5,6,AIR)
B(6,-5,7,STONE:2)
B(6,-5,8,STONE)
B(6,-5,9,STONE)
B(6,-5,10,STONE)
B(6,-5,11,STONE)
B(6,-5,12,STONE)
B(6,-4,-13,DIRT)
B(6,-4,-12,STONE:2)
B(6,-4,-11,BOOKSHELF)
B(6,-4,-10,AIR)
B(6,-4,-9,AIR)
B(6,-4,-8,AIR)
B(6,-4,-7,AIR)
B(6,-4,-6,AIR)
B(6,-4,-5,AIR)
B(6,-4,-4,AIR)
B(6,-4,-3,STONE:2)
B(6,-4,-2,AIR)
B(6,-4,-1,AIR)
B(6,-4,0,AIR)
B(6,-4,1,AIR)
B(6,-4,2,AIR)
B(6,-4,3,AIR)
B(6,-4,4,AIR)
B(6,-4,5,AIR)
B(6,-4,6,AIR)
B(6,-4,7,STONE:2)
B(6,-4,8,STONE)
B(6,-4,9,STONE)
B(6,-4,10,STONE)
B(6,-4,11,STONE)
B(6,-4,12,STONE)
B(6,-4,13,STONE)
B(6,-4,14,STONE)
B(6,-3,-14,DIRT)
B(6,-3,-13,DIRT)
B(6,-3,-12,STONE:2)
B(6,-3,-11,BOOKSHELF)
B(6,-3,-10,AIR)
B(6,-3,-9,AIR)
B(6,-3,-8,AIR)
B(6,-3,-7,AIR)
B(6,-3,-6,AIR)
B(6,-3,-5,AIR)
B(6,-3,-4,AIR)
B(6,-3,-3,STONE:2)
B(6,-3,-2,AIR)
B(6,-3,-1,AIR)
B(6,-3,0,AIR)
B(6,-3,1,AIR)
B(6,-3,2,AIR)
B(6,-3,3,AIR)
B(6,-3,4,AIR)
B(6,-3,5,AIR)
B(6,-3,6,AIR)
B(6,-3,7,STONE:2)
B(6,-3,8,STONE)
B(6,-3,9,STONE)
B(6,-3,10,STONE)
B(6,-3,11,STONE)
B(6,-3,12,AIR)
B(6,-3,13,STONE)
B(6,-3,14,DIRT)
B(6,-3,15,DIRT)
B(6,-3,16,DIRT)
B(6,-2,-14,GRASS)
B(6,-2,-13,DIRT)
B(6,-2,-12,STONE:2)
B(6,-2,-11,AIR)
B(6,-2,-10,AIR)
B(6,-2,-9,AIR)
B(6,-2,-8,AIR)
B(6,-2,-7,AIR)
B(6,-2,-6,AIR)
B(6,-2,-5,AIR)
B(6,-2,-4,AIR)
B(6,-2,-3,STONE:2)
B(6,-2,-2,AIR)
B(6,-2,-1,AIR)
B(6,-2,0,AIR)
B(6,-2,1,AIR)
B(6,-2,2,AIR)
B(6,-2,3,AIR)
B(6,-2,4,AIR)
B(6,-2,5,AIR)
B(6,-2,6,AIR)
B(6,-2,7,STONE:2)
B(6,-2,8,STONE)
B(6,-2,9,STONE)
B(6,-2,10,STONE)
B(6,-2,11,STONE)
B(6,-2,12,DIRT)
B(6,-2,13,DIRT)
B(6,-2,14,DIRT)
B(6,-2,15,DIRT)
B(6,-2,16,GRASS)
B(6,-1,-13,GRASS)
B(6,-1,-12,STONE:2)
B(6,-1,-11,AIR)
B(6,-1,-10,AIR)
B(6,-1,-9,AIR)
B(6,-1,-8,AIR)
B(6,-1,-7,AIR)
B(6,-1,-6,AIR)
B(6,-1,-5,AIR)
B(6,-1,-4,AIR)
B(6,-1,-3,STONE:2)
B(6,-1,-2,STEP:8)
B(6,-1,-1,STEP:12)
B(6,-1,0,STEP:8)
B(6,-1,1,STEP:8)
B(6,-1,2,STEP:8)
B(6,-1,3,STEP:8)
B(6,-1,4,STEP:8)
B(6,-1,5,STEP:12)
B(6,-1,6,STEP:8)
B(6,-1,7,STONE:2)
B(6,-1,8,STONE)
B(6,-1,9,STONE)
B(6,-1,10,STONE)
B(6,-1,11,DIRT)
B(6,-1,12,DIRT)
B(6,-1,13,DIRT)
B(6,-1,14,DIRT)
B(6,-1,15,GRASS)
B(6,0,-12,GRASS)
B(6,0,-11,WOOD:5)
B(6,0,-10,WOOD:5)
B(6,0,-9,WOOD:5)
B(6,0,-8,WOOD:5)
B(6,0,-7,WOOD:5)
B(6,0,-6,WOOD:5)
B(6,0,-5,WOOD:5)
B(6,0,-4,WOOD:5)
B(6,0,-3,WOOD:5)
B(6,0,-2,WOOD:5)
B(6,0,-1,WOOD:5)
B(6,0,0,WOOD:5)
B(6,0,1,WOOD:5)
B(6,0,2,WOOD:5)
B(6,0,3,WOOD:5)
B(6,0,4,WOOD:5)
B(6,0,5,WOOD:5)
B(6,0,6,WOOD:5)
B(6,0,7,STONE)
B(6,0,8,STONE)
B(6,0,9,DIRT)
B(6,0,10,DIRT)
B(6,0,11,DIRT)
B(6,0,12,DIRT)
B(6,0,13,DIRT)
B(6,0,14,GRASS)
B(6,1,-11,GRASS)
B(6,1,-10,GRASS)
B(6,1,-9,DIRT)
B(6,1,-8,DIRT)
B(6,1,-7,WOOD:2)
B(16,1,-5,AIR)
Entity(6,1,-5,ArmorStand,1,ArmorStandCommon1.txt)
B(6,1,-6,AIR)
B(6,1,-4,AIR)
B(6,1,-3,DARK_OAK_FENCE)
B(6,1,-2,AIR)
B(6,1,-1,AIR)
B(6,1,0,AIR)
B(6,1,1,AIR)
B(6,1,2,DARK_OAK_FENCE)
B(6,1,3,AIR)
B(6,1,5,AIR)
B(6,1,4,AIR)
B(6,1,6,AIR)
B(6,1,7,WOOD:2)
B(6,1,8,DIRT)
B(6,1,9,DIRT)
B(6,1,10,DIRT)
B(6,1,11,DIRT)
B(6,1,12,GRASS)
B(6,1,13,GRASS)
B(6,2,-9,GRASS)
B(6,2,-8,DIRT)
B(6,2,-7,WOOD:2)
B(6,2,-6,AIR)
B(6,2,-5,AIR)
B(6,2,-4,AIR)
B(6,2,-3,DARK_OAK_FENCE)
B(6,2,-2,AIR)
B(6,2,-1,AIR)
B(6,2,0,AIR)
B(6,2,1,AIR)
B(6,2,2,DARK_OAK_FENCE)
B(6,2,3,AIR)
B(6,2,4,AIR)
B(6,2,5,AIR)
B(6,2,6,AIR)
B(6,2,7,WOOD:2)
B(6,2,8,DIRT)
B(6,2,9,DIRT)
B(6,2,10,DIRT)
B(6,2,11,GRASS)
B(6,3,-8,GRASS)
B(6,3,-7,WOOD:2)
B(6,3,-6,WOOD_STEP:10)
B(6,3,-5,AIR)
B(6,3,-4,AIR)
B(6,3,-3,50)
B(6,3,-2,AIR)
B(6,3,-1,AIR)
B(6,3,0,AIR)
B(6,3,1,AIR)
B(6,3,2,50)
B(6,3,3,AIR)
B(6,3,4,AIR)
B(6,3,5,AIR)
B(6,3,6,AIR)
B(6,3,7,WOOD:2)
B(6,3,8,DIRT)
B(6,3,9,GRASS)
B(6,3,10,GRASS)
B(6,4,-7,GRASS)
B(6,4,-6,WOOD:2)
B(6,4,-5,WOOD:2)
B(6,4,-4,AIR)
B(6,4,-3,AIR)
B(6,4,-2,AIR)
B(6,4,-1,AIR)
B(6,4,0,AIR)
B(6,4,1,AIR)
B(6,4,2,AIR)
B(6,4,3,AIR)
B(6,4,4,AIR)
B(6,4,5,AIR)
B(6,4,6,WOOD_STEP:10)
B(6,4,7,WOOD:2)
B(6,4,8,GRASS)
B(6,5,-6,GRASS)
B(6,5,-5,GRASS)
B(6,5,-4,WOOD:2)
B(6,5,-3,WOOD_STEP:10)
B(6,5,-2,WOOD_STEP:10)
B(6,5,-1,WOOD_STEP:10)
B(6,5,0,WOOD_STEP:10)
B(6,5,1,WOOD_STEP:10)
B(6,5,2,WOOD_STEP:10)
B(6,5,3,WOOD_DOUBLE_STEP:2)
B(6,5,4,WOOD:2)
B(6,5,5,WOOD:2)
B(6,5,6,GRASS)
B(6,5,7,GRASS)
B(6,6,-4,GRASS)
B(6,6,-3,DIRT)
B(6,6,-2,DIRT)
B(6,6,-1,DIRT)
B(6,6,0,DIRT)
B(6,6,1,GRASS)
B(6,6,2,GRASS)
B(6,6,3,GRASS)
B(6,6,4,GRASS)
B(6,6,5,GRASS)
B(6,7,-3,GRASS)
B(6,7,-2,GRASS)
B(6,7,-1,GRASS)
B(6,7,0,GRASS)
B(7,-10,-8,STONE)
B(7,-10,-7,STONE)
B(7,-10,-6,STONE)
B(7,-10,-5,STONE)
B(7,-10,-4,STONE)
B(7,-10,-3,STONE)
B(7,-10,-2,STONE)
B(7,-10,-1,STONE)
B(7,-10,0,STONE)
B(7,-10,1,STONE)
B(7,-10,2,STONE)
B(7,-10,3,STONE)
B(7,-10,4,STONE)
B(7,-10,5,STONE)
B(7,-10,6,STONE)
B(7,-10,7,STONE)
B(7,-10,8,STONE)
B(7,-9,-9,STONE)
B(7,-9,-8,STONE)
B(7,-9,-7,STONE)
B(7,-9,-6,STONE)
B(7,-9,-5,STONE)
B(7,-9,-4,STONE)
B(7,-9,-3,STONE)
B(7,-9,-2,STONE)
B(7,-9,-1,STONE)
B(7,-9,0,STONE)
B(7,-9,1,STONE)
B(7,-9,2,STONE)
B(7,-9,3,STONE)
B(7,-9,4,STONE)
B(7,-9,5,STONE)
B(7,-9,6,STONE)
B(7,-9,7,STONE)
B(7,-9,8,STONE)
B(7,-9,9,STONE)
B(7,-9,10,STONE)
B(7,-8,-10,STONE)
B(7,-8,-9,STONE)
B(7,-8,-8,STONE)
B(7,-8,-7,STONE)
B(7,-8,-6,STONE)
B(7,-8,-5,STONE)
B(7,-8,-4,STONE)
B(7,-8,-3,STONE)
B(7,-8,-2,SMOOTH_BRICK)
B(7,-8,-1,SMOOTH_BRICK)
B(7,-8,0,SMOOTH_BRICK)
B(7,-8,1,SMOOTH_BRICK)
B(7,-8,2,SMOOTH_BRICK)
B(7,-8,3,SMOOTH_BRICK)
B(7,-8,4,SMOOTH_BRICK)
B(7,-8,5,SMOOTH_BRICK)
B(7,-8,6,SMOOTH_BRICK)
B(7,-8,7,STONE)
B(7,-8,8,STONE)
B(7,-8,9,STONE)
B(7,-8,10,STONE)
B(7,-7,-11,STONE)
B(7,-7,-10,STONE)
B(7,-7,-9,STONE)
B(7,-7,-8,STONE)
B(7,-7,-7,STONE)
B(7,-7,-6,STONE)
B(7,-7,-5,STONE)
B(7,-7,-4,STONE)
B(7,-7,-3,STONE:2)
B(7,-7,-2,AIR)
B(7,-7,-1,AIR)
B(7,-7,0,AIR)
B(7,-7,1,AIR)
B(7,-7,2,AIR)
B(7,-7,3,AIR)
B(7,-7,4,AIR)
B(7,-7,5,AIR)
B(7,-7,6,AIR)
B(7,-7,7,BRICK)
B(7,-7,8,STONE)
B(7,-7,9,STONE)
B(7,-7,10,STONE)
B(7,-7,11,STONE)
B(7,-6,-13,STONE)
B(7,-6,-12,STONE)
B(7,-6,-11,SMOOTH_BRICK)
B(7,-6,-10,WOOL:7)
B(7,-6,-9,WOOL:7)
B(7,-6,-8,WOOL:7)
B(7,-6,-7,WOOL:7)
B(7,-6,-6,WOOL:7)
B(7,-6,-5,SMOOTH_BRICK)
B(7,-6,-4,SMOOTH_BRICK)
B(7,-6,-3,STONE:2)
B(7,-6,-2,AIR)
B(7,-6,-1,AIR)
B(7,-6,0,AIR)
B(7,-6,1,AIR)
B(7,-6,2,AIR)
B(7,-6,3,AIR)
B(7,-6,4,AIR)
B(7,-6,5,AIR)
B(7,-6,6,AIR)
B(7,-6,7,STONE:2)
B(7,-6,8,STONE)
B(7,-6,9,STONE)
B(7,-6,10,STONE)
B(7,-6,11,STONE)
B(7,-5,-13,STONE)
B(7,-5,-12,STONE:2)
B(7,-5,-11,AIR)
B(7,-5,-10,AIR)
B(7,-5,-9,AIR)
B(7,-5,-8,AIR)
B(7,-5,-7,AIR)
B(7,-5,-6,AIR)
B(7,-5,-5,AIR)
B(7,-5,-4,AIR)
B(7,-5,-3,BRICK)
B(7,-5,-2,AIR)
B(7,-5,-1,AIR)
B(7,-5,0,AIR)
B(7,-5,1,AIR)
B(7,-5,2,AIR)
B(7,-5,3,AIR)
B(7,-5,4,AIR)
B(7,-5,5,AIR)
B(7,-5,6,AIR)
B(7,-5,7,BRICK)
B(7,-5,8,STONE)
B(7,-5,9,STONE)
B(7,-5,10,STONE)
B(7,-5,11,STONE)
B(7,-5,12,STONE)
B(7,-4,-13,DIRT)
B(7,-4,-12,BRICK)
B(7,-4,-11,AIR)
B(7,-4,-10,AIR)
B(7,-4,-9,AIR)
B(7,-4,-8,AIR)
B(7,-4,-7,AIR)
B(7,-4,-6,AIR)
B(7,-4,-5,AIR)
B(7,-4,-4,AIR)
B(7,-4,-3,BRICK)
B(7,-4,-2,AIR)
B(7,-4,-1,AIR)
B(7,-4,0,AIR)
B(7,-4,1,AIR)
B(7,-4,2,AIR)
B(7,-4,3,AIR)
B(7,-4,4,AIR)
B(7,-4,5,AIR)
B(7,-4,6,AIR)
B(7,-4,7,BRICK)
B(7,-4,8,STONE)
B(7,-4,9,STONE)
B(7,-4,10,STONE)
B(7,-4,11,STONE)
B(7,-4,12,STONE)
B(7,-4,13,STONE)
B(7,-4,14,DIRT)
B(7,-3,-14,DIRT)
B(7,-3,-13,DIRT)
B(7,-3,-12,STONE:2)
B(7,-3,-11,AIR)
B(7,-3,-10,AIR)
B(7,-3,-9,AIR)
B(7,-3,-8,AIR)
B(7,-3,-7,AIR)
B(7,-3,-6,AIR)
B(7,-3,-5,AIR)
B(7,-3,-4,AIR)
B(7,-3,-3,BRICK)
B(7,-3,-2,AIR)
B(7,-3,-1,AIR)
B(7,-3,0,AIR)
B(7,-3,1,AIR)
B(7,-3,2,AIR)
B(7,-3,3,AIR)
B(7,-3,4,AIR)
B(7,-3,5,AIR)
B(7,-3,6,AIR)
B(7,-3,7,STONE:2)
B(7,-3,8,STONE)
B(7,-3,9,STONE)
B(7,-3,10,STONE)
B(7,-3,11,STONE)
B(7,-3,12,STONE)
B(7,-3,13,DIRT)
B(7,-3,14,DIRT)
B(7,-3,15,DIRT)
B(7,-2,-14,GRASS)
B(7,-2,-13,DIRT)
B(7,-2,-12,STAINED_CLAY:14)
B(7,-2,-11,AIR)
B(7,-2,-10,AIR)
B(7,-2,-9,AIR)
B(7,-2,-8,AIR)
B(7,-2,-7,AIR)
B(7,-2,-6,AIR)
B(7,-2,-5,AIR)
B(7,-2,-4,AIR)
B(7,-2,-3,BRICK)
B(7,-2,-2,AIR)
B(7,-2,-1,AIR)
B(7,-2,0,AIR)
B(7,-2,1,AIR)
B(7,-2,2,AIR)
B(7,-2,3,AIR)
B(7,-2,4,AIR)
B(7,-2,5,AIR)
B(7,-2,6,AIR)
B(7,-2,7,STAINED_CLAY:14)
B(7,-2,8,STONE)
B(7,-2,9,STONE)
B(7,-2,10,STONE)
B(7,-2,11,STONE)
B(7,-2,12,DIRT)
B(7,-2,13,DIRT)
B(7,-2,14,DIRT)
B(7,-2,15,DIRT)
B(7,-1,-13,GRASS)
B(7,-1,-12,STONE:2)
B(7,-1,-11,AIR)
B(7,-1,-10,AIR)
B(7,-1,-9,AIR)
B(7,-1,-8,AIR)
B(7,-1,-7,AIR)
B(7,-1,-6,AIR)
B(7,-1,-5,AIR)
B(7,-1,-4,AIR)
B(7,-1,-3,STONE:2)
B(7,-1,-2,STEP:8)
B(7,-1,-1,STEP:12)
B(7,-1,0,STEP:8)
B(7,-1,1,AIR)
B(7,-1,2,AIR)
B(7,-1,3,AIR)
B(7,-1,4,STEP:8)
B(7,-1,5,STEP:12)
B(7,-1,6,STEP:8)
B(7,-1,7,STONE:2)
B(7,-1,8,STONE)
B(7,-1,9,STONE)
B(7,-1,10,STONE)
B(7,-1,11,DIRT)
B(7,-1,12,DIRT)
B(7,-1,13,DIRT)
B(7,-1,14,GRASS)
B(7,-1,15,GRASS)
B(7,0,-12,GRASS)
B(7,0,-11,WOOD:5)
B(7,0,-10,WOOD:5)
B(7,0,-9,WOOD:5)
B(7,0,-8,WOOD:5)
B(7,0,-7,WOOD:5)
B(7,0,-6,WOOD:5)
B(7,0,-5,WOOD:5)
B(7,0,-4,WOOD:5)
B(7,0,-3,WOOD:5)
B(7,0,-2,WOOD:5)
B(7,0,-1,WOOD:5)
B(7,0,0,WOOD:5)
B(7,0,1,WOOD:5)
B(7,0,2,WOOD:5)
B(7,0,3,WOOD:5)
B(7,0,4,WOOD:5)
B(7,0,5,WOOD:5)
B(7,0,6,WOOD:5)
B(7,0,7,STONE)
B(7,0,8,STONE)
B(7,0,9,DIRT)
B(7,0,10,DIRT)
B(7,0,11,DIRT)
B(7,0,12,DIRT)
B(7,0,13,GRASS)
B(7,1,-11,GRASS)
B(7,1,-10,DIRT)
B(7,1,-9,DIRT)
B(7,1,-8,DIRT)
B(7,1,-7,WOOD:2)
B(7,1,-6,AIR)
B(7,1,-5,AIR)
B(7,1,-4,AIR)
B(7,1,-3,AIR)
B(7,1,-2,AIR)
B(7,1,-1,AIR)
B(7,1,0,AIR)
B(7,1,1,AIR)
B(7,1,2,AIR)
B(7,1,3,AIR)
B(7,1,4,AIR)
B(7,1,5,AIR)
B(7,1,6,AIR)
B(7,1,7,WOOD:2)
B(7,1,8,DIRT)
B(7,1,9,DIRT)
B(7,1,10,DIRT)
B(7,1,11,DIRT)
B(7,1,12,GRASS)
B(7,2,-10,GRASS)
B(7,2,-9,GRASS)
B(7,2,-8,DIRT)
B(7,2,-7,WOOD:2)
B(7,2,-6,AIR)
B(7,2,-5,AIR)
B(7,2,-4,AIR)
B(7,2,-3,AIR)
B(7,2,-2,AIR)
B(7,2,-1,AIR)
B(7,2,0,AIR)
B(7,2,1,AIR)
B(7,2,2,AIR)
B(7,2,3,AIR)
B(7,2,4,AIR)
B(7,2,5,AIR)
B(7,2,6,AIR)
B(7,2,7,WOOD:2)
B(7,2,8,DIRT)
B(7,2,9,DIRT)
B(7,2,10,DIRT)
B(7,2,11,GRASS)
B(7,3,-8,GRASS)
B(7,3,-7,WOOD:2)
B(7,3,-6,AIR)
B(7,3,-5,AIR)
B(7,3,-4,AIR)
B(7,3,-3,AIR)
B(7,3,-2,AIR)
B(7,3,-1,AIR)
B(7,3,0,AIR)
B(7,3,1,AIR)
B(7,3,2,AIR)
B(7,3,3,AIR)
B(7,3,4,AIR)
B(7,3,5,AIR)
B(7,3,6,AIR)
B(7,3,7,WOOD:2)
B(7,3,8,DIRT)
B(7,3,9,GRASS)
B(7,3,10,GRASS)
B(7,4,-7,GRASS)
B(7,4,-6,WOOD:2)
B(7,4,-5,AIR)
B(7,4,-4,AIR)
B(7,4,-3,AIR)
B(7,4,-2,177:4)
B(7,4,0,177:4)
B(7,4,-1,AIR)
B(7,4,1,AIR)
B(7,4,2,AIR)
B(7,4,3,AIR)
B(7,4,4,AIR)
B(7,4,5,WOOD_STEP:10)
B(7,4,6,WOOD:2)
B(7,4,7,DIRT)
B(7,4,8,GRASS)
B(7,5,-6,GRASS)
B(7,5,-5,WOOD:2)
B(7,5,-4,WOOD_STEP:10)
B(7,5,-3,WOOD_STEP:10)
B(7,5,-2,WOOD_STEP:10)
B(7,5,-1,WOOD_STEP:10)
B(7,5,0,WOOD_STEP:10)
B(7,5,1,WOOD_STEP:10)
B(7,5,2,WOOD_STEP:10)
B(7,5,3,WOOD:2)
B(7,5,4,WOOD:2)
B(7,5,5,DIRT)
B(7,5,6,GRASS)
B(7,5,7,GRASS)
B(7,6,-5,GRASS)
B(7,6,-4,GRASS)
B(7,6,-3,DIRT)
B(7,6,-2,DIRT)
B(7,6,-1,DIRT)
B(7,6,0,DIRT)
B(7,6,1,DIRT)
B(7,6,2,GRASS)
B(7,6,3,GRASS)
B(7,6,4,GRASS)
B(7,6,5,GRASS)
B(7,7,-3,GRASS)
B(7,7,-2,GRASS)
B(7,7,-1,GRASS)
B(7,7,0,GRASS)
B(7,7,1,GRASS)
B(8,-10,-9,STONE)
B(8,-10,-8,STONE)
B(8,-10,-7,STONE)
B(8,-10,-6,STONE)
B(8,-10,-5,STONE)
B(8,-10,-4,STONE)
B(8,-10,-3,STONE)
B(8,-10,-2,STONE)
B(8,-10,-1,STONE)
B(8,-10,0,STONE)
B(8,-10,1,STONE)
B(8,-10,2,STONE)
B(8,-10,3,STONE)
B(8,-10,4,STONE)
B(8,-10,6,STONE)
B(8,-10,7,STONE)
B(8,-10,8,STONE)
B(8,-9,-10,STONE)
B(8,-9,-9,STONE)
B(8,-9,-8,STONE)
B(8,-9,-7,STONE)
B(8,-9,-6,STONE)
B(8,-9,-5,STONE)
B(8,-9,-4,STONE)
B(8,-9,-3,STONE)
B(8,-9,-2,STONE)
B(8,-9,-1,STONE)
B(8,-9,0,STONE)
B(8,-9,1,STONE)
B(8,-9,2,STONE)
B(8,-9,3,STONE)
B(8,-9,4,STONE)
B(8,-9,5,STONE)
B(8,-9,6,STONE)
B(8,-9,7,STONE)
B(8,-9,8,STONE)
B(8,-9,9,STONE)
B(8,-8,-10,STONE)
B(8,-8,-9,STONE)
B(8,-8,-8,STONE)
B(8,-8,-7,STONE)
B(8,-8,-6,STONE)
B(8,-8,-5,STONE)
B(8,-8,-4,STONE)
B(8,-8,-3,STONE)
B(8,-8,-2,SMOOTH_BRICK)
B(8,-8,-1,SMOOTH_BRICK)
B(8,-8,0,WOOL:15)
B(8,-8,1,WOOL:15)
B(8,-8,2,WOOL:15)
B(8,-8,3,WOOL:15)
B(8,-8,4,WOOL:15)
B(8,-8,5,WOOL:15)
B(8,-8,6,WOOL:15)
B(8,-8,7,STONE)
B(8,-8,8,STONE)
B(8,-8,9,STONE)
B(8,-8,10,STONE)
B(8,-7,-11,STONE)
B(8,-7,-10,STONE)
B(8,-7,-9,STONE)
B(8,-7,-8,STONE)
B(8,-7,-7,STONE)
B(8,-7,-6,STONE)
B(8,-7,-5,STONE)
B(8,-7,-4,STONE)
B(8,-7,-3,BRICK_STAIRS)
B(8,-7,-2,AIR)
B(8,-7,-1,AIR)
B(8,-7,0,AIR)
B(8,-7,1,AIR)
B(8,-7,2,AIR)
B(8,-7,3,WOOD_STAIRS:1)
B(8,-7,4,AIR)
B(8,-7,5,AIR)
B(8,-7,6,DARK_OAK_FENCE)
B(8,-7,7,BRICK)
B(8,-7,8,STONE)
B(8,-7,9,STONE)
B(8,-7,10,STONE)
B(8,-7,11,STONE)
B(8,-6,-12,STONE)
B(8,-6,-11,SMOOTH_BRICK)
B(8,-6,-10,WOOL:7)
B(8,-6,-9,WOOL:7)
B(8,-6,-8,WOOL:7)
B(8,-6,-7,WOOL:7)
B(8,-6,-6,WOOL:7)
B(8,-6,-5,SMOOTH_BRICK)
B(8,-6,-4,BRICK_STAIRS)
B(8,-6,-3,AIR)
B(8,-6,-2,AIR)
B(8,-6,-1,AIR)
B(8,-6,0,AIR)
B(8,-6,1,AIR)
B(8,-6,2,AIR)
B(8,-6,3,AIR)
B(8,-6,4,AIR)
B(8,-6,5,AIR)
B(8,-6,6,DARK_OAK_FENCE)
B(8,-6,7,STONE:2)
B(8,-6,8,STONE)
B(8,-6,9,STONE)
B(8,-6,10,STONE)
B(8,-6,11,STONE)
B(8,-5,-13,STONE)
B(8,-5,-12,STONE:2)
B(8,-5,-11,WOOD_STAIRS:5)
B(8,-5,-10,AIR)
B(8,-5,-9,AIR)
B(8,-5,-8,AIR)
B(8,-5,-7,AIR)
B(8,-5,-6,AIR)
B(8,-5,-5,AIR)
B(8,-5,-4,AIR)
B(8,-5,-3,AIR)
B(8,-5,-2,AIR)
B(8,-5,-1,AIR)
B(8,-5,0,AIR)
B(8,-5,1,AIR)
B(8,-5,2,AIR)
B(8,-5,3,AIR)
B(8,-5,4,AIR)
B(8,-5,5,AIR)
B(8,-5,6,DARK_OAK_FENCE)
B(8,-5,7,BRICK)
B(8,-5,8,STONE)
B(8,-5,9,STONE)
B(8,-5,10,STONE)
B(8,-5,11,STONE)
B(8,-5,12,STONE)
B(8,-4,-13,DIRT)
B(8,-4,-12,BRICK)
B(8,-4,-11,JACK_O_LANTERN:0)
B(8,-4,-10,AIR)
B(8,-4,-9,AIR)
B(8,-4,-8,AIR)
B(8,-4,-7,AIR)
B(8,-4,-6,AIR)
B(8,-4,-5,AIR)
B(8,-4,-4,AIR)
B(8,-4,-3,AIR)
B(8,-4,-2,AIR)
B(8,-4,-1,AIR)
B(8,-4,0,AIR)
B(8,-4,1,AIR)
B(8,-4,2,AIR)
B(8,-4,3,AIR)
B(8,-4,4,AIR)
B(8,-4,5,AIR)
B(8,-4,6,50)
B(8,-4,7,BRICK)
B(8,-4,8,STONE)
B(8,-4,9,STONE)
B(8,-4,10,STONE)
B(8,-4,11,STONE)
B(8,-4,12,STONE)
B(8,-4,13,STONE)
B(8,-4,14,DIRT)
B(8,-3,-14,DIRT)
B(8,-3,-13,DIRT)
B(8,-3,-12,STONE:2)
B(8,-3,-11,AIR)
B(8,-3,-10,AIR)
B(8,-3,-9,AIR)
B(8,-3,-8,AIR)
B(8,-3,-7,AIR)
B(8,-3,-6,AIR)
B(8,-3,-5,AIR)
B(8,-3,-4,AIR)
B(8,-3,-3,BRICK_STAIRS:5)
B(8,-3,-2,AIR)
B(8,-3,-1,AIR)
B(8,-3,0,AIR)
B(8,-3,1,AIR)
B(8,-3,2,AIR)
B(8,-3,3,AIR)
B(8,-3,4,AIR)
B(8,-3,5,AIR)
B(8,-3,6,AIR)
B(8,-3,7,STONE:2)
B(8,-3,8,STONE)
B(8,-3,9,STONE)
B(8,-3,10,STONE)
B(8,-3,11,STONE)
B(8,-3,12,STONE)
B(8,-3,13,DIRT)
B(8,-3,14,DIRT)
B(8,-3,15,DIRT)
B(8,-2,-14,GRASS)
B(8,-2,-13,DIRT)
B(8,-2,-12,STAINED_CLAY:14)
B(8,-2,-11,AIR)
B(8,-2,-10,AIR)
B(8,-2,-9,AIR)
B(8,-2,-8,AIR)
B(8,-2,-7,AIR)
B(8,-2,-6,AIR)
B(8,-2,-5,AIR)
B(8,-2,-4,AIR)
B(8,-2,-3,BRICK)
B(8,-2,-2,AIR)
B(8,-2,-1,AIR)
B(8,-2,0,AIR)
B(8,-2,1,AIR)
B(8,-2,2,AIR)
B(8,-2,3,AIR)
B(8,-2,4,AIR)
B(8,-2,5,AIR)
B(8,-2,6,AIR)
B(8,-2,7,STAINED_CLAY:14)
B(8,-2,8,STONE)
B(8,-2,9,STONE)
B(8,-2,10,STONE)
B(8,-2,11,STONE)
B(8,-2,12,DIRT)
B(8,-2,13,DIRT)
B(8,-2,14,DIRT)
B(8,-2,15,DIRT)
B(8,-1,-13,GRASS)
B(8,-1,-12,STONE:2)
B(8,-1,-11,AIR)
B(8,-1,-10,AIR)
B(8,-1,-9,AIR)
B(8,-1,-8,AIR)
B(8,-1,-7,AIR)
B(8,-1,-6,AIR)
B(8,-1,-5,AIR)
B(8,-1,-4,AIR)
B(8,-1,-3,STONE:2)
B(8,-1,-2,STEP:8)
B(8,-1,-1,STEP:12)
B(8,-1,0,STEP:8)
B(8,-1,1,AIR)
B(8,-1,2,AIR)
B(8,-1,3,AIR)
B(8,-1,4,STEP:8)
B(8,-1,5,STEP:12)
B(8,-1,6,STEP:8)
B(8,-1,7,STONE:2)
B(8,-1,8,STONE)
B(8,-1,9,STONE)
B(8,-1,10,STONE)
B(8,-1,11,DIRT)
B(8,-1,12,DIRT)
B(8,-1,13,DIRT)
B(8,-1,14,GRASS)
B(8,-1,15,GRASS)
B(8,0,-12,GRASS)
B(8,0,-11,WOOD:5)
B(8,0,-10,WOOD:5)
B(8,0,-9,WOOD:5)
B(8,0,-8,WOOD:5)
B(8,0,-7,WOOD:5)
B(8,0,-6,WOOD:5)
B(8,0,-5,WOOD:5)
B(8,0,-4,WOOD:5)
B(8,0,-3,WOOD:5)
B(8,0,-2,WOOD:5)
B(8,0,-1,WOOD:5)
B(8,0,0,WOOD:5)
B(8,0,1,WOOD:5)
B(8,0,2,WOOD:5)
B(8,0,3,WOOD:5)
B(8,0,4,WOOD:5)
B(8,0,5,WOOD:5)
B(8,0,6,STONE)
B(8,0,7,STONE)
B(8,0,8,STONE)
B(8,0,9,DIRT)
B(8,0,10,DIRT)
B(8,0,11,DIRT)
B(8,0,12,DIRT)
B(8,0,13,GRASS)
B(8,1,-11,GRASS)
B(8,1,-10,DIRT)
B(8,1,-9,DIRT)
B(8,1,-8,DIRT)
B(8,1,-7,WOOD:2)
B(8,1,-6,DARK_OAK_STAIRS:0)
B(8,1,-5,DARK_OAK_STAIRS:0)
B(8,1,-4,DARK_OAK_STAIRS:0)
B(8,1,-3,DARK_OAK_STAIRS:0)
B(8,1,-2,WOOD:5)
B(8,1,-1,AIR)
B(8,1,0,WOOD:5)
B(8,1,1,DARK_OAK_STAIRS:0)
B(8,1,2,DARK_OAK_STAIRS:0)
B(8,1,3,DARK_OAK_STAIRS:0)
B(8,1,4,DARK_OAK_STAIRS:0)
B(8,1,5,DARK_OAK_STAIRS:0)
B(8,1,6,WOOD:2)
B(8,1,7,STONE)
B(8,1,8,DIRT)
B(8,1,9,DIRT)
B(8,1,10,DIRT)
B(8,1,11,DIRT)
B(8,1,12,GRASS)
B(8,2,-10,GRASS)
B(8,2,-9,DIRT)
B(8,2,-8,DIRT)
B(8,2,-7,WOOD:2)
B(8,2,-6,AIR)
B(8,2,-5,AIR)
B(8,2,-4,AIR)
B(8,2,-3,AIR)
B(8,2,-2,DARK_OAK_FENCE)
B(8,2,-1,AIR)
B(8,2,0,DARK_OAK_FENCE)
B(8,2,1,AIR)
B(8,2,2,AIR)
B(8,2,3,AIR)
B(8,2,4,AIR)
B(8,2,5,AIR)
B(8,2,6,WOOD:2)
B(8,2,7,DIRT)
B(8,2,8,DIRT)
B(8,2,9,DIRT)
B(8,2,10,DIRT)
B(8,2,11,GRASS)
B(8,3,-9,GRASS)
B(8,3,-8,DIRT)
B(8,3,-7,WOOD:2)
B(8,3,-6,AIR)
B(8,3,-5,AIR)
B(8,3,-4,AIR)
B(8,3,-3,AIR)
B(8,3,-2,DARK_OAK_FENCE)
B(8,3,-1,AIR)
B(8,3,0,DARK_OAK_FENCE)
B(8,3,1,AIR)
B(8,3,2,AIR)
B(8,3,3,AIR)
B(8,3,4,AIR)
B(8,3,5,AIR)
B(8,3,6,WOOD:2)
B(8,3,7,DIRT)
B(8,3,8,DIRT)
B(8,3,9,GRASS)
B(8,3,10,GRASS)
B(8,4,-8,GRASS)
B(8,4,-7,DIRT)
B(8,4,-6,WOOD_DOUBLE_STEP:2)
B(8,4,-5,AIR)
B(8,4,-4,AIR)
B(8,4,-3,DARK_OAK_STAIRS:4)
B(8,4,-2,WOOD:5)
B(8,4,-1,DARK_OAK_STAIRS:4)
B(8,4,0,WOOD:5)
B(8,4,1,DARK_OAK_STAIRS:4)
B(8,4,2,AIR)
B(8,4,3,AIR)
B(8,4,4,AIR)
B(8,4,5,AIR)
B(8,4,6,WOOD_DOUBLE_STEP:2)
B(8,4,7,DIRT)
B(8,4,8,GRASS)
B(8,5,-7,GRASS)
B(8,5,-6,WOOD_DOUBLE_STEP:2)
B(8,5,-5,WOOD_STEP:10)
B(8,5,-4,WOOD_STEP:10)
B(8,5,-3,WOOD_DOUBLE_STEP:2)
B(8,5,-2,WOOD_DOUBLE_STEP:2)
B(8,5,-1,WOOD_DOUBLE_STEP:2)
B(8,5,0,WOOD_DOUBLE_STEP:2)
B(8,5,1,WOOD_DOUBLE_STEP:2)
B(8,5,2,WOOD_STEP:10)
B(8,5,3,WOOD_STEP:10)
B(8,5,4,WOOD_DOUBLE_STEP:2)
B(8,5,5,WOOD_DOUBLE_STEP:2)
B(8,5,6,DIRT)
B(8,5,7,GRASS)
B(8,6,-6,GRASS)
B(8,6,-5,GRASS)
B(8,6,-4,DIRT)
B(8,6,-3,DIRT)
B(8,6,-2,DIRT)
B(8,6,-1,DIRT)
B(8,6,0,DIRT)
B(8,6,1,DIRT)
B(8,6,2,DIRT)
B(8,6,3,GRASS)
B(8,6,4,GRASS)
B(8,6,5,GRASS)
B(8,6,6,GRASS)
B(8,7,-4,GRASS)
B(8,7,-3,GRASS)
B(8,7,-2,GRASS)
B(8,7,-1,DIRT)
B(8,7,0,DIRT)
B(8,7,1,GRASS)
B(8,7,2,GRASS)
B(8,8,-1,GRASS)
B(8,8,0,GRASS)
B(9,-10,-8,STONE)
B(9,-10,-7,STONE)
B(9,-10,-6,STONE)
B(9,-10,-5,STONE)
B(9,-10,-4,STONE)
B(9,-10,-3,STONE)
B(9,-10,-2,STONE)
B(9,-10,-1,STONE)
B(9,-10,0,STONE)
B(9,-10,1,STONE)
B(9,-10,2,STONE)
B(9,-10,3,STONE)
B(9,-10,4,STONE)
B(9,-10,5,STONE)
B(9,-10,6,STONE)
B(9,-10,7,STONE)
B(9,-10,8,STONE)
B(9,-10,9,STONE)
B(9,-9,-10,STONE)
B(9,-9,-9,STONE)
B(9,-9,-8,STONE)
B(9,-9,-7,STONE)
B(9,-9,-6,STONE)
B(9,-9,-5,STONE)
B(9,-9,-4,STONE)
B(9,-9,-3,STONE)
B(9,-9,-2,STONE)
B(9,-9,-1,STONE)
B(9,-9,0,STONE)
B(9,-9,1,STONE)
B(9,-9,2,STONE)
B(9,-9,3,STONE)
B(9,-9,4,STONE)
B(9,-9,5,STONE)
B(9,-9,6,STONE)
B(9,-9,7,STONE)
B(9,-9,8,STONE)
B(9,-9,9,STONE)
B(9,-8,-11,STONE)
B(9,-8,-10,STONE)
B(9,-8,-9,STONE)
B(9,-8,-8,STONE)
B(9,-8,-7,STONE)
B(9,-8,-6,STONE)
B(9,-8,-5,STONE)
B(9,-8,-4,STONE)
B(9,-8,-3,STONE)
B(9,-8,-2,SMOOTH_BRICK)
B(9,-8,-1,SMOOTH_BRICK)
B(9,-8,0,WOOL:15)
B(9,-8,1,WOOL:15)
B(9,-8,2,WOOL:15)
B(9,-8,3,WOOL:15)
B(9,-8,4,WOOL:15)
B(9,-8,5,WOOL:15)
B(9,-8,6,WOOL:15)
B(9,-8,7,STONE)
B(9,-8,8,STONE)
B(9,-8,9,STONE)
B(9,-8,10,STONE)
B(9,-7,-12,STONE)
B(9,-7,-11,STONE)
B(9,-7,-10,STONE)
B(9,-7,-9,STONE)
B(9,-7,-8,STONE)
B(9,-7,-7,STONE)
B(9,-7,-6,STONE)
B(9,-7,-5,STONE)
B(9,-7,-4,STONE)
B(9,-7,-3,BRICK_STAIRS)
B(9,-7,-2,AIR)
B(9,-7,-1,AIR)
B(9,-7,0,AIR)
B(9,-7,1,AIR)
B(9,-7,2,WOOD_STAIRS:5)
B(9,-7,3,WOOD_STAIRS:5)
B(9,-7,4,WOOD_STAIRS:5)
B(9,-7,5,AIR)
B(9,-7,6,AIR)
B(9,-7,7,BRICK)
B(9,-7,8,STONE)
B(9,-7,9,STONE)
B(9,-7,10,STONE)
B(9,-7,11,STONE)
B(9,-6,-12,STONE)
B(9,-6,-11,SMOOTH_BRICK)
B(9,-6,-10,WOOL:7)
B(9,-6,-9,WOOL:7)
B(9,-6,-8,WOOL:7)
B(9,-6,-7,WOOL:7)
B(9,-6,-6,WOOL:7)
B(9,-6,-5,SMOOTH_BRICK)
B(9,-6,-4,BRICK_STAIRS)
B(9,-6,-3,AIR)
B(9,-6,-2,AIR)
B(9,-6,-1,AIR)
B(9,-6,0,AIR)
B(9,-6,1,AIR)
B(9,-6,2,AIR)
B(9,-6,3,CAKE_BLOCK:4)
B(9,-6,4,AIR)
B(9,-6,5,AIR)
B(9,-6,6,AIR)
B(9,-6,7,STONE:2)
B(9,-6,8,STONE)
B(9,-6,9,STONE)
B(9,-6,10,STONE)
B(9,-6,11,STONE)
B(9,-5,-13,STONE)
B(9,-5,-12,STONE:2)
B(9,-5,-11,WOOD_STEP:8)
B(9,-5,-10,WOOD_STAIRS:2)
B(9,-5,-9,AIR)
B(9,-5,-8,AIR)
B(9,-5,-7,AIR)
B(9,-5,-6,AIR)
B(9,-5,-5,AIR)
B(9,-5,-4,AIR)
B(9,-5,-3,AIR)
B(9,-5,-2,AIR)
B(9,-5,-1,AIR)
B(9,-5,0,AIR)
B(9,-5,1,AIR)
B(9,-5,2,AIR)
B(9,-5,3,AIR)
B(9,-5,4,AIR)
B(9,-5,5,AIR)
B(9,-5,6,AIR)
B(9,-5,7,BRICK)
B(9,-5,8,STONE)
B(9,-5,9,STONE)
B(9,-5,10,STONE)
B(9,-5,11,STONE)
B(9,-5,12,STONE)
B(9,-4,-13,DIRT)
B(9,-4,-12,BRICK)
B(9,-4,-11,AIR)
B(9,-4,-10,AIR)
B(9,-4,-9,AIR)
B(9,-4,-8,AIR)
B(9,-4,-7,AIR)
B(9,-4,-6,AIR)
B(9,-4,-5,AIR)
B(9,-4,-4,AIR)
B(9,-4,-3,AIR)
B(9,-4,-2,AIR)
B(9,-4,-1,AIR)
B(9,-4,0,AIR)
B(9,-4,1,AIR)
B(9,-4,2,AIR)
B(9,-4,3,AIR)
B(9,-4,4,AIR)
B(9,-4,5,AIR)
B(9,-4,6,AIR)
B(9,-4,7,BRICK)
B(9,-4,8,STONE)
B(9,-4,9,STONE)
B(9,-4,10,STONE)
B(9,-4,11,STONE)
B(9,-4,12,STONE)
B(9,-4,13,STONE)
B(9,-4,14,DIRT)
B(9,-3,-14,DIRT)
B(9,-3,-13,DIRT)
B(9,-3,-12,STONE:2)
B(9,-3,-11,AIR)
B(9,-3,-10,AIR)
B(9,-3,-9,AIR)
B(9,-3,-8,AIR)
B(9,-3,-7,AIR)
B(9,-3,-6,AIR)
B(9,-3,-5,AIR)
B(9,-3,-4,AIR)
B(9,-3,-3,AIR)
B(9,-3,-2,AIR)
B(9,-3,-1,AIR)
B(9,-3,0,AIR)
B(9,-3,1,AIR)
B(9,-3,2,AIR)
B(9,-3,3,AIR)
B(9,-3,4,AIR)
B(9,-3,5,AIR)
B(9,-3,6,AIR)
B(9,-3,7,STONE:2)
B(9,-3,8,STONE)
B(9,-3,9,STONE)
B(9,-3,10,STONE)
B(9,-3,11,STONE)
B(9,-3,12,STONE)
B(9,-3,13,DIRT)
B(9,-3,14,DIRT)
B(9,-3,15,DIRT)
B(9,-2,-14,GRASS)
B(9,-2,-13,DIRT)
B(9,-2,-12,STAINED_CLAY:14)
B(9,-2,-11,AIR)
B(9,-2,-10,AIR)
B(9,-2,-9,AIR)
B(9,-2,-8,AIR)
B(9,-2,-7,AIR)
B(9,-2,-6,AIR)
B(9,-2,-5,AIR)
B(9,-2,-4,AIR)
B(9,-2,-3,BRICK)
B(9,-2,-2,AIR)
B(9,-2,-1,AIR)
B(9,-2,0,AIR)
B(9,-2,1,AIR)
B(9,-2,2,AIR)
B(9,-2,3,AIR)
B(9,-2,4,AIR)
B(9,-2,5,AIR)
B(9,-2,6,AIR)
B(9,-2,7,STAINED_CLAY:14)
B(9,-2,8,STONE)
B(9,-2,9,STONE)
B(9,-2,10,STONE)
B(9,-2,11,STONE)
B(9,-2,12,DIRT)
B(9,-2,13,DIRT)
B(9,-2,14,DIRT)
B(9,-2,15,GRASS)
B(9,-1,-13,GRASS)
B(9,-1,-12,STONE:2)
B(9,-1,-11,AIR)
B(9,-1,-10,AIR)
B(9,-1,-9,AIR)
B(9,-1,-8,AIR)
B(9,-1,-7,AIR)
B(9,-1,-6,AIR)
B(9,-1,-5,AIR)
B(9,-1,-4,AIR)
B(9,-1,-3,STONE:2)
B(9,-1,-2,STEP:8)
B(9,-1,-1,STEP:12)
B(9,-1,0,STEP:8)
B(9,-1,1,AIR)
B(9,-1,2,AIR)
B(9,-1,3,AIR)
B(9,-1,4,STEP:8)
B(9,-1,5,STEP:12)
B(9,-1,6,STEP:8)
B(9,-1,7,STONE:2)
B(9,-1,8,STONE)
B(9,-1,9,STONE)
B(9,-1,10,STONE)
B(9,-1,11,DIRT)
B(9,-1,12,DIRT)
B(9,-1,13,DIRT)
B(9,-1,14,GRASS)
B(9,0,-12,GRASS)
B(9,0,-11,WOOD:5)
B(9,0,-10,WOOD:5)
B(9,0,-9,WOOD:5)
B(9,0,-8,WOOD:5)
B(9,0,-7,WOOD:5)
B(9,0,-6,WOOD:5)
B(9,0,-5,WOOD:5)
B(9,0,-4,WOOD:5)
B(9,0,-3,WOOD:5)
B(9,0,-2,WOOD:5)
B(9,0,-1,WOOD:5)
B(9,0,0,WOOD:5)
B(9,0,1,WOOD:5)
B(9,0,2,WOOD:5)
B(9,0,3,WOOD:5)
B(9,0,4,WOOD:5)
B(9,0,5,STONE)
B(9,0,6,STONE)
B(9,0,7,STONE)
B(9,0,8,STONE)
B(9,0,9,DIRT)
B(9,0,10,DIRT)
B(9,0,11,DIRT)
B(9,0,12,DIRT)
B(9,0,13,GRASS)
B(9,1,-11,GRASS)
B(9,1,-10,DIRT)
B(9,1,-9,DIRT)
B(9,1,-8,STONE)
B(9,1,-7,WOOD:2)
B(9,1,-6,WOOD:5)
B(9,1,-5,WOOD:5)
B(9,1,-4,WOOD:5)
B(9,1,-3,WOOD:5)
B(9,1,-2,WOOD:5)
B(9,1,0,WOOD:5)
B(9,1,1,WOOD:5)
B(9,1,2,WOOD:5)
B(9,1,3,WOOD:5)
B(9,1,4,WOOD:5)
B(9,1,5,WOOD:5)
B(9,1,6,WOOD:2)
B(9,1,7,STONE)
B(9,1,8,DIRT)
B(9,1,9,DIRT)
B(9,1,10,DIRT)
B(9,1,11,DIRT)
B(9,1,12,GRASS)
B(9,2,-10,GRASS)
B(9,2,-9,DIRT)
B(9,2,-8,DIRT)
B(9,2,-7,WOOD:2)
B(9,2,-6,WOOD:5)
B(9,2,-5,WOOD:2)
B(9,2,-4,WOOD:2)
B(9,2,-3,WOOD:5)
B(9,2,-2,WOOD:5)
B(9,2,0,WOOD:5)
B(9,2,1,WOOD:5)
B(9,2,2,WOOD:2)
B(9,2,3,WOOD:2)
B(9,2,4,WOOD:5)
B(9,2,5,WOOD:2)
B(9,2,6,WOOD:2)
B(9,2,7,DIRT)
B(9,2,8,DIRT)
B(9,2,9,DIRT)
B(9,2,10,DIRT)
B(9,2,11,GRASS)
B(9,3,-9,GRASS)
B(9,3,-8,DIRT)
B(9,3,-7,WOOD:2)
B(9,3,-6,WOOD:5)
B(9,3,-5,WOOD:2)
B(9,3,-4,WOOD:2)
B(9,3,-3,WOOD:5)
B(9,3,-2,WOOD:5)
B(9,3,-1,WOOD:5)
B(9,3,0,WOOD:5)
B(9,3,1,WOOD:5)
B(9,3,2,WOOD:2)
B(9,3,3,WOOD:2)
B(9,3,4,WOOD:5)
B(9,3,5,WOOD:2)
B(9,3,6,WOOD:2)
B(9,3,7,DIRT)
B(9,3,8,DIRT)
B(9,3,9,GRASS)
B(9,3,10,GRASS)
B(9,4,-8,DIRT)
B(9,4,-7,WOOD:2)
B(9,4,-6,WOOD:5)
B(9,4,-5,WOOD:2)
B(9,4,-4,WOOD:2)
B(9,4,-3,WOOD:5)
B(9,4,-2,DARK_OAK_FENCE)
B(9,4,-1,50)
B(9,1,-1,dark_oak_door:0)
B(9,2,-1,dark_oak_door:8)
B(9,4,0,DARK_OAK_FENCE)
B(9,4,1,WOOD:5)
B(9,4,2,WOOD:2)
B(9,4,3,WOOD:2)
B(9,4,4,WOOD:5)
B(9,4,5,WOOD:2)
B(9,4,6,DIRT)
B(9,4,7,DIRT)
B(9,4,8,GRASS)
B(9,5,-8,GRASS)
B(9,5,-7,WOOD:5)
B(9,5,-6,WOOD:5)
B(9,5,-5,WOOD:2)
B(9,5,-4,WOOD:2)
B(9,5,-3,WOOD:5)
B(9,5,-2,WOOD:5)
B(9,5,-1,WOOD:5)
B(9,5,0,WOOD:5)
B(9,5,1,WOOD:5)
B(9,5,2,WOOD:2)
B(9,5,3,WOOD:2)
B(9,5,4,WOOD:5)
B(9,5,5,WOOD:5)
B(9,5,6,AIR)
B(9,5,7,GRASS)
B(9,6,-7,GRASS)
B(9,6,-6,GRASS)
B(9,6,-5,DIRT)
B(9,6,-4,DIRT)
B(9,6,-3,DIRT)
B(9,6,-2,DIRT)
B(9,6,-1,DIRT)
B(9,6,0,DIRT)
B(9,6,1,DIRT)
B(9,6,2,DIRT)
B(9,6,3,DIRT)
B(9,6,4,GRASS)
B(9,6,5,GRASS)
B(9,6,6,GRASS)
B(9,7,-5,GRASS)
B(9,7,-4,GRASS)
B(9,7,-3,GRASS)
B(9,7,-2,DIRT)
B(9,7,-1,DIRT)
B(9,7,0,DIRT)
B(9,7,1,DIRT)
B(9,7,2,GRASS)
B(9,7,3,GRASS)
B(9,8,-2,GRASS)
B(9,8,-1,GRASS)
B(9,8,0,GRASS)
B(9,8,1,GRASS)
B(10,-10,-8,STONE)
B(10,-10,-7,STONE)
B(10,-10,-6,STONE)
B(10,-10,-5,STONE)
B(10,-10,-4,STONE)
B(10,-10,-3,STONE)
B(10,-10,-2,STONE)
B(10,-10,-1,STONE)
B(10,-10,0,STONE)
B(10,-10,1,STONE)
B(10,-10,2,STONE)
B(10,-10,3,STONE)
B(10,-10,4,STONE)
B(10,-10,5,STONE)
B(10,-10,6,STONE)
B(10,-10,7,STONE)
B(10,-10,8,STONE)
B(10,-9,-10,STONE)
B(10,-9,-9,STONE)
B(10,-9,-8,STONE)
B(10,-9,-7,STONE)
B(10,-9,-6,STONE)
B(10,-9,-5,STONE)
B(10,-9,-4,STONE)
B(10,-9,-3,STONE)
B(10,-9,-2,STONE)
B(10,-9,-1,STONE)
B(10,-9,0,STONE)
B(10,-9,1,STONE)
B(10,-9,2,STONE)
B(10,-9,3,STONE)
B(10,-9,4,STONE)
B(10,-9,5,STONE)
B(10,-9,6,STONE)
B(10,-9,7,STONE)
B(10,-9,8,STONE)
B(10,-9,9,STONE)
B(10,-8,-11,STONE)
B(10,-8,-10,STONE)
B(10,-8,-9,STONE)
B(10,-8,-8,STONE)
B(10,-8,-7,STONE)
B(10,-8,-6,STONE)
B(10,-8,-5,STONE)
B(10,-8,-4,STONE)
B(10,-8,-3,STONE)
B(10,-8,-2,SMOOTH_BRICK)
B(10,-8,-1,SMOOTH_BRICK)
B(10,-8,0,WOOL:15)
B(10,-8,1,WOOL:15)
B(10,-8,2,WOOL:15)
B(10,-8,3,WOOL:15)
B(10,-8,4,WOOL:15)
B(10,-8,5,WOOL:15)
B(10,-8,6,WOOL:15)
B(10,-8,7,STONE)
B(10,-8,8,STONE)
B(10,-8,9,STONE)
B(10,-8,10,STONE)
B(10,-7,-12,STONE)
B(10,-7,-11,STONE)
B(10,-7,-10,STONE)
B(10,-7,-9,STONE)
B(10,-7,-8,STONE)
B(10,-7,-7,STONE)
B(10,-7,-6,STONE)
B(10,-7,-5,STONE)
B(10,-7,-4,STONE)
B(10,-7,-3,BRICK_STAIRS)
B(10,-7,-2,AIR)
B(10,-7,-1,AIR)
B(10,-7,0,AIR)
B(10,-7,1,WOOD_STAIRS)
B(10,-7,2,WOOD_STEP:8)
B(10,-7,3,WOOD_STEP:8)
B(10,-7,4,WOOD_STEP:8)
B(10,-7,5,WOOD_STAIRS:2)
B(10,-7,6,AIR)
B(10,-7,7,BRICK)
B(10,-7,8,STONE)
B(10,-7,9,STONE)
B(10,-7,10,STONE)
B(10,-7,11,STONE)
B(10,-6,-12,STONE)
B(10,-6,-11,SMOOTH_BRICK)
B(10,-6,-10,WOOL:7)
B(10,-6,-9,WOOL:7)
B(10,-6,-8,WOOL:7)
B(10,-6,-7,WOOL:7)
B(10,-6,-6,WOOL:7)
B(10,-6,-5,SMOOTH_BRICK)
B(10,-6,-4,BRICK_STAIRS)
B(10,-6,-3,AIR)
B(10,-6,-2,AIR)
B(10,-6,-1,AIR)
B(10,-6,0,AIR)
B(10,-6,1,AIR)
B(10,-6,2,DARK_OAK_FENCE)
B(10,-6,3,AIR)
B(10,-6,4,AIR)
B(10,-6,5,AIR)
B(10,-6,6,AIR)
B(10,-6,7,STONE:2)
B(10,-6,8,STONE)
B(10,-6,9,STONE)
B(10,-6,10,STONE)
B(10,-6,11,STONE)
B(10,-5,-13,STONE)
B(10,-5,-12,STONE:2)
B(10,-5,-11,WOOD_STAIRS:4)
B(10,-5,-10,AIR)
B(10,-5,-9,AIR)
B(10,-5,-8,AIR)
B(10,-5,-7,AIR)
B(10,-5,-6,AIR)
B(10,-5,-5,AIR)
B(10,-5,-4,AIR)
B(10,-5,-3,AIR)
B(10,-5,-2,AIR)
B(10,-5,-1,AIR)
B(10,-5,0,AIR)
B(10,-5,1,AIR)
B(10,-5,2,50)
B(10,-5,3,AIR)
B(10,-5,4,AIR)
B(10,-5,5,AIR)
B(10,-5,6,AIR)
B(10,-5,7,BRICK)
B(10,-5,8,STONE)
B(10,-5,9,STONE)
B(10,-5,10,STONE)
B(10,-5,11,STONE)
B(10,-5,12,STONE)
B(10,-4,-13,STONE)
B(10,-4,-12,BRICK)
B(10,-4,-11,AIR)
B(10,-4,-10,AIR)
B(10,-4,-9,AIR)
B(10,-4,-8,AIR)
B(10,-4,-7,AIR)
B(10,-4,-6,AIR)
B(10,-4,-5,AIR)
B(10,-4,-4,AIR)
B(10,-4,-3,AIR)
B(10,-4,-2,AIR)
B(10,-4,-1,AIR)
B(10,-4,0,AIR)
B(10,-4,1,AIR)
B(10,-4,2,AIR)
B(10,-4,3,AIR)
B(10,-4,4,AIR)
B(10,-4,5,AIR)
B(10,-4,6,AIR)
B(10,-4,7,BRICK)
B(10,-4,8,STONE)
B(10,-4,9,STONE)
B(10,-4,10,STONE)
B(10,-4,11,STONE)
B(10,-4,12,STONE)
B(10,-4,13,STONE)
B(10,-4,14,DIRT)
B(10,-3,-15,DIRT)
B(10,-3,-14,DIRT)
B(10,-3,-13,DIRT)
B(10,-3,-12,STONE:2)
B(10,-3,-11,AIR)
B(10,-3,-10,AIR)
B(10,-3,-9,AIR)
B(10,-3,-8,AIR)
B(10,-3,-7,AIR)
B(10,-3,-6,AIR)
B(10,-3,-5,AIR)
B(10,-3,-4,AIR)
B(10,-3,-3,BRICK_STAIRS:4)
B(10,-3,-2,AIR)
B(10,-3,-1,AIR)
B(10,-3,0,AIR)
B(10,-3,1,AIR)
B(10,-3,2,AIR)
B(10,-3,3,AIR)
B(10,-3,4,AIR)
B(10,-3,5,AIR)
B(10,-3,6,AIR)
B(10,-3,7,STONE:2)
B(10,-3,8,STONE)
B(10,-3,9,STONE)
B(10,-3,10,STONE)
B(10,-3,11,STONE)
B(10,-3,12,STONE)
B(10,-3,13,DIRT)
B(10,-3,14,DIRT)
B(10,-3,15,DIRT)
B(10,-2,-15,GRASS)
B(10,-2,-14,GRASS)
B(10,-2,-13,DIRT)
B(10,-2,-12,STAINED_CLAY:14)
B(10,-2,-11,AIR)
B(10,-2,-10,AIR)
B(10,-2,-9,AIR)
B(10,-2,-8,AIR)
B(10,-2,-7,AIR)
B(10,-2,-6,AIR)
B(10,-2,-5,AIR)
B(10,-2,-4,AIR)
B(10,-2,-3,BRICK)
B(10,-2,-2,AIR)
B(10,-2,-1,AIR)
B(10,-2,0,AIR)
B(10,-2,1,AIR)
B(10,-2,2,AIR)
B(10,-2,3,AIR)
B(10,-2,4,AIR)
B(10,-2,5,AIR)
B(10,-2,6,AIR)
B(10,-2,7,STAINED_CLAY:14)
B(10,-2,8,STONE)
B(10,-2,9,STONE)
B(10,-2,10,STONE)
B(10,-2,11,STONE)
B(10,-2,12,DIRT)
B(10,-2,13,DIRT)
B(10,-2,14,DIRT)
B(10,-2,15,GRASS)
B(10,-1,-13,DIRT)
B(10,-1,-12,STONE:2)
B(10,-1,-11,AIR)
B(10,-1,-10,AIR)
B(10,-1,-9,AIR)
B(10,-1,-8,AIR)
B(10,-1,-7,AIR)
B(10,-1,-6,AIR)
B(10,-1,-5,AIR)
B(10,-1,-4,AIR)
B(10,-1,-3,STONE:2)
B(10,-1,-2,STEP:8)
B(10,-1,-1,STEP:12)
B(10,-1,0,STEP:8)
B(10,-1,1,AIR)
B(10,-1,2,AIR)
B(10,-1,3,AIR)
B(10,-1,4,STEP:8)
B(10,-1,5,STEP:12)
B(10,-1,6,STEP:8)
B(10,-1,7,STONE:2)
B(10,-1,8,STONE)
B(10,-1,9,STONE)
B(10,-1,10,STONE)
B(10,-1,11,DIRT)
B(10,-1,12,DIRT)
B(10,-1,13,DIRT)
B(10,-1,14,GRASS)
B(10,0,-13,GRASS)
B(10,0,-12,DIRT)
B(10,0,-11,WOOD:5)
B(10,0,-10,WOOD:5)
B(10,0,-9,WOOD:5)
B(10,0,-8,WOOD:5)
B(10,0,-7,WOOD:5)
B(10,0,-6,WOOD:5)
B(10,0,-5,WOOD:5)
B(10,0,-4,WOOD:5)
B(10,0,-3,WOOD:5)
B(10,0,-2,WOOD:5)
B(10,0,-1,WOOD:5)
B(10,0,0,WOOD:5)
B(10,0,1,WOOD:5)
B(10,0,2,WOOD:5)
B(10,0,3,WOOD:5)
B(10,0,4,WOOD:5)
B(10,0,5,STONE)
B(10,0,6,STONE)
B(10,0,7,STONE)
B(10,0,8,STONE)
B(10,0,9,DIRT)
B(10,0,10,DIRT)
B(10,0,11,DIRT)
B(10,0,12,DIRT)
B(10,0,13,GRASS)
B(10,1,-12,GRASS)
B(10,1,-11,DIRT)
B(10,1,-10,DIRT)
B(10,1,-9,DIRT)
B(10,1,-8,STONE)
B(10,1,-7,WOOD:5)
B(10,1,-6,AIR)
B(10,1,-5,AIR)
B(10,1,-4,AIR)
B(10,1,-3,AIR)
B(10,1,-2,AIR)
B(10,1,-1,AIR)
B(10,1,0,AIR)
B(10,1,1,AIR)
B(10,1,2,AIR)
B(10,1,3,AIR)
B(10,1,4,AIR)
B(10,1,5,WOOD:5)
B(10,1,6,STONE)
B(10,1,7,STONE)
B(10,1,8,DIRT)
B(10,1,9,DIRT)
B(10,1,10,DIRT)
B(10,1,11,DIRT)
B(10,1,12,GRASS)
B(10,2,-11,GRASS)
B(10,2,-10,DIRT)
B(10,2,-9,DIRT)
B(10,2,-8,DIRT)
B(10,2,-7,WOOD:2)
B(10,2,-6,AIR)
B(10,2,-5,AIR)
B(10,2,-4,AIR)
B(10,2,-3,AIR)
B(10,2,-2,AIR)
B(10,2,-1,AIR)
B(10,2,0,AIR)
B(10,2,1,AIR)
B(10,2,2,AIR)
B(10,2,3,AIR)
B(10,2,4,AIR)
B(10,2,5,WOOD:5)
B(10,2,6,STONE)
B(10,2,7,DIRT)
B(10,2,8,DIRT)
B(10,2,9,DIRT)
B(10,2,10,DIRT)
B(10,2,11,GRASS)
B(10,3,-10,GRASS)
B(10,3,-9,DIRT)
B(10,3,-8,DIRT)
B(10,3,-7,WOOD:2)
B(10,3,-6,AIR)
B(10,3,-5,AIR)
B(10,3,-4,AIR)
B(10,3,-3,AIR)
B(10,3,-2,AIR)
B(10,3,-1,AIR)
B(10,3,0,AIR)
B(10,3,1,AIR)
B(10,3,2,AIR)
B(10,3,3,AIR)
B(10,3,4,AIR)
B(10,3,5,WOOD:5)
B(10,3,6,DIRT)
B(10,3,7,DIRT)
B(10,3,8,DIRT)
B(10,3,9,GRASS)
B(10,3,10,GRASS)
B(10,4,-9,GRASS)
B(10,4,-8,DIRT)
B(10,4,-7,WOOD:2)
B(10,4,-6,AIR)
B(10,4,-5,AIR)
B(10,4,-4,AIR)
B(10,4,-3,AIR)
B(10,4,-2,AIR)
B(10,4,-1,AIR)
B(10,4,0,AIR)
B(10,4,1,AIR)
B(10,4,2,AIR)
B(10,4,3,AIR)
B(10,4,4,AIR)
B(10,4,5,WOOD:5)
B(10,4,6,DIRT)
B(10,4,7,DIRT)
B(10,4,8,GRASS)
B(10,5,-8,GRASS)
B(10,5,-7,WOOD:2)
B(10,5,-6,WOOD_STEP:10)
B(10,5,-5,WOOD_STEP:10)
B(10,5,-4,WOOD_STEP:10)
B(10,5,-3,WOOD_STEP:10)
B(10,5,-2,WOOD_STEP:10)
B(10,5,-1,WOOD_STEP:10)
B(10,5,0,WOOD_STEP:10)
B(10,5,1,WOOD_STEP:10)
B(10,5,2,WOOD_STEP:10)
B(10,5,3,WOOD_STEP:10)
B(10,5,4,WOOD_STEP:10)
B(10,5,5,WOOD:5)
B(10,5,6,DIRT)
B(10,5,7,GRASS)
B(10,6,-7,GRASS)
B(10,6,-6,DIRT)
B(10,6,-5,DIRT)
B(10,6,-4,DIRT)
B(10,6,-3,DIRT)
B(10,6,-2,DIRT)
B(10,6,-1,DIRT)
B(10,6,0,DIRT)
B(10,6,1,DIRT)
B(10,6,2,DIRT)
B(10,6,3,DIRT)
B(10,6,4,GRASS)
B(10,6,5,GRASS)
B(10,6,6,GRASS)
B(10,7,-6,GRASS)
B(10,7,-5,GRASS)
B(10,7,-4,GRASS)
B(10,7,-3,DIRT)
B(10,7,-2,DIRT)
B(10,7,-1,DIRT)
B(10,7,0,DIRT)
B(10,7,1,DIRT)
B(10,7,2,GRASS)
B(10,7,3,GRASS)
B(10,8,-3,GRASS)
B(10,8,-2,GRASS)
B(10,8,-1,GRASS)
B(10,8,0,GRASS)
B(10,8,1,GRASS)
B(11,-10,-8,STONE)
B(11,-10,-7,STONE)
B(11,-10,-6,STONE)
B(11,-10,-5,STONE)
B(11,-10,-4,STONE)
B(11,-10,-3,STONE)
B(11,-10,-2,STONE)
B(11,-10,-1,STONE)
B(11,-10,0,STONE)
B(11,-10,1,STONE)
B(11,-10,2,STONE)
B(11,-10,3,STONE)
B(11,-10,4,STONE)
B(11,-10,5,STONE)
B(11,-10,6,STONE)
B(11,-10,7,STONE)
B(11,-9,-10,STONE)
B(11,-9,-9,STONE)
B(11,-9,-8,STONE)
B(11,-9,-7,STONE)
B(11,-9,-6,STONE)
B(11,-9,-5,STONE)
B(11,-9,-4,STONE)
B(11,-9,-3,STONE)
B(11,-9,-2,STONE)
B(11,-9,-1,STONE)
B(11,-9,0,STONE)
B(11,-9,1,STONE)
B(11,-9,2,STONE)
B(11,-9,3,STONE)
B(11,-9,4,STONE)
B(11,-9,5,STONE)
B(11,-9,6,STONE)
B(11,-9,7,STONE)
B(11,-9,8,STONE)
B(11,-9,9,STONE)
B(11,-8,-10,STONE)
B(11,-8,-9,STONE)
B(11,-8,-8,STONE)
B(11,-8,-7,STONE)
B(11,-8,-6,STONE)
B(11,-8,-5,STONE)
B(11,-8,-4,STONE)
B(11,-8,-3,STONE)
B(11,-8,-2,SMOOTH_BRICK)
B(11,-8,-1,SMOOTH_BRICK)
B(11,-8,0,WOOL:15)
B(11,-8,1,WOOL:15)
B(11,-8,2,WOOL:15)
B(11,-8,3,WOOL:15)
B(11,-8,4,WOOL:15)
B(11,-8,5,WOOL:15)
B(11,-8,6,WOOL:15)
B(11,-8,7,STONE)
B(11,-8,8,STONE)
B(11,-8,9,STONE)
B(11,-8,10,STONE)
B(11,-8,11,STONE)
B(11,-7,-12,STONE)
B(11,-7,-11,STONE)
B(11,-7,-10,STONE)
B(11,-7,-9,STONE)
B(11,-7,-8,STONE)
B(11,-7,-7,STONE)
B(11,-7,-6,STONE)
B(11,-7,-5,STONE)
B(11,-7,-4,STONE)
B(11,-7,-3,STONE:2)
B(11,-7,-2,AIR)
B(11,-7,-1,AIR)
B(11,-7,0,AIR)
B(11,-7,1,AIR)
B(11,-7,2,WOOD_STEP:8)
B(11,-7,3,WOOD_STEP:8)
B(11,-7,4,WOOD_STEP:8)
B(11,-7,5,AIR)
B(11,-7,6,AIR)
B(11,-7,7,BRICK)
B(11,-7,8,STONE)
B(11,-7,9,STONE)
B(11,-7,10,STONE)
B(11,-7,11,STONE)
B(11,-6,-12,STONE)
B(11,-6,-11,SMOOTH_BRICK)
B(11,-6,-10,WOOL:7)
B(11,-6,-9,WOOL:7)
B(11,-6,-8,WOOL:7)
B(11,-6,-7,WOOL:7)
B(11,-6,-6,WOOL:7)
B(11,-6,-5,SMOOTH_BRICK)
B(11,-6,-4,SMOOTH_BRICK)
B(11,-6,-3,STONE:2)
B(11,-6,-2,AIR)
B(11,-6,-1,AIR)
B(11,-6,0,AIR)
B(11,-6,1,AIR)
B(11,-6,2,AIR)
B(11,-6,3,CAKE_BLOCK:1)
B(11,-6,4,AIR)
B(11,-6,5,AIR)
B(11,-6,6,AIR)
B(11,-6,7,STONE:2)
B(11,-6,8,STONE)
B(11,-6,9,STONE)
B(11,-6,10,STONE)
B(11,-6,11,STONE)
B(11,-5,-13,STONE)
B(11,-5,-12,STONE:2)
B(11,-5,-11,AIR)
B(11,-5,-10,AIR)
B(11,-5,-9,AIR)
B(11,-5,-8,AIR)
B(11,-5,-7,AIR)
B(11,-5,-6,AIR)
B(11,-5,-5,AIR)
B(11,-5,-4,AIR)
B(11,-5,-3,BRICK)
B(11,-5,-2,AIR)
B(11,-5,-1,AIR)
B(11,-5,0,AIR)
B(11,-5,1,AIR)
B(11,-5,2,AIR)
B(11,-5,3,AIR)
B(11,-5,4,AIR)
B(11,-5,5,AIR)
B(11,-5,6,AIR)
B(11,-5,7,BRICK)
B(11,-5,8,STONE)
B(11,-5,9,STONE)
B(11,-5,10,STONE)
B(11,-5,11,STONE)
B(11,-5,12,STONE)
B(11,-4,-13,STONE)
B(11,-4,-12,BRICK)
B(11,-4,-11,AIR)
B(11,-4,-10,AIR)
B(11,-4,-9,AIR)
B(11,-4,-8,AIR)
B(11,-4,-7,AIR)
B(11,-4,-6,AIR)
B(11,-4,-5,AIR)
B(11,-4,-4,AIR)
B(11,-4,-3,BRICK)
B(11,-4,-2,AIR)
B(11,-4,-1,AIR)
B(11,-4,0,AIR)
B(11,-4,1,AIR)
B(11,-4,2,AIR)
B(11,-4,3,AIR)
B(11,-4,4,AIR)
B(11,-4,5,AIR)
B(11,-4,6,AIR)
B(11,-4,7,BRICK)
B(11,-4,8,STONE)
B(11,-4,9,STONE)
B(11,-4,10,STONE)
B(11,-4,11,STONE)
B(11,-4,12,STONE)
B(11,-4,13,STONE)
B(11,-4,14,DIRT)
B(11,-3,-15,DIRT)
B(11,-3,-14,DIRT)
B(11,-3,-13,DIRT)
B(11,-3,-12,STONE:2)
B(11,-3,-11,AIR)
B(11,-3,-10,AIR)
B(11,-3,-9,AIR)
B(11,-3,-8,AIR)
B(11,-3,-7,AIR)
B(11,-3,-6,AIR)
B(11,-3,-5,AIR)
B(11,-3,-4,AIR)
B(11,-3,-3,BRICK)
B(11,-3,-2,AIR)
B(11,-3,-1,AIR)
B(11,-3,0,AIR)
B(11,-3,1,AIR)
B(11,-3,2,AIR)
B(11,-3,3,AIR)
B(11,-3,4,AIR)
B(11,-3,5,AIR)
B(11,-3,6,AIR)
B(11,-3,7,STONE:2)
B(11,-3,8,AIR)
B(11,-3,9,STONE)
B(11,-3,10,STONE)
B(11,-3,11,STONE)
B(11,-3,12,STONE)
B(11,-3,13,DIRT)
B(11,-3,14,DIRT)
B(11,-3,15,DIRT)
B(11,-2,-15,GRASS)
B(11,-2,-14,DIRT)
B(11,-2,-13,DIRT)
B(11,-2,-12,STAINED_CLAY:14)
B(11,-2,-11,AIR)
B(11,-2,-10,AIR)
B(11,-2,-9,AIR)
B(11,-2,-8,AIR)
B(11,-2,-7,AIR)
B(11,-2,-6,AIR)
B(11,-2,-5,AIR)
B(11,-2,-4,AIR)
B(11,-2,-3,BRICK)
B(11,-2,-2,AIR)
B(11,-2,-1,AIR)
B(11,-2,0,AIR)
B(11,-2,1,AIR)
B(11,-2,2,AIR)
B(11,-2,3,AIR)
B(11,-2,4,AIR)
B(11,-2,5,AIR)
B(11,-2,6,AIR)
B(11,-2,7,STAINED_CLAY:14)
B(11,-2,8,STONE)
B(11,-2,9,STONE)
B(11,-2,10,STONE)
B(11,-2,11,STONE)
B(11,-2,12,DIRT)
B(11,-2,13,DIRT)
B(11,-2,14,DIRT)
B(11,-2,15,GRASS)
B(11,-1,-14,GRASS)
B(11,-1,-13,DIRT)
B(11,-1,-12,STONE:2)
B(11,-1,-11,AIR)
B(11,-1,-10,AIR)
B(11,-1,-9,AIR)
B(11,-1,-8,AIR)
B(11,-1,-7,AIR)
B(11,-1,-6,AIR)
B(11,-1,-5,DARK_OAK_STAIRS:4)
B(11,-1,-4,DARK_OAK_STAIRS:4)
B(11,-1,-3,STONE:2)
B(11,-1,-2,STEP:8)
B(11,-1,-1,STEP:12)
B(11,-1,0,STEP:8)
B(11,-1,1,AIR)
B(11,-1,2,AIR)
B(11,-1,3,AIR)
B(11,-1,4,STEP:8)
B(11,-1,5,STEP:12)
B(11,-1,6,STEP:8)
B(11,-1,7,STONE:2)
B(11,-1,8,STONE)
B(11,-1,9,STONE)
B(11,-1,10,STONE)
B(11,-1,11,DIRT)
B(11,-1,12,DIRT)
B(11,-1,13,DIRT)
B(11,-1,14,GRASS)
B(11,0,-13,GRASS)
B(11,0,-12,DIRT)
B(11,0,-11,WOOD:5)
B(11,0,-10,WOOD:5)
B(11,0,-9,WOOD:5)
B(11,0,-8,WOOD:5)
B(11,0,-7,WOOD:5)
B(11,0,-6,WOOD:5)
B(11,0,-5,DARK_OAK_STAIRS:1)
B(11,0,-4,DARK_OAK_STAIRS:1)
B(11,0,-3,DARK_OAK_FENCE)
B(11,0,-2,WOOD:5)
B(11,0,-1,WOOD:5)
B(11,0,0,WOOD:5)
B(11,0,1,WOOD:5)
B(11,0,2,WOOD:5)
B(11,0,3,WOOD:5)
B(11,0,4,WOOD:5)
B(11,0,5,STONE)
B(11,0,6,STONE)
B(11,0,7,STONE)
B(11,0,8,STONE)
B(11,0,9,DIRT)
B(11,0,10,DIRT)
B(11,0,11,DIRT)
B(11,0,12,DIRT)
B(11,0,13,GRASS)
B(11,1,-12,GRASS)
B(11,1,-11,DIRT)
B(11,1,-10,DIRT)
B(11,1,-9,DIRT)
B(11,1,-8,WOOD:2)
B(11,1,-7,WOOD:5)
B(11,1,-6,AIR)
B(11,1,-5,AIR)
B(11,1,-4,AIR)
B(11,1,-3,AIR)
B(11,1,-2,AIR)
B(11,1,-1,CARPET:11)
B(11,1,0,CARPET:11)
B(11,1,1,CARPET:11)
B(11,1,2,CARPET:11)
B(11,1,3,AIR)
B(11,1,4,WOOD_STAIRS:5)
B(11,1,5,WOOD:2)
B(11,1,6,STONE)
B(11,1,7,STONE)
B(11,1,8,DIRT)
B(11,1,9,DIRT)
B(11,1,10,DIRT)
B(11,1,11,DIRT)
B(11,1,12,GRASS)
B(11,2,-11,GRASS)
B(11,2,-10,DIRT)
B(11,2,-9,DIRT)
B(11,2,-8,WOOD:2)
B(11,2,-7,WOOD:5)
B(11,2,-6,AIR)
B(11,2,-5,AIR)
B(11,2,-4,AIR)
B(11,2,-3,AIR)
B(11,2,-2,AIR)
B(11,2,-1,AIR)
B(11,2,0,AIR)
B(11,2,1,AIR)
B(11,2,2,AIR)
B(11,2,3,AIR)
RB(11,2,4,FLOWER_POT,../../nbt/Misc/FlowerPot1.nbt,20,FLOWER_POT,../../nbt/Misc/FlowerPot2.nbt,20,FLOWER_POT,../../nbt/Misc/FlowerPot3.nbt,20,FLOWER_POT,../../nbt/Misc/FlowerPot8.nbt,20,FLOWER_POT,../../nbt/Misc/FlowerPot4.nbt,20,FLOWER_POT,../../nbt/Misc/FlowerPot5.nbt,20,FLOWER_POT,../../nbt/Misc/FlowerPot6.nbt,20,FLOWER_POT,../../nbt/Misc/FlowerPot7.nbt,20,FLOWER_POT,../../nbt/Misc/FlowerPot8.nbt,100)
B(11,2,5,WOOD:2)
B(11,2,6,STONE)
B(11,2,7,DIRT)
B(11,2,8,DIRT)
B(11,2,9,DIRT)
B(11,2,10,DIRT)
B(11,2,11,GRASS)
B(11,3,-10,GRASS)
B(11,3,-9,DIRT)
B(11,3,-8,WOOD:2)
B(11,3,-7,WOOD:5)
B(11,3,-6,AIR)
B(11,3,-5,AIR)
B(11,3,-4,AIR)
B(11,3,-3,AIR)
B(11,3,-2,AIR)
B(11,3,-1,AIR)
B(11,3,0,AIR)
B(11,3,1,AIR)
B(11,3,2,AIR)
B(11,3,3,AIR)
B(11,3,4,AIR)
B(11,3,5,DARK_OAK_FENCE)
B(11,3,6,WOOD:2)
B(11,3,7,DIRT)
B(11,3,8,DIRT)
B(11,3,9,GRASS)
B(11,3,10,GRASS)
B(11,4,-9,GRASS)
B(11,4,-8,WOOD:2)
B(11,4,-7,WOOD:5)
B(11,4,-6,AIR)
B(11,4,-5,AIR)
B(11,4,-4,AIR)
B(11,4,-3,AIR)
B(11,4,-2,AIR)
B(11,4,-1,AIR)
B(11,4,0,AIR)
B(11,4,1,AIR)
B(11,4,2,AIR)
B(11,4,3,AIR)
B(11,4,4,AIR)
B(11,4,5,50)
B(11,4,6,WOOD:2)
B(11,4,7,DIRT)
B(11,4,8,GRASS)
B(11,5,-8,GRASS)
B(11,5,-7,WOOD:5)
B(11,5,-6,WOOD_STEP:10)
B(11,5,-5,WOOD_STEP:10)
B(11,5,-4,WOOD_STEP:10)
B(11,5,-3,WOOD_STEP:10)
B(11,5,-2,WOOD_STEP:10)
B(11,5,-1,WOOD_STEP:10)
B(11,5,0,WOOD_STEP:10)
B(11,5,1,WOOD_STEP:10)
B(11,5,2,WOOD_STEP:10)
B(11,5,3,WOOD_STEP:10)
B(11,5,4,WOOD:2)
B(11,5,5,WOOD:2)
B(11,5,6,DIRT)
B(11,5,7,GRASS)
B(11,6,-7,GRASS)
B(11,6,-6,DIRT)
B(11,6,-5,DIRT)
B(11,6,-4,DIRT)
B(11,6,-3,DIRT)
B(11,6,-2,DIRT)
B(11,6,-1,DIRT)
B(11,6,0,DIRT)
B(11,6,1,DIRT)
B(11,6,2,DIRT)
B(11,6,3,DIRT)
B(11,6,4,DIRT)
B(11,6,5,GRASS)
B(11,6,6,GRASS)
B(11,7,-6,GRASS)
B(11,7,-5,GRASS)
B(11,7,-4,DIRT)
B(11,7,-3,DIRT)
B(11,7,-2,DIRT)
B(11,7,-1,DIRT)
B(11,7,0,DIRT)
B(11,7,1,DIRT)
B(11,7,2,GRASS)
B(11,7,3,GRASS)
B(11,7,4,GRASS)
B(11,8,-4,GRASS)
B(11,8,-3,GRASS)
B(11,8,-2,GRASS)
B(11,8,-1,GRASS)
B(11,8,0,GRASS)
B(11,8,1,GRASS)
B(12,-10,-8,STONE)
B(12,-10,-7,STONE)
B(12,-10,-6,STONE)
B(12,-10,-5,STONE)
B(12,-10,-4,STONE)
B(12,-10,-3,STONE)
B(12,-10,-2,STONE)
B(12,-10,-1,STONE)
B(12,-10,0,STONE)
B(12,-10,1,STONE)
B(12,-10,2,STONE)
B(12,-10,3,STONE)
B(12,-10,5,STONE)
B(12,-10,6,STONE)
B(12,-10,7,STONE)
B(12,-9,-10,STONE)
B(12,-9,-9,STONE)
B(12,-9,-8,STONE)
B(12,-9,-7,STONE)
B(12,-9,-6,STONE)
B(12,-9,-5,STONE)
B(12,-9,-4,STONE)
B(12,-9,-3,STONE)
B(12,-9,-2,STONE)
B(12,-9,-1,STONE)
B(12,-9,0,STONE)
B(12,-9,1,STONE)
B(12,-9,2,STONE)
B(12,-9,3,STONE)
B(12,-9,4,STONE)
B(12,-9,5,STONE)
B(12,-9,6,STONE)
B(12,-9,7,STONE)
B(12,-9,8,STONE)
B(12,-9,9,STONE)
B(12,-8,-11,STONE)
B(12,-8,-10,STONE)
B(12,-8,-9,STONE)
B(12,-8,-8,STONE)
B(12,-8,-7,STONE)
B(12,-8,-6,STONE)
B(12,-8,-5,STONE)
B(12,-8,-4,STONE)
B(12,-8,-3,STONE)
B(12,-8,-2,SMOOTH_BRICK)
B(12,-8,-1,SMOOTH_BRICK)
B(12,-8,0,WOOL:15)
B(12,-8,1,WOOL:15)
B(12,-8,2,WOOL:15)
B(12,-8,3,WOOL:15)
B(12,-8,4,WOOL:15)
B(12,-8,5,WOOL:15)
B(12,-8,6,WOOL:15)
B(12,-8,7,STONE)
B(12,-8,8,STONE)
B(12,-8,9,STONE)
B(12,-8,10,STONE)
B(12,-7,-11,STONE)
B(12,-7,-10,STONE)
B(12,-7,-9,STONE)
B(12,-7,-8,STONE)
B(12,-7,-7,STONE)
B(12,-7,-6,STONE)
B(12,-7,-5,STONE)
B(12,-7,-4,STONE)
B(12,-7,-3,BRICK)
B(12,-7,-2,AIR)
B(12,-7,-1,AIR)
B(12,-7,0,AIR)
B(12,-7,1,WOOD_STAIRS)
B(12,-7,2,WOOD_STEP:8)
B(12,-7,3,WOOD_STEP:8)
B(12,-7,4,WOOD_STEP:8)
B(12,-7,5,WOOD_STAIRS:2)
B(12,-7,6,AIR)
B(12,-7,7,BRICK)
B(12,-7,8,STONE)
B(12,-7,9,STONE)
B(12,-7,10,STONE)
B(12,-7,11,STONE)
B(12,-6,-12,STONE)
B(12,-6,-11,SMOOTH_BRICK)
B(12,-6,-10,WOOL:7)
B(12,-6,-9,WOOL:7)
B(12,-6,-8,WOOL:7)
B(12,-6,-7,WOOL:7)
B(12,-6,-6,WOOL:7)
B(12,-6,-5,SMOOTH_BRICK)
B(12,-6,-4,SMOOTH_BRICK)
B(12,-6,-3,STONE:2)
B(12,-6,-2,AIR)
B(12,-6,-1,AIR)
B(12,-6,0,AIR)
B(12,-6,1,AIR)
B(12,-6,2,CAKE_BLOCK:3)
B(12,-6,3,AIR)
B(12,-6,4,AIR)
B(12,-6,5,AIR)
B(12,-6,6,AIR)
B(12,-6,7,STONE:2)
B(12,-6,8,STONE)
B(12,-6,9,STONE)
B(12,-6,10,STONE)
B(12,-6,11,STONE)
B(12,-5,-13,STONE)
B(12,-5,-12,STONE:2)
B(12,-5,-11,WOOD_STAIRS:7)
B(12,-5,-10,AIR)
B(12,-5,-9,AIR)
B(12,-5,-8,AIR)
B(12,-5,-7,AIR)
B(12,-5,-6,AIR)
B(12,-5,-5,AIR)
B(12,-5,-4,AIR)
B(12,-5,-3,BRICK)
B(12,-5,-2,AIR)
B(12,-5,-1,AIR)
B(12,-5,0,AIR)
B(12,-5,1,AIR)
B(12,-5,2,AIR)
B(12,-5,3,AIR)
B(12,-5,4,AIR)
B(12,-5,5,AIR)
B(12,-5,6,AIR)
B(12,-5,7,BRICK)
B(12,-5,8,STONE)
B(12,-5,9,STONE)
B(12,-5,10,STONE)
B(12,-5,11,STONE)
B(12,-5,12,STONE)
B(12,-4,-13,STONE)
B(12,-4,-12,BRICK)
B(12,-4,-11,BOOKSHELF)
B(12,-4,-10,AIR)
B(12,-4,-9,AIR)
B(12,-4,-8,AIR)
B(12,-4,-7,AIR)
B(12,-4,-6,AIR)
B(12,-4,-5,AIR)
B(12,-4,-4,AIR)
B(12,-4,-3,BRICK)
B(12,-4,-2,AIR)
B(12,-4,-1,AIR)
B(12,-4,0,AIR)
B(12,-4,1,AIR)
B(12,-4,2,AIR)
B(12,-4,3,AIR)
B(12,-4,4,AIR)
B(12,-4,5,AIR)
B(12,-4,6,AIR)
B(12,-4,7,BRICK)
B(12,-4,8,STONE)
B(12,-4,9,STONE)
B(12,-4,10,STONE)
B(12,-4,11,STONE)
B(12,-4,12,STONE)
B(12,-4,13,STONE)
B(12,-4,14,DIRT)
B(12,-3,-14,DIRT)
B(12,-3,-13,DIRT)
B(12,-3,-12,STONE:2)
B(12,-3,-11,BOOKSHELF)
B(12,-3,-10,AIR)
B(12,-3,-9,AIR)
B(12,-3,-8,AIR)
B(12,-3,-7,AIR)
B(12,-3,-6,AIR)
B(12,-3,-5,AIR)
B(12,-3,-4,AIR)
B(12,-3,-3,BRICK)
B(12,-3,-2,AIR)
B(12,-3,-1,AIR)
B(12,-3,0,AIR)
B(12,-3,1,AIR)
B(12,-3,2,AIR)
B(12,-3,3,AIR)
B(12,-3,4,AIR)
B(12,-3,5,AIR)
B(12,-3,6,AIR)
B(12,-3,7,STONE:2)
B(12,-3,8,STONE)
B(12,-3,9,STONE)
B(12,-3,10,STONE)
B(12,-3,11,STONE)
B(12,-3,12,STONE)
B(12,-3,13,DIRT)
B(12,-3,14,DIRT)
B(12,-3,15,DIRT)
B(12,-2,-15,GRASS)
B(12,-2,-14,DIRT)
B(12,-2,-13,DIRT)
B(12,-2,-12,STAINED_CLAY:14)
B(12,-2,-11,AIR)
B(12,-2,-10,AIR)
B(12,-2,-9,AIR)
B(12,-2,-8,AIR)
B(12,-2,-7,AIR)
B(12,-2,-6,AIR)
B(12,-2,-5,DARK_OAK_STAIRS:4)
B(12,-2,-4,DARK_OAK_STAIRS:4)
B(12,-2,-3,STONE:2)
B(12,-2,-2,AIR)
B(12,-2,-1,AIR)
B(12,-2,0,AIR)
B(12,-2,1,AIR)
B(12,-2,2,AIR)
B(12,-2,3,AIR)
B(12,-2,4,AIR)
B(12,-2,5,AIR)
B(12,-2,6,AIR)
B(12,-2,7,STAINED_CLAY:14)
B(12,-2,8,STONE)
B(12,-2,9,STONE)
B(12,-2,10,STONE)
B(12,-2,11,STONE)
B(12,-2,12,DIRT)
B(12,-2,13,DIRT)
B(12,-2,14,DIRT)
B(12,-2,15,GRASS)
B(12,-1,-14,GRASS)
B(12,-1,-13,DIRT)
B(12,-1,-12,STONE:2)
B(12,-1,-11,AIR)
B(12,-1,-10,AIR)
B(12,-1,-9,AIR)
B(12,-1,-8,AIR)
B(12,-1,-7,AIR)
B(12,-1,-6,AIR)
B(12,-1,-5,DARK_OAK_STAIRS:1)
B(12,-1,-4,DARK_OAK_STAIRS:1)
B(12,-1,-3,DARK_OAK_FENCE)
B(12,-1,-2,STEP:8)
B(12,-1,-1,STEP:12)
B(12,-1,0,STEP:8)
B(12,-1,1,AIR)
B(12,-1,2,AIR)
B(12,-1,3,AIR)
B(12,-1,4,STEP:8)
B(12,-1,5,STEP:12)
B(12,-1,6,STEP:8)
B(12,-1,7,STONE:2)
B(12,-1,8,STONE)
B(12,-1,9,STONE)
B(12,-1,10,STONE)
B(12,-1,11,DIRT)
B(12,-1,12,DIRT)
B(12,-1,13,DIRT)
B(12,-1,14,GRASS)
B(12,0,-13,GRASS)
B(12,0,-12,DIRT)
B(12,0,-11,WOOD:5)
B(12,0,-10,WOOD:5)
B(12,0,-9,WOOD:5)
B(12,0,-8,WOOD:5)
B(12,0,-7,WOOD:5)
B(12,0,-6,WOOD:5)
B(12,0,-5,AIR)
B(12,0,-4,AIR)
B(12,0,-3,DARK_OAK_FENCE)
B(12,0,-2,WOOD:5)
B(12,0,-1,WOOD:5)
B(12,0,0,WOOD:5)
B(12,0,1,WOOD:5)
B(12,0,2,WOOD:5)
B(12,0,3,WOOD:5)
B(12,0,4,WOOD:5)
B(12,0,5,STONE)
B(12,0,6,STONE)
B(12,0,7,STONE)
B(12,0,8,STONE)
B(12,0,9,DIRT)
B(12,0,10,DIRT)
B(12,0,11,DIRT)
B(12,0,12,DIRT)
B(12,0,13,GRASS)
B(12,1,-12,GRASS)
B(12,1,-11,DIRT)
B(12,1,-10,DIRT)
B(12,1,-9,DIRT)
B(12,1,-8,WOOD:2)
B(12,1,-7,WOOD:5)
B(12,1,-6,AIR)
B(12,1,-5,AIR)
B(12,1,-4,AIR)
B(12,1,-3,AIR)
B(12,1,-2,AIR)
B(12,1,-1,CARPET:11)
B(12,1,0,CARPET:11)
B(12,1,1,CARPET:11)
B(12,1,2,CARPET:11)
B(12,1,3,AIR)
B(12,1,4,WOOD_STEP:8)
B(12,1,5,WOOD:2)
B(12,1,6,STONE)
B(12,1,7,STONE)
B(12,1,8,DIRT)
B(12,1,9,DIRT)
B(12,1,10,DIRT)
B(12,1,11,DIRT)
B(12,1,12,GRASS)
B(12,2,-11,GRASS)
B(12,2,-10,DIRT)
B(12,2,-9,DIRT)
B(12,2,-8,WOOD:2)
B(12,2,-7,WOOD:2)
B(12,2,-6,AIR)
B(12,2,-5,AIR)
B(12,2,-4,AIR)
B(12,2,-3,AIR)
B(12,2,-2,AIR)
B(12,2,-1,AIR)
B(12,2,0,AIR)
B(12,2,1,AIR)
B(12,2,2,AIR)
B(12,2,3,AIR)
B(12,2,4,SKULL:1)
B(12,2,5,WOOD:2)
B(12,2,6,STONE)
B(12,2,7,DIRT)
B(12,2,8,DIRT)
B(12,2,9,DIRT)
B(12,2,10,DIRT)
B(12,2,11,GRASS)
B(12,3,-10,GRASS)
B(12,3,-9,DIRT)
B(12,3,-8,WOOD:2)
B(12,3,-7,WOOD:2)
B(12,3,-6,AIR)
B(12,3,-5,AIR)
B(12,3,-4,AIR)
B(12,3,-3,AIR)
B(12,3,-2,AIR)
B(12,3,-1,AIR)
B(12,3,0,AIR)
B(12,3,1,AIR)
B(12,3,2,AIR)
B(12,3,3,AIR)
B(12,3,4,AIR)
B(12,3,5,DARK_OAK_FENCE)
B(12,3,6,WOOD:2)
B(12,3,7,DIRT)
B(12,3,8,DIRT)
B(12,3,9,GRASS)
B(12,3,10,GRASS)
B(12,4,-9,GRASS)
B(12,4,-8,WOOD:2)
B(12,4,-7,WOOD:2)
B(12,4,-6,AIR)
B(12,4,-5,AIR)
B(12,4,-4,AIR)
B(12,4,-3,AIR)
B(12,4,-2,AIR)
B(12,4,-1,AIR)
B(12,4,0,AIR)
B(12,4,1,AIR)
B(12,4,2,AIR)
B(12,4,3,AIR)
B(12,4,4,AIR)
B(12,4,5,50)
B(12,4,6,WOOD:2)
B(12,4,7,DIRT)
B(12,4,8,GRASS)
B(12,5,-8,DIRT)
B(12,5,-7,WOOD:2)
B(12,5,-6,WOOD_STEP:10)
B(12,5,-5,AIR)
B(12,5,-4,AIR)
B(12,5,-3,AIR)
B(12,5,-2,AIR)
B(12,5,-1,AIR)
B(12,5,0,AIR)
B(12,5,1,WOOD_STEP:10)
B(12,5,2,WOOD_STEP:10)
B(12,5,3,WOOD_STEP:10)
B(12,5,4,WOOD:2)
B(12,5,5,WOOD:2)
B(12,5,6,DIRT)
B(12,5,7,GRASS)
B(12,6,-8,GRASS)
B(12,6,-7,DIRT)
B(12,6,-6,DIRT)
B(12,6,-5,WOOD:2)
B(12,6,-4,WOOD:2)
B(12,6,-3,WOOD:2)
B(12,6,-2,WOOD:2)
B(12,6,-1,WOOD:2)
B(12,6,0,WOOD:2)
B(12,6,1,DIRT)
B(12,6,2,DIRT)
B(12,6,3,DIRT)
B(12,6,4,DIRT)
B(12,6,5,GRASS)
B(12,6,6,GRASS)
B(12,7,-7,GRASS)
B(12,7,-6,GRASS)
B(12,7,-5,GRASS)
B(12,7,-4,DIRT)
B(12,7,-3,DIRT)
B(12,7,-2,DIRT)
B(12,7,-1,DIRT)
B(12,7,0,DIRT)
B(12,7,1,GRASS)
B(12,7,2,GRASS)
B(12,7,3,GRASS)
B(12,7,4,GRASS)
B(12,8,-4,GRASS)
B(12,8,-3,GRASS)
B(12,8,-2,GRASS)
B(12,8,-1,GRASS)
B(12,8,0,GRASS)
B(13,-10,-8,STONE)
B(13,-10,-7,STONE)
B(13,-10,-6,STONE)
B(13,-10,-5,STONE)
B(13,-10,-4,STONE)
B(13,-10,-3,STONE)
B(13,-10,-2,STONE)
B(13,-10,-1,STONE)
B(13,-10,0,STONE)
B(13,-10,1,STONE)
B(13,-10,2,STONE)
B(13,-10,3,STONE)
B(13,-10,4,STONE)
B(13,-10,5,STONE)
B(13,-10,6,STONE)
B(13,-10,7,STONE)
B(13,-9,-9,STONE)
B(13,-9,-8,STONE)
B(13,-9,-7,STONE)
B(13,-9,-6,STONE)
B(13,-9,-5,STONE)
B(13,-9,-4,STONE)
B(13,-9,-3,STONE)
B(13,-9,-2,STONE)
B(13,-9,-1,STONE)
B(13,-9,0,STONE)
B(13,-9,1,STONE)
B(13,-9,2,STONE)
B(13,-9,3,STONE)
B(13,-9,4,STONE)
B(13,-9,5,STONE)
B(13,-9,6,STONE)
B(13,-9,7,STONE)
B(13,-9,8,STONE)
B(13,-9,9,STONE)
B(13,-8,-11,STONE)
B(13,-8,-10,STONE)
B(13,-8,-9,STONE)
B(13,-8,-8,STONE)
B(13,-8,-7,STONE)
B(13,-8,-6,STONE)
B(13,-8,-5,STONE)
B(13,-8,-4,STONE)
B(13,-8,-3,STONE)
B(13,-8,-2,SMOOTH_BRICK)
B(13,-8,-1,SMOOTH_BRICK)
B(13,-8,0,WOOL:15)
B(13,-8,1,WOOL:15)
B(13,-8,2,WOOL:15)
B(13,-8,3,WOOL:15)
B(13,-8,4,WOOL:15)
B(13,-8,5,WOOL:15)
B(13,-8,6,WOOL:15)
B(13,-8,7,STONE)
B(13,-8,8,STONE)
B(13,-8,9,STONE)
B(13,-8,10,STONE)
B(13,-7,-12,STONE)
B(13,-7,-11,STONE)
B(13,-7,-10,STONE)
B(13,-7,-9,STONE)
B(13,-7,-8,STONE)
B(13,-7,-7,STONE)
B(13,-7,-6,STONE)
B(13,-7,-5,STONE)
B(13,-7,-4,STONE)
B(13,-7,-3,BRICK)
B(13,-7,-2,AIR)
B(13,-7,-1,AIR)
B(13,-7,0,AIR)
B(13,-7,1,AIR)
B(13,-7,2,WOOD_STAIRS:4)
B(13,-7,3,WOOD_STAIRS:4)
B(13,-7,4,WOOD_STAIRS:4)
B(13,-7,5,AIR)
B(13,-7,6,AIR)
B(13,-7,7,BRICK)
B(13,-7,8,STONE)
B(13,-7,9,STONE)
B(13,-7,10,STONE)
B(13,-7,11,STONE)
B(13,-6,-12,STONE)
B(13,-6,-11,SMOOTH_BRICK)
B(13,-6,-10,SMOOTH_BRICK)
B(13,-6,-9,SMOOTH_BRICK)
B(13,-6,-8,SMOOTH_BRICK)
B(13,-6,-7,SMOOTH_BRICK)
B(13,-6,-6,SMOOTH_BRICK)
B(13,-6,-5,SMOOTH_BRICK)
B(13,-6,-4,SMOOTH_BRICK)
B(13,-6,-3,STONE:2)
B(13,-6,-2,AIR)
B(13,-6,-1,AIR)
B(13,-6,0,AIR)
B(13,-6,1,AIR)
B(13,-6,2,AIR)
B(13,-6,3,AIR)
B(13,-6,4,DARK_OAK_FENCE)
B(13,-6,5,AIR)
B(13,-6,6,AIR)
B(13,-6,7,STONE:2)
B(13,-6,8,STONE)
B(13,-6,9,STONE)
B(13,-6,10,STONE)
B(13,-6,11,STONE)
B(13,-5,-13,STONE)
B(13,-5,-12,STONE:2)
B(13,-5,-11,WOOD_STAIRS:7)
B(13,-5,-10,AIR)
B(13,-5,-9,AIR)
B(13,-5,-8,AIR)
B(13,-5,-7,AIR)
B(13,-5,-6,AIR)
B(13,-5,-5,50)
B(13,-5,-4,AIR)
B(13,-5,-3,BRICK)
B(13,-5,-2,AIR)
B(13,-5,-1,AIR)
B(13,-5,0,AIR)
B(13,-5,1,AIR)
B(13,-5,2,AIR)
B(13,-5,3,AIR)
B(13,-5,4,50)
B(13,-5,5,AIR)
B(13,-5,6,AIR)
B(13,-5,7,BRICK)
B(13,-5,8,STONE)
B(13,-5,9,STONE)
B(13,-5,10,STONE)
B(13,-5,11,STONE)
B(13,-5,12,STONE)
B(13,-4,-13,DIRT)
B(13,-4,-12,STONE:2)
B(13,-4,-11,BOOKSHELF)
B(13,-4,-10,AIR)
B(13,-4,-9,AIR)
B(13,-4,-8,AIR)
B(13,-4,-7,AIR)
B(13,-4,-6,AIR)
B(13,-4,-5,AIR)
B(13,-4,-4,AIR)
B(13,-4,-3,BRICK)
B(13,-4,-2,AIR)
B(13,-4,-1,AIR)
B(13,-4,0,AIR)
B(13,-4,1,AIR)
B(13,-4,2,AIR)
B(13,-4,3,AIR)
B(13,-4,4,AIR)
B(13,-4,5,AIR)
B(13,-4,6,AIR)
B(13,-4,7,BRICK)
B(13,-4,8,STONE)
B(13,-4,9,STONE)
B(13,-4,10,STONE)
B(13,-4,11,STONE)
B(13,-4,12,STONE)
B(13,-4,13,STONE)
B(13,-3,-14,DIRT)
B(13,-3,-13,DIRT)
B(13,-3,-12,STONE:2)
B(13,-3,-11,BOOKSHELF)
B(13,-3,-10,AIR)
B(13,-3,-9,AIR)
B(13,-3,-8,AIR)
B(13,-3,-7,AIR)
B(13,-3,-6,AIR)
B(13,-3,-5,DARK_OAK_STAIRS:4)
B(13,-3,-4,DARK_OAK_STAIRS:4)
B(13,-3,-3,STONE:2)
B(13,-3,-2,AIR)
B(13,-3,-1,AIR)
B(13,-3,0,AIR)
B(13,-3,1,AIR)
B(13,-3,2,AIR)
B(13,-3,3,AIR)
B(13,-3,4,AIR)
B(13,-3,5,AIR)
B(13,-3,6,AIR)
B(13,-3,7,STONE:2)
B(13,-3,8,STONE)
B(13,-3,9,STONE)
B(13,-3,10,STONE)
B(13,-3,11,STONE)
B(13,-3,12,STONE)
B(13,-3,13,DIRT)
B(13,-3,14,DIRT)
B(13,-3,15,DIRT)
B(13,-2,-15,GRASS)
B(13,-2,-14,DIRT)
B(13,-2,-13,DIRT)
B(13,-2,-12,STONE:2)
RB(13,-2,-11,CHEST,../../nbt/VanillaLoot/simple_dungeon.nbt,50,CHEST,../../nbt/VanillaLoot/abandoned_mineshaft.nbt,30,CHEST,../../nbt/VanillaLoot/stronghold_corridor.nbt,100)
B(13,-2,-10,AIR)
B(13,-2,-9,AIR)
B(13,-2,-8,AIR)
B(13,-2,-7,AIR)
B(13,-2,-6,AIR)
B(13,-2,-5,DARK_OAK_STAIRS:1)
B(13,-2,-4,DARK_OAK_STAIRS:1)
B(13,-2,-3,DARK_OAK_FENCE)
B(13,-2,-2,AIR)
B(13,-2,-1,AIR)
B(13,-2,0,AIR)
B(13,-2,1,AIR)
B(13,-2,2,AIR)
B(13,-2,3,AIR)
B(13,-2,4,AIR)
B(13,-2,5,AIR)
B(13,-2,6,AIR)
B(13,-2,7,STAINED_CLAY:14)
B(13,-2,8,STONE)
B(13,-2,9,STONE)
B(13,-2,10,STONE)
B(13,-2,11,STONE)
B(13,-2,12,DIRT)
B(13,-2,13,DIRT)
B(13,-2,14,DIRT)
B(13,-2,15,GRASS)
B(13,-1,-14,GRASS)
B(13,-1,-13,GRASS)
B(13,-1,-12,STONE:2)
B(13,-1,-11,AIR)
B(13,-1,-10,AIR)
B(13,-1,-9,AIR)
B(13,-1,-8,AIR)
B(13,-1,-7,AIR)
B(13,-1,-6,AIR)
B(13,-1,-5,AIR)
B(13,-1,-4,AIR)
B(13,-1,-3,DARK_OAK_FENCE)
B(13,-1,-2,STEP:8)
B(13,-1,-1,STEP:12)
B(13,-1,0,STEP:8)
B(13,-1,1,AIR)
B(13,-1,2,AIR)
B(13,-1,3,AIR)
B(13,-1,4,STEP:8)
B(13,-1,5,STEP:12)
B(13,-1,6,STEP:8)
B(13,-1,7,STONE:2)
B(13,-1,8,STONE)
B(13,-1,9,STONE)
B(13,-1,10,DIRT)
B(13,-1,11,DIRT)
B(13,-1,12,DIRT)
B(13,-1,13,DIRT)
B(13,-1,14,GRASS)
B(13,0,-12,DIRT)
B(13,0,-11,WOOD:5)
B(13,0,-10,WOOD:5)
B(13,0,-9,WOOD:5)
B(13,0,-8,WOOD:5)
B(13,0,-7,WOOD:5)
B(13,0,-6,WOOD:5)
B(13,0,-5,AIR)
B(13,0,-4,AIR)
B(13,0,-3,DARK_OAK_FENCE)
B(13,0,-2,WOOD:5)
