
#######################################################################
# +-----------------------------------------------------------------+ #
# |                            BO3 object                           | #
# +-----------------------------------------------------------------+ #
#######################################################################

Author: Unknown

Description: Converted version of the BO2 AcaciaSavanna6

Version: 3

SettingsMode: WriteWithoutComments


#######################################################################
# +-----------------------------------------------------------------+ #
# |                          Main settings                          | #
# +-----------------------------------------------------------------+ #
#######################################################################

Tree: true

Frequency: 1

Rarity: 5.0

RotateRandomly: true

SpawnHeight: highestSolidBlock

SpawnHeightOffset: 0

SpawnHeightVariance: 0

##############################
# Height Limits for the BO3. #
##############################

MinHeight: 62

MaxHeight: 210

######################
# Extrusion settings #
######################

ExtrudeMode: None

ExtrudeThroughBlocks: AIR

MaxBranchDepth: 10

ExcludedBiomes: All


#######################################################################
# +-----------------------------------------------------------------+ #
# |                      Source block settings                      | #
# +-----------------------------------------------------------------+ #
#######################################################################

SourceBlocks: AIR

MaxPercentageOutsideSourceBlock: 0

OutsideSourceBlock: placeAnyway

DoReplaceBlocks: true

IsOTGPlus: false


#######################################################################
# +-----------------------------------------------------------------+ #
# |                              Blocks                             | #
# +-----------------------------------------------------------------+ #
#######################################################################

Block(6,7,-2,LEAVES_2)
Block(3,7,-3,LEAVES_2)
Block(3,8,-3,LEAVES_2)
Block(1,9,0,LEAVES_2)
Block(1,8,0,LEAVES_2)
Block(0,7,-4,LEAVES_2)
Block(1,7,0,LEAVES_2)
Block(2,8,2,LEAVES_2)
Block(1,7,-4,LEAVES_2)
Block(4,7,-3,LEAVES_2)
Block(2,7,2,LEAVES_2)
Block(4,8,-3,LEAVES_2)
Block(-2,4,-3,LEAVES_2)
Block(-3,5,0,LEAVES_2)
Block(-3,4,0,LEAVES_2)
Block(3,8,0,LEAVES_2)
Block(-1,4,0,LEAVES_2)
Block(3,7,0,LEAVES_2)
Block(3,6,0,LEAVES_2)
Block(-1,7,0,LEAVES_2)
Block(-1,8,0,LEAVES_2)
Block(-1,7,-3,LEAVES_2)
Block(-3,4,-2,LEAVES_2)
Block(4,7,2,LEAVES_2)
Block(2,7,-3,LEAVES_2)
Block(2,6,-3,LEAVES_2)
Block(5,7,-3,LEAVES_2)
Block(5,7,0,LEAVES_2)
Block(2,8,-3,LEAVES_2)
Block(0,5,-1,LOG_2)
Block(3,6,-2,LEAVES_2)
Block(3,7,-2,LEAVES_2)
Block(0,7,-1,LEAVES_2)
Block(3,8,-2,LEAVES_2)
Block(0,6,-1,LEAVES_2)
Block(6,7,-1,LEAVES_2)
Block(0,8,-1,LEAVES_2)
Block(1,8,1,LEAVES_2)
Block(1,7,1,LEAVES_2)
Block(1,6,1,LEAVES_2)
Block(2,7,3,LEAVES_2)
Block(1,7,-3,LEAVES_2)
Block(1,8,-3,LEAVES_2)
Block(4,8,-2,LEAVES_2)
Block(4,7,-2,LEAVES_2)
Block(3,7,1,LEAVES_2)
Block(-1,4,-2,LEAVES_2)
Block(-4,4,-2,LEAVES_2)
Block(3,8,1,LEAVES_2)
Block(-2,4,1,LEAVES_2)
Block(-1,8,-2,LEAVES_2)
Block(-1,7,-2,LEAVES_2)
Block(-3,3,-1,LEAVES_2)
Block(-3,4,-1,LEAVES_2)
Block(-3,5,-1,LEAVES_2)
Block(1,6,0,LEAVES_2)
Block(0,7,2,LEAVES_2)
Block(5,7,1,LEAVES_2)
Block(2,8,-4,LEAVES_2)
Block(2,7,-4,LEAVES_2)
Block(3,7,-1,LEAVES_2)
Block(3,8,-1,LEAVES_2)
Block(3,9,-1,LEAVES_2)
Block(3,7,-5,LEAVES_2)
Block(0,8,-2,LEAVES_2)
Block(0,7,-2,LEAVES_2)
Block(1,7,2,LEAVES_2)
Block(0,7,0,LEAVES_2)
Block(0,6,0,LEAVES_2)
Block(-4,4,0,LEAVES_2)
Block(3,6,-1,LEAVES_2)
Block(1,8,-2,LEAVES_2)
Block(1,6,-2,LEAVES_2)
Block(2,7,0,LEAVES_2)
Block(2,6,0,LEAVES_2)
Block(1,7,-2,LEAVES_2)
Block(4,8,-1,LEAVES_2)
Block(2,9,0,LEAVES_2)
Block(2,8,0,LEAVES_2)
Block(-2,4,-1,LOG_2)
Block(-2,3,-1,LEAVES_2)
Block(4,7,-1,LEAVES_2)
Block(4,6,-1,LEAVES_2)
Block(-2,7,-1,LEAVES_2)
Block(-2,5,-1,LEAVES_2)
Block(-1,7,-1,LEAVES_2)
Block(-1,5,-1,LEAVES_2)
Block(-1,4,-1,LOG_2)
Block(-1,3,-1,LOG_2)
Block(-4,4,-1,LEAVES_2)
Block(-1,2,-1,LOG_2)
Block(-1,1,-1,LOG_2)
Block(3,8,2,LEAVES_2)
Block(-1,0,-1,LOG_2)
Block(3,7,2,LEAVES_2)
Block(-2,7,0,LEAVES_2)
Block(-2,5,0,LEAVES_2)
Block(-2,4,0,LEAVES_2)
Block(-2,3,0,LEAVES_2)
Block(-1,8,-1,LEAVES_2)
Block(4,7,0,LEAVES_2)
Block(5,7,-1,LEAVES_2)
Block(5,8,-1,LEAVES_2)
Block(4,8,0,LEAVES_2)
Block(0,8,1,LEAVES_2)
Block(2,9,-1,LEAVES_2)
Block(0,7,1,LEAVES_2)
Block(2,8,-1,LOG_2)
Block(2,7,-1,LOG_2)
Block(2,6,-1,LEAVES_2)
Block(2,7,-5,LEAVES_2)
Block(3,7,-4,LEAVES_2)
Block(0,7,-3,LEAVES_2)
Block(3,8,-4,LEAVES_2)
Block(0,8,-3,LEAVES_2)
Block(1,7,-5,LEAVES_2)
Block(1,9,-1,LEAVES_2)
Block(2,6,1,LEAVES_2)
Block(1,7,-1,LEAVES_2)
Block(1,8,-1,LEAVES_2)
Block(2,8,1,LEAVES_2)
Block(1,6,-1,LOG_2)
Block(4,7,-4,LEAVES_2)
Block(2,7,1,LEAVES_2)
Block(-2,3,-2,LEAVES_2)
Block(-2,7,-2,LEAVES_2)
Block(-3,4,1,LEAVES_2)
Block(-2,5,-2,LEAVES_2)
Block(-2,4,-2,LEAVES_2)
Block(-1,7,1,LEAVES_2)
Block(3,7,3,LEAVES_2)
Block(-3,4,-3,LEAVES_2)
Block(5,7,-2,LEAVES_2)
Block(4,7,1,LEAVES_2)
Block(2,8,-2,LEAVES_2)
Block(2,7,-2,LEAVES_2)
Block(0,8,0,LEAVES_2)
Block(2,6,-2,LEAVES_2)
Block(5,8,-2,LEAVES_2)
Block(2,9,-2,LEAVES_2)

#######################################################################
# +-----------------------------------------------------------------+ #
# |                            BO3 checks                           | #
# +-----------------------------------------------------------------+ #
#######################################################################

BlockCheck(-1,-1,-1,GRASS,DIRT,DIRT:2)

#######################################################################
# +-----------------------------------------------------------------+ #
# |                             Branches                            | #
# +-----------------------------------------------------------------+ #
#######################################################################


#######################################################################
# +-----------------------------------------------------------------+ #
# |                             Entities                            | #
# +-----------------------------------------------------------------+ #
#######################################################################


#######################################################################
# +-----------------------------------------------------------------+ #
# |                            Particles                            | #
# +-----------------------------------------------------------------+ #
#######################################################################


#######################################################################
# +-----------------------------------------------------------------+ #
# |                             Spawners                            | #
# +-----------------------------------------------------------------+ #
#######################################################################


#######################################################################
# +-----------------------------------------------------------------+ #
# |                             ModData                             | #
# +-----------------------------------------------------------------+ #
#######################################################################

