[META]
version=2.0
spawnOnBlockType=GRASS, STONE, DIRT
spawnSunlight=True
spawnDarkness=True
spawnWater=False
spawnLava=False
spawnUnderground=True
underFill=False
randomRotation=True
dig=True
tree=False
branch=False
needsFoundation=True
rarity=25
collisionPercentage=50
spawnElevationMin=92
spawnElevationMax=95
spawnInBiome=Custom
[DATA]
0,-2,-3:1.0
-1,-1,-3:1.0
0,-1,-3:1.0
1,-1,-3:1.0
2,-1,-3:1.0
3,-1,-3:1.0
0,0,-3:1.0
1,0,-3:1.0
2,0,-3:1.0
0,-2,-2:1
1,-2,-2:1.0
2,-2,-2:1.0
-1,-1,-2:1
0,-1,-2:1
1,-1,-2:1.0
2,-1,-2:1.0
3,-1,-2:1.0
0,0,-2:1
1,0,-2:1
2,0,-2:1.0
1,-2,-1:1.0
0,-1,-1:1
1,-1,-1:1.0
2,-1,-1:1.0
3,-1,-1:1
0,0,-1:1.0
2,0,-1:1
1,-2,0:1.0
-1,-1,0:1.0
0,-1,0:1.0
1,-1,0:1.0
2,-1,0:1.0
0,0,0:1.0
1,0,0:1.0
2,0,0:1.0
1,-2,1:1
-1,-1,1:1
0,-1,1:1.0
1,-1,1:1.0
2,-1,1:1
0,0,1:1
1,0,1:1
1,-2,2:1
0,-1,2:1.0
1,-1,2:1.0
2,-1,2:1
1,-1,3:1.0
2,-1,3:1
