[META]
version=2.0
spawnOnBlockType=GRASS, STONE, DIRT
spawnSunlight=True
spawnDarkness=True
spawnWater=False
spawnLava=False
spawnUnderground=True
underFill=False
randomRotation=True
dig=True
tree=False
branch=False
needsFoundation=True
rarity=25
collisionPercentage=50
spawnElevationMin=92
spawnElevationMax=95
spawnInBiome=Custom
[DATA]
0,-4,-4:1.0
-1,-3,-4:1.0
0,-3,-4:1.0
-1,-2,-4:1.0
0,-2,-4:1.0
1,-2,-4:1.0
-2,-1,-4:1.0
-1,-1,-4:1.0
0,-1,-4:1.0
1,-1,-4:1.0
-1,0,-4:1.0
0,0,-4:1.0
1,0,-4:1.0
-1,-5,-3:1.0
-1,-4,-3:1.0
0,-4,-3:1.0
1,-4,-3:1.0
-2,-3,-3:1.0
-1,-3,-3:1.0
0,-3,-3:1.0
1,-3,-3:1.0
-3,-2,-3:1.0
-2,-2,-3:1.0
-1,-2,-3:1.0
0,-2,-3:1.0
1,-2,-3:1.0
2,-2,-3:1
-3,-1,-3:1.0
-2,-1,-3:1.0
-1,-1,-3:1.0
0,-1,-3:1.0
1,-1,-3:1.0
2,-1,-3:1.0
3,-1,-3:1
-3,0,-3:1
-2,0,-3:1
-1,0,-3:1
0,0,-3:1.0
1,0,-3:1.0
2,0,-3:1.0
0,1,-3:1
1,1,-3:1
-1,-5,-2:1.0
0,-5,-2:1.0
-3,-4,-2:1
-2,-4,-2:1.0
-1,-4,-2:1.0
0,-4,-2:1.0
1,-4,-2:1
-4,-3,-2:1
-3,-3,-2:1
-2,-3,-2:1
-1,-3,-2:1
0,-3,-2:1.0
1,-3,-2:1.0
2,-3,-2:1.0
-4,-2,-2:1
-3,-2,-2:1
-2,-2,-2:1
-1,-2,-2:1
0,-2,-2:1.0
1,-2,-2:1.0
2,-2,-2:1
-3,-1,-2:1
-2,-1,-2:1
-1,-1,-2:1
0,-1,-2:1.0
1,-1,-2:1.0
2,-1,-2:1.0
3,-1,-2:1
-2,0,-2:1
-1,0,-2:1.0
0,0,-2:1.0
1,0,-2:1.0
2,0,-2:1.0
3,0,-2:1
-2,1,-2:1.0
-1,1,-2:1.0
0,1,-2:1.0
1,1,-2:1.0
2,1,-2:1
0,2,-2:1
0,-5,-1:1.0
1,-5,-1:1.0
-2,-4,-1:1
-1,-4,-1:1
0,-4,-1:1
1,-4,-1:1
-3,-3,-1:1
-2,-3,-1:1
-1,-3,-1:1
0,-3,-1:1
1,-3,-1:1
2,-3,-1:1
-3,-2,-1:1
-2,-2,-1:1
-1,-2,-1:1
1,-2,-1:1
2,-2,-1:1
3,-2,-1:1
-2,-1,-1:1
-1,-1,-1:1
0,-1,-1:1
1,-1,-1:1.0
2,-1,-1:1.0
3,-1,-1:1.0
4,-1,-1:1
-2,0,-1:1
-1,0,-1:1
0,0,-1:1
1,0,-1:1.0
2,0,-1:1.0
3,0,-1:1.0
4,0,-1:1.0
-1,1,-1:1.0
0,1,-1:1.0
1,1,-1:1.0
2,1,-1:1
3,1,-1:1.0
-1,2,-1:1
0,2,-1:1.0
1,2,-1:1.0
-1,-4,0:1
0,-4,0:1
1,-4,0:1
-2,-3,0:1
-1,-3,0:1
1,-3,0:1
2,-3,0:1
-2,-2,0:1
-1,-2,0:1
0,-2,0:1
1,-2,0:1
2,-2,0:1
3,-2,0:1.0
-2,-1,0:1
-1,-1,0:1
0,-1,0:1
1,-1,0:1.0
2,-1,0:1.0
3,-1,0:1
4,-1,0:1
-1,0,0:1
0,0,0:1
1,0,0:1.0
2,0,0:1.0
3,0,0:1.0
4,0,0:1
-1,1,0:1
0,1,0:1
1,1,0:1
2,1,0:1
3,1,0:1.0
-1,2,0:1
0,2,0:1.0
1,2,0:1
2,2,0:1.0
0,-3,1:1
1,-3,1:1
2,-3,1:1
-1,-2,1:1
0,-2,1:1
1,-2,1:1
2,-2,1:1
3,-2,1:1.0
-2,-1,1:1
-1,-1,1:1
0,-1,1:1
1,-1,1:1.0
2,-1,1:1.0
3,-1,1:1.0
4,-1,1:1
-1,0,1:1
0,0,1:1
1,0,1:1.0
2,0,1:1.0
4,0,1:1
0,1,1:1
1,1,1:1
2,1,1:1
3,1,1:1
4,1,1:1
0,2,1:1
1,2,1:1
2,2,1:1
3,2,1:1
0,-2,2:1
1,-2,2:1
2,-2,2:1
3,-2,2:1
-2,-1,2:1
0,-1,2:1
1,-1,2:1
2,-1,2:1
3,-1,2:1
4,-1,2:1
-1,0,2:1
0,0,2:1
1,0,2:1
2,0,2:1
3,0,2:1
4,0,2:1
5,0,2:1
0,1,2:1
1,1,2:1
2,1,2:1
3,1,2:1
4,1,2:1
0,2,2:1
1,2,2:1
2,2,2:1
3,2,2:1
4,2,2:1
2,3,2:1
3,3,2:1
0,-2,3:1
3,-2,3:1
4,-2,3:1
1,-1,3:1
2,-1,3:1
3,-1,3:1
4,-1,3:1
-1,0,3:1
1,0,3:1
2,0,3:1
3,0,3:1
4,0,3:1
5,0,3:1
6,0,3:1
1,1,3:1
2,1,3:1
3,1,3:1
4,1,3:1
5,1,3:1
0,2,3:1
2,2,3:1
3,2,3:1
4,2,3:1
3,3,3:1
3,-1,4:1
2,0,4:1
3,0,4:1
4,0,4:1
5,0,4:1
6,0,4:1
2,1,4:1
3,1,4:1
4,1,4:1
5,1,4:1
3,3,4:1
1,-1,4:1
-1,-1,2:1
3,-2,4:1
