[META]
version=2.0
spawnOnBlockType=2
spawnSunlight=True
spawnDarkness=True
spawnWater=False
spawnLava=False
underFill=False
randomRotation=True
dig=True
tree=False
branch=False
needsFoundation=True
rarity=10
collisionPercentage=20
spawnElevationMin=0
spawnElevationMax=200
spawnInBiome=Custom
[DATA]
0,-2,0:18
-1,-1,0:18
0,-1,0:17.0
1,-1,0:18
-2,0,0:18
-1,0,0:17.0
0,0,0:17.0
1,0,0:17.0
2,0,0:18
-1,1,0:18
0,1,0:17.0
1,1,0:18
0,2,0:18
2,1,0:31.1
2,-1,0:31.1
1,-2,0:31.1
0,-1,-2:3
-1,0,-2:3
0,0,-2:17.0
1,0,-2:3
0,-2,-1:2
1,-2,-1:2
-1,-1,-1:2
0,-1,-1:17.0
1,-1,-1:2
2,-1,-1:2
-2,0,-1:2
-1,0,-1:17.0
0,0,-1:3
1,0,-1:17.0
2,0,-1:2
-1,1,-1:2
0,1,-1:3
1,1,-1:2
2,1,-1:2
0,2,-1:2
1,2,-1:2
-1,-1,1:18
0,-1,1:18
1,-1,1:18
-1,0,1:18
0,0,1:91.2
1,0,1:18
2,0,1:18
0,1,1:18
1,1,1:18
0,-1,2:18
0,0,2:18
1,0,2:18
