
#######################################################################
# +-----------------------------------------------------------------+ #
# |                            BO3 object                           | #
# +-----------------------------------------------------------------+ #
#######################################################################

Author: Unknown

Description: This BO3 was converted from a schematic using OTGEdit. The author and description information of the schematic could not be found. If you know who the author of the schematic is then please add this information.

Version: 3

SettingsMode: WriteWithoutComments


#######################################################################
# +-----------------------------------------------------------------+ #
# |                          Main settings                          | #
# +-----------------------------------------------------------------+ #
#######################################################################

Tree: false

Frequency: 1

Rarity: 0.5

RotateRandomly: true

SpawnHeight: highestSolidBlock

SpawnHeightOffset: 0

SpawnHeightVariance: 0

##############################
# Height Limits for the BO3. #
##############################

MinHeight: 0

MaxHeight: 255

######################
# Extrusion settings #
######################

ExtrudeMode: None

ExtrudeThroughBlocks: AIR

MaxBranchDepth: 10

ExcludedBiomes: All


#######################################################################
# +-----------------------------------------------------------------+ #
# |                      Source block settings                      | #
# +-----------------------------------------------------------------+ #
#######################################################################

SourceBlocks: AIR

MaxPercentageOutsideSourceBlock: 100

OutsideSourceBlock: placeAnyway

DoReplaceBlocks: true

IsOTGPlus: false


#######################################################################
# +-----------------------------------------------------------------+ #
# |                              Blocks                             | #
# +-----------------------------------------------------------------+ #
#######################################################################

Block(-9,32,-2,CONCRETE:6)
Block(-9,32,-1,CONCRETE:6)
Block(-9,33,-3,CONCRETE:6)
Block(-9,33,-2,CONCRETE:6)
Block(-9,33,-1,CONCRETE:6)
Block(-9,33,0,CONCRETE:6)
Block(-9,34,-4,CONCRETE:6)
Block(-9,34,-3,CONCRETE:6)
Block(-9,34,-2,CONCRETE:6)
Block(-9,34,-1,CONCRETE:6)
Block(-9,34,0,CONCRETE:6)
Block(-9,35,-3,CONCRETE:6)
Block(-9,35,-2,CONCRETE:6)
Block(-9,35,-1,CONCRETE:6)
Block(-9,35,0,CONCRETE:6)
Block(-9,36,-3,CONCRETE:6)
Block(-9,36,-2,CONCRETE:6)
Block(-9,36,-1,CONCRETE:6)
Block(-9,37,1,CONCRETE:0)
Block(-9,37,2,CONCRETE:0)
Block(-9,38,0,CONCRETE:0)
Block(-9,38,1,CONCRETE:0)
Block(-9,38,2,CONCRETE:0)
Block(-9,38,3,CONCRETE:0)
Block(-9,38,4,CONCRETE:6)
Block(-9,38,5,CONCRETE:6)
Block(-9,39,-1,CONCRETE:0)
Block(-9,39,0,CONCRETE:0)
Block(-9,39,1,CONCRETE:0)
Block(-9,39,2,CONCRETE:0)
Block(-9,39,3,CONCRETE:6)
Block(-9,39,4,CONCRETE:6)
Block(-9,39,5,CONCRETE:6)
Block(-9,39,6,CONCRETE:6)
Block(-9,40,0,CONCRETE:0)
Block(-9,40,1,CONCRETE:0)
Block(-9,40,2,CONCRETE:6)
Block(-9,40,3,CONCRETE:6)
Block(-9,40,4,CONCRETE:6)
Block(-9,40,5,CONCRETE:6)
Block(-9,40,6,CONCRETE:6)
Block(-9,40,7,CONCRETE:6)
Block(-9,41,2,CONCRETE:6)
Block(-9,41,3,CONCRETE:6)
Block(-9,41,4,CONCRETE:6)
Block(-9,41,5,CONCRETE:6)
Block(-9,41,6,CONCRETE:6)
Block(-9,41,7,CONCRETE:6)
Block(-9,42,2,CONCRETE:6)
Block(-9,42,3,CONCRETE:6)
Block(-9,42,4,CONCRETE:6)
Block(-9,42,5,CONCRETE:6)
Block(-9,42,6,CONCRETE:6)
Block(-9,42,7,CONCRETE:6)
Block(-9,43,3,CONCRETE:6)
Block(-9,43,4,CONCRETE:6)
Block(-9,43,5,CONCRETE:6)
Block(-9,43,6,CONCRETE:6)
Block(-8,31,-2,CONCRETE:6)
Block(-8,32,-3,CONCRETE:6)
Block(-8,32,-2,CONCRETE:6)
Block(-8,32,-1,CONCRETE:6)
Block(-8,32,0,CONCRETE:6)
Block(-8,33,-4,CONCRETE:6)
Block(-8,33,-3,CONCRETE:6)
Block(-8,33,-2,CONCRETE:6)
Block(-8,33,-1,CONCRETE:6)
Block(-8,33,0,CONCRETE:6)
Block(-8,34,-4,CONCRETE:6)
Block(-8,34,-3,CONCRETE:6)
Block(-8,34,-2,CONCRETE:6)
Block(-8,34,-1,CONCRETE:6)
Block(-8,34,0,CONCRETE:6)
Block(-8,34,1,CONCRETE:6)
Block(-8,35,-4,CONCRETE:6)
Block(-8,35,-3,CONCRETE:6)
Block(-8,35,-2,CONCRETE:6)
Block(-8,35,-1,CONCRETE:6)
Block(-8,35,0,CONCRETE:6)
Block(-8,35,1,CONCRETE:6)
Block(-8,35,2,CONCRETE:0)
Block(-8,35,3,CONCRETE:0)
Block(-8,36,-4,CONCRETE:6)
Block(-8,36,-3,CONCRETE:6)
Block(-8,36,-2,CONCRETE:6)
Block(-8,36,-1,CONCRETE:6)
Block(-8,36,0,CONCRETE:6)
Block(-8,36,1,CONCRETE:0)
Block(-8,36,2,CONCRETE:0)
Block(-8,36,3,CONCRETE:0)
Block(-8,36,4,CONCRETE:0)
Block(-8,37,-3,CONCRETE:6)
Block(-8,37,-2,CONCRETE:6)
Block(-8,37,-1,CONCRETE:6)
Block(-8,37,0,CONCRETE:0)
Block(-8,37,1,CONCRETE:0)
Block(-8,37,2,CONCRETE:0)
Block(-8,37,3,CONCRETE:0)
Block(-8,37,4,CONCRETE:0)
Block(-8,37,5,CONCRETE:0)
Block(-8,38,-2,CONCRETE:0)
Block(-8,38,-1,CONCRETE:0)
Block(-8,38,0,CONCRETE:0)
Block(-8,38,1,CONCRETE:0)
Block(-8,38,2,CONCRETE:0)
Block(-8,38,3,CONCRETE:0)
Block(-8,38,4,CONCRETE:6)
Block(-8,38,5,CONCRETE:6)
Block(-8,38,6,CONCRETE:6)
Block(-8,39,-2,CONCRETE:0)
Block(-8,39,-1,CONCRETE:0)
Block(-8,39,0,CONCRETE:0)
Block(-8,39,1,CONCRETE:0)
Block(-8,39,2,CONCRETE:0)
Block(-8,39,3,CONCRETE:6)
Block(-8,39,4,CONCRETE:6)
Block(-8,39,5,CONCRETE:6)
Block(-8,39,6,CONCRETE:6)
Block(-8,39,7,CONCRETE:6)
Block(-8,40,-2,CONCRETE:0)
Block(-8,40,-1,CONCRETE:0)
Block(-8,40,0,CONCRETE:0)
Block(-8,40,1,CONCRETE:0)
Block(-8,40,2,CONCRETE:0)
Block(-8,40,3,CONCRETE:6)
Block(-8,40,4,CONCRETE:6)
Block(-8,40,5,CONCRETE:6)
Block(-8,40,6,CONCRETE:6)
Block(-8,40,7,CONCRETE:6)
Block(-8,41,-2,CONCRETE:0)
Block(-8,41,-1,CONCRETE:0)
Block(-8,41,0,CONCRETE:0)
Block(-8,41,1,CONCRETE:0)
Block(-8,41,2,CONCRETE:6)
Block(-8,41,3,CONCRETE:6)
Block(-8,41,4,CONCRETE:6)
Block(-8,41,5,CONCRETE:6)
Block(-8,41,6,CONCRETE:6)
Block(-8,41,7,CONCRETE:6)
Block(-8,42,-1,CONCRETE:0)
Block(-8,42,0,CONCRETE:0)
Block(-8,42,1,CONCRETE:0)
Block(-8,42,2,CONCRETE:6)
Block(-8,42,3,CONCRETE:6)
Block(-8,42,4,CONCRETE:6)
Block(-8,42,5,CONCRETE:6)
Block(-8,42,6,CONCRETE:6)
Block(-8,42,7,CONCRETE:6)
Block(-8,43,0,CONCRETE:0)
Block(-8,43,1,CONCRETE:0)
Block(-8,43,2,CONCRETE:0)
Block(-8,43,3,CONCRETE:6)
Block(-8,43,4,CONCRETE:6)
Block(-8,43,5,CONCRETE:6)
Block(-8,43,6,CONCRETE:6)
Block(-8,43,7,CONCRETE:6)
Block(-8,44,4,CONCRETE:6)
Block(-8,44,5,CONCRETE:6)
Block(-8,44,6,CONCRETE:6)
Block(-7,0,-2,STAINED_CLAY:6)
Block(-7,0,-1,STAINED_CLAY:6)
Block(-7,0,0,STAINED_CLAY:6)
Block(-7,31,-3,CONCRETE:6)
Block(-7,31,-2,CONCRETE:6)
Block(-7,31,-1,CONCRETE:6)
Block(-7,32,-4,CONCRETE:6)
Block(-7,32,-3,CONCRETE:6)
Block(-7,32,-2,CONCRETE:6)
Block(-7,32,-1,CONCRETE:6)
Block(-7,32,0,CONCRETE:6)
Block(-7,33,-4,CONCRETE:6)
Block(-7,33,-3,CONCRETE:6)
Block(-7,33,-2,CONCRETE:6)
Block(-7,33,-1,CONCRETE:6)
Block(-7,33,0,CONCRETE:6)
Block(-7,33,1,CONCRETE:6)
Block(-7,34,-5,CONCRETE:6)
Block(-7,34,-4,CONCRETE:6)
Block(-7,34,-3,CONCRETE:6)
Block(-7,34,-2,CONCRETE:6)
Block(-7,34,-1,CONCRETE:6)
Block(-7,34,0,CONCRETE:6)
Block(-7,34,1,CONCRETE:6)
Block(-7,34,2,CONCRETE:0)
Block(-7,34,3,CONCRETE:0)
Block(-7,34,4,CONCRETE:0)
Block(-7,35,-5,CONCRETE:6)
Block(-7,35,-4,CONCRETE:6)
Block(-7,35,-3,CONCRETE:6)
Block(-7,35,-2,CONCRETE:6)
Block(-7,35,-1,CONCRETE:6)
Block(-7,35,0,CONCRETE:6)
Block(-7,35,1,CONCRETE:6)
Block(-7,35,2,CONCRETE:0)
Block(-7,35,3,CONCRETE:0)
Block(-7,35,4,CONCRETE:0)
Block(-7,35,5,CONCRETE:0)
Block(-7,36,-4,CONCRETE:6)
Block(-7,36,-3,CONCRETE:6)
Block(-7,36,-2,CONCRETE:6)
Block(-7,36,-1,CONCRETE:6)
Block(-7,36,0,CONCRETE:6)
Block(-7,36,1,CONCRETE:0)
Block(-7,36,2,CONCRETE:0)
Block(-7,36,3,CONCRETE:0)
Block(-7,36,4,CONCRETE:0)
Block(-7,36,5,CONCRETE:0)
Block(-7,37,-5,CONCRETE:6)
Block(-7,37,-4,CONCRETE:6)
Block(-7,37,-3,CONCRETE:6)
Block(-7,37,-2,CONCRETE:6)
Block(-7,37,-1,CONCRETE:0)
Block(-7,37,0,CONCRETE:0)
Block(-7,37,1,CONCRETE:0)
Block(-7,37,2,CONCRETE:0)
Block(-7,37,3,CONCRETE:0)
Block(-7,37,4,CONCRETE:0)
Block(-7,37,5,CONCRETE:0)
Block(-7,37,6,CONCRETE:0)
Block(-7,38,-6,CONCRETE:6)
Block(-7,38,-5,CONCRETE:6)
Block(-7,38,-4,CONCRETE:6)
Block(-7,38,-3,CONCRETE:6)
Block(-7,38,-2,CONCRETE:0)
Block(-7,38,-1,CONCRETE:0)
Block(-7,38,0,CONCRETE:0)
Block(-7,38,1,CONCRETE:0)
Block(-7,38,2,CONCRETE:0)
Block(-7,38,3,CONCRETE:0)
Block(-7,38,4,CONCRETE:0)
Block(-7,38,5,CONCRETE:6)
Block(-7,38,6,CONCRETE:6)
Block(-7,39,-7,CONCRETE:6)
Block(-7,39,-6,CONCRETE:6)
Block(-7,39,-5,CONCRETE:6)
Block(-7,39,-4,CONCRETE:6)
Block(-7,39,-3,CONCRETE:0)
Block(-7,39,-2,CONCRETE:0)
Block(-7,39,-1,CONCRETE:0)
Block(-7,39,0,CONCRETE:0)
Block(-7,39,1,CONCRETE:0)
Block(-7,39,2,CONCRETE:0)
Block(-7,39,3,CONCRETE:0)
Block(-7,39,4,CONCRETE:6)
Block(-7,39,5,CONCRETE:6)
Block(-7,39,6,CONCRETE:6)
Block(-7,39,7,CONCRETE:6)
Block(-7,40,-7,CONCRETE:6)
Block(-7,40,-6,CONCRETE:6)
Block(-7,40,-5,CONCRETE:6)
Block(-7,40,-4,CONCRETE:6)
Block(-7,40,-3,CONCRETE:0)
Block(-7,40,-2,CONCRETE:0)
Block(-7,40,-1,CONCRETE:0)
Block(-7,40,0,CONCRETE:0)
Block(-7,40,1,CONCRETE:0)
Block(-7,40,2,CONCRETE:0)
Block(-7,40,3,CONCRETE:6)
Block(-7,40,4,CONCRETE:6)
Block(-7,40,5,CONCRETE:6)
Block(-7,40,6,CONCRETE:6)
Block(-7,40,7,CONCRETE:6)
Block(-7,41,-7,CONCRETE:6)
Block(-7,41,-6,CONCRETE:6)
Block(-7,41,-5,CONCRETE:6)
Block(-7,41,-4,CONCRETE:6)
Block(-7,41,-3,CONCRETE:0)
Block(-7,41,-2,CONCRETE:0)
Block(-7,41,-1,CONCRETE:0)
Block(-7,41,0,CONCRETE:0)
Block(-7,41,1,CONCRETE:0)
Block(-7,41,2,CONCRETE:0)
Block(-7,41,3,CONCRETE:6)
Block(-7,41,4,CONCRETE:6)
Block(-7,41,5,CONCRETE:6)
Block(-7,41,6,CONCRETE:6)
Block(-7,41,7,CONCRETE:6)
Block(-7,42,-6,CONCRETE:6)
Block(-7,42,-5,CONCRETE:6)
Block(-7,42,-3,CONCRETE:0)
Block(-7,42,-2,CONCRETE:0)
Block(-7,42,-1,CONCRETE:0)
Block(-7,42,0,CONCRETE:0)
Block(-7,42,1,CONCRETE:0)
Block(-7,42,2,CONCRETE:0)
Block(-7,42,3,CONCRETE:6)
Block(-7,42,4,CONCRETE:6)
Block(-7,42,5,CONCRETE:6)
Block(-7,42,6,CONCRETE:6)
Block(-7,42,7,CONCRETE:6)
Block(-7,43,-2,CONCRETE:0)
Block(-7,43,-1,CONCRETE:0)
Block(-7,43,0,CONCRETE:0)
Block(-7,43,1,CONCRETE:0)
Block(-7,43,2,CONCRETE:0)
Block(-7,43,3,CONCRETE:6)
Block(-7,43,4,CONCRETE:6)
Block(-7,43,5,CONCRETE:6)
Block(-7,43,6,CONCRETE:6)
Block(-7,43,7,CONCRETE:6)
Block(-7,44,-1,CONCRETE:0)
Block(-7,44,0,CONCRETE:0)
Block(-7,44,1,CONCRETE:0)
Block(-7,44,2,CONCRETE:0)
Block(-7,44,3,CONCRETE:0)
Block(-7,44,4,CONCRETE:6)
Block(-7,44,5,CONCRETE:6)
Block(-7,45,-2,CONCRETE:6)
Block(-7,45,-1,CONCRETE:6)
Block(-7,45,0,CONCRETE:6)
Block(-7,46,-1,CONCRETE:6)
Block(-7,46,0,CONCRETE:6)
Block(-6,0,-3,STAINED_CLAY:6)
Block(-6,0,-2,STAINED_CLAY:6)
Block(-6,0,-1,STAINED_CLAY:6)
Block(-6,0,0,STAINED_CLAY:6)
Block(-6,0,1,STAINED_CLAY:6)
Block(-6,1,-2,STAINED_CLAY:6)
Block(-6,1,-1,STAINED_CLAY:6)
Block(-6,1,0,STAINED_CLAY:6)
Block(-6,1,1,STAINED_CLAY:6)
Block(-6,2,-2,STAINED_CLAY:6)
Block(-6,2,-1,STAINED_CLAY:6)
Block(-6,2,0,STAINED_CLAY:6)
Block(-6,3,-2,STAINED_CLAY:6)
Block(-6,3,-1,STAINED_CLAY:6)
Block(-6,3,0,STAINED_CLAY:6)
Block(-6,4,-2,STAINED_CLAY:6)
Block(-6,4,-1,STAINED_CLAY:6)
Block(-6,4,0,STAINED_CLAY:6)
Block(-6,5,-1,STAINED_CLAY:6)
Block(-6,28,0,STAINED_CLAY:6)
Block(-6,29,-1,STAINED_CLAY:6)
Block(-6,29,0,STAINED_CLAY:6)
Block(-6,30,-1,STAINED_CLAY:6)
Block(-6,30,0,STAINED_CLAY:6)
Block(-6,30,1,STAINED_CLAY:6)
Block(-6,31,-3,CONCRETE:6)
Block(-6,31,-2,CONCRETE:6)
Block(-6,31,-1,CONCRETE:6)
Block(-6,31,0,STAINED_CLAY:6)
Block(-6,32,-4,CONCRETE:6)
Block(-6,32,-3,CONCRETE:6)
Block(-6,32,-2,CONCRETE:6)
Block(-6,32,-1,CONCRETE:6)
Block(-6,32,0,CONCRETE:6)
Block(-6,32,1,CONCRETE:6)
Block(-6,32,4,CONCRETE:6)
Block(-6,32,5,CONCRETE:6)
Block(-6,32,6,CONCRETE:6)
Block(-6,33,-4,CONCRETE:6)
Block(-6,33,-3,CONCRETE:6)
Block(-6,33,-2,CONCRETE:6)
Block(-6,33,-1,CONCRETE:6)
Block(-6,33,0,CONCRETE:6)
Block(-6,33,1,CONCRETE:6)
Block(-6,33,2,CONCRETE:0)
Block(-6,33,3,CONCRETE:0)
Block(-6,33,4,CONCRETE:6)
Block(-6,33,5,CONCRETE:6)
Block(-6,34,-5,CONCRETE:6)
Block(-6,34,-4,CONCRETE:6)
Block(-6,34,-3,CONCRETE:6)
Block(-6,34,-2,CONCRETE:6)
Block(-6,34,-1,CONCRETE:6)
Block(-6,34,0,CONCRETE:6)
Block(-6,34,1,CONCRETE:6)
Block(-6,34,2,CONCRETE:0)
Block(-6,34,3,CONCRETE:0)
Block(-6,34,4,CONCRETE:0)
Block(-6,34,5,CONCRETE:0)
Block(-6,35,-5,CONCRETE:6)
Block(-6,35,-4,CONCRETE:6)
Block(-6,35,-3,CONCRETE:6)
Block(-6,35,-2,CONCRETE:6)
Block(-6,35,-1,CONCRETE:6)
Block(-6,35,0,CONCRETE:6)
Block(-6,35,1,CONCRETE:0)
Block(-6,35,2,CONCRETE:0)
Block(-6,35,3,CONCRETE:0)
Block(-6,35,4,CONCRETE:0)
Block(-6,35,5,CONCRETE:0)
Block(-6,35,6,CONCRETE:0)
Block(-6,36,-5,CONCRETE:6)
Block(-6,36,-4,CONCRETE:6)
Block(-6,36,-3,CONCRETE:6)
Block(-6,36,-2,CONCRETE:6)
Block(-6,36,-1,CONCRETE:6)
Block(-6,36,0,CONCRETE:0)
Block(-6,36,1,CONCRETE:0)
Block(-6,36,2,CONCRETE:0)
Block(-6,36,3,CONCRETE:0)
Block(-6,36,4,CONCRETE:0)
Block(-6,36,5,CONCRETE:0)
Block(-6,36,6,CONCRETE:0)
Block(-6,37,-6,CONCRETE:6)
Block(-6,37,-5,CONCRETE:6)
Block(-6,37,-4,CONCRETE:6)
Block(-6,37,-3,CONCRETE:6)
Block(-6,37,-2,CONCRETE:0)
Block(-6,37,-1,CONCRETE:0)
Block(-6,37,0,CONCRETE:0)
Block(-6,37,1,CONCRETE:0)
Block(-6,37,2,CONCRETE:0)
Block(-6,37,3,CONCRETE:0)
Block(-6,37,4,CONCRETE:0)
Block(-6,37,5,CONCRETE:0)
Block(-6,37,6,CONCRETE:0)
Block(-6,37,7,CONCRETE:0)
Block(-6,38,-7,CONCRETE:6)
Block(-6,38,-6,CONCRETE:6)
Block(-6,38,-5,CONCRETE:6)
Block(-6,38,-4,CONCRETE:6)
Block(-6,38,-3,CONCRETE:6)
Block(-6,38,-2,CONCRETE:0)
Block(-6,38,-1,CONCRETE:0)
Block(-6,38,0,CONCRETE:0)
Block(-6,38,1,CONCRETE:0)
Block(-6,38,2,CONCRETE:0)
Block(-6,38,3,CONCRETE:0)
Block(-6,38,4,CONCRETE:0)
Block(-6,38,5,CONCRETE:0)
Block(-6,38,6,CONCRETE:0)
Block(-6,38,7,CONCRETE:0)
Block(-6,39,-8,CONCRETE:6)
Block(-6,39,-7,CONCRETE:6)
Block(-6,39,-6,CONCRETE:6)
Block(-6,39,-5,CONCRETE:6)
Block(-6,39,-4,CONCRETE:6)
Block(-6,39,-3,CONCRETE:0)
Block(-6,39,-2,CONCRETE:0)
Block(-6,39,-1,CONCRETE:0)
Block(-6,39,0,CONCRETE:0)
Block(-6,39,1,CONCRETE:0)
Block(-6,39,2,CONCRETE:0)
Block(-6,39,3,CONCRETE:0)
Block(-6,39,4,CONCRETE:0)
Block(-6,39,5,CONCRETE:0)
Block(-6,39,6,CONCRETE:6)
Block(-6,39,7,CONCRETE:0)
Block(-6,40,-8,CONCRETE:6)
Block(-6,40,-7,CONCRETE:6)
Block(-6,40,-6,CONCRETE:6)
Block(-6,40,-5,CONCRETE:6)
Block(-6,40,-4,CONCRETE:6)
Block(-6,40,-3,CONCRETE:0)
Block(-6,40,-2,CONCRETE:0)
Block(-6,40,-1,CONCRETE:0)
Block(-6,40,0,CONCRETE:0)
Block(-6,40,1,CONCRETE:0)
Block(-6,40,2,CONCRETE:0)
Block(-6,40,3,CONCRETE:0)
Block(-6,40,4,CONCRETE:0)
Block(-6,40,5,CONCRETE:6)
Block(-6,40,6,CONCRETE:6)
Block(-6,40,7,CONCRETE:6)
Block(-6,41,-8,CONCRETE:6)
Block(-6,41,-7,CONCRETE:6)
Block(-6,41,-6,CONCRETE:6)
Block(-6,41,-5,CONCRETE:6)
Block(-6,41,-4,CONCRETE:6)
Block(-6,41,-3,CONCRETE:0)
Block(-6,41,-2,CONCRETE:0)
Block(-6,41,-1,CONCRETE:0)
Block(-6,41,0,CONCRETE:0)
Block(-6,41,1,CONCRETE:0)
Block(-6,41,2,CONCRETE:0)
Block(-6,41,3,CONCRETE:0)
Block(-6,41,4,CONCRETE:6)
Block(-6,41,5,CONCRETE:6)
Block(-6,41,6,CONCRETE:6)
Block(-6,41,7,CONCRETE:6)
Block(-6,42,-7,CONCRETE:6)
Block(-6,42,-6,CONCRETE:6)
Block(-6,42,-5,CONCRETE:6)
Block(-6,42,-4,CONCRETE:6)
Block(-6,42,-3,CONCRETE:0)
Block(-6,42,-2,CONCRETE:0)
Block(-6,42,-1,CONCRETE:0)
Block(-6,42,0,CONCRETE:0)
Block(-6,42,1,CONCRETE:0)
Block(-6,42,2,CONCRETE:0)
Block(-6,42,3,CONCRETE:0)
Block(-6,42,4,CONCRETE:6)
Block(-6,42,5,CONCRETE:6)
Block(-6,42,6,CONCRETE:6)
Block(-6,42,7,CONCRETE:6)
Block(-6,43,-6,CONCRETE:6)
Block(-6,43,-5,CONCRETE:6)
Block(-6,43,-4,CONCRETE:6)
Block(-6,43,-3,CONCRETE:0)
Block(-6,43,-2,CONCRETE:0)
Block(-6,43,-1,CONCRETE:0)
Block(-6,43,0,CONCRETE:0)
Block(-6,43,1,CONCRETE:0)
Block(-6,43,2,CONCRETE:0)
Block(-6,43,3,CONCRETE:0)
Block(-6,43,4,CONCRETE:0)
Block(-6,43,5,CONCRETE:6)
Block(-6,43,6,CONCRETE:6)
Block(-6,44,-3,CONCRETE:6)
Block(-6,44,-2,CONCRETE:6)
Block(-6,44,-1,CONCRETE:6)
Block(-6,44,0,CONCRETE:0)
Block(-6,44,1,CONCRETE:0)
Block(-6,44,2,CONCRETE:0)
Block(-6,44,3,CONCRETE:0)
Block(-6,44,4,CONCRETE:0)
Block(-6,44,5,CONCRETE:0)
Block(-6,45,-3,CONCRETE:6)
Block(-6,45,-2,CONCRETE:6)
Block(-6,45,-1,CONCRETE:6)
Block(-6,45,0,CONCRETE:6)
Block(-6,45,1,CONCRETE:6)
Block(-6,45,2,CONCRETE:0)
Block(-6,45,3,CONCRETE:0)
Block(-6,45,4,CONCRETE:0)
Block(-6,46,-3,CONCRETE:6)
Block(-6,46,-2,CONCRETE:6)
Block(-6,46,-1,CONCRETE:6)
Block(-6,46,0,CONCRETE:6)
Block(-6,46,1,CONCRETE:6)
Block(-6,47,-2,CONCRETE:6)
Block(-6,47,-1,CONCRETE:6)
Block(-6,47,0,CONCRETE:6)
Block(-6,47,1,CONCRETE:6)
Block(-6,48,-2,CONCRETE:6)
Block(-6,48,-1,CONCRETE:6)
Block(-6,48,0,CONCRETE:6)
Block(-5,0,-3,STAINED_CLAY:6)
Block(-5,0,-2,STAINED_CLAY:6)
Block(-5,0,-1,STAINED_CLAY:6)
Block(-5,0,0,STAINED_CLAY:6)
Block(-5,0,1,STAINED_CLAY:6)
Block(-5,0,2,STAINED_CLAY:6)
Block(-5,1,-3,STAINED_CLAY:6)
Block(-5,1,-2,STAINED_CLAY:6)
Block(-5,1,-1,STAINED_CLAY:6)
Block(-5,1,0,STAINED_CLAY:6)
Block(-5,1,1,STAINED_CLAY:6)
Block(-5,2,-3,STAINED_CLAY:6)
Block(-5,2,-2,STAINED_CLAY:6)
Block(-5,2,-1,STAINED_CLAY:6)
Block(-5,2,0,STAINED_CLAY:6)
Block(-5,2,1,STAINED_CLAY:6)
Block(-5,3,-3,STAINED_CLAY:6)
Block(-5,3,-2,STAINED_CLAY:6)
Block(-5,3,-1,STAINED_CLAY:6)
Block(-5,3,0,STAINED_CLAY:6)
Block(-5,3,1,STAINED_CLAY:6)
Block(-5,4,-3,STAINED_CLAY:6)
Block(-5,4,-2,STAINED_CLAY:6)
Block(-5,4,-1,STAINED_CLAY:6)
Block(-5,4,0,STAINED_CLAY:6)
Block(-5,4,1,STAINED_CLAY:6)
Block(-5,5,-3,STAINED_CLAY:6)
Block(-5,5,-2,STAINED_CLAY:6)
Block(-5,5,-1,STAINED_CLAY:6)
Block(-5,5,0,STAINED_CLAY:6)
Block(-5,5,1,STAINED_CLAY:6)
Block(-5,6,-2,STAINED_CLAY:6)
Block(-5,6,-1,STAINED_CLAY:6)
Block(-5,6,0,STAINED_CLAY:6)
Block(-5,6,1,STAINED_CLAY:6)
Block(-5,7,-1,STAINED_CLAY:6)
Block(-5,7,0,STAINED_CLAY:6)
Block(-5,7,1,STAINED_CLAY:6)
Block(-5,8,-1,STAINED_CLAY:6)
Block(-5,8,0,STAINED_CLAY:6)
Block(-5,8,1,STAINED_CLAY:6)
Block(-5,9,-1,STAINED_CLAY:6)
Block(-5,9,0,STAINED_CLAY:6)
Block(-5,9,1,STAINED_CLAY:6)
Block(-5,10,-1,STAINED_CLAY:6)
Block(-5,10,0,STAINED_CLAY:6)
Block(-5,10,1,STAINED_CLAY:6)
Block(-5,11,-1,STAINED_CLAY:6)
Block(-5,11,0,STAINED_CLAY:6)
Block(-5,11,1,STAINED_CLAY:6)
Block(-5,23,-1,STAINED_CLAY:6)
Block(-5,23,0,STAINED_CLAY:6)
Block(-5,24,-1,STAINED_CLAY:6)
Block(-5,24,0,STAINED_CLAY:6)
Block(-5,24,1,STAINED_CLAY:6)
Block(-5,25,-2,STAINED_CLAY:6)
Block(-5,25,-1,STAINED_CLAY:6)
Block(-5,25,0,STAINED_CLAY:6)
Block(-5,25,1,STAINED_CLAY:6)
Block(-5,26,-2,STAINED_CLAY:6)
Block(-5,26,-1,STAINED_CLAY:6)
Block(-5,26,0,STAINED_CLAY:6)
Block(-5,26,1,STAINED_CLAY:6)
Block(-5,27,-2,STAINED_CLAY:6)
Block(-5,27,-1,STAINED_CLAY:6)
Block(-5,27,0,STAINED_CLAY:6)
Block(-5,27,1,STAINED_CLAY:6)
Block(-5,28,-2,STAINED_CLAY:6)
Block(-5,28,-1,STAINED_CLAY:6)
Block(-5,28,0,STAINED_CLAY:6)
Block(-5,28,1,STAINED_CLAY:6)
Block(-5,29,-2,STAINED_CLAY:6)
Block(-5,29,-1,STAINED_CLAY:6)
Block(-5,29,0,STAINED_CLAY:6)
Block(-5,29,1,STAINED_CLAY:6)
Block(-5,29,2,STAINED_CLAY:6)
Block(-5,30,-2,STAINED_CLAY:6)
Block(-5,30,-1,STAINED_CLAY:6)
Block(-5,30,0,STAINED_CLAY:6)
Block(-5,30,1,STAINED_CLAY:6)
Block(-5,30,2,STAINED_CLAY:6)
Block(-5,30,4,CONCRETE:6)
Block(-5,30,5,CONCRETE:6)
Block(-5,31,-2,CONCRETE:6)
Block(-5,31,-1,STAINED_CLAY:6)
Block(-5,31,0,STAINED_CLAY:6)
Block(-5,31,1,STAINED_CLAY:6)
Block(-5,31,2,CONCRETE:6)
Block(-5,31,3,CONCRETE:6)
Block(-5,31,4,CONCRETE:6)
Block(-5,31,5,CONCRETE:6)
Block(-5,31,6,CONCRETE:6)
Block(-5,32,-3,CONCRETE:6)
Block(-5,32,-2,CONCRETE:6)
Block(-5,32,-1,CONCRETE:6)
Block(-5,32,0,CONCRETE:6)
Block(-5,32,1,CONCRETE:0)
Block(-5,32,2,CONCRETE:6)
Block(-5,32,3,CONCRETE:6)
Block(-5,32,4,CONCRETE:6)
Block(-5,32,5,CONCRETE:6)
Block(-5,32,6,CONCRETE:6)
Block(-5,32,7,CONCRETE:6)
Block(-5,33,-4,CONCRETE:6)
Block(-5,33,-3,CONCRETE:6)
Block(-5,33,-2,CONCRETE:6)
Block(-5,33,-1,CONCRETE:6)
Block(-5,33,0,CONCRETE:6)
Block(-5,33,1,CONCRETE:0)
Block(-5,33,2,CONCRETE:0)
Block(-5,33,3,CONCRETE:6)
Block(-5,33,4,CONCRETE:6)
Block(-5,33,5,CONCRETE:6)
Block(-5,33,6,CONCRETE:6)
Block(-5,33,7,CONCRETE:6)
Block(-5,34,-4,CONCRETE:6)
Block(-5,34,-3,CONCRETE:6)
Block(-5,34,-2,CONCRETE:6)
Block(-5,34,-1,CONCRETE:6)
Block(-5,34,0,CONCRETE:0)
Block(-5,34,1,CONCRETE:0)
Block(-5,34,2,CONCRETE:0)
Block(-5,34,3,CONCRETE:0)
Block(-5,34,4,CONCRETE:0)
Block(-5,34,5,CONCRETE:6)
Block(-5,34,6,CONCRETE:6)
Block(-5,35,-5,CONCRETE:0)
Block(-5,35,-4,CONCRETE:6)
Block(-5,35,-3,CONCRETE:6)
Block(-5,35,-2,CONCRETE:6)
Block(-5,35,-1,CONCRETE:6)
Block(-5,35,0,CONCRETE:0)
Block(-5,35,1,CONCRETE:0)
Block(-5,35,2,CONCRETE:0)
Block(-5,35,3,CONCRETE:0)
Block(-5,35,4,CONCRETE:0)
Block(-5,35,5,CONCRETE:0)
Block(-5,35,6,CONCRETE:0)
Block(-5,36,-5,CONCRETE:6)
Block(-5,36,-4,CONCRETE:6)
Block(-5,36,-3,CONCRETE:6)
Block(-5,36,-2,CONCRETE:0)
Block(-5,36,-1,CONCRETE:0)
Block(-5,36,0,CONCRETE:0)
Block(-5,36,1,CONCRETE:0)
Block(-5,36,2,CONCRETE:0)
Block(-5,36,3,CONCRETE:0)
Block(-5,36,4,CONCRETE:0)
Block(-5,36,5,CONCRETE:0)
Block(-5,36,6,CONCRETE:0)
Block(-5,36,7,CONCRETE:0)
Block(-5,37,-7,CONCRETE:6)
Block(-5,37,-6,CONCRETE:6)
Block(-5,37,-5,CONCRETE:6)
Block(-5,37,-4,CONCRETE:6)
Block(-5,37,-3,CONCRETE:0)
Block(-5,37,-2,CONCRETE:0)
Block(-5,37,-1,CONCRETE:0)
Block(-5,37,0,CONCRETE:0)
Block(-5,37,1,CONCRETE:0)
Block(-5,37,2,CONCRETE:0)
Block(-5,37,3,CONCRETE:0)
Block(-5,37,4,CONCRETE:0)
Block(-5,37,5,CONCRETE:0)
Block(-5,37,6,CONCRETE:0)
Block(-5,37,7,CONCRETE:0)
Block(-5,38,-8,CONCRETE:6)
Block(-5,38,-7,CONCRETE:6)
Block(-5,38,-6,CONCRETE:6)
Block(-5,38,-5,CONCRETE:6)
Block(-5,38,-4,CONCRETE:6)
Block(-5,38,-3,CONCRETE:0)
Block(-5,38,-2,CONCRETE:0)
Block(-5,38,-1,CONCRETE:0)
Block(-5,38,0,CONCRETE:0)
Block(-5,38,1,CONCRETE:0)
Block(-5,38,2,CONCRETE:0)
Block(-5,38,3,CONCRETE:0)
Block(-5,38,4,CONCRETE:0)
Block(-5,38,5,CONCRETE:0)
Block(-5,38,6,CONCRETE:0)
Block(-5,38,7,CONCRETE:0)
Block(-5,38,8,CONCRETE:0)
Block(-5,39,-8,CONCRETE:6)
Block(-5,39,-7,CONCRETE:6)
Block(-5,39,-6,CONCRETE:6)
Block(-5,39,-5,CONCRETE:6)
Block(-5,39,-4,CONCRETE:6)
Block(-5,39,-3,CONCRETE:0)
Block(-5,39,-2,CONCRETE:0)
Block(-5,39,-1,CONCRETE:0)
Block(-5,39,0,CONCRETE:0)
Block(-5,39,1,CONCRETE:0)
Block(-5,39,2,CONCRETE:0)
Block(-5,39,3,CONCRETE:0)
Block(-5,39,4,CONCRETE:0)
Block(-5,39,5,CONCRETE:0)
Block(-5,39,6,CONCRETE:0)
Block(-5,39,7,CONCRETE:0)
Block(-5,39,8,CONCRETE:0)
Block(-5,40,-9,CONCRETE:6)
Block(-5,40,-8,CONCRETE:6)
Block(-5,40,-7,CONCRETE:6)
Block(-5,40,-6,CONCRETE:6)
Block(-5,40,-5,CONCRETE:6)
Block(-5,40,-4,CONCRETE:6)
Block(-5,40,-3,CONCRETE:0)
Block(-5,40,-2,CONCRETE:0)
Block(-5,40,-1,CONCRETE:0)
Block(-5,40,0,CONCRETE:0)
Block(-5,40,1,CONCRETE:0)
Block(-5,40,2,CONCRETE:0)
Block(-5,40,3,CONCRETE:0)
Block(-5,40,4,CONCRETE:0)
Block(-5,40,5,CONCRETE:0)
Block(-5,40,6,CONCRETE:0)
Block(-5,40,7,CONCRETE:0)
Block(-5,41,-8,CONCRETE:6)
Block(-5,41,-7,CONCRETE:6)
Block(-5,41,-6,CONCRETE:6)
Block(-5,41,-5,CONCRETE:6)
Block(-5,41,-4,CONCRETE:6)
Block(-5,41,-3,CONCRETE:0)
Block(-5,41,-2,CONCRETE:0)
Block(-5,41,-1,CONCRETE:0)
Block(-5,41,0,CONCRETE:0)
Block(-5,41,1,CONCRETE:0)
Block(-5,41,2,CONCRETE:0)
Block(-5,41,3,CONCRETE:0)
Block(-5,41,4,CONCRETE:0)
Block(-5,41,5,CONCRETE:0)
Block(-5,41,6,CONCRETE:0)
Block(-5,41,7,CONCRETE:0)
Block(-5,42,-8,CONCRETE:6)
Block(-5,42,-7,CONCRETE:6)
Block(-5,42,-6,CONCRETE:6)
Block(-5,42,-5,CONCRETE:6)
Block(-5,42,-4,CONCRETE:6)
Block(-5,42,-3,CONCRETE:0)
Block(-5,42,-2,CONCRETE:0)
Block(-5,42,-1,CONCRETE:0)
Block(-5,42,0,CONCRETE:0)
Block(-5,42,1,CONCRETE:0)
Block(-5,42,2,CONCRETE:0)
Block(-5,42,3,CONCRETE:0)
Block(-5,42,4,CONCRETE:0)
Block(-5,42,5,CONCRETE:0)
Block(-5,42,6,CONCRETE:0)
Block(-5,42,7,CONCRETE:0)
Block(-5,43,-7,CONCRETE:6)
Block(-5,43,-6,CONCRETE:6)
Block(-5,43,-5,CONCRETE:6)
Block(-5,43,-4,CONCRETE:6)
Block(-5,43,-3,CONCRETE:0)
Block(-5,43,-2,CONCRETE:0)
Block(-5,43,-1,CONCRETE:0)
Block(-5,43,0,CONCRETE:0)
Block(-5,43,1,CONCRETE:0)
Block(-5,43,2,CONCRETE:0)
Block(-5,43,3,CONCRETE:0)
Block(-5,43,4,CONCRETE:0)
Block(-5,43,5,CONCRETE:0)
Block(-5,43,6,CONCRETE:0)
Block(-5,43,7,CONCRETE:0)
Block(-5,44,-4,CONCRETE:6)
Block(-5,44,-3,CONCRETE:6)
Block(-5,44,-2,CONCRETE:6)
Block(-5,44,-1,CONCRETE:6)
Block(-5,44,0,CONCRETE:6)
Block(-5,44,1,CONCRETE:0)
Block(-5,44,2,CONCRETE:0)
Block(-5,44,3,CONCRETE:0)
Block(-5,44,4,CONCRETE:0)
Block(-5,44,5,CONCRETE:0)
Block(-5,44,6,CONCRETE:0)
Block(-5,45,-4,CONCRETE:6)
Block(-5,45,-3,CONCRETE:6)
Block(-5,45,-2,CONCRETE:6)
Block(-5,45,-1,CONCRETE:6)
Block(-5,45,0,CONCRETE:6)
Block(-5,45,1,CONCRETE:6)
Block(-5,45,2,CONCRETE:0)
Block(-5,45,3,CONCRETE:0)
Block(-5,45,4,CONCRETE:0)
Block(-5,45,5,CONCRETE:0)
Block(-5,46,-4,CONCRETE:6)
Block(-5,46,-3,CONCRETE:6)
Block(-5,46,-2,CONCRETE:6)
Block(-5,46,-1,CONCRETE:6)
Block(-5,46,0,CONCRETE:6)
Block(-5,46,1,CONCRETE:6)
Block(-5,46,2,CONCRETE:6)
Block(-5,46,3,CONCRETE:0)
Block(-5,47,-3,CONCRETE:6)
Block(-5,47,-2,CONCRETE:6)
Block(-5,47,-1,CONCRETE:6)
Block(-5,47,0,CONCRETE:6)
Block(-5,47,1,CONCRETE:6)
Block(-5,47,2,CONCRETE:6)
Block(-5,48,-2,CONCRETE:6)
Block(-5,48,-1,CONCRETE:6)
Block(-5,48,0,CONCRETE:6)
Block(-5,48,1,CONCRETE:6)
Block(-5,49,-1,CONCRETE:6)
Block(-4,0,-4,STAINED_CLAY:6)
Block(-4,0,-3,STAINED_CLAY:6)
Block(-4,0,-2,STAINED_CLAY:6)
Block(-4,0,-1,STAINED_CLAY:6)
Block(-4,0,0,STAINED_CLAY:6)
Block(-4,0,1,STAINED_CLAY:6)
Block(-4,0,2,STAINED_CLAY:6)
Block(-4,1,-4,STAINED_CLAY:6)
Block(-4,1,-3,STAINED_CLAY:6)
Block(-4,1,-2,STAINED_CLAY:6)
Block(-4,1,-1,STAINED_CLAY:6)
Block(-4,1,0,STAINED_CLAY:6)
Block(-4,1,1,STAINED_CLAY:6)
Block(-4,1,2,STAINED_CLAY:6)
Block(-4,2,-4,STAINED_CLAY:6)
Block(-4,2,-3,STAINED_CLAY:6)
Block(-4,2,-2,STAINED_CLAY:6)
Block(-4,2,-1,STAINED_CLAY:6)
Block(-4,2,0,STAINED_CLAY:6)
Block(-4,2,1,STAINED_CLAY:6)
Block(-4,2,2,STAINED_CLAY:6)
Block(-4,3,-4,STAINED_CLAY:6)
Block(-4,3,-3,STAINED_CLAY:6)
Block(-4,3,-2,STAINED_CLAY:6)
Block(-4,3,-1,STAINED_CLAY:6)
Block(-4,3,0,STAINED_CLAY:6)
Block(-4,3,1,STAINED_CLAY:6)
Block(-4,3,2,STAINED_CLAY:6)
Block(-4,4,-4,STAINED_CLAY:6)
Block(-4,4,-3,STAINED_CLAY:6)
Block(-4,4,-2,STAINED_CLAY:6)
Block(-4,4,-1,STAINED_CLAY:6)
Block(-4,4,0,STAINED_CLAY:6)
Block(-4,4,1,STAINED_CLAY:6)
Block(-4,5,-4,STAINED_CLAY:6)
Block(-4,5,-3,STAINED_CLAY:6)
Block(-4,5,-2,STAINED_CLAY:6)
Block(-4,5,-1,STAINED_CLAY:6)
Block(-4,5,0,STAINED_CLAY:6)
Block(-4,5,1,STAINED_CLAY:6)
Block(-4,6,-3,STAINED_CLAY:6)
Block(-4,6,-2,STAINED_CLAY:6)
Block(-4,6,-1,STAINED_CLAY:6)
Block(-4,6,0,STAINED_CLAY:6)
Block(-4,6,1,STAINED_CLAY:6)
Block(-4,6,2,STAINED_CLAY:6)
Block(-4,7,-2,STAINED_CLAY:6)
Block(-4,7,-1,STAINED_CLAY:6)
Block(-4,7,0,STAINED_CLAY:6)
Block(-4,7,1,STAINED_CLAY:6)
Block(-4,7,2,STAINED_CLAY:6)
Block(-4,8,-2,STAINED_CLAY:6)
Block(-4,8,-1,STAINED_CLAY:6)
Block(-4,8,0,STAINED_CLAY:6)
Block(-4,8,1,STAINED_CLAY:6)
Block(-4,8,2,STAINED_CLAY:6)
Block(-4,9,-2,STAINED_CLAY:6)
Block(-4,9,-1,STAINED_CLAY:6)
Block(-4,9,0,STAINED_CLAY:6)
Block(-4,9,1,STAINED_CLAY:6)
Block(-4,9,2,STAINED_CLAY:6)
Block(-4,10,-2,STAINED_CLAY:6)
Block(-4,10,-1,STAINED_CLAY:6)
Block(-4,10,0,STAINED_CLAY:6)
Block(-4,10,1,STAINED_CLAY:6)
Block(-4,10,2,STAINED_CLAY:6)
Block(-4,10,3,STAINED_CLAY:6)
Block(-4,11,-2,STAINED_CLAY:6)
Block(-4,11,-1,STAINED_CLAY:6)
Block(-4,11,0,STAINED_CLAY:6)
Block(-4,11,1,STAINED_CLAY:6)
Block(-4,11,2,STAINED_CLAY:6)
Block(-4,11,3,STAINED_CLAY:6)
Block(-4,12,-1,STAINED_CLAY:6)
Block(-4,12,0,STAINED_CLAY:6)
Block(-4,12,1,STAINED_CLAY:6)
Block(-4,12,2,STAINED_CLAY:6)
Block(-4,13,-1,STAINED_CLAY:6)
Block(-4,13,0,STAINED_CLAY:6)
Block(-4,13,1,STAINED_CLAY:6)
Block(-4,14,-2,STAINED_CLAY:6)
Block(-4,14,-1,STAINED_CLAY:6)
Block(-4,14,0,STAINED_CLAY:6)
Block(-4,15,-2,STAINED_CLAY:6)
Block(-4,15,-1,STAINED_CLAY:6)
Block(-4,15,0,STAINED_CLAY:6)
Block(-4,16,-2,STAINED_CLAY:6)
Block(-4,16,-1,STAINED_CLAY:6)
Block(-4,16,0,STAINED_CLAY:6)
Block(-4,17,-2,STAINED_CLAY:6)
Block(-4,17,-1,STAINED_CLAY:6)
Block(-4,17,0,STAINED_CLAY:6)
Block(-4,18,-2,STAINED_CLAY:6)
Block(-4,18,-1,STAINED_CLAY:6)
Block(-4,18,0,STAINED_CLAY:6)
Block(-4,19,-2,STAINED_CLAY:6)
Block(-4,19,-1,STAINED_CLAY:6)
Block(-4,19,0,STAINED_CLAY:6)
Block(-4,20,-2,STAINED_CLAY:6)
Block(-4,20,-1,STAINED_CLAY:6)
Block(-4,20,0,STAINED_CLAY:6)
Block(-4,21,-2,STAINED_CLAY:6)
Block(-4,21,-1,STAINED_CLAY:6)
Block(-4,21,0,STAINED_CLAY:6)
Block(-4,22,-2,STAINED_CLAY:6)
Block(-4,22,-1,STAINED_CLAY:6)
Block(-4,22,0,STAINED_CLAY:6)
Block(-4,23,-2,STAINED_CLAY:6)
Block(-4,23,-1,STAINED_CLAY:6)
Block(-4,23,0,STAINED_CLAY:6)
Block(-4,23,1,STAINED_CLAY:6)
Block(-4,24,-2,STAINED_CLAY:6)
Block(-4,24,-1,STAINED_CLAY:6)
Block(-4,24,0,STAINED_CLAY:6)
Block(-4,24,1,STAINED_CLAY:6)
Block(-4,25,-3,STAINED_CLAY:6)
Block(-4,25,-2,STAINED_CLAY:6)
Block(-4,25,-1,STAINED_CLAY:6)
Block(-4,25,0,STAINED_CLAY:6)
Block(-4,25,1,STAINED_CLAY:6)
Block(-4,25,2,STAINED_CLAY:6)
Block(-4,26,-3,STAINED_CLAY:6)
Block(-4,26,-2,STAINED_CLAY:6)
Block(-4,26,-1,STAINED_CLAY:6)
Block(-4,26,0,STAINED_CLAY:6)
Block(-4,26,1,STAINED_CLAY:6)
Block(-4,26,2,STAINED_CLAY:6)
Block(-4,27,-3,STAINED_CLAY:6)
Block(-4,27,-2,STAINED_CLAY:6)
Block(-4,27,-1,STAINED_CLAY:6)
Block(-4,27,0,STAINED_CLAY:6)
Block(-4,27,1,STAINED_CLAY:6)
Block(-4,27,2,STAINED_CLAY:6)
Block(-4,28,-3,STAINED_CLAY:6)
Block(-4,28,-2,STAINED_CLAY:6)
Block(-4,28,-1,STAINED_CLAY:6)
Block(-4,28,0,STAINED_CLAY:6)
Block(-4,28,1,STAINED_CLAY:6)
Block(-4,28,2,STAINED_CLAY:6)
Block(-4,29,-2,STAINED_CLAY:6)
Block(-4,29,-1,STAINED_CLAY:6)
Block(-4,29,0,STAINED_CLAY:6)
Block(-4,29,1,STAINED_CLAY:6)
Block(-4,29,2,STAINED_CLAY:6)
Block(-4,29,3,STAINED_CLAY:6)
Block(-4,29,4,CONCRETE:6)
Block(-4,29,5,CONCRETE:6)
Block(-4,30,-2,STAINED_CLAY:6)
Block(-4,30,-1,STAINED_CLAY:6)
Block(-4,30,0,STAINED_CLAY:6)
Block(-4,30,1,STAINED_CLAY:6)
Block(-4,30,2,STAINED_CLAY:6)
Block(-4,30,3,CONCRETE:6)
Block(-4,30,4,CONCRETE:6)
Block(-4,30,5,CONCRETE:6)
Block(-4,30,6,CONCRETE:6)
Block(-4,30,7,CONCRETE:6)
Block(-4,31,-2,STAINED_CLAY:6)
Block(-4,31,-1,STAINED_CLAY:6)
Block(-4,31,0,STAINED_CLAY:6)
Block(-4,31,1,STAINED_CLAY:6)
Block(-4,31,2,CONCRETE:6)
Block(-4,31,3,CONCRETE:6)
Block(-4,31,4,CONCRETE:6)
Block(-4,31,5,CONCRETE:6)
Block(-4,31,6,CONCRETE:6)
Block(-4,31,7,CONCRETE:6)
Block(-4,32,-2,CONCRETE:0)
Block(-4,32,-1,CONCRETE:0)
Block(-4,32,0,CONCRETE:0)
Block(-4,32,1,CONCRETE:0)
Block(-4,32,2,CONCRETE:6)
Block(-4,32,3,CONCRETE:6)
Block(-4,32,4,CONCRETE:6)
Block(-4,32,5,CONCRETE:6)
Block(-4,32,6,CONCRETE:6)
Block(-4,32,7,CONCRETE:6)
Block(-4,33,-3,CONCRETE:6)
Block(-4,33,-2,CONCRETE:6)
Block(-4,33,-1,CONCRETE:0)
Block(-4,33,0,CONCRETE:0)
Block(-4,33,1,CONCRETE:0)
Block(-4,33,2,CONCRETE:0)
Block(-4,33,3,CONCRETE:6)
Block(-4,33,4,CONCRETE:6)
Block(-4,33,5,CONCRETE:6)
Block(-4,33,6,CONCRETE:6)
Block(-4,33,7,CONCRETE:6)
Block(-4,34,-4,CONCRETE:0)
Block(-4,34,-3,CONCRETE:6)
Block(-4,34,-2,CONCRETE:6)
Block(-4,34,-1,CONCRETE:0)
Block(-4,34,0,CONCRETE:0)
Block(-4,34,1,CONCRETE:0)
Block(-4,34,2,CONCRETE:0)
Block(-4,34,3,CONCRETE:0)
Block(-4,34,4,CONCRETE:6)
Block(-4,34,5,CONCRETE:6)
Block(-4,34,6,CONCRETE:6)
Block(-4,34,7,CONCRETE:6)
Block(-4,35,-5,CONCRETE:0)
Block(-4,35,-4,CONCRETE:0)
Block(-4,35,-3,CONCRETE:0)
Block(-4,35,-2,CONCRETE:0)
Block(-4,35,-1,CONCRETE:0)
Block(-4,35,0,CONCRETE:0)
Block(-4,35,1,CONCRETE:0)
Block(-4,35,2,CONCRETE:0)
Block(-4,35,3,CONCRETE:0)
Block(-4,35,4,CONCRETE:0)
Block(-4,35,5,CONCRETE:6)
Block(-4,35,6,CONCRETE:6)
Block(-4,35,7,CONCRETE:6)
Block(-4,36,-6,CONCRETE:0)
Block(-4,36,-5,CONCRETE:0)
Block(-4,36,-4,CONCRETE:0)
Block(-4,36,-3,CONCRETE:0)
Block(-4,36,-2,CONCRETE:0)
Block(-4,36,-1,CONCRETE:0)
Block(-4,36,0,CONCRETE:0)
Block(-4,36,1,CONCRETE:0)
Block(-4,36,2,CONCRETE:0)
Block(-4,36,3,CONCRETE:0)
Block(-4,36,4,CONCRETE:0)
Block(-4,36,5,CONCRETE:0)
Block(-4,36,6,CONCRETE:0)
Block(-4,36,7,CONCRETE:6)
Block(-4,36,8,CONCRETE:6)
Block(-4,37,-7,CONCRETE:6)
Block(-4,37,-6,CONCRETE:6)
Block(-4,37,-5,CONCRETE:6)
Block(-4,37,-4,CONCRETE:0)
Block(-4,37,-3,CONCRETE:0)
Block(-4,37,-2,CONCRETE:0)
Block(-4,37,-1,CONCRETE:0)
Block(-4,37,0,CONCRETE:0)
Block(-4,37,1,CONCRETE:0)
Block(-4,37,2,CONCRETE:0)
Block(-4,37,3,CONCRETE:0)
Block(-4,37,4,CONCRETE:0)
Block(-4,37,5,CONCRETE:0)
Block(-4,37,6,CONCRETE:0)
Block(-4,37,7,CONCRETE:0)
Block(-4,37,8,CONCRETE:6)
Block(-4,37,9,CONCRETE:6)
Block(-4,38,-8,CONCRETE:6)
Block(-4,38,-7,CONCRETE:6)
Block(-4,38,-6,CONCRETE:6)
Block(-4,38,-5,CONCRETE:6)
Block(-4,38,-4,CONCRETE:0)
Block(-4,38,-3,CONCRETE:0)
Block(-4,38,-2,CONCRETE:0)
Block(-4,38,-1,CONCRETE:0)
Block(-4,38,0,CONCRETE:0)
Block(-4,38,1,CONCRETE:0)
Block(-4,38,2,CONCRETE:0)
Block(-4,38,3,CONCRETE:0)
Block(-4,38,4,CONCRETE:0)
Block(-4,38,5,CONCRETE:0)
Block(-4,38,6,CONCRETE:0)
Block(-4,38,7,CONCRETE:0)
Block(-4,38,8,CONCRETE:6)
Block(-4,38,9,CONCRETE:6)
Block(-4,39,-8,CONCRETE:6)
Block(-4,39,-7,CONCRETE:6)
Block(-4,39,-6,CONCRETE:6)
Block(-4,39,-5,CONCRETE:6)
Block(-4,39,-4,CONCRETE:6)
Block(-4,39,-3,CONCRETE:0)
Block(-4,39,-2,CONCRETE:0)
Block(-4,39,-1,CONCRETE:0)
Block(-4,39,0,CONCRETE:0)
Block(-4,39,1,CONCRETE:0)
Block(-4,39,2,CONCRETE:0)
Block(-4,39,3,CONCRETE:0)
Block(-4,39,4,CONCRETE:0)
Block(-4,39,5,CONCRETE:0)
Block(-4,39,6,CONCRETE:0)
Block(-4,39,7,CONCRETE:0)
Block(-4,39,8,CONCRETE:0)
Block(-4,40,-8,CONCRETE:6)
Block(-4,40,-7,CONCRETE:6)
Block(-4,40,-6,CONCRETE:6)
Block(-4,40,-5,CONCRETE:6)
Block(-4,40,-4,CONCRETE:6)
Block(-4,40,-3,CONCRETE:0)
Block(-4,40,-2,CONCRETE:0)
Block(-4,40,-1,CONCRETE:0)
Block(-4,40,0,CONCRETE:0)
Block(-4,40,1,CONCRETE:0)
Block(-4,40,2,CONCRETE:0)
Block(-4,40,3,CONCRETE:0)
Block(-4,40,4,CONCRETE:0)
Block(-4,40,5,CONCRETE:0)
Block(-4,40,6,CONCRETE:0)
Block(-4,40,7,CONCRETE:0)
Block(-4,40,8,CONCRETE:0)
Block(-4,41,-8,CONCRETE:6)
Block(-4,41,-7,CONCRETE:6)
Block(-4,41,-6,CONCRETE:6)
Block(-4,41,-5,CONCRETE:6)
Block(-4,41,-4,CONCRETE:6)
Block(-4,41,-3,CONCRETE:0)
Block(-4,41,-2,CONCRETE:0)
Block(-4,41,-1,CONCRETE:0)
Block(-4,41,0,CONCRETE:0)
Block(-4,41,1,CONCRETE:0)
Block(-4,41,2,CONCRETE:0)
Block(-4,41,3,CONCRETE:0)
Block(-4,41,4,CONCRETE:0)
Block(-4,41,5,CONCRETE:0)
Block(-4,41,6,CONCRETE:0)
Block(-4,41,7,CONCRETE:0)
Block(-4,41,8,CONCRETE:0)
Block(-4,42,-8,CONCRETE:6)
Block(-4,42,-7,CONCRETE:6)
Block(-4,42,-6,CONCRETE:6)
Block(-4,42,-5,CONCRETE:6)
Block(-4,42,-4,CONCRETE:6)
Block(-4,42,-3,CONCRETE:0)
Block(-4,42,-2,CONCRETE:0)
Block(-4,42,-1,CONCRETE:0)
Block(-4,42,0,CONCRETE:0)
Block(-4,42,1,CONCRETE:0)
Block(-4,42,2,CONCRETE:0)
Block(-4,42,3,CONCRETE:0)
Block(-4,42,4,CONCRETE:0)
Block(-4,42,5,CONCRETE:0)
Block(-4,42,6,CONCRETE:0)
Block(-4,42,7,CONCRETE:0)
Block(-4,42,8,CONCRETE:0)
Block(-4,43,-6,CONCRETE:6)
Block(-4,43,-5,CONCRETE:6)
Block(-4,43,-4,CONCRETE:6)
Block(-4,43,-3,CONCRETE:0)
Block(-4,43,-2,CONCRETE:0)
Block(-4,43,-1,CONCRETE:0)
Block(-4,43,0,CONCRETE:0)
Block(-4,43,1,CONCRETE:0)
Block(-4,43,2,CONCRETE:0)
Block(-4,43,3,CONCRETE:0)
Block(-4,43,4,CONCRETE:0)
Block(-4,43,5,CONCRETE:0)
Block(-4,43,6,CONCRETE:0)
Block(-4,43,7,CONCRETE:0)
Block(-4,44,-5,CONCRETE:6)
Block(-4,44,-4,CONCRETE:6)
Block(-4,44,-3,CONCRETE:6)
Block(-4,44,-2,CONCRETE:6)
Block(-4,44,-1,CONCRETE:6)
Block(-4,44,0,CONCRETE:6)
Block(-4,44,1,CONCRETE:0)
Block(-4,44,2,CONCRETE:0)
Block(-4,44,3,CONCRETE:0)
Block(-4,44,4,CONCRETE:0)
Block(-4,44,5,CONCRETE:0)
Block(-4,44,6,CONCRETE:0)
Block(-4,44,7,CONCRETE:0)
Block(-4,45,-4,CONCRETE:6)
Block(-4,45,-3,CONCRETE:6)
Block(-4,45,-2,CONCRETE:6)
Block(-4,45,-1,CONCRETE:6)
Block(-4,45,0,CONCRETE:6)
Block(-4,45,1,CONCRETE:6)
Block(-4,45,2,CONCRETE:0)
Block(-4,45,3,CONCRETE:0)
Block(-4,45,4,CONCRETE:0)
Block(-4,45,5,CONCRETE:0)
Block(-4,45,6,CONCRETE:0)
Block(-4,46,-4,CONCRETE:6)
Block(-4,46,-3,CONCRETE:6)
Block(-4,46,-2,CONCRETE:6)
Block(-4,46,-1,CONCRETE:6)
Block(-4,46,0,CONCRETE:6)
Block(-4,46,1,CONCRETE:6)
Block(-4,46,2,CONCRETE:6)
Block(-4,46,3,CONCRETE:0)
Block(-4,46,4,CONCRETE:0)
Block(-4,47,-3,CONCRETE:6)
Block(-4,47,-2,CONCRETE:6)
Block(-4,47,-1,CONCRETE:6)
Block(-4,47,0,CONCRETE:6)
Block(-4,47,1,CONCRETE:6)
Block(-4,47,2,CONCRETE:6)
Block(-4,48,-3,CONCRETE:6)
Block(-4,48,-2,CONCRETE:6)
Block(-4,48,-1,CONCRETE:6)
Block(-4,48,0,CONCRETE:6)
Block(-4,48,1,CONCRETE:6)
Block(-4,49,-2,CONCRETE:6)
Block(-4,49,-1,CONCRETE:6)
Block(-4,49,0,CONCRETE:6)
Block(-3,0,-4,STAINED_CLAY:6)
Block(-3,0,-3,STAINED_CLAY:6)
Block(-3,0,-2,STAINED_CLAY:6)
Block(-3,0,-1,STAINED_CLAY:6)
Block(-3,0,0,STAINED_CLAY:6)
Block(-3,0,1,STAINED_CLAY:6)
Block(-3,0,2,STAINED_CLAY:6)
Block(-3,1,-4,STAINED_CLAY:6)
Block(-3,1,-3,STAINED_CLAY:6)
Block(-3,1,-2,STAINED_CLAY:6)
Block(-3,1,-1,STAINED_CLAY:6)
Block(-3,1,0,STAINED_CLAY:6)
Block(-3,1,1,STAINED_CLAY:6)
Block(-3,1,2,STAINED_CLAY:6)
Block(-3,2,-4,STAINED_CLAY:6)
Block(-3,2,-3,STAINED_CLAY:6)
Block(-3,2,-2,STAINED_CLAY:6)
Block(-3,2,-1,STAINED_CLAY:6)
Block(-3,2,0,STAINED_CLAY:6)
Block(-3,2,1,STAINED_CLAY:6)
Block(-3,2,2,STAINED_CLAY:6)
Block(-3,3,-4,STAINED_CLAY:6)
Block(-3,3,-3,STAINED_CLAY:6)
Block(-3,3,-2,STAINED_CLAY:6)
Block(-3,3,-1,STAINED_CLAY:6)
Block(-3,3,0,STAINED_CLAY:6)
Block(-3,3,1,STAINED_CLAY:6)
Block(-3,3,2,STAINED_CLAY:6)
Block(-3,4,-4,STAINED_CLAY:6)
Block(-3,4,-3,STAINED_CLAY:6)
Block(-3,4,-2,STAINED_CLAY:6)
Block(-3,4,-1,STAINED_CLAY:6)
Block(-3,4,0,STAINED_CLAY:6)
Block(-3,4,1,STAINED_CLAY:6)
Block(-3,4,2,STAINED_CLAY:6)
Block(-3,5,-4,STAINED_CLAY:6)
Block(-3,5,-3,STAINED_CLAY:6)
Block(-3,5,-2,STAINED_CLAY:6)
Block(-3,5,-1,STAINED_CLAY:6)
Block(-3,5,0,STAINED_CLAY:6)
Block(-3,5,1,STAINED_CLAY:6)
Block(-3,5,2,STAINED_CLAY:6)
Block(-3,6,-3,STAINED_CLAY:6)
Block(-3,6,-2,STAINED_CLAY:6)
Block(-3,6,-1,STAINED_CLAY:6)
Block(-3,6,0,STAINED_CLAY:6)
Block(-3,6,1,STAINED_CLAY:6)
Block(-3,6,2,STAINED_CLAY:6)
Block(-3,7,-3,STAINED_CLAY:6)
Block(-3,7,-2,STAINED_CLAY:6)
Block(-3,7,-1,STAINED_CLAY:6)
Block(-3,7,0,STAINED_CLAY:6)
Block(-3,7,1,STAINED_CLAY:6)
Block(-3,7,2,STAINED_CLAY:6)
Block(-3,7,3,STAINED_CLAY:6)
Block(-3,8,-2,STAINED_CLAY:6)
Block(-3,8,-1,STAINED_CLAY:6)
Block(-3,8,0,STAINED_CLAY:6)
Block(-3,8,1,STAINED_CLAY:6)
Block(-3,8,2,STAINED_CLAY:6)
Block(-3,8,3,STAINED_CLAY:6)
Block(-3,9,-2,STAINED_CLAY:6)
Block(-3,9,-1,STAINED_CLAY:6)
Block(-3,9,0,STAINED_CLAY:6)
Block(-3,9,1,STAINED_CLAY:6)
Block(-3,9,2,STAINED_CLAY:6)
Block(-3,9,3,STAINED_CLAY:6)
Block(-3,9,4,STAINED_CLAY:6)
Block(-3,10,-2,STAINED_CLAY:6)
Block(-3,10,-1,STAINED_CLAY:6)
Block(-3,10,0,STAINED_CLAY:6)
Block(-3,10,1,STAINED_CLAY:6)
Block(-3,10,2,STAINED_CLAY:6)
Block(-3,10,3,STAINED_CLAY:6)
Block(-3,10,4,STAINED_CLAY:6)
Block(-3,11,-2,STAINED_CLAY:6)
Block(-3,11,-1,STAINED_CLAY:6)
Block(-3,11,0,STAINED_CLAY:6)
Block(-3,11,1,STAINED_CLAY:6)
Block(-3,11,2,STAINED_CLAY:6)
Block(-3,11,3,STAINED_CLAY:6)
Block(-3,11,4,STAINED_CLAY:6)
Block(-3,12,-2,STAINED_CLAY:6)
Block(-3,12,-1,STAINED_CLAY:6)
Block(-3,12,0,STAINED_CLAY:6)
Block(-3,12,1,STAINED_CLAY:6)
Block(-3,12,2,STAINED_CLAY:6)
Block(-3,12,3,STAINED_CLAY:6)
Block(-3,12,4,STAINED_CLAY:6)
Block(-3,13,-2,STAINED_CLAY:6)
Block(-3,13,-1,STAINED_CLAY:6)
Block(-3,13,0,STAINED_CLAY:6)
Block(-3,13,1,STAINED_CLAY:6)
Block(-3,13,2,STAINED_CLAY:6)
Block(-3,14,-3,STAINED_CLAY:6)
Block(-3,14,-2,STAINED_CLAY:6)
Block(-3,14,-1,STAINED_CLAY:6)
Block(-3,14,0,STAINED_CLAY:6)
Block(-3,14,1,STAINED_CLAY:6)
Block(-3,15,-3,STAINED_CLAY:6)
Block(-3,15,-2,STAINED_CLAY:6)
Block(-3,15,-1,STAINED_CLAY:6)
Block(-3,15,0,STAINED_CLAY:6)
Block(-3,15,1,STAINED_CLAY:6)
Block(-3,16,-3,STAINED_CLAY:6)
Block(-3,16,-2,STAINED_CLAY:6)
Block(-3,16,-1,STAINED_CLAY:6)
Block(-3,16,0,STAINED_CLAY:6)
Block(-3,16,1,STAINED_CLAY:6)
Block(-3,17,-3,STAINED_CLAY:6)
Block(-3,17,-2,STAINED_CLAY:6)
Block(-3,17,-1,STAINED_CLAY:6)
Block(-3,17,0,STAINED_CLAY:6)
Block(-3,17,1,STAINED_CLAY:6)
Block(-3,18,-3,STAINED_CLAY:6)
Block(-3,18,-2,STAINED_CLAY:6)
Block(-3,18,-1,STAINED_CLAY:6)
Block(-3,18,0,STAINED_CLAY:6)
Block(-3,18,1,STAINED_CLAY:6)
Block(-3,19,-3,STAINED_CLAY:6)
Block(-3,19,-2,STAINED_CLAY:6)
Block(-3,19,-1,STAINED_CLAY:6)
Block(-3,19,0,STAINED_CLAY:6)
Block(-3,19,1,STAINED_CLAY:6)
Block(-3,20,-3,STAINED_CLAY:6)
Block(-3,20,-2,STAINED_CLAY:6)
Block(-3,20,-1,STAINED_CLAY:6)
Block(-3,20,0,STAINED_CLAY:6)
Block(-3,20,1,STAINED_CLAY:6)
Block(-3,21,-3,STAINED_CLAY:6)
Block(-3,21,-2,STAINED_CLAY:6)
Block(-3,21,-1,STAINED_CLAY:6)
Block(-3,21,0,STAINED_CLAY:6)
Block(-3,21,1,STAINED_CLAY:6)
Block(-3,22,-3,STAINED_CLAY:6)
Block(-3,22,-2,STAINED_CLAY:6)
Block(-3,22,-1,STAINED_CLAY:6)
Block(-3,22,0,STAINED_CLAY:6)
Block(-3,22,1,STAINED_CLAY:6)
Block(-3,23,-3,STAINED_CLAY:6)
Block(-3,23,-2,STAINED_CLAY:6)
Block(-3,23,-1,STAINED_CLAY:6)
Block(-3,23,0,STAINED_CLAY:6)
Block(-3,23,1,STAINED_CLAY:6)
Block(-3,23,2,STAINED_CLAY:6)
Block(-3,24,-3,STAINED_CLAY:6)
Block(-3,24,-2,STAINED_CLAY:6)
Block(-3,24,-1,STAINED_CLAY:6)
Block(-3,24,0,STAINED_CLAY:6)
Block(-3,24,1,STAINED_CLAY:6)
Block(-3,24,2,STAINED_CLAY:6)
Block(-3,25,-3,STAINED_CLAY:6)
Block(-3,25,-2,STAINED_CLAY:6)
Block(-3,25,-1,STAINED_CLAY:6)
Block(-3,25,0,STAINED_CLAY:6)
Block(-3,25,1,STAINED_CLAY:6)
Block(-3,25,2,STAINED_CLAY:6)
Block(-3,26,-3,STAINED_CLAY:6)
Block(-3,26,-2,STAINED_CLAY:6)
Block(-3,26,-1,STAINED_CLAY:6)
Block(-3,26,0,STAINED_CLAY:6)
Block(-3,26,1,STAINED_CLAY:6)
Block(-3,26,2,STAINED_CLAY:6)
Block(-3,27,-3,STAINED_CLAY:6)
Block(-3,27,-2,STAINED_CLAY:6)
Block(-3,27,-1,STAINED_CLAY:6)
Block(-3,27,0,STAINED_CLAY:6)
Block(-3,27,1,STAINED_CLAY:6)
Block(-3,27,2,STAINED_CLAY:6)
Block(-3,28,-2,STAINED_CLAY:6)
Block(-3,28,-1,STAINED_CLAY:6)
Block(-3,28,0,STAINED_CLAY:6)
Block(-3,28,1,STAINED_CLAY:6)
Block(-3,28,2,STAINED_CLAY:6)
Block(-3,29,-2,STAINED_CLAY:6)
Block(-3,29,-1,STAINED_CLAY:6)
Block(-3,29,0,STAINED_CLAY:6)
Block(-3,29,1,STAINED_CLAY:6)
Block(-3,29,2,STAINED_CLAY:6)
Block(-3,29,3,STAINED_CLAY:6)
Block(-3,29,4,CONCRETE:6)
Block(-3,29,5,CONCRETE:6)
Block(-3,29,6,CONCRETE:6)
Block(-3,30,-2,STAINED_CLAY:6)
Block(-3,30,-1,STAINED_CLAY:6)
Block(-3,30,0,STAINED_CLAY:6)
Block(-3,30,1,STAINED_CLAY:6)
Block(-3,30,2,STAINED_CLAY:6)
Block(-3,30,3,CONCRETE:6)
Block(-3,30,4,CONCRETE:6)
Block(-3,30,5,CONCRETE:6)
Block(-3,30,6,CONCRETE:6)
Block(-3,30,7,CONCRETE:6)
Block(-3,31,-2,STAINED_CLAY:6)
Block(-3,31,-1,STAINED_CLAY:6)
Block(-3,31,0,STAINED_CLAY:6)
Block(-3,31,1,STAINED_CLAY:6)
Block(-3,31,2,CONCRETE:6)
Block(-3,31,3,CONCRETE:6)
Block(-3,31,4,CONCRETE:6)
Block(-3,31,5,CONCRETE:6)
Block(-3,31,6,CONCRETE:6)
Block(-3,31,7,CONCRETE:6)
Block(-3,31,8,CONCRETE:6)
Block(-3,32,-3,CONCRETE:0)
Block(-3,32,-2,CONCRETE:0)
Block(-3,32,-1,CONCRETE:0)
Block(-3,32,0,CONCRETE:0)
Block(-3,32,1,CONCRETE:0)
Block(-3,32,2,CONCRETE:6)
Block(-3,32,3,CONCRETE:6)
Block(-3,32,4,CONCRETE:6)
Block(-3,32,5,CONCRETE:6)
Block(-3,32,6,CONCRETE:6)
Block(-3,32,7,CONCRETE:6)
Block(-3,32,8,CONCRETE:6)
Block(-3,33,-4,CONCRETE:0)
Block(-3,33,-3,CONCRETE:0)
Block(-3,33,-2,CONCRETE:0)
Block(-3,33,-1,CONCRETE:0)
Block(-3,33,0,CONCRETE:0)
Block(-3,33,1,CONCRETE:0)
Block(-3,33,2,CONCRETE:0)
Block(-3,33,3,CONCRETE:6)
Block(-3,33,4,CONCRETE:6)
Block(-3,33,5,CONCRETE:6)
Block(-3,33,6,CONCRETE:6)
Block(-3,33,7,CONCRETE:6)
Block(-3,33,8,CONCRETE:6)
Block(-3,34,-5,CONCRETE:0)
Block(-3,34,-4,CONCRETE:0)
Block(-3,34,-3,CONCRETE:0)
Block(-3,34,-2,CONCRETE:0)
Block(-3,34,-1,CONCRETE:0)
Block(-3,34,0,CONCRETE:0)
Block(-3,34,1,CONCRETE:0)
Block(-3,34,2,CONCRETE:0)
Block(-3,34,3,CONCRETE:0)
Block(-3,34,4,CONCRETE:6)
Block(-3,34,5,CONCRETE:6)
Block(-3,34,6,CONCRETE:6)
Block(-3,34,7,CONCRETE:6)
Block(-3,34,8,CONCRETE:6)
Block(-3,35,-5,CONCRETE:0)
Block(-3,35,-4,CONCRETE:0)
Block(-3,35,-3,CONCRETE:0)
Block(-3,35,-2,CONCRETE:0)
Block(-3,35,-1,CONCRETE:0)
Block(-3,35,0,CONCRETE:0)
Block(-3,35,1,CONCRETE:0)
Block(-3,35,2,CONCRETE:0)
Block(-3,35,3,CONCRETE:0)
Block(-3,35,4,CONCRETE:0)
Block(-3,35,5,CONCRETE:6)
Block(-3,35,6,CONCRETE:6)
Block(-3,35,7,CONCRETE:6)
Block(-3,35,8,CONCRETE:6)
Block(-3,35,9,CONCRETE:6)
Block(-3,36,-6,CONCRETE:0)
Block(-3,36,-5,CONCRETE:0)
Block(-3,36,-4,CONCRETE:0)
Block(-3,36,-3,CONCRETE:0)
Block(-3,36,-2,CONCRETE:0)
Block(-3,36,-1,CONCRETE:0)
Block(-3,36,0,CONCRETE:0)
Block(-3,36,1,CONCRETE:0)
Block(-3,36,2,CONCRETE:0)
Block(-3,36,3,CONCRETE:0)
Block(-3,36,4,CONCRETE:0)
Block(-3,36,5,CONCRETE:0)
Block(-3,36,6,CONCRETE:6)
Block(-3,36,7,CONCRETE:6)
Block(-3,36,8,CONCRETE:6)
Block(-3,36,9,CONCRETE:6)
Block(-3,36,10,CONCRETE:6)
Block(-3,37,-6,CONCRETE:0)
Block(-3,37,-5,CONCRETE:0)
Block(-3,37,-4,CONCRETE:0)
Block(-3,37,-3,CONCRETE:0)
Block(-3,37,-2,CONCRETE:0)
Block(-3,37,-1,CONCRETE:0)
Block(-3,37,0,CONCRETE:0)
Block(-3,37,1,CONCRETE:0)
Block(-3,37,2,CONCRETE:0)
Block(-3,37,3,CONCRETE:0)
Block(-3,37,4,CONCRETE:0)
Block(-3,37,5,CONCRETE:0)
Block(-3,37,6,CONCRETE:0)
Block(-3,37,7,CONCRETE:6)
Block(-3,37,8,CONCRETE:6)
Block(-3,37,9,CONCRETE:6)
Block(-3,37,10,CONCRETE:6)
Block(-3,38,-7,CONCRETE:6)
Block(-3,38,-6,CONCRETE:6)
Block(-3,38,-5,CONCRETE:0)
Block(-3,38,-4,CONCRETE:0)
Block(-3,38,-3,CONCRETE:0)
Block(-3,38,-2,CONCRETE:0)
Block(-3,38,-1,CONCRETE:0)
Block(-3,38,0,CONCRETE:0)
Block(-3,38,1,CONCRETE:0)
Block(-3,38,2,CONCRETE:0)
Block(-3,38,3,CONCRETE:0)
Block(-3,38,4,CONCRETE:0)
Block(-3,38,5,CONCRETE:0)
Block(-3,38,6,CONCRETE:0)
Block(-3,38,7,CONCRETE:0)
Block(-3,38,8,CONCRETE:6)
Block(-3,38,9,CONCRETE:6)
Block(-3,38,10,CONCRETE:6)
Block(-3,39,-8,CONCRETE:6)
Block(-3,39,-7,CONCRETE:6)
Block(-3,39,-6,CONCRETE:6)
Block(-3,39,-5,CONCRETE:6)
Block(-3,39,-4,CONCRETE:0)
Block(-3,39,-3,CONCRETE:0)
Block(-3,39,-2,CONCRETE:0)
Block(-3,39,-1,CONCRETE:0)
Block(-3,39,0,CONCRETE:0)
Block(-3,39,1,CONCRETE:0)
Block(-3,39,2,CONCRETE:0)
Block(-3,39,3,CONCRETE:0)
Block(-3,39,4,CONCRETE:0)
Block(-3,39,5,CONCRETE:0)
Block(-3,39,6,CONCRETE:0)
Block(-3,39,7,CONCRETE:0)
Block(-3,39,8,CONCRETE:6)
Block(-3,39,9,CONCRETE:6)
Block(-3,40,-8,CONCRETE:6)
Block(-3,40,-7,CONCRETE:6)
Block(-3,40,-6,CONCRETE:6)
Block(-3,40,-5,CONCRETE:6)
Block(-3,40,-4,CONCRETE:0)
Block(-3,40,-3,CONCRETE:0)
Block(-3,40,-2,CONCRETE:0)
Block(-3,40,-1,CONCRETE:0)
Block(-3,40,0,CONCRETE:0)
Block(-3,40,1,CONCRETE:0)
Block(-3,40,2,CONCRETE:0)
Block(-3,40,3,CONCRETE:0)
Block(-3,40,4,CONCRETE:0)
Block(-3,40,5,CONCRETE:0)
Block(-3,40,6,CONCRETE:0)
Block(-3,40,7,CONCRETE:0)
Block(-3,40,8,CONCRETE:0)
Block(-3,41,-8,CONCRETE:6)
Block(-3,41,-7,CONCRETE:6)
Block(-3,41,-6,CONCRETE:6)
Block(-3,41,-5,CONCRETE:6)
Block(-3,41,-4,CONCRETE:6)
Block(-3,41,-3,CONCRETE:0)
Block(-3,41,-2,CONCRETE:0)
Block(-3,41,-1,CONCRETE:0)
Block(-3,41,0,CONCRETE:0)
Block(-3,41,1,CONCRETE:0)
Block(-3,41,2,CONCRETE:0)
Block(-3,41,3,CONCRETE:0)
Block(-3,41,4,CONCRETE:0)
Block(-3,41,5,CONCRETE:0)
Block(-3,41,6,CONCRETE:0)
Block(-3,41,7,CONCRETE:0)
Block(-3,41,8,CONCRETE:0)
Block(-3,42,-7,CONCRETE:6)
Block(-3,42,-6,CONCRETE:6)
Block(-3,42,-5,CONCRETE:6)
Block(-3,42,-4,CONCRETE:0)
Block(-3,42,-3,CONCRETE:0)
Block(-3,42,-2,CONCRETE:0)
Block(-3,42,-1,CONCRETE:0)
Block(-3,42,0,CONCRETE:0)
Block(-3,42,1,CONCRETE:0)
Block(-3,42,2,CONCRETE:0)
Block(-3,42,3,CONCRETE:0)
Block(-3,42,4,CONCRETE:0)
Block(-3,42,5,CONCRETE:0)
Block(-3,42,6,CONCRETE:0)
Block(-3,42,7,CONCRETE:0)
Block(-3,42,8,CONCRETE:0)
Block(-3,43,-6,CONCRETE:6)
Block(-3,43,-5,CONCRETE:6)
Block(-3,43,-4,CONCRETE:6)
Block(-3,43,-3,CONCRETE:0)
Block(-3,43,-2,CONCRETE:0)
Block(-3,43,-1,CONCRETE:0)
Block(-3,43,0,CONCRETE:0)
Block(-3,43,1,CONCRETE:0)
Block(-3,43,2,CONCRETE:0)
Block(-3,43,3,CONCRETE:0)
Block(-3,43,4,CONCRETE:0)
Block(-3,43,5,CONCRETE:0)
Block(-3,43,6,CONCRETE:0)
Block(-3,43,7,CONCRETE:0)
Block(-3,43,8,CONCRETE:0)
Block(-3,44,-5,CONCRETE:6)
Block(-3,44,-4,CONCRETE:6)
Block(-3,44,-3,CONCRETE:6)
Block(-3,44,-2,CONCRETE:6)
Block(-3,44,-1,CONCRETE:6)
Block(-3,44,0,CONCRETE:6)
Block(-3,44,1,CONCRETE:0)
Block(-3,44,2,CONCRETE:0)
Block(-3,44,3,CONCRETE:0)
Block(-3,44,4,CONCRETE:0)
Block(-3,44,5,CONCRETE:0)
Block(-3,44,6,CONCRETE:0)
Block(-3,44,7,CONCRETE:0)
Block(-3,45,-5,CONCRETE:6)
Block(-3,45,-4,CONCRETE:6)
Block(-3,45,-3,CONCRETE:6)
Block(-3,45,-2,CONCRETE:6)
Block(-3,45,-1,CONCRETE:6)
Block(-3,45,0,CONCRETE:6)
Block(-3,45,1,CONCRETE:6)
Block(-3,45,2,CONCRETE:0)
Block(-3,45,3,CONCRETE:0)
Block(-3,45,4,CONCRETE:0)
Block(-3,45,5,CONCRETE:0)
Block(-3,45,6,CONCRETE:0)
Block(-3,46,-4,CONCRETE:6)
Block(-3,46,-3,CONCRETE:6)
Block(-3,46,-2,CONCRETE:6)
Block(-3,46,-1,CONCRETE:6)
Block(-3,46,0,CONCRETE:6)
Block(-3,46,1,CONCRETE:6)
Block(-3,46,2,CONCRETE:6)
Block(-3,46,3,CONCRETE:0)
Block(-3,46,4,CONCRETE:0)
Block(-3,46,5,CONCRETE:0)
Block(-3,47,-3,CONCRETE:6)
Block(-3,47,-2,CONCRETE:6)
Block(-3,47,-1,CONCRETE:6)
Block(-3,47,0,CONCRETE:6)
Block(-3,47,1,CONCRETE:6)
Block(-3,47,2,CONCRETE:6)
Block(-3,48,-3,CONCRETE:6)
Block(-3,48,-2,CONCRETE:6)
Block(-3,48,-1,CONCRETE:6)
Block(-3,48,0,CONCRETE:6)
Block(-3,48,1,CONCRETE:6)
Block(-3,49,-1,CONCRETE:6)
Block(-3,49,0,CONCRETE:6)
Block(-2,0,-4,STAINED_CLAY:6)
Block(-2,0,-3,STAINED_CLAY:6)
Block(-2,0,-2,STAINED_CLAY:6)
Block(-2,0,-1,STAINED_CLAY:6)
Block(-2,0,0,STAINED_CLAY:6)
Block(-2,0,1,STAINED_CLAY:6)
Block(-2,0,2,STAINED_CLAY:6)
Block(-2,1,-3,STAINED_CLAY:6)
Block(-2,1,-2,STAINED_CLAY:6)
Block(-2,1,-1,STAINED_CLAY:6)
Block(-2,1,0,STAINED_CLAY:6)
Block(-2,1,1,STAINED_CLAY:6)
Block(-2,2,-3,STAINED_CLAY:6)
Block(-2,2,-2,STAINED_CLAY:6)
Block(-2,2,-1,STAINED_CLAY:6)
Block(-2,2,0,STAINED_CLAY:6)
Block(-2,2,1,STAINED_CLAY:6)
Block(-2,3,-3,STAINED_CLAY:6)
Block(-2,3,-2,STAINED_CLAY:6)
Block(-2,3,-1,STAINED_CLAY:6)
Block(-2,3,0,STAINED_CLAY:6)
Block(-2,3,1,STAINED_CLAY:6)
Block(-2,4,-4,STAINED_CLAY:6)
Block(-2,4,-3,STAINED_CLAY:6)
Block(-2,4,-2,STAINED_CLAY:6)
Block(-2,4,-1,STAINED_CLAY:6)
Block(-2,4,0,STAINED_CLAY:6)
Block(-2,4,1,STAINED_CLAY:6)
Block(-2,4,2,STAINED_CLAY:6)
Block(-2,5,-4,STAINED_CLAY:6)
Block(-2,5,-3,STAINED_CLAY:6)
Block(-2,5,-2,STAINED_CLAY:6)
Block(-2,5,-1,STAINED_CLAY:6)
Block(-2,5,0,STAINED_CLAY:6)
Block(-2,5,1,STAINED_CLAY:6)
Block(-2,5,2,STAINED_CLAY:6)
Block(-2,6,-3,STAINED_CLAY:6)
Block(-2,6,-2,STAINED_CLAY:6)
Block(-2,6,-1,STAINED_CLAY:6)
Block(-2,6,0,STAINED_CLAY:6)
Block(-2,6,1,STAINED_CLAY:6)
Block(-2,6,2,STAINED_CLAY:6)
Block(-2,7,-3,STAINED_CLAY:6)
Block(-2,7,-2,STAINED_CLAY:6)
Block(-2,7,-1,STAINED_CLAY:6)
Block(-2,7,0,STAINED_CLAY:6)
Block(-2,7,1,STAINED_CLAY:6)
Block(-2,7,2,STAINED_CLAY:6)
Block(-2,7,3,STAINED_CLAY:6)
Block(-2,8,-2,STAINED_CLAY:6)
Block(-2,8,-1,STAINED_CLAY:6)
Block(-2,8,0,STAINED_CLAY:6)
Block(-2,8,1,STAINED_CLAY:6)
Block(-2,8,2,STAINED_CLAY:6)
Block(-2,8,3,STAINED_CLAY:6)
Block(-2,9,-2,STAINED_CLAY:6)
Block(-2,9,-1,STAINED_CLAY:6)
Block(-2,9,0,STAINED_CLAY:6)
Block(-2,9,1,STAINED_CLAY:6)
Block(-2,9,2,STAINED_CLAY:6)
Block(-2,9,3,STAINED_CLAY:6)
Block(-2,9,4,STAINED_CLAY:6)
Block(-2,10,-2,STAINED_CLAY:6)
Block(-2,10,-1,STAINED_CLAY:6)
Block(-2,10,0,STAINED_CLAY:6)
Block(-2,10,1,STAINED_CLAY:6)
Block(-2,10,2,STAINED_CLAY:6)
Block(-2,10,3,STAINED_CLAY:6)
Block(-2,10,4,STAINED_CLAY:6)
Block(-2,10,5,STAINED_CLAY:6)
Block(-2,11,-2,STAINED_CLAY:6)
Block(-2,11,-1,STAINED_CLAY:6)
Block(-2,11,0,STAINED_CLAY:6)
Block(-2,11,1,STAINED_CLAY:6)
Block(-2,11,2,STAINED_CLAY:6)
Block(-2,11,3,STAINED_CLAY:6)
Block(-2,11,4,STAINED_CLAY:6)
Block(-2,11,5,STAINED_CLAY:6)
Block(-2,12,-2,STAINED_CLAY:6)
Block(-2,12,-1,STAINED_CLAY:6)
Block(-2,12,0,STAINED_CLAY:6)
Block(-2,12,1,STAINED_CLAY:6)
Block(-2,12,2,STAINED_CLAY:6)
Block(-2,12,3,STAINED_CLAY:6)
Block(-2,12,4,STAINED_CLAY:6)
Block(-2,12,5,STAINED_CLAY:6)
Block(-2,12,6,STAINED_CLAY:6)
Block(-2,13,-3,STAINED_CLAY:6)
Block(-2,13,-2,STAINED_CLAY:6)
Block(-2,13,-1,STAINED_CLAY:6)
Block(-2,13,0,STAINED_CLAY:6)
Block(-2,13,1,STAINED_CLAY:6)
Block(-2,13,2,STAINED_CLAY:6)
Block(-2,13,3,STAINED_CLAY:6)
Block(-2,13,4,STAINED_CLAY:6)
Block(-2,14,-3,STAINED_CLAY:6)
Block(-2,14,-2,STAINED_CLAY:6)
Block(-2,14,-1,STAINED_CLAY:6)
Block(-2,14,0,STAINED_CLAY:6)
Block(-2,14,1,STAINED_CLAY:6)
Block(-2,14,2,STAINED_CLAY:6)
Block(-2,15,-3,STAINED_CLAY:6)
Block(-2,15,-2,STAINED_CLAY:6)
Block(-2,15,-1,STAINED_CLAY:6)
Block(-2,15,0,STAINED_CLAY:6)
Block(-2,15,1,STAINED_CLAY:6)
Block(-2,15,2,STAINED_CLAY:6)
Block(-2,16,-4,STAINED_CLAY:6)
Block(-2,16,-3,STAINED_CLAY:6)
Block(-2,16,-2,STAINED_CLAY:6)
Block(-2,16,-1,STAINED_CLAY:6)
Block(-2,16,0,STAINED_CLAY:6)
Block(-2,16,1,STAINED_CLAY:6)
Block(-2,16,2,STAINED_CLAY:6)
Block(-2,17,-4,STAINED_CLAY:6)
Block(-2,17,-3,STAINED_CLAY:6)
Block(-2,17,-2,STAINED_CLAY:6)
Block(-2,17,-1,STAINED_CLAY:6)
Block(-2,17,0,STAINED_CLAY:6)
Block(-2,17,1,STAINED_CLAY:6)
Block(-2,17,2,STAINED_CLAY:6)
Block(-2,18,-4,STAINED_CLAY:6)
Block(-2,18,-3,STAINED_CLAY:6)
Block(-2,18,-2,STAINED_CLAY:6)
Block(-2,18,-1,STAINED_CLAY:6)
Block(-2,18,0,STAINED_CLAY:6)
Block(-2,18,1,STAINED_CLAY:6)
Block(-2,18,2,STAINED_CLAY:6)
Block(-2,19,-4,STAINED_CLAY:6)
Block(-2,19,-3,STAINED_CLAY:6)
Block(-2,19,-2,STAINED_CLAY:6)
Block(-2,19,-1,STAINED_CLAY:6)
Block(-2,19,0,STAINED_CLAY:6)
Block(-2,19,1,STAINED_CLAY:6)
Block(-2,19,2,STAINED_CLAY:6)
Block(-2,20,-3,STAINED_CLAY:6)
Block(-2,20,-2,STAINED_CLAY:6)
Block(-2,20,-1,STAINED_CLAY:6)
Block(-2,20,0,STAINED_CLAY:6)
Block(-2,20,1,STAINED_CLAY:6)
Block(-2,20,2,STAINED_CLAY:6)
Block(-2,21,-3,STAINED_CLAY:6)
Block(-2,21,-2,STAINED_CLAY:6)
Block(-2,21,-1,STAINED_CLAY:6)
Block(-2,21,0,STAINED_CLAY:6)
Block(-2,21,1,STAINED_CLAY:6)
Block(-2,21,2,STAINED_CLAY:6)
Block(-2,22,-3,STAINED_CLAY:6)
Block(-2,22,-2,STAINED_CLAY:6)
Block(-2,22,-1,STAINED_CLAY:6)
Block(-2,22,0,STAINED_CLAY:6)
Block(-2,22,1,STAINED_CLAY:6)
Block(-2,22,2,STAINED_CLAY:6)
Block(-2,23,-3,STAINED_CLAY:6)
Block(-2,23,-2,STAINED_CLAY:6)
Block(-2,23,-1,STAINED_CLAY:6)
Block(-2,23,0,STAINED_CLAY:6)
Block(-2,23,1,STAINED_CLAY:6)
Block(-2,23,2,STAINED_CLAY:6)
Block(-2,24,-3,STAINED_CLAY:6)
Block(-2,24,-2,STAINED_CLAY:6)
Block(-2,24,-1,STAINED_CLAY:6)
Block(-2,24,0,STAINED_CLAY:6)
Block(-2,24,1,STAINED_CLAY:6)
Block(-2,24,2,STAINED_CLAY:6)
Block(-2,25,-2,STAINED_CLAY:6)
Block(-2,25,-1,STAINED_CLAY:6)
Block(-2,25,0,STAINED_CLAY:6)
Block(-2,25,1,STAINED_CLAY:6)
Block(-2,25,2,STAINED_CLAY:6)
Block(-2,26,-2,STAINED_CLAY:6)
Block(-2,26,-1,STAINED_CLAY:6)
Block(-2,26,0,STAINED_CLAY:6)
Block(-2,26,1,STAINED_CLAY:6)
Block(-2,26,2,STAINED_CLAY:6)
Block(-2,27,-2,STAINED_CLAY:6)
Block(-2,27,-1,STAINED_CLAY:6)
Block(-2,27,0,STAINED_CLAY:6)
Block(-2,27,1,STAINED_CLAY:6)
Block(-2,27,2,STAINED_CLAY:6)
Block(-2,28,-2,STAINED_CLAY:6)
Block(-2,28,-1,STAINED_CLAY:6)
Block(-2,28,0,STAINED_CLAY:6)
Block(-2,28,1,STAINED_CLAY:6)
Block(-2,28,2,STAINED_CLAY:6)
Block(-2,29,-2,STAINED_CLAY:6)
Block(-2,29,-1,STAINED_CLAY:6)
Block(-2,29,0,STAINED_CLAY:6)
Block(-2,29,1,STAINED_CLAY:6)
Block(-2,29,2,STAINED_CLAY:6)
Block(-2,29,4,CONCRETE:6)
Block(-2,29,5,CONCRETE:6)
Block(-2,30,-2,STAINED_CLAY:6)
Block(-2,30,-1,STAINED_CLAY:6)
Block(-2,30,0,STAINED_CLAY:6)
Block(-2,30,1,STAINED_CLAY:6)
Block(-2,30,2,STAINED_CLAY:6)
Block(-2,30,3,CONCRETE:6)
Block(-2,30,4,CONCRETE:6)
Block(-2,30,5,CONCRETE:6)
Block(-2,30,6,CONCRETE:6)
Block(-2,30,7,CONCRETE:6)
Block(-2,31,-2,CONCRETE:0)
Block(-2,31,-1,CONCRETE:0)
Block(-2,31,0,CONCRETE:0)
Block(-2,31,1,CONCRETE:0)
Block(-2,31,2,CONCRETE:6)
Block(-2,31,3,CONCRETE:6)
Block(-2,31,4,CONCRETE:6)
Block(-2,31,5,CONCRETE:6)
Block(-2,31,6,CONCRETE:6)
Block(-2,31,7,CONCRETE:6)
Block(-2,32,-3,CONCRETE:0)
Block(-2,32,-2,CONCRETE:0)
Block(-2,32,-1,CONCRETE:0)
Block(-2,32,0,CONCRETE:0)
Block(-2,32,1,CONCRETE:0)
Block(-2,32,2,CONCRETE:0)
Block(-2,32,3,CONCRETE:6)
Block(-2,32,4,CONCRETE:6)
Block(-2,32,5,CONCRETE:6)
Block(-2,32,6,CONCRETE:6)
Block(-2,32,7,CONCRETE:6)
Block(-2,32,8,CONCRETE:6)
Block(-2,33,-4,CONCRETE:0)
Block(-2,33,-3,CONCRETE:0)
Block(-2,33,-2,CONCRETE:0)
Block(-2,33,-1,CONCRETE:0)
Block(-2,33,0,CONCRETE:0)
Block(-2,33,1,CONCRETE:0)
Block(-2,33,2,CONCRETE:0)
Block(-2,33,3,CONCRETE:6)
Block(-2,33,4,CONCRETE:6)
Block(-2,33,5,CONCRETE:6)
Block(-2,33,6,CONCRETE:6)
Block(-2,33,7,CONCRETE:6)
Block(-2,33,8,CONCRETE:6)
Block(-2,34,-5,CONCRETE:0)
Block(-2,34,-4,CONCRETE:0)
Block(-2,34,-3,CONCRETE:0)
Block(-2,34,-2,CONCRETE:0)
Block(-2,34,-1,CONCRETE:0)
Block(-2,34,0,CONCRETE:0)
Block(-2,34,1,CONCRETE:0)
Block(-2,34,2,CONCRETE:0)
Block(-2,34,3,CONCRETE:0)
Block(-2,34,4,CONCRETE:6)
Block(-2,34,5,CONCRETE:6)
Block(-2,34,6,CONCRETE:6)
Block(-2,34,7,CONCRETE:6)
Block(-2,34,8,CONCRETE:6)
Block(-2,34,9,CONCRETE:6)
Block(-2,35,-6,CONCRETE:0)
Block(-2,35,-5,CONCRETE:0)
Block(-2,35,-4,CONCRETE:0)
Block(-2,35,-3,CONCRETE:0)
Block(-2,35,-2,CONCRETE:0)
Block(-2,35,-1,CONCRETE:0)
Block(-2,35,0,CONCRETE:0)
Block(-2,35,1,CONCRETE:0)
Block(-2,35,2,CONCRETE:0)
Block(-2,35,3,CONCRETE:0)
Block(-2,35,4,CONCRETE:0)
Block(-2,35,5,CONCRETE:6)
Block(-2,35,6,CONCRETE:6)
Block(-2,35,7,CONCRETE:6)
Block(-2,35,8,CONCRETE:6)
Block(-2,35,9,CONCRETE:6)
Block(-2,35,10,CONCRETE:6)
Block(-2,36,-6,CONCRETE:0)
Block(-2,36,-5,CONCRETE:0)
Block(-2,36,-4,CONCRETE:0)
Block(-2,36,-3,CONCRETE:0)
Block(-2,36,-2,CONCRETE:0)
Block(-2,36,-1,CONCRETE:0)
Block(-2,36,0,CONCRETE:0)
Block(-2,36,1,CONCRETE:0)
Block(-2,36,2,CONCRETE:0)
Block(-2,36,3,CONCRETE:0)
Block(-2,36,4,CONCRETE:0)
Block(-2,36,5,CONCRETE:0)
Block(-2,36,6,CONCRETE:6)
Block(-2,36,7,CONCRETE:6)
Block(-2,36,8,CONCRETE:6)
Block(-2,36,9,CONCRETE:6)
Block(-2,36,10,CONCRETE:6)
Block(-2,36,11,CONCRETE:6)
Block(-2,37,-6,CONCRETE:0)
Block(-2,37,-5,CONCRETE:0)
Block(-2,37,-4,CONCRETE:0)
Block(-2,37,-3,CONCRETE:0)
Block(-2,37,-2,CONCRETE:0)
Block(-2,37,-1,CONCRETE:0)
Block(-2,37,0,CONCRETE:0)
Block(-2,37,1,CONCRETE:0)
Block(-2,37,2,CONCRETE:0)
Block(-2,37,3,CONCRETE:0)
Block(-2,37,4,CONCRETE:0)
Block(-2,37,5,CONCRETE:0)
Block(-2,37,6,CONCRETE:0)
Block(-2,37,7,CONCRETE:6)
Block(-2,37,8,CONCRETE:6)
Block(-2,37,9,CONCRETE:6)
Block(-2,37,10,CONCRETE:6)
Block(-2,37,11,CONCRETE:6)
Block(-2,38,-7,CONCRETE:0)
Block(-2,38,-6,CONCRETE:0)
Block(-2,38,-5,CONCRETE:0)
Block(-2,38,-4,CONCRETE:0)
Block(-2,38,-3,CONCRETE:0)
Block(-2,38,-2,CONCRETE:0)
Block(-2,38,-1,CONCRETE:0)
Block(-2,38,0,CONCRETE:0)
Block(-2,38,1,CONCRETE:0)
Block(-2,38,2,CONCRETE:0)
Block(-2,38,3,CONCRETE:0)
Block(-2,38,4,CONCRETE:0)
Block(-2,38,5,CONCRETE:0)
Block(-2,38,6,CONCRETE:0)
Block(-2,38,7,CONCRETE:6)
Block(-2,38,8,CONCRETE:6)
Block(-2,38,9,CONCRETE:6)
Block(-2,38,10,CONCRETE:6)
Block(-2,38,11,CONCRETE:6)
Block(-2,39,-7,CONCRETE:6)
Block(-2,39,-6,CONCRETE:6)
Block(-2,39,-5,CONCRETE:0)
Block(-2,39,-4,CONCRETE:0)
Block(-2,39,-3,CONCRETE:0)
Block(-2,39,-2,CONCRETE:0)
Block(-2,39,-1,CONCRETE:0)
Block(-2,39,0,CONCRETE:0)
Block(-2,39,1,CONCRETE:0)
Block(-2,39,2,CONCRETE:0)
Block(-2,39,3,CONCRETE:0)
Block(-2,39,4,CONCRETE:0)
Block(-2,39,5,CONCRETE:0)
Block(-2,39,6,CONCRETE:0)
Block(-2,39,7,CONCRETE:0)
Block(-2,39,8,CONCRETE:6)
Block(-2,39,9,CONCRETE:6)
Block(-2,39,10,CONCRETE:6)
Block(-2,40,-7,CONCRETE:6)
Block(-2,40,-6,CONCRETE:6)
Block(-2,40,-5,CONCRETE:6)
Block(-2,40,-4,CONCRETE:0)
Block(-2,40,-3,CONCRETE:0)
Block(-2,40,-2,CONCRETE:0)
Block(-2,40,-1,CONCRETE:0)
Block(-2,40,0,CONCRETE:0)
Block(-2,40,1,CONCRETE:0)
Block(-2,40,2,CONCRETE:0)
Block(-2,40,3,CONCRETE:0)
Block(-2,40,4,CONCRETE:0)
Block(-2,40,5,CONCRETE:0)
Block(-2,40,6,CONCRETE:0)
Block(-2,40,7,CONCRETE:0)
Block(-2,40,8,CONCRETE:6)
Block(-2,40,9,CONCRETE:6)
Block(-2,41,-7,CONCRETE:6)
Block(-2,41,-6,CONCRETE:6)
Block(-2,41,-5,CONCRETE:6)
Block(-2,41,-4,CONCRETE:0)
Block(-2,41,-3,CONCRETE:0)
Block(-2,41,-2,CONCRETE:0)
Block(-2,41,-1,CONCRETE:0)
Block(-2,41,0,CONCRETE:0)
Block(-2,41,1,CONCRETE:0)
Block(-2,41,2,CONCRETE:0)
Block(-2,41,3,CONCRETE:0)
Block(-2,41,4,CONCRETE:0)
Block(-2,41,5,CONCRETE:0)
Block(-2,41,6,CONCRETE:0)
Block(-2,41,7,CONCRETE:0)
Block(-2,41,8,CONCRETE:0)
Block(-2,42,-7,CONCRETE:6)
Block(-2,42,-6,CONCRETE:6)
Block(-2,42,-5,CONCRETE:6)
Block(-2,42,-4,CONCRETE:6)
Block(-2,42,-3,CONCRETE:0)
Block(-2,42,-2,CONCRETE:0)
Block(-2,42,-1,CONCRETE:0)
Block(-2,42,0,CONCRETE:0)
Block(-2,42,1,CONCRETE:0)
Block(-2,42,2,CONCRETE:0)
Block(-2,42,3,CONCRETE:0)
Block(-2,42,4,CONCRETE:0)
Block(-2,42,5,CONCRETE:0)
Block(-2,42,6,CONCRETE:0)
Block(-2,42,7,CONCRETE:0)
Block(-2,42,8,CONCRETE:0)
Block(-2,43,-6,CONCRETE:6)
Block(-2,43,-5,CONCRETE:6)
Block(-2,43,-4,CONCRETE:6)
Block(-2,43,-3,CONCRETE:6)
Block(-2,43,-2,CONCRETE:0)
Block(-2,43,-1,CONCRETE:0)
Block(-2,43,0,CONCRETE:0)
Block(-2,43,1,CONCRETE:0)
Block(-2,43,2,CONCRETE:0)
Block(-2,43,3,CONCRETE:0)
Block(-2,43,4,CONCRETE:0)
Block(-2,43,5,CONCRETE:0)
Block(-2,43,6,CONCRETE:0)
Block(-2,43,7,CONCRETE:0)
Block(-2,43,8,CONCRETE:0)
Block(-2,44,-6,CONCRETE:6)
Block(-2,44,-5,CONCRETE:6)
Block(-2,44,-4,CONCRETE:6)
Block(-2,44,-3,CONCRETE:6)
Block(-2,44,-2,CONCRETE:6)
Block(-2,44,-1,CONCRETE:6)
Block(-2,44,0,CONCRETE:6)
Block(-2,44,1,CONCRETE:0)
Block(-2,44,2,CONCRETE:0)
Block(-2,44,3,CONCRETE:0)
Block(-2,44,4,CONCRETE:0)
Block(-2,44,5,CONCRETE:0)
Block(-2,44,6,CONCRETE:0)
Block(-2,44,7,CONCRETE:0)
Block(-2,45,-5,CONCRETE:6)
Block(-2,45,-4,CONCRETE:6)
Block(-2,45,-3,CONCRETE:6)
Block(-2,45,-2,CONCRETE:6)
Block(-2,45,-1,CONCRETE:6)
Block(-2,45,0,CONCRETE:6)
Block(-2,45,1,CONCRETE:6)
Block(-2,45,2,CONCRETE:0)
Block(-2,45,3,CONCRETE:0)
Block(-2,45,4,CONCRETE:0)
Block(-2,45,5,CONCRETE:0)
Block(-2,45,6,CONCRETE:0)
Block(-2,46,-4,CONCRETE:6)
Block(-2,46,-3,CONCRETE:6)
Block(-2,46,-2,CONCRETE:6)
Block(-2,46,-1,CONCRETE:6)
Block(-2,46,0,CONCRETE:6)
Block(-2,46,1,CONCRETE:6)
Block(-2,46,2,CONCRETE:6)
Block(-2,46,3,CONCRETE:0)
Block(-2,46,4,CONCRETE:0)
Block(-2,46,5,CONCRETE:0)
Block(-2,47,-3,CONCRETE:6)
Block(-2,47,-2,CONCRETE:6)
Block(-2,47,-1,CONCRETE:6)
Block(-2,47,0,CONCRETE:6)
Block(-2,47,1,CONCRETE:6)
Block(-2,47,2,CONCRETE:6)
Block(-2,48,-2,CONCRETE:6)
Block(-2,48,-1,CONCRETE:6)
Block(-2,48,0,CONCRETE:6)
Block(-2,48,1,CONCRETE:6)
Block(-2,49,-1,CONCRETE:6)
Block(-2,49,0,CONCRETE:6)
Block(-1,0,-3,STAINED_CLAY:6)
Block(-1,0,-2,STAINED_CLAY:6)
Block(-1,0,-1,STAINED_CLAY:6)
Block(-1,0,0,STAINED_CLAY:6)
Block(-1,0,1,STAINED_CLAY:6)
Block(-1,1,-2,STAINED_CLAY:6)
Block(-1,1,-1,STAINED_CLAY:6)
Block(-1,1,0,STAINED_CLAY:6)
Block(-1,1,1,STAINED_CLAY:6)
Block(-1,2,-2,STAINED_CLAY:6)
Block(-1,2,-1,STAINED_CLAY:6)
Block(-1,2,0,STAINED_CLAY:6)
Block(-1,3,-3,STAINED_CLAY:6)
Block(-1,3,-2,STAINED_CLAY:6)
Block(-1,3,-1,STAINED_CLAY:6)
Block(-1,3,0,STAINED_CLAY:6)
Block(-1,4,-3,STAINED_CLAY:6)
Block(-1,4,-2,STAINED_CLAY:6)
Block(-1,4,-1,STAINED_CLAY:6)
Block(-1,4,0,STAINED_CLAY:6)
Block(-1,4,1,STAINED_CLAY:6)
Block(-1,5,-3,STAINED_CLAY:6)
Block(-1,5,-2,STAINED_CLAY:6)
Block(-1,5,-1,STAINED_CLAY:6)
Block(-1,5,0,STAINED_CLAY:6)
Block(-1,5,1,STAINED_CLAY:6)
Block(-1,6,-3,STAINED_CLAY:6)
Block(-1,6,-2,STAINED_CLAY:6)
Block(-1,6,-1,STAINED_CLAY:6)
Block(-1,6,0,STAINED_CLAY:6)
Block(-1,6,1,STAINED_CLAY:6)
Block(-1,6,2,STAINED_CLAY:6)
Block(-1,7,-2,STAINED_CLAY:6)
Block(-1,7,-1,STAINED_CLAY:6)
Block(-1,7,0,STAINED_CLAY:6)
Block(-1,7,1,STAINED_CLAY:6)
Block(-1,7,2,STAINED_CLAY:6)
Block(-1,8,-2,STAINED_CLAY:6)
Block(-1,8,-1,STAINED_CLAY:6)
Block(-1,8,0,STAINED_CLAY:6)
Block(-1,8,1,STAINED_CLAY:6)
Block(-1,8,2,STAINED_CLAY:6)
Block(-1,8,3,STAINED_CLAY:6)
Block(-1,9,-2,STAINED_CLAY:6)
Block(-1,9,-1,STAINED_CLAY:6)
Block(-1,9,0,STAINED_CLAY:6)
Block(-1,9,1,STAINED_CLAY:6)
Block(-1,9,2,STAINED_CLAY:6)
Block(-1,9,3,STAINED_CLAY:6)
Block(-1,9,4,STAINED_CLAY:6)
Block(-1,10,-2,STAINED_CLAY:6)
Block(-1,10,-1,STAINED_CLAY:6)
Block(-1,10,0,STAINED_CLAY:6)
Block(-1,10,1,STAINED_CLAY:6)
Block(-1,10,2,STAINED_CLAY:6)
Block(-1,10,3,STAINED_CLAY:6)
Block(-1,10,4,STAINED_CLAY:6)
Block(-1,11,-2,STAINED_CLAY:6)
Block(-1,11,-1,STAINED_CLAY:6)
Block(-1,11,0,STAINED_CLAY:6)
Block(-1,11,1,STAINED_CLAY:6)
Block(-1,11,2,STAINED_CLAY:6)
Block(-1,11,3,STAINED_CLAY:6)
Block(-1,11,4,STAINED_CLAY:6)
Block(-1,11,5,STAINED_CLAY:6)
Block(-1,11,6,STAINED_CLAY:6)
Block(-1,12,-2,STAINED_CLAY:6)
Block(-1,12,-1,STAINED_CLAY:6)
Block(-1,12,0,STAINED_CLAY:6)
Block(-1,12,1,STAINED_CLAY:6)
Block(-1,12,2,STAINED_CLAY:6)
Block(-1,12,3,STAINED_CLAY:6)
Block(-1,12,4,STAINED_CLAY:6)
Block(-1,12,5,STAINED_CLAY:6)
Block(-1,12,6,STAINED_CLAY:6)
Block(-1,13,-3,STAINED_CLAY:6)
Block(-1,13,-2,STAINED_CLAY:6)
Block(-1,13,-1,STAINED_CLAY:6)
Block(-1,13,0,STAINED_CLAY:6)
Block(-1,13,1,STAINED_CLAY:6)
Block(-1,13,2,STAINED_CLAY:6)
Block(-1,13,3,STAINED_CLAY:6)
Block(-1,13,5,STAINED_CLAY:6)
Block(-1,13,6,STAINED_CLAY:6)
Block(-1,13,7,STAINED_CLAY:6)
Block(-1,14,-3,STAINED_CLAY:6)
Block(-1,14,-2,STAINED_CLAY:6)
Block(-1,14,-1,STAINED_CLAY:6)
Block(-1,14,0,STAINED_CLAY:6)
Block(-1,14,1,STAINED_CLAY:6)
Block(-1,14,2,STAINED_CLAY:6)
Block(-1,14,7,STAINED_CLAY:6)
Block(-1,15,-4,STAINED_CLAY:6)
Block(-1,15,-3,STAINED_CLAY:6)
Block(-1,15,-2,STAINED_CLAY:6)
Block(-1,15,-1,STAINED_CLAY:6)
Block(-1,15,0,STAINED_CLAY:6)
Block(-1,15,1,STAINED_CLAY:6)
Block(-1,15,2,STAINED_CLAY:6)
Block(-1,16,-4,STAINED_CLAY:6)
Block(-1,16,-3,STAINED_CLAY:6)
Block(-1,16,-2,STAINED_CLAY:6)
Block(-1,16,-1,STAINED_CLAY:6)
Block(-1,16,0,STAINED_CLAY:6)
Block(-1,16,1,STAINED_CLAY:6)
Block(-1,16,2,STAINED_CLAY:6)
Block(-1,17,-5,STAINED_CLAY:6)
Block(-1,17,-4,STAINED_CLAY:6)
Block(-1,17,-3,STAINED_CLAY:6)
Block(-1,17,-2,STAINED_CLAY:6)
Block(-1,17,-1,STAINED_CLAY:6)
Block(-1,17,0,STAINED_CLAY:6)
Block(-1,17,1,STAINED_CLAY:6)
Block(-1,17,2,STAINED_CLAY:6)
Block(-1,18,-5,STAINED_CLAY:6)
Block(-1,18,-4,STAINED_CLAY:6)
Block(-1,18,-3,STAINED_CLAY:6)
Block(-1,18,-2,STAINED_CLAY:6)
Block(-1,18,-1,STAINED_CLAY:6)
Block(-1,18,0,STAINED_CLAY:6)
Block(-1,18,1,STAINED_CLAY:6)
Block(-1,18,2,STAINED_CLAY:6)
Block(-1,19,-4,STAINED_CLAY:6)
Block(-1,19,-3,STAINED_CLAY:6)
Block(-1,19,-2,STAINED_CLAY:6)
Block(-1,19,-1,STAINED_CLAY:6)
Block(-1,19,0,STAINED_CLAY:6)
Block(-1,19,1,STAINED_CLAY:6)
Block(-1,19,2,STAINED_CLAY:6)
Block(-1,20,-4,STAINED_CLAY:6)
Block(-1,20,-3,STAINED_CLAY:6)
Block(-1,20,-2,STAINED_CLAY:6)
Block(-1,20,-1,STAINED_CLAY:6)
Block(-1,20,0,STAINED_CLAY:6)
Block(-1,20,1,STAINED_CLAY:6)
Block(-1,20,2,STAINED_CLAY:6)
Block(-1,21,-3,STAINED_CLAY:6)
Block(-1,21,-2,STAINED_CLAY:6)
Block(-1,21,-1,STAINED_CLAY:6)
Block(-1,21,0,STAINED_CLAY:6)
Block(-1,21,1,STAINED_CLAY:6)
Block(-1,21,2,STAINED_CLAY:6)
Block(-1,22,-3,STAINED_CLAY:6)
Block(-1,22,-2,STAINED_CLAY:6)
Block(-1,22,-1,STAINED_CLAY:6)
Block(-1,22,0,STAINED_CLAY:6)
Block(-1,22,1,STAINED_CLAY:6)
Block(-1,22,2,STAINED_CLAY:6)
Block(-1,23,-3,STAINED_CLAY:6)
Block(-1,23,-2,STAINED_CLAY:6)
Block(-1,23,-1,STAINED_CLAY:6)
Block(-1,23,0,STAINED_CLAY:6)
Block(-1,23,1,STAINED_CLAY:6)
Block(-1,23,2,STAINED_CLAY:6)
Block(-1,24,-2,STAINED_CLAY:6)
Block(-1,24,-1,STAINED_CLAY:6)
Block(-1,24,0,STAINED_CLAY:6)
Block(-1,24,1,STAINED_CLAY:6)
Block(-1,25,-1,STAINED_CLAY:6)
Block(-1,25,0,STAINED_CLAY:6)
Block(-1,25,1,STAINED_CLAY:6)
Block(-1,26,-1,STAINED_CLAY:6)
Block(-1,26,0,STAINED_CLAY:6)
Block(-1,26,1,STAINED_CLAY:6)
Block(-1,27,-1,STAINED_CLAY:6)
Block(-1,27,0,STAINED_CLAY:6)
Block(-1,27,1,STAINED_CLAY:6)
Block(-1,28,-1,STAINED_CLAY:6)
Block(-1,28,0,STAINED_CLAY:6)
Block(-1,28,1,STAINED_CLAY:6)
Block(-1,29,-1,STAINED_CLAY:6)
Block(-1,29,0,STAINED_CLAY:6)
Block(-1,29,1,STAINED_CLAY:6)
Block(-1,30,-1,STAINED_CLAY:6)
Block(-1,30,0,STAINED_CLAY:6)
Block(-1,30,1,STAINED_CLAY:6)
Block(-1,30,3,CONCRETE:6)
Block(-1,30,4,CONCRETE:6)
Block(-1,30,5,CONCRETE:6)
Block(-1,30,6,CONCRETE:6)
Block(-1,31,-2,CONCRETE:0)
Block(-1,31,-1,CONCRETE:0)
Block(-1,31,0,CONCRETE:0)
Block(-1,31,1,CONCRETE:0)
Block(-1,31,2,CONCRETE:0)
Block(-1,31,3,CONCRETE:6)
Block(-1,31,4,CONCRETE:6)
Block(-1,31,5,CONCRETE:6)
Block(-1,31,6,CONCRETE:6)
Block(-1,32,-3,CONCRETE:0)
Block(-1,32,-2,CONCRETE:0)
Block(-1,32,-1,CONCRETE:0)
Block(-1,32,0,CONCRETE:0)
Block(-1,32,1,CONCRETE:0)
Block(-1,32,2,CONCRETE:0)
Block(-1,32,3,CONCRETE:6)
Block(-1,32,4,CONCRETE:6)
Block(-1,32,5,CONCRETE:6)
Block(-1,32,6,CONCRETE:6)
Block(-1,32,7,CONCRETE:6)
Block(-1,33,-6,CONCRETE:6)
Block(-1,33,-5,CONCRETE:6)
Block(-1,33,-4,CONCRETE:6)
Block(-1,33,-3,CONCRETE:0)
Block(-1,33,-2,CONCRETE:0)
Block(-1,33,-1,CONCRETE:0)
Block(-1,33,0,CONCRETE:0)
Block(-1,33,1,CONCRETE:0)
Block(-1,33,2,CONCRETE:0)
Block(-1,33,3,CONCRETE:0)
Block(-1,33,4,CONCRETE:6)
Block(-1,33,5,CONCRETE:6)
Block(-1,33,6,CONCRETE:6)
Block(-1,33,7,CONCRETE:6)
Block(-1,33,8,CONCRETE:6)
Block(-1,34,-6,CONCRETE:6)
Block(-1,34,-5,CONCRETE:6)
Block(-1,34,-4,CONCRETE:6)
Block(-1,34,-3,CONCRETE:0)
Block(-1,34,-2,CONCRETE:0)
Block(-1,34,-1,CONCRETE:0)
Block(-1,34,0,CONCRETE:0)
Block(-1,34,1,CONCRETE:0)
Block(-1,34,2,CONCRETE:0)
Block(-1,34,3,CONCRETE:0)
Block(-1,34,4,CONCRETE:0)
Block(-1,34,5,CONCRETE:6)
Block(-1,34,6,CONCRETE:6)
Block(-1,34,7,CONCRETE:6)
Block(-1,34,8,CONCRETE:6)
Block(-1,34,9,CONCRETE:6)
Block(-1,35,-6,CONCRETE:6)
Block(-1,35,-5,CONCRETE:6)
Block(-1,35,-4,CONCRETE:0)
Block(-1,35,-3,CONCRETE:0)
Block(-1,35,-2,CONCRETE:0)
Block(-1,35,-1,CONCRETE:0)
Block(-1,35,0,CONCRETE:0)
Block(-1,35,1,CONCRETE:0)
Block(-1,35,2,CONCRETE:0)
Block(-1,35,3,CONCRETE:0)
Block(-1,35,4,CONCRETE:0)
Block(-1,35,5,CONCRETE:0)
Block(-1,35,6,CONCRETE:6)
Block(-1,35,7,CONCRETE:6)
Block(-1,35,8,CONCRETE:6)
Block(-1,35,9,CONCRETE:6)
Block(-1,35,10,CONCRETE:6)
Block(-1,36,-6,CONCRETE:0)
Block(-1,36,-5,CONCRETE:0)
Block(-1,36,-4,CONCRETE:0)
Block(-1,36,-3,CONCRETE:0)
Block(-1,36,-2,CONCRETE:0)
Block(-1,36,-1,CONCRETE:0)
Block(-1,36,0,CONCRETE:0)
Block(-1,36,1,CONCRETE:0)
Block(-1,36,2,CONCRETE:0)
Block(-1,36,3,CONCRETE:0)
Block(-1,36,4,CONCRETE:0)
Block(-1,36,5,CONCRETE:0)
Block(-1,36,6,CONCRETE:6)
Block(-1,36,7,CONCRETE:6)
Block(-1,36,8,CONCRETE:6)
Block(-1,36,9,CONCRETE:6)
Block(-1,36,10,CONCRETE:6)
Block(-1,36,11,CONCRETE:6)
Block(-1,37,-7,CONCRETE:0)
Block(-1,37,-6,CONCRETE:0)
Block(-1,37,-5,CONCRETE:0)
Block(-1,37,-4,CONCRETE:0)
Block(-1,37,-3,CONCRETE:0)
Block(-1,37,-2,CONCRETE:0)
Block(-1,37,-1,CONCRETE:0)
Block(-1,37,0,CONCRETE:0)
Block(-1,37,1,CONCRETE:0)
Block(-1,37,2,CONCRETE:0)
Block(-1,37,3,CONCRETE:0)
Block(-1,37,4,CONCRETE:0)
Block(-1,37,5,CONCRETE:0)
Block(-1,37,6,CONCRETE:0)
Block(-1,37,7,CONCRETE:6)
Block(-1,37,8,CONCRETE:6)
Block(-1,37,9,CONCRETE:6)
Block(-1,37,10,CONCRETE:6)
Block(-1,37,11,CONCRETE:6)
Block(-1,38,-7,CONCRETE:0)
Block(-1,38,-6,CONCRETE:0)
Block(-1,38,-5,CONCRETE:0)
Block(-1,38,-4,CONCRETE:0)
Block(-1,38,-3,CONCRETE:0)
Block(-1,38,-2,CONCRETE:0)
Block(-1,38,-1,CONCRETE:0)
Block(-1,38,0,CONCRETE:0)
Block(-1,38,1,CONCRETE:0)
Block(-1,38,2,CONCRETE:0)
Block(-1,38,3,CONCRETE:0)
Block(-1,38,4,CONCRETE:0)
Block(-1,38,5,CONCRETE:0)
Block(-1,38,6,CONCRETE:0)
Block(-1,38,7,CONCRETE:6)
Block(-1,38,8,CONCRETE:6)
Block(-1,38,9,CONCRETE:6)
Block(-1,38,10,CONCRETE:6)
Block(-1,38,11,CONCRETE:6)
Block(-1,39,-7,CONCRETE:0)
Block(-1,39,-6,CONCRETE:0)
Block(-1,39,-5,CONCRETE:0)
Block(-1,39,-4,CONCRETE:0)
Block(-1,39,-3,CONCRETE:0)
Block(-1,39,-2,CONCRETE:0)
Block(-1,39,-1,CONCRETE:0)
Block(-1,39,0,CONCRETE:0)
Block(-1,39,1,CONCRETE:0)
Block(-1,39,2,CONCRETE:0)
Block(-1,39,3,CONCRETE:0)
Block(-1,39,4,CONCRETE:0)
Block(-1,39,5,CONCRETE:0)
Block(-1,39,6,CONCRETE:0)
Block(-1,39,7,CONCRETE:0)
Block(-1,39,8,CONCRETE:6)
Block(-1,39,9,CONCRETE:6)
Block(-1,39,10,CONCRETE:6)
Block(-1,40,-6,CONCRETE:0)
Block(-1,40,-5,CONCRETE:0)
Block(-1,40,-4,CONCRETE:0)
Block(-1,40,-3,CONCRETE:0)
Block(-1,40,-2,CONCRETE:0)
Block(-1,40,-1,CONCRETE:0)
Block(-1,40,0,CONCRETE:0)
Block(-1,40,1,CONCRETE:0)
Block(-1,40,2,CONCRETE:0)
Block(-1,40,3,CONCRETE:0)
Block(-1,40,4,CONCRETE:0)
Block(-1,40,5,CONCRETE:0)
Block(-1,40,6,CONCRETE:0)
Block(-1,40,7,CONCRETE:0)
Block(-1,40,8,CONCRETE:6)
Block(-1,40,9,CONCRETE:6)
Block(-1,40,10,CONCRETE:6)
Block(-1,41,-7,CONCRETE:6)
Block(-1,41,-6,CONCRETE:6)
Block(-1,41,-5,CONCRETE:6)
Block(-1,41,-4,CONCRETE:0)
Block(-1,41,-3,CONCRETE:0)
Block(-1,41,-2,CONCRETE:0)
Block(-1,41,-1,CONCRETE:0)
Block(-1,41,0,CONCRETE:0)
Block(-1,41,1,CONCRETE:0)
Block(-1,41,2,CONCRETE:0)
Block(-1,41,3,CONCRETE:0)
Block(-1,41,4,CONCRETE:0)
Block(-1,41,5,CONCRETE:0)
Block(-1,41,6,CONCRETE:0)
Block(-1,41,7,CONCRETE:0)
Block(-1,41,8,CONCRETE:0)
Block(-1,41,9,CONCRETE:6)
Block(-1,42,-7,CONCRETE:6)
Block(-1,42,-6,CONCRETE:6)
Block(-1,42,-5,CONCRETE:6)
Block(-1,42,-4,CONCRETE:6)
Block(-1,42,-3,CONCRETE:0)
Block(-1,42,-2,CONCRETE:0)
Block(-1,42,-1,CONCRETE:0)
Block(-1,42,0,CONCRETE:0)
Block(-1,42,1,CONCRETE:0)
Block(-1,42,2,CONCRETE:0)
Block(-1,42,3,CONCRETE:0)
Block(-1,42,4,CONCRETE:0)
Block(-1,42,5,CONCRETE:0)
Block(-1,42,6,CONCRETE:0)
Block(-1,42,7,CONCRETE:0)
Block(-1,42,8,CONCRETE:0)
Block(-1,43,-7,CONCRETE:6)
Block(-1,43,-6,CONCRETE:6)
Block(-1,43,-5,CONCRETE:6)
Block(-1,43,-4,CONCRETE:6)
Block(-1,43,-3,CONCRETE:6)
Block(-1,43,-2,CONCRETE:6)
Block(-1,43,-1,CONCRETE:0)
Block(-1,43,0,CONCRETE:0)
Block(-1,43,1,CONCRETE:0)
Block(-1,43,2,CONCRETE:0)
Block(-1,43,3,CONCRETE:0)
Block(-1,43,4,CONCRETE:0)
Block(-1,43,5,CONCRETE:0)
Block(-1,43,6,CONCRETE:0)
Block(-1,43,7,CONCRETE:6)
Block(-1,43,8,CONCRETE:6)
Block(-1,44,-7,CONCRETE:6)
Block(-1,44,-6,CONCRETE:6)
Block(-1,44,-5,CONCRETE:6)
Block(-1,44,-4,CONCRETE:6)
Block(-1,44,-3,CONCRETE:6)
Block(-1,44,-2,CONCRETE:6)
Block(-1,44,-1,CONCRETE:6)
Block(-1,44,0,CONCRETE:6)
Block(-1,44,1,CONCRETE:0)
Block(-1,44,2,CONCRETE:0)
Block(-1,44,3,CONCRETE:0)
Block(-1,44,4,CONCRETE:0)
Block(-1,44,5,CONCRETE:0)
Block(-1,44,6,CONCRETE:6)
Block(-1,44,7,CONCRETE:6)
Block(-1,44,8,CONCRETE:6)
Block(-1,45,-6,CONCRETE:6)
Block(-1,45,-5,CONCRETE:6)
Block(-1,45,-4,CONCRETE:6)
Block(-1,45,-3,CONCRETE:6)
Block(-1,45,-2,CONCRETE:6)
Block(-1,45,-1,CONCRETE:6)
Block(-1,45,0,CONCRETE:6)
Block(-1,45,1,CONCRETE:6)
Block(-1,45,2,CONCRETE:0)
Block(-1,45,3,CONCRETE:0)
Block(-1,45,4,CONCRETE:0)
Block(-1,45,5,CONCRETE:0)
Block(-1,45,6,CONCRETE:6)
Block(-1,45,7,CONCRETE:6)
Block(-1,46,-5,CONCRETE:6)
Block(-1,46,-4,CONCRETE:6)
Block(-1,46,-3,CONCRETE:6)
Block(-1,46,-2,CONCRETE:6)
Block(-1,46,-1,CONCRETE:6)
Block(-1,46,0,CONCRETE:6)
Block(-1,46,1,CONCRETE:6)
Block(-1,46,2,CONCRETE:6)
Block(-1,46,3,CONCRETE:0)
Block(-1,46,4,CONCRETE:0)
Block(-1,47,-4,CONCRETE:6)
Block(-1,47,-3,CONCRETE:6)
Block(-1,47,-2,CONCRETE:6)
Block(-1,47,-1,CONCRETE:6)
Block(-1,47,0,CONCRETE:6)
Block(-1,47,1,CONCRETE:6)
Block(-1,47,2,CONCRETE:6)
Block(-1,47,3,CONCRETE:6)
Block(-1,48,-2,CONCRETE:6)
Block(-1,48,-1,CONCRETE:6)
Block(-1,48,0,CONCRETE:6)
Block(-1,48,1,CONCRETE:6)
Block(-1,48,2,CONCRETE:6)
Block(-1,49,-1,CONCRETE:6)
Block(-1,49,0,CONCRETE:6)
Block(-1,49,1,CONCRETE:6)
Block(0,0,-1,STAINED_CLAY:6)
Block(0,0,0,STAINED_CLAY:6)
Block(0,0,1,STAINED_CLAY:6)
Block(0,1,0,STAINED_CLAY:6)
Block(0,3,-1,STAINED_CLAY:6)
Block(0,4,-2,STAINED_CLAY:6)
Block(0,4,-1,STAINED_CLAY:6)
Block(0,4,0,STAINED_CLAY:6)
Block(0,5,-2,STAINED_CLAY:6)
Block(0,5,-1,STAINED_CLAY:6)
Block(0,5,0,STAINED_CLAY:6)
Block(0,6,-1,STAINED_CLAY:6)
Block(0,6,0,STAINED_CLAY:6)
Block(0,6,1,STAINED_CLAY:6)
Block(0,7,-1,STAINED_CLAY:6)
Block(0,7,0,STAINED_CLAY:6)
Block(0,7,1,STAINED_CLAY:6)
Block(0,8,-1,STAINED_CLAY:6)
Block(0,8,0,STAINED_CLAY:6)
Block(0,8,1,STAINED_CLAY:6)
Block(0,9,-1,STAINED_CLAY:6)
Block(0,9,0,STAINED_CLAY:6)
Block(0,9,1,STAINED_CLAY:6)
Block(0,9,2,STAINED_CLAY:6)
Block(0,10,-1,STAINED_CLAY:6)
Block(0,10,0,STAINED_CLAY:6)
Block(0,10,1,STAINED_CLAY:6)
Block(0,10,2,STAINED_CLAY:6)
Block(0,11,-1,STAINED_CLAY:6)
Block(0,11,0,STAINED_CLAY:6)
Block(0,11,1,STAINED_CLAY:6)
Block(0,12,-1,STAINED_CLAY:6)
Block(0,12,0,STAINED_CLAY:6)
Block(0,12,1,STAINED_CLAY:6)
Block(0,12,6,STAINED_CLAY:6)
Block(0,13,-2,STAINED_CLAY:6)
Block(0,13,-1,STAINED_CLAY:6)
Block(0,13,0,STAINED_CLAY:6)
Block(0,13,1,STAINED_CLAY:6)
Block(0,13,6,STAINED_CLAY:6)
Block(0,13,7,STAINED_CLAY:6)
Block(0,13,8,STAINED_CLAY:6)
Block(0,14,-3,STAINED_CLAY:6)
Block(0,14,-2,STAINED_CLAY:6)
Block(0,14,-1,STAINED_CLAY:6)
Block(0,14,0,STAINED_CLAY:6)
Block(0,14,1,STAINED_CLAY:6)
Block(0,14,7,STAINED_CLAY:6)
Block(0,14,8,STAINED_CLAY:6)
Block(0,15,-4,STAINED_CLAY:6)
Block(0,15,-3,STAINED_CLAY:6)
Block(0,15,-2,STAINED_CLAY:6)
Block(0,15,-1,STAINED_CLAY:6)
Block(0,15,0,STAINED_CLAY:6)
Block(0,15,1,STAINED_CLAY:6)
Block(0,15,8,STAINED_CLAY:6)
Block(0,16,-5,STAINED_CLAY:6)
Block(0,16,-4,STAINED_CLAY:6)
Block(0,16,-3,STAINED_CLAY:6)
Block(0,16,-2,STAINED_CLAY:6)
Block(0,16,-1,STAINED_CLAY:6)
Block(0,16,0,STAINED_CLAY:6)
Block(0,16,1,STAINED_CLAY:6)
Block(0,17,-5,STAINED_CLAY:6)
Block(0,17,-4,STAINED_CLAY:6)
Block(0,17,-3,STAINED_CLAY:6)
Block(0,17,-2,STAINED_CLAY:6)
Block(0,17,-1,STAINED_CLAY:6)
Block(0,17,0,STAINED_CLAY:6)
Block(0,17,1,STAINED_CLAY:6)
Block(0,18,-5,STAINED_CLAY:6)
Block(0,18,-4,STAINED_CLAY:6)
Block(0,18,-3,STAINED_CLAY:6)
Block(0,18,-2,STAINED_CLAY:6)
Block(0,18,-1,STAINED_CLAY:6)
Block(0,18,0,STAINED_CLAY:6)
Block(0,18,1,STAINED_CLAY:6)
Block(0,19,-5,STAINED_CLAY:6)
Block(0,19,-4,STAINED_CLAY:6)
Block(0,19,-3,STAINED_CLAY:6)
Block(0,19,-2,STAINED_CLAY:6)
Block(0,19,-1,STAINED_CLAY:6)
Block(0,19,0,STAINED_CLAY:6)
Block(0,19,1,STAINED_CLAY:6)
Block(0,20,-5,STAINED_CLAY:6)
Block(0,20,-4,STAINED_CLAY:6)
Block(0,20,-3,STAINED_CLAY:6)
Block(0,20,-2,STAINED_CLAY:6)
Block(0,20,-1,STAINED_CLAY:6)
Block(0,20,0,STAINED_CLAY:6)
Block(0,20,1,STAINED_CLAY:6)
Block(0,21,-4,STAINED_CLAY:6)
Block(0,21,-3,STAINED_CLAY:6)
Block(0,21,-2,STAINED_CLAY:6)
Block(0,21,-1,STAINED_CLAY:6)
Block(0,21,0,STAINED_CLAY:6)
Block(0,21,1,STAINED_CLAY:6)
Block(0,22,-3,STAINED_CLAY:6)
Block(0,22,-2,STAINED_CLAY:6)
Block(0,22,-1,STAINED_CLAY:6)
Block(0,22,0,STAINED_CLAY:6)
Block(0,22,1,STAINED_CLAY:6)
Block(0,23,-2,STAINED_CLAY:6)
Block(0,23,-1,STAINED_CLAY:6)
Block(0,23,0,STAINED_CLAY:6)
Block(0,23,1,STAINED_CLAY:6)
Block(0,24,-1,STAINED_CLAY:6)
Block(0,24,0,STAINED_CLAY:6)
Block(0,31,-1,CONCRETE:0)
Block(0,31,0,CONCRETE:0)
Block(0,31,1,CONCRETE:0)
Block(0,31,2,CONCRETE:0)
Block(0,31,3,CONCRETE:0)
Block(0,31,4,CONCRETE:6)
Block(0,31,5,CONCRETE:6)
Block(0,32,-7,CONCRETE:6)
Block(0,32,-6,CONCRETE:6)
Block(0,32,-5,CONCRETE:6)
Block(0,32,-4,CONCRETE:6)
Block(0,32,-3,CONCRETE:6)
Block(0,32,-2,CONCRETE:0)
Block(0,32,-1,CONCRETE:0)
Block(0,32,0,CONCRETE:0)
Block(0,32,1,CONCRETE:0)
Block(0,32,2,CONCRETE:0)
Block(0,32,3,CONCRETE:0)
Block(0,32,4,CONCRETE:6)
Block(0,32,5,CONCRETE:6)
Block(0,32,6,CONCRETE:6)
Block(0,33,-7,CONCRETE:6)
Block(0,33,-6,CONCRETE:6)
Block(0,33,-5,CONCRETE:6)
Block(0,33,-4,CONCRETE:6)
Block(0,33,-3,CONCRETE:6)
Block(0,33,-2,CONCRETE:0)
Block(0,33,-1,CONCRETE:0)
Block(0,33,0,CONCRETE:0)
Block(0,33,1,CONCRETE:0)
Block(0,33,2,CONCRETE:0)
Block(0,33,3,CONCRETE:0)
Block(0,33,4,CONCRETE:0)
Block(0,33,5,CONCRETE:6)
Block(0,33,6,CONCRETE:6)
Block(0,33,7,CONCRETE:6)
Block(0,34,-7,CONCRETE:6)
Block(0,34,-6,CONCRETE:6)
Block(0,34,-5,CONCRETE:6)
Block(0,34,-4,CONCRETE:6)
Block(0,34,-3,CONCRETE:6)
Block(0,34,-2,CONCRETE:0)
Block(0,34,-1,CONCRETE:0)
Block(0,34,0,CONCRETE:0)
Block(0,34,1,CONCRETE:0)
Block(0,34,2,CONCRETE:0)
Block(0,34,3,CONCRETE:0)
Block(0,34,4,CONCRETE:0)
Block(0,34,5,CONCRETE:0)
Block(0,34,6,CONCRETE:6)
Block(0,34,7,CONCRETE:6)
Block(0,34,8,CONCRETE:6)
Block(0,34,9,CONCRETE:6)
Block(0,35,-7,CONCRETE:6)
Block(0,35,-6,CONCRETE:6)
Block(0,35,-5,CONCRETE:6)
Block(0,35,-4,CONCRETE:6)
Block(0,35,-3,CONCRETE:0)
Block(0,35,-2,CONCRETE:0)
Block(0,35,-1,CONCRETE:0)
Block(0,35,0,CONCRETE:0)
Block(0,35,1,CONCRETE:0)
Block(0,35,2,CONCRETE:0)
Block(0,35,3,CONCRETE:0)
Block(0,35,4,CONCRETE:0)
Block(0,35,5,CONCRETE:0)
Block(0,35,6,CONCRETE:0)
Block(0,35,7,CONCRETE:6)
Block(0,35,8,CONCRETE:6)
Block(0,35,9,CONCRETE:6)
Block(0,35,10,CONCRETE:6)
Block(0,36,-7,CONCRETE:6)
Block(0,36,-6,CONCRETE:6)
Block(0,36,-5,CONCRETE:6)
Block(0,36,-4,CONCRETE:6)
Block(0,36,-3,CONCRETE:0)
Block(0,36,-2,CONCRETE:0)
Block(0,36,-1,CONCRETE:0)
Block(0,36,0,CONCRETE:0)
Block(0,36,1,CONCRETE:0)
Block(0,36,2,CONCRETE:0)
Block(0,36,3,CONCRETE:0)
Block(0,36,4,CONCRETE:0)
Block(0,36,5,CONCRETE:0)
Block(0,36,6,CONCRETE:0)
Block(0,36,7,CONCRETE:6)
Block(0,36,8,CONCRETE:6)
Block(0,36,9,CONCRETE:6)
Block(0,36,10,CONCRETE:6)
Block(0,37,-6,CONCRETE:0)
Block(0,37,-5,CONCRETE:0)
Block(0,37,-4,CONCRETE:0)
Block(0,37,-3,CONCRETE:0)
Block(0,37,-2,CONCRETE:0)
Block(0,37,-1,CONCRETE:0)
Block(0,37,0,CONCRETE:0)
Block(0,37,1,CONCRETE:0)
Block(0,37,2,CONCRETE:0)
Block(0,37,3,CONCRETE:0)
Block(0,37,4,CONCRETE:0)
Block(0,37,5,CONCRETE:0)
Block(0,37,6,CONCRETE:0)
Block(0,37,7,CONCRETE:6)
Block(0,37,8,CONCRETE:6)
Block(0,37,9,CONCRETE:6)
Block(0,37,10,CONCRETE:6)
Block(0,37,11,CONCRETE:6)
Block(0,38,-7,CONCRETE:0)
Block(0,38,-6,CONCRETE:0)
Block(0,38,-5,CONCRETE:0)
Block(0,38,-4,CONCRETE:0)
Block(0,38,-3,CONCRETE:0)
Block(0,38,-2,CONCRETE:0)
Block(0,38,-1,CONCRETE:0)
Block(0,38,0,CONCRETE:0)
Block(0,38,1,CONCRETE:0)
Block(0,38,2,CONCRETE:0)
Block(0,38,3,CONCRETE:0)
Block(0,38,4,CONCRETE:0)
Block(0,38,5,CONCRETE:0)
Block(0,38,6,CONCRETE:0)
Block(0,38,7,CONCRETE:6)
Block(0,38,8,CONCRETE:6)
Block(0,38,9,CONCRETE:6)
Block(0,38,10,CONCRETE:6)
Block(0,38,11,CONCRETE:6)
Block(0,39,-7,CONCRETE:0)
Block(0,39,-6,CONCRETE:0)
Block(0,39,-5,CONCRETE:0)
Block(0,39,-4,CONCRETE:0)
Block(0,39,-3,CONCRETE:0)
Block(0,39,-2,CONCRETE:0)
Block(0,39,-1,CONCRETE:0)
Block(0,39,0,CONCRETE:0)
Block(0,39,1,CONCRETE:0)
Block(0,39,2,CONCRETE:0)
Block(0,39,3,CONCRETE:0)
Block(0,39,4,CONCRETE:0)
Block(0,39,5,CONCRETE:0)
Block(0,39,6,CONCRETE:0)
Block(0,39,7,CONCRETE:0)
Block(0,39,8,CONCRETE:6)
Block(0,39,9,CONCRETE:6)
Block(0,39,10,CONCRETE:6)
Block(0,40,-6,CONCRETE:0)
Block(0,40,-5,CONCRETE:0)
Block(0,40,-4,CONCRETE:0)
Block(0,40,-3,CONCRETE:0)
Block(0,40,-2,CONCRETE:0)
Block(0,40,-1,CONCRETE:0)
Block(0,40,0,CONCRETE:0)
Block(0,40,1,CONCRETE:0)
Block(0,40,2,CONCRETE:0)
Block(0,40,3,CONCRETE:0)
Block(0,40,4,CONCRETE:0)
Block(0,40,5,CONCRETE:0)
Block(0,40,6,CONCRETE:0)
Block(0,40,7,CONCRETE:0)
Block(0,40,8,CONCRETE:6)
Block(0,40,9,CONCRETE:6)
Block(0,40,10,CONCRETE:6)
Block(0,41,-6,CONCRETE:6)
Block(0,41,-5,CONCRETE:6)
Block(0,41,-4,CONCRETE:0)
Block(0,41,-3,CONCRETE:0)
Block(0,41,-2,CONCRETE:0)
Block(0,41,-1,CONCRETE:0)
Block(0,41,0,CONCRETE:0)
Block(0,41,1,CONCRETE:0)
Block(0,41,2,CONCRETE:0)
Block(0,41,3,CONCRETE:0)
Block(0,41,4,CONCRETE:0)
Block(0,41,5,CONCRETE:0)
Block(0,41,6,CONCRETE:0)
Block(0,41,7,CONCRETE:0)
Block(0,41,8,CONCRETE:6)
Block(0,41,9,CONCRETE:6)
Block(0,42,-7,CONCRETE:6)
Block(0,42,-6,CONCRETE:6)
Block(0,42,-5,CONCRETE:6)
Block(0,42,-4,CONCRETE:6)
Block(0,42,-3,CONCRETE:6)
Block(0,42,-2,CONCRETE:0)
Block(0,42,-1,CONCRETE:0)
Block(0,42,0,CONCRETE:0)
Block(0,42,1,CONCRETE:0)
Block(0,42,2,CONCRETE:0)
Block(0,42,3,CONCRETE:0)
Block(0,42,4,CONCRETE:0)
Block(0,42,5,CONCRETE:0)
Block(0,42,6,CONCRETE:0)
Block(0,42,7,CONCRETE:6)
Block(0,42,8,CONCRETE:6)
Block(0,42,9,CONCRETE:6)
Block(0,43,-7,CONCRETE:6)
Block(0,43,-6,CONCRETE:6)
Block(0,43,-5,CONCRETE:6)
Block(0,43,-4,CONCRETE:6)
Block(0,43,-3,CONCRETE:6)
Block(0,43,-2,CONCRETE:6)
Block(0,43,-1,CONCRETE:0)
Block(0,43,0,CONCRETE:0)
Block(0,43,1,CONCRETE:0)
Block(0,43,2,CONCRETE:0)
Block(0,43,3,CONCRETE:0)
Block(0,43,4,CONCRETE:0)
Block(0,43,5,CONCRETE:0)
Block(0,43,6,CONCRETE:6)
Block(0,43,7,CONCRETE:6)
Block(0,43,8,CONCRETE:6)
Block(0,43,9,CONCRETE:6)
Block(0,44,-7,CONCRETE:6)
Block(0,44,-6,CONCRETE:6)
Block(0,44,-5,CONCRETE:6)
Block(0,44,-4,CONCRETE:6)
Block(0,44,-3,CONCRETE:6)
Block(0,44,-2,CONCRETE:6)
Block(0,44,-1,CONCRETE:6)
Block(0,44,0,CONCRETE:6)
Block(0,44,1,CONCRETE:0)
Block(0,44,2,CONCRETE:0)
Block(0,44,3,CONCRETE:0)
Block(0,44,4,CONCRETE:0)
Block(0,44,5,CONCRETE:6)
Block(0,44,6,CONCRETE:6)
Block(0,44,7,CONCRETE:6)
Block(0,44,8,CONCRETE:6)
Block(0,44,9,CONCRETE:6)
Block(0,45,-7,CONCRETE:6)
Block(0,45,-6,CONCRETE:6)
Block(0,45,-5,CONCRETE:6)
Block(0,45,-4,CONCRETE:6)
Block(0,45,-3,CONCRETE:6)
Block(0,45,-2,CONCRETE:6)
Block(0,45,-1,CONCRETE:6)
Block(0,45,0,CONCRETE:6)
Block(0,45,1,CONCRETE:6)
Block(0,45,2,CONCRETE:6)
Block(0,45,3,CONCRETE:0)
Block(0,45,4,CONCRETE:0)
Block(0,45,5,CONCRETE:6)
Block(0,45,6,CONCRETE:6)
Block(0,45,7,CONCRETE:6)
Block(0,45,8,CONCRETE:6)
Block(0,46,-6,CONCRETE:6)
Block(0,46,-5,CONCRETE:6)
Block(0,46,-4,CONCRETE:6)
Block(0,46,-3,CONCRETE:6)
Block(0,46,-2,CONCRETE:6)
Block(0,46,-1,CONCRETE:6)
Block(0,46,0,CONCRETE:6)
Block(0,46,1,CONCRETE:6)
Block(0,46,2,CONCRETE:6)
Block(0,46,3,CONCRETE:6)
Block(0,46,4,CONCRETE:6)
Block(0,46,5,CONCRETE:6)
Block(0,46,6,CONCRETE:6)
Block(0,47,-5,CONCRETE:6)
Block(0,47,-4,CONCRETE:6)
Block(0,47,-3,CONCRETE:6)
Block(0,47,-2,CONCRETE:6)
Block(0,47,-1,CONCRETE:6)
Block(0,47,0,CONCRETE:6)
Block(0,47,1,CONCRETE:6)
Block(0,47,2,CONCRETE:6)
Block(0,47,3,CONCRETE:6)
Block(0,48,-3,CONCRETE:6)
Block(0,48,-2,CONCRETE:6)
Block(0,48,-1,CONCRETE:6)
Block(0,48,0,CONCRETE:6)
Block(0,48,1,CONCRETE:6)
Block(0,48,2,CONCRETE:6)
Block(0,49,-2,CONCRETE:6)
Block(0,49,-1,CONCRETE:6)
Block(0,49,0,CONCRETE:6)
Block(0,49,1,CONCRETE:6)
Block(1,13,8,STAINED_CLAY:6)
Block(1,14,-2,STAINED_CLAY:6)
Block(1,14,7,STAINED_CLAY:6)
Block(1,14,8,STAINED_CLAY:6)
Block(1,14,9,STAINED_CLAY:6)
Block(1,15,-4,STAINED_CLAY:6)
Block(1,15,-3,STAINED_CLAY:6)
Block(1,15,-2,STAINED_CLAY:6)
Block(1,15,-1,STAINED_CLAY:6)
Block(1,15,7,STAINED_CLAY:6)
Block(1,15,8,STAINED_CLAY:6)
Block(1,15,9,STAINED_CLAY:6)
Block(1,16,-4,STAINED_CLAY:6)
Block(1,16,-3,STAINED_CLAY:6)
Block(1,16,-2,STAINED_CLAY:6)
Block(1,16,-1,STAINED_CLAY:6)
Block(1,16,0,STAINED_CLAY:6)
Block(1,16,8,STAINED_CLAY:6)
Block(1,16,9,STAINED_CLAY:6)
Block(1,17,-5,STAINED_CLAY:6)
Block(1,17,-4,STAINED_CLAY:6)
Block(1,17,-3,STAINED_CLAY:6)
Block(1,17,-2,STAINED_CLAY:6)
Block(1,17,-1,STAINED_CLAY:6)
Block(1,17,0,STAINED_CLAY:6)
Block(1,18,-6,STAINED_CLAY:6)
Block(1,18,-5,STAINED_CLAY:6)
Block(1,18,-4,STAINED_CLAY:6)
Block(1,18,-3,STAINED_CLAY:6)
Block(1,18,-2,STAINED_CLAY:6)
Block(1,18,-1,STAINED_CLAY:6)
Block(1,18,0,STAINED_CLAY:6)
Block(1,19,-6,STAINED_CLAY:6)
Block(1,19,-5,STAINED_CLAY:6)
Block(1,19,-4,STAINED_CLAY:6)
Block(1,19,-3,STAINED_CLAY:6)
Block(1,19,-2,STAINED_CLAY:6)
Block(1,19,-1,STAINED_CLAY:6)
Block(1,19,0,STAINED_CLAY:6)
Block(1,20,-5,STAINED_CLAY:6)
Block(1,20,-4,STAINED_CLAY:6)
Block(1,20,-3,STAINED_CLAY:6)
Block(1,20,-2,STAINED_CLAY:6)
Block(1,20,-1,STAINED_CLAY:6)
Block(1,20,0,STAINED_CLAY:6)
Block(1,21,-4,STAINED_CLAY:6)
Block(1,21,-3,STAINED_CLAY:6)
Block(1,21,-2,STAINED_CLAY:6)
Block(1,21,-1,STAINED_CLAY:6)
Block(1,21,0,STAINED_CLAY:6)
Block(1,22,-2,STAINED_CLAY:6)
Block(1,22,-1,STAINED_CLAY:6)
Block(1,22,0,STAINED_CLAY:6)
Block(1,31,-6,CONCRETE:6)
Block(1,31,-5,CONCRETE:6)
Block(1,31,0,CONCRETE:0)
Block(1,31,1,CONCRETE:0)
Block(1,31,2,CONCRETE:0)
Block(1,32,-7,CONCRETE:6)
Block(1,32,-6,CONCRETE:6)
Block(1,32,-5,CONCRETE:6)
Block(1,32,-4,CONCRETE:6)
Block(1,32,-3,CONCRETE:6)
Block(1,32,-2,CONCRETE:0)
Block(1,32,-1,CONCRETE:0)
Block(1,32,0,CONCRETE:0)
Block(1,32,1,CONCRETE:0)
Block(1,32,2,CONCRETE:0)
Block(1,32,3,CONCRETE:0)
Block(1,32,4,CONCRETE:0)
Block(1,33,-7,CONCRETE:6)
Block(1,33,-6,CONCRETE:6)
Block(1,33,-5,CONCRETE:6)
Block(1,33,-4,CONCRETE:6)
Block(1,33,-3,CONCRETE:6)
Block(1,33,-2,CONCRETE:0)
Block(1,33,-1,CONCRETE:0)
Block(1,33,0,CONCRETE:0)
Block(1,33,1,CONCRETE:0)
Block(1,33,2,CONCRETE:0)
Block(1,33,3,CONCRETE:0)
Block(1,33,4,CONCRETE:0)
Block(1,33,5,CONCRETE:0)
Block(1,34,-8,CONCRETE:6)
Block(1,34,-7,CONCRETE:6)
Block(1,34,-6,CONCRETE:6)
Block(1,34,-5,CONCRETE:6)
Block(1,34,-4,CONCRETE:6)
Block(1,34,-3,CONCRETE:6)
Block(1,34,-2,CONCRETE:6)
Block(1,34,-1,CONCRETE:0)
Block(1,34,0,CONCRETE:0)
Block(1,34,1,CONCRETE:0)
Block(1,34,2,CONCRETE:0)
Block(1,34,3,CONCRETE:0)
Block(1,34,4,CONCRETE:0)
Block(1,34,5,CONCRETE:0)
Block(1,34,6,CONCRETE:0)
Block(1,35,-7,CONCRETE:6)
Block(1,35,-6,CONCRETE:6)
Block(1,35,-5,CONCRETE:6)
Block(1,35,-4,CONCRETE:6)
Block(1,35,-3,CONCRETE:6)
Block(1,35,-2,CONCRETE:0)
Block(1,35,-1,CONCRETE:0)
Block(1,35,0,CONCRETE:0)
Block(1,35,1,CONCRETE:0)
Block(1,35,2,CONCRETE:0)
Block(1,35,3,CONCRETE:0)
Block(1,35,4,CONCRETE:0)
Block(1,35,5,CONCRETE:0)
Block(1,35,6,CONCRETE:0)
Block(1,35,7,CONCRETE:0)
Block(1,35,8,CONCRETE:6)
Block(1,35,9,CONCRETE:6)
Block(1,36,-7,CONCRETE:6)
Block(1,36,-6,CONCRETE:6)
Block(1,36,-5,CONCRETE:6)
Block(1,36,-4,CONCRETE:6)
Block(1,36,-3,CONCRETE:6)
Block(1,36,-2,CONCRETE:0)
Block(1,36,-1,CONCRETE:0)
Block(1,36,0,CONCRETE:0)
Block(1,36,1,CONCRETE:0)
Block(1,36,2,CONCRETE:0)
Block(1,36,3,CONCRETE:0)
Block(1,36,4,CONCRETE:0)
Block(1,36,5,CONCRETE:0)
Block(1,36,6,CONCRETE:0)
Block(1,36,7,CONCRETE:6)
Block(1,36,8,CONCRETE:6)
Block(1,36,9,CONCRETE:6)
Block(1,36,10,CONCRETE:6)
Block(1,37,-6,CONCRETE:6)
Block(1,37,-5,CONCRETE:6)
Block(1,37,-4,CONCRETE:6)
Block(1,37,-3,CONCRETE:0)
Block(1,37,-2,CONCRETE:0)
Block(1,37,-1,CONCRETE:0)
Block(1,37,0,CONCRETE:0)
Block(1,37,1,CONCRETE:0)
Block(1,37,2,CONCRETE:0)
Block(1,37,3,CONCRETE:0)
Block(1,37,4,CONCRETE:0)
Block(1,37,5,CONCRETE:0)
Block(1,37,6,CONCRETE:0)
Block(1,37,7,CONCRETE:6)
Block(1,37,8,CONCRETE:6)
Block(1,37,9,CONCRETE:6)
Block(1,37,10,CONCRETE:6)
Block(1,38,-6,CONCRETE:0)
Block(1,38,-5,CONCRETE:0)
Block(1,38,-4,CONCRETE:0)
Block(1,38,-3,CONCRETE:0)
Block(1,38,-2,CONCRETE:0)
Block(1,38,-1,CONCRETE:0)
Block(1,38,0,CONCRETE:0)
Block(1,38,1,CONCRETE:0)
Block(1,38,2,CONCRETE:0)
Block(1,38,3,CONCRETE:0)
Block(1,38,4,CONCRETE:0)
Block(1,38,5,CONCRETE:0)
Block(1,38,6,CONCRETE:0)
Block(1,38,7,CONCRETE:0)
Block(1,38,8,CONCRETE:6)
Block(1,38,9,CONCRETE:6)
Block(1,38,10,CONCRETE:6)
Block(1,39,-6,CONCRETE:0)
Block(1,39,-5,CONCRETE:0)
Block(1,39,-4,CONCRETE:0)
Block(1,39,-3,CONCRETE:0)
Block(1,39,-2,CONCRETE:0)
Block(1,39,-1,CONCRETE:0)
Block(1,39,0,CONCRETE:0)
Block(1,39,1,CONCRETE:0)
Block(1,39,2,CONCRETE:0)
Block(1,39,3,CONCRETE:0)
Block(1,39,4,CONCRETE:0)
Block(1,39,5,CONCRETE:0)
Block(1,39,6,CONCRETE:0)
Block(1,39,7,CONCRETE:0)
Block(1,39,8,CONCRETE:6)
Block(1,39,9,CONCRETE:6)
Block(1,40,-6,CONCRETE:6)
Block(1,40,-5,CONCRETE:6)
Block(1,40,-4,CONCRETE:0)
Block(1,40,-3,CONCRETE:0)
Block(1,40,-2,CONCRETE:0)
Block(1,40,-1,CONCRETE:0)
Block(1,40,0,CONCRETE:0)
Block(1,40,1,CONCRETE:0)
Block(1,40,2,CONCRETE:0)
Block(1,40,3,CONCRETE:0)
Block(1,40,4,CONCRETE:0)
Block(1,40,5,CONCRETE:0)
Block(1,40,6,CONCRETE:0)
Block(1,40,7,CONCRETE:0)
Block(1,40,8,CONCRETE:6)
Block(1,40,9,CONCRETE:6)
Block(1,41,-6,CONCRETE:6)
Block(1,41,-5,CONCRETE:6)
Block(1,41,-4,CONCRETE:6)
Block(1,41,-3,CONCRETE:0)
Block(1,41,-2,CONCRETE:0)
Block(1,41,-1,CONCRETE:0)
Block(1,41,0,CONCRETE:0)
Block(1,41,1,CONCRETE:0)
Block(1,41,2,CONCRETE:0)
Block(1,41,3,CONCRETE:0)
Block(1,41,4,CONCRETE:0)
Block(1,41,5,CONCRETE:0)
Block(1,41,6,CONCRETE:0)
Block(1,41,7,CONCRETE:6)
Block(1,41,8,CONCRETE:6)
Block(1,41,9,CONCRETE:6)
Block(1,42,-7,CONCRETE:6)
Block(1,42,-6,CONCRETE:6)
Block(1,42,-5,CONCRETE:6)
Block(1,42,-4,CONCRETE:6)
Block(1,42,-3,CONCRETE:6)
Block(1,42,-2,CONCRETE:0)
Block(1,42,-1,CONCRETE:0)
Block(1,42,0,CONCRETE:0)
Block(1,42,1,CONCRETE:0)
Block(1,42,2,CONCRETE:0)
Block(1,42,3,CONCRETE:0)
Block(1,42,4,CONCRETE:0)
Block(1,42,5,CONCRETE:0)
Block(1,42,6,CONCRETE:6)
Block(1,42,7,CONCRETE:6)
Block(1,42,8,CONCRETE:6)
Block(1,42,9,CONCRETE:6)
Block(1,43,-7,CONCRETE:6)
Block(1,43,-6,CONCRETE:6)
Block(1,43,-5,CONCRETE:6)
Block(1,43,-4,CONCRETE:6)
Block(1,43,-3,CONCRETE:6)
Block(1,43,-2,CONCRETE:6)
Block(1,43,-1,CONCRETE:0)
Block(1,43,0,CONCRETE:0)
Block(1,43,1,CONCRETE:0)
Block(1,43,2,CONCRETE:0)
Block(1,43,3,CONCRETE:0)
Block(1,43,4,CONCRETE:0)
Block(1,43,5,CONCRETE:6)
Block(1,43,6,CONCRETE:6)
Block(1,43,7,CONCRETE:6)
Block(1,43,8,CONCRETE:6)
Block(1,43,9,CONCRETE:6)
Block(1,44,-7,CONCRETE:6)
Block(1,44,-6,CONCRETE:6)
Block(1,44,-5,CONCRETE:6)
Block(1,44,-4,CONCRETE:6)
Block(1,44,-3,CONCRETE:6)
Block(1,44,-2,CONCRETE:6)
Block(1,44,-1,CONCRETE:6)
Block(1,44,0,CONCRETE:6)
Block(1,44,1,CONCRETE:0)
Block(1,44,2,CONCRETE:0)
Block(1,44,3,CONCRETE:0)
Block(1,44,4,CONCRETE:6)
Block(1,44,5,CONCRETE:6)
Block(1,44,6,CONCRETE:6)
Block(1,44,7,CONCRETE:6)
Block(1,44,8,CONCRETE:6)
Block(1,44,9,CONCRETE:6)
Block(1,45,-7,CONCRETE:6)
Block(1,45,-6,CONCRETE:6)
Block(1,45,-5,CONCRETE:6)
Block(1,45,-4,CONCRETE:6)
Block(1,45,-3,CONCRETE:6)
Block(1,45,-2,CONCRETE:6)
Block(1,45,-1,CONCRETE:6)
Block(1,45,0,CONCRETE:6)
Block(1,45,1,CONCRETE:6)
Block(1,45,2,CONCRETE:6)
Block(1,45,3,CONCRETE:6)
Block(1,45,4,CONCRETE:6)
Block(1,45,5,CONCRETE:6)
Block(1,45,6,CONCRETE:6)
Block(1,45,7,CONCRETE:6)
Block(1,45,8,CONCRETE:6)
Block(1,45,9,CONCRETE:6)
Block(1,46,-7,CONCRETE:6)
Block(1,46,-6,CONCRETE:6)
Block(1,46,-5,CONCRETE:6)
Block(1,46,-4,CONCRETE:6)
Block(1,46,-3,CONCRETE:6)
Block(1,46,-2,CONCRETE:6)
Block(1,46,-1,CONCRETE:6)
Block(1,46,0,CONCRETE:6)
Block(1,46,1,CONCRETE:6)
Block(1,46,2,CONCRETE:6)
Block(1,46,3,CONCRETE:6)
Block(1,46,4,CONCRETE:6)
Block(1,46,5,CONCRETE:6)
Block(1,46,6,CONCRETE:6)
Block(1,46,7,CONCRETE:6)
Block(1,46,8,CONCRETE:6)
Block(1,47,-5,CONCRETE:6)
Block(1,47,-4,CONCRETE:6)
Block(1,47,-3,CONCRETE:6)
Block(1,47,-2,CONCRETE:6)
Block(1,47,-1,CONCRETE:6)
Block(1,47,0,CONCRETE:6)
Block(1,47,1,CONCRETE:6)
Block(1,47,2,CONCRETE:6)
Block(1,47,3,CONCRETE:6)
Block(1,48,-3,CONCRETE:6)
Block(1,48,-2,CONCRETE:6)
Block(1,48,-1,CONCRETE:6)
Block(1,48,0,CONCRETE:6)
Block(1,48,1,CONCRETE:6)
Block(1,48,2,CONCRETE:6)
Block(1,49,-2,CONCRETE:6)
Block(1,49,-1,CONCRETE:6)
Block(1,49,0,CONCRETE:6)
Block(1,49,1,CONCRETE:6)
Block(1,50,0,CONCRETE:6)
Block(2,14,8,STAINED_CLAY:6)
Block(2,15,8,STAINED_CLAY:6)
Block(2,15,9,STAINED_CLAY:6)
Block(2,16,-4,STAINED_CLAY:6)
Block(2,16,-3,STAINED_CLAY:6)
Block(2,16,-2,STAINED_CLAY:6)
Block(2,16,7,STAINED_CLAY:6)
Block(2,16,8,STAINED_CLAY:6)
Block(2,16,9,STAINED_CLAY:6)
Block(2,17,-5,STAINED_CLAY:6)
Block(2,17,-4,STAINED_CLAY:6)
Block(2,17,-3,STAINED_CLAY:6)
Block(2,17,-2,STAINED_CLAY:6)
Block(2,17,-1,STAINED_CLAY:6)
Block(2,17,8,STAINED_CLAY:6)
Block(2,17,9,STAINED_CLAY:6)
Block(2,18,-6,STAINED_CLAY:6)
Block(2,18,-5,STAINED_CLAY:6)
Block(2,18,-4,STAINED_CLAY:6)
Block(2,18,-3,STAINED_CLAY:6)
Block(2,18,-2,STAINED_CLAY:6)
Block(2,18,-1,STAINED_CLAY:6)
Block(2,19,-7,STAINED_CLAY:6)
Block(2,19,-6,STAINED_CLAY:6)
Block(2,19,-5,STAINED_CLAY:6)
Block(2,19,-4,STAINED_CLAY:6)
Block(2,19,-3,STAINED_CLAY:6)
Block(2,19,-2,STAINED_CLAY:6)
Block(2,19,-1,STAINED_CLAY:6)
Block(2,20,-7,STAINED_CLAY:6)
Block(2,20,-6,STAINED_CLAY:6)
Block(2,20,-5,STAINED_CLAY:6)
Block(2,20,-4,STAINED_CLAY:6)
Block(2,20,-3,STAINED_CLAY:6)
Block(2,20,-2,STAINED_CLAY:6)
Block(2,31,-6,CONCRETE:6)
Block(2,31,-5,CONCRETE:6)
Block(2,31,-4,CONCRETE:6)
Block(2,32,-7,CONCRETE:6)
Block(2,32,-6,CONCRETE:6)
Block(2,32,-5,CONCRETE:6)
Block(2,32,-4,CONCRETE:6)
Block(2,32,-3,CONCRETE:6)
Block(2,32,-1,CONCRETE:0)
Block(2,32,0,CONCRETE:0)
Block(2,32,1,CONCRETE:0)
Block(2,32,2,CONCRETE:0)
Block(2,32,3,CONCRETE:0)
Block(2,33,-8,CONCRETE:6)
Block(2,33,-7,CONCRETE:6)
Block(2,33,-6,CONCRETE:6)
Block(2,33,-5,CONCRETE:6)
Block(2,33,-4,CONCRETE:6)
Block(2,33,-3,CONCRETE:6)
Block(2,33,-2,CONCRETE:6)
Block(2,33,-1,CONCRETE:0)
Block(2,33,0,CONCRETE:0)
Block(2,33,1,CONCRETE:0)
Block(2,33,2,CONCRETE:0)
Block(2,33,3,CONCRETE:0)
Block(2,33,4,CONCRETE:6)
Block(2,33,5,CONCRETE:6)
Block(2,34,-8,CONCRETE:6)
Block(2,34,-7,CONCRETE:6)
Block(2,34,-6,CONCRETE:6)
Block(2,34,-5,CONCRETE:6)
Block(2,34,-4,CONCRETE:6)
Block(2,34,-3,CONCRETE:6)
Block(2,34,-2,CONCRETE:6)
Block(2,34,-1,CONCRETE:0)
Block(2,34,0,CONCRETE:0)
Block(2,34,1,CONCRETE:0)
Block(2,34,2,CONCRETE:0)
Block(2,34,3,CONCRETE:0)
Block(2,34,4,CONCRETE:0)
Block(2,34,5,CONCRETE:0)
Block(2,34,6,CONCRETE:0)
Block(2,35,-8,CONCRETE:6)
Block(2,35,-7,CONCRETE:6)
Block(2,35,-6,CONCRETE:6)
Block(2,35,-5,CONCRETE:6)
Block(2,35,-4,CONCRETE:6)
Block(2,35,-3,CONCRETE:6)
Block(2,35,-2,CONCRETE:0)
Block(2,35,-1,CONCRETE:0)
Block(2,35,0,CONCRETE:0)
Block(2,35,1,CONCRETE:0)
Block(2,35,2,CONCRETE:0)
Block(2,35,3,CONCRETE:0)
Block(2,35,4,CONCRETE:0)
Block(2,35,5,CONCRETE:0)
Block(2,35,6,CONCRETE:0)
Block(2,35,7,CONCRETE:0)
Block(2,36,-7,CONCRETE:6)
Block(2,36,-6,CONCRETE:6)
Block(2,36,-5,CONCRETE:6)
Block(2,36,-4,CONCRETE:6)
Block(2,36,-3,CONCRETE:6)
Block(2,36,-2,CONCRETE:0)
Block(2,36,-1,CONCRETE:0)
Block(2,36,0,CONCRETE:0)
Block(2,36,1,CONCRETE:0)
Block(2,36,2,CONCRETE:0)
Block(2,36,3,CONCRETE:0)
Block(2,36,4,CONCRETE:0)
Block(2,36,5,CONCRETE:0)
Block(2,36,6,CONCRETE:0)
Block(2,36,7,CONCRETE:0)
Block(2,36,8,CONCRETE:6)
Block(2,37,-6,CONCRETE:6)
Block(2,37,-5,CONCRETE:6)
Block(2,37,-4,CONCRETE:6)
Block(2,37,-3,CONCRETE:0)
Block(2,37,-2,CONCRETE:0)
Block(2,37,-1,CONCRETE:0)
Block(2,37,0,CONCRETE:0)
Block(2,37,1,CONCRETE:0)
Block(2,37,2,CONCRETE:0)
Block(2,37,3,CONCRETE:0)
Block(2,37,4,CONCRETE:0)
Block(2,37,5,CONCRETE:0)
Block(2,37,6,CONCRETE:0)
Block(2,37,7,CONCRETE:0)
Block(2,37,8,CONCRETE:6)
Block(2,37,9,CONCRETE:6)
Block(2,38,-6,CONCRETE:6)
Block(2,38,-5,CONCRETE:6)
Block(2,38,-4,CONCRETE:6)
Block(2,38,-3,CONCRETE:0)
Block(2,38,-2,CONCRETE:0)
Block(2,38,-1,CONCRETE:0)
Block(2,38,0,CONCRETE:0)
Block(2,38,1,CONCRETE:0)
Block(2,38,2,CONCRETE:0)
Block(2,38,3,CONCRETE:0)
Block(2,38,4,CONCRETE:0)
Block(2,38,5,CONCRETE:0)
Block(2,38,6,CONCRETE:0)
Block(2,38,7,CONCRETE:0)
Block(2,38,8,CONCRETE:6)
Block(2,38,9,CONCRETE:6)
Block(2,39,-6,CONCRETE:6)
Block(2,39,-5,CONCRETE:6)
Block(2,39,-4,CONCRETE:6)
Block(2,39,-3,CONCRETE:0)
Block(2,39,-2,CONCRETE:0)
Block(2,39,-1,CONCRETE:0)
Block(2,39,0,CONCRETE:0)
Block(2,39,1,CONCRETE:0)
Block(2,39,2,CONCRETE:0)
Block(2,39,3,CONCRETE:0)
Block(2,39,4,CONCRETE:0)
Block(2,39,5,CONCRETE:0)
Block(2,39,6,CONCRETE:0)
Block(2,39,7,CONCRETE:0)
Block(2,39,8,CONCRETE:0)
Block(2,40,-6,CONCRETE:6)
Block(2,40,-5,CONCRETE:6)
Block(2,40,-4,CONCRETE:6)
Block(2,40,-3,CONCRETE:0)
Block(2,40,-2,CONCRETE:0)
Block(2,40,-1,CONCRETE:0)
Block(2,40,0,CONCRETE:0)
Block(2,40,1,CONCRETE:0)
Block(2,40,2,CONCRETE:0)
Block(2,40,3,CONCRETE:0)
Block(2,40,4,CONCRETE:0)
Block(2,40,5,CONCRETE:0)
Block(2,40,6,CONCRETE:0)
Block(2,40,7,CONCRETE:0)
Block(2,40,8,CONCRETE:6)
Block(2,41,-7,CONCRETE:6)
Block(2,41,-6,CONCRETE:6)
Block(2,41,-5,CONCRETE:6)
Block(2,41,-4,CONCRETE:6)
Block(2,41,-3,CONCRETE:0)
Block(2,41,-2,CONCRETE:0)
Block(2,41,-1,CONCRETE:0)
Block(2,41,0,CONCRETE:0)
Block(2,41,1,CONCRETE:0)
Block(2,41,2,CONCRETE:0)
Block(2,41,3,CONCRETE:0)
Block(2,41,4,CONCRETE:0)
Block(2,41,5,CONCRETE:0)
Block(2,41,6,CONCRETE:0)
Block(2,41,7,CONCRETE:6)
Block(2,41,8,CONCRETE:6)
Block(2,42,-7,CONCRETE:6)
Block(2,42,-6,CONCRETE:6)
Block(2,42,-5,CONCRETE:6)
Block(2,42,-4,CONCRETE:6)
Block(2,42,-3,CONCRETE:6)
Block(2,42,-2,CONCRETE:0)
Block(2,42,-1,CONCRETE:0)
Block(2,42,0,CONCRETE:0)
Block(2,42,1,CONCRETE:0)
Block(2,42,2,CONCRETE:0)
Block(2,42,3,CONCRETE:0)
Block(2,42,4,CONCRETE:0)
Block(2,42,5,CONCRETE:0)
Block(2,42,6,CONCRETE:6)
Block(2,42,7,CONCRETE:6)
Block(2,42,8,CONCRETE:6)
Block(2,42,9,CONCRETE:6)
Block(2,43,-7,CONCRETE:6)
Block(2,43,-6,CONCRETE:6)
Block(2,43,-5,CONCRETE:6)
Block(2,43,-4,CONCRETE:6)
Block(2,43,-3,CONCRETE:6)
Block(2,43,-2,CONCRETE:6)
Block(2,43,-1,CONCRETE:0)
Block(2,43,0,CONCRETE:0)
Block(2,43,1,CONCRETE:0)
Block(2,43,2,CONCRETE:0)
Block(2,43,3,CONCRETE:0)
Block(2,43,4,CONCRETE:0)
Block(2,43,5,CONCRETE:6)
Block(2,43,6,CONCRETE:6)
Block(2,43,7,CONCRETE:6)
Block(2,43,8,CONCRETE:6)
Block(2,43,9,CONCRETE:6)
Block(2,44,-7,CONCRETE:6)
Block(2,44,-6,CONCRETE:6)
Block(2,44,-5,CONCRETE:6)
Block(2,44,-4,CONCRETE:6)
Block(2,44,-3,CONCRETE:6)
Block(2,44,-2,CONCRETE:6)
Block(2,44,-1,CONCRETE:6)
Block(2,44,0,CONCRETE:6)
Block(2,44,1,CONCRETE:0)
Block(2,44,2,CONCRETE:0)
Block(2,44,3,CONCRETE:0)
Block(2,44,4,CONCRETE:6)
Block(2,44,5,CONCRETE:6)
Block(2,44,6,CONCRETE:6)
Block(2,44,7,CONCRETE:6)
Block(2,44,8,CONCRETE:6)
Block(2,44,9,CONCRETE:6)
Block(2,45,-7,CONCRETE:6)
Block(2,45,-6,CONCRETE:6)
Block(2,45,-5,CONCRETE:6)
Block(2,45,-4,CONCRETE:6)
Block(2,45,-3,CONCRETE:6)
Block(2,45,-2,CONCRETE:6)
Block(2,45,-1,CONCRETE:6)
Block(2,45,0,CONCRETE:6)
Block(2,45,1,CONCRETE:6)
Block(2,45,2,CONCRETE:6)
Block(2,45,3,CONCRETE:6)
Block(2,45,4,CONCRETE:6)
Block(2,45,5,CONCRETE:6)
Block(2,45,6,CONCRETE:6)
Block(2,45,7,CONCRETE:6)
Block(2,45,8,CONCRETE:6)
Block(2,45,9,CONCRETE:6)
Block(2,46,-6,CONCRETE:6)
Block(2,46,-5,CONCRETE:6)
Block(2,46,-4,CONCRETE:6)
Block(2,46,-3,CONCRETE:6)
Block(2,46,-2,CONCRETE:6)
Block(2,46,-1,CONCRETE:6)
Block(2,46,0,CONCRETE:6)
Block(2,46,1,CONCRETE:6)
Block(2,46,2,CONCRETE:6)
Block(2,46,3,CONCRETE:6)
Block(2,46,4,CONCRETE:6)
Block(2,46,5,CONCRETE:6)
Block(2,46,6,CONCRETE:6)
Block(2,46,7,CONCRETE:6)
Block(2,46,8,CONCRETE:6)
Block(2,47,-5,CONCRETE:6)
Block(2,47,-4,CONCRETE:6)
Block(2,47,-3,CONCRETE:6)
Block(2,47,-2,CONCRETE:6)
Block(2,47,-1,CONCRETE:6)
Block(2,47,0,CONCRETE:6)
Block(2,47,1,CONCRETE:6)
Block(2,47,2,CONCRETE:6)
Block(2,47,3,CONCRETE:6)
Block(2,48,-3,CONCRETE:6)
Block(2,48,-2,CONCRETE:6)
Block(2,48,-1,CONCRETE:6)
Block(2,48,0,CONCRETE:6)
Block(2,48,1,CONCRETE:6)
Block(2,48,2,CONCRETE:6)
Block(2,49,-2,CONCRETE:6)
Block(2,49,-1,CONCRETE:6)
Block(2,49,0,CONCRETE:6)
Block(2,49,1,CONCRETE:6)
Block(3,15,9,STAINED_CLAY:6)
Block(3,16,8,STAINED_CLAY:6)
Block(3,16,9,STAINED_CLAY:6)
Block(3,17,8,STAINED_CLAY:6)
Block(3,17,9,STAINED_CLAY:6)
Block(3,18,-6,STAINED_CLAY:6)
Block(3,18,-5,STAINED_CLAY:6)
Block(3,18,-4,STAINED_CLAY:6)
Block(3,19,-7,STAINED_CLAY:6)
Block(3,19,-6,STAINED_CLAY:6)
Block(3,19,-5,STAINED_CLAY:6)
Block(3,19,-4,STAINED_CLAY:6)
Block(3,20,-8,STAINED_CLAY:6)
Block(3,20,-7,STAINED_CLAY:6)
Block(3,20,-6,STAINED_CLAY:6)
Block(3,20,-5,STAINED_CLAY:6)
Block(3,21,-8,STAINED_CLAY:6)
Block(3,21,-7,STAINED_CLAY:6)
Block(3,21,-6,STAINED_CLAY:6)
Block(3,22,-10,STAINED_CLAY:6)
Block(3,22,-9,STAINED_CLAY:6)
Block(3,22,-8,STAINED_CLAY:6)
Block(3,23,-11,STAINED_CLAY:6)
Block(3,23,-10,STAINED_CLAY:6)
Block(3,23,-9,STAINED_CLAY:6)
Block(3,31,-5,CONCRETE:6)
Block(3,32,-7,CONCRETE:6)
Block(3,32,-6,CONCRETE:6)
Block(3,32,-5,CONCRETE:6)
Block(3,32,-4,CONCRETE:6)
Block(3,32,-3,CONCRETE:6)
