
#######################################################################
# +-----------------------------------------------------------------+ #
# |                            BO3 object                           | #
# +-----------------------------------------------------------------+ #
#######################################################################

Author: Unknown

Description: This BO3 was converted from a schematic using OTGEdit. The author and description information of the schematic could not be found. If you know who the author of the schematic is then please add this information.

Version: 3

SettingsMode: WriteWithoutComments


#######################################################################
# +-----------------------------------------------------------------+ #
# |                          Main settings                          | #
# +-----------------------------------------------------------------+ #
#######################################################################

Tree: false

Frequency: 1

Rarity: 10.0

RotateRandomly: true

SpawnHeight: highestSolidBlock

SpawnHeightOffset: 0

SpawnHeightVariance: 0

##############################
# Height Limits for the BO3. #
##############################

MinHeight: 0

MaxHeight: 255

######################
# Extrusion settings #
######################

ExtrudeMode: None

ExtrudeThroughBlocks: AIR

MaxBranchDepth: 10

ExcludedBiomes: All


#######################################################################
# +-----------------------------------------------------------------+ #
# |                      Source block settings                      | #
# +-----------------------------------------------------------------+ #
#######################################################################

SourceBlocks: AIR

MaxPercentageOutsideSourceBlock: 100

OutsideSourceBlock: placeAnyway

DoReplaceBlocks: true

IsOTGPlus: false


#######################################################################
# +-----------------------------------------------------------------+ #
# |                              Blocks                             | #
# +-----------------------------------------------------------------+ #
#######################################################################

Block(-5,22,2,GLOWSTONE)
Block(-5,23,1,GLOWSTONE)
Block(-5,23,2,GLOWSTONE)
Block(-5,23,3,GLOWSTONE)
Block(-5,24,2,GLOWSTONE)
Block(-5,28,-3,GLOWSTONE)
Block(-5,29,-4,GLOWSTONE)
Block(-5,29,-3,GLOWSTONE)
Block(-5,29,-2,GLOWSTONE)
Block(-5,30,-3,GLOWSTONE)
Block(-4,21,2,GLOWSTONE)
Block(-4,22,1,GLOWSTONE)
Block(-4,22,2,GLOWSTONE)
Block(-4,22,3,GLOWSTONE)
Block(-4,23,0,GLOWSTONE)
Block(-4,23,1,GLOWSTONE)
Block(-4,23,2,GLOWSTONE)
Block(-4,23,3,GLOWSTONE)
Block(-4,23,4,GLOWSTONE)
Block(-4,24,1,GLOWSTONE)
Block(-4,24,2,GLOWSTONE)
Block(-4,24,3,GLOWSTONE)
Block(-4,25,2,GLOWSTONE)
Block(-4,27,-3,GLOWSTONE)
Block(-4,28,-4,GLOWSTONE)
Block(-4,28,-3,GLOWSTONE)
Block(-4,28,-2,GLOWSTONE)
Block(-4,29,-5,GLOWSTONE)
Block(-4,29,-4,GLOWSTONE)
Block(-4,29,-3,GLOWSTONE)
Block(-4,29,-2,GLOWSTONE)
Block(-4,29,-1,GLOWSTONE)
Block(-4,30,-4,GLOWSTONE)
Block(-4,30,-3,GLOWSTONE)
Block(-4,30,-2,GLOWSTONE)
Block(-4,31,-3,GLOWSTONE)
Block(-3,9,-3,GLOWSTONE)
Block(-3,10,-4,GLOWSTONE)
Block(-3,10,-3,GLOWSTONE)
Block(-3,10,-2,GLOWSTONE)
Block(-3,11,-3,GLOWSTONE)
Block(-3,20,2,PRISMARINE:0)
Block(-3,21,1,GLOWSTONE)
Block(-3,21,2,PRISMARINE:0)
Block(-3,21,3,GLOWSTONE)
Block(-3,22,0,GLOWSTONE)
Block(-3,22,1,GLOWSTONE)
Block(-3,22,2,PRISMARINE:0)
Block(-3,22,3,GLOWSTONE)
Block(-3,22,4,GLOWSTONE)
Block(-3,23,0,GLOWSTONE)
Block(-3,23,1,GLOWSTONE)
Block(-3,23,3,GLOWSTONE)
Block(-3,23,4,GLOWSTONE)
Block(-3,24,0,GLOWSTONE)
Block(-3,24,1,GLOWSTONE)
Block(-3,24,2,GLOWSTONE)
Block(-3,24,3,GLOWSTONE)
Block(-3,24,4,GLOWSTONE)
Block(-3,25,1,GLOWSTONE)
Block(-3,25,2,GLOWSTONE)
Block(-3,25,3,GLOWSTONE)
Block(-3,26,-3,PRISMARINE:0)
Block(-3,27,-4,GLOWSTONE)
Block(-3,27,-3,PRISMARINE:0)
Block(-3,27,-2,GLOWSTONE)
Block(-3,28,-5,GLOWSTONE)
Block(-3,28,-4,GLOWSTONE)
Block(-3,28,-3,PRISMARINE:0)
Block(-3,28,-2,GLOWSTONE)
Block(-3,28,-1,GLOWSTONE)
Block(-3,29,-5,GLOWSTONE)
Block(-3,29,-4,GLOWSTONE)
Block(-3,29,-1,GLOWSTONE)
Block(-3,30,-5,GLOWSTONE)
Block(-3,30,-4,GLOWSTONE)
Block(-3,30,-3,GLOWSTONE)
Block(-3,30,-2,GLOWSTONE)
Block(-3,30,-1,GLOWSTONE)
Block(-3,31,-4,GLOWSTONE)
Block(-3,31,-3,GLOWSTONE)
Block(-3,31,-2,GLOWSTONE)
Block(-2,8,-3,PRISMARINE:0)
Block(-2,9,-4,GLOWSTONE)
Block(-2,9,-3,PRISMARINE:0)
Block(-2,9,-2,GLOWSTONE)
Block(-2,10,-4,GLOWSTONE)
Block(-2,10,-3,GLOWSTONE)
Block(-2,10,-2,GLOWSTONE)
Block(-2,11,-4,GLOWSTONE)
Block(-2,11,-3,GLOWSTONE)
Block(-2,11,-2,GLOWSTONE)
Block(-2,19,0,PRISMARINE:0)
Block(-2,19,1,PRISMARINE:0)
Block(-2,20,1,PRISMARINE:0)
Block(-2,20,2,PRISMARINE:0)
Block(-2,21,2,GLOWSTONE)
Block(-2,22,1,GLOWSTONE)
Block(-2,22,2,GLOWSTONE)
Block(-2,22,3,GLOWSTONE)
Block(-2,23,0,GLOWSTONE)
Block(-2,23,1,GLOWSTONE)
Block(-2,23,2,GLOWSTONE)
Block(-2,23,3,GLOWSTONE)
Block(-2,23,4,GLOWSTONE)
Block(-2,24,1,GLOWSTONE)
Block(-2,24,2,GLOWSTONE)
Block(-2,24,3,GLOWSTONE)
Block(-2,25,-2,PRISMARINE:0)
Block(-2,25,2,GLOWSTONE)
Block(-2,26,-3,PRISMARINE:0)
Block(-2,26,-2,PRISMARINE:0)
Block(-2,27,-3,GLOWSTONE)
Block(-2,28,-4,GLOWSTONE)
Block(-2,28,-3,GLOWSTONE)
Block(-2,28,-2,GLOWSTONE)
Block(-2,29,-5,GLOWSTONE)
Block(-2,29,-4,GLOWSTONE)
Block(-2,29,-2,GLOWSTONE)
Block(-2,29,-1,GLOWSTONE)
Block(-2,30,-4,GLOWSTONE)
Block(-2,30,-3,GLOWSTONE)
Block(-2,30,-2,GLOWSTONE)
Block(-2,31,-3,GLOWSTONE)
Block(-1,6,-2,PRISMARINE:0)
Block(-1,6,-1,PRISMARINE:0)
Block(-1,7,-2,PRISMARINE:0)
Block(-1,9,-3,GLOWSTONE)
Block(-1,10,-4,GLOWSTONE)
Block(-1,10,-3,GLOWSTONE)
Block(-1,10,-2,GLOWSTONE)
Block(-1,11,-3,GLOWSTONE)
Block(-1,17,0,PRISMARINE:0)
Block(-1,18,0,PRISMARINE:0)
Block(-1,19,-1,PRISMARINE:0)
Block(-1,19,0,PRISMARINE:0)
Block(-1,20,-1,PRISMARINE:0)
Block(-1,21,-1,PRISMARINE:0)
Block(-1,22,-1,PRISMARINE:0)
Block(-1,22,2,GLOWSTONE)
Block(-1,23,-1,PRISMARINE:0)
Block(-1,23,1,GLOWSTONE)
Block(-1,23,2,GLOWSTONE)
Block(-1,23,3,GLOWSTONE)
Block(-1,24,-1,PRISMARINE:0)
Block(-1,24,2,GLOWSTONE)
Block(-1,25,-2,PRISMARINE:0)
Block(-1,25,-1,PRISMARINE:0)
Block(-1,26,-1,PRISMARINE:0)
Block(-1,28,-3,GLOWSTONE)
Block(-1,29,-4,GLOWSTONE)
Block(-1,29,-3,GLOWSTONE)
Block(-1,29,-2,GLOWSTONE)
Block(-1,30,-3,GLOWSTONE)
Block(-1,30,1,GLOWSTONE)
Block(-1,31,0,GLOWSTONE)
Block(-1,31,1,GLOWSTONE)
Block(-1,31,2,GLOWSTONE)
Block(-1,32,1,GLOWSTONE)
Block(0,0,-1,PRISMARINE:0)
Block(0,1,-1,PRISMARINE:0)
Block(0,2,-1,PRISMARINE:0)
Block(0,3,-1,PRISMARINE:0)
Block(0,4,-1,PRISMARINE:0)
Block(0,5,-1,PRISMARINE:0)
Block(0,6,-1,PRISMARINE:0)
Block(0,12,-1,PRISMARINE:0)
Block(0,12,0,PRISMARINE:0)
Block(0,13,0,PRISMARINE:0)
Block(0,14,0,PRISMARINE:0)
Block(0,15,0,PRISMARINE:0)
Block(0,16,-1,PRISMARINE:0)
Block(0,16,0,PRISMARINE:0)
Block(0,17,0,PRISMARINE:0)
Block(0,26,-1,PRISMARINE:0)
Block(0,26,0,PRISMARINE:0)
Block(0,27,0,PRISMARINE:0)
Block(0,29,1,GLOWSTONE)
Block(0,30,0,GLOWSTONE)
Block(0,30,1,GLOWSTONE)
Block(0,30,2,GLOWSTONE)
Block(0,31,-1,GLOWSTONE)
Block(0,31,0,GLOWSTONE)
Block(0,31,1,GLOWSTONE)
Block(0,31,2,GLOWSTONE)
Block(0,31,3,GLOWSTONE)
Block(0,32,0,GLOWSTONE)
Block(0,32,1,GLOWSTONE)
Block(0,32,2,GLOWSTONE)
Block(0,33,1,GLOWSTONE)
Block(1,6,-1,PRISMARINE:0)
Block(1,7,-1,PRISMARINE:0)
Block(1,8,-1,PRISMARINE:0)
Block(1,9,-1,PRISMARINE:0)
Block(1,10,-1,PRISMARINE:0)
Block(1,11,-1,PRISMARINE:0)
Block(1,12,-1,PRISMARINE:0)
Block(1,12,1,PRISMARINE:0)
Block(1,14,2,GLOWSTONE)
Block(1,15,1,GLOWSTONE)
Block(1,15,2,GLOWSTONE)
Block(1,15,3,GLOWSTONE)
Block(1,16,-2,PRISMARINE:0)
Block(1,16,-1,PRISMARINE:0)
Block(1,16,2,GLOWSTONE)
Block(1,27,0,PRISMARINE:0)
Block(1,28,0,PRISMARINE:0)
Block(1,29,0,PRISMARINE:0)
Block(1,29,1,PRISMARINE:0)
Block(1,29,2,GLOWSTONE)
Block(1,30,-1,GLOWSTONE)
Block(1,30,0,GLOWSTONE)
Block(1,30,1,PRISMARINE:0)
Block(1,30,2,GLOWSTONE)
Block(1,30,3,GLOWSTONE)
Block(1,31,-1,GLOWSTONE)
Block(1,31,0,GLOWSTONE)
Block(1,31,2,GLOWSTONE)
Block(1,31,3,GLOWSTONE)
Block(1,32,-1,GLOWSTONE)
Block(1,32,0,GLOWSTONE)
Block(1,32,1,GLOWSTONE)
Block(1,32,2,GLOWSTONE)
Block(1,32,3,GLOWSTONE)
Block(1,33,0,GLOWSTONE)
Block(1,33,1,GLOWSTONE)
Block(1,33,2,GLOWSTONE)
Block(2,13,2,PRISMARINE:0)
Block(2,14,1,GLOWSTONE)
Block(2,14,2,PRISMARINE:0)
Block(2,14,3,GLOWSTONE)
Block(2,15,1,GLOWSTONE)
Block(2,15,3,GLOWSTONE)
Block(2,16,-2,PRISMARINE:0)
Block(2,16,1,GLOWSTONE)
Block(2,16,2,GLOWSTONE)
Block(2,16,3,GLOWSTONE)
Block(2,17,-2,PRISMARINE:0)
Block(2,20,-2,GLOWSTONE)
Block(2,21,-3,GLOWSTONE)
Block(2,21,-2,GLOWSTONE)
Block(2,21,-1,GLOWSTONE)
Block(2,22,-2,GLOWSTONE)
Block(2,29,1,GLOWSTONE)
Block(2,30,0,GLOWSTONE)
Block(2,30,1,GLOWSTONE)
Block(2,30,2,GLOWSTONE)
Block(2,31,-1,GLOWSTONE)
Block(2,31,0,GLOWSTONE)
Block(2,31,1,GLOWSTONE)
Block(2,31,2,GLOWSTONE)
Block(2,31,3,GLOWSTONE)
Block(2,32,0,GLOWSTONE)
Block(2,32,1,GLOWSTONE)
Block(2,32,2,GLOWSTONE)
Block(2,33,1,GLOWSTONE)
Block(3,14,2,GLOWSTONE)
Block(3,15,1,GLOWSTONE)
Block(3,15,2,GLOWSTONE)
Block(3,15,3,GLOWSTONE)
Block(3,16,2,GLOWSTONE)
Block(3,17,-2,PRISMARINE:0)
Block(3,18,-2,PRISMARINE:0)
Block(3,19,-2,PRISMARINE:0)
Block(3,20,-3,GLOWSTONE)
Block(3,20,-2,PRISMARINE:0)
Block(3,20,-1,GLOWSTONE)
Block(3,21,-3,GLOWSTONE)
Block(3,21,-1,GLOWSTONE)
Block(3,22,-3,GLOWSTONE)
Block(3,22,-2,GLOWSTONE)
Block(3,22,-1,GLOWSTONE)
Block(3,30,1,GLOWSTONE)
Block(3,31,0,GLOWSTONE)
Block(3,31,1,GLOWSTONE)
Block(3,31,2,GLOWSTONE)
Block(3,32,1,GLOWSTONE)
Block(4,20,-2,GLOWSTONE)
Block(4,21,-3,GLOWSTONE)
Block(4,21,-2,GLOWSTONE)
Block(4,21,-1,GLOWSTONE)
Block(4,22,-2,GLOWSTONE)

#######################################################################
# +-----------------------------------------------------------------+ #
# |                            BO3 checks                           | #
# +-----------------------------------------------------------------+ #
#######################################################################

BlockCheck(0,-1,-1,GRASS:0,DIRT:0)

#######################################################################
# +-----------------------------------------------------------------+ #
# |                             Branches                            | #
# +-----------------------------------------------------------------+ #
#######################################################################


#######################################################################
# +-----------------------------------------------------------------+ #
# |                             Entities                            | #
# +-----------------------------------------------------------------+ #
#######################################################################


#######################################################################
# +-----------------------------------------------------------------+ #
# |                            Particles                            | #
# +-----------------------------------------------------------------+ #
#######################################################################


#######################################################################
# +-----------------------------------------------------------------+ #
# |                             Spawners                            | #
# +-----------------------------------------------------------------+ #
#######################################################################


#######################################################################
# +-----------------------------------------------------------------+ #
# |                             ModData                             | #
# +-----------------------------------------------------------------+ #
#######################################################################

