
#######################################################################
# +-----------------------------------------------------------------+ #
# |                            BO3 object                           | #
# +-----------------------------------------------------------------+ #
#######################################################################

Author: Unknown

Description: This BO3 was converted from a schematic using OTGEdit. The author and description information of the schematic could not be found. If you know who the author of the schematic is then please add this information.

Version: 3

SettingsMode: WriteWithoutComments


#######################################################################
# +-----------------------------------------------------------------+ #
# |                          Main settings                          | #
# +-----------------------------------------------------------------+ #
#######################################################################

Tree: false

Frequency: 1

Rarity: 10.0

RotateRandomly: true

SpawnHeight: highestSolidBlock

SpawnHeightOffset: 0

SpawnHeightVariance: 0

##############################
# Height Limits for the BO3. #
##############################

MinHeight: 0

MaxHeight: 255

######################
# Extrusion settings #
######################

ExtrudeMode: None

ExtrudeThroughBlocks: AIR

MaxBranchDepth: 10

ExcludedBiomes: All


#######################################################################
# +-----------------------------------------------------------------+ #
# |                      Source block settings                      | #
# +-----------------------------------------------------------------+ #
#######################################################################

SourceBlocks: AIR

MaxPercentageOutsideSourceBlock: 100

OutsideSourceBlock: placeAnyway

DoReplaceBlocks: true

IsOTGPlus: false


#######################################################################
# +-----------------------------------------------------------------+ #
# |                              Blocks                             | #
# +-----------------------------------------------------------------+ #
#######################################################################

Block(-3,27,2,GLOWSTONE)
Block(-3,28,1,GLOWSTONE)
Block(-3,28,2,GLOWSTONE)
Block(-3,28,3,GLOWSTONE)
Block(-3,29,2,GLOWSTONE)
Block(-3,33,-3,GLOWSTONE)
Block(-3,34,-4,GLOWSTONE)
Block(-3,34,-3,GLOWSTONE)
Block(-3,34,-2,GLOWSTONE)
Block(-3,35,-3,GLOWSTONE)
Block(-2,17,1,GLOWSTONE)
Block(-2,18,0,GLOWSTONE)
Block(-2,18,1,GLOWSTONE)
Block(-2,18,2,GLOWSTONE)
Block(-2,19,1,GLOWSTONE)
Block(-2,26,2,GLOWSTONE)
Block(-2,27,1,GLOWSTONE)
Block(-2,27,2,GLOWSTONE)
Block(-2,27,3,GLOWSTONE)
Block(-2,28,0,GLOWSTONE)
Block(-2,28,1,GLOWSTONE)
Block(-2,28,2,GLOWSTONE)
Block(-2,28,3,GLOWSTONE)
Block(-2,28,4,GLOWSTONE)
Block(-2,29,1,GLOWSTONE)
Block(-2,29,2,GLOWSTONE)
Block(-2,29,3,GLOWSTONE)
Block(-2,30,2,GLOWSTONE)
Block(-2,32,-3,GLOWSTONE)
Block(-2,33,-4,GLOWSTONE)
Block(-2,33,-3,GLOWSTONE)
Block(-2,33,-2,GLOWSTONE)
Block(-2,34,-5,GLOWSTONE)
Block(-2,34,-4,GLOWSTONE)
Block(-2,34,-3,GLOWSTONE)
Block(-2,34,-2,GLOWSTONE)
Block(-2,34,-1,GLOWSTONE)
Block(-2,35,-4,GLOWSTONE)
Block(-2,35,-3,GLOWSTONE)
Block(-2,35,-2,GLOWSTONE)
Block(-2,36,-3,GLOWSTONE)
Block(-1,15,1,PRISMARINE:0)
Block(-1,16,1,PRISMARINE:0)
Block(-1,17,0,GLOWSTONE)
Block(-1,17,1,GLOWSTONE)
Block(-1,17,2,GLOWSTONE)
Block(-1,18,0,GLOWSTONE)
Block(-1,18,2,GLOWSTONE)
Block(-1,19,0,GLOWSTONE)
Block(-1,19,1,GLOWSTONE)
Block(-1,19,2,GLOWSTONE)
Block(-1,26,1,PRISMARINE:0)
Block(-1,26,2,PRISMARINE:0)
Block(-1,26,3,GLOWSTONE)
Block(-1,27,0,GLOWSTONE)
Block(-1,27,1,GLOWSTONE)
Block(-1,27,2,PRISMARINE:0)
Block(-1,27,3,GLOWSTONE)
Block(-1,27,4,GLOWSTONE)
Block(-1,28,0,GLOWSTONE)
Block(-1,28,1,GLOWSTONE)
Block(-1,28,2,GLOWSTONE)
Block(-1,28,3,GLOWSTONE)
Block(-1,28,4,GLOWSTONE)
Block(-1,29,0,GLOWSTONE)
Block(-1,29,1,GLOWSTONE)
Block(-1,29,2,GLOWSTONE)
Block(-1,29,3,GLOWSTONE)
Block(-1,29,4,GLOWSTONE)
Block(-1,30,1,GLOWSTONE)
Block(-1,30,2,GLOWSTONE)
Block(-1,30,3,GLOWSTONE)
Block(-1,32,-4,GLOWSTONE)
Block(-1,32,-3,GLOWSTONE)
Block(-1,32,-2,PRISMARINE:0)
Block(-1,33,-5,GLOWSTONE)
Block(-1,33,-4,GLOWSTONE)
Block(-1,33,-3,PRISMARINE:0)
Block(-1,33,-2,GLOWSTONE)
Block(-1,33,-1,GLOWSTONE)
Block(-1,34,-5,GLOWSTONE)
Block(-1,34,-4,GLOWSTONE)
Block(-1,34,-3,GLOWSTONE)
Block(-1,34,-2,GLOWSTONE)
Block(-1,34,-1,GLOWSTONE)
Block(-1,35,-5,GLOWSTONE)
Block(-1,35,-4,GLOWSTONE)
Block(-1,35,-3,GLOWSTONE)
Block(-1,35,-2,GLOWSTONE)
Block(-1,35,-1,GLOWSTONE)
Block(-1,36,-4,GLOWSTONE)
Block(-1,36,-3,GLOWSTONE)
Block(-1,36,-2,GLOWSTONE)
Block(0,14,0,PRISMARINE:0)
Block(0,14,1,PRISMARINE:0)
Block(0,15,1,PRISMARINE:0)
Block(0,17,1,GLOWSTONE)
Block(0,18,0,GLOWSTONE)
Block(0,18,1,GLOWSTONE)
Block(0,18,2,GLOWSTONE)
Block(0,19,1,GLOWSTONE)
Block(0,25,0,PRISMARINE:0)
Block(0,25,1,PRISMARINE:0)
Block(0,26,1,PRISMARINE:0)
Block(0,26,2,GLOWSTONE)
Block(0,27,1,GLOWSTONE)
Block(0,27,2,GLOWSTONE)
Block(0,27,3,GLOWSTONE)
Block(0,28,0,GLOWSTONE)
Block(0,28,1,GLOWSTONE)
Block(0,28,2,GLOWSTONE)
Block(0,28,3,GLOWSTONE)
Block(0,28,4,GLOWSTONE)
Block(0,29,1,GLOWSTONE)
Block(0,29,2,GLOWSTONE)
Block(0,29,3,GLOWSTONE)
Block(0,30,2,GLOWSTONE)
Block(0,31,-2,PRISMARINE:0)
Block(0,32,-3,GLOWSTONE)
Block(0,32,-2,PRISMARINE:0)
Block(0,33,-4,GLOWSTONE)
Block(0,33,-3,GLOWSTONE)
Block(0,33,-2,GLOWSTONE)
Block(0,34,-5,GLOWSTONE)
Block(0,34,-4,GLOWSTONE)
Block(0,34,-3,GLOWSTONE)
Block(0,34,-2,GLOWSTONE)
Block(0,34,-1,GLOWSTONE)
Block(0,35,-4,GLOWSTONE)
Block(0,35,-3,GLOWSTONE)
Block(0,35,-2,GLOWSTONE)
Block(0,36,-3,GLOWSTONE)
Block(1,8,-1,PRISMARINE:0)
Block(1,9,-1,PRISMARINE:0)
Block(1,13,-1,PRISMARINE:0)
Block(1,14,-1,PRISMARINE:0)
Block(1,14,0,PRISMARINE:0)
Block(1,15,-1,PRISMARINE:0)
Block(1,16,-1,PRISMARINE:0)
Block(1,17,-1,PRISMARINE:0)
Block(1,18,-1,PRISMARINE:0)
Block(1,19,-1,PRISMARINE:0)
Block(1,20,-1,PRISMARINE:0)
Block(1,21,-2,PRISMARINE:0)
Block(1,21,-1,PRISMARINE:0)
Block(1,22,-1,PRISMARINE:0)
Block(1,23,-1,PRISMARINE:0)
Block(1,24,-1,PRISMARINE:0)
Block(1,25,-1,PRISMARINE:0)
Block(1,25,0,PRISMARINE:0)
Block(1,26,-1,PRISMARINE:0)
Block(1,27,-1,PRISMARINE:0)
Block(1,27,2,GLOWSTONE)
Block(1,28,-1,PRISMARINE:0)
Block(1,28,1,GLOWSTONE)
Block(1,28,2,GLOWSTONE)
Block(1,28,3,GLOWSTONE)
Block(1,29,-1,PRISMARINE:0)
Block(1,29,2,GLOWSTONE)
Block(1,30,-1,PRISMARINE:0)
Block(1,31,-2,PRISMARINE:0)
Block(1,31,-1,PRISMARINE:0)
Block(1,33,-3,GLOWSTONE)
Block(1,34,-4,GLOWSTONE)
Block(1,34,-3,GLOWSTONE)
Block(1,34,-2,GLOWSTONE)
Block(1,35,-3,GLOWSTONE)
Block(2,0,-2,PRISMARINE:0)
Block(2,0,-1,PRISMARINE:0)
Block(2,1,-2,PRISMARINE:0)
Block(2,1,-1,PRISMARINE:0)
Block(2,2,-1,PRISMARINE:0)
Block(2,3,-1,PRISMARINE:0)
Block(2,4,-1,PRISMARINE:0)
Block(2,5,-1,PRISMARINE:0)
Block(2,6,-1,PRISMARINE:0)
Block(2,7,-1,PRISMARINE:0)
Block(2,8,-1,PRISMARINE:0)
Block(2,9,-1,PRISMARINE:0)
Block(2,10,-1,PRISMARINE:0)
Block(2,11,-1,PRISMARINE:0)
Block(2,11,0,PRISMARINE:0)
Block(2,12,-1,PRISMARINE:0)
Block(2,12,0,PRISMARINE:0)
Block(2,13,-1,PRISMARINE:0)
Block(2,13,0,PRISMARINE:0)
Block(2,14,-1,PRISMARINE:0)
Block(2,14,0,PRISMARINE:0)
Block(2,15,-1,PRISMARINE:0)
Block(2,16,-1,PRISMARINE:0)
Block(2,17,-1,PRISMARINE:0)
Block(2,21,-3,PRISMARINE:0)
Block(2,21,-2,PRISMARINE:0)
Block(2,22,-3,PRISMARINE:0)
Block(2,25,-4,GLOWSTONE)
Block(2,26,-5,GLOWSTONE)
Block(2,26,-4,GLOWSTONE)
Block(2,26,-3,GLOWSTONE)
Block(2,27,-4,GLOWSTONE)
Block(2,29,-1,PRISMARINE:0)
Block(2,30,-1,PRISMARINE:0)
Block(2,31,-1,PRISMARINE:0)
Block(2,31,0,PRISMARINE:0)
Block(3,0,-2,PRISMARINE:0)
Block(3,0,-1,PRISMARINE:0)
Block(3,1,-2,PRISMARINE:0)
Block(3,1,-1,PRISMARINE:0)
Block(3,2,-1,PRISMARINE:0)
Block(3,3,-1,PRISMARINE:0)
Block(3,13,-2,PRISMARINE:0)
Block(3,13,-1,PRISMARINE:0)
Block(3,14,-2,PRISMARINE:0)
Block(3,14,-1,PRISMARINE:0)
Block(3,16,-3,GLOWSTONE)
Block(3,17,-4,GLOWSTONE)
Block(3,17,-3,GLOWSTONE)
Block(3,17,-2,GLOWSTONE)
Block(3,18,-3,GLOWSTONE)
Block(3,22,-3,PRISMARINE:0)
Block(3,23,-4,PRISMARINE:0)
Block(3,23,-3,PRISMARINE:0)
Block(3,24,-4,PRISMARINE:0)
Block(3,25,-5,GLOWSTONE)
Block(3,25,-4,GLOWSTONE)
Block(3,25,-3,GLOWSTONE)
Block(3,26,-5,GLOWSTONE)
Block(3,26,-3,GLOWSTONE)
Block(3,27,-5,GLOWSTONE)
Block(3,27,-4,GLOWSTONE)
Block(3,27,-3,GLOWSTONE)
Block(3,31,0,PRISMARINE:0)
Block(3,32,0,PRISMARINE:0)
Block(3,32,1,PRISMARINE:0)
Block(3,36,2,GLOWSTONE)
Block(3,37,1,GLOWSTONE)
Block(3,37,2,GLOWSTONE)
Block(3,37,3,GLOWSTONE)
Block(3,38,2,GLOWSTONE)
Block(4,14,-3,PRISMARINE:0)
Block(4,14,-2,PRISMARINE:0)
Block(4,15,-3,PRISMARINE:0)
Block(4,16,-4,GLOWSTONE)
Block(4,16,-3,PRISMARINE:0)
Block(4,16,-2,GLOWSTONE)
Block(4,17,-4,GLOWSTONE)
Block(4,17,-2,GLOWSTONE)
Block(4,18,-4,GLOWSTONE)
Block(4,18,-3,GLOWSTONE)
Block(4,18,-2,GLOWSTONE)
Block(4,25,-4,GLOWSTONE)
Block(4,26,-5,GLOWSTONE)
Block(4,26,-4,GLOWSTONE)
Block(4,26,-3,GLOWSTONE)
Block(4,27,-4,GLOWSTONE)
Block(4,32,1,PRISMARINE:0)
Block(4,33,1,PRISMARINE:0)
Block(4,34,1,PRISMARINE:0)
Block(4,34,2,PRISMARINE:0)
Block(4,35,2,PRISMARINE:0)
Block(4,36,1,GLOWSTONE)
Block(4,36,2,GLOWSTONE)
Block(4,36,3,GLOWSTONE)
Block(4,37,0,GLOWSTONE)
Block(4,37,1,GLOWSTONE)
Block(4,37,2,GLOWSTONE)
Block(4,37,3,GLOWSTONE)
Block(4,37,4,GLOWSTONE)
Block(4,38,1,GLOWSTONE)
Block(4,38,2,GLOWSTONE)
Block(4,38,3,GLOWSTONE)
Block(4,39,2,GLOWSTONE)
Block(5,16,-3,GLOWSTONE)
Block(5,17,-4,GLOWSTONE)
Block(5,17,-3,GLOWSTONE)
Block(5,17,-2,GLOWSTONE)
Block(5,18,-3,GLOWSTONE)
Block(5,35,1,GLOWSTONE)
Block(5,35,2,PRISMARINE:0)
Block(5,35,3,GLOWSTONE)
Block(5,36,0,GLOWSTONE)
Block(5,36,1,GLOWSTONE)
Block(5,36,2,GLOWSTONE)
Block(5,36,3,GLOWSTONE)
Block(5,36,4,GLOWSTONE)
Block(5,37,0,GLOWSTONE)
Block(5,37,1,GLOWSTONE)
Block(5,37,2,GLOWSTONE)
Block(5,37,3,GLOWSTONE)
Block(5,37,4,GLOWSTONE)
Block(5,38,0,GLOWSTONE)
Block(5,38,1,GLOWSTONE)
Block(5,38,2,GLOWSTONE)
Block(5,38,3,GLOWSTONE)
Block(5,38,4,GLOWSTONE)
Block(5,39,1,GLOWSTONE)
Block(5,39,2,GLOWSTONE)
Block(5,39,3,GLOWSTONE)
Block(6,35,2,GLOWSTONE)
Block(6,36,1,GLOWSTONE)
Block(6,36,2,GLOWSTONE)
Block(6,36,3,GLOWSTONE)
Block(6,37,0,GLOWSTONE)
Block(6,37,1,GLOWSTONE)
Block(6,37,2,GLOWSTONE)
Block(6,37,3,GLOWSTONE)
Block(6,37,4,GLOWSTONE)
Block(6,38,1,GLOWSTONE)
Block(6,38,2,GLOWSTONE)
Block(6,38,3,GLOWSTONE)
Block(6,39,2,GLOWSTONE)
Block(7,36,2,GLOWSTONE)
Block(7,37,1,GLOWSTONE)
Block(7,37,2,GLOWSTONE)
Block(7,37,3,GLOWSTONE)
Block(7,38,2,GLOWSTONE)

#######################################################################
# +-----------------------------------------------------------------+ #
# |                            BO3 checks                           | #
# +-----------------------------------------------------------------+ #
#######################################################################

BlockCheck(2,-1,-2,GRASS:0,DIRT:0)
BlockCheck(2,-1,-1,GRASS:0,DIRT:0)

#######################################################################
# +-----------------------------------------------------------------+ #
# |                             Branches                            | #
# +-----------------------------------------------------------------+ #
#######################################################################


#######################################################################
# +-----------------------------------------------------------------+ #
# |                             Entities                            | #
# +-----------------------------------------------------------------+ #
#######################################################################


#######################################################################
# +-----------------------------------------------------------------+ #
# |                            Particles                            | #
# +-----------------------------------------------------------------+ #
#######################################################################


#######################################################################
# +-----------------------------------------------------------------+ #
# |                             Spawners                            | #
# +-----------------------------------------------------------------+ #
#######################################################################


#######################################################################
# +-----------------------------------------------------------------+ #
# |                             ModData                             | #
# +-----------------------------------------------------------------+ #
#######################################################################

