
#######################################################################
# +-----------------------------------------------------------------+ #
# |                            BO3 object                           | #
# +-----------------------------------------------------------------+ #
#######################################################################

Author: LordSmellyPants

Description: Converted version of the BO2 FloatingIsland1

Version: 3

SettingsMode: WriteWithoutComments


#######################################################################
# +-----------------------------------------------------------------+ #
# |                          Main settings                          | #
# +-----------------------------------------------------------------+ #
#######################################################################

Tree: false

Frequency: 1

Rarity: 5.0

RotateRandomly: true

SpawnHeight: randomY

SpawnHeightOffset: 0

SpawnHeightVariance: 0

##############################
# Height Limits for the BO3. #
##############################

MinHeight: 30

MaxHeight: 110

######################
# Extrusion settings #
######################

ExtrudeMode: None

ExtrudeThroughBlocks: AIR

MaxBranchDepth: 10

ExcludedBiomes: 


#######################################################################
# +-----------------------------------------------------------------+ #
# |                      Source block settings                      | #
# +-----------------------------------------------------------------+ #
#######################################################################

SourceBlocks: AIR,STATIONARY_WATER:0

MaxPercentageOutsideSourceBlock: 0

OutsideSourceBlock: placeAnyway

DoReplaceBlocks: true

IsOTGPlus: false


#######################################################################
# +-----------------------------------------------------------------+ #
# |                              Blocks                             | #
# +-----------------------------------------------------------------+ #
#######################################################################

Block(6,9,1,STONE:0)
Block(-6,9,-6,STONE:0)
Block(0,4,-8,AIR)
Block(-6,8,-6,STONE:0)
Block(2,10,4,GRASS:0)
Block(0,3,-8,AIR)
Block(6,6,1,STONE:0)
Block(-6,7,-6,STONE:0)
Block(6,5,1,STONE:0)
Block(-6,6,-6,AIR)
Block(6,8,1,STONE:0)
Block(6,7,1,STONE:0)
Block(6,4,1,STONE:0)
Block(0,6,-8,STONE:0)
Block(0,5,-8,AIR)
Block(0,8,-8,STONE:0)
Block(0,7,-8,STONE:0)
Block(0,9,-8,STONE:0)
Block(2,16,-5,GRASS:0)
Block(2,15,-5,STONE:0)
Block(5,2,-3,AIR)
Block(2,14,-5,STONE:0)
Block(2,13,-5,STONE:0)
Block(5,5,-3,STONE:0)
Block(2,12,-5,STONE:0)
Block(5,6,-3,STONE:0)
Block(2,11,-5,STONE:0)
Block(2,10,-5,STONE:0)
Block(5,3,-3,AIR)
Block(5,4,-3,STONE:0)
Block(5,9,-3,STONE:0)
Block(5,7,-3,STONE:0)
Block(5,8,-3,STONE:0)
Block(1,10,2,STONE:0)
Block(1,11,2,STONE:0)
Block(1,12,2,GRASS:0)
Block(1,13,2,AIR)
Block(1,14,2,AIR)
Block(1,15,2,AIR)
Block(1,16,2,AIR)
Block(1,17,2,AIR)
Block(4,10,-2,STONE:0)
Block(4,11,-2,STONE:0)
Block(4,12,-2,STONE:0)
Block(4,13,-2,GRASS:0)
Block(-3,11,3,GRASS:0)
Block(-3,10,3,STONE:0)
Block(0,1,0,STONE:0)
Block(0,0,0,STONE:0)
Block(0,3,0,STONE:0)
Block(0,2,0,STONE:0)
Block(0,5,0,STONE:0)
Block(0,4,0,STONE:0)
Block(0,7,0,STONE:0)
Block(0,6,0,STONE:0)
Block(-2,9,-5,STONE:0)
Block(4,9,-5,STONE:0)
Block(-5,8,-8,STONE:0)
Block(4,8,-5,STONE:0)
Block(1,8,-2,STONE:0)
Block(1,9,-2,STONE:0)
Block(-2,5,-5,STONE:0)
Block(1,6,-2,STONE:0)
Block(-2,6,-5,STONE:0)
Block(1,7,-2,STONE:0)
Block(1,4,-2,STONE:0)
Block(-2,7,-5,STONE:0)
Block(4,7,-5,STONE:0)
Block(-5,9,-8,STONE:0)
Block(1,5,-2,STONE:0)
Block(4,6,-5,STONE:0)
Block(-2,8,-5,STONE:0)
Block(1,2,-2,STONE:0)
Block(1,3,-2,STONE:0)
Block(1,0,-2,STONE:0)
Block(1,1,-2,STONE:0)
Block(-2,4,-5,STONE:0)
Block(-4,8,-1,STONE:0)
Block(-4,7,-1,STONE:0)
Block(-5,14,-4,GRASS:0)
Block(-4,9,-1,STONE:0)
Block(-4,4,-1,STONE:0)
Block(-5,12,-4,STONE:0)
Block(-4,3,-1,STONE:0)
Block(-5,13,-4,STONE:0)
Block(-4,6,-1,STONE:0)
Block(-5,10,-4,STONE:0)
Block(-4,5,-1,STONE:0)
Block(-5,11,-4,STONE:0)
Block(-5,8,1,STONE:0)
Block(-5,7,1,STONE:0)
Block(-5,9,1,STONE:0)
Block(-5,4,1,AIR)
Block(-5,6,1,STONE:0)
Block(-5,5,1,STONE:0)
Block(-4,9,3,STONE:0)
Block(-4,8,3,STONE:0)
Block(-4,7,3,STONE:0)
Block(-4,6,3,STONE:0)
Block(6,11,-3,GRASS:0)
Block(4,12,1,STONE:0)
Block(4,13,1,GRASS:0)
Block(-4,5,3,STONE:0)
Block(4,10,1,STONE:0)
Block(-4,4,3,STONE:0)
Block(4,11,1,STONE:0)
Block(-4,3,3,AIR)
Block(-4,2,3,AIR)
Block(-2,14,-5,STONE:0)
Block(-2,15,-5,STONE:0)
Block(-3,8,5,GRASS:0)
Block(-2,16,-5,GRASS:0)
Block(6,10,-3,STONE:0)
Block(5,16,-8,GRASS:0)
Block(-6,10,2,GRASS:0)
Block(5,15,-8,STONE:0)
Block(5,14,-8,STONE:0)
Block(-2,10,-5,STONE:0)
Block(-2,11,-5,STONE:0)
Block(-2,12,-5,STONE:0)
Block(-2,13,-5,STONE:0)
Block(8,7,-2,AIR)
Block(8,8,-2,GRASS:0)
Block(0,9,0,STONE:0)
Block(0,8,0,STONE:0)
Block(0,2,-4,STONE:0)
Block(0,4,-4,STONE:0)
Block(0,3,-4,STONE:0)
Block(0,6,-4,STONE:0)
Block(0,5,-4,STONE:0)
Block(0,8,-4,STONE:0)
Block(0,7,-4,STONE:0)
Block(4,2,1,STONE:0)
Block(7,9,3,GRASS:0)
Block(7,8,3,STONE:0)
Block(7,7,3,STONE:0)
Block(7,6,3,STONE:0)
Block(0,9,-4,STONE:0)
Block(8,8,1,STONE:0)
Block(8,7,1,STONE:0)
Block(8,9,1,GRASS:0)
Block(-1,9,-7,STONE:0)
Block(3,16,-7,GRASS:0)
Block(-1,8,-7,STONE:0)
Block(-1,7,-7,STONE:0)
Block(3,14,-7,STONE:0)
Block(-1,6,-7,STONE:0)
Block(3,15,-7,STONE:0)
Block(-1,5,-7,STONE:0)
Block(3,12,-7,STONE:0)
Block(7,10,0,GRASS:0)
Block(3,13,-7,STONE:0)
Block(-1,4,-7,AIR)
Block(3,10,-7,STONE:0)
Block(3,11,-7,STONE:0)
Block(-2,12,-1,STONE:0)
Block(-2,13,-1,GRASS:0)
Block(-2,10,-1,STONE:0)
Block(-2,11,-1,STONE:0)
Block(-2,16,-1,AIR)
Block(-2,14,-1,AIR)
Block(-2,15,-1,AIR)
Block(5,10,-4,STONE:0)
Block(5,12,-4,GRASS:0)
Block(5,11,-4,STONE:0)
Block(-2,10,1,STONE:0)
Block(-2,12,1,GRASS:0)
Block(-2,11,1,STONE:0)
Block(0,13,0,GRASS:0)
Block(0,12,0,STONE:0)
Block(0,11,0,STONE:0)
Block(0,18,0,AIR)
Block(0,17,0,LEAVES:3)
Block(0,16,0,LEAVES:3)
Block(2,6,-4,STONE:0)
Block(2,5,-4,STONE:0)
Block(2,4,-4,STONE:0)
Block(2,3,-4,STONE:0)
Block(0,10,0,STONE:0)
Block(2,9,-4,STONE:0)
Block(2,8,-4,STONE:0)
Block(2,7,-4,STONE:0)
Block(2,10,0,STONE:0)
Block(2,11,0,STONE:0)
Block(2,12,0,STONE:0)
Block(2,17,0,LEAVES:3)
Block(2,18,0,LEAVES:3)
Block(2,19,0,AIR)
Block(2,13,0,GRASS:0)
Block(2,16,0,LEAVES:3)
Block(0,10,-8,STONE:0)
Block(-1,10,-3,STONE:0)
Block(0,11,-8,STONE:0)
Block(0,12,-8,STONE:0)
Block(-1,12,-3,STONE:0)
Block(-2,9,-1,STONE:0)
Block(-1,11,-3,STONE:0)
Block(0,13,-8,STONE:0)
Block(-2,4,-1,STONE:0)
Block(-2,3,-1,STONE:0)
Block(-2,2,-1,STONE:0)
Block(-2,1,-1,STONE:0)
Block(-2,8,-1,STONE:0)
Block(0,14,-8,STONE:0)
Block(-2,7,-1,STONE:0)
Block(0,15,-8,STONE:0)
Block(-2,6,-1,STONE:0)
Block(-7,8,1,DIRT:0)
Block(0,16,-8,GRASS:0)
Block(-2,5,-1,STONE:0)
Block(-7,7,1,DIRT:0)
Block(-4,4,-5,AIR)
Block(-4,3,-5,AIR)
Block(-4,6,-5,STONE:0)
Block(-4,5,-5,STONE:0)
Block(5,11,3,GRASS:0)
Block(-4,2,-5,AIR)
Block(-6,9,3,GRASS:0)
Block(-6,8,3,STONE:0)
Block(-6,7,3,STONE:0)
Block(-4,8,-5,STONE:0)
Block(-1,14,-3,STONE:0)
Block(-6,6,3,STONE:0)
Block(-4,7,-5,STONE:0)
Block(-1,13,-3,STONE:0)
Block(-1,16,-3,LEAVES:3)
Block(-4,9,-5,STONE:0)
Block(-1,15,-3,GRASS:0)
Block(5,10,3,STONE:0)
Block(-4,13,-2,GRASS:0)
Block(-4,12,-2,STONE:0)
Block(-4,11,-2,STONE:0)
Block(-4,10,-2,STONE:0)
Block(-4,11,1,GRASS:0)
Block(4,12,-6,STONE:0)
Block(4,13,-6,STONE:0)
Block(4,14,-6,GRASS:0)
Block(4,15,-6,AIR)
Block(4,10,-6,STONE:0)
Block(4,11,-6,STONE:0)
Block(-4,10,1,STONE:0)
Block(5,9,3,STONE:0)
Block(5,8,3,STONE:0)
Block(5,7,3,STONE:0)
Block(4,8,5,GRASS:0)
Block(5,6,3,STONE:0)
Block(5,5,3,STONE:0)
Block(5,4,3,STONE:0)
Block(3,5,-3,STONE:0)
Block(3,6,-3,STONE:0)
Block(3,7,-3,STONE:0)
Block(3,8,-3,STONE:0)
Block(3,9,-3,STONE:0)
Block(3,1,-3,AIR)
Block(3,2,-3,AIR)
Block(3,3,-3,STONE:0)
Block(3,4,-3,STONE:0)
Block(-1,5,0,STONE:0)
Block(-1,4,0,STONE:0)
Block(-1,7,0,STONE:0)
Block(-1,6,0,STONE:0)
Block(-1,9,0,STONE:0)
Block(-1,8,0,STONE:0)
Block(-1,1,0,STONE:0)
Block(-1,3,0,STONE:0)
Block(-1,2,0,STONE:0)
Block(-3,10,-3,STONE:0)
Block(-1,6,-2,STONE:0)
Block(0,16,-1,LEAVES:3)
Block(-1,5,-2,STONE:0)
Block(2,9,-8,STONE:0)
Block(0,15,-1,AIR)
Block(-1,4,-2,STONE:0)
Block(2,8,-8,STONE:0)
Block(0,18,-1,LEAVES:3)
Block(-1,3,-2,STONE:0)
Block(2,7,-8,STONE:0)
Block(0,17,-1,LEAVES:3)
Block(-1,2,-2,STONE:0)
Block(-1,1,-2,STONE:0)
Block(0,19,-1,LEAVES:3)
Block(-2,16,-9,GRASS:0)
Block(-2,14,-9,STONE:0)
Block(-2,15,-9,STONE:0)
Block(-2,12,-9,STONE:0)
Block(-1,9,-2,STONE:0)
Block(-2,13,-9,STONE:0)
Block(-1,8,-2,STONE:0)
Block(-2,10,-9,STONE:0)
Block(-1,7,-2,STONE:0)
Block(7,10,-1,GRASS:0)
Block(-2,11,-9,STONE:0)
Block(-1,10,2,STONE:0)
Block(-3,12,-3,STONE:0)
Block(-3,11,-3,STONE:0)
Block(0,10,-1,STONE:0)
Block(-1,12,2,GRASS:0)
Block(-3,14,-3,STONE:0)
Block(-1,11,2,STONE:0)
Block(-3,13,-3,STONE:0)
Block(0,12,-1,STONE:0)
Block(-3,16,-3,AIR)
Block(0,11,-1,STONE:0)
Block(-3,15,-3,GRASS:0)
Block(0,14,-1,LONG_GRASS:1)
Block(0,13,-1,GRASS:0)
Block(2,7,4,STONE:0)
Block(2,6,4,STONE:0)
Block(2,9,4,STONE:0)
Block(2,8,4,STONE:0)
Block(2,3,4,STONE:0)
Block(2,5,4,STONE:0)
Block(2,4,4,STONE:0)
Block(3,6,2,STONE:0)
Block(3,5,2,STONE:0)
Block(3,4,2,STONE:0)
Block(3,3,2,STONE:0)
Block(3,9,2,STONE:0)
Block(3,8,2,STONE:0)
Block(3,7,2,STONE:0)
Block(-4,8,-9,GRASS:0)
Block(3,11,-3,STONE:0)
Block(3,10,-3,STONE:0)
Block(-4,7,-9,AIR)
Block(3,13,-3,STONE:0)
Block(3,12,-3,STONE:0)
Block(-4,4,-9,AIR)
Block(-4,3,-9,AIR)
Block(-4,6,-9,AIR)
Block(-4,5,-9,AIR)
Block(4,5,0,STONE:0)
Block(4,4,0,STONE:0)
Block(4,7,0,STONE:0)
Block(4,6,0,STONE:0)
Block(4,9,0,STONE:0)
Block(4,8,0,STONE:0)
Block(3,14,-3,GRASS:0)
Block(3,17,-3,LEAVES:3)
Block(3,16,-3,LEAVES:3)
Block(4,3,0,STONE:0)
Block(4,2,0,STONE:0)
Block(-4,10,-9,DIRT:0)
Block(-4,11,-9,STONE:0)
Block(3,2,2,STONE:0)
Block(-4,12,-9,STONE:0)
Block(-6,10,-3,STONE:0)
Block(-6,11,-3,GRASS:0)
Block(-3,6,-7,STONE:0)
Block(-3,7,-7,STONE:0)
Block(-3,8,-7,STONE:0)
Block(-3,9,-7,STONE:0)
Block(0,10,4,GRASS:0)
Block(3,7,-7,STONE:0)
Block(3,8,-7,STONE:0)
Block(1,16,-3,LEAVES:3)
Block(1,17,-3,LEAVES:3)
Block(-1,16,-7,GRASS:0)
Block(-1,15,-7,STONE:0)
Block(1,10,-3,STONE:0)
Block(-1,14,-7,STONE:0)
Block(1,11,-3,STONE:0)
Block(-1,13,-7,STONE:0)
Block(-1,12,-7,STONE:0)
Block(1,12,-3,STONE:0)
Block(-1,11,-7,STONE:0)
Block(1,13,-3,STONE:0)
Block(-1,10,-7,STONE:0)
Block(1,14,-3,STONE:0)
Block(1,15,-3,GRASS:0)
Block(-3,7,0,STONE:0)
Block(3,9,-7,STONE:0)
Block(-3,6,0,STONE:0)
Block(-3,9,0,STONE:0)
Block(-3,8,0,STONE:0)
Block(-3,3,0,STONE:0)
Block(-3,2,0,STONE:0)
Block(-3,5,0,STONE:0)
Block(-3,4,0,STONE:0)
Block(-7,7,-5,STONE:0)
Block(-7,8,-5,STONE:0)
Block(-7,9,-5,STONE:0)
Block(-1,2,4,AIR)
Block(-1,5,4,STONE:0)
Block(-1,4,4,STONE:0)
Block(-1,7,4,STONE:0)
Block(-1,6,4,STONE:0)
Block(-2,9,2,STONE:0)
Block(-2,8,2,STONE:0)
Block(-1,9,4,STONE:0)
Block(-2,7,2,STONE:0)
Block(-1,8,4,STONE:0)
Block(-2,6,2,STONE:0)
Block(-2,5,2,STONE:0)
Block(-2,4,2,STONE:0)
Block(-2,3,2,STONE:0)
Block(-2,2,2,STONE:0)
Block(6,8,-1,STONE:0)
Block(6,9,-1,STONE:0)
Block(6,6,-1,STONE:0)
Block(6,7,-1,STONE:0)
Block(6,4,-1,STONE:0)
Block(6,5,-1,STONE:0)
Block(-6,9,-1,STONE:0)
Block(-6,8,-1,STONE:0)
Block(-6,7,-1,STONE:0)
Block(-6,6,-1,STONE:0)
Block(-6,5,-1,STONE:0)
Block(-6,10,-7,GRASS:0)
Block(-6,4,-1,AIR)
Block(-6,11,-7,LONG_GRASS:1)
Block(-4,11,-5,STONE:0)
Block(-4,10,-5,STONE:0)
Block(-4,13,-5,STONE:0)
Block(-4,12,-5,STONE:0)
Block(-4,15,-5,STONE:0)
Block(-4,14,-5,STONE:0)
Block(-4,16,-5,GRASS:0)
Block(1,9,2,STONE:0)
Block(1,8,2,STONE:0)
Block(1,7,2,STONE:0)
Block(0,3,4,STONE:0)
Block(1,6,2,STONE:0)
Block(1,5,2,STONE:0)
Block(-5,13,-7,GRASS:0)
Block(-5,14,-7,AIR)
Block(1,8,-6,STONE:0)
Block(1,9,-6,STONE:0)
Block(1,6,-6,STONE:0)
Block(1,7,-6,STONE:0)
Block(1,4,-6,STONE:0)
Block(-5,9,-4,STONE:0)
Block(1,5,-6,STONE:0)
Block(2,7,0,STONE:0)
Block(2,6,0,STONE:0)
Block(2,9,0,STONE:0)
Block(2,8,0,STONE:0)
Block(6,10,1,STONE:0)
Block(6,11,1,DIRT:0)
Block(6,12,1,GRASS:0)
Block(-5,7,-4,STONE:0)
Block(-5,8,-4,STONE:0)
Block(-5,5,-4,STONE:0)
Block(-5,6,-4,STONE:0)
Block(5,10,-1,STONE:0)
Block(5,11,-1,STONE:0)
Block(5,12,-1,STONE:0)
Block(5,13,-1,GRASS:0)
Block(2,18,-1,LEAVES:3)
Block(2,17,-1,LEAVES:3)
Block(2,19,-1,LEAVES:3)
Block(2,14,-1,AIR)
Block(2,13,-1,GRASS:0)
Block(2,16,-1,LEAVES:3)
Block(2,15,-1,AIR)
Block(2,10,-1,STONE:0)
Block(2,12,-1,STONE:0)
Block(2,11,-1,STONE:0)
Block(-5,10,-7,STONE:0)
Block(-5,11,-7,STONE:0)
Block(-5,12,-7,STONE:0)
Block(-3,10,-7,STONE:0)
Block(-3,14,-7,STONE:0)
Block(-3,13,-7,STONE:0)
Block(-3,12,-7,STONE:0)
Block(-3,11,-7,STONE:0)
Block(-5,11,0,GRASS:0)
Block(2,3,0,STONE:0)
Block(2,2,0,STONE:0)
Block(2,5,0,STONE:0)
Block(2,4,0,STONE:0)
Block(2,1,0,STONE:0)
Block(-3,3,-3,STONE:0)
Block(-3,4,-3,STONE:0)
Block(-5,10,0,STONE:0)
Block(-3,5,-3,STONE:0)
Block(-3,6,-3,STONE:0)
Block(-3,7,-3,STONE:0)
Block(1,4,2,STONE:0)
Block(0,5,4,STONE:0)
Block(-3,8,-3,STONE:0)
Block(1,3,2,STONE:0)
Block(0,4,4,STONE:0)
Block(-3,9,-3,STONE:0)
Block(1,2,2,STONE:0)
Block(0,7,4,STONE:0)
Block(-3,16,-7,GRASS:0)
Block(1,1,2,STONE:0)
Block(0,6,4,STONE:0)
Block(-3,15,-7,STONE:0)
Block(0,9,4,STONE:0)
Block(1,0,2,AIR)
Block(0,8,4,DIRT:0)
Block(-4,9,2,STONE:0)
Block(-4,8,2,STONE:0)
Block(-4,7,2,STONE:0)
Block(5,10,2,STONE:0)
Block(5,11,2,STONE:0)
Block(5,12,2,GRASS:0)
Block(-4,6,2,STONE:0)
Block(-4,5,2,STONE:0)
Block(-4,4,2,STONE:0)
Block(-3,7,4,STONE:0)
Block(-3,6,4,STONE:0)
Block(-3,9,4,STONE:0)
Block(-3,8,4,STONE:0)
Block(-3,5,4,STONE:0)
Block(-4,12,-1,GRASS:0)
Block(-3,10,2,STONE:0)
Block(-4,11,-1,STONE:0)
Block(-4,10,-1,STONE:0)
Block(-3,12,-8,STONE:0)
Block(-3,13,-8,STONE:0)
Block(-3,12,2,GRASS:0)
Block(-3,14,-8,STONE:0)
Block(-3,11,2,STONE:0)
Block(-3,15,-8,STONE:0)
Block(-3,10,-8,STONE:0)
Block(-3,11,-8,STONE:0)
Block(-3,2,-2,STONE:0)
Block(-3,3,-2,STONE:0)
Block(-3,4,-2,STONE:0)
Block(-3,5,-2,STONE:0)
Block(-3,6,-2,STONE:0)
Block(5,9,4,GRASS:0)
Block(1,10,1,STONE:0)
Block(-3,7,-2,STONE:0)
Block(5,8,4,STONE:0)
Block(1,11,1,STONE:0)
Block(5,7,4,STONE:0)
Block(-3,8,-2,STONE:0)
Block(1,12,1,STONE:0)
Block(5,6,4,STONE:0)
Block(-3,9,-2,STONE:0)
Block(1,13,1,GRASS:0)
Block(1,16,1,LEAVES:3)
Block(1,17,1,LEAVES:3)
Block(-5,16,-5,GRASS:0)
Block(-5,15,-5,STONE:0)
Block(-5,14,-5,STONE:0)
Block(-5,13,-5,STONE:0)
Block(-5,12,-5,STONE:0)
Block(-5,11,-5,STONE:0)
Block(-2,10,-4,STONE:0)
Block(-2,11,-4,STONE:0)
Block(-2,12,-4,STONE:0)
Block(4,8,-6,STONE:0)
Block(-2,7,-8,STONE:0)
Block(4,7,-6,STONE:0)
Block(-2,8,-8,STONE:0)
Block(-2,9,-8,STONE:0)
Block(4,9,-6,STONE:0)
Block(-3,16,-8,GRASS:0)
Block(-5,9,0,STONE:0)
Block(-5,8,0,STONE:0)
Block(-5,10,-5,STONE:0)
Block(-5,5,0,STONE:0)
Block(-5,7,0,STONE:0)
Block(-5,6,0,STONE:0)
Block(-2,12,0,GRASS:0)
Block(-2,11,0,STONE:0)
Block(-2,10,0,STONE:0)
Block(-7,8,-3,GRASS:0)
Block(2,10,3,STONE:0)
Block(2,11,3,GRASS:0)
Block(6,11,-2,GRASS:0)
Block(6,10,-2,STONE:0)
Block(-2,13,-4,STONE:0)
Block(-2,14,-4,STONE:0)
Block(-2,15,-4,STONE:0)
Block(-2,16,-4,GRASS:0)
Block(0,8,1,STONE:0)
Block(0,7,1,STONE:0)
Block(0,9,1,STONE:0)
Block(0,5,-7,STONE:0)
Block(0,4,-7,AIR)
Block(-6,9,-3,STONE:0)
Block(-6,8,-3,STONE:0)
Block(-6,7,-3,STONE:0)
Block(-6,6,-3,STONE:0)
Block(1,9,-1,STONE:0)
Block(1,7,-1,STONE:0)
Block(1,8,-1,STONE:0)
Block(1,5,-1,STONE:0)
Block(-5,8,-9,AIR)
Block(1,6,-1,STONE:0)
Block(-5,9,-9,AIR)
Block(1,3,-1,STONE:0)
Block(0,7,-7,STONE:0)
Block(1,4,-1,STONE:0)
Block(0,6,-7,STONE:0)
Block(1,1,-1,STONE:0)
Block(0,9,-7,STONE:0)
Block(1,2,-1,STONE:0)
Block(0,8,-7,STONE:0)
Block(1,0,-1,STONE:0)
Block(0,10,-5,STONE:0)
Block(0,14,-5,STONE:0)
Block(5,6,-6,AIR)
Block(0,13,-5,STONE:0)
Block(5,7,-6,AIR)
Block(0,12,-5,STONE:0)
Block(0,11,-5,STONE:0)
Block(5,5,-6,AIR)
Block(5,8,-6,GRASS:0)
Block(0,16,-5,GRASS:0)
Block(0,15,-5,STONE:0)
Block(-1,9,-8,STONE:0)
Block(3,4,4,STONE:0)
Block(3,8,4,STONE:0)
Block(3,7,4,STONE:0)
Block(3,6,4,STONE:0)
Block(3,5,4,STONE:0)
Block(3,9,4,STONE:0)
Block(4,3,2,STONE:0)
Block(4,2,2,STONE:0)
Block(4,5,2,STONE:0)
Block(4,4,2,STONE:0)
Block(2,3,-3,STONE:0)
Block(4,7,2,STONE:0)
Block(2,2,-3,STONE:0)
Block(4,6,2,STONE:0)
Block(4,9,2,STONE:0)
Block(4,8,2,STONE:0)
Block(2,7,-3,STONE:0)
Block(2,6,-3,STONE:0)
Block(5,9,0,STONE:0)
Block(2,5,-3,STONE:0)
Block(5,8,0,STONE:0)
Block(2,4,-3,STONE:0)
Block(5,7,0,STONE:0)
Block(5,6,0,STONE:0)
Block(5,12,-5,AIR)
Block(5,5,0,STONE:0)
Block(5,13,-5,AIR)
Block(5,4,0,STONE:0)
Block(2,9,-3,STONE:0)
Block(5,10,-5,GRASS:0)
Block(5,3,0,STONE:0)
Block(2,8,-3,STONE:0)
Block(5,11,-5,AIR)
Block(4,11,-5,STONE:0)
Block(4,12,-5,STONE:0)
Block(4,13,-5,GRASS:0)
Block(4,14,-5,LONG_GRASS:1)
Block(4,10,-5,STONE:0)
Block(1,17,-9,LONG_GRASS:1)
Block(1,16,-9,GRASS:0)
Block(1,15,-9,STONE:0)
Block(1,14,-9,STONE:0)
Block(-2,6,-4,STONE:0)
Block(-2,7,-4,STONE:0)
Block(-2,8,-4,STONE:0)
Block(-2,9,-4,STONE:0)
Block(-2,3,-4,STONE:0)
Block(-2,4,-4,STONE:0)
Block(-2,5,-4,STONE:0)
Block(-7,7,0,DIRT:0)
Block(1,13,-9,STONE:0)
Block(1,12,-9,STONE:0)
Block(-7,6,0,AIR)
Block(-7,9,0,GRASS:0)
Block(1,11,-9,STONE:0)
Block(-7,8,0,DIRT:0)
Block(1,10,-9,STONE:0)
Block(-6,9,2,STONE:0)
Block(-6,8,2,STONE:0)
Block(-6,7,2,STONE:0)
Block(-6,6,2,STONE:0)
Block(0,12,-9,STONE:0)
Block(0,11,-9,STONE:0)
Block(-5,7,4,STONE:0)
Block(0,14,-9,STONE:0)
Block(-5,6,4,STONE:0)
Block(0,13,-9,STONE:0)
Block(-5,9,4,GRASS:0)
Block(-5,8,4,DIRT:0)
Block(0,10,-9,STONE:0)
Block(-5,10,4,LONG_GRASS:1)
Block(0,16,-9,GRASS:0)
Block(0,15,-9,STONE:0)
Block(7,10,1,GRASS:0)
Block(3,11,3,GRASS:0)
Block(3,10,3,STONE:0)
Block(2,10,-6,STONE:0)
Block(2,11,-6,STONE:0)
Block(2,12,-6,STONE:0)
Block(2,13,-6,STONE:0)
Block(2,14,-6,STONE:0)
Block(2,15,-6,STONE:0)
Block(2,16,-6,GRASS:0)
Block(-4,12,0,GRASS:0)
Block(-4,10,0,STONE:0)
Block(-4,11,0,STONE:0)
Block(-3,10,-1,STONE:0)
Block(-3,11,-1,STONE:0)
Block(-3,12,-1,STONE:0)
Block(-3,13,-1,GRASS:0)
Block(0,3,-3,STONE:0)
Block(0,2,-3,STONE:0)
Block(-5,11,-1,GRASS:0)
Block(0,5,-3,STONE:0)
Block(0,4,-3,STONE:0)
Block(0,7,-3,STONE:0)
Block(6,9,2,STONE:0)
Block(0,6,-3,STONE:0)
Block(6,8,2,STONE:0)
Block(-6,9,-7,STONE:0)
Block(-6,8,-7,STONE:0)
Block(0,9,-3,STONE:0)
Block(-5,10,-1,STONE:0)
Block(0,8,-3,STONE:0)
Block(-6,7,-7,AIR)
Block(6,5,2,STONE:0)
Block(3,15,-6,STONE:0)
Block(6,4,2,STONE:0)
Block(3,16,-6,GRASS:0)
Block(6,7,2,STONE:0)
Block(3,13,-6,STONE:0)
Block(6,6,2,STONE:0)
Block(3,14,-6,STONE:0)
Block(3,11,-6,STONE:0)
Block(3,12,-6,STONE:0)
Block(0,1,-3,STONE:0)
Block(3,10,-6,STONE:0)
Block(7,9,0,STONE:0)
Block(7,4,0,AIR)
Block(7,8,0,STONE:0)
Block(7,7,0,STONE:0)
Block(7,6,0,STONE:0)
Block(7,5,0,AIR)
Block(-4,5,-4,STONE:0)
Block(-4,4,-4,STONE:0)
Block(-4,7,-4,STONE:0)
Block(-4,6,-4,STONE:0)
Block(-1,8,-8,STONE:0)
Block(-1,7,-8,STONE:0)
Block(-1,6,-8,STONE:0)
Block(-1,5,-8,AIR)
Block(-4,9,-4,STONE:0)
Block(-1,4,-8,AIR)
Block(-4,8,-4,STONE:0)
Block(-1,3,-8,AIR)
Block(-1,2,-8,AIR)
Block(-1,1,-8,AIR)
Block(5,3,-2,STONE:0)
Block(5,6,-2,STONE:0)
Block(5,7,-2,STONE:0)
Block(5,4,-2,STONE:0)
Block(5,5,-2,STONE:0)
Block(5,8,-2,STONE:0)
Block(5,9,-2,STONE:0)
Block(5,12,-2,STONE:0)
Block(5,11,-2,STONE:0)
Block(5,13,-2,GRASS:0)
Block(-1,15,-4,STONE:0)
Block(-1,14,-4,STONE:0)
Block(-1,17,-4,LONG_GRASS:1)
Block(-1,16,-4,GRASS:0)
Block(5,10,-2,STONE:0)
Block(-1,5,-3,STONE:0)
Block(-1,4,-3,STONE:0)
Block(-1,3,-3,STONE:0)
Block(2,9,-7,STONE:0)
Block(-1,2,-3,STONE:0)
Block(2,8,-7,STONE:0)
Block(2,2,1,STONE:0)
Block(2,1,1,STONE:0)
Block(2,4,1,STONE:0)
Block(2,3,1,STONE:0)
Block(-1,9,-3,STONE:0)
Block(-1,8,-3,STONE:0)
Block(-1,7,-3,STONE:0)
Block(-1,6,-3,STONE:0)
Block(1,3,3,STONE:0)
Block(2,3,-7,AIR)
Block(1,2,3,STONE:0)
Block(2,2,-7,AIR)
Block(1,1,3,STONE:0)
Block(2,7,-7,STONE:0)
Block(2,6,-7,STONE:0)
Block(2,5,-7,AIR)
Block(2,4,-7,AIR)
Block(-6,10,-4,STONE:0)
Block(-6,11,-4,GRASS:0)
Block(0,10,3,STONE:0)
Block(0,11,3,GRASS:0)
Block(-1,11,-4,STONE:0)
Block(1,12,-6,STONE:0)
Block(-1,10,-4,STONE:0)
Block(-2,10,4,GRASS:0)
Block(1,11,-6,STONE:0)
Block(-1,13,-4,STONE:0)
Block(1,14,-6,STONE:0)
Block(-1,12,-4,STONE:0)
Block(1,13,-6,STONE:0)
Block(1,16,-6,GRASS:0)
Block(1,15,-6,STONE:0)
Block(-4,10,-8,STONE:0)
Block(6,10,0,STONE:0)
Block(6,11,0,DIRT:0)
Block(6,12,0,GRASS:0)
Block(-4,13,-8,GRASS:0)
Block(-4,14,-8,VINE:9)
Block(1,10,-6,STONE:0)
Block(-4,11,-8,STONE:0)
Block(-4,12,-8,STONE:0)
Block(-4,15,-8,VINE:9)
Block(-4,16,-8,AIR)
Block(2,12,-9,STONE:0)
Block(2,11,-9,AIR)
Block(2,14,-9,STONE:0)
Block(2,13,-9,STONE:0)
Block(2,16,-9,GRASS:0)
Block(2,15,-9,STONE:0)
Block(-3,10,-4,STONE:0)
Block(-3,11,-4,STONE:0)
Block(3,4,-4,STONE:0)
Block(3,5,-4,STONE:0)
Block(3,6,-4,STONE:0)
Block(3,7,-4,STONE:0)
Block(3,8,-4,STONE:0)
Block(3,9,-4,STONE:0)
Block(1,9,-9,STONE:0)
Block(7,10,-2,GRASS:0)
Block(1,8,-9,STONE:0)
Block(2,6,5,STONE:0)
Block(7,8,4,GRASS:0)
Block(7,7,4,STONE:0)
Block(2,5,5,AIR)
Block(2,8,5,DIRT:0)
Block(2,7,5,STONE:0)
Block(2,4,5,AIR)
Block(7,9,4,AIR)
Block(-5,6,-1,STONE:0)
Block(7,6,-1,STONE:0)
Block(-3,14,-4,STONE:0)
Block(-5,7,-1,STONE:0)
Block(-3,15,-4,STONE:0)
Block(-5,4,-1,STONE:0)
Block(-3,12,-4,STONE:0)
Block(-5,5,-1,STONE:0)
Block(-3,13,-4,STONE:0)
Block(7,9,-1,STONE:0)
Block(2,9,5,GRASS:0)
Block(-5,8,-1,STONE:0)
Block(7,8,-1,STONE:0)
Block(-3,16,-4,GRASS:0)
Block(7,7,-1,STONE:0)
Block(-5,9,-1,STONE:0)
Block(3,5,3,STONE:0)
Block(8,7,2,STONE:0)
Block(3,4,3,STONE:0)
Block(3,3,3,STONE:0)
Block(8,9,2,GRASS:0)
Block(3,2,3,STONE:0)
Block(8,8,2,STONE:0)
Block(3,9,3,STONE:0)
Block(3,8,3,STONE:0)
Block(3,7,3,STONE:0)
Block(3,6,3,STONE:0)
Block(-4,9,-8,STONE:0)
Block(-4,8,-8,STONE:0)
Block(-4,7,-8,STONE:0)
Block(4,4,1,STONE:0)
Block(4,3,1,STONE:0)
Block(4,6,1,STONE:0)
Block(4,5,1,STONE:0)
Block(4,8,1,STONE:0)
Block(4,7,1,STONE:0)
Block(4,9,1,STONE:0)
Block(9,7,0,AIR)
Block(-4,11,-4,STONE:0)
Block(-4,12,-4,STONE:0)
Block(-4,13,-4,STONE:0)
Block(-4,14,-4,STONE:0)
Block(-4,15,-4,STONE:0)
Block(-4,16,-4,GRASS:0)
Block(-6,9,-2,STONE:0)
Block(2,18,-2,LEAVES:3)
Block(-6,8,-2,STONE:0)
Block(-6,7,-2,STONE:0)
Block(2,16,-2,LEAVES:3)
Block(-6,6,-2,STONE:0)
Block(2,17,-2,LEAVES:3)
Block(2,14,-2,GRASS:0)
Block(2,12,-2,STONE:0)
Block(2,13,-2,STONE:0)
Block(2,10,-2,STONE:0)
Block(2,11,-2,STONE:0)
Block(-3,5,-6,STONE:0)
Block(-3,6,-6,STONE:0)
Block(-3,7,-6,STONE:0)
Block(-3,8,-6,STONE:0)
Block(-3,9,-6,STONE:0)
Block(0,0,1,AIR)
Block(0,2,1,STONE:0)
Block(0,1,1,STONE:0)
Block(0,4,1,STONE:0)
Block(0,3,1,STONE:0)
Block(0,6,1,STONE:0)
Block(0,5,1,STONE:0)
Block(3,10,-2,STONE:0)
Block(3,11,-2,STONE:0)
Block(3,12,-2,STONE:0)
Block(3,17,-2,LEAVES:3)
Block(3,18,-2,AIR)
Block(-5,10,-8,GRASS:0)
Block(3,13,-2,GRASS:0)
Block(-5,11,-8,LONG_GRASS:1)
Block(3,16,-2,LEAVES:3)
Block(-1,2,3,STONE:0)
Block(-1,4,3,STONE:0)
Block(-1,3,3,STONE:0)
Block(-1,6,3,STONE:0)
Block(-1,5,3,STONE:0)
Block(-1,8,3,STONE:0)
Block(-1,7,3,STONE:0)
Block(-2,9,1,STONE:0)
Block(-2,8,1,STONE:0)
Block(-1,9,3,STONE:0)
Block(-2,7,1,STONE:0)
Block(-2,6,1,STONE:0)
Block(-2,5,1,STONE:0)
Block(-2,4,1,STONE:0)
Block(-2,3,1,STONE:0)
Block(-2,2,1,STONE:0)
Block(-2,1,1,AIR)
Block(-2,0,1,AIR)
Block(3,17,0,LEAVES:3)
Block(3,16,0,LEAVES:3)
Block(3,11,0,STONE:0)
Block(3,10,0,STONE:0)
Block(3,13,0,GRASS:0)
Block(3,12,0,STONE:0)
Block(6,9,-4,GRASS:0)
Block(6,7,-4,STONE:0)
Block(6,8,-4,STONE:0)
Block(-5,10,1,STONE:0)
Block(-2,8,-9,STONE:0)
Block(-5,11,1,GRASS:0)
Block(4,9,-1,STONE:0)
Block(4,8,-1,STONE:0)
Block(4,5,-1,STONE:0)
Block(4,4,-1,STONE:0)
Block(4,7,-1,STONE:0)
Block(4,6,-1,STONE:0)
Block(4,3,-1,STONE:0)
Block(4,2,-1,STONE:0)
Block(-2,9,-9,STONE:0)
Block(0,6,5,STONE:0)
Block(0,8,5,DIRT:0)
Block(0,7,5,STONE:0)
Block(0,9,5,GRASS:0)
Block(0,17,-2,LEAVES:3)
Block(0,16,-2,LEAVES:3)
Block(1,9,3,STONE:0)
Block(0,19,-2,AIR)
Block(1,8,3,STONE:0)
Block(0,18,-2,AIR)
Block(1,7,3,STONE:0)
Block(1,6,3,STONE:0)
Block(1,5,3,STONE:0)
Block(1,4,3,STONE:0)
Block(-2,14,-8,STONE:0)
Block(-2,13,-8,STONE:0)
Block(-2,16,-8,GRASS:0)
Block(-2,15,-8,STONE:0)
Block(-2,10,-8,STONE:0)
Block(1,9,-5,STONE:0)
Block(-2,12,-8,STONE:0)
Block(-2,11,-8,STONE:0)
Block(1,7,-5,STONE:0)
Block(1,8,-5,STONE:0)
Block(2,9,1,STONE:0)
Block(1,5,-5,STONE:0)
Block(-5,8,-5,STONE:0)
Block(1,6,-5,STONE:0)
Block(-5,9,-5,STONE:0)
Block(1,3,-5,STONE:0)
Block(2,6,1,STONE:0)
Block(1,4,-5,STONE:0)
Block(2,5,1,STONE:0)
Block(2,8,1,STONE:0)
Block(1,1,-5,AIR)
Block(1,2,-5,STONE:0)
Block(2,7,1,STONE:0)
Block(-1,11,3,GRASS:0)
Block(3,9,-8,STONE:0)
Block(-1,10,3,STONE:0)
Block(0,11,-2,STONE:0)
Block(0,10,-2,STONE:0)
Block(-5,6,-5,STONE:0)
Block(0,13,-2,STONE:0)
Block(-5,7,-5,STONE:0)
Block(0,12,-2,STONE:0)
Block(-5,5,-5,STONE:0)
Block(0,14,-2,GRASS:0)
Block(1,15,-2,AIR)
Block(1,16,-2,LEAVES:3)
Block(1,17,-2,LEAVES:3)
Block(1,18,-2,LEAVES:3)
Block(1,19,-2,LEAVES:3)
Block(-7,7,-8,AIR)
Block(-7,8,-8,AIR)
Block(-1,16,-8,GRASS:0)
Block(-1,15,-8,STONE:0)
Block(1,10,-2,STONE:0)
Block(-1,14,-8,STONE:0)
Block(1,11,-2,STONE:0)
Block(-1,13,-8,STONE:0)
Block(-1,12,-8,STONE:0)
Block(1,12,-2,STONE:0)
Block(-1,11,-8,STONE:0)
Block(1,13,-2,STONE:0)
Block(-1,10,-8,STONE:0)
Block(1,14,-2,GRASS:0)
Block(6,11,-1,GRASS:0)
Block(6,10,-1,STONE:0)
Block(-2,7,-7,STONE:0)
Block(1,8,-4,STONE:0)
Block(-2,15,-3,GRASS:0)
Block(4,7,-7,AIR)
Block(-2,8,-7,STONE:0)
Block(1,9,-4,STONE:0)
Block(-2,14,-3,STONE:0)
Block(1,6,-4,STONE:0)
Block(-2,9,-7,STONE:0)
Block(-2,13,-3,STONE:0)
Block(1,7,-4,STONE:0)
Block(4,8,-7,GRASS:0)
Block(-2,12,-3,STONE:0)
Block(1,4,-4,STONE:0)
Block(1,5,-4,STONE:0)
Block(1,2,-4,STONE:0)
Block(1,3,-4,STONE:0)
Block(-2,6,-7,STONE:0)
Block(-5,11,-6,STONE:0)
Block(1,1,-4,STONE:0)
Block(-5,10,-6,STONE:0)
Block(-6,10,0,GRASS:0)
Block(-2,11,-3,STONE:0)
Block(-2,10,-3,STONE:0)
Block(-4,9,1,STONE:0)
Block(1,19,-1,LEAVES:3)
Block(-4,8,1,STONE:0)
Block(1,18,-1,LOG:3)
Block(1,17,-1,LOG:3)
Block(1,16,-1,LOG:3)
Block(1,15,-1,LOG:3)
Block(1,14,-1,LOG:3)
Block(-4,7,1,STONE:0)
Block(-4,6,1,STONE:0)
Block(-4,5,1,STONE:0)
Block(-4,4,1,STONE:0)
Block(-3,8,3,STONE:0)
Block(0,11,-6,STONE:0)
Block(-3,7,3,STONE:0)
Block(0,10,-6,STONE:0)
Block(-3,9,3,STONE:0)
Block(-3,4,3,STONE:0)
Block(1,13,-1,DIRT:0)
Block(0,15,-6,STONE:0)
Block(-3,3,3,STONE:0)
Block(1,12,-1,STONE:0)
Block(0,14,-6,STONE:0)
Block(-3,6,3,STONE:0)
Block(1,11,-1,STONE:0)
Block(0,13,-6,STONE:0)
Block(-3,5,3,STONE:0)
Block(1,10,-1,STONE:0)
Block(0,12,-6,STONE:0)
Block(0,16,-6,GRASS:0)
Block(-7,9,-2,GRASS:0)
Block(5,12,1,GRASS:0)
Block(5,11,1,STONE:0)
Block(5,10,1,STONE:0)
Block(-2,9,5,GRASS:0)
Block(-2,8,5,DIRT:0)
Block(-2,7,5,STONE:0)
Block(-7,8,-2,DIRT:0)
Block(-3,2,-1,STONE:0)
Block(-3,3,-1,STONE:0)
Block(-3,4,-1,STONE:0)
Block(-3,5,-1,STONE:0)
Block(-3,6,-1,STONE:0)
Block(-3,7,-1,STONE:0)
Block(5,8,5,GRASS:0)
Block(-3,8,-1,STONE:0)
Block(5,7,5,AIR)
Block(-3,9,-1,STONE:0)
Block(-3,13,-9,GRASS:0)
Block(0,4,-6,STONE:0)
Block(-3,10,-9,STONE:0)
Block(0,6,-6,STONE:0)
Block(-3,11,-9,STONE:0)
Block(0,5,-6,STONE:0)
Block(-3,12,-9,STONE:0)
Block(-6,9,-4,STONE:0)
Block(-6,8,-4,STONE:0)
Block(-6,7,-4,STONE:0)
Block(-6,6,-4,STONE:0)
Block(0,8,-6,STONE:0)
Block(0,7,-6,STONE:0)
Block(0,9,-6,STONE:0)
Block(4,13,-4,GRASS:0)
Block(-4,10,3,STONE:0)
Block(4,12,-4,STONE:0)
Block(4,11,-4,STONE:0)
Block(-4,11,3,GRASS:0)
Block(4,10,-4,STONE:0)
Block(5,7,-5,STONE:0)
Block(5,8,-5,STONE:0)
Block(4,14,-4,LONG_GRASS:1)
Block(5,9,-5,STONE:0)
Block(2,12,2,GRASS:0)
Block(2,11,2,STONE:0)
Block(2,10,2,STONE:0)
Block(3,10,-9,AIR)
Block(3,16,-9,GRASS:0)
Block(3,15,-9,STONE:0)
Block(3,14,-9,STONE:0)
Block(3,13,-9,STONE:0)
Block(3,12,-9,AIR)
Block(2,4,-2,STONE:0)
Block(2,3,-2,STONE:0)
Block(2,2,-2,STONE:0)
Block(2,1,-2,STONE:0)
Block(2,8,-2,STONE:0)
Block(2,7,-2,STONE:0)
Block(2,6,-2,STONE:0)
Block(2,5,-2,STONE:0)
Block(2,9,-2,STONE:0)
Block(-4,10,-4,STONE:0)
Block(-2,9,-3,STONE:0)
Block(-2,8,-3,STONE:0)
Block(-2,7,-3,STONE:0)
Block(1,10,4,GRASS:0)
Block(-2,6,-3,STONE:0)
Block(-2,5,-3,STONE:0)
Block(-2,4,-3,STONE:0)
Block(-2,3,-3,STONE:0)
Block(-4,6,-3,STONE:0)
Block(-6,5,1,AIR)
Block(-4,5,-3,STONE:0)
Block(-4,8,-3,STONE:0)
Block(-4,7,-3,STONE:0)
Block(-4,4,-3,STONE:0)
Block(-6,9,1,STONE:0)
Block(-6,8,1,STONE:0)
Block(-4,9,-3,STONE:0)
Block(7,10,-3,LONG_GRASS:1)
Block(-6,7,1,STONE:0)
Block(-6,6,1,AIR)
Block(-5,6,3,STONE:0)
Block(1,15,-8,STONE:0)
Block(-5,5,3,STONE:0)
Block(1,16,-8,GRASS:0)
Block(-5,8,3,STONE:0)
Block(1,13,-8,STONE:0)
Block(-5,7,3,STONE:0)
Block(1,14,-8,STONE:0)
Block(-5,9,3,STONE:0)
Block(1,11,-8,STONE:0)
Block(1,12,-8,STONE:0)
Block(1,10,-8,STONE:0)
Block(-4,8,5,GRASS:0)
Block(-1,10,-1,STONE:0)
Block(3,7,5,STONE:0)
Block(3,6,5,AIR)
Block(-5,11,-2,GRASS:0)
Block(3,5,5,AIR)
Block(-5,10,-2,STONE:0)
Block(3,4,5,AIR)
Block(-1,16,-1,LEAVES:3)
Block(3,9,5,GRASS:0)
Block(-1,17,-1,LEAVES:3)
Block(3,8,5,DIRT:0)
Block(-1,18,-1,AIR)
Block(-1,11,-1,STONE:0)
Block(-1,12,-1,STONE:0)
Block(-1,13,-1,GRASS:0)
Block(4,4,3,STONE:0)
Block(4,3,3,STONE:0)
Block(4,6,3,STONE:0)
Block(4,5,3,STONE:0)
Block(4,8,3,STONE:0)
Block(4,7,3,STONE:0)
Block(5,9,1,STONE:0)
Block(5,8,1,STONE:0)
Block(4,9,3,STONE:0)
Block(5,7,1,STONE:0)
Block(5,6,1,STONE:0)
Block(5,5,1,STONE:0)
Block(5,4,1,STONE:0)
Block(5,3,1,STONE:0)
Block(0,4,-2,STONE:0)
Block(0,3,-2,STONE:0)
Block(0,6,-2,STONE:0)
Block(0,5,-2,STONE:0)
Block(0,8,-2,STONE:0)
Block(6,8,3,STONE:0)
Block(0,7,-2,STONE:0)
Block(6,7,3,STONE:0)
Block(-6,8,-8,GRASS:0)
Block(0,9,-2,STONE:0)
Block(6,9,3,STONE:0)
Block(6,6,3,STONE:0)
Block(6,5,3,STONE:0)
Block(0,2,-2,STONE:0)
Block(0,1,-2,STONE:0)
Block(-2,10,3,STONE:0)
Block(7,9,1,STONE:0)
Block(7,8,1,STONE:0)
Block(7,3,1,AIR)
Block(7,7,1,STONE:0)
Block(5,13,-6,AIR)
Block(7,6,1,STONE:0)
Block(5,14,-6,AIR)
Block(7,5,1,AIR)
Block(5,12,-6,AIR)
Block(7,4,1,AIR)
Block(-2,11,3,GRASS:0)
Block(-6,10,-1,GRASS:0)
Block(5,3,-1,STONE:0)
Block(0,17,2,AIR)
Block(5,4,-1,STONE:0)
Block(5,7,-1,STONE:0)
Block(0,13,2,AIR)
Block(5,8,-1,STONE:0)
Block(0,14,2,AIR)
Block(5,5,-1,STONE:0)
Block(0,15,2,AIR)
Block(5,6,-1,STONE:0)
Block(0,16,2,AIR)
Block(0,10,2,STONE:0)
Block(5,9,-1,STONE:0)
Block(0,11,2,STONE:0)
Block(0,12,2,GRASS:0)
Block(2,10,-7,STONE:0)
Block(2,11,-7,STONE:0)
Block(2,12,-7,STONE:0)
Block(2,13,-7,STONE:0)
Block(2,14,-7,STONE:0)
Block(2,15,-7,STONE:0)
Block(2,16,-7,GRASS:0)
Block(-1,9,-9,STONE:0)
Block(-1,8,-9,STONE:0)
Block(2,9,-6,STONE:0)
Block(3,10,4,GRASS:0)
Block(2,8,-6,STONE:0)
Block(2,7,-6,STONE:0)
Block(2,6,-6,STONE:0)
Block(2,5,-6,STONE:0)
Block(1,9,4,STONE:0)
Block(1,8,4,STONE:0)
Block(1,7,4,STONE:0)
Block(1,6,4,STONE:0)
Block(1,5,4,STONE:0)
Block(1,4,4,STONE:0)
Block(1,3,4,STONE:0)
Block(2,9,2,STONE:0)
Block(2,8,2,STONE:0)
Block(2,5,2,STONE:0)
Block(2,4,2,STONE:0)
Block(2,7,2,STONE:0)
Block(2,6,2,STONE:0)
Block(-5,5,-2,STONE:0)
Block(-5,6,-2,STONE:0)
Block(7,4,-2,AIR)
Block(-5,3,-2,AIR)
Block(-5,4,-2,AIR)
Block(-5,9,-2,STONE:0)
Block(7,9,-2,STONE:0)
Block(-4,11,-7,STONE:0)
Block(7,8,-2,STONE:0)
Block(-4,10,-7,STONE:0)
Block(-5,7,-2,STONE:0)
Block(7,7,-2,STONE:0)
Block(-4,13,-7,STONE:0)
Block(7,6,-2,STONE:0)
Block(-5,8,-2,STONE:0)
Block(-4,12,-7,STONE:0)
Block(3,8,0,STONE:0)
Block(4,15,-8,STONE:0)
Block(-4,15,-7,GRASS:0)
Block(3,7,0,STONE:0)
Block(4,14,-8,STONE:0)
Block(-4,14,-7,STONE:0)
Block(3,6,0,STONE:0)
Block(-4,4,-7,AIR)
Block(3,5,0,STONE:0)
Block(4,16,-8,GRASS:0)
Block(4,13,-8,STONE:0)
Block(3,9,0,STONE:0)
Block(4,12,-8,STONE:0)
Block(-4,9,-7,STONE:0)
Block(-4,6,-7,STONE:0)
Block(-6,11,-5,GRASS:0)
Block(-6,10,-5,STONE:0)
Block(-4,5,-7,AIR)
Block(-4,8,-7,STONE:0)
Block(-4,7,-7,STONE:0)
Block(-5,10,2,STONE:0)
Block(-5,11,2,GRASS:0)
Block(3,4,0,STONE:0)
Block(3,3,0,STONE:0)
Block(3,2,0,STONE:0)
Block(2,1,2,STONE:0)
Block(3,13,-5,STONE:0)
Block(3,12,-5,STONE:0)
Block(2,3,2,STONE:0)
Block(3,15,-5,STONE:0)
Block(2,2,2,STONE:0)
Block(3,14,-5,STONE:0)
Block(3,11,-5,STONE:0)
Block(3,10,-5,STONE:0)
Block(7,11,2,GRASS:0)
Block(7,10,2,DIRT:0)
Block(3,16,-5,GRASS:0)
Block(-3,8,-9,DIRT:0)
Block(-3,9,-9,STONE:0)
Block(3,5,-5,STONE:0)
Block(3,6,-5,STONE:0)
Block(3,7,-5,STONE:0)
Block(3,8,-5,STONE:0)
Block(3,9,-5,STONE:0)
Block(-1,3,2,STONE:0)
Block(-1,2,2,STONE:0)
Block(-1,5,2,STONE:0)
Block(8,8,3,GRASS:0)
Block(-1,4,2,STONE:0)
Block(8,7,3,STONE:0)
Block(-1,7,2,STONE:0)
Block(-1,6,2,STONE:0)
Block(8,9,3,AIR)
Block(-1,9,2,STONE:0)
Block(-1,8,2,STONE:0)
Block(-2,9,0,STONE:0)
Block(-2,8,0,STONE:0)
Block(-2,7,0,STONE:0)
Block(-2,6,0,STONE:0)
Block(-2,5,0,STONE:0)
Block(-2,4,0,STONE:0)
Block(-2,3,0,STONE:0)
Block(-2,2,0,STONE:0)
Block(-1,16,0,LEAVES:3)
Block(-1,17,0,LEAVES:3)
Block(-1,10,0,STONE:0)
Block(-1,11,0,STONE:0)
Block(-1,12,0,STONE:0)
Block(-1,13,0,GRASS:0)
Block(1,11,-5,STONE:0)
Block(-1,13,-5,STONE:0)
Block(1,10,-5,STONE:0)
Block(-1,14,-5,STONE:0)
Block(-1,11,-5,STONE:0)
Block(1,13,-5,STONE:0)
Block(-1,12,-5,STONE:0)
Block(1,12,-5,STONE:0)
Block(3,16,1,LEAVES:3)
Block(1,15,-5,STONE:0)
Block(-1,10,-5,STONE:0)
Block(1,14,-5,STONE:0)
Block(1,16,-5,GRASS:0)
Block(3,10,1,STONE:0)
Block(3,13,1,GRASS:0)
Block(3,11,1,STONE:0)
Block(3,12,1,STONE:0)
Block(-1,4,-4,STONE:0)
Block(-1,3,-4,STONE:0)
Block(5,12,-3,GRASS:0)
Block(-1,9,-4,STONE:0)
Block(-1,8,-4,STONE:0)
Block(-1,7,-4,STONE:0)
Block(-1,6,-4,STONE:0)
Block(-1,15,-5,STONE:0)
Block(-1,5,-4,STONE:0)
Block(-1,16,-5,GRASS:0)
Block(-5,10,-9,AIR)
Block(6,13,-8,AIR)
Block(6,12,-8,AIR)
Block(6,15,-8,AIR)
Block(6,14,-8,AIR)
Block(5,11,-3,STONE:0)
Block(5,10,-3,STONE:0)
Block(0,1,2,STONE:0)
Block(0,3,2,STONE:0)
Block(-3,11,-5,STONE:0)
Block(0,2,2,STONE:0)
Block(1,9,0,STONE:0)
Block(-1,10,4,GRASS:0)
Block(-3,12,-5,STONE:0)
Block(0,5,2,STONE:0)
Block(1,8,0,STONE:0)
Block(0,4,2,STONE:0)
Block(1,7,0,STONE:0)
Block(-3,10,-5,STONE:0)
Block(1,8,-8,STONE:0)
Block(1,9,-8,STONE:0)
Block(1,6,-8,STONE:0)
Block(1,7,-8,STONE:0)
Block(-5,9,-6,STONE:0)
Block(-5,7,-6,STONE:0)
Block(-5,8,-6,STONE:0)
Block(-5,6,-6,STONE:0)
Block(-3,15,-5,STONE:0)
Block(-3,16,-5,GRASS:0)
Block(-3,13,-5,STONE:0)
Block(-3,14,-5,STONE:0)
Block(6,10,3,STONE:0)
Block(4,8,-2,STONE:0)
Block(4,7,-2,STONE:0)
Block(4,9,-2,STONE:0)
Block(4,4,-2,STONE:0)
Block(4,3,-2,STONE:0)
Block(4,6,-2,STONE:0)
Block(4,5,-2,STONE:0)
Block(4,12,2,GRASS:0)
Block(2,17,-3,LEAVES:3)
Block(4,11,2,STONE:0)
Block(4,10,2,STONE:0)
Block(2,16,-3,LEAVES:3)
Block(2,13,-3,STONE:0)
Block(2,14,-3,GRASS:0)
Block(2,11,-3,STONE:0)
Block(2,12,-3,STONE:0)
Block(2,10,-3,STONE:0)
Block(-3,3,-5,AIR)
Block(-3,4,-5,STONE:0)
Block(-3,5,-5,STONE:0)
Block(-3,6,-5,STONE:0)
Block(1,6,0,STONE:0)
Block(0,7,2,STONE:0)
Block(1,5,0,STONE:0)
Block(0,6,2,STONE:0)
Block(-3,7,-5,STONE:0)
Block(1,4,0,STONE:0)
Block(-3,8,-5,STONE:0)
Block(0,9,2,STONE:0)
Block(1,3,0,STONE:0)
Block(0,8,2,STONE:0)
Block(-3,9,-5,STONE:0)
Block(1,2,0,STONE:0)
Block(1,1,0,STONE:0)
Block(1,0,0,STONE:0)
Block(-4,9,0,STONE:0)
Block(-4,4,0,STONE:0)
Block(-4,3,0,STONE:0)
Block(-4,8,0,STONE:0)
Block(-4,7,0,STONE:0)
Block(-4,6,0,STONE:0)
Block(-4,5,0,STONE:0)
Block(-3,9,2,STONE:0)
Block(-3,8,2,STONE:0)
Block(-2,16,-7,GRASS:0)
Block(-3,5,2,STONE:0)
Block(-3,4,2,STONE:0)
Block(-3,7,2,STONE:0)
Block(3,9,-9,AIR)
Block(-3,6,2,STONE:0)
Block(-3,1,2,AIR)
Block(-3,0,2,AIR)
Block(-3,3,2,STONE:0)
Block(-3,2,2,AIR)
Block(1,19,0,LEAVES:3)
Block(1,18,0,LEAVES:3)
Block(0,17,-3,LEAVES:3)
Block(1,17,0,LEAVES:3)
Block(1,16,0,LEAVES:3)
Block(1,15,0,AIR)
Block(-2,9,4,STONE:0)
Block(1,14,0,AIR)
Block(1,13,0,GRASS:0)
Block(-2,7,4,STONE:0)
Block(1,12,0,STONE:0)
Block(-2,6,4,STONE:0)
Block(1,11,0,STONE:0)
Block(-2,13,-7,STONE:0)
Block(-2,5,4,STONE:0)
Block(1,10,0,STONE:0)
Block(-2,12,-7,STONE:0)
Block(-2,15,-7,STONE:0)
Block(-2,14,-7,STONE:0)
Block(-7,8,-7,GRASS:0)
Block(-7,9,-7,LONG_GRASS:1)
Block(-2,11,-7,STONE:0)
Block(-2,10,-7,STONE:0)
Block(0,11,-3,STONE:0)
Block(0,12,-3,STONE:0)
Block(0,10,-3,STONE:0)
Block(0,15,-3,GRASS:0)
Block(0,16,-3,LEAVES:3)
Block(0,13,-3,STONE:0)
Block(0,14,-3,STONE:0)
Block(6,6,-3,STONE:0)
Block(-3,12,1,GRASS:0)
Block(6,7,-3,STONE:0)
Block(-3,10,1,STONE:0)
Block(6,4,-3,AIR)
Block(6,5,-3,STONE:0)
Block(-3,11,1,STONE:0)
Block(4,10,-1,STONE:0)
Block(6,8,-3,STONE:0)
Block(6,9,-3,STONE:0)
Block(4,13,-1,GRASS:0)
Block(4,11,-1,STONE:0)
Block(4,12,-1,STONE:0)
Block(3,10,-1,STONE:0)
Block(3,11,-1,STONE:0)
Block(3,16,-1,LEAVES:3)
Block(3,17,-1,LEAVES:3)
Block(3,12,-1,STONE:0)
Block(3,13,-1,GRASS:0)
Block(4,12,-3,STONE:0)
Block(4,11,-3,STONE:0)
Block(4,10,-3,STONE:0)
Block(4,16,-3,AIR)
Block(4,15,-3,AIR)
Block(4,14,-3,LONG_GRASS:1)
Block(4,13,-3,GRASS:0)
Block(4,17,-3,AIR)
Block(-7,7,-1,DIRT:0)
Block(-7,8,-1,DIRT:0)
Block(-7,9,-1,GRASS:0)
Block(0,10,-7,STONE:0)
Block(0,11,-7,STONE:0)
Block(0,12,-7,STONE:0)
Block(-7,5,-1,AIR)
Block(0,13,-7,STONE:0)
Block(0,14,-7,STONE:0)
Block(0,15,-7,STONE:0)
Block(0,16,-7,GRASS:0)
Block(-6,9,-5,STONE:0)
Block(-1,10,-9,STONE:0)
Block(6,7,0,STONE:0)
Block(-6,8,-5,STONE:0)
Block(-1,11,-9,STONE:0)
Block(6,6,0,STONE:0)
Block(-6,7,-5,STONE:0)
Block(-1,12,-9,STONE:0)
Block(-6,6,-5,STONE:0)
Block(6,9,0,STONE:0)
Block(-1,13,-9,STONE:0)
Block(6,8,0,STONE:0)
Block(-1,14,-9,STONE:0)
Block(-1,15,-9,STONE:0)
Block(-1,16,-9,GRASS:0)
Block(6,5,0,STONE:0)
Block(6,4,0,STONE:0)
Block(1,9,-3,STONE:0)
Block(1,7,-3,STONE:0)
Block(1,8,-3,STONE:0)
Block(1,5,-3,STONE:0)
Block(1,6,-3,STONE:0)
Block(1,3,-3,STONE:0)
Block(1,4,-3,STONE:0)
Block(1,1,-3,STONE:0)
Block(1,2,-3,STONE:0)
Block(0,7,-9,AIR)
Block(1,0,-3,STONE:0)
Block(0,6,-9,AIR)
Block(0,9,-9,STONE:0)
Block(0,8,-9,STONE:0)
Block(5,16,-7,AIR)
Block(5,4,-4,AIR)
Block(5,5,-4,STONE:0)
Block(5,8,-4,STONE:0)
Block(5,11,-7,AIR)
Block(5,9,-4,STONE:0)
Block(5,10,-7,AIR)
Block(5,6,-4,STONE:0)
Block(5,7,-4,STONE:0)
Block(5,15,-7,AIR)
Block(5,14,-7,AIR)
Block(5,13,-7,AIR)
Block(5,12,-7,AIR)
Block(-4,8,4,STONE:0)
Block(3,10,-8,STONE:0)
Block(-4,7,4,STONE:0)
Block(-4,6,4,STONE:0)
Block(-4,9,4,GRASS:0)
Block(3,16,-8,GRASS:0)
Block(3,15,-8,STONE:0)
Block(3,14,-8,STONE:0)
Block(3,13,-8,STONE:0)
Block(3,12,-8,STONE:0)
Block(3,11,-8,STONE:0)
Block(-4,10,-3,STONE:0)
Block(-4,11,-3,STONE:0)
Block(-4,12,-3,STONE:0)
Block(-4,13,-3,STONE:0)
Block(-4,14,-3,GRASS:0)
Block(4,13,0,GRASS:0)
Block(4,11,0,STONE:0)
Block(4,12,0,STONE:0)
Block(4,10,0,STONE:0)
Block(2,1,-1,STONE:0)
Block(2,0,-1,STONE:0)
Block(2,5,-1,STONE:0)
Block(2,4,-1,STONE:0)
Block(2,3,-1,STONE:0)
Block(2,2,-1,STONE:0)
Block(2,9,-1,STONE:0)
Block(2,8,-1,STONE:0)
Block(2,7,-1,STONE:0)
Block(2,6,-1,STONE:0)
Block(-6,10,1,GRASS:0)
Block(5,11,0,STONE:0)
Block(5,10,0,STONE:0)
Block(5,13,0,GRASS:0)
Block(5,12,0,STONE:0)
Block(2,17,-4,AIR)
Block(2,16,-4,GRASS:0)
Block(-2,8,-6,STONE:0)
Block(2,15,-4,STONE:0)
Block(-2,9,-6,STONE:0)
Block(4,9,-4,STONE:0)
Block(2,14,-4,STONE:0)
Block(2,13,-4,STONE:0)
Block(2,12,-4,STONE:0)
Block(4,6,-4,STONE:0)
Block(2,11,-4,STONE:0)
Block(-2,5,-6,STONE:0)
Block(4,5,-4,STONE:0)
Block(2,10,-4,STONE:0)
Block(-2,6,-6,STONE:0)
Block(4,8,-4,STONE:0)
Block(-2,7,-6,STONE:0)
Block(4,7,-4,STONE:0)
Block(4,4,-4,STONE:0)
Block(-6,6,0,STONE:0)
Block(-6,5,0,AIR)
Block(-6,9,0,STONE:0)
Block(-6,8,0,STONE:0)
Block(-6,7,0,DIRT:0)
Block(-5,7,2,STONE:0)
Block(-5,6,2,STONE:0)
Block(-5,9,2,STONE:0)
Block(1,10,3,STONE:0)
Block(-5,8,2,STONE:0)
Block(1,11,3,GRASS:0)
Block(-5,5,2,STONE:0)
Block(-5,13,-3,GRASS:0)
Block(-5,11,-3,STONE:0)
Block(-5,12,-3,STONE:0)
Block(-5,10,-3,STONE:0)
Block(-4,11,2,GRASS:0)
Block(-4,10,2,STONE:0)
Block(-6,10,-2,GRASS:0)
Block(0,13,1,GRASS:0)
Block(0,12,1,STONE:0)
Block(0,17,1,LEAVES:3)
Block(0,16,1,LEAVES:3)
Block(0,11,1,STONE:0)
Block(0,10,1,STONE:0)
Block(-1,10,-2,STONE:0)
Block(-1,11,-2,STONE:0)
Block(8,8,-1,STONE:0)
Block(8,9,-1,GRASS:0)
Block(0,1,-5,AIR)
Block(0,3,-5,STONE:0)
Block(0,2,-5,AIR)
Block(0,5,-5,STONE:0)
Block(6,7,4,STONE:0)
Block(0,4,-5,STONE:0)
Block(0,7,-5,STONE:0)
Block(6,9,4,GRASS:0)
Block(0,6,-5,STONE:0)
Block(6,8,4,STONE:0)
Block(7,9,2,STONE:0)
Block(7,8,2,STONE:0)
Block(7,7,2,STONE:0)
Block(0,9,-5,STONE:0)
Block(7,2,2,AIR)
Block(0,8,-5,STONE:0)
Block(7,6,2,STONE:0)
Block(7,5,2,AIR)
Block(7,4,2,AIR)
Block(7,3,2,AIR)
Block(-4,7,-2,STONE:0)
Block(8,9,0,GRASS:0)
Block(2,11,1,STONE:0)
Block(-4,6,-2,STONE:0)
Block(8,8,0,STONE:0)
Block(2,10,1,STONE:0)
Block(-4,9,-2,STONE:0)
Block(2,13,1,GRASS:0)
Block(-4,8,-2,STONE:0)
Block(2,12,1,STONE:0)
Block(-4,5,-2,STONE:0)
Block(2,11,-8,STONE:0)
Block(-4,4,-2,STONE:0)
Block(2,10,-8,STONE:0)
Block(2,13,-8,STONE:0)
Block(-1,9,-6,STONE:0)
Block(2,12,-8,STONE:0)
Block(-1,8,-6,STONE:0)
Block(2,15,-8,STONE:0)
Block(-1,7,-6,STONE:0)
Block(2,14,-8,STONE:0)
Block(-1,6,-6,STONE:0)
Block(-1,5,-6,STONE:0)
Block(2,16,-8,GRASS:0)
Block(-1,4,-6,STONE:0)
Block(8,7,0,STONE:0)
Block(2,17,1,LEAVES:3)
Block(2,16,1,LEAVES:3)
Block(8,6,0,AIR)
Block(-4,12,2,LONG_GRASS:1)
Block(3,7,-1,STONE:0)
Block(4,14,-7,STONE:0)
Block(3,8,-1,STONE:0)
Block(4,13,-7,STONE:0)
Block(3,9,-1,STONE:0)
Block(4,16,-7,GRASS:0)
Block(4,15,-7,STONE:0)
Block(4,10,-7,STONE:0)
Block(4,12,-7,STONE:0)
Block(4,11,-7,STONE:0)
Block(3,1,-1,STONE:0)
Block(3,2,-1,STONE:0)
Block(3,3,-1,STONE:0)
Block(-2,10,-2,STONE:0)
Block(3,4,-1,STONE:0)
Block(3,5,-1,STONE:0)
Block(3,6,-1,STONE:0)
Block(1,14,-7,STONE:0)
Block(1,15,-7,STONE:0)
Block(1,12,-7,STONE:0)
Block(1,13,-7,STONE:0)
Block(1,16,-7,GRASS:0)
Block(1,10,-7,STONE:0)
Block(1,11,-7,STONE:0)
Block(4,5,4,STONE:0)
Block(4,4,4,AIR)
Block(4,7,4,STONE:0)
Block(4,6,4,STONE:0)
Block(5,9,2,STONE:0)
Block(2,5,-5,STONE:0)
Block(5,8,2,STONE:0)
Block(4,9,4,GRASS:0)
Block(2,4,-5,STONE:0)
Block(5,7,2,STONE:0)
Block(4,8,4,STONE:0)
Block(5,6,2,STONE:0)
Block(5,5,2,STONE:0)
Block(5,4,2,STONE:0)
Block(2,9,-5,STONE:0)
Block(5,3,2,STONE:0)
Block(2,8,-5,STONE:0)
Block(2,7,-5,STONE:0)
Block(2,6,-5,STONE:0)
Block(-1,16,-2,LEAVES:3)
Block(-1,17,-2,LEAVES:3)
Block(-1,12,-2,STONE:0)
Block(-2,12,2,GRASS:0)
Block(-1,13,-2,STONE:0)
Block(-2,10,2,STONE:0)
Block(-1,14,-2,GRASS:0)
Block(-2,11,2,STONE:0)
Block(-2,9,-2,STONE:0)
Block(-2,8,-2,STONE:0)
Block(-2,3,-2,STONE:0)
Block(-2,2,-2,STONE:0)
Block(-7,8,2,GRASS:0)
Block(-2,1,-2,AIR)
Block(-2,7,-2,STONE:0)
Block(-2,6,-2,STONE:0)
Block(-2,5,-2,STONE:0)
Block(-7,7,2,AIR)
Block(-2,4,-2,STONE:0)
Block(-7,6,2,AIR)
Block(-6,8,4,GRASS:0)
Block(-6,7,4,AIR)
Block(-6,6,4,AIR)
Block(-6,5,4,AIR)
Block(-2,14,-2,GRASS:0)
Block(-2,13,-2,STONE:0)
Block(-2,12,-2,STONE:0)
Block(-2,11,-2,STONE:0)
Block(-2,17,-2,AIR)
Block(-2,16,-2,AIR)
Block(-2,15,-2,AIR)
Block(3,12,-4,STONE:0)
Block(3,11,-4,STONE:0)
Block(3,14,-4,GRASS:0)
Block(3,13,-4,STONE:0)
Block(3,10,-4,STONE:0)
Block(-1,16,1,AIR)
Block(-1,17,1,LEAVES:3)
Block(3,16,-4,AIR)
Block(3,15,-4,AIR)
Block(-3,11,-2,STONE:0)
Block(-3,10,-2,STONE:0)
Block(-1,10,1,STONE:0)
Block(-3,13,-2,STONE:0)
Block(-1,11,1,STONE:0)
Block(-3,12,-2,STONE:0)
Block(-1,12,1,GRASS:0)
Block(-3,14,-2,GRASS:0)
Block(-1,13,1,AIR)
Block(-1,14,1,AIR)
Block(-1,15,1,AIR)
Block(3,10,2,STONE:0)
Block(3,11,2,DIRT:0)
Block(3,12,2,GRASS:0)
Block(0,5,-1,STONE:0)
Block(3,6,-2,STONE:0)
Block(1,9,5,GRASS:0)
Block(0,4,-1,STONE:0)
Block(3,7,-2,STONE:0)
Block(1,8,5,DIRT:0)
Block(0,7,-1,STONE:0)
Block(1,7,5,STONE:0)
Block(3,8,-2,STONE:0)
Block(0,6,-1,STONE:0)
Block(1,6,5,STONE:0)
Block(3,9,-2,STONE:0)
Block(1,5,5,STONE:0)
Block(0,9,-1,STONE:0)
Block(0,8,-1,STONE:0)
Block(0,1,-1,STONE:0)
Block(3,2,-2,STONE:0)
Block(0,0,-1,STONE:0)
Block(3,3,-2,STONE:0)
Block(0,3,-1,STONE:0)
Block(3,4,-2,STONE:0)
Block(0,2,-1,STONE:0)
Block(3,5,-2,STONE:0)
Block(2,8,3,STONE:0)
Block(2,7,3,STONE:0)
Block(7,9,-3,GRASS:0)
Block(2,9,3,STONE:0)
Block(2,4,3,STONE:0)
Block(2,3,3,STONE:0)
Block(2,6,3,STONE:0)
Block(2,5,3,STONE:0)
Block(-5,5,-3,STONE:0)
Block(-5,8,-3,STONE:0)
Block(7,8,-3,STONE:0)
Block(7,7,-3,STONE:0)
Block(-5,9,-3,STONE:0)
Block(-5,6,-3,STONE:0)
Block(-5,7,-3,STONE:0)
Block(3,7,1,STONE:0)
Block(3,6,1,STONE:0)
Block(-4,5,-6,STONE:0)
Block(3,5,1,STONE:0)
Block(3,4,1,STONE:0)
Block(3,9,1,STONE:0)
Block(3,8,1,STONE:0)
Block(-4,7,-6,STONE:0)
Block(-4,6,-6,STONE:0)
Block(-4,9,-6,STONE:0)
Block(-4,8,-6,STONE:0)
Block(3,3,1,STONE:0)
Block(3,2,1,STONE:0)
Block(-1,3,-5,STONE:0)
Block(2,8,-9,GRASS:0)
Block(2,2,3,STONE:0)
Block(-1,9,-5,STONE:0)
Block(-1,8,-5,STONE:0)
Block(-1,7,-5,STONE:0)
Block(-1,6,-5,STONE:0)
Block(-1,5,-5,STONE:0)
Block(-1,4,-5,STONE:0)
Block(1,10,-4,STONE:0)
Block(-1,14,-6,STONE:0)
Block(-1,15,-6,STONE:0)
Block(-1,12,-6,STONE:0)
Block(1,12,-4,STONE:0)
Block(1,11,-4,STONE:0)
Block(-1,13,-6,STONE:0)
Block(-1,10,-6,STONE:0)
Block(1,14,-4,STONE:0)
Block(-1,11,-6,STONE:0)
Block(1,13,-4,STONE:0)
Block(1,16,-4,GRASS:0)
Block(1,15,-4,STONE:0)
Block(-3,7,-8,STONE:0)
Block(-3,8,-8,STONE:0)
Block(-3,9,-8,STONE:0)
Block(-5,10,3,GRASS:0)
Block(-1,4,1,STONE:0)
Block(-1,3,1,STONE:0)
Block(-1,6,1,STONE:0)
Block(-1,5,1,STONE:0)
Block(-1,8,1,STONE:0)
Block(-1,7,1,STONE:0)
Block(-1,9,1,STONE:0)
Block(-1,2,1,STONE:0)
Block(-1,1,1,STONE:0)
Block(6,7,-2,STONE:0)
Block(6,8,-2,STONE:0)
Block(6,5,-2,STONE:0)
Block(6,6,-2,STONE:0)
Block(6,3,-2,AIR)
Block(6,4,-2,STONE:0)
Block(-2,12,-6,STONE:0)
Block(-2,11,-6,STONE:0)
Block(-2,14,-6,STONE:0)
Block(-2,13,-6,STONE:0)
Block(6,9,-2,STONE:0)
Block(-2,10,-6,STONE:0)
Block(4,7,-3,STONE:0)
Block(4,6,-3,STONE:0)
Block(4,9,-3,STONE:0)
Block(4,8,-3,STONE:0)
Block(4,3,-3,STONE:0)
Block(0,12,-4,STONE:0)
Block(0,13,-4,STONE:0)
Block(4,5,-3,STONE:0)
Block(0,10,-4,STONE:0)
Block(4,4,-3,STONE:0)
Block(0,11,-4,STONE:0)
Block(0,16,-4,GRASS:0)
Block(0,14,-4,STONE:0)
Block(0,15,-4,STONE:0)
Block(6,10,2,STONE:0)
Block(-7,10,-6,GRASS:0)
Block(0,6,3,STONE:0)
Block(6,12,2,GRASS:0)
Block(0,5,3,STONE:0)
Block(6,11,2,DIRT:0)
Block(0,8,3,STONE:0)
Block(0,7,3,STONE:0)
Block(0,9,3,STONE:0)
Block(3,6,-6,STONE:0)
Block(1,9,1,STONE:0)
Block(3,7,-6,STONE:0)
Block(1,8,1,STONE:0)
Block(1,7,1,STONE:0)
Block(3,8,-6,STONE:0)
Block(1,6,1,STONE:0)
Block(3,9,-6,STONE:0)
Block(1,9,-7,STONE:0)
Block(1,7,-7,STONE:0)
Block(-1,16,-6,GRASS:0)
Block(1,8,-7,STONE:0)
Block(-1,17,-6,LONG_GRASS:1)
Block(1,5,-7,STONE:0)
Block(-5,8,-7,STONE:0)
Block(1,6,-7,STONE:0)
Block(-5,9,-7,STONE:0)
Block(-5,7,-7,STONE:0)
Block(-3,11,0,STONE:0)
Block(-3,12,0,GRASS:0)
Block(-7,8,-6,STONE:0)
Block(-3,10,0,STONE:0)
Block(-3,13,-6,STONE:0)
Block(-3,12,-6,STONE:0)
Block(-3,11,-6,STONE:0)
Block(-3,13,0,AIR)
Block(-3,10,-6,STONE:0)
Block(-7,9,-6,STONE:0)
Block(-2,16,-6,GRASS:0)
Block(-2,15,-6,STONE:0)
Block(-6,12,-6,GRASS:0)
Block(-6,11,-6,STONE:0)
Block(4,11,3,GRASS:0)
Block(4,10,3,STONE:0)
Block(-3,16,-6,GRASS:0)
Block(-3,15,-6,STONE:0)
Block(-3,14,-6,STONE:0)
Block(-1,7,-1,STONE:0)
Block(-1,6,-1,STONE:0)
Block(-1,5,-1,STONE:0)
Block(-1,4,-1,STONE:0)
Block(-1,3,-1,STONE:0)
Block(-1,2,-1,STONE:0)
Block(-1,1,-1,STONE:0)
Block(-1,0,-1,STONE:0)
Block(-1,9,-1,STONE:0)
Block(-1,8,-1,STONE:0)
Block(-3,3,-4,STONE:0)
Block(-3,4,-4,STONE:0)
Block(-3,5,-4,STONE:0)
Block(-3,6,-4,STONE:0)
Block(1,5,1,STONE:0)
Block(-3,7,-4,STONE:0)
Block(1,4,1,STONE:0)
Block(-3,8,-4,STONE:0)
Block(1,3,1,STONE:0)
Block(-3,9,-4,STONE:0)
Block(1,2,1,STONE:0)
Block(1,1,1,STONE:0)
Block(-4,10,-6,STONE:0)
Block(1,0,1,STONE:0)
Block(-4,12,-6,STONE:0)
Block(-4,11,-6,STONE:0)
Block(-4,14,-6,STONE:0)
Block(-4,13,-6,STONE:0)
Block(-4,16,-6,GRASS:0)
Block(-4,15,-6,STONE:0)
Block(0,2,3,STONE:0)
Block(0,4,3,STONE:0)
Block(0,3,3,STONE:0)
Block(-3,9,1,STONE:0)
Block(-3,6,1,STONE:0)
Block(-3,5,1,STONE:0)
Block(-3,8,1,STONE:0)
Block(-3,7,1,STONE:0)
Block(-3,2,1,STONE:0)
Block(-3,4,1,STONE:0)
Block(-3,3,1,STONE:0)
Block(-5,14,-6,GRASS:0)
Block(-2,9,3,STONE:0)
Block(-5,13,-6,STONE:0)
Block(-2,8,3,STONE:0)
Block(-5,12,-6,STONE:0)
Block(-2,7,3,STONE:0)
Block(-1,8,5,DIRT:0)
Block(-2,6,3,STONE:0)
Block(-1,7,5,STONE:0)
Block(-2,5,3,STONE:0)
Block(-2,4,3,STONE:0)
Block(-1,9,5,GRASS:0)
Block(-2,3,3,STONE:0)
Block(-2,2,3,STONE:0)
Block(-6,10,-6,STONE:0)

#######################################################################
# +-----------------------------------------------------------------+ #
# |                            BO3 checks                           | #
# +-----------------------------------------------------------------+ #
#######################################################################


#######################################################################
# +-----------------------------------------------------------------+ #
# |                             Branches                            | #
# +-----------------------------------------------------------------+ #
#######################################################################


#######################################################################
# +-----------------------------------------------------------------+ #
# |                             Entities                            | #
# +-----------------------------------------------------------------+ #
#######################################################################


#######################################################################
# +-----------------------------------------------------------------+ #
# |                            Particles                            | #
# +-----------------------------------------------------------------+ #
#######################################################################


#######################################################################
# +-----------------------------------------------------------------+ #
# |                             Spawners                            | #
# +-----------------------------------------------------------------+ #
#######################################################################


#######################################################################
# +-----------------------------------------------------------------+ #
# |                             ModData                             | #
# +-----------------------------------------------------------------+ #
#######################################################################

