
#######################################################################
# +-----------------------------------------------------------------+ #
# |                            BO3 object                           | #
# +-----------------------------------------------------------------+ #
#######################################################################

Author: LordSmellyPants

Description: Converted version of the BO2 FloatingIsland3

Version: 3

SettingsMode: WriteWithoutComments


#######################################################################
# +-----------------------------------------------------------------+ #
# |                          Main settings                          | #
# +-----------------------------------------------------------------+ #
#######################################################################

Tree: false

Frequency: 1

Rarity: 5.0

RotateRandomly: true

SpawnHeight: randomY

SpawnHeightOffset: 0

SpawnHeightVariance: 0

##############################
# Height Limits for the BO3. #
##############################

MinHeight: 30

MaxHeight: 110

######################
# Extrusion settings #
######################

ExtrudeMode: None

ExtrudeThroughBlocks: AIR

MaxBranchDepth: 10

ExcludedBiomes: 


#######################################################################
# +-----------------------------------------------------------------+ #
# |                      Source block settings                      | #
# +-----------------------------------------------------------------+ #
#######################################################################

SourceBlocks: AIR,STATIONARY_WATER:0

MaxPercentageOutsideSourceBlock: 0

OutsideSourceBlock: placeAnyway

DoReplaceBlocks: true

IsOTGPlus: false


#######################################################################
# +-----------------------------------------------------------------+ #
# |                              Blocks                             | #
# +-----------------------------------------------------------------+ #
#######################################################################

Block(3,1,-3,STONE:0)
Block(6,2,1,AIR)
Block(3,2,-3,STONE:0)
Block(3,3,-3,STONE:0)
Block(6,3,1,GRASS:0)
Block(3,4,-3,GRASS:0)
Block(1,4,-4,GRASS:0)
Block(2,4,2,GRASS:0)
Block(1,2,-4,STONE:0)
Block(1,3,-4,STONE:0)
Block(-1,4,-3,GRASS:0)
Block(-1,3,-3,STONE:0)
Block(-1,2,-3,STONE:0)
Block(3,5,0,GRASS:0)
Block(-1,1,-3,STONE:0)
Block(2,2,1,STONE:0)
Block(2,1,1,STONE:0)
Block(2,4,1,STONE:0)
Block(2,3,1,STONE:0)
Block(5,3,-3,GRASS:0)
Block(1,3,3,AIR)
Block(-1,1,0,AIR)
Block(-1,3,0,GRASS:0)
Block(-1,2,0,AIR)
Block(0,4,-1,GRASS:0)
Block(3,1,-2,STONE:0)
Block(3,2,-2,STONE:0)
Block(6,3,0,AIR)
Block(3,3,-2,STONE:0)
Block(6,2,0,AIR)
Block(0,3,-1,STONE:0)
Block(3,4,-2,GRASS:0)
Block(0,2,-1,STONE:0)
Block(6,4,0,AIR)
Block(1,3,-3,STONE:0)
Block(1,4,-3,GRASS:0)
Block(1,1,-3,STONE:0)
Block(1,2,-3,STONE:0)
Block(3,4,0,STONE:0)
Block(3,3,0,STONE:0)
Block(3,2,0,STONE:0)
Block(3,1,0,STONE:0)
Block(-1,4,-2,GRASS:0)
Block(3,5,1,GRASS:0)
Block(-1,3,-2,STONE:0)
Block(3,4,1,STONE:0)
Block(-1,2,-2,STONE:0)
Block(2,3,2,STONE:0)
Block(2,2,2,STONE:0)
Block(3,3,-5,AIR)
Block(0,3,0,STONE:0)
Block(0,2,0,STONE:0)
Block(0,4,0,GRASS:0)
Block(1,4,-2,GRASS:0)
Block(1,5,-2,AIR)
Block(1,2,-2,STONE:0)
Block(1,3,-2,STONE:0)
Block(-2,3,-5,GRASS:0)
Block(4,3,-5,AIR)
Block(1,1,-2,STONE:0)
Block(-2,4,-5,LONG_GRASS:1)
Block(3,3,1,STONE:0)
Block(3,2,1,STONE:0)
Block(3,1,1,STONE:0)
Block(-1,3,-5,GRASS:0)
Block(3,4,2,GRASS:0)
Block(3,3,2,STONE:0)
Block(-1,4,-5,AIR)
Block(2,1,-1,STONE:0)
Block(4,5,0,GRASS:0)
Block(4,4,0,STONE:0)
Block(2,5,-1,GRASS:0)
Block(2,4,-1,STONE:0)
Block(2,3,-1,STONE:0)
Block(2,2,-1,STONE:0)
Block(4,1,0,STONE:0)
Block(4,0,0,STONE:0)
Block(3,1,-4,AIR)
Block(4,3,0,STONE:0)
Block(3,2,-4,AIR)
Block(4,2,0,STONE:0)
Block(3,3,-4,GRASS:0)
Block(1,5,-1,GRASS:0)
Block(1,3,-1,STONE:0)
Block(1,4,-1,STONE:0)
Block(1,1,-1,STONE:0)
Block(1,2,-1,STONE:0)
Block(4,3,-4,GRASS:0)
Block(3,2,2,STONE:0)
Block(-1,4,-4,GRASS:0)
Block(-1,3,-4,STONE:0)
Block(3,4,3,LONG_GRASS:1)
Block(-1,2,-4,STONE:0)
Block(3,3,3,GRASS:0)
Block(4,4,1,STONE:0)
Block(4,3,1,STONE:0)
Block(4,5,1,GRASS:0)
Block(2,4,-2,GRASS:0)
Block(2,3,-2,STONE:0)
Block(2,2,-2,STONE:0)
Block(2,1,-2,STONE:0)
Block(0,2,-4,STONE:0)
Block(0,4,-4,GRASS:0)
Block(0,3,-4,STONE:0)
Block(6,3,-2,AIR)
Block(0,5,-4,LONG_GRASS:1)
Block(6,2,-2,AIR)
Block(4,0,1,STONE:0)
Block(4,2,1,STONE:0)
Block(4,1,1,STONE:0)
Block(-2,2,-3,STONE:0)
Block(4,3,-3,STONE:0)
Block(4,2,-3,STONE:0)
Block(4,4,-3,GRASS:0)
Block(-2,4,-3,GRASS:0)
Block(-2,3,-3,STONE:0)
Block(-4,3,-3,GRASS:0)
Block(4,3,2,STONE:0)
Block(4,2,2,STONE:0)
Block(4,4,2,GRASS:0)
Block(2,3,-3,STONE:0)
Block(2,2,-3,STONE:0)
Block(2,1,-3,STONE:0)
Block(2,4,-3,GRASS:0)
Block(5,4,0,GRASS:0)
Block(5,3,0,STONE:0)
Block(5,2,0,STONE:0)
Block(0,2,1,STONE:0)
Block(0,3,-5,GRASS:0)
Block(0,2,-5,AIR)
Block(0,4,1,GRASS:0)
Block(0,3,1,STONE:0)
Block(6,2,-1,AIR)
Block(6,3,-1,AIR)
Block(4,1,2,STONE:0)
Block(4,4,-2,GRASS:0)
Block(-2,3,-4,GRASS:0)
Block(4,3,-2,STONE:0)
Block(4,5,-2,LONG_GRASS:1)
Block(4,2,-2,STONE:0)
Block(4,1,-2,STONE:0)
Block(4,2,3,STONE:0)
Block(4,3,3,GRASS:0)
Block(2,2,-4,STONE:0)
Block(-3,3,-5,GRASS:0)
Block(1,5,0,GRASS:0)
Block(1,4,0,STONE:0)
Block(2,4,-4,AIR)
Block(2,3,-4,GRASS:0)
Block(1,3,0,STONE:0)
Block(1,2,0,STONE:0)
Block(5,4,1,GRASS:0)
Block(5,3,1,STONE:0)
Block(5,2,1,STONE:0)
Block(5,1,1,STONE:0)
Block(0,4,-2,STONE:0)
Block(0,3,-2,STONE:0)
Block(0,5,-2,GRASS:0)
Block(3,1,-1,STONE:0)
Block(3,2,-1,STONE:0)
Block(3,3,-1,STONE:0)
Block(3,4,-1,STONE:0)
Block(0,2,-2,STONE:0)
Block(3,5,-1,GRASS:0)
Block(0,1,-2,STONE:0)
Block(4,5,-1,GRASS:0)
Block(-2,4,-1,AIR)
Block(4,4,-1,STONE:0)
Block(-2,3,-1,AIR)
Block(4,1,-1,STONE:0)
Block(4,3,-1,STONE:0)
Block(4,2,-1,STONE:0)
Block(-1,4,-1,GRASS:0)
Block(-1,3,-1,STONE:0)
Block(5,3,-1,GRASS:0)
Block(5,2,-1,STONE:0)
Block(-3,3,-4,GRASS:0)
Block(1,5,1,GRASS:0)
Block(1,4,1,STONE:0)
Block(2,3,-5,GRASS:0)
Block(1,3,1,STONE:0)
Block(1,2,1,STONE:0)
Block(2,2,-5,AIR)
Block(5,3,2,GRASS:0)
Block(0,3,-3,STONE:0)
Block(0,2,-3,STONE:0)
Block(0,5,-3,GRASS:0)
Block(0,4,-3,STONE:0)
Block(0,1,-3,STONE:0)
Block(1,3,-5,GRASS:0)
Block(2,5,1,GRASS:0)
Block(-2,3,-2,GRASS:0)
Block(2,3,0,STONE:0)
Block(2,2,0,STONE:0)
Block(2,5,0,GRASS:0)
Block(2,4,0,STONE:0)
Block(2,1,0,STONE:0)
Block(5,3,-2,GRASS:0)
Block(-3,3,-3,STONE:0)
Block(-3,4,-3,GRASS:0)
Block(1,3,2,GRASS:0)

#######################################################################
# +-----------------------------------------------------------------+ #
# |                            BO3 checks                           | #
# +-----------------------------------------------------------------+ #
#######################################################################


#######################################################################
# +-----------------------------------------------------------------+ #
# |                             Branches                            | #
# +-----------------------------------------------------------------+ #
#######################################################################


#######################################################################
# +-----------------------------------------------------------------+ #
# |                             Entities                            | #
# +-----------------------------------------------------------------+ #
#######################################################################


#######################################################################
# +-----------------------------------------------------------------+ #
# |                            Particles                            | #
# +-----------------------------------------------------------------+ #
#######################################################################


#######################################################################
# +-----------------------------------------------------------------+ #
# |                             Spawners                            | #
# +-----------------------------------------------------------------+ #
#######################################################################


#######################################################################
# +-----------------------------------------------------------------+ #
# |                             ModData                             | #
# +-----------------------------------------------------------------+ #
#######################################################################

