
#######################################################################
# +-----------------------------------------------------------------+ #
# |                            BO3 object                           | #
# +-----------------------------------------------------------------+ #
#######################################################################

Author: LordSmellyPants

Description: Converted version of the BO2 FloatingIsland5

Version: 3

SettingsMode: WriteWithoutComments


#######################################################################
# +-----------------------------------------------------------------+ #
# |                          Main settings                          | #
# +-----------------------------------------------------------------+ #
#######################################################################

Tree: false

Frequency: 1

Rarity: 5.0

RotateRandomly: true

SpawnHeight: randomY

SpawnHeightOffset: 0

SpawnHeightVariance: 0

##############################
# Height Limits for the BO3. #
##############################

MinHeight: 30

MaxHeight: 110

######################
# Extrusion settings #
######################

ExtrudeMode: None

ExtrudeThroughBlocks: AIR

MaxBranchDepth: 10

ExcludedBiomes: 


#######################################################################
# +-----------------------------------------------------------------+ #
# |                      Source block settings                      | #
# +-----------------------------------------------------------------+ #
#######################################################################

SourceBlocks: AIR,STATIONARY_WATER:0

MaxPercentageOutsideSourceBlock: 0

OutsideSourceBlock: placeAnyway

DoReplaceBlocks: true

IsOTGPlus: false


#######################################################################
# +-----------------------------------------------------------------+ #
# |                              Blocks                             | #
# +-----------------------------------------------------------------+ #
#######################################################################

Block(-6,5,-6,GRASS:0)
Block(1,6,-4,GRASS:0)
Block(1,4,-4,STONE:0)
Block(1,5,-4,STONE:0)
Block(-2,5,-7,GRASS:0)
Block(1,3,-4,STONE:0)
Block(-6,10,0,STONE:0)
Block(-6,11,0,GRASS:0)
Block(-2,10,-3,AIR)
Block(-4,9,1,STONE:0)
Block(-4,8,1,STONE:0)
Block(-4,3,1,STONE:0)
Block(-4,7,1,STONE:0)
Block(-4,6,1,STONE:0)
Block(-4,5,1,STONE:0)
Block(-4,4,1,STONE:0)
Block(-3,8,3,STONE:0)
Block(1,10,2,GRASS:0)
Block(-3,7,3,STONE:0)
Block(-3,9,3,STONE:0)
Block(-3,4,3,STONE:0)
Block(-3,3,3,STONE:0)
Block(-3,6,3,STONE:0)
Block(-3,5,3,STONE:0)
Block(-7,5,-2,STONE:0)
Block(-2,9,5,STONE:0)
Block(-7,6,-2,STONE:0)
Block(-2,8,5,STONE:0)
Block(-1,4,7,STONE:0)
Block(-7,7,-2,GRASS:0)
Block(-2,7,5,STONE:0)
Block(-2,6,5,STONE:0)
Block(-2,5,5,STONE:0)
Block(-1,6,7,STONE:0)
Block(-2,4,5,STONE:0)
Block(-1,5,7,STONE:0)
Block(-2,3,5,DIRT:0)
Block(-1,7,7,GRASS:0)
Block(-3,2,-1,STONE:0)
Block(-3,3,-1,STONE:0)
Block(-3,4,-1,STONE:0)
Block(-3,5,-1,STONE:0)
Block(-3,6,-1,STONE:0)
Block(-3,7,-1,STONE:0)
Block(-3,8,-1,STONE:0)
Block(-3,9,-1,STONE:0)
Block(-7,4,-2,STONE:0)
Block(-3,11,3,STONE:0)
Block(-3,10,3,STONE:0)
Block(0,1,0,STONE:0)
Block(0,3,0,STONE:0)
Block(0,2,-6,AIR)
Block(-3,13,3,LONG_GRASS:1)
Block(0,2,0,STONE:0)
Block(-3,12,3,GRASS:0)
Block(0,4,-6,STONE:0)
Block(0,5,0,STONE:0)
Block(0,4,0,STONE:0)
Block(0,3,-6,AIR)
Block(0,7,0,STONE:0)
Block(0,5,-6,GRASS:0)
Block(0,6,0,STONE:0)
Block(-6,7,-4,GRASS:0)
Block(-6,6,-4,STONE:0)
Block(-6,5,-4,STONE:0)
Block(-6,4,-4,STONE:0)
Block(-2,5,-5,GRAVEL)
Block(1,6,-2,STONE:0)
Block(-2,6,-5,STONE:0)
Block(1,7,-2,GRASS:0)
Block(1,4,-2,STONE:0)
Block(-2,7,-5,GRASS:0)
Block(1,5,-2,STONE:0)
Block(1,2,-2,STONE:0)
Block(-2,2,-5,STONE:0)
Block(1,3,-2,STONE:0)
Block(-2,3,-5,STONE:0)
Block(1,1,-2,STONE:0)
Block(-2,4,-5,STONE:0)
Block(-4,8,-1,STONE:0)
Block(-4,7,-1,STONE:0)
Block(-4,9,-1,STONE:0)
Block(-4,4,-1,STONE:0)
Block(-4,3,-1,STONE:0)
Block(-4,10,3,STONE:0)
Block(-4,6,-1,STONE:0)
Block(-4,11,3,GRASS:0)
Block(-4,5,-1,STONE:0)
Block(-5,8,1,STONE:0)
Block(-5,7,1,STONE:0)
Block(-5,9,1,STONE:0)
Block(-4,2,-1,STONE:0)
Block(-5,4,1,STONE:0)
Block(-5,6,1,STONE:0)
Block(-5,5,1,STONE:0)
Block(-4,9,3,STONE:0)
Block(-4,8,3,STONE:0)
Block(-4,7,3,STONE:0)
Block(-4,6,3,STONE:0)
Block(-4,5,3,STONE:0)
Block(-4,4,3,STONE:0)
Block(-3,9,5,GRASS:0)
Block(-3,6,5,STONE:0)
Block(-3,5,5,STONE:0)
Block(-3,8,5,STONE:0)
Block(-3,7,5,STONE:0)
Block(-3,4,5,STONE:0)
Block(-6,11,2,STONE:0)
Block(-6,10,2,STONE:0)
Block(-6,13,2,GRASS:0)
Block(-6,12,2,STONE:0)
Block(-7,7,-4,AIR)
Block(-2,8,7,GRASS:0)
Block(-2,7,7,STONE:0)
Block(-2,6,7,STONE:0)
Block(-7,4,-4,AIR)
Block(-7,5,-4,GRASS:0)
Block(-2,5,7,STONE:0)
Block(-2,4,7,STONE:0)
Block(2,4,-2,STONE:0)
Block(2,3,-2,STONE:0)
Block(2,2,-2,STONE:0)
Block(0,9,0,GRASS:0)
Block(0,8,0,STONE:0)
Block(2,6,-2,GRASS:0)
Block(2,5,-2,STONE:0)
Block(0,2,-4,STONE:0)
Block(0,1,-4,AIR)
Block(0,4,-4,STONE:0)
Block(0,3,-4,STONE:0)
Block(0,6,-4,STONE:0)
Block(0,5,-4,STONE:0)
Block(0,7,-4,GRASS:0)
Block(-2,9,-3,GRASS:0)
Block(-2,8,-3,STONE:0)
Block(-2,7,-3,STONE:0)
Block(-2,2,-3,STONE:0)
Block(-2,1,-3,STONE:0)
Block(-2,0,-3,STONE:0)
Block(-2,6,-3,STONE:0)
Block(-2,5,-3,STONE:0)
Block(-2,4,-3,STONE:0)
Block(-2,3,-3,STONE:0)
Block(-6,5,1,STONE:0)
Block(-4,6,-3,STONE:0)
Block(-4,5,-3,STONE:0)
Block(-4,8,-3,STONE:0)
Block(-4,7,-3,STONE:0)
Block(-4,2,-3,STONE:0)
Block(-4,4,-3,STONE:0)
Block(-4,3,-3,STONE:0)
Block(-1,5,-7,GRASS:0)
Block(-6,9,1,STONE:0)
Block(-6,8,1,STONE:0)
Block(-4,9,-3,GRASS:0)
Block(-6,7,1,STONE:0)
Block(-6,6,1,STONE:0)
Block(-5,6,3,STONE:0)
Block(-5,5,3,STONE:0)
Block(-5,8,3,STONE:0)
Block(-5,7,3,STONE:0)
Block(-5,9,3,STONE:0)
Block(-4,7,5,STONE:0)
Block(-4,6,5,STONE:0)
Block(-4,5,5,STONE:0)
Block(-4,8,5,GRASS:0)
Block(-2,10,-1,GRASS:0)
Block(-3,6,7,GRASS:0)
Block(-3,5,7,STONE:0)
Block(-2,5,9,GRASS:0)
Block(3,5,5,GRASS:0)
Block(-5,10,-2,GRASS:0)
Block(-2,10,1,STONE:0)
Block(-2,12,1,GRASS:0)
Block(-2,11,1,STONE:0)
Block(4,2,3,AIR)
Block(4,4,3,STONE:0)
Block(4,3,3,AIR)
Block(4,6,3,LONG_GRASS:1)
Block(4,5,3,GRASS:0)
Block(2,6,-4,AIR)
Block(2,5,-4,GRASS:0)
Block(2,4,-4,STONE:0)
Block(5,5,1,GRASS:0)
Block(5,4,1,STONE:0)
Block(0,4,-2,STONE:0)
Block(0,3,-2,STONE:0)
Block(0,6,-2,STONE:0)
Block(0,5,-2,STONE:0)
Block(0,8,-2,GRASS:0)
Block(-2,0,-1,AIR)
Block(0,7,-2,STONE:0)
Block(0,0,-2,STONE:0)
Block(0,2,-2,STONE:0)
Block(0,1,-2,STONE:0)
Block(-2,10,3,STONE:0)
Block(-2,9,-1,STONE:0)
Block(-2,4,-1,STONE:0)
Block(-2,3,-1,STONE:0)
Block(-2,2,-1,STONE:0)
Block(-2,1,-1,STONE:0)
Block(-2,8,-1,STONE:0)
Block(-7,5,1,GRASS:0)
Block(-2,7,-1,STONE:0)
Block(-2,6,-1,STONE:0)
Block(-2,5,-1,STONE:0)
Block(-4,4,-5,GRAVEL)
Block(-4,3,-5,STONE:0)
Block(-4,6,-5,GRASS:0)
Block(-4,5,-5,GRAVEL)
Block(-6,9,3,AIR)
Block(-6,8,3,AIR)
Block(-6,7,3,AIR)
Block(-6,6,3,AIR)
Block(-2,11,3,STONE:0)
Block(-6,10,-1,GRASS:0)
Block(-2,12,3,GRASS:0)
Block(-5,6,5,AIR)
Block(-5,5,5,AIR)
Block(-5,8,5,AIR)
Block(-5,7,5,AIR)
Block(5,5,-1,GRASS:0)
Block(5,6,-1,LONG_GRASS:1)
Block(0,10,2,GRASS:0)
Block(-4,11,-2,LONG_GRASS:1)
Block(-4,10,-2,GRASS:0)
Block(-4,12,1,GRASS:0)
Block(-4,11,1,STONE:0)
Block(-4,10,1,STONE:0)
Block(2,5,-6,GRASS:0)
Block(3,5,-3,GRASS:0)
Block(1,8,4,GRASS:0)
Block(1,7,4,STONE:0)
Block(1,6,4,STONE:0)
Block(1,5,4,STONE:0)
Block(1,4,4,STONE:0)
Block(1,3,4,STONE:0)
Block(-5,13,2,GRASS:0)
Block(3,4,-3,STONE:0)
Block(2,9,2,GRASS:0)
Block(2,8,2,STONE:0)
Block(2,5,2,STONE:0)
Block(2,4,2,STONE:0)
Block(2,7,2,STONE:0)
Block(2,6,2,STONE:0)
Block(-5,5,-2,STONE:0)
Block(-5,6,-2,STONE:0)
Block(-5,3,-2,STONE:0)
Block(-5,4,-2,STONE:0)
Block(-5,9,-2,STONE:0)
Block(-5,7,-2,STONE:0)
Block(-5,8,-2,STONE:0)
Block(-1,5,0,STONE:0)
Block(-1,4,0,STONE:0)
Block(3,6,0,GRASS:0)
Block(-1,7,0,STONE:0)
Block(3,5,0,STONE:0)
Block(-1,6,0,STONE:0)
Block(-1,9,0,STONE:0)
Block(-1,8,0,STONE:0)
Block(-5,10,2,STONE:0)
Block(-5,11,2,STONE:0)
Block(-5,12,2,STONE:0)
Block(-1,1,0,STONE:0)
Block(-1,3,0,STONE:0)
Block(-1,2,0,STONE:0)
Block(3,4,0,STONE:0)
Block(3,3,0,STONE:0)
Block(3,2,0,STONE:0)
Block(3,1,0,AIR)
Block(-1,6,-2,STONE:0)
Block(-1,5,-2,STONE:0)
Block(-1,4,-2,STONE:0)
Block(-1,3,-2,STONE:0)
Block(-1,2,-2,STONE:0)
Block(-1,1,-2,STONE:0)
Block(-1,0,-2,STONE:0)
Block(2,1,2,STONE:0)
Block(2,3,2,STONE:0)
Block(2,2,2,STONE:0)
Block(-1,9,-2,GRASS:0)
Block(-1,8,-2,STONE:0)
Block(-1,7,-2,STONE:0)
Block(-1,10,2,STONE:0)
Block(0,5,6,STONE:0)
Block(-1,12,2,GRASS:0)
Block(0,4,6,STONE:0)
Block(-1,11,2,STONE:0)
Block(0,7,6,GRASS:0)
Block(0,6,6,STONE:0)
Block(0,8,6,AIR)
Block(3,4,-5,AIR)
Block(1,6,6,GRASS:0)
Block(3,5,-5,AIR)
Block(1,5,6,STONE:0)
Block(1,4,6,STONE:0)
Block(2,7,4,GRASS:0)
Block(2,6,4,STONE:0)
Block(2,3,4,STONE:0)
Block(2,5,4,STONE:0)
Block(2,4,4,STONE:0)
Block(-1,3,2,STONE:0)
Block(3,6,2,STONE:0)
Block(-1,2,2,STONE:0)
Block(3,5,2,STONE:0)
Block(3,4,2,STONE:0)
Block(-1,5,2,STONE:0)
Block(3,3,2,STONE:0)
Block(-1,4,2,STONE:0)
Block(-1,7,2,STONE:0)
Block(-1,6,2,STONE:0)
Block(-1,9,2,STONE:0)
Block(3,7,2,GRASS:0)
Block(-1,8,2,STONE:0)
Block(-2,9,0,STONE:0)
Block(-2,8,0,STONE:0)
Block(-2,7,0,STONE:0)
Block(-2,6,0,STONE:0)
Block(-2,5,0,STONE:0)
Block(-2,4,0,STONE:0)
Block(-2,3,0,STONE:0)
Block(-2,2,0,STONE:0)
Block(4,5,0,GRASS:0)
Block(-2,1,0,STONE:0)
Block(4,4,0,STONE:0)
Block(4,6,0,LONG_GRASS:1)
Block(-1,10,0,GRASS:0)
Block(4,1,0,AIR)
Block(4,3,0,STONE:0)
Block(4,2,0,AIR)
Block(-2,10,5,GRASS:0)
Block(3,2,2,STONE:0)
Block(-1,4,-4,STONE:0)
Block(-1,3,-4,STONE:0)
Block(-1,2,-4,STONE:0)
Block(-1,1,-4,STONE:0)
Block(-1,7,-4,GRASS:0)
Block(-1,6,-4,STONE:0)
Block(-1,5,-4,STONE:0)
Block(0,5,8,GRASS:0)
Block(0,3,2,STONE:0)
Block(0,2,2,STONE:0)
Block(0,5,2,STONE:0)
Block(1,8,0,GRASS:0)
Block(0,4,2,STONE:0)
Block(1,7,0,STONE:0)
Block(-3,7,0,STONE:0)
Block(-3,6,0,STONE:0)
Block(-3,9,0,STONE:0)
Block(-3,8,0,STONE:0)
Block(-3,3,0,STONE:0)
Block(-5,5,-6,GRASS:0)
Block(-3,2,0,STONE:0)
Block(-3,5,0,STONE:0)
Block(-3,4,0,STONE:0)
Block(-1,3,4,STONE:0)
Block(-1,5,4,STONE:0)
Block(-1,4,4,STONE:0)
Block(-1,7,4,STONE:0)
Block(-1,6,4,STONE:0)
Block(-2,9,2,STONE:0)
Block(-2,8,2,STONE:0)
Block(-1,9,4,GRASS:0)
Block(-2,7,2,STONE:0)
Block(-1,8,4,STONE:0)
Block(-2,6,2,STONE:0)
Block(-2,5,2,STONE:0)
Block(-2,4,2,STONE:0)
Block(-2,3,2,STONE:0)
Block(-2,2,2,STONE:0)
Block(-1,11,4,AIR)
Block(-6,9,-1,STONE:0)
Block(-6,8,-1,STONE:0)
Block(-6,7,-1,STONE:0)
Block(-6,6,-1,STONE:0)
Block(-6,5,-1,STONE:0)
Block(-6,4,-1,STONE:0)
Block(4,4,-2,STONE:0)
Block(4,5,-2,GRASS:0)
Block(-3,3,-5,STONE:0)
Block(-3,4,-5,GRAVEL)
Block(-3,5,-5,GRAVEL)
Block(-3,6,-5,STONE:0)
Block(1,6,0,STONE:0)
Block(0,7,2,STONE:0)
Block(1,5,0,STONE:0)
Block(0,6,2,STONE:0)
Block(-3,7,-5,GRASS:0)
Block(-6,10,3,AIR)
Block(1,4,0,STONE:0)
Block(0,9,2,STONE:0)
Block(1,3,0,STONE:0)
Block(0,8,2,STONE:0)
Block(1,2,0,STONE:0)
Block(-6,13,3,AIR)
Block(1,1,0,STONE:0)
Block(-6,11,3,AIR)
Block(-6,12,3,AIR)
Block(-4,9,0,STONE:0)
Block(1,9,2,STONE:0)
Block(1,8,2,STONE:0)
Block(1,7,2,STONE:0)
Block(0,3,4,STONE:0)
Block(1,6,2,STONE:0)
Block(1,5,2,STONE:0)
Block(-4,4,0,STONE:0)
Block(-4,3,0,STONE:0)
Block(-4,2,0,AIR)
Block(-4,8,0,STONE:0)
Block(-4,7,0,STONE:0)
Block(-4,6,0,STONE:0)
Block(-4,5,0,STONE:0)
Block(1,4,-6,STONE:0)
Block(1,5,-6,GRASS:0)
Block(2,7,0,GRASS:0)
Block(-3,9,2,STONE:0)
Block(2,6,0,STONE:0)
Block(-3,8,2,STONE:0)
Block(-3,5,2,STONE:0)
Block(-5,4,-4,STONE:0)
Block(-3,4,2,STONE:0)
Block(-3,7,2,STONE:0)
Block(-3,6,2,STONE:0)
Block(-5,7,-4,GRASS:0)
Block(-3,3,2,STONE:0)
Block(-5,5,-4,STONE:0)
Block(-5,6,-4,STONE:0)
Block(-3,2,2,AIR)
Block(-1,3,6,STONE:0)
Block(-2,9,4,STONE:0)
Block(-1,5,6,STONE:0)
Block(-2,8,4,STONE:0)
Block(-1,4,6,STONE:0)
Block(-2,7,4,STONE:0)
Block(-2,6,4,STONE:0)
Block(-1,7,6,STONE:0)
Block(-2,5,4,STONE:0)
Block(-1,6,6,STONE:0)
Block(-2,4,4,STONE:0)
Block(-2,3,4,STONE:0)
Block(-1,8,6,GRASS:0)
Block(-3,12,1,GRASS:0)
Block(-3,10,1,STONE:0)
Block(-3,11,1,STONE:0)
Block(-8,5,-2,GRASS:0)
Block(-5,11,0,GRASS:0)
Block(2,3,0,STONE:0)
Block(2,2,0,STONE:0)
Block(2,5,0,STONE:0)
Block(2,4,0,STONE:0)
Block(2,1,0,STONE:0)
Block(-3,0,-3,AIR)
Block(-3,1,-3,STONE:0)
Block(-3,2,-3,STONE:0)
Block(-3,3,-3,STONE:0)
Block(-3,4,-3,STONE:0)
Block(-5,10,0,STONE:0)
Block(-3,5,-3,STONE:0)
Block(-3,6,-3,STONE:0)
Block(-3,7,-3,STONE:0)
Block(1,4,2,STONE:0)
Block(0,5,4,STONE:0)
Block(-3,8,-3,STONE:0)
Block(1,3,2,STONE:0)
Block(0,4,4,STONE:0)
Block(-3,9,-3,GRASS:0)
Block(1,2,2,STONE:0)
Block(0,7,4,STONE:0)
Block(1,1,2,STONE:0)
Block(0,6,4,STONE:0)
Block(0,8,4,GRASS:0)
Block(-4,9,2,STONE:0)
Block(-4,8,2,STONE:0)
Block(-4,7,2,STONE:0)
Block(-4,6,2,STONE:0)
Block(-4,5,2,STONE:0)
Block(-4,4,2,STONE:0)
Block(-3,7,4,STONE:0)
Block(-3,6,4,STONE:0)
Block(-3,9,4,STONE:0)
Block(-3,8,4,STONE:0)
Block(-3,3,4,DIRT:0)
Block(-3,5,4,STONE:0)
Block(-3,4,4,STONE:0)
Block(-3,10,2,STONE:0)
Block(-4,10,-1,GRASS:0)
Block(-3,13,2,GRASS:0)
Block(-3,12,2,STONE:0)
Block(-2,9,6,GRASS:0)
Block(-3,11,2,STONE:0)
Block(-7,6,-1,STONE:0)
Block(-2,8,6,STONE:0)
Block(-7,7,-1,GRASS:0)
Block(-2,7,6,STONE:0)
Block(-2,6,6,STONE:0)
Block(-2,5,6,STONE:0)
Block(-2,4,6,STONE:0)
Block(-1,5,8,GRASS:0)
Block(-2,3,6,STONE:0)
Block(-1,4,8,AIR)
Block(-3,0,-2,AIR)
Block(-3,1,-2,STONE:0)
Block(-3,2,-2,STONE:0)
Block(-3,3,-2,STONE:0)
Block(-3,4,-2,STONE:0)
Block(-3,5,-2,STONE:0)
Block(-3,6,-2,STONE:0)
Block(-3,7,-2,STONE:0)
Block(-3,8,-2,STONE:0)
Block(-3,9,-2,STONE:0)
Block(-7,5,-1,STONE:0)
Block(-6,6,-5,GRASS:0)
Block(-6,5,-5,STONE:0)
Block(1,5,-3,STONE:0)
Block(1,6,-3,GRASS:0)
Block(1,3,-3,STONE:0)
Block(1,4,-3,STONE:0)
Block(1,2,-3,STONE:0)
Block(-5,9,0,STONE:0)
Block(-5,8,0,STONE:0)
Block(-5,5,0,STONE:0)
Block(-5,4,0,STONE:0)
Block(-5,7,0,STONE:0)
Block(-5,6,0,STONE:0)
Block(-4,8,4,STONE:0)
Block(-4,7,4,STONE:0)
Block(-4,6,4,STONE:0)
Block(-4,5,4,STONE:0)
Block(-4,9,4,GRASS:0)
Block(-4,4,4,STONE:0)
Block(-2,11,0,GRASS:0)
Block(-2,10,0,STONE:0)
Block(-3,8,6,GRASS:0)
Block(-3,5,6,STONE:0)
Block(-3,4,6,STONE:0)
Block(-3,7,6,STONE:0)
Block(-3,6,6,STONE:0)
Block(-2,6,8,GRASS:0)
Block(-7,5,-3,STONE:0)
Block(-2,5,8,STONE:0)
Block(-2,4,8,STONE:0)
Block(-7,6,-3,GRASS:0)
Block(2,1,-1,AIR)
Block(2,0,-1,AIR)
Block(2,5,-1,STONE:0)
Block(2,4,-1,STONE:0)
Block(2,3,-1,STONE:0)
Block(2,2,-1,STONE:0)
Block(0,8,1,STONE:0)
Block(0,7,1,STONE:0)
Block(2,7,-1,GRASS:0)
Block(2,6,-1,STONE:0)
Block(0,9,1,STONE:0)
Block(-6,10,1,STONE:0)
Block(-6,12,1,GRASS:0)
Block(-6,11,1,STONE:0)
Block(0,5,-7,GRASS:0)
Block(-6,8,-3,GRASS:0)
Block(-6,7,-3,STONE:0)
Block(-6,6,-3,STONE:0)
Block(-6,5,-3,STONE:0)
Block(-6,4,-3,STONE:0)
Block(-2,4,-6,STONE:0)
Block(1,7,-1,GRASS:0)
Block(-2,5,-6,GRAVEL)
Block(1,5,-1,STONE:0)
Block(-2,6,-6,GRASS:0)
Block(1,6,-1,STONE:0)
Block(1,3,-1,STONE:0)
Block(1,4,-1,STONE:0)
Block(1,1,-1,STONE:0)
Block(-2,2,-6,AIR)
Block(1,2,-1,STONE:0)
Block(-2,3,-6,STONE:0)
Block(-3,10,4,GRASS:0)
Block(-6,6,0,STONE:0)
Block(-6,5,0,STONE:0)
Block(-6,4,0,STONE:0)
Block(-6,9,0,STONE:0)
Block(-6,8,0,STONE:0)
Block(-6,7,0,STONE:0)
Block(-5,7,2,STONE:0)
Block(-5,6,2,STONE:0)
Block(-5,9,2,STONE:0)
Block(-5,8,2,STONE:0)
Block(-5,5,2,STONE:0)
Block(-5,4,2,STONE:0)
Block(-4,6,6,GRASS:0)
Block(-4,5,6,STONE:0)
Block(-4,11,2,STONE:0)
Block(-4,10,2,STONE:0)
Block(-6,10,-2,GRASS:0)
Block(2,5,6,GRASS:0)
Block(-3,5,8,GRASS:0)
Block(0,10,1,GRASS:0)
Block(3,4,4,STONE:0)
Block(3,5,4,GRASS:0)
Block(4,3,2,STONE:0)
Block(4,2,2,STONE:0)
Block(4,5,2,STONE:0)
Block(4,4,2,STONE:0)
Block(2,3,-3,STONE:0)
Block(4,6,2,GRASS:0)
Block(2,6,-3,GRASS:0)
Block(2,5,-3,STONE:0)
Block(2,4,-3,STONE:0)
Block(5,5,0,GRASS:0)
Block(0,3,-5,STONE:0)
Block(0,5,-5,STONE:0)
Block(0,4,-5,STONE:0)
Block(0,6,-5,GRASS:0)
Block(-7,5,0,STONE:0)
Block(-2,6,-4,STONE:0)
Block(-2,7,-4,STONE:0)
Block(-2,8,-4,GRASS:0)
Block(-2,2,-4,STONE:0)
Block(-2,3,-4,STONE:0)
Block(-2,4,-4,STONE:0)
Block(-2,5,-4,STONE:0)
Block(-7,6,0,GRASS:0)
Block(-2,1,-4,STONE:0)
Block(-4,7,-2,STONE:0)
Block(-6,4,2,AIR)
Block(-1,2,-6,AIR)
Block(-4,6,-2,STONE:0)
Block(-1,1,-6,AIR)
Block(-4,9,-2,STONE:0)
Block(-4,8,-2,STONE:0)
Block(-4,3,-2,STONE:0)
Block(-4,2,-2,STONE:0)
Block(-4,5,-2,STONE:0)
Block(-4,4,-2,STONE:0)
Block(-6,9,2,STONE:0)
Block(-1,6,-6,GRASS:0)
Block(-6,8,2,STONE:0)
Block(-1,5,-6,STONE:0)
Block(-6,7,2,STONE:0)
Block(-1,4,-6,STONE:0)
Block(-6,6,2,STONE:0)
Block(-6,5,2,STONE:0)
Block(-1,3,-6,AIR)
Block(-5,5,4,STONE:0)
Block(-5,4,4,AIR)
Block(-5,7,4,GRASS:0)
Block(-5,6,4,STONE:0)
Block(-4,13,2,GRASS:0)
Block(-4,12,2,STONE:0)
Block(3,2,-1,STONE:0)
Block(3,3,-1,STONE:0)
Block(-2,10,-2,GRASS:0)
Block(3,4,-1,STONE:0)
Block(3,5,-1,STONE:0)
Block(3,6,-1,GRASS:0)
Block(-4,12,0,LONG_GRASS:1)
Block(-4,10,0,STONE:0)
Block(-4,11,0,GRASS:0)
Block(2,5,-5,GRASS:0)
Block(2,4,-5,STONE:0)
Block(-3,10,-1,GRASS:0)
Block(5,5,2,GRASS:0)
Block(5,4,2,STONE:0)
Block(0,3,-3,STONE:0)
Block(0,2,-3,STONE:0)
Block(-5,11,-1,LONG_GRASS:1)
Block(0,5,-3,STONE:0)
Block(0,4,-3,STONE:0)
Block(0,7,-3,GRASS:0)
Block(0,6,-3,STONE:0)
Block(-5,10,-1,GRASS:0)
Block(0,8,-3,LONG_GRASS:1)
Block(-2,12,2,STONE:0)
Block(-2,13,2,GRASS:0)
Block(0,1,-3,STONE:0)
Block(-2,10,2,STONE:0)
Block(-2,11,2,STONE:0)
Block(0,0,-3,AIR)
Block(-2,9,-2,STONE:0)
Block(-2,8,-2,STONE:0)
Block(-2,3,-2,STONE:0)
Block(-2,2,-2,STONE:0)
Block(-2,1,-2,STONE:0)
Block(-2,0,-2,STONE:0)
Block(-2,7,-2,STONE:0)
Block(-2,6,-2,STONE:0)
Block(-2,5,-2,STONE:0)
Block(-2,4,-2,STONE:0)
Block(-4,5,-4,STONE:0)
Block(-4,4,-4,STONE:0)
Block(-4,7,-4,GRASS:0)
Block(-4,6,-4,STONE:0)
Block(-4,3,-4,STONE:0)
Block(-4,9,-4,AIR)
Block(-5,6,6,AIR)
Block(5,4,-2,AIR)
Block(5,5,-2,AIR)
Block(-3,10,-2,GRASS:0)
Block(-1,10,1,STONE:0)
Block(-1,11,1,GRASS:0)
Block(-1,5,-3,STONE:0)
Block(-1,4,-3,STONE:0)
Block(-1,3,-3,STONE:0)
Block(-1,2,-3,STONE:0)
Block(-1,1,-3,STONE:0)
Block(2,2,1,STONE:0)
Block(2,1,1,STONE:0)
Block(2,4,1,STONE:0)
Block(2,3,1,STONE:0)
Block(-1,8,-3,GRASS:0)
Block(-1,7,-3,STONE:0)
Block(-1,6,-3,STONE:0)
Block(1,3,3,STONE:0)
Block(1,2,3,STONE:0)
Block(0,6,7,GRASS:0)
Block(0,5,7,STONE:0)
Block(0,7,7,AIR)
Block(0,5,-1,STONE:0)
Block(0,4,-1,STONE:0)
Block(0,7,-1,STONE:0)
Block(1,7,5,GRASS:0)
Block(0,6,-1,STONE:0)
Block(1,6,5,STONE:0)
Block(1,5,5,STONE:0)
Block(0,9,-1,AIR)
Block(1,4,5,STONE:0)
Block(0,8,-1,GRASS:0)
Block(1,3,5,STONE:0)
Block(0,1,-1,STONE:0)
Block(3,3,-2,STONE:0)
Block(0,3,-1,STONE:0)
Block(3,4,-2,STONE:0)
Block(0,2,-1,STONE:0)
Block(3,5,-2,GRASS:0)
Block(2,8,3,GRASS:0)
Block(2,7,3,STONE:0)
Block(2,4,3,STONE:0)
Block(2,3,3,STONE:0)
Block(2,6,3,STONE:0)
Block(2,5,3,STONE:0)
Block(-5,4,-3,STONE:0)
Block(-5,5,-3,STONE:0)
Block(-5,3,-3,STONE:0)
Block(-5,8,-3,GRASS:0)
Block(-5,6,-3,STONE:0)
Block(-5,7,-3,STONE:0)
Block(3,7,1,GRASS:0)
Block(-4,3,-6,AIR)
Block(3,6,1,STONE:0)
Block(-4,5,-6,GRASS:0)
Block(3,5,1,STONE:0)
Block(-4,4,-6,GRAVEL)
Block(3,4,1,STONE:0)
Block(-5,12,1,GRASS:0)
Block(-2,11,4,GRASS:0)
Block(-2,10,4,STONE:0)
Block(3,3,1,STONE:0)
Block(3,2,1,STONE:0)
Block(-1,3,-5,STONE:0)
Block(-1,2,-5,STONE:0)
Block(2,2,3,STONE:0)
Block(-1,6,-5,GRASS:0)
Block(-1,5,-5,STONE:0)
Block(-1,4,-5,STONE:0)
Block(3,5,-4,GRASS:0)
Block(1,5,7,GRASS:0)
Block(-5,2,-1,AIR)
Block(-5,3,-1,STONE:0)
Block(2,6,5,GRASS:0)
Block(-5,11,3,GRASS:0)
Block(2,5,5,STONE:0)
Block(-5,10,3,STONE:0)
Block(-5,13,3,AIR)
Block(-5,12,3,AIR)
Block(2,2,5,AIR)
Block(2,4,5,STONE:0)
Block(2,3,5,AIR)
Block(-5,6,-1,STONE:0)
Block(-5,7,-1,STONE:0)
Block(-5,4,-1,STONE:0)
Block(-5,5,-1,STONE:0)
Block(-5,8,-1,STONE:0)
Block(-5,9,-1,STONE:0)
Block(-1,4,1,STONE:0)
Block(3,5,3,STONE:0)
Block(-1,3,1,STONE:0)
Block(3,4,3,STONE:0)
Block(3,3,3,STONE:0)
Block(-1,6,1,STONE:0)
Block(-1,5,1,STONE:0)
Block(-1,8,1,STONE:0)
Block(-1,7,1,STONE:0)
Block(3,6,3,GRASS:0)
Block(-1,9,1,STONE:0)
Block(4,4,1,STONE:0)
Block(4,3,1,STONE:0)
Block(4,6,1,GRASS:0)
Block(4,5,1,STONE:0)
Block(-1,2,1,STONE:0)
Block(-6,9,-2,STONE:0)
Block(-6,8,-2,STONE:0)
Block(-6,7,-2,STONE:0)
Block(-6,6,-2,STONE:0)
Block(-6,5,-2,STONE:0)
Block(-6,4,-2,STONE:0)
Block(-3,4,-6,GRAVEL)
Block(-3,5,-6,GRAVEL)
Block(0,6,3,STONE:0)
Block(0,5,3,STONE:0)
Block(-3,6,-6,GRASS:0)
Block(0,8,3,STONE:0)
Block(-3,7,-6,LONG_GRASS:1)
Block(0,7,3,STONE:0)
Block(0,9,3,GRASS:0)
Block(0,2,1,STONE:0)
Block(3,5,-6,AIR)
Block(0,4,1,STONE:0)
Block(1,9,1,GRASS:0)
Block(0,3,1,STONE:0)
Block(1,8,1,STONE:0)
Block(0,6,1,STONE:0)
Block(1,7,1,STONE:0)
Block(0,5,1,STONE:0)
Block(1,6,1,STONE:0)
Block(-1,2,3,STONE:0)
Block(-3,11,0,GRASS:0)
Block(-1,4,3,STONE:0)
Block(-1,3,3,STONE:0)
Block(-3,10,0,STONE:0)
Block(-1,6,3,STONE:0)
Block(-1,5,3,STONE:0)
Block(-1,8,3,STONE:0)
Block(-1,7,3,STONE:0)
Block(-2,9,1,STONE:0)
Block(-2,8,1,STONE:0)
Block(-1,9,3,STONE:0)
Block(-2,7,1,STONE:0)
Block(-2,6,1,STONE:0)
Block(-2,5,1,STONE:0)
Block(-2,4,1,STONE:0)
Block(-2,3,1,STONE:0)
Block(-2,2,1,STONE:0)
Block(-5,10,1,STONE:0)
Block(-5,11,1,STONE:0)
Block(4,5,-1,GRASS:0)
Block(4,4,-1,STONE:0)
Block(4,3,-1,AIR)
Block(4,2,-1,AIR)
Block(-1,7,-1,STONE:0)
Block(-1,6,-1,STONE:0)
Block(-1,5,-1,STONE:0)
Block(-1,4,-1,STONE:0)
Block(-1,3,-1,STONE:0)
Block(-1,2,-1,STONE:0)
Block(-1,1,-1,STONE:0)
Block(-1,0,-1,AIR)
Block(-1,9,-1,GRASS:0)
Block(-1,8,-1,STONE:0)
Block(-3,2,-4,STONE:0)
Block(-3,3,-4,STONE:0)
Block(-3,4,-4,STONE:0)
Block(-3,5,-4,STONE:0)
Block(-3,6,-4,STONE:0)
Block(0,4,5,STONE:0)
Block(1,5,1,STONE:0)
Block(-3,7,-4,STONE:0)
Block(0,3,5,STONE:0)
Block(1,4,1,STONE:0)
Block(-3,8,-4,GRASS:0)
Block(1,3,1,STONE:0)
Block(0,6,5,STONE:0)
Block(1,2,1,STONE:0)
Block(0,5,5,STONE:0)
Block(1,1,1,STONE:0)
Block(0,7,5,GRASS:0)
Block(1,9,3,GRASS:0)
Block(1,8,3,STONE:0)
Block(0,2,3,STONE:0)
Block(1,7,3,STONE:0)
Block(1,6,3,STONE:0)
Block(0,4,3,STONE:0)
Block(1,5,3,STONE:0)
Block(0,3,3,STONE:0)
Block(1,4,3,STONE:0)
Block(2,9,1,LONG_GRASS:1)
Block(1,5,-5,STONE:0)
Block(1,6,-5,GRASS:0)
Block(2,6,1,STONE:0)
Block(1,3,-5,AIR)
Block(1,4,-5,STONE:0)
Block(2,5,1,STONE:0)
Block(-3,9,1,STONE:0)
Block(2,8,1,GRASS:0)
Block(2,7,1,STONE:0)
Block(-3,6,1,STONE:0)
Block(-3,5,1,STONE:0)
Block(-1,10,3,GRASS:0)
Block(-3,8,1,STONE:0)
Block(-3,7,1,STONE:0)
Block(-3,2,1,STONE:0)
Block(-5,6,-5,GRASS:0)
Block(-5,4,-5,STONE:0)
Block(-3,4,1,STONE:0)
Block(-3,3,1,STONE:0)
Block(-5,5,-5,STONE:0)
Block(-1,4,5,STONE:0)
Block(-1,3,5,STONE:0)
Block(-1,6,5,STONE:0)
Block(-2,9,3,STONE:0)
Block(-1,5,5,STONE:0)
Block(-2,8,3,STONE:0)
Block(-2,7,3,STONE:0)
Block(-1,8,5,GRASS:0)
Block(-2,6,3,STONE:0)
Block(-1,7,5,STONE:0)
Block(-2,5,3,STONE:0)
Block(-2,4,3,STONE:0)
Block(-2,3,3,STONE:0)
Block(-2,2,3,STONE:0)

#######################################################################
# +-----------------------------------------------------------------+ #
# |                            BO3 checks                           | #
# +-----------------------------------------------------------------+ #
#######################################################################


#######################################################################
# +-----------------------------------------------------------------+ #
# |                             Branches                            | #
# +-----------------------------------------------------------------+ #
#######################################################################


#######################################################################
# +-----------------------------------------------------------------+ #
# |                             Entities                            | #
# +-----------------------------------------------------------------+ #
#######################################################################


#######################################################################
# +-----------------------------------------------------------------+ #
# |                            Particles                            | #
# +-----------------------------------------------------------------+ #
#######################################################################


#######################################################################
# +-----------------------------------------------------------------+ #
# |                             Spawners                            | #
# +-----------------------------------------------------------------+ #
#######################################################################


#######################################################################
# +-----------------------------------------------------------------+ #
# |                             ModData                             | #
# +-----------------------------------------------------------------+ #
#######################################################################

