
#######################################################################
# +-----------------------------------------------------------------+ #
# |                            BO3 object                           | #
# +-----------------------------------------------------------------+ #
#######################################################################

Author: LordSmellyPants

Description: Converted version of the BO2 FloatingIsland7

Version: 3

SettingsMode: WriteWithoutComments


#######################################################################
# +-----------------------------------------------------------------+ #
# |                          Main settings                          | #
# +-----------------------------------------------------------------+ #
#######################################################################

Tree: false

Frequency: 1

Rarity: 5.0

RotateRandomly: true

SpawnHeight: randomY

SpawnHeightOffset: 0

SpawnHeightVariance: 0

##############################
# Height Limits for the BO3. #
##############################

MinHeight: 30

MaxHeight: 110

######################
# Extrusion settings #
######################

ExtrudeMode: None

ExtrudeThroughBlocks: AIR

MaxBranchDepth: 10

ExcludedBiomes: 


#######################################################################
# +-----------------------------------------------------------------+ #
# |                      Source block settings                      | #
# +-----------------------------------------------------------------+ #
#######################################################################

SourceBlocks: AIR,STATIONARY_WATER:0

MaxPercentageOutsideSourceBlock: 0

OutsideSourceBlock: placeAnyway

DoReplaceBlocks: true

IsOTGPlus: false


#######################################################################
# +-----------------------------------------------------------------+ #
# |                              Blocks                             | #
# +-----------------------------------------------------------------+ #
#######################################################################

Block(1,8,-4,AIR)
Block(1,6,-4,AIR)
Block(1,7,-4,AIR)
Block(1,4,-4,AIR)
Block(2,4,2,GRASS:0)
Block(1,5,-4,AIR)
Block(-3,10,-2,AIR)
Block(-1,10,1,AIR)
Block(-1,5,0,STONE:0)
Block(-1,4,-3,GRASS:0)
Block(-1,4,0,STONE:0)
Block(-1,3,-3,STONE:0)
Block(-1,7,0,AIR)
Block(-1,6,0,GRASS:0)
Block(-1,9,0,LEAVES:3)
Block(-1,8,0,LEAVES:3)
Block(2,2,1,STONE:0)
Block(2,4,1,GRASS:0)
Block(2,3,1,STONE:0)
Block(-1,9,-3,LEAVES:3)
Block(-1,8,-3,LEAVES:3)
Block(-3,3,-2,STONE:0)
Block(-3,4,-2,GRASS:0)
Block(-3,8,-2,LEAVES:3)
Block(-3,9,-2,LEAVES:3)
Block(-1,1,0,STONE:0)
Block(-1,0,0,STONE:0)
Block(-1,3,0,STONE:0)
Block(-1,2,0,STONE:0)
Block(0,5,-1,STONE:0)
Block(0,4,-1,STONE:0)
Block(0,7,-1,AIR)
Block(0,6,-1,GRASS:0)
Block(0,9,-1,LEAVES:3)
Block(0,8,-1,LEAVES:3)
Block(0,1,-1,STONE:0)
Block(0,3,-1,STONE:0)
Block(0,2,-1,STONE:0)
Block(1,8,-3,LEAVES:3)
Block(1,4,-3,GRASS:0)
Block(3,0,0,AIR)
Block(3,4,0,GRASS:0)
Block(3,3,0,STONE:0)
Block(3,2,0,AIR)
Block(3,1,0,AIR)
Block(-1,6,-2,LONG_GRASS:1)
Block(-1,5,-2,GRASS:0)
Block(-1,4,-2,STONE:0)
Block(-1,3,-2,STONE:0)
Block(3,4,1,GRASS:0)
Block(-1,2,-2,STONE:0)
Block(2,1,2,AIR)
Block(2,3,2,AIR)
Block(2,2,2,AIR)
Block(-1,9,-2,LEAVES:3)
Block(-1,8,-2,LEAVES:3)
Block(-3,2,-1,AIR)
Block(-3,3,-1,STONE:0)
Block(-3,4,-1,GRASS:0)
Block(-3,8,-1,LEAVES:3)
Block(-3,9,-1,LEAVES:3)
Block(0,10,-1,LEAVES:3)
Block(0,11,-1,LEAVES:3)
Block(0,1,0,STONE:0)
Block(0,0,0,STONE:0)
Block(0,3,0,STONE:0)
Block(0,2,0,STONE:0)
Block(0,5,0,STONE:0)
Block(0,4,0,STONE:0)
Block(0,6,0,GRASS:0)
Block(-2,10,0,LEAVES:3)
Block(1,8,-2,LEAVES:3)
Block(1,9,-2,LEAVES:3)
Block(1,4,-2,GRASS:0)
Block(1,3,-2,STONE:0)
Block(-4,8,-1,AIR)
Block(-1,3,2,AIR)
Block(-4,7,-1,AIR)
Block(-1,2,2,AIR)
Block(-1,5,2,AIR)
Block(-1,4,2,GRASS:0)
Block(-4,9,-1,AIR)
Block(-4,4,-1,GRASS:0)
Block(-4,6,-1,AIR)
Block(-4,5,-1,AIR)
Block(-2,9,0,LEAVES:3)
Block(-2,8,0,LEAVES:3)
Block(-2,6,0,LONG_GRASS:1)
Block(-2,5,0,GRASS:0)
Block(-2,4,0,STONE:0)
Block(-2,3,0,STONE:0)
Block(-2,2,0,STONE:0)
Block(-2,1,0,STONE:0)
Block(4,4,0,GRASS:0)
Block(2,5,-1,AIR)
Block(2,4,-1,GRASS:0)
Block(2,3,-1,STONE:0)
Block(0,8,1,LEAVES:3)
Block(2,9,-1,AIR)
Block(2,8,-1,AIR)
Block(2,7,-1,AIR)
Block(0,9,1,LEAVES:3)
Block(-1,10,0,LEAVES:3)
Block(2,6,-1,AIR)
Block(-1,11,0,LEAVES:3)
Block(-1,1,2,AIR)
Block(1,9,-1,LEAVES:3)
Block(1,8,-1,LEAVES:3)
Block(1,5,-1,GRASS:0)
Block(1,3,-1,STONE:0)
Block(1,4,-1,STONE:0)
Block(1,2,-1,STONE:0)
Block(-1,4,-4,GRASS:0)
Block(-1,4,1,STONE:0)
Block(-1,3,1,STONE:0)
Block(-1,6,1,LONG_GRASS:1)
Block(-1,5,1,GRASS:0)
Block(-1,8,1,LEAVES:3)
Block(-1,9,1,LEAVES:3)
Block(-1,9,-4,AIR)
Block(-1,8,-4,AIR)
Block(-1,7,-4,AIR)
Block(-1,6,-4,AIR)
Block(-1,5,-4,AIR)
Block(2,4,-2,AIR)
Block(0,9,0,LEAVES:3)
Block(2,8,-2,AIR)
Block(0,8,0,LEAVES:3)
Block(2,7,-2,AIR)
Block(2,6,-2,AIR)
Block(2,5,-2,AIR)
Block(-1,2,1,STONE:0)
Block(-1,1,1,STONE:0)
Block(0,1,2,STONE:0)
Block(0,4,-4,GRASS:0)
Block(0,3,-4,AIR)
Block(0,3,2,STONE:0)
Block(0,6,-4,AIR)
Block(0,2,2,STONE:0)
Block(1,9,0,LEAVES:3)
Block(0,5,-4,AIR)
Block(0,5,2,GRASS:0)
Block(1,8,0,LEAVES:3)
Block(0,8,-4,AIR)
Block(0,4,2,STONE:0)
Block(0,7,-4,AIR)
Block(-2,9,-3,LEAVES:3)
Block(-2,8,-3,LEAVES:3)
Block(-3,9,0,LEAVES:3)
Block(-3,8,0,LEAVES:3)
Block(-3,3,0,STONE:0)
Block(-3,2,0,STONE:0)
Block(-2,4,-3,GRASS:0)
Block(-3,5,0,GRASS:0)
Block(-3,4,0,STONE:0)
Block(-4,4,-3,GRASS:0)
Block(-1,10,-2,LEAVES:3)
Block(-1,11,-2,LEAVES:3)
Block(0,5,3,AIR)
Block(0,0,1,STONE:0)
Block(0,2,1,STONE:0)
Block(0,1,1,STONE:0)
Block(0,4,1,STONE:0)
Block(1,9,1,LEAVES:3)
Block(0,3,1,STONE:0)
Block(1,8,1,AIR)
Block(1,7,1,AIR)
Block(0,5,1,GRASS:0)
Block(1,6,1,AIR)
Block(-2,10,-1,LEAVES:3)
Block(-1,10,-1,LOG:3)
Block(-2,11,-1,LEAVES:3)
Block(-2,6,-4,AIR)
Block(-2,7,-4,AIR)
Block(-2,8,-4,AIR)
Block(-2,9,-4,AIR)
Block(-2,4,-4,GRASS:0)
Block(-2,5,-4,AIR)
Block(-4,3,-2,AIR)
Block(-4,2,-2,AIR)
Block(-4,4,-2,GRASS:0)
Block(-2,9,1,LEAVES:3)
Block(-2,8,1,LEAVES:3)
Block(-1,11,-1,LEAVES:3)
Block(-2,4,1,GRASS:0)
Block(-2,3,1,STONE:0)
Block(1,6,0,GRASS:0)
Block(1,5,0,STONE:0)
Block(1,4,0,STONE:0)
Block(-4,1,-2,AIR)
Block(1,3,0,STONE:0)
Block(1,2,0,STONE:0)
Block(0,10,0,LEAVES:3)
Block(1,1,0,STONE:0)
Block(0,4,-2,STONE:0)
Block(0,3,-2,STONE:0)
Block(0,5,-2,GRASS:0)
Block(0,8,-2,LEAVES:3)
Block(0,9,-2,LEAVES:3)
Block(-4,4,0,GRASS:0)
Block(-4,3,0,STONE:0)
Block(-2,10,-2,LEAVES:3)
Block(-4,8,0,AIR)
Block(3,3,-1,AIR)
Block(-4,7,0,AIR)
Block(3,4,-1,AIR)
Block(0,2,-2,STONE:0)
Block(-4,6,0,AIR)
Block(-4,5,0,AIR)
Block(-1,10,-3,AIR)
Block(-2,9,-1,LEAVES:3)
Block(-1,11,-3,AIR)
Block(-2,4,-1,STONE:0)
Block(-2,3,-1,STONE:0)
Block(-2,2,-1,STONE:0)
Block(-2,8,-1,LEAVES:3)
Block(-2,7,-1,AIR)
Block(-2,5,-1,GRASS:0)
Block(-1,7,-1,LOG:3)
Block(-1,6,-1,LOG:3)
Block(-1,5,-1,DIRT:0)
Block(-1,4,-1,STONE:0)
Block(-1,3,-1,STONE:0)
Block(-1,2,-1,STONE:0)
Block(-1,1,-1,STONE:0)
Block(-1,9,-1,LOG:3)
Block(-1,8,-1,LOG:3)
Block(-3,4,-4,GRASS:0)
Block(1,5,1,GRASS:0)
Block(1,4,1,STONE:0)
Block(-3,10,-1,AIR)
Block(1,3,1,STONE:0)
Block(-3,11,-1,AIR)
Block(1,2,1,STONE:0)
Block(1,1,1,STONE:0)
Block(0,3,-3,STONE:0)
Block(0,5,-3,GRASS:0)
Block(0,4,-3,STONE:0)
Block(0,2,3,STONE:0)
Block(0,4,3,GRASS:0)
Block(0,9,-3,LEAVES:3)
Block(0,3,3,STONE:0)
Block(0,8,-3,LEAVES:3)
Block(-2,9,-2,LEAVES:3)
Block(-2,8,-2,LEAVES:3)
Block(-3,9,1,AIR)
Block(-2,3,-2,STONE:0)
Block(-3,6,1,AIR)
Block(-3,5,1,AIR)
Block(0,11,-2,AIR)
Block(-3,8,1,AIR)
Block(0,10,-2,AIR)
Block(-3,7,1,AIR)
Block(-3,2,1,AIR)
Block(-3,1,1,AIR)
Block(-3,4,1,AIR)
Block(-2,4,-2,GRASS:0)
Block(-3,3,1,AIR)
Block(2,3,0,STONE:0)
Block(2,2,0,STONE:0)
Block(2,5,0,GRASS:0)
Block(2,4,0,STONE:0)
Block(-3,4,-3,GRASS:0)
Block(1,4,2,GRASS:0)
Block(1,3,2,STONE:0)
Block(-3,9,-3,LEAVES:3)
Block(1,2,2,STONE:0)
Block(1,1,2,AIR)

#######################################################################
# +-----------------------------------------------------------------+ #
# |                            BO3 checks                           | #
# +-----------------------------------------------------------------+ #
#######################################################################


#######################################################################
# +-----------------------------------------------------------------+ #
# |                             Branches                            | #
# +-----------------------------------------------------------------+ #
#######################################################################


#######################################################################
# +-----------------------------------------------------------------+ #
# |                             Entities                            | #
# +-----------------------------------------------------------------+ #
#######################################################################


#######################################################################
# +-----------------------------------------------------------------+ #
# |                            Particles                            | #
# +-----------------------------------------------------------------+ #
#######################################################################


#######################################################################
# +-----------------------------------------------------------------+ #
# |                             Spawners                            | #
# +-----------------------------------------------------------------+ #
#######################################################################


#######################################################################
# +-----------------------------------------------------------------+ #
# |                             ModData                             | #
# +-----------------------------------------------------------------+ #
#######################################################################

