
#######################################################################
# +-----------------------------------------------------------------+ #
# |                            BO3 object                           | #
# +-----------------------------------------------------------------+ #
#######################################################################

Author: LordSmellyPants

Description: Converted version of the BO2 FloatingIsland6

Version: 3

SettingsMode: WriteWithoutComments


#######################################################################
# +-----------------------------------------------------------------+ #
# |                          Main settings                          | #
# +-----------------------------------------------------------------+ #
#######################################################################

Tree: false

Frequency: 1

Rarity: 5.0

RotateRandomly: true

SpawnHeight: randomY

SpawnHeightOffset: 0

SpawnHeightVariance: 0

##############################
# Height Limits for the BO3. #
##############################

MinHeight: 30

MaxHeight: 110

######################
# Extrusion settings #
######################

ExtrudeMode: None

ExtrudeThroughBlocks: AIR

MaxBranchDepth: 10

ExcludedBiomes: 


#######################################################################
# +-----------------------------------------------------------------+ #
# |                      Source block settings                      | #
# +-----------------------------------------------------------------+ #
#######################################################################

SourceBlocks: AIR,STATIONARY_WATER:0

MaxPercentageOutsideSourceBlock: 0

OutsideSourceBlock: placeAnyway

DoReplaceBlocks: true

IsOTGPlus: false


#######################################################################
# +-----------------------------------------------------------------+ #
# |                              Blocks                             | #
# +-----------------------------------------------------------------+ #
#######################################################################

Block(2,11,4,LEAVES:3)
Block(6,12,5,LEAVES:3)
Block(2,12,4,LEAVES:3)
Block(6,10,5,AIR)
Block(6,11,5,AIR)
Block(6,6,1,GRASS:0)
Block(1,8,-4,GRASS:0)
Block(4,7,-7,AIR)
Block(4,6,-7,GRASS:0)
Block(-2,14,-3,LEAVES:0)
Block(1,9,-4,AIR)
Block(1,6,-4,STONE:0)
Block(-2,13,-3,LEAVES:0)
Block(1,7,-4,STONE:0)
Block(-2,12,-3,LEAVES:3)
Block(1,4,-4,STONE:0)
Block(1,5,-4,STONE:0)
Block(1,2,-4,STONE:0)
Block(1,3,-4,STONE:0)
Block(1,1,-4,STONE:0)
Block(-2,11,-3,LEAVES:3)
Block(5,5,-3,STONE:0)
Block(5,6,-3,STONE:0)
Block(5,7,-3,STONE:0)
Block(5,8,-3,GRASS:0)
Block(-4,8,1,GRASS:0)
Block(-4,3,1,STONE:0)
Block(-4,7,1,STONE:0)
Block(-4,6,1,STONE:0)
Block(-4,5,1,STONE:0)
Block(-4,4,1,STONE:0)
Block(-3,8,3,GRASS:0)
Block(0,11,-6,LEAVES:3)
Block(1,10,2,AIR)
Block(-3,7,3,STONE:0)
Block(1,11,2,AIR)
Block(1,12,2,AIR)
Block(-3,9,3,LONG_GRASS:1)
Block(-3,6,3,STONE:0)
Block(0,13,-6,AIR)
Block(-3,5,3,STONE:0)
Block(0,12,-6,LEAVES:3)
Block(5,12,1,LEAVES:3)
Block(5,11,1,LEAVES:3)
Block(-7,6,-2,GRASS:0)
Block(-2,7,5,GRASS:0)
Block(-2,6,5,STONE:0)
Block(5,13,1,AIR)
Block(-1,6,7,AIR)
Block(-3,1,-1,STONE:0)
Block(-3,2,-1,STONE:0)
Block(-3,3,-1,STONE:0)
Block(-3,4,-1,STONE:0)
Block(-3,5,-1,STONE:0)
Block(-3,6,-1,STONE:0)
Block(-3,7,-1,STONE:0)
Block(-3,8,-1,STONE:0)
Block(5,7,5,YELLOW_FLOWER:0)
Block(5,6,5,GRASS:0)
Block(-3,9,-1,GRASS:0)
Block(0,1,0,STONE:0)
Block(0,0,0,STONE:0)
Block(0,3,0,STONE:0)
Block(0,2,0,STONE:0)
Block(0,5,0,STONE:0)
Block(0,4,0,STONE:0)
Block(0,6,-6,STONE:0)
Block(0,7,0,DIRT:0)
Block(0,5,-6,STONE:0)
Block(0,6,0,STONE:0)
Block(-6,6,-4,GRASS:0)
Block(-2,9,-5,LOG:3)
Block(4,8,-5,GRASS:0)
Block(1,8,-2,STONE:0)
Block(1,9,-2,GRASS:0)
Block(1,6,-2,STONE:0)
Block(-2,6,-5,STONE:0)
Block(1,7,-2,STONE:0)
Block(1,4,-2,STONE:0)
Block(-2,7,-5,DIRT:0)
Block(4,7,-5,STONE:0)
Block(1,5,-2,STONE:0)
Block(4,6,-5,STONE:0)
Block(-2,8,-5,LOG:3)
Block(1,2,-2,STONE:0)
Block(1,3,-2,STONE:0)
Block(0,7,-6,GRASS:0)
Block(1,1,-2,STONE:0)
Block(-4,8,-1,GRASS:0)
Block(-4,7,-1,STONE:0)
Block(3,10,6,AIR)
Block(3,11,6,AIR)
Block(-4,4,-1,STONE:0)
Block(-4,3,-1,STONE:0)
Block(-4,6,-1,STONE:0)
Block(-4,5,-1,STONE:0)
Block(-5,7,1,GRASS:0)
Block(5,6,-5,STONE:0)
Block(-5,4,1,STONE:0)
Block(3,12,6,AIR)
Block(-5,6,1,STONE:0)
Block(-5,5,1,STONE:0)
Block(2,12,2,LEAVES:3)
Block(2,11,2,LEAVES:3)
Block(-4,7,3,GRASS:0)
Block(-4,6,3,STONE:0)
Block(2,10,2,LONG_GRASS:1)
Block(4,14,1,AIR)
Block(4,12,1,LEAVES:3)
Block(4,13,1,AIR)
Block(-4,5,3,STONE:0)
Block(4,11,1,LEAVES:3)
Block(-3,6,5,GRASS:0)
Block(-2,14,-5,LEAVES:3)
Block(-2,10,-5,LOG:3)
Block(-2,11,-5,LOG:3)
Block(-2,12,-5,LOG:3)
Block(-2,13,-5,LOG:3)
Block(2,4,-2,STONE:0)
Block(2,3,-2,STONE:0)
Block(2,2,-2,STONE:0)
Block(2,8,-2,STONE:0)
Block(0,9,0,GRASS:0)
Block(2,7,-2,STONE:0)
Block(0,8,0,DIRT:0)
Block(2,6,-2,STONE:0)
Block(2,5,-2,STONE:0)
Block(2,9,-2,GRASS:0)
Block(0,2,-4,STONE:0)
Block(0,1,-4,STONE:0)
Block(6,9,5,AIR)
Block(0,4,-4,STONE:0)
Block(0,3,-4,STONE:0)
Block(0,6,-4,STONE:0)
Block(6,6,5,AIR)
Block(0,5,-4,STONE:0)
Block(0,8,-4,GRASS:0)
Block(6,8,5,AIR)
Block(0,7,-4,STONE:0)
Block(6,7,5,AIR)
Block(-2,8,-3,GRASS:0)
Block(1,11,4,AIR)
Block(-2,7,-3,STONE:0)
Block(1,10,4,AIR)
Block(-2,2,-3,STONE:0)
Block(-2,1,-3,STONE:0)
Block(-2,6,-3,STONE:0)
Block(-2,5,-3,STONE:0)
Block(-2,4,-3,STONE:0)
Block(-2,3,-3,STONE:0)
Block(-6,5,1,STONE:0)
Block(-4,6,-3,STONE:0)
Block(-4,5,-3,STONE:0)
Block(-4,7,-3,GRASS:0)
Block(-6,7,1,GRASS:0)
Block(-6,6,1,STONE:0)
Block(-5,6,3,STONE:0)
Block(-5,5,3,AIR)
Block(-5,7,3,GRASS:0)
Block(-5,4,3,AIR)
Block(-4,7,5,AIR)
Block(-4,6,5,GRASS:0)
Block(-2,12,-1,LOG:0)
Block(-2,13,-1,LOG:0)
Block(2,6,7,GRASS:0)
Block(-2,10,-1,LOG:0)
Block(-2,11,-1,LOG:0)
Block(-2,16,-1,LEAVES:0)
Block(-2,14,-1,LOG:0)
Block(-2,15,-1,LOG:0)
Block(3,7,5,GRASS:0)
Block(3,6,5,STONE:0)
Block(-2,14,1,LEAVES:0)
Block(-1,15,-1,LEAVES:0)
Block(-2,13,1,LEAVES:0)
Block(-1,16,-1,LEAVES:0)
Block(-1,13,-1,LEAVES:0)
Block(-1,14,-1,LEAVES:0)
Block(0,14,0,LEAVES:0)
Block(0,13,0,LEAVES:0)
Block(4,4,3,STONE:0)
Block(2,2,-4,STONE:0)
Block(4,6,3,STONE:0)
Block(4,5,3,STONE:0)
Block(4,8,3,DIRT:0)
Block(4,7,3,STONE:0)
Block(2,6,-4,STONE:0)
Block(2,5,-4,STONE:0)
Block(5,8,1,GRASS:0)
Block(4,9,3,LOG:3)
Block(2,4,-4,STONE:0)
Block(5,7,1,DIRT:0)
Block(2,3,-4,STONE:0)
Block(5,6,1,DIRT:0)
Block(5,5,1,STONE:0)
Block(2,9,-4,RED_ROSE:0)
Block(2,8,-4,GRASS:0)
Block(2,7,-4,STONE:0)
Block(0,4,-2,STONE:0)
Block(0,3,-2,STONE:0)
Block(0,6,-2,STONE:0)
Block(0,5,-2,STONE:0)
Block(-2,0,-1,STONE:0)
Block(0,8,-2,STONE:0)
Block(0,7,-2,STONE:0)
Block(0,9,-2,GRASS:0)
Block(0,0,-2,STONE:0)
Block(0,2,-2,STONE:0)
Block(0,1,-2,STONE:0)
Block(-1,12,-3,LEAVES:3)
Block(-2,9,-1,DIRT:0)
Block(-1,11,-3,LEAVES:3)
Block(-2,4,-1,STONE:0)
Block(-2,3,-1,STONE:0)
Block(-2,2,-1,STONE:0)
Block(-2,1,-1,STONE:0)
Block(-7,6,1,GRASS:0)
Block(-2,8,-1,STONE:0)
Block(-2,7,-1,STONE:0)
Block(-2,6,-1,STONE:0)
Block(-2,5,-1,STONE:0)
Block(-4,6,-5,GRASS:0)
Block(5,11,3,LEAVES:3)
Block(5,12,3,LEAVES:3)
Block(5,13,3,LEAVES:3)
Block(5,14,3,LEAVES:3)
Block(-1,14,-3,LEAVES:0)
Block(-6,6,3,GRASS:0)
Block(-1,13,-3,LEAVES:0)
Block(5,7,-1,DIRT:0)
Block(5,8,-1,GRASS:0)
Block(5,5,-1,STONE:0)
Block(5,6,-1,STONE:0)
Block(-4,14,-2,LEAVES:0)
Block(-4,13,-2,LEAVES:0)
Block(5,10,3,AIR)
Block(-4,12,-2,AIR)
Block(-4,11,-2,AIR)
Block(-4,10,-2,AIR)
Block(-4,14,1,LEAVES:0)
Block(4,6,5,STONE:0)
Block(5,8,3,GRASS:0)
Block(5,7,3,STONE:0)
Block(3,13,4,LEAVES:3)
Block(5,6,3,STONE:0)
Block(4,7,5,GRASS:0)
Block(3,12,4,LEAVES:3)
Block(5,5,3,STONE:0)
Block(3,11,4,LEAVES:3)
Block(2,7,-6,GRASS:0)
Block(2,6,-6,STONE:0)
Block(2,5,-6,STONE:0)
Block(3,14,4,AIR)
Block(3,5,-3,STONE:0)
Block(3,6,-3,STONE:0)
Block(1,9,4,AIR)
Block(3,7,-3,STONE:0)
Block(1,8,4,GRASS:0)
Block(1,7,4,STONE:0)
Block(3,8,-3,GRASS:0)
Block(1,6,4,STONE:0)
Block(3,9,-3,AIR)
Block(1,5,4,STONE:0)
Block(1,4,4,STONE:0)
Block(3,3,-3,STONE:0)
Block(3,4,-3,STONE:0)
Block(2,9,2,GRASS:0)
Block(2,8,2,DIRT:0)
Block(2,5,2,STONE:0)
Block(2,4,2,STONE:0)
Block(2,7,2,DIRT:0)
Block(2,6,2,STONE:0)
Block(-5,5,-2,STONE:0)
Block(-5,6,-2,STONE:0)
Block(-7,6,3,GRASS:0)
Block(-5,7,-2,GRASS:0)
Block(-4,12,-7,LEAVES:3)
Block(-1,5,0,STONE:0)
Block(3,8,0,DIRT:0)
Block(-1,4,0,STONE:0)
Block(3,7,0,DIRT:0)
Block(3,6,0,DIRT:0)
Block(-1,7,0,STONE:0)
Block(3,5,0,STONE:0)
Block(-1,6,0,STONE:0)
Block(-1,9,0,GRASS:0)
Block(-1,8,0,STONE:0)
Block(3,9,0,GRASS:0)
Block(-6,6,5,AIR)
Block(-1,1,0,STONE:0)
Block(-1,0,0,STONE:0)
Block(-1,3,0,STONE:0)
Block(-1,2,0,STONE:0)
Block(4,10,4,AIR)
Block(4,11,4,LEAVES:3)
Block(4,12,4,LEAVES:3)
Block(4,13,4,LEAVES:3)
Block(4,14,4,LEAVES:3)
Block(3,4,0,STONE:0)
Block(3,3,0,STONE:0)
Block(-1,6,-2,STONE:0)
Block(-1,5,-2,STONE:0)
Block(-1,4,-2,STONE:0)
Block(-1,3,-2,STONE:0)
Block(-1,2,-2,STONE:0)
Block(-1,1,-2,STONE:0)
Block(-1,0,-2,STONE:0)
Block(2,3,2,STONE:0)
Block(2,2,2,STONE:0)
Block(-1,9,-2,GRASS:0)
Block(-1,8,-2,STONE:0)
Block(-1,7,-2,STONE:0)
Block(-3,12,-3,LEAVES:3)
Block(-3,11,-3,LEAVES:3)
Block(-3,14,-3,LEAVES:0)
Block(-3,13,-3,LEAVES:0)
Block(0,7,6,YELLOW_FLOWER:0)
Block(0,6,6,GRASS:0)
Block(0,14,-1,LEAVES:0)
Block(0,13,-1,LEAVES:0)
Block(1,7,6,GRASS:0)
Block(3,5,-5,STONE:0)
Block(1,6,6,STONE:0)
Block(3,6,-5,STONE:0)
Block(3,7,-5,STONE:0)
Block(3,8,-5,GRASS:0)
Block(2,7,4,STONE:0)
Block(2,6,4,STONE:0)
Block(2,9,4,LONG_GRASS:1)
Block(2,8,4,GRASS:0)
Block(2,5,4,STONE:0)
Block(-1,3,2,STONE:0)
Block(3,6,2,DIRT:0)
Block(-1,2,2,STONE:0)
Block(3,5,2,STONE:0)
Block(3,4,2,STONE:0)
Block(-1,5,2,STONE:0)
Block(3,3,2,STONE:0)
Block(-1,4,2,STONE:0)
Block(-1,7,2,STONE:0)
Block(-1,6,2,STONE:0)
Block(3,8,2,GRASS:0)
Block(-1,9,2,LONG_GRASS:1)
Block(3,7,2,DIRT:0)
Block(-1,8,2,GRASS:0)
Block(-2,9,0,GRASS:0)
Block(-2,8,0,STONE:0)
Block(-2,7,0,STONE:0)
Block(-2,6,0,STONE:0)
Block(-2,5,0,STONE:0)
Block(-2,4,0,STONE:0)
Block(-2,3,0,STONE:0)
Block(-2,2,0,STONE:0)
Block(4,5,0,STONE:0)
Block(-1,15,0,LEAVES:0)
Block(-2,1,0,STONE:0)
Block(4,4,0,STONE:0)
Block(4,7,0,DIRT:0)
Block(4,6,0,DIRT:0)
Block(4,9,0,AIR)
Block(4,8,0,GRASS:0)
Block(-1,1,2,STONE:0)
Block(-1,13,0,LEAVES:0)
Block(-1,14,0,LEAVES:0)
Block(-1,13,-5,LEAVES:3)
Block(-1,14,-5,LEAVES:3)
Block(-1,11,-5,LEAVES:3)
Block(-1,12,-5,LEAVES:3)
Block(3,13,1,AIR)
Block(3,11,1,LEAVES:3)
Block(3,12,1,LEAVES:3)
Block(-1,4,-4,STONE:0)
Block(-1,3,-4,STONE:0)
Block(-1,2,-4,STONE:0)
Block(-1,8,-4,GRASS:0)
Block(-1,7,-4,STONE:0)
Block(-1,6,-4,STONE:0)
Block(-1,5,-4,STONE:0)
Block(5,12,5,LEAVES:3)
Block(5,11,5,LEAVES:3)
Block(0,1,2,STONE:0)
Block(0,3,2,STONE:0)
Block(-3,11,-5,LEAVES:3)
Block(0,2,2,STONE:0)
Block(3,6,-7,GRASS:0)
Block(1,9,0,GRASS:0)
Block(-3,12,-5,LEAVES:3)
Block(0,5,2,STONE:0)
Block(1,8,0,DIRT:0)
Block(3,7,-7,AIR)
Block(0,4,2,STONE:0)
Block(1,7,0,DIRT:0)
Block(-1,13,-7,AIR)
Block(-1,12,-7,LEAVES:3)
Block(-1,11,-7,LEAVES:3)
Block(-3,7,0,STONE:0)
Block(-3,6,0,STONE:0)
Block(-3,9,0,GRASS:0)
Block(-3,8,0,STONE:0)
Block(-3,3,0,STONE:0)
Block(-3,2,0,STONE:0)
Block(-3,5,0,STONE:0)
Block(-3,4,0,STONE:0)
Block(-1,5,4,STONE:0)
Block(-1,7,4,STONE:0)
Block(-1,6,4,STONE:0)
Block(-2,8,2,GRASS:0)
Block(-2,7,2,STONE:0)
Block(-1,8,4,GRASS:0)
Block(-2,6,2,STONE:0)
Block(-2,5,2,STONE:0)
Block(-2,4,2,STONE:0)
Block(-2,3,2,STONE:0)
Block(-2,2,2,STONE:0)
Block(-2,1,2,STONE:0)
Block(-3,13,-5,LEAVES:3)
Block(-3,14,-5,LEAVES:3)
Block(6,6,-1,STONE:0)
Block(6,7,-1,GRASS:0)
Block(6,5,-1,AIR)
Block(6,11,3,LEAVES:3)
Block(-6,7,-1,GRASS:0)
Block(-6,6,-1,STONE:0)
Block(-6,5,-1,STONE:0)
Block(4,8,-2,STONE:0)
Block(4,7,-2,STONE:0)
Block(4,9,-2,GRASS:0)
Block(4,4,-2,STONE:0)
Block(6,13,3,AIR)
Block(6,12,3,LEAVES:3)
Block(4,6,-2,STONE:0)
Block(4,5,-2,STONE:0)
Block(6,14,3,AIR)
Block(-4,11,-5,LEAVES:3)
Block(-4,12,-5,LEAVES:3)
Block(4,14,2,LEAVES:3)
Block(4,13,2,LEAVES:3)
Block(4,12,2,LEAVES:3)
Block(4,11,2,LEAVES:3)
Block(4,10,2,AIR)
Block(-3,6,-5,GRASS:0)
Block(1,6,0,DIRT:0)
Block(0,7,2,STONE:0)
Block(1,5,0,STONE:0)
Block(0,6,2,STONE:0)
Block(1,4,0,STONE:0)
Block(0,9,2,GRASS:0)
Block(1,3,0,STONE:0)
Block(0,8,2,STONE:0)
Block(1,2,0,STONE:0)
Block(1,1,0,STONE:0)
Block(1,9,2,GRASS:0)
Block(1,8,2,DIRT:0)
Block(1,7,2,DIRT:0)
Block(0,3,4,STONE:0)
Block(1,6,2,STONE:0)
Block(1,5,2,STONE:0)
Block(-4,4,0,STONE:0)
Block(-4,3,0,STONE:0)
Block(-4,8,0,GRASS:0)
Block(-4,7,0,STONE:0)
Block(-4,6,0,STONE:0)
Block(-4,5,0,STONE:0)
Block(1,6,-6,STONE:0)
Block(1,7,-6,GRASS:0)
Block(1,4,-6,STONE:0)
Block(1,5,-6,STONE:0)
Block(2,7,0,DIRT:0)
Block(2,6,0,DIRT:0)
Block(-3,8,2,GRASS:0)
Block(2,9,0,GRASS:0)
Block(2,8,0,DIRT:0)
Block(-3,5,2,STONE:0)
Block(-3,4,2,STONE:0)
Block(6,11,1,LEAVES:3)
Block(-3,7,2,STONE:0)
Block(-3,6,2,STONE:0)
Block(-3,3,2,STONE:0)
Block(-3,2,2,STONE:0)
Block(-5,6,-4,GRASS:0)
Block(-2,8,4,LONG_GRASS:1)
Block(-2,7,4,GRASS:0)
Block(-2,6,4,STONE:0)
Block(-2,13,-7,AIR)
Block(-1,7,6,LONG_GRASS:1)
Block(-2,5,4,STONE:0)
Block(-1,6,6,GRASS:0)
Block(-2,12,-7,LEAVES:3)
Block(-2,11,-7,LEAVES:3)
Block(0,11,-3,LEAVES:3)
Block(6,6,-3,STONE:0)
Block(-3,13,1,LEAVES:0)
Block(-3,12,-7,LEAVES:3)
Block(-3,14,1,LEAVES:0)
Block(-3,11,-7,LEAVES:3)
Block(2,12,5,AIR)
Block(2,11,5,LEAVES:3)
Block(2,3,0,STONE:0)
Block(2,2,0,STONE:0)
Block(2,5,0,STONE:0)
Block(2,4,0,STONE:0)
Block(-3,4,-3,STONE:0)
Block(-3,5,-3,STONE:0)
Block(-3,6,-3,STONE:0)
Block(-3,7,-3,STONE:0)
Block(1,4,2,STONE:0)
Block(0,5,4,STONE:0)
Block(-3,8,-3,GRASS:0)
Block(1,3,2,STONE:0)
Block(0,4,4,STONE:0)
Block(1,2,2,STONE:0)
Block(0,7,4,STONE:0)
Block(1,1,2,STONE:0)
Block(0,6,4,STONE:0)
Block(0,9,4,YELLOW_FLOWER:0)
Block(0,8,4,GRASS:0)
Block(-4,8,2,GRASS:0)
Block(-4,7,2,STONE:0)
Block(5,11,2,LEAVES:3)
Block(5,12,2,LEAVES:3)
Block(5,13,2,LEAVES:3)
Block(-4,6,2,STONE:0)
Block(-4,5,2,STONE:0)
Block(-4,4,2,STONE:0)
Block(-3,7,4,GRASS:0)
Block(-3,6,4,STONE:0)
Block(-4,14,-1,LEAVES:0)
Block(-4,13,-1,LEAVES:0)
Block(-7,6,-1,GRASS:0)
Block(-7,7,-1,LONG_GRASS:1)
Block(-2,6,6,GRASS:0)
Block(-3,3,-2,STONE:0)
Block(-3,4,-2,STONE:0)
Block(0,12,-7,LEAVES:3)
Block(-3,5,-2,STONE:0)
Block(-3,6,-2,STONE:0)
Block(-3,7,-2,STONE:0)
Block(5,8,4,YELLOW_FLOWER:0)
Block(5,7,4,GRASS:0)
Block(-3,8,-2,STONE:0)
Block(5,6,4,STONE:0)
Block(-3,9,-2,GRASS:0)
Block(4,6,6,GRASS:0)
Block(6,7,0,GRASS:0)
Block(6,6,0,DIRT:0)
Block(-2,10,-4,AIR)
Block(-2,11,-4,LEAVES:3)
Block(-2,12,-4,LEAVES:3)
Block(1,9,-3,GRASS:0)
Block(4,7,-6,GRASS:0)
Block(1,7,-3,STONE:0)
Block(1,8,-3,STONE:0)
Block(1,5,-3,STONE:0)
Block(1,6,-3,STONE:0)
Block(1,3,-3,STONE:0)
Block(4,6,-6,STONE:0)
Block(1,4,-3,STONE:0)
Block(1,1,-3,STONE:0)
Block(1,2,-3,STONE:0)
Block(-5,8,0,GRASS:0)
Block(5,6,-4,STONE:0)
Block(5,7,-4,GRASS:0)
Block(-5,5,0,STONE:0)
Block(-5,4,0,STONE:0)
Block(-5,7,0,STONE:0)
Block(-5,6,0,STONE:0)
Block(-4,7,4,GRASS:0)
Block(-4,6,4,STONE:0)
Block(-4,5,4,AIR)
Block(-2,16,0,LEAVES:0)
Block(-2,13,0,LEAVES:0)
Block(-2,15,0,LEAVES:0)
Block(-2,14,0,LEAVES:0)
Block(-3,6,6,AIR)
Block(-4,11,-3,LEAVES:3)
Block(-4,12,-3,LEAVES:3)
Block(2,12,3,LEAVES:3)
Block(-4,14,-3,LEAVES:0)
Block(2,11,3,LEAVES:3)
Block(-7,6,-3,GRASS:0)
Block(4,11,0,AIR)
Block(4,12,0,AIR)
Block(4,10,0,AIR)
Block(2,5,-1,STONE:0)
Block(-2,13,-4,LEAVES:3)
Block(2,4,-1,STONE:0)
Block(-2,14,-4,LEAVES:3)
Block(2,3,-1,STONE:0)
Block(5,6,6,GRASS:0)
Block(2,2,-1,STONE:0)
Block(0,8,1,DIRT:0)
Block(2,9,-1,GRASS:0)
Block(0,7,1,DIRT:0)
Block(2,8,-1,DIRT:0)
Block(2,7,-1,DIRT:0)
Block(2,6,-1,STONE:0)
Block(0,9,1,GRASS:0)
Block(5,11,0,AIR)
Block(5,10,0,AIR)
Block(5,12,0,AIR)
Block(-6,7,-3,LONG_GRASS:1)
Block(-6,6,-3,GRASS:0)
Block(-2,9,-6,AIR)
Block(1,9,-1,GRASS:0)
Block(4,6,-4,STONE:0)
Block(1,7,-1,STONE:0)
Block(1,8,-1,STONE:0)
Block(1,5,-1,STONE:0)
Block(-2,6,-6,GRASS:0)
Block(4,8,-4,GRASS:0)
Block(1,6,-1,STONE:0)
Block(4,7,-4,STONE:0)
Block(1,3,-1,STONE:0)
Block(1,4,-1,STONE:0)
Block(0,6,-7,GRASS:0)
Block(1,1,-1,STONE:0)
Block(1,2,-1,STONE:0)
Block(-6,6,0,STONE:0)
Block(-6,5,0,STONE:0)
Block(6,11,4,LEAVES:3)
Block(6,12,4,LEAVES:3)
Block(-6,7,0,GRASS:0)
Block(-5,7,2,GRASS:0)
Block(-5,6,2,STONE:0)
Block(1,10,3,AIR)
Block(1,11,3,AIR)
Block(0,13,-5,AIR)
Block(0,12,-5,LEAVES:3)
Block(6,13,4,AIR)
Block(0,11,-5,LEAVES:3)
Block(-5,5,2,STONE:0)
Block(2,7,6,GRASS:0)
Block(0,13,1,LEAVES:0)
Block(2,6,6,STONE:0)
Block(3,8,4,GRASS:0)
Block(3,7,4,STONE:0)
Block(3,6,4,STONE:0)
Block(3,5,4,STONE:0)
Block(4,5,2,STONE:0)
Block(4,4,2,STONE:0)
Block(2,3,-3,STONE:0)
Block(4,7,2,DIRT:0)
Block(2,2,-3,STONE:0)
Block(4,6,2,DIRT:0)
Block(4,8,2,GRASS:0)
Block(2,7,-3,STONE:0)
Block(2,6,-3,STONE:0)
Block(5,9,0,AIR)
Block(2,5,-3,STONE:0)
Block(5,8,0,GRASS:0)
Block(2,4,-3,STONE:0)
Block(5,7,0,DIRT:0)
Block(5,6,0,DIRT:0)
Block(5,5,0,STONE:0)
Block(2,9,-3,GRASS:0)
Block(2,8,-3,STONE:0)
Block(0,3,-5,STONE:0)
Block(0,5,-5,STONE:0)
Block(5,13,4,LEAVES:3)
Block(0,4,-5,STONE:0)
Block(5,12,4,LEAVES:3)
Block(0,7,-5,GRASS:0)
Block(0,6,-5,STONE:0)
Block(5,14,4,AIR)
Block(-2,6,-4,STONE:0)
Block(-2,7,-4,GRASS:0)
Block(-2,9,-4,AIR)
Block(-2,4,-4,STONE:0)
Block(5,11,4,LEAVES:3)
Block(3,12,5,LEAVES:3)
Block(3,11,5,LEAVES:3)
Block(-7,7,0,LONG_GRASS:1)
Block(-7,6,0,GRASS:0)
Block(-4,7,-2,STONE:0)
Block(2,11,1,LEAVES:3)
Block(-4,6,-2,STONE:0)
Block(-4,9,-2,AIR)
Block(-4,8,-2,GRASS:0)
Block(2,12,1,AIR)
Block(-4,5,-2,STONE:0)
Block(-4,4,-2,STONE:0)
Block(-1,6,-6,GRASS:0)
Block(-6,6,2,GRASS:0)
Block(-6,5,2,GRASS:0)
Block(-5,6,4,GRASS:0)
Block(3,7,-1,DIRT:0)
Block(3,8,-1,DIRT:0)
Block(3,9,-1,GRASS:0)
Block(3,3,-1,STONE:0)
Block(3,4,-1,STONE:0)
Block(3,5,-1,STONE:0)
Block(3,6,-1,DIRT:0)
Block(3,12,3,LEAVES:3)
Block(3,11,3,LEAVES:3)
Block(3,10,3,AIR)
Block(3,14,3,LEAVES:3)
Block(3,13,3,LEAVES:3)
Block(3,6,6,GRASS:0)
Block(3,9,6,AIR)
Block(3,8,6,AIR)
Block(3,7,6,YELLOW_FLOWER:0)
Block(-4,14,0,LEAVES:0)
Block(4,5,4,STONE:0)
Block(-4,13,0,LEAVES:0)
Block(4,7,4,GRASS:0)
Block(4,6,4,STONE:0)
Block(2,5,-5,STONE:0)
Block(5,8,2,GRASS:0)
Block(2,4,-5,STONE:0)
Block(5,7,2,DIRT:0)
Block(2,3,-5,STONE:0)
Block(5,6,2,STONE:0)
Block(5,5,2,STONE:0)
Block(-3,13,-1,LEAVES:0)
Block(2,8,-5,GRASS:0)
Block(-3,14,-1,LEAVES:0)
Block(2,7,-5,STONE:0)
Block(-3,15,-1,LEAVES:0)
Block(2,6,-5,STONE:0)
Block(-3,16,-1,LEAVES:0)
Block(0,3,-3,STONE:0)
Block(0,2,-3,STONE:0)
Block(0,5,-3,STONE:0)
Block(0,4,-3,STONE:0)
Block(0,7,-3,STONE:0)
Block(0,6,-3,STONE:0)
Block(0,8,-3,GRASS:0)
Block(6,6,2,STONE:0)
Block(-1,13,-2,LEAVES:0)
Block(0,1,-3,STONE:0)
Block(-1,14,-2,LEAVES:0)
Block(0,0,-3,STONE:0)
Block(-2,9,-2,GRASS:0)
Block(-2,8,-2,STONE:0)
Block(-2,3,-2,STONE:0)
Block(-2,2,-2,STONE:0)
Block(-2,1,-2,STONE:0)
Block(-2,7,-2,STONE:0)
Block(-2,6,-2,STONE:0)
Block(-2,5,-2,STONE:0)
Block(-2,4,-2,STONE:0)
Block(-7,6,2,GRASS:0)
Block(-4,7,-4,GRASS:0)
Block(-4,6,-4,STONE:0)
Block(-6,6,4,GRASS:0)
Block(-2,14,-2,LEAVES:0)
Block(-2,13,-2,LEAVES:0)
Block(5,6,-2,STONE:0)
Block(5,7,-2,STONE:0)
Block(-2,16,-2,LEAVES:0)
Block(5,5,-2,STONE:0)
Block(-2,15,-2,LEAVES:0)
Block(5,8,-2,GRASS:0)
Block(-1,14,-4,AIR)
Block(-3,13,-2,LEAVES:0)
Block(-3,15,-2,LEAVES:0)
Block(-1,13,1,LEAVES:0)
Block(-3,14,-2,LEAVES:0)
Block(-1,14,1,LEAVES:0)
Block(-1,5,-3,STONE:0)
Block(-1,4,-3,STONE:0)
Block(-1,3,-3,STONE:0)
Block(-1,2,-3,STONE:0)
Block(-1,1,-3,STONE:0)
Block(2,2,1,STONE:0)
Block(2,4,1,STONE:0)
Block(2,3,1,STONE:0)
Block(-1,8,-3,GRASS:0)
Block(-1,7,-3,STONE:0)
Block(-1,6,-3,STONE:0)
Block(4,11,5,LEAVES:3)
Block(4,12,5,LEAVES:3)
Block(4,13,5,AIR)
Block(1,3,3,STONE:0)
Block(1,2,3,STONE:0)
Block(3,11,2,LEAVES:3)
Block(0,6,7,GRASS:0)
Block(3,14,2,AIR)
Block(2,6,-7,GRASS:0)
Block(3,12,2,LEAVES:3)
Block(3,13,2,LEAVES:3)
Block(0,5,-1,STONE:0)
Block(3,6,-2,STONE:0)
Block(1,9,5,LONG_GRASS:1)
Block(0,4,-1,STONE:0)
Block(3,7,-2,STONE:0)
Block(1,8,5,GRASS:0)
Block(0,7,-1,STONE:0)
Block(1,7,5,STONE:0)
Block(3,8,-2,STONE:0)
Block(0,6,-1,STONE:0)
Block(1,6,5,STONE:0)
Block(3,9,-2,GRASS:0)
Block(1,5,5,STONE:0)
Block(0,9,-1,GRASS:0)
Block(0,8,-1,STONE:0)
Block(0,1,-1,STONE:0)
Block(0,0,-1,STONE:0)
Block(3,3,-2,STONE:0)
Block(0,3,-1,STONE:0)
Block(3,4,-2,STONE:0)
Block(0,2,-1,STONE:0)
Block(3,5,-2,STONE:0)
Block(2,8,3,GRASS:0)
Block(2,7,3,STONE:0)
Block(2,4,3,STONE:0)
Block(2,3,3,STONE:0)
Block(2,6,3,STONE:0)
Block(2,5,3,STONE:0)
Block(-5,5,-3,DIRT:0)
Block(-5,6,-3,STONE:0)
Block(-5,7,-3,GRASS:0)
Block(3,7,1,DIRT:0)
Block(3,6,1,DIRT:0)
Block(3,5,1,STONE:0)
Block(3,4,1,STONE:0)
Block(3,8,1,GRASS:0)
Block(-1,11,-4,LEAVES:3)
Block(-1,13,-4,LEAVES:3)
Block(-1,12,-4,LEAVES:3)
Block(3,3,1,STONE:0)
Block(-3,11,-4,LEAVES:3)
Block(-1,9,-5,AIR)
Block(-1,7,-5,GRASS:0)
Block(-1,6,-5,STONE:0)
Block(-1,5,-5,STONE:0)
Block(1,10,-4,AIR)
Block(-1,12,-6,LEAVES:3)
Block(1,12,-4,AIR)
Block(-1,13,-6,LEAVES:3)
Block(1,11,-4,AIR)
Block(-1,11,-6,LEAVES:3)
Block(3,4,-4,STONE:0)
Block(3,5,-4,STONE:0)
Block(1,6,7,GRASS:0)
Block(3,6,-4,STONE:0)
Block(3,7,-4,STONE:0)
Block(3,8,-4,GRASS:0)
Block(3,3,-4,STONE:0)
Block(2,6,5,STONE:0)
Block(2,5,5,STONE:0)
Block(2,7,5,GRASS:0)
Block(-5,6,-1,STONE:0)
Block(-5,7,-1,STONE:0)
Block(-5,4,-1,STONE:0)
Block(-3,12,-4,LEAVES:3)
Block(-5,5,-1,STONE:0)
Block(-3,13,-4,LEAVES:3)
Block(-5,8,-1,GRASS:0)
Block(-1,4,1,STONE:0)
Block(3,5,3,STONE:0)
Block(-1,3,1,STONE:0)
Block(3,4,3,STONE:0)
Block(-1,6,1,STONE:0)
Block(-1,5,1,STONE:0)
Block(-1,8,1,STONE:0)
Block(3,9,3,YELLOW_FLOWER:0)
Block(-1,7,1,STONE:0)
Block(3,8,3,GRASS:0)
Block(3,7,3,STONE:0)
Block(3,6,3,STONE:0)
Block(-1,9,1,GRASS:0)
Block(4,4,1,STONE:0)
Block(4,6,1,DIRT:0)
Block(4,5,1,STONE:0)
Block(4,8,1,GRASS:0)
Block(4,7,1,DIRT:0)
Block(-1,0,1,STONE:0)
Block(-1,2,1,STONE:0)
Block(-1,1,1,STONE:0)
Block(6,7,-2,GRASS:0)
Block(-4,11,-4,LEAVES:3)
Block(-4,12,-4,LEAVES:3)
Block(6,6,-2,STONE:0)
Block(-2,12,-6,LEAVES:3)
Block(-2,11,-6,LEAVES:3)
Block(-2,14,-6,LEAVES:3)
Block(-2,13,-6,LEAVES:3)
Block(-6,7,-2,GRASS:0)
Block(-6,6,-2,STONE:0)
Block(-6,5,-2,DIRT:0)
Block(-2,10,-6,AIR)
Block(4,7,-3,STONE:0)
Block(4,6,-3,STONE:0)
Block(4,8,-3,GRASS:0)
Block(0,12,-4,LEAVES:3)
Block(0,13,-4,AIR)
Block(4,5,-3,STONE:0)
Block(4,4,-3,STONE:0)
Block(0,11,-4,LEAVES:3)
Block(0,6,3,STONE:0)
Block(6,12,2,LEAVES:3)
Block(0,5,3,STONE:0)
Block(6,11,2,LEAVES:3)
Block(5,6,-7,AIR)
Block(0,8,3,GRASS:0)
Block(0,7,3,STONE:0)
Block(6,13,2,AIR)
Block(0,0,1,STONE:0)
Block(0,2,1,STONE:0)
Block(0,1,1,STONE:0)
Block(0,4,1,STONE:0)
Block(3,6,-6,STONE:0)
Block(1,9,1,GRASS:0)
Block(0,3,1,STONE:0)
Block(3,7,-6,GRASS:0)
Block(1,8,1,DIRT:0)
Block(0,6,1,STONE:0)
Block(1,7,1,DIRT:0)
Block(0,5,1,STONE:0)
Block(1,6,1,DIRT:0)
Block(1,6,-7,GRASS:0)
Block(-1,2,3,STONE:0)
Block(-1,4,3,STONE:0)
Block(-1,3,3,STONE:0)
Block(-1,6,3,STONE:0)
Block(-3,13,-6,LEAVES:3)
Block(-1,5,3,STONE:0)
Block(-3,12,-6,LEAVES:3)
Block(-1,8,3,GRASS:0)
Block(-3,11,-6,LEAVES:3)
Block(-3,13,0,LEAVES:0)
Block(-1,7,3,STONE:0)
Block(-3,14,0,LEAVES:0)
Block(-2,8,1,GRASS:0)
Block(-2,7,1,STONE:0)
Block(-2,6,1,STONE:0)
Block(-2,5,1,STONE:0)
Block(-2,4,1,STONE:0)
Block(-2,3,1,STONE:0)
Block(-2,2,1,STONE:0)
Block(-2,1,1,STONE:0)
Block(6,6,-4,STONE:0)
Block(4,14,3,LEAVES:3)
Block(4,13,3,LOG:3)
Block(4,12,3,LOG:3)
Block(4,11,3,LOG:3)
Block(4,10,3,LOG:3)
Block(4,9,-1,GRASS:0)
Block(4,8,-1,DIRT:0)
Block(4,5,-1,STONE:0)
Block(4,4,-1,STONE:0)
Block(4,7,-1,DIRT:0)
Block(4,6,-1,DIRT:0)
Block(-1,7,-1,STONE:0)
Block(-1,6,-1,STONE:0)
Block(-1,5,-1,STONE:0)
Block(-1,4,-1,STONE:0)
Block(-1,3,-1,STONE:0)
Block(-1,2,-1,STONE:0)
Block(-1,1,-1,STONE:0)
Block(-1,0,-1,STONE:0)
Block(-1,9,-1,GRASS:0)
Block(-1,8,-1,STONE:0)
Block(-3,6,-4,STONE:0)
Block(1,5,1,STONE:0)
Block(-3,7,-4,GRASS:0)
Block(1,4,1,STONE:0)
Block(1,3,1,STONE:0)
Block(0,6,5,STONE:0)
Block(1,2,1,STONE:0)
Block(0,5,5,STONE:0)
Block(1,1,1,STONE:0)
Block(0,8,5,YELLOW_FLOWER:0)
Block(0,7,5,GRASS:0)
Block(-4,12,-6,LEAVES:3)
Block(-4,11,-6,LEAVES:3)
Block(1,9,3,GRASS:0)
Block(1,8,3,STONE:0)
Block(0,2,3,STONE:0)
Block(1,7,3,STONE:0)
Block(0,1,3,STONE:0)
Block(1,6,3,STONE:0)
Block(0,4,3,STONE:0)
Block(1,5,3,STONE:0)
Block(0,3,3,STONE:0)
Block(1,4,3,STONE:0)
Block(1,7,-5,STONE:0)
Block(1,8,-5,GRASS:0)
Block(2,9,1,GRASS:0)
Block(1,5,-5,STONE:0)
Block(1,6,-5,STONE:0)
Block(1,3,-5,STONE:0)
Block(2,6,1,DIRT:0)
Block(1,4,-5,STONE:0)
Block(2,5,1,STONE:0)
Block(2,8,1,DIRT:0)
Block(1,2,-5,STONE:0)
Block(2,7,1,DIRT:0)
Block(-3,6,1,STONE:0)
Block(-3,5,1,STONE:0)
Block(-3,8,1,GRASS:0)
Block(-3,7,1,STONE:0)
Block(-3,2,1,STONE:0)
Block(0,13,-2,LEAVES:0)
Block(-5,6,-5,AIR)
Block(-3,4,1,STONE:0)
Block(-3,3,1,STONE:0)
Block(0,14,-2,LEAVES:0)
Block(-1,6,5,STONE:0)
Block(-2,8,3,GRASS:0)
Block(-2,7,3,STONE:0)
Block(-2,6,3,STONE:0)
Block(-1,7,5,GRASS:0)
Block(-2,5,3,STONE:0)
Block(-2,4,3,STONE:0)
Block(-2,3,3,STONE:0)

#######################################################################
# +-----------------------------------------------------------------+ #
# |                            BO3 checks                           | #
# +-----------------------------------------------------------------+ #
#######################################################################


#######################################################################
# +-----------------------------------------------------------------+ #
# |                             Branches                            | #
# +-----------------------------------------------------------------+ #
#######################################################################


#######################################################################
# +-----------------------------------------------------------------+ #
# |                             Entities                            | #
# +-----------------------------------------------------------------+ #
#######################################################################


#######################################################################
# +-----------------------------------------------------------------+ #
# |                            Particles                            | #
# +-----------------------------------------------------------------+ #
#######################################################################


#######################################################################
# +-----------------------------------------------------------------+ #
# |                             Spawners                            | #
# +-----------------------------------------------------------------+ #
#######################################################################


#######################################################################
# +-----------------------------------------------------------------+ #
# |                             ModData                             | #
# +-----------------------------------------------------------------+ #
#######################################################################

