
#######################################################################
# +-----------------------------------------------------------------+ #
# |                            BO3 object                           | #
# +-----------------------------------------------------------------+ #
#######################################################################

Author: MC_Pitman

Description: No description given

Version: 3

SettingsMode: WriteWithoutComments


#######################################################################
# +-----------------------------------------------------------------+ #
# |                          Main settings                          | #
# +-----------------------------------------------------------------+ #
#######################################################################

Tree: true

Frequency: 1

Rarity: 1.0E-6

RotateRandomly: false

SpawnHeight: randomY

SpawnHeightOffset: 0

SpawnHeightVariance: 0

##############################
# Height Limits for the BO3. #
##############################

MinHeight: 50

MaxHeight: 120

######################
# Extrusion settings #
######################

ExtrudeMode: None

ExtrudeThroughBlocks: AIR

MaxBranchDepth: 10

ExcludedBiomes: All


#######################################################################
# +-----------------------------------------------------------------+ #
# |                      Source block settings                      | #
# +-----------------------------------------------------------------+ #
#######################################################################

SourceBlocks: AIR

MaxPercentageOutsideSourceBlock: 100

OutsideSourceBlock: placeAnyway

DoReplaceBlocks: true

IsOTGPlus: false


#######################################################################
# +-----------------------------------------------------------------+ #
# |                              Blocks                             | #
# +-----------------------------------------------------------------+ #
#######################################################################

Block(-28,3,-5,DIRT:0)
Block(-28,4,-5,STONE:0)
Block(-28,4,-4,DIRT:0)
Block(-28,5,-7,STONE:0)
Block(-28,5,-6,DIRT:0)
Block(-28,5,-5,DIRT:0)
Block(-28,5,-4,DIRT:0)
Block(-28,5,-3,DIRT:0)
Block(-28,6,-6,GRASS:0)
Block(-28,6,-5,DIRT:0)
Block(-28,6,-4,DIRT:0)
Block(-28,6,-3,DIRT:0)
Block(-28,7,-6,LONG_GRASS:1)
Block(-28,7,-5,GRASS:0)
Block(-28,7,-4,GRASS:0)
Block(-28,7,-3,GRASS:0)
Block(-28,8,-5,LONG_GRASS:1)
Block(-28,8,-3,LONG_GRASS:1)
Block(-27,1,-6,STONE:0)
Block(-27,2,-6,DIRT:0)
Block(-27,2,-5,DIRT:0)
Block(-27,3,-6,STONE:0)
Block(-27,3,-5,STONE:0)
Block(-27,3,-4,DIRT:0)
Block(-27,4,-10,DIRT:0)
Block(-27,4,-9,STONE:0)
Block(-27,4,-8,STONE:0)
Block(-27,4,-7,STONE:0)
Block(-27,4,-6,STONE:0)
Block(-27,4,-5,STONE:0)
Block(-27,4,-4,STONE:0)
Block(-27,4,-3,STONE:0)
Block(-27,4,-2,STONE:0)
Block(-27,5,-12,STONE:0)
Block(-27,5,-11,STONE:0)
Block(-27,5,-10,STONE:0)
Block(-27,5,-9,STONE:0)
Block(-27,5,-8,STONE:0)
Block(-27,5,-7,DIRT:0)
Block(-27,5,-6,STONE:0)
Block(-27,5,-5,STONE:0)
Block(-27,5,-4,STONE:0)
Block(-27,5,-3,STONE:0)
Block(-27,5,-2,DIRT:0)
Block(-27,5,-1,STONE:0)
Block(-27,6,-12,GRASS:0)
Block(-27,6,-10,STONE:0)
Block(-27,6,-9,STONE:0)
Block(-27,6,-7,GRASS:0)
Block(-27,6,-6,DIRT:0)
Block(-27,6,-5,STONE:0)
Block(-27,6,-4,STONE:0)
Block(-27,6,-3,STONE:0)
Block(-27,6,-2,DIRT:0)
Block(-27,6,-1,DIRT:0)
Block(-27,7,-12,LONG_GRASS:1)
Block(-27,7,-10,GRASS:0)
Block(-27,7,-9,STONE:0)
Block(-27,7,-6,GRASS:0)
Block(-27,7,-5,GRASS:0)
Block(-27,7,-4,GRASS:0)
Block(-27,7,-3,GRASS:0)
Block(-27,7,-2,GRASS:0)
Block(-27,7,-1,GRASS:0)
Block(-27,8,-6,LONG_GRASS:1)
Block(-27,8,-5,LONG_GRASS:1)
Block(-27,8,-4,LONG_GRASS:1)
Block(-27,8,-3,YELLOW_FLOWER:0)
Block(-27,8,-2,LONG_GRASS:1)
Block(-27,8,-1,RED_ROSE:0)
Block(-27,10,-18,LEAVES:0)
Block(-27,10,-17,LEAVES:0)
Block(-27,10,-16,LEAVES:0)
Block(-27,10,-15,LEAVES:0)
Block(-27,10,-14,LEAVES:0)
Block(-27,11,-17,LEAVES:0)
Block(-27,11,-16,LEAVES:0)
Block(-27,11,-15,LEAVES:0)
Block(-27,11,-14,LEAVES:0)
Block(-27,11,3,LEAVES:0)
Block(-27,11,4,LEAVES:0)
Block(-27,11,5,LEAVES:0)
Block(-27,11,6,LEAVES:0)
Block(-27,12,-18,LEAVES:0)
Block(-27,12,-17,LEAVES:0)
Block(-27,12,-16,LEAVES:0)
Block(-27,12,-15,LEAVES:0)
Block(-27,12,3,LEAVES:0)
Block(-27,12,4,LEAVES:0)
Block(-27,12,5,LEAVES:0)
Block(-27,12,6,LEAVES:0)
Block(-27,12,7,LEAVES:0)
Block(-27,13,4,LEAVES:0)
Block(-27,13,5,LEAVES:0)
Block(-27,13,6,LEAVES:0)
Block(-26,0,-6,DIRT:0)
Block(-26,0,0,DIRT:0)
Block(-26,0,1,DIRT:0)
Block(-26,1,-7,DIRT:0)
Block(-26,1,-6,STONE:0)
Block(-26,1,-5,STONE:0)
Block(-26,1,-4,DIRT:0)
Block(-26,1,0,DIRT:0)
Block(-26,1,1,STONE:0)
Block(-26,1,2,STONE:0)
Block(-26,2,-8,STONE:0)
Block(-26,2,-7,STONE:0)
Block(-26,2,-6,DIRT:0)
Block(-26,2,-5,STONE:0)
Block(-26,2,-4,STONE:0)
Block(-26,2,0,DIRT:0)
Block(-26,2,1,DIRT:0)
Block(-26,2,2,DIRT:0)
Block(-26,3,-8,DIRT:0)
Block(-26,3,-7,DIRT:0)
Block(-26,3,-6,DIRT:0)
Block(-26,3,-5,DIRT:0)
Block(-26,3,-4,DIRT:0)
Block(-26,3,-3,STONE:0)
Block(-26,3,-2,STONE:0)
Block(-26,3,-1,STONE:0)
Block(-26,3,0,STONE:0)
Block(-26,3,1,STONE:0)
Block(-26,3,2,DIRT:0)
Block(-26,3,3,STONE:0)
Block(-26,4,-11,DIRT:0)
Block(-26,4,-10,DIRT:0)
Block(-26,4,-9,STONE:0)
Block(-26,4,-8,STONE:0)
Block(-26,4,-7,STONE:0)
Block(-26,4,-6,STONE:0)
Block(-26,4,-5,STONE:0)
Block(-26,4,-4,STONE:0)
Block(-26,4,-3,STONE:0)
Block(-26,4,-2,STONE:0)
Block(-26,4,-1,STONE:0)
Block(-26,4,0,STONE:0)
Block(-26,4,1,STONE:0)
Block(-26,4,2,STONE:0)
Block(-26,4,3,DIRT:0)
Block(-26,5,-15,STONE:0)
Block(-26,5,-14,STONE:0)
Block(-26,5,-13,DIRT:0)
Block(-26,5,-12,STONE:0)
Block(-26,5,-11,DIRT:0)
Block(-26,5,-10,STONE:0)
Block(-26,5,-9,STONE:0)
Block(-26,5,-8,STONE:0)
Block(-26,5,-7,STONE:0)
Block(-26,5,-6,STONE:0)
Block(-26,5,-5,DIRT:0)
Block(-26,5,-4,STONE:0)
Block(-26,5,-3,STONE:0)
Block(-26,5,-2,DIRT:0)
Block(-26,5,-1,STONE:0)
Block(-26,5,0,STONE:0)
Block(-26,5,1,STONE:0)
Block(-26,5,2,STONE:0)
Block(-26,5,3,DIRT:0)
Block(-26,5,4,DIRT:0)
Block(-26,6,-15,STONE:0)
Block(-26,6,-14,STONE:0)
Block(-26,6,-13,STONE:0)
Block(-26,6,-12,STONE:0)
Block(-26,6,-11,STONE:0)
Block(-26,6,-10,DIRT:0)
Block(-26,6,-9,STONE:0)
Block(-26,6,-8,DIRT:0)
Block(-26,6,-7,STONE:0)
Block(-26,6,-6,STONE:0)
Block(-26,6,-5,STONE:0)
Block(-26,6,-4,DIRT:0)
Block(-26,6,-3,DIRT:0)
Block(-26,6,-2,STONE:0)
Block(-26,6,-1,STONE:0)
Block(-26,6,0,STONE:0)
Block(-26,6,1,STONE:0)
Block(-26,6,2,DIRT:0)
Block(-26,6,3,DIRT:0)
Block(-26,6,4,DIRT:0)
Block(-26,6,5,DIRT:0)
Block(-26,7,-15,GRASS:0)
Block(-26,7,-14,GRASS:0)
Block(-26,7,-13,GRASS:0)
Block(-26,7,-12,GRASS:0)
Block(-26,7,-11,STONE:0)
Block(-26,7,-10,STONE:0)
Block(-26,7,-9,STONE:0)
Block(-26,7,-8,STONE:0)
Block(-26,7,-7,STONE:0)
Block(-26,7,-6,STONE:0)
Block(-26,7,-5,STONE:0)
Block(-26,7,-4,STONE:0)
Block(-26,7,-3,STONE:0)
Block(-26,7,-2,STONE:0)
Block(-26,7,-1,DIRT:0)
Block(-26,7,0,STONE:0)
Block(-26,7,1,DIRT:0)
Block(-26,7,2,DIRT:0)
Block(-26,7,3,DIRT:0)
Block(-26,7,4,GRASS:0)
Block(-26,7,5,GRASS:0)
Block(-26,8,-14,LONG_GRASS:1)
Block(-26,8,-13,LONG_GRASS:1)
Block(-26,8,-12,LONG_GRASS:1)
Block(-26,8,-10,STONE:0)
Block(-26,8,-9,STONE:0)
Block(-26,8,-8,STONE:0)
Block(-26,8,-7,GRASS:0)
Block(-26,8,-6,GRASS:0)
Block(-26,8,-5,GRASS:0)
Block(-26,8,-4,GRASS:0)
Block(-26,8,-3,GRASS:0)
Block(-26,8,-2,GRASS:0)
Block(-26,8,-1,GRASS:0)
Block(-26,8,0,GRASS:0)
Block(-26,8,1,GRASS:0)
Block(-26,8,2,GRASS:0)
Block(-26,8,3,GRASS:0)
Block(-26,8,4,LONG_GRASS:1)
Block(-26,8,5,LONG_GRASS:1)
Block(-26,9,-4,LONG_GRASS:1)
Block(-26,9,-3,LONG_GRASS:1)
Block(-26,9,-2,LONG_GRASS:1)
Block(-26,9,0,LONG_GRASS:1)
Block(-26,9,1,LONG_GRASS:1)
Block(-26,9,2,LONG_GRASS:1)
Block(-26,10,-18,LEAVES:0)
Block(-26,10,-17,LEAVES:0)
Block(-26,10,-16,LEAVES:0)
Block(-26,10,-15,LEAVES:0)
Block(-26,10,-14,LEAVES:0)
Block(-26,11,-18,LEAVES:0)
Block(-26,11,-17,LEAVES:0)
Block(-26,11,-16,LEAVES:0)
Block(-26,11,-15,LEAVES:0)
Block(-26,11,-14,LEAVES:0)
Block(-26,11,3,LEAVES:0)
Block(-26,11,4,LEAVES:0)
Block(-26,11,5,LEAVES:0)
Block(-26,11,6,LEAVES:0)
Block(-26,11,7,LEAVES:0)
Block(-26,12,-18,LEAVES:0)
Block(-26,12,-17,LEAVES:0)
Block(-26,12,-16,LEAVES:0)
Block(-26,12,-15,LEAVES:0)
Block(-26,12,-14,LEAVES:0)
Block(-26,12,3,LEAVES:0)
Block(-26,12,4,LEAVES:0)
Block(-26,12,5,LEAVES:0)
Block(-26,12,6,LEAVES:0)
Block(-26,12,7,LEAVES:0)
Block(-26,13,-17,LEAVES:0)
Block(-26,13,-16,LEAVES:0)
Block(-26,13,-15,LEAVES:0)
Block(-26,13,-7,LEAVES:0)
Block(-26,13,-6,LEAVES:0)
Block(-26,13,-5,LEAVES:0)
Block(-26,13,-4,LEAVES:0)
Block(-26,13,3,LEAVES:0)
Block(-26,13,4,LEAVES:0)
Block(-26,13,5,LEAVES:0)
Block(-26,13,6,LEAVES:0)
Block(-26,13,7,LEAVES:0)
Block(-26,14,-16,LEAVES:0)
Block(-26,14,-7,LEAVES:0)
Block(-26,14,-6,LEAVES:0)
Block(-26,14,-5,LEAVES:0)
Block(-26,14,-4,LEAVES:0)
Block(-26,14,5,LEAVES:0)
Block(-26,15,-8,LEAVES:0)
Block(-26,15,-7,LEAVES:0)
Block(-26,15,-6,LEAVES:0)
Block(-26,15,-5,LEAVES:0)
Block(-26,15,5,LEAVES:0)
Block(-25,-2,-7,STONE:0)
Block(-25,-2,-6,DIRT:0)
Block(-25,-2,-5,DIRT:0)
Block(-25,-2,-1,STONE:0)
Block(-25,-2,0,STONE:0)
Block(-25,-2,2,DIRT:0)
Block(-25,-1,-7,DIRT:0)
Block(-25,-1,-6,DIRT:0)
Block(-25,-1,-5,DIRT:0)
Block(-25,-1,-4,STONE:0)
Block(-25,-1,-1,DIRT:0)
Block(-25,-1,0,DIRT:0)
Block(-25,-1,1,DIRT:0)
Block(-25,-1,2,DIRT:0)
Block(-25,-1,3,DIRT:0)
Block(-25,0,-8,STONE:0)
Block(-25,0,-7,DIRT:0)
Block(-25,0,-6,DIRT:0)
Block(-25,0,-5,DIRT:0)
Block(-25,0,-4,STONE:0)
Block(-25,0,-3,STONE:0)
Block(-25,0,-1,DIRT:0)
Block(-25,0,0,STONE:0)
Block(-25,0,1,STONE:0)
Block(-25,0,2,STONE:0)
Block(-25,0,3,DIRT:0)
Block(-25,1,-9,STONE:0)
Block(-25,1,-8,STONE:0)
Block(-25,1,-7,STONE:0)
Block(-25,1,-6,DIRT:0)
Block(-25,1,-5,STONE:0)
Block(-25,1,-4,DIRT:0)
Block(-25,1,-3,DIRT:0)
Block(-25,1,-2,STONE:0)
Block(-25,1,-1,STONE:0)
Block(-25,1,0,STONE:0)
Block(-25,1,1,STONE:0)
Block(-25,1,2,STONE:0)
Block(-25,1,3,DIRT:0)
Block(-25,1,4,DIRT:0)
Block(-25,2,-9,DIRT:0)
Block(-25,2,-8,STONE:0)
Block(-25,2,-7,STONE:0)
Block(-25,2,-6,STONE:0)
Block(-25,2,-5,STONE:0)
Block(-25,2,-4,STONE:0)
Block(-25,2,-3,DIRT:0)
Block(-25,2,-2,DIRT:0)
Block(-25,2,-1,STONE:0)
Block(-25,2,0,DIRT:0)
Block(-25,2,1,STONE:0)
Block(-25,2,2,DIRT:0)
Block(-25,2,3,DIRT:0)
Block(-25,2,4,STONE:0)
Block(-25,3,-10,DIRT:0)
Block(-25,3,-9,STONE:0)
Block(-25,3,-8,STONE:0)
Block(-25,3,-7,STONE:0)
Block(-25,3,-6,STONE:0)
Block(-25,3,-5,DIRT:0)
Block(-25,3,-4,DIRT:0)
Block(-25,3,-3,DIRT:0)
Block(-25,3,-2,DIRT:0)
Block(-25,3,-1,DIRT:0)
Block(-25,3,0,STONE:0)
Block(-25,3,1,STONE:0)
Block(-25,3,2,DIRT:0)
Block(-25,3,3,STONE:0)
Block(-25,3,4,DIRT:0)
Block(-25,4,-15,STONE:0)
Block(-25,4,-14,STONE:0)
Block(-25,4,-13,STONE:0)
Block(-25,4,-12,STONE:0)
Block(-25,4,-11,STONE:0)
Block(-25,4,-10,STONE:0)
Block(-25,4,-9,STONE:0)
Block(-25,4,-8,STONE:0)
Block(-25,4,-7,STONE:0)
Block(-25,4,-6,STONE:0)
Block(-25,4,-5,STONE:0)
Block(-25,4,-4,STONE:0)
Block(-25,4,-3,STONE:0)
Block(-25,4,-2,STONE:0)
Block(-25,4,-1,STONE:0)
Block(-25,4,0,STONE:0)
Block(-25,4,1,STONE:0)
Block(-25,4,2,STONE:0)
Block(-25,4,3,STONE:0)
Block(-25,4,4,STONE:0)
Block(-25,4,5,DIRT:0)
Block(-25,5,-16,STONE:0)
Block(-25,5,-15,STONE:0)
Block(-25,5,-14,DIRT:0)
Block(-25,5,-13,DIRT:0)
Block(-25,5,-12,STONE:0)
Block(-25,5,-11,STONE:0)
Block(-25,5,-10,STONE:0)
Block(-25,5,-9,STONE:0)
Block(-25,5,-8,STONE:0)
Block(-25,5,-7,DIRT:0)
Block(-25,5,-6,STONE:0)
Block(-25,5,-5,DIRT:0)
Block(-25,5,-4,DIRT:0)
Block(-25,5,-3,STONE:0)
Block(-25,5,-2,STONE:0)
Block(-25,5,-1,STONE:0)
Block(-25,5,0,STONE:0)
Block(-25,5,1,STONE:0)
Block(-25,5,2,STONE:0)
Block(-25,5,3,STONE:0)
Block(-25,5,4,STONE:0)
Block(-25,5,5,DIRT:0)
Block(-25,6,-16,DIRT:0)
Block(-25,6,-15,STONE:0)
Block(-25,6,-14,DIRT:0)
Block(-25,6,-13,DIRT:0)
Block(-25,6,-12,STONE:0)
Block(-25,6,-11,DIRT:0)
Block(-25,6,-10,STONE:0)
Block(-25,6,-9,DIRT:0)
Block(-25,6,-8,STONE:0)
Block(-25,6,-7,STONE:0)
Block(-25,6,-6,STONE:0)
Block(-25,6,-5,DIRT:0)
Block(-25,6,-4,STONE:0)
Block(-25,6,-3,STONE:0)
Block(-25,6,-2,STONE:0)
Block(-25,6,-1,STONE:0)
Block(-25,6,0,DIRT:0)
Block(-25,6,1,DIRT:0)
Block(-25,6,2,STONE:0)
Block(-25,6,3,STONE:0)
Block(-25,6,4,DIRT:0)
Block(-25,6,5,DIRT:0)
Block(-25,6,6,DIRT:0)
Block(-25,7,-16,DIRT:0)
Block(-25,7,-15,STONE:0)
Block(-25,7,-14,STONE:0)
Block(-25,7,-13,GRASS:0)
Block(-25,7,-12,GRASS:0)
Block(-25,7,-11,DIRT:0)
Block(-25,7,-10,DIRT:0)
Block(-25,7,-9,STONE:0)
Block(-25,7,-8,STONE:0)
Block(-25,7,-7,STONE:0)
Block(-25,7,-6,STONE:0)
Block(-25,7,-5,STONE:0)
Block(-25,7,-4,DIRT:0)
Block(-25,7,-3,STONE:0)
Block(-25,7,-2,STONE:0)
Block(-25,7,-1,STONE:0)
Block(-25,7,0,STONE:0)
Block(-25,7,1,STONE:0)
Block(-25,7,2,DIRT:0)
Block(-25,7,3,STONE:0)
Block(-25,7,4,DIRT:0)
Block(-25,7,5,DIRT:0)
Block(-25,7,6,GRASS:0)
Block(-25,8,-16,LOG:0)
Block(-25,8,-13,DOUBLE_PLANT:2)
Block(-25,8,-11,GRASS:0)
Block(-25,8,-10,STONE:0)
Block(-25,8,-9,STONE:0)
Block(-25,8,-8,STONE:0)
Block(-25,8,-7,DIRT:0)
Block(-25,8,-6,STONE:0)
Block(-25,8,-5,STONE:0)
Block(-25,8,-4,DIRT:0)
Block(-25,8,-3,STONE:0)
Block(-25,8,-2,STONE:0)
Block(-25,8,-1,STONE:0)
Block(-25,8,0,DIRT:0)
Block(-25,8,1,STONE:0)
Block(-25,8,2,STONE:0)
Block(-25,8,3,STONE:0)
Block(-25,8,4,DIRT:0)
Block(-25,8,5,DIRT:0)
Block(-25,8,6,YELLOW_FLOWER:0)
Block(-25,9,-16,LOG:0)
Block(-25,9,-13,DOUBLE_PLANT:10)
Block(-25,9,-10,GRASS:0)
Block(-25,9,-9,STONE:0)
Block(-25,9,-8,GRASS:0)
Block(-25,9,-7,GRASS:0)
Block(-25,9,-6,GRASS:0)
Block(-25,9,-5,GRASS:0)
Block(-25,9,-4,GRASS:0)
Block(-25,9,-3,GRASS:0)
Block(-25,9,-2,GRASS:0)
Block(-25,9,-1,GRASS:0)
Block(-25,9,0,GRASS:0)
Block(-25,9,1,STONE:0)
Block(-25,9,2,STONE:0)
Block(-25,9,3,GRASS:0)
Block(-25,9,4,GRASS:0)
Block(-25,9,5,LOG:0)
Block(-25,10,-18,LEAVES:0)
Block(-25,10,-17,LEAVES:0)
Block(-25,10,-16,LOG:0)
Block(-25,10,-15,LEAVES:0)
Block(-25,10,-14,LEAVES:0)
Block(-25,10,-6,RED_ROSE:0)
Block(-25,10,-5,YELLOW_FLOWER:0)
Block(-25,10,-4,LONG_GRASS:1)
Block(-25,10,-2,LONG_GRASS:1)
Block(-25,10,1,GRASS:0)
Block(-25,10,2,STONE:0)
Block(-25,10,3,LONG_GRASS:1)
Block(-25,10,5,LOG:0)
Block(-25,11,-18,LEAVES:0)
Block(-25,11,-17,LEAVES:0)
Block(-25,11,-16,LOG:0)
Block(-25,11,-15,LEAVES:0)
Block(-25,11,-14,LEAVES:0)
Block(-25,11,3,LEAVES:0)
Block(-25,11,4,LEAVES:0)
Block(-25,11,5,LOG:0)
Block(-25,11,6,LEAVES:0)
Block(-25,11,7,LEAVES:0)
Block(-25,12,-18,LEAVES:0)
Block(-25,12,-17,LEAVES:0)
Block(-25,12,-16,LOG:0)
Block(-25,12,-15,LEAVES:0)
Block(-25,12,-14,LEAVES:0)
Block(-25,12,3,LEAVES:0)
Block(-25,12,4,LEAVES:0)
Block(-25,12,5,LOG:0)
Block(-25,12,6,LEAVES:0)
Block(-25,12,7,LEAVES:0)
Block(-25,13,-17,LEAVES:0)
Block(-25,13,-16,LOG:0)
Block(-25,13,-15,LEAVES:0)
Block(-25,13,-8,LEAVES:0)
Block(-25,13,-7,LEAVES:0)
Block(-25,13,-6,LEAVES:0)
Block(-25,13,-5,LEAVES:0)
Block(-25,13,-4,LEAVES:0)
Block(-25,13,3,LEAVES:0)
Block(-25,13,4,LEAVES:0)
Block(-25,13,5,LOG:0)
Block(-25,13,6,LEAVES:0)
Block(-25,13,7,LEAVES:0)
Block(-25,14,-17,LEAVES:0)
Block(-25,14,-16,LEAVES:0)
Block(-25,14,-15,LEAVES:0)
Block(-25,14,-8,LEAVES:0)
Block(-25,14,-7,LEAVES:0)
Block(-25,14,-6,LEAVES:0)
Block(-25,14,-5,LEAVES:0)
Block(-25,14,-4,LEAVES:0)
Block(-25,14,4,LEAVES:0)
Block(-25,14,5,LOG:0)
Block(-25,14,6,LEAVES:0)
Block(-25,15,-8,LEAVES:0)
Block(-25,15,-7,LEAVES:0)
Block(-25,15,-6,LEAVES:0)
Block(-25,15,-5,LEAVES:0)
Block(-25,15,-4,LEAVES:0)
Block(-25,15,4,LEAVES:0)
Block(-25,15,5,LEAVES:0)
Block(-25,15,6,LEAVES:0)
Block(-25,16,-6,LEAVES:0)
Block(-25,17,-6,LEAVES:0)
Block(-24,-6,-5,STONE:0)
Block(-24,-5,-7,STONE:0)
Block(-24,-5,-6,STONE:0)
Block(-24,-5,-5,STONE:0)
Block(-24,-5,-4,STONE:0)
Block(-24,-4,-7,DIRT:0)
Block(-24,-4,-6,DIRT:0)
Block(-24,-4,-5,STONE:0)
Block(-24,-4,-4,DIRT:0)
Block(-24,-4,-2,STONE:0)
Block(-24,-3,-8,STONE:0)
Block(-24,-3,-7,DIRT:0)
Block(-24,-3,-6,STONE:0)
Block(-24,-3,-5,DIRT:0)
Block(-24,-3,-4,DIRT:0)
Block(-24,-3,-3,DIRT:0)
Block(-24,-3,-2,DIRT:0)
Block(-24,-3,-1,STONE:0)
Block(-24,-3,0,DIRT:0)
Block(-24,-3,1,DIRT:0)
Block(-24,-3,2,STONE:0)
Block(-24,-2,-8,DIRT:0)
Block(-24,-2,-7,DIRT:0)
Block(-24,-2,-6,DIRT:0)
Block(-24,-2,-5,STONE:0)
Block(-24,-2,-4,DIRT:0)
Block(-24,-2,-3,STONE:0)
Block(-24,-2,-2,DIRT:0)
Block(-24,-2,-1,DIRT:0)
Block(-24,-2,0,DIRT:0)
Block(-24,-2,1,STONE:0)
Block(-24,-2,2,DIRT:0)
Block(-24,-2,3,DIRT:0)
Block(-24,-1,-9,STONE:0)
Block(-24,-1,-8,DIRT:0)
Block(-24,-1,-7,DIRT:0)
Block(-24,-1,-6,DIRT:0)
Block(-24,-1,-5,STONE:0)
Block(-24,-1,-4,STONE:0)
Block(-24,-1,-3,DIRT:0)
Block(-24,-1,-2,STONE:0)
Block(-24,-1,-1,DIRT:0)
Block(-24,-1,0,STONE:0)
Block(-24,-1,1,DIRT:0)
Block(-24,-1,2,STONE:0)
Block(-24,-1,3,DIRT:0)
Block(-24,-1,4,DIRT:0)
Block(-24,0,-10,DIRT:0)
Block(-24,0,-9,STONE:0)
Block(-24,0,-8,STONE:0)
Block(-24,0,-7,DIRT:0)
Block(-24,0,-6,STONE:0)
Block(-24,0,-5,STONE:0)
Block(-24,0,-4,STONE:0)
Block(-24,0,-3,DIRT:0)
Block(-24,0,-2,DIRT:0)
Block(-24,0,-1,STONE:0)
Block(-24,0,0,DIRT:0)
Block(-24,0,1,STONE:0)
Block(-24,0,2,DIRT:0)
Block(-24,0,3,STONE:0)
Block(-24,0,4,DIRT:0)
Block(-24,1,-10,STONE:0)
Block(-24,1,-9,DIRT:0)
Block(-24,1,-8,STONE:0)
Block(-24,1,-7,DIRT:0)
Block(-24,1,-6,STONE:0)
Block(-24,1,-5,DIRT:0)
Block(-24,1,-4,DIRT:0)
Block(-24,1,-3,STONE:0)
Block(-24,1,-2,STONE:0)
Block(-24,1,-1,DIRT:0)
Block(-24,1,0,DIRT:0)
Block(-24,1,1,DIRT:0)
Block(-24,1,2,DIRT:0)
Block(-24,1,3,STONE:0)
Block(-24,1,4,STONE:0)
Block(-24,2,-11,STONE:0)
Block(-24,2,-10,DIRT:0)
Block(-24,2,-9,DIRT:0)
Block(-24,2,-8,STONE:0)
Block(-24,2,-7,STONE:0)
Block(-24,2,-6,DIRT:0)
Block(-24,2,-5,STONE:0)
Block(-24,2,-4,STONE:0)
Block(-24,2,-3,STONE:0)
Block(-24,2,-2,STONE:0)
Block(-24,2,-1,DIRT:0)
Block(-24,2,0,DIRT:0)
Block(-24,2,1,DIRT:0)
Block(-24,2,2,DIRT:0)
Block(-24,2,3,DIRT:0)
Block(-24,2,4,STONE:0)
Block(-24,2,5,DIRT:0)
Block(-24,3,-13,DIRT:0)
Block(-24,3,-12,STONE:0)
Block(-24,3,-11,STONE:0)
Block(-24,3,-10,STONE:0)
Block(-24,3,-9,STONE:0)
Block(-24,3,-8,STONE:0)
Block(-24,3,-7,STONE:0)
Block(-24,3,-6,DIRT:0)
Block(-24,3,-5,STONE:0)
Block(-24,3,-4,DIRT:0)
Block(-24,3,-3,STONE:0)
Block(-24,3,-2,STONE:0)
Block(-24,3,-1,DIRT:0)
Block(-24,3,0,STONE:0)
Block(-24,3,1,DIRT:0)
Block(-24,3,2,DIRT:0)
Block(-24,3,3,DIRT:0)
Block(-24,3,4,DIRT:0)
Block(-24,3,5,DIRT:0)
Block(-24,4,-15,STONE:0)
Block(-24,4,-14,STATIONARY_WATER:0)
Block(-24,4,-13,STONE:0)
Block(-24,4,-12,STONE:0)
Block(-24,4,-11,DIRT:0)
Block(-24,4,-10,STONE:0)
Block(-24,4,-9,STONE:0)
Block(-24,4,-8,STONE:0)
Block(-24,4,-7,STONE:0)
Block(-24,4,-6,STONE:0)
Block(-24,4,-5,STONE:0)
Block(-24,4,-4,STONE:0)
Block(-24,4,-3,DIRT:0)
Block(-24,4,-2,DIRT:0)
Block(-24,4,-1,STONE:0)
Block(-24,4,0,DIRT:0)
Block(-24,4,1,STONE:0)
Block(-24,4,2,STONE:0)
Block(-24,4,3,STONE:0)
Block(-24,4,4,STONE:0)
Block(-24,4,5,STONE:0)
Block(-24,5,-17,STONE:0)
Block(-24,5,-16,STONE:0)
Block(-24,5,-15,STONE:0)
Block(-24,5,-14,STONE:0)
Block(-24,5,-13,STONE:0)
Block(-24,5,-12,STONE:0)
Block(-24,5,-11,DIRT:0)
Block(-24,5,-10,DIRT:0)
Block(-24,5,-9,STONE:0)
Block(-24,5,-8,DIRT:0)
Block(-24,5,-7,STONE:0)
Block(-24,5,-6,STONE:0)
Block(-24,5,-5,STONE:0)
Block(-24,5,-4,STONE:0)
Block(-24,5,-3,DIRT:0)
Block(-24,5,-2,STONE:0)
Block(-24,5,-1,STONE:0)
Block(-24,5,0,STONE:0)
Block(-24,5,1,STONE:0)
Block(-24,5,2,STONE:0)
Block(-24,5,3,STONE:0)
Block(-24,5,4,STONE:0)
Block(-24,5,5,STONE:0)
Block(-24,5,6,DIRT:0)
Block(-24,6,-17,GRASS:0)
Block(-24,6,-16,STONE:0)
Block(-24,6,-15,STONE:0)
Block(-24,6,-14,STONE:0)
Block(-24,6,-13,DIRT:0)
Block(-24,6,-12,DIRT:0)
Block(-24,6,-11,DIRT:0)
Block(-24,6,-10,STONE:0)
Block(-24,6,-9,STONE:0)
Block(-24,6,-8,DIRT:0)
Block(-24,6,-7,STONE:0)
Block(-24,6,-6,STONE:0)
Block(-24,6,-5,STONE:0)
Block(-24,6,-4,STONE:0)
Block(-24,6,-3,STONE:0)
Block(-24,6,-2,STONE:0)
Block(-24,6,-1,STONE:0)
Block(-24,6,0,STONE:0)
Block(-24,6,1,STONE:0)
Block(-24,6,2,STONE:0)
Block(-24,6,3,STONE:0)
Block(-24,6,4,STONE:0)
Block(-24,6,5,DIRT:0)
Block(-24,6,6,DIRT:0)
Block(-24,6,7,DIRT:0)
Block(-24,7,-16,GRASS:0)
Block(-24,7,-15,GRASS:0)
Block(-24,7,-14,GRASS:0)
Block(-24,7,-13,GRASS:0)
Block(-24,7,-12,STONE:0)
Block(-24,7,-11,STONE:0)
Block(-24,7,-10,STONE:0)
Block(-24,7,-9,DIRT:0)
Block(-24,7,-8,DIRT:0)
Block(-24,7,-7,STONE:0)
Block(-24,7,-6,STONE:0)
Block(-24,7,-5,STONE:0)
Block(-24,7,-4,STONE:0)
Block(-24,7,-3,DIRT:0)
Block(-24,7,-2,STONE:0)
Block(-24,7,-1,STONE:0)
Block(-24,7,0,STONE:0)
Block(-24,7,1,STONE:0)
Block(-24,7,2,STONE:0)
Block(-24,7,3,STONE:0)
Block(-24,7,4,STONE:0)
Block(-24,7,5,STONE:0)
Block(-24,7,6,DIRT:0)
Block(-24,7,7,DIRT:0)
Block(-24,8,-16,LONG_GRASS:1)
Block(-24,8,-15,LONG_GRASS:1)
Block(-24,8,-14,LONG_GRASS:1)
Block(-24,8,-12,GRASS:0)
Block(-24,8,-11,STONE:0)
Block(-24,8,-10,STONE:0)
Block(-24,8,-9,STONE:0)
Block(-24,8,-8,STONE:0)
Block(-24,8,-7,DIRT:0)
Block(-24,8,-6,DIRT:0)
Block(-24,8,-5,STONE:0)
Block(-24,8,-4,STONE:0)
Block(-24,8,-3,STONE:0)
Block(-24,8,-2,DIRT:0)
Block(-24,8,-1,STONE:0)
Block(-24,8,0,DIRT:0)
Block(-24,8,1,STONE:0)
Block(-24,8,2,STONE:0)
Block(-24,8,3,STONE:0)
Block(-24,8,4,STONE:0)
Block(-24,8,5,STONE:0)
Block(-24,8,6,DIRT:0)
Block(-24,8,7,GRASS:0)
Block(-24,9,-11,GRASS:0)
Block(-24,9,-10,STONE:0)
Block(-24,9,-9,STONE:0)
Block(-24,9,-8,DIRT:0)
Block(-24,9,-7,STONE:0)
Block(-24,9,-6,STONE:0)
Block(-24,9,-5,DIRT:0)
Block(-24,9,-4,STONE:0)
Block(-24,9,-3,STONE:0)
Block(-24,9,-2,STONE:0)
Block(-24,9,-1,STONE:0)
Block(-24,9,0,DIRT:0)
Block(-24,9,1,STONE:0)
Block(-24,9,2,DIRT:0)
Block(-24,9,3,DIRT:0)
Block(-24,9,4,STONE:0)
Block(-24,9,5,GRASS:0)
Block(-24,9,6,GRASS:0)
Block(-24,10,-18,LEAVES:0)
Block(-24,10,-17,LEAVES:0)
Block(-24,10,-16,LEAVES:0)
Block(-24,10,-15,LEAVES:0)
Block(-24,10,-14,LEAVES:0)
Block(-24,10,-10,GRASS:0)
Block(-24,10,-9,GRASS:0)
Block(-24,10,-8,STONE:0)
Block(-24,10,-7,STONE:0)
Block(-24,10,-6,STONE:0)
Block(-24,10,-5,GRASS:0)
Block(-24,10,-4,GRASS:0)
Block(-24,10,-3,GRASS:0)
Block(-24,10,-2,GRASS:0)
Block(-24,10,-1,GRASS:0)
Block(-24,10,0,GRASS:0)
Block(-24,10,1,STONE:0)
Block(-24,10,2,STONE:0)
Block(-24,10,3,STONE:0)
Block(-24,10,4,GRASS:0)
Block(-24,11,-18,LEAVES:0)
Block(-24,11,-17,LEAVES:0)
Block(-24,11,-16,LEAVES:0)
Block(-24,11,-15,LEAVES:0)
Block(-24,11,-14,LEAVES:0)
Block(-24,11,-10,LONG_GRASS:1)
Block(-24,11,-9,DOUBLE_PLANT:2)
Block(-24,11,-8,GRASS:0)
Block(-24,11,-7,GRASS:0)
Block(-24,11,-6,DIRT:0)
Block(-24,11,-5,LONG_GRASS:1)
Block(-24,11,-4,LONG_GRASS:1)
Block(-24,11,-3,LONG_GRASS:1)
Block(-24,11,-2,LONG_GRASS:1)
Block(-24,11,1,GRASS:0)
Block(-24,11,2,GRASS:0)
Block(-24,11,3,GRASS:0)
Block(-24,11,4,LEAVES:0)
Block(-24,11,5,LEAVES:0)
Block(-24,11,6,LEAVES:0)
Block(-24,11,7,LEAVES:0)
Block(-24,12,-18,LEAVES:0)
Block(-24,12,-17,LEAVES:0)
Block(-24,12,-16,LEAVES:0)
Block(-24,12,-15,LEAVES:0)
Block(-24,12,-14,LEAVES:0)
Block(-24,12,-9,DOUBLE_PLANT:10)
Block(-24,12,-8,LONG_GRASS:1)
Block(-24,12,-6,LOG:0)
Block(-24,12,1,LONG_GRASS:1)
Block(-24,12,2,LONG_GRASS:1)
Block(-24,12,3,LEAVES:0)
Block(-24,12,4,LEAVES:0)
Block(-24,12,5,LEAVES:0)
Block(-24,12,6,LEAVES:0)
Block(-24,12,7,LEAVES:0)
Block(-24,13,-17,LEAVES:0)
Block(-24,13,-16,LEAVES:0)
Block(-24,13,-8,LEAVES:0)
Block(-24,13,-7,LEAVES:0)
Block(-24,13,-6,LOG:0)
Block(-24,13,-5,LEAVES:0)
Block(-24,13,-4,LEAVES:0)
Block(-24,13,3,LEAVES:0)
Block(-24,13,4,LEAVES:0)
Block(-24,13,5,LEAVES:0)
Block(-24,13,6,LEAVES:0)
Block(-24,13,7,LEAVES:0)
Block(-24,14,-16,LEAVES:0)
Block(-24,14,-8,LEAVES:0)
Block(-24,14,-7,LEAVES:0)
Block(-24,14,-6,LOG:0)
Block(-24,14,-5,LEAVES:0)
Block(-24,14,-4,LEAVES:0)
Block(-24,14,5,LEAVES:0)
Block(-24,15,-8,LEAVES:0)
Block(-24,15,-7,LEAVES:0)
Block(-24,15,-6,LOG:0)
Block(-24,15,-5,LEAVES:0)
Block(-24,15,-4,LEAVES:0)
Block(-24,15,5,LEAVES:0)
Block(-24,16,-7,LEAVES:0)
Block(-24,16,-6,LOG:0)
Block(-24,16,-5,LEAVES:0)
Block(-24,17,-7,LEAVES:0)
Block(-24,17,-6,LEAVES:0)
Block(-24,17,-5,LEAVES:0)
Block(-23,-8,-7,STONE:0)
Block(-23,-8,-6,DIRT:0)
Block(-23,-8,-5,STONE:0)
Block(-23,-7,-8,DIRT:0)
Block(-23,-7,-7,STONE:0)
Block(-23,-7,-6,STONE:0)
Block(-23,-7,-5,STONE:0)
Block(-23,-7,-4,DIRT:0)
Block(-23,-6,-8,STONE:0)
Block(-23,-6,-7,STONE:0)
Block(-23,-6,-6,STONE:0)
Block(-23,-6,-5,STONE:0)
Block(-23,-6,-4,STONE:0)
Block(-23,-6,-2,STONE:0)
Block(-23,-5,-8,STONE:0)
Block(-23,-5,-7,STONE:0)
Block(-23,-5,-6,DIRT:0)
Block(-23,-5,-5,STONE:0)
Block(-23,-5,-4,STONE:0)
Block(-23,-5,-3,DIRT:0)
Block(-23,-5,-2,STONE:0)
Block(-23,-4,-9,STONE:0)
Block(-23,-4,-8,STONE:0)
Block(-23,-4,-7,STONE:0)
Block(-23,-4,-6,DIRT:0)
Block(-23,-4,-5,STONE:0)
Block(-23,-4,-4,STONE:0)
Block(-23,-4,-3,STONE:0)
Block(-23,-4,-2,STONE:0)
Block(-23,-3,-10,DIRT:0)
Block(-23,-3,-9,DIRT:0)
Block(-23,-3,-8,DIRT:0)
Block(-23,-3,-7,DIRT:0)
Block(-23,-3,-6,DIRT:0)
Block(-23,-3,-5,STONE:0)
Block(-23,-3,-4,STONE:0)
Block(-23,-3,-3,DIRT:0)
Block(-23,-3,-2,DIRT:0)
Block(-23,-3,-1,DIRT:0)
Block(-23,-3,0,DIRT:0)
Block(-23,-3,1,STONE:0)
Block(-23,-3,2,STONE:0)
Block(-23,-3,3,DIRT:0)
Block(-23,-2,-10,DIRT:0)
Block(-23,-2,-9,DIRT:0)
Block(-23,-2,-8,DIRT:0)
Block(-23,-2,-7,STONE:0)
Block(-23,-2,-6,STONE:0)
Block(-23,-2,-5,STONE:0)
Block(-23,-2,-4,STONE:0)
Block(-23,-2,-3,STONE:0)
Block(-23,-2,-2,STONE:0)
Block(-23,-2,-1,DIRT:0)
Block(-23,-2,0,STONE:0)
Block(-23,-2,1,DIRT:0)
Block(-23,-2,2,STONE:0)
Block(-23,-2,3,STONE:0)
Block(-23,-2,4,DIRT:0)
Block(-23,-1,-10,DIRT:0)
Block(-23,-1,-9,DIRT:0)
Block(-23,-1,-8,DIRT:0)
Block(-23,-1,-7,DIRT:0)
Block(-23,-1,-6,STONE:0)
Block(-23,-1,-5,DIRT:0)
Block(-23,-1,-4,STONE:0)
Block(-23,-1,-3,STONE:0)
Block(-23,-1,-2,DIRT:0)
Block(-23,-1,-1,DIRT:0)
Block(-23,-1,0,STONE:0)
Block(-23,-1,1,STONE:0)
Block(-23,-1,2,DIRT:0)
Block(-23,-1,3,STONE:0)
Block(-23,-1,4,DIRT:0)
Block(-23,0,-11,STONE:0)
Block(-23,0,-10,DIRT:0)
Block(-23,0,-9,STONE:0)
Block(-23,0,-8,DIRT:0)
Block(-23,0,-7,STONE:0)
Block(-23,0,-6,STONE:0)
Block(-23,0,-5,STONE:0)
Block(-23,0,-4,STONE:0)
Block(-23,0,-3,DIRT:0)
Block(-23,0,-2,STONE:0)
Block(-23,0,-1,STONE:0)
Block(-23,0,0,STONE:0)
Block(-23,0,1,STONE:0)
Block(-23,0,2,STONE:0)
Block(-23,0,3,DIRT:0)
Block(-23,0,4,STONE:0)
Block(-23,0,5,STONE:0)
Block(-23,1,-13,DIRT:0)
Block(-23,1,-12,STONE:0)
Block(-23,1,-11,STONE:0)
Block(-23,1,-10,DIRT:0)
Block(-23,1,-9,DIRT:0)
Block(-23,1,-8,STONE:0)
Block(-23,1,-7,STONE:0)
Block(-23,1,-6,DIRT:0)
Block(-23,1,-5,DIRT:0)
Block(-23,1,-4,STONE:0)
Block(-23,1,-3,STONE:0)
Block(-23,1,-2,STONE:0)
Block(-23,1,-1,DIRT:0)
Block(-23,1,0,DIRT:0)
Block(-23,1,1,DIRT:0)
Block(-23,1,2,STONE:0)
Block(-23,1,3,STONE:0)
Block(-23,1,4,DIRT:0)
Block(-23,1,5,DIRT:0)
Block(-23,1,6,STONE:0)
Block(-23,2,-14,DIRT:0)
Block(-23,2,-13,STONE:0)
Block(-23,2,-12,DIRT:0)
Block(-23,2,-11,STONE:0)
Block(-23,2,-10,DIRT:0)
Block(-23,2,-9,STONE:0)
Block(-23,2,-8,STONE:0)
Block(-23,2,-7,STONE:0)
Block(-23,2,-6,DIRT:0)
Block(-23,2,-5,DIRT:0)
Block(-23,2,-4,DIRT:0)
Block(-23,2,-3,DIRT:0)
Block(-23,2,-2,DIRT:0)
Block(-23,2,-1,STONE:0)
Block(-23,2,0,DIRT:0)
Block(-23,2,1,STONE:0)
Block(-23,2,2,STONE:0)
Block(-23,2,3,STONE:0)
Block(-23,2,4,DIRT:0)
Block(-23,2,5,STONE:0)
Block(-23,2,6,DIRT:0)
Block(-23,3,-14,DIRT:0)
Block(-23,3,-13,DIRT:0)
Block(-23,3,-12,DIRT:0)
Block(-23,3,-11,STONE:0)
Block(-23,3,-10,STONE:0)
Block(-23,3,-9,DIRT:0)
Block(-23,3,-8,DIRT:0)
Block(-23,3,-7,STONE:0)
Block(-23,3,-6,STONE:0)
Block(-23,3,-5,STONE:0)
Block(-23,3,-4,DIRT:0)
Block(-23,3,-3,DIRT:0)
Block(-23,3,-2,DIRT:0)
Block(-23,3,-1,STONE:0)
Block(-23,3,0,STONE:0)
Block(-23,3,1,DIRT:0)
Block(-23,3,2,STONE:0)
Block(-23,3,3,STONE:0)
Block(-23,3,4,STONE:0)
Block(-23,3,5,STONE:0)
Block(-23,3,6,STONE:0)
Block(-23,4,-17,STONE:0)
Block(-23,4,-16,STONE:0)
Block(-23,4,-15,STONE:0)
Block(-23,4,-14,STONE:0)
Block(-23,4,-13,STONE:0)
Block(-23,4,-12,STONE:0)
Block(-23,4,-11,STONE:0)
Block(-23,4,-10,DIRT:0)
Block(-23,4,-9,STONE:0)
Block(-23,4,-8,STONE:0)
Block(-23,4,-7,STONE:0)
Block(-23,4,-6,DIRT:0)
Block(-23,4,-5,STONE:0)
Block(-23,4,-4,STONE:0)
Block(-23,4,-3,STONE:0)
Block(-23,4,-2,STONE:0)
Block(-23,4,-1,DIRT:0)
Block(-23,4,0,STONE:0)
Block(-23,4,1,DIRT:0)
Block(-23,4,2,DIRT:0)
Block(-23,4,3,STONE:0)
Block(-23,4,4,STONE:0)
Block(-23,4,5,STONE:0)
Block(-23,4,6,STONE:0)
Block(-23,5,-17,STONE:0)
Block(-23,5,-16,STONE:0)
Block(-23,5,-15,DIRT:0)
Block(-23,5,-14,STONE:0)
Block(-23,5,-13,STONE:0)
Block(-23,5,-12,STONE:0)
Block(-23,5,-11,STONE:0)
Block(-23,5,-10,DIRT:0)
Block(-23,5,-9,STONE:0)
Block(-23,5,-8,DIRT:0)
Block(-23,5,-7,STONE:0)
Block(-23,5,-6,STONE:0)
Block(-23,5,-5,STONE:0)
Block(-23,5,-4,STONE:0)
Block(-23,5,-3,STONE:0)
Block(-23,5,-2,STONE:0)
Block(-23,5,-1,STONE:0)
Block(-23,5,0,STONE:0)
Block(-23,5,1,STONE:0)
Block(-23,5,2,STONE:0)
Block(-23,5,3,STONE:0)
Block(-23,5,4,STONE:0)
Block(-23,5,5,STONE:0)
Block(-23,5,6,STONE:0)
Block(-23,5,7,DIRT:0)
Block(-23,6,-18,DIRT:0)
Block(-23,6,-17,DIRT:0)
Block(-23,6,-16,STONE:0)
Block(-23,6,-15,STONE:0)
Block(-23,6,-14,STONE:0)
Block(-23,6,-13,DIRT:0)
Block(-23,6,-12,STONE:0)
Block(-23,6,-11,STONE:0)
Block(-23,6,-10,STONE:0)
Block(-23,6,-9,STONE:0)
Block(-23,6,-8,STONE:0)
Block(-23,6,-7,STONE:0)
Block(-23,6,-6,STONE:0)
Block(-23,6,-5,STONE:0)
Block(-23,6,-4,STONE:0)
Block(-23,6,-3,STONE:0)
Block(-23,6,-2,STONE:0)
Block(-23,6,-1,STONE:0)
Block(-23,6,0,STONE:0)
Block(-23,6,1,STONE:0)
Block(-23,6,2,STONE:0)
Block(-23,6,3,STONE:0)
Block(-23,6,4,STONE:0)
Block(-23,6,5,STONE:0)
Block(-23,6,6,STONE:0)
Block(-23,6,7,DIRT:0)
Block(-23,7,-19,STONE:0)
Block(-23,7,-18,GRASS:0)
Block(-23,7,-17,GRASS:0)
Block(-23,7,-16,GRASS:0)
Block(-23,7,-15,DIRT:0)
Block(-23,7,-14,DIRT:0)
Block(-23,7,-13,STONE:0)
Block(-23,7,-12,STONE:0)
Block(-23,7,-11,DIRT:0)
Block(-23,7,-10,STONE:0)
Block(-23,7,-9,DIRT:0)
Block(-23,7,-8,STONE:0)
Block(-23,7,-7,DIRT:0)
Block(-23,7,-6,STONE:0)
Block(-23,7,-5,STONE:0)
Block(-23,7,-4,STONE:0)
Block(-23,7,-3,STONE:0)
Block(-23,7,-2,STONE:0)
Block(-23,7,-1,STONE:0)
Block(-23,7,0,STONE:0)
Block(-23,7,1,STONE:0)
Block(-23,7,2,STONE:0)
Block(-23,7,3,STONE:0)
Block(-23,7,4,STONE:0)
Block(-23,7,5,STONE:0)
Block(-23,7,6,DIRT:0)
Block(-23,7,7,STONE:0)
Block(-23,8,-19,GRASS:0)
Block(-23,8,-18,LONG_GRASS:1)
Block(-23,8,-17,LONG_GRASS:1)
Block(-23,8,-16,LONG_GRASS:1)
Block(-23,8,-15,STONE:0)
Block(-23,8,-14,GRASS:0)
Block(-23,8,-13,GRASS:0)
Block(-23,8,-12,STONE:0)
Block(-23,8,-11,STONE:0)
Block(-23,8,-10,DIRT:0)
Block(-23,8,-9,STONE:0)
Block(-23,8,-8,STONE:0)
Block(-23,8,-7,STONE:0)
Block(-23,8,-6,STONE:0)
Block(-23,8,-5,STONE:0)
Block(-23,8,-4,STONE:0)
Block(-23,8,-3,STONE:0)
Block(-23,8,-2,STONE:0)
Block(-23,8,-1,DIRT:0)
Block(-23,8,0,STONE:0)
Block(-23,8,1,STONE:0)
Block(-23,8,2,STONE:0)
Block(-23,8,3,DIRT:0)
Block(-23,8,4,STONE:0)
Block(-23,8,5,DIRT:0)
Block(-23,8,6,STONE:0)
Block(-23,8,7,STONE:0)
Block(-23,9,-12,GRASS:0)
Block(-23,9,-11,STONE:0)
Block(-23,9,-10,STONE:0)
Block(-23,9,-9,STONE:0)
Block(-23,9,-8,STONE:0)
Block(-23,9,-7,DIRT:0)
Block(-23,9,-6,DIRT:0)
Block(-23,9,-5,STONE:0)
Block(-23,9,-4,STONE:0)
Block(-23,9,-3,STONE:0)
Block(-23,9,-2,STONE:0)
Block(-23,9,-1,STONE:0)
Block(-23,9,0,DIRT:0)
Block(-23,9,1,STONE:0)
Block(-23,9,2,STONE:0)
Block(-23,9,3,STONE:0)
Block(-23,9,4,DIRT:0)
Block(-23,9,5,DIRT:0)
Block(-23,9,6,DIRT:0)
Block(-23,9,7,GRASS:0)
Block(-23,10,-17,LEAVES:0)
Block(-23,10,-16,LEAVES:0)
Block(-23,10,-15,LEAVES:0)
Block(-23,10,-12,LONG_GRASS:1)
Block(-23,10,-11,GRASS:0)
Block(-23,10,-10,STONE:0)
Block(-23,10,-9,STONE:0)
Block(-23,10,-8,DIRT:0)
Block(-23,10,-7,DIRT:0)
Block(-23,10,-6,DIRT:0)
Block(-23,10,-5,DIRT:0)
Block(-23,10,-4,STONE:0)
Block(-23,10,-3,DIRT:0)
Block(-23,10,-2,STONE:0)
Block(-23,10,-1,STONE:0)
Block(-23,10,0,STONE:0)
Block(-23,10,1,STONE:0)
Block(-23,10,2,STONE:0)
Block(-23,10,3,STONE:0)
Block(-23,10,4,DIRT:0)
Block(-23,10,5,STONE:0)
Block(-23,10,6,STONE:0)
Block(-23,11,-18,LEAVES:0)
Block(-23,11,-17,LEAVES:0)
Block(-23,11,-16,LEAVES:0)
Block(-23,11,-15,LEAVES:0)
Block(-23,11,-14,LEAVES:0)
Block(-23,11,-11,LONG_GRASS:1)
Block(-23,11,-10,GRASS:0)
Block(-23,11,-9,STONE:0)
Block(-23,11,-8,STONE:0)
Block(-23,11,-7,STONE:0)
Block(-23,11,-6,STONE:0)
Block(-23,11,-5,DIRT:0)
Block(-23,11,-4,GRASS:0)
Block(-23,11,-3,GRASS:0)
Block(-23,11,-2,GRASS:0)
Block(-23,11,-1,GRASS:0)
Block(-23,11,0,GRASS:0)
Block(-23,11,1,GRASS:0)
Block(-23,11,2,STATIONARY_WATER:0)
Block(-23,11,3,GRASS:0)
Block(-23,11,4,GRASS:0)
Block(-23,11,5,GRASS:0)
Block(-23,11,6,LEAVES:0)
Block(-23,11,7,LEAVES:0)
Block(-23,12,-17,LEAVES:0)
Block(-23,12,-16,LEAVES:0)
Block(-23,12,-15,LEAVES:0)
Block(-23,12,-14,LEAVES:0)
Block(-23,12,-9,GRASS:0)
Block(-23,12,-8,GRASS:0)
Block(-23,12,-7,GRASS:0)
Block(-23,12,-6,GRASS:0)
Block(-23,12,-5,GRASS:0)
Block(-23,12,-1,LONG_GRASS:1)
Block(-23,12,1,LONG_GRASS:1)
Block(-23,12,3,LEAVES:0)
Block(-23,12,4,LEAVES:0)
Block(-23,12,5,LEAVES:0)
Block(-23,12,6,LEAVES:0)
Block(-23,12,7,LEAVES:0)
Block(-23,13,-8,LEAVES:0)
Block(-23,13,-7,LEAVES:0)
Block(-23,13,-6,LEAVES:0)
Block(-23,13,-5,LEAVES:0)
Block(-23,13,-4,LEAVES:0)
Block(-23,13,4,LEAVES:0)
Block(-23,13,5,LEAVES:0)
Block(-23,13,6,LEAVES:0)
Block(-23,14,-8,LEAVES:0)
Block(-23,14,-7,LEAVES:0)
Block(-23,14,-6,LEAVES:0)
Block(-23,14,-5,LEAVES:0)
Block(-23,14,-4,LEAVES:0)
Block(-23,15,-8,LEAVES:0)
Block(-23,15,-7,LEAVES:0)
Block(-23,15,-6,LEAVES:0)
Block(-23,15,-5,LEAVES:0)
Block(-23,15,-4,LEAVES:0)
Block(-23,16,-6,LEAVES:0)
Block(-23,17,-6,LEAVES:0)
Block(-22,-10,-7,DIRT:0)
Block(-22,-9,-7,DIRT:0)
Block(-22,-9,-6,STONE:0)
Block(-22,-9,-5,DIRT:0)
Block(-22,-9,-4,STONE:0)
Block(-22,-8,-9,STONE:0)
Block(-22,-8,-8,DIRT:0)
Block(-22,-8,-7,STONE:0)
Block(-22,-8,-6,STONE:0)
Block(-22,-8,-5,STONE:0)
Block(-22,-8,-4,STONE:0)
Block(-22,-8,-1,STONE:0)
Block(-22,-7,-10,STONE:0)
Block(-22,-7,-9,STONE:0)
Block(-22,-7,-8,STONE:0)
Block(-22,-7,-7,DIRT:0)
Block(-22,-7,-6,STONE:0)
Block(-22,-7,-5,STONE:0)
Block(-22,-7,-4,STONE:0)
Block(-22,-7,-3,STONE:0)
Block(-22,-7,-2,DIRT:0)
Block(-22,-7,-1,DIRT:0)
Block(-22,-7,1,STONE:0)
Block(-22,-6,-10,STONE:0)
Block(-22,-6,-9,STONE:0)
Block(-22,-6,-8,STONE:0)
Block(-22,-6,-7,DIRT:0)
Block(-22,-6,-6,STONE:0)
Block(-22,-6,-5,DIRT:0)
Block(-22,-6,-4,STONE:0)
Block(-22,-6,-3,STONE:0)
Block(-22,-6,-2,STONE:0)
Block(-22,-6,-1,DIRT:0)
Block(-22,-6,0,STONE:0)
Block(-22,-6,1,STONE:0)
Block(-22,-5,-10,DIRT:0)
Block(-22,-5,-9,STONE:0)
Block(-22,-5,-8,STONE:0)
Block(-22,-5,-7,STONE:0)
Block(-22,-5,-6,STONE:0)
Block(-22,-5,-5,DIRT:0)
Block(-22,-5,-4,STONE:0)
Block(-22,-5,-3,STONE:0)
Block(-22,-5,-2,STONE:0)
Block(-22,-5,-1,STONE:0)
Block(-22,-5,0,STONE:0)
Block(-22,-5,1,STONE:0)
Block(-22,-4,-11,DIRT:0)
Block(-22,-4,-10,DIRT:0)
Block(-22,-4,-9,DIRT:0)
Block(-22,-4,-8,STONE:0)
Block(-22,-4,-7,STONE:0)
Block(-22,-4,-6,STONE:0)
Block(-22,-4,-5,STONE:0)
Block(-22,-4,-4,DIRT:0)
Block(-22,-4,-3,STONE:0)
Block(-22,-4,-2,DIRT:0)
Block(-22,-4,-1,STATIONARY_WATER:0)
Block(-22,-4,0,STONE:0)
Block(-22,-4,1,DIRT:0)
Block(-22,-4,2,DIRT:0)
Block(-22,-4,3,DIRT:0)
Block(-22,-3,-11,DIRT:0)
Block(-22,-3,-10,DIRT:0)
Block(-22,-3,-9,STONE:0)
Block(-22,-3,-8,STONE:0)
Block(-22,-3,-7,DIRT:0)
Block(-22,-3,-6,DIRT:0)
Block(-22,-3,-5,DIRT:0)
Block(-22,-3,-4,STONE:0)
Block(-22,-3,-3,STONE:0)
Block(-22,-3,-2,DIRT:0)
Block(-22,-3,-1,DIRT:0)
Block(-22,-3,0,DIRT:0)
Block(-22,-3,1,DIRT:0)
Block(-22,-3,2,STONE:0)
Block(-22,-3,3,STONE:0)
Block(-22,-2,-12,DIRT:0)
Block(-22,-2,-11,DIRT:0)
Block(-22,-2,-10,DIRT:0)
Block(-22,-2,-9,STONE:0)
Block(-22,-2,-8,DIRT:0)
Block(-22,-2,-7,DIRT:0)
Block(-22,-2,-6,STONE:0)
Block(-22,-2,-5,DIRT:0)
Block(-22,-2,-4,DIRT:0)
Block(-22,-2,-3,DIRT:0)
Block(-22,-2,-2,STONE:0)
Block(-22,-2,-1,DIRT:0)
Block(-22,-2,0,DIRT:0)
Block(-22,-2,1,DIRT:0)
Block(-22,-2,2,STONE:0)
Block(-22,-2,3,STONE:0)
Block(-22,-2,4,DIRT:0)
Block(-22,-1,-13,STONE:0)
Block(-22,-1,-12,DIRT:0)
Block(-22,-1,-11,DIRT:0)
Block(-22,-1,-10,DIRT:0)
Block(-22,-1,-9,STONE:0)
Block(-22,-1,-8,STONE:0)
Block(-22,-1,-7,STONE:0)
Block(-22,-1,-6,STONE:0)
Block(-22,-1,-5,DIRT:0)
Block(-22,-1,-4,DIRT:0)
Block(-22,-1,-3,DIRT:0)
Block(-22,-1,-2,STONE:0)
Block(-22,-1,-1,DIRT:0)
Block(-22,-1,0,DIRT:0)
Block(-22,-1,1,DIRT:0)
Block(-22,-1,2,STONE:0)
Block(-22,-1,3,STONE:0)
Block(-22,-1,4,DIRT:0)
Block(-22,-1,5,STONE:0)
Block(-22,0,-13,STONE:0)
Block(-22,0,-12,STONE:0)
Block(-22,0,-11,DIRT:0)
Block(-22,0,-10,STONE:0)
Block(-22,0,-9,DIRT:0)
Block(-22,0,-8,DIRT:0)
Block(-22,0,-7,DIRT:0)
Block(-22,0,-6,STONE:0)
Block(-22,0,-5,DIRT:0)
Block(-22,0,-4,STONE:0)
Block(-22,0,-3,STONE:0)
Block(-22,0,-2,DIRT:0)
Block(-22,0,-1,DIRT:0)
Block(-22,0,0,STONE:0)
Block(-22,0,1,STONE:0)
Block(-22,0,2,DIRT:0)
Block(-22,0,3,STONE:0)
Block(-22,0,4,STONE:0)
Block(-22,0,5,DIRT:0)
Block(-22,1,-14,DIRT:0)
Block(-22,1,-13,DIRT:0)
Block(-22,1,-12,STONE:0)
Block(-22,1,-11,DIRT:0)
Block(-22,1,-10,STONE:0)
Block(-22,1,-9,DIRT:0)
Block(-22,1,-8,STONE:0)
Block(-22,1,-7,STONE:0)
Block(-22,1,-6,DIRT:0)
Block(-22,1,-5,DIRT:0)
Block(-22,1,-4,STONE:0)
Block(-22,1,-3,DIRT:0)
Block(-22,1,-2,STONE:0)
Block(-22,1,-1,STONE:0)
Block(-22,1,0,STONE:0)
Block(-22,1,1,DIRT:0)
Block(-22,1,2,STONE:0)
Block(-22,1,3,STONE:0)
Block(-22,1,4,STONE:0)
Block(-22,1,5,STONE:0)
Block(-22,1,6,STONE:0)
Block(-22,2,-15,STONE:0)
Block(-22,2,-14,STONE:0)
Block(-22,2,-13,DIRT:0)
Block(-22,2,-12,STONE:0)
Block(-22,2,-11,STONE:0)
Block(-22,2,-10,STONE:0)
Block(-22,2,-9,DIRT:0)
Block(-22,2,-8,DIRT:0)
Block(-22,2,-7,DIRT:0)
Block(-22,2,-6,STONE:0)
Block(-22,2,-5,DIRT:0)
Block(-22,2,-4,STONE:0)
Block(-22,2,-3,STONE:0)
Block(-22,2,-2,DIRT:0)
Block(-22,2,-1,STONE:0)
Block(-22,2,0,STONE:0)
Block(-22,2,1,STONE:0)
Block(-22,2,2,DIRT:0)
Block(-22,2,3,DIRT:0)
Block(-22,2,4,DIRT:0)
Block(-22,2,5,STONE:0)
Block(-22,2,6,STONE:0)
Block(-22,3,-16,DIRT:0)
Block(-22,3,-15,STONE:0)
Block(-22,3,-14,STONE:0)
Block(-22,3,-13,DIRT:0)
Block(-22,3,-12,STONE:0)
Block(-22,3,-11,DIRT:0)
Block(-22,3,-10,STONE:0)
Block(-22,3,-9,DIRT:0)
Block(-22,3,-8,DIRT:0)
Block(-22,3,-7,DIRT:0)
Block(-22,3,-6,DIRT:0)
Block(-22,3,-5,DIRT:0)
Block(-22,3,-4,STONE:0)
Block(-22,3,-3,DIRT:0)
Block(-22,3,-2,STONE:0)
Block(-22,3,-1,STONE:0)
Block(-22,3,0,STONE:0)
Block(-22,3,1,STONE:0)
Block(-22,3,2,DIRT:0)
Block(-22,3,3,STONE:0)
Block(-22,3,4,DIRT:0)
Block(-22,3,5,STONE:0)
Block(-22,3,6,DIRT:0)
Block(-22,4,-18,DIRT:0)
Block(-22,4,-17,STONE:0)
Block(-22,4,-16,STONE:0)
Block(-22,4,-15,STONE:0)
Block(-22,4,-14,STONE:0)
Block(-22,4,-13,STONE:0)
Block(-22,4,-12,STONE:0)
Block(-22,4,-11,STONE:0)
Block(-22,4,-10,STONE:0)
Block(-22,4,-9,STONE:0)
Block(-22,4,-8,STONE:0)
Block(-22,4,-7,STONE:0)
Block(-22,4,-6,STONE:0)
Block(-22,4,-5,STONE:0)
Block(-22,4,-4,STONE:0)
Block(-22,4,-3,STONE:0)
Block(-22,4,-2,STONE:0)
Block(-22,4,-1,STONE:0)
Block(-22,4,0,STONE:0)
Block(-22,4,1,STONE:0)
Block(-22,4,2,STONE:0)
Block(-22,4,3,STONE:0)
Block(-22,4,4,DIRT:0)
Block(-22,4,5,STONE:0)
Block(-22,4,6,DIRT:0)
Block(-22,4,7,STONE:0)
Block(-22,5,-18,STONE:0)
Block(-22,5,-17,STONE:0)
Block(-22,5,-16,STONE:0)
Block(-22,5,-15,STONE:0)
Block(-22,5,-14,STONE:0)
Block(-22,5,-13,STONE:0)
Block(-22,5,-12,STONE:0)
Block(-22,5,-11,STONE:0)
Block(-22,5,-10,STONE:0)
Block(-22,5,-9,STONE:0)
Block(-22,5,-8,DIRT:0)
Block(-22,5,-7,STONE:0)
Block(-22,5,-6,STONE:0)
Block(-22,5,-5,STONE:0)
Block(-22,5,-4,STONE:0)
Block(-22,5,-3,STONE:0)
Block(-22,5,-2,STONE:0)
Block(-22,5,-1,STONE:0)
Block(-22,5,0,STONE:0)
Block(-22,5,1,STONE:0)
Block(-22,5,2,DIRT:0)
Block(-22,5,3,STONE:0)
Block(-22,5,4,STONE:0)
Block(-22,5,5,STONE:0)
Block(-22,5,6,DIRT:0)
Block(-22,5,7,STONE:0)
Block(-22,6,-19,STONE:0)
Block(-22,6,-18,STONE:0)
Block(-22,6,-17,STONE:0)
Block(-22,6,-16,DIRT:0)
Block(-22,6,-15,STONE:0)
Block(-22,6,-14,DIRT:0)
Block(-22,6,-13,STONE:0)
Block(-22,6,-12,STONE:0)
Block(-22,6,-11,STONE:0)
Block(-22,6,-10,DIRT:0)
Block(-22,6,-9,DIRT:0)
Block(-22,6,-8,STONE:0)
Block(-22,6,-7,STONE:0)
Block(-22,6,-6,STONE:0)
Block(-22,6,-5,STONE:0)
Block(-22,6,-4,STONE:0)
Block(-22,6,-3,DIRT:0)
Block(-22,6,-2,STONE:0)
Block(-22,6,-1,STONE:0)
Block(-22,6,0,DIRT:0)
Block(-22,6,1,DIRT:0)
Block(-22,6,2,STONE:0)
Block(-22,6,3,STONE:0)
Block(-22,6,4,STONE:0)
Block(-22,6,5,STONE:0)
Block(-22,6,6,STONE:0)
Block(-22,6,7,DIRT:0)
Block(-22,7,-20,STONE:0)
Block(-22,7,-19,STONE:0)
Block(-22,7,-18,STONE:0)
Block(-22,7,-17,GRASS:0)
Block(-22,7,-16,STONE:0)
Block(-22,7,-15,STONE:0)
Block(-22,7,-14,DIRT:0)
Block(-22,7,-13,STONE:0)
Block(-22,7,-12,STONE:0)
Block(-22,7,-11,STONE:0)
Block(-22,7,-10,STONE:0)
Block(-22,7,-9,STONE:0)
Block(-22,7,-8,STONE:0)
Block(-22,7,-7,STONE:0)
Block(-22,7,-6,STONE:0)
Block(-22,7,-5,STONE:0)
Block(-22,7,-4,STONE:0)
Block(-22,7,-3,STONE:0)
Block(-22,7,-2,STONE:0)
Block(-22,7,-1,STONE:0)
Block(-22,7,0,STONE:0)
Block(-22,7,1,STONE:0)
Block(-22,7,2,STONE:0)
Block(-22,7,3,STONE:0)
Block(-22,7,4,STONE:0)
Block(-22,7,5,STONE:0)
Block(-22,7,6,STONE:0)
Block(-22,7,7,STONE:0)
Block(-22,8,-20,GRASS:0)
Block(-22,8,-19,GRASS:0)
Block(-22,8,-18,GRASS:0)
Block(-22,8,-17,LONG_GRASS:1)
Block(-22,8,-16,GRASS:0)
Block(-22,8,-15,GRASS:0)
Block(-22,8,-14,STONE:0)
Block(-22,8,-13,STONE:0)
Block(-22,8,-12,STONE:0)
Block(-22,8,-11,STONE:0)
Block(-22,8,-10,DIRT:0)
Block(-22,8,-9,STONE:0)
Block(-22,8,-8,STONE:0)
Block(-22,8,-7,STONE:0)
Block(-22,8,-6,STONE:0)
Block(-22,8,-5,STONE:0)
Block(-22,8,-4,STONE:0)
Block(-22,8,-3,STONE:0)
Block(-22,8,-2,STONE:0)
Block(-22,8,-1,STONE:0)
Block(-22,8,0,STONE:0)
Block(-22,8,1,STONE:0)
Block(-22,8,2,STONE:0)
Block(-22,8,3,STONE:0)
Block(-22,8,4,STONE:0)
Block(-22,8,5,DIRT:0)
Block(-22,8,6,STONE:0)
Block(-22,8,7,DIRT:0)
Block(-22,9,-19,LONG_GRASS:1)
Block(-22,9,-16,LONG_GRASS:1)
Block(-22,9,-15,LONG_GRASS:1)
Block(-22,9,-14,GRASS:0)
Block(-22,9,-13,GRASS:0)
Block(-22,9,-12,STONE:0)
Block(-22,9,-11,STONE:0)
Block(-22,9,-10,STONE:0)
Block(-22,9,-9,STONE:0)
Block(-22,9,-8,STONE:0)
Block(-22,9,-7,STONE:0)
Block(-22,9,-6,STONE:0)
Block(-22,9,-5,STONE:0)
Block(-22,9,-4,STONE:0)
Block(-22,9,-3,STONE:0)
Block(-22,9,-2,STONE:0)
Block(-22,9,-1,DIRT:0)
Block(-22,9,0,DIRT:0)
Block(-22,9,1,DIRT:0)
Block(-22,9,2,STONE:0)
Block(-22,9,3,STONE:0)
Block(-22,9,4,STONE:0)
Block(-22,9,5,STONE:0)
Block(-22,9,6,STONE:0)
Block(-22,9,7,GRASS:0)
Block(-22,10,-14,LONG_GRASS:1)
Block(-22,10,-13,LONG_GRASS:1)
Block(-22,10,-12,GRASS:0)
Block(-22,10,-11,STONE:0)
Block(-22,10,-10,DIRT:0)
Block(-22,10,-9,DIRT:0)
Block(-22,10,-8,STONE:0)
Block(-22,10,-7,STONE:0)
Block(-22,10,-6,STONE:0)
Block(-22,10,-5,STONE:0)
Block(-22,10,-4,STONE:0)
Block(-22,10,-3,STONE:0)
Block(-22,10,-2,DIRT:0)
Block(-22,10,-1,STONE:0)
Block(-22,10,0,STONE:0)
Block(-22,10,1,STONE:0)
Block(-22,10,2,STONE:0)
Block(-22,10,3,STONE:0)
Block(-22,10,4,STONE:0)
Block(-22,10,5,STONE:0)
Block(-22,10,6,STATIONARY_WATER:0)
Block(-22,11,-11,GRASS:0)
Block(-22,11,-10,STONE:0)
Block(-22,11,-9,DIRT:0)
Block(-22,11,-8,STONE:0)
Block(-22,11,-7,DIRT:0)
Block(-22,11,-6,STONE:0)
Block(-22,11,-5,STONE:0)
Block(-22,11,-4,STONE:0)
Block(-22,11,-3,STONE:0)
Block(-22,11,-2,STONE:0)
Block(-22,11,-1,STONE:0)
Block(-22,11,0,STONE:0)
Block(-22,11,1,DIRT:0)
Block(-22,11,2,STATIONARY_WATER:0)
Block(-22,11,3,STATIONARY_WATER:0)
Block(-22,11,4,STATIONARY_WATER:0)
Block(-22,11,5,GRASS:0)
Block(-22,11,6,GRASS:0)
Block(-22,12,-10,STONE:0)
Block(-22,12,-9,STONE:0)
Block(-22,12,-8,STONE:0)
Block(-22,12,-7,STONE:0)
Block(-22,12,-6,DIRT:0)
Block(-22,12,-5,DIRT:0)
Block(-22,12,-4,DIRT:0)
Block(-22,12,-3,GRASS:0)
Block(-22,12,-2,GRASS:0)
Block(-22,12,-1,GRASS:0)
Block(-22,12,0,GRASS:0)
Block(-22,12,1,GRASS:0)
Block(-22,12,5,LONG_GRASS:1)
Block(-22,12,6,LONG_GRASS:1)
Block(-22,13,-10,GRASS:0)
Block(-22,13,-9,GRASS:0)
Block(-22,13,-8,STONE:0)
Block(-22,13,-7,DIRT:0)
Block(-22,13,-6,STONE:0)
Block(-22,13,-5,STONE:0)
Block(-22,13,-4,GRASS:0)
Block(-22,13,-1,LONG_GRASS:1)
Block(-22,13,0,DOUBLE_PLANT:2)
Block(-22,14,-8,GRASS:0)
Block(-22,14,-7,GRASS:0)
Block(-22,14,-6,GRASS:0)
Block(-22,14,-5,GRASS:0)
Block(-22,14,-4,LEAVES:0)
Block(-22,14,0,DOUBLE_PLANT:10)
Block(-22,15,-7,LEAVES:0)
Block(-22,15,-6,LEAVES:0)
Block(-22,15,-5,LEAVES:0)
Block(-22,15,-4,LEAVES:0)
Block(-22,15,-2,LEAVES:0)
Block(-22,15,-1,LEAVES:0)
Block(-22,15,0,LEAVES:0)
Block(-22,15,1,LEAVES:0)
Block(-22,16,-1,LEAVES:0)
Block(-22,16,0,LEAVES:0)
Block(-22,16,1,LEAVES:0)
Block(-22,16,2,LEAVES:0)
Block(-22,17,-2,LEAVES:0)
Block(-22,17,-1,LEAVES:0)
Block(-22,17,0,LEAVES:0)
Block(-22,17,1,LEAVES:0)
Block(-22,17,2,LEAVES:0)
Block(-22,18,-1,LEAVES:0)
Block(-22,18,0,LEAVES:0)
Block(-22,18,1,LEAVES:0)
Block(-21,-14,-6,STONE:0)
Block(-21,-13,-8,DIRT:0)
Block(-21,-13,-7,STONE:0)
Block(-21,-13,-6,STONE:0)
Block(-21,-12,-8,STONE:0)
Block(-21,-12,-7,STONE:0)
Block(-21,-12,-6,STONE:0)
Block(-21,-12,-2,STONE:0)
Block(-21,-11,-8,STONE:0)
Block(-21,-11,-7,STONE:0)
Block(-21,-11,-6,STONE:0)
Block(-21,-11,-5,DIRT:0)
Block(-21,-11,-3,STONE:0)
Block(-21,-11,-2,DIRT:0)
Block(-21,-11,-1,DIRT:0)
Block(-21,-10,-10,STONE:0)
Block(-21,-10,-9,STONE:0)
Block(-21,-10,-8,STONE:0)
Block(-21,-10,-7,STONE:0)
Block(-21,-10,-6,DIRT:0)
Block(-21,-10,-5,DIRT:0)
Block(-21,-10,-4,STONE:0)
Block(-21,-10,-3,STONE:0)
Block(-21,-10,-2,STONE:0)
Block(-21,-10,-1,STONE:0)
Block(-21,-9,-10,DIRT:0)
Block(-21,-9,-9,STONE:0)
Block(-21,-9,-8,STONE:0)
Block(-21,-9,-7,STONE:0)
Block(-21,-9,-6,DIRT:0)
Block(-21,-9,-5,DIRT:0)
Block(-21,-9,-4,STONE:0)
Block(-21,-9,-3,STONE:0)
Block(-21,-9,-2,STONE:0)
Block(-21,-9,-1,DIRT:0)
Block(-21,-9,2,STONE:0)
Block(-21,-8,-11,DIRT:0)
Block(-21,-8,-10,DIRT:0)
Block(-21,-8,-9,STONE:0)
Block(-21,-8,-8,STONE:0)
Block(-21,-8,-7,STONE:0)
Block(-21,-8,-6,STONE:0)
Block(-21,-8,-5,STONE:0)
Block(-21,-8,-4,DIRT:0)
Block(-21,-8,-3,DIRT:0)
Block(-21,-8,-2,STONE:0)
Block(-21,-8,-1,STONE:0)
Block(-21,-8,0,STONE:0)
Block(-21,-8,1,STONE:0)
Block(-21,-8,2,STONE:0)
Block(-21,-7,-11,DIRT:0)
Block(-21,-7,-10,STONE:0)
Block(-21,-7,-9,STONE:0)
Block(-21,-7,-8,STONE:0)
Block(-21,-7,-7,STONE:0)
Block(-21,-7,-6,STONE:0)
Block(-21,-7,-5,STONE:0)
Block(-21,-7,-4,DIRT:0)
Block(-21,-7,-3,DIRT:0)
Block(-21,-7,-2,DIRT:0)
Block(-21,-7,-1,STONE:0)
Block(-21,-7,0,DIRT:0)
Block(-21,-7,1,STONE:0)
Block(-21,-7,2,STONE:0)
Block(-21,-6,-12,STONE:0)
Block(-21,-6,-11,STONE:0)
Block(-21,-6,-10,STONE:0)
Block(-21,-6,-9,STONE:0)
Block(-21,-6,-8,STONE:0)
Block(-21,-6,-7,STONE:0)
Block(-21,-6,-6,DIRT:0)
Block(-21,-6,-5,STONE:0)
Block(-21,-6,-4,STONE:0)
Block(-21,-6,-3,DIRT:0)
Block(-21,-6,-2,STONE:0)
Block(-21,-6,-1,STONE:0)
Block(-21,-6,0,STONE:0)
Block(-21,-6,1,STONE:0)
Block(-21,-6,2,STONE:0)
Block(-21,-6,3,STONE:0)
Block(-21,-5,-12,STONE:0)
Block(-21,-5,-11,STONE:0)
Block(-21,-5,-10,STONE:0)
Block(-21,-5,-9,DIRT:0)
Block(-21,-5,-8,STONE:0)
Block(-21,-5,-7,STONE:0)
Block(-21,-5,-6,STONE:0)
Block(-21,-5,-5,STONE:0)
Block(-21,-5,-4,DIRT:0)
Block(-21,-5,-3,STONE:0)
Block(-21,-5,-2,STONE:0)
Block(-21,-5,-1,STONE:0)
Block(-21,-5,0,DIRT:0)
Block(-21,-5,1,STONE:0)
Block(-21,-5,2,STONE:0)
Block(-21,-5,3,DIRT:0)
Block(-21,-4,-13,STONE:0)
Block(-21,-4,-12,STONE:0)
Block(-21,-4,-11,DIRT:0)
Block(-21,-4,-10,DIRT:0)
Block(-21,-4,-9,STONE:0)
Block(-21,-4,-8,DIRT:0)
Block(-21,-4,-7,STONE:0)
Block(-21,-4,-6,STONE:0)
Block(-21,-4,-5,STONE:0)
Block(-21,-4,-4,DIRT:0)
Block(-21,-4,-3,STONE:0)
Block(-21,-4,-2,DIRT:0)
Block(-21,-4,-1,STONE:0)
Block(-21,-4,0,DIRT:0)
Block(-21,-4,1,STONE:0)
Block(-21,-4,2,STONE:0)
Block(-21,-4,3,DIRT:0)
Block(-21,-3,-13,DIRT:0)
Block(-21,-3,-12,STONE:0)
Block(-21,-3,-11,STONE:0)
Block(-21,-3,-10,DIRT:0)
Block(-21,-3,-9,DIRT:0)
Block(-21,-3,-8,DIRT:0)
Block(-21,-3,-7,DIRT:0)
Block(-21,-3,-6,STONE:0)
Block(-21,-3,-5,DIRT:0)
Block(-21,-3,-4,DIRT:0)
Block(-21,-3,-3,STONE:0)
Block(-21,-3,-2,STONE:0)
Block(-21,-3,-1,DIRT:0)
Block(-21,-3,0,STONE:0)
Block(-21,-3,1,STONE:0)
Block(-21,-3,2,STONE:0)
Block(-21,-3,3,STONE:0)
Block(-21,-3,4,STONE:0)
Block(-21,-2,-14,STONE:0)
Block(-21,-2,-13,STONE:0)
Block(-21,-2,-12,STONE:0)
Block(-21,-2,-11,STONE:0)
Block(-21,-2,-10,STONE:0)
Block(-21,-2,-9,DIRT:0)
Block(-21,-2,-8,STONE:0)
Block(-21,-2,-7,DIRT:0)
Block(-21,-2,-6,DIRT:0)
Block(-21,-2,-5,DIRT:0)
Block(-21,-2,-4,DIRT:0)
Block(-21,-2,-3,STONE:0)
Block(-21,-2,-2,STONE:0)
Block(-21,-2,-1,DIRT:0)
Block(-21,-2,0,STONE:0)
Block(-21,-2,1,DIRT:0)
Block(-21,-2,2,DIRT:0)
Block(-21,-2,3,STONE:0)
Block(-21,-2,4,STONE:0)
Block(-21,-1,-14,DIRT:0)
Block(-21,-1,-13,DIRT:0)
Block(-21,-1,-12,STONE:0)
Block(-21,-1,-11,STONE:0)
Block(-21,-1,-10,DIRT:0)
Block(-21,-1,-9,STONE:0)
Block(-21,-1,-8,STONE:0)
Block(-21,-1,-7,STONE:0)
Block(-21,-1,-6,DIRT:0)
Block(-21,-1,-5,STONE:0)
Block(-21,-1,-4,STONE:0)
Block(-21,-1,-3,STONE:0)
Block(-21,-1,-2,STONE:0)
Block(-21,-1,-1,STONE:0)
Block(-21,-1,0,STONE:0)
Block(-21,-1,1,STONE:0)
Block(-21,-1,2,DIRT:0)
Block(-21,-1,3,STONE:0)
Block(-21,-1,4,DIRT:0)
Block(-21,-1,5,STONE:0)
Block(-21,0,-15,STONE:0)
Block(-21,0,-14,STONE:0)
Block(-21,0,-13,STONE:0)
Block(-21,0,-12,DIRT:0)
Block(-21,0,-11,DIRT:0)
Block(-21,0,-10,STONE:0)
Block(-21,0,-9,DIRT:0)
Block(-21,0,-8,STONE:0)
Block(-21,0,-7,STONE:0)
Block(-21,0,-6,STONE:0)
Block(-21,0,-5,DIRT:0)
Block(-21,0,-4,DIRT:0)
Block(-21,0,-3,DIRT:0)
Block(-21,0,-2,STONE:0)
Block(-21,0,-1,STONE:0)
Block(-21,0,0,DIRT:0)
Block(-21,0,1,STONE:0)
Block(-21,0,2,DIRT:0)
Block(-21,0,3,STONE:0)
Block(-21,0,4,STONE:0)
Block(-21,0,5,STONE:0)
Block(-21,1,-16,DIRT:0)
Block(-21,1,-15,DIRT:0)
Block(-21,1,-14,STONE:0)
Block(-21,1,-13,STONE:0)
Block(-21,1,-12,STONE:0)
Block(-21,1,-11,STONE:0)
Block(-21,1,-10,DIRT:0)
Block(-21,1,-9,DIRT:0)
Block(-21,1,-8,DIRT:0)
Block(-21,1,-7,STONE:0)
Block(-21,1,-6,DIRT:0)
Block(-21,1,-5,DIRT:0)
Block(-21,1,-4,DIRT:0)
Block(-21,1,-3,DIRT:0)
Block(-21,1,-2,STONE:0)
Block(-21,1,-1,STONE:0)
Block(-21,1,0,DIRT:0)
Block(-21,1,1,STONE:0)
Block(-21,1,2,DIRT:0)
Block(-21,1,3,DIRT:0)
Block(-21,1,4,STONE:0)
Block(-21,1,5,STONE:0)
Block(-21,1,6,STONE:0)
Block(-21,2,-17,DIRT:0)
Block(-21,2,-16,DIRT:0)
Block(-21,2,-15,DIRT:0)
Block(-21,2,-14,DIRT:0)
Block(-21,2,-13,DIRT:0)
Block(-21,2,-12,DIRT:0)
Block(-21,2,-11,DIRT:0)
Block(-21,2,-10,STONE:0)
Block(-21,2,-9,STONE:0)
Block(-21,2,-8,STONE:0)
Block(-21,2,-7,DIRT:0)
Block(-21,2,-6,DIRT:0)
Block(-21,2,-5,DIRT:0)
Block(-21,2,-4,DIRT:0)
Block(-21,2,-3,DIRT:0)
Block(-21,2,-2,DIRT:0)
Block(-21,2,-1,STONE:0)
Block(-21,2,0,STONE:0)
Block(-21,2,1,STONE:0)
Block(-21,2,2,DIRT:0)
Block(-21,2,3,DIRT:0)
Block(-21,2,4,STONE:0)
Block(-21,2,5,STONE:0)
Block(-21,2,6,DIRT:0)
Block(-21,3,-18,STONE:0)
Block(-21,3,-17,DIRT:0)
Block(-21,3,-16,STONE:0)
Block(-21,3,-15,STONE:0)
Block(-21,3,-14,STONE:0)
Block(-21,3,-13,DIRT:0)
Block(-21,3,-12,STONE:0)
Block(-21,3,-11,DIRT:0)
Block(-21,3,-10,DIRT:0)
Block(-21,3,-9,DIRT:0)
Block(-21,3,-8,DIRT:0)
Block(-21,3,-7,DIRT:0)
Block(-21,3,-6,DIRT:0)
Block(-21,3,-5,STONE:0)
Block(-21,3,-4,STONE:0)
Block(-21,3,-3,DIRT:0)
Block(-21,3,-2,STONE:0)
Block(-21,3,-1,DIRT:0)
Block(-21,3,0,STONE:0)
Block(-21,3,1,DIRT:0)
Block(-21,3,2,DIRT:0)
Block(-21,3,3,DIRT:0)
Block(-21,3,4,DIRT:0)
Block(-21,3,5,DIRT:0)
Block(-21,3,6,DIRT:0)
Block(-21,3,7,DIRT:0)
Block(-21,4,-20,STONE:0)
Block(-21,4,-19,DIRT:0)
Block(-21,4,-18,STONE:0)
Block(-21,4,-17,STONE:0)
Block(-21,4,-16,STONE:0)
Block(-21,4,-15,STONE:0)
Block(-21,4,-14,DIRT:0)
Block(-21,4,-13,STONE:0)
Block(-21,4,-12,STONE:0)
Block(-21,4,-11,STONE:0)
Block(-21,4,-10,STONE:0)
Block(-21,4,-9,STONE:0)
Block(-21,4,-8,STONE:0)
Block(-21,4,-7,STONE:0)
Block(-21,4,-6,STONE:0)
Block(-21,4,-5,STONE:0)
Block(-21,4,-4,STONE:0)
Block(-21,4,-3,STONE:0)
Block(-21,4,-2,STONE:0)
Block(-21,4,-1,STONE:0)
Block(-21,4,0,DIRT:0)
Block(-21,4,1,STONE:0)
Block(-21,4,2,STONE:0)
Block(-21,4,3,STONE:0)
Block(-21,4,4,STONE:0)
Block(-21,4,5,STONE:0)
Block(-21,4,6,STONE:0)
Block(-21,4,7,STONE:0)
Block(-21,5,-20,DIRT:0)
Block(-21,5,-19,STONE:0)
Block(-21,5,-18,STONE:0)
Block(-21,5,-17,DIRT:0)
Block(-21,5,-16,STONE:0)
Block(-21,5,-15,STONE:0)
Block(-21,5,-14,STONE:0)
Block(-21,5,-13,STONE:0)
Block(-21,5,-12,DIRT:0)
Block(-21,5,-11,STONE:0)
Block(-21,5,-10,DIRT:0)
Block(-21,5,-9,DIRT:0)
Block(-21,5,-8,STONE:0)
Block(-21,5,-7,STONE:0)
Block(-21,5,-6,STONE:0)
Block(-21,5,-5,STONE:0)
Block(-21,5,-4,STONE:0)
Block(-21,5,-3,STONE:0)
Block(-21,5,-2,STONE:0)
Block(-21,5,-1,STONE:0)
Block(-21,5,0,DIRT:0)
Block(-21,5,1,STONE:0)
Block(-21,5,2,STONE:0)
Block(-21,5,3,STONE:0)
Block(-21,5,4,STONE:0)
Block(-21,5,5,STONE:0)
Block(-21,5,6,STONE:0)
Block(-21,5,7,STONE:0)
Block(-21,6,-20,STONE:0)
Block(-21,6,-19,STONE:0)
Block(-21,6,-18,DIRT:0)
Block(-21,6,-17,STONE:0)
Block(-21,6,-16,STONE:0)
Block(-21,6,-15,STONE:0)
Block(-21,6,-14,STONE:0)
Block(-21,6,-13,STONE:0)
Block(-21,6,-12,STONE:0)
Block(-21,6,-11,STONE:0)
Block(-21,6,-10,DIRT:0)
Block(-21,6,-9,DIRT:0)
Block(-21,6,-8,DIRT:0)
Block(-21,6,-7,STONE:0)
Block(-21,6,-6,STONE:0)
Block(-21,6,-5,STONE:0)
Block(-21,6,-4,STONE:0)
Block(-21,6,-3,STONE:0)
Block(-21,6,-2,STONE:0)
Block(-21,6,-1,STONE:0)
Block(-21,6,0,DIRT:0)
Block(-21,6,1,DIRT:0)
Block(-21,6,2,STONE:0)
Block(-21,6,3,STONE:0)
Block(-21,6,4,STONE:0)
Block(-21,6,5,DIRT:0)
Block(-21,6,6,STONE:0)
Block(-21,6,7,STONE:0)
Block(-21,7,-21,STONE:0)
Block(-21,7,-20,STONE:0)
Block(-21,7,-19,DIRT:0)
Block(-21,7,-18,DIRT:0)
Block(-21,7,-17,STONE:0)
Block(-21,7,-16,STONE:0)
Block(-21,7,-15,DIRT:0)
Block(-21,7,-14,STONE:0)
Block(-21,7,-13,STONE:0)
Block(-21,7,-12,STONE:0)
Block(-21,7,-11,STONE:0)
Block(-21,7,-10,STONE:0)
Block(-21,7,-9,STONE:0)
Block(-21,7,-8,STONE:0)
Block(-21,7,-7,STONE:0)
Block(-21,7,-6,STONE:0)
Block(-21,7,-5,STONE:0)
Block(-21,7,-4,STONE:0)
Block(-21,7,-3,STONE:0)
Block(-21,7,-2,STONE:0)
Block(-21,7,-1,DIRT:0)
Block(-21,7,0,STONE:0)
Block(-21,7,1,STONE:0)
Block(-21,7,2,STONE:0)
Block(-21,7,3,STONE:0)
Block(-21,7,4,STONE:0)
Block(-21,7,5,STONE:0)
Block(-21,7,6,STONE:0)
Block(-21,7,7,STONE:0)
Block(-21,7,8,DIRT:0)
Block(-21,8,-21,GRASS:0)
Block(-21,8,-20,GRASS:0)
Block(-21,8,-19,GRASS:0)
Block(-21,8,-18,STONE:0)
Block(-21,8,-17,GRASS:0)
Block(-21,8,-16,GRASS:0)
Block(-21,8,-15,STONE:0)
Block(-21,8,-14,DIRT:0)
Block(-21,8,-13,DIRT:0)
Block(-21,8,-12,STONE:0)
Block(-21,8,-11,STONE:0)
Block(-21,8,-10,STONE:0)
Block(-21,8,-9,STONE:0)
Block(-21,8,-8,STONE:0)
Block(-21,8,-7,STONE:0)
Block(-21,8,-6,STONE:0)
Block(-21,8,-5,STONE:0)
Block(-21,8,-4,STONE:0)
Block(-21,8,-3,STONE:0)
Block(-21,8,-2,STONE:0)
Block(-21,8,-1,STONE:0)
Block(-21,8,0,STONE:0)
Block(-21,8,1,STONE:0)
Block(-21,8,2,STONE:0)
Block(-21,8,3,STONE:0)
Block(-21,8,4,STONE:0)
Block(-21,8,5,STONE:0)
Block(-21,8,6,STONE:0)
Block(-21,8,7,STONE:0)
Block(-21,8,8,GRASS:0)
Block(-21,9,-21,LONG_GRASS:1)
Block(-21,9,-20,LONG_GRASS:1)
Block(-21,9,-19,LONG_GRASS:1)
Block(-21,9,-15,GRASS:0)
Block(-21,9,-14,DIRT:0)
Block(-21,9,-13,STONE:0)
Block(-21,9,-12,STONE:0)
Block(-21,9,-11,STONE:0)
Block(-21,9,-10,STONE:0)
Block(-21,9,-9,STONE:0)
Block(-21,9,-8,STONE:0)
Block(-21,9,-7,STONE:0)
Block(-21,9,-6,STONE:0)
Block(-21,9,-5,STONE:0)
Block(-21,9,-4,STONE:0)
Block(-21,9,-3,STONE:0)
Block(-21,9,-2,STONE:0)
Block(-21,9,-1,STONE:0)
Block(-21,9,0,STONE:0)
Block(-21,9,1,DIRT:0)
Block(-21,9,2,DIRT:0)
Block(-21,9,3,STONE:0)
Block(-21,9,4,STONE:0)
Block(-21,9,5,STONE:0)
Block(-21,9,6,DIRT:0)
Block(-21,9,7,STONE:0)
Block(-21,10,-14,GRASS:0)
Block(-21,10,-13,STONE:0)
Block(-21,10,-12,STONE:0)
Block(-21,10,-11,STONE:0)
Block(-21,10,-10,STONE:0)
Block(-21,10,-9,STONE:0)
Block(-21,10,-8,STONE:0)
Block(-21,10,-7,STONE:0)
Block(-21,10,-6,STONE:0)
Block(-21,10,-5,STONE:0)
Block(-21,10,-4,STONE:0)
Block(-21,10,-3,STONE:0)
Block(-21,10,-2,STONE:0)
Block(-21,10,-1,DIRT:0)
Block(-21,10,0,STONE:0)
Block(-21,10,1,STONE:0)
Block(-21,10,2,DIRT:0)
Block(-21,10,3,STONE:0)
Block(-21,10,4,STONE:0)
Block(-21,10,5,DIRT:0)
Block(-21,10,6,DIRT:0)
Block(-21,10,7,GRASS:0)
Block(-21,11,-13,GRASS:0)
Block(-21,11,-12,STONE:0)
Block(-21,11,-11,STONE:0)
Block(-21,11,-10,STONE:0)
Block(-21,11,-9,STONE:0)
Block(-21,11,-8,STONE:0)
Block(-21,11,-7,STONE:0)
Block(-21,11,-6,DIRT:0)
Block(-21,11,-5,STONE:0)
Block(-21,11,-4,STONE:0)
Block(-21,11,-3,STONE:0)
Block(-21,11,-2,DIRT:0)
Block(-21,11,-1,STONE:0)
Block(-21,11,0,STONE:0)
Block(-21,11,1,DIRT:0)
Block(-21,11,2,STONE:0)
Block(-21,11,3,STATIONARY_WATER:0)
Block(-21,11,4,STATIONARY_WATER:0)
Block(-21,11,5,STATIONARY_WATER:0)
Block(-21,11,6,GRASS:0)
Block(-21,11,7,LONG_GRASS:1)
Block(-21,12,-12,GRASS:0)
Block(-21,12,-11,STONE:0)
Block(-21,12,-10,DIRT:0)
Block(-21,12,-9,STONE:0)
Block(-21,12,-8,STONE:0)
Block(-21,12,-7,STONE:0)
Block(-21,12,-6,STONE:0)
Block(-21,12,-5,STONE:0)
Block(-21,12,-4,STONE:0)
Block(-21,12,-3,DIRT:0)
Block(-21,12,-2,STONE:0)
Block(-21,12,-1,STONE:0)
Block(-21,12,0,GRASS:0)
Block(-21,12,1,GRASS:0)
Block(-21,12,2,GRASS:0)
Block(-21,12,6,LONG_GRASS:1)
Block(-21,13,-11,GRASS:0)
Block(-21,13,-10,STONE:0)
Block(-21,13,-9,DIRT:0)
Block(-21,13,-8,STONE:0)
Block(-21,13,-7,STONE:0)
Block(-21,13,-6,STONE:0)
Block(-21,13,-5,STONE:0)
Block(-21,13,-4,STONE:0)
Block(-21,13,-3,STONE:0)
Block(-21,13,-2,GRASS:0)
Block(-21,13,-1,GRASS:0)
Block(-21,14,-10,GRASS:0)
Block(-21,14,-9,STONE:0)
Block(-21,14,-8,STONE:0)
Block(-21,14,-7,STONE:0)
Block(-21,14,-6,STONE:0)
Block(-21,14,-5,STONE:0)
Block(-21,14,-4,GRASS:0)
Block(-21,14,-3,GRASS:0)
Block(-21,14,-2,LONG_GRASS:1)
Block(-21,14,-1,LONG_GRASS:1)
Block(-21,15,-9,GRASS:0)
Block(-21,15,-8,STONE:0)
Block(-21,15,-7,STONE:0)
Block(-21,15,-6,DIRT:0)
Block(-21,15,-5,GRASS:0)
Block(-21,15,-3,LONG_GRASS:1)
Block(-21,15,-2,LEAVES:0)
Block(-21,15,-1,LEAVES:0)
Block(-21,15,0,LEAVES:0)
Block(-21,15,1,LEAVES:0)
Block(-21,15,2,LEAVES:0)
Block(-21,16,-8,GRASS:0)
Block(-21,16,-7,GRASS:0)
Block(-21,16,-6,GRASS:0)
Block(-21,16,-5,DOUBLE_PLANT:2)
Block(-21,16,-2,LEAVES:0)
Block(-21,16,-1,LEAVES:0)
Block(-21,16,0,LEAVES:0)
Block(-21,16,1,LEAVES:0)
Block(-21,16,2,LEAVES:0)
Block(-21,17,-6,LONG_GRASS:1)
Block(-21,17,-5,DOUBLE_PLANT:10)
Block(-21,17,-2,LEAVES:0)
Block(-21,17,-1,LEAVES:0)
Block(-21,17,0,LEAVES:0)
Block(-21,17,1,LEAVES:0)
Block(-21,17,2,LEAVES:0)
Block(-21,18,-2,LEAVES:0)
Block(-21,18,-1,LEAVES:0)
Block(-21,18,0,LEAVES:0)
Block(-21,18,1,LEAVES:0)
Block(-21,18,2,LEAVES:0)
Block(-21,19,0,LEAVES:0)
Block(-21,20,0,LEAVES:0)
Block(-20,-17,-6,STONE:0)
Block(-20,-17,-5,STONE:0)
Block(-20,-16,-6,STONE:0)
Block(-20,-16,-5,STONE:0)
Block(-20,-16,-4,STONE:0)
Block(-20,-15,-7,STONE:0)
Block(-20,-15,-6,DIRT:0)
Block(-20,-15,-5,STONE:0)
Block(-20,-15,-4,STONE:0)
Block(-20,-15,-3,DIRT:0)
Block(-20,-14,-9,STONE:0)
Block(-20,-14,-8,DIRT:0)
Block(-20,-14,-7,DIRT:0)
Block(-20,-14,-6,STONE:0)
Block(-20,-14,-5,STONE:0)
Block(-20,-14,-4,STONE:0)
Block(-20,-14,-3,STONE:0)
Block(-20,-14,-2,STONE:0)
Block(-20,-14,-1,STONE:0)
Block(-20,-13,-10,DIRT:0)
Block(-20,-13,-9,STONE:0)
Block(-20,-13,-8,STONE:0)
Block(-20,-13,-7,STONE:0)
Block(-20,-13,-6,DIRT:0)
Block(-20,-13,-5,STONE:0)
Block(-20,-13,-4,DIRT:0)
Block(-20,-13,-3,DIRT:0)
Block(-20,-13,-2,DIRT:0)
Block(-20,-13,-1,STONE:0)
Block(-20,-13,0,STONE:0)
Block(-20,-12,-11,STONE:0)
Block(-20,-12,-10,STONE:0)
Block(-20,-12,-9,DIRT:0)
Block(-20,-12,-8,STONE:0)
Block(-20,-12,-7,STONE:0)
Block(-20,-12,-6,STONE:0)
Block(-20,-12,-5,STONE:0)
Block(-20,-12,-4,DIRT:0)
Block(-20,-12,-3,STONE:0)
Block(-20,-12,-2,STONE:0)
Block(-20,-12,-1,STONE:0)
Block(-20,-12,0,DIRT:0)
Block(-20,-12,1,DIRT:0)
Block(-20,-11,-11,DIRT:0)
Block(-20,-11,-10,STONE:0)
Block(-20,-11,-9,DIRT:0)
Block(-20,-11,-8,STONE:0)
Block(-20,-11,-7,STONE:0)
Block(-20,-11,-6,STONE:0)
Block(-20,-11,-5,DIRT:0)
Block(-20,-11,-4,STONE:0)
Block(-20,-11,-3,STONE:0)
Block(-20,-11,-2,STONE:0)
Block(-20,-11,-1,STONE:0)
Block(-20,-11,0,STONE:0)
Block(-20,-11,1,STONE:0)
Block(-20,-10,-12,DIRT:0)
Block(-20,-10,-11,STONE:0)
Block(-20,-10,-10,STONE:0)
Block(-20,-10,-9,STONE:0)
Block(-20,-10,-8,STONE:0)
Block(-20,-10,-7,STONE:0)
Block(-20,-10,-6,STONE:0)
Block(-20,-10,-5,STONE:0)
Block(-20,-10,-4,STONE:0)
Block(-20,-10,-3,STONE:0)
Block(-20,-10,-2,STONE:0)
Block(-20,-10,-1,STONE:0)
Block(-20,-10,0,STONE:0)
Block(-20,-10,1,STONE:0)
Block(-20,-9,-12,STONE:0)
Block(-20,-9,-11,STONE:0)
Block(-20,-9,-10,STONE:0)
Block(-20,-9,-9,STONE:0)
Block(-20,-9,-8,STONE:0)
Block(-20,-9,-7,DIRT:0)
Block(-20,-9,-6,DIRT:0)
Block(-20,-9,-5,DIRT:0)
Block(-20,-9,-4,DIRT:0)
Block(-20,-9,-3,STONE:0)
Block(-20,-9,-2,STONE:0)
Block(-20,-9,-1,DIRT:0)
Block(-20,-9,0,STONE:0)
Block(-20,-9,1,STONE:0)
Block(-20,-9,2,STONE:0)
Block(-20,-8,-13,DIRT:0)
Block(-20,-8,-12,STONE:0)
Block(-20,-8,-11,STONE:0)
Block(-20,-8,-10,STONE:0)
Block(-20,-8,-9,STONE:0)
Block(-20,-8,-8,DIRT:0)
Block(-20,-8,-7,DIRT:0)
Block(-20,-8,-6,STONE:0)
Block(-20,-8,-5,STONE:0)
Block(-20,-8,-4,DIRT:0)
Block(-20,-8,-3,STONE:0)
Block(-20,-8,-2,STONE:0)
Block(-20,-8,-1,STONE:0)
Block(-20,-8,0,STONE:0)
Block(-20,-8,1,DIRT:0)
Block(-20,-8,2,STONE:0)
Block(-20,-7,-13,DIRT:0)
Block(-20,-7,-12,STONE:0)
Block(-20,-7,-11,STONE:0)
Block(-20,-7,-10,STONE:0)
Block(-20,-7,-9,STONE:0)
Block(-20,-7,-8,STONE:0)
Block(-20,-7,-7,DIRT:0)
Block(-20,-7,-6,STONE:0)
Block(-20,-7,-5,STONE:0)
Block(-20,-7,-4,DIRT:0)
Block(-20,-7,-3,STONE:0)
Block(-20,-7,-2,STONE:0)
Block(-20,-7,-1,STONE:0)
Block(-20,-7,0,DIRT:0)
Block(-20,-7,1,STONE:0)
Block(-20,-7,2,DIRT:0)
Block(-20,-7,3,DIRT:0)
Block(-20,-6,-14,STONE:0)
Block(-20,-6,-13,STONE:0)
Block(-20,-6,-12,DIRT:0)
Block(-20,-6,-11,STONE:0)
Block(-20,-6,-10,STONE:0)
Block(-20,-6,-9,STONE:0)
Block(-20,-6,-8,STONE:0)
Block(-20,-6,-7,STONE:0)
Block(-20,-6,-6,STONE:0)
Block(-20,-6,-5,STONE:0)
Block(-20,-6,-4,STONE:0)
Block(-20,-6,-3,STONE:0)
Block(-20,-6,-2,DIRT:0)
Block(-20,-6,-1,STONE:0)
Block(-20,-6,0,STONE:0)
Block(-20,-6,1,STONE:0)
Block(-20,-6,2,STONE:0)
Block(-20,-6,3,STONE:0)
Block(-20,-5,-14,STONE:0)
Block(-20,-5,-13,STONE:0)
Block(-20,-5,-12,STONE:0)
Block(-20,-5,-11,STONE:0)
Block(-20,-5,-10,STONE:0)
Block(-20,-5,-9,STONE:0)
Block(-20,-5,-8,STONE:0)
Block(-20,-5,-7,STONE:0)
Block(-20,-5,-6,STONE:0)
Block(-20,-5,-5,STONE:0)
Block(-20,-5,-4,STONE:0)
Block(-20,-5,-3,STONE:0)
Block(-20,-5,-2,DIRT:0)
Block(-20,-5,-1,STONE:0)
Block(-20,-5,0,STONE:0)
Block(-20,-5,1,STONE:0)
Block(-20,-5,2,DIRT:0)
Block(-20,-5,3,STONE:0)
Block(-20,-5,4,STONE:0)
Block(-20,-4,-15,DIRT:0)
Block(-20,-4,-14,DIRT:0)
Block(-20,-4,-13,STONE:0)
Block(-20,-4,-12,STONE:0)
Block(-20,-4,-11,STONE:0)
Block(-20,-4,-10,STONE:0)
Block(-20,-4,-9,DIRT:0)
Block(-20,-4,-8,DIRT:0)
Block(-20,-4,-7,DIRT:0)
Block(-20,-4,-6,STONE:0)
Block(-20,-4,-5,STONE:0)
Block(-20,-4,-4,DIRT:0)
Block(-20,-4,-3,STONE:0)
Block(-20,-4,-2,STONE:0)
Block(-20,-4,-1,DIRT:0)
Block(-20,-4,0,STONE:0)
Block(-20,-4,1,STONE:0)
Block(-20,-4,2,DIRT:0)
Block(-20,-4,3,DIRT:0)
Block(-20,-4,4,STONE:0)
Block(-20,-3,-15,DIRT:0)
Block(-20,-3,-14,STONE:0)
Block(-20,-3,-13,STONE:0)
Block(-20,-3,-12,DIRT:0)
Block(-20,-3,-11,STONE:0)
Block(-20,-3,-10,DIRT:0)
Block(-20,-3,-9,STONE:0)
Block(-20,-3,-8,DIRT:0)
Block(-20,-3,-7,DIRT:0)
Block(-20,-3,-6,DIRT:0)
Block(-20,-3,-5,DIRT:0)
Block(-20,-3,-4,DIRT:0)
Block(-20,-3,-3,STONE:0)
Block(-20,-3,-2,STONE:0)
Block(-20,-3,-1,DIRT:0)
Block(-20,-3,0,DIRT:0)
Block(-20,-3,1,DIRT:0)
Block(-20,-3,2,STONE:0)
Block(-20,-3,3,STONE:0)
Block(-20,-3,4,STONE:0)
Block(-20,-3,5,STONE:0)
Block(-20,-2,-15,DIRT:0)
Block(-20,-2,-14,STONE:0)
Block(-20,-2,-13,DIRT:0)
Block(-20,-2,-12,DIRT:0)
Block(-20,-2,-11,STONE:0)
Block(-20,-2,-10,DIRT:0)
Block(-20,-2,-9,STONE:0)
Block(-20,-2,-8,STONE:0)
Block(-20,-2,-7,DIRT:0)
Block(-20,-2,-6,DIRT:0)
Block(-20,-2,-5,STONE:0)
Block(-20,-2,-4,STONE:0)
Block(-20,-2,-3,DIRT:0)
Block(-20,-2,-2,STONE:0)
Block(-20,-2,-1,DIRT:0)
Block(-20,-2,0,STONE:0)
Block(-20,-2,1,DIRT:0)
Block(-20,-2,2,DIRT:0)
Block(-20,-2,3,DIRT:0)
Block(-20,-2,4,STONE:0)
Block(-20,-2,5,STONE:0)
Block(-20,-1,-16,DIRT:0)
Block(-20,-1,-15,DIRT:0)
Block(-20,-1,-14,STONE:0)
Block(-20,-1,-13,STONE:0)
Block(-20,-1,-12,DIRT:0)
Block(-20,-1,-11,STONE:0)
Block(-20,-1,-10,DIRT:0)
Block(-20,-1,-9,DIRT:0)
Block(-20,-1,-8,STONE:0)
Block(-20,-1,-7,DIRT:0)
Block(-20,-1,-6,DIRT:0)
Block(-20,-1,-5,STONE:0)
Block(-20,-1,-4,STONE:0)
Block(-20,-1,-3,DIRT:0)
Block(-20,-1,-2,STONE:0)
Block(-20,-1,-1,DIRT:0)
Block(-20,-1,0,STONE:0)
Block(-20,-1,1,DIRT:0)
Block(-20,-1,2,STONE:0)
Block(-20,-1,3,DIRT:0)
Block(-20,-1,4,STONE:0)
Block(-20,-1,5,DIRT:0)
Block(-20,0,-16,STONE:0)
Block(-20,0,-15,DIRT:0)
Block(-20,0,-14,STONE:0)
Block(-20,0,-13,DIRT:0)
Block(-20,0,-12,DIRT:0)
Block(-20,0,-11,DIRT:0)
Block(-20,0,-10,STONE:0)
Block(-20,0,-9,DIRT:0)
Block(-20,0,-8,STONE:0)
Block(-20,0,-7,DIRT:0)
Block(-20,0,-6,DIRT:0)
Block(-20,0,-5,DIRT:0)
Block(-20,0,-4,DIRT:0)
Block(-20,0,-3,STONE:0)
Block(-20,0,-2,STONE:0)
Block(-20,0,-1,STONE:0)
Block(-20,0,0,STONE:0)
Block(-20,0,1,STONE:0)
Block(-20,0,2,STONE:0)
Block(-20,0,3,DIRT:0)
Block(-20,0,4,STONE:0)
Block(-20,0,5,DIRT:0)
Block(-20,0,6,STONE:0)
Block(-20,1,-17,DIRT:0)
Block(-20,1,-16,STONE:0)
Block(-20,1,-15,STONE:0)
Block(-20,1,-14,DIRT:0)
Block(-20,1,-13,STONE:0)
Block(-20,1,-12,STONE:0)
Block(-20,1,-11,DIRT:0)
Block(-20,1,-10,STONE:0)
Block(-20,1,-9,STONE:0)
Block(-20,1,-8,DIRT:0)
Block(-20,1,-7,DIRT:0)
Block(-20,1,-6,DIRT:0)
Block(-20,1,-5,STONE:0)
Block(-20,1,-4,DIRT:0)
Block(-20,1,-3,DIRT:0)
Block(-20,1,-2,DIRT:0)
Block(-20,1,-1,DIRT:0)
Block(-20,1,0,DIRT:0)
Block(-20,1,1,DIRT:0)
Block(-20,1,2,STONE:0)
Block(-20,1,3,STONE:0)
Block(-20,1,4,STONE:0)
Block(-20,1,5,STONE:0)
Block(-20,1,6,STONE:0)
Block(-20,2,-18,DIRT:0)
Block(-20,2,-17,STONE:0)
Block(-20,2,-16,STONE:0)
Block(-20,2,-15,DIRT:0)
Block(-20,2,-14,STONE:0)
Block(-20,2,-13,DIRT:0)
Block(-20,2,-12,STONE:0)
Block(-20,2,-11,DIRT:0)
Block(-20,2,-10,DIRT:0)
Block(-20,2,-9,DIRT:0)
Block(-20,2,-8,DIRT:0)
Block(-20,2,-7,STONE:0)
Block(-20,2,-6,DIRT:0)
Block(-20,2,-5,DIRT:0)
Block(-20,2,-4,STONE:0)
Block(-20,2,-3,STONE:0)
Block(-20,2,-2,DIRT:0)
Block(-20,2,-1,STONE:0)
Block(-20,2,0,STONE:0)
Block(-20,2,1,DIRT:0)
Block(-20,2,2,STONE:0)
Block(-20,2,3,STONE:0)
Block(-20,2,4,STONE:0)
Block(-20,2,5,STONE:0)
Block(-20,2,6,DIRT:0)
Block(-20,2,7,STONE:0)
Block(-20,3,-20,STONE:0)
Block(-20,3,-19,DIRT:0)
Block(-20,3,-18,STONE:0)
Block(-20,3,-17,DIRT:0)
Block(-20,3,-16,DIRT:0)
Block(-20,3,-15,STONE:0)
Block(-20,3,-14,STONE:0)
Block(-20,3,-13,DIRT:0)
Block(-20,3,-12,DIRT:0)
Block(-20,3,-11,STONE:0)
Block(-20,3,-10,DIRT:0)
Block(-20,3,-9,DIRT:0)
Block(-20,3,-8,DIRT:0)
Block(-20,3,-7,DIRT:0)
Block(-20,3,-6,DIRT:0)
Block(-20,3,-5,STONE:0)
Block(-20,3,-4,DIRT:0)
Block(-20,3,-3,STONE:0)
Block(-20,3,-2,STONE:0)
Block(-20,3,-1,STONE:0)
Block(-20,3,0,STONE:0)
Block(-20,3,1,STONE:0)
Block(-20,3,2,DIRT:0)
Block(-20,3,3,DIRT:0)
Block(-20,3,4,STONE:0)
Block(-20,3,5,STONE:0)
Block(-20,3,6,DIRT:0)
Block(-20,3,7,DIRT:0)
Block(-20,4,-21,STONE:0)
Block(-20,4,-20,STONE:0)
Block(-20,4,-19,STONE:0)
Block(-20,4,-18,STONE:0)
Block(-20,4,-17,DIRT:0)
Block(-20,4,-16,STONE:0)
Block(-20,4,-15,STONE:0)
Block(-20,4,-14,STONE:0)
Block(-20,4,-13,DIRT:0)
Block(-20,4,-12,DIRT:0)
Block(-20,4,-11,STONE:0)
Block(-20,4,-10,STONE:0)
Block(-20,4,-9,STONE:0)
Block(-20,4,-8,STONE:0)
Block(-20,4,-7,STONE:0)
Block(-20,4,-6,STONE:0)
Block(-20,4,-5,STONE:0)
Block(-20,4,-4,STONE:0)
Block(-20,4,-3,STONE:0)
Block(-20,4,-2,STONE:0)
Block(-20,4,-1,STONE:0)
Block(-20,4,0,STONE:0)
Block(-20,4,1,STONE:0)
Block(-20,4,2,STONE:0)
Block(-20,4,3,STONE:0)
Block(-20,4,4,STONE:0)
Block(-20,4,5,STONE:0)
Block(-20,4,6,STONE:0)
Block(-20,4,7,STONE:0)
Block(-20,5,-21,STONE:0)
Block(-20,5,-20,STONE:0)
Block(-20,5,-19,STONE:0)
Block(-20,5,-18,STONE:0)
Block(-20,5,-17,STONE:0)
Block(-20,5,-16,DIRT:0)
Block(-20,5,-15,STONE:0)
Block(-20,5,-14,STONE:0)
Block(-20,5,-13,STONE:0)
Block(-20,5,-12,STONE:0)
Block(-20,5,-11,DIRT:0)
Block(-20,5,-10,STONE:0)
Block(-20,5,-9,STONE:0)
Block(-20,5,-8,STONE:0)
Block(-20,5,-7,STONE:0)
Block(-20,5,-6,STONE:0)
Block(-20,5,-5,STONE:0)
Block(-20,5,-4,DIRT:0)
Block(-20,5,-3,STONE:0)
Block(-20,5,-2,STONE:0)
Block(-20,5,-1,STONE:0)
Block(-20,5,0,STONE:0)
Block(-20,5,1,STONE:0)
Block(-20,5,2,STONE:0)
Block(-20,5,3,STONE:0)
Block(-20,5,4,DIRT:0)
Block(-20,5,5,STONE:0)
Block(-20,5,6,STONE:0)
Block(-20,5,7,DIRT:0)
Block(-20,6,-22,DIRT:0)
Block(-20,6,-21,STONE:0)
Block(-20,6,-20,DIRT:0)
Block(-20,6,-19,DIRT:0)
Block(-20,6,-18,STONE:0)
Block(-20,6,-17,STONE:0)
Block(-20,6,-16,STONE:0)
Block(-20,6,-15,STONE:0)
Block(-20,6,-14,STONE:0)
Block(-20,6,-13,STONE:0)
Block(-20,6,-12,STONE:0)
Block(-20,6,-11,STONE:0)
Block(-20,6,-10,STONE:0)
Block(-20,6,-9,STONE:0)
Block(-20,6,-8,STONE:0)
Block(-20,6,-7,DIRT:0)
Block(-20,6,-6,STONE:0)
Block(-20,6,-5,STONE:0)
Block(-20,6,-4,STONE:0)
Block(-20,6,-3,STONE:0)
Block(-20,6,-2,DIRT:0)
Block(-20,6,-1,STONE:0)
Block(-20,6,0,STONE:0)
Block(-20,6,1,STONE:0)
Block(-20,6,2,STONE:0)
Block(-20,6,3,STONE:0)
Block(-20,6,4,STONE:0)
Block(-20,6,5,STONE:0)
Block(-20,6,6,STONE:0)
Block(-20,6,7,STONE:0)
Block(-20,6,8,STONE:0)
Block(-20,7,-22,GRASS:0)
Block(-20,7,-21,STONE:0)
Block(-20,7,-20,DIRT:0)
Block(-20,7,-19,DIRT:0)
Block(-20,7,-18,DIRT:0)
Block(-20,7,-17,DIRT:0)
Block(-20,7,-16,STONE:0)
Block(-20,7,-15,STONE:0)
Block(-20,7,-14,DIRT:0)
Block(-20,7,-13,STONE:0)
Block(-20,7,-12,STONE:0)
Block(-20,7,-11,STONE:0)
Block(-20,7,-10,DIRT:0)
Block(-20,7,-9,STONE:0)
Block(-20,7,-8,STONE:0)
Block(-20,7,-7,STONE:0)
Block(-20,7,-6,STONE:0)
Block(-20,7,-5,STONE:0)
Block(-20,7,-4,STONE:0)
Block(-20,7,-3,STONE:0)
Block(-20,7,-2,STONE:0)
Block(-20,7,-1,STONE:0)
Block(-20,7,0,STONE:0)
Block(-20,7,1,STONE:0)
Block(-20,7,2,STONE:0)
Block(-20,7,3,STONE:0)
Block(-20,7,4,STONE:0)
Block(-20,7,5,DIRT:0)
Block(-20,7,6,STONE:0)
Block(-20,7,7,STONE:0)
Block(-20,7,8,STONE:0)
Block(-20,8,-20,GRASS:0)
Block(-20,8,-19,GRASS:0)
Block(-20,8,-18,GRASS:0)
Block(-20,8,-17,STONE:0)
Block(-20,8,-16,STONE:0)
Block(-20,8,-15,STONE:0)
Block(-20,8,-14,STONE:0)
Block(-20,8,-13,STONE:0)
Block(-20,8,-12,STONE:0)
Block(-20,8,-11,STONE:0)
Block(-20,8,-10,STONE:0)
Block(-20,8,-9,STONE:0)
Block(-20,8,-8,STONE:0)
Block(-20,8,-7,STONE:0)
Block(-20,8,-6,STONE:0)
Block(-20,8,-5,STONE:0)
Block(-20,8,-4,STONE:0)
Block(-20,8,-3,STONE:0)
Block(-20,8,-2,STONE:0)
Block(-20,8,-1,STONE:0)
Block(-20,8,0,STONE:0)
Block(-20,8,1,STONE:0)
Block(-20,8,2,STONE:0)
Block(-20,8,3,STONE:0)
Block(-20,8,4,STONE:0)
Block(-20,8,5,STONE:0)
Block(-20,8,6,STONE:0)
Block(-20,8,7,STONE:0)
Block(-20,8,8,GRASS:0)
Block(-20,9,-20,DOUBLE_PLANT:2)
Block(-20,9,-19,LONG_GRASS:1)
Block(-20,9,-18,LONG_GRASS:1)
Block(-20,9,-17,GRASS:0)
Block(-20,9,-16,GRASS:0)
Block(-20,9,-15,DIRT:0)
Block(-20,9,-14,STONE:0)
Block(-20,9,-13,DIRT:0)
Block(-20,9,-12,STONE:0)
Block(-20,9,-11,STONE:0)
Block(-20,9,-10,STONE:0)
Block(-20,9,-9,STONE:0)
Block(-20,9,-8,STONE:0)
Block(-20,9,-7,STONE:0)
Block(-20,9,-6,STONE:0)
Block(-20,9,-5,STONE:0)
Block(-20,9,-4,STONE:0)
Block(-20,9,-3,STONE:0)
Block(-20,9,-2,STONE:0)
Block(-20,9,-1,STONE:0)
Block(-20,9,0,STONE:0)
Block(-20,9,1,STONE:0)
Block(-20,9,2,DIRT:0)
Block(-20,9,3,STONE:0)
Block(-20,9,4,STONE:0)
Block(-20,9,5,STONE:0)
Block(-20,9,6,STONE:0)
Block(-20,9,7,STONE:0)
Block(-20,10,-20,DOUBLE_PLANT:10)
Block(-20,10,-15,GRASS:0)
Block(-20,10,-14,STONE:0)
Block(-20,10,-13,STONE:0)
Block(-20,10,-12,STONE:0)
Block(-20,10,-11,DIRT:0)
Block(-20,10,-10,STONE:0)
Block(-20,10,-9,STONE:0)
Block(-20,10,-8,STONE:0)
Block(-20,10,-7,STONE:0)
Block(-20,10,-6,STONE:0)
Block(-20,10,-5,STONE:0)
Block(-20,10,-4,DIRT:0)
Block(-20,10,-3,STONE:0)
Block(-20,10,-2,STONE:0)
Block(-20,10,-1,DIRT:0)
Block(-20,10,0,STONE:0)
Block(-20,10,1,DIRT:0)
Block(-20,10,2,STONE:0)
Block(-20,10,3,STONE:0)
Block(-20,10,4,STONE:0)
Block(-20,10,5,DIRT:0)
Block(-20,10,6,STONE:0)
Block(-20,10,7,GRASS:0)
Block(-20,11,-15,YELLOW_FLOWER:0)
Block(-20,11,-14,GRASS:0)
Block(-20,11,-13,STONE:0)
Block(-20,11,-12,DIRT:0)
Block(-20,11,-11,STONE:0)
Block(-20,11,-10,STONE:0)
Block(-20,11,-9,STONE:0)
Block(-20,11,-8,DIRT:0)
Block(-20,11,-7,STONE:0)
Block(-20,11,-6,STONE:0)
Block(-20,11,-5,STONE:0)
Block(-20,11,-4,STONE:0)
Block(-20,11,-3,STONE:0)
Block(-20,11,-2,STONE:0)
Block(-20,11,-1,STONE:0)
Block(-20,11,0,STONE:0)
Block(-20,11,1,STONE:0)
Block(-20,11,2,DIRT:0)
Block(-20,11,3,STONE:0)
Block(-20,11,4,STATIONARY_WATER:0)
Block(-20,11,5,STATIONARY_WATER:0)
Block(-20,11,6,GRASS:0)
Block(-20,11,7,LONG_GRASS:1)
Block(-20,12,-13,GRASS:0)
Block(-20,12,-12,STONE:0)
Block(-20,12,-11,DIRT:0)
Block(-20,12,-10,STONE:0)
Block(-20,12,-9,DIRT:0)
Block(-20,12,-8,STONE:0)
Block(-20,12,-7,STONE:0)
Block(-20,12,-6,STONE:0)
Block(-20,12,-5,STONE:0)
Block(-20,12,-4,STONE:0)
Block(-20,12,-3,STONE:0)
Block(-20,12,-2,STONE:0)
Block(-20,12,-1,DIRT:0)
Block(-20,12,0,DIRT:0)
Block(-20,12,1,STONE:0)
Block(-20,12,2,STONE:0)
Block(-20,12,3,GRASS:0)
Block(-20,13,-12,GRASS:0)
Block(-20,13,-11,STONE:0)
Block(-20,13,-10,DIRT:0)
Block(-20,13,-9,STONE:0)
Block(-20,13,-8,STONE:0)
Block(-20,13,-7,STONE:0)
Block(-20,13,-6,STONE:0)
Block(-20,13,-5,STONE:0)
Block(-20,13,-4,DIRT:0)
Block(-20,13,-3,DIRT:0)
Block(-20,13,-2,DIRT:0)
Block(-20,13,-1,GRASS:0)
Block(-20,13,0,DIRT:0)
Block(-20,13,4,LEAVES:0)
Block(-20,13,5,LEAVES:0)
Block(-20,13,6,LEAVES:0)
Block(-20,13,7,LEAVES:0)
Block(-20,13,8,LEAVES:0)
Block(-20,14,-11,STONE:0)
Block(-20,14,-10,DIRT:0)
Block(-20,14,-9,DIRT:0)
Block(-20,14,-8,DIRT:0)
Block(-20,14,-7,STONE:0)
Block(-20,14,-6,STONE:0)
Block(-20,14,-5,STONE:0)
Block(-20,14,-4,STONE:0)
Block(-20,14,-3,DIRT:0)
Block(-20,14,-2,GRASS:0)
Block(-20,14,-1,LONG_GRASS:1)
Block(-20,14,0,LOG:0)
Block(-20,14,4,LEAVES:0)
Block(-20,14,5,LEAVES:0)
Block(-20,14,6,LEAVES:0)
Block(-20,14,7,LEAVES:0)
Block(-20,14,8,LEAVES:0)
Block(-20,15,-11,GRASS:0)
Block(-20,15,-10,STONE:0)
Block(-20,15,-9,DIRT:0)
Block(-20,15,-8,DIRT:0)
Block(-20,15,-7,DIRT:0)
Block(-20,15,-6,DIRT:0)
Block(-20,15,-5,STONE:0)
Block(-20,15,-4,DIRT:0)
Block(-20,15,-3,GRASS:0)
Block(-20,15,-2,LEAVES:0)
Block(-20,15,-1,LEAVES:0)
Block(-20,15,0,LOG:0)
Block(-20,15,1,LEAVES:0)
Block(-20,15,2,LEAVES:0)
Block(-20,15,5,LEAVES:0)
Block(-20,15,6,LEAVES:0)
Block(-20,15,7,LEAVES:0)
Block(-20,15,8,LEAVES:0)
Block(-20,16,-10,GRASS:0)
Block(-20,16,-9,STONE:0)
Block(-20,16,-8,STONE:0)
Block(-20,16,-7,STONE:0)
Block(-20,16,-6,DIRT:0)
Block(-20,16,-5,GRASS:0)
Block(-20,16,-4,GRASS:0)
Block(-20,16,-2,LEAVES:0)
Block(-20,16,-1,LEAVES:0)
Block(-20,16,0,LOG:0)
Block(-20,16,1,LEAVES:0)
Block(-20,16,2,LEAVES:0)
Block(-20,17,-10,LONG_GRASS:1)
Block(-20,17,-9,GRASS:0)
Block(-20,17,-8,GRASS:0)
Block(-20,17,-7,GRASS:0)
Block(-20,17,-6,GRASS:0)
Block(-20,17,-5,LONG_GRASS:1)
Block(-20,17,-2,LEAVES:0)
Block(-20,17,-1,LEAVES:0)
Block(-20,17,0,LOG:0)
Block(-20,17,1,LEAVES:0)
Block(-20,17,2,LEAVES:0)
Block(-20,18,-9,LONG_GRASS:1)
Block(-20,18,-2,LEAVES:0)
Block(-20,18,-1,LEAVES:0)
Block(-20,18,0,LOG:0)
Block(-20,18,1,LEAVES:0)
Block(-20,18,2,LEAVES:0)
Block(-20,19,-1,LEAVES:0)
Block(-20,19,0,LOG:0)
Block(-20,19,1,LEAVES:0)
Block(-20,20,-1,LEAVES:0)
Block(-20,20,0,LEAVES:0)
Block(-20,20,1,LEAVES:0)
Block(-19,-20,-6,DIRT:0)
Block(-19,-20,-5,STONE:0)
Block(-19,-19,-7,STONE:0)
Block(-19,-19,-6,STONE:0)
Block(-19,-19,-5,STONE:0)
Block(-19,-19,-4,STONE:0)
Block(-19,-18,-7,STONE:0)
Block(-19,-18,-6,STONE:0)
Block(-19,-18,-5,STONE:0)
Block(-19,-18,-4,STONE:0)
Block(-19,-17,-10,STONE:0)
Block(-19,-17,-9,STONE:0)
Block(-19,-17,-8,STONE:0)
Block(-19,-17,-7,STONE:0)
Block(-19,-17,-6,DIRT:0)
Block(-19,-17,-5,DIRT:0)
Block(-19,-17,-4,STONE:0)
Block(-19,-17,-3,STONE:0)
Block(-19,-16,-10,STONE:0)
Block(-19,-16,-9,STONE:0)
Block(-19,-16,-8,DIRT:0)
Block(-19,-16,-7,STONE:0)
Block(-19,-16,-6,STONE:0)
Block(-19,-16,-5,STONE:0)
Block(-19,-16,-4,DIRT:0)
Block(-19,-16,-3,STONE:0)
Block(-19,-16,-2,STONE:0)
Block(-19,-16,-1,STONE:0)
Block(-19,-15,-10,STONE:0)
Block(-19,-15,-9,STONE:0)
Block(-19,-15,-8,STONE:0)
Block(-19,-15,-7,DIRT:0)
Block(-19,-15,-6,STONE:0)
Block(-19,-15,-5,STONE:0)
Block(-19,-15,-4,STONE:0)
Block(-19,-15,-3,STONE:0)
Block(-19,-15,-2,STONE:0)
Block(-19,-15,-1,DIRT:0)
Block(-19,-15,0,STONE:0)
Block(-19,-14,-11,STONE:0)
Block(-19,-14,-10,STONE:0)
Block(-19,-14,-9,STONE:0)
Block(-19,-14,-8,STONE:0)
Block(-19,-14,-7,STONE:0)
Block(-19,-14,-6,STONE:0)
Block(-19,-14,-5,STONE:0)
Block(-19,-14,-4,DIRT:0)
Block(-19,-14,-3,STONE:0)
Block(-19,-14,-2,STONE:0)
Block(-19,-14,-1,STONE:0)
Block(-19,-14,0,STONE:0)
Block(-19,-13,-11,STONE:0)
Block(-19,-13,-10,STONE:0)
Block(-19,-13,-9,STONE:0)
Block(-19,-13,-8,STONE:0)
Block(-19,-13,-7,STONE:0)
Block(-19,-13,-6,STONE:0)
Block(-19,-13,-5,STONE:0)
Block(-19,-13,-4,STONE:0)
Block(-19,-13,-3,STONE:0)
Block(-19,-13,-2,STONE:0)
Block(-19,-13,-1,STONE:0)
Block(-19,-13,0,STONE:0)
Block(-19,-13,1,STONE:0)
Block(-19,-12,-12,STONE:0)
Block(-19,-12,-11,DIRT:0)
Block(-19,-12,-10,STONE:0)
Block(-19,-12,-9,STONE:0)
Block(-19,-12,-8,STONE:0)
Block(-19,-12,-7,STONE:0)
Block(-19,-12,-6,STONE:0)
Block(-19,-12,-5,STONE:0)
Block(-19,-12,-4,STONE:0)
Block(-19,-12,-3,DIRT:0)
Block(-19,-12,-2,STONE:0)
Block(-19,-12,-1,STONE:0)
Block(-19,-12,0,STONE:0)
Block(-19,-12,1,STONE:0)
Block(-19,-12,2,STONE:0)
Block(-19,-11,-12,STONE:0)
Block(-19,-11,-11,STONE:0)
Block(-19,-11,-10,STONE:0)
Block(-19,-11,-9,STONE:0)
Block(-19,-11,-8,STONE:0)
Block(-19,-11,-7,DIRT:0)
Block(-19,-11,-6,STONE:0)
Block(-19,-11,-5,STONE:0)
Block(-19,-11,-4,DIRT:0)
Block(-19,-11,-3,STONE:0)
Block(-19,-11,-2,STONE:0)
Block(-19,-11,-1,STONE:0)
Block(-19,-11,0,STONE:0)
Block(-19,-11,1,STONE:0)
Block(-19,-11,2,STONE:0)
Block(-19,-10,-13,STONE:0)
Block(-19,-10,-12,STONE:0)
Block(-19,-10,-11,STONE:0)
Block(-19,-10,-10,STONE:0)
Block(-19,-10,-9,STONE:0)
Block(-19,-10,-8,STONE:0)
Block(-19,-10,-7,STONE:0)
Block(-19,-10,-6,STONE:0)
Block(-19,-10,-5,STONE:0)
Block(-19,-10,-4,DIRT:0)
Block(-19,-10,-3,DIRT:0)
Block(-19,-10,-2,STONE:0)
Block(-19,-10,-1,STONE:0)
Block(-19,-10,0,STONE:0)
Block(-19,-10,1,STONE:0)
Block(-19,-10,2,STONE:0)
Block(-19,-9,-13,STONE:0)
Block(-19,-9,-12,STONE:0)
Block(-19,-9,-11,STONE:0)
Block(-19,-9,-10,STONE:0)
Block(-19,-9,-9,STONE:0)
Block(-19,-9,-8,STONE:0)
Block(-19,-9,-7,STONE:0)
Block(-19,-9,-6,STONE:0)
Block(-19,-9,-5,STONE:0)
Block(-19,-9,-4,STONE:0)
Block(-19,-9,-3,STONE:0)
Block(-19,-9,-2,DIRT:0)
Block(-19,-9,-1,STONE:0)
Block(-19,-9,0,STONE:0)
Block(-19,-9,1,STONE:0)
Block(-19,-9,2,DIRT:0)
Block(-19,-9,3,STONE:0)
Block(-19,-8,-14,DIRT:0)
Block(-19,-8,-13,DIRT:0)
Block(-19,-8,-12,DIRT:0)
Block(-19,-8,-11,DIRT:0)
Block(-19,-8,-10,STONE:0)
Block(-19,-8,-9,STONE:0)
Block(-19,-8,-8,STONE:0)
Block(-19,-8,-7,DIRT:0)
Block(-19,-8,-6,DIRT:0)
Block(-19,-8,-5,STONE:0)
Block(-19,-8,-4,STONE:0)
Block(-19,-8,-3,STONE:0)
Block(-19,-8,-2,STONE:0)
Block(-19,-8,-1,DIRT:0)
Block(-19,-8,0,STONE:0)
Block(-19,-8,1,STONE:0)
Block(-19,-8,2,DIRT:0)
Block(-19,-8,3,STONE:0)
Block(-19,-7,-15,STONE:0)
Block(-19,-7,-14,DIRT:0)
Block(-19,-7,-13,DIRT:0)
Block(-19,-7,-12,STONE:0)
Block(-19,-7,-11,STONE:0)
Block(-19,-7,-10,STONE:0)
Block(-19,-7,-9,DIRT:0)
Block(-19,-7,-8,STONE:0)
Block(-19,-7,-7,STONE:0)
Block(-19,-7,-6,STONE:0)
Block(-19,-7,-5,STONE:0)
Block(-19,-7,-4,STONE:0)
Block(-19,-7,-3,STONE:0)
Block(-19,-7,-2,STONE:0)
Block(-19,-7,-1,DIRT:0)
Block(-19,-7,0,STONE:0)
Block(-19,-7,1,STONE:0)
Block(-19,-7,2,STONE:0)
Block(-19,-7,3,STONE:0)
Block(-19,-6,-15,STONE:0)
Block(-19,-6,-14,STONE:0)
Block(-19,-6,-13,STONE:0)
Block(-19,-6,-12,STONE:0)
Block(-19,-6,-11,STONE:0)
Block(-19,-6,-10,STONE:0)
Block(-19,-6,-9,STONE:0)
Block(-19,-6,-8,STONE:0)
Block(-19,-6,-7,STONE:0)
Block(-19,-6,-6,STONE:0)
Block(-19,-6,-5,DIRT:0)
Block(-19,-6,-4,STONE:0)
Block(-19,-6,-3,STONE:0)
Block(-19,-6,-2,STONE:0)
Block(-19,-6,-1,STONE:0)
Block(-19,-6,0,STONE:0)
Block(-19,-6,1,STONE:0)
Block(-19,-6,2,STONE:0)
Block(-19,-6,3,STONE:0)
Block(-19,-5,-15,STONE:0)
Block(-19,-5,-14,DIRT:0)
Block(-19,-5,-13,STONE:0)
Block(-19,-5,-12,DIRT:0)
Block(-19,-5,-11,STONE:0)
Block(-19,-5,-10,STONE:0)
Block(-19,-5,-9,STONE:0)
Block(-19,-5,-8,STONE:0)
Block(-19,-5,-7,STONE:0)
Block(-19,-5,-6,DIRT:0)
Block(-19,-5,-5,STONE:0)
Block(-19,-5,-4,DIRT:0)
Block(-19,-5,-3,STONE:0)
Block(-19,-5,-2,STONE:0)
Block(-19,-5,-1,STONE:0)
Block(-19,-5,0,STONE:0)
Block(-19,-5,1,STONE:0)
Block(-19,-5,2,DIRT:0)
Block(-19,-5,3,DIRT:0)
Block(-19,-5,4,STONE:0)
Block(-19,-4,-16,STONE:0)
Block(-19,-4,-15,STONE:0)
Block(-19,-4,-14,STONE:0)
Block(-19,-4,-13,DIRT:0)
Block(-19,-4,-12,DIRT:0)
Block(-19,-4,-11,DIRT:0)
Block(-19,-4,-10,DIRT:0)
Block(-19,-4,-9,STONE:0)
Block(-19,-4,-8,STONE:0)
Block(-19,-4,-7,DIRT:0)
Block(-19,-4,-6,STONE:0)
Block(-19,-4,-5,STONE:0)
Block(-19,-4,-4,DIRT:0)
Block(-19,-4,-3,DIRT:0)
Block(-19,-4,-2,STONE:0)
Block(-19,-4,-1,DIRT:0)
Block(-19,-4,0,STONE:0)
Block(-19,-4,1,STONE:0)
Block(-19,-4,2,STONE:0)
Block(-19,-4,3,DIRT:0)
Block(-19,-4,4,STONE:0)
Block(-19,-4,5,STONE:0)
Block(-19,-3,-16,STONE:0)
Block(-19,-3,-15,DIRT:0)
Block(-19,-3,-14,DIRT:0)
Block(-19,-3,-13,STONE:0)
Block(-19,-3,-12,DIRT:0)
Block(-19,-3,-11,DIRT:0)
Block(-19,-3,-10,STONE:0)
Block(-19,-3,-9,DIRT:0)
Block(-19,-3,-8,DIRT:0)
Block(-19,-3,-7,STONE:0)
Block(-19,-3,-6,STONE:0)
Block(-19,-3,-5,DIRT:0)
Block(-19,-3,-4,DIRT:0)
Block(-19,-3,-3,STONE:0)
Block(-19,-3,-2,DIRT:0)
Block(-19,-3,-1,DIRT:0)
Block(-19,-3,0,DIRT:0)
Block(-19,-3,1,STONE:0)
Block(-19,-3,2,STONE:0)
Block(-19,-3,3,STONE:0)
Block(-19,-3,4,STONE:0)
Block(-19,-3,5,DIRT:0)
Block(-19,-2,-16,DIRT:0)
Block(-19,-2,-15,DIRT:0)
Block(-19,-2,-14,STONE:0)
Block(-19,-2,-13,DIRT:0)
Block(-19,-2,-12,STONE:0)
Block(-19,-2,-11,STONE:0)
Block(-19,-2,-10,STONE:0)
Block(-19,-2,-9,DIRT:0)
Block(-19,-2,-8,STONE:0)
Block(-19,-2,-7,DIRT:0)
Block(-19,-2,-6,STONE:0)
Block(-19,-2,-5,STONE:0)
Block(-19,-2,-4,DIRT:0)
Block(-19,-2,-3,DIRT:0)
Block(-19,-2,-2,DIRT:0)
Block(-19,-2,-1,DIRT:0)
Block(-19,-2,0,STONE:0)
Block(-19,-2,1,STONE:0)
Block(-19,-2,2,DIRT:0)
Block(-19,-2,3,DIRT:0)
Block(-19,-2,4,DIRT:0)
Block(-19,-2,5,DIRT:0)
Block(-19,-1,-17,DIRT:0)
Block(-19,-1,-16,STONE:0)
Block(-19,-1,-15,DIRT:0)
Block(-19,-1,-14,STONE:0)
Block(-19,-1,-13,DIRT:0)
Block(-19,-1,-12,STONE:0)
Block(-19,-1,-11,STONE:0)
Block(-19,-1,-10,DIRT:0)
Block(-19,-1,-9,STONE:0)
Block(-19,-1,-8,DIRT:0)
Block(-19,-1,-7,DIRT:0)
Block(-19,-1,-6,DIRT:0)
Block(-19,-1,-5,DIRT:0)
Block(-19,-1,-4,DIRT:0)
Block(-19,-1,-3,STONE:0)
Block(-19,-1,-2,DIRT:0)
Block(-19,-1,-1,DIRT:0)
Block(-19,-1,0,STONE:0)
Block(-19,-1,1,DIRT:0)
Block(-19,-1,2,STONE:0)
Block(-19,-1,3,STONE:0)
Block(-19,-1,4,STONE:0)
Block(-19,-1,5,DIRT:0)
Block(-19,-1,6,STONE:0)
Block(-19,0,-17,STONE:0)
Block(-19,0,-16,STONE:0)
Block(-19,0,-15,DIRT:0)
Block(-19,0,-14,STONE:0)
Block(-19,0,-13,DIRT:0)
Block(-19,0,-12,DIRT:0)
Block(-19,0,-11,STONE:0)
Block(-19,0,-10,STONE:0)
Block(-19,0,-9,STONE:0)
Block(-19,0,-8,DIRT:0)
Block(-19,0,-7,DIRT:0)
Block(-19,0,-6,DIRT:0)
Block(-19,0,-5,DIRT:0)
Block(-19,0,-4,STONE:0)
Block(-19,0,-3,DIRT:0)
Block(-19,0,-2,DIRT:0)
Block(-19,0,-1,DIRT:0)
Block(-19,0,0,STONE:0)
Block(-19,0,1,DIRT:0)
Block(-19,0,2,DIRT:0)
Block(-19,0,3,DIRT:0)
Block(-19,0,4,DIRT:0)
Block(-19,0,5,DIRT:0)
Block(-19,0,6,DIRT:0)
Block(-19,1,-18,DIRT:0)
Block(-19,1,-17,STONE:0)
Block(-19,1,-16,DIRT:0)
Block(-19,1,-15,DIRT:0)
Block(-19,1,-14,DIRT:0)
Block(-19,1,-13,STONE:0)
Block(-19,1,-12,STONE:0)
Block(-19,1,-11,STONE:0)
Block(-19,1,-10,DIRT:0)
Block(-19,1,-9,STONE:0)
Block(-19,1,-8,STONE:0)
Block(-19,1,-7,DIRT:0)
Block(-19,1,-6,STONE:0)
Block(-19,1,-5,DIRT:0)
Block(-19,1,-4,STONE:0)
Block(-19,1,-3,DIRT:0)
Block(-19,1,-2,STONE:0)
Block(-19,1,-1,STONE:0)
Block(-19,1,0,DIRT:0)
Block(-19,1,1,STONE:0)
Block(-19,1,2,STONE:0)
Block(-19,1,3,STONE:0)
Block(-19,1,4,DIRT:0)
Block(-19,1,5,DIRT:0)
Block(-19,1,6,STONE:0)
Block(-19,1,7,STONE:0)
Block(-19,2,-19,DIRT:0)
Block(-19,2,-18,STONE:0)
Block(-19,2,-17,STONE:0)
Block(-19,2,-16,DIRT:0)
Block(-19,2,-15,STONE:0)
Block(-19,2,-14,DIRT:0)
Block(-19,2,-13,STONE:0)
Block(-19,2,-12,STONE:0)
Block(-19,2,-11,STONE:0)
Block(-19,2,-10,DIRT:0)
Block(-19,2,-9,STONE:0)
Block(-19,2,-8,DIRT:0)
Block(-19,2,-7,STONE:0)
Block(-19,2,-6,STONE:0)
Block(-19,2,-5,DIRT:0)
Block(-19,2,-4,STONE:0)
Block(-19,2,-3,DIRT:0)
Block(-19,2,-2,DIRT:0)
Block(-19,2,-1,DIRT:0)
Block(-19,2,0,STONE:0)
Block(-19,2,1,STONE:0)
Block(-19,2,2,STONE:0)
Block(-19,2,3,DIRT:0)
Block(-19,2,4,STONE:0)
Block(-19,2,5,DIRT:0)
Block(-19,2,6,STONE:0)
Block(-19,2,7,DIRT:0)
Block(-19,3,-21,STONE:0)
Block(-19,3,-20,STONE:0)
Block(-19,3,-19,STONE:0)
Block(-19,3,-18,STONE:0)
Block(-19,3,-17,STONE:0)
Block(-19,3,-16,STONE:0)
Block(-19,3,-15,DIRT:0)
Block(-19,3,-14,STONE:0)
Block(-19,3,-13,STONE:0)
Block(-19,3,-12,DIRT:0)
Block(-19,3,-11,DIRT:0)
Block(-19,3,-10,DIRT:0)
Block(-19,3,-9,DIRT:0)
Block(-19,3,-8,DIRT:0)
Block(-19,3,-7,DIRT:0)
Block(-19,3,-6,DIRT:0)
Block(-19,3,-5,STONE:0)
Block(-19,3,-4,DIRT:0)
Block(-19,3,-3,STONE:0)
Block(-19,3,-2,DIRT:0)
Block(-19,3,-1,STONE:0)
Block(-19,3,0,STONE:0)
Block(-19,3,1,DIRT:0)
Block(-19,3,2,DIRT:0)
Block(-19,3,3,DIRT:0)
Block(-19,3,4,DIRT:0)
Block(-19,3,5,STONE:0)
Block(-19,3,6,DIRT:0)
Block(-19,3,7,STONE:0)
Block(-19,4,-22,STONE:0)
Block(-19,4,-21,STONE:0)
Block(-19,4,-20,STONE:0)
Block(-19,4,-19,STONE:0)
Block(-19,4,-18,STONE:0)
Block(-19,4,-17,STONE:0)
Block(-19,4,-16,DIRT:0)
Block(-19,4,-15,STONE:0)
Block(-19,4,-14,STONE:0)
Block(-19,4,-13,STONE:0)
Block(-19,4,-12,STONE:0)
Block(-19,4,-11,DIRT:0)
Block(-19,4,-10,STONE:0)
Block(-19,4,-9,STONE:0)
Block(-19,4,-8,STONE:0)
Block(-19,4,-7,STONE:0)
Block(-19,4,-6,DIRT:0)
Block(-19,4,-5,STONE:0)
Block(-19,4,-4,STONE:0)
Block(-19,4,-3,STONE:0)
Block(-19,4,-2,STONE:0)
Block(-19,4,-1,STONE:0)
Block(-19,4,0,STONE:0)
Block(-19,4,1,DIRT:0)
Block(-19,4,2,STONE:0)
Block(-19,4,3,DIRT:0)
Block(-19,4,4,DIRT:0)
Block(-19,4,5,STONE:0)
Block(-19,4,6,STONE:0)
Block(-19,4,7,STONE:0)
Block(-19,5,-23,STONE:0)
Block(-19,5,-22,STONE:0)
Block(-19,5,-21,STONE:0)
Block(-19,5,-20,STONE:0)
Block(-19,5,-19,DIRT:0)
Block(-19,5,-18,DIRT:0)
Block(-19,5,-17,STONE:0)
Block(-19,5,-16,STONE:0)
Block(-19,5,-15,STONE:0)
Block(-19,5,-14,STONE:0)
Block(-19,5,-13,STONE:0)
Block(-19,5,-12,STONE:0)
Block(-19,5,-11,STONE:0)
Block(-19,5,-10,STONE:0)
Block(-19,5,-9,STONE:0)
Block(-19,5,-8,STONE:0)
Block(-19,5,-7,STONE:0)
Block(-19,5,-6,STONE:0)
Block(-19,5,-5,STONE:0)
Block(-19,5,-4,STONE:0)
Block(-19,5,-3,STONE:0)
Block(-19,5,-2,DIRT:0)
Block(-19,5,-1,STONE:0)
Block(-19,5,0,STONE:0)
Block(-19,5,1,STONE:0)
Block(-19,5,2,DIRT:0)
Block(-19,5,3,STONE:0)
Block(-19,5,4,STONE:0)
Block(-19,5,5,STONE:0)
Block(-19,5,6,STONE:0)
Block(-19,5,7,STONE:0)
Block(-19,5,8,DIRT:0)
Block(-19,6,-23,GRASS:0)
Block(-19,6,-22,STONE:0)
Block(-19,6,-21,DIRT:0)
Block(-19,6,-20,STONE:0)
Block(-19,6,-19,STONE:0)
Block(-19,6,-18,STONE:0)
Block(-19,6,-17,STONE:0)
Block(-19,6,-16,DIRT:0)
Block(-19,6,-15,STONE:0)
Block(-19,6,-14,STONE:0)
Block(-19,6,-13,STONE:0)
Block(-19,6,-12,STONE:0)
Block(-19,6,-11,STONE:0)
Block(-19,6,-10,STONE:0)
Block(-19,6,-9,STONE:0)
Block(-19,6,-8,STONE:0)
Block(-19,6,-7,STONE:0)
Block(-19,6,-6,STONE:0)
Block(-19,6,-5,STONE:0)
Block(-19,6,-4,STONE:0)
Block(-19,6,-3,STONE:0)
Block(-19,6,-2,DIRT:0)
Block(-19,6,-1,STONE:0)
Block(-19,6,0,STONE:0)
Block(-19,6,1,STONE:0)
Block(-19,6,2,DIRT:0)
Block(-19,6,3,STONE:0)
Block(-19,6,4,STONE:0)
Block(-19,6,5,STONE:0)
Block(-19,6,6,DIRT:0)
Block(-19,6,7,STONE:0)
Block(-19,6,8,DIRT:0)
Block(-19,7,-22,GRASS:0)
Block(-19,7,-21,GRASS:0)
Block(-19,7,-20,STONE:0)
Block(-19,7,-19,DIRT:0)
Block(-19,7,-18,DIRT:0)
Block(-19,7,-17,STONE:0)
Block(-19,7,-16,STONE:0)
Block(-19,7,-15,STONE:0)
Block(-19,7,-14,STONE:0)
Block(-19,7,-13,STONE:0)
Block(-19,7,-12,STONE:0)
Block(-19,7,-11,STONE:0)
Block(-19,7,-10,DIRT:0)
Block(-19,7,-9,STONE:0)
Block(-19,7,-8,STONE:0)
Block(-19,7,-7,STONE:0)
Block(-19,7,-6,STONE:0)
Block(-19,7,-5,STONE:0)
Block(-19,7,-4,STONE:0)
Block(-19,7,-3,STONE:0)
Block(-19,7,-2,STONE:0)
Block(-19,7,-1,STONE:0)
Block(-19,7,0,STONE:0)
Block(-19,7,1,STONE:0)
Block(-19,7,2,DIRT:0)
Block(-19,7,3,STONE:0)
Block(-19,7,4,DIRT:0)
Block(-19,7,5,STONE:0)
Block(-19,7,6,STONE:0)
Block(-19,7,7,STONE:0)
Block(-19,7,8,STONE:0)
Block(-19,8,-20,GRASS:0)
Block(-19,8,-19,GRASS:0)
Block(-19,8,-18,DIRT:0)
Block(-19,8,-17,STONE:0)
Block(-19,8,-16,STONE:0)
Block(-19,8,-15,STONE:0)
Block(-19,8,-14,STONE:0)
Block(-19,8,-13,STONE:0)
Block(-19,8,-12,STONE:0)
Block(-19,8,-11,STONE:0)
Block(-19,8,-10,DIRT:0)
Block(-19,8,-9,STONE:0)
Block(-19,8,-8,STONE:0)
Block(-19,8,-7,STONE:0)
Block(-19,8,-6,STONE:0)
Block(-19,8,-5,STONE:0)
Block(-19,8,-4,STONE:0)
Block(-19,8,-3,STONE:0)
Block(-19,8,-2,STONE:0)
Block(-19,8,-1,STONE:0)
Block(-19,8,0,STONE:0)
Block(-19,8,1,STONE:0)
Block(-19,8,2,STONE:0)
Block(-19,8,3,STONE:0)
Block(-19,8,4,STONE:0)
Block(-19,8,5,STONE:0)
Block(-19,8,6,STONE:0)
Block(-19,8,7,DIRT:0)
Block(-19,8,8,STONE:0)
Block(-19,9,-20,LONG_GRASS:1)
Block(-19,9,-19,LONG_GRASS:1)
Block(-19,9,-18,GRASS:0)
Block(-19,9,-17,GRASS:0)
Block(-19,9,-16,STONE:0)
Block(-19,9,-15,STONE:0)
Block(-19,9,-14,STONE:0)
Block(-19,9,-13,STONE:0)
Block(-19,9,-12,STONE:0)
Block(-19,9,-11,STONE:0)
Block(-19,9,-10,STONE:0)
Block(-19,9,-9,STONE:0)
Block(-19,9,-8,STONE:0)
Block(-19,9,-7,STONE:0)
Block(-19,9,-6,STONE:0)
Block(-19,9,-5,STONE:0)
Block(-19,9,-4,STONE:0)
Block(-19,9,-3,DIRT:0)
Block(-19,9,-2,STONE:0)
Block(-19,9,-1,STONE:0)
Block(-19,9,0,STONE:0)
Block(-19,9,1,STONE:0)
Block(-19,9,2,STONE:0)
Block(-19,9,3,STONE:0)
Block(-19,9,4,DIRT:0)
Block(-19,9,5,STONE:0)
Block(-19,9,6,STONE:0)
Block(-19,9,7,DIRT:0)
Block(-19,9,8,GRASS:0)
Block(-19,10,-16,GRASS:0)
Block(-19,10,-15,STONE:0)
Block(-19,10,-14,STONE:0)
Block(-19,10,-13,DIRT:0)
Block(-19,10,-12,STONE:0)
Block(-19,10,-11,STONE:0)
Block(-19,10,-10,STONE:0)
Block(-19,10,-9,STONE:0)
Block(-19,10,-8,STONE:0)
Block(-19,10,-7,STONE:0)
Block(-19,10,-6,STONE:0)
Block(-19,10,-5,STONE:0)
Block(-19,10,-4,STONE:0)
Block(-19,10,-3,STONE:0)
Block(-19,10,-2,STONE:0)
Block(-19,10,-1,STONE:0)
Block(-19,10,0,STONE:0)
Block(-19,10,1,DIRT:0)
Block(-19,10,2,DIRT:0)
Block(-19,10,3,STONE:0)
Block(-19,10,4,STONE:0)
Block(-19,10,5,STONE:0)
Block(-19,10,6,STONE:0)
Block(-19,10,7,GRASS:0)
Block(-19,10,8,YELLOW_FLOWER:0)
Block(-19,11,-15,GRASS:0)
Block(-19,11,-14,STONE:0)
Block(-19,11,-13,STONE:0)
Block(-19,11,-12,STONE:0)
Block(-19,11,-11,STONE:0)
Block(-19,11,-10,STONE:0)
Block(-19,11,-9,STONE:0)
Block(-19,11,-8,STONE:0)
Block(-19,11,-7,STONE:0)
Block(-19,11,-6,STONE:0)
Block(-19,11,-5,STONE:0)
Block(-19,11,-4,STONE:0)
Block(-19,11,-3,STONE:0)
Block(-19,11,-2,STONE:0)
Block(-19,11,-1,STONE:0)
Block(-19,11,0,STONE:0)
Block(-19,11,1,STONE:0)
Block(-19,11,2,STONE:0)
Block(-19,11,3,STONE:0)
Block(-19,11,4,STONE:0)
Block(-19,11,5,STONE:0)
Block(-19,11,6,GRASS:0)
Block(-19,11,7,LONG_GRASS:1)
Block(-19,12,-15,LONG_GRASS:1)
Block(-19,12,-14,GRASS:0)
Block(-19,12,-13,DIRT:0)
Block(-19,12,-12,DIRT:0)
Block(-19,12,-11,STONE:0)
Block(-19,12,-10,STONE:0)
Block(-19,12,-9,STONE:0)
Block(-19,12,-8,STONE:0)
Block(-19,12,-7,STONE:0)
Block(-19,12,-6,STONE:0)
Block(-19,12,-5,STONE:0)
Block(-19,12,-4,STONE:0)
Block(-19,12,-3,STONE:0)
Block(-19,12,-2,STONE:0)
Block(-19,12,-1,STONE:0)
Block(-19,12,0,DIRT:0)
Block(-19,12,1,DIRT:0)
Block(-19,12,2,GRASS:0)
Block(-19,12,3,GRASS:0)
Block(-19,13,-14,LONG_GRASS:1)
Block(-19,13,-13,GRASS:0)
Block(-19,13,-12,STONE:0)
Block(-19,13,-11,STONE:0)
Block(-19,13,-10,STONE:0)
Block(-19,13,-9,STONE:0)
Block(-19,13,-8,STONE:0)
Block(-19,13,-7,STONE:0)
Block(-19,13,-6,STONE:0)
Block(-19,13,-5,STONE:0)
Block(-19,13,-4,DIRT:0)
Block(-19,13,-3,STONE:0)
Block(-19,13,-2,DIRT:0)
Block(-19,13,-1,STONE:0)
Block(-19,13,0,GRASS:0)
Block(-19,13,1,GRASS:0)
Block(-19,13,4,LEAVES:0)
Block(-19,13,5,LEAVES:0)
Block(-19,13,6,LEAVES:0)
Block(-19,13,7,LEAVES:0)
Block(-19,13,8,LEAVES:0)
Block(-19,14,-12,STONE:0)
Block(-19,14,-11,STONE:0)
Block(-19,14,-10,DIRT:0)
Block(-19,14,-9,STONE:0)
Block(-19,14,-8,STONE:0)
Block(-19,14,-7,STONE:0)
Block(-19,14,-6,STONE:0)
Block(-19,14,-5,DIRT:0)
Block(-19,14,-4,DIRT:0)
Block(-19,14,-3,STONE:0)
Block(-19,14,-2,STONE:0)
Block(-19,14,-1,STONE:0)
Block(-19,14,0,LONG_GRASS:1)
Block(-19,14,1,LONG_GRASS:1)
Block(-19,14,4,LEAVES:0)
Block(-19,14,5,LEAVES:0)
Block(-19,14,6,LEAVES:0)
Block(-19,14,7,LEAVES:0)
Block(-19,14,8,LEAVES:0)
Block(-19,15,-12,GRASS:0)
Block(-19,15,-11,STONE:0)
Block(-19,15,-10,STONE:0)
Block(-19,15,-9,STONE:0)
Block(-19,15,-8,STONE:0)
Block(-19,15,-7,DIRT:0)
Block(-19,15,-6,STONE:0)
Block(-19,15,-5,STONE:0)
Block(-19,15,-4,STONE:0)
Block(-19,15,-3,GRASS:0)
Block(-19,15,-2,STONE:0)
Block(-19,15,-1,LEAVES:0)
Block(-19,15,0,LEAVES:0)
Block(-19,15,1,LEAVES:0)
Block(-19,15,2,LEAVES:0)
Block(-19,15,4,LEAVES:0)
Block(-19,15,5,LEAVES:0)
Block(-19,15,6,LEAVES:0)
Block(-19,15,7,LEAVES:0)
Block(-19,15,8,LEAVES:0)
Block(-19,16,-11,STONE:0)
Block(-19,16,-10,STONE:0)
Block(-19,16,-9,STONE:0)
Block(-19,16,-8,STONE:0)
Block(-19,16,-7,STONE:0)
Block(-19,16,-6,STONE:0)
Block(-19,16,-5,STONE:0)
Block(-19,16,-4,GRASS:0)
Block(-19,16,-2,LEAVES:0)
Block(-19,16,-1,LEAVES:0)
Block(-19,16,0,LEAVES:0)
Block(-19,16,1,LEAVES:0)
Block(-19,16,2,LEAVES:0)
Block(-19,16,5,LEAVES:0)
Block(-19,16,6,LEAVES:0)
Block(-19,16,7,LEAVES:0)
Block(-19,17,-11,GRASS:0)
Block(-19,17,-10,STONE:0)
Block(-19,17,-9,DIRT:0)
Block(-19,17,-8,DIRT:0)
Block(-19,17,-7,STONE:0)
Block(-19,17,-6,STONE:0)
Block(-19,17,-5,GRASS:0)
Block(-19,17,-4,LONG_GRASS:1)
Block(-19,17,-2,LEAVES:0)
Block(-19,17,-1,LEAVES:0)
Block(-19,17,0,LEAVES:0)
Block(-19,17,1,LEAVES:0)
Block(-19,17,2,LEAVES:0)
Block(-19,17,6,LEAVES:0)
Block(-19,18,-10,GRASS:0)
Block(-19,18,-9,GRASS:0)
Block(-19,18,-8,GRASS:0)
Block(-19,18,-7,GRASS:0)
Block(-19,18,-6,GRASS:0)
Block(-19,18,-2,LEAVES:0)
Block(-19,18,-1,LEAVES:0)
Block(-19,18,0,LEAVES:0)
Block(-19,18,1,LEAVES:0)
Block(-19,18,2,LEAVES:0)
Block(-19,19,-7,LONG_GRASS:1)
Block(-19,19,-1,LEAVES:0)
Block(-19,19,0,LEAVES:0)
Block(-19,19,1,LEAVES:0)
Block(-19,20,0,LEAVES:0)
Block(-18,-22,-7,STONE:0)
Block(-18,-22,-6,STONE:0)
Block(-18,-21,-8,DIRT:0)
Block(-18,-21,-7,STONE:0)
Block(-18,-21,-6,STONE:0)
Block(-18,-21,-5,STONE:0)
Block(-18,-20,-9,STONE:0)
Block(-18,-20,-8,DIRT:0)
Block(-18,-20,-7,DIRT:0)
Block(-18,-20,-6,DIRT:0)
Block(-18,-20,-5,STONE:0)
Block(-18,-20,-4,DIRT:0)
Block(-18,-19,-9,STONE:0)
Block(-18,-19,-8,STONE:0)
Block(-18,-19,-7,STONE:0)
Block(-18,-19,-6,STONE:0)
Block(-18,-19,-5,STONE:0)
Block(-18,-19,-4,STONE:0)
Block(-18,-18,-10,STONE:0)
Block(-18,-18,-9,STONE:0)
Block(-18,-18,-8,STONE:0)
Block(-18,-18,-7,STONE:0)
Block(-18,-18,-6,STONE:0)
Block(-18,-18,-5,DIRT:0)
Block(-18,-18,-4,STONE:0)
Block(-18,-18,-3,STONE:0)
Block(-18,-18,-2,STONE:0)
Block(-18,-17,-10,STONE:0)
Block(-18,-17,-9,STONE:0)
Block(-18,-17,-8,STONE:0)
Block(-18,-17,-7,STONE:0)
Block(-18,-17,-6,DIRT:0)
Block(-18,-17,-5,STONE:0)
Block(-18,-17,-4,STONE:0)
Block(-18,-17,-3,STONE:0)
Block(-18,-17,-2,STONE:0)
Block(-18,-17,-1,STONE:0)
Block(-18,-16,-10,STONE:0)
Block(-18,-16,-9,STONE:0)
Block(-18,-16,-8,STONE:0)
Block(-18,-16,-7,STONE:0)
Block(-18,-16,-6,STONE:0)
Block(-18,-16,-5,STONE:0)
Block(-18,-16,-4,STONE:0)
Block(-18,-16,-3,STONE:0)
Block(-18,-16,-2,STONE:0)
Block(-18,-16,-1,STONE:0)
Block(-18,-16,0,STONE:0)
Block(-18,-15,-10,DIRT:0)
Block(-18,-15,-9,STONE:0)
Block(-18,-15,-8,STONE:0)
Block(-18,-15,-7,STONE:0)
Block(-18,-15,-6,DIRT:0)
Block(-18,-15,-5,STONE:0)
Block(-18,-15,-4,DIRT:0)
Block(-18,-15,-3,STONE:0)
Block(-18,-15,-2,STONE:0)
Block(-18,-15,-1,STONE:0)
Block(-18,-15,0,STONE:0)
Block(-18,-14,-11,STONE:0)
Block(-18,-14,-10,STONE:0)
Block(-18,-14,-9,DIRT:0)
Block(-18,-14,-8,STONE:0)
Block(-18,-14,-7,STONE:0)
Block(-18,-14,-6,STONE:0)
Block(-18,-14,-5,STONE:0)
Block(-18,-14,-4,STONE:0)
Block(-18,-14,-3,STONE:0)
Block(-18,-14,-2,DIRT:0)
Block(-18,-14,-1,STONE:0)
Block(-18,-14,0,STONE:0)
Block(-18,-14,1,STONE:0)
Block(-18,-13,-12,STONE:0)
Block(-18,-13,-11,STONE:0)
Block(-18,-13,-10,DIRT:0)
Block(-18,-13,-9,STONE:0)
Block(-18,-13,-8,STONE:0)
Block(-18,-13,-7,DIRT:0)
Block(-18,-13,-6,STONE:0)
Block(-18,-13,-5,DIRT:0)
Block(-18,-13,-4,STONE:0)
Block(-18,-13,-3,STONE:0)
Block(-18,-13,-2,STONE:0)
Block(-18,-13,-1,STONE:0)
Block(-18,-13,0,STONE:0)
Block(-18,-13,1,STONE:0)
Block(-18,-12,-13,STONE:0)
Block(-18,-12,-12,STONE:0)
Block(-18,-12,-11,STONE:0)
Block(-18,-12,-10,STONE:0)
Block(-18,-12,-9,STONE:0)
Block(-18,-12,-8,STONE:0)
Block(-18,-12,-7,STONE:0)
Block(-18,-12,-6,STONE:0)
Block(-18,-12,-5,STONE:0)
Block(-18,-12,-4,STONE:0)
Block(-18,-12,-3,STONE:0)
Block(-18,-12,-2,DIRT:0)
Block(-18,-12,-1,DIRT:0)
Block(-18,-12,0,STONE:0)
Block(-18,-12,1,STONE:0)
Block(-18,-12,2,STONE:0)
Block(-18,-12,3,STONE:0)
Block(-18,-11,-14,STONE:0)
Block(-18,-11,-13,STONE:0)
Block(-18,-11,-12,STONE:0)
Block(-18,-11,-11,STONE:0)
Block(-18,-11,-10,STONE:0)
Block(-18,-11,-9,STONE:0)
Block(-18,-11,-8,STONE:0)
Block(-18,-11,-7,STONE:0)
Block(-18,-11,-6,STONE:0)
Block(-18,-11,-5,STONE:0)
Block(-18,-11,-4,STONE:0)
Block(-18,-11,-3,STONE:0)
Block(-18,-11,-2,STONE:0)
Block(-18,-11,-1,STONE:0)
Block(-18,-11,0,STONE:0)
Block(-18,-11,1,STONE:0)
Block(-18,-11,2,STONE:0)
Block(-18,-11,3,STONE:0)
Block(-18,-10,-15,DIRT:0)
Block(-18,-10,-14,STONE:0)
Block(-18,-10,-13,STONE:0)
Block(-18,-10,-12,DIRT:0)
Block(-18,-10,-11,STONE:0)
Block(-18,-10,-10,STONE:0)
Block(-18,-10,-9,STONE:0)
Block(-18,-10,-8,STONE:0)
Block(-18,-10,-7,DIRT:0)
Block(-18,-10,-6,STONE:0)
Block(-18,-10,-5,STONE:0)
Block(-18,-10,-4,STONE:0)
Block(-18,-10,-3,STONE:0)
Block(-18,-10,-2,STONE:0)
Block(-18,-10,-1,STONE:0)
Block(-18,-10,0,STONE:0)
Block(-18,-10,1,STONE:0)
Block(-18,-10,2,STONE:0)
Block(-18,-10,3,STONE:0)
Block(-18,-9,-15,STONE:0)
Block(-18,-9,-14,STONE:0)
Block(-18,-9,-13,STONE:0)
Block(-18,-9,-12,DIRT:0)
Block(-18,-9,-11,STONE:0)
Block(-18,-9,-10,STONE:0)
Block(-18,-9,-9,STONE:0)
Block(-18,-9,-8,DIRT:0)
Block(-18,-9,-7,STONE:0)
Block(-18,-9,-6,STONE:0)
Block(-18,-9,-5,STONE:0)
Block(-18,-9,-4,STONE:0)
Block(-18,-9,-3,STONE:0)
Block(-18,-9,-2,STONE:0)
Block(-18,-9,-1,STONE:0)
Block(-18,-9,0,STONE:0)
Block(-18,-9,1,STONE:0)
Block(-18,-9,2,STONE:0)
Block(-18,-9,3,STONE:0)
Block(-18,-8,-15,STONE:0)
Block(-18,-8,-14,STONE:0)
Block(-18,-8,-13,STONE:0)
Block(-18,-8,-12,STONE:0)
Block(-18,-8,-11,STONE:0)
Block(-18,-8,-10,STONE:0)
Block(-18,-8,-9,STONE:0)
Block(-18,-8,-8,STONE:0)
Block(-18,-8,-7,STONE:0)
Block(-18,-8,-6,STONE:0)
Block(-18,-8,-5,STONE:0)
Block(-18,-8,-4,STONE:0)
Block(-18,-8,-3,STONE:0)
Block(-18,-8,-2,STONE:0)
Block(-18,-8,-1,STONE:0)
Block(-18,-8,0,STONE:0)
Block(-18,-8,1,STONE:0)
Block(-18,-8,2,STONE:0)
Block(-18,-8,3,STONE:0)
Block(-18,-7,-16,STONE:0)
Block(-18,-7,-15,STONE:0)
Block(-18,-7,-14,STONE:0)
Block(-18,-7,-13,DIRT:0)
Block(-18,-7,-12,STONE:0)
Block(-18,-7,-11,STONE:0)
Block(-18,-7,-10,STONE:0)
Block(-18,-7,-9,STONE:0)
Block(-18,-7,-8,STONE:0)
Block(-18,-7,-7,STONE:0)
Block(-18,-7,-6,STONE:0)
Block(-18,-7,-5,DIRT:0)
Block(-18,-7,-4,STONE:0)
Block(-18,-7,-3,DIRT:0)
Block(-18,-7,-2,STONE:0)
Block(-18,-7,-1,STONE:0)
Block(-18,-7,0,STONE:0)
Block(-18,-7,1,STONE:0)
Block(-18,-7,2,DIRT:0)
Block(-18,-7,3,STONE:0)
Block(-18,-6,-16,STONE:0)
Block(-18,-6,-15,DIRT:0)
Block(-18,-6,-14,STONE:0)
Block(-18,-6,-13,STONE:0)
Block(-18,-6,-12,STONE:0)
Block(-18,-6,-11,DIRT:0)
Block(-18,-6,-10,STONE:0)
Block(-18,-6,-9,DIRT:0)
Block(-18,-6,-8,STONE:0)
Block(-18,-6,-7,STONE:0)
Block(-18,-6,-6,STONE:0)
Block(-18,-6,-5,STONE:0)
Block(-18,-6,-4,STONE:0)
Block(-18,-6,-3,STONE:0)
Block(-18,-6,-2,DIRT:0)
Block(-18,-6,-1,STONE:0)
Block(-18,-6,0,STONE:0)
Block(-18,-6,1,DIRT:0)
Block(-18,-6,2,STONE:0)
Block(-18,-6,3,STONE:0)
Block(-18,-6,4,STONE:0)
Block(-18,-5,-16,STONE:0)
Block(-18,-5,-15,STONE:0)
Block(-18,-5,-14,STONE:0)
Block(-18,-5,-13,DIRT:0)
Block(-18,-5,-12,DIRT:0)
Block(-18,-5,-11,STONE:0)
Block(-18,-5,-10,STONE:0)
Block(-18,-5,-9,STONE:0)
Block(-18,-5,-8,STONE:0)
Block(-18,-5,-7,STONE:0)
Block(-18,-5,-6,STONE:0)
Block(-18,-5,-5,STONE:0)
Block(-18,-5,-4,DIRT:0)
Block(-18,-5,-3,DIRT:0)
Block(-18,-5,-2,STONE:0)
Block(-18,-5,-1,STONE:0)
Block(-18,-5,0,STONE:0)
Block(-18,-5,1,STONE:0)
Block(-18,-5,2,STONE:0)
Block(-18,-5,3,DIRT:0)
Block(-18,-5,4,STONE:0)
Block(-18,-5,5,STONE:0)
Block(-18,-4,-16,DIRT:0)
Block(-18,-4,-15,STONE:0)
Block(-18,-4,-14,STONE:0)
Block(-18,-4,-13,DIRT:0)
Block(-18,-4,-12,DIRT:0)
Block(-18,-4,-11,STONE:0)
Block(-18,-4,-10,STONE:0)
Block(-18,-4,-9,DIRT:0)
Block(-18,-4,-8,STONE:0)
Block(-18,-4,-7,DIRT:0)
Block(-18,-4,-6,STONE:0)
Block(-18,-4,-5,DIRT:0)
Block(-18,-4,-4,STONE:0)
Block(-18,-4,-3,STONE:0)
Block(-18,-4,-2,DIRT:0)
Block(-18,-4,-1,DIRT:0)
Block(-18,-4,0,DIRT:0)
Block(-18,-4,1,DIRT:0)
Block(-18,-4,2,STONE:0)
Block(-18,-4,3,STONE:0)
Block(-18,-4,4,STONE:0)
Block(-18,-4,5,STONE:0)
Block(-18,-3,-16,DIRT:0)
Block(-18,-3,-15,DIRT:0)
Block(-18,-3,-14,DIRT:0)
Block(-18,-3,-13,STONE:0)
Block(-18,-3,-12,DIRT:0)
Block(-18,-3,-11,STONE:0)
Block(-18,-3,-10,STONE:0)
Block(-18,-3,-9,STONE:0)
Block(-18,-3,-8,DIRT:0)
Block(-18,-3,-7,DIRT:0)
Block(-18,-3,-6,DIRT:0)
Block(-18,-3,-5,STONE:0)
Block(-18,-3,-4,DIRT:0)
Block(-18,-3,-3,DIRT:0)
Block(-18,-3,-2,STONE:0)
Block(-18,-3,-1,DIRT:0)
Block(-18,-3,0,DIRT:0)
Block(-18,-3,1,STONE:0)
Block(-18,-3,2,STONE:0)
Block(-18,-3,3,DIRT:0)
Block(-18,-3,4,DIRT:0)
Block(-18,-3,5,DIRT:0)
Block(-18,-2,-17,DIRT:0)
Block(-18,-2,-16,DIRT:0)
Block(-18,-2,-15,STONE:0)
Block(-18,-2,-14,DIRT:0)
Block(-18,-2,-13,DIRT:0)
Block(-18,-2,-12,STONE:0)
Block(-18,-2,-11,DIRT:0)
Block(-18,-2,-10,DIRT:0)
Block(-18,-2,-9,DIRT:0)
Block(-18,-2,-8,DIRT:0)
Block(-18,-2,-7,DIRT:0)
Block(-18,-2,-6,STONE:0)
Block(-18,-2,-5,STONE:0)
Block(-18,-2,-4,STONE:0)
Block(-18,-2,-3,STONE:0)
Block(-18,-2,-2,STONE:0)
Block(-18,-2,-1,DIRT:0)
Block(-18,-2,0,STONE:0)
Block(-18,-2,1,DIRT:0)
Block(-18,-2,2,DIRT:0)
Block(-18,-2,3,STONE:0)
Block(-18,-2,4,DIRT:0)
Block(-18,-2,5,STONE:0)
Block(-18,-2,6,DIRT:0)
Block(-18,-1,-18,STONE:0)
Block(-18,-1,-17,DIRT:0)
Block(-18,-1,-16,DIRT:0)
