
#######################################################################
# +-----------------------------------------------------------------+ #
# |                            BO3 object                           | #
# +-----------------------------------------------------------------+ #
#######################################################################

Author: Unknown

Description: This BO3 was converted from a schematic using OTGEdit. The author and description information of the schematic could not be found. If you know who the author of the schematic is then please add this information.

Version: 3

SettingsMode: WriteWithoutComments


#######################################################################
# +-----------------------------------------------------------------+ #
# |                          Main settings                          | #
# +-----------------------------------------------------------------+ #
#######################################################################

Tree: false

Frequency: 1

Rarity: 25.0

RotateRandomly: true

SpawnHeight: highestSolidBlock

SpawnHeightOffset: 0

SpawnHeightVariance: 0

##############################
# Height Limits for the BO3. #
##############################

MinHeight: 0

MaxHeight: 255

######################
# Extrusion settings #
######################

ExtrudeMode: None

ExtrudeThroughBlocks: AIR

MaxBranchDepth: 10

ExcludedBiomes: All


#######################################################################
# +-----------------------------------------------------------------+ #
# |                      Source block settings                      | #
# +-----------------------------------------------------------------+ #
#######################################################################

SourceBlocks: AIR

MaxPercentageOutsideSourceBlock: 100

OutsideSourceBlock: placeAnyway

DoReplaceBlocks: true

IsOTGPlus: false


#######################################################################
# +-----------------------------------------------------------------+ #
# |                              Blocks                             | #
# +-----------------------------------------------------------------+ #
#######################################################################

Block(-2,0,-1,STAINED_CLAY:15)
Block(-2,0,0,STAINED_CLAY:15)
Block(-2,0,1,STAINED_CLAY:15)
Block(-1,0,-2,STAINED_CLAY:15)
Block(-1,0,-1,STAINED_CLAY:15)
Block(-1,0,0,STAINED_CLAY:15)
Block(-1,0,1,STAINED_CLAY:15)
Block(-1,0,2,STAINED_CLAY:15)
Block(-1,25,0,STAINED_CLAY:10)
Block(-1,26,-2,STAINED_GLASS:10)
Block(-1,26,-1,STAINED_GLASS:10)
Block(-1,26,0,STAINED_GLASS:10)
Block(-1,26,1,STAINED_GLASS:10)
Block(-1,26,2,STAINED_GLASS:10)
Block(-1,27,-2,STAINED_GLASS:10)
Block(-1,27,-1,STAINED_GLASS:10)
Block(-1,27,0,STAINED_GLASS:10)
Block(-1,27,1,STAINED_GLASS:10)
Block(-1,27,2,STAINED_GLASS:10)
Block(-1,28,-2,STAINED_GLASS:10)
Block(-1,28,-1,STAINED_GLASS:10)
Block(-1,28,0,STAINED_GLASS:10)
Block(-1,28,1,STAINED_GLASS:10)
Block(-1,28,2,STAINED_GLASS:10)
Block(-1,29,-2,STAINED_GLASS:10)
Block(-1,29,-1,STAINED_GLASS:10)
Block(-1,29,0,STAINED_GLASS:10)
Block(-1,29,1,STAINED_GLASS:10)
Block(-1,29,2,STAINED_GLASS:10)
Block(-1,30,-2,STAINED_GLASS:10)
Block(-1,30,-1,STAINED_GLASS:10)
Block(-1,30,0,STAINED_GLASS:10)
Block(-1,30,1,STAINED_GLASS:10)
Block(-1,30,2,STAINED_GLASS:10)
Block(-1,31,-2,STAINED_GLASS:10)
Block(-1,31,-1,STAINED_GLASS:10)
Block(-1,31,0,STAINED_GLASS:10)
Block(-1,31,1,STAINED_GLASS:10)
Block(-1,31,2,STAINED_GLASS:10)
Block(-1,32,-2,STAINED_GLASS:10)
Block(-1,32,-1,STAINED_GLASS:10)
Block(-1,32,0,STAINED_GLASS:10)
Block(-1,32,1,STAINED_GLASS:10)
Block(-1,32,2,STAINED_GLASS:10)
Block(-1,33,-2,STAINED_GLASS:10)
Block(-1,33,-1,STAINED_GLASS:10)
Block(-1,33,0,STAINED_GLASS:10)
Block(-1,33,1,STAINED_GLASS:10)
Block(-1,33,2,STAINED_GLASS:10)
Block(0,0,-3,STAINED_CLAY:15)
Block(0,0,-2,STAINED_CLAY:15)
Block(0,0,-1,STAINED_CLAY:15)
Block(0,0,0,STAINED_CLAY:15)
Block(0,0,1,STAINED_CLAY:15)
Block(0,0,2,STAINED_CLAY:15)
Block(0,0,3,STAINED_CLAY:15)
Block(0,1,-1,STAINED_GLASS:10)
Block(0,1,0,STAINED_GLASS:10)
Block(0,1,1,STAINED_GLASS:10)
Block(0,2,-1,STAINED_GLASS:10)
Block(0,2,0,STAINED_GLASS:10)
Block(0,2,1,STAINED_GLASS:10)
Block(0,3,-1,STAINED_CLAY:10)
Block(0,3,0,STAINED_CLAY:10)
Block(0,3,1,STAINED_CLAY:10)
Block(0,4,-1,STAINED_GLASS:10)
Block(0,4,0,STAINED_GLASS:10)
Block(0,4,1,STAINED_GLASS:10)
Block(0,5,-1,STAINED_GLASS:10)
Block(0,5,0,STAINED_GLASS:10)
Block(0,5,1,STAINED_GLASS:10)
Block(0,6,-1,STAINED_CLAY:10)
Block(0,6,0,STAINED_CLAY:10)
Block(0,6,1,STAINED_CLAY:10)
Block(0,7,-1,STAINED_GLASS:10)
Block(0,7,0,STAINED_GLASS:10)
Block(0,7,1,STAINED_GLASS:10)
Block(0,8,-1,STAINED_GLASS:10)
Block(0,8,0,STAINED_GLASS:10)
Block(0,8,1,STAINED_GLASS:10)
Block(0,9,-1,STAINED_CLAY:10)
Block(0,9,0,STAINED_CLAY:10)
Block(0,9,1,STAINED_CLAY:10)
Block(0,10,-1,STAINED_GLASS:10)
Block(0,10,0,STAINED_GLASS:10)
Block(0,10,1,STAINED_GLASS:10)
Block(0,11,-1,STAINED_GLASS:10)
Block(0,11,0,STAINED_GLASS:10)
Block(0,11,1,STAINED_GLASS:10)
Block(0,12,-1,STAINED_CLAY:10)
Block(0,12,0,STAINED_CLAY:10)
Block(0,12,1,STAINED_CLAY:10)
Block(0,13,-1,STAINED_GLASS:10)
Block(0,13,0,STAINED_GLASS:10)
Block(0,13,1,STAINED_GLASS:10)
Block(0,14,-1,STAINED_GLASS:10)
Block(0,14,0,STAINED_GLASS:10)
Block(0,14,1,STAINED_GLASS:10)
Block(0,15,-1,STAINED_CLAY:10)
Block(0,15,0,STAINED_CLAY:10)
Block(0,15,1,STAINED_CLAY:10)
Block(0,16,-1,STAINED_GLASS:10)
Block(0,16,0,STAINED_GLASS:10)
Block(0,16,1,STAINED_GLASS:10)
Block(0,17,-1,STAINED_GLASS:10)
Block(0,17,0,STAINED_GLASS:10)
Block(0,17,1,STAINED_GLASS:10)
Block(0,18,-1,STAINED_CLAY:10)
Block(0,18,0,STAINED_CLAY:10)
Block(0,18,1,STAINED_CLAY:10)
Block(0,19,-1,STAINED_GLASS:10)
Block(0,19,0,STAINED_GLASS:10)
Block(0,19,1,STAINED_GLASS:10)
Block(0,20,-1,STAINED_GLASS:10)
Block(0,20,0,STAINED_GLASS:10)
Block(0,20,1,STAINED_GLASS:10)
Block(0,21,-1,STAINED_CLAY:10)
Block(0,21,0,STAINED_CLAY:10)
Block(0,21,1,STAINED_CLAY:10)
Block(0,22,-1,STAINED_GLASS:10)
Block(0,22,0,STAINED_GLASS:10)
Block(0,22,1,STAINED_GLASS:10)
Block(0,23,-1,STAINED_GLASS:10)
Block(0,23,0,STAINED_GLASS:10)
Block(0,23,1,STAINED_GLASS:10)
Block(0,24,-1,STAINED_CLAY:10)
Block(0,24,0,STAINED_CLAY:10)
Block(0,24,1,STAINED_CLAY:10)
Block(0,25,-1,STAINED_CLAY:10)
Block(0,25,0,STAINED_CLAY:10)
Block(0,25,1,STAINED_CLAY:10)
Block(0,26,-2,STAINED_GLASS:10)
Block(0,26,-1,STAINED_GLASS:10)
Block(0,26,0,STAINED_GLASS:10)
Block(0,26,1,STAINED_GLASS:10)
Block(0,26,2,STAINED_GLASS:10)
Block(0,27,-2,STAINED_GLASS:10)
Block(0,27,-1,STAINED_GLASS:2)
Block(0,27,0,STAINED_GLASS:2)
Block(0,27,1,STAINED_GLASS:2)
Block(0,27,2,STAINED_GLASS:10)
Block(0,28,-2,STAINED_GLASS:10)
Block(0,28,-1,STAINED_GLASS:2)
Block(0,28,0,STAINED_GLASS:2)
Block(0,28,1,STAINED_GLASS:2)
Block(0,28,2,STAINED_GLASS:10)
Block(0,29,-2,STAINED_GLASS:10)
Block(0,29,-1,STAINED_GLASS:2)
Block(0,29,0,STAINED_GLASS:2)
Block(0,29,1,STAINED_GLASS:2)
Block(0,29,2,STAINED_GLASS:10)
Block(0,30,-2,STAINED_GLASS:10)
Block(0,30,-1,STAINED_GLASS:2)
Block(0,30,0,STAINED_GLASS:2)
Block(0,30,1,STAINED_GLASS:2)
Block(0,30,2,STAINED_GLASS:10)
Block(0,31,-2,STAINED_GLASS:10)
Block(0,31,-1,STAINED_GLASS:2)
Block(0,31,0,STAINED_GLASS:2)
Block(0,31,1,STAINED_GLASS:2)
Block(0,31,2,STAINED_GLASS:10)
Block(0,32,-2,STAINED_GLASS:10)
Block(0,32,-1,STAINED_GLASS:2)
Block(0,32,0,STAINED_GLASS:2)
Block(0,32,1,STAINED_GLASS:2)
Block(0,32,2,STAINED_GLASS:10)
Block(0,33,-2,STAINED_GLASS:10)
Block(0,33,-1,STAINED_GLASS:10)
Block(0,33,0,STAINED_GLASS:10)
Block(0,33,1,STAINED_GLASS:10)
Block(0,33,2,STAINED_GLASS:10)
Block(1,0,-3,STAINED_CLAY:15)
Block(1,0,-2,STAINED_CLAY:15)
Block(1,0,-1,STAINED_CLAY:15)
Block(1,0,0,STAINED_CLAY:15)
Block(1,0,1,STAINED_CLAY:15)
Block(1,0,2,STAINED_CLAY:15)
Block(1,0,3,STAINED_CLAY:15)
Block(1,1,-1,STAINED_GLASS:10)
Block(1,1,0,CONCRETE:10)
Block(1,1,1,STAINED_GLASS:10)
Block(1,2,-1,STAINED_GLASS:10)
Block(1,2,0,CONCRETE:10)
Block(1,2,1,STAINED_GLASS:10)
Block(1,3,-1,STAINED_CLAY:10)
Block(1,3,0,CONCRETE:10)
Block(1,3,1,STAINED_CLAY:10)
Block(1,4,-1,STAINED_GLASS:10)
Block(1,4,0,CONCRETE:10)
Block(1,4,1,STAINED_GLASS:10)
Block(1,5,-1,STAINED_GLASS:10)
Block(1,5,0,CONCRETE:10)
Block(1,5,1,STAINED_GLASS:10)
Block(1,6,-1,STAINED_CLAY:10)
Block(1,6,0,CONCRETE:10)
Block(1,6,1,STAINED_CLAY:10)
Block(1,7,-1,STAINED_GLASS:10)
Block(1,7,0,CONCRETE:10)
Block(1,7,1,STAINED_GLASS:10)
Block(1,8,-1,STAINED_GLASS:10)
Block(1,8,0,CONCRETE:10)
Block(1,8,1,STAINED_GLASS:10)
Block(1,9,-1,STAINED_CLAY:10)
Block(1,9,0,CONCRETE:10)
Block(1,9,1,STAINED_CLAY:10)
Block(1,10,-1,STAINED_GLASS:10)
Block(1,10,0,CONCRETE:10)
Block(1,10,1,STAINED_GLASS:10)
Block(1,11,-1,STAINED_GLASS:10)
Block(1,11,0,CONCRETE:10)
Block(1,11,1,STAINED_GLASS:10)
Block(1,12,-1,STAINED_CLAY:10)
Block(1,12,0,CONCRETE:10)
Block(1,12,1,STAINED_CLAY:10)
Block(1,13,-1,STAINED_GLASS:10)
Block(1,13,0,CONCRETE:10)
Block(1,13,1,STAINED_GLASS:10)
Block(1,14,-1,STAINED_GLASS:10)
Block(1,14,0,CONCRETE:10)
Block(1,14,1,STAINED_GLASS:10)
Block(1,15,-1,STAINED_CLAY:10)
Block(1,15,0,CONCRETE:10)
Block(1,15,1,STAINED_CLAY:10)
Block(1,16,-1,STAINED_GLASS:10)
Block(1,16,0,CONCRETE:10)
Block(1,16,1,STAINED_GLASS:10)
Block(1,17,-1,STAINED_GLASS:10)
Block(1,17,0,CONCRETE:10)
Block(1,17,1,STAINED_GLASS:10)
Block(1,18,-1,STAINED_CLAY:10)
Block(1,18,0,CONCRETE:10)
Block(1,18,1,STAINED_CLAY:10)
Block(1,19,-1,STAINED_GLASS:10)
Block(1,19,0,CONCRETE:10)
Block(1,19,1,STAINED_GLASS:10)
Block(1,20,-1,STAINED_GLASS:10)
Block(1,20,0,CONCRETE:10)
Block(1,20,1,STAINED_GLASS:10)
Block(1,21,-1,STAINED_CLAY:10)
Block(1,21,0,CONCRETE:10)
Block(1,21,1,STAINED_CLAY:10)
Block(1,22,-1,STAINED_GLASS:10)
Block(1,22,0,CONCRETE:10)
Block(1,22,1,STAINED_GLASS:10)
Block(1,23,-1,STAINED_GLASS:10)
Block(1,23,0,CONCRETE:10)
Block(1,23,1,STAINED_GLASS:10)
Block(1,24,-1,STAINED_CLAY:10)
Block(1,24,0,CONCRETE:10)
Block(1,24,1,STAINED_CLAY:10)
Block(1,25,-2,STAINED_CLAY:10)
Block(1,25,-1,STAINED_CLAY:10)
Block(1,25,0,CONCRETE:10)
Block(1,25,1,STAINED_CLAY:10)
Block(1,25,2,STAINED_CLAY:10)
Block(1,26,-2,STAINED_GLASS:10)
Block(1,26,-1,STAINED_GLASS:10)
Block(1,26,0,CONCRETE:10)
Block(1,26,1,STAINED_GLASS:10)
Block(1,26,2,STAINED_GLASS:10)
Block(1,27,-2,STAINED_GLASS:10)
Block(1,27,-1,STAINED_GLASS:2)
Block(1,27,0,CONCRETE:10)
Block(1,27,1,STAINED_GLASS:2)
Block(1,27,2,STAINED_GLASS:10)
Block(1,28,-2,STAINED_GLASS:10)
Block(1,28,-1,STAINED_GLASS:2)
Block(1,28,0,CONCRETE:10)
Block(1,28,1,STAINED_GLASS:2)
Block(1,28,2,STAINED_GLASS:10)
Block(1,29,-2,STAINED_GLASS:10)
Block(1,29,-1,STAINED_GLASS:2)
Block(1,29,0,CONCRETE:10)
Block(1,29,1,STAINED_GLASS:2)
Block(1,29,2,STAINED_GLASS:10)
Block(1,30,-2,STAINED_GLASS:10)
Block(1,30,-1,STAINED_GLASS:2)
Block(1,30,0,CONCRETE:10)
Block(1,30,1,STAINED_GLASS:2)
Block(1,30,2,STAINED_GLASS:10)
Block(1,31,-2,STAINED_GLASS:10)
Block(1,31,-1,STAINED_GLASS:2)
Block(1,31,0,CONCRETE:10)
Block(1,31,1,STAINED_GLASS:2)
Block(1,31,2,STAINED_GLASS:10)
Block(1,32,-2,STAINED_GLASS:10)
Block(1,32,-1,STAINED_GLASS:2)
Block(1,32,0,STAINED_GLASS:2)
Block(1,32,1,STAINED_GLASS:2)
Block(1,32,2,STAINED_GLASS:10)
Block(1,33,-2,STAINED_GLASS:10)
Block(1,33,-1,STAINED_GLASS:10)
Block(1,33,0,STAINED_GLASS:10)
Block(1,33,1,STAINED_GLASS:10)
Block(1,33,2,STAINED_GLASS:10)
Block(2,0,-3,STAINED_CLAY:15)
Block(2,0,-2,STAINED_CLAY:15)
Block(2,0,-1,STAINED_CLAY:15)
Block(2,0,0,STAINED_CLAY:15)
Block(2,0,1,STAINED_CLAY:15)
Block(2,0,2,STAINED_CLAY:15)
Block(2,0,3,STAINED_CLAY:15)
Block(2,1,-1,STAINED_GLASS:10)
Block(2,1,0,STAINED_GLASS:10)
Block(2,1,1,STAINED_GLASS:10)
Block(2,2,-1,STAINED_GLASS:10)
Block(2,2,0,STAINED_GLASS:10)
Block(2,2,1,STAINED_GLASS:10)
Block(2,3,-1,STAINED_CLAY:10)
Block(2,3,0,STAINED_CLAY:10)
Block(2,3,1,STAINED_CLAY:10)
Block(2,4,-1,STAINED_GLASS:10)
Block(2,4,0,STAINED_GLASS:10)
Block(2,4,1,STAINED_GLASS:10)
Block(2,5,-1,STAINED_GLASS:10)
Block(2,5,0,STAINED_GLASS:10)
Block(2,5,1,STAINED_GLASS:10)
Block(2,6,-1,STAINED_CLAY:10)
Block(2,6,0,STAINED_CLAY:10)
Block(2,6,1,STAINED_CLAY:10)
Block(2,7,-1,STAINED_GLASS:10)
Block(2,7,0,STAINED_GLASS:10)
Block(2,7,1,STAINED_GLASS:10)
Block(2,8,-1,STAINED_GLASS:10)
Block(2,8,0,STAINED_GLASS:10)
Block(2,8,1,STAINED_GLASS:10)
Block(2,9,-1,STAINED_CLAY:10)
Block(2,9,0,STAINED_CLAY:10)
Block(2,9,1,STAINED_CLAY:10)
Block(2,10,-1,STAINED_GLASS:10)
Block(2,10,0,STAINED_GLASS:10)
Block(2,10,1,STAINED_GLASS:10)
Block(2,11,-1,STAINED_GLASS:10)
Block(2,11,0,STAINED_GLASS:10)
Block(2,11,1,STAINED_GLASS:10)
Block(2,12,-1,STAINED_CLAY:10)
Block(2,12,0,STAINED_CLAY:10)
Block(2,12,1,STAINED_CLAY:10)
Block(2,13,-1,STAINED_GLASS:10)
Block(2,13,0,STAINED_GLASS:10)
Block(2,13,1,STAINED_GLASS:10)
Block(2,14,-1,STAINED_GLASS:10)
Block(2,14,0,STAINED_GLASS:10)
Block(2,14,1,STAINED_GLASS:10)
Block(2,15,-1,STAINED_CLAY:10)
Block(2,15,0,STAINED_CLAY:10)
Block(2,15,1,STAINED_CLAY:10)
Block(2,16,-1,STAINED_GLASS:10)
Block(2,16,0,STAINED_GLASS:10)
Block(2,16,1,STAINED_GLASS:10)
Block(2,17,-1,STAINED_GLASS:10)
Block(2,17,0,STAINED_GLASS:10)
Block(2,17,1,STAINED_GLASS:10)
Block(2,18,-1,STAINED_CLAY:10)
Block(2,18,0,STAINED_CLAY:10)
Block(2,18,1,STAINED_CLAY:10)
Block(2,19,-1,STAINED_GLASS:10)
Block(2,19,0,STAINED_GLASS:10)
Block(2,19,1,STAINED_GLASS:10)
Block(2,20,-1,STAINED_GLASS:10)
Block(2,20,0,STAINED_GLASS:10)
Block(2,20,1,STAINED_GLASS:10)
Block(2,21,-1,STAINED_CLAY:10)
Block(2,21,0,STAINED_CLAY:10)
Block(2,21,1,STAINED_CLAY:10)
Block(2,22,-1,STAINED_GLASS:10)
Block(2,22,0,STAINED_GLASS:10)
Block(2,22,1,STAINED_GLASS:10)
Block(2,23,-1,STAINED_GLASS:10)
Block(2,23,0,STAINED_GLASS:10)
Block(2,23,1,STAINED_GLASS:10)
Block(2,24,-1,STAINED_CLAY:10)
Block(2,24,0,STAINED_CLAY:10)
Block(2,24,1,STAINED_CLAY:10)
Block(2,25,-1,STAINED_CLAY:10)
Block(2,25,0,STAINED_CLAY:10)
Block(2,25,1,STAINED_CLAY:10)
Block(2,26,-2,STAINED_GLASS:10)
Block(2,26,-1,STAINED_GLASS:10)
Block(2,26,0,STAINED_GLASS:10)
Block(2,26,1,STAINED_GLASS:10)
Block(2,26,2,STAINED_GLASS:10)
Block(2,27,-2,STAINED_GLASS:10)
Block(2,27,-1,STAINED_GLASS:2)
Block(2,27,0,STAINED_GLASS:2)
Block(2,27,1,STAINED_GLASS:2)
Block(2,27,2,STAINED_GLASS:10)
Block(2,28,-2,STAINED_GLASS:10)
Block(2,28,-1,STAINED_GLASS:2)
Block(2,28,0,STAINED_GLASS:2)
Block(2,28,1,STAINED_GLASS:2)
Block(2,28,2,STAINED_GLASS:10)
Block(2,29,-2,STAINED_GLASS:10)
Block(2,29,-1,STAINED_GLASS:2)
Block(2,29,0,STAINED_GLASS:2)
Block(2,29,1,STAINED_GLASS:2)
Block(2,29,2,STAINED_GLASS:10)
Block(2,30,-2,STAINED_GLASS:10)
Block(2,30,-1,STAINED_GLASS:2)
Block(2,30,0,STAINED_GLASS:2)
Block(2,30,1,STAINED_GLASS:2)
Block(2,30,2,STAINED_GLASS:10)
Block(2,31,-2,STAINED_GLASS:10)
Block(2,31,-1,STAINED_GLASS:2)
Block(2,31,0,STAINED_GLASS:2)
Block(2,31,1,STAINED_GLASS:2)
Block(2,31,2,STAINED_GLASS:10)
Block(2,32,-2,STAINED_GLASS:10)
Block(2,32,-1,STAINED_GLASS:2)
Block(2,32,0,STAINED_GLASS:2)
Block(2,32,1,STAINED_GLASS:2)
Block(2,32,2,STAINED_GLASS:10)
Block(2,33,-2,STAINED_GLASS:10)
Block(2,33,-1,STAINED_GLASS:10)
Block(2,33,0,STAINED_GLASS:10)
Block(2,33,1,STAINED_GLASS:10)
Block(2,33,2,STAINED_GLASS:10)
Block(3,0,-2,STAINED_CLAY:15)
Block(3,0,-1,STAINED_CLAY:15)
Block(3,0,0,STAINED_CLAY:15)
Block(3,0,1,STAINED_CLAY:15)
Block(3,0,2,STAINED_CLAY:15)
Block(3,25,0,STAINED_CLAY:10)
Block(3,26,-2,STAINED_GLASS:10)
Block(3,26,-1,STAINED_GLASS:10)
Block(3,26,0,STAINED_GLASS:10)
Block(3,26,1,STAINED_GLASS:10)
Block(3,26,2,STAINED_GLASS:10)
Block(3,27,-2,STAINED_GLASS:10)
Block(3,27,-1,STAINED_GLASS:10)
Block(3,27,0,STAINED_GLASS:10)
Block(3,27,1,STAINED_GLASS:10)
Block(3,27,2,STAINED_GLASS:10)
Block(3,28,-2,STAINED_GLASS:10)
Block(3,28,-1,STAINED_GLASS:10)
Block(3,28,0,STAINED_GLASS:10)
Block(3,28,1,STAINED_GLASS:10)
Block(3,28,2,STAINED_GLASS:10)
Block(3,29,-2,STAINED_GLASS:10)
Block(3,29,-1,STAINED_GLASS:10)
Block(3,29,0,STAINED_GLASS:10)
Block(3,29,1,STAINED_GLASS:10)
Block(3,29,2,STAINED_GLASS:10)
Block(3,30,-2,STAINED_GLASS:10)
Block(3,30,-1,STAINED_GLASS:10)
Block(3,30,0,STAINED_GLASS:10)
Block(3,30,1,STAINED_GLASS:10)
Block(3,30,2,STAINED_GLASS:10)
Block(3,31,-2,STAINED_GLASS:10)
Block(3,31,-1,STAINED_GLASS:10)
Block(3,31,0,STAINED_GLASS:10)
Block(3,31,1,STAINED_GLASS:10)
Block(3,31,2,STAINED_GLASS:10)
Block(3,32,-2,STAINED_GLASS:10)
Block(3,32,-1,STAINED_GLASS:10)
Block(3,32,0,STAINED_GLASS:10)
Block(3,32,1,STAINED_GLASS:10)
Block(3,32,2,STAINED_GLASS:10)
Block(3,33,-2,STAINED_GLASS:10)
Block(3,33,-1,STAINED_GLASS:10)
Block(3,33,0,STAINED_GLASS:10)
Block(3,33,1,STAINED_GLASS:10)
Block(3,33,2,STAINED_GLASS:10)
Block(4,0,-1,STAINED_CLAY:15)
Block(4,0,0,STAINED_CLAY:15)
Block(4,0,1,STAINED_CLAY:15)

#######################################################################
# +-----------------------------------------------------------------+ #
# |                            BO3 checks                           | #
# +-----------------------------------------------------------------+ #
#######################################################################


#######################################################################
# +-----------------------------------------------------------------+ #
# |                             Branches                            | #
# +-----------------------------------------------------------------+ #
#######################################################################


#######################################################################
# +-----------------------------------------------------------------+ #
# |                             Entities                            | #
# +-----------------------------------------------------------------+ #
#######################################################################


#######################################################################
# +-----------------------------------------------------------------+ #
# |                            Particles                            | #
# +-----------------------------------------------------------------+ #
#######################################################################


#######################################################################
# +-----------------------------------------------------------------+ #
# |                             Spawners                            | #
# +-----------------------------------------------------------------+ #
#######################################################################


#######################################################################
# +-----------------------------------------------------------------+ #
# |                             ModData                             | #
# +-----------------------------------------------------------------+ #
#######################################################################

