
#######################################################################
# +-----------------------------------------------------------------+ #
# |                            BO3 object                           | #
# +-----------------------------------------------------------------+ #
#######################################################################

Author: LordSmellyPants

Description: No description given

Version: 3

SettingsMode: WriteWithoutComments


#######################################################################
# +-----------------------------------------------------------------+ #
# |                          Main settings                          | #
# +-----------------------------------------------------------------+ #
#######################################################################

Tree: true

Frequency: 0

Rarity: 100.0

RotateRandomly: true

SpawnHeight: highestSolidBlock

SpawnHeightOffset: 0

SpawnHeightVariance: 0

##############################
# Height Limits for the BO3. #
##############################

MinHeight: 0

MaxHeight: 30

######################
# Extrusion settings #
######################

ExtrudeMode: BottomDown

ExtrudeThroughBlocks: AIR

MaxBranchDepth: 10

ExcludedBiomes: All


#######################################################################
# +-----------------------------------------------------------------+ #
# |                      Source block settings                      | #
# +-----------------------------------------------------------------+ #
#######################################################################

SourceBlocks: AIR

MaxPercentageOutsideSourceBlock: 100

OutsideSourceBlock: placeAnyway

DoReplaceBlocks: true

IsOTGPlus: false


#######################################################################
# +-----------------------------------------------------------------+ #
# |                              Blocks                             | #
# +-----------------------------------------------------------------+ #
#######################################################################

Block(-5,4,2,NETHER_WART_BLOCK)
Block(-5,5,1,NETHER_WART_BLOCK)
Block(-5,5,2,NETHER_WART_BLOCK)
Block(-5,6,0,NETHER_WART_BLOCK)
Block(-5,6,1,NETHER_WART_BLOCK)
Block(-5,6,2,NETHER_WART_BLOCK)
Block(-4,3,-1,NETHER_WART_BLOCK)
Block(-4,4,-1,NETHER_WART_BLOCK)
Block(-4,5,-1,NETHER_WART_BLOCK)
Block(-4,6,-1,NETHER_WART_BLOCK)
Block(-4,6,0,NETHER_WART_BLOCK)
Block(-4,6,1,NETHER_WART_BLOCK)
Block(-4,6,2,NETHER_WART_BLOCK)
Block(-4,6,3,NETHER_WART_BLOCK)
Block(-4,7,0,NETHER_WART_BLOCK)
Block(-4,7,1,NETHER_WART_BLOCK)
Block(-4,7,2,NETHER_WART_BLOCK)
Block(-3,5,1,GLOWSTONE)
Block(-3,5,4,NETHER_WART_BLOCK)
Block(-3,6,-2,NETHER_WART_BLOCK)
Block(-3,6,-1,NETHER_WART_BLOCK)
Block(-3,6,0,NETHER_WART_BLOCK)
Block(-3,6,1,NETHER_WART_BLOCK)
Block(-3,6,2,NETHER_WART_BLOCK)
Block(-3,6,3,NETHER_WART_BLOCK)
Block(-3,6,4,NETHER_WART_BLOCK)
Block(-3,7,-1,NETHER_WART_BLOCK)
Block(-3,7,0,NETHER_WART_BLOCK)
Block(-3,7,1,NETHER_WART_BLOCK)
Block(-3,7,2,NETHER_WART_BLOCK)
Block(-3,7,3,NETHER_WART_BLOCK)
Block(-3,8,0,NETHER_WART_BLOCK)
Block(-3,8,1,NETHER_WART_BLOCK)
Block(-3,8,2,NETHER_WART_BLOCK)
Block(-2,0,1,CONCRETE:15)
Block(-2,1,1,CONCRETE:15)
Block(-2,2,1,CONCRETE:15)
Block(-2,3,1,CONCRETE:15)
Block(-2,4,-2,NETHER_WART_BLOCK)
Block(-2,4,1,CONCRETE:15)
Block(-2,5,-2,NETHER_WART_BLOCK)
Block(-2,5,1,CONCRETE:15)
Block(-2,6,-2,NETHER_WART_BLOCK)
Block(-2,6,-1,NETHER_WART_BLOCK)
Block(-2,6,0,NETHER_WART_BLOCK)
Block(-2,6,1,NETHER_WART_BLOCK)
Block(-2,6,2,NETHER_WART_BLOCK)
Block(-2,6,3,NETHER_WART_BLOCK)
Block(-2,6,4,NETHER_WART_BLOCK)
Block(-2,7,-2,NETHER_WART_BLOCK)
Block(-2,7,-1,NETHER_WART_BLOCK)
Block(-2,7,0,NETHER_WART_BLOCK)
Block(-2,7,1,NETHER_WART_BLOCK)
Block(-2,7,2,NETHER_WART_BLOCK)
Block(-2,7,3,NETHER_WART_BLOCK)
Block(-2,8,-1,NETHER_WART_BLOCK)
Block(-2,8,0,NETHER_WART_BLOCK)
Block(-2,8,1,NETHER_WART_BLOCK)
Block(-2,8,2,NETHER_WART_BLOCK)
Block(-1,4,4,NETHER_WART_BLOCK)
Block(-1,5,-2,NETHER_WART_BLOCK)
Block(-1,5,4,NETHER_WART_BLOCK)
Block(-1,6,-2,NETHER_WART_BLOCK)
Block(-1,6,-1,NETHER_WART_BLOCK)
Block(-1,6,0,NETHER_WART_BLOCK)
Block(-1,6,1,NETHER_WART_BLOCK)
Block(-1,6,2,NETHER_WART_BLOCK)
Block(-1,6,3,NETHER_WART_BLOCK)
Block(-1,6,4,NETHER_WART_BLOCK)
Block(-1,7,-2,NETHER_WART_BLOCK)
Block(-1,7,-1,NETHER_WART_BLOCK)
Block(-1,7,0,NETHER_WART_BLOCK)
Block(-1,7,1,NETHER_WART_BLOCK)
Block(-1,7,2,NETHER_WART_BLOCK)
Block(-1,7,3,NETHER_WART_BLOCK)
Block(-1,8,-1,NETHER_WART_BLOCK)
Block(-1,8,0,NETHER_WART_BLOCK)
Block(-1,8,1,NETHER_WART_BLOCK)
Block(-1,8,2,NETHER_WART_BLOCK)
Block(0,6,-2,NETHER_WART_BLOCK)
Block(0,6,-1,NETHER_WART_BLOCK)
Block(0,6,0,NETHER_WART_BLOCK)
Block(0,6,1,NETHER_WART_BLOCK)
Block(0,6,2,NETHER_WART_BLOCK)
Block(0,6,3,NETHER_WART_BLOCK)
Block(0,7,-1,NETHER_WART_BLOCK)
Block(0,7,0,NETHER_WART_BLOCK)
Block(0,7,1,NETHER_WART_BLOCK)
Block(0,7,2,NETHER_WART_BLOCK)
Block(0,8,0,NETHER_WART_BLOCK)
Block(1,4,0,NETHER_WART_BLOCK)
Block(1,5,0,NETHER_WART_BLOCK)
Block(1,6,-1,NETHER_WART_BLOCK)
Block(1,6,0,NETHER_WART_BLOCK)
Block(1,6,1,NETHER_WART_BLOCK)
Block(1,6,2,NETHER_WART_BLOCK)
Block(1,7,0,NETHER_WART_BLOCK)
Block(1,7,1,NETHER_WART_BLOCK)

#######################################################################
# +-----------------------------------------------------------------+ #
# |                            BO3 checks                           | #
# +-----------------------------------------------------------------+ #
#######################################################################


#######################################################################
# +-----------------------------------------------------------------+ #
# |                             Branches                            | #
# +-----------------------------------------------------------------+ #
#######################################################################


#######################################################################
# +-----------------------------------------------------------------+ #
# |                             Entities                            | #
# +-----------------------------------------------------------------+ #
#######################################################################


#######################################################################
# +-----------------------------------------------------------------+ #
# |                            Particles                            | #
# +-----------------------------------------------------------------+ #
#######################################################################


#######################################################################
# +-----------------------------------------------------------------+ #
# |                             Spawners                            | #
# +-----------------------------------------------------------------+ #
#######################################################################


#######################################################################
# +-----------------------------------------------------------------+ #
# |                             ModData                             | #
# +-----------------------------------------------------------------+ #
#######################################################################

