
#######################################################################
# +-----------------------------------------------------------------+ #
# |                            BO3 object                           | #
# +-----------------------------------------------------------------+ #
#######################################################################

Author: LordSmellyPants

Description: No description given

Version: 3

SettingsMode: WriteWithoutComments


#######################################################################
# +-----------------------------------------------------------------+ #
# |                          Main settings                          | #
# +-----------------------------------------------------------------+ #
#######################################################################

Tree: true

Frequency: 0

Rarity: 100.0

RotateRandomly: true

SpawnHeight: highestSolidBlock

SpawnHeightOffset: 0

SpawnHeightVariance: 0

##############################
# Height Limits for the BO3. #
##############################

MinHeight: 0

MaxHeight: 30

######################
# Extrusion settings #
######################

ExtrudeMode: BottomDown

ExtrudeThroughBlocks: AIR

MaxBranchDepth: 10

ExcludedBiomes: All


#######################################################################
# +-----------------------------------------------------------------+ #
# |                      Source block settings                      | #
# +-----------------------------------------------------------------+ #
#######################################################################

SourceBlocks: AIR

MaxPercentageOutsideSourceBlock: 100

OutsideSourceBlock: placeAnyway

DoReplaceBlocks: true

IsOTGPlus: false


#######################################################################
# +-----------------------------------------------------------------+ #
# |                              Blocks                             | #
# +-----------------------------------------------------------------+ #
#######################################################################

Block(-7,20,0,NETHER_WART_BLOCK)
Block(-6,15,6,NETHER_WART_BLOCK)
Block(-6,16,5,NETHER_WART_BLOCK)
Block(-6,17,1,NETHER_WART_BLOCK)
Block(-6,18,2,NETHER_WART_BLOCK)
Block(-6,20,-1,NETHER_WART_BLOCK)
Block(-6,20,0,NETHER_WART_BLOCK)
Block(-6,21,1,NETHER_WART_BLOCK)
Block(-6,21,2,NETHER_WART_BLOCK)
Block(-5,16,2,NETHER_WART_BLOCK)
Block(-5,16,3,NETHER_WART_BLOCK)
Block(-5,16,4,NETHER_WART_BLOCK)
Block(-5,16,5,NETHER_WART_BLOCK)
Block(-5,16,6,NETHER_WART_BLOCK)
Block(-5,17,2,NETHER_WART_BLOCK)
Block(-5,18,1,NETHER_WART_BLOCK)
Block(-5,18,2,NETHER_WART_BLOCK)
Block(-5,21,0,NETHER_WART_BLOCK)
Block(-5,21,1,NETHER_WART_BLOCK)
Block(-5,22,2,NETHER_WART_BLOCK)
Block(-5,25,1,NETHER_WART_BLOCK)
Block(-5,26,2,NETHER_WART_BLOCK)
Block(-4,14,3,CONCRETE:15)
Block(-4,15,3,CONCRETE:15)
Block(-4,16,3,CONCRETE:15)
Block(-4,16,4,NETHER_WART_BLOCK)
Block(-4,17,3,CONCRETE:15)
Block(-4,18,3,CONCRETE:15)
Block(-4,21,0,NETHER_WART_BLOCK)
Block(-4,22,1,NETHER_WART_BLOCK)
Block(-4,22,2,NETHER_WART_BLOCK)
Block(-4,25,6,NETHER_WART_BLOCK)
Block(-4,26,1,NETHER_WART_BLOCK)
Block(-4,26,2,NETHER_WART_BLOCK)
Block(-4,26,5,NETHER_WART_BLOCK)
Block(-4,27,3,NETHER_WART_BLOCK)
Block(-3,2,-1,CONCRETE:15)
Block(-3,12,2,CONCRETE:15)
Block(-3,13,2,CONCRETE:15)
Block(-3,14,2,CONCRETE:15)
Block(-3,15,2,CONCRETE:15)
Block(-3,18,3,CONCRETE:15)
Block(-3,19,3,CONCRETE:15)
Block(-3,19,4,CONCRETE:15)
Block(-3,20,4,CONCRETE:15)
Block(-3,22,2,NETHER_WART_BLOCK)
Block(-3,24,5,NETHER_WART_BLOCK)
Block(-3,25,3,NETHER_WART_BLOCK)
Block(-3,25,5,NETHER_WART_BLOCK)
Block(-3,26,3,NETHER_WART_BLOCK)
Block(-3,26,5,NETHER_WART_BLOCK)
Block(-3,26,6,NETHER_WART_BLOCK)
Block(-3,27,2,NETHER_WART_BLOCK)
Block(-3,27,3,NETHER_WART_BLOCK)
Block(-2,2,-1,CONCRETE:15)
Block(-2,3,-1,CONCRETE:15)
Block(-2,11,2,CONCRETE:15)
Block(-2,11,3,CONCRETE:15)
Block(-2,12,2,CONCRETE:15)
Block(-2,13,2,CONCRETE:15)
Block(-2,20,4,CONCRETE:15)
Block(-2,21,3,NETHER_WART_BLOCK)
Block(-2,21,4,CONCRETE:15)
Block(-2,22,2,NETHER_WART_BLOCK)
Block(-2,22,3,NETHER_WART_BLOCK)
Block(-2,22,4,CONCRETE:15)
Block(-2,23,4,CONCRETE:15)
Block(-2,24,2,NETHER_WART_BLOCK)
Block(-2,24,4,NETHER_WART_BLOCK)
Block(-2,24,5,NETHER_WART_BLOCK)
Block(-2,25,3,NETHER_WART_BLOCK)
Block(-2,25,4,NETHER_WART_BLOCK)
Block(-1,2,-2,CONCRETE:15)
Block(-1,2,3,CONCRETE:15)
Block(-1,3,-1,CONCRETE:15)
Block(-1,3,0,CONCRETE:15)
Block(-1,10,3,NETHER_WART_BLOCK)
Block(-1,11,3,CONCRETE:15)
Block(-1,12,3,CONCRETE:15)
Block(-1,22,2,NETHER_WART_BLOCK)
Block(-1,23,0,NETHER_WART_BLOCK)
Block(-1,23,2,NETHER_WART_BLOCK)
Block(-1,24,1,NETHER_WART_BLOCK)
Block(-1,24,2,NETHER_WART_BLOCK)
Block(-1,24,3,NETHER_WART_BLOCK)
Block(-1,24,5,NETHER_WART_BLOCK)
Block(-1,24,6,NETHER_WART_BLOCK)
Block(0,2,-2,CONCRETE:15)
Block(0,2,-1,CONCRETE:15)
Block(0,2,0,CONCRETE:15)
Block(0,2,1,CONCRETE:15)
Block(0,2,2,CONCRETE:15)
Block(0,2,3,CONCRETE:15)
Block(0,3,-2,CONCRETE:15)
Block(0,3,0,CONCRETE:15)
Block(0,3,2,CONCRETE:15)
Block(0,9,2,NETHER_WART_BLOCK)
Block(0,9,3,NETHER_WART_BLOCK)
Block(0,10,3,NETHER_WART_BLOCK)
Block(0,11,3,CONCRETE:15)
Block(0,12,3,CONCRETE:15)
Block(0,23,0,NETHER_WART_BLOCK)
Block(0,23,1,NETHER_WART_BLOCK)
Block(0,23,6,NETHER_WART_BLOCK)
Block(0,24,2,NETHER_WART_BLOCK)
Block(0,24,5,NETHER_WART_BLOCK)
Block(1,2,-1,CONCRETE:15)
Block(1,2,0,CONCRETE:15)
Block(1,2,1,CONCRETE:15)
Block(1,3,-2,CONCRETE:15)
Block(1,3,-1,CONCRETE:15)
Block(1,3,0,CONCRETE:15)
Block(1,3,1,CONCRETE:15)
Block(1,3,2,CONCRETE:15)
Block(1,4,0,CONCRETE:15)
Block(1,8,2,NETHER_WART_BLOCK)
Block(1,9,2,NETHER_WART_BLOCK)
Block(1,12,3,CONCRETE:15)
Block(1,13,2,CONCRETE:15)
Block(1,13,3,CONCRETE:15)
Block(1,22,-1,NETHER_WART_BLOCK)
Block(1,22,0,NETHER_WART_BLOCK)
Block(1,23,1,NETHER_WART_BLOCK)
Block(1,23,2,NETHER_WART_BLOCK)
Block(2,2,0,CONCRETE:15)
Block(2,2,1,CONCRETE:15)
Block(2,2,2,CONCRETE:15)
Block(2,3,-1,CONCRETE:15)
Block(2,3,0,CONCRETE:15)
Block(2,3,1,CONCRETE:15)
Block(2,3,2,CONCRETE:15)
Block(2,4,0,CONCRETE:15)
Block(2,4,1,CONCRETE:15)
Block(2,4,2,CONCRETE:15)
Block(2,5,1,CONCRETE:15)
Block(2,8,2,NETHER_WART_BLOCK)
Block(2,12,3,CONCRETE:15)
Block(2,13,2,CONCRETE:15)
Block(2,13,3,CONCRETE:15)
Block(2,22,0,NETHER_WART_BLOCK)
Block(3,3,1,CONCRETE:15)
Block(3,3,2,CONCRETE:15)
Block(3,4,0,CONCRETE:15)
Block(3,4,1,CONCRETE:15)
Block(3,4,2,CONCRETE:15)
Block(3,5,0,CONCRETE:15)
Block(3,5,1,CONCRETE:15)
Block(3,5,2,CONCRETE:15)
Block(3,6,1,CONCRETE:15)
Block(3,8,1,NETHER_WART_BLOCK)
Block(3,8,2,NETHER_WART_BLOCK)
Block(3,9,1,NETHER_WART_BLOCK)
Block(3,12,2,CONCRETE:15)
Block(3,12,3,CONCRETE:15)
Block(3,13,2,CONCRETE:15)
Block(3,13,3,CONCRETE:15)
Block(3,15,0,NETHER_WART_BLOCK)
Block(3,16,1,NETHER_WART_BLOCK)
Block(4,3,0,CONCRETE:15)
Block(4,4,0,CONCRETE:15)
Block(4,4,1,CONCRETE:15)
Block(4,5,0,CONCRETE:15)
Block(4,5,1,CONCRETE:15)
Block(4,5,2,CONCRETE:15)
Block(4,6,0,CONCRETE:15)
Block(4,6,1,CONCRETE:15)
Block(4,6,2,CONCRETE:15)
Block(4,7,1,CONCRETE:15)
Block(4,9,1,NETHER_WART_BLOCK)
Block(4,10,1,NETHER_WART_BLOCK)
Block(4,11,3,CONCRETE:15)
Block(4,12,2,CONCRETE:15)
Block(4,12,3,CONCRETE:15)
Block(4,13,2,CONCRETE:15)
Block(4,13,3,CONCRETE:15)
Block(4,14,1,NETHER_WART_BLOCK)
Block(4,14,2,NETHER_WART_BLOCK)
Block(4,15,1,NETHER_WART_BLOCK)
Block(4,15,2,NETHER_WART_BLOCK)
Block(4,16,0,NETHER_WART_BLOCK)
Block(4,16,1,NETHER_WART_BLOCK)
Block(5,6,0,CONCRETE:15)
Block(5,6,1,CONCRETE:15)
Block(5,7,0,CONCRETE:15)
Block(5,7,1,CONCRETE:15)
Block(5,8,0,CONCRETE:15)
Block(5,8,1,CONCRETE:15)
Block(5,9,1,CONCRETE:15)
Block(5,10,1,CONCRETE:15)
Block(5,10,2,CONCRETE:15)
Block(5,10,3,CONCRETE:15)
Block(5,11,2,CONCRETE:15)
Block(5,11,3,CONCRETE:15)
Block(5,12,2,CONCRETE:15)
Block(5,13,1,NETHER_WART_BLOCK)
Block(5,13,2,NETHER_WART_BLOCK)
Block(5,13,3,NETHER_WART_BLOCK)
Block(5,14,2,NETHER_WART_BLOCK)
Block(6,7,0,CONCRETE:15)
Block(6,7,1,CONCRETE:15)
Block(6,8,0,CONCRETE:15)
Block(6,8,1,CONCRETE:15)
Block(6,9,0,CONCRETE:15)
Block(6,9,1,CONCRETE:15)
Block(6,9,2,CONCRETE:15)
Block(6,10,1,CONCRETE:15)
Block(6,10,2,CONCRETE:15)
Block(6,11,2,CONCRETE:15)
Block(6,12,1,NETHER_WART_BLOCK)
Block(6,12,2,NETHER_WART_BLOCK)
Block(6,13,-1,NETHER_WART_BLOCK)
Block(6,13,1,NETHER_WART_BLOCK)
Block(6,13,2,NETHER_WART_BLOCK)
Block(6,13,3,NETHER_WART_BLOCK)
Block(6,13,5,NETHER_WART_BLOCK)
Block(6,14,0,NETHER_WART_BLOCK)
Block(6,14,1,NETHER_WART_BLOCK)
Block(6,14,3,NETHER_WART_BLOCK)
Block(6,14,4,NETHER_WART_BLOCK)
Block(7,13,-1,NETHER_WART_BLOCK)
Block(7,13,0,NETHER_WART_BLOCK)
Block(7,13,4,NETHER_WART_BLOCK)
Block(7,13,5,NETHER_WART_BLOCK)
Block(7,14,1,NETHER_WART_BLOCK)
Block(7,14,3,NETHER_WART_BLOCK)
Block(7,14,4,NETHER_WART_BLOCK)
Block(8,12,-2,NETHER_WART_BLOCK)
Block(8,12,-1,NETHER_WART_BLOCK)
Block(8,12,5,NETHER_WART_BLOCK)
Block(8,12,6,NETHER_WART_BLOCK)
Block(8,13,0,NETHER_WART_BLOCK)
Block(8,13,1,NETHER_WART_BLOCK)
Block(8,13,3,NETHER_WART_BLOCK)
Block(8,13,4,NETHER_WART_BLOCK)
Block(9,12,-1,NETHER_WART_BLOCK)
Block(9,12,5,NETHER_WART_BLOCK)

#######################################################################
# +-----------------------------------------------------------------+ #
# |                            BO3 checks                           | #
# +-----------------------------------------------------------------+ #
#######################################################################


#######################################################################
# +-----------------------------------------------------------------+ #
# |                             Branches                            | #
# +-----------------------------------------------------------------+ #
#######################################################################


#######################################################################
# +-----------------------------------------------------------------+ #
# |                             Entities                            | #
# +-----------------------------------------------------------------+ #
#######################################################################


#######################################################################
# +-----------------------------------------------------------------+ #
# |                            Particles                            | #
# +-----------------------------------------------------------------+ #
#######################################################################


#######################################################################
# +-----------------------------------------------------------------+ #
# |                             Spawners                            | #
# +-----------------------------------------------------------------+ #
#######################################################################


#######################################################################
# +-----------------------------------------------------------------+ #
# |                             ModData                             | #
# +-----------------------------------------------------------------+ #
#######################################################################

