
#######################################################################
# +-----------------------------------------------------------------+ #
# |                            BO3 object                           | #
# +-----------------------------------------------------------------+ #
#######################################################################

# This is the config file of a custom object.
# If you add this object correctly to your BiomeConfigs, it will spawn in the world.

# This is the creator of this BO3 object
Author: LordSmellyPants

# A short description of this BO3 object
Description: No description given

# The BO3 version, don't change this! It can be used by external applications to do a version check.
Version: 3

# The settings mode, WriteAll, WriteWithoutComments or WriteDisable. See WorldConfig.
SettingsMode: WriteDisable


#######################################################################
# +-----------------------------------------------------------------+ #
# |                          Main settings                          | #
# +-----------------------------------------------------------------+ #
#######################################################################

# This needs to be set to true to spawn the object in the Tree and Sapling resources.
Tree: false

# The frequency of the BO3 from 1 to 200. Tries this many times to spawn this BO3 when using the CustomObject(...) resource.
# Ignored by Tree(..), Sapling(..) and CustomStructure(..)
Frequency: 1

# The rarity of the BO3 from 0 to 100. Each spawn attempt has rarity% chance to succeed when using the CustomObject(...) resource.
# Ignored by Tree(..), Sapling(..) and CustomStructure(..)
Rarity: 100.0

# If you set this to true, the BO3 will be placed with a random rotation.
RotateRandomly: true

# The spawn height of the BO3 - atMinY, randomY, highestBlock or highestSolidBlock.
SpawnHeight: highestSolidBlock

# The offset from the spawn height to spawn this BO3
# Ex. SpawnHeight = highestSolidBlock, SpawnHeightOffset = 3; This object will spawn 3 blocks above the highest solid block
SpawnHeightOffset: 0

# A random amount to offset the spawn location from the spawn offset height
# Ex. SpawnHeightOffset = 3, SpawnHeightVariance = 3; This object will spawn 3 to 6 blocks above the original spot it would have spawned
SpawnHeightVariance: 0

##############################
# Height Limits for the BO3. #
##############################

# When in randomY mode used as the minimum Y or in atMinY mode as the actual Y to spawn this BO3 at.
MinHeight: 0

# When in randomY mode used as the maximum Y to spawn this BO3 at.
MaxHeight: 256

######################
# Extrusion settings #
######################

# The style of extrusion you wish to use - BottomDown, TopUp, None (Default)
ExtrudeMode: None

# The blocks to extrude your BO3 through
ExtrudeThroughBlocks: AIR

# Objects can have other objects attacthed to it: branches. Branches can also
# have branches attached to it, which can also have branches, etc. This is the
# maximum branch depth for this objects.
MaxBranchDepth: 10

# When spawned with the UseWorld keyword, this BO3 should NOT spawn in the following biomes.
# If you write the BO3 name directly in the BiomeConfigs, this will be ignored.
ExcludedBiomes: All


#######################################################################
# +-----------------------------------------------------------------+ #
# |                      Source block settings                      | #
# +-----------------------------------------------------------------+ #
#######################################################################

# The B(s) the BO3 should spawn in.
SourceBlocks: AIR

# The maximum percentage of the BO3 that can be outside the SourceBlock.
# The BO3 won't be placed on a location with more blocks outside the SourceBlock than this percentage.
MaxPercentageOutsideSourceBlock: 100

# What to do when a block is about to be placed outside the SourceBlock? (dontPlace, placeAnyway)
OutsideSourceBlock: placeAnyway


#######################################################################
# +-----------------------------------------------------------------+ #
# |                              Blocks                             | #
# +-----------------------------------------------------------------+ #
#######################################################################

# All the blocks used in the BO3 are listed here. Possible blocks:
# B(x,y,z,id[.data][,nbtfile.nbt)
# RandomB(x,y,z,id[:data][,nbtfile.nbt],chance[,id[:data][,nbtfile.nbt],chance[,...]])
#  So RandomB(0,0,0,CHEST,chest.nbt,50,CHEST,anotherchest.nbt,100) will spawn a chest at
#  the BO3 origin, and give it a 50% chance to have the contents of chest.nbt, or, if that
#  fails, a 100% percent chance to have the contents of anotherchest.nbt.
# MinecraftObject(x,y,z,name)
#  Spawns an object in the Mojang NBT structure format. For example, 
#  MinecraftObject(0,0,0,minecraft:igloo/igloo_bottom)
#  spawns the bottom part of an igloo.
B(-12,-4,0,SNOW_BLOCK)
B(-12,-4,1,SNOW_BLOCK)
B(-12,-4,2,SNOW_BLOCK)
B(-12,-3,0,SNOW_BLOCK)
B(-12,-3,1,SNOW_BLOCK)
B(-12,-3,2,SNOW_BLOCK)
B(-12,-2,0,SNOW_BLOCK)
B(-12,-2,1,SNOW_BLOCK)
B(-12,-2,2,SNOW_BLOCK)
B(-12,-1,0,SNOW_BLOCK)
B(-12,-1,1,SNOW_BLOCK)
B(-12,-1,2,SNOW_BLOCK)
B(-12,0,0,SNOW_BLOCK)
B(-12,0,1,AIR)
B(-12,0,2,SNOW_BLOCK)
B(-12,1,0,SNOW_BLOCK)
B(-12,1,1,AIR)
B(-12,1,2,SNOW_BLOCK)
B(-12,2,1,SNOW_BLOCK)
B(-11,-4,-2,SNOW_BLOCK)
B(-11,-4,-1,SNOW_BLOCK)
B(-11,-4,0,SNOW_BLOCK)
B(-11,-4,1,SNOW_BLOCK)
B(-11,-4,2,SNOW_BLOCK)
B(-11,-4,3,SNOW_BLOCK)
B(-11,-4,4,SNOW_BLOCK)
B(-11,-3,-2,SNOW_BLOCK)
B(-11,-3,-1,SNOW_BLOCK)
B(-11,-3,0,SNOW_BLOCK)
B(-11,-3,1,SNOW_BLOCK)
B(-11,-3,2,SNOW_BLOCK)
B(-11,-3,3,SNOW_BLOCK)
B(-11,-3,4,SNOW_BLOCK)
B(-11,-2,-2,SNOW_BLOCK)
B(-11,-2,-1,SNOW_BLOCK)
B(-11,-2,0,SNOW_BLOCK)
B(-11,-2,1,SNOW_BLOCK)
B(-11,-2,2,SNOW_BLOCK)
B(-11,-2,3,SNOW_BLOCK)
B(-11,-2,4,SNOW_BLOCK)
B(-11,-1,-2,SNOW_BLOCK)
B(-11,-1,-1,SNOW_BLOCK)
B(-11,-1,0,SNOW_BLOCK)
B(-11,-1,1,SNOW_BLOCK)
B(-11,-1,2,SNOW_BLOCK)
B(-11,-1,3,SNOW_BLOCK)
B(-11,-1,4,SNOW_BLOCK)
B(-11,0,-2,SNOW_BLOCK)
B(-11,0,-1,SNOW_BLOCK)
B(-11,0,0,AIR)
B(-11,0,1,AIR)
B(-11,0,2,AIR)
B(-11,0,3,SNOW_BLOCK)
B(-11,0,4,SNOW_BLOCK)
B(-11,1,-2,SNOW_BLOCK)
B(-11,1,-1,SNOW_BLOCK)
B(-11,1,0,AIR)
B(-11,1,1,AIR)
B(-11,1,2,AIR)
B(-11,1,3,SNOW_BLOCK)
B(-11,1,4,SNOW_BLOCK)
B(-11,2,-2,SNOW_BLOCK)
B(-11,2,-1,SNOW_BLOCK)
B(-11,2,0,SNOW_BLOCK)
B(-11,2,1,AIR)
B(-11,2,2,SNOW_BLOCK)
B(-11,2,3,SNOW_BLOCK)
B(-11,2,4,SNOW_BLOCK)
B(-11,3,-1,SNOW_BLOCK)
B(-11,3,0,SNOW_BLOCK)
B(-11,3,1,SNOW_BLOCK)
B(-11,3,2,SNOW_BLOCK)
B(-11,3,3,SNOW_BLOCK)
B(-11,4,0,SNOW_BLOCK)
B(-11,4,1,SNOW_BLOCK)
B(-11,4,2,SNOW_BLOCK)
B(-10,-4,-4,SNOW_BLOCK)
B(-10,-4,-3,SNOW_BLOCK)
B(-10,-4,-2,SNOW_BLOCK)
B(-10,-4,-1,SNOW_BLOCK)
B(-10,-4,0,SNOW_BLOCK)
B(-10,-4,1,SNOW_BLOCK)
B(-10,-4,2,SNOW_BLOCK)
B(-10,-4,3,SNOW_BLOCK)
B(-10,-4,4,SNOW_BLOCK)
B(-10,-4,5,SNOW_BLOCK)
B(-10,-4,6,SNOW_BLOCK)
B(-10,-3,-4,SNOW_BLOCK)
B(-10,-3,-3,SNOW_BLOCK)
B(-10,-3,-2,SNOW_BLOCK)
B(-10,-3,-1,SNOW_BLOCK)
B(-10,-3,0,SNOW_BLOCK)
B(-10,-3,1,SNOW_BLOCK)
B(-10,-3,2,SNOW_BLOCK)
B(-10,-3,3,SNOW_BLOCK)
B(-10,-3,4,SNOW_BLOCK)
B(-10,-3,5,SNOW_BLOCK)
B(-10,-3,6,SNOW_BLOCK)
B(-10,-2,-4,SNOW_BLOCK)
B(-10,-2,-3,SNOW_BLOCK)
B(-10,-2,-2,SNOW_BLOCK)
B(-10,-2,-1,SNOW_BLOCK)
B(-10,-2,0,SNOW_BLOCK)
B(-10,-2,1,SNOW_BLOCK)
B(-10,-2,2,SNOW_BLOCK)
B(-10,-2,3,SNOW_BLOCK)
B(-10,-2,4,SNOW_BLOCK)
B(-10,-2,5,SNOW_BLOCK)
B(-10,-2,6,SNOW_BLOCK)
B(-10,-1,-4,SNOW_BLOCK)
B(-10,-1,-3,SNOW_BLOCK)
B(-10,-1,-2,SNOW_BLOCK)
B(-10,-1,-1,SNOW_BLOCK)
B(-10,-1,0,SNOW_BLOCK)
B(-10,-1,1,SNOW_BLOCK)
B(-10,-1,2,SNOW_BLOCK)
B(-10,-1,3,SNOW_BLOCK)
B(-10,-1,4,SNOW_BLOCK)
B(-10,-1,5,SNOW_BLOCK)
B(-10,-1,6,SNOW_BLOCK)
B(-10,0,-4,SNOW_BLOCK)
B(-10,0,-3,SNOW_BLOCK)
B(-10,0,-2,SNOW:1)
B(-10,0,-1,SNOW:1)
B(-10,0,0,AIR)
B(-10,0,1,AIR)
B(-10,0,2,AIR)
B(-10,0,3,AIR)
B(-10,0,4,SNOW:1)
B(-10,0,5,SNOW_BLOCK)
B(-10,0,6,SNOW_BLOCK)
B(-10,1,-4,SNOW_BLOCK)
B(-10,1,-3,SNOW_BLOCK)
B(-10,1,-1,AIR)
B(-10,1,0,AIR)
B(-10,1,1,AIR)
B(-10,1,2,AIR)
B(-10,1,3,AIR)
B(-10,1,4,AIR)
B(-10,1,5,SNOW_BLOCK)
B(-10,1,6,SNOW_BLOCK)
B(-10,2,-4,SNOW_BLOCK)
B(-10,2,-3,SNOW_BLOCK)
B(-10,2,-2,AIR)
B(-10,2,-1,AIR)
B(-10,2,0,AIR)
B(-10,2,1,AIR)
B(-10,2,2,AIR)
B(-10,2,3,AIR)
B(-10,2,4,AIR)
B(-10,2,5,SNOW_BLOCK)
B(-10,2,6,SNOW_BLOCK)
B(-10,3,-4,SNOW_BLOCK)
B(-10,3,-3,SNOW_BLOCK)
B(-10,3,-2,SNOW_BLOCK)
B(-10,3,-1,SNOW_BLOCK)
B(-10,3,0,AIR)
B(-10,3,1,AIR)
B(-10,3,2,AIR)
B(-10,3,3,AIR)
B(-10,3,4,SNOW_BLOCK)
B(-10,3,5,SNOW_BLOCK)
B(-10,3,6,SNOW_BLOCK)
B(-10,4,-4,SNOW)
B(-10,4,-3,SNOW_BLOCK)
B(-10,4,-2,SNOW_BLOCK)
B(-10,4,-1,SNOW_BLOCK)
B(-10,4,0,SNOW_BLOCK)
B(-10,4,1,AIR)
B(-10,4,2,AIR)
B(-10,4,3,SNOW_BLOCK)
B(-10,4,4,SNOW_BLOCK)
B(-10,4,5,SNOW_BLOCK)
B(-10,4,6,SNOW)
B(-10,5,-3,SNOW_BLOCK)
B(-10,5,-2,SNOW_BLOCK)
B(-10,5,-1,SNOW_BLOCK)
B(-10,5,0,SNOW_BLOCK)
B(-10,5,1,SNOW_BLOCK)
B(-10,5,2,SNOW_BLOCK)
B(-10,5,3,SNOW_BLOCK)
B(-10,5,4,SNOW_BLOCK)
B(-10,5,5,SNOW_BLOCK)
B(-10,6,-3,SNOW)
B(-10,6,-2,SNOW)
B(-10,6,-1,SNOW_BLOCK)
B(-10,6,0,SNOW_BLOCK)
B(-10,6,1,SNOW_BLOCK)
B(-10,6,2,SNOW_BLOCK)
B(-10,6,3,SNOW_BLOCK)
B(-10,6,4,SNOW)
B(-10,6,5,SNOW)
B(-10,7,-1,SNOW)
B(-10,7,0,SNOW)
B(-10,7,1,SNOW)
B(-10,7,2,SNOW)
B(-10,7,3,SNOW)
B(-9,-4,-6,SNOW_BLOCK)
B(-9,-4,-5,SNOW_BLOCK)
B(-9,-4,-4,SNOW_BLOCK)
B(-9,-4,-3,SNOW_BLOCK)
B(-9,-4,-2,SNOW_BLOCK)
B(-9,-4,-1,SNOW_BLOCK)
B(-9,-4,0,SNOW_BLOCK)
B(-9,-4,1,SNOW_BLOCK)
B(-9,-4,2,SNOW_BLOCK)
B(-9,-4,3,SNOW_BLOCK)
B(-9,-4,4,SNOW_BLOCK)
B(-9,-4,5,SNOW_BLOCK)
B(-9,-4,6,SNOW_BLOCK)
B(-9,-4,7,SNOW_BLOCK)
B(-9,-4,8,SNOW_BLOCK)
B(-9,-3,-6,SNOW_BLOCK)
B(-9,-3,-5,SNOW_BLOCK)
B(-9,-3,-4,SNOW_BLOCK)
B(-9,-3,-3,SNOW_BLOCK)
B(-9,-3,-2,SNOW_BLOCK)
B(-9,-3,-1,SNOW_BLOCK)
B(-9,-3,0,SNOW_BLOCK)
B(-9,-3,1,SNOW_BLOCK)
B(-9,-3,2,SNOW_BLOCK)
B(-9,-3,3,SNOW_BLOCK)
B(-9,-3,4,SNOW_BLOCK)
B(-9,-3,5,SNOW_BLOCK)
B(-9,-3,6,SNOW_BLOCK)
B(-9,-3,7,SNOW_BLOCK)
B(-9,-3,8,SNOW_BLOCK)
B(-9,-2,-6,SNOW_BLOCK)
B(-9,-2,-5,SNOW_BLOCK)
B(-9,-2,-4,SNOW_BLOCK)
B(-9,-2,-3,SNOW_BLOCK)
B(-9,-2,-2,SNOW_BLOCK)
B(-9,-2,-1,SNOW_BLOCK)
B(-9,-2,0,SNOW_BLOCK)
B(-9,-2,1,SNOW_BLOCK)
B(-9,-2,2,SNOW_BLOCK)
B(-9,-2,3,SNOW_BLOCK)
B(-9,-2,4,SNOW_BLOCK)
B(-9,-2,5,SNOW_BLOCK)
B(-9,-2,6,SNOW_BLOCK)
B(-9,-2,7,SNOW_BLOCK)
B(-9,-2,8,SNOW_BLOCK)
B(-9,-1,-6,SNOW_BLOCK)
B(-9,-1,-5,SNOW_BLOCK)
B(-9,-1,-4,SNOW_BLOCK)
B(-9,-1,-3,SNOW_BLOCK)
B(-9,-1,-2,SNOW_BLOCK)
B(-9,-1,-1,SNOW_BLOCK)
B(-9,-1,0,SNOW_BLOCK)
B(-9,-1,1,SNOW_BLOCK)
B(-9,-1,2,SNOW_BLOCK)
B(-9,-1,3,SNOW_BLOCK)
B(-9,-1,4,SNOW_BLOCK)
B(-9,-1,5,SNOW_BLOCK)
B(-9,-1,6,SNOW_BLOCK)
B(-9,-1,7,SNOW_BLOCK)
B(-9,-1,8,SNOW_BLOCK)
B(-9,0,-6,SNOW_BLOCK)
B(-9,0,-5,SNOW_BLOCK)
B(-9,0,-4,SNOW:2)
B(-9,0,-3,SNOW:1)
B(-9,0,-2,AIR)
B(-9,0,-1,AIR)
B(-9,0,0,AIR)
B(-9,0,1,AIR)
B(-9,0,2,AIR)
B(-9,0,3,AIR)
B(-9,0,4,SNOW)
B(-9,0,5,SNOW:2)
B(-9,0,6,SNOW:2)
B(-9,0,7,SNOW_BLOCK)
B(-9,0,8,SNOW_BLOCK)
B(-9,1,-6,SNOW_BLOCK)
B(-9,1,-5,SNOW_BLOCK)
B(-9,1,-4,AIR)
B(-9,1,-3,AIR)
B(-9,1,-2,AIR)
B(-9,1,-1,AIR)
B(-9,1,0,AIR)
B(-9,1,1,AIR)
B(-9,1,2,AIR)
B(-9,1,3,AIR)
B(-9,1,4,AIR)
B(-9,1,5,AIR)
B(-9,1,6,AIR)
B(-9,1,7,SNOW_BLOCK)
B(-9,1,8,SNOW_BLOCK)
B(-9,2,-6,SNOW_BLOCK)
B(-9,2,-5,SNOW_BLOCK)
B(-9,2,-4,AIR)
B(-9,2,-3,AIR)
B(-9,2,-2,AIR)
B(-9,2,-1,AIR)
B(-9,2,0,AIR)
B(-9,2,1,AIR)
B(-9,2,2,AIR)
B(-9,2,3,AIR)
B(-9,2,4,AIR)
B(-9,2,5,AIR)
B(-9,2,6,AIR)
B(-9,2,7,SNOW_BLOCK)
B(-9,2,8,SNOW_BLOCK)
B(-9,3,-6,SNOW)
B(-9,3,-5,SNOW_BLOCK)
B(-9,3,-4,AIR)
B(-9,3,-3,AIR)
B(-9,3,-2,AIR)
B(-9,3,-1,AIR)
B(-9,3,0,AIR)
B(-9,3,1,AIR)
B(-9,3,2,AIR)
B(-9,3,3,AIR)
B(-9,3,4,AIR)
B(-9,3,5,AIR)
B(-9,3,6,AIR)
B(-9,3,7,SNOW_BLOCK)
B(-9,3,8,SNOW)
B(-9,4,-5,SNOW_BLOCK)
B(-9,4,-4,SNOW_BLOCK)
B(-9,4,-3,AIR)
B(-9,4,-2,AIR)
B(-9,4,-1,AIR)
B(-9,4,0,AIR)
B(-9,4,1,AIR)
B(-9,4,2,AIR)
B(-9,4,3,AIR)
B(-9,4,4,AIR)
B(-9,4,5,AIR)
B(-9,4,6,SNOW_BLOCK)
B(-9,4,7,SNOW_BLOCK)
B(-9,5,-5,SNOW)
B(-9,5,-4,SNOW_BLOCK)
B(-9,5,-3,SNOW_BLOCK)
B(-9,5,-2,AIR)
B(-9,5,-1,AIR)
B(-9,5,0,AIR)
B(-9,5,1,AIR)
B(-9,5,2,AIR)
B(-9,5,3,AIR)
B(-9,5,4,AIR)
B(-9,5,5,AIR)
B(-9,5,6,SNOW_BLOCK)
B(-9,5,7,SNOW)
B(-9,6,-4,SNOW_BLOCK)
B(-9,6,-3,SNOW_BLOCK)
B(-9,6,-2,SNOW_BLOCK)
B(-9,6,-1,AIR)
B(-9,6,0,AIR)
B(-9,6,1,AIR)
B(-9,6,2,SNOW_BLOCK)
B(-9,6,3,SNOW_BLOCK)
B(-9,6,4,SNOW_BLOCK)
B(-9,6,5,SNOW_BLOCK)
B(-9,6,6,SNOW_BLOCK)
B(-9,7,-4,SNOW)
B(-9,7,-3,SNOW)
B(-9,7,-2,SNOW_BLOCK)
B(-9,7,-1,SNOW_BLOCK)
B(-9,7,0,SNOW_BLOCK)
B(-9,7,1,SNOW_BLOCK)
B(-9,7,2,SNOW_BLOCK)
B(-9,7,3,SNOW_BLOCK)
B(-9,7,4,SNOW_BLOCK)
B(-9,7,5,SNOW)
B(-9,7,6,SNOW)
B(-9,8,-2,SNOW)
B(-9,8,-1,SNOW)
B(-9,8,0,SNOW_BLOCK)
B(-9,8,1,SNOW_BLOCK)
B(-9,8,2,SNOW_BLOCK)
B(-9,8,3,SNOW)
B(-9,8,4,SNOW)
B(-9,9,0,SNOW)
B(-9,9,1,SNOW)
B(-9,9,2,SNOW)
B(-8,-4,-7,SNOW_BLOCK)
B(-8,-4,-6,SNOW_BLOCK)
B(-8,-4,-5,SNOW_BLOCK)
B(-8,-4,-4,SNOW_BLOCK)
B(-8,-4,-3,SNOW_BLOCK)
B(-8,-4,-2,SNOW_BLOCK)
B(-8,-4,-1,SNOW_BLOCK)
B(-8,-4,0,SNOW_BLOCK)
B(-8,-4,1,SNOW_BLOCK)
B(-8,-4,2,SNOW_BLOCK)
B(-8,-4,3,SNOW_BLOCK)
B(-8,-4,4,SNOW_BLOCK)
B(-8,-4,5,SNOW_BLOCK)
B(-8,-4,6,SNOW_BLOCK)
B(-8,-4,7,SNOW_BLOCK)
B(-8,-4,8,SNOW_BLOCK)
B(-8,-4,9,SNOW_BLOCK)
B(-8,-3,-7,SNOW_BLOCK)
B(-8,-3,-6,SNOW_BLOCK)
B(-8,-3,-5,SNOW_BLOCK)
B(-8,-3,-4,SNOW_BLOCK)
B(-8,-3,-3,SNOW_BLOCK)
B(-8,-3,-2,SNOW_BLOCK)
B(-8,-3,-1,SNOW_BLOCK)
B(-8,-3,0,SNOW_BLOCK)
B(-8,-3,1,SNOW_BLOCK)
B(-8,-3,2,SNOW_BLOCK)
B(-8,-3,3,SNOW_BLOCK)
B(-8,-3,4,SNOW_BLOCK)
B(-8,-3,5,SNOW_BLOCK)
B(-8,-3,6,SNOW_BLOCK)
B(-8,-3,7,SNOW_BLOCK)
B(-8,-3,8,SNOW_BLOCK)
B(-8,-3,9,SNOW_BLOCK)
B(-8,-2,-7,SNOW_BLOCK)
B(-8,-2,-6,SNOW_BLOCK)
B(-8,-2,-5,SNOW_BLOCK)
B(-8,-2,-4,SNOW_BLOCK)
B(-8,-2,-3,SNOW_BLOCK)
B(-8,-2,-2,SNOW_BLOCK)
B(-8,-2,-1,SNOW_BLOCK)
B(-8,-2,0,SNOW_BLOCK)
B(-8,-2,1,SNOW_BLOCK)
B(-8,-2,2,SNOW_BLOCK)
B(-8,-2,3,SNOW_BLOCK)
B(-8,-2,4,SNOW_BLOCK)
B(-8,-2,5,SNOW_BLOCK)
B(-8,-2,6,SNOW_BLOCK)
B(-8,-2,7,SNOW_BLOCK)
B(-8,-2,8,SNOW_BLOCK)
B(-8,-2,9,SNOW_BLOCK)
B(-8,-1,-7,SNOW_BLOCK)
B(-8,-1,-6,SNOW_BLOCK)
B(-8,-1,-5,SNOW_BLOCK)
B(-8,-1,-4,SNOW_BLOCK)
B(-8,-1,-3,SNOW_BLOCK)
B(-8,-1,-2,SNOW_BLOCK)
B(-8,-1,-1,SNOW_BLOCK)
B(-8,-1,0,SNOW_BLOCK)
B(-8,-1,1,SNOW_BLOCK)
B(-8,-1,2,SNOW_BLOCK)
B(-8,-1,3,SNOW_BLOCK)
B(-8,-1,4,SNOW_BLOCK)
B(-8,-1,5,SNOW_BLOCK)
B(-8,-1,6,SNOW_BLOCK)
B(-8,-1,7,SNOW_BLOCK)
B(-8,-1,8,SNOW_BLOCK)
B(-8,-1,9,SNOW_BLOCK)
B(-8,0,-7,SNOW_BLOCK)
B(-8,0,-6,SNOW:1)
B(-8,0,-5,SNOW:1)
B(-8,0,-4,AIR)
B(-8,0,-3,AIR)
B(-8,0,-2,AIR)
B(-8,0,-1,AIR)
B(-8,0,0,AIR)
B(-8,0,1,AIR)
B(-8,0,2,AIR)
B(-8,0,3,AIR)
B(-8,0,4,AIR)
B(-8,0,5,SNOW)
B(-8,0,6,SNOW:1)
B(-8,0,7,SNOW)
RB(-8,0,8,CHEST,../../nbt/VanillaLoot/igloo_chest.nbt,50,CHEST,../../nbt/VanillaLoot/igloo_chest.nbt,100)
B(-8,0,9,SNOW_BLOCK)
B(-8,1,-7,SNOW_BLOCK)
B(-8,1,-6,AIR)
B(-8,1,-5,AIR)
B(-8,1,-4,AIR)
B(-8,1,-3,AIR)
B(-8,1,-2,AIR)
B(-8,1,-1,AIR)
B(-8,1,0,AIR)
B(-8,1,1,AIR)
B(-8,1,2,AIR)
B(-8,1,3,AIR)
B(-8,1,4,AIR)
B(-8,1,5,AIR)
B(-8,1,6,AIR)
B(-8,1,7,AIR)
B(-8,1,8,AIR)
B(-8,1,9,SNOW_BLOCK)
B(-8,2,-7,SNOW_BLOCK)
B(-8,2,-6,AIR)
B(-8,2,-5,AIR)
B(-8,2,-4,AIR)
B(-8,2,-3,AIR)
B(-8,2,-2,AIR)
B(-8,2,-1,AIR)
B(-8,2,0,AIR)
B(-8,2,1,AIR)
B(-8,2,2,AIR)
B(-8,2,3,AIR)
B(-8,2,4,AIR)
B(-8,2,5,AIR)
B(-8,2,6,AIR)
B(-8,2,7,AIR)
B(-8,2,8,AIR)
B(-8,2,9,SNOW_BLOCK)
B(-8,3,-7,SNOW_BLOCK)
B(-8,3,-6,SNOW_BLOCK)
B(-8,3,-5,AIR)
B(-8,3,-4,AIR)
B(-8,3,-3,AIR)
B(-8,3,-2,AIR)
B(-8,3,-1,AIR)
B(-8,3,0,AIR)
B(-8,3,1,AIR)
B(-8,3,2,AIR)
B(-8,3,3,AIR)
B(-8,3,4,AIR)
B(-8,3,5,AIR)
B(-8,3,6,AIR)
B(-8,3,7,AIR)
B(-8,3,8,SNOW_BLOCK)
B(-8,3,9,SNOW_BLOCK)
B(-8,4,-7,SNOW)
B(-8,4,-6,SNOW_BLOCK)
B(-8,4,-5,SNOW_BLOCK)
B(-8,4,-4,AIR)
B(-8,4,-3,AIR)
B(-8,4,-2,AIR)
B(-8,4,-1,AIR)
B(-8,4,0,AIR)
B(-8,4,1,AIR)
B(-8,4,2,AIR)
B(-8,4,3,AIR)
B(-8,4,4,AIR)
B(-8,4,5,AIR)
B(-8,4,6,AIR)
B(-8,4,7,AIR)
B(-8,4,8,SNOW_BLOCK)
B(-8,4,9,SNOW)
B(-8,5,-6,SNOW_BLOCK)
B(-8,5,-5,SNOW_BLOCK)
B(-8,5,-4,AIR)
B(-8,5,-3,AIR)
B(-8,5,-2,AIR)
B(-8,5,-1,AIR)
B(-8,5,0,AIR)
B(-8,5,1,AIR)
B(-8,5,2,AIR)
B(-8,5,3,AIR)
B(-8,5,4,AIR)
B(-8,5,5,AIR)
B(-8,5,6,AIR)
B(-8,5,7,SNOW_BLOCK)
B(-8,5,8,SNOW_BLOCK)
B(-8,6,-6,SNOW)
B(-8,6,-5,SNOW_BLOCK)
B(-8,6,-4,AIR)
B(-8,6,-3,AIR)
B(-8,6,-2,AIR)
B(-8,6,-1,AIR)
B(-8,6,0,AIR)
B(-8,6,1,AIR)
B(-8,6,2,AIR)
B(-8,6,3,AIR)
B(-8,6,4,AIR)
B(-8,6,5,AIR)
B(-8,6,6,SNOW_BLOCK)
B(-8,6,7,SNOW_BLOCK)
B(-8,6,8,SNOW)
B(-8,7,-5,SNOW)
B(-8,7,-4,SNOW_BLOCK)
B(-8,7,-3,SNOW_BLOCK)
B(-8,7,-2,SNOW_BLOCK)
B(-8,7,-1,AIR)
B(-8,7,0,AIR)
B(-8,7,1,AIR)
B(-8,7,2,AIR)
B(-8,7,3,AIR)
B(-8,7,4,AIR)
B(-8,7,5,SNOW_BLOCK)
B(-8,7,6,SNOW_BLOCK)
B(-8,7,7,SNOW)
B(-8,8,-4,SNOW)
B(-8,8,-3,SNOW_BLOCK)
B(-8,8,-2,SNOW_BLOCK)
B(-8,8,-1,SNOW_BLOCK)
B(-8,8,0,SNOW_BLOCK)
B(-8,8,1,SNOW_BLOCK)
B(-8,8,2,AIR)
B(-8,8,3,SNOW_BLOCK)
B(-8,8,4,SNOW_BLOCK)
B(-8,8,5,SNOW_BLOCK)
B(-8,8,6,SNOW)
B(-8,9,-3,SNOW)
B(-8,9,-2,SNOW)
B(-8,9,-1,SNOW_BLOCK)
B(-8,9,0,SNOW_BLOCK)
B(-8,9,1,SNOW_BLOCK)
B(-8,9,2,SNOW_BLOCK)
B(-8,9,3,SNOW_BLOCK)
B(-8,9,4,SNOW)
B(-8,9,5,SNOW)
B(-8,10,-1,SNOW)
B(-8,10,0,SNOW)
B(-8,10,1,SNOW)
B(-8,10,2,SNOW)
B(-8,10,3,SNOW)
B(-7,-4,-8,SNOW_BLOCK)
B(-7,-4,-7,SNOW_BLOCK)
B(-7,-4,-6,SNOW_BLOCK)
B(-7,-4,-5,SNOW_BLOCK)
B(-7,-4,-4,SNOW_BLOCK)
B(-7,-4,-3,SNOW_BLOCK)
B(-7,-4,-2,SNOW_BLOCK)
B(-7,-4,-1,SNOW_BLOCK)
B(-7,-4,0,SNOW_BLOCK)
B(-7,-4,1,SNOW_BLOCK)
B(-7,-4,2,SNOW_BLOCK)
B(-7,-4,3,SNOW_BLOCK)
B(-7,-4,4,SNOW_BLOCK)
B(-7,-4,5,SNOW_BLOCK)
B(-7,-4,6,SNOW_BLOCK)
B(-7,-4,7,SNOW_BLOCK)
B(-7,-4,8,SNOW_BLOCK)
B(-7,-4,9,SNOW_BLOCK)
B(-7,-4,10,SNOW_BLOCK)
B(-7,-3,-8,SNOW_BLOCK)
B(-7,-3,-7,SNOW_BLOCK)
B(-7,-3,-6,SNOW_BLOCK)
B(-7,-3,-5,SNOW_BLOCK)
B(-7,-3,-4,SNOW_BLOCK)
B(-7,-3,-3,SNOW_BLOCK)
B(-7,-3,-2,SNOW_BLOCK)
B(-7,-3,-1,SNOW_BLOCK)
B(-7,-3,0,SNOW_BLOCK)
B(-7,-3,1,SNOW_BLOCK)
B(-7,-3,2,SNOW_BLOCK)
B(-7,-3,3,SNOW_BLOCK)
B(-7,-3,4,SNOW_BLOCK)
B(-7,-3,5,SNOW_BLOCK)
B(-7,-3,6,SNOW_BLOCK)
B(-7,-3,7,SNOW_BLOCK)
B(-7,-3,8,SNOW_BLOCK)
B(-7,-3,9,SNOW_BLOCK)
B(-7,-3,10,SNOW_BLOCK)
B(-7,-2,-8,SNOW_BLOCK)
B(-7,-2,-7,SNOW_BLOCK)
B(-7,-2,-6,SNOW_BLOCK)
B(-7,-2,-5,SNOW_BLOCK)
B(-7,-2,-4,SNOW_BLOCK)
B(-7,-2,-3,SNOW_BLOCK)
B(-7,-2,-2,SNOW_BLOCK)
B(-7,-2,-1,SNOW_BLOCK)
B(-7,-2,0,SNOW_BLOCK)
B(-7,-2,1,SNOW_BLOCK)
B(-7,-2,2,SNOW_BLOCK)
B(-7,-2,3,SNOW_BLOCK)
B(-7,-2,4,SNOW_BLOCK)
B(-7,-2,5,SNOW_BLOCK)
B(-7,-2,6,SNOW_BLOCK)
B(-7,-2,7,SNOW_BLOCK)
B(-7,-2,8,SNOW_BLOCK)
B(-7,-2,9,SNOW_BLOCK)
B(-7,-2,10,SNOW_BLOCK)
B(-7,-1,-8,SNOW_BLOCK)
B(-7,-1,-7,SNOW_BLOCK)
B(-7,-1,-6,SNOW_BLOCK)
B(-7,-1,-5,SNOW_BLOCK)
B(-7,-1,-4,SNOW_BLOCK)
B(-7,-1,-3,SNOW_BLOCK)
B(-7,-1,-2,SNOW_BLOCK)
B(-7,-1,-1,SNOW_BLOCK)
B(-7,-1,0,SNOW_BLOCK)
B(-7,-1,1,DIRT)
B(-7,-1,2,SNOW_BLOCK)
B(-7,-1,3,DIRT)
B(-7,-1,4,SNOW_BLOCK)
B(-7,-1,5,SNOW_BLOCK)
B(-7,-1,6,SNOW_BLOCK)
B(-7,-1,7,SNOW_BLOCK)
B(-7,-1,8,SNOW_BLOCK)
B(-7,-1,9,SNOW_BLOCK)
B(-7,-1,10,SNOW_BLOCK)
B(-7,0,-8,SNOW_BLOCK)
B(-7,0,-7,SNOW:1)
B(-7,0,-6,SNOW)
B(-7,0,-5,SNOW)
B(-7,0,-4,AIR)
B(-7,0,-3,AIR)
B(-7,0,-2,AIR)
B(-7,0,-1,AIR)
B(-7,0,0,AIR)
B(-7,0,1,AIR)
B(-7,0,2,AIR)
B(-7,0,3,AIR)
B(-7,0,4,AIR)
B(-7,0,5,SNOW)
B(-7,0,6,AIR)
B(-7,0,7,SNOW)
B(-7,0,8,SNOW)
B(-7,0,9,SNOW)
B(-7,0,10,SNOW_BLOCK)
B(-7,1,-8,SNOW_BLOCK)
B(-7,1,-7,AIR)
B(-7,1,-6,AIR)
B(-7,1,-5,AIR)
B(-7,1,-4,AIR)
B(-7,1,-3,AIR)
B(-7,1,-2,AIR)
B(-7,1,-1,AIR)
B(-7,1,0,AIR)
B(-7,1,1,AIR)
B(-7,1,2,AIR)
B(-7,1,3,AIR)
B(-7,1,4,AIR)
B(-7,1,5,AIR)
B(-7,1,6,AIR)
B(-7,1,7,AIR)
Entity(-7,1,8,SnowMan,2,PumpkinSnowGolem.txt)
B(-7,1,9,AIR)
B(-7,1,10,SNOW_BLOCK)
B(-7,2,-8,SNOW_BLOCK)
B(-7,2,-7,AIR)
B(-7,2,-6,AIR)
B(-7,2,-5,AIR)
B(-7,2,-4,AIR)
B(-7,2,-3,AIR)
B(-7,2,-2,AIR)
B(-7,2,-1,AIR)
B(-7,2,0,AIR)
B(-7,2,1,AIR)
B(-7,2,2,AIR)
B(-7,2,3,AIR)
B(-7,2,4,AIR)
B(-7,2,5,AIR)
B(-7,2,6,AIR)
B(-7,2,7,AIR)
B(-7,2,8,AIR)
B(-7,2,9,AIR)
B(-7,2,10,SNOW_BLOCK)
B(-7,3,-8,SNOW)
B(-7,3,-7,SNOW_BLOCK)
B(-7,3,-6,AIR)
B(-7,3,-5,AIR)
B(-7,3,-4,AIR)
B(-7,3,-3,AIR)
B(-7,3,-2,AIR)
B(-7,3,-1,AIR)
B(-7,3,0,AIR)
B(-7,3,1,AIR)
B(-7,3,2,AIR)
B(-7,3,3,AIR)
B(-7,3,4,AIR)
B(-7,3,5,AIR)
B(-7,3,6,AIR)
B(-7,3,7,AIR)
B(-7,3,8,AIR)
B(-7,3,9,SNOW_BLOCK)
B(-7,3,10,SNOW)
B(-7,4,-7,SNOW_BLOCK)
B(-7,4,-6,AIR)
B(-7,4,-5,AIR)
B(-7,4,-4,AIR)
B(-7,4,-3,AIR)
B(-7,4,-2,AIR)
B(-7,4,-1,AIR)
B(-7,4,0,AIR)
B(-7,4,1,AIR)
B(-7,4,2,AIR)
B(-7,4,3,AIR)
B(-7,4,4,AIR)
B(-7,4,5,AIR)
B(-7,4,6,AIR)
B(-7,4,7,AIR)
B(-7,4,8,AIR)
B(-7,4,9,SNOW_BLOCK)
B(-7,5,-7,SNOW_BLOCK)
B(-7,5,-6,AIR)
B(-7,5,-5,AIR)
B(-7,5,-4,AIR)
B(-7,5,-3,AIR)
B(-7,5,-2,AIR)
B(-7,5,-1,AIR)
B(-7,5,0,AIR)
B(-7,5,1,AIR)
B(-7,5,2,AIR)
B(-7,5,3,AIR)
B(-7,5,4,AIR)
B(-7,5,5,AIR)
B(-7,5,6,AIR)
B(-7,5,7,AIR)
B(-7,5,8,SNOW_BLOCK)
B(-7,5,9,SNOW_BLOCK)
B(-7,6,-7,SNOW)
B(-7,6,-6,SNOW_BLOCK)
B(-7,6,-5,AIR)
B(-7,6,-4,AIR)
B(-7,6,-3,AIR)
B(-7,6,-2,AIR)
B(-7,6,-1,AIR)
B(-7,6,0,AIR)
B(-7,6,1,AIR)
B(-7,6,2,AIR)
B(-7,6,3,AIR)
B(-7,6,4,AIR)
B(-7,6,5,AIR)
B(-7,6,6,AIR)
B(-7,6,7,AIR)
B(-7,6,8,SNOW_BLOCK)
B(-7,6,9,SNOW)
B(-7,7,-6,SNOW)
B(-7,7,-5,SNOW_BLOCK)
B(-7,7,-4,SNOW_BLOCK)
B(-7,7,-3,AIR)
B(-7,7,-2,AIR)
B(-7,7,-1,AIR)
B(-7,7,0,AIR)
B(-7,7,1,AIR)
B(-7,7,2,AIR)
B(-7,7,3,AIR)
B(-7,7,4,AIR)
B(-7,7,5,AIR)
B(-7,7,6,SNOW_BLOCK)
B(-7,7,7,SNOW_BLOCK)
B(-7,7,8,SNOW)
B(-7,8,-5,SNOW)
B(-7,8,-4,SNOW_BLOCK)
B(-7,8,-3,AIR)
B(-7,8,-2,AIR)
B(-7,8,-1,AIR)
B(-7,8,0,AIR)
B(-7,8,1,AIR)
B(-7,8,2,AIR)
B(-7,8,3,AIR)
B(-7,8,4,AIR)
B(-7,8,5,AIR)
B(-7,8,6,SNOW_BLOCK)
B(-7,8,7,SNOW:1)
B(-7,9,-4,SNOW)
B(-7,9,-3,SNOW_BLOCK)
B(-7,9,-2,SNOW_BLOCK)
B(-7,9,-1,SNOW_BLOCK)
B(-7,9,0,AIR)
B(-7,9,1,AIR)
B(-7,9,2,AIR)
B(-7,9,3,SNOW_BLOCK)
B(-7,9,4,SNOW_BLOCK)
B(-7,9,5,SNOW_BLOCK)
B(-7,9,6,SNOW:1)
B(-7,10,-3,SNOW)
B(-7,10,-2,SNOW)
B(-7,10,-1,SNOW)
B(-7,10,0,SNOW_BLOCK)
B(-7,10,1,SNOW_BLOCK)
B(-7,10,2,SNOW_BLOCK)
B(-7,10,3,SNOW)
B(-7,10,4,SNOW:1)
B(-7,10,5,SNOW)
B(-7,11,0,SNOW)
B(-7,11,1,SNOW)
B(-7,11,2,SNOW:1)
B(-6,-4,-8,SNOW_BLOCK)
B(-6,-4,-7,SNOW_BLOCK)
B(-6,-4,-6,SNOW_BLOCK)
B(-6,-4,-5,SNOW_BLOCK)
B(-6,-4,-4,SNOW_BLOCK)
B(-6,-4,-3,SNOW_BLOCK)
B(-6,-4,-2,SNOW_BLOCK)
B(-6,-4,-1,SNOW_BLOCK)
B(-6,-4,0,SNOW_BLOCK)
B(-6,-4,1,SNOW_BLOCK)
B(-6,-4,2,SNOW_BLOCK)
B(-6,-4,3,SNOW_BLOCK)
B(-6,-4,4,SNOW_BLOCK)
B(-6,-4,5,SNOW_BLOCK)
B(-6,-4,6,SNOW_BLOCK)
B(-6,-4,7,SNOW_BLOCK)
B(-6,-4,8,SNOW_BLOCK)
B(-6,-4,9,SNOW_BLOCK)
B(-6,-4,10,SNOW_BLOCK)
B(-6,-3,-8,SNOW_BLOCK)
B(-6,-3,-7,SNOW_BLOCK)
B(-6,-3,-6,SNOW_BLOCK)
B(-6,-3,-5,SNOW_BLOCK)
B(-6,-3,-4,SNOW_BLOCK)
B(-6,-3,-3,SNOW_BLOCK)
B(-6,-3,-2,SNOW_BLOCK)
B(-6,-3,-1,SNOW_BLOCK)
B(-6,-3,0,SNOW_BLOCK)
B(-6,-3,1,SNOW_BLOCK)
B(-6,-3,2,SNOW_BLOCK)
B(-6,-3,3,SNOW_BLOCK)
B(-6,-3,4,SNOW_BLOCK)
B(-6,-3,5,SNOW_BLOCK)
B(-6,-3,6,SNOW_BLOCK)
B(-6,-3,7,SNOW_BLOCK)
B(-6,-3,8,SNOW_BLOCK)
B(-6,-3,9,SNOW_BLOCK)
B(-6,-3,10,SNOW_BLOCK)
B(-6,-2,-8,SNOW_BLOCK)
B(-6,-2,-7,SNOW_BLOCK)
B(-6,-2,-6,SNOW_BLOCK)
B(-6,-2,-5,SNOW_BLOCK)
B(-6,-2,-4,SNOW_BLOCK)
B(-6,-2,-3,SNOW_BLOCK)
B(-6,-2,-2,SNOW_BLOCK)
B(-6,-2,-1,SNOW_BLOCK)
B(-6,-2,0,SNOW_BLOCK)
B(-6,-2,1,SNOW_BLOCK)
B(-6,-2,2,SNOW_BLOCK)
B(-6,-2,3,SNOW_BLOCK)
B(-6,-2,4,SNOW_BLOCK)
B(-6,-2,5,SNOW_BLOCK)
B(-6,-2,6,SNOW_BLOCK)
B(-6,-2,7,SNOW_BLOCK)
B(-6,-2,8,SNOW_BLOCK)
B(-6,-2,9,SNOW_BLOCK)
B(-6,-2,10,SNOW_BLOCK)
B(-6,-1,-8,SNOW_BLOCK)
B(-6,-1,-7,SNOW_BLOCK)
B(-6,-1,-6,SNOW_BLOCK)
B(-6,-1,-5,SNOW_BLOCK)
B(-6,-1,-4,SNOW_BLOCK)
B(-6,-1,-3,SNOW_BLOCK)
B(-6,-1,-2,SNOW_BLOCK)
B(-6,-1,-1,SNOW_BLOCK)
B(-6,-1,0,SNOW_BLOCK)
B(-6,-1,1,SNOW_BLOCK)
B(-6,-1,2,SNOW_BLOCK)
B(-6,-1,3,DIRT)
B(-6,-1,4,SNOW_BLOCK)
B(-6,-1,5,DIRT)
B(-6,-1,6,SNOW_BLOCK)
B(-6,-1,7,SNOW_BLOCK)
B(-6,-1,8,SNOW_BLOCK)
B(-6,-1,9,SNOW_BLOCK)
B(-6,-1,10,SNOW_BLOCK)
B(-6,0,-8,SNOW_BLOCK)
B(-6,0,-7,SNOW:1)
B(-6,0,-6,SNOW)
B(-6,0,-5,AIR)
B(-6,0,-4,AIR)
B(-6,0,-3,AIR)
B(-6,0,-2,AIR)
B(-6,0,-1,AIR)
B(-6,0,0,AIR)
B(-6,0,1,AIR)
B(-6,0,2,AIR)
B(-6,0,3,AIR)
B(-6,0,4,AIR)
B(-6,0,5,AIR)
B(-6,0,6,AIR)
B(-6,0,7,AIR)
B(-6,0,8,SNOW:1)
B(-6,0,9,SNOW)
B(-6,0,10,SNOW_BLOCK)
B(-6,1,-8,SNOW_BLOCK)
B(-6,1,-7,AIR)
B(-6,1,-6,AIR)
B(-6,1,-5,AIR)
B(-6,1,-4,AIR)
B(-6,1,-3,AIR)
B(-6,1,-2,AIR)
B(-6,1,-1,AIR)
B(-6,1,0,AIR)
B(-6,1,1,AIR)
B(-6,1,2,AIR)
B(-6,1,3,AIR)
B(-6,1,4,AIR)
B(-6,1,5,AIR)
B(-6,1,6,AIR)
B(-6,1,7,AIR)
B(-6,1,8,AIR)
B(-6,1,9,AIR)
B(-6,1,10,SNOW_BLOCK)
B(-6,2,-8,SNOW_BLOCK)
B(-6,2,-7,AIR)
B(-6,2,-6,AIR)
B(-6,2,-5,AIR)
B(-6,2,-4,AIR)
B(-6,2,-3,AIR)
B(-6,2,-2,AIR)
B(-6,2,-1,AIR)
B(-6,2,0,AIR)
B(-6,2,1,AIR)
B(-6,2,2,AIR)
B(-6,2,3,AIR)
B(-6,2,4,AIR)
B(-6,2,5,AIR)
B(-6,2,6,AIR)
B(-6,2,7,AIR)
B(-6,2,8,AIR)
B(-6,2,9,AIR)
B(-6,2,10,SNOW_BLOCK)
B(-6,3,-8,SNOW_BLOCK)
B(-6,3,-7,AIR)
B(-6,3,-6,AIR)
B(-6,3,-5,AIR)
B(-6,3,-4,AIR)
B(-6,3,-3,AIR)
B(-6,3,-2,AIR)
B(-6,3,-1,AIR)
B(-6,3,0,AIR)
B(-6,3,1,AIR)
B(-6,3,2,AIR)
B(-6,3,3,AIR)
B(-6,3,4,AIR)
B(-6,3,5,AIR)
B(-6,3,6,AIR)
B(-6,3,7,AIR)
B(-6,3,8,AIR)
B(-6,3,9,AIR)
B(-6,3,10,SNOW_BLOCK)
B(-6,4,-8,SNOW_BLOCK)
B(-6,4,-7,SNOW_BLOCK)
B(-6,4,-6,AIR)
B(-6,4,-5,AIR)
B(-6,4,-4,AIR)
B(-6,4,-3,AIR)
B(-6,4,-2,AIR)
B(-6,4,-1,AIR)
B(-6,4,0,PACKED_ICE)
B(-6,4,1,AIR)
B(-6,4,2,AIR)
B(-6,4,3,AIR)
B(-6,4,4,AIR)
B(-6,4,5,AIR)
B(-6,4,6,AIR)
B(-6,4,7,AIR)
B(-6,4,8,AIR)
B(-6,4,9,AIR)
B(-6,4,10,SNOW_BLOCK)
B(-6,5,-8,SNOW)
B(-6,5,-7,SNOW_BLOCK)
B(-6,5,-6,AIR)
B(-6,5,-5,AIR)
B(-6,5,-4,AIR)
B(-6,5,-3,AIR)
B(-6,5,-2,AIR)
B(-6,5,-1,AIR)
B(-6,5,0,PACKED_ICE)
B(-6,5,1,AIR)
B(-6,5,2,AIR)
B(-6,5,3,AIR)
B(-6,5,4,AIR)
B(-6,5,5,AIR)
B(-6,5,6,AIR)
B(-6,5,7,AIR)
B(-6,5,8,AIR)
B(-6,5,9,SNOW_BLOCK)
B(-6,5,10,SNOW)
B(-6,6,-7,SNOW_BLOCK)
B(-6,6,-6,SNOW_BLOCK)
B(-6,6,-5,AIR)
B(-6,6,-4,AIR)
B(-6,6,-3,AIR)
B(-6,6,-2,AIR)
B(-6,6,-1,AIR)
B(-6,6,0,PACKED_ICE)
B(-6,6,1,AIR)
B(-6,6,2,AIR)
B(-6,6,3,AIR)
B(-6,6,4,AIR)
B(-6,6,5,AIR)
B(-6,6,6,AIR)
B(-6,6,7,AIR)
B(-6,6,8,SNOW_BLOCK)
B(-6,6,9,SNOW_BLOCK)
B(-6,7,-7,SNOW)
B(-6,7,-6,SNOW_BLOCK)
B(-6,7,-5,SNOW_BLOCK)
B(-6,7,-4,AIR)
B(-6,7,-3,AIR)
B(-6,7,-2,AIR)
B(-6,7,-1,AIR)
B(-6,7,0,PACKED_ICE)
B(-6,7,1,AIR)
B(-6,7,2,AIR)
B(-6,7,3,AIR)
B(-6,7,4,AIR)
B(-6,7,5,AIR)
B(-6,7,6,AIR)
B(-6,7,7,AIR)
B(-6,7,8,SNOW_BLOCK)
B(-6,7,9,SNOW)
B(-6,8,-6,SNOW)
B(-6,8,-5,SNOW_BLOCK)
B(-6,8,-4,AIR)
B(-6,8,-3,AIR)
B(-6,8,-2,AIR)
B(-6,8,-1,AIR)
B(-6,8,0,PACKED_ICE)
B(-6,8,1,AIR)
B(-6,8,2,AIR)
B(-6,8,3,AIR)
B(-6,8,4,AIR)
B(-6,8,5,AIR)
B(-6,8,6,AIR)
B(-6,8,7,SNOW_BLOCK)
B(-6,8,8,SNOW)
B(-6,9,-5,SNOW)
B(-6,9,-4,SNOW_BLOCK)
B(-6,9,-3,SNOW_BLOCK)
B(-6,9,-2,AIR)
B(-6,9,-1,AIR)
B(-6,9,0,PACKED_ICE)
B(-6,9,1,AIR)
B(-6,9,2,AIR)
B(-6,9,3,AIR)
B(-6,9,4,AIR)
B(-6,9,5,SNOW_BLOCK)
B(-6,9,6,SNOW_BLOCK)
B(-6,9,7,SNOW)
B(-6,10,-4,SNOW)
B(-6,10,-3,SNOW)
B(-6,10,-2,SNOW_BLOCK)
B(-6,10,-1,SNOW_BLOCK)
B(-6,10,0,SNOW_BLOCK)
B(-6,10,1,SNOW_BLOCK)
B(-6,10,2,SNOW_BLOCK)
B(-6,10,3,SNOW_BLOCK)
B(-6,10,4,SNOW_BLOCK)
B(-6,10,5,SNOW)
B(-6,10,6,SNOW)
B(-6,11,-2,SNOW)
B(-6,11,-1,SNOW)
B(-6,11,0,SNOW)
B(-6,11,1,SNOW)
B(-6,11,2,SNOW)
B(-6,11,3,SNOW)
B(-6,11,4,SNOW)
B(-5,-4,-9,SNOW_BLOCK)
B(-5,-4,-8,SNOW_BLOCK)
B(-5,-4,-7,SNOW_BLOCK)
B(-5,-4,-6,SNOW_BLOCK)
B(-5,-4,-5,SNOW_BLOCK)
B(-5,-4,-4,SNOW_BLOCK)
B(-5,-4,-3,SNOW_BLOCK)
B(-5,-4,-2,SNOW_BLOCK)
B(-5,-4,-1,SNOW_BLOCK)
B(-5,-4,0,SNOW_BLOCK)
B(-5,-4,1,SNOW_BLOCK)
B(-5,-4,2,SNOW_BLOCK)
B(-5,-4,3,SNOW_BLOCK)
B(-5,-4,4,SNOW_BLOCK)
B(-5,-4,5,SNOW_BLOCK)
B(-5,-4,6,SNOW_BLOCK)
B(-5,-4,7,SNOW_BLOCK)
B(-5,-4,8,SNOW_BLOCK)
B(-5,-4,9,SNOW_BLOCK)
B(-5,-4,10,SNOW_BLOCK)
B(-5,-4,11,SNOW_BLOCK)
B(-5,-3,-9,SNOW_BLOCK)
B(-5,-3,-8,SNOW_BLOCK)
B(-5,-3,-7,SNOW_BLOCK)
B(-5,-3,-6,SNOW_BLOCK)
B(-5,-3,-5,SNOW_BLOCK)
B(-5,-3,-4,SNOW_BLOCK)
B(-5,-3,-3,SNOW_BLOCK)
B(-5,-3,-2,SNOW_BLOCK)
B(-5,-3,-1,SNOW_BLOCK)
B(-5,-3,0,SNOW_BLOCK)
B(-5,-3,1,SNOW_BLOCK)
B(-5,-3,2,SNOW_BLOCK)
B(-5,-3,3,SNOW_BLOCK)
B(-5,-3,4,SNOW_BLOCK)
B(-5,-3,5,SNOW_BLOCK)
B(-5,-3,6,SNOW_BLOCK)
B(-5,-3,7,SNOW_BLOCK)
B(-5,-3,8,SNOW_BLOCK)
B(-5,-3,9,SNOW_BLOCK)
B(-5,-3,10,SNOW_BLOCK)
B(-5,-3,11,SNOW_BLOCK)
B(-5,-2,-9,SNOW_BLOCK)
B(-5,-2,-8,SNOW_BLOCK)
B(-5,-2,-7,SNOW_BLOCK)
B(-5,-2,-6,SNOW_BLOCK)
B(-5,-2,-5,SNOW_BLOCK)
B(-5,-2,-4,SNOW_BLOCK)
B(-5,-2,-3,SNOW_BLOCK)
B(-5,-2,-2,SNOW_BLOCK)
B(-5,-2,-1,SNOW_BLOCK)
B(-5,-2,0,SNOW_BLOCK)
B(-5,-2,1,SNOW_BLOCK)
B(-5,-2,2,SNOW_BLOCK)
B(-5,-2,3,SNOW_BLOCK)
B(-5,-2,4,SNOW_BLOCK)
B(-5,-2,5,SNOW_BLOCK)
B(-5,-2,6,SNOW_BLOCK)
B(-5,-2,7,SNOW_BLOCK)
B(-5,-2,8,SNOW_BLOCK)
B(-5,-2,9,SNOW_BLOCK)
B(-5,-2,10,SNOW_BLOCK)
B(-5,-2,11,SNOW_BLOCK)
B(-5,-1,-9,SNOW_BLOCK)
B(-5,-1,-8,SNOW_BLOCK)
B(-5,-1,-7,SNOW_BLOCK)
B(-5,-1,-6,SNOW_BLOCK)
B(-5,-1,-5,SNOW_BLOCK)
B(-5,-1,-4,SNOW_BLOCK)
B(-5,-1,-3,SNOW_BLOCK)
B(-5,-1,-2,DIRT)
B(-5,-1,-1,SNOW_BLOCK)
B(-5,-1,0,SNOW_BLOCK)
B(-5,-1,1,DIRT)
B(-5,-1,2,SNOW_BLOCK)
B(-5,-1,3,SNOW_BLOCK)
B(-5,-1,4,DIRT)
B(-5,-1,5,DIRT)
B(-5,-1,6,SNOW_BLOCK)
B(-5,-1,7,SNOW_BLOCK)
B(-5,-1,8,SNOW_BLOCK)
B(-5,-1,9,SNOW_BLOCK)
B(-5,-1,10,SNOW_BLOCK)
B(-5,-1,11,SNOW_BLOCK)
B(-5,0,-9,SNOW_BLOCK)
B(-5,0,-8,SNOW:1)
B(-5,0,-7,SNOW)
B(-5,0,-6,AIR)
B(-5,0,-5,AIR)
B(-5,0,-4,AIR)
B(-5,0,-3,AIR)
B(-5,0,-2,AIR)
B(-5,0,-1,AIR)
B(-5,0,0,AIR)
B(-5,0,1,AIR)
B(-5,0,2,AIR)
B(-5,0,3,AIR)
B(-5,0,4,AIR)
B(-5,0,5,AIR)
B(-5,0,6,AIR)
B(-5,0,7,SNOW)
B(-5,0,8,SNOW)
B(-5,0,9,SNOW)
B(-5,0,10,SNOW:1)
B(-5,0,11,SNOW_BLOCK)
B(-5,1,-9,SNOW_BLOCK)
B(-5,1,-8,AIR)
B(-5,1,-7,AIR)
B(-5,1,-6,AIR)
B(-5,1,-5,AIR)
B(-5,1,-4,AIR)
B(-5,1,-3,AIR)
B(-5,1,-2,AIR)
B(-5,1,-1,AIR)
B(-5,1,0,AIR)
B(-5,1,1,AIR)
B(-5,1,2,AIR)
B(-5,1,3,AIR)
B(-5,1,4,AIR)
B(-5,1,5,AIR)
B(-5,1,6,AIR)
B(-5,1,7,AIR)
B(-5,1,8,AIR)
B(-5,1,9,AIR)
B(-5,1,10,AIR)
B(-5,1,11,SNOW_BLOCK)
B(-5,2,-9,SNOW_BLOCK)
B(-5,2,-8,AIR)
B(-5,2,-7,AIR)
B(-5,2,-6,AIR)
B(-5,2,-5,AIR)
B(-5,2,-4,AIR)
B(-5,2,-3,AIR)
B(-5,2,-2,AIR)
B(-5,2,-1,AIR)
B(-5,2,0,AIR)
B(-5,2,1,AIR)
B(-5,2,2,AIR)
B(-5,2,3,AIR)
B(-5,2,4,AIR)
B(-5,2,5,AIR)
B(-5,2,6,AIR)
B(-5,2,7,AIR)
B(-5,2,8,AIR)
B(-5,2,9,AIR)
B(-5,2,10,AIR)
B(-5,2,11,SNOW_BLOCK)
B(-5,3,-9,SNOW_BLOCK)
B(-5,3,-8,AIR)
B(-5,3,-7,AIR)
B(-5,3,-6,AIR)
B(-5,3,-5,AIR)
B(-5,3,-4,AIR)
B(-5,3,-3,AIR)
B(-5,3,-2,AIR)
B(-5,3,-1,AIR)
B(-5,3,0,AIR)
B(-5,3,1,AIR)
B(-5,3,2,AIR)
B(-5,3,3,AIR)
B(-5,3,4,AIR)
B(-5,3,5,AIR)
B(-5,3,6,AIR)
B(-5,3,7,AIR)
B(-5,3,8,AIR)
B(-5,3,9,AIR)
B(-5,3,10,AIR)
B(-5,3,11,SNOW_BLOCK)
B(-5,4,-9,SNOW)
B(-5,4,-8,SNOW_BLOCK)
B(-5,4,-7,AIR)
B(-5,4,-6,AIR)
B(-5,4,-5,AIR)
B(-5,4,-4,AIR)
B(-5,4,-3,AIR)
B(-5,4,-2,AIR)
B(-5,4,-1,AIR)
B(-5,4,0,AIR)
B(-5,4,1,AIR)
B(-5,4,2,AIR)
B(-5,4,3,AIR)
B(-5,4,4,AIR)
B(-5,4,5,AIR)
B(-5,4,6,AIR)
B(-5,4,7,AIR)
B(-5,4,8,AIR)
B(-5,4,9,AIR)
B(-5,4,10,SNOW_BLOCK)
B(-5,4,11,SNOW)
B(-5,5,-8,SNOW_BLOCK)
B(-5,5,-7,AIR)
B(-5,5,-6,AIR)
B(-5,5,-5,AIR)
B(-5,5,-4,AIR)
B(-5,5,-3,AIR)
B(-5,5,-2,AIR)
B(-5,5,-1,AIR)
B(-5,5,0,AIR)
B(-5,5,1,AIR)
B(-5,5,2,AIR)
B(-5,5,3,AIR)
B(-5,5,4,AIR)
B(-5,5,5,AIR)
B(-5,5,6,AIR)
B(-5,5,7,AIR)
B(-5,5,8,AIR)
B(-5,5,9,AIR)
B(-5,5,10,SNOW_BLOCK)
B(-5,6,-8,SNOW_BLOCK)
B(-5,6,-7,AIR)
B(-5,6,-6,AIR)
B(-5,6,-5,AIR)
B(-5,6,-4,AIR)
B(-5,6,-3,AIR)
B(-5,6,-2,PACKED_ICE)
B(-5,6,-1,AIR)
B(-5,6,0,AIR)
B(-5,6,1,AIR)
B(-5,6,2,AIR)
B(-5,6,3,AIR)
B(-5,6,4,AIR)
B(-5,6,5,AIR)
B(-5,6,6,AIR)
B(-5,6,7,AIR)
B(-5,6,8,AIR)
B(-5,6,9,AIR)
B(-5,6,10,SNOW_BLOCK)
B(-5,7,-8,SNOW)
B(-5,7,-7,SNOW_BLOCK)
B(-5,7,-6,SNOW_BLOCK)
B(-5,7,-5,AIR)
B(-5,7,-4,AIR)
B(-5,7,-3,AIR)
B(-5,7,-2,PACKED_ICE)
B(-5,7,-1,AIR)
B(-5,7,0,AIR)
B(-5,7,1,AIR)
B(-5,7,2,AIR)
B(-5,7,3,AIR)
B(-5,7,4,AIR)
B(-5,7,5,PACKED_ICE)
B(-5,7,6,AIR)
B(-5,7,7,AIR)
B(-5,7,8,SNOW_BLOCK)
B(-5,7,9,SNOW_BLOCK)
B(-5,7,10,SNOW)
B(-5,8,-7,SNOW)
B(-5,8,-6,SNOW_BLOCK)
B(-5,8,-5,AIR)
B(-5,8,-4,AIR)
B(-5,8,-3,AIR)
B(-5,8,-2,PACKED_ICE)
B(-5,8,-1,AIR)
B(-5,8,0,AIR)
B(-5,8,1,AIR)
B(-5,8,2,AIR)
B(-5,8,3,AIR)
B(-5,8,4,AIR)
B(-5,8,5,PACKED_ICE)
B(-5,8,6,AIR)
B(-5,8,7,AIR)
B(-5,8,8,SNOW_BLOCK)
B(-5,8,9,SNOW)
B(-5,9,-6,SNOW)
B(-5,9,-5,SNOW_BLOCK)
B(-5,9,-4,AIR)
B(-5,9,-3,AIR)
B(-5,9,-2,PACKED_ICE)
B(-5,9,-1,AIR)
B(-5,9,0,PACKED_ICE)
B(-5,9,1,AIR)
B(-5,9,2,AIR)
B(-5,9,3,AIR)
B(-5,9,4,AIR)
B(-5,9,5,PACKED_ICE)
B(-5,9,6,AIR)
B(-5,9,7,SNOW_BLOCK)
B(-5,9,8,SNOW:1)
B(-5,10,-5,SNOW)
B(-5,10,-4,SNOW_BLOCK)
B(-5,10,-3,SNOW_BLOCK)
B(-5,10,-2,SNOW_BLOCK)
B(-5,10,-1,AIR)
B(-5,10,0,PACKED_ICE)
B(-5,10,1,PACKED_ICE)
B(-5,10,2,AIR)
B(-5,10,3,AIR)
B(-5,10,4,SNOW_BLOCK)
B(-5,10,5,SNOW_BLOCK)
B(-5,10,6,SNOW_BLOCK)
B(-5,10,7,SNOW)
B(-5,11,-4,SNOW)
B(-5,11,-3,SNOW)
B(-5,11,-2,SNOW)
B(-5,11,-1,SNOW_BLOCK)
B(-5,11,0,SNOW_BLOCK)
B(-5,11,1,SNOW_BLOCK)
B(-5,11,2,SNOW_BLOCK)
B(-5,11,3,SNOW_BLOCK)
B(-5,11,4,SNOW)
B(-5,11,5,SNOW)
B(-5,11,6,SNOW)
B(-5,12,-1,SNOW)
B(-5,12,0,SNOW)
B(-5,12,1,SNOW)
B(-5,12,3,SNOW)
B(-4,-4,-9,SNOW_BLOCK)
B(-4,-4,-8,SNOW_BLOCK)
B(-4,-4,-7,SNOW_BLOCK)
B(-4,-4,-6,SNOW_BLOCK)
B(-4,-4,-5,SNOW_BLOCK)
B(-4,-4,-4,SNOW_BLOCK)
B(-4,-4,-3,SNOW_BLOCK)
B(-4,-4,-2,SNOW_BLOCK)
B(-4,-4,-1,SNOW_BLOCK)
B(-4,-4,0,SNOW_BLOCK)
B(-4,-4,1,SNOW_BLOCK)
B(-4,-4,2,SNOW_BLOCK)
B(-4,-4,3,SNOW_BLOCK)
B(-4,-4,4,SNOW_BLOCK)
B(-4,-4,5,SNOW_BLOCK)
B(-4,-4,6,SNOW_BLOCK)
B(-4,-4,7,SNOW_BLOCK)
B(-4,-4,8,SNOW_BLOCK)
B(-4,-4,9,SNOW_BLOCK)
B(-4,-4,10,SNOW_BLOCK)
B(-4,-4,11,SNOW_BLOCK)
B(-4,-3,-9,SNOW_BLOCK)
B(-4,-3,-8,SNOW_BLOCK)
B(-4,-3,-7,SNOW_BLOCK)
B(-4,-3,-6,SNOW_BLOCK)
B(-4,-3,-5,SNOW_BLOCK)
B(-4,-3,-4,SNOW_BLOCK)
B(-4,-3,-3,SNOW_BLOCK)
B(-4,-3,-2,SNOW_BLOCK)
B(-4,-3,-1,SNOW_BLOCK)
B(-4,-3,0,SNOW_BLOCK)
B(-4,-3,1,SNOW_BLOCK)
B(-4,-3,2,SNOW_BLOCK)
B(-4,-3,3,SNOW_BLOCK)
B(-4,-3,4,SNOW_BLOCK)
B(-4,-3,5,SNOW_BLOCK)
B(-4,-3,6,SNOW_BLOCK)
B(-4,-3,7,SNOW_BLOCK)
B(-4,-3,8,SNOW_BLOCK)
B(-4,-3,9,SNOW_BLOCK)
B(-4,-3,10,SNOW_BLOCK)
B(-4,-3,11,SNOW_BLOCK)
B(-4,-2,-9,SNOW_BLOCK)
B(-4,-2,-8,SNOW_BLOCK)
B(-4,-2,-7,SNOW_BLOCK)
B(-4,-2,-6,SNOW_BLOCK)
B(-4,-2,-5,SNOW_BLOCK)
B(-4,-2,-4,SNOW_BLOCK)
B(-4,-2,-3,SNOW_BLOCK)
B(-4,-2,-2,SNOW_BLOCK)
B(-4,-2,-1,SNOW_BLOCK)
B(-4,-2,0,SNOW_BLOCK)
B(-4,-2,1,SNOW_BLOCK)
B(-4,-2,2,SNOW_BLOCK)
B(-4,-2,3,SNOW_BLOCK)
B(-4,-2,4,SNOW_BLOCK)
B(-4,-2,5,SNOW_BLOCK)
B(-4,-2,6,SNOW_BLOCK)
B(-4,-2,7,SNOW_BLOCK)
B(-4,-2,8,SNOW_BLOCK)
B(-4,-2,9,SNOW_BLOCK)
B(-4,-2,10,SNOW_BLOCK)
B(-4,-2,11,SNOW_BLOCK)
B(-4,-1,-9,SNOW_BLOCK)
B(-4,-1,-8,SNOW_BLOCK)
B(-4,-1,-7,SNOW_BLOCK)
B(-4,-1,-6,DIRT)
B(-4,-1,-5,DIRT)
B(-4,-1,-4,SNOW_BLOCK)
B(-4,-1,-3,DIRT)
B(-4,-1,-2,DIRT)
B(-4,-1,-1,SNOW_BLOCK)
B(-4,-1,0,DIRT)
B(-4,-1,1,DIRT)
B(-4,-1,2,SNOW_BLOCK)
B(-4,-1,3,DIRT)
B(-4,-1,4,DIRT)
B(-4,-1,5,SNOW_BLOCK)
B(-4,-1,6,SNOW_BLOCK)
B(-4,-1,7,SNOW_BLOCK)
B(-4,-1,8,SNOW_BLOCK)
B(-4,-1,9,SNOW_BLOCK)
B(-4,-1,10,SNOW_BLOCK)
B(-4,-1,11,SNOW_BLOCK)
B(-4,0,-9,SNOW_BLOCK)
B(-4,0,-8,SNOW:1)
B(-4,0,-7,AIR)
B(-4,0,-6,AIR)
B(-4,0,-5,AIR)
B(-4,0,-4,AIR)
B(-4,0,-3,AIR)
B(-4,0,-2,AIR)
B(-4,0,-1,AIR)
B(-4,0,0,AIR)
B(-4,0,1,AIR)
B(-4,0,2,AIR)
B(-4,0,3,AIR)
B(-4,0,4,AIR)
B(-4,0,5,AIR)
B(-4,0,6,AIR)
B(-4,0,7,AIR)
B(-4,0,8,AIR)
B(-4,0,9,SNOW)
B(-4,0,10,SNOW)
B(-4,0,11,SNOW_BLOCK)
B(-4,1,-9,SNOW_BLOCK)
B(-4,1,-8,AIR)
B(-4,1,-7,AIR)
B(-4,1,-6,AIR)
B(-4,1,-5,AIR)
B(-4,1,-4,AIR)
B(-4,1,-3,AIR)
B(-4,1,-2,AIR)
B(-4,1,-1,AIR)
B(-4,1,0,AIR)
B(-4,1,1,AIR)
B(-4,1,2,AIR)
B(-4,1,3,AIR)
B(-4,1,4,AIR)
B(-4,1,5,AIR)
B(-4,1,6,AIR)
B(-4,1,7,AIR)
B(-4,1,8,AIR)
B(-4,1,9,AIR)
B(-4,1,10,AIR)
B(-4,1,11,SNOW_BLOCK)
B(-4,2,-9,SNOW_BLOCK)
B(-4,2,-8,AIR)
B(-4,2,-7,AIR)
B(-4,2,-6,AIR)
B(-4,2,-5,AIR)
B(-4,2,-4,AIR)
B(-4,2,-3,AIR)
B(-4,2,-2,AIR)
B(-4,2,-1,AIR)
B(-4,2,0,AIR)
B(-4,2,1,AIR)
B(-4,2,2,AIR)
B(-4,2,3,AIR)
B(-4,2,4,AIR)
B(-4,2,5,AIR)
B(-4,2,6,AIR)
B(-4,2,7,AIR)
B(-4,2,8,AIR)
B(-4,2,9,AIR)
B(-4,2,10,AIR)
B(-4,2,11,SNOW_BLOCK)
B(-4,3,-9,SNOW_BLOCK)
B(-4,3,-8,AIR)
B(-4,3,-7,AIR)
B(-4,3,-6,AIR)
B(-4,3,-5,AIR)
B(-4,3,-4,AIR)
B(-4,3,-3,AIR)
B(-4,3,-2,AIR)
B(-4,3,-1,AIR)
B(-4,3,0,AIR)
B(-4,3,1,AIR)
B(-4,3,2,AIR)
B(-4,3,3,AIR)
B(-4,3,4,AIR)
B(-4,3,5,AIR)
B(-4,3,6,AIR)
B(-4,3,7,AIR)
B(-4,3,8,AIR)
B(-4,3,9,AIR)
B(-4,3,10,AIR)
B(-4,3,11,SNOW_BLOCK)
B(-4,4,-9,SNOW_BLOCK)
B(-4,4,-8,AIR)
B(-4,4,-7,AIR)
B(-4,4,-6,AIR)
B(-4,4,-5,AIR)
B(-4,4,-4,AIR)
B(-4,4,-3,AIR)
B(-4,4,-2,AIR)
B(-4,4,-1,AIR)
B(-4,4,0,AIR)
B(-4,4,1,AIR)
B(-4,4,2,PACKED_ICE)
B(-4,4,3,AIR)
B(-4,4,4,AIR)
B(-4,4,5,AIR)
B(-4,4,6,AIR)
B(-4,4,7,AIR)
B(-4,4,8,AIR)
B(-4,4,9,AIR)
B(-4,4,10,AIR)
B(-4,4,11,SNOW_BLOCK)
B(-4,5,-9,SNOW_BLOCK)
B(-4,5,-8,SNOW_BLOCK)
B(-4,5,-7,AIR)
B(-4,5,-6,AIR)
B(-4,5,-5,AIR)
B(-4,5,-4,AIR)
B(-4,5,-3,AIR)
B(-4,5,-2,AIR)
B(-4,5,-1,AIR)
B(-4,5,0,AIR)
B(-4,5,1,AIR)
B(-4,5,2,PACKED_ICE)
B(-4,5,3,AIR)
B(-4,5,4,AIR)
B(-4,5,5,AIR)
B(-4,5,6,AIR)
B(-4,5,7,AIR)
B(-4,5,8,AIR)
B(-4,5,9,AIR)
B(-4,5,10,SNOW_BLOCK)
B(-4,5,11,SNOW_BLOCK)
B(-4,6,-9,SNOW)
B(-4,6,-8,SNOW_BLOCK)
B(-4,6,-7,AIR)
B(-4,6,-6,AIR)
B(-4,6,-5,AIR)
B(-4,6,-4,AIR)
B(-4,6,-3,AIR)
B(-4,6,-2,AIR)
B(-4,6,-1,AIR)
B(-4,6,0,AIR)
B(-4,6,1,AIR)
B(-4,6,2,PACKED_ICE)
B(-4,6,3,AIR)
B(-4,6,4,AIR)
B(-4,6,5,AIR)
B(-4,6,6,AIR)
B(-4,6,7,AIR)
B(-4,6,8,AIR)
B(-4,6,9,AIR)
B(-4,6,10,SNOW_BLOCK)
B(-4,6,11,SNOW)
B(-4,7,-8,SNOW)
B(-4,7,-7,SNOW_BLOCK)
B(-4,7,-6,AIR)
B(-4,7,-5,AIR)
B(-4,7,-4,AIR)
B(-4,7,-3,AIR)
B(-4,7,-2,AIR)
B(-4,7,-1,AIR)
B(-4,7,0,AIR)
B(-4,7,1,AIR)
B(-4,7,2,PACKED_ICE)
B(-4,7,3,AIR)
B(-4,7,4,AIR)
B(-4,7,5,AIR)
B(-4,7,6,AIR)
B(-4,7,7,AIR)
B(-4,7,8,AIR)
B(-4,7,9,SNOW_BLOCK)
B(-4,7,10,SNOW)
B(-4,8,-7,SNOW_BLOCK)
B(-4,8,-6,AIR)
B(-4,8,-5,AIR)
B(-4,8,-4,AIR)
B(-4,8,-3,AIR)
B(-4,8,-2,AIR)
B(-4,8,-1,AIR)
B(-4,8,0,AIR)
B(-4,8,1,AIR)
B(-4,8,2,PACKED_ICE)
B(-4,8,3,AIR)
B(-4,8,4,AIR)
B(-4,8,5,AIR)
B(-4,8,6,AIR)
B(-4,8,7,AIR)
B(-4,8,8,AIR)
B(-4,8,9,SNOW_BLOCK)
B(-4,9,-7,SNOW)
B(-4,9,-6,SNOW_BLOCK)
B(-4,9,-5,SNOW_BLOCK)
B(-4,9,-4,AIR)
B(-4,9,-3,AIR)
B(-4,9,-2,AIR)
B(-4,9,-1,AIR)
B(-4,9,0,AIR)
B(-4,9,1,AIR)
B(-4,9,2,PACKED_ICE)
B(-4,9,3,AIR)
B(-4,9,4,AIR)
B(-4,9,5,AIR)
B(-4,9,6,AIR)
B(-4,9,7,SNOW_BLOCK)
B(-4,9,8,SNOW_BLOCK)
B(-4,9,9,SNOW:1)
B(-4,10,-6,SNOW)
B(-4,10,-5,SNOW)
B(-4,10,-4,SNOW_BLOCK)
B(-4,10,-3,AIR)
B(-4,10,-2,AIR)
B(-4,10,-1,AIR)
B(-4,10,0,PACKED_ICE)
B(-4,10,1,AIR)
B(-4,10,2,PACKED_ICE)
B(-4,10,3,AIR)
B(-4,10,4,AIR)
B(-4,10,5,AIR)
B(-4,10,6,SNOW_BLOCK)
B(-4,10,7,SNOW)
B(-4,10,8,SNOW)
B(-4,11,-4,SNOW)
B(-4,11,-3,SNOW_BLOCK)
B(-4,11,-2,SNOW_BLOCK)
B(-4,11,-1,SNOW_BLOCK)
B(-4,11,0,SNOW_BLOCK)
B(-4,11,1,SNOW_BLOCK)
B(-4,11,2,SNOW_BLOCK)
B(-4,11,3,SNOW_BLOCK)
B(-4,11,4,SNOW_BLOCK)
B(-4,11,5,SNOW_BLOCK)
B(-4,11,6,SNOW)
B(-4,12,-3,SNOW)
B(-4,12,-2,SNOW)
B(-4,12,-1,SNOW)
B(-4,12,0,SNOW)
B(-4,12,1,SNOW)
B(-4,12,2,SNOW)
B(-4,12,3,SNOW)
B(-4,12,4,SNOW)
B(-4,12,5,SNOW)
B(-3,-4,-10,SNOW_BLOCK)
B(-3,-4,-9,SNOW_BLOCK)
B(-3,-4,-8,SNOW_BLOCK)
B(-3,-4,-7,SNOW_BLOCK)
B(-3,-4,-6,SNOW_BLOCK)
B(-3,-4,-5,DIRT)
B(-3,-4,-4,DIRT)
B(-3,-4,-3,DIRT)
B(-3,-4,-2,SNOW_BLOCK)
B(-3,-4,-1,DIRT)
B(-3,-4,0,DIRT)
B(-3,-4,1,DIRT)
B(-3,-4,2,DIRT)
B(-3,-4,3,DIRT)
B(-3,-4,4,AIR)
B(-3,-4,5,SNOW_BLOCK)
B(-3,-4,6,SNOW_BLOCK)
B(-3,-4,7,SNOW_BLOCK)
B(-3,-4,8,SNOW_BLOCK)
B(-3,-4,9,SNOW_BLOCK)
B(-3,-4,10,SNOW_BLOCK)
B(-3,-4,11,SNOW_BLOCK)
B(-3,-4,12,SNOW_BLOCK)
B(-3,-3,-10,SNOW_BLOCK)
B(-3,-3,-9,SNOW_BLOCK)
B(-3,-3,-8,SNOW_BLOCK)
B(-3,-3,-7,SNOW_BLOCK)
B(-3,-3,-6,SNOW_BLOCK)
B(-3,-3,-5,DIRT)
B(-3,-3,-4,DIRT)
B(-3,-3,-3,DIRT)
B(-3,-3,-2,SNOW_BLOCK)
B(-3,-3,-1,DIRT)
B(-3,-3,0,DIRT)
B(-3,-3,1,DIRT)
B(-3,-3,2,DIRT)
B(-3,-3,3,DIRT)
B(-3,-3,4,AIR)
B(-3,-3,5,SNOW_BLOCK)
B(-3,-3,6,SNOW_BLOCK)
B(-3,-3,7,SNOW_BLOCK)
B(-3,-3,8,SNOW_BLOCK)
B(-3,-3,9,SNOW_BLOCK)
B(-3,-3,10,SNOW_BLOCK)
B(-3,-3,11,SNOW_BLOCK)
B(-3,-3,12,SNOW_BLOCK)
B(-3,-2,-10,SNOW_BLOCK)
B(-3,-2,-9,SNOW_BLOCK)
B(-3,-2,-8,SNOW_BLOCK)
B(-3,-2,-7,SNOW_BLOCK)
B(-3,-2,-6,SNOW_BLOCK)
B(-3,-2,-5,DIRT)
B(-3,-2,-4,DIRT)
B(-3,-2,-3,DIRT)
B(-3,-2,-2,SNOW_BLOCK)
B(-3,-2,-1,DIRT)
B(-3,-2,0,DIRT)
B(-3,-2,1,DIRT)
B(-3,-2,2,DIRT)
B(-3,-2,3,DIRT)
B(-3,-2,4,AIR)
B(-3,-2,5,SNOW_BLOCK)
B(-3,-2,6,SNOW_BLOCK)
B(-3,-2,7,SNOW_BLOCK)
B(-3,-2,8,SNOW_BLOCK)
B(-3,-2,9,SNOW_BLOCK)
B(-3,-2,10,SNOW_BLOCK)
B(-3,-2,11,SNOW_BLOCK)
B(-3,-2,12,SNOW_BLOCK)
B(-3,-1,-10,SNOW_BLOCK)
B(-3,-1,-9,SNOW_BLOCK)
B(-3,-1,-8,SNOW_BLOCK)
B(-3,-1,-7,SNOW_BLOCK)
B(-3,-1,-6,SNOW_BLOCK)
B(-3,-1,-5,GRAVEL)
B(-3,-1,-4,DIRT)
B(-3,-1,-3,DIRT)
B(-3,-1,-2,SNOW_BLOCK)
B(-3,-1,-1,STONE)
B(-3,-1,0,DIRT)
B(-3,-1,1,SNOW_BLOCK)
B(-3,-1,2,GRAVEL)
B(-3,-1,3,SNOW_BLOCK)
B(-3,-1,4,STONE)
B(-3,-1,5,SNOW_BLOCK)
B(-3,-1,6,SNOW_BLOCK)
B(-3,-1,7,SNOW_BLOCK)
B(-3,-1,8,SNOW_BLOCK)
B(-3,-1,9,SNOW_BLOCK)
B(-3,-1,10,SNOW_BLOCK)
B(-3,-1,11,SNOW_BLOCK)
B(-3,-1,12,SNOW_BLOCK)
B(-3,0,-10,SNOW_BLOCK)
B(-3,0,-9,SNOW:1)
B(-3,0,-8,SNOW)
B(-3,0,-7,SNOW)
B(-3,0,-6,AIR)
B(-3,0,-5,AIR)
B(-3,0,-4,AIR)
B(-3,0,-3,AIR)
B(-3,0,-2,AIR)
B(-3,0,-1,AIR)
B(-3,0,0,AIR)
B(-3,0,1,AIR)
B(-3,0,2,AIR)
B(-3,0,3,AIR)
B(-3,0,4,AIR)
B(-3,0,5,AIR)
B(-3,0,6,AIR)
B(-3,0,7,AIR)
B(-3,0,8,SNOW)
B(-3,0,9,AIR)
B(-3,0,10,SNOW:1)
B(-3,0,11,SNOW:3)
B(-3,0,12,SNOW_BLOCK)
B(-3,1,-10,SNOW_BLOCK)
B(-3,1,-9,AIR)
B(-3,1,-8,AIR)
B(-3,1,-7,AIR)
B(-3,1,-6,AIR)
B(-3,1,-5,AIR)
B(-3,1,-4,AIR)
B(-3,1,-3,AIR)
B(-3,1,-2,AIR)
B(-3,1,-1,AIR)
B(-3,1,0,AIR)
B(-3,1,1,AIR)
B(-3,1,2,AIR)
B(-3,1,3,AIR)
B(-3,1,4,AIR)
B(-3,1,5,AIR)
B(-3,1,6,AIR)
B(-3,1,7,AIR)
B(-3,1,8,AIR)
B(-3,1,9,AIR)
B(-3,1,10,AIR)
B(-3,1,11,AIR)
B(-3,1,12,SNOW_BLOCK)
B(-3,2,-10,SNOW_BLOCK)
B(-3,2,-9,AIR)
B(-3,2,-8,AIR)
B(-3,2,-7,AIR)
B(-3,2,-6,AIR)
B(-3,2,-5,AIR)
B(-3,2,-4,AIR)
B(-3,2,-3,AIR)
B(-3,2,-2,AIR)
B(-3,2,-1,AIR)
B(-3,2,0,AIR)
B(-3,2,1,AIR)
B(-3,2,2,AIR)
B(-3,2,3,AIR)
B(-3,2,4,AIR)
B(-3,2,5,AIR)
B(-3,2,6,AIR)
B(-3,2,7,AIR)
B(-3,2,8,AIR)
B(-3,2,9,AIR)
B(-3,2,10,AIR)
B(-3,2,11,AIR)
B(-3,2,12,SNOW_BLOCK)
B(-3,3,-10,SNOW)
B(-3,3,-9,SNOW_BLOCK)
B(-3,3,-8,AIR)
B(-3,3,-7,AIR)
B(-3,3,-6,AIR)
B(-3,3,-5,AIR)
B(-3,3,-4,AIR)
B(-3,3,-3,AIR)
B(-3,3,-2,AIR)
B(-3,3,-1,AIR)
B(-3,3,0,AIR)
B(-3,3,1,AIR)
B(-3,3,2,AIR)
B(-3,3,3,AIR)
B(-3,3,4,AIR)
B(-3,3,5,AIR)
B(-3,3,6,AIR)
B(-3,3,7,AIR)
B(-3,3,8,AIR)
B(-3,3,9,AIR)
B(-3,3,10,AIR)
B(-3,3,11,SNOW_BLOCK)
B(-3,3,12,SNOW)
B(-3,4,-9,SNOW_BLOCK)
B(-3,4,-8,AIR)
B(-3,4,-7,AIR)
B(-3,4,-6,AIR)
B(-3,4,-5,AIR)
B(-3,4,-4,AIR)
B(-3,4,-3,AIR)
B(-3,4,-2,AIR)
B(-3,4,-1,AIR)
B(-3,4,0,AIR)
B(-3,4,1,AIR)
B(-3,4,2,AIR)
B(-3,4,3,AIR)
B(-3,4,4,AIR)
B(-3,4,5,AIR)
B(-3,4,6,AIR)
B(-3,4,7,AIR)
B(-3,4,8,AIR)
B(-3,4,9,AIR)
B(-3,4,10,AIR)
B(-3,4,11,SNOW_BLOCK)
B(-3,5,-9,SNOW_BLOCK)
B(-3,5,-8,AIR)
B(-3,5,-7,AIR)
B(-3,5,-6,AIR)
B(-3,5,-5,AIR)
B(-3,5,-4,AIR)
B(-3,5,-3,AIR)
B(-3,5,-2,AIR)
B(-3,5,-1,AIR)
B(-3,5,0,AIR)
B(-3,5,1,AIR)
B(-3,5,2,AIR)
B(-3,5,3,AIR)
B(-3,5,4,AIR)
B(-3,5,5,AIR)
B(-3,5,6,AIR)
B(-3,5,7,AIR)
B(-3,5,8,AIR)
B(-3,5,9,AIR)
B(-3,5,10,AIR)
B(-3,5,11,SNOW_BLOCK)
B(-3,6,-9,SNOW)
B(-3,6,-8,SNOW_BLOCK)
B(-3,6,-7,AIR)
B(-3,6,-6,AIR)
B(-3,6,-5,AIR)
B(-3,6,-4,AIR)
B(-3,6,-3,AIR)
B(-3,6,-2,AIR)
B(-3,6,-1,AIR)
B(-3,6,0,AIR)
B(-3,6,1,AIR)
B(-3,6,2,AIR)
B(-3,6,3,AIR)
B(-3,6,4,AIR)
B(-3,6,5,AIR)
B(-3,6,6,AIR)
B(-3,6,7,AIR)
B(-3,6,8,AIR)
B(-3,6,9,AIR)
B(-3,6,10,SNOW_BLOCK)
B(-3,6,11,SNOW)
B(-3,7,-8,SNOW_BLOCK)
B(-3,7,-7,AIR)
B(-3,7,-6,AIR)
B(-3,7,-5,AIR)
B(-3,7,-4,PACKED_ICE)
B(-3,7,-3,AIR)
B(-3,7,-2,AIR)
B(-3,7,-1,AIR)
B(-3,7,0,AIR)
B(-3,7,1,AIR)
B(-3,7,2,AIR)
B(-3,7,3,AIR)
B(-3,7,4,AIR)
B(-3,7,5,AIR)
B(-3,7,6,AIR)
B(-3,7,7,AIR)
B(-3,7,8,AIR)
B(-3,7,9,SNOW_BLOCK)
B(-3,7,10,SNOW_BLOCK)
B(-3,8,-8,SNOW)
B(-3,8,-7,SNOW_BLOCK)
B(-3,8,-6,AIR)
B(-3,8,-5,AIR)
B(-3,8,-4,PACKED_ICE)
B(-3,8,-3,AIR)
B(-3,8,-2,AIR)
B(-3,8,-1,PACKED_ICE)
B(-3,8,0,AIR)
B(-3,8,1,AIR)
B(-3,8,2,AIR)
B(-3,8,3,AIR)
B(-3,8,4,AIR)
B(-3,8,5,AIR)
B(-3,8,6,AIR)
B(-3,8,7,AIR)
B(-3,8,8,AIR)
B(-3,8,9,SNOW_BLOCK)
B(-3,8,10,SNOW)
B(-3,9,-7,SNOW)
B(-3,9,-6,SNOW_BLOCK)
B(-3,9,-5,AIR)
B(-3,9,-4,PACKED_ICE)
B(-3,9,-3,AIR)
B(-3,9,-2,AIR)
B(-3,9,-1,PACKED_ICE)
B(-3,9,0,AIR)
B(-3,9,1,AIR)
B(-3,9,2,AIR)
B(-3,9,3,AIR)
B(-3,9,4,AIR)
B(-3,9,5,AIR)
B(-3,9,6,AIR)
B(-3,9,7,AIR)
B(-3,9,8,SNOW_BLOCK)
B(-3,9,9,SNOW:1)
B(-3,10,-6,SNOW)
B(-3,10,-5,SNOW_BLOCK)
B(-3,10,-4,SNOW_BLOCK)
B(-3,10,-3,AIR)
B(-3,10,-2,AIR)
B(-3,10,-1,PACKED_ICE)
B(-3,10,0,AIR)
B(-3,10,1,PACKED_ICE)
B(-3,10,2,AIR)
B(-3,10,3,AIR)
B(-3,10,4,AIR)
B(-3,10,5,AIR)
B(-3,10,6,SNOW_BLOCK)
B(-3,10,7,SNOW_BLOCK)
B(-3,10,8,SNOW)
B(-3,11,-5,SNOW)
B(-3,11,-4,SNOW)
B(-3,11,-3,SNOW_BLOCK)
B(-3,11,-2,SNOW_BLOCK)
B(-3,11,-1,SNOW_BLOCK)
B(-3,11,0,AIR)
B(-3,11,1,PACKED_ICE)
B(-3,11,2,PACKED_ICE)
B(-3,11,3,SNOW_BLOCK)
B(-3,11,4,SNOW_BLOCK)
B(-3,11,5,SNOW_BLOCK)
B(-3,11,6,SNOW)
B(-3,11,7,SNOW)
B(-3,12,-3,SNOW)
B(-3,12,-2,SNOW)
B(-3,12,-1,SNOW)
B(-3,12,0,SNOW_BLOCK)
B(-3,12,1,SNOW_BLOCK)
B(-3,12,2,SNOW_BLOCK)
B(-3,12,3,SNOW)
B(-3,12,4,SNOW)
B(-3,12,5,SNOW)
B(-3,13,0,SNOW)
B(-3,13,1,SNOW)
B(-3,13,2,SNOW:1)
B(-2,-4,-10,SNOW_BLOCK)
B(-2,-4,-9,SNOW_BLOCK)
B(-2,-4,-8,SNOW_BLOCK)
B(-2,-4,-7,SNOW_BLOCK)
B(-2,-4,-6,SNOW_BLOCK)
B(-2,-4,-5,DIRT)
B(-2,-4,-4,DIRT)
B(-2,-4,-3,DIRT)
B(-2,-4,-2,SNOW_BLOCK)
B(-2,-4,-1,DIRT)
B(-2,-4,0,DIRT)
B(-2,-4,1,DIRT)
B(-2,-4,2,DIRT)
B(-2,-4,3,AIR)
B(-2,-4,4,DIRT)
B(-2,-4,5,SNOW_BLOCK)
B(-2,-4,6,SNOW_BLOCK)
B(-2,-4,7,SNOW_BLOCK)
B(-2,-4,8,SNOW_BLOCK)
B(-2,-4,9,SNOW_BLOCK)
B(-2,-4,10,SNOW_BLOCK)
B(-2,-4,11,SNOW_BLOCK)
B(-2,-4,12,SNOW_BLOCK)
B(-2,-3,-10,SNOW_BLOCK)
B(-2,-3,-9,SNOW_BLOCK)
B(-2,-3,-8,SNOW_BLOCK)
B(-2,-3,-7,SNOW_BLOCK)
B(-2,-3,-6,SNOW_BLOCK)
B(-2,-3,-5,DIRT)
B(-2,-3,-4,DIRT)
B(-2,-3,-3,DIRT)
B(-2,-3,-2,SNOW_BLOCK)
B(-2,-3,-1,DIRT)
B(-2,-3,0,DIRT)
B(-2,-3,1,DIRT)
B(-2,-3,2,DIRT)
B(-2,-3,3,AIR)
B(-2,-3,4,DIRT)
B(-2,-3,5,SNOW_BLOCK)
B(-2,-3,6,SNOW_BLOCK)
B(-2,-3,7,SNOW_BLOCK)
B(-2,-3,8,SNOW_BLOCK)
B(-2,-3,9,SNOW_BLOCK)
B(-2,-3,10,SNOW_BLOCK)
B(-2,-3,11,SNOW_BLOCK)
B(-2,-3,12,SNOW_BLOCK)
B(-2,-2,-10,SNOW_BLOCK)
B(-2,-2,-9,SNOW_BLOCK)
B(-2,-2,-8,SNOW_BLOCK)
B(-2,-2,-7,SNOW_BLOCK)
B(-2,-2,-6,SNOW_BLOCK)
B(-2,-2,-5,DIRT)
B(-2,-2,-4,DIRT)
B(-2,-2,-3,DIRT)
B(-2,-2,-2,SNOW_BLOCK)
B(-2,-2,-1,DIRT)
B(-2,-2,0,DIRT)
B(-2,-2,1,DIRT)
B(-2,-2,2,DIRT)
B(-2,-2,3,AIR)
B(-2,-2,4,DIRT)
B(-2,-2,5,SNOW_BLOCK)
B(-2,-2,6,SNOW_BLOCK)
B(-2,-2,7,SNOW_BLOCK)
B(-2,-2,8,SNOW_BLOCK)
B(-2,-2,9,SNOW_BLOCK)
B(-2,-2,10,SNOW_BLOCK)
B(-2,-2,11,SNOW_BLOCK)
B(-2,-2,12,SNOW_BLOCK)
B(-2,-1,-10,SNOW_BLOCK)
B(-2,-1,-9,SNOW_BLOCK)
B(-2,-1,-8,SNOW_BLOCK)
B(-2,-1,-7,SNOW_BLOCK)
B(-2,-1,-6,SNOW_BLOCK)
B(-2,-1,-5,DIRT)
B(-2,-1,-4,GRAVEL)
B(-2,-1,-3,SNOW_BLOCK)
B(-2,-1,-2,SNOW_BLOCK)
B(-2,-1,-1,STONE)
B(-2,-1,0,STONE)
B(-2,-1,1,STONE)
B(-2,-1,2,DIRT)
B(-2,-1,3,STONE)
B(-2,-1,4,STONE)
B(-2,-1,5,SNOW_BLOCK)
B(-2,-1,6,SNOW_BLOCK)
B(-2,-1,7,SNOW_BLOCK)
B(-2,-1,8,SNOW_BLOCK)
B(-2,-1,9,SNOW_BLOCK)
B(-2,-1,10,SNOW_BLOCK)
B(-2,-1,11,SNOW_BLOCK)
B(-2,-1,12,SNOW_BLOCK)
B(-2,0,-10,SNOW_BLOCK)
B(-2,0,-9,AIR)
B(-2,0,-8,SNOW)
B(-2,0,-7,AIR)
B(-2,0,-6,AIR)
B(-2,0,-5,AIR)
B(-2,0,-4,AIR)
B(-2,0,-3,AIR)
B(-2,0,-2,AIR)
B(-2,0,-1,AIR)
B(-2,0,0,AIR)
B(-2,0,1,AIR)
B(-2,0,2,AIR)
B(-2,0,3,AIR)
B(-2,0,4,AIR)
B(-2,0,5,AIR)
B(-2,0,6,AIR)
B(-2,0,7,AIR)
B(-2,0,8,AIR)
B(-2,0,9,AIR)
B(-2,0,10,SNOW)
B(-2,0,11,SNOW)
B(-2,0,12,SNOW_BLOCK)
B(-2,1,-10,SNOW_BLOCK)
B(-2,1,-9,AIR)
B(-2,1,-8,AIR)
B(-2,1,-7,AIR)
B(-2,1,-6,AIR)
B(-2,1,-5,AIR)
B(-2,1,-4,AIR)
B(-2,1,-3,AIR)
B(-2,1,-2,AIR)
B(-2,1,-1,AIR)
B(-2,1,0,AIR)
B(-2,1,1,AIR)
B(-2,1,2,AIR)
B(-2,1,3,AIR)
B(-2,1,4,AIR)
B(-2,1,5,AIR)
B(-2,1,6,AIR)
B(-2,1,7,AIR)
B(-2,1,8,AIR)
B(-2,1,9,AIR)
B(-2,1,10,AIR)
B(-2,1,11,AIR)
B(-2,1,12,SNOW_BLOCK)
B(-2,2,-10,SNOW_BLOCK)
B(-2,2,-9,AIR)
B(-2,2,-8,AIR)
B(-2,2,-7,AIR)
B(-2,2,-6,AIR)
B(-2,2,-5,AIR)
B(-2,2,-4,AIR)
B(-2,2,-3,AIR)
B(-2,2,-2,AIR)
B(-2,2,-1,AIR)
B(-2,2,0,AIR)
B(-2,2,1,AIR)
B(-2,2,2,AIR)
B(-2,2,3,AIR)
B(-2,2,4,AIR)
B(-2,2,5,AIR)
B(-2,2,6,AIR)
B(-2,2,7,AIR)
B(-2,2,8,AIR)
B(-2,2,9,AIR)
B(-2,2,10,AIR)
B(-2,2,11,AIR)
B(-2,2,12,SNOW_BLOCK)
B(-2,3,-10,SNOW_BLOCK)
B(-2,3,-9,AIR)
B(-2,3,-8,AIR)
B(-2,3,-7,AIR)
B(-2,3,-6,AIR)
B(-2,3,-5,AIR)
B(-2,3,-4,AIR)
B(-2,3,-3,AIR)
B(-2,3,-2,AIR)
B(-2,3,-1,AIR)
B(-2,3,0,AIR)
B(-2,3,1,AIR)
B(-2,3,2,AIR)
B(-2,3,3,AIR)
B(-2,3,4,AIR)
B(-2,3,5,AIR)
B(-2,3,6,AIR)
B(-2,3,7,AIR)
B(-2,3,8,AIR)
B(-2,3,9,AIR)
B(-2,3,10,AIR)
B(-2,3,11,AIR)
B(-2,3,12,SNOW_BLOCK)
B(-2,4,-10,SNOW)
B(-2,4,-9,SNOW_BLOCK)
B(-2,4,-8,AIR)
B(-2,4,-7,AIR)
B(-2,4,-6,AIR)
B(-2,4,-5,AIR)
B(-2,4,-4,AIR)
B(-2,4,-3,AIR)
B(-2,4,-2,AIR)
B(-2,4,-1,AIR)
B(-2,4,0,AIR)
B(-2,4,1,AIR)
B(-2,4,2,AIR)
B(-2,4,3,AIR)
B(-2,4,4,AIR)
B(-2,4,5,AIR)
B(-2,4,6,AIR)
B(-2,4,7,PACKED_ICE)
B(-2,4,8,AIR)
B(-2,4,9,AIR)
B(-2,4,10,AIR)
B(-2,4,11,SNOW_BLOCK)
B(-2,4,12,SNOW)
B(-2,5,-9,SNOW_BLOCK)
B(-2,5,-8,AIR)
B(-2,5,-7,AIR)
B(-2,5,-6,AIR)
B(-2,5,-5,AIR)
B(-2,5,-4,AIR)
B(-2,5,-3,AIR)
B(-2,5,-2,AIR)
B(-2,5,-1,AIR)
B(-2,5,0,AIR)
B(-2,5,1,AIR)
B(-2,5,2,AIR)
B(-2,5,3,AIR)
B(-2,5,4,AIR)
B(-2,5,5,AIR)
B(-2,5,6,AIR)
B(-2,5,7,PACKED_ICE)
B(-2,5,8,AIR)
B(-2,5,9,AIR)
B(-2,5,10,AIR)
B(-2,5,11,SNOW_BLOCK)
B(-2,6,-9,SNOW_BLOCK)
B(-2,6,-8,SNOW_BLOCK)
B(-2,6,-7,AIR)
B(-2,6,-6,AIR)
B(-2,6,-5,AIR)
B(-2,6,-4,AIR)
B(-2,6,-3,AIR)
B(-2,6,-2,AIR)
B(-2,6,-1,AIR)
B(-2,6,0,AIR)
B(-2,6,1,AIR)
B(-2,6,2,AIR)
B(-2,6,3,AIR)
B(-2,6,4,AIR)
B(-2,6,5,AIR)
B(-2,6,6,AIR)
B(-2,6,7,PACKED_ICE)
B(-2,6,8,AIR)
B(-2,6,9,AIR)
B(-2,6,10,SNOW_BLOCK)
B(-2,6,11,SNOW_BLOCK)
B(-2,7,-9,SNOW)
B(-2,7,-8,SNOW_BLOCK)
B(-2,7,-7,AIR)
B(-2,7,-6,AIR)
B(-2,7,-5,AIR)
B(-2,7,-4,AIR)
B(-2,7,-3,AIR)
B(-2,7,-2,AIR)
B(-2,7,-1,AIR)
B(-2,7,0,AIR)
B(-2,7,1,AIR)
B(-2,7,2,AIR)
B(-2,7,3,AIR)
B(-2,7,4,AIR)
B(-2,7,5,AIR)
B(-2,7,6,AIR)
B(-2,7,7,PACKED_ICE)
B(-2,7,8,AIR)
B(-2,7,9,AIR)
B(-2,7,10,SNOW_BLOCK)
B(-2,7,11,SNOW)
B(-2,8,-8,SNOW)
B(-2,8,-7,SNOW_BLOCK)
B(-2,8,-6,AIR)
B(-2,8,-5,AIR)
B(-2,8,-4,AIR)
B(-2,8,-3,AIR)
B(-2,8,-2,AIR)
B(-2,8,-1,AIR)
B(-2,8,0,AIR)
B(-2,8,1,AIR)
B(-2,8,2,AIR)
B(-2,8,3,AIR)
B(-2,8,4,AIR)
B(-2,8,5,AIR)
B(-2,8,6,AIR)
B(-2,8,7,PACKED_ICE)
B(-2,8,8,AIR)
B(-2,8,9,SNOW_BLOCK)
B(-2,8,10,SNOW)
B(-2,9,-7,SNOW_BLOCK)
B(-2,9,-6,SNOW_BLOCK)
B(-2,9,-5,AIR)
B(-2,9,-4,AIR)
B(-2,9,-3,AIR)
B(-2,9,-2,AIR)
B(-2,9,-1,AIR)
B(-2,9,0,AIR)
B(-2,9,1,AIR)
B(-2,9,2,AIR)
B(-2,9,3,AIR)
B(-2,9,4,AIR)
B(-2,9,5,AIR)
B(-2,9,6,AIR)
B(-2,9,7,PACKED_ICE)
B(-2,9,8,SNOW_BLOCK)
B(-2,9,9,SNOW_BLOCK)
B(-2,10,-7,SNOW)
B(-2,10,-6,SNOW)
B(-2,10,-5,SNOW_BLOCK)
B(-2,10,-4,AIR)
B(-2,10,-3,AIR)
B(-2,10,-2,AIR)
B(-2,10,-1,PACKED_ICE)
B(-2,10,0,AIR)
B(-2,10,1,AIR)
B(-2,10,2,AIR)
B(-2,10,3,AIR)
B(-2,10,4,PACKED_ICE)
B(-2,10,5,AIR)
B(-2,10,6,PACKED_ICE)
B(-2,10,7,SNOW_BLOCK)
B(-2,10,8,SNOW)
B(-2,10,9,SNOW)
B(-2,11,-5,SNOW)
B(-2,11,-4,SNOW_BLOCK)
B(-2,11,-3,SNOW_BLOCK)
B(-2,11,-2,SNOW_BLOCK)
B(-2,11,-1,PACKED_ICE)
B(-2,11,0,AIR)
B(-2,11,1,AIR)
B(-2,11,2,AIR)
B(-2,11,3,PACKED_ICE)
B(-2,11,4,SNOW_BLOCK)
B(-2,11,5,SNOW_BLOCK)
B(-2,11,6,SNOW_BLOCK)
B(-2,11,7,SNOW)
B(-2,12,-4,SNOW)
B(-2,12,-3,SNOW)
B(-2,12,-2,SNOW)
B(-2,12,-1,SNOW_BLOCK)
B(-2,12,0,SNOW_BLOCK)
B(-2,12,1,SNOW_BLOCK)
B(-2,12,2,SNOW_BLOCK)
B(-2,12,3,SNOW_BLOCK)
B(-2,12,4,SNOW)
B(-2,12,5,SNOW)
B(-2,12,6,SNOW)
B(-2,13,-1,SNOW)
B(-2,13,0,SNOW)
B(-2,13,1,SNOW)
B(-2,13,2,SNOW)
B(-2,13,3,SNOW)
B(-1,-4,-11,SNOW_BLOCK)
B(-1,-4,-10,SNOW_BLOCK)
B(-1,-4,-9,SNOW_BLOCK)
B(-1,-4,-8,SNOW_BLOCK)
B(-1,-4,-7,SNOW_BLOCK)
B(-1,-4,-6,SNOW_BLOCK)
B(-1,-4,-5,SNOW_BLOCK)
B(-1,-4,-4,DIRT)
B(-1,-4,-3,DIRT)
B(-1,-4,-2,DIRT)
B(-1,-4,-1,DIRT)
B(-1,-4,0,DIRT)
B(-1,-4,1,DIRT)
B(-1,-4,2,DIRT)
B(-1,-4,3,DIRT)
B(-1,-4,4,DIRT)
B(-1,-4,5,SNOW_BLOCK)
B(-1,-4,6,SNOW_BLOCK)
B(-1,-4,7,SNOW_BLOCK)
B(-1,-4,8,SNOW_BLOCK)
B(-1,-4,9,SNOW_BLOCK)
B(-1,-4,10,SNOW_BLOCK)
B(-1,-4,11,SNOW_BLOCK)
B(-1,-4,12,SNOW_BLOCK)
B(-1,-4,13,SNOW_BLOCK)
B(-1,-3,-11,SNOW_BLOCK)
B(-1,-3,-10,SNOW_BLOCK)
B(-1,-3,-9,SNOW_BLOCK)
B(-1,-3,-8,SNOW_BLOCK)
B(-1,-3,-7,SNOW_BLOCK)
B(-1,-3,-6,SNOW_BLOCK)
B(-1,-3,-5,SNOW_BLOCK)
B(-1,-3,-4,DIRT)
B(-1,-3,-3,DIRT)
B(-1,-3,-2,DIRT)
B(-1,-3,-1,DIRT)
B(-1,-3,0,DIRT)
B(-1,-3,1,DIRT)
B(-1,-3,2,DIRT)
B(-1,-3,3,DIRT)
B(-1,-3,4,DIRT)
B(-1,-3,5,SNOW_BLOCK)
B(-1,-3,6,SNOW_BLOCK)
B(-1,-3,7,SNOW_BLOCK)
B(-1,-3,8,SNOW_BLOCK)
B(-1,-3,9,SNOW_BLOCK)
B(-1,-3,10,SNOW_BLOCK)
B(-1,-3,11,SNOW_BLOCK)
B(-1,-3,12,SNOW_BLOCK)
B(-1,-3,13,SNOW_BLOCK)
B(-1,-2,-11,SNOW_BLOCK)
B(-1,-2,-10,SNOW_BLOCK)
B(-1,-2,-9,SNOW_BLOCK)
B(-1,-2,-8,SNOW_BLOCK)
B(-1,-2,-7,SNOW_BLOCK)
B(-1,-2,-6,SNOW_BLOCK)
B(-1,-2,-5,SNOW_BLOCK)
B(-1,-2,-4,DIRT)
B(-1,-2,-3,DIRT)
B(-1,-2,-2,DIRT)
B(-1,-2,-1,DIRT)
B(-1,-2,0,DIRT)
B(-1,-2,1,DIRT)
B(-1,-2,2,DIRT)
B(-1,-2,3,DIRT)
B(-1,-2,4,DIRT)
B(-1,-2,5,DIRT)
B(-1,-2,6,SNOW_BLOCK)
B(-1,-2,7,SNOW_BLOCK)
B(-1,-2,8,SNOW_BLOCK)
B(-1,-2,9,SNOW_BLOCK)
B(-1,-2,10,SNOW_BLOCK)
B(-1,-2,11,SNOW_BLOCK)
B(-1,-2,12,SNOW_BLOCK)
B(-1,-2,13,SNOW_BLOCK)
B(-1,-1,-11,SNOW_BLOCK)
B(-1,-1,-10,SNOW_BLOCK)
B(-1,-1,-9,SNOW_BLOCK)
B(-1,-1,-8,SNOW_BLOCK)
B(-1,-1,-7,SNOW_BLOCK)
B(-1,-1,-6,SNOW_BLOCK)
B(-1,-1,-5,SNOW_BLOCK)
B(-1,-1,-4,STONE)
B(-1,-1,-3,DIRT)
B(-1,-1,-2,STONE)
B(-1,-1,-1,STONE)
B(-1,-1,0,DIRT)
B(-1,-1,1,STONE)
B(-1,-1,2,DIRT)
B(-1,-1,3,STONE)
B(-1,-1,4,STONE)
B(-1,-1,5,DIRT)
B(-1,-1,6,SNOW_BLOCK)
B(-1,-1,7,GRAVEL)
B(-1,-1,8,SNOW_BLOCK)
B(-1,-1,9,SNOW_BLOCK)
B(-1,-1,10,SNOW_BLOCK)
B(-1,-1,11,SNOW_BLOCK)
B(-1,-1,12,SNOW_BLOCK)
B(-1,-1,13,SNOW_BLOCK)
B(-1,0,-11,SNOW_BLOCK)
B(-1,0,-10,AIR)
B(-1,0,-9,AIR)
B(-1,0,-8,AIR)
B(-1,0,-7,AIR)
B(-1,0,-6,AIR)
B(-1,0,-5,AIR)
B(-1,0,-4,AIR)
B(-1,0,-3,AIR)
B(-1,0,-2,AIR)
B(-1,0,-1,AIR)
B(-1,0,0,STEP:3)
B(-1,0,1,AIR)
B(-1,0,2,AIR)
B(-1,0,3,AIR)
B(-1,0,4,AIR)
B(-1,0,5,AIR)
B(-1,0,6,AIR)
B(-1,0,7,AIR)
B(-1,0,8,AIR)
B(-1,0,9,AIR)
B(-1,0,10,AIR)
B(-1,0,11,SNOW:1)
B(-1,0,12,AIR)
B(-1,0,13,SNOW_BLOCK)
B(-1,1,-11,SNOW_BLOCK)
B(-1,1,-10,AIR)
B(-1,1,-9,AIR)
B(-1,1,-8,AIR)
B(-1,1,-7,AIR)
B(-1,1,-6,AIR)
B(-1,1,-5,AIR)
B(-1,1,-4,AIR)
B(-1,1,-3,AIR)
B(-1,1,-2,AIR)
B(-1,1,-1,AIR)
B(-1,1,0,AIR)
B(-1,1,1,AIR)
B(-1,1,2,AIR)
B(-1,1,3,AIR)
B(-1,1,4,AIR)
B(-1,1,5,AIR)
Entity(-1,1,6,SnowMan,2,PumpkinSnowGolem.txt)
B(-1,1,7,AIR)
B(-1,1,8,AIR)
B(-1,1,9,AIR)
B(-1,1,10,AIR)
B(-1,1,11,AIR)
B(-1,1,12,AIR)
B(-1,1,13,SNOW_BLOCK)
B(-1,2,-11,SNOW)
B(-1,2,-10,SNOW_BLOCK)
B(-1,2,-9,AIR)
B(-1,2,-8,AIR)
B(-1,2,-7,AIR)
B(-1,2,-6,AIR)
B(-1,2,-5,AIR)
B(-1,2,-4,AIR)
B(-1,2,-3,AIR)
B(-1,2,-2,AIR)
B(-1,2,-1,AIR)
B(-1,2,0,AIR)
B(-1,2,1,AIR)
B(-1,2,2,AIR)
B(-1,2,3,AIR)
B(-1,2,4,AIR)
B(-1,2,5,AIR)
B(-1,2,6,AIR)
B(-1,2,7,AIR)
B(-1,2,8,AIR)
B(-1,2,9,AIR)
B(-1,2,10,AIR)
B(-1,2,11,AIR)
B(-1,2,12,SNOW_BLOCK)
B(-1,2,13,SNOW)
B(-1,3,-10,SNOW_BLOCK)
B(-1,3,-9,AIR)
B(-1,3,-8,AIR)
B(-1,3,-7,AIR)
B(-1,3,-6,AIR)
B(-1,3,-5,AIR)
B(-1,3,-4,AIR)
B(-1,3,-3,AIR)
B(-1,3,-2,AIR)
B(-1,3,-1,AIR)
B(-1,3,0,AIR)
B(-1,3,1,AIR)
B(-1,3,2,AIR)
B(-1,3,3,AIR)
B(-1,3,4,AIR)
B(-1,3,5,AIR)
B(-1,3,6,AIR)
B(-1,3,7,AIR)
B(-1,3,8,AIR)
B(-1,3,9,AIR)
B(-1,3,10,AIR)
B(-1,3,11,AIR)
B(-1,3,12,SNOW_BLOCK)
B(-1,4,-10,SNOW_BLOCK)
B(-1,4,-9,AIR)
B(-1,4,-8,AIR)
B(-1,4,-7,AIR)
B(-1,4,-6,AIR)
B(-1,4,-5,AIR)
B(-1,4,-4,AIR)
B(-1,4,-3,AIR)
B(-1,4,-2,AIR)
B(-1,4,-1,AIR)
B(-1,4,0,AIR)
B(-1,4,1,AIR)
B(-1,4,2,AIR)
B(-1,4,3,AIR)
B(-1,4,4,AIR)
B(-1,4,5,AIR)
B(-1,4,6,AIR)
B(-1,4,7,AIR)
B(-1,4,8,AIR)
B(-1,4,9,AIR)
B(-1,4,10,AIR)
B(-1,4,11,SNOW_BLOCK)
B(-1,4,12,SNOW_BLOCK)
B(-1,5,-10,SNOW)
B(-1,5,-9,SNOW_BLOCK)
B(-1,5,-8,AIR)
B(-1,5,-7,AIR)
B(-1,5,-6,AIR)
B(-1,5,-5,AIR)
B(-1,5,-4,AIR)
B(-1,5,-3,AIR)
B(-1,5,-2,AIR)
B(-1,5,-1,AIR)
B(-1,5,0,AIR)
B(-1,5,1,AIR)
B(-1,5,2,AIR)
B(-1,5,3,AIR)
B(-1,5,4,AIR)
B(-1,5,5,AIR)
B(-1,5,6,AIR)
B(-1,5,7,AIR)
B(-1,5,8,AIR)
B(-1,5,9,AIR)
B(-1,5,10,AIR)
B(-1,5,11,SNOW_BLOCK)
B(-1,5,12,SNOW)
B(-1,6,-9,SNOW_BLOCK)
B(-1,6,-8,AIR)
B(-1,6,-7,AIR)
B(-1,6,-6,AIR)
B(-1,6,-5,AIR)
B(-1,6,-4,AIR)
B(-1,6,-3,AIR)
B(-1,6,-2,AIR)
B(-1,6,-1,AIR)
B(-1,6,0,AIR)
B(-1,6,1,AIR)
B(-1,6,2,AIR)
B(-1,6,3,AIR)
B(-1,6,4,AIR)
B(-1,6,5,AIR)
B(-1,6,6,AIR)
B(-1,6,7,AIR)
B(-1,6,8,AIR)
B(-1,6,9,AIR)
B(-1,6,10,AIR)
B(-1,6,11,SNOW_BLOCK)
B(-1,7,-9,SNOW)
B(-1,7,-8,SNOW_BLOCK)
B(-1,7,-7,AIR)
B(-1,7,-6,AIR)
B(-1,7,-5,AIR)
B(-1,7,-4,AIR)
B(-1,7,-3,AIR)
B(-1,7,-2,AIR)
B(-1,7,-1,AIR)
B(-1,7,0,AIR)
B(-1,7,1,AIR)
B(-1,7,2,AIR)
B(-1,7,3,AIR)
B(-1,7,4,AIR)
B(-1,7,5,AIR)
B(-1,7,6,AIR)
B(-1,7,7,AIR)
B(-1,7,8,AIR)
B(-1,7,9,AIR)
B(-1,7,10,SNOW_BLOCK)
B(-1,7,11,SNOW)
B(-1,8,-8,SNOW_BLOCK)
B(-1,8,-7,AIR)
B(-1,8,-6,AIR)
B(-1,8,-5,AIR)
B(-1,8,-4,AIR)
B(-1,8,-3,AIR)
B(-1,8,-2,AIR)
B(-1,8,-1,AIR)
B(-1,8,0,AIR)
B(-1,8,1,AIR)
B(-1,8,2,AIR)
B(-1,8,3,AIR)
B(-1,8,4,AIR)
B(-1,8,5,AIR)
B(-1,8,6,AIR)
B(-1,8,7,AIR)
B(-1,8,8,AIR)
B(-1,8,9,AIR)
B(-1,8,10,SNOW_BLOCK)
B(-1,9,-8,SNOW)
B(-1,9,-7,SNOW_BLOCK)
B(-1,9,-6,AIR)
B(-1,9,-5,AIR)
B(-1,9,-4,AIR)
B(-1,9,-3,AIR)
B(-1,9,-2,AIR)
B(-1,9,-1,AIR)
B(-1,9,0,AIR)
B(-1,9,1,AIR)
B(-1,9,2,AIR)
B(-1,9,3,AIR)
B(-1,9,4,AIR)
B(-1,9,5,AIR)
B(-1,9,6,AIR)
B(-1,9,7,PACKED_ICE)
B(-1,9,8,AIR)
B(-1,9,9,SNOW_BLOCK)
B(-1,9,10,SNOW)
B(-1,10,-7,SNOW)
B(-1,10,-6,SNOW_BLOCK)
B(-1,10,-5,SNOW_BLOCK)
B(-1,10,-4,AIR)
B(-1,10,-3,PACKED_ICE)
B(-1,10,-2,AIR)
B(-1,10,-1,AIR)
B(-1,10,0,AIR)
B(-1,10,1,AIR)
B(-1,10,2,PACKED_ICE)
B(-1,10,3,AIR)
B(-1,10,4,AIR)
B(-1,10,5,AIR)
B(-1,10,6,AIR)
B(-1,10,7,SNOW_BLOCK)
B(-1,10,8,SNOW_BLOCK)
B(-1,10,9,SNOW)
B(-1,11,-6,SNOW:1)
B(-1,11,-5,SNOW:1)
B(-1,11,-4,SNOW_BLOCK)
B(-1,11,-3,SNOW_BLOCK)
B(-1,11,-2,PACKED_ICE)
B(-1,11,-1,AIR)
B(-1,11,0,AIR)
B(-1,11,1,AIR)
B(-1,11,2,PACKED_ICE)
B(-1,11,3,PACKED_ICE)
B(-1,11,4,AIR)
B(-1,11,5,SNOW_BLOCK)
B(-1,11,6,SNOW_BLOCK)
B(-1,11,7,SNOW)
B(-1,11,8,SNOW)
B(-1,12,-4,SNOW:1)
B(-1,12,-3,SNOW)
B(-1,12,-2,SNOW_BLOCK)
B(-1,12,-1,SNOW_BLOCK)
B(-1,12,0,SNOW_BLOCK)
B(-1,12,1,SNOW_BLOCK)
B(-1,12,2,SNOW_BLOCK)
B(-1,12,3,SNOW_BLOCK)
B(-1,12,4,SNOW_BLOCK)
B(-1,12,5,SNOW)
B(-1,12,6,SNOW)
B(-1,13,-2,SNOW)
B(-1,13,-1,SNOW)
B(-1,13,0,SNOW)
B(-1,13,1,SNOW:1)
B(-1,13,2,SNOW)
B(-1,13,3,SNOW)
B(-1,13,4,SNOW)
B(0,-4,-11,SNOW_BLOCK)
B(0,-4,-10,SNOW_BLOCK)
B(0,-4,-9,SNOW_BLOCK)
B(0,-4,-8,SNOW_BLOCK)
B(0,-4,-7,SNOW_BLOCK)
B(0,-4,-6,SNOW_BLOCK)
B(0,-4,-5,DIRT)
B(0,-4,-4,DIRT)
B(0,-4,-3,DIRT)
B(0,-4,-2,DIRT)
B(0,-4,-1,DIRT)
B(0,-4,0,DIRT)
B(0,-4,1,STONE)
B(0,-4,2,DIRT)
B(0,-4,3,DIRT)
B(0,-4,4,DIRT)
B(0,-4,5,SNOW_BLOCK)
B(0,-4,6,SNOW_BLOCK)
B(0,-4,7,SNOW_BLOCK)
B(0,-4,8,SNOW_BLOCK)
B(0,-4,9,SNOW_BLOCK)
B(0,-4,10,SNOW_BLOCK)
B(0,-4,11,SNOW_BLOCK)
B(0,-4,12,SNOW_BLOCK)
B(0,-4,13,SNOW_BLOCK)
B(0,-3,-11,SNOW_BLOCK)
B(0,-3,-10,SNOW_BLOCK)
B(0,-3,-9,SNOW_BLOCK)
B(0,-3,-8,SNOW_BLOCK)
B(0,-3,-7,SNOW_BLOCK)
B(0,-3,-6,SNOW_BLOCK)
B(0,-3,-5,DIRT)
B(0,-3,-4,DIRT)
B(0,-3,-3,DIRT)
B(0,-3,-2,DIRT)
B(0,-3,-1,DIRT)
B(0,-3,0,DIRT)
B(0,-3,1,STONE)
B(0,-3,2,DIRT)
B(0,-3,3,DIRT)
B(0,-3,4,DIRT)
B(0,-3,5,SNOW_BLOCK)
B(0,-3,6,SNOW_BLOCK)
B(0,-3,7,SNOW_BLOCK)
B(0,-3,8,SNOW_BLOCK)
B(0,-3,9,SNOW_BLOCK)
B(0,-3,10,SNOW_BLOCK)
B(0,-3,11,SNOW_BLOCK)
B(0,-3,12,SNOW_BLOCK)
B(0,-3,13,SNOW_BLOCK)
B(0,-2,-11,SNOW_BLOCK)
B(0,-2,-10,SNOW_BLOCK)
B(0,-2,-9,SNOW_BLOCK)
B(0,-2,-8,SNOW_BLOCK)
B(0,-2,-7,SNOW_BLOCK)
B(0,-2,-6,SNOW_BLOCK)
B(0,-2,-5,DIRT)
B(0,-2,-4,DIRT)
B(0,-2,-3,DIRT)
B(0,-2,-2,DIRT)
B(0,-2,-1,DIRT)
B(0,-2,0,DIRT)
B(0,-2,1,STONE)
B(0,-2,2,DIRT)
B(0,-2,3,DIRT)
B(0,-2,4,DIRT)
B(0,-2,5,SNOW_BLOCK)
B(0,-2,6,SNOW_BLOCK)
B(0,-2,7,SNOW_BLOCK)
B(0,-2,8,SNOW_BLOCK)
B(0,-2,9,SNOW_BLOCK)
B(0,-2,10,SNOW_BLOCK)
B(0,-2,11,SNOW_BLOCK)
B(0,-2,12,SNOW_BLOCK)
B(0,-2,13,SNOW_BLOCK)
B(0,-1,-11,SNOW_BLOCK)
B(0,-1,-10,SNOW_BLOCK)
B(0,-1,-9,SNOW_BLOCK)
B(0,-1,-8,SNOW_BLOCK)
B(0,-1,-7,SNOW_BLOCK)
B(0,-1,-6,SNOW_BLOCK)
B(0,-1,-5,DIRT)
B(0,-1,-4,DIRT)
B(0,-1,-3,STONE)
B(0,-1,-2,GRAVEL)
B(0,-1,-1,DIRT)
B(0,-1,0,NETHERRACK)
B(0,-1,1,STONE)
B(0,-1,2,GRAVEL)
B(0,-1,3,STONE)
B(0,-1,4,STONE)
B(0,-1,5,SNOW_BLOCK)
B(0,-1,6,GRAVEL)
B(0,-1,7,GRAVEL)
B(0,-1,8,SNOW_BLOCK)
B(0,-1,9,SNOW_BLOCK)
B(0,-1,10,SNOW_BLOCK)
B(0,-1,11,SNOW_BLOCK)
B(0,-1,12,SNOW_BLOCK)
B(0,-1,13,SNOW_BLOCK)
B(0,0,-11,AIR)
B(0,0,-10,AIR)
B(0,0,-9,AIR)
B(0,0,-8,AIR)
B(0,0,-7,AIR)
B(0,0,-6,AIR)
B(0,0,-5,AIR)
B(0,0,-4,AIR)
B(0,0,-3,AIR)
B(0,0,-2,AIR)
B(0,0,-1,STEP:3)
B(0,0,0,FIRE)
B(0,0,1,STEP:3)
B(0,0,2,AIR)
B(0,0,3,AIR)
B(0,0,4,AIR)
B(0,0,5,AIR)
B(0,0,6,AIR)
B(0,0,7,AIR)
B(0,0,8,AIR)
B(0,0,9,AIR)
B(0,0,10,AIR)
B(0,0,11,AIR)
B(0,0,12,AIR)
B(0,0,13,AIR)
B(0,1,-11,AIR)
B(0,1,-10,AIR)
B(0,1,-9,AIR)
B(0,1,-8,AIR)
B(0,1,-7,AIR)
B(0,1,-6,AIR)
B(0,1,-5,AIR)
B(0,1,-4,AIR)
B(0,1,-3,AIR)
B(0,1,-2,AIR)
B(0,1,-1,AIR)
B(0,1,0,AIR)
B(0,1,1,AIR)
B(0,1,2,AIR)
B(0,1,3,AIR)
B(0,1,4,AIR)
B(0,1,5,AIR)
B(0,1,6,AIR)
B(0,1,7,AIR)
B(0,1,8,AIR)
B(0,1,9,AIR)
B(0,1,10,AIR)
B(0,1,11,AIR)
B(0,1,12,AIR)
B(0,1,13,AIR)
B(0,2,-11,SNOW_BLOCK)
B(0,2,-10,AIR)
B(0,2,-9,AIR)
B(0,2,-8,AIR)
B(0,2,-7,AIR)
B(0,2,-6,AIR)
B(0,2,-5,AIR)
B(0,2,-4,AIR)
B(0,2,-3,AIR)
B(0,2,-2,AIR)
B(0,2,-1,AIR)
B(0,2,0,AIR)
B(0,2,1,AIR)
B(0,2,2,AIR)
B(0,2,3,AIR)
B(0,2,4,AIR)
B(0,2,5,AIR)
B(0,2,6,AIR)
B(0,2,7,AIR)
B(0,2,8,AIR)
B(0,2,9,AIR)
B(0,2,10,AIR)
B(0,2,11,AIR)
B(0,2,12,AIR)
B(0,2,13,SNOW_BLOCK)
B(0,3,-11,SNOW)
B(0,3,-10,SNOW_BLOCK)
B(0,3,-9,AIR)
B(0,3,-8,AIR)
B(0,3,-7,AIR)
B(0,3,-6,AIR)
B(0,3,-5,AIR)
B(0,3,-4,AIR)
B(0,3,-3,AIR)
B(0,3,-2,AIR)
B(0,3,-1,AIR)
B(0,3,0,AIR)
B(0,3,1,AIR)
B(0,3,2,AIR)
B(0,3,3,AIR)
B(0,3,4,AIR)
B(0,3,5,AIR)
B(0,3,6,AIR)
B(0,3,7,AIR)
B(0,3,8,AIR)
B(0,3,9,AIR)
B(0,3,10,AIR)
B(0,3,11,AIR)
B(0,3,12,SNOW_BLOCK)
B(0,3,13,SNOW)
B(0,4,-10,SNOW_BLOCK)
B(0,4,-9,AIR)
B(0,4,-8,AIR)
B(0,4,-7,AIR)
B(0,4,-6,AIR)
B(0,4,-5,AIR)
B(0,4,-4,AIR)
B(0,4,-3,AIR)
B(0,4,-2,AIR)
B(0,4,-1,AIR)
B(0,4,0,AIR)
B(0,4,1,AIR)
B(0,4,2,AIR)
B(0,4,3,AIR)
B(0,4,4,AIR)
B(0,4,5,AIR)
B(0,4,6,AIR)
B(0,4,7,AIR)
B(0,4,8,AIR)
B(0,4,9,AIR)
B(0,4,10,AIR)
B(0,4,11,AIR)
B(0,4,12,SNOW_BLOCK)
B(0,5,-10,SNOW)
B(0,5,-9,SNOW_BLOCK)
B(0,5,-8,AIR)
B(0,5,-7,AIR)
B(0,5,-6,AIR)
B(0,5,-5,AIR)
B(0,5,-4,AIR)
B(0,5,-3,AIR)
B(0,5,-2,AIR)
B(0,5,-1,AIR)
B(0,5,0,AIR)
B(0,5,1,AIR)
B(0,5,2,AIR)
B(0,5,3,AIR)
B(0,5,4,AIR)
B(0,5,5,AIR)
B(0,5,6,AIR)
B(0,5,7,AIR)
B(0,5,8,AIR)
B(0,5,9,AIR)
B(0,5,10,AIR)
B(0,5,11,SNOW_BLOCK)
B(0,5,12,SNOW)
B(0,6,-9,SNOW_BLOCK)
B(0,6,-8,AIR)
B(0,6,-7,AIR)
B(0,6,-6,AIR)
B(0,6,-5,AIR)
B(0,6,-4,AIR)
B(0,6,-3,PACKED_ICE)
B(0,6,-2,AIR)
B(0,6,-1,AIR)
B(0,6,0,AIR)
B(0,6,1,AIR)
B(0,6,2,PACKED_ICE)
B(0,6,3,AIR)
B(0,6,4,AIR)
B(0,6,5,AIR)
B(0,6,6,AIR)
B(0,6,7,AIR)
B(0,6,8,AIR)
B(0,6,9,AIR)
B(0,6,10,AIR)
B(0,6,11,SNOW_BLOCK)
B(0,7,-9,SNOW)
B(0,7,-8,SNOW_BLOCK)
B(0,7,-7,AIR)
B(0,7,-6,AIR)
B(0,7,-5,AIR)
B(0,7,-4,AIR)
B(0,7,-3,PACKED_ICE)
B(0,7,-2,AIR)
B(0,7,-1,AIR)
B(0,7,0,AIR)
B(0,7,1,AIR)
B(0,7,2,PACKED_ICE)
B(0,7,3,AIR)
B(0,7,4,AIR)
B(0,7,5,AIR)
B(0,7,6,AIR)
B(0,7,7,AIR)
B(0,7,8,AIR)
B(0,7,9,AIR)
B(0,7,10,SNOW_BLOCK)
B(0,7,11,SNOW:1)
B(0,8,-8,SNOW_BLOCK)
B(0,8,-7,SNOW_BLOCK)
B(0,8,-6,AIR)
B(0,8,-5,AIR)
B(0,8,-4,AIR)
B(0,8,-3,PACKED_ICE)
B(0,8,-2,AIR)
B(0,8,-1,AIR)
B(0,8,0,AIR)
B(0,8,1,AIR)
B(0,8,2,PACKED_ICE)
B(0,8,3,AIR)
B(0,8,4,AIR)
B(0,8,5,PACKED_ICE)
B(0,8,6,AIR)
B(0,8,7,AIR)
B(0,8,8,AIR)
B(0,8,9,AIR)
B(0,8,10,SNOW_BLOCK)
B(0,9,-8,SNOW)
B(0,9,-7,SNOW_BLOCK)
B(0,9,-6,AIR)
B(0,9,-5,AIR)
B(0,9,-4,AIR)
B(0,9,-3,PACKED_ICE)
B(0,9,-2,AIR)
B(0,9,-1,AIR)
B(0,9,0,AIR)
B(0,9,1,AIR)
B(0,9,2,PACKED_ICE)
B(0,9,3,AIR)
B(0,9,4,AIR)
B(0,9,5,PACKED_ICE)
B(0,9,6,AIR)
B(0,9,7,AIR)
B(0,9,8,AIR)
B(0,9,9,SNOW_BLOCK)
B(0,9,10,SNOW)
B(0,10,-7,SNOW:1)
B(0,10,-6,SNOW_BLOCK)
B(0,10,-5,SNOW_BLOCK)
B(0,10,-4,AIR)
B(0,10,-3,PACKED_ICE)
B(0,10,-2,PACKED_ICE)
B(0,10,-1,AIR)
B(0,10,0,AIR)
B(0,10,1,PACKED_ICE)
B(0,10,2,PACKED_ICE)
B(0,10,3,AIR)
B(0,10,4,AIR)
B(0,10,5,PACKED_ICE)
B(0,10,6,AIR)
B(0,10,7,SNOW_BLOCK)
B(0,10,8,SNOW_BLOCK)
B(0,10,9,SNOW)
B(0,11,-6,SNOW)
B(0,11,-5,SNOW)
B(0,11,-4,SNOW_BLOCK)
B(0,11,-3,SNOW_BLOCK)
B(0,11,-2,PACKED_ICE)
B(0,11,-1,PACKED_ICE)
B(0,11,0,AIR)
B(0,11,1,PACKED_ICE)
B(0,11,2,PACKED_ICE)
B(0,11,3,PACKED_ICE)
B(0,11,4,AIR)
B(0,11,5,SNOW_BLOCK)
B(0,11,6,SNOW_BLOCK)
B(0,11,7,SNOW)
B(0,11,8,SNOW)
B(0,12,-4,SNOW)
B(0,12,-3,SNOW)
B(0,12,-2,SNOW_BLOCK)
B(0,12,-1,SNOW_BLOCK)
B(0,12,0,SNOW_BLOCK)
B(0,12,1,SNOW_BLOCK)
B(0,12,2,SNOW_BLOCK)
B(0,12,3,SNOW_BLOCK)
B(0,12,4,SNOW_BLOCK)
B(0,12,5,SNOW)
B(0,12,6,SNOW)
B(0,13,-2,SNOW)
B(0,13,-1,SNOW)
B(0,13,0,SNOW)
B(0,13,1,SNOW:1)
B(0,13,2,SNOW)
B(0,13,3,SNOW)
B(0,13,4,SNOW)
B(1,-4,-11,SNOW_BLOCK)
B(1,-4,-10,SNOW_BLOCK)
B(1,-4,-9,SNOW_BLOCK)
B(1,-4,-8,SNOW_BLOCK)
B(1,-4,-7,SNOW_BLOCK)
B(1,-4,-6,SNOW_BLOCK)
B(1,-4,-5,DIRT)
B(1,-4,-4,DIRT)
B(1,-4,-3,DIRT)
B(1,-4,-2,DIRT)
B(1,-4,-1,DIRT)
B(1,-4,0,DIRT)
B(1,-4,1,DIRT)
B(1,-4,2,DIRT)
B(1,-4,3,DIRT)
B(1,-4,4,DIRT)
B(1,-4,5,DIRT)
B(1,-4,6,SNOW_BLOCK)
B(1,-4,7,SNOW_BLOCK)
B(1,-4,8,SNOW_BLOCK)
B(1,-4,9,SNOW_BLOCK)
B(1,-4,10,SNOW_BLOCK)
B(1,-4,11,SNOW_BLOCK)
B(1,-4,12,SNOW_BLOCK)
B(1,-4,13,SNOW_BLOCK)
B(1,-3,-11,SNOW_BLOCK)
B(1,-3,-10,SNOW_BLOCK)
B(1,-3,-9,SNOW_BLOCK)
B(1,-3,-8,SNOW_BLOCK)
B(1,-3,-7,SNOW_BLOCK)
B(1,-3,-6,SNOW_BLOCK)
B(1,-3,-5,DIRT)
B(1,-3,-4,DIRT)
B(1,-3,-3,DIRT)
B(1,-3,-2,DIRT)
B(1,-3,-1,DIRT)
B(1,-3,0,DIRT)
B(1,-3,1,DIRT)
B(1,-3,2,DIRT)
B(1,-3,3,DIRT)
B(1,-3,4,DIRT)
B(1,-3,5,DIRT)
B(1,-3,6,SNOW_BLOCK)
B(1,-3,7,SNOW_BLOCK)
B(1,-3,8,SNOW_BLOCK)
B(1,-3,9,SNOW_BLOCK)
B(1,-3,10,SNOW_BLOCK)
B(1,-3,11,SNOW_BLOCK)
B(1,-3,12,SNOW_BLOCK)
B(1,-3,13,SNOW_BLOCK)
B(1,-2,-11,SNOW_BLOCK)
B(1,-2,-10,SNOW_BLOCK)
B(1,-2,-9,SNOW_BLOCK)
B(1,-2,-8,SNOW_BLOCK)
B(1,-2,-7,SNOW_BLOCK)
B(1,-2,-6,SNOW_BLOCK)
B(1,-2,-5,DIRT)
B(1,-2,-4,DIRT)
B(1,-2,-3,DIRT)
B(1,-2,-2,DIRT)
B(1,-2,-1,DIRT)
B(1,-2,0,DIRT)
B(1,-2,1,DIRT)
B(1,-2,2,DIRT)
B(1,-2,3,DIRT)
B(1,-2,4,DIRT)
B(1,-2,5,DIRT)
B(1,-2,6,SNOW_BLOCK)
B(1,-2,7,SNOW_BLOCK)
B(1,-2,8,SNOW_BLOCK)
B(1,-2,9,SNOW_BLOCK)
B(1,-2,10,SNOW_BLOCK)
B(1,-2,11,SNOW_BLOCK)
B(1,-2,12,SNOW_BLOCK)
B(1,-2,13,SNOW_BLOCK)
B(1,-1,-11,SNOW_BLOCK)
B(1,-1,-10,SNOW_BLOCK)
B(1,-1,-9,SNOW_BLOCK)
B(1,-1,-8,SNOW_BLOCK)
B(1,-1,-7,SNOW_BLOCK)
B(1,-1,-6,DIRT)
B(1,-1,-5,STONE)
B(1,-1,-4,STONE)
B(1,-1,-3,GRAVEL)
B(1,-1,-2,DIRT)
B(1,-1,-1,STONE)
B(1,-1,0,STONE)
B(1,-1,1,STONE)
B(1,-1,2,DIRT)
B(1,-1,3,SNOW_BLOCK)
B(1,-1,4,SNOW_BLOCK)
B(1,-1,5,DIRT)
B(1,-1,6,GRAVEL)
B(1,-1,7,SNOW_BLOCK)
B(1,-1,8,SNOW_BLOCK)
B(1,-1,9,SNOW_BLOCK)
B(1,-1,10,SNOW_BLOCK)
B(1,-1,11,SNOW_BLOCK)
B(1,-1,12,SNOW_BLOCK)
B(1,-1,13,SNOW_BLOCK)
B(1,0,-11,SNOW_BLOCK)
B(1,0,-10,AIR)
B(1,0,-9,AIR)
B(1,0,-8,AIR)
B(1,0,-7,AIR)
B(1,0,-6,AIR)
B(1,0,-5,AIR)
B(1,0,-4,LOG)
B(1,0,-3,AIR)
B(1,0,-2,AIR)
B(1,0,-1,AIR)
B(1,0,0,STEP:3)
B(1,0,1,AIR)
B(1,0,2,AIR)
B(1,0,3,AIR)
B(1,0,4,AIR)
B(1,0,5,AIR)
B(1,0,6,AIR)
B(1,0,7,AIR)
B(1,0,8,AIR)
B(1,0,9,AIR)
B(1,0,10,AIR)
B(1,0,11,AIR)
B(1,0,12,AIR)
B(1,0,13,SNOW_BLOCK)
B(1,1,-11,SNOW_BLOCK)
B(1,1,-10,AIR)
B(1,1,-9,AIR)
B(1,1,-8,AIR)
B(1,1,-7,AIR)
B(1,1,-6,AIR)
B(1,1,-5,AIR)
B(1,1,-4,AIR)
B(1,1,-3,AIR)
B(1,1,-2,AIR)
B(1,1,-1,AIR)
B(1,1,0,AIR)
B(1,1,1,AIR)
B(1,1,2,AIR)
B(1,1,3,AIR)
B(1,1,4,AIR)
B(1,1,5,AIR)
B(1,1,6,AIR)
B(1,1,7,AIR)
B(1,1,8,AIR)
B(1,1,9,AIR)
B(1,1,10,AIR)
B(1,1,11,AIR)
B(1,1,12,AIR)
B(1,1,13,SNOW_BLOCK)
B(1,2,-11,SNOW)
B(1,2,-10,SNOW_BLOCK)
B(1,2,-9,AIR)
B(1,2,-8,AIR)
B(1,2,-7,AIR)
B(1,2,-6,AIR)
B(1,2,-5,AIR)
B(1,2,-4,AIR)
B(1,2,-3,AIR)
B(1,2,-2,AIR)
B(1,2,-1,AIR)
B(1,2,0,AIR)
B(1,2,1,AIR)
B(1,2,2,AIR)
B(1,2,3,AIR)
B(1,2,4,AIR)
B(1,2,5,AIR)
B(1,2,6,AIR)
B(1,2,7,AIR)
B(1,2,8,AIR)
B(1,2,9,AIR)
B(1,2,10,AIR)
B(1,2,11,AIR)
B(1,2,12,SNOW_BLOCK)
B(1,2,13,SNOW)
B(1,3,-10,SNOW_BLOCK)
B(1,3,-9,AIR)
B(1,3,-8,AIR)
B(1,3,-7,AIR)
B(1,3,-6,AIR)
B(1,3,-5,AIR)
B(1,3,-4,AIR)
B(1,3,-3,AIR)
B(1,3,-2,AIR)
B(1,3,-1,AIR)
B(1,3,0,AIR)
B(1,3,1,AIR)
B(1,3,2,AIR)
B(1,3,3,AIR)
B(1,3,4,AIR)
B(1,3,5,AIR)
B(1,3,6,AIR)
B(1,3,7,AIR)
B(1,3,8,AIR)
B(1,3,9,AIR)
B(1,3,10,AIR)
B(1,3,11,AIR)
B(1,3,12,SNOW_BLOCK)
B(1,4,-10,SNOW_BLOCK)
B(1,4,-9,AIR)
B(1,4,-8,AIR)
B(1,4,-7,AIR)
B(1,4,-6,AIR)
B(1,4,-5,AIR)
B(1,4,-4,AIR)
B(1,4,-3,AIR)
B(1,4,-2,AIR)
B(1,4,-1,AIR)
B(1,4,0,AIR)
B(1,4,1,AIR)
B(1,4,2,AIR)
B(1,4,3,AIR)
B(1,4,4,AIR)
B(1,4,5,AIR)
B(1,4,6,AIR)
B(1,4,7,AIR)
B(1,4,8,AIR)
B(1,4,9,AIR)
B(1,4,10,AIR)
B(1,4,11,SNOW_BLOCK)
B(1,4,12,SNOW_BLOCK)
B(1,5,-10,SNOW)
B(1,5,-9,SNOW_BLOCK)
B(1,5,-8,AIR)
B(1,5,-7,AIR)
B(1,5,-6,AIR)
B(1,5,-5,AIR)
B(1,5,-4,AIR)
B(1,5,-3,AIR)
B(1,5,-2,AIR)
B(1,5,-1,AIR)
B(1,5,0,AIR)
B(1,5,1,AIR)
B(1,5,2,AIR)
B(1,5,3,AIR)
B(1,5,4,AIR)
B(1,5,5,AIR)
B(1,5,6,AIR)
B(1,5,7,AIR)
B(1,5,8,AIR)
B(1,5,9,AIR)
B(1,5,10,AIR)
B(1,5,11,SNOW_BLOCK)
B(1,5,12,SNOW)
B(1,6,-9,SNOW_BLOCK)
B(1,6,-8,AIR)
B(1,6,-7,AIR)
B(1,6,-6,AIR)
B(1,6,-5,AIR)
B(1,6,-4,AIR)
B(1,6,-3,AIR)
B(1,6,-2,AIR)
B(1,6,-1,AIR)
B(1,6,0,AIR)
B(1,6,1,AIR)
B(1,6,2,AIR)
B(1,6,3,AIR)
B(1,6,4,AIR)
B(1,6,5,AIR)
B(1,6,6,AIR)
B(1,6,7,AIR)
B(1,6,8,AIR)
B(1,6,9,AIR)
B(1,6,10,PACKED_ICE)
B(1,6,11,SNOW_BLOCK)
B(1,7,-9,SNOW)
B(1,7,-8,SNOW_BLOCK)
B(1,7,-7,AIR)
B(1,7,-6,AIR)
B(1,7,-5,AIR)
B(1,7,-4,AIR)
B(1,7,-3,AIR)
B(1,7,-2,AIR)
B(1,7,-1,AIR)
B(1,7,0,AIR)
B(1,7,1,AIR)
B(1,7,2,AIR)
B(1,7,3,AIR)
B(1,7,4,AIR)
B(1,7,5,AIR)
B(1,7,6,AIR)
B(1,7,7,AIR)
B(1,7,8,AIR)
B(1,7,9,AIR)
B(1,7,10,SNOW_BLOCK)
B(1,7,11,SNOW)
B(1,8,-8,SNOW_BLOCK)
B(1,8,-7,SNOW_BLOCK)
B(1,8,-6,AIR)
B(1,8,-5,AIR)
B(1,8,-4,AIR)
B(1,8,-3,AIR)
B(1,8,-2,AIR)
B(1,8,-1,AIR)
B(1,8,0,AIR)
B(1,8,1,AIR)
B(1,8,2,AIR)
B(1,8,3,AIR)
B(1,8,4,AIR)
B(1,8,5,AIR)
B(1,8,6,AIR)
B(1,8,7,AIR)
B(1,8,8,AIR)
B(1,8,9,SNOW_BLOCK)
B(1,8,10,SNOW_BLOCK)
B(1,9,-8,SNOW:1)
B(1,9,-7,SNOW_BLOCK)
B(1,9,-6,AIR)
B(1,9,-5,AIR)
B(1,9,-4,AIR)
B(1,9,-3,AIR)
B(1,9,-2,AIR)
B(1,9,-1,AIR)
B(1,9,0,AIR)
B(1,9,1,AIR)
B(1,9,2,AIR)
B(1,9,3,AIR)
B(1,9,4,AIR)
B(1,9,5,AIR)
B(1,9,6,AIR)
B(1,9,7,AIR)
B(1,9,8,AIR)
B(1,9,9,SNOW_BLOCK)
B(1,9,10,SNOW)
B(1,10,-7,SNOW)
B(1,10,-6,SNOW_BLOCK)
B(1,10,-5,SNOW_BLOCK)
B(1,10,-4,AIR)
B(1,10,-3,AIR)
B(1,10,-2,AIR)
B(1,10,-1,AIR)
B(1,10,0,AIR)
B(1,10,1,AIR)
B(1,10,2,AIR)
B(1,10,3,AIR)
B(1,10,4,AIR)
B(1,10,5,AIR)
B(1,10,6,AIR)
B(1,10,7,SNOW_BLOCK)
B(1,10,8,SNOW_BLOCK)
B(1,10,9,SNOW)
B(1,11,-6,SNOW)
B(1,11,-5,SNOW)
B(1,11,-4,SNOW_BLOCK)
B(1,11,-3,SNOW_BLOCK)
B(1,11,-2,PACKED_ICE)
B(1,11,-1,AIR)
B(1,11,0,AIR)
B(1,11,1,AIR)
B(1,11,2,AIR)
B(1,11,3,AIR)
B(1,11,4,AIR)
B(1,11,5,SNOW_BLOCK)
B(1,11,6,SNOW_BLOCK)
B(1,11,7,SNOW)
B(1,11,8,SNOW)
B(1,12,-4,SNOW)
B(1,12,-3,SNOW:1)
B(1,12,-2,SNOW_BLOCK)
B(1,12,-1,SNOW_BLOCK)
B(1,12,0,SNOW_BLOCK)
B(1,12,1,SNOW_BLOCK)
B(1,12,2,SNOW_BLOCK)
B(1,12,3,SNOW_BLOCK)
B(1,12,4,SNOW_BLOCK)
B(1,12,5,SNOW)
B(1,12,6,SNOW)
B(1,13,-2,SNOW:1)
B(1,13,-1,SNOW)
B(1,13,0,SNOW:1)
B(1,13,1,SNOW)
B(1,13,2,SNOW)
B(1,13,3,SNOW)
B(1,13,4,SNOW)
B(2,-4,-10,SNOW_BLOCK)
B(2,-4,-9,SNOW_BLOCK)
B(2,-4,-8,SNOW_BLOCK)
B(2,-4,-7,SNOW_BLOCK)
B(2,-4,-6,SNOW_BLOCK)
B(2,-4,-5,DIRT)
B(2,-4,-4,DIRT)
B(2,-4,-3,DIRT)
B(2,-4,-2,DIRT)
B(2,-4,-1,DIRT)
B(2,-4,0,DIRT)
B(2,-4,1,DIRT)
B(2,-4,2,DIRT)
B(2,-4,3,DIRT)
B(2,-4,4,SNOW_BLOCK)
B(2,-4,5,SNOW_BLOCK)
B(2,-4,6,SNOW_BLOCK)
B(2,-4,7,SNOW_BLOCK)
B(2,-4,8,SNOW_BLOCK)
B(2,-4,9,SNOW_BLOCK)
B(2,-4,10,SNOW_BLOCK)
B(2,-4,11,SNOW_BLOCK)
B(2,-4,12,SNOW_BLOCK)
B(2,-3,-10,SNOW_BLOCK)
B(2,-3,-9,SNOW_BLOCK)
B(2,-3,-8,SNOW_BLOCK)
B(2,-3,-7,SNOW_BLOCK)
B(2,-3,-6,SNOW_BLOCK)
B(2,-3,-5,DIRT)
B(2,-3,-4,DIRT)
B(2,-3,-3,DIRT)
B(2,-3,-2,DIRT)
B(2,-3,-1,DIRT)
B(2,-3,0,DIRT)
B(2,-3,1,DIRT)
B(2,-3,2,DIRT)
B(2,-3,3,DIRT)
B(2,-3,4,SNOW_BLOCK)
B(2,-3,5,SNOW_BLOCK)
B(2,-3,6,SNOW_BLOCK)
B(2,-3,7,SNOW_BLOCK)
B(2,-3,8,SNOW_BLOCK)
B(2,-3,9,SNOW_BLOCK)
B(2,-3,10,SNOW_BLOCK)
B(2,-3,11,SNOW_BLOCK)
B(2,-3,12,SNOW_BLOCK)
B(2,-2,-10,SNOW_BLOCK)
B(2,-2,-9,SNOW_BLOCK)
B(2,-2,-8,SNOW_BLOCK)
B(2,-2,-7,SNOW_BLOCK)
B(2,-2,-6,SNOW_BLOCK)
B(2,-2,-5,DIRT)
B(2,-2,-4,DIRT)
B(2,-2,-3,DIRT)
B(2,-2,-2,DIRT)
B(2,-2,-1,DIRT)
B(2,-2,0,DIRT)
B(2,-2,1,DIRT)
B(2,-2,2,DIRT)
B(2,-2,3,DIRT)
B(2,-2,4,SNOW_BLOCK)
B(2,-2,5,SNOW_BLOCK)
B(2,-2,6,SNOW_BLOCK)
B(2,-2,7,SNOW_BLOCK)
B(2,-2,8,SNOW_BLOCK)
B(2,-2,9,SNOW_BLOCK)
B(2,-2,10,SNOW_BLOCK)
B(2,-2,11,SNOW_BLOCK)
B(2,-2,12,SNOW_BLOCK)
B(2,-1,-10,SNOW_BLOCK)
B(2,-1,-9,SNOW_BLOCK)
B(2,-1,-8,SNOW_BLOCK)
B(2,-1,-7,SNOW_BLOCK)
B(2,-1,-6,SNOW_BLOCK)
B(2,-1,-5,STONE)
B(2,-1,-4,STONE)
B(2,-1,-3,STONE)
B(2,-1,-2,STONE)
B(2,-1,-1,STONE)
B(2,-1,0,STONE)
B(2,-1,1,DIRT)
B(2,-1,2,SNOW_BLOCK)
B(2,-1,3,DIRT)
B(2,-1,4,STONE)
B(2,-1,5,SNOW_BLOCK)
B(2,-1,6,SNOW_BLOCK)
B(2,-1,7,SNOW_BLOCK)
B(2,-1,8,SNOW_BLOCK)
B(2,-1,9,SNOW_BLOCK)
B(2,-1,10,SNOW_BLOCK)
B(2,-1,11,SNOW_BLOCK)
B(2,-1,12,SNOW_BLOCK)
B(2,0,-10,SNOW_BLOCK)
B(2,0,-9,AIR)
B(2,0,-8,AIR)
B(2,0,-7,AIR)
B(2,0,-6,AIR)
B(2,0,-5,AIR)
B(2,0,-4,LOG)
B(2,0,-3,AIR)
B(2,0,-2,AIR)
B(2,0,-1,AIR)
B(2,0,0,AIR)
B(2,0,1,AIR)
B(2,0,2,AIR)
B(2,0,3,AIR)
B(2,0,4,AIR)
B(2,0,5,AIR)
B(2,0,6,AIR)
B(2,0,7,AIR)
B(2,0,8,SNOW)
B(2,0,9,AIR)
B(2,0,10,SNOW)
B(2,0,11,SNOW)
B(2,0,12,SNOW_BLOCK)
B(2,1,-10,SNOW_BLOCK)
B(2,1,-9,AIR)
B(2,1,-8,AIR)
B(2,1,-7,AIR)
B(2,1,-6,AIR)
B(2,1,-5,AIR)
B(2,1,-4,AIR)
B(2,1,-3,AIR)
B(2,1,-2,AIR)
B(2,1,-1,AIR)
B(2,1,0,AIR)
B(2,1,1,AIR)
B(2,1,2,AIR)
B(2,1,3,AIR)
B(2,1,4,AIR)
B(2,1,5,AIR)
B(2,1,6,AIR)
B(2,1,7,AIR)
B(2,1,8,AIR)
B(2,1,9,AIR)
B(2,1,10,AIR)
B(2,1,11,AIR)
B(2,1,12,SNOW_BLOCK)
B(2,2,-10,SNOW_BLOCK)
B(2,2,-9,AIR)
B(2,2,-8,AIR)
B(2,2,-7,AIR)
B(2,2,-6,AIR)
B(2,2,-5,AIR)
B(2,2,-4,AIR)
B(2,2,-3,AIR)
B(2,2,-2,AIR)
B(2,2,-1,AIR)
B(2,2,0,AIR)
B(2,2,1,AIR)
B(2,2,2,AIR)
B(2,2,3,AIR)
B(2,2,4,AIR)
B(2,2,5,AIR)
B(2,2,6,AIR)
B(2,2,7,AIR)
B(2,2,8,AIR)
B(2,2,9,AIR)
B(2,2,10,AIR)
B(2,2,11,AIR)
B(2,2,12,SNOW_BLOCK)
B(2,3,-10,SNOW_BLOCK)
B(2,3,-9,AIR)
B(2,3,-8,AIR)
B(2,3,-7,AIR)
B(2,3,-6,AIR)
B(2,3,-5,AIR)
B(2,3,-4,AIR)
B(2,3,-3,AIR)
B(2,3,-2,AIR)
B(2,3,-1,AIR)
B(2,3,0,AIR)
B(2,3,1,AIR)
B(2,3,2,AIR)
B(2,3,3,AIR)
B(2,3,4,AIR)
B(2,3,5,AIR)
B(2,3,6,AIR)
B(2,3,7,AIR)
B(2,3,8,AIR)
B(2,3,9,AIR)
B(2,3,10,AIR)
B(2,3,11,SNOW_BLOCK)
B(2,3,12,SNOW_BLOCK)
B(2,4,-10,SNOW)
B(2,4,-9,SNOW_BLOCK)
B(2,4,-8,AIR)
B(2,4,-7,AIR)
B(2,4,-6,AIR)
B(2,4,-5,AIR)
B(2,4,-4,AIR)
B(2,4,-3,AIR)
B(2,4,-2,AIR)
B(2,4,-1,AIR)
B(2,4,0,AIR)
B(2,4,1,AIR)
B(2,4,2,AIR)
B(2,4,3,AIR)
B(2,4,4,AIR)
B(2,4,5,AIR)
B(2,4,6,AIR)
B(2,4,7,AIR)
B(2,4,8,AIR)
B(2,4,9,PACKED_ICE)
B(2,4,10,AIR)
B(2,4,11,SNOW_BLOCK)
B(2,4,12,SNOW)
B(2,5,-9,SNOW_BLOCK)
B(2,5,-8,AIR)
B(2,5,-7,AIR)
B(2,5,-6,AIR)
B(2,5,-5,AIR)
B(2,5,-4,AIR)
B(2,5,-3,AIR)
B(2,5,-2,AIR)
B(2,5,-1,AIR)
B(2,5,0,AIR)
B(2,5,1,AIR)
B(2,5,2,AIR)
B(2,5,3,AIR)
B(2,5,4,AIR)
B(2,5,5,AIR)
B(2,5,6,AIR)
B(2,5,7,AIR)
B(2,5,8,AIR)
B(2,5,9,PACKED_ICE)
B(2,5,10,AIR)
B(2,5,11,SNOW_BLOCK)
B(2,6,-9,SNOW_BLOCK)
B(2,6,-8,AIR)
B(2,6,-7,AIR)
B(2,6,-6,AIR)
B(2,6,-5,AIR)
B(2,6,-4,AIR)
B(2,6,-3,AIR)
B(2,6,-2,PACKED_ICE)
B(2,6,-1,AIR)
B(2,6,0,AIR)
B(2,6,1,AIR)
B(2,6,2,AIR)
B(2,6,3,AIR)
B(2,6,4,AIR)
B(2,6,5,AIR)
B(2,6,6,AIR)
B(2,6,7,AIR)
B(2,6,8,AIR)
B(2,6,9,PACKED_ICE)
B(2,6,10,PACKED_ICE)
B(2,6,11,SNOW_BLOCK)
B(2,7,-9,SNOW:1)
B(2,7,-8,SNOW_BLOCK)
B(2,7,-7,AIR)
B(2,7,-6,AIR)
B(2,7,-5,AIR)
B(2,7,-4,AIR)
B(2,7,-3,AIR)
B(2,7,-2,PACKED_ICE)
B(2,7,-1,AIR)
B(2,7,0,AIR)
B(2,7,1,AIR)
B(2,7,2,AIR)
B(2,7,3,AIR)
B(2,7,4,AIR)
B(2,7,5,AIR)
B(2,7,6,AIR)
B(2,7,7,AIR)
B(2,7,8,AIR)
B(2,7,9,PACKED_ICE)
B(2,7,10,SNOW_BLOCK)
B(2,7,11,SNOW)
B(2,8,-8,SNOW:1)
B(2,8,-7,SNOW_BLOCK)
B(2,8,-6,AIR)
B(2,8,-5,AIR)
B(2,8,-4,AIR)
B(2,8,-3,AIR)
B(2,8,-2,PACKED_ICE)
B(2,8,-1,AIR)
B(2,8,0,AIR)
B(2,8,1,AIR)
B(2,8,2,AIR)
B(2,8,3,AIR)
B(2,8,4,AIR)
B(2,8,5,AIR)
B(2,8,6,AIR)
B(2,8,7,AIR)
B(2,8,8,SNOW_BLOCK)
B(2,8,9,SNOW_BLOCK)
B(2,8,10,SNOW)
B(2,9,-7,SNOW_BLOCK)
B(2,9,-6,SNOW_BLOCK)
B(2,9,-5,AIR)
B(2,9,-4,AIR)
B(2,9,-3,AIR)
B(2,9,-2,PACKED_ICE)
B(2,9,-1,AIR)
B(2,9,0,AIR)
B(2,9,1,AIR)
B(2,9,2,AIR)
B(2,9,3,AIR)
B(2,9,4,AIR)
B(2,9,5,AIR)
B(2,9,6,AIR)
B(2,9,7,AIR)
B(2,9,8,SNOW_BLOCK)
B(2,9,9,SNOW_BLOCK)
B(2,10,-7,SNOW)
B(2,10,-6,SNOW)
B(2,10,-5,SNOW_BLOCK)
B(2,10,-4,AIR)
B(2,10,-3,AIR)
B(2,10,-2,PACKED_ICE)
B(2,10,-1,AIR)
B(2,10,0,AIR)
B(2,10,1,AIR)
B(2,10,2,AIR)
B(2,10,3,AIR)
B(2,10,4,AIR)
B(2,10,5,AIR)
B(2,10,6,AIR)
B(2,10,7,SNOW_BLOCK)
B(2,10,8,SNOW)
B(2,10,9,SNOW)
B(2,11,-5,SNOW)
B(2,11,-4,SNOW_BLOCK)
B(2,11,-3,SNOW_BLOCK)
B(2,11,-2,SNOW_BLOCK)
B(2,11,-1,AIR)
B(2,11,0,AIR)
B(2,11,1,PACKED_ICE)
B(2,11,2,AIR)
B(2,11,3,AIR)
B(2,11,4,SNOW_BLOCK)
B(2,11,5,SNOW_BLOCK)
B(2,11,6,SNOW_BLOCK)
B(2,11,7,SNOW)
B(2,12,-4,SNOW)
B(2,12,-3,SNOW)
B(2,12,-2,SNOW)
B(2,12,-1,SNOW_BLOCK)
B(2,12,0,SNOW_BLOCK)
B(2,12,1,SNOW_BLOCK)
B(2,12,2,SNOW_BLOCK)
B(2,12,3,SNOW_BLOCK)
B(2,12,4,SNOW)
B(2,12,5,SNOW)
B(2,12,6,SNOW)
B(2,13,-1,SNOW)
B(2,13,0,SNOW)
B(2,13,1,SNOW)
B(2,13,2,SNOW)
B(2,13,3,SNOW)
B(3,-4,-10,SNOW_BLOCK)
B(3,-4,-9,SNOW_BLOCK)
B(3,-4,-8,SNOW_BLOCK)
B(3,-4,-7,SNOW_BLOCK)
B(3,-4,-6,SNOW_BLOCK)
B(3,-4,-5,SNOW_BLOCK)
B(3,-4,-4,DIRT)
B(3,-4,-3,DIRT)
B(3,-4,-2,DIRT)
B(3,-4,-1,DIRT)
B(3,-4,0,DIRT)
B(3,-4,1,DIRT)
B(3,-4,2,DIRT)
B(3,-4,3,DIRT)
B(3,-4,4,SNOW_BLOCK)
B(3,-4,5,SNOW_BLOCK)
B(3,-4,6,SNOW_BLOCK)
B(3,-4,7,SNOW_BLOCK)
B(3,-4,8,SNOW_BLOCK)
B(3,-4,9,SNOW_BLOCK)
B(3,-4,10,SNOW_BLOCK)
B(3,-4,11,SNOW_BLOCK)
B(3,-4,12,SNOW_BLOCK)
B(3,-3,-10,SNOW_BLOCK)
B(3,-3,-9,SNOW_BLOCK)
B(3,-3,-8,SNOW_BLOCK)
B(3,-3,-7,SNOW_BLOCK)
B(3,-3,-6,SNOW_BLOCK)
B(3,-3,-5,SNOW_BLOCK)
B(3,-3,-4,DIRT)
B(3,-3,-3,DIRT)
B(3,-3,-2,DIRT)
B(3,-3,-1,DIRT)
B(3,-3,0,DIRT)
B(3,-3,1,DIRT)
B(3,-3,2,DIRT)
B(3,-3,3,DIRT)
B(3,-3,4,SNOW_BLOCK)
B(3,-3,5,SNOW_BLOCK)
B(3,-3,6,SNOW_BLOCK)
B(3,-3,7,SNOW_BLOCK)
B(3,-3,8,SNOW_BLOCK)
B(3,-3,9,SNOW_BLOCK)
B(3,-3,10,SNOW_BLOCK)
B(3,-3,11,SNOW_BLOCK)
B(3,-3,12,SNOW_BLOCK)
B(3,-2,-10,SNOW_BLOCK)
B(3,-2,-9,SNOW_BLOCK)
B(3,-2,-8,SNOW_BLOCK)
B(3,-2,-7,SNOW_BLOCK)
B(3,-2,-6,SNOW_BLOCK)
B(3,-2,-5,SNOW_BLOCK)
B(3,-2,-4,DIRT)
B(3,-2,-3,DIRT)
B(3,-2,-2,DIRT)
B(3,-2,-1,DIRT)
B(3,-2,0,DIRT)
B(3,-2,1,DIRT)
B(3,-2,2,DIRT)
B(3,-2,3,DIRT)
B(3,-2,4,SNOW_BLOCK)
B(3,-2,5,SNOW_BLOCK)
B(3,-2,6,SNOW_BLOCK)
B(3,-2,7,SNOW_BLOCK)
B(3,-2,8,SNOW_BLOCK)
B(3,-2,9,SNOW_BLOCK)
B(3,-2,10,SNOW_BLOCK)
B(3,-2,11,SNOW_BLOCK)
B(3,-2,12,SNOW_BLOCK)
B(3,-1,-10,SNOW_BLOCK)
B(3,-1,-9,SNOW_BLOCK)
B(3,-1,-8,SNOW_BLOCK)
B(3,-1,-7,SNOW_BLOCK)
B(3,-1,-6,SNOW_BLOCK)
B(3,-1,-5,SNOW_BLOCK)
B(3,-1,-4,SNOW_BLOCK)
B(3,-1,-3,SNOW_BLOCK)
B(3,-1,-2,STONE)
B(3,-1,-1,GRAVEL)
B(3,-1,0,GRAVEL)
B(3,-1,1,STONE)
B(3,-1,2,GRAVEL)
B(3,-1,3,DIRT)
B(3,-1,4,STONE)
B(3,-1,5,DIRT)
B(3,-1,6,SNOW_BLOCK)
B(3,-1,7,SNOW_BLOCK)
B(3,-1,8,SNOW_BLOCK)
B(3,-1,9,SNOW_BLOCK)
B(3,-1,10,SNOW_BLOCK)
B(3,-1,11,SNOW_BLOCK)
B(3,-1,12,SNOW_BLOCK)
B(3,0,-10,SNOW_BLOCK)
B(3,0,-9,SNOW:1)
B(3,0,-8,AIR)
B(3,0,-7,AIR)
B(3,0,-6,AIR)
B(3,0,-5,AIR)
B(3,0,-4,AIR)
B(3,0,-3,AIR)
B(3,0,-2,AIR)
B(3,0,-1,AIR)
B(3,0,0,AIR)
B(3,0,1,AIR)
B(3,0,2,AIR)
B(3,0,3,AIR)
B(3,0,4,AIR)
B(3,0,5,AIR)
B(3,0,6,AIR)
B(3,0,7,AIR)
B(3,0,8,AIR)
B(3,0,9,SNOW)
B(3,0,10,SNOW:2)
B(3,0,11,SNOW:2)
B(3,0,12,SNOW_BLOCK)
B(3,1,-10,SNOW_BLOCK)
B(3,1,-9,AIR)
B(3,1,-8,AIR)
B(3,1,-7,AIR)
B(3,1,-6,AIR)
B(3,1,-5,AIR)
B(3,1,-4,AIR)
B(3,1,-3,AIR)
B(3,1,-2,AIR)
B(3,1,-1,AIR)
B(3,1,0,AIR)
B(3,1,1,AIR)
B(3,1,2,AIR)
B(3,1,3,AIR)
B(3,1,4,AIR)
B(3,1,5,AIR)
B(3,1,6,AIR)
B(3,1,7,AIR)
B(3,1,8,AIR)
B(3,1,9,AIR)
B(3,1,10,AIR)
B(3,1,11,AIR)
B(3,1,12,SNOW_BLOCK)
B(3,2,-10,SNOW_BLOCK)
B(3,2,-9,AIR)
B(3,2,-8,AIR)
B(3,2,-7,AIR)
B(3,2,-6,AIR)
B(3,2,-5,AIR)
B(3,2,-4,AIR)
B(3,2,-3,AIR)
B(3,2,-2,AIR)
B(3,2,-1,AIR)
B(3,2,0,AIR)
B(3,2,1,AIR)
B(3,2,2,AIR)
B(3,2,3,AIR)
B(3,2,4,AIR)
B(3,2,5,AIR)
B(3,2,6,AIR)
B(3,2,7,AIR)
B(3,2,8,AIR)
B(3,2,9,AIR)
B(3,2,10,AIR)
B(3,2,11,AIR)
B(3,2,12,SNOW_BLOCK)
B(3,3,-10,SNOW)
B(3,3,-9,SNOW_BLOCK)
B(3,3,-8,AIR)
B(3,3,-7,AIR)
B(3,3,-6,AIR)
B(3,3,-5,AIR)
B(3,3,-4,AIR)
B(3,3,-3,AIR)
B(3,3,-2,AIR)
B(3,3,-1,AIR)
B(3,3,0,AIR)
B(3,3,1,AIR)
B(3,3,2,AIR)
B(3,3,3,AIR)
B(3,3,4,AIR)
B(3,3,5,AIR)
B(3,3,6,AIR)
B(3,3,7,AIR)
B(3,3,8,AIR)
B(3,3,9,AIR)
B(3,3,10,AIR)
B(3,3,11,SNOW_BLOCK)
B(3,3,12,SNOW)
B(3,4,-9,SNOW_BLOCK)
B(3,4,-8,AIR)
B(3,4,-7,AIR)
B(3,4,-6,AIR)
B(3,4,-5,PACKED_ICE)
B(3,4,-4,AIR)
B(3,4,-3,AIR)
B(3,4,-2,AIR)
B(3,4,-1,AIR)
B(3,4,0,AIR)
B(3,4,1,AIR)
B(3,4,2,AIR)
B(3,4,3,AIR)
B(3,4,4,AIR)
B(3,4,5,AIR)
B(3,4,6,AIR)
B(3,4,7,AIR)
B(3,4,8,AIR)
B(3,4,9,AIR)
B(3,4,10,AIR)
B(3,4,11,SNOW_BLOCK)
B(3,5,-9,SNOW_BLOCK)
B(3,5,-8,AIR)
B(3,5,-7,AIR)
B(3,5,-6,AIR)
B(3,5,-5,PACKED_ICE)
B(3,5,-4,AIR)
B(3,5,-3,AIR)
B(3,5,-2,AIR)
B(3,5,-1,AIR)
B(3,5,0,AIR)
B(3,5,1,AIR)
B(3,5,2,AIR)
B(3,5,3,AIR)
B(3,5,4,AIR)
B(3,5,5,AIR)
B(3,5,6,AIR)
B(3,5,7,AIR)
B(3,5,8,AIR)
B(3,5,9,AIR)
B(3,5,10,AIR)
B(3,5,11,SNOW_BLOCK)
B(3,6,-9,SNOW)
B(3,6,-8,SNOW_BLOCK)
B(3,6,-7,AIR)
B(3,6,-6,AIR)
B(3,6,-5,PACKED_ICE)
B(3,6,-4,AIR)
B(3,6,-3,AIR)
B(3,6,-2,AIR)
B(3,6,-1,AIR)
B(3,6,0,AIR)
B(3,6,1,AIR)
B(3,6,2,AIR)
B(3,6,3,AIR)
B(3,6,4,AIR)
B(3,6,5,AIR)
B(3,6,6,AIR)
B(3,6,7,AIR)
B(3,6,8,AIR)
B(3,6,9,AIR)
B(3,6,10,SNOW_BLOCK)
B(3,6,11,SNOW)
B(3,7,-8,SNOW_BLOCK)
B(3,7,-7,SNOW_BLOCK)
B(3,7,-6,AIR)
B(3,7,-5,PACKED_ICE)
B(3,7,-4,AIR)
B(3,7,-3,AIR)
B(3,7,-2,AIR)
B(3,7,-1,AIR)
B(3,7,0,AIR)
B(3,7,1,AIR)
B(3,7,2,AIR)
B(3,7,3,AIR)
B(3,7,4,AIR)
B(3,7,5,AIR)
B(3,7,6,AIR)
B(3,7,7,AIR)
B(3,7,8,AIR)
B(3,7,9,SNOW_BLOCK)
B(3,7,10,SNOW_BLOCK)
B(3,8,-8,SNOW)
B(3,8,-7,SNOW_BLOCK)
B(3,8,-6,AIR)
B(3,8,-5,PACKED_ICE)
B(3,8,-4,AIR)
B(3,8,-3,AIR)
B(3,8,-2,AIR)
B(3,8,-1,AIR)
B(3,8,0,AIR)
B(3,8,1,AIR)
B(3,8,2,AIR)
B(3,8,3,AIR)
B(3,8,4,AIR)
B(3,8,5,AIR)
B(3,8,6,AIR)
B(3,8,7,AIR)
B(3,8,8,AIR)
B(3,8,9,SNOW_BLOCK)
B(3,8,10,SNOW)
B(3,9,-7,SNOW)
B(3,9,-6,SNOW_BLOCK)
B(3,9,-5,PACKED_ICE)
B(3,9,-4,AIR)
B(3,9,-3,AIR)
B(3,9,-2,AIR)
B(3,9,-1,AIR)
B(3,9,0,AIR)
B(3,9,1,PACKED_ICE)
B(3,9,2,AIR)
B(3,9,3,AIR)
B(3,9,4,AIR)
B(3,9,5,AIR)
B(3,9,6,AIR)
B(3,9,7,AIR)
B(3,9,8,SNOW_BLOCK)
B(3,9,9,SNOW)
B(3,10,-6,SNOW)
B(3,10,-5,SNOW_BLOCK)
B(3,10,-4,SNOW_BLOCK)
B(3,10,-3,AIR)
B(3,10,-2,AIR)
B(3,10,-1,AIR)
B(3,10,0,AIR)
B(3,10,1,PACKED_ICE)
B(3,10,2,AIR)
B(3,10,3,AIR)
B(3,10,4,PACKED_ICE)
B(3,10,5,AIR)
B(3,10,6,SNOW_BLOCK)
B(3,10,7,SNOW_BLOCK)
B(3,10,8,SNOW)
B(3,11,-5,SNOW)
B(3,11,-4,SNOW)
B(3,11,-3,SNOW_BLOCK)
B(3,11,-2,SNOW_BLOCK)
B(3,11,-1,SNOW_BLOCK)
B(3,11,0,PACKED_ICE)
B(3,11,1,PACKED_ICE)
B(3,11,2,AIR)
B(3,11,3,SNOW_BLOCK)
B(3,11,4,SNOW_BLOCK)
B(3,11,5,SNOW_BLOCK)
B(3,11,6,SNOW)
B(3,11,7,SNOW)
B(3,12,-3,SNOW)
B(3,12,-2,SNOW)
B(3,12,-1,SNOW)
B(3,12,0,SNOW_BLOCK)
B(3,12,1,SNOW_BLOCK)
B(3,12,2,SNOW_BLOCK)
B(3,12,3,SNOW)
B(3,12,4,SNOW)
B(3,12,5,SNOW)
B(3,13,0,SNOW)
B(3,13,1,SNOW:1)
B(3,13,2,SNOW)
B(4,-4,-9,SNOW_BLOCK)
B(4,-4,-8,SNOW_BLOCK)
B(4,-4,-7,SNOW_BLOCK)
B(4,-4,-6,SNOW_BLOCK)
B(4,-4,-5,SNOW_BLOCK)
B(4,-4,-4,DIRT)
B(4,-4,-3,DIRT)
B(4,-4,-2,DIRT)
B(4,-4,-1,SNOW_BLOCK)
B(4,-4,0,SNOW_BLOCK)
B(4,-4,1,DIRT)
B(4,-4,2,DIRT)
B(4,-4,3,DIRT)
B(4,-4,4,SNOW_BLOCK)
B(4,-4,5,SNOW_BLOCK)
B(4,-4,6,SNOW_BLOCK)
B(4,-4,7,SNOW_BLOCK)
B(4,-4,8,SNOW_BLOCK)
B(4,-4,9,SNOW_BLOCK)
B(4,-4,10,SNOW_BLOCK)
B(4,-4,11,SNOW_BLOCK)
B(4,-3,-9,SNOW_BLOCK)
B(4,-3,-8,SNOW_BLOCK)
B(4,-3,-7,SNOW_BLOCK)
B(4,-3,-6,SNOW_BLOCK)
B(4,-3,-5,SNOW_BLOCK)
B(4,-3,-4,DIRT)
B(4,-3,-3,DIRT)
B(4,-3,-2,DIRT)
B(4,-3,-1,SNOW_BLOCK)
B(4,-3,0,SNOW_BLOCK)
B(4,-3,1,DIRT)
B(4,-3,2,DIRT)
B(4,-3,3,DIRT)
B(4,-3,4,SNOW_BLOCK)
B(4,-3,5,SNOW_BLOCK)
B(4,-3,6,SNOW_BLOCK)
B(4,-3,7,SNOW_BLOCK)
B(4,-3,8,SNOW_BLOCK)
B(4,-3,9,SNOW_BLOCK)
B(4,-3,10,SNOW_BLOCK)
B(4,-3,11,SNOW_BLOCK)
B(4,-2,-9,SNOW_BLOCK)
B(4,-2,-8,SNOW_BLOCK)
B(4,-2,-7,SNOW_BLOCK)
B(4,-2,-6,SNOW_BLOCK)
B(4,-2,-5,SNOW_BLOCK)
B(4,-2,-4,DIRT)
B(4,-2,-3,DIRT)
B(4,-2,-2,DIRT)
B(4,-2,-1,SNOW_BLOCK)
B(4,-2,0,SNOW_BLOCK)
B(4,-2,1,DIRT)
B(4,-2,2,DIRT)
B(4,-2,3,DIRT)
B(4,-2,4,SNOW_BLOCK)
B(4,-2,5,SNOW_BLOCK)
B(4,-2,6,SNOW_BLOCK)
B(4,-2,7,SNOW_BLOCK)
B(4,-2,8,SNOW_BLOCK)
B(4,-2,9,SNOW_BLOCK)
B(4,-2,10,SNOW_BLOCK)
B(4,-2,11,SNOW_BLOCK)
B(4,-1,-9,SNOW_BLOCK)
B(4,-1,-8,SNOW_BLOCK)
B(4,-1,-7,SNOW_BLOCK)
B(4,-1,-6,STONE)
B(4,-1,-5,SNOW_BLOCK)
B(4,-1,-4,SNOW_BLOCK)
B(4,-1,-3,STONE)
B(4,-1,-2,GRAVEL)
B(4,-1,-1,GRAVEL)
B(4,-1,0,STONE)
B(4,-1,1,DIRT)
B(4,-1,2,DIRT)
B(4,-1,3,GRAVEL)
B(4,-1,4,STONE)
B(4,-1,5,SNOW_BLOCK)
B(4,-1,6,SNOW_BLOCK)
B(4,-1,7,SNOW_BLOCK)
B(4,-1,8,SNOW_BLOCK)
B(4,-1,9,SNOW_BLOCK)
B(4,-1,10,SNOW_BLOCK)
B(4,-1,11,SNOW_BLOCK)
B(4,0,-9,SNOW_BLOCK)
B(4,0,-8,SNOW:1)
B(4,0,-7,AIR)
B(4,0,-6,AIR)
B(4,0,-5,AIR)
B(4,0,-4,AIR)
B(4,0,-3,AIR)
B(4,0,-2,AIR)
B(4,0,-1,AIR)
B(4,0,0,AIR)
B(4,0,1,LOG)
B(4,0,2,AIR)
B(4,0,3,AIR)
B(4,0,4,AIR)
B(4,0,5,AIR)
B(4,0,6,AIR)
B(4,0,7,SNOW)
B(4,0,8,SNOW)
B(4,0,9,AIR)
B(4,0,10,SNOW:1)
B(4,0,11,SNOW_BLOCK)
B(4,1,-9,SNOW_BLOCK)
B(4,1,-8,AIR)
B(4,1,-7,AIR)
B(4,1,-6,AIR)
B(4,1,-5,AIR)
B(4,1,-4,AIR)
B(4,1,-3,AIR)
B(4,1,-2,AIR)
B(4,1,-1,AIR)
B(4,1,0,AIR)
Entity(4,1,1,VillagerGolem,1,VillagerGolem.txt)
B(4,1,2,AIR)
B(4,1,3,AIR)
B(4,1,4,AIR)
B(4,1,5,AIR)
B(4,1,6,AIR)
B(4,1,7,AIR)
B(4,1,8,AIR)
B(4,1,9,AIR)
B(4,1,10,AIR)
B(4,1,11,SNOW_BLOCK)
B(4,2,-9,SNOW_BLOCK)
B(4,2,-8,AIR)
B(4,2,-7,AIR)
B(4,2,-6,AIR)
B(4,2,-5,AIR)
B(4,2,-4,AIR)
B(4,2,-3,AIR)
B(4,2,-2,AIR)
B(4,2,-1,AIR)
B(4,2,0,AIR)
B(4,2,1,AIR)
B(4,2,2,AIR)
B(4,2,3,AIR)
B(4,2,4,AIR)
B(4,2,5,AIR)
B(4,2,6,AIR)
B(4,2,7,AIR)
B(4,2,8,AIR)
B(4,2,9,AIR)
B(4,2,10,AIR)
B(4,2,11,SNOW_BLOCK)
B(4,3,-9,SNOW_BLOCK)
B(4,3,-8,AIR)
B(4,3,-7,AIR)
B(4,3,-6,AIR)
B(4,3,-5,AIR)
B(4,3,-4,AIR)
B(4,3,-3,AIR)
B(4,3,-2,AIR)
B(4,3,-1,AIR)
B(4,3,0,AIR)
B(4,3,1,AIR)
B(4,3,2,AIR)
B(4,3,3,AIR)
B(4,3,4,AIR)
B(4,3,5,AIR)
B(4,3,6,AIR)
B(4,3,7,AIR)
B(4,3,8,AIR)
B(4,3,9,AIR)
B(4,3,10,AIR)
B(4,3,11,SNOW_BLOCK)
B(4,4,-9,SNOW_BLOCK)
B(4,4,-8,AIR)
B(4,4,-7,AIR)
B(4,4,-6,AIR)
B(4,4,-5,AIR)
B(4,4,-4,AIR)
B(4,4,-3,AIR)
B(4,4,-2,AIR)
B(4,4,-1,AIR)
B(4,4,0,AIR)
B(4,4,1,AIR)
B(4,4,2,AIR)
B(4,4,3,AIR)
B(4,4,4,AIR)
B(4,4,5,AIR)
B(4,4,6,AIR)
B(4,4,7,AIR)
B(4,4,8,AIR)
B(4,4,9,AIR)
B(4,4,10,SNOW_BLOCK)
B(4,4,11,SNOW_BLOCK)
B(4,5,-9,SNOW_BLOCK)
B(4,5,-8,AIR)
B(4,5,-7,AIR)
B(4,5,-6,AIR)
B(4,5,-5,AIR)
B(4,5,-4,AIR)
B(4,5,-3,AIR)
B(4,5,-2,AIR)
B(4,5,-1,AIR)
B(4,5,0,AIR)
B(4,5,1,AIR)
B(4,5,2,AIR)
B(4,5,3,AIR)
B(4,5,4,AIR)
B(4,5,5,AIR)
B(4,5,6,AIR)
B(4,5,7,AIR)
B(4,5,8,AIR)
B(4,5,9,AIR)
B(4,5,10,AIR)
B(4,5,11,SNOW_BLOCK)
B(4,6,-8,SNOW_BLOCK)
B(4,6,-7,AIR)
B(4,6,-6,AIR)
B(4,6,-5,AIR)
B(4,6,-4,AIR)
B(4,6,-3,AIR)
B(4,6,-2,AIR)
B(4,6,-1,AIR)
B(4,6,0,AIR)
B(4,6,1,PACKED_ICE)
B(4,6,2,AIR)
B(4,6,3,AIR)
B(4,6,4,AIR)
B(4,6,5,AIR)
B(4,6,6,AIR)
B(4,6,7,AIR)
B(4,6,8,AIR)
B(4,6,9,AIR)
B(4,6,10,SNOW_BLOCK)
B(4,7,-8,SNOW)
B(4,7,-7,SNOW_BLOCK)
B(4,7,-6,AIR)
B(4,7,-5,AIR)
B(4,7,-4,AIR)
B(4,7,-3,AIR)
B(4,7,-2,AIR)
B(4,7,-1,AIR)
B(4,7,0,AIR)
B(4,7,1,PACKED_ICE)
B(4,7,2,AIR)
B(4,7,3,AIR)
B(4,7,4,AIR)
B(4,7,5,AIR)
B(4,7,6,AIR)
B(4,7,7,AIR)
B(4,7,8,AIR)
B(4,7,9,SNOW_BLOCK)
B(4,8,-7,SNOW_BLOCK)
B(4,8,-6,AIR)
B(4,8,-5,AIR)
B(4,8,-4,AIR)
B(4,8,-3,AIR)
B(4,8,-2,AIR)
B(4,8,-1,AIR)
B(4,8,0,AIR)
B(4,8,1,PACKED_ICE)
B(4,8,2,PACKED_ICE)
B(4,8,3,AIR)
B(4,8,4,AIR)
B(4,8,5,AIR)
B(4,8,6,AIR)
B(4,8,7,AIR)
B(4,8,8,SNOW_BLOCK)
B(4,8,9,SNOW_BLOCK)
B(4,9,-6,SNOW_BLOCK)
B(4,9,-5,SNOW_BLOCK)
B(4,9,-4,AIR)
B(4,9,-3,AIR)
B(4,9,-2,AIR)
B(4,9,-1,AIR)
B(4,9,0,AIR)
B(4,9,1,PACKED_ICE)
B(4,9,2,PACKED_ICE)
B(4,9,3,AIR)
B(4,9,4,PACKED_ICE)
B(4,9,5,AIR)
B(4,9,6,SNOW_BLOCK)
B(4,9,7,SNOW_BLOCK)
B(4,9,8,SNOW_BLOCK)
B(4,10,-4,SNOW_BLOCK)
B(4,10,-3,AIR)
B(4,10,-2,AIR)
B(4,10,-1,AIR)
B(4,10,0,AIR)
B(4,10,1,PACKED_ICE)
B(4,10,2,PACKED_ICE)
B(4,10,3,PACKED_ICE)
B(4,10,4,PACKED_ICE)
B(4,10,5,AIR)
B(4,10,6,SNOW_BLOCK)
B(4,11,-3,SNOW_BLOCK)
B(4,11,-2,SNOW_BLOCK)
B(4,11,-1,SNOW_BLOCK)
B(4,11,0,SNOW_BLOCK)
B(4,11,1,SNOW_BLOCK)
B(4,11,2,SNOW_BLOCK)
B(4,11,3,SNOW_BLOCK)
B(4,11,4,SNOW_BLOCK)
B(4,11,5,SNOW_BLOCK)
B(4,12,-2,SNOW)
B(5,-4,-9,SNOW_BLOCK)
B(5,-4,-8,SNOW_BLOCK)
B(5,-4,-7,SNOW_BLOCK)
B(5,-4,-6,SNOW_BLOCK)
B(5,-4,-5,SNOW_BLOCK)
B(5,-4,-4,SNOW_BLOCK)
B(5,-4,-3,SNOW_BLOCK)
B(5,-4,-2,SNOW_BLOCK)
B(5,-4,-1,SNOW_BLOCK)
B(5,-4,0,SNOW_BLOCK)
B(5,-4,1,DIRT)
B(5,-4,2,SNOW_BLOCK)
B(5,-4,3,DIRT)
B(5,-4,4,SNOW_BLOCK)
B(5,-4,5,SNOW_BLOCK)
B(5,-4,6,SNOW_BLOCK)
B(5,-4,7,SNOW_BLOCK)
B(5,-4,8,SNOW_BLOCK)
B(5,-4,9,SNOW_BLOCK)
B(5,-4,10,SNOW_BLOCK)
B(5,-4,11,SNOW_BLOCK)
B(5,-3,-9,SNOW_BLOCK)
B(5,-3,-8,SNOW_BLOCK)
B(5,-3,-7,SNOW_BLOCK)
B(5,-3,-6,SNOW_BLOCK)
B(5,-3,-5,SNOW_BLOCK)
B(5,-3,-4,SNOW_BLOCK)
B(5,-3,-3,SNOW_BLOCK)
B(5,-3,-2,SNOW_BLOCK)
B(5,-3,-1,SNOW_BLOCK)
B(5,-3,0,SNOW_BLOCK)
B(5,-3,1,DIRT)
B(5,-3,2,SNOW_BLOCK)
B(5,-3,3,DIRT)
B(5,-3,4,SNOW_BLOCK)
B(5,-3,5,SNOW_BLOCK)
B(5,-3,6,SNOW_BLOCK)
B(5,-3,7,SNOW_BLOCK)
B(5,-3,8,SNOW_BLOCK)
B(5,-3,9,SNOW_BLOCK)
B(5,-3,10,SNOW_BLOCK)
B(5,-3,11,SNOW_BLOCK)
B(5,-2,-9,SNOW_BLOCK)
B(5,-2,-8,SNOW_BLOCK)
B(5,-2,-7,SNOW_BLOCK)
B(5,-2,-6,SNOW_BLOCK)
B(5,-2,-5,SNOW_BLOCK)
B(5,-2,-4,SNOW_BLOCK)
B(5,-2,-3,SNOW_BLOCK)
B(5,-2,-2,SNOW_BLOCK)
B(5,-2,-1,SNOW_BLOCK)
B(5,-2,0,SNOW_BLOCK)
B(5,-2,1,DIRT)
B(5,-2,2,SNOW_BLOCK)
B(5,-2,3,DIRT)
B(5,-2,4,SNOW_BLOCK)
B(5,-2,5,SNOW_BLOCK)
B(5,-2,6,SNOW_BLOCK)
B(5,-2,7,SNOW_BLOCK)
B(5,-2,8,SNOW_BLOCK)
B(5,-2,9,SNOW_BLOCK)
B(5,-2,10,SNOW_BLOCK)
B(5,-2,11,SNOW_BLOCK)
B(5,-1,-9,SNOW_BLOCK)
B(5,-1,-8,SNOW_BLOCK)
B(5,-1,-7,SNOW_BLOCK)
B(5,-1,-6,SNOW_BLOCK)
B(5,-1,-5,STONE)
B(5,-1,-4,SNOW_BLOCK)
B(5,-1,-3,STONE)
B(5,-1,-2,SNOW_BLOCK)
B(5,-1,-1,DIRT)
B(5,-1,0,SNOW_BLOCK)
B(5,-1,1,DIRT)
B(5,-1,2,SNOW_BLOCK)
B(5,-1,3,DIRT)
B(5,-1,4,SNOW_BLOCK)
B(5,-1,5,SNOW_BLOCK)
B(5,-1,6,SNOW_BLOCK)
B(5,-1,7,SNOW_BLOCK)
B(5,-1,8,SNOW_BLOCK)
B(5,-1,9,SNOW_BLOCK)
B(5,-1,10,SNOW_BLOCK)
B(5,-1,11,SNOW_BLOCK)
B(5,0,-9,SNOW_BLOCK)
B(5,0,-8,SNOW)
B(5,0,-7,AIR)
B(5,0,-6,AIR)
B(5,0,-5,AIR)
B(5,0,-4,AIR)
B(5,0,-3,AIR)
B(5,0,-2,AIR)
B(5,0,-1,AIR)
B(5,0,0,AIR)
B(5,0,1,AIR)
B(5,0,2,AIR)
B(5,0,3,AIR)
B(5,0,4,AIR)
B(5,0,5,AIR)
B(5,0,6,AIR)
B(5,0,7,AIR)
B(5,0,8,SNOW)
B(5,0,9,AIR)
B(5,0,10,SNOW:2)
B(5,0,11,SNOW_BLOCK)
B(5,1,-9,SNOW_BLOCK)
B(5,1,-8,AIR)
B(5,1,-7,AIR)
B(5,1,-6,AIR)
B(5,1,-5,AIR)
B(5,1,-4,AIR)
B(5,1,-3,AIR)
B(5,1,-2,AIR)
B(5,1,-1,AIR)
B(5,1,0,AIR)
B(5,1,1,AIR)
B(5,1,2,AIR)
B(5,1,3,AIR)
B(5,1,4,AIR)
B(5,1,5,AIR)
B(5,1,6,AIR)
B(5,1,7,AIR)
B(5,1,8,AIR)
B(5,1,9,AIR)
B(5,1,10,AIR)
B(5,1,11,SNOW_BLOCK)
B(5,2,-9,SNOW_BLOCK)
B(5,2,-8,AIR)
B(5,2,-7,AIR)
B(5,2,-6,AIR)
B(5,2,-5,AIR)
B(5,2,-4,AIR)
B(5,2,-3,AIR)
B(5,2,-2,AIR)
B(5,2,-1,AIR)
B(5,2,0,AIR)
B(5,2,1,AIR)
B(5,2,2,AIR)
B(5,2,3,AIR)
B(5,2,4,AIR)
B(5,2,5,AIR)
B(5,2,6,AIR)
B(5,2,7,AIR)
B(5,2,8,AIR)
B(5,2,9,AIR)
B(5,2,10,AIR)
B(5,2,11,SNOW_BLOCK)
B(5,3,-9,SNOW_BLOCK)
B(5,3,-8,AIR)
B(5,3,-7,AIR)
B(5,3,-6,AIR)
B(5,3,-5,AIR)
B(5,3,-4,AIR)
B(5,3,-3,AIR)
B(5,3,-2,AIR)
B(5,3,-1,AIR)
B(5,3,0,AIR)
B(5,3,1,AIR)
B(5,3,2,AIR)
B(5,3,3,AIR)
B(5,3,4,AIR)
B(5,3,5,AIR)
B(5,3,6,AIR)
B(5,3,7,AIR)
B(5,3,8,AIR)
B(5,3,9,AIR)
B(5,3,10,SNOW_BLOCK)
B(5,3,11,SNOW_BLOCK)
B(5,4,-8,SNOW_BLOCK)
B(5,4,-7,AIR)
B(5,4,-6,AIR)
B(5,4,-5,AIR)
B(5,4,-4,AIR)
B(5,4,-3,AIR)
B(5,4,-2,AIR)
B(5,4,-1,AIR)
B(5,4,0,AIR)
B(5,4,1,AIR)
B(5,4,2,AIR)
B(5,4,3,AIR)
B(5,4,4,AIR)
B(5,4,5,AIR)
B(5,4,6,AIR)
B(5,4,7,AIR)
B(5,4,8,AIR)
B(5,4,9,AIR)
B(5,4,10,SNOW_BLOCK)
B(5,5,-8,SNOW_BLOCK)
B(5,5,-7,AIR)
B(5,5,-6,AIR)
B(5,5,-5,AIR)
B(5,5,-4,AIR)
B(5,5,-3,AIR)
B(5,5,-2,AIR)
B(5,5,-1,AIR)
B(5,5,0,AIR)
B(5,5,1,AIR)
B(5,5,2,AIR)
B(5,5,3,AIR)
B(5,5,4,PACKED_ICE)
B(5,5,5,AIR)
B(5,5,6,AIR)
B(5,5,7,AIR)
B(5,5,8,AIR)
B(5,5,9,AIR)
B(5,5,10,SNOW_BLOCK)
B(5,6,-8,SNOW_BLOCK)
B(5,6,-7,AIR)
B(5,6,-6,AIR)
B(5,6,-5,AIR)
B(5,6,-4,AIR)
B(5,6,-3,AIR)
B(5,6,-2,AIR)
B(5,6,-1,AIR)
B(5,6,0,AIR)
B(5,6,1,AIR)
B(5,6,2,AIR)
B(5,6,3,AIR)
B(5,6,4,PACKED_ICE)
B(5,6,5,AIR)
B(5,6,6,AIR)
B(5,6,7,AIR)
B(5,6,8,AIR)
B(5,6,9,AIR)
B(5,6,10,SNOW_BLOCK)
B(5,7,-7,SNOW_BLOCK)
B(5,7,-6,SNOW_BLOCK)
B(5,7,-5,AIR)
B(5,7,-4,AIR)
B(5,7,-3,AIR)
B(5,7,-2,AIR)
B(5,7,-1,AIR)
B(5,7,0,AIR)
B(5,7,1,AIR)
B(5,7,2,AIR)
B(5,7,3,AIR)
B(5,7,4,PACKED_ICE)
B(5,7,5,AIR)
B(5,7,6,AIR)
B(5,7,7,AIR)
B(5,7,8,SNOW_BLOCK)
B(5,7,9,SNOW_BLOCK)
B(5,8,-6,SNOW_BLOCK)
B(5,8,-5,AIR)
B(5,8,-4,AIR)
B(5,8,-3,AIR)
B(5,8,-2,AIR)
B(5,8,-1,AIR)
B(5,8,0,AIR)
B(5,8,1,AIR)
B(5,8,2,AIR)
B(5,8,3,AIR)
B(5,8,4,PACKED_ICE)
B(5,8,5,AIR)
B(5,8,6,AIR)
B(5,8,7,AIR)
B(5,8,8,SNOW_BLOCK)
B(5,9,-5,SNOW_BLOCK)
B(5,9,-4,AIR)
B(5,9,-3,AIR)
B(5,9,-2,AIR)
B(5,9,-1,AIR)
B(5,9,0,AIR)
B(5,9,1,AIR)
B(5,9,2,AIR)
B(5,9,3,AIR)
B(5,9,4,PACKED_ICE)
B(5,9,5,AIR)
B(5,9,6,AIR)
B(5,9,7,SNOW_BLOCK)
B(5,10,-4,SNOW_BLOCK)
B(5,10,-3,SNOW_BLOCK)
B(5,10,-2,SNOW_BLOCK)
B(5,10,-1,PACKED_ICE)
B(5,10,0,AIR)
B(5,10,1,AIR)
B(5,10,2,AIR)
B(5,10,3,AIR)
B(5,10,4,SNOW_BLOCK)
B(5,10,5,SNOW_BLOCK)
B(5,10,6,SNOW_BLOCK)
B(5,11,-2,SNOW)
B(5,11,-1,SNOW_BLOCK)
B(5,11,0,SNOW_BLOCK)
B(5,11,1,SNOW_BLOCK)
B(5,11,2,SNOW_BLOCK)
B(5,11,3,SNOW_BLOCK)
B(5,12,0,SNOW)
B(5,12,1,SNOW)
B(6,-4,-8,SNOW_BLOCK)
B(6,-4,-7,SNOW_BLOCK)
B(6,-4,-6,SNOW_BLOCK)
B(6,-4,-5,SNOW_BLOCK)
B(6,-4,-4,SNOW_BLOCK)
B(6,-4,-3,SNOW_BLOCK)
B(6,-4,-2,SNOW_BLOCK)
B(6,-4,-1,SNOW_BLOCK)
B(6,-4,0,SNOW_BLOCK)
B(6,-4,1,SNOW_BLOCK)
B(6,-4,2,SNOW_BLOCK)
B(6,-4,3,SNOW_BLOCK)
B(6,-4,4,SNOW_BLOCK)
B(6,-4,5,SNOW_BLOCK)
B(6,-4,6,SNOW_BLOCK)
B(6,-4,7,SNOW_BLOCK)
B(6,-4,8,SNOW_BLOCK)
B(6,-4,9,SNOW_BLOCK)
B(6,-4,10,SNOW_BLOCK)
B(6,-3,-8,SNOW_BLOCK)
B(6,-3,-7,SNOW_BLOCK)
B(6,-3,-6,SNOW_BLOCK)
B(6,-3,-5,SNOW_BLOCK)
B(6,-3,-4,SNOW_BLOCK)
B(6,-3,-3,SNOW_BLOCK)
B(6,-3,-2,SNOW_BLOCK)
B(6,-3,-1,SNOW_BLOCK)
B(6,-3,0,SNOW_BLOCK)
B(6,-3,1,SNOW_BLOCK)
B(6,-3,2,SNOW_BLOCK)
B(6,-3,3,SNOW_BLOCK)
B(6,-3,4,SNOW_BLOCK)
B(6,-3,5,SNOW_BLOCK)
B(6,-3,6,SNOW_BLOCK)
B(6,-3,7,SNOW_BLOCK)
B(6,-3,8,SNOW_BLOCK)
B(6,-3,9,SNOW_BLOCK)
B(6,-3,10,SNOW_BLOCK)
B(6,-2,-8,SNOW_BLOCK)
B(6,-2,-7,SNOW_BLOCK)
B(6,-2,-6,SNOW_BLOCK)
B(6,-2,-5,SNOW_BLOCK)
B(6,-2,-4,SNOW_BLOCK)
B(6,-2,-3,SNOW_BLOCK)
B(6,-2,-2,SNOW_BLOCK)
B(6,-2,-1,SNOW_BLOCK)
B(6,-2,0,SNOW_BLOCK)
B(6,-2,1,SNOW_BLOCK)
B(6,-2,2,SNOW_BLOCK)
B(6,-2,3,SNOW_BLOCK)
B(6,-2,4,SNOW_BLOCK)
B(6,-2,5,SNOW_BLOCK)
B(6,-2,6,SNOW_BLOCK)
B(6,-2,7,SNOW_BLOCK)
B(6,-2,8,SNOW_BLOCK)
B(6,-2,9,SNOW_BLOCK)
B(6,-2,10,SNOW_BLOCK)
B(6,-1,-8,SNOW_BLOCK)
B(6,-1,-7,SNOW_BLOCK)
B(6,-1,-6,SNOW_BLOCK)
B(6,-1,-5,SNOW_BLOCK)
B(6,-1,-4,SNOW_BLOCK)
B(6,-1,-3,SNOW_BLOCK)
B(6,-1,-2,SNOW_BLOCK)
B(6,-1,-1,SNOW_BLOCK)
B(6,-1,0,SNOW_BLOCK)
B(6,-1,1,SNOW_BLOCK)
B(6,-1,2,SNOW_BLOCK)
B(6,-1,3,SNOW_BLOCK)
B(6,-1,4,SNOW_BLOCK)
B(6,-1,5,SNOW_BLOCK)
B(6,-1,6,SNOW_BLOCK)
B(6,-1,7,SNOW_BLOCK)
B(6,-1,8,SNOW_BLOCK)
B(6,-1,9,SNOW_BLOCK)
B(6,-1,10,SNOW_BLOCK)
B(6,0,-8,SNOW_BLOCK)
B(6,0,-7,SNOW:1)
B(6,0,-6,AIR)
B(6,0,-5,AIR)
B(6,0,-4,AIR)
B(6,0,-3,AIR)
B(6,0,-2,AIR)
B(6,0,-1,AIR)
B(6,0,0,AIR)
B(6,0,1,AIR)
B(6,0,2,AIR)
B(6,0,3,AIR)
B(6,0,4,AIR)
B(6,0,5,AIR)
B(6,0,6,AIR)
B(6,0,7,AIR)
B(6,0,8,SNOW)
B(6,0,9,SNOW:1)
B(6,0,10,SNOW_BLOCK)
B(6,1,-8,SNOW_BLOCK)
B(6,1,-7,AIR)
B(6,1,-6,AIR)
B(6,1,-5,AIR)
B(6,1,-4,AIR)
B(6,1,-3,AIR)
B(6,1,-2,AIR)
B(6,1,-1,AIR)
B(6,1,0,AIR)
B(6,1,1,AIR)
B(6,1,2,AIR)
B(6,1,3,AIR)
B(6,1,4,AIR)
B(6,1,5,AIR)
B(6,1,6,AIR)
B(6,1,7,AIR)
B(6,1,8,AIR)
B(6,1,9,AIR)
B(6,1,10,SNOW_BLOCK)
B(6,2,-8,SNOW_BLOCK)
B(6,2,-7,AIR)
B(6,2,-6,AIR)
B(6,2,-5,AIR)
B(6,2,-4,AIR)
B(6,2,-3,AIR)
B(6,2,-2,AIR)
B(6,2,-1,AIR)
B(6,2,0,AIR)
B(6,2,1,AIR)
B(6,2,2,AIR)
B(6,2,3,AIR)
B(6,2,4,AIR)
B(6,2,5,AIR)
B(6,2,6,AIR)
B(6,2,7,AIR)
B(6,2,8,AIR)
B(6,2,9,AIR)
B(6,2,10,SNOW_BLOCK)
B(6,3,-8,SNOW_BLOCK)
B(6,3,-7,AIR)
B(6,3,-6,AIR)
B(6,3,-5,AIR)
B(6,3,-4,AIR)
B(6,3,-3,AIR)
B(6,3,-2,AIR)
B(6,3,-1,AIR)
B(6,3,0,AIR)
B(6,3,1,AIR)
B(6,3,2,AIR)
B(6,3,3,AIR)
B(6,3,4,AIR)
B(6,3,5,AIR)
B(6,3,6,AIR)
B(6,3,7,AIR)
B(6,3,8,AIR)
B(6,3,9,AIR)
B(6,3,10,SNOW_BLOCK)
B(6,4,-8,SNOW_BLOCK)
B(6,4,-7,AIR)
B(6,4,-6,AIR)
B(6,4,-5,AIR)
B(6,4,-4,AIR)
B(6,4,-3,AIR)
B(6,4,-2,AIR)
B(6,4,-1,PACKED_ICE)
B(6,4,0,AIR)
B(6,4,1,AIR)
B(6,4,2,AIR)
B(6,4,3,AIR)
B(6,4,4,AIR)
B(6,4,5,AIR)
B(6,4,6,AIR)
B(6,4,7,AIR)
B(6,4,8,AIR)
B(6,4,9,SNOW_BLOCK)
B(6,4,10,SNOW_BLOCK)
B(6,5,-8,SNOW)
B(6,5,-7,SNOW_BLOCK)
B(6,5,-6,AIR)
B(6,5,-5,AIR)
B(6,5,-4,AIR)
B(6,5,-3,AIR)
B(6,5,-2,AIR)
B(6,5,-1,PACKED_ICE)
B(6,5,0,AIR)
B(6,5,1,AIR)
B(6,5,2,AIR)
B(6,5,3,AIR)
B(6,5,4,AIR)
B(6,5,5,AIR)
B(6,5,6,AIR)
B(6,5,7,AIR)
B(6,5,8,AIR)
B(6,5,9,SNOW_BLOCK)
B(6,5,10,SNOW)
B(6,6,-7,SNOW_BLOCK)
B(6,6,-6,AIR)
B(6,6,-5,AIR)
B(6,6,-4,AIR)
B(6,6,-3,AIR)
B(6,6,-2,AIR)
B(6,6,-1,PACKED_ICE)
B(6,6,0,AIR)
B(6,6,1,AIR)
B(6,6,2,AIR)
B(6,6,3,AIR)
B(6,6,4,AIR)
B(6,6,5,AIR)
B(6,6,6,AIR)
B(6,6,7,AIR)
B(6,6,8,SNOW_BLOCK)
B(6,6,9,SNOW_BLOCK)
B(6,7,-7,SNOW:1)
B(6,7,-6,SNOW_BLOCK)
B(6,7,-5,SNOW_BLOCK)
B(6,7,-4,AIR)
B(6,7,-3,AIR)
B(6,7,-2,AIR)
B(6,7,-1,PACKED_ICE)
B(6,7,0,AIR)
B(6,7,1,AIR)
B(6,7,2,AIR)
B(6,7,3,AIR)
B(6,7,4,AIR)
B(6,7,5,AIR)
B(6,7,6,AIR)
B(6,7,7,SNOW_BLOCK)
B(6,7,8,SNOW_BLOCK)
B(6,7,9,SNOW)
B(6,8,-6,SNOW)
B(6,8,-5,SNOW_BLOCK)
B(6,8,-4,AIR)
B(6,8,-3,AIR)
B(6,8,-2,AIR)
B(6,8,-1,PACKED_ICE)
B(6,8,0,AIR)
B(6,8,1,AIR)
B(6,8,2,AIR)
B(6,8,3,AIR)
B(6,8,4,AIR)
B(6,8,5,AIR)
B(6,8,6,AIR)
B(6,8,7,SNOW_BLOCK)
B(6,8,8,SNOW)
B(6,9,-5,SNOW)
B(6,9,-4,SNOW_BLOCK)
B(6,9,-3,SNOW_BLOCK)
B(6,9,-2,PACKED_ICE)
B(6,9,-1,PACKED_ICE)
B(6,9,0,AIR)
B(6,9,1,AIR)
B(6,9,2,AIR)
B(6,9,3,AIR)
B(6,9,4,AIR)
B(6,9,5,SNOW_BLOCK)
B(6,9,6,SNOW_BLOCK)
B(6,9,7,SNOW)
B(6,10,-4,SNOW)
B(6,10,-3,SNOW)
B(6,10,-2,SNOW_BLOCK)
B(6,10,-1,SNOW_BLOCK)
B(6,10,0,SNOW_BLOCK)
B(6,10,1,SNOW_BLOCK)
B(6,10,2,SNOW_BLOCK)
B(6,10,3,SNOW_BLOCK)
B(6,10,4,SNOW_BLOCK)
B(6,10,5,SNOW)
B(6,10,6,SNOW)
B(6,11,-2,SNOW)
B(6,11,-1,SNOW)
B(6,11,0,SNOW)
B(6,11,1,SNOW)
B(6,11,2,SNOW)
B(6,11,3,SNOW)
B(6,11,4,SNOW)
B(7,-4,-8,SNOW_BLOCK)
B(7,-4,-7,SNOW_BLOCK)
B(7,-4,-6,SNOW_BLOCK)
B(7,-4,-5,SNOW_BLOCK)
B(7,-4,-4,SNOW_BLOCK)
B(7,-4,-3,SNOW_BLOCK)
B(7,-4,-2,SNOW_BLOCK)
B(7,-4,-1,SNOW_BLOCK)
B(7,-4,0,SNOW_BLOCK)
B(7,-4,1,SNOW_BLOCK)
B(7,-4,2,SNOW_BLOCK)
B(7,-4,3,SNOW_BLOCK)
B(7,-4,4,SNOW_BLOCK)
B(7,-4,5,SNOW_BLOCK)
B(7,-4,6,SNOW_BLOCK)
B(7,-4,7,SNOW_BLOCK)
B(7,-4,8,SNOW_BLOCK)
B(7,-4,9,SNOW_BLOCK)
B(7,-4,10,SNOW_BLOCK)
B(7,-3,-8,SNOW_BLOCK)
B(7,-3,-7,SNOW_BLOCK)
B(7,-3,-6,SNOW_BLOCK)
B(7,-3,-5,SNOW_BLOCK)
B(7,-3,-4,SNOW_BLOCK)
B(7,-3,-3,SNOW_BLOCK)
B(7,-3,-2,SNOW_BLOCK)
B(7,-3,-1,SNOW_BLOCK)
B(7,-3,0,SNOW_BLOCK)
B(7,-3,1,SNOW_BLOCK)
B(7,-3,2,SNOW_BLOCK)
B(7,-3,3,SNOW_BLOCK)
B(7,-3,4,SNOW_BLOCK)
B(7,-3,5,SNOW_BLOCK)
B(7,-3,6,SNOW_BLOCK)
B(7,-3,7,SNOW_BLOCK)
B(7,-3,8,SNOW_BLOCK)
B(7,-3,9,SNOW_BLOCK)
B(7,-3,10,SNOW_BLOCK)
B(7,-2,-8,SNOW_BLOCK)
B(7,-2,-7,SNOW_BLOCK)
B(7,-2,-6,SNOW_BLOCK)
B(7,-2,-5,SNOW_BLOCK)
B(7,-2,-4,SNOW_BLOCK)
B(7,-2,-3,SNOW_BLOCK)
B(7,-2,-2,SNOW_BLOCK)
B(7,-2,-1,SNOW_BLOCK)
B(7,-2,0,SNOW_BLOCK)
B(7,-2,1,SNOW_BLOCK)
B(7,-2,2,SNOW_BLOCK)
B(7,-2,3,SNOW_BLOCK)
B(7,-2,4,SNOW_BLOCK)
B(7,-2,5,SNOW_BLOCK)
B(7,-2,6,SNOW_BLOCK)
B(7,-2,7,SNOW_BLOCK)
B(7,-2,8,SNOW_BLOCK)
B(7,-2,9,SNOW_BLOCK)
B(7,-2,10,SNOW_BLOCK)
B(7,-1,-8,SNOW_BLOCK)
B(7,-1,-7,SNOW_BLOCK)
B(7,-1,-6,SNOW_BLOCK)
B(7,-1,-5,SNOW_BLOCK)
B(7,-1,-4,SNOW_BLOCK)
B(7,-1,-3,SNOW_BLOCK)
B(7,-1,-2,SNOW_BLOCK)
B(7,-1,-1,SNOW_BLOCK)
B(7,-1,0,SNOW_BLOCK)
B(7,-1,1,SNOW_BLOCK)
B(7,-1,2,SNOW_BLOCK)
B(7,-1,3,SNOW_BLOCK)
B(7,-1,4,SNOW_BLOCK)
B(7,-1,5,SNOW_BLOCK)
B(7,-1,6,SNOW_BLOCK)
B(7,-1,7,SNOW_BLOCK)
B(7,-1,8,SNOW_BLOCK)
B(7,-1,9,SNOW_BLOCK)
B(7,-1,10,SNOW_BLOCK)
B(7,0,-8,SNOW_BLOCK)
B(7,0,-7,SNOW:2)
B(7,0,-6,AIR)
B(7,0,-5,SNOW)
B(7,0,-4,AIR)
B(7,0,-3,AIR)
B(7,0,-2,AIR)
B(7,0,-1,AIR)
B(7,0,0,AIR)
B(7,0,1,AIR)
B(7,0,2,SNOW)
B(7,0,3,AIR)
B(7,0,4,AIR)
B(7,0,5,AIR)
B(7,0,6,AIR)
B(7,0,7,SNOW:1)
B(7,0,8,SNOW)
B(7,0,9,SNOW)
B(7,0,10,SNOW_BLOCK)
B(7,1,-8,SNOW_BLOCK)
B(7,1,-7,AIR)
B(7,1,-6,AIR)
B(7,1,-5,AIR)
B(7,1,-4,AIR)
B(7,1,-3,AIR)
B(7,1,-2,AIR)
B(7,1,-1,AIR)
B(7,1,0,AIR)
B(7,1,1,AIR)
B(7,1,2,AIR)
B(7,1,3,AIR)
B(7,1,4,AIR)
B(7,1,5,AIR)
B(7,1,6,AIR)
B(7,1,7,AIR)
B(7,1,8,AIR)
B(7,1,9,AIR)
B(7,1,10,SNOW_BLOCK)
B(7,2,-8,SNOW_BLOCK)
B(7,2,-7,AIR)
B(7,2,-6,AIR)
B(7,2,-5,AIR)
B(7,2,-4,AIR)
B(7,2,-3,AIR)
B(7,2,-2,AIR)
B(7,2,-1,AIR)
B(7,2,0,AIR)
B(7,2,1,AIR)
B(7,2,2,AIR)
B(7,2,3,AIR)
B(7,2,4,AIR)
B(7,2,5,AIR)
B(7,2,6,AIR)
B(7,2,7,AIR)
B(7,2,8,AIR)
B(7,2,9,SNOW_BLOCK)
B(7,2,10,SNOW_BLOCK)
B(7,3,-8,SNOW)
B(7,3,-7,SNOW_BLOCK)
B(7,3,-6,AIR)
B(7,3,-5,AIR)
B(7,3,-4,AIR)
B(7,3,-3,AIR)
B(7,3,-2,AIR)
B(7,3,-1,AIR)
B(7,3,0,AIR)
B(7,3,1,AIR)
B(7,3,2,AIR)
B(7,3,3,AIR)
B(7,3,4,AIR)
B(7,3,5,AIR)
B(7,3,6,AIR)
B(7,3,7,AIR)
B(7,3,8,AIR)
B(7,3,9,SNOW_BLOCK)
B(7,3,10,SNOW)
B(7,4,-7,SNOW_BLOCK)
B(7,4,-6,AIR)
B(7,4,-5,AIR)
B(7,4,-4,AIR)
B(7,4,-3,AIR)
B(7,4,-2,AIR)
B(7,4,-1,AIR)
B(7,4,0,AIR)
B(7,4,1,AIR)
B(7,4,2,AIR)
B(7,4,3,AIR)
B(7,4,4,AIR)
B(7,4,5,AIR)
B(7,4,6,AIR)
B(7,4,7,AIR)
B(7,4,8,AIR)
B(7,4,9,SNOW_BLOCK)
B(7,5,-7,SNOW_BLOCK)
B(7,5,-6,SNOW_BLOCK)
B(7,5,-5,AIR)
B(7,5,-4,AIR)
B(7,5,-3,AIR)
B(7,5,-2,AIR)
B(7,5,-1,AIR)
B(7,5,0,AIR)
B(7,5,1,AIR)
B(7,5,2,AIR)
B(7,5,3,AIR)
B(7,5,4,AIR)
B(7,5,5,AIR)
B(7,5,6,AIR)
B(7,5,7,AIR)
B(7,5,8,AIR)
B(7,5,9,SNOW_BLOCK)
B(7,6,-7,SNOW)
B(7,6,-6,SNOW_BLOCK)
B(7,6,-5,AIR)
B(7,6,-4,AIR)
B(7,6,-3,AIR)
B(7,6,-2,AIR)
B(7,6,-1,AIR)
B(7,6,0,AIR)
B(7,6,1,AIR)
B(7,6,2,AIR)
B(7,6,3,AIR)
B(7,6,4,AIR)
B(7,6,5,AIR)
B(7,6,6,AIR)
B(7,6,7,AIR)
B(7,6,8,SNOW_BLOCK)
B(7,6,9,SNOW)
B(7,7,-6,SNOW:2)
B(7,7,-5,SNOW_BLOCK)
B(7,7,-4,AIR)
B(7,7,-3,AIR)
B(7,7,-2,AIR)
B(7,7,-1,AIR)
B(7,7,0,AIR)
B(7,7,1,AIR)
B(7,7,2,AIR)
B(7,7,3,AIR)
B(7,7,4,AIR)
B(7,7,5,AIR)
B(7,7,6,SNOW_BLOCK)
B(7,7,7,SNOW_BLOCK)
B(7,7,8,SNOW)
B(7,8,-5,SNOW)
B(7,8,-4,SNOW_BLOCK)
B(7,8,-3,AIR)
B(7,8,-2,AIR)
B(7,8,-1,AIR)
B(7,8,0,AIR)
B(7,8,1,AIR)
B(7,8,2,AIR)
B(7,8,3,AIR)
B(7,8,4,AIR)
B(7,8,5,AIR)
B(7,8,6,SNOW_BLOCK)
B(7,8,7,SNOW)
B(7,9,-4,SNOW)
B(7,9,-3,SNOW_BLOCK)
B(7,9,-2,SNOW_BLOCK)
B(7,9,-1,SNOW_BLOCK)
B(7,9,0,AIR)
B(7,9,1,AIR)
B(7,9,2,AIR)
B(7,9,3,SNOW_BLOCK)
B(7,9,4,SNOW_BLOCK)
B(7,9,5,SNOW_BLOCK)
B(7,9,6,SNOW)
B(7,10,-3,SNOW)
B(7,10,-2,SNOW)
B(7,10,-1,SNOW)
B(7,10,0,SNOW_BLOCK)
B(7,10,1,SNOW_BLOCK)
B(7,10,2,SNOW_BLOCK)
B(7,10,3,SNOW)
B(7,10,4,SNOW)
B(7,10,5,SNOW)
B(7,11,0,SNOW:1)
B(7,11,1,SNOW)
B(7,11,2,SNOW)
B(8,-4,-7,SNOW_BLOCK)
B(8,-4,-6,SNOW_BLOCK)
B(8,-4,-5,SNOW_BLOCK)
B(8,-4,-4,SNOW_BLOCK)
B(8,-4,-3,SNOW_BLOCK)
B(8,-4,-2,SNOW_BLOCK)
B(8,-4,-1,SNOW_BLOCK)
B(8,-4,0,SNOW_BLOCK)
B(8,-4,1,SNOW_BLOCK)
B(8,-4,2,SNOW_BLOCK)
B(8,-4,3,SNOW_BLOCK)
B(8,-4,4,SNOW_BLOCK)
B(8,-4,5,SNOW_BLOCK)
B(8,-4,6,SNOW_BLOCK)
B(8,-4,7,SNOW_BLOCK)
B(8,-4,8,SNOW_BLOCK)
B(8,-4,9,SNOW_BLOCK)
B(8,-3,-7,SNOW_BLOCK)
B(8,-3,-6,SNOW_BLOCK)
B(8,-3,-5,SNOW_BLOCK)
B(8,-3,-4,SNOW_BLOCK)
B(8,-3,-3,SNOW_BLOCK)
B(8,-3,-2,SNOW_BLOCK)
B(8,-3,-1,SNOW_BLOCK)
B(8,-3,0,SNOW_BLOCK)
B(8,-3,1,SNOW_BLOCK)
B(8,-3,2,SNOW_BLOCK)
B(8,-3,3,SNOW_BLOCK)
B(8,-3,4,SNOW_BLOCK)
B(8,-3,5,SNOW_BLOCK)
B(8,-3,6,SNOW_BLOCK)
B(8,-3,7,SNOW_BLOCK)
B(8,-3,8,SNOW_BLOCK)
B(8,-3,9,SNOW_BLOCK)
B(8,-2,-7,SNOW_BLOCK)
B(8,-2,-6,SNOW_BLOCK)
B(8,-2,-5,SNOW_BLOCK)
B(8,-2,-4,SNOW_BLOCK)
B(8,-2,-3,SNOW_BLOCK)
B(8,-2,-2,SNOW_BLOCK)
B(8,-2,-1,SNOW_BLOCK)
B(8,-2,0,SNOW_BLOCK)
B(8,-2,1,SNOW_BLOCK)
B(8,-2,2,SNOW_BLOCK)
B(8,-2,3,SNOW_BLOCK)
B(8,-2,4,SNOW_BLOCK)
B(8,-2,5,SNOW_BLOCK)
B(8,-2,6,SNOW_BLOCK)
B(8,-2,7,SNOW_BLOCK)
B(8,-2,8,SNOW_BLOCK)
B(8,-2,9,SNOW_BLOCK)
B(8,-1,-7,SNOW_BLOCK)
B(8,-1,-6,SNOW_BLOCK)
B(8,-1,-5,SNOW_BLOCK)
B(8,-1,-4,SNOW_BLOCK)
B(8,-1,-3,SNOW_BLOCK)
B(8,-1,-2,SNOW_BLOCK)
B(8,-1,-1,SNOW_BLOCK)
B(8,-1,0,SNOW_BLOCK)
B(8,-1,1,SNOW_BLOCK)
B(8,-1,2,SNOW_BLOCK)
B(8,-1,3,SNOW_BLOCK)
B(8,-1,4,SNOW_BLOCK)
B(8,-1,5,SNOW_BLOCK)
B(8,-1,6,SNOW_BLOCK)
B(8,-1,7,SNOW_BLOCK)
B(8,-1,8,SNOW_BLOCK)
B(8,-1,9,SNOW_BLOCK)
B(8,0,-7,SNOW_BLOCK)
B(8,0,-6,SNOW:1)
B(8,0,-5,SNOW:1)
B(8,0,-4,SNOW:1)
B(8,0,-3,AIR)
B(8,0,-2,AIR)
B(8,0,-1,AIR)
B(8,0,0,AIR)
B(8,0,1,AIR)
B(8,0,2,SNOW)
B(8,0,3,SNOW:1)
B(8,0,4,AIR)
B(8,0,5,AIR)
B(8,0,6,SNOW)
B(8,0,7,SNOW)
B(8,0,8,SNOW:1)
B(8,0,9,SNOW_BLOCK)
B(8,1,-7,SNOW_BLOCK)
B(8,1,-6,AIR)
B(8,1,-5,AIR)
B(8,1,-4,AIR)
B(8,1,-3,AIR)
B(8,1,-2,AIR)
B(8,1,-1,AIR)
B(8,1,0,AIR)
B(8,1,1,AIR)
B(8,1,2,AIR)
B(8,1,3,AIR)
B(8,1,4,AIR)
B(8,1,5,AIR)
B(8,1,6,AIR)
B(8,1,7,AIR)
B(8,1,8,AIR)
B(8,1,9,SNOW_BLOCK)
B(8,2,-7,SNOW_BLOCK)
B(8,2,-6,SNOW_BLOCK)
B(8,2,-5,AIR)
B(8,2,-4,AIR)
B(8,2,-3,AIR)
B(8,2,-2,AIR)
B(8,2,-1,AIR)
B(8,2,0,AIR)
B(8,2,1,AIR)
B(8,2,2,AIR)
B(8,2,3,AIR)
B(8,2,4,AIR)
B(8,2,5,AIR)
B(8,2,6,AIR)
B(8,2,7,AIR)
B(8,2,8,SNOW_BLOCK)
B(8,2,9,SNOW_BLOCK)
B(8,3,-7,SNOW_BLOCK)
B(8,3,-6,SNOW_BLOCK)
B(8,3,-5,AIR)
B(8,3,-4,AIR)
B(8,3,-3,AIR)
B(8,3,-2,AIR)
B(8,3,-1,AIR)
B(8,3,0,AIR)
B(8,3,1,AIR)
B(8,3,2,AIR)
B(8,3,3,AIR)
B(8,3,4,AIR)
B(8,3,5,AIR)
B(8,3,6,AIR)
B(8,3,7,AIR)
B(8,3,8,SNOW_BLOCK)
