
#######################################################################
# +-----------------------------------------------------------------+ #
# |                            BO3 object                           | #
# +-----------------------------------------------------------------+ #
#######################################################################

Author: LordSmellyPants

Description: Converted version of the BO2 HauntedTwisted1

Version: 3

SettingsMode: WriteWithoutComments


#######################################################################
# +-----------------------------------------------------------------+ #
# |                          Main settings                          | #
# +-----------------------------------------------------------------+ #
#######################################################################

Tree: true

Frequency: 1

Rarity: 20.0

RotateRandomly: true

SpawnHeight: highestSolidBlock

SpawnHeightOffset: 0

SpawnHeightVariance: 0

##############################
# Height Limits for the BO3. #
##############################

MinHeight: 0

MaxHeight: 30

######################
# Extrusion settings #
######################

ExtrudeMode: None

ExtrudeThroughBlocks: AIR

MaxBranchDepth: 10

ExcludedBiomes: All


#######################################################################
# +-----------------------------------------------------------------+ #
# |                      Source block settings                      | #
# +-----------------------------------------------------------------+ #
#######################################################################

SourceBlocks: AIR

MaxPercentageOutsideSourceBlock: 20

OutsideSourceBlock: dontPlace

DoReplaceBlocks: true

IsOTGPlus: false


#######################################################################
# +-----------------------------------------------------------------+ #
# |                              Blocks                             | #
# +-----------------------------------------------------------------+ #
#######################################################################

Block(-2,8,-7,LOG_2:13)
Block(-2,9,-7,LOG_2:13)
Block(14,0,-4,LOG_2:13)
Block(10,7,-6,LOG_2:13)
Block(14,1,-4,LOG_2:13)
Block(10,6,-6,LOG_2:13)
Block(0,9,-8,LOG_2:13)
Block(-6,-3,-1,LOG_2:13)
Block(13,0,-8,LOG_2:13)
Block(10,1,-6,LOG_2:5)
Block(-6,-2,-1,LOG_2:13)
Block(10,0,-6,LOG_2:5)
Block(-6,-1,-1,LOG_2:13)
Block(13,2,-8,LOG_2:13)
Block(13,1,-8,LOG_2:13)
Block(10,5,-6,LOG_2:13)
Block(-4,-1,-3,LOG_2:13)
Block(14,-1,-3,LOG_2:13)
Block(13,3,-8,LOG_2:13)
Block(10,4,-6,LOG_2:13)
Block(14,-2,-3,LOG_2:13)
Block(10,3,-6,LOG_2:13)
Block(14,-3,-3,LOG_2:13)
Block(10,2,-6,LOG_2:13)
Block(-3,0,-2,LOG_2:13)
Block(-3,1,-2,LOG_2:13)
Block(-3,2,-2,LOG_2:13)
Block(0,10,-7,LOG_2:13)
Block(-3,3,-2,LOG_2:13)
Block(5,9,-10,LOG_2:13)
Block(0,11,-7,LOG_2:13)
Block(-3,4,-2,LOG_2:13)
Block(0,12,-7,LOG_2:13)
Block(-3,5,-2,LOG_2:13)
Block(-3,6,-2,LOG_2:13)
Block(-3,7,-2,LOG_2:13)
Block(-3,8,-2,LOG_2:13)
Block(-4,-1,-2,LOG_2:13)
Block(-1,10,-9,LOG_2:13)
Block(-4,3,1,LOG_2:13)
Block(-1,11,-9,LOG_2:13)
Block(-4,2,1,LOG_2:13)
Block(-2,10,-4,LOG_2:13)
Block(-4,1,1,LOG_2:13)
Block(-4,0,1,LOG_2:13)
Block(10,-3,-6,LOG_2:13)
Block(-2,8,-8,LOG_2:13)
Block(-2,9,-8,LOG_2:13)
Block(0,11,-6,LOG_2:13)
Block(0,10,-6,LOG_2:13)
Block(10,-2,-6,LOG_2:13)
Block(10,-1,-6,LEAVES_2:13)
Block(14,1,-5,LOG_2:13)
Block(10,8,-7,LOG_2:13)
Block(14,2,-5,LOG_2:13)
Block(10,7,-7,LOG_2:13)
Block(10,6,-7,LOG_2:13)
Block(14,0,-5,LOG_2:13)
Block(10,5,-7,LOG_2:13)
Block(0,12,-6,LOG_2:13)
Block(0,9,-9,LOG_2:13)
Block(10,0,-7,LOG_2:9)
Block(13,1,-7,LOG_2:13)
Block(13,0,-7,LOG_2:13)
Block(13,3,-7,LOG_2:13)
Block(13,2,-7,LOG_2:13)
Block(12,-1,-5,LOG_2:13)
Block(10,4,-7,LOG_2:13)
Block(13,5,-7,LOG_2:13)
Block(10,3,-7,LOG_2:13)
Block(13,4,-7,LOG_2:13)
Block(12,-3,-5,LOG_2:13)
Block(10,2,-7,LOG_2:5)
Block(12,-2,-5,LOG_2:13)
Block(10,1,-7,LOG_2:9)
Block(-3,0,-1,LOG_2:13)
Block(-3,1,-1,LOG_2:13)
Block(-3,2,-1,LOG_2:13)
Block(-3,3,-1,LOG_2:13)
Block(-3,4,-1,LOG_2:13)
Block(-3,5,-1,LOG_2:13)
Block(-3,6,-1,LOG_2:13)
Block(8,6,-4,LEAVES_2:1)
Block(-5,1,0,LOG_2:13)
Block(5,11,-7,LOG_2:13)
Block(-5,0,0,LOG_2:13)
Block(5,10,-7,LOG_2:13)
Block(-5,3,0,LOG_2:13)
Block(-5,2,0,LOG_2:13)
Block(3,10,-8,LOG_2:13)
Block(-4,-1,-4,LOG_2:9)
Block(-4,-2,-4,LOG_2:13)
Block(-4,-3,-4,LOG_2:9)
Block(3,12,-8,LOG_2:13)
Block(3,11,-8,LOG_2:13)
Block(7,7,-8,LOG_2:13)
Block(-2,9,-5,LOG_2:13)
Block(7,6,-8,LOG_2:13)
Block(-2,6,-5,LOG_2:13)
Block(-4,-3,-1,LOG_2:13)
Block(-2,7,-5,LOG_2:13)
Block(7,9,-8,LOG_2:13)
Block(-4,-2,-1,LOG_2:13)
Block(7,8,-8,LOG_2:13)
Block(-2,8,-5,LOG_2:13)
Block(-4,-1,-1,LOG_2:13)
Block(0,8,-6,LOG_2:13)
Block(13,-1,-8,LOG_2:13)
Block(0,9,-6,LOG_2:13)
Block(13,-2,-8,LOG_2:13)
Block(14,0,-2,LEAVES_2:13)
Block(13,-3,-8,LOG_2:13)
Block(-4,4,-1,LOG_2:13)
Block(-4,3,-1,LOG_2:13)
Block(-4,6,-1,LOG_2:13)
Block(-4,5,-1,LOG_2:13)
Block(7,11,-7,LOG_2:13)
Block(7,10,-7,LOG_2:13)
Block(-4,0,-1,LOG_2:13)
Block(-5,0,1,LOG_2:13)
Block(-4,2,-1,LOG_2:13)
Block(-5,2,1,LOG_2:13)
Block(-4,1,-1,LOG_2:13)
Block(-5,1,1,LOG_2:13)
Block(5,10,-9,LOG_2:13)
Block(5,11,-9,LOG_2:13)
Block(-6,5,-3,LOG_2:13)
Block(-6,4,-3,LOG_2:13)
Block(-2,8,-6,LOG_2:13)
Block(-2,9,-6,LOG_2:13)
Block(7,9,-9,LOG_2:13)
Block(7,8,-9,LOG_2:13)
Block(7,7,-9,LOG_2:13)
Block(-2,7,-6,LOG_2:13)
Block(5,12,-8,LOG_2:13)
Block(5,11,-8,LOG_2:13)
Block(0,9,-7,LOG_2:13)
Block(5,10,-8,LOG_2:13)
Block(11,9,-10,LEAVES_2:1)
Block(14,0,-3,LOG_2:13)
Block(10,2,-5,LOG_2:5)
Block(3,11,-9,LOG_2:13)
Block(3,10,-9,LOG_2:13)
Block(10,0,-5,LEAVES_2:13)
Block(-6,2,0,LOG_2:13)
Block(-6,1,0,LOG_2:13)
Block(10,5,-5,LOG_2:13)
Block(-6,0,0,LOG_2:13)
Block(10,4,-5,LOG_2:5)
Block(10,3,-5,LOG_2:5)
Block(-1,-1,-1,LOG_2:5)
Block(-2,10,-5,LOG_2:13)
Block(-1,-2,-1,LOG_2:5)
Block(-1,-3,-1,LOG_2:13)
Block(3,12,-9,LOG_2:13)
Block(0,10,-5,LOG_2:13)
Block(7,9,-10,LOG_2:13)
Block(0,11,-5,LOG_2:13)
Block(7,7,-6,LOG_2:13)
Block(-2,8,-3,LOG_2:13)
Block(14,5,-8,LEAVES_2:13)
Block(-2,7,-3,LOG_2:13)
Block(-1,9,-8,LOG_2:13)
Block(-2,6,-3,LOG_2:13)
Block(-2,5,-3,LOG_2:13)
Block(-2,4,-3,LOG_2:13)
Block(-4,6,-3,LOG_2:13)
Block(12,-1,-7,LOG_2:13)
Block(-4,5,-3,LOG_2:13)
Block(10,7,-10,LOG_2:13)
Block(10,6,-10,LOG_2:13)
Block(-4,7,-3,LOG_2:13)
Block(-4,2,-3,LOG_2:13)
Block(-4,1,-3,LOG_2:13)
Block(12,-2,-7,LOG_2:13)
Block(-4,4,-3,LOG_2:13)
Block(12,-3,-7,LOG_2:13)
Block(-4,3,-3,LOG_2:13)
Block(15,-3,-4,LOG_2:13)
Block(-1,9,-7,LOG_2:13)
Block(15,-2,-4,LOG_2:13)
Block(-1,8,-7,LOG_2:13)
Block(15,-1,-4,LOG_2:13)
Block(3,11,-7,LOG_2:13)
Block(14,-1,-6,LOG_2:13)
Block(14,-2,-6,LOG_2:13)
Block(-4,0,-3,LOG_2:13)
Block(1,11,-8,LOG_2:13)
Block(1,12,-8,LOG_2:13)
Block(-3,-1,-1,LOG_2:13)
Block(1,10,-8,LOG_2:13)
Block(5,11,-5,LEAVES_2:1)
Block(9,5,-6,LOG_2:13)
Block(9,4,-6,WEB)
Block(9,7,-6,LOG_2:13)
Block(9,6,-6,LOG_2:13)
Block(14,-3,-6,LOG_2:13)
Block(6,9,-9,LOG_2:13)
Block(6,8,-9,LOG_2:13)
Block(6,7,-9,LOG_2:13)
Block(6,6,-9,LEAVES_2:1)
Block(9,8,-6,LOG_2:13)
Block(7,8,-7,LOG_2:13)
Block(7,7,-7,LOG_2:13)
Block(7,6,-7,LOG_2:13)
Block(-2,6,-4,LOG_2:13)
Block(-2,7,-4,LOG_2:13)
Block(-2,8,-4,LOG_2:13)
Block(7,9,-7,LOG_2:13)
Block(-2,9,-4,LOG_2:13)
Block(0,9,-5,LOG_2:13)
Block(3,11,-10,LOG_2:13)
Block(0,8,-5,LOG_2:13)
Block(3,10,-10,LOG_2:13)
Block(-2,4,-4,LOG_2:13)
Block(-2,5,-4,LOG_2:13)
Block(3,12,-10,LOG_2:13)
Block(1,12,-9,LOG_2:13)
Block(1,11,-9,LOG_2:13)
Block(1,10,-9,LOG_2:13)
Block(-4,7,-2,LOG_2:13)
Block(-4,6,-2,LOG_2:13)
Block(-4,3,-2,LOG_2:13)
Block(-4,2,-2,LOG_2:13)
Block(-4,5,-2,LOG_2:13)
Block(2,11,-8,LOG_2:13)
Block(-4,4,-2,LOG_2:13)
Block(2,10,-8,LOG_2:13)
Block(-1,9,-6,LOG_2:13)
Block(2,12,-8,LOG_2:13)
Block(-1,8,-6,LOG_2:13)
Block(-1,7,-6,WEB)
Block(0,12,-9,LOG_2:13)
Block(0,11,-9,LOG_2:13)
Block(4,11,-11,LOG_2:13)
Block(0,10,-9,LOG_2:13)
Block(-4,1,-2,LOG_2:13)
Block(4,12,-11,LEAVES_2:1)
Block(-4,0,-2,LOG_2:13)
Block(13,-1,-7,LOG_2:13)
Block(13,-2,-7,LOG_2:13)
Block(13,-3,-7,LOG_2:13)
Block(13,-2,-5,LOG_2:13)
Block(9,4,-7,LOG_2:13)
Block(13,-1,-5,LOG_2:13)
Block(9,3,-7,LOG_2:13)
Block(9,6,-7,LOG_2:13)
Block(9,5,-7,LOG_2:13)
Block(12,-2,-6,LOG_2:13)
Block(14,-2,-4,LOG_2:13)
Block(-2,0,-1,LOG_2:13)
Block(4,10,-7,LOG_2:13)
Block(12,-1,-6,LOG_2:13)
Block(14,-1,-4,LOG_2:13)
Block(4,12,-7,LOG_2:13)
Block(12,-3,-6,LOG_2:13)
Block(14,-3,-4,LOG_2:13)
Block(4,11,-7,LOG_2:13)
Block(9,8,-7,LOG_2:13)
Block(4,9,-9,LOG_2:13)
Block(9,7,-7,LOG_2:13)
Block(9,9,-7,LOG_2:13)
Block(0,10,-8,LOG_2:13)
Block(0,11,-8,LOG_2:13)
Block(0,12,-8,LOG_2:13)
Block(1,12,-7,LOG_2:13)
Block(15,-1,-6,LEAVES_2:13)
Block(14,2,-6,LOG_2:13)
Block(14,3,-6,LOG_2:13)
Block(14,0,-6,LOG_2:13)
Block(-2,4,-1,LOG_2:13)
Block(14,1,-6,LOG_2:13)
Block(-2,3,-1,LOG_2:13)
Block(-2,2,-1,LOG_2:13)
Block(-2,1,-1,LOG_2:13)
Block(-3,-1,-2,LOG_2:13)
Block(1,10,-7,LOG_2:13)
Block(1,11,-7,LOG_2:13)
Block(-3,-3,-2,LOG_2:13)
Block(-2,6,-1,LOG_2:13)
Block(5,11,-6,LEAVES_2:1)
Block(-3,-2,-2,LOG_2:13)
Block(-2,5,-1,LOG_2:13)
Block(-4,6,-5,LOG_2:13)
Block(-4,5,-5,LOG_2:13)
Block(-4,8,-5,LOG_2:13)
Block(-4,7,-5,LOG_2:13)
Block(-4,9,-5,LOG_2:13)
Block(16,-1,-5,LOG_2:13)
Block(3,11,-11,LOG_2:13)
Block(13,-3,-5,LOG_2:13)
Block(9,5,-8,LOG_2:13)
Block(2,10,-7,LOG_2:13)
Block(2,11,-7,LOG_2:13)
Block(15,-3,-5,LOG_2:13)
Block(2,12,-7,LOG_2:13)
Block(15,-2,-5,LOG_2:13)
Block(15,-1,-5,LOG_2:13)
Block(9,7,-8,LOG_2:13)
Block(0,9,-10,LEAVES_2:1)
Block(9,6,-8,LOG_2:13)
Block(4,9,-8,LOG_2:13)
Block(9,9,-8,LOG_2:13)
Block(9,8,-8,LOG_2:13)
Block(4,8,-8,LOG_2:13)
Block(-2,8,-2,LOG_2:13)
Block(4,10,-10,LOG_2:13)
Block(14,1,-7,LOG_2:13)
Block(-1,9,-9,LOG_2:13)
Block(14,2,-7,LOG_2:13)
Block(-2,3,-2,LOG_2:13)
Block(14,0,-7,LOG_2:13)
Block(-2,2,-2,LOG_2:13)
Block(14,-1,-5,LOG_2:13)
Block(4,11,-10,LOG_2:13)
Block(4,12,-10,LOG_2:13)
Block(-2,7,-2,LOG_2:13)
Block(-2,6,-2,LOG_2:13)
Block(-2,5,-2,LOG_2:13)
Block(-2,4,-2,LOG_2:13)
Block(13,-3,-6,LOG_2:13)
Block(-4,5,-4,LOG_2:13)
Block(13,-2,-6,LOG_2:13)
Block(-4,4,-4,LOG_2:13)
Block(13,-1,-6,LOG_2:13)
Block(-5,-1,-2,LOG_2:13)
Block(-4,7,-4,LOG_2:13)
Block(-6,-1,0,LOG_2:13)
Block(-4,6,-4,LOG_2:13)
Block(14,-3,-5,LOG_2:13)
Block(-6,-2,0,LOG_2:13)
Block(-6,-3,0,LOG_2:13)
Block(14,-2,-5,LOG_2:13)
Block(-4,3,-4,LOG_2:13)
Block(-4,8,-4,LOG_2:13)
Block(12,1,-4,LOG_2:13)
Block(10,-1,-7,LOG_2:9)
Block(10,-3,-7,LOG_2:13)
Block(10,-2,-7,LOG_2:13)
Block(12,2,-4,LOG_2:13)
Block(12,3,-4,LEAVES_2:13)
Block(-5,1,-2,LOG_2:13)
Block(-5,2,-2,LOG_2:13)
Block(-5,0,-2,LOG_2:13)
Block(9,9,-9,LOG_2:13)
Block(9,6,-9,LOG_2:13)
Block(9,8,-9,LOG_2:13)
Block(11,3,-9,LOG_2:13)
Block(9,7,-9,LOG_2:13)
Block(-5,5,-2,LOG_2:13)
Block(-5,6,-2,LOG_2:13)
Block(-5,3,-2,LOG_2:13)
Block(-5,4,-2,LOG_2:13)
Block(13,-1,-4,LOG_2:13)
Block(-1,5,-3,LOG_2:13)
Block(-1,6,0,LEAVES_2:1)
Block(4,11,-8,LOG_2:13)
Block(4,10,-8,LOG_2:13)
Block(4,12,-8,LOG_2:13)
Block(11,-3,-6,LOG_2:13)
Block(-1,7,-3,LOG_2:13)
Block(-4,-2,0,LOG_2:13)
Block(-4,-3,0,LOG_2:13)
Block(-4,-1,0,LOG_2:13)
Block(12,0,-5,LOG_2:13)
Block(15,1,-7,LEAVES_2:13)
Block(12,5,-5,LOG_2:13)
Block(12,1,-5,LOG_2:13)
Block(12,2,-5,LOG_2:13)
Block(12,3,-5,LOG_2:13)
Block(12,4,-5,LOG_2:13)
Block(-5,1,-3,LOG_2:13)
Block(-5,-1,-1,LOG_2:13)
Block(11,3,-8,LOG_2:13)
Block(11,4,-8,LOG_2:13)
Block(-4,-3,1,LOG_2:13)
Block(6,10,-10,LOG_2:13)
Block(-4,-2,1,LOG_2:13)
Block(6,9,-11,LOG_2:13)
Block(6,10,-7,LOG_2:13)
Block(-4,-1,1,LOG_2:13)
Block(6,11,-7,LOG_2:13)
Block(-5,4,-3,LOG_2:13)
Block(-5,5,-3,LOG_2:13)
Block(2,10,-10,LOG_2:13)
Block(-5,2,-3,LOG_2:13)
Block(2,11,-10,LOG_2:13)
Block(-5,3,-3,LOG_2:13)
Block(2,12,-10,LOG_2:13)
Block(13,-3,-4,LOG_2:13)
Block(-5,6,-3,LOG_2:13)
Block(13,-2,-4,LOG_2:13)
Block(-1,6,-2,LOG_2:13)
Block(-1,5,-2,LOG_2:13)
Block(2,9,-8,LOG_2:13)
Block(-1,4,-2,LOG_2:13)
Block(-4,7,-6,LOG_2:13)
Block(-4,6,-6,LOG_2:13)
Block(-4,9,-6,LEAVES_2:1)
Block(-4,8,-6,LOG_2:13)
Block(11,4,-9,LOG_2:13)
Block(1,12,-6,LOG_2:13)
Block(11,5,-9,LOG_2:13)
Block(-1,10,-4,LOG_2:13)
Block(11,6,-9,LOG_2:13)
Block(15,1,-6,LOG_2:13)
Block(11,9,-9,LEAVES_2:1)
Block(15,0,-6,LOG_2:13)
Block(12,4,-6,LOG_2:13)
Block(12,5,-6,LOG_2:13)
Block(12,6,-6,LOG_2:13)
Block(12,0,-6,LOG_2:13)
Block(12,1,-6,LOG_2:13)
Block(12,2,-6,LOG_2:13)
Block(12,3,-6,LOG_2:13)
Block(12,7,-7,LOG_2:13)
Block(2,10,-9,LOG_2:13)
Block(2,12,-9,LOG_2:13)
Block(2,11,-9,LOG_2:13)
Block(6,9,-8,LOG_2:13)
Block(11,0,-7,LEAVES_2:13)
Block(6,8,-8,LOG_2:13)
Block(11,1,-7,LOG_2:9)
Block(6,7,-8,LOG_2:13)
Block(11,2,-7,LOG_2:13)
Block(9,8,-10,LOG_2:13)
Block(11,3,-7,LOG_2:13)
Block(9,7,-10,LOG_2:13)
Block(11,4,-7,LOG_2:13)
Block(11,5,-7,LOG_2:13)
Block(6,8,-10,LOG_2:13)
Block(6,9,-10,LOG_2:13)
Block(6,6,-10,LEAVES_2:1)
Block(14,-1,-7,LOG_2:13)
Block(2,9,-9,WEB)
Block(-1,9,-5,LOG_2:13)
Block(-1,8,-5,LOG_2:13)
Block(-1,7,-5,LOG_2:13)
Block(16,1,-6,LEAVES_2:5)
Block(11,5,-8,LOG_2:13)
Block(11,6,-8,LOG_2:13)
Block(11,7,-8,LOG_2:13)
Block(-1,10,-6,LOG_2:13)
Block(-1,11,-6,LOG_2:13)
Block(15,1,-5,LOG_2:13)
Block(5,10,-11,LOG_2:13)
Block(15,0,-5,LOG_2:13)
Block(12,3,-7,LOG_2:13)
Block(12,4,-7,LOG_2:13)
Block(12,5,-7,LOG_2:13)
Block(12,6,-7,LOG_2:13)
Block(12,0,-7,LOG_2:13)
Block(12,1,-7,LOG_2:13)
Block(12,2,-7,LOG_2:13)
Block(-5,2,-1,LOG_2:13)
Block(12,6,-8,LOG_2:13)
Block(4,12,-9,LOG_2:13)
Block(-5,3,-1,LOG_2:13)
Block(4,11,-9,LOG_2:13)
Block(-5,0,-1,LOG_2:13)
Block(-5,1,-1,LOG_2:13)
Block(11,0,-6,LOG_2:13)
Block(11,1,-6,LOG_2:13)
Block(1,9,-9,LOG_2:13)
Block(6,9,-7,LOG_2:13)
Block(4,10,-9,LOG_2:13)
Block(11,2,-6,LOG_2:13)
Block(6,8,-7,LOG_2:13)
Block(11,3,-6,LOG_2:13)
Block(6,7,-7,LOG_2:13)
Block(11,4,-6,LOG_2:13)
Block(11,5,-6,LOG_2:13)
Block(11,6,-6,LOG_2:13)
Block(-1,11,-5,LOG_2:13)
Block(5,11,-10,LOG_2:13)
Block(5,10,-10,LOG_2:13)
Block(-1,10,-5,LOG_2:13)
Block(-2,-1,-1,LOG_2:13)
Block(-5,4,-1,LOG_2:13)
Block(-5,5,-1,LOG_2:13)
Block(-3,-1,0,LOG_2:13)
Block(-3,-2,0,LOG_2:13)
Block(8,10,-7,LOG_2:13)
Block(-3,-3,0,LOG_2:13)
Block(16,0,-5,LOG_2:13)
Block(-1,9,-4,LOG_2:13)
Block(-1,8,-4,LOG_2:13)
Block(-1,7,-4,LOG_2:13)
Block(-1,6,-4,LOG_2:13)
Block(15,0,-4,LOG_2:13)
Block(11,6,-7,LOG_2:13)
Block(11,7,-7,LOG_2:13)
Block(11,8,-7,LOG_2:13)
Block(6,11,-8,LOG_2:13)
Block(6,10,-8,LOG_2:13)
Block(12,2,-8,LOG_2:13)
Block(12,3,-8,LOG_2:13)
Block(2,11,-11,LOG_2:13)
Block(12,4,-8,LOG_2:13)
Block(12,5,-8,LOG_2:13)
Block(-3,7,-7,LOG_2:13)
Block(-3,8,-7,LOG_2:13)
Block(-3,9,-7,LOG_2:13)
Block(-3,1,0,LOG_2:13)
Block(-3,0,0,LOG_2:13)
Block(11,0,-5,LOG_2:13)
Block(11,1,-5,LOG_2:13)
Block(-2,11,-6,LOG_2:13)
Block(11,2,-5,LOG_2:13)
Block(11,3,-5,LOG_2:13)
Block(11,4,-5,LOG_2:13)
Block(11,5,-5,LOG_2:13)
Block(1,9,-8,LOG_2:13)
Block(11,6,-5,LOG_2:13)
Block(-2,10,-6,LOG_2:13)
Block(-6,4,-2,LOG_2:13)
Block(-6,3,-2,LOG_2:13)
Block(-5,9,-6,LEAVES_2:1)
Block(6,11,-9,LOG_2:13)
Block(-6,2,-2,LOG_2:13)
Block(-6,1,-2,LOG_2:13)
Block(6,10,-9,LOG_2:13)
Block(-1,12,-7,LOG_2:13)
Block(-1,11,-7,LOG_2:13)
Block(-1,10,-7,LOG_2:13)
Block(-3,3,0,LOG_2:13)
Block(-3,2,0,LOG_2:13)
Block(-5,3,-6,LEAVES_2:1)
Block(-3,5,0,LOG_2:13)
Block(-3,4,0,LOG_2:13)
Block(8,9,-10,LOG_2:13)
Block(8,8,-10,LOG_2:13)
Block(7,10,-8,LOG_2:13)
Block(13,0,-4,LOG_2:13)
Block(7,11,-8,LOG_2:13)
Block(13,2,-4,LOG_2:13)
Block(13,1,-4,LOG_2:13)
Block(11,7,-6,LOG_2:13)
Block(11,8,-6,LOG_2:13)
Block(-3,5,-6,LOG_2:13)
Block(-3,6,-6,LOG_2:13)
Block(12,4,-9,LOG_2:13)
Block(8,6,-9,LOG_2:13)
Block(-3,7,-6,LOG_2:13)
Block(12,3,-9,LOG_2:13)
Block(8,7,-9,LOG_2:13)
Block(-3,8,-6,LOG_2:13)
Block(8,8,-9,LOG_2:13)
Block(5,9,-7,LOG_2:13)
Block(-3,9,-6,LOG_2:13)
Block(8,9,-9,LOG_2:13)
Block(5,8,-7,LOG_2:13)
Block(7,10,-9,LOG_2:13)
Block(8,10,-8,LOG_2:13)
Block(1,9,-7,LOG_2:13)
Block(-5,-3,0,LOG_2:13)
Block(-5,-2,0,LOG_2:13)
Block(-5,-1,0,LOG_2:13)
Block(-6,3,-1,LOG_2:13)
Block(-5,9,-7,LEAVES_2:1)
Block(-6,2,-1,LOG_2:13)
Block(-6,1,-1,LOG_2:13)
Block(-6,0,-1,LOG_2:13)
Block(-3,10,-6,LOG_2:13)
Block(13,1,-3,LOG_2:13)
Block(-3,4,-5,LOG_2:13)
Block(-3,5,-5,LOG_2:13)
Block(-3,6,-5,LOG_2:13)
Block(8,6,-8,LOG_2:13)
Block(-3,7,-5,LOG_2:13)
Block(8,7,-8,LOG_2:13)
Block(-3,8,-5,LOG_2:13)
Block(8,8,-8,LOG_2:13)
Block(-3,9,-5,LOG_2:13)
Block(5,8,-8,LOG_2:13)
Block(8,9,-8,LOG_2:13)
Block(5,9,-8,LOG_2:13)
Block(-4,4,0,LOG_2:13)
Block(-4,3,0,LOG_2:13)
Block(-4,2,0,LOG_2:13)
Block(-4,1,0,LOG_2:13)
Block(-4,5,0,LOG_2:13)
Block(-4,0,0,LOG_2:13)
Block(10,7,-8,LOG_2:13)
Block(-5,4,-4,LOG_2:13)
Block(10,6,-8,LOG_2:13)
Block(10,5,-8,LOG_2:13)
Block(10,4,-8,LOG_2:13)
Block(-5,7,-4,LOG_2:13)
Block(-5,5,-4,LOG_2:13)
Block(-5,6,-4,LOG_2:13)
Block(10,8,-8,LOG_2:13)
Block(13,2,-6,LOG_2:13)
Block(13,1,-6,LOG_2:13)
Block(-1,6,-1,LEAVES_2:5)
Block(13,4,-6,LOG_2:13)
Block(5,9,-9,LOG_2:13)
Block(13,3,-6,LOG_2:13)
Block(10,3,-8,LOG_2:13)
Block(13,5,-6,LOG_2:13)
Block(1,11,-10,LOG_2:13)
Block(13,0,-6,LOG_2:13)
Block(-2,11,-7,LOG_2:13)
Block(-2,10,-7,LOG_2:13)
Block(-3,3,-4,LOG_2:13)
Block(-3,4,-4,LOG_2:13)
Block(-3,5,-4,LOG_2:13)
Block(8,5,-7,LOG_2:13)
Block(-3,6,-4,LOG_2:13)
Block(8,6,-7,LOG_2:13)
Block(-3,7,-4,LOG_2:13)
Block(8,7,-7,LOG_2:13)
Block(-3,8,-4,LOG_2:13)
Block(8,8,-7,LOG_2:13)
Block(-3,9,-4,LOG_2:13)
Block(8,9,-7,LOG_2:13)
Block(5,8,-9,LOG_2:13)
Block(-3,10,-7,LOG_2:13)
Block(-2,10,-8,LOG_2:13)
Block(-2,11,-8,LOG_2:13)
Block(10,6,-9,LOG_2:13)
Block(-5,3,-5,LEAVES_2:1)
Block(10,5,-9,LOG_2:13)
Block(3,9,-8,LOG_2:13)
Block(10,4,-9,LOG_2:13)
Block(-5,6,-5,LOG_2:13)
Block(-5,7,-5,LOG_2:13)
Block(10,8,-9,LOG_2:13)
Block(-5,5,-5,LOG_2:13)
Block(10,7,-9,LOG_2:13)
Block(13,3,-5,LOG_2:13)
Block(13,2,-5,LOG_2:13)
Block(-5,-2,1,LOG_2:13)
Block(-5,-3,1,LOG_2:13)
Block(13,1,-5,LOG_2:13)
Block(-5,-1,1,LOG_2:13)
Block(13,0,-5,LOG_2:13)
Block(-3,3,-3,LOG_2:13)
Block(-3,4,-3,LOG_2:13)
Block(-3,5,-3,LOG_2:13)
Block(-1,12,-8,LOG_2:13)
Block(-3,6,-3,LOG_2:13)
Block(-1,11,-8,LOG_2:13)
Block(8,6,-6,LOG_2:13)
Block(-3,7,-3,LOG_2:13)
Block(-1,10,-8,LOG_2:13)
Block(8,7,-6,LOG_2:13)
Block(-3,8,-3,LOG_2:13)
Block(8,8,-6,LOG_2:13)
Block(-3,9,-3,LOG_2:13)
Block(8,9,-6,LOG_2:13)

#######################################################################
# +-----------------------------------------------------------------+ #
# |                            BO3 checks                           | #
# +-----------------------------------------------------------------+ #
#######################################################################

BlockCheck(14,-1,-4,GRASS:0,DIRT:0)
BlockCheck(13,-1,-8,GRASS:0,DIRT:0)
BlockCheck(10,-1,-6,GRASS:0,DIRT:0)
BlockCheck(-3,-1,-2,GRASS:0,DIRT:0)
BlockCheck(-4,-1,1,GRASS:0,DIRT:0)
BlockCheck(14,-1,-5,GRASS:0,DIRT:0)

#######################################################################
# +-----------------------------------------------------------------+ #
# |                             Branches                            | #
# +-----------------------------------------------------------------+ #
#######################################################################


#######################################################################
# +-----------------------------------------------------------------+ #
# |                             Entities                            | #
# +-----------------------------------------------------------------+ #
#######################################################################


#######################################################################
# +-----------------------------------------------------------------+ #
# |                            Particles                            | #
# +-----------------------------------------------------------------+ #
#######################################################################


#######################################################################
# +-----------------------------------------------------------------+ #
# |                             Spawners                            | #
# +-----------------------------------------------------------------+ #
#######################################################################


#######################################################################
# +-----------------------------------------------------------------+ #
# |                             ModData                             | #
# +-----------------------------------------------------------------+ #
#######################################################################

