
#######################################################################
# +-----------------------------------------------------------------+ #
# |                            BO3 object                           | #
# +-----------------------------------------------------------------+ #
#######################################################################

Author: LordSmellyPants

Description: Converted version of the BO2 HauntedTwisted4

Version: 3

SettingsMode: WriteWithoutComments


#######################################################################
# +-----------------------------------------------------------------+ #
# |                          Main settings                          | #
# +-----------------------------------------------------------------+ #
#######################################################################

Tree: true

Frequency: 1

Rarity: 20.0

RotateRandomly: true

SpawnHeight: highestSolidBlock

SpawnHeightOffset: 0

SpawnHeightVariance: 0

##############################
# Height Limits for the BO3. #
##############################

MinHeight: 0

MaxHeight: 30

######################
# Extrusion settings #
######################

ExtrudeMode: None

ExtrudeThroughBlocks: AIR

MaxBranchDepth: 10

ExcludedBiomes: All


#######################################################################
# +-----------------------------------------------------------------+ #
# |                      Source block settings                      | #
# +-----------------------------------------------------------------+ #
#######################################################################

SourceBlocks: AIR

MaxPercentageOutsideSourceBlock: 20

OutsideSourceBlock: dontPlace

DoReplaceBlocks: true

IsOTGPlus: false


#######################################################################
# +-----------------------------------------------------------------+ #
# |                              Blocks                             | #
# +-----------------------------------------------------------------+ #
#######################################################################

Block(-4,9,2,LOG_2:13)
Block(-4,8,2,LOG_2:13)
Block(-4,7,2,WEB)
Block(2,19,4,LOG_2:13)
Block(-3,7,4,LEAVES_2:1)
Block(-3,8,4,LEAVES_2:1)
Block(-3,10,2,LOG_2:13)
Block(-4,11,-1,LEAVES_2:9)
Block(1,28,1,LOG_2:13)
Block(-4,10,-1,LOG_2:13)
Block(1,29,1,LOG_2:13)
Block(-3,14,2,LOG_2:13)
Block(-3,13,2,LOG_2:13)
Block(-3,12,2,LOG_2:13)
Block(2,24,4,LOG_2:13)
Block(-3,11,2,LOG_2:13)
Block(2,25,4,LOG_2:13)
Block(2,22,4,LOG_2:13)
Block(2,23,4,LOG_2:13)
Block(-3,16,2,LOG_2:13)
Block(2,20,4,LOG_2:13)
Block(-3,15,2,LOG_2:13)
Block(2,21,4,LOG_2:13)
Block(-3,5,-2,LOG_2:13)
Block(-3,6,-2,LOG_2:13)
Block(1,10,1,LOG_2:13)
Block(-3,7,-2,LOG_2:13)
Block(-4,14,4,LOG_2:13)
Block(-4,15,4,LOG_2:13)
Block(-4,16,4,LOG_2:13)
Block(-4,17,4,LOG_2:13)
Block(2,25,3,LOG_2:13)
Block(2,26,3,LOG_2:13)
Block(-4,9,1,LOG_2:13)
Block(2,23,3,LOG_2:13)
Block(-4,8,1,LOG_2:13)
Block(2,24,3,LOG_2:13)
Block(4,-4,1,LOG_2:13)
Block(2,21,3,LOG_2:13)
Block(2,22,3,LOG_2:13)
Block(4,-2,1,LOG_2:13)
Block(4,-3,1,LOG_2:13)
Block(4,-1,1,LOG_2:13)
Block(-4,7,1,WEB)
Block(-4,6,1,WEB)
Block(2,27,3,LOG_2:13)
Block(2,28,3,LOG_2:13)
Block(-3,8,3,LOG_2:13)
Block(-3,9,3,LOG_2:13)
Block(-4,15,5,LOG_2:13)
Block(-4,14,5,WEB)
Block(-4,13,5,WEB)
Block(3,-2,-1,LOG_2:13)
Block(3,-3,-1,LOG_2:13)
Block(3,-4,-1,LOG_2:13)
Block(-3,5,-1,LOG_2:13)
Block(1,30,1,LOG_2:13)
Block(-3,6,-1,LOG_2:13)
Block(1,31,1,LOG_2:13)
Block(-3,7,-1,LOG_2:13)
Block(-3,8,-1,LOG_2:13)
Block(3,-1,-1,LOG_2:13)
Block(-3,9,-1,LOG_2:13)
Block(-3,11,3,LOG_2:13)
Block(-3,10,3,LOG_2:13)
Block(0,1,0,LOG_2:13)
Block(-3,15,3,LOG_2:13)
Block(0,0,0,LOG_2:13)
Block(-3,14,3,LOG_2:13)
Block(0,3,0,LOG_2:13)
Block(-3,13,3,LOG_2:13)
Block(0,2,0,LOG_2:13)
Block(-3,12,3,LOG_2:13)
Block(0,5,0,LOG_2:13)
Block(-1,21,5,LEAVES_2:5)
Block(0,4,0,LOG_2:13)
Block(0,7,0,LOG_2:13)
Block(-3,17,3,LOG_2:13)
Block(0,6,0,LOG_2:13)
Block(-3,16,3,LOG_2:13)
Block(-1,20,5,LOG_2:13)
Block(-2,13,0,LEAVES_2:5)
Block(-2,12,0,LOG_2:13)
Block(-2,11,0,LOG_2:13)
Block(-2,10,0,LOG_2:13)
Block(0,-1,1,LOG_2:13)
Block(1,6,-2,LOG_2:13)
Block(0,-4,1,LOG_2:13)
Block(1,7,-2,LOG_2:13)
Block(0,-3,1,LOG_2:13)
Block(1,4,-2,LOG_2:13)
Block(0,-2,1,LOG_2:13)
Block(1,5,-2,LOG_2:13)
Block(1,2,-2,LOG_2:13)
Block(-4,13,3,LOG_2:13)
Block(-1,14,5,LOG_2:13)
Block(1,3,-2,LOG_2:13)
Block(-4,14,3,LOG_2:13)
Block(-1,15,5,LOG_2:13)
Block(-4,15,3,LOG_2:13)
Block(1,1,-2,LOG_2:13)
Block(-1,13,5,LOG_2:13)
Block(-4,16,3,LOG_2:13)
Block(-1,18,5,LOG_2:13)
Block(-1,19,5,LOG_2:13)
Block(-1,16,5,LOG_2:13)
Block(-1,17,5,LOG_2:13)
Block(-4,8,-1,LOG_2:13)
Block(-4,9,-1,LOG_2:13)
Block(-4,10,3,LOG_2:13)
Block(-4,11,3,LOG_2:13)
Block(-4,12,3,LOG_2:13)
Block(2,1,-1,LOG_2:13)
Block(-5,8,1,LOG_2:13)
Block(2,0,-1,LOG_2:13)
Block(-5,9,1,LOG_2:13)
Block(1,21,2,LOG_2:13)
Block(2,4,-1,LOG_2:13)
Block(1,22,2,LOG_2:13)
Block(2,3,-1,LOG_2:13)
Block(2,2,-1,LOG_2:13)
Block(0,8,1,LOG_2:13)
Block(1,25,2,LOG_2:13)
Block(0,7,1,LOG_2:13)
Block(1,26,2,LOG_2:13)
Block(1,27,2,LOG_2:13)
Block(0,9,1,LOG_2:13)
Block(1,28,2,LOG_2:13)
Block(1,29,2,LOG_2:13)
Block(-4,9,3,LOG_2:13)
Block(-4,8,3,LOG_2:13)
Block(1,-4,-1,LOG_2:13)
Block(1,-3,-1,LOG_2:13)
Block(1,-2,-1,LOG_2:13)
Block(1,-1,-1,LOG_2:13)
Block(-4,12,4,LOG_2:13)
Block(-4,13,4,LOG_2:13)
Block(1,21,3,LOG_2:13)
Block(1,20,3,LOG_2:13)
Block(1,7,-1,LOG_2:13)
Block(1,23,3,LOG_2:13)
Block(1,22,3,LOG_2:13)
Block(1,5,-1,LOG_2:13)
Block(1,25,3,LOG_2:13)
Block(1,6,-1,LOG_2:13)
Block(1,24,3,LOG_2:13)
Block(1,3,-1,LOG_2:13)
Block(1,4,-1,LOG_2:13)
Block(1,1,-1,LOG_2:13)
Block(1,2,-1,LOG_2:13)
Block(-3,12,4,LOG_2:13)
Block(1,0,-1,LOG_2:13)
Block(-3,11,4,LOG_2:13)
Block(-3,16,4,LOG_2:13)
Block(2,23,2,LOG_2:13)
Block(-3,15,4,LOG_2:13)
Block(2,22,2,LOG_2:13)
Block(-3,14,4,LOG_2:13)
Block(2,25,2,LOG_2:13)
Block(-3,13,4,LOG_2:13)
Block(2,24,2,LOG_2:13)
Block(-2,-4,1,LOG_2:13)
Block(-2,-3,1,LOG_2:13)
Block(-3,19,4,LOG_2:13)
Block(-3,18,4,LOG_2:13)
Block(-3,17,4,LOG_2:13)
Block(-1,-1,-1,LOG_2:13)
Block(-1,-2,-1,LOG_2:13)
Block(-1,-3,-1,LOG_2:13)
Block(-2,-2,1,LOG_2:13)
Block(-1,-4,-1,LOG_2:13)
Block(-2,-1,1,LOG_2:13)
Block(2,27,2,LOG_2:13)
Block(2,26,2,LOG_2:13)
Block(2,29,2,LOG_2:13)
Block(2,28,2,LOG_2:13)
Block(0,-4,0,LOG_2:13)
Block(2,4,-2,LOG_2:13)
Block(0,-3,0,LOG_2:13)
Block(2,3,-2,LOG_2:13)
Block(0,-2,0,LOG_2:13)
Block(2,2,-2,LOG_2:13)
Block(0,9,0,LOG_2:13)
Block(-1,16,6,LOG_2:13)
Block(0,8,0,LOG_2:13)
Block(-1,15,6,LOG_2:13)
Block(1,18,3,WEB)
Block(1,19,3,LOG_2:13)
Block(-1,19,6,LOG_2:13)
Block(-1,18,6,LOG_2:13)
Block(-4,11,2,LOG_2:13)
Block(-4,10,2,LOG_2:13)
Block(4,0,1,LOG_2:13)
Block(2,26,1,LOG_2:13)
Block(2,25,1,LOG_2:13)
Block(2,28,1,LOG_2:13)
Block(4,1,1,LOG_2:13)
Block(2,27,1,LOG_2:13)
Block(3,24,4,LOG_2:13)
Block(3,23,4,LOG_2:13)
Block(1,19,4,LOG_2:13)
Block(3,22,4,LOG_2:13)
Block(1,18,4,LOG_2:13)
Block(3,21,4,LOG_2:13)
Block(3,1,3,LOG_2:13)
Block(0,11,1,LOG_2:13)
Block(3,0,3,LOG_2:13)
Block(0,10,1,LOG_2:13)
Block(2,-1,3,LOG_2:13)
Block(2,-4,3,LOG_2:13)
Block(2,-2,3,LOG_2:13)
Block(2,-3,3,LOG_2:13)
Block(0,-3,2,LOG_2:13)
Block(-1,-1,0,LOG_2:13)
Block(0,-4,2,LOG_2:13)
Block(-1,-2,0,LOG_2:13)
Block(-1,-3,0,LOG_2:13)
Block(-1,-4,0,LOG_2:13)
Block(0,-1,2,LOG_2:13)
Block(0,-2,2,LOG_2:13)
Block(-3,12,5,LOG_2:13)
Block(-3,13,5,LOG_2:13)
Block(-3,19,5,LEAVES_2:1)
Block(-3,14,5,LOG_2:13)
Block(-3,15,5,LOG_2:13)
Block(-3,16,5,LOG_2:13)
Block(-3,17,5,LOG_2:13)
Block(2,-2,2,LOG_2:13)
Block(2,-1,2,LOG_2:13)
Block(-5,15,4,LOG_2:13)
Block(2,-4,2,LOG_2:13)
Block(2,-3,2,LOG_2:13)
Block(-2,10,-1,LOG_2:13)
Block(-1,10,-1,LOG_2:13)
Block(-2,11,-1,LOG_2:13)
Block(-2,14,1,LOG_2:13)
Block(-2,13,1,LOG_2:13)
Block(-2,16,1,LOG_2:13)
Block(-2,15,1,LOG_2:13)
Block(-2,10,1,LOG_2:13)
Block(-2,12,1,LOG_2:13)
Block(-2,11,1,LOG_2:13)
Block(1,20,4,LOG_2:13)
Block(1,22,4,LOG_2:13)
Block(1,21,4,LOG_2:13)
Block(-4,15,2,LEAVES_2:5)
Block(-4,14,2,LOG_2:13)
Block(-4,13,2,LOG_2:13)
Block(-4,12,2,LOG_2:13)
Block(0,10,0,LOG_2:13)
Block(0,4,-2,LOG_2:13)
Block(0,3,-2,LOG_2:13)
Block(0,6,-2,LOG_2:13)
Block(0,5,-2,LOG_2:13)
Block(0,7,-2,LOG_2:13)
Block(3,0,-1,LOG_2:13)
Block(3,1,-1,LOG_2:13)
Block(0,2,-2,LOG_2:13)
Block(-2,10,3,LOG_2:13)
Block(1,20,5,LOG_2:13)
Block(-2,9,-1,LOG_2:13)
Block(1,21,5,LOG_2:13)
Block(-2,4,-1,LOG_2:13)
Block(0,20,2,LOG_2:13)
Block(-2,3,-1,LOG_2:13)
Block(-2,2,-1,LOG_2:13)
Block(-2,8,-1,LOG_2:13)
Block(-2,7,-1,LOG_2:13)
Block(-2,6,-1,LOG_2:13)
Block(-2,5,-1,LOG_2:13)
Block(-3,15,6,LOG_2:13)
Block(-2,19,3,LOG_2:13)
Block(-2,17,3,LOG_2:13)
Block(2,28,0,LOG_2:13)
Block(-2,18,3,LOG_2:13)
Block(-2,15,3,LOG_2:13)
Block(-2,16,3,LOG_2:13)
Block(-2,13,3,LOG_2:13)
Block(-2,14,3,LOG_2:13)
Block(-2,11,3,LOG_2:13)
Block(-2,12,3,LOG_2:13)
Block(2,27,0,LOG_2:13)
Block(0,19,2,LOG_2:13)
Block(-4,10,0,LOG_2:13)
Block(-4,11,0,LOG_2:13)
Block(1,19,5,LOG_2:13)
Block(3,23,3,LOG_2:13)
Block(-3,10,-1,LOG_2:13)
Block(0,10,2,LOG_2:13)
Block(3,22,3,LOG_2:13)
Block(-3,11,-1,LOG_2:13)
Block(0,11,2,LOG_2:13)
Block(0,12,2,LOG_2:13)
Block(3,25,3,LOG_2:13)
Block(3,24,3,LOG_2:13)
Block(0,3,-3,LOG_2:13)
Block(0,2,-3,LOG_2:13)
Block(0,4,-3,LOG_2:13)
Block(-2,16,2,LOG_2:13)
Block(-2,17,2,LOG_2:13)
Block(-2,14,2,LOG_2:13)
Block(-2,15,2,LOG_2:13)
Block(-2,12,2,LOG_2:13)
Block(-2,13,2,LOG_2:13)
Block(-2,10,2,LOG_2:13)
Block(-2,11,2,LOG_2:13)
Block(-2,9,-2,LOG_2:13)
Block(-2,8,-2,LOG_2:13)
Block(0,34,1,LOG_2:13)
Block(-4,13,1,LOG_2:13)
Block(-4,12,1,LOG_2:13)
Block(-4,11,1,LOG_2:13)
Block(-2,3,-2,LOG_2:13)
Block(-2,2,-2,LOG_2:13)
Block(-2,7,-2,LOG_2:13)
Block(0,33,1,LOG_2:13)
Block(-2,6,-2,LOG_2:13)
Block(0,32,1,LOG_2:13)
Block(-2,5,-2,LOG_2:13)
Block(0,31,1,LOG_2:13)
Block(-2,4,-2,LOG_2:13)
Block(0,30,1,LOG_2:13)
Block(-4,10,1,LOG_2:13)
Block(2,-4,1,LOG_2:13)
Block(2,-1,1,LOG_2:13)
Block(2,-3,1,LOG_2:13)
Block(2,-2,1,LOG_2:13)
Block(2,-3,0,LOG_2:13)
Block(-2,19,4,LOG_2:13)
Block(2,-4,0,LOG_2:13)
Block(-2,18,4,LOG_2:13)
Block(-2,17,4,LOG_2:13)
Block(-2,16,4,LOG_2:13)
Block(-5,13,2,LOG_2:13)
Block(-2,15,4,LOG_2:13)
Block(-2,14,4,LOG_2:13)
Block(2,-1,0,LOG_2:13)
Block(-2,13,4,LOG_2:13)
Block(2,-2,0,LOG_2:13)
Block(-2,12,4,LOG_2:13)
Block(-5,16,2,LEAVES_2:1)
Block(3,-4,3,LOG_2:13)
Block(-2,20,4,LOG_2:13)
Block(3,-3,3,LOG_2:13)
Block(2,4,2,LOG_2:13)
Block(-1,10,1,LOG_2:13)
Block(-1,11,1,LOG_2:13)
Block(3,-2,3,LOG_2:13)
Block(-1,12,1,LOG_2:13)
Block(3,-1,3,LOG_2:13)
Block(-1,13,1,LEAVES_2:9)
Block(-1,5,-3,LOG_2:13)
Block(-1,5,0,LOG_2:13)
Block(-1,4,0,LOG_2:13)
Block(-1,7,0,LOG_2:13)
Block(3,5,0,LEAVES_2:5)
Block(-1,6,0,LOG_2:13)
Block(-1,9,0,LOG_2:13)
Block(-1,8,0,LOG_2:13)
Block(2,-4,-1,LOG_2:13)
Block(2,2,1,LOG_2:13)
Block(2,-3,-1,LOG_2:13)
Block(2,1,1,LOG_2:13)
Block(2,4,1,LOG_2:13)
Block(2,3,1,LOG_2:13)
Block(2,-2,-1,LOG_2:13)
Block(2,0,1,LOG_2:13)
Block(-1,7,-3,LOG_2:13)
Block(2,-1,-1,LOG_2:13)
Block(-1,6,-3,LOG_2:13)
Block(-5,11,2,LOG_2:13)
Block(-5,12,2,LOG_2:13)
Block(0,21,3,LOG_2:13)
Block(0,22,3,LOG_2:13)
Block(1,1,3,LOG_2:13)
Block(-1,1,0,LOG_2:13)
Block(-1,0,0,LOG_2:13)
Block(-1,3,0,LOG_2:13)
Block(-1,2,0,LOG_2:13)
Block(0,20,3,LOG_2:13)
Block(0,5,-1,LOG_2:13)
Block(0,4,-1,LOG_2:13)
Block(0,7,-1,LOG_2:13)
Block(0,6,-1,LOG_2:13)
Block(0,9,-1,LOG_2:13)
Block(0,8,-1,LOG_2:13)
Block(0,1,-1,LOG_2:13)
Block(0,3,-1,LOG_2:13)
Block(0,2,-1,LOG_2:13)
Block(0,18,3,LOG_2:13)
Block(0,19,3,LOG_2:13)
Block(3,27,2,LOG_2:13)
Block(0,15,3,LOG_2:13)
Block(0,16,3,LOG_2:13)
Block(0,17,3,LOG_2:13)
Block(3,0,0,LOG_2:13)
Block(0,10,3,LOG_2:13)
Block(3,22,2,WEB)
Block(0,11,3,BROWN_MUSHROOM)
Block(0,12,3,LOG_2:13)
Block(0,13,3,LOG_2:13)
Block(3,4,0,LOG_2:13)
Block(3,25,2,LOG_2:13)
Block(3,3,0,LOG_2:13)
Block(3,26,2,LOG_2:13)
Block(3,2,0,LOG_2:13)
Block(3,23,2,LOG_2:13)
Block(3,1,0,LOG_2:13)
Block(3,24,2,LOG_2:13)
Block(-1,6,-2,LOG_2:13)
Block(-1,5,-2,LOG_2:13)
Block(-1,4,-2,LOG_2:13)
Block(-1,3,-2,LOG_2:13)
Block(-1,2,-2,LOG_2:13)
Block(2,1,2,LOG_2:13)
Block(2,0,2,LOG_2:13)
Block(2,3,2,LOG_2:13)
Block(2,2,2,LOG_2:13)
Block(-1,7,-2,LOG_2:13)
Block(-2,11,4,LOG_2:13)
Block(-1,18,2,LOG_2:13)
Block(4,22,4,LEAVES_2:1)
Block(-2,10,4,LOG_2:13)
Block(4,23,4,LEAVES_2:1)
Block(-1,19,2,LOG_2:13)
Block(-1,10,2,LOG_2:13)
Block(1,1,4,LOG_2:13)
Block(-1,12,2,LOG_2:13)
Block(-1,11,2,LOG_2:13)
Block(-1,14,2,LOG_2:13)
Block(-1,13,2,LOG_2:13)
Block(-1,16,2,LOG_2:13)
Block(-1,15,2,LOG_2:13)
Block(-1,-2,1,LOG_2:13)
Block(-1,-3,1,LOG_2:13)
Block(-1,-4,1,LOG_2:13)
Block(0,16,5,LOG_2:13)
Block(0,19,5,LOG_2:13)
Block(0,18,5,LOG_2:13)
Block(3,1,1,LOG_2:13)
Block(-1,-1,1,LOG_2:13)
Block(3,0,1,LOG_2:13)
Block(-1,3,2,LOG_2:13)
Block(-1,2,2,LOG_2:13)
Block(-1,5,2,LOG_2:13)
Block(-1,4,2,LOG_2:13)
Block(-1,7,2,LOG_2:13)
Block(-1,6,2,LOG_2:13)
Block(-1,9,2,LOG_2:13)
Block(-1,8,2,LOG_2:13)
Block(2,0,3,LOG_2:13)
Block(-2,9,0,LOG_2:13)
Block(-2,8,0,LOG_2:13)
Block(2,1,3,LOG_2:13)
Block(-2,7,0,LOG_2:13)
Block(-2,6,0,LOG_2:13)
Block(-2,5,0,LOG_2:13)
Block(-5,14,3,LOG_2:13)
Block(-2,4,0,LOG_2:13)
Block(-2,3,0,LOG_2:13)
Block(-5,16,3,LEAVES_2:1)
Block(3,-4,2,LOG_2:13)
Block(-2,2,0,LOG_2:13)
Block(3,-2,2,LOG_2:13)
Block(3,-3,2,LOG_2:13)
Block(-1,10,0,LOG_2:13)
Block(-1,11,0,LOG_2:13)
Block(3,-1,2,LOG_2:13)
Block(-1,1,2,LOG_2:13)
Block(-1,0,2,LOG_2:13)
Block(-2,12,5,LOG_2:13)
Block(-5,13,3,LOG_2:13)
Block(-5,12,3,LOG_2:13)
Block(3,1,2,LOG_2:13)
Block(3,0,2,LOG_2:13)
Block(0,20,4,LOG_2:13)
Block(0,21,4,LOG_2:13)
Block(-1,4,1,LOG_2:13)
Block(-1,3,1,LOG_2:13)
Block(-1,6,1,LOG_2:13)
Block(-1,5,1,LOG_2:13)
Block(-1,8,1,LOG_2:13)
Block(-1,7,1,LOG_2:13)
Block(-1,9,1,LOG_2:13)
Block(-2,19,5,LOG_2:13)
Block(-2,18,5,LOG_2:13)
Block(-2,17,5,LOG_2:13)
Block(-2,16,5,LOG_2:13)
Block(-2,15,5,LOG_2:13)
Block(-2,14,5,LOG_2:13)
Block(-2,13,5,LOG_2:13)
Block(-1,-4,2,LOG_2:13)
Block(0,19,4,LOG_2:13)
Block(-1,-3,2,LOG_2:13)
Block(-2,20,5,LEAVES_2:5)
Block(0,15,4,LOG_2:13)
Block(0,16,4,LOG_2:13)
Block(0,17,4,LOG_2:13)
Block(0,18,4,LOG_2:13)
Block(-1,0,1,LOG_2:13)
Block(3,25,1,LOG_2:13)
Block(-1,-2,2,LOG_2:13)
Block(-1,2,1,LOG_2:13)
Block(-1,-1,2,LOG_2:13)
Block(-1,1,1,LOG_2:13)
Block(0,1,2,LOG_2:13)
Block(0,0,2,LOG_2:13)
Block(0,3,2,LOG_2:13)
Block(0,2,2,LOG_2:13)
Block(0,5,2,LOG_2:13)
Block(0,4,2,LOG_2:13)
Block(1,7,0,LOG_2:13)
Block(-3,7,0,LOG_2:13)
Block(-3,6,0,LOG_2:13)
Block(-3,9,0,LOG_2:13)
Block(-3,8,0,LOG_2:13)
Block(-3,3,0,LOG_2:13)
Block(-3,2,0,LOG_2:13)
Block(0,20,6,LOG_2:13)
Block(-3,5,0,LOG_2:13)
Block(-3,4,0,LOG_2:13)
Block(1,-4,0,LOG_2:13)
Block(1,-3,0,LOG_2:13)
Block(1,-2,0,LOG_2:13)
Block(1,-1,0,LOG_2:13)
Block(-1,20,4,LOG_2:13)
Block(-2,9,2,LOG_2:13)
Block(-2,8,2,LOG_2:13)
Block(-2,7,2,LOG_2:13)
Block(-2,6,2,LOG_2:13)
Block(-2,5,2,LOG_2:13)
Block(-2,4,2,LOG_2:13)
Block(-2,3,2,LOG_2:13)
Block(-2,2,2,LOG_2:13)
Block(-1,19,4,LOG_2:13)
Block(0,19,6,LOG_2:13)
Block(-1,13,4,LOG_2:13)
Block(-1,14,4,LOG_2:13)
Block(0,8,3,LOG_2:13)
Block(0,16,6,LEAVES_2:1)
Block(-1,12,4,LOG_2:13)
Block(-1,17,4,LOG_2:13)
Block(0,9,3,LOG_2:13)
Block(-1,18,4,LOG_2:13)
Block(-1,15,4,LOG_2:13)
Block(-1,16,4,LOG_2:13)
Block(0,0,1,LOG_2:13)
Block(0,2,1,LOG_2:13)
Block(0,1,1,LOG_2:13)
Block(0,4,1,LOG_2:13)
Block(1,9,1,LOG_2:13)
Block(0,3,1,LOG_2:13)
Block(1,8,1,LOG_2:13)
Block(0,6,1,LOG_2:13)
Block(1,7,1,LOG_2:13)
Block(0,5,1,LOG_2:13)
Block(1,6,1,LOG_2:13)
Block(4,25,2,LOG_2:13)
Block(-2,17,6,LOG_2:13)
Block(-2,16,6,LOG_2:13)
Block(-2,15,6,LOG_2:13)
Block(-2,14,6,LOG_2:13)
Block(3,-3,1,LOG_2:13)
Block(3,-4,1,LOG_2:13)
Block(3,-1,1,LOG_2:13)
Block(3,-2,1,LOG_2:13)
Block(-3,11,0,LOG_2:13)
Block(-1,2,3,BROWN_MUSHROOM)
Block(-1,1,3,LOG_2:13)
Block(-3,12,0,LOG_2:13)
Block(-3,10,0,LOG_2:13)
Block(-1,6,3,LOG_2:13)
Block(-1,5,3,LOG_2:13)
Block(-1,8,3,LOG_2:13)
Block(-3,13,0,LOG_2:13)
Block(-1,7,3,LOG_2:13)
Block(-2,9,1,LOG_2:13)
Block(-2,8,1,LOG_2:13)
Block(-1,9,3,LOG_2:13)
Block(-2,7,1,LOG_2:13)
Block(-2,6,1,LOG_2:13)
Block(-2,5,1,LOG_2:13)
Block(-2,4,1,LOG_2:13)
Block(-2,3,1,LOG_2:13)
Block(-2,2,1,LOG_2:13)
Block(-2,1,1,LOG_2:13)
Block(-2,0,1,LOG_2:13)
Block(1,6,0,LOG_2:13)
Block(0,7,2,LOG_2:13)
Block(1,5,0,LOG_2:13)
Block(0,6,2,LOG_2:13)
Block(1,4,0,LOG_2:13)
Block(0,9,2,LOG_2:13)
Block(1,3,0,LOG_2:13)
Block(0,8,2,LOG_2:13)
Block(1,2,0,LOG_2:13)
Block(0,20,5,LOG_2:13)
Block(1,1,0,LOG_2:13)
Block(1,0,0,LOG_2:13)
Block(-4,9,0,LOG_2:13)
Block(1,7,2,LOG_2:13)
Block(1,6,2,LOG_2:13)
Block(2,22,5,LOG_2:13)
Block(1,5,2,LEAVES_2:5)
Block(2,21,5,LOG_2:13)
Block(-4,8,0,LOG_2:13)
Block(-4,7,0,LOG_2:13)
Block(-4,6,0,LOG_2:13)
Block(-4,5,0,LOG_2:13)
Block(-5,10,1,LOG_2:13)
Block(-5,11,1,LOG_2:13)
Block(2,7,0,LOG_2:13)
Block(-3,9,2,LOG_2:13)
Block(2,6,0,LOG_2:13)
Block(-3,8,2,LOG_2:13)
Block(-3,5,2,LOG_2:13)
Block(-3,7,2,LOG_2:13)
Block(-3,6,2,LOG_2:13)
Block(-1,7,-1,LOG_2:13)
Block(-1,6,-1,LOG_2:13)
Block(-1,5,-1,LOG_2:13)
Block(-1,4,-1,LOG_2:13)
Block(-1,3,-1,LOG_2:13)
Block(-1,2,-1,LOG_2:13)
Block(-2,9,4,LOG_2:13)
Block(-1,1,-1,LOG_2:13)
Block(-2,8,4,LOG_2:13)
Block(-1,0,-1,LOG_2:13)
Block(-1,9,-1,LOG_2:13)
Block(-1,8,-1,LOG_2:13)
Block(1,5,1,LOG_2:13)
Block(1,4,1,LOG_2:13)
Block(1,-1,1,LOG_2:13)
Block(1,3,1,LOG_2:13)
Block(1,-2,1,LOG_2:13)
Block(1,2,1,LOG_2:13)
Block(1,-3,1,LOG_2:13)
Block(1,1,1,LOG_2:13)
Block(1,-4,1,LOG_2:13)
Block(1,0,1,LOG_2:13)
Block(-3,12,1,LOG_2:13)
Block(-3,13,1,LOG_2:13)
Block(1,29,0,LOG_2:13)
Block(-3,10,1,LOG_2:13)
Block(1,28,0,LOG_2:13)
Block(-3,11,1,LOG_2:13)
Block(0,2,3,LOG_2:13)
Block(0,1,3,LOG_2:13)
Block(0,4,3,LOG_2:13)
Block(-3,14,1,LOG_2:13)
Block(-1,20,3,LOG_2:13)
Block(0,3,3,LOG_2:13)
Block(-1,19,3,LOG_2:13)
Block(-1,18,3,LOG_2:13)
Block(2,6,1,LEAVES_2:5)
Block(2,5,1,LEAVES_2:5)
Block(-3,9,1,LOG_2:13)
Block(-3,6,1,LOG_2:13)
Block(-1,11,3,LOG_2:13)
Block(1,-1,2,LOG_2:13)
Block(-3,5,1,LOG_2:13)
Block(-1,10,3,LOG_2:13)
Block(1,-2,2,LOG_2:13)
Block(-3,8,1,LOG_2:13)
Block(-1,13,3,LOG_2:13)
Block(1,-3,2,LOG_2:13)
Block(-3,7,1,LOG_2:13)
Block(-1,12,3,LOG_2:13)
Block(1,-4,2,LOG_2:13)
Block(-1,15,3,LOG_2:13)
Block(-1,14,3,LOG_2:13)
Block(-1,17,3,LOG_2:13)
Block(-1,16,3,LOG_2:13)
Block(-2,9,3,LOG_2:13)
Block(-2,8,3,LOG_2:13)
Block(2,3,0,LOG_2:13)
Block(2,2,0,LOG_2:13)
Block(2,5,0,LOG_2:13)
Block(2,4,0,LOG_2:13)
Block(1,30,0,LOG_2:13)
Block(4,24,3,LOG_2:13)
Block(4,23,3,LOG_2:13)
Block(2,1,0,LOG_2:13)
Block(2,0,0,LOG_2:13)
Block(3,-1,0,LOG_2:13)
Block(3,-3,0,LOG_2:13)
Block(3,-2,0,LOG_2:13)
Block(3,-4,0,LOG_2:13)
Block(1,4,2,LOG_2:13)
Block(1,3,2,LOG_2:13)
Block(1,2,2,LOG_2:13)
Block(1,1,2,LOG_2:13)
Block(1,0,2,LOG_2:13)

#######################################################################
# +-----------------------------------------------------------------+ #
# |                            BO3 checks                           | #
# +-----------------------------------------------------------------+ #
#######################################################################

BlockCheck(0,-1,0,GRASS:0,DIRT:0)
BlockCheck(2,-1,-1,GRASS:0,DIRT:0)
BlockCheck(1,-1,-1,GRASS:0,DIRT:0)
BlockCheck(4,-1,1,GRASS:0,DIRT:0)

#######################################################################
# +-----------------------------------------------------------------+ #
# |                             Branches                            | #
# +-----------------------------------------------------------------+ #
#######################################################################


#######################################################################
# +-----------------------------------------------------------------+ #
# |                             Entities                            | #
# +-----------------------------------------------------------------+ #
#######################################################################


#######################################################################
# +-----------------------------------------------------------------+ #
# |                            Particles                            | #
# +-----------------------------------------------------------------+ #
#######################################################################


#######################################################################
# +-----------------------------------------------------------------+ #
# |                             Spawners                            | #
# +-----------------------------------------------------------------+ #
#######################################################################


#######################################################################
# +-----------------------------------------------------------------+ #
# |                             ModData                             | #
# +-----------------------------------------------------------------+ #
#######################################################################

