
#######################################################################
# +-----------------------------------------------------------------+ #
# |                            BO3 object                           | #
# +-----------------------------------------------------------------+ #
#######################################################################

Author: LordSmellyPants

Description: Converted version of the BO2 HauntedTwisted9

Version: 3

SettingsMode: WriteWithoutComments


#######################################################################
# +-----------------------------------------------------------------+ #
# |                          Main settings                          | #
# +-----------------------------------------------------------------+ #
#######################################################################

Tree: true

Frequency: 1

Rarity: 20.0

RotateRandomly: true

SpawnHeight: highestSolidBlock

SpawnHeightOffset: 0

SpawnHeightVariance: 0

##############################
# Height Limits for the BO3. #
##############################

MinHeight: 0

MaxHeight: 30

######################
# Extrusion settings #
######################

ExtrudeMode: None

ExtrudeThroughBlocks: AIR

MaxBranchDepth: 10

ExcludedBiomes: All


#######################################################################
# +-----------------------------------------------------------------+ #
# |                      Source block settings                      | #
# +-----------------------------------------------------------------+ #
#######################################################################

SourceBlocks: AIR

MaxPercentageOutsideSourceBlock: 20

OutsideSourceBlock: dontPlace

DoReplaceBlocks: true

IsOTGPlus: false


#######################################################################
# +-----------------------------------------------------------------+ #
# |                              Blocks                             | #
# +-----------------------------------------------------------------+ #
#######################################################################

Block(3,5,-3,LOG_2:13)
Block(6,3,-6,LOG_2:13)
Block(3,6,-3,LOG_2:13)
Block(6,2,-6,LOG_2:13)
Block(3,7,-3,LOG_2:13)
Block(6,1,-6,LOG_2:13)
Block(6,0,-6,LOG_2:13)
Block(3,4,-3,LOG_2:13)
Block(1,5,-4,LOG_2:13)
Block(4,0,-7,LEAVES_2:5)
Block(-1,5,-3,LOG_2:13)
Block(-1,5,0,LOG_2:13)
Block(-1,4,-3,LEAVES_2:9)
Block(-1,4,0,LOG_2:13)
Block(3,5,0,LEAVES_2:5)
Block(-1,6,0,LOG_2:13)
Block(-4,-1,-3,LOG_2:13)
Block(-4,-2,-3,LOG_2:13)
Block(-4,-3,-3,LOG_2:13)
Block(-4,-4,-3,LOG_2:13)
Block(8,0,-5,LOG_2:13)
Block(-3,1,-2,LOG_2:13)
Block(-3,2,-2,LOG_2:13)
Block(-4,-1,0,LOG_2:13)
Block(5,5,-3,LOG_2:13)
Block(5,3,-3,LOG_2:13)
Block(5,4,-3,LOG_2:13)
Block(-4,-1,-2,LOG_2:13)
Block(-1,3,0,LOG_2:13)
Block(6,-4,-3,LOG_2:13)
Block(6,4,-5,LOG_2:13)
Block(0,5,-1,LOG_2:13)
Block(3,6,-2,LOG_2:13)
Block(6,-3,-3,LOG_2:13)
Block(0,4,-1,LOG_2:13)
Block(6,5,-5,LOG_2:13)
Block(3,7,-2,LOG_2:13)
Block(6,-2,-3,LOG_2:13)
Block(6,2,-5,LOG_2:13)
Block(0,7,-1,LOG_2:13)
Block(6,-1,-3,LOG_2:13)
Block(6,3,-5,LOG_2:13)
Block(0,6,-1,LOG_2:13)
Block(6,0,-5,LOG_2:13)
Block(6,1,-5,LOG_2:13)
Block(-4,2,1,LOG_2:13)
Block(-4,1,1,LOG_2:13)
Block(-4,0,1,LOG_2:13)
Block(3,5,-2,LOG_2:13)
Block(-4,-3,1,LOG_2:13)
Block(-4,-2,1,LOG_2:13)
Block(-4,-1,1,LOG_2:13)
Block(1,5,-3,LOG_2:13)
Block(4,3,-6,LOG_2:13)
Block(1,6,-3,LOG_2:13)
Block(4,5,-6,LEAVES_2:1)
Block(4,0,-6,LOG_2:13)
Block(4,2,-6,LOG_2:13)
Block(-1,6,-2,LOG_2:13)
Block(-1,5,-2,LOG_2:13)
Block(-1,4,-2,LOG_2:13)
Block(-3,0,-1,LOG_2:13)
Block(-3,1,-1,LOG_2:13)
Block(5,0,-4,LOG_2:13)
Block(-3,2,-1,LOG_2:13)
Block(5,1,-4,LOG_2:13)
Block(-3,3,-1,LOG_2:13)
Block(-3,4,-1,LOG_2:13)
Block(-3,5,-1,LOG_2:13)
Block(5,4,-4,LOG_2:13)
Block(-3,6,-1,LEAVES_2:13)
Block(5,5,-4,LOG_2:13)
Block(5,2,-4,LOG_2:13)
Block(5,3,-4,LOG_2:13)
Block(-5,1,0,LOG_2:13)
Block(-5,0,0,LOG_2:13)
Block(5,6,-4,LOG_2:13)
Block(-5,2,0,LOG_2:13)
Block(3,4,-5,LOG_2:13)
Block(0,3,0,LEAVES_2:13)
Block(3,5,-5,LOG_2:13)
Block(0,5,0,LOG_2:13)
Block(0,4,0,LOG_2:13)
Block(0,7,0,LOG_2:13)
Block(0,6,0,LOG_2:13)
Block(4,5,-5,LOG_2:13)
Block(1,6,-2,LOG_2:13)
Block(4,4,-5,LOG_2:13)
Block(1,7,-2,LOG_2:13)
Block(1,4,-2,LOG_2:13)
Block(1,5,-2,LOG_2:13)
Block(-4,-1,-1,LOG_2:13)
Block(4,0,-5,LOG_2:13)
Block(4,3,-5,LOG_2:13)
Block(4,2,-5,LOG_2:13)
Block(5,-1,-5,LOG_2:13)
Block(-2,6,0,LOG_2:13)
Block(-2,5,0,LOG_2:13)
Block(-2,4,0,LOG_2:13)
Block(-2,3,0,LOG_2:13)
Block(-2,2,0,LOG_2:13)
Block(5,0,-5,LOG_2:13)
Block(-2,1,0,LOG_2:13)
Block(5,3,-5,LOG_2:13)
Block(2,5,-1,LOG_2:13)
Block(5,4,-5,LOG_2:13)
Block(5,1,-5,LOG_2:13)
Block(5,2,-5,LOG_2:13)
Block(-4,0,-1,LOG_2:13)
Block(-4,2,-1,LOG_2:13)
Block(5,5,-5,LOG_2:13)
Block(2,7,-1,LOG_2:13)
Block(-4,1,-1,LOG_2:13)
Block(5,6,-5,LOG_2:13)
Block(2,6,-1,LOG_2:13)
Block(3,4,-4,LOG_2:13)
Block(3,5,-4,LOG_2:13)
Block(5,-2,-4,LOG_2:13)
Block(3,6,-4,LOG_2:13)
Block(5,-1,-4,LOG_2:13)
Block(6,0,-7,LOG_2:13)
Block(-5,0,-1,LOG_2:13)
Block(3,3,-4,WEB)
Block(4,6,-4,LOG_2:13)
Block(1,7,-1,LOG_2:13)
Block(4,5,-4,LOG_2:13)
Block(1,5,-1,LOG_2:13)
Block(1,6,-1,LOG_2:13)
Block(4,7,-4,LOG_2:13)
Block(4,4,-4,LOG_2:13)
Block(4,3,-4,LOG_2:13)
Block(4,-1,-5,LOG_2:13)
Block(4,-2,-5,LOG_2:13)
Block(-1,4,1,LOG_2:13)
Block(-1,6,1,LOG_2:13)
Block(-1,5,1,LOG_2:13)
Block(-2,-4,1,LOG_2:13)
Block(-3,-1,0,LOG_2:13)
Block(-2,-3,1,LOG_2:13)
Block(-3,-2,0,LOG_2:13)
Block(-3,-3,0,LOG_2:13)
Block(-2,-2,1,LOG_2:13)
Block(-3,-4,0,LOG_2:13)
Block(6,-1,-4,LOG_2:13)
Block(6,-2,-4,LOG_2:13)
Block(3,-3,-5,LOG_2:13)
Block(5,2,-6,LOG_2:13)
Block(3,-2,-5,LOG_2:5)
Block(5,3,-6,LOG_2:13)
Block(5,0,-6,LOG_2:13)
Block(3,-4,-5,LOG_2:13)
Block(5,1,-6,LOG_2:13)
Block(2,7,-2,LOG_2:13)
Block(5,4,-6,LOG_2:13)
Block(2,6,-2,LOG_2:13)
Block(2,5,-2,LOG_2:13)
Block(5,-1,-6,LOG_2:13)
Block(-3,1,0,LOG_2:13)
Block(-3,0,0,LOG_2:13)
Block(1,7,0,LOG_2:13)
Block(6,-1,-5,LOG_2:13)
Block(7,-1,-4,LOG_2:13)
Block(4,6,-3,LOG_2:13)
Block(7,0,-6,LOG_2:13)
Block(4,5,-3,LOG_2:13)
Block(4,4,-3,LOG_2:13)
Block(-3,3,0,LOG_2:13)
Block(-3,2,0,LOG_2:13)
Block(7,3,-6,LEAVES_2:9)
Block(-3,5,0,LOG_2:13)
Block(-3,4,0,LOG_2:13)
Block(-2,6,2,LEAVES_2:1)
Block(5,1,-7,LOG_2:13)
Block(5,2,-7,LOG_2:13)
Block(5,0,-7,LOG_2:13)
Block(2,7,-3,LOG_2:13)
Block(2,6,-3,LOG_2:13)
Block(2,5,-3,LOG_2:13)
Block(-3,-1,-1,LOG_2:13)
Block(0,6,1,LOG_2:13)
Block(-5,-4,0,LOG_2:13)
Block(-5,-3,0,LOG_2:13)
Block(-5,-2,0,LOG_2:13)
Block(3,0,-6,LEAVES_2:5)
Block(-5,-1,0,LOG_2:13)
Block(4,4,-2,LOG_2:13)
Block(4,6,-2,LOG_2:13)
Block(4,5,-2,LOG_2:13)
Block(4,-1,-6,LOG_2:13)
Block(-2,5,1,LOG_2:13)
Block(7,-1,-5,LOG_2:13)
Block(-2,4,1,LOG_2:13)
Block(-2,3,1,LOG_2:13)
Block(2,6,-4,LOG_2:13)
Block(1,6,0,LOG_2:13)
Block(2,5,-4,LOG_2:13)
Block(1,5,0,LOG_2:13)
Block(-4,1,-2,LEAVES_2:13)
Block(2,4,-4,LOG_2:13)
Block(-4,0,-2,LOG_2:13)
Block(4,-2,-6,LOG_2:13)
Block(0,4,-2,LOG_2:13)
Block(6,5,-4,LEAVES_2:5)
Block(6,3,-4,LOG_2:13)
Block(0,6,-2,LOG_2:13)
Block(6,4,-4,LOG_2:13)
Block(0,5,-2,LOG_2:13)
Block(6,1,-4,LOG_2:13)
Block(6,2,-4,LOG_2:13)
Block(0,7,-2,LOG_2:13)
Block(6,0,-4,LOG_2:13)
Block(-4,4,0,LOG_2:13)
Block(-4,3,0,LOG_2:13)
Block(-4,2,0,LOG_2:13)
Block(-4,1,0,LOG_2:13)
Block(3,4,-1,LEAVES_2:5)
Block(3,5,-1,LOG_2:13)
Block(3,6,-1,LOG_2:13)
Block(-4,0,0,LOG_2:13)
Block(2,6,0,LOG_2:13)
Block(-2,4,-1,LOG_2:13)
Block(-2,3,-1,LOG_2:13)
Block(-3,4,2,LEAVES_2:1)
Block(7,1,-4,LOG_2:13)
Block(-2,2,-1,LOG_2:13)
Block(7,0,-4,LOG_2:13)
Block(-2,1,-1,LOG_2:13)
Block(-2,6,-1,LOG_2:13)
Block(-2,5,-1,LOG_2:13)
Block(-1,7,-1,LOG_2:13)
Block(-1,6,-1,LOG_2:13)
Block(-1,5,-1,LOG_2:13)
Block(-1,4,-1,LOG_2:13)
Block(-1,3,-1,LOG_2:13)
Block(6,-1,-6,LOG_2:13)
Block(8,-2,-5,LOG_2:13)
Block(8,-1,-5,LOG_2:13)
Block(8,-4,-5,LOG_2:13)
Block(8,-3,-5,LOG_2:13)
Block(2,5,-5,LEAVES_2:1)
Block(0,5,-3,LOG_2:13)
Block(0,4,-3,LOG_2:13)
Block(6,5,-3,LEAVES_2:1)
Block(0,6,-3,LOG_2:13)
Block(6,0,-3,LOG_2:13)
Block(6,1,-3,LOG_2:13)
Block(6,-2,-7,LOG_2:13)
Block(6,-1,-7,LOG_2:13)
Block(6,-3,-7,LOG_2:13)
Block(7,-2,-6,LOG_2:13)
Block(7,-1,-6,LOG_2:13)
Block(7,2,-5,LOG_2:13)
Block(-2,3,-2,LOG_2:13)
Block(7,1,-5,LOG_2:13)
Block(7,0,-5,LOG_2:13)
Block(-3,1,1,LOG_2:13)
Block(-3,4,1,LOG_2:13)
Block(-2,5,-2,LOG_2:13)
Block(7,3,-5,LOG_2:13)
Block(-3,3,1,LOG_2:13)
Block(-2,4,-2,LOG_2:13)
Block(5,-4,-7,LOG_2:13)
Block(5,-3,-7,LOG_2:13)
Block(-5,-1,-2,LOG_2:5)
Block(5,-2,-7,LOG_2:13)
Block(-5,-3,-2,LOG_2:13)
Block(-5,-2,-2,LOG_2:13)
Block(-5,-4,-2,LOG_2:13)
Block(5,-1,-7,LOG_2:13)

#######################################################################
# +-----------------------------------------------------------------+ #
# |                            BO3 checks                           | #
# +-----------------------------------------------------------------+ #
#######################################################################

BlockCheck(6,-1,-6,GRASS:0,DIRT:0)
BlockCheck(4,-1,-7,GRASS:0,DIRT:0)
BlockCheck(8,-1,-5,GRASS:0,DIRT:0)
BlockCheck(6,-1,-5,GRASS:0,DIRT:0)
BlockCheck(-4,-1,1,GRASS:0,DIRT:0)
BlockCheck(4,-1,-6,GRASS:0,DIRT:0)
BlockCheck(-3,-1,-1,GRASS:0,DIRT:0)

#######################################################################
# +-----------------------------------------------------------------+ #
# |                             Branches                            | #
# +-----------------------------------------------------------------+ #
#######################################################################


#######################################################################
# +-----------------------------------------------------------------+ #
# |                             Entities                            | #
# +-----------------------------------------------------------------+ #
#######################################################################


#######################################################################
# +-----------------------------------------------------------------+ #
# |                            Particles                            | #
# +-----------------------------------------------------------------+ #
#######################################################################


#######################################################################
# +-----------------------------------------------------------------+ #
# |                             Spawners                            | #
# +-----------------------------------------------------------------+ #
#######################################################################


#######################################################################
# +-----------------------------------------------------------------+ #
# |                             ModData                             | #
# +-----------------------------------------------------------------+ #
#######################################################################

