
#######################################################################
# +-----------------------------------------------------------------+ #
# |                            BO3 object                           | #
# +-----------------------------------------------------------------+ #
#######################################################################

Author: LordSmellyPants

Description: Converted version of the BO2 HauntedTwisted7

Version: 3

SettingsMode: WriteWithoutComments


#######################################################################
# +-----------------------------------------------------------------+ #
# |                          Main settings                          | #
# +-----------------------------------------------------------------+ #
#######################################################################

Tree: true

Frequency: 1

Rarity: 20.0

RotateRandomly: true

SpawnHeight: highestSolidBlock

SpawnHeightOffset: 0

SpawnHeightVariance: 0

##############################
# Height Limits for the BO3. #
##############################

MinHeight: 0

MaxHeight: 30

######################
# Extrusion settings #
######################

ExtrudeMode: None

ExtrudeThroughBlocks: AIR

MaxBranchDepth: 10

ExcludedBiomes: All


#######################################################################
# +-----------------------------------------------------------------+ #
# |                      Source block settings                      | #
# +-----------------------------------------------------------------+ #
#######################################################################

SourceBlocks: AIR

MaxPercentageOutsideSourceBlock: 20

OutsideSourceBlock: dontPlace

DoReplaceBlocks: true

IsOTGPlus: false


#######################################################################
# +-----------------------------------------------------------------+ #
# |                              Blocks                             | #
# +-----------------------------------------------------------------+ #
#######################################################################

Block(-3,-1,3,LOG_2:13)
Block(-10,12,9,LOG_2:13)
Block(-10,11,9,LOG_2:13)
Block(-10,10,9,LOG_2:13)
Block(-5,-3,9,LOG_2:13)
Block(-2,13,-3,LOG_2:13)
Block(-5,-2,9,LOG_2:13)
Block(-2,12,-3,LOG_2:13)
Block(-5,-1,9,LOG_2:13)
Block(-2,11,-3,LOG_2:13)
Block(-2,10,-3,LOG_2:13)
Block(-8,17,6,LOG_2:13)
Block(-8,16,6,LOG_2:13)
Block(-8,18,6,LOG_2:13)
Block(-8,15,6,LOG_2:13)
Block(-1,-5,8,LOG_2:13)
Block(-1,-6,8,LOG_2:13)
Block(-1,-1,8,LOG_2:13)
Block(-1,-2,8,LOG_2:13)
Block(-1,-3,8,LOG_2:13)
Block(-1,-4,8,LOG_2:13)
Block(-9,8,6,LOG_2:13)
Block(-9,7,6,LOG_2:13)
Block(-4,3,1,LOG_2:13)
Block(-4,2,1,LOG_2:13)
Block(-4,1,1,LOG_2:13)
Block(-4,6,1,LOG_2:13)
Block(-4,5,1,LOG_2:13)
Block(-4,4,1,LOG_2:13)
Block(-9,10,8,LOG_2:13)
Block(-9,13,8,LOG_2:13)
Block(-9,14,8,LOG_2:13)
Block(-9,11,8,LOG_2:13)
Block(-9,12,8,LOG_2:13)
Block(-3,4,3,LOG_2:13)
Block(-9,17,8,LEAVES_2:1)
Block(-3,3,3,LOG_2:13)
Block(-9,15,8,LOG_2:13)
Block(-3,5,3,LOG_2:13)
Block(-9,16,8,LOG_2:13)
Block(-3,0,3,LOG_2:13)
Block(-3,2,3,LOG_2:13)
Block(-3,1,3,LOG_2:13)
Block(-7,9,-2,LEAVES_2:5)
Block(-1,0,7,LOG_2:13)
Block(-6,14,0,LOG_2:13)
Block(-6,15,0,LOG_2:13)
Block(-1,2,7,LOG_2:13)
Block(-6,16,0,LOG_2:13)
Block(-1,1,7,LOG_2:13)
Block(-6,17,0,LOG_2:13)
Block(-2,4,5,LOG_2:13)
Block(-2,3,5,LOG_2:13)
Block(-2,2,5,LOG_2:13)
Block(-2,1,5,LOG_2:13)
Block(-2,0,5,LOG_2:13)
Block(-3,3,-1,LOG_2:13)
Block(-3,4,-1,LOG_2:13)
Block(-1,0,10,LOG_2:13)
Block(-3,5,-1,LOG_2:13)
Block(-1,1,10,LOG_2:13)
Block(-3,6,-1,LOG_2:13)
Block(-7,17,2,LOG_2:13)
Block(-3,7,-1,LOG_2:13)
Block(-7,18,2,LOG_2:13)
Block(-3,8,-1,LOG_2:13)
Block(-7,15,2,LEAVES_2:5)
Block(-3,9,-1,LOG_2:13)
Block(-7,16,2,LOG_2:13)
Block(0,5,0,LOG_2:13)
Block(0,4,0,LOG_2:13)
Block(0,6,0,LOG_2:13)
Block(-6,9,-4,LOG_2:13)
Block(-6,8,-4,LOG_2:13)
Block(2,-3,10,LOG_2:13)
Block(-8,18,4,LOG_2:13)
Block(2,-2,10,LOG_2:13)
Block(2,-5,10,LOG_2:13)
Block(2,-4,10,LOG_2:13)
Block(-4,8,-1,LOG_2:13)
Block(-4,7,-1,LOG_2:13)
Block(-5,14,-4,LOG_2:13)
Block(-4,9,-1,LOG_2:13)
Block(-5,15,-4,LOG_2:13)
Block(-4,4,-1,LOG_2:13)
Block(-5,12,-4,LOG_2:13)
Block(-4,3,-1,LOG_2:13)
Block(-5,13,-4,LOG_2:13)
Block(-4,6,-1,LOG_2:13)
Block(-5,10,-4,LOG_2:13)
Block(-4,5,-1,LOG_2:13)
Block(-5,11,-4,LOG_2:13)
Block(-4,2,-1,LEAVES_2:5)
Block(-5,4,1,LOG_2:13)
Block(-5,3,1,LOG_2:13)
Block(-9,7,4,LOG_2:13)
Block(-5,5,1,LOG_2:13)
Block(-3,-4,5,LOG_2:13)
Block(-3,-5,5,LOG_2:13)
Block(-3,-1,5,LOG_2:13)
Block(-3,-2,5,LOG_2:13)
Block(-3,-3,5,LOG_2:13)
Block(-4,1,3,LOG_2:13)
Block(-4,0,3,LOG_2:13)
Block(-4,5,3,LEAVES_2:5)
Block(-4,4,3,LOG_2:13)
Block(-4,3,3,LOG_2:13)
Block(-4,2,3,LOG_2:13)
Block(-4,-2,5,LOG_2:13)
Block(-3,2,5,LOG_2:13)
Block(-4,-1,5,LOG_2:13)
Block(-3,1,5,LOG_2:13)
Block(-3,4,5,LOG_2:13)
Block(-3,3,5,LOG_2:13)
Block(-3,0,5,LOG_2:13)
Block(-2,-1,10,LOG_2:13)
Block(-2,-2,10,LOG_2:13)
Block(-1,0,9,LOG_2:13)
Block(-2,-3,10,LOG_2:13)
Block(-2,-4,10,LOG_2:13)
Block(-1,1,9,LOG_2:13)
Block(-2,3,7,LOG_2:13)
Block(-2,2,7,LOG_2:13)
Block(-2,1,7,LOG_2:13)
Block(-2,0,7,LOG_2:13)
Block(-1,0,12,LOG_2:13)
Block(-4,10,-4,LOG_2:13)
Block(0,7,-4,LEAVES_2:13)
Block(-2,9,-3,LOG_2:13)
Block(-2,8,-3,LOG_2:13)
Block(-2,7,-3,LOG_2:13)
Block(-7,14,-1,LOG_2:13)
Block(-7,13,-1,LOG_2:13)
Block(-7,16,-1,LOG_2:13)
Block(-7,15,-1,LOG_2:13)
Block(-2,6,-3,LOG_2:13)
Block(-7,17,-1,LOG_2:13)
Block(-4,6,-3,LOG_2:13)
Block(-4,5,-3,LOG_2:13)
Block(-4,8,-3,LOG_2:13)
Block(-4,7,-3,LOG_2:13)
Block(-2,-1,3,LOG_2:13)
Block(-4,9,-3,LOG_2:13)
Block(0,-2,11,LOG_2:13)
Block(-5,2,3,LOG_2:13)
Block(0,-1,11,LOG_2:13)
Block(0,-4,11,LOG_2:13)
Block(-5,4,3,LEAVES_2:5)
Block(0,-3,11,LOG_2:13)
Block(-5,3,3,LOG_2:13)
Block(1,0,9,LOG_2:13)
Block(-4,3,5,LOG_2:13)
Block(-4,2,5,LOG_2:13)
Block(-10,15,7,LOG_2:13)
Block(-4,1,5,LOG_2:13)
Block(-4,0,5,LOG_2:13)
Block(1,-2,6,LOG_2:13)
Block(1,-3,6,LOG_2:13)
Block(1,-1,6,LOG_2:13)
Block(1,-6,6,LOG_2:13)
Block(-3,0,7,LOG_2:13)
Block(1,-4,6,LOG_2:13)
Block(-3,2,7,LOG_2:13)
Block(1,-5,6,LOG_2:13)
Block(-3,1,7,LOG_2:13)
Block(-5,13,-2,LOG_2:13)
Block(-5,12,-2,LOG_2:13)
Block(-5,15,-2,LOG_2:13)
Block(-5,14,-2,LOG_2:13)
Block(-5,11,-2,LOG_2:13)
Block(-5,10,-2,LOG_2:13)
Block(-2,1,9,LOG_2:13)
Block(-2,0,9,LOG_2:13)
Block(-5,16,-2,LOG_2:13)
Block(-3,-1,7,LOG_2:13)
Block(-3,-3,7,LOG_2:13)
Block(-3,-2,7,LOG_2:13)
Block(-3,-4,7,LOG_2:13)
Block(-7,16,4,LOG_2:13)
Block(-2,4,-1,LOG_2:13)
Block(-2,3,-1,LOG_2:13)
Block(-2,8,-1,LOG_2:13)
Block(-2,7,-1,LOG_2:13)
Block(-2,6,-1,LOG_2:13)
Block(-2,5,-1,LOG_2:13)
Block(-6,17,-1,LOG_2:13)
Block(-6,16,-1,LOG_2:13)
Block(-6,15,-1,LOG_2:13)
Block(-6,14,-1,LOG_2:13)
Block(-5,-6,7,LOG_2:13)
Block(-4,8,-5,LOG_2:13)
Block(-6,13,-1,LOG_2:13)
Block(-4,7,-5,LOG_2:13)
Block(-6,12,-1,LOG_2:13)
Block(-5,-4,7,LOG_2:13)
Block(-6,11,-1,LOG_2:13)
Block(-5,-5,7,LOG_2:13)
Block(-4,9,-5,LOG_2:13)
Block(-7,18,4,LOG_2:13)
Block(-7,17,4,LOG_2:13)
Block(-4,15,-2,LOG_2:13)
Block(-4,14,-2,LOG_2:13)
Block(-4,13,-2,LOG_2:13)
Block(-5,0,5,LOG_2:13)
Block(-4,12,-2,LOG_2:13)
Block(-4,11,-2,LOG_2:13)
Block(-5,2,5,LEAVES_2:13)
Block(-4,10,-2,LOG_2:13)
Block(-9,17,1,LOG_2:13)
Block(-5,1,5,LOG_2:13)
Block(-4,1,7,LOG_2:13)
Block(-4,0,7,LOG_2:13)
Block(-5,-2,7,LOG_2:13)
Block(-5,-3,7,LOG_2:13)
Block(-5,-1,7,LOG_2:13)
Block(-3,1,9,LOG_2:13)
Block(-3,0,9,LOG_2:13)
Block(-3,0,11,LOG_2:13)
Block(-5,17,5,LEAVES_2:13)
Block(-8,15,8,LOG_2:13)
Block(-8,14,8,LOG_2:13)
Block(-8,17,8,LOG_2:13)
Block(-8,16,8,LOG_2:13)
Block(0,-1,13,LOG_2:13)
Block(0,-2,13,LOG_2:13)
Block(-8,13,8,LOG_2:13)
Block(0,-5,13,LOG_2:13)
Block(0,-6,13,LOG_2:13)
Block(0,-3,13,LOG_2:13)
Block(0,-4,13,LOG_2:13)
Block(-7,14,8,LOG_2:13)
Block(-7,13,8,LOG_2:13)
Block(-7,16,8,LOG_2:13)
Block(-6,17,5,LOG_2:13)
Block(-7,15,8,LOG_2:13)
Block(0,1,6,LOG_2:13)
Block(0,0,6,LOG_2:13)
Block(1,3,4,LEAVES_2:13)
Block(-8,16,0,LOG_2:13)
Block(-5,17,2,LOG_2:13)
Block(-8,17,0,LOG_2:13)
Block(-5,5,-2,LOG_2:13)
Block(-5,6,-2,LOG_2:13)
Block(-5,9,-2,LOG_2:13)
Block(-5,7,-2,LOG_2:13)
Block(-5,8,-2,LOG_2:13)
Block(-6,1,5,LEAVES_2:13)
Block(-1,5,0,LOG_2:13)
Block(-1,4,0,LOG_2:13)
Block(-1,7,0,LOG_2:13)
Block(-1,6,0,LOG_2:13)
Block(1,-2,12,LOG_2:13)
Block(1,-3,12,LOG_2:13)
Block(1,-4,12,LOG_2:13)
Block(-3,0,10,LOG_2:13)
Block(-5,0,7,LOG_2:13)
Block(-1,3,0,LOG_2:13)
Block(-4,0,9,LOG_2:13)
Block(-3,10,-3,LOG_2:13)
Block(-1,6,-2,LOG_2:13)
Block(-2,-4,5,LOG_2:13)
Block(-2,-3,5,LOG_2:13)
Block(-2,-2,5,LOG_2:13)
Block(-2,-1,5,LOG_2:13)
Block(-1,9,-2,LOG_2:13)
Block(-1,8,-2,LOG_2:13)
Block(-1,7,-2,LOG_2:13)
Block(1,2,4,LOG_2:13)
Block(0,3,6,LEAVES_2:5)
Block(-3,12,-3,LOG_2:13)
Block(1,1,4,LOG_2:13)
Block(0,2,6,LOG_2:13)
Block(-3,11,-3,LOG_2:13)
Block(-3,14,-3,LOG_2:13)
Block(-3,13,-3,LOG_2:13)
Block(-9,17,3,LOG_2:13)
Block(-3,-6,10,LOG_2:13)
Block(1,1,6,LOG_2:13)
Block(-3,-1,10,LOG_2:13)
Block(-3,-2,10,LOG_2:13)
Block(-3,-3,10,LOG_2:13)
Block(-3,-4,10,LOG_2:13)
Block(-3,-5,10,LOG_2:13)
Block(-1,3,2,LOG_2:13)
Block(-1,2,2,LOG_2:13)
Block(-1,5,2,LOG_2:13)
Block(-1,4,2,LOG_2:13)
Block(-2,8,0,LOG_2:13)
Block(-2,7,0,LOG_2:13)
Block(-2,6,0,LOG_2:13)
Block(-2,5,0,LOG_2:13)
Block(-2,4,0,LOG_2:13)
Block(-2,3,0,LOG_2:13)
Block(1,-3,9,LOG_2:13)
Block(-2,-1,7,LOG_2:13)
Block(-2,2,0,LOG_2:13)
Block(1,-4,9,LOG_2:13)
Block(-2,-2,7,LOG_2:13)
Block(1,-5,9,LOG_2:13)
Block(-2,-3,7,LOG_2:13)
Block(1,-6,9,LOG_2:13)
Block(-2,-4,7,LOG_2:13)
Block(-2,-5,7,LOG_2:13)
Block(0,-4,6,LOG_2:13)
Block(-2,-6,7,LOG_2:13)
Block(0,-3,6,LOG_2:13)
Block(1,-1,9,LOG_2:13)
Block(1,-2,9,LOG_2:13)
Block(0,-2,6,LOG_2:13)
Block(0,-1,6,LOG_2:13)
Block(-9,17,5,LOG_2:13)
Block(-9,16,5,LOG_2:13)
Block(-1,1,2,LOG_2:13)
Block(-1,0,2,LOG_2:13)
Block(-7,15,6,LOG_2:13)
Block(-7,16,6,LOG_2:13)
Block(-7,17,6,LOG_2:13)
Block(-1,-4,10,LOG_2:13)
Block(-1,-1,10,LOG_2:13)
Block(-1,-2,10,LOG_2:13)
Block(-1,-3,10,LOG_2:13)
Block(0,-5,10,LOG_2:13)
Block(0,-4,10,LOG_2:13)
Block(0,-1,10,LOG_2:13)
Block(0,-3,10,LOG_2:13)
Block(0,-2,10,LOG_2:13)
Block(-6,16,-3,LOG_2:13)
Block(-6,12,-3,LOG_2:13)
Block(-6,13,-3,LOG_2:13)
Block(-6,14,-3,LOG_2:13)
Block(-6,15,-3,LOG_2:13)
Block(-1,8,-4,LEAVES_2:1)
Block(-6,10,-3,LOG_2:13)
Block(-6,11,-3,LOG_2:13)
Block(1,-5,10,LOG_2:13)
Block(1,-4,10,LOG_2:13)
Block(1,-3,10,LOG_2:13)
Block(1,-2,10,LOG_2:13)
Block(1,0,6,LOG_2:13)
Block(0,1,8,LOG_2:13)
Block(1,-1,10,LOG_2:13)
Block(0,0,8,LOG_2:13)
Block(-6,15,7,LOG_2:13)
Block(-3,1,0,LOG_2:13)
Block(0,1,2,LOG_2:13)
Block(0,3,2,LOG_2:13)
Block(-3,11,-5,LOG_2:13)
Block(0,2,2,LOG_2:13)
Block(-2,0,11,LOG_2:13)
Block(0,4,2,LOG_2:13)
Block(-3,10,-5,LOG_2:13)
Block(-3,7,0,LOG_2:13)
Block(-3,6,0,LOG_2:13)
Block(-3,8,0,LOG_2:13)
Block(-3,3,0,LOG_2:13)
Block(-3,2,0,LOG_2:13)
Block(-3,5,0,LOG_2:13)
Block(-3,4,0,LOG_2:13)
Block(-1,1,4,LOG_2:13)
Block(-2,-3,12,LOG_2:13)
Block(-1,0,4,LOG_2:13)
Block(-2,-2,12,LOG_2:13)
Block(-1,3,4,LOG_2:13)
Block(-2,-1,12,LOG_2:13)
Block(-1,2,4,LOG_2:13)
Block(-1,4,4,LOG_2:13)
Block(-4,-6,10,LOG_2:13)
Block(-4,-5,10,LOG_2:13)
Block(-2,6,2,LOG_2:13)
Block(-2,5,2,LOG_2:13)
Block(-2,4,2,LOG_2:13)
Block(-2,3,2,LOG_2:13)
Block(-2,2,2,LOG_2:13)
Block(-2,1,2,LOG_2:13)
Block(-2,0,2,LOG_2:13)
Block(-4,-4,10,LOG_2:13)
Block(-4,-3,10,LOG_2:13)
Block(-4,-4,8,LOG_2:13)
Block(-4,-2,10,LOG_2:13)
Block(-3,13,-5,LEAVES_2:5)
Block(-4,-1,10,LOG_2:13)
Block(-6,17,3,LOG_2:13)
Block(-5,-5,10,LOG_2:13)
Block(-5,-4,10,LOG_2:13)
Block(-6,7,-1,LEAVES_2:13)
Block(-5,-6,10,LOG_2:13)
Block(-5,-3,10,LOG_2:13)
Block(-5,-2,10,LOG_2:13)
Block(-4,11,-5,LOG_2:13)
Block(-4,10,-5,LOG_2:13)
Block(-4,13,-5,LOG_2:13)
Block(-4,12,-5,LOG_2:13)
Block(-4,14,-5,LEAVES_2:13)
Block(-10,7,6,LOG_2:13)
Block(-8,15,4,LOG_2:13)
Block(-8,16,4,LOG_2:13)
Block(-8,17,4,LOG_2:13)
Block(-8,8,7,LOG_2:13)
Block(-1,-2,6,LOG_2:13)
Block(1,6,0,LOG_2:13)
Block(-9,12,10,LOG_2:13)
Block(-1,-1,6,LOG_2:13)
Block(1,5,0,LOG_2:13)
Block(-3,8,-5,LOG_2:13)
Block(-9,10,10,LOG_2:13)
Block(-3,9,-5,LOG_2:13)
Block(-9,11,10,LOG_2:13)
Block(-1,-6,6,LOG_2:13)
Block(-1,-5,6,LOG_2:13)
Block(-1,-4,6,LOG_2:13)
Block(-1,-3,6,LOG_2:13)
Block(-1,-1,12,LOG_2:13)
Block(0,1,4,LOG_2:13)
Block(-9,9,9,LOG_2:13)
Block(0,0,4,LOG_2:13)
Block(0,3,4,LOG_2:13)
Block(0,2,4,LOG_2:13)
Block(-4,4,0,LOG_2:13)
Block(-4,3,0,LOG_2:13)
Block(-4,2,0,LOG_2:13)
Block(-1,-3,12,LOG_2:13)
Block(-1,-2,12,LOG_2:13)
Block(-4,7,0,LOG_2:13)
Block(-4,6,0,LOG_2:13)
Block(-4,5,0,LOG_2:13)
Block(-5,9,-4,LOG_2:13)
Block(-3,5,2,LOG_2:13)
Block(-3,4,2,LOG_2:13)
Block(-3,6,2,LOG_2:13)
Block(-3,1,2,LOG_2:13)
Block(-5,7,-4,LOG_2:13)
Block(-3,0,2,LOG_2:13)
Block(-5,8,-4,LOG_2:13)
Block(-3,3,2,LOG_2:13)
Block(-3,2,2,LOG_2:13)
Block(-1,1,6,LOG_2:13)
Block(-1,0,6,LOG_2:13)
Block(-1,3,6,LOG_2:13)
Block(-1,2,6,LOG_2:13)
Block(-1,4,6,LEAVES_2:5)
Block(-2,4,4,LOG_2:13)
Block(-2,3,4,LOG_2:13)
Block(-2,2,4,LOG_2:13)
Block(-2,1,4,LOG_2:13)
Block(-2,0,4,LOG_2:13)
Block(0,0,10,LOG_2:13)
Block(-1,-3,4,LOG_2:13)
Block(-1,-1,4,LOG_2:13)
Block(-1,-2,4,LOG_2:13)
Block(-4,-2,8,LOG_2:13)
Block(-4,-3,8,LOG_2:13)
Block(-4,-1,8,LOG_2:13)
Block(-5,14,0,LOG_2:13)
Block(-8,18,2,LOG_2:13)
Block(-8,17,2,LOG_2:13)
Block(-8,16,2,LOG_2:13)
Block(-5,17,0,LOG_2:13)
Block(-2,-2,9,LOG_2:13)
Block(-5,16,0,LOG_2:13)
Block(-2,-1,9,LOG_2:13)
Block(-5,15,0,LOG_2:13)
Block(-3,-1,12,LOG_2:13)
Block(-3,-3,12,LOG_2:13)
Block(-3,-2,12,LOG_2:13)
Block(-3,-5,12,LOG_2:13)
Block(-3,-4,12,LOG_2:13)
Block(-3,-6,12,LOG_2:13)
Block(-10,9,8,LOG_2:13)
Block(-2,-4,9,LOG_2:13)
Block(-2,-3,9,LOG_2:13)
Block(-4,-1,12,LOG_2:13)
Block(-2,-5,9,LOG_2:13)
Block(-4,-2,12,LOG_2:13)
Block(-4,-3,12,LOG_2:13)
Block(-3,5,-3,LOG_2:13)
Block(-9,13,7,LOG_2:13)
Block(-3,6,-3,LOG_2:13)
Block(-3,7,-3,LOG_2:13)
Block(1,4,2,LOG_2:13)
Block(-3,8,-3,LOG_2:13)
Block(-9,16,7,LOG_2:13)
Block(0,4,4,LOG_2:13)
Block(-3,9,-3,LOG_2:13)
Block(0,-1,8,LOG_2:13)
Block(-9,14,7,LOG_2:13)
Block(0,-2,8,LOG_2:13)
Block(-9,15,7,LOG_2:13)
Block(-9,7,7,LOG_2:13)
Block(-9,8,7,LOG_2:13)
Block(-4,-1,6,LOG_2:13)
Block(-9,9,7,LOG_2:13)
Block(-4,2,2,LOG_2:13)
Block(-4,1,2,LOG_2:13)
Block(-4,0,2,LOG_2:13)
Block(-4,5,2,LOG_2:13)
Block(-4,4,2,LOG_2:13)
Block(-4,3,2,LOG_2:13)
Block(-4,16,-1,LOG_2:13)
Block(-3,3,4,LOG_2:13)
Block(-4,15,-1,LOG_2:13)
Block(-3,2,4,LOG_2:13)
Block(-4,14,-1,LOG_2:13)
Block(-4,13,-1,LOG_2:13)
Block(-3,4,4,LOG_2:13)
Block(-4,12,-1,LOG_2:13)
Block(-4,11,-1,LOG_2:13)
Block(-4,10,-1,LOG_2:13)
Block(-3,1,4,LOG_2:13)
Block(-3,0,4,LOG_2:13)
Block(-1,1,8,LOG_2:13)
Block(-1,0,8,LOG_2:13)
Block(-2,4,6,LEAVES_2:5)
Block(-2,3,6,LOG_2:13)
Block(-2,2,6,LOG_2:13)
Block(-2,1,6,LOG_2:13)
Block(-2,0,6,LOG_2:13)
Block(-9,11,9,LOG_2:13)
Block(-9,10,9,LOG_2:13)
Block(-1,0,11,LOG_2:13)
Block(-3,5,-2,LOG_2:13)
Block(-1,1,11,LOG_2:13)
Block(-3,6,-2,LOG_2:13)
Block(-9,14,9,LOG_2:13)
Block(-3,7,-2,LOG_2:13)
Block(-9,13,9,LOG_2:13)
Block(-3,8,-2,LOG_2:13)
Block(-9,12,9,LOG_2:13)
Block(-3,9,-2,LOG_2:13)
Block(-2,10,-4,LOG_2:13)
Block(-2,11,-4,LOG_2:13)
Block(0,-3,14,LOG_2:13)
Block(0,-2,14,LOG_2:13)
Block(0,-4,14,LOG_2:13)
Block(-3,-2,4,LOG_2:13)
Block(-3,-1,4,LOG_2:13)
Block(-1,-1,9,LOG_2:13)
Block(-3,-3,4,LOG_2:13)
Block(-5,-2,8,LOG_2:13)
Block(-5,-1,8,LOG_2:13)
Block(-4,-3,6,LOG_2:13)
Block(-4,-2,6,LOG_2:13)
Block(-5,3,0,LEAVES_2:5)
Block(-4,-4,6,LOG_2:13)
Block(-5,5,0,LOG_2:13)
Block(-4,-6,6,LOG_2:13)
Block(-5,4,0,LOG_2:13)
Block(-5,7,0,LEAVES_2:5)
Block(-5,6,0,LOG_2:13)
Block(-2,-3,11,LOG_2:13)
Block(-2,-2,11,LOG_2:13)
Block(-2,-1,11,LOG_2:13)
Block(-9,7,5,LOG_2:13)
Block(-6,16,1,LOG_2:13)
Block(-6,15,1,WEB)
Block(-6,18,1,LOG_2:13)
Block(-6,17,1,LOG_2:13)
Block(-2,-4,11,LOG_2:13)
Block(-4,0,4,LOG_2:13)
Block(-4,4,4,LOG_2:13)
Block(-4,3,4,LOG_2:13)
Block(-4,2,4,LOG_2:13)
Block(-4,1,4,LOG_2:13)
Block(-7,18,1,LOG_2:13)
Block(-7,15,1,LOG_2:13)
Block(-3,4,6,LEAVES_2:5)
Block(-7,17,1,LOG_2:13)
Block(-7,16,1,LOG_2:13)
Block(-3,1,6,LOG_2:13)
Block(-3,0,6,LOG_2:13)
Block(-3,3,6,LOG_2:13)
Block(-3,2,6,LOG_2:13)
Block(-4,10,-3,LOG_2:13)
Block(-4,11,-3,LOG_2:13)
Block(-4,12,-3,LOG_2:13)
Block(-4,13,-3,LOG_2:13)
Block(-4,14,-3,LOG_2:13)
Block(-4,15,-3,LOG_2:13)
Block(-2,2,8,LOG_2:13)
Block(-2,1,8,LOG_2:13)
Block(-2,0,8,LOG_2:13)
Block(-7,12,-2,LOG_2:13)
Block(-7,13,-2,LOG_2:13)
Block(-7,11,-2,LOG_2:13)
Block(-4,-1,4,LOG_2:13)
Block(-4,-2,4,LOG_2:13)
Block(-7,14,-2,LOG_2:13)
Block(-6,9,-3,LOG_2:13)
Block(-6,8,-3,LOG_2:13)
Block(-6,7,-3,LOG_2:13)
Block(-8,15,5,LOG_2:13)
Block(-8,16,5,LOG_2:13)
Block(-8,17,5,LOG_2:13)
Block(-8,18,5,LOG_2:13)
Block(-1,-3,7,LOG_2:13)
Block(-1,-2,7,LOG_2:13)
Block(-1,-1,7,LOG_2:13)
Block(-1,-6,7,LOG_2:13)
Block(-1,-5,7,LOG_2:13)
Block(-1,-4,7,LOG_2:13)
Block(-6,6,0,LEAVES_2:5)
Block(-5,3,2,LOG_2:13)
Block(-5,5,2,LEAVES_2:5)
Block(-5,4,2,LOG_2:13)
Block(-5,15,-3,LOG_2:13)
Block(-5,13,-3,LOG_2:13)
Block(-5,14,-3,LOG_2:13)
Block(-5,11,-3,LOG_2:13)
Block(-6,15,-2,LOG_2:13)
Block(-5,12,-3,LOG_2:13)
Block(-6,16,-2,LOG_2:13)
Block(1,0,8,LOG_2:13)
Block(-6,17,-2,LOG_2:13)
Block(-5,10,-3,LOG_2:13)
Block(-6,11,-2,LOG_2:13)
Block(-6,12,-2,LOG_2:13)
Block(-6,13,-2,LOG_2:13)
Block(-6,14,-2,LOG_2:13)
Block(-4,2,6,LOG_2:13)
Block(-4,1,6,LOG_2:13)
Block(-5,-3,6,LOG_2:13)
Block(-4,0,6,LOG_2:13)
Block(-6,10,-2,LOG_2:13)
Block(-3,1,8,LOG_2:13)
Block(-3,0,8,LOG_2:13)
Block(-3,-5,6,LOG_2:13)
Block(-3,-1,6,LOG_2:13)
Block(-3,-2,6,LOG_2:13)
Block(-3,-3,6,LOG_2:13)
Block(-3,-4,6,LOG_2:13)
Block(-5,-1,6,LOG_2:13)
Block(-5,-2,6,LOG_2:13)
Block(-1,10,-2,LOG_2:13)
Block(-2,-1,2,LOG_2:13)
Block(-2,7,-4,LOG_2:13)
Block(-2,8,-4,LOG_2:13)
Block(-8,15,9,LOG_2:13)
Block(-2,9,-4,LOG_2:13)
Block(-8,16,9,LOG_2:13)
Block(-8,13,9,LOG_2:13)
Block(-8,14,9,LOG_2:13)
Block(-8,11,9,LOG_2:13)
Block(-8,12,9,LOG_2:13)
Block(-8,10,9,LOG_2:13)
Block(-6,4,2,LEAVES_2:5)
Block(-4,7,-2,LOG_2:13)
Block(-4,6,-2,LOG_2:13)
Block(-4,9,-2,LOG_2:13)
Block(-4,8,-2,LOG_2:13)
Block(-4,5,-2,LOG_2:13)
Block(-4,4,-2,LOG_2:13)
Block(-7,17,5,LOG_2:13)
Block(-7,16,5,LOG_2:13)
Block(-5,4,4,LEAVES_2:1)
Block(-5,1,4,LOG_2:13)
Block(-5,0,4,LOG_2:13)
Block(-5,3,4,LOG_2:13)
Block(-5,2,4,LOG_2:13)
Block(-4,1,8,LOG_2:13)
Block(-2,-6,4,LOG_2:13)
Block(-2,-5,4,LOG_2:13)
Block(-2,-4,4,LOG_2:13)
Block(-2,-3,4,LOG_2:13)
Block(-2,-2,4,LOG_2:13)
Block(-2,-1,4,LOG_2:13)
Block(-4,0,8,LOG_2:13)
Block(-2,10,-2,LOG_2:13)
Block(-5,18,6,LEAVES_2:1)
Block(-8,17,7,LOG_2:13)
Block(-8,14,7,LOG_2:13)
Block(-8,16,7,LOG_2:13)
Block(-8,15,7,LOG_2:13)
Block(-1,-6,9,LOG_2:13)
Block(0,-1,12,LOG_2:13)
Block(0,-4,12,LOG_2:13)
Block(-1,-2,9,LOG_2:13)
Block(-1,-3,9,LOG_2:13)
Block(-1,-4,9,LOG_2:13)
Block(0,-2,12,LOG_2:13)
Block(-1,-5,9,LOG_2:13)
Block(0,-3,12,LOG_2:13)
Block(-9,17,2,LOG_2:13)
Block(-10,11,8,LEAVES_2:5)
Block(-10,14,8,LOG_2:13)
Block(-10,13,8,LOG_2:13)
Block(-3,0,12,LOG_2:13)
Block(-10,16,8,LEAVES_2:1)
Block(-4,16,0,LOG_2:13)
Block(-4,15,0,LOG_2:13)
Block(-4,10,0,LEAVES_2:13)
Block(-3,10,-1,LOG_2:13)
Block(-3,15,-1,LOG_2:13)
Block(-5,14,-1,LOG_2:13)
Block(-5,16,-1,LOG_2:13)
Block(-5,15,-1,LOG_2:13)
Block(-5,17,-1,LOG_2:13)
Block(-2,9,-2,LOG_2:13)
Block(-2,8,-2,LOG_2:13)
Block(-7,18,3,LOG_2:13)
Block(-7,16,3,LOG_2:13)
Block(-7,17,3,LOG_2:13)
Block(-3,-2,8,LOG_2:13)
Block(-3,-1,8,LOG_2:13)
Block(-2,7,-2,LOG_2:13)
Block(-2,6,-2,LOG_2:13)
Block(-2,5,-2,LOG_2:13)
Block(-2,4,-2,LOG_2:13)
Block(-6,2,4,LEAVES_2:5)
Block(-4,7,-4,LOG_2:13)
Block(-3,-4,8,LOG_2:13)
Block(-3,-3,8,LOG_2:13)
Block(-4,9,-4,LOG_2:13)
Block(-4,8,-4,LOG_2:13)
Block(-2,11,-2,LOG_2:13)
Block(1,-3,7,LOG_2:13)
Block(1,-2,7,LOG_2:13)
Block(1,-1,7,LOG_2:13)
Block(-5,1,6,LOG_2:13)
Block(-5,0,6,LOG_2:13)
Block(1,-1,8,LOG_2:13)
Block(0,-2,5,LOG_2:13)
Block(1,-2,8,LOG_2:13)
Block(-3,11,-2,LOG_2:13)
Block(-3,10,-2,LOG_2:13)
Block(0,-1,5,LOG_2:13)
Block(-3,13,-2,LOG_2:13)
Block(-3,12,-2,LOG_2:13)
Block(-3,15,-2,LOG_2:13)
Block(-3,14,-2,LOG_2:13)
Block(-1,-5,11,LOG_2:13)
Block(-1,-6,11,LOG_2:13)
Block(-1,-1,11,LOG_2:13)
Block(-1,-2,11,LOG_2:13)
Block(-1,8,-3,LOG_2:13)
Block(-1,-3,11,LOG_2:13)
Block(-1,7,-3,LOG_2:13)
Block(-1,-4,11,LOG_2:13)
Block(-3,-2,9,LOG_2:13)
Block(1,3,3,LOG_2:13)
Block(-3,-3,9,LOG_2:13)
Block(0,1,7,LOG_2:13)
Block(1,2,3,LOG_2:13)
Block(-3,-1,9,LOG_2:13)
Block(0,7,-1,LOG_2:13)
Block(0,6,-1,LOG_2:13)
Block(0,0,5,LOG_2:13)
Block(-3,-4,9,LOG_2:13)
Block(0,2,5,LOG_2:13)
Block(0,1,5,LOG_2:13)
Block(-6,10,-4,LOG_2:13)
Block(-6,11,-4,LOG_2:13)
Block(-1,-1,3,LOG_2:13)
Block(-5,8,-3,LOG_2:13)
Block(-5,9,-3,LOG_2:13)
Block(-6,16,6,LOG_2:13)
Block(-5,6,-3,LOG_2:13)
Block(-5,7,-3,LOG_2:13)
Block(-5,16,1,LOG_2:13)
Block(-8,17,1,LOG_2:13)
Block(-5,17,1,LOG_2:13)
Block(-8,18,1,LOG_2:13)
Block(-8,16,1,LOG_2:13)
Block(-5,15,1,LOG_2:13)
Block(-5,0,8,LOG_2:13)
Block(1,-1,11,LOG_2:13)
Block(1,-2,11,LOG_2:13)
Block(1,-3,11,LOG_2:13)
Block(1,-4,11,LOG_2:13)
Block(1,-5,11,LOG_2:13)
Block(1,-6,11,LOG_2:13)
Block(-5,-1,5,LOG_2:13)
Block(-7,14,7,LOG_2:13)
Block(-7,15,7,LOG_2:13)
Block(-3,10,-4,LOG_2:13)
Block(-7,16,7,LOG_2:13)
Block(-3,11,-4,LOG_2:13)
Block(-7,17,7,LOG_2:13)
Block(0,0,9,LOG_2:13)
Block(1,1,5,LOG_2:13)
Block(1,0,5,LOG_2:13)
Block(0,1,9,LOG_2:13)
Block(0,0,7,LOG_2:13)
Block(1,0,7,LOG_2:13)
Block(-2,-4,6,LOG_2:13)
Block(-2,-3,6,LOG_2:13)
Block(-2,-2,6,LOG_2:13)
Block(-2,-1,6,LOG_2:13)
Block(-5,6,-1,LOG_2:13)
Block(-5,7,-1,LOG_2:13)
Block(-3,12,-4,LOG_2:13)
Block(-3,13,-4,LOG_2:13)
Block(-9,16,4,LOG_2:13)
Block(-9,17,4,LOG_2:13)
Block(-5,8,-1,BROWN_MUSHROOM)
Block(-1,4,1,LOG_2:13)
Block(-1,3,1,LOG_2:13)
Block(-1,6,1,LOG_2:13)
Block(-1,5,1,LOG_2:13)
Block(-10,16,6,LOG_2:13)
Block(-1,2,1,LOG_2:13)
Block(-1,1,1,LOG_2:13)
Block(-4,11,-4,LOG_2:13)
Block(-4,12,-4,LOG_2:13)
Block(-4,13,-4,LOG_2:13)
Block(-4,14,-4,LOG_2:13)
Block(-6,9,-2,LOG_2:13)
Block(-6,8,-2,LOG_2:13)
Block(-6,7,-2,LOG_2:13)
Block(-2,-2,8,LOG_2:13)
Block(-2,-3,8,LOG_2:13)
Block(-2,-4,8,LOG_2:13)
Block(-2,-5,8,LOG_2:13)
Block(-8,16,3,LOG_2:13)
Block(-1,-1,5,LOG_2:13)
Block(-9,16,6,LOG_2:13)
Block(-9,15,6,LOG_2:13)
Block(-1,-4,5,LOG_2:13)
Block(-9,17,6,LOG_2:13)
Block(-1,-2,5,LOG_2:13)
Block(-1,-3,5,LOG_2:13)
Block(-6,17,2,LOG_2:13)
Block(-6,16,2,LOG_2:13)
Block(-6,18,2,LOG_2:13)
Block(-8,18,3,LOG_2:13)
Block(-8,17,3,LOG_2:13)
Block(-7,18,0,LOG_2:13)
Block(-7,17,0,LOG_2:13)
Block(-7,16,0,LOG_2:13)
Block(-7,15,0,LOG_2:13)
Block(-4,0,11,LOG_2:13)
Block(0,4,1,LOG_2:13)
Block(0,3,1,LOG_2:13)
Block(0,6,1,LOG_2:13)
Block(0,5,1,LOG_2:13)
Block(0,-6,7,LOG_2:13)
Block(0,-4,7,LOG_2:13)
Block(0,-5,7,LOG_2:13)
Block(0,-2,7,LOG_2:13)
Block(-4,-4,11,LOG_2:13)
Block(0,-3,7,LOG_2:13)
Block(-4,-6,9,LOG_2:13)
Block(-4,-3,11,LOG_2:13)
Block(-4,-5,9,LOG_2:13)
Block(-4,-2,11,LOG_2:13)
Block(0,-1,7,LOG_2:13)
Block(-4,-1,11,LOG_2:13)
Block(-1,2,3,LOG_2:13)
Block(-1,1,3,LOG_2:13)
Block(-1,4,3,LOG_2:13)
Block(-1,3,3,LOG_2:13)
Block(-4,-4,9,LOG_2:13)
Block(-4,-3,9,LOG_2:13)
Block(-1,5,3,LEAVES_2:13)
Block(-4,-2,9,LOG_2:13)
Block(-4,-1,9,LOG_2:13)
Block(-2,7,1,LOG_2:13)
Block(-2,6,1,LOG_2:13)
Block(-2,5,1,LOG_2:13)
Block(-2,4,1,LOG_2:13)
Block(-2,3,1,LOG_2:13)
Block(-2,-1,8,LOG_2:13)
Block(-2,2,1,LOG_2:13)
Block(-2,1,1,LOG_2:13)
Block(-2,0,1,LOG_2:13)
Block(-3,-2,11,LOG_2:13)
Block(-3,-1,11,LOG_2:13)
Block(-3,-4,11,LOG_2:13)
Block(-3,-3,11,LOG_2:13)
Block(-1,0,3,LOG_2:13)
Block(0,-4,9,LOG_2:13)
Block(-4,-3,7,LOG_2:13)
Block(0,-3,9,LOG_2:13)
Block(-4,-4,7,LOG_2:13)
Block(0,-2,9,LOG_2:13)
Block(0,-1,9,LOG_2:13)
Block(-1,7,-1,LOG_2:13)
Block(-1,6,-1,LOG_2:13)
Block(-1,5,-1,LOG_2:13)
Block(-1,4,-1,LOG_2:13)
Block(-4,-1,7,LOG_2:13)
Block(-4,-2,7,LOG_2:13)
Block(-10,8,7,LOG_2:13)
Block(-10,7,7,LOG_2:13)
Block(-5,-2,11,LOG_2:13)
Block(-8,9,8,LOG_2:13)
Block(-5,-3,11,LOG_2:13)
Block(-3,6,-4,LOG_2:13)
Block(0,4,5,LEAVES_2:13)
Block(1,5,1,LOG_2:13)
Block(-3,7,-4,LOG_2:13)
Block(0,3,5,LOG_2:13)
Block(1,4,1,LOG_2:13)
Block(-3,8,-4,LOG_2:13)
Block(1,3,1,LOG_2:13)
Block(-3,9,-4,LOG_2:13)
Block(-3,-2,13,LOG_2:13)
Block(-3,0,1,LOG_2:13)
Block(-2,-2,13,LOG_2:13)
Block(0,2,3,LOG_2:13)
Block(-2,-3,13,LOG_2:13)
Block(0,1,3,LOG_2:13)
Block(-2,-4,13,LOG_2:13)
Block(-2,1,10,LOG_2:13)
Block(0,4,3,LOG_2:13)
Block(-9,8,8,LOG_2:13)
Block(-2,-5,13,LOG_2:13)
Block(-2,0,10,LOG_2:13)
Block(0,3,3,LOG_2:13)
Block(-9,9,8,LOG_2:13)
Block(0,0,11,LOG_2:13)
Block(-3,6,1,LOG_2:13)
Block(-3,5,1,LOG_2:13)
Block(-3,7,1,LOG_2:13)
Block(-3,2,1,LOG_2:13)
Block(-3,1,1,LOG_2:13)
Block(-3,4,1,LOG_2:13)
Block(-3,3,1,LOG_2:13)
Block(-1,0,5,LOG_2:13)
Block(-7,14,9,LOG_2:13)
Block(-1,-2,13,LOG_2:13)
Block(-1,2,5,LOG_2:13)
Block(-1,-1,13,LOG_2:13)
Block(-1,1,5,LOG_2:13)
Block(-6,17,4,LOG_2:13)
Block(-1,3,5,LOG_2:13)
Block(-2,5,3,LOG_2:13)
Block(-2,4,3,LOG_2:13)
Block(-1,-4,13,LOG_2:13)
Block(-2,3,3,LOG_2:13)
Block(-1,-3,13,LOG_2:13)
Block(-2,2,3,LOG_2:13)
Block(-2,1,3,LOG_2:13)
Block(-2,0,3,LOG_2:13)

#######################################################################
# +-----------------------------------------------------------------+ #
# |                            BO3 checks                           | #
# +-----------------------------------------------------------------+ #
#######################################################################

BlockCheck(-3,-1,3,GRASS:0,DIRT:0)
BlockCheck(-1,-1,7,GRASS:0,DIRT:0)
BlockCheck(-2,-1,5,GRASS:0,DIRT:0)
BlockCheck(-1,-1,10,GRASS:0,DIRT:0)
BlockCheck(-4,-1,3,GRASS:0,DIRT:0)
BlockCheck(-2,-1,7,GRASS:0,DIRT:0)
BlockCheck(0,-1,11,GRASS:0,DIRT:0)

#######################################################################
# +-----------------------------------------------------------------+ #
# |                             Branches                            | #
# +-----------------------------------------------------------------+ #
#######################################################################


#######################################################################
# +-----------------------------------------------------------------+ #
# |                             Entities                            | #
# +-----------------------------------------------------------------+ #
#######################################################################


#######################################################################
# +-----------------------------------------------------------------+ #
# |                            Particles                            | #
# +-----------------------------------------------------------------+ #
#######################################################################


#######################################################################
# +-----------------------------------------------------------------+ #
# |                             Spawners                            | #
# +-----------------------------------------------------------------+ #
#######################################################################


#######################################################################
# +-----------------------------------------------------------------+ #
# |                             ModData                             | #
# +-----------------------------------------------------------------+ #
#######################################################################

