
#######################################################################
# +-----------------------------------------------------------------+ #
# |                            BO3 object                           | #
# +-----------------------------------------------------------------+ #
#######################################################################

Author: LordSmellyPants

Description: Converted version of the BO2 HauntedTwisted6

Version: 3

SettingsMode: WriteWithoutComments


#######################################################################
# +-----------------------------------------------------------------+ #
# |                          Main settings                          | #
# +-----------------------------------------------------------------+ #
#######################################################################

Tree: true

Frequency: 1

Rarity: 20.0

RotateRandomly: true

SpawnHeight: highestSolidBlock

SpawnHeightOffset: 0

SpawnHeightVariance: 0

##############################
# Height Limits for the BO3. #
##############################

MinHeight: 0

MaxHeight: 30

######################
# Extrusion settings #
######################

ExtrudeMode: None

ExtrudeThroughBlocks: AIR

MaxBranchDepth: 10

ExcludedBiomes: All


#######################################################################
# +-----------------------------------------------------------------+ #
# |                      Source block settings                      | #
# +-----------------------------------------------------------------+ #
#######################################################################

SourceBlocks: AIR

MaxPercentageOutsideSourceBlock: 20

OutsideSourceBlock: dontPlace

DoReplaceBlocks: true

IsOTGPlus: false


#######################################################################
# +-----------------------------------------------------------------+ #
# |                              Blocks                             | #
# +-----------------------------------------------------------------+ #
#######################################################################

Block(-2,-3,0,LOG_2:13)
Block(-2,-2,0,LOG_2:13)
Block(-2,-4,0,LOG_2:13)
Block(-2,-1,0,LOG_2:13)
Block(-1,16,1,LOG_2:13)
Block(-1,17,1,LOG_2:13)
Block(-1,18,1,LOG_2:13)
Block(-1,14,1,LEAVES_2:9)
Block(-1,15,1,LOG_2:13)
Block(-1,5,0,LOG_2:13)
Block(-1,4,0,LOG_2:13)
Block(-1,7,0,LOG_2:13)
Block(-1,6,0,LOG_2:13)
Block(-1,9,0,LOG_2:13)
Block(-1,8,0,LOG_2:13)
Block(-1,8,-3,LEAVES_2:1)
Block(2,0,1,LOG_2:13)
Block(1,0,3,LOG_2:13)
Block(-1,1,0,LOG_2:13)
Block(-1,0,0,LOG_2:13)
Block(-1,3,0,LOG_2:13)
Block(-1,2,0,LOG_2:13)
Block(0,7,-1,LOG_2:13)
Block(0,9,-1,LOG_2:13)
Block(0,8,-1,LOG_2:13)
Block(-4,3,1,LOG_2:13)
Block(0,0,-1,LOG_2:13)
Block(-4,4,1,LOG_2:13)
Block(-1,-4,3,LOG_2:13)
Block(1,12,-1,LOG_2:13)
Block(1,11,-1,LOG_2:13)
Block(-1,-1,3,LOG_2:13)
Block(-1,-3,3,LOG_2:13)
Block(-1,-2,3,LOG_2:13)
Block(-1,6,-2,LEAVES_2:13)
Block(2,0,2,LOG_2:13)
Block(-1,9,-2,LOG_2:13)
Block(-1,8,-2,LOG_2:13)
Block(-1,7,-2,LOG_2:13)
Block(-3,5,-1,LOG_2:13)
Block(0,-1,4,LOG_2:13)
Block(-3,6,-1,LOG_2:13)
Block(0,-2,4,LOG_2:13)
Block(-3,7,-1,LOG_2:13)
Block(0,-3,4,LOG_2:13)
Block(0,-4,4,LOG_2:13)
Block(1,-2,3,LOG_2:13)
Block(1,-1,3,LOG_2:13)
Block(1,-4,3,LOG_2:13)
Block(0,10,-1,LOG_2:13)
Block(1,-3,3,LOG_2:13)
Block(0,12,-1,LOG_2:13)
Block(0,11,-1,LOG_2:13)
Block(0,14,-1,LOG_2:13)
Block(0,13,-1,LOG_2:13)
Block(0,1,0,LOG_2:13)
Block(0,0,0,LOG_2:13)
Block(0,2,0,LOG_2:13)
Block(0,5,0,LOG_2:13)
Block(0,4,0,LOG_2:13)
Block(0,6,0,LOG_2:13)
Block(-1,-2,1,LOG_2:13)
Block(0,-1,1,LOG_2:13)
Block(-1,-3,1,LOG_2:13)
Block(-1,-4,1,LOG_2:13)
Block(0,-4,1,LOG_2:13)
Block(0,-3,1,LOG_2:13)
Block(0,-2,1,LOG_2:13)
Block(-1,-1,1,LOG_2:13)
Block(-1,3,2,LOG_2:13)
Block(-1,2,2,LOG_2:13)
Block(-1,5,2,LEAVES_2:1)
Block(-1,4,2,LOG_2:13)
Block(-1,6,2,LEAVES_2:13)
Block(-2,7,0,LOG_2:13)
Block(-2,6,0,LOG_2:13)
Block(-2,5,0,LOG_2:13)
Block(-2,4,0,LOG_2:13)
Block(-2,3,0,LOG_2:13)
Block(-2,2,0,LOG_2:13)
Block(-1,15,0,LOG_2:13)
Block(-2,1,0,LOG_2:13)
Block(-1,16,0,LOG_2:13)
Block(-2,0,0,LOG_2:13)
Block(-1,10,0,LOG_2:13)
Block(-1,1,2,LOG_2:13)
Block(-1,13,0,LOG_2:13)
Block(-1,0,2,LOG_2:13)
Block(-1,14,0,LOG_2:13)
Block(0,-2,-1,LOG_2:13)
Block(-1,4,1,LOG_2:13)
Block(0,-1,-1,LOG_2:13)
Block(-1,3,1,LOG_2:13)
Block(0,-4,-1,LOG_2:13)
Block(-1,6,1,LOG_2:13)
Block(0,-3,-1,LOG_2:13)
Block(-1,5,1,LOG_2:13)
Block(-2,-4,1,LOG_2:13)
Block(-2,-3,1,LOG_2:13)
Block(-1,-1,-1,LOG_2:13)
Block(-1,-2,-1,LOG_2:13)
Block(-1,-3,-1,LOG_2:13)
Block(-2,-2,1,LOG_2:13)
Block(-1,-4,-1,LOG_2:13)
Block(-2,-1,1,LOG_2:13)
Block(-1,-4,2,LOG_2:13)
Block(-1,-3,2,LOG_2:13)
Block(0,-4,0,LOG_2:13)
Block(0,-3,0,LOG_2:13)
Block(0,-2,0,LOG_2:13)
Block(0,9,0,LOG_2:13)
Block(-1,0,1,LOG_2:13)
Block(-1,-2,2,LOG_2:13)
Block(-1,2,1,LOG_2:13)
Block(-1,-1,2,LOG_2:13)
Block(-1,1,1,LOG_2:13)
Block(0,1,2,LOG_2:13)
Block(0,0,2,LOG_2:13)
Block(0,3,2,LEAVES_2:13)
Block(0,2,2,LOG_2:13)
Block(0,15,1,LOG_2:13)
Block(0,14,1,LOG_2:13)
Block(0,13,1,LOG_2:13)
Block(0,12,1,LOG_2:13)
Block(0,17,1,LOG_2:13)
Block(0,16,1,LOG_2:13)
Block(-3,7,0,LOG_2:13)
Block(-3,6,0,LOG_2:13)
Block(-3,3,0,LOG_2:13)
Block(-3,2,0,LOG_2:13)
Block(-3,5,0,LOG_2:13)
Block(-3,4,0,LOG_2:13)
Block(-1,1,4,LOG_2:13)
Block(1,-4,0,LOG_2:13)
Block(-1,0,4,LOG_2:13)
Block(1,-3,0,LOG_2:13)
Block(1,-2,0,LOG_2:13)
Block(1,-1,0,LOG_2:13)
Block(-2,-3,3,LOG_2:13)
Block(-2,-4,3,LOG_2:13)
Block(-2,-1,3,LOG_2:13)
Block(-2,6,2,LOG_2:13)
Block(-2,-2,3,LOG_2:13)
Block(-2,5,2,LOG_2:13)
Block(-2,4,2,LOG_2:13)
Block(-2,3,2,LOG_2:13)
Block(-2,2,2,LOG_2:13)
Block(-2,1,2,LOG_2:13)
Block(0,-3,2,LOG_2:13)
Block(-1,-1,0,LOG_2:13)
Block(-2,0,2,LOG_2:13)
Block(0,-4,2,LOG_2:13)
Block(-1,-2,0,LOG_2:13)
Block(-1,-3,0,LOG_2:13)
Block(-1,10,-2,LOG_2:13)
Block(-1,-4,0,LOG_2:13)
Block(-1,11,-2,LOG_2:13)
Block(0,-1,2,LOG_2:13)
Block(0,-2,2,LOG_2:13)
Block(0,0,1,LOG_2:13)
Block(0,2,1,LOG_2:13)
Block(0,1,1,LOG_2:13)
Block(-3,-2,1,LOG_2:13)
Block(0,4,1,LOG_2:13)
Block(-3,-3,1,LOG_2:13)
Block(0,3,1,LOG_2:13)
Block(-2,-4,2,LOG_2:13)
Block(-3,-1,1,LOG_2:13)
Block(-2,-2,2,LOG_2:13)
Block(-2,-3,2,LOG_2:13)
Block(-3,-4,1,LOG_2:13)
Block(-2,-1,2,LOG_2:13)
Block(2,-2,2,LOG_2:13)
Block(2,-1,2,LOG_2:13)
Block(2,-4,2,LOG_2:13)
Block(2,-3,2,LOG_2:13)
Block(-2,10,-1,LOG_2:13)
Block(-1,10,-1,LOG_2:13)
Block(-1,2,3,LOG_2:13)
Block(2,11,1,LEAVES_2:13)
Block(-1,1,3,LOG_2:13)
Block(-1,5,3,LEAVES_2:1)
Block(-2,7,1,LOG_2:13)
Block(-2,6,1,LOG_2:13)
Block(-2,5,1,LOG_2:13)
Block(-1,11,-1,LOG_2:13)
Block(-2,4,1,LOG_2:13)
Block(-1,12,-1,LOG_2:13)
Block(-2,3,1,LOG_2:13)
Block(-2,2,1,LOG_2:13)
Block(-2,1,1,LOG_2:13)
Block(0,14,0,LOG_2:13)
Block(-2,0,1,LOG_2:13)
Block(0,13,0,LOG_2:13)
Block(0,12,0,LOG_2:13)
Block(0,11,0,LOG_2:13)
Block(0,10,0,LOG_2:13)
Block(1,0,0,LOG_2:13)
Block(-1,0,3,LOG_2:13)
Block(0,0,4,LOG_2:13)
Block(-4,4,0,LOG_2:13)
Block(-4,6,0,LOG_2:13)
Block(-4,5,0,LOG_2:13)
Block(-2,9,-1,LOG_2:13)
Block(-2,4,-1,LOG_2:13)
Block(-2,3,-1,LOG_2:13)
Block(-3,4,2,LOG_2:13)
Block(-2,2,-1,LOG_2:13)
Block(-2,8,-1,LOG_2:13)
Block(-3,0,2,LOG_2:13)
Block(-2,7,-1,LOG_2:13)
Block(-3,3,2,LOG_2:13)
Block(-2,6,-1,LOG_2:13)
Block(-3,2,2,LOG_2:13)
Block(-2,5,-1,LOG_2:13)
Block(-1,7,-1,LOG_2:13)
Block(-1,6,-1,LOG_2:13)
Block(-1,5,-1,LOG_2:13)
Block(-3,-4,2,LOG_2:13)
Block(-1,3,-1,BROWN_MUSHROOM)
Block(-3,-3,2,LOG_2:13)
Block(-1,2,-1,LOG_2:13)
Block(1,14,0,LOG_2:13)
Block(-3,-2,2,LOG_2:13)
Block(-1,1,-1,LOG_2:13)
Block(1,13,0,LOG_2:13)
Block(-3,-1,2,LOG_2:13)
Block(-1,0,-1,LOG_2:13)
Block(1,12,0,LEAVES_2:9)
Block(1,11,0,LEAVES_2:13)
Block(-2,4,4,LEAVES_2:5)
Block(-1,9,-1,LOG_2:13)
Block(-1,8,-1,LOG_2:13)
Block(2,12,-1,LEAVES_2:5)
Block(1,4,1,LEAVES_2:1)
Block(1,-1,1,LOG_2:13)
Block(1,-2,1,LOG_2:13)
Block(1,2,1,LOG_2:13)
Block(1,-3,1,LOG_2:13)
Block(-1,-3,4,LOG_2:13)
Block(1,1,1,LOG_2:13)
Block(1,-4,1,LOG_2:13)
Block(-1,-4,4,LOG_2:13)
Block(1,0,1,LOG_2:13)
Block(-1,-1,4,LOG_2:13)
Block(-1,-2,4,LOG_2:13)
Block(-3,0,1,LOG_2:13)
Block(0,0,3,LOG_2:13)
Block(0,2,3,LEAVES_2:5)
Block(0,1,3,LOG_2:13)
Block(0,-4,3,LOG_2:13)
Block(-2,8,-2,LOG_2:13)
Block(0,-1,3,LOG_2:13)
Block(0,-2,3,LOG_2:13)
Block(0,-3,3,LOG_2:13)
Block(-3,6,1,LOG_2:13)
Block(1,-1,2,LOG_2:13)
Block(-3,5,1,LOG_2:13)
Block(1,-2,2,LOG_2:13)
Block(0,11,-2,LOG_2:13)
Block(1,-3,2,LOG_2:13)
Block(0,10,-2,LOG_2:13)
Block(1,-4,2,LOG_2:13)
Block(-3,2,1,LOG_2:13)
Block(-2,7,-2,LOG_2:13)
Block(-3,1,1,LOG_2:13)
Block(-2,6,-2,LOG_2:13)
Block(0,12,-2,LOG_2:13)
Block(-3,4,1,LOG_2:13)
Block(-3,3,1,LOG_2:13)
Block(2,-4,1,LOG_2:13)
Block(-2,4,3,LOG_2:13)
Block(2,-1,1,LOG_2:13)
Block(-2,3,3,LOG_2:13)
Block(-2,2,3,LOG_2:13)
Block(2,-3,1,LOG_2:13)
Block(2,-2,1,LOG_2:13)
Block(-2,0,3,LOG_2:13)
Block(1,1,2,LOG_2:13)
Block(1,0,2,LOG_2:13)

#######################################################################
# +-----------------------------------------------------------------+ #
# |                            BO3 checks                           | #
# +-----------------------------------------------------------------+ #
#######################################################################

BlockCheck(2,-1,1,GRASS:0,DIRT:0)
BlockCheck(1,-1,3,GRASS:0,DIRT:0)
BlockCheck(0,-1,-1,GRASS:0,DIRT:0)
BlockCheck(0,-1,3,GRASS:0,DIRT:0)
BlockCheck(1,-1,1,GRASS:0,DIRT:0)
BlockCheck(-1,-1,-1,GRASS:0,DIRT:0)

#######################################################################
# +-----------------------------------------------------------------+ #
# |                             Branches                            | #
# +-----------------------------------------------------------------+ #
#######################################################################


#######################################################################
# +-----------------------------------------------------------------+ #
# |                             Entities                            | #
# +-----------------------------------------------------------------+ #
#######################################################################


#######################################################################
# +-----------------------------------------------------------------+ #
# |                            Particles                            | #
# +-----------------------------------------------------------------+ #
#######################################################################


#######################################################################
# +-----------------------------------------------------------------+ #
# |                             Spawners                            | #
# +-----------------------------------------------------------------+ #
#######################################################################


#######################################################################
# +-----------------------------------------------------------------+ #
# |                             ModData                             | #
# +-----------------------------------------------------------------+ #
#######################################################################

