
#######################################################################
# +-----------------------------------------------------------------+ #
# |                            BO3 object                           | #
# +-----------------------------------------------------------------+ #
#######################################################################

Author: LordSmellyPants

Description: Converted version of the BO2 HauntedTwisted2

Version: 3

SettingsMode: WriteWithoutComments


#######################################################################
# +-----------------------------------------------------------------+ #
# |                          Main settings                          | #
# +-----------------------------------------------------------------+ #
#######################################################################

Tree: true

Frequency: 1

Rarity: 20.0

RotateRandomly: true

SpawnHeight: highestSolidBlock

SpawnHeightOffset: 0

SpawnHeightVariance: 0

##############################
# Height Limits for the BO3. #
##############################

MinHeight: 0

MaxHeight: 30

######################
# Extrusion settings #
######################

ExtrudeMode: None

ExtrudeThroughBlocks: AIR

MaxBranchDepth: 10

ExcludedBiomes: All


#######################################################################
# +-----------------------------------------------------------------+ #
# |                      Source block settings                      | #
# +-----------------------------------------------------------------+ #
#######################################################################

SourceBlocks: AIR

MaxPercentageOutsideSourceBlock: 20

OutsideSourceBlock: dontPlace

DoReplaceBlocks: true

IsOTGPlus: false


#######################################################################
# +-----------------------------------------------------------------+ #
# |                              Blocks                             | #
# +-----------------------------------------------------------------+ #
#######################################################################

Block(6,9,1,LOG_2:13)
Block(2,10,4,LOG_2:13)
Block(6,6,1,LOG_2:13)
Block(6,5,1,LOG_2:13)
Block(6,8,1,LOG_2:13)
Block(6,7,1,LOG_2:13)
Block(-11,11,-1,LOG_2:13)
Block(-11,12,-1,LOG_2:13)
Block(13,7,-9,LOG_2:13)
Block(13,6,-9,LOG_2:13)
Block(10,7,-6,LOG_2:13)
Block(10,6,-6,LOG_2:13)
Block(13,8,-9,LOG_2:13)
Block(10,1,-6,LOG_2:13)
Block(10,0,-6,LOG_2:13)
Block(10,5,-6,LOG_2:13)
Block(10,4,-6,LOG_2:13)
Block(10,3,-6,LOG_2:13)
Block(10,2,-6,LOG_2:13)
Block(5,5,-3,LOG_2:13)
Block(5,6,-3,LOG_2:13)
Block(5,7,-3,LOG_2:13)
Block(5,8,-3,LOG_2:13)
Block(9,8,-2,LOG_2:13)
Block(9,5,-2,LOG_2:13)
Block(9,4,-2,LOG_2:13)
Block(9,7,-2,LOG_2:13)
Block(9,6,-2,LOG_2:13)
Block(-7,10,2,LOG_2:13)
Block(8,0,-4,LOG_2:13)
Block(1,10,2,LOG_2:13)
Block(14,6,-5,LEAVES_2:1)
Block(-3,9,3,LOG_2:13)
Block(5,10,1,LOG_2:13)
Block(-2,9,5,LOG_2:13)
Block(-2,8,5,LOG_2:13)
Block(8,1,-4,LOG_2:13)
Block(8,2,-4,LOG_2:13)
Block(9,-3,-4,LOG_2:13)
Block(8,3,-4,LOG_2:13)
Block(9,-4,-4,LOG_2:13)
Block(8,4,-4,LOG_2:13)
Block(8,5,-4,LOG_2:13)
Block(8,6,-4,LOG_2:13)
Block(8,7,-4,LOG_2:13)
Block(8,8,-4,LOG_2:13)
Block(9,-1,-4,LOG_2:13)
Block(9,-2,-4,LOG_2:13)
Block(7,5,-8,LOG_2:13)
Block(-11,11,0,LOG_2:13)
Block(10,3,-4,LOG_2:13)
Block(10,2,-4,LOG_2:13)
Block(10,1,-4,LOG_2:13)
Block(10,0,-4,LOG_2:13)
Block(10,7,-4,LOG_2:13)
Block(10,6,-4,LOG_2:13)
Block(-4,10,3,LOG_2:13)
Block(10,5,-4,LOG_2:13)
Block(10,4,-4,LOG_2:13)
Block(-10,10,0,LOG_2:13)
Block(-10,12,0,LOG_2:13)
Block(-10,11,0,LOG_2:13)
Block(10,-2,-5,LOG_2:13)
Block(10,-3,-5,LOG_2:13)
Block(10,-4,-5,LOG_2:13)
Block(10,-1,-5,LOG_2:13)
Block(-8,13,-7,LOG_2:13)
Block(9,3,-2,LOG_2:13)
Block(5,5,-5,LEAVES_2:5)
Block(-8,14,-7,LOG_2:13)
Block(9,7,-4,LOG_2:13)
Block(-4,9,3,LOG_2:13)
Block(9,6,-4,LOG_2:13)
Block(-4,8,3,LOG_2:13)
Block(2,11,2,LOG_2:13)
Block(9,3,-4,LOG_2:13)
Block(9,2,-4,LOG_2:13)
Block(9,5,-4,LOG_2:13)
Block(2,10,2,LOG_2:13)
Block(9,4,-4,LOG_2:13)
Block(4,10,1,LOG_2:13)
Block(-6,14,-8,LOG_2:13)
Block(-3,9,5,LOG_2:13)
Block(-3,8,5,LOG_2:13)
Block(13,3,-9,LOG_2:13)
Block(13,2,-9,LOG_2:13)
Block(13,5,-9,LOG_2:13)
Block(13,4,-9,LOG_2:13)
Block(8,3,-2,LOG_2:13)
Block(8,4,-2,LOG_2:13)
Block(8,5,-2,LOG_2:13)
Block(8,6,-2,LOG_2:13)
Block(8,7,-2,LOG_2:13)
Block(8,8,-2,LOG_2:13)
Block(9,6,-12,LOG_2:13)
Block(7,8,3,LOG_2:13)
Block(7,7,-6,LOG_2:13)
Block(7,7,3,LOG_2:13)
Block(7,6,-6,LOG_2:13)
Block(1,10,4,LOG_2:13)
Block(11,2,-11,LOG_2:13)
Block(7,1,-6,LOG_2:13)
Block(11,4,-11,LOG_2:13)
Block(7,0,-6,LOG_2:13)
Block(11,3,-11,LOG_2:13)
Block(11,6,-11,LOG_2:13)
Block(11,5,-11,LOG_2:13)
Block(7,5,-6,LOG_2:13)
Block(11,8,-11,LOG_2:13)
Block(7,4,-6,LOG_2:13)
Block(11,7,-11,LOG_2:13)
Block(7,3,-6,LOG_2:13)
Block(7,2,-6,LOG_2:13)
Block(10,5,-2,LOG_2:13)
Block(10,4,-2,WEB)
Block(8,7,1,LOG_2:13)
Block(8,6,1,LOG_2:13)
Block(8,5,1,LOG_2:13)
Block(10,-4,-9,LOG_2:13)
Block(-5,9,3,LOG_2:13)
Block(10,-2,-9,LOG_2:13)
Block(10,-3,-9,LOG_2:13)
Block(10,-1,-9,LOG_2:13)
Block(9,1,-4,LOG_2:13)
Block(9,0,-4,LOG_2:13)
Block(-9,8,2,LEAVES_2:1)
Block(-9,9,2,LEAVES_2:1)
Block(9,5,-6,LOG_2:13)
Block(-4,7,5,LOG_2:13)
Block(9,4,-6,LOG_2:13)
Block(9,7,-6,LOG_2:13)
Block(9,6,-6,LOG_2:13)
Block(9,1,-6,LOG_2:13)
Block(-9,11,1,LOG_2:13)
Block(9,0,-6,LOG_2:13)
Block(-9,10,1,LOG_2:13)
Block(9,3,-6,LOG_2:13)
Block(-4,9,5,LOG_2:13)
Block(9,2,-6,LOG_2:13)
Block(-4,8,5,LOG_2:13)
Block(8,-1,-4,LOG_2:13)
Block(8,-2,-4,LOG_2:13)
Block(8,-3,-4,LOG_2:13)
Block(14,4,-9,LEAVES_2:13)
Block(8,-4,-4,LOG_2:13)
Block(10,7,-11,LOG_2:13)
Block(10,6,-11,LOG_2:13)
Block(10,5,-11,LOG_2:13)
Block(10,4,-11,LOG_2:13)
Block(10,8,-11,LOG_2:13)
Block(7,-4,-5,LOG_2:13)
Block(7,-2,-5,LOG_2:13)
Block(3,9,5,LOG_2:13)
Block(7,-3,-5,LOG_2:13)
Block(10,3,-11,LOG_2:13)
Block(7,-1,-5,LOG_2:13)
Block(10,2,-11,LOG_2:13)
Block(14,8,-9,LEAVES_2:5)
Block(4,8,3,LOG_2:13)
Block(4,7,3,LOG_2:13)
Block(5,9,1,LOG_2:13)
Block(5,8,1,LOG_2:13)
Block(4,9,3,LOG_2:13)
Block(5,7,1,LOG_2:13)
Block(5,6,1,LOG_2:13)
Block(5,5,1,LOG_2:13)
Block(6,8,3,LOG_2:13)
Block(12,-1,-6,LEAVES_2:5)
Block(6,7,3,LOG_2:13)
Block(11,-2,-7,LOG_2:13)
Block(11,-1,-7,LOG_2:13)
Block(11,-4,-7,LOG_2:13)
Block(-7,10,4,LOG_2:13)
Block(11,-3,-7,LOG_2:13)
Block(-2,10,3,LOG_2:13)
Block(7,8,-4,LOG_2:13)
Block(7,8,1,LOG_2:13)
Block(11,6,-13,LEAVES_2:5)
Block(7,7,-4,LOG_2:13)
Block(7,7,1,LOG_2:13)
Block(7,6,-4,LOG_2:13)
Block(7,6,1,LOG_2:13)
Block(7,5,-4,LOG_2:13)
Block(7,5,1,LOG_2:13)
Block(-6,9,3,LOG_2:13)
Block(-6,8,3,LOG_2:13)
Block(5,7,-1,LOG_2:13)
Block(-5,8,5,LOG_2:13)
Block(-5,7,5,LOG_2:13)
Block(5,8,-1,LOG_2:13)
Block(5,5,-1,LOG_2:13)
Block(5,6,-1,LOG_2:13)
Block(-5,9,5,LOG_2:13)
Block(0,10,2,LEAVES_2:1)
Block(9,-4,-6,LOG_2:13)
Block(9,-3,-6,LOG_2:13)
Block(9,-2,-6,LOG_2:13)
Block(9,-1,-6,LOG_2:13)
Block(9,3,-8,LOG_2:13)
Block(9,2,-8,LOG_2:13)
Block(9,5,-8,LOG_2:13)
Block(9,4,-8,LOG_2:13)
Block(9,1,-8,LOG_2:13)
Block(9,0,-8,LOG_2:13)
Block(9,7,-8,LOG_2:13)
Block(9,6,-8,LOG_2:13)
Block(10,-4,-7,LOG_2:13)
Block(10,-1,-7,LOG_2:13)
Block(10,-3,-7,LOG_2:13)
Block(5,9,3,LOG_2:13)
Block(10,-2,-7,LOG_2:13)
Block(5,8,3,LOG_2:13)
Block(5,7,3,LOG_2:13)
Block(3,10,4,LOG_2:13)
Block(1,9,4,LOG_2:13)
Block(1,8,4,LOG_2:13)
Block(8,-3,-6,LOG_2:13)
Block(2,9,2,LOG_2:13)
Block(8,-2,-6,LOG_2:13)
Block(2,8,2,LOG_2:13)
Block(8,-4,-6,LOG_2:13)
Block(-10,11,-2,LOG_2:13)
Block(8,-1,-6,LOG_2:13)
Block(2,7,2,LOG_2:13)
Block(7,5,-2,LOG_2:13)
Block(-7,8,3,LOG_2:13)
Block(7,4,-2,LOG_2:13)
Block(7,3,-2,LOG_2:13)
Block(-10,12,-2,LOG_2:13)
Block(7,2,-2,LOG_2:13)
Block(-7,9,3,LOG_2:13)
Block(7,9,-2,LOG_2:13)
Block(7,8,-2,LOG_2:13)
Block(7,7,-2,LOG_2:13)
Block(7,6,-2,LOG_2:13)
Block(3,8,0,LOG_2:13)
Block(-6,9,5,LOG_2:13)
Block(10,7,1,LEAVES_2:1)
Block(10,4,1,LEAVES_2:5)
Block(10,5,1,LEAVES_2:5)
Block(6,5,-5,LEAVES_2:1)
Block(6,1,-5,LEAVES_2:5)
Block(11,0,-8,LOG_2:13)
Block(11,1,-8,LOG_2:13)
Block(11,2,-8,LOG_2:13)
Block(11,3,-8,LOG_2:13)
Block(6,6,-5,LOG_2:13)
Block(11,-1,-5,LEAVES_2:5)
Block(11,4,-8,LOG_2:13)
Block(7,1,-2,LOG_2:13)
Block(7,0,-2,LOG_2:13)
Block(12,4,-6,LOG_2:13)
Block(-9,10,3,LOG_2:13)
Block(12,5,-6,LOG_2:13)
Block(0,9,6,LOG_2:13)
Block(9,4,-10,LOG_2:13)
Block(9,3,-10,LOG_2:13)
Block(9,6,-10,LOG_2:13)
Block(9,5,-10,LOG_2:13)
Block(-8,9,3,LOG_2:13)
Block(9,7,-10,LOG_2:13)
Block(1,9,6,LOG_2:13)
Block(4,11,6,LEAVES_2:1)
Block(2,9,4,LOG_2:13)
Block(2,8,4,LOG_2:13)
Block(6,8,-10,LEAVES_2:1)
Block(3,6,2,LOG_2:13)
Block(3,9,2,LOG_2:13)
Block(3,8,2,LOG_2:13)
Block(-1,9,2,LOG_2:13)
Block(3,7,2,LOG_2:13)
Block(11,5,-8,LOG_2:13)
Block(9,5,1,LOG_2:13)
Block(9,4,1,LEAVES_2:5)
Block(11,6,-8,LOG_2:13)
Block(11,7,-8,LOG_2:13)
Block(4,7,0,LOG_2:13)
Block(11,8,-8,LOG_2:13)
Block(9,0,-10,LOG_2:13)
Block(11,9,-8,LEAVES_2:1)
Block(4,9,0,LOG_2:13)
Block(4,8,0,LOG_2:13)
Block(9,2,-10,LOG_2:13)
Block(9,1,-10,LOG_2:13)
Block(-1,10,0,LEAVES_2:1)
Block(9,7,1,LEAVES_2:5)
Block(9,6,1,LOG_2:13)
Block(12,6,-8,LOG_2:13)
Block(12,7,-8,LOG_2:13)
Block(12,8,-8,LOG_2:13)
Block(11,0,-6,LOG_2:13)
Block(11,1,-6,LOG_2:13)
Block(11,2,-6,LOG_2:13)
Block(11,3,-6,LOG_2:13)
Block(11,4,-6,LOG_2:13)
Block(6,5,-7,LOG_2:13)
Block(11,5,-6,LOG_2:13)
Block(11,6,-6,LOG_2:13)
Block(8,-4,-8,LOG_2:13)
Block(8,-2,-8,LOG_2:13)
Block(8,-3,-8,LOG_2:13)
Block(8,-1,-8,LOG_2:13)
Block(3,10,1,LOG_2:13)
Block(12,2,-10,LOG_2:13)
Block(9,-3,-8,LOG_2:13)
Block(12,2,-8,LOG_2:13)
Block(0,11,4,LOG_2:13)
Block(9,-4,-8,LOG_2:13)
Block(12,3,-8,LOG_2:13)
Block(12,4,-8,LOG_2:13)
Block(12,8,-10,LOG_2:13)
Block(12,5,-8,LOG_2:13)
Block(12,7,-10,LOG_2:13)
Block(12,6,-10,LOG_2:13)
Block(12,5,-10,LOG_2:13)
Block(9,-1,-8,LOG_2:13)
Block(12,4,-10,LOG_2:13)
Block(9,-2,-8,LOG_2:13)
Block(12,3,-10,LOG_2:13)
Block(5,10,-3,LEAVES_2:1)
Block(0,10,4,LOG_2:13)
Block(-1,10,4,LOG_2:13)
Block(-10,11,1,LOG_2:13)
Block(11,-1,-3,LEAVES_2:5)
Block(8,3,-10,LEAVES_2:5)
Block(8,5,-10,LOG_2:13)
Block(8,4,-10,LEAVES_2:5)
Block(-1,7,4,LOG_2:13)
Block(-9,13,-5,LOG_2:13)
Block(-1,9,4,LOG_2:13)
Block(-1,8,4,LOG_2:13)
Block(11,7,-6,LOG_2:13)
Block(-1,11,4,LOG_2:13)
Block(-11,12,-4,LOG_2:13)
Block(6,8,-1,LOG_2:13)
Block(6,9,-1,LOG_2:13)
Block(6,6,-1,LOG_2:13)
Block(6,7,-1,LOG_2:13)
Block(6,4,-1,LOG_2:13)
Block(6,5,-1,LOG_2:13)
Block(11,0,-4,LOG_2:13)
Block(6,3,-1,LOG_2:13)
Block(11,1,-4,LOG_2:13)
Block(11,2,-4,LOG_2:13)
Block(11,3,-4,LOG_2:13)
Block(10,-4,-3,LOG_2:13)
Block(11,4,-4,LOG_2:13)
Block(11,5,-4,LOG_2:13)
Block(11,6,-4,LOG_2:13)
Block(11,7,-4,LOG_2:13)
Block(-10,13,-4,LOG_2:13)
Block(4,7,-2,LOG_2:13)
Block(-10,12,-4,LOG_2:13)
Block(-10,11,-4,LOG_2:13)
Block(-7,14,-7,LOG_2:13)
Block(4,6,-2,LOG_2:13)
Block(4,10,2,LOG_2:13)
Block(8,0,-8,LOG_2:13)
Block(10,-3,-3,LOG_2:13)
Block(8,1,-8,LOG_2:13)
Block(10,-2,-3,LOG_2:13)
Block(8,2,-8,LOG_2:13)
Block(10,-1,-3,LOG_2:13)
Block(8,3,-8,LOG_2:13)
Block(8,4,-8,LOG_2:13)
Block(8,5,-8,LOG_2:13)
Block(8,6,-8,LOG_2:13)
Block(-6,10,3,LOG_2:13)
Block(8,7,-8,LOG_2:13)
Block(0,9,2,LOG_2:13)
Block(0,8,2,LOG_2:13)
Block(1,9,2,LOG_2:13)
Block(-4,10,6,LEAVES_2:1)
Block(1,8,2,LOG_2:13)
Block(-3,9,2,LOG_2:13)
Block(6,10,1,LOG_2:13)
Block(-2,9,4,LOG_2:13)
Block(-2,8,4,LOG_2:13)
Block(-2,7,4,LOG_2:13)
Block(-1,7,6,LEAVES_2:1)
Block(-1,9,6,LOG_2:13)
Block(-1,8,6,LEAVES_2:1)
Block(-8,11,2,LOG_2:13)
Block(-8,10,2,LOG_2:13)
Block(6,6,-3,LOG_2:13)
Block(6,7,-3,LOG_2:13)
Block(6,4,-3,LOG_2:13)
Block(6,5,-3,LOG_2:13)
Block(6,3,-3,LOG_2:13)
Block(6,8,-3,LOG_2:13)
Block(6,9,-3,LEAVES_2:1)
Block(10,6,-9,LOG_2:13)
Block(10,5,-9,LOG_2:13)
Block(10,4,-9,LOG_2:13)
Block(10,3,-9,LOG_2:13)
Block(10,7,-9,LOG_2:13)
Block(13,5,-5,LEAVES_2:1)
Block(10,2,-9,LOG_2:13)
Block(10,1,-9,LOG_2:13)
Block(13,6,-5,LEAVES_2:1)
Block(10,0,-9,LOG_2:13)
Block(-11,12,-2,LOG_2:13)
Block(8,0,-6,LOG_2:13)
Block(8,1,-6,LOG_2:13)
Block(8,2,-6,LOG_2:13)
Block(8,3,-6,LOG_2:13)
Block(8,4,-6,LOG_2:13)
Block(8,5,-6,LOG_2:13)
Block(8,6,-6,LOG_2:13)
Block(8,7,-6,LOG_2:13)
Block(0,7,4,LOG_2:13)
Block(0,9,4,LOG_2:13)
Block(0,8,4,LOG_2:13)
Block(9,6,-1,LOG_2:13)
Block(5,10,2,LOG_2:13)
Block(9,5,-1,LOG_2:13)
Block(9,8,-1,LOG_2:13)
Block(9,7,-1,LOG_2:13)
Block(9,-4,-5,LOG_2:13)
Block(-3,7,4,LOG_2:13)
Block(-3,9,4,LOG_2:13)
Block(-3,8,4,LOG_2:13)
Block(9,-3,-5,LOG_2:13)
Block(9,-2,-5,LOG_2:13)
Block(9,-1,-5,LOG_2:13)
Block(6,-1,-2,LEAVES_2:13)
Block(-2,9,6,LOG_2:13)
Block(13,6,-8,LOG_2:13)
Block(-7,10,3,LOG_2:13)
Block(8,0,-5,LOG_2:13)
Block(8,1,-5,LOG_2:13)
Block(8,2,-5,LOG_2:13)
Block(8,3,-5,LOG_2:13)
Block(8,4,-5,LOG_2:13)
Block(8,5,-5,LOG_2:13)
Block(5,9,4,LOG_2:13)
Block(1,10,1,LOG_2:13)
Block(8,6,-5,LOG_2:13)
Block(5,8,4,WEB)
Block(8,7,-5,LOG_2:13)
Block(6,7,0,LOG_2:13)
Block(6,6,0,LOG_2:13)
Block(6,9,0,LOG_2:13)
Block(6,8,0,LOG_2:13)
Block(6,3,0,LOG_2:13)
Block(6,5,0,LOG_2:13)
Block(6,4,0,LOG_2:13)
Block(10,-4,-6,LOG_2:13)
Block(10,-3,-6,LOG_2:13)
Block(10,-2,-6,LOG_2:13)
Block(10,-1,-6,LOG_2:13)
Block(10,8,-7,LOG_2:13)
Block(10,7,-7,LOG_2:13)
Block(10,6,-7,LOG_2:13)
Block(10,5,-7,LOG_2:13)
Block(10,0,-7,LOG_2:13)
Block(10,4,-7,LOG_2:13)
Block(10,3,-7,LOG_2:13)
Block(10,2,-7,LOG_2:13)
Block(10,1,-7,LOG_2:13)
Block(9,4,-1,LOG_2:13)
Block(5,6,-4,LOG_2:13)
Block(9,3,-1,LOG_2:13)
Block(-4,8,4,LOG_2:13)
Block(9,7,-3,LOG_2:13)
Block(-4,7,4,WEB)
Block(9,4,-3,LOG_2:13)
Block(9,3,-3,LOG_2:13)
Block(9,6,-3,LOG_2:13)
Block(9,5,-3,LOG_2:13)
Block(-4,9,4,LOG_2:13)
Block(8,0,-3,LOG_2:13)
Block(8,1,-3,LOG_2:13)
Block(-10,8,3,LEAVES_2:1)
Block(-3,8,6,LOG_2:13)
Block(2,10,3,LOG_2:13)
Block(2,11,3,LOG_2:13)
Block(4,10,0,LOG_2:13)
Block(8,2,-3,LOG_2:13)
Block(8,3,-3,LOG_2:13)
Block(8,4,-3,LOG_2:13)
Block(8,5,-3,LOG_2:13)
Block(8,6,-3,LOG_2:13)
Block(8,7,-3,LOG_2:13)
Block(8,8,-3,LOG_2:13)
Block(8,9,-3,LOG_2:13)
Block(5,10,0,LOG_2:13)
Block(7,4,-10,LEAVES_2:5)
Block(-4,10,4,LOG_2:13)
Block(9,-4,-3,LOG_2:13)
Block(7,5,-9,LOG_2:13)
Block(9,-2,-3,LOG_2:13)
Block(9,-3,-3,LOG_2:13)
Block(11,1,-10,LOG_2:13)
Block(11,0,-10,LOG_2:13)
Block(11,3,-10,LOG_2:13)
Block(11,2,-10,LOG_2:13)
Block(11,5,-10,LOG_2:13)
Block(11,4,-10,LOG_2:13)
Block(11,7,-10,LOG_2:13)
Block(11,6,-10,LOG_2:13)
Block(10,7,-5,LOG_2:13)
Block(11,9,-10,LOG_2:13)
Block(9,-1,-3,LOG_2:13)
Block(11,8,-10,LOG_2:13)
Block(-3,10,4,LOG_2:13)
Block(10,2,-5,LOG_2:13)
Block(10,1,-5,LOG_2:13)
Block(10,0,-5,LOG_2:13)
Block(10,6,-5,LOG_2:13)
Block(10,5,-5,LOG_2:13)
Block(10,4,-5,LOG_2:13)
Block(10,3,-5,LOG_2:13)
Block(-10,12,-5,LOG_2:13)
Block(8,-1,-3,LOG_2:13)
Block(1,10,3,LOG_2:13)
Block(-10,13,-5,LOG_2:13)
Block(8,-2,-3,LOG_2:13)
Block(5,1,-6,LEAVES_2:5)
Block(9,0,-3,LOG_2:13)
Block(9,2,-3,LOG_2:13)
Block(9,1,-3,LOG_2:13)
Block(8,-3,-3,LOG_2:13)
Block(8,-4,-3,LOG_2:13)
Block(-9,8,3,LEAVES_2:1)
Block(9,6,-5,LOG_2:13)
Block(9,5,-5,LOG_2:13)
Block(9,8,-5,LOG_2:13)
Block(9,7,-5,LOG_2:13)
Block(9,2,-5,LOG_2:13)
Block(9,1,-5,LOG_2:13)
Block(9,4,-5,LOG_2:13)
Block(9,3,-5,LOG_2:13)
Block(8,3,-1,LOG_2:13)
Block(14,4,-8,LEAVES_2:5)
Block(0,10,1,LEAVES_2:1)
Block(10,8,-10,LOG_2:13)
Block(12,-1,-7,LOG_2:13)
Block(10,7,-10,LOG_2:13)
Block(10,6,-10,LOG_2:13)
Block(10,5,-10,LOG_2:13)
Block(-9,11,0,LOG_2:13)
Block(12,-4,-7,LOG_2:13)
Block(3,8,4,LOG_2:13)
Block(3,7,4,LOG_2:13)
Block(12,-2,-7,LOG_2:13)
Block(12,-3,-7,LOG_2:13)
Block(3,9,4,LOG_2:13)
Block(10,4,-10,LOG_2:13)
Block(10,3,-10,LOG_2:13)
Block(10,2,-10,LOG_2:13)
Block(8,4,-1,LOG_2:13)
Block(8,5,-1,LOG_2:13)
Block(8,6,-1,LOG_2:13)
Block(8,7,-1,LOG_2:13)
Block(4,7,2,LOG_2:13)
Block(8,8,-1,LOG_2:13)
Block(4,6,2,LOG_2:13)
Block(4,9,2,LOG_2:13)
Block(4,8,2,LOG_2:13)
Block(5,9,0,LOG_2:13)
Block(5,8,0,LOG_2:13)
Block(5,7,0,LOG_2:13)
Block(5,6,0,LOG_2:13)
Block(5,5,0,LOG_2:13)
Block(3,10,5,LEAVES_2:5)
Block(6,8,4,LOG_2:13)
Block(6,8,-9,LEAVES_2:1)
Block(6,7,-9,LEAVES_2:1)
Block(9,-2,-10,LOG_2:13)
Block(9,-3,-10,LOG_2:13)
Block(9,-4,-10,LOG_2:13)
Block(7,8,2,LOG_2:13)
Block(7,5,-7,LOG_2:13)
Block(7,7,2,LOG_2:13)
Block(9,-2,-7,LOG_2:13)
Block(9,-3,-7,LOG_2:13)
Block(9,-4,-7,LOG_2:13)
Block(7,4,-7,WEB)
Block(11,6,-12,LEAVES_2:5)
Block(7,2,-7,LEAVES_2:5)
Block(9,-1,-10,LOG_2:13)
Block(9,-1,-7,LOG_2:13)
Block(10,4,-3,LOG_2:13)
Block(10,3,-3,LOG_2:13)
Block(8,8,0,LOG_2:13)
Block(10,2,-3,LOG_2:13)
Block(10,1,-3,LOG_2:13)
Block(10,7,-3,LOG_2:13)
Block(10,6,-3,LOG_2:13)
Block(10,5,-3,LOG_2:13)
Block(11,-4,-8,LOG_2:13)
Block(8,3,0,LOG_2:13)
Block(-6,9,2,LOG_2:13)
Block(10,0,-3,LOG_2:13)
Block(8,5,0,LOG_2:13)
Block(11,-1,-8,LOG_2:13)
Block(8,4,0,LOG_2:13)
Block(11,-2,-8,LOG_2:13)
Block(8,7,0,LOG_2:13)
Block(11,-3,-8,LOG_2:13)
Block(8,6,0,LOG_2:13)
Block(-5,7,4,LOG_2:13)
Block(-5,9,4,LOG_2:13)
Block(-5,8,4,LOG_2:13)
Block(-5,10,4,LOG_2:13)
Block(9,0,-5,LOG_2:13)
Block(-9,9,1,LOG_2:13)
Block(9,4,-7,LOG_2:13)
Block(9,3,-7,LOG_2:13)
Block(3,8,-1,LOG_2:13)
Block(9,6,-7,LOG_2:13)
Block(9,5,-7,LOG_2:13)
Block(9,0,-7,LOG_2:13)
Block(9,2,-7,LOG_2:13)
Block(9,1,-7,LOG_2:13)
Block(11,5,1,LEAVES_2:5)
Block(9,8,-7,LOG_2:13)
Block(9,7,-7,LOG_2:13)
Block(10,-3,-8,LOG_2:13)
Block(10,-4,-8,LOG_2:13)
Block(10,-1,-8,LOG_2:13)
Block(10,-2,-8,LOG_2:13)
Block(-9,10,2,LOG_2:13)
Block(3,10,3,LOG_2:13)
Block(10,6,-12,LOG_2:13)
Block(10,5,-12,LOG_2:13)
Block(10,4,-12,LOG_2:13)
Block(10,3,-12,LOG_2:13)
Block(10,8,-12,LOG_2:13)
Block(10,7,-12,LOG_2:13)
Block(6,-1,-6,LEAVES_2:5)
Block(10,2,-12,LOG_2:13)
Block(8,-2,-5,LOG_2:13)
Block(8,-1,-5,LOG_2:13)
Block(12,0,-3,LEAVES_2:13)
Block(8,-4,-5,LOG_2:13)
Block(8,-3,-5,LOG_2:13)
Block(4,7,4,LEAVES_2:1)
Block(4,6,4,LEAVES_2:1)
Block(5,9,2,LOG_2:13)
Block(-5,10,6,LEAVES_2:1)
Block(5,8,2,LOG_2:13)
Block(4,9,4,LOG_2:13)
Block(5,7,2,LOG_2:13)
Block(4,8,4,LOG_2:13)
Block(5,6,2,LOG_2:13)
Block(5,5,2,LOG_2:13)
Block(6,9,2,LOG_2:13)
Block(6,8,2,LOG_2:13)
Block(7,-4,-6,LOG_2:13)
Block(6,7,2,LOG_2:13)
Block(7,-3,-6,LOG_2:13)
Block(6,6,2,LOG_2:13)
Block(7,-2,-6,LOG_2:13)
Block(7,-1,-6,LOG_2:13)
Block(7,7,-5,LOG_2:13)
Block(7,9,0,LOG_2:13)
Block(7,2,-5,LOG_2:13)
Block(7,4,0,LOG_2:13)
Block(7,1,-5,LOG_2:13)
Block(7,3,0,LOG_2:13)
Block(7,0,-5,LOG_2:13)
Block(7,6,-5,LOG_2:13)
Block(7,8,0,LOG_2:13)
Block(7,5,-5,LOG_2:13)
Block(7,7,0,LOG_2:13)
Block(7,4,-5,LOG_2:13)
Block(7,6,0,LOG_2:13)
Block(7,3,-5,LOG_2:13)
Block(7,5,0,LOG_2:13)
Block(10,6,-1,LOG_2:13)
Block(10,5,-1,LOG_2:13)
Block(-6,9,4,LOG_2:13)
Block(-6,8,4,LOG_2:13)
Block(-6,7,4,LOG_2:13)
Block(5,6,-2,LOG_2:13)
Block(5,7,-2,LOG_2:13)
Block(9,2,-9,LOG_2:13)
Block(9,1,-9,LOG_2:13)
Block(6,2,-6,LEAVES_2:5)
Block(9,4,-9,LOG_2:13)
Block(6,1,-6,LEAVES_2:5)
Block(9,3,-9,LOG_2:13)
Block(9,0,-9,LOG_2:13)
Block(9,6,-9,LOG_2:13)
Block(9,5,-9,LOG_2:13)
Block(11,2,-9,LOG_2:13)
Block(11,3,-9,LOG_2:13)
Block(6,5,-6,LOG_2:13)
Block(9,7,-9,LOG_2:13)
Block(-1,10,1,LEAVES_2:1)
Block(11,-1,-6,LOG_2:13)
Block(11,-4,-6,LOG_2:13)
Block(11,-3,-6,LOG_2:13)
Block(4,10,5,LEAVES_2:1)
Block(11,-2,-6,LOG_2:13)
Block(4,11,5,LEAVES_2:1)
Block(12,5,-5,LOG_2:13)
Block(3,10,2,LOG_2:13)
Block(3,11,2,LOG_2:13)
Block(12,4,-5,LOG_2:13)
Block(1,9,5,LOG_2:13)
Block(7,-4,-2,LOG_2:13)
Block(7,-3,-2,LOG_2:13)
Block(7,-2,-2,LOG_2:13)
Block(7,-1,-2,LOG_2:13)
Block(-8,9,2,LOG_2:13)
Block(2,8,3,LOG_2:13)
Block(2,7,3,LOG_2:13)
Block(-8,10,1,LOG_2:13)
Block(2,9,3,LOG_2:13)
Block(2,6,3,LOG_2:13)
Block(7,4,-3,LOG_2:13)
Block(0,10,3,LOG_2:13)
Block(7,3,-3,LOG_2:13)
Block(-7,9,4,LOG_2:13)
Block(-7,8,4,LOG_2:13)
Block(7,8,-3,LOG_2:13)
Block(7,7,-3,LOG_2:13)
Block(7,6,-3,LOG_2:13)
Block(7,5,-3,LOG_2:13)
Block(3,7,1,LOG_2:13)
Block(3,9,1,LOG_2:13)
Block(3,8,1,LOG_2:13)
Block(8,-4,-7,LOG_2:13)
Block(11,4,-9,LOG_2:13)
Block(9,4,2,LEAVES_2:5)
Block(-2,11,4,LOG_2:13)
Block(8,-3,-7,LOG_2:13)
Block(11,5,-9,LOG_2:13)
Block(-2,10,4,LOG_2:13)
Block(11,6,-9,LOG_2:13)
Block(11,7,-9,LOG_2:13)
Block(11,8,-9,LOG_2:13)
Block(-10,10,-1,LOG_2:13)
Block(8,-2,-7,LOG_2:13)
Block(8,-1,-7,LOG_2:13)
Block(-10,11,-1,LOG_2:13)
Block(-10,12,-1,LOG_2:13)
Block(12,7,-7,LOG_2:13)
Block(-9,12,-6,LOG_2:13)
Block(-9,13,-6,LOG_2:13)
Block(11,0,-7,LOG_2:13)
Block(11,1,-7,LOG_2:13)
Block(11,2,-7,LOG_2:13)
Block(11,3,-7,LOG_2:13)
Block(11,4,-7,LOG_2:13)
Block(11,5,-7,LOG_2:13)
Block(11,-4,-4,LOG_2:13)
Block(9,-4,-9,LOG_2:13)
Block(9,-1,-9,LOG_2:13)
Block(9,-3,-9,LOG_2:13)
Block(9,-2,-9,LOG_2:13)
Block(0,10,5,LOG_2:13)
Block(-8,9,4,LOG_2:13)
Block(12,3,-7,LOG_2:13)
Block(12,4,-7,LOG_2:13)
Block(12,5,-7,LOG_2:13)
Block(12,6,-7,LOG_2:13)
Block(12,0,-7,LOG_2:13)
Block(12,1,-7,LOG_2:13)
Block(12,2,-7,LOG_2:13)
Block(9,3,-11,LOG_2:13)
Block(9,2,-11,LOG_2:13)
Block(9,5,-11,LOG_2:13)
Block(9,4,-11,LOG_2:13)
Block(9,7,-11,LOG_2:13)
Block(9,6,-11,LOG_2:13)
Block(9,8,-11,LOG_2:13)
Block(7,6,-1,LOG_2:13)
Block(7,5,-1,LOG_2:13)
Block(7,4,-1,LOG_2:13)
Block(7,3,-1,LOG_2:13)
Block(2,9,5,LOG_2:13)
Block(7,8,-1,LOG_2:13)
Block(7,7,-1,LOG_2:13)
Block(8,7,2,LOG_2:13)
Block(8,6,2,LOG_2:13)
Block(8,4,-11,LEAVES_2:5)
Block(3,9,3,LOG_2:13)
Block(3,8,3,LOG_2:13)
Block(3,7,3,LOG_2:13)
Block(11,-2,-4,LOG_2:13)
Block(11,-3,-4,LOG_2:13)
Block(8,5,2,LOG_2:13)
Block(11,-1,-4,LOG_2:13)
Block(11,6,-7,LOG_2:13)
Block(9,6,0,LOG_2:13)
Block(9,5,0,LOG_2:13)
Block(11,7,-7,LOG_2:13)
Block(4,6,1,LOG_2:13)
Block(4,8,1,LOG_2:13)
Block(4,7,1,LOG_2:13)
Block(4,9,1,LOG_2:13)
Block(10,5,0,LOG_2:13)
Block(10,6,0,LOG_2:13)
Block(6,7,-2,LOG_2:13)
Block(6,8,-2,LOG_2:13)
Block(6,5,-2,LOG_2:13)
Block(6,6,-2,LOG_2:13)
Block(6,3,-2,LOG_2:13)
Block(12,6,-9,LOG_2:13)
Block(6,4,-2,LOG_2:13)
Block(12,5,-9,LOG_2:13)
Block(12,8,-9,LOG_2:13)
Block(12,7,-9,LOG_2:13)
Block(11,-1,-10,LOG_2:13)
Block(11,-2,-10,LOG_2:13)
Block(11,1,-5,LEAVES_2:5)
Block(11,-3,-10,LOG_2:13)
Block(11,2,-5,LEAVES_2:5)
Block(11,-4,-10,LOG_2:13)
Block(11,4,-5,LOG_2:13)
Block(11,5,-5,LOG_2:13)
Block(10,-1,-4,LOG_2:13)
Block(10,-2,-4,LOG_2:13)
Block(-8,11,3,LOG_2:13)
Block(10,-3,-4,LOG_2:13)
Block(-8,10,3,LOG_2:13)
Block(10,-4,-4,LOG_2:13)
Block(-5,14,-8,LOG_2:13)
Block(8,-3,-9,LOG_2:13)
Block(8,0,-9,LOG_2:13)
Block(8,-4,-9,LOG_2:13)
Block(8,1,-9,LOG_2:13)
Block(8,-1,-9,LOG_2:13)
Block(8,2,-9,LOG_2:13)
Block(8,-2,-9,LOG_2:13)
Block(8,3,-9,LOG_2:13)
Block(12,2,-9,LOG_2:13)
Block(8,4,-9,LOG_2:13)
Block(8,5,-9,LOG_2:13)
Block(-9,12,-4,LOG_2:13)
Block(12,4,-9,LOG_2:13)
Block(8,6,-9,LOG_2:13)
Block(0,8,3,LOG_2:13)
Block(12,3,-9,LOG_2:13)
Block(8,7,-9,LOG_2:13)
Block(0,9,3,LOG_2:13)
Block(1,9,1,LOG_2:13)
Block(1,8,1,LOG_2:13)
Block(-11,12,-3,LOG_2:13)
Block(-8,13,-6,LOG_2:13)
Block(-1,10,5,LOG_2:13)
Block(-1,8,3,LOG_2:13)
Block(-1,9,3,LOG_2:13)
Block(6,5,-4,LOG_2:13)
Block(6,6,-4,LOG_2:13)
Block(6,3,-4,LOG_2:13)
Block(6,4,-4,LOG_2:13)
Block(11,4,-3,LOG_2:13)
Block(11,5,-3,LOG_2:13)
Block(6,7,-4,LOG_2:13)
Block(4,11,3,LOG_2:13)
Block(6,8,-4,LOG_2:13)
Block(4,10,3,LOG_2:13)
Block(4,8,-1,LOG_2:13)
Block(10,7,-8,LOG_2:13)
Block(-6,10,4,LOG_2:13)
Block(10,6,-8,LOG_2:13)
Block(10,5,-8,LOG_2:13)
Block(4,7,-1,LOG_2:13)
Block(10,4,-8,LOG_2:13)
Block(10,8,-8,LOG_2:13)
Block(13,4,-6,LOG_2:13)
Block(10,3,-8,LOG_2:13)
Block(10,2,-8,LOG_2:13)
Block(13,5,-6,LOG_2:13)
Block(10,1,-8,LOG_2:13)
Block(10,0,-8,LOG_2:13)
Block(8,0,-7,LOG_2:13)
Block(8,1,-7,LOG_2:13)
Block(8,2,-7,LOG_2:13)
Block(-10,12,-3,LOG_2:13)
Block(8,3,-7,LOG_2:13)
Block(-10,11,-3,LOG_2:13)
Block(8,4,-7,LOG_2:13)
Block(8,5,-7,LOG_2:13)
Block(8,6,-7,LOG_2:13)
Block(8,7,-7,LOG_2:13)
Block(-10,13,-3,LOG_2:13)
Block(0,8,5,LOG_2:13)
Block(0,9,5,LOG_2:13)
Block(1,9,3,LOG_2:13)
Block(1,8,3,LOG_2:13)
Block(2,9,1,LOG_2:13)
Block(2,8,1,LOG_2:13)
Block(-1,10,3,LOG_2:13)
Block(-2,9,3,LOG_2:13)
Block(-2,8,3,LOG_2:13)
Block(-1,8,5,LOG_2:13)
Block(-1,9,5,LOG_2:13)

#######################################################################
# +-----------------------------------------------------------------+ #
# |                            BO3 checks                           | #
# +-----------------------------------------------------------------+ #
#######################################################################

BlockCheck(10,-1,-6,GRASS:0,DIRT:0)
BlockCheck(8,-1,-4,GRASS:0,DIRT:0)
BlockCheck(8,-1,-9,GRASS:0,DIRT:0)
BlockCheck(7,-1,-6,GRASS:0,DIRT:0)

#######################################################################
# +-----------------------------------------------------------------+ #
# |                             Branches                            | #
# +-----------------------------------------------------------------+ #
#######################################################################


#######################################################################
# +-----------------------------------------------------------------+ #
# |                             Entities                            | #
# +-----------------------------------------------------------------+ #
#######################################################################


#######################################################################
# +-----------------------------------------------------------------+ #
# |                            Particles                            | #
# +-----------------------------------------------------------------+ #
#######################################################################


#######################################################################
# +-----------------------------------------------------------------+ #
# |                             Spawners                            | #
# +-----------------------------------------------------------------+ #
#######################################################################


#######################################################################
# +-----------------------------------------------------------------+ #
# |                             ModData                             | #
# +-----------------------------------------------------------------+ #
#######################################################################

