[META]
version=2.0
spawnOnBlockType=49,11
spawnSunlight=True
spawnDarkness=True
spawnWater=False
spawnLava=False
underFill=False
randomRotation=True
dig=True
tree=False
branch=False
needsFoundation=True
rarity=25
collisionPercentage=5
spawnElevationMin=0
spawnElevationMax=58
spawnInBiome=Custom
[DATA]
1,0,-4:49.0
0,-1,-3:49.0
1,-1,-3:49.0
-1,0,-3:49.0
0,0,-3:49.0
1,0,-3:49.0
2,0,-3:49.0
-1,1,-3:49.0
0,1,-3:49.0
1,1,-3:49.0
2,1,-3:49.0
0,2,-3:49.0
1,-3,-2:49.0
-1,-2,-2:49.0
0,-2,-2:49.0
1,-2,-2:49.0
2,-2,-2:49.0
-2,-1,-2:49.0
-1,-1,-2:49.0
0,-1,-2:49.0
1,-1,-2:49.0
2,-1,-2:49.0
3,-1,-2:49.0
-3,0,-2:49.0
-2,0,-2:49.0
-1,0,-2:49.0
0,0,-2:49.0
1,0,-2:49.0
2,0,-2:49.0
3,0,-2:49.0
4,0,-2:49.0
-2,1,-2:49.0
-1,1,-2:49.0
0,1,-2:49.0
1,1,-2:49.0
2,1,-2:49.0
3,1,-2:49.0
-2,2,-2:49.0
-1,2,-2:49.0
0,2,-2:49.0
1,2,-2:49.0
2,2,-2:49.0
-1,3,-2:49.0
0,3,-2:49.0
1,3,-2:49.0
0,-4,-1:49.0
1,-4,-1:49.0
-1,-3,-1:49.0
0,-3,-1:49.0
1,-3,-1:49.0
2,-3,-1:49.0
-1,-2,-1:49.0
0,-2,-1:49.0
1,-2,-1:49.0
2,-2,-1:49.0
3,-2,-1:49.0
-3,-1,-1:49.0
-2,-1,-1:49.0
-1,-1,-1:49.0
0,-1,-1:49.0
1,-1,-1:49.0
2,-1,-1:49.0
3,-1,-1:49.0
4,-1,-1:49.0
-4,0,-1:49.0
-3,0,-1:49.0
-2,0,-1:49.0
-1,0,-1:49.0
0,0,-1:49.0
1,0,-1:49.0
2,0,-1:49.0
3,0,-1:49.0
4,0,-1:49.0
-3,1,-1:49.0
-2,1,-1:49.0
-1,1,-1:49.0
0,1,-1:49.0
1,1,-1:49.0
2,1,-1:49.0
3,1,-1:49.0
4,1,-1:49.0
-3,2,-1:49.0
-2,2,-1:49.0
-1,2,-1:49.0
0,2,-1:49.0
1,2,-1:49.0
2,2,-1:49.0
3,2,-1:49.0
-2,3,-1:49.0
-1,3,-1:49.0
0,3,-1:49.0
1,3,-1:49.0
2,3,-1:49.0
-1,4,-1:49.0
0,-4,0:49.0
1,-4,0:49.0
-2,-3,0:49.0
-1,-3,0:49.0
0,-3,0:49.0
1,-3,0:49.0
2,-3,0:49.0
-2,-2,0:49.0
-1,-2,0:49.0
0,-2,0:49.0
1,-2,0:49.0
2,-2,0:49.0
3,-2,0:49.0
-3,-1,0:49.0
-2,-1,0:49.0
-1,-1,0:11.0
0,-1,0:11.0
1,-1,0:11.0
2,-1,0:49.0
3,-1,0:49.0
4,-1,0:49.0
-4,0,0:49.0
-3,0,0:49.0
-2,0,0:49.0
-1,0,0:11.0
0,0,0:11.0
1,0,0:11.0
2,0,0:49.0
3,0,0:49.0
4,0,0:49.0
-4,1,0:49.0
-3,1,0:49.0
-2,1,0:49.0
-1,1,0:49.0
0,1,0:49.0
1,1,0:49.0
2,1,0:49.0
3,1,0:49.0
4,1,0:49.0
-2,2,0:49.0
-1,2,0:49.0
0,2,0:49.0
1,2,0:49.0
2,2,0:49.0
-2,3,0:49.0
-1,3,0:49.0
0,3,0:49.0
1,3,0:49.0
2,3,0:49.0
-1,4,0:49.0
0,4,0:49.0
1,4,0:49.0
0,-4,1:49.0
-1,-3,1:49.0
0,-3,1:49.0
1,-3,1:49.0
-2,-2,1:49.0
-1,-2,1:49.0
0,-2,1:11.0
1,-2,1:11.0
2,-2,1:49.0
-3,-1,1:49.0
-2,-1,1:49.0
-1,-1,1:11.0
0,-1,1:11.0
1,-1,1:11.0
2,-1,1:11.0
3,-1,1:49.0
-3,0,1:49.0
-2,0,1:49.0
-1,0,1:11.0
0,0,1:11.0
1,0,1:11.0
2,0,1:11.0
3,0,1:49.0
-3,1,1:49.0
-2,1,1:49.0
-1,1,1:11.0
0,1,1:11.0
1,1,1:49.0
2,1,1:49.0
3,1,1:49.0
-2,2,1:49.0
-1,2,1:49.0
0,2,1:49.0
1,2,1:49.0
2,2,1:49.0
-1,3,1:49.0
0,3,1:49.0
1,3,1:49.0
2,3,1:49.0
0,4,1:49.0
0,-3,2:49.0
-2,-2,2:49.0
-1,-2,2:49.0
0,-2,2:49.0
1,-2,2:49.0
-2,-1,2:49.0
-1,-1,2:11.0
0,-1,2:11.0
1,-1,2:11.0
2,-1,2:49.0
-3,0,2:49.0
-2,0,2:49.0
-1,0,2:11.0
0,0,2:11.0
1,0,2:11.0
2,0,2:49.0
3,0,2:49.0
-2,1,2:49.0
-1,1,2:11.0
0,1,2:11.0
1,1,2:49.0
2,1,2:49.0
-1,2,2:49.0
0,2,2:49.0
1,2,2:49.0
0,3,2:49.0
2,3,2:49.0
-2,-2,3:49.0
0,-2,3:49.0
-1,-1,3:49.0
0,-1,3:11.0
1,-1,3:49.0
-2,0,3:49.0
-1,0,3:49.0
0,0,3:11.0
1,0,3:11.0
2,0,3:49.0
-1,1,3:49.0
0,1,3:11.0
1,1,3:49.0
-1,2,3:49.0
0,2,3:49.0
0,-1,4:49.0
1,-1,4:49.0
2,0,4:49.0
0,1,4:49.0
1,1,4:49.0
-1,2,4:49.0
1,-1,5:49.0
2,0,5:49.0
1,1,5:49.0
1,-1,6:49.0
2,0,6:49.0
2,0,7:49.0
