[META]
version=2.0
spawnOnBlockType=2
spawnSunlight=True
spawnDarkness=True
spawnWater=False
spawnLava=False
underFill=False
spawnUnderground=True
randomRotation=True
dig=True
tree=False
branch=False
needsFoundation=True
rarity=20
collisionPercentage=20
spawnElevationMin=30
spawnElevationMax=200
spawnInBiome=CustomFloatingPlains
[DATA]
0,-2,0:18
-1,-1,0:18
0,-1,0:17.0
1,-1,0:18
-2,0,0:18
-1,0,0:17.0
0,0,0:17.0
1,0,0:17.0
2,0,0:18
-1,1,0:18
0,1,0:17.0
1,1,0:18
0,2,0:18
0,3,0:106.4
1,2,0:106.4
2,1,0:31.1
3,0,0:106.2
-3,0,0:106.8
2,-1,0:31.1
-2,-1,0:106.8
1,-2,0:31.1
-1,-2,0:106.8
0,-3,0:106.1
0,-1,-2:3
-1,0,-2:3
0,0,-2:17.0
1,0,-2:3
-1,-2,-2:106.8
0,-2,-1:2
1,-2,-1:2
-1,-1,-1:2
0,-1,-1:17.0
1,-1,-1:2
2,-1,-1:2
-2,0,-1:2
-1,0,-1:17.0
0,0,-1:3
1,0,-1:17.0
2,0,-1:2
-1,1,-1:2
0,1,-1:3
1,1,-1:2
2,1,-1:2
0,2,-1:2
1,2,-1:2
0,3,-1:106.4
3,0,-1:106.2
-3,0,-1:106.8
-1,-2,-1:106.8
0,-3,-1:106.1
-1,-1,1:18
0,-1,1:18
1,-1,1:18
-1,0,1:18
0,0,1:91.2
1,0,1:18
2,0,1:18
0,1,1:18
1,1,1:18
1,2,1:106.4
2,1,1:106.2
-1,1,1:106.8
3,0,1:106.2
2,-1,1:106.1
-2,-1,1:106.8
1,-2,1:106.1
0,-1,2:18
0,0,2:18
1,0,2:18
0,-2,2:106.1
