
#######################################################################
# +-----------------------------------------------------------------+ #
# |                            BO3 object                           | #
# +-----------------------------------------------------------------+ #
#######################################################################

Author: Unknown

Description: Converted version of the BO2 OakForestLarge5

Version: 3

SettingsMode: WriteWithoutComments


#######################################################################
# +-----------------------------------------------------------------+ #
# |                          Main settings                          | #
# +-----------------------------------------------------------------+ #
#######################################################################

Tree: true

Frequency: 1

Rarity: 10.0

RotateRandomly: true

SpawnHeight: highestSolidBlock

SpawnHeightOffset: 0

SpawnHeightVariance: 0

##############################
# Height Limits for the BO3. #
##############################

MinHeight: 62

MaxHeight: 210

######################
# Extrusion settings #
######################

ExtrudeMode: None

ExtrudeThroughBlocks: AIR

MaxBranchDepth: 10

ExcludedBiomes: All


#######################################################################
# +-----------------------------------------------------------------+ #
# |                      Source block settings                      | #
# +-----------------------------------------------------------------+ #
#######################################################################

SourceBlocks: AIR

MaxPercentageOutsideSourceBlock: 0

OutsideSourceBlock: placeAnyway

DoReplaceBlocks: true

IsOTGPlus: false


#######################################################################
# +-----------------------------------------------------------------+ #
# |                              Blocks                             | #
# +-----------------------------------------------------------------+ #
#######################################################################

Block(-6,8,-6,LEAVES:0)
Block(2,10,4,LEAVES:0)
Block(-6,7,-6,LEAVES:0)
Block(-2,7,-7,LEAVES:0)
Block(-2,15,-3,LEAVES:0)
Block(1,9,-4,LEAVES:0)
Block(-2,14,-3,LEAVES:0)
Block(-2,13,-3,LEAVES:0)
Block(-2,11,-3,LEAVES:0)
Block(-2,10,-3,LOG)
Block(2,11,-5,LEAVES:0)
Block(-4,9,1,LEAVES:0)
Block(-4,8,1,LEAVES:0)
Block(1,15,-1,LEAVES:0)
Block(1,14,-1,LEAVES:0)
Block(-4,7,1,LEAVES:0)
Block(-4,6,1,LEAVES:0)
Block(-4,5,1,LOG:4)
Block(-4,4,1,LEAVES:0)
Block(-3,8,3,LEAVES:0)
Block(1,10,2,LEAVES:0)
Block(0,10,-6,LEAVES:0)
Block(1,12,2,LEAVES:0)
Block(-3,9,3,LEAVES:0)
Block(1,13,-1,LEAVES:0)
Block(1,12,-1,LEAVES:0)
Block(-3,6,3,LOG)
Block(1,11,-1,LEAVES:0)
Block(-3,5,3,LEAVES:0)
Block(1,10,-1,LEAVES:0)
Block(-2,9,5,LEAVES:0)
Block(4,10,-2,LEAVES:0)
Block(-4,12,5,LEAVES:0)
Block(-2,8,5,LEAVES:0)
Block(4,11,-2,LEAVES:0)
Block(-7,7,-2,LEAVES:0)
Block(-2,7,5,LEAVES:0)
Block(-1,8,7,LEAVES:0)
Block(-1,9,7,LEAVES:0)
Block(-3,5,-1,LOG:8)
Block(-3,6,-1,LEAVES:0)
Block(-3,7,-1,LEAVES:0)
Block(-3,8,-1,LEAVES:0)
Block(-3,9,-1,LEAVES:0)
Block(-3,11,3,LEAVES:0)
Block(-3,10,3,LEAVES:0)
Block(-3,14,3,LEAVES:0)
Block(-3,13,3,LEAVES:0)
Block(-3,12,3,LEAVES:0)
Block(0,5,0,LEAVES:0)
Block(0,7,0,LEAVES:0)
Block(0,6,0,LEAVES:0)
Block(-6,9,-4,LEAVES:0)
Block(-6,8,-4,LEAVES:0)
Block(-6,7,-4,LEAVES:0)
Block(-6,6,-4,LEAVES:0)
Block(-2,9,-5,LEAVES:0)
Block(1,8,-2,LEAVES:0)
Block(1,9,-2,LEAVES:0)
Block(-2,6,-5,LEAVES:0)
Block(1,7,-2,LEAVES:0)
Block(-2,7,-5,LEAVES:0)
Block(-2,8,-5,LEAVES:0)
Block(0,7,-6,LEAVES:0)
Block(-4,8,-1,LEAVES:0)
Block(-4,7,-1,LEAVES:0)
Block(-4,9,-1,LEAVES:0)
Block(-4,10,3,LEAVES:0)
Block(-4,6,-1,LEAVES:0)
Block(-4,5,-1,LEAVES:0)
Block(-4,12,3,LEAVES:0)
Block(-5,8,1,LEAVES:0)
Block(-5,7,1,LEAVES:0)
Block(-5,9,1,LEAVES:0)
Block(-5,6,1,LEAVES:0)
Block(-5,5,1,LOG:4)
Block(-4,9,3,LEAVES:0)
Block(-4,8,3,LEAVES:0)
Block(-4,7,3,LEAVES:0)
Block(-4,6,3,LEAVES:0)
Block(-1,12,6,LEAVES:0)
Block(2,10,2,LEAVES:0)
Block(-1,10,6,LEAVES:0)
Block(-4,5,3,LEAVES:0)
Block(-3,9,5,LEAVES:0)
Block(-2,14,-5,LEAVES:0)
Block(-3,8,5,LEAVES:0)
Block(-3,7,5,LEAVES:0)
Block(-7,7,-4,LEAVES:0)
Block(-7,8,-4,LEAVES:0)
Block(-2,9,7,LEAVES:0)
Block(-2,8,7,LEAVES:0)
Block(-7,6,-4,LEAVES:0)
Block(-2,10,-5,LEAVES:0)
Block(2,8,-2,LEAVES:0)
Block(0,9,0,LEAVES:0)
Block(0,8,0,LEAVES:0)
Block(2,9,-2,LEAVES:0)
Block(0,8,-4,LEAVES:0)
Block(-2,9,-3,LEAVES:0)
Block(-2,8,-3,LEAVES:0)
Block(-2,7,-3,LEAVES:0)
Block(1,10,4,LEAVES:0)
Block(1,12,4,LEAVES:0)
Block(0,9,-4,LEAVES:0)
Block(-2,6,-3,LEAVES:0)
Block(-2,5,-3,LEAVES:0)
Block(-6,5,1,LEAVES:0)
Block(-4,6,-3,LEAVES:0)
Block(-4,5,-3,LOG:8)
Block(-4,8,-3,LEAVES:0)
Block(-4,7,-3,LEAVES:0)
Block(-1,7,-7,LEAVES:0)
Block(-6,8,1,LEAVES:0)
Block(-4,9,-3,LEAVES:0)
Block(-6,6,1,LEAVES:0)
Block(-5,5,3,LEAVES:0)
Block(-5,8,3,LEAVES:0)
Block(-5,7,3,LEAVES:0)
Block(-5,9,3,LEAVES:0)
Block(-3,10,5,LEAVES:0)
Block(-3,12,5,LEAVES:0)
Block(-3,13,5,LEAVES:0)
Block(-4,7,5,LEAVES:0)
Block(-4,9,5,LEAVES:0)
Block(-4,8,5,LEAVES:0)
Block(-2,12,-1,LEAVES:0)
Block(-2,13,-1,LEAVES:0)
Block(-2,10,-1,LEAVES:0)
Block(-3,9,7,LEAVES:0)
Block(-1,10,-1,LEAVES:0)
Block(-2,11,-1,LEAVES:0)
Block(-2,16,-1,LEAVES:0)
Block(-2,14,-1,LEAVES:0)
Block(-2,15,-1,LEAVES:0)
Block(-5,14,-2,LEAVES:0)
Block(-2,14,1,LOG)
Block(-1,15,-1,LEAVES:0)
Block(-2,13,1,LOG)
Block(-1,16,-1,LEAVES:0)
Block(-2,16,1,LEAVES:0)
Block(3,8,5,LEAVES:0)
Block(-2,15,1,LOG)
Block(-2,10,1,LOG)
Block(-1,11,-1,LEAVES:0)
Block(-2,12,1,LOG)
Block(-1,13,-1,LEAVES:0)
Block(-2,11,1,LOG)
Block(-1,14,-1,LEAVES:0)
Block(0,14,0,LOG:4)
Block(0,13,0,LEAVES:0)
Block(0,12,0,LEAVES:0)
Block(0,11,0,LEAVES:0)
Block(4,8,3,LEAVES:0)
Block(0,15,0,LEAVES:0)
Block(5,8,1,LEAVES:0)
Block(4,9,3,LEAVES:0)
Block(0,10,0,LEAVES:0)
Block(2,9,-4,LEAVES:0)
Block(2,8,-4,LEAVES:0)
Block(2,10,0,LEAVES:0)
Block(2,11,0,LEAVES:0)
Block(2,12,0,LEAVES:0)
Block(0,8,-2,LEAVES:0)
Block(0,7,-2,LEAVES:0)
Block(0,9,-2,LEAVES:0)
Block(2,13,0,LEAVES:0)
Block(2,14,0,LEAVES:0)
Block(-1,10,-3,LEAVES:0)
Block(-2,10,3,LEAVES:0)
Block(-1,12,-3,LEAVES:0)
Block(-2,9,-1,LEAVES:0)
Block(-1,11,-3,LEAVES:0)
Block(-7,6,1,LEAVES:0)
Block(-2,8,-1,LEAVES:0)
Block(-7,5,1,LEAVES:0)
Block(-2,7,-1,LEAVES:0)
Block(-2,6,-1,LEAVES:0)
Block(-2,5,-1,LOG:8)
Block(-4,6,-5,LEAVES:0)
Block(-4,5,-5,LEAVES:0)
Block(-6,9,3,LEAVES:0)
Block(-2,15,3,LEAVES:0)
Block(-6,8,3,LEAVES:0)
Block(-4,8,-5,LEAVES:0)
Block(-2,13,3,LEAVES:0)
Block(-1,14,-3,LEAVES:0)
Block(-4,7,-5,LEAVES:0)
Block(-2,14,3,LEAVES:0)
Block(-6,5,3,LEAVES:0)
Block(-2,11,3,LEAVES:0)
Block(-2,12,3,LEAVES:0)
Block(-1,15,-3,LEAVES:0)
Block(-5,8,5,LEAVES:0)
Block(0,13,2,LEAVES:0)
Block(0,14,2,LEAVES:0)
Block(0,10,2,LEAVES:0)
Block(-4,15,-2,LEAVES:0)
Block(5,9,-1,LEAVES:0)
Block(0,11,2,LEAVES:0)
Block(-4,14,-2,LEAVES:0)
Block(0,12,2,LEAVES:0)
Block(-4,14,1,LEAVES:0)
Block(-4,13,1,LEAVES:0)
Block(-4,11,1,LEAVES:0)
Block(-4,10,1,LEAVES:0)
Block(5,9,3,LEAVES:0)
Block(1,9,4,LEAVES:0)
Block(1,8,4,LEAVES:0)
Block(1,7,4,LEAVES:0)
Block(3,8,-3,LEAVES:0)
Block(3,9,-3,LEAVES:0)
Block(-8,5,1,LEAVES:0)
Block(2,9,2,LEAVES:0)
Block(2,8,2,LEAVES:0)
Block(2,7,2,LEAVES:0)
Block(-5,5,-2,LEAVES:0)
Block(-7,8,3,LEAVES:0)
Block(-5,6,-2,LEAVES:0)
Block(-5,7,-2,LEAVES:0)
Block(-5,8,-2,LEAVES:0)
Block(-1,5,0,LEAVES:0)
Block(3,8,0,LOG)
Block(3,7,0,LEAVES:0)
Block(-1,7,0,LEAVES:0)
Block(-1,6,0,LEAVES:0)
Block(-1,9,0,LEAVES:0)
Block(-1,8,0,LEAVES:0)
Block(3,9,0,LEAVES:0)
Block(-4,7,-7,LEAVES:0)
Block(-5,10,2,LEAVES:0)
Block(-3,10,-3,LEAVES:0)
Block(-8,7,-4,LEAVES:0)
Block(-1,6,-2,LEAVES:0)
Block(0,16,-1,LEAVES:0)
Block(0,15,-1,LEAVES:0)
Block(-1,9,-2,LEAVES:0)
Block(-1,8,-2,LEAVES:0)
Block(-1,10,2,LEAVES:0)
Block(-3,11,-3,LEAVES:0)
Block(0,10,-1,LOG:4)
Block(-1,12,2,LEAVES:0)
Block(-3,14,-3,LEAVES:0)
Block(-1,11,2,LEAVES:0)
Block(0,12,-1,LEAVES:0)
Block(-1,14,2,LEAVES:0)
Block(0,11,-1,LEAVES:0)
Block(-1,13,2,LEAVES:0)
Block(-3,15,-3,LEAVES:0)
Block(0,9,6,LEAVES:0)
Block(0,14,-1,LEAVES:0)
Block(0,8,6,LEAVES:0)
Block(0,13,-1,LEAVES:0)
Block(-1,15,2,LEAVES:0)
Block(1,8,6,LEAVES:0)
Block(2,9,4,LEAVES:0)
Block(2,8,4,LEAVES:0)
Block(-1,5,2,LEAVES:0)
Block(-1,7,2,LEAVES:0)
Block(-1,6,2,LEAVES:0)
Block(3,9,2,LOG)
Block(3,8,2,LEAVES:0)
Block(-1,9,2,LEAVES:0)
Block(3,7,2,LEAVES:0)
Block(-1,8,2,LEAVES:0)
Block(3,11,-3,LEAVES:0)
Block(-2,9,0,LEAVES:0)
Block(3,10,-3,LEAVES:0)
Block(-2,8,0,LOG:8)
Block(-2,7,0,LEAVES:0)
Block(3,12,-3,LEAVES:0)
Block(-2,6,0,LEAVES:0)
Block(-2,5,0,LOG:8)
Block(-2,4,0,LEAVES:0)
Block(-1,15,0,LEAVES:0)
Block(-1,16,0,LEAVES:0)
Block(4,9,0,LEAVES:0)
Block(4,8,0,LEAVES:0)
Block(-1,10,0,LEAVES:0)
Block(-1,11,0,LEAVES:0)
Block(-1,12,0,LEAVES:0)
Block(-1,13,0,LEAVES:0)
Block(-1,14,0,LEAVES:0)
Block(1,11,-5,LEAVES:0)
Block(-2,12,5,LEAVES:0)
Block(-2,11,5,LEAVES:0)
Block(-1,14,-5,LEAVES:0)
Block(-2,10,5,LEAVES:0)
Block(-1,11,-5,LEAVES:0)
Block(-1,10,-5,LEAVES:0)
Block(3,10,1,LEAVES:0)
Block(-1,9,-4,LEAVES:0)
Block(-1,8,-4,LEAVES:0)
Block(-1,7,-4,LEAVES:0)
Block(-1,6,-4,LEAVES:0)
Block(-2,13,5,LEAVES:0)
Block(0,11,4,LEAVES:0)
Block(0,12,4,LEAVES:0)
Block(0,10,4,LEAVES:0)
Block(1,9,0,LEAVES:0)
Block(-1,10,4,LEAVES:0)
Block(1,8,0,LEAVES:0)
Block(1,7,0,LEAVES:0)
Block(-2,10,7,LEAVES:0)
Block(-5,7,-6,LEAVES:0)
Block(1,10,-3,LEAVES:0)
Block(-5,8,-6,LEAVES:0)
Block(1,11,-3,LEAVES:0)
Block(1,12,-3,LEAVES:0)
Block(1,14,-3,LEAVES:0)
Block(-3,7,0,LEAVES:0)
Block(-3,6,0,LEAVES:0)
Block(-3,9,0,LEAVES:0)
Block(-3,8,0,LEAVES:0)
Block(-5,6,-6,LEAVES:0)
Block(-3,5,0,LEAVES:0)
Block(-3,4,0,LEAVES:0)
Block(-7,7,-5,LEAVES:0)
Block(-7,8,-5,LEAVES:0)
Block(-1,7,4,LEAVES:0)
Block(-2,9,2,LEAVES:0)
Block(-2,8,2,LEAVES:0)
Block(-1,9,4,LEAVES:0)
Block(-2,7,2,LEAVES:0)
Block(-1,8,4,LEAVES:0)
Block(-2,6,2,LEAVES:0)
Block(-2,5,2,LOG:8)
Block(-2,4,2,LEAVES:0)
Block(-1,13,4,LEAVES:0)
Block(-1,11,4,LEAVES:0)
Block(-1,12,4,LEAVES:0)
Block(-6,7,-1,LEAVES:0)
Block(-6,6,-1,LEAVES:0)
Block(-6,5,-1,LEAVES:0)
Block(4,8,-2,LEAVES:0)
Block(4,9,-2,LEAVES:0)
Block(4,10,2,LEAVES:0)
Block(2,11,-3,LEAVES:0)
Block(2,12,-3,LEAVES:0)
Block(2,10,-3,LEAVES:0)
Block(-3,5,-5,LEAVES:0)
Block(-3,6,-5,LEAVES:0)
Block(1,6,0,LEAVES:0)
Block(0,7,2,LEAVES:0)
Block(0,6,2,LEAVES:0)
Block(-3,7,-5,LOG)
Block(-3,8,-5,LEAVES:0)
Block(0,9,2,LEAVES:0)
Block(0,8,2,LEAVES:0)
Block(-4,9,0,LEAVES:0)
Block(1,9,2,LEAVES:0)
Block(1,8,2,LEAVES:0)
Block(1,7,2,LEAVES:0)
Block(1,6,2,LEAVES:0)
Block(-4,8,0,LEAVES:0)
Block(-4,7,0,LEAVES:0)
Block(-4,6,0,LEAVES:0)
Block(-4,5,0,LEAVES:0)
Block(-5,9,-4,LEAVES:0)
Block(2,7,0,LEAVES:0)
Block(-3,9,2,LEAVES:0)
Block(-3,8,2,LEAVES:0)
Block(2,9,0,LEAVES:0)
Block(2,8,0,LEAVES:0)
Block(-3,5,2,LEAVES:0)
Block(-3,4,2,LEAVES:0)
Block(-3,6,2,LEAVES:0)
Block(-5,7,-4,LOG)
Block(-5,8,-4,LEAVES:0)
Block(-5,5,-4,LEAVES:0)
Block(-5,6,-4,LEAVES:0)
Block(5,10,-1,LEAVES:0)
Block(1,15,0,LEAVES:0)
Block(-2,9,4,LEAVES:0)
Block(1,14,0,LEAVES:0)
Block(-2,8,4,LOG)
Block(1,13,0,LEAVES:0)
Block(-2,7,4,LEAVES:0)
Block(1,12,0,LEAVES:0)
Block(-2,6,4,LEAVES:0)
Block(-1,7,6,LEAVES:0)
Block(1,11,0,LEAVES:0)
Block(1,10,0,LEAVES:0)
Block(-1,9,6,LEAVES:0)
Block(-1,8,6,LEAVES:0)
Block(2,14,-1,LEAVES:0)
Block(2,13,-1,LEAVES:0)
Block(2,15,-1,LEAVES:0)
Block(2,10,-1,LEAVES:0)
Block(2,12,-1,LEAVES:0)
Block(2,11,-1,LEAVES:0)
Block(0,11,-3,LEAVES:0)
Block(0,12,-3,LEAVES:0)
Block(0,10,-3,LEAVES:0)
Block(0,13,-3,LEAVES:0)
Block(0,14,-3,LEAVES:0)
Block(-3,12,1,LEAVES:0)
Block(-3,13,1,LEAVES:0)
Block(-3,10,1,LEAVES:0)
Block(-3,11,1,LEAVES:0)
Block(4,10,-1,LEAVES:0)
Block(-3,14,1,LEAVES:0)
Block(-3,15,1,LEAVES:0)
Block(-5,14,0,LEAVES:0)
Block(4,11,-1,LEAVES:0)
Block(3,10,-1,LEAVES:0)
Block(3,11,-1,LEAVES:0)
Block(-3,5,-3,LEAVES:0)
Block(-3,6,-3,LEAVES:0)
Block(3,14,-1,LEAVES:0)
Block(-3,7,-3,LEAVES:0)
Block(-3,8,-3,LEAVES:0)
Block(-3,9,-3,LEAVES:0)
Block(0,7,4,LEAVES:0)
Block(0,9,4,LEAVES:0)
Block(0,8,4,LEAVES:0)
Block(-4,9,2,LEAVES:0)
Block(-4,8,2,LEAVES:0)
Block(-4,7,2,LOG)
Block(4,11,-3,LEAVES:0)
Block(-4,6,2,LEAVES:0)
Block(-4,5,2,LEAVES:0)
Block(-3,7,4,LOG:8)
Block(-3,6,4,LEAVES:0)
Block(-3,9,4,LEAVES:0)
Block(-3,8,4,LEAVES:0)
Block(-4,15,-1,LEAVES:0)
Block(-4,14,-1,LOG)
Block(-4,13,-1,LEAVES:0)
Block(-3,10,2,LEAVES:0)
Block(-3,14,2,LEAVES:0)
Block(-3,13,2,LEAVES:0)
Block(-3,12,2,LEAVES:0)
Block(-2,9,6,LEAVES:0)
Block(-3,11,2,LEAVES:0)
Block(-2,8,6,LEAVES:0)
Block(-2,7,6,LEAVES:0)
Block(-3,15,2,LEAVES:0)
Block(-1,9,8,LEAVES:0)
Block(-1,8,8,LEAVES:0)
Block(-3,5,-2,LOG:8)
Block(-3,6,-2,LEAVES:0)
Block(1,10,1,LEAVES:0)
Block(-3,7,-2,LEAVES:0)
Block(1,11,1,LEAVES:0)
Block(-3,8,-2,LEAVES:0)
Block(1,12,1,LEAVES:0)
Block(-3,9,-2,LEAVES:0)
Block(1,13,1,LEAVES:0)
Block(1,14,1,LEAVES:0)
Block(-7,5,-1,LEAVES:0)
Block(-6,9,-5,LEAVES:0)
Block(-6,8,-5,LEAVES:0)
Block(-6,7,-5,LEAVES:0)
Block(-2,10,-4,LEAVES:0)
Block(-6,6,-5,LEAVES:0)
Block(-2,11,-4,LEAVES:0)
Block(1,9,-3,LEAVES:0)
Block(1,8,-3,LEAVES:0)
Block(-5,9,0,LEAVES:0)
Block(-5,8,0,LEAVES:0)
Block(-5,5,0,LEAVES:0)
Block(-5,7,0,LEAVES:0)
Block(-5,6,0,LEAVES:0)
Block(-4,8,4,LEAVES:0)
Block(-4,7,4,LEAVES:0)
Block(-2,16,0,LEAVES:0)
Block(-4,9,4,LEAVES:0)
Block(-2,13,0,LEAVES:0)
Block(-2,12,0,LEAVES:0)
Block(-2,15,0,LEAVES:0)
Block(-2,14,0,LEAVES:0)
Block(-2,11,0,LEAVES:0)
Block(-2,10,0,LEAVES:0)
Block(-3,9,6,LEAVES:0)
Block(-3,8,6,LEAVES:0)
Block(-1,12,5,LEAVES:0)
Block(-7,8,-3,LEAVES:0)
Block(-4,10,-3,LEAVES:0)
Block(-2,9,8,LEAVES:0)
Block(2,12,3,LEAVES:0)
Block(2,10,3,LEAVES:0)
Block(-4,14,-3,LEAVES:0)
Block(-7,6,-3,LEAVES:0)
Block(-7,7,-3,LEAVES:0)
Block(4,10,0,LEAVES:0)
Block(-2,14,-4,LEAVES:0)
Block(-2,15,-4,LEAVES:0)
Block(0,8,1,LEAVES:0)
Block(2,9,-1,LEAVES:0)
Block(0,7,1,LEAVES:0)
Block(2,8,-1,LEAVES:0)
Block(2,7,-1,LEAVES:0)
Block(0,9,1,LEAVES:0)
Block(-4,12,4,LEAVES:0)
Block(-6,8,-3,LEAVES:0)
Block(-6,7,-3,LEAVES:0)
Block(-6,6,-3,LEAVES:0)
Block(-2,8,-6,LEAVES:0)
Block(1,9,-1,LEAVES:0)
Block(1,7,-1,LEAVES:0)
Block(2,11,-4,LEAVES:0)
Block(1,8,-1,LEAVES:0)
Block(2,10,-4,LEAVES:0)
Block(-2,6,-6,LEAVES:0)
Block(-2,7,-6,LEAVES:0)
Block(-3,12,4,LEAVES:0)
Block(-3,11,4,LEAVES:0)
Block(-3,10,4,LEAVES:0)
Block(-6,6,0,LEAVES:0)
Block(-6,5,0,LOG:4)
Block(-3,13,4,LEAVES:0)
Block(-5,7,2,LEAVES:0)
Block(-5,6,2,LEAVES:0)
Block(-5,9,2,LEAVES:0)
Block(1,10,3,LEAVES:0)
Block(-5,8,2,LOG)
Block(0,10,-5,LEAVES:0)
Block(1,12,3,LEAVES:0)
Block(1,11,3,LEAVES:0)
Block(0,11,-5,LEAVES:0)
Block(-5,5,2,LEAVES:0)
Block(-4,9,6,LEAVES:0)
Block(-4,11,2,LEAVES:0)
Block(-4,10,2,LEAVES:0)
Block(0,15,1,LEAVES:0)
Block(0,14,1,LEAVES:0)
Block(0,13,1,LEAVES:0)
Block(0,12,1,LEAVES:0)
Block(0,11,1,LEAVES:0)
Block(0,10,1,LEAVES:0)
Block(3,8,4,LEAVES:0)
Block(3,9,4,LEAVES:0)
Block(-1,10,-2,LEAVES:0)
Block(-1,11,-2,LEAVES:0)
Block(4,9,2,LEAVES:0)
Block(4,8,2,LEAVES:0)
Block(5,9,0,LEAVES:0)
Block(5,8,0,LEAVES:0)
Block(2,9,-3,LEAVES:0)
Block(2,8,-3,LEAVES:0)
Block(0,7,-5,LEAVES:0)
Block(-7,5,0,LEAVES:0)
Block(-2,6,-4,LEAVES:0)
Block(-2,7,-4,LEAVES:0)
Block(-2,8,-4,LEAVES:0)
Block(-2,9,-4,LEAVES:0)
Block(0,9,-5,LEAVES:0)
Block(-2,5,-4,LEAVES:0)
Block(-7,6,0,LEAVES:0)
Block(-4,7,-2,LEAVES:0)
Block(2,11,1,LEAVES:0)
Block(-4,6,-2,LEAVES:0)
Block(2,10,1,LEAVES:0)
Block(-4,9,-2,LEAVES:0)
Block(-4,8,-2,LEAVES:0)
Block(-4,5,-2,LEAVES:0)
Block(-1,8,-6,LEAVES:0)
Block(-1,7,-6,LEAVES:0)
Block(-6,9,2,LEAVES:0)
Block(-6,8,2,LEAVES:0)
Block(-6,7,2,LEAVES:0)
Block(2,14,1,LEAVES:0)
Block(-6,6,2,LEAVES:0)
Block(-6,5,2,LEAVES:0)
Block(-5,7,4,LEAVES:0)
Block(-5,9,4,LEAVES:0)
Block(-5,8,4,LEAVES:0)
Block(-4,14,2,LEAVES:0)
Block(3,8,-1,LEAVES:0)
Block(3,9,-1,LEAVES:0)
Block(-2,10,-2,LEAVES:0)
Block(-3,12,6,LEAVES:0)
Block(3,10,3,LEAVES:0)
Block(-3,10,6,LEAVES:0)
Block(-4,14,0,LEAVES:0)
Block(-4,15,0,LEAVES:0)
Block(-4,13,0,LEAVES:0)
Block(-4,10,0,LEAVES:0)
Block(5,9,2,LEAVES:0)
Block(4,9,4,LEAVES:0)
Block(-3,10,-1,LEAVES:0)
Block(-3,12,-1,LEAVES:0)
Block(2,9,-5,LEAVES:0)
Block(-3,13,-1,LEAVES:0)
Block(-3,14,-1,LEAVES:0)
Block(-3,15,-1,LEAVES:0)
Block(-3,16,-1,LEAVES:0)
Block(-5,14,-1,LEAVES:0)
Block(0,7,-3,LEAVES:0)
Block(0,9,-3,LEAVES:0)
Block(-6,7,-7,LEAVES:0)
Block(0,8,-3,LEAVES:0)
Block(-2,16,2,LEAVES:0)
Block(-2,14,2,LEAVES:0)
Block(-8,5,0,LEAVES:0)
Block(-2,15,2,LEAVES:0)
Block(-1,12,-2,LEAVES:0)
Block(-2,12,2,LEAVES:0)
Block(-1,13,-2,LEAVES:0)
Block(-2,13,2,LEAVES:0)
Block(-2,10,2,LEAVES:0)
Block(-1,14,-2,LEAVES:0)
Block(-2,11,2,LOG:8)
Block(-1,15,-2,LEAVES:0)
Block(-2,9,-2,LOG:8)
Block(-2,8,-2,LEAVES:0)
Block(-7,8,2,LEAVES:0)
Block(-7,5,2,LEAVES:0)
Block(-2,6,-2,LEAVES:0)
Block(-2,5,-2,LEAVES:0)
Block(-4,5,-4,LEAVES:0)
Block(-4,7,-4,LEAVES:0)
Block(-4,6,-4,LOG)
Block(-6,8,4,LEAVES:0)
Block(-4,9,-4,LEAVES:0)
Block(-4,8,-4,LEAVES:0)
Block(-2,14,-2,LEAVES:0)
Block(-2,13,-2,LEAVES:0)
Block(-2,12,-2,LEAVES:0)
Block(-2,11,-2,LEAVES:0)
Block(-2,16,-2,LEAVES:0)
Block(-2,15,-2,LEAVES:0)
Block(5,9,-2,LEAVES:0)
Block(3,11,-4,LEAVES:0)
Block(-1,15,-4,LEAVES:0)
Block(-1,14,-4,LEAVES:0)
Block(-2,14,4,LEAVES:0)
Block(-2,13,4,LOG)
Block(-2,12,4,LEAVES:0)
Block(-1,16,1,LEAVES:0)
Block(-3,10,-2,LEAVES:0)
Block(-1,10,1,LEAVES:0)
Block(-3,13,-2,LEAVES:0)
Block(-1,11,1,LEAVES:0)
Block(-1,12,1,LEAVES:0)
Block(-3,15,-2,LEAVES:0)
Block(-8,7,-5,LEAVES:0)
Block(-1,13,1,LOG:4)
Block(-3,14,-2,LEAVES:0)
Block(-1,14,1,LEAVES:0)
Block(-1,15,1,LEAVES:0)
Block(-1,9,-3,LEAVES:0)
Block(-1,8,-3,LEAVES:0)
Block(-1,7,-3,LEAVES:0)
Block(-1,6,-3,LEAVES:0)
Block(0,9,7,LEAVES:0)
Block(3,10,2,LEAVES:0)
Block(0,8,7,LEAVES:0)
Block(1,9,5,LEAVES:0)
Block(1,8,5,LEAVES:0)
Block(0,7,-1,LEAVES:0)
Block(3,8,-2,LEAVES:0)
Block(0,6,-1,LEAVES:0)
Block(3,9,-2,LEAVES:0)
Block(0,9,-1,LEAVES:0)
Block(0,8,-1,LEAVES:0)
Block(2,8,3,LEAVES:0)
Block(2,7,3,LEAVES:0)
Block(2,9,3,LEAVES:0)
Block(0,10,3,LEAVES:0)
Block(-5,5,-3,LEAVES:0)
Block(0,11,3,LEAVES:0)
Block(0,12,3,LEAVES:0)
Block(0,13,3,LEAVES:0)
Block(-5,8,-3,LEAVES:0)
Block(-5,9,-3,LEAVES:0)
Block(-5,6,-3,LEAVES:0)
Block(-5,7,-3,LEAVES:0)
Block(3,7,1,LEAVES:0)
Block(3,9,1,LEAVES:0)
Block(3,8,1,LEAVES:0)
Block(-4,7,-6,LEAVES:0)
Block(-4,6,-6,LEAVES:0)
Block(-1,11,-4,LEAVES:0)
Block(-2,11,4,LEAVES:0)
Block(-1,10,-4,LEAVES:0)
Block(-2,10,4,LEAVES:0)
Block(0,12,5,LEAVES:0)
Block(0,10,5,LEAVES:0)
Block(-3,10,-4,LEAVES:0)
Block(-1,9,-5,LEAVES:0)
Block(-1,8,-5,LEAVES:0)
Block(-1,7,-5,LEAVES:0)
Block(-1,6,-5,LEAVES:0)
Block(1,10,-4,LEAVES:0)
Block(-2,12,6,LEAVES:0)
Block(-2,11,6,LEAVES:0)
Block(1,12,-4,LEAVES:0)
Block(-2,10,6,LEAVES:0)
Block(1,11,-4,LEAVES:0)
Block(-1,10,-6,LEAVES:0)
Block(3,9,-4,LEAVES:0)
Block(-5,10,3,LEAVES:0)
Block(2,8,5,LEAVES:0)
Block(-5,6,-1,LEAVES:0)
Block(-3,14,-4,LEAVES:0)
Block(-5,7,-1,LEAVES:0)
Block(-5,5,-1,LEAVES:0)
Block(-5,8,-1,LEAVES:0)
Block(-1,4,1,LEAVES:0)
Block(-1,6,1,LOG:4)
Block(-1,5,1,LEAVES:0)
Block(-1,8,1,LEAVES:0)
Block(3,9,3,LEAVES:0)
Block(-1,7,1,LEAVES:0)
Block(3,8,3,LEAVES:0)
Block(-1,9,1,LEAVES:0)
Block(4,8,1,LEAVES:0)
Block(4,9,1,LEAVES:0)
Block(-6,8,-2,LEAVES:0)
Block(-6,7,-2,LEAVES:0)
Block(-6,6,-2,LEAVES:0)
Block(-6,5,-2,LEAVES:0)
Block(-2,10,-6,LEAVES:0)
Block(2,14,-2,LEAVES:0)
Block(2,12,-2,LEAVES:0)
Block(2,10,-2,LEAVES:0)
Block(2,11,-2,LEAVES:0)
Block(4,9,-3,LEAVES:0)
Block(0,12,-4,LEAVES:0)
Block(0,10,-4,LEAVES:0)
Block(0,11,-4,LEAVES:0)
Block(0,14,-4,LEAVES:0)
Block(0,6,3,LEAVES:0)
Block(-3,6,-6,LEAVES:0)
Block(-3,7,-6,LEAVES:0)
Block(0,8,3,LEAVES:0)
Block(0,7,3,LEAVES:0)
Block(0,9,3,LEAVES:0)
Block(1,9,1,LEAVES:0)
Block(1,8,1,LEAVES:0)
Block(0,6,1,LOG:4)
Block(1,7,1,LOG)
Block(0,5,1,LEAVES:0)
Block(1,6,1,LEAVES:0)
Block(3,10,-2,LEAVES:0)
Block(3,11,-2,LEAVES:0)
Block(3,12,-2,LEAVES:0)
Block(-5,7,-7,LEAVES:0)
Block(-3,11,0,LEAVES:0)
Block(-3,12,0,LEAVES:0)
Block(-7,7,-6,LEAVES:0)
Block(-3,10,0,LEAVES:0)
Block(-1,6,3,LEAVES:0)
Block(-1,10,5,LEAVES:0)
Block(-3,15,0,LEAVES:0)
Block(-3,16,0,LEAVES:0)
Block(-1,8,3,LEAVES:0)
Block(-3,13,0,LOG:8)
Block(-1,7,3,LEAVES:0)
Block(-3,14,0,LEAVES:0)
Block(-2,9,1,LOG)
Block(-2,8,1,LOG)
Block(-1,9,3,LEAVES:0)
Block(-2,7,1,LOG)
Block(-2,6,1,LOG)
Block(-2,5,1,LOG)
Block(-2,4,1,LOG)
Block(-2,3,1,LOG)
Block(-2,2,1,LOG)
Block(-2,1,1,LOG)
Block(-2,0,1,LOG)
Block(3,14,0,LEAVES:0)
Block(3,11,0,LEAVES:0)
Block(3,10,0,LEAVES:0)
Block(-5,10,1,LEAVES:0)
Block(4,9,-1,LOG)
Block(4,8,-1,LEAVES:0)
Block(-8,7,-3,LEAVES:0)
Block(-1,7,-1,LEAVES:0)
Block(-1,6,-1,LEAVES:0)
Block(-1,5,-1,LEAVES:0)
Block(-1,9,-1,LOG)
Block(-1,8,-1,LEAVES:0)
Block(-3,5,-4,LEAVES:0)
Block(-3,6,-4,LEAVES:0)
Block(-3,7,-4,LEAVES:0)
Block(-3,8,-4,LEAVES:0)
Block(-3,9,-4,LEAVES:0)
Block(0,8,5,LEAVES:0)
Block(0,7,5,LEAVES:0)
Block(0,9,5,LEAVES:0)
Block(1,9,3,LEAVES:0)
Block(1,8,3,LEAVES:0)
Block(1,7,3,LEAVES:0)
Block(1,9,-5,LEAVES:0)
Block(2,9,1,LEAVES:0)
Block(-5,8,-5,LEAVES:0)
Block(-5,9,-5,LEAVES:0)
Block(2,6,1,LEAVES:0)
Block(-3,9,1,LEAVES:0)
Block(2,8,1,LOG)
Block(2,7,1,LEAVES:0)
Block(-3,6,1,LEAVES:0)
Block(-1,11,3,LEAVES:0)
Block(-3,5,1,LOG:4)
Block(-1,10,3,LEAVES:0)
Block(-3,8,1,LEAVES:0)
Block(0,11,-2,LEAVES:0)
Block(-1,13,3,LEAVES:0)
Block(-3,7,1,LEAVES:0)
Block(0,10,-2,LEAVES:0)
Block(-1,12,3,LOG)
Block(-5,6,-5,LEAVES:0)
Block(0,13,-2,LEAVES:0)
Block(-5,7,-5,LEAVES:0)
Block(0,12,-2,LEAVES:0)
Block(-1,14,3,LEAVES:0)
Block(-3,4,1,LOG:4)
Block(0,15,-2,LEAVES:0)
Block(0,14,-2,LEAVES:0)
Block(-2,9,3,LEAVES:0)
Block(-2,8,3,LEAVES:0)
Block(-2,7,3,LEAVES:0)
Block(-1,8,5,LEAVES:0)
Block(1,15,-2,LEAVES:0)
Block(-2,6,3,LEAVES:0)
Block(-1,7,5,LEAVES:0)
Block(-2,5,3,LEAVES:0)
Block(-1,9,5,LOG)
Block(1,10,-2,LEAVES:0)
Block(1,11,-2,LOG)
Block(1,12,-2,LEAVES:0)
Block(1,13,-2,LEAVES:0)
Block(1,14,-2,LEAVES:0)

#######################################################################
# +-----------------------------------------------------------------+ #
# |                            BO3 checks                           | #
# +-----------------------------------------------------------------+ #
#######################################################################

BlockCheck(-2,-1,1,GRASS,DIRT,DIRT:2)

#######################################################################
# +-----------------------------------------------------------------+ #
# |                             Branches                            | #
# +-----------------------------------------------------------------+ #
#######################################################################


#######################################################################
# +-----------------------------------------------------------------+ #
# |                             Entities                            | #
# +-----------------------------------------------------------------+ #
#######################################################################


#######################################################################
# +-----------------------------------------------------------------+ #
# |                            Particles                            | #
# +-----------------------------------------------------------------+ #
#######################################################################


#######################################################################
# +-----------------------------------------------------------------+ #
# |                             Spawners                            | #
# +-----------------------------------------------------------------+ #
#######################################################################


#######################################################################
# +-----------------------------------------------------------------+ #
# |                             ModData                             | #
# +-----------------------------------------------------------------+ #
#######################################################################

