
#######################################################################
# +-----------------------------------------------------------------+ #
# |                            BO3 object                           | #
# +-----------------------------------------------------------------+ #
#######################################################################

Author: Unknown

Description: Converted version of the BO2 OakMangroveTree8

Version: 3

SettingsMode: WriteWithoutComments


#######################################################################
# +-----------------------------------------------------------------+ #
# |                          Main settings                          | #
# +-----------------------------------------------------------------+ #
#######################################################################

Tree: true

Frequency: 1

Rarity: 10.0

RotateRandomly: true

SpawnHeight: highestSolidBlock

SpawnHeightOffset: 0

SpawnHeightVariance: 0

##############################
# Height Limits for the BO3. #
##############################

MinHeight: 59

MaxHeight: 67

######################
# Extrusion settings #
######################

ExtrudeMode: None

ExtrudeThroughBlocks: AIR

MaxBranchDepth: 10

ExcludedBiomes: All


#######################################################################
# +-----------------------------------------------------------------+ #
# |                      Source block settings                      | #
# +-----------------------------------------------------------------+ #
#######################################################################

SourceBlocks: STONE:1,STONE:3,STONE:5,DIRT:1,DIRT,SAND,GRASS,DIRT:2,STATIONARY_WATER,HARD_CLAY,STAINED_CLAY,CLAY,SANDSTONE,SAND:1,AIR,STONE,GRAVEL,LONG_GRASS,LONG_GRASS:1,LONG_GRASS:2,DEAD_BUSH,YELLOW_FLOWER,RED_ROSE,BROWN_MUSHROOM,RED_MUSHROOM,WATER_LILY,WATER

MaxPercentageOutsideSourceBlock: 0

OutsideSourceBlock: placeAnyway


#######################################################################
# +-----------------------------------------------------------------+ #
# |                              Blocks                             | #
# +-----------------------------------------------------------------+ #
#######################################################################

B(-3,1,0,biomesoplenty:log_1:6)
B(5,10,2,biomesoplenty:leaves_4:0)
B(1,9,0,biomesoplenty:leaves_4:0)
B(-4,10,2,biomesoplenty:leaves_4:0)
B(1,10,-3,biomesoplenty:leaves_4:0)
B(2,10,-2,biomesoplenty:leaves_4:0)
B(0,9,-4,biomesoplenty:leaves_4:0)
B(-3,10,-2,biomesoplenty:leaves_4:0)
B(0,10,-4,biomesoplenty:leaves_4:0)
B(-1,10,1,biomesoplenty:leaves_4:0)
B(-3,10,2,biomesoplenty:log_1:6)
B(-4,10,-1,biomesoplenty:leaves_4:0)
B(0,10,1,biomesoplenty:leaves_4:0)
B(-1,5,0,biomesoplenty:log_1:6)
B(-1,4,0,biomesoplenty:log_1:6)
B(-1,7,0,biomesoplenty:log_1:6)
B(-1,6,0,biomesoplenty:log_1:6)
B(-3,11,2,biomesoplenty:leaves_4:0)
B(-1,9,0,biomesoplenty:log_1:6)
B(-1,8,0,biomesoplenty:log_1:6)
B(3,9,0,biomesoplenty:leaves_4:0)
B(-2,9,2,biomesoplenty:leaves_4:0)
B(-1,9,-3,biomesoplenty:leaves_4:0)
B(-2,10,-3,biomesoplenty:leaves_4:0)
B(-2,0,2,biomesoplenty:log_1:6)
B(-5,10,2,biomesoplenty:leaves_4:0)
B(-1,10,-2,biomesoplenty:log_1:6)
B(-1,11,-2,biomesoplenty:leaves_4:0)
B(1,10,1,biomesoplenty:leaves_4:0)
B(3,10,2,biomesoplenty:leaves_4:0)
B(-3,10,5,biomesoplenty:leaves_4:0)
B(0,2,1,biomesoplenty:log_1:6)
B(0,1,1,biomesoplenty:log_1:6)
B(0,9,-1,biomesoplenty:leaves_4:0)
B(1,9,1,biomesoplenty:leaves_4:0)
B(-3,10,-3,biomesoplenty:leaves_4:0)
B(-2,10,-4,biomesoplenty:leaves_4:0)
B(3,10,-2,biomesoplenty:leaves_4:0)
B(0,1,-1,biomesoplenty:log_1:6)
B(0,2,-1,biomesoplenty:log_1:6)
B(-2,10,-1,biomesoplenty:leaves_4:0)
B(-1,10,-1,biomesoplenty:log_1:6)
B(-2,11,-1,biomesoplenty:leaves_4:0)
B(1,10,2,biomesoplenty:leaves_4:0)
B(0,10,-6,biomesoplenty:leaves_4:0)
B(1,11,-1,biomesoplenty:leaves_4:0)
B(1,10,-1,biomesoplenty:leaves_4:0)
B(-3,11,0,biomesoplenty:leaves_4:0)
B(2,11,1,biomesoplenty:leaves_4:0)
B(2,10,1,biomesoplenty:leaves_4:0)
B(5,10,1,biomesoplenty:leaves_4:0)
B(-3,10,0,biomesoplenty:leaves_4:0)
B(3,9,1,biomesoplenty:leaves_4:0)
B(-2,9,1,biomesoplenty:leaves_4:0)
B(-2,10,1,biomesoplenty:log_1:6)
B(-1,11,-1,biomesoplenty:leaves_4:0)
B(-1,9,-2,biomesoplenty:leaves_4:0)
B(-3,0,-1,biomesoplenty:log_1:6)
B(4,10,2,biomesoplenty:leaves_4:0)
B(-2,11,1,biomesoplenty:leaves_4:0)
B(-1,10,-4,biomesoplenty:leaves_4:0)
B(0,11,0,biomesoplenty:leaves_4:0)
B(2,10,-3,biomesoplenty:leaves_4:0)
B(-1,10,2,biomesoplenty:leaves_4:0)
B(6,10,0,biomesoplenty:leaves_4:0)
B(0,10,-1,biomesoplenty:leaves_4:0)
B(0,10,0,biomesoplenty:log_1:6)
B(3,11,0,biomesoplenty:leaves_4:0)
B(3,10,0,biomesoplenty:log_1:6)
B(-3,10,3,biomesoplenty:leaves_4:0)
B(0,11,-1,biomesoplenty:leaves_4:0)
B(-1,0,3,biomesoplenty:log_1:6)
B(2,10,0,biomesoplenty:log_1:6)
B(2,11,0,biomesoplenty:leaves_4:0)
B(0,9,-2,biomesoplenty:leaves_4:0)
B(0,0,-2,biomesoplenty:log_1:6)
B(-2,10,-2,biomesoplenty:leaves_4:0)
B(-2,11,0,biomesoplenty:leaves_4:0)
B(-2,10,0,biomesoplenty:log_1:6)
B(4,10,3,biomesoplenty:leaves_4:0)
B(-1,10,-3,biomesoplenty:log_1:6)
B(-2,10,3,biomesoplenty:leaves_4:0)
B(-5,10,1,biomesoplenty:leaves_4:0)
B(7,10,1,biomesoplenty:leaves_4:0)
B(1,9,-2,biomesoplenty:leaves_4:0)
B(-2,9,-1,biomesoplenty:leaves_4:0)
B(-1,11,-3,biomesoplenty:leaves_4:0)
B(-4,0,0,biomesoplenty:log_1:6)
B(-3,9,2,biomesoplenty:leaves_4:0)
B(2,9,0,biomesoplenty:leaves_4:0)
B(6,10,1,biomesoplenty:leaves_4:0)
B(3,10,3,biomesoplenty:leaves_4:0)
B(-4,10,-3,biomesoplenty:leaves_4:0)
B(-1,2,2,biomesoplenty:log_1:6)
B(-1,4,-1,biomesoplenty:log_1:6)
B(-1,3,-1,biomesoplenty:log_1:6)
B(-3,10,-4,biomesoplenty:leaves_4:0)
B(2,10,3,biomesoplenty:leaves_4:0)
B(-4,10,3,biomesoplenty:leaves_4:0)
B(1,11,0,biomesoplenty:leaves_4:0)
B(-2,9,0,biomesoplenty:leaves_4:0)
B(3,10,-3,biomesoplenty:leaves_4:0)
B(1,10,0,biomesoplenty:log_1:6)
B(4,10,0,biomesoplenty:leaves_4:0)
B(-2,4,0,biomesoplenty:log_1:6)
B(-1,9,-1,biomesoplenty:leaves_4:0)
B(-2,3,0,biomesoplenty:log_1:6)
B(-2,2,0,biomesoplenty:log_1:6)
B(1,10,-4,biomesoplenty:leaves_4:0)
B(2,10,-1,biomesoplenty:leaves_4:0)
B(2,11,-1,biomesoplenty:leaves_4:0)
B(-1,10,-6,biomesoplenty:leaves_4:0)
B(-4,10,0,biomesoplenty:leaves_4:0)
B(2,9,-1,biomesoplenty:leaves_4:0)
B(0,11,-3,biomesoplenty:leaves_4:0)
B(-3,10,-1,biomesoplenty:leaves_4:0)
B(0,10,2,biomesoplenty:leaves_4:0)
B(0,9,1,biomesoplenty:leaves_4:0)
B(0,10,-3,biomesoplenty:log_1:6)
B(-1,10,0,biomesoplenty:log_1:6)
B(-6,10,1,biomesoplenty:leaves_4:0)
B(-1,11,0,biomesoplenty:leaves_4:0)
B(1,0,1,biomesoplenty:log_1:6)
B(-1,1,2,biomesoplenty:log_1:6)
B(-4,10,-2,biomesoplenty:leaves_4:0)
B(5,10,0,biomesoplenty:leaves_4:0)
B(-3,10,1,biomesoplenty:log_1:6)
B(-3,11,1,biomesoplenty:leaves_4:0)
B(4,10,-1,biomesoplenty:leaves_4:0)
B(0,9,-3,biomesoplenty:leaves_4:0)
B(2,10,2,biomesoplenty:leaves_4:0)
B(4,10,1,biomesoplenty:log_1:6)
B(4,11,1,biomesoplenty:leaves_4:0)
B(-2,10,2,biomesoplenty:leaves_4:0)
B(2,9,1,biomesoplenty:leaves_4:0)
B(1,10,-5,biomesoplenty:leaves_4:0)
B(-5,10,3,biomesoplenty:leaves_4:0)
B(1,9,-1,biomesoplenty:leaves_4:0)
B(-3,9,1,biomesoplenty:leaves_4:0)
B(-1,10,-5,biomesoplenty:leaves_4:0)
B(2,10,-4,biomesoplenty:leaves_4:0)
B(3,10,1,biomesoplenty:log_1:6)
B(0,11,-2,biomesoplenty:leaves_4:0)
B(0,10,-2,biomesoplenty:leaves_4:0)
B(1,0,-1,biomesoplenty:log_1:6)
B(-6,10,2,biomesoplenty:leaves_4:0)
B(-3,10,4,biomesoplenty:leaves_4:0)
B(3,11,1,biomesoplenty:leaves_4:0)
B(-1,4,1,biomesoplenty:log_1:6)
B(-1,3,1,biomesoplenty:log_1:6)
B(-1,9,1,biomesoplenty:leaves_4:0)
B(-2,10,-5,biomesoplenty:leaves_4:0)
B(-4,10,1,biomesoplenty:leaves_4:0)
B(3,10,-1,biomesoplenty:leaves_4:0)
B(1,10,-2,biomesoplenty:leaves_4:0)
B(-2,11,-2,biomesoplenty:leaves_4:0)
B(0,10,-5,biomesoplenty:leaves_4:0)
B(-5,10,0,biomesoplenty:leaves_4:0)
B(1,11,-2,biomesoplenty:leaves_4:0)
B(4,9,1,biomesoplenty:leaves_4:0)
B(0,9,0,biomesoplenty:leaves_4:0)
B(3,10,4,biomesoplenty:leaves_4:0)

#######################################################################
# +-----------------------------------------------------------------+ #
# |                            BO3 checks                           | #
# +-----------------------------------------------------------------+ #
#######################################################################


#######################################################################
# +-----------------------------------------------------------------+ #
# |                             Branches                            | #
# +-----------------------------------------------------------------+ #
#######################################################################


#######################################################################
# +-----------------------------------------------------------------+ #
# |                         EntityFunctions                         | #
# +-----------------------------------------------------------------+ #
#######################################################################

