
#######################################################################
# +-----------------------------------------------------------------+ #
# |                            BO3 object                           | #
# +-----------------------------------------------------------------+ #
#######################################################################

Author: LordSmellyPants

Description: No description given

Version: 3

SettingsMode: WriteWithoutComments


#######################################################################
# +-----------------------------------------------------------------+ #
# |                          Main settings                          | #
# +-----------------------------------------------------------------+ #
#######################################################################

Tree: false

Frequency: 1

Rarity: 100.0

RotateRandomly: false

SpawnHeight: randomY

SpawnHeightOffset: 0

SpawnHeightVariance: 0

##############################
# Height Limits for the BO3. #
##############################

MinHeight: 52

MaxHeight: 52

######################
# Extrusion settings #
######################

ExtrudeMode: None

ExtrudeThroughBlocks: AIR

MaxBranchDepth: 10

ExcludedBiomes: All


#######################################################################
# +-----------------------------------------------------------------+ #
# |                      Source block settings                      | #
# +-----------------------------------------------------------------+ #
#######################################################################

SourceBlocks: AIR

MaxPercentageOutsideSourceBlock: 100

OutsideSourceBlock: placeAnyway


#######################################################################
# +-----------------------------------------------------------------+ #
# |                              Blocks                             | #
# +-----------------------------------------------------------------+ #
#######################################################################

B(-15,0,-4,STATIONARY_WATER)
B(-15,0,-3,STATIONARY_WATER)
B(-15,0,-2,STATIONARY_WATER)
B(-15,0,-1,STATIONARY_WATER)
B(-15,0,0,STATIONARY_WATER)
B(-15,0,1,STATIONARY_WATER)
B(-15,0,2,STATIONARY_WATER)
B(-15,0,3,STATIONARY_WATER)
B(-15,0,4,STATIONARY_WATER)
B(-15,1,-4,STATIONARY_WATER)
B(-15,1,-3,STATIONARY_WATER)
B(-15,1,-2,STATIONARY_WATER)
B(-15,1,-1,STATIONARY_WATER)
B(-15,1,0,STATIONARY_WATER)
B(-15,1,1,STATIONARY_WATER)
B(-15,1,2,STATIONARY_WATER)
B(-15,1,3,STATIONARY_WATER)
B(-15,1,4,STATIONARY_WATER)
B(-15,2,-4,STATIONARY_WATER)
B(-15,2,-3,STATIONARY_WATER)
B(-15,2,-2,STATIONARY_WATER)
B(-15,2,-1,STATIONARY_WATER)
B(-15,2,0,STATIONARY_WATER)
B(-15,2,1,STATIONARY_WATER)
B(-15,2,2,STATIONARY_WATER)
B(-15,2,3,STATIONARY_WATER)
B(-15,2,4,STATIONARY_WATER)
B(-15,3,-3,STATIONARY_WATER)
B(-15,3,-2,STATIONARY_WATER)
B(-15,3,-1,STATIONARY_WATER)
B(-15,3,0,STATIONARY_WATER)
B(-15,3,1,STATIONARY_WATER)
B(-15,3,2,STATIONARY_WATER)
B(-15,3,3,STATIONARY_WATER)
B(-15,4,-3,STATIONARY_WATER)
B(-15,4,-2,STATIONARY_WATER)
B(-15,4,-1,STATIONARY_WATER)
B(-15,4,0,STATIONARY_WATER)
B(-15,4,1,STATIONARY_WATER)
B(-15,4,2,STATIONARY_WATER)
B(-15,4,3,STATIONARY_WATER)
B(-15,5,-2,STATIONARY_WATER)
B(-15,5,-1,STATIONARY_WATER)
B(-15,5,0,STATIONARY_WATER)
B(-15,5,1,STATIONARY_WATER)
B(-15,5,2,STATIONARY_WATER)
B(-15,6,-1,STATIONARY_WATER)
B(-15,6,0,STATIONARY_WATER)
B(-15,6,1,STATIONARY_WATER)
B(-14,0,-6,STATIONARY_WATER)
B(-14,0,-5,STATIONARY_WATER)
B(-14,0,-4,STATIONARY_WATER)
B(-14,0,-3,STATIONARY_WATER)
B(-14,0,-2,STATIONARY_WATER)
B(-14,0,-1,STATIONARY_WATER)
B(-14,0,0,STATIONARY_WATER)
B(-14,0,1,STATIONARY_WATER)
B(-14,0,2,STATIONARY_WATER)
B(-14,0,3,STATIONARY_WATER)
B(-14,0,4,STATIONARY_WATER)
B(-14,0,5,STATIONARY_WATER)
B(-14,0,6,STATIONARY_WATER)
B(-14,1,-6,STATIONARY_WATER)
B(-14,1,-5,STATIONARY_WATER)
B(-14,1,-4,STATIONARY_WATER)
B(-14,1,-3,STATIONARY_WATER)
B(-14,1,-2,STATIONARY_WATER)
B(-14,1,-1,STATIONARY_WATER)
B(-14,1,0,STATIONARY_WATER)
B(-14,1,1,STATIONARY_WATER)
B(-14,1,2,STATIONARY_WATER)
B(-14,1,3,STATIONARY_WATER)
B(-14,1,4,STATIONARY_WATER)
B(-14,1,5,STATIONARY_WATER)
B(-14,1,6,STATIONARY_WATER)
B(-14,2,-6,STATIONARY_WATER)
B(-14,2,-5,STATIONARY_WATER)
B(-14,2,-4,STATIONARY_WATER)
B(-14,2,-3,STATIONARY_WATER)
B(-14,2,-2,STATIONARY_WATER)
B(-14,2,-1,STATIONARY_WATER)
B(-14,2,0,STATIONARY_WATER)
B(-14,2,1,STATIONARY_WATER)
B(-14,2,2,STATIONARY_WATER)
B(-14,2,3,STATIONARY_WATER)
B(-14,2,4,STATIONARY_WATER)
B(-14,2,5,STATIONARY_WATER)
B(-14,2,6,STATIONARY_WATER)
B(-14,3,-5,STATIONARY_WATER)
B(-14,3,-4,STATIONARY_WATER)
B(-14,3,-3,STATIONARY_WATER)
B(-14,3,-2,STATIONARY_WATER)
B(-14,3,-1,STATIONARY_WATER)
B(-14,3,0,STATIONARY_WATER)
B(-14,3,1,STATIONARY_WATER)
B(-14,3,2,STATIONARY_WATER)
B(-14,3,3,STATIONARY_WATER)
B(-14,3,4,STATIONARY_WATER)
B(-14,3,5,STATIONARY_WATER)
B(-14,4,-5,STATIONARY_WATER)
B(-14,4,-4,STATIONARY_WATER)
B(-14,4,-3,STATIONARY_WATER)
B(-14,4,-2,STATIONARY_WATER)
B(-14,4,-1,STATIONARY_WATER)
B(-14,4,0,STATIONARY_WATER)
B(-14,4,1,STATIONARY_WATER)
B(-14,4,2,STATIONARY_WATER)
B(-14,4,3,STATIONARY_WATER)
B(-14,4,4,STATIONARY_WATER)
B(-14,4,5,STATIONARY_WATER)
B(-14,5,-4,STATIONARY_WATER)
B(-14,5,-3,STATIONARY_WATER)
B(-14,5,-2,STATIONARY_WATER)
B(-14,5,-1,STATIONARY_WATER)
B(-14,5,0,STATIONARY_WATER)
B(-14,5,1,STATIONARY_WATER)
B(-14,5,2,STATIONARY_WATER)
B(-14,5,3,STATIONARY_WATER)
B(-14,5,4,STATIONARY_WATER)
B(-14,6,-4,STATIONARY_WATER)
B(-14,6,-3,STATIONARY_WATER)
B(-14,6,-2,STATIONARY_WATER)
B(-14,6,-1,STATIONARY_WATER)
B(-14,6,0,STATIONARY_WATER)
B(-14,6,1,STATIONARY_WATER)
B(-14,6,2,STATIONARY_WATER)
B(-14,6,3,STATIONARY_WATER)
B(-14,6,4,STATIONARY_WATER)
B(-14,7,-2,STATIONARY_WATER)
B(-14,7,-1,STATIONARY_WATER)
B(-14,7,0,STATIONARY_WATER)
B(-14,7,1,STATIONARY_WATER)
B(-14,7,2,STATIONARY_WATER)
B(-14,8,-1,STATIONARY_WATER)
B(-14,8,0,STATIONARY_WATER)
B(-14,8,1,STATIONARY_WATER)
B(-13,0,-8,STATIONARY_WATER)
B(-13,0,-7,STATIONARY_WATER)
B(-13,0,-6,STATIONARY_WATER)
B(-13,0,-5,STATIONARY_WATER)
B(-13,0,-4,STATIONARY_WATER)
B(-13,0,-3,STATIONARY_WATER)
B(-13,0,-2,STATIONARY_WATER)
B(-13,0,-1,STATIONARY_WATER)
B(-13,0,0,STATIONARY_WATER)
B(-13,0,1,STATIONARY_WATER)
B(-13,0,2,STATIONARY_WATER)
B(-13,0,3,STATIONARY_WATER)
B(-13,0,4,STATIONARY_WATER)
B(-13,0,5,STATIONARY_WATER)
B(-13,0,6,STATIONARY_WATER)
B(-13,0,7,STATIONARY_WATER)
B(-13,0,8,STATIONARY_WATER)
B(-13,1,-8,STATIONARY_WATER)
B(-13,1,-7,STATIONARY_WATER)
B(-13,1,-6,STATIONARY_WATER)
B(-13,1,-5,STATIONARY_WATER)
B(-13,1,-4,STATIONARY_WATER)
B(-13,1,-3,STATIONARY_WATER)
B(-13,1,-2,STATIONARY_WATER)
B(-13,1,-1,STATIONARY_WATER)
B(-13,1,0,STATIONARY_WATER)
B(-13,1,1,STATIONARY_WATER)
B(-13,1,2,STATIONARY_WATER)
B(-13,1,3,STATIONARY_WATER)
B(-13,1,4,STATIONARY_WATER)
B(-13,1,5,STATIONARY_WATER)
B(-13,1,6,STATIONARY_WATER)
B(-13,1,7,STATIONARY_WATER)
B(-13,1,8,STATIONARY_WATER)
B(-13,2,-8,STATIONARY_WATER)
B(-13,2,-7,STATIONARY_WATER)
B(-13,2,-6,STATIONARY_WATER)
B(-13,2,-5,STATIONARY_WATER)
B(-13,2,-4,STATIONARY_WATER)
B(-13,2,-3,STATIONARY_WATER)
B(-13,2,-2,STATIONARY_WATER)
B(-13,2,-1,STATIONARY_WATER)
B(-13,2,0,STATIONARY_WATER)
B(-13,2,1,STATIONARY_WATER)
B(-13,2,2,STATIONARY_WATER)
B(-13,2,3,STATIONARY_WATER)
B(-13,2,4,STATIONARY_WATER)
B(-13,2,5,STATIONARY_WATER)
B(-13,2,6,STATIONARY_WATER)
B(-13,2,7,STATIONARY_WATER)
B(-13,2,8,STATIONARY_WATER)
B(-13,3,-7,STATIONARY_WATER)
B(-13,3,-6,STATIONARY_WATER)
B(-13,3,-5,STATIONARY_WATER)
B(-13,3,-4,STATIONARY_WATER)
B(-13,3,-3,STATIONARY_WATER)
B(-13,3,-2,STATIONARY_WATER)
B(-13,3,-1,STATIONARY_WATER)
B(-13,3,0,STATIONARY_WATER)
B(-13,3,1,STATIONARY_WATER)
B(-13,3,2,STATIONARY_WATER)
B(-13,3,3,STATIONARY_WATER)
B(-13,3,4,STATIONARY_WATER)
B(-13,3,5,STATIONARY_WATER)
B(-13,3,6,STATIONARY_WATER)
B(-13,3,7,STATIONARY_WATER)
B(-13,4,-7,STATIONARY_WATER)
B(-13,4,-6,STATIONARY_WATER)
B(-13,4,-5,STATIONARY_WATER)
B(-13,4,-4,STATIONARY_WATER)
B(-13,4,-3,STATIONARY_WATER)
B(-13,4,-2,STATIONARY_WATER)
B(-13,4,-1,STATIONARY_WATER)
B(-13,4,0,STATIONARY_WATER)
B(-13,4,1,STATIONARY_WATER)
B(-13,4,2,STATIONARY_WATER)
B(-13,4,3,STATIONARY_WATER)
B(-13,4,4,STATIONARY_WATER)
B(-13,4,5,STATIONARY_WATER)
B(-13,4,6,STATIONARY_WATER)
B(-13,4,7,STATIONARY_WATER)
B(-13,5,-7,STATIONARY_WATER)
B(-13,5,-6,STATIONARY_WATER)
B(-13,5,-5,STATIONARY_WATER)
B(-13,5,-4,STATIONARY_WATER)
B(-13,5,-3,STATIONARY_WATER)
B(-13,5,-2,STATIONARY_WATER)
B(-13,5,-1,STATIONARY_WATER)
B(-13,5,0,STATIONARY_WATER)
B(-13,5,1,STATIONARY_WATER)
B(-13,5,2,STATIONARY_WATER)
B(-13,5,3,STATIONARY_WATER)
B(-13,5,4,STATIONARY_WATER)
B(-13,5,5,STATIONARY_WATER)
B(-13,5,6,STATIONARY_WATER)
B(-13,5,7,STATIONARY_WATER)
B(-13,6,-6,STATIONARY_WATER)
B(-13,6,-5,STATIONARY_WATER)
B(-13,6,-4,STATIONARY_WATER)
B(-13,6,-3,STATIONARY_WATER)
B(-13,6,-2,STATIONARY_WATER)
B(-13,6,-1,STATIONARY_WATER)
B(-13,6,0,STATIONARY_WATER)
B(-13,6,1,STATIONARY_WATER)
B(-13,6,2,STATIONARY_WATER)
B(-13,6,3,STATIONARY_WATER)
B(-13,6,4,STATIONARY_WATER)
B(-13,6,5,STATIONARY_WATER)
B(-13,6,6,STATIONARY_WATER)
B(-13,7,-5,STATIONARY_WATER)
B(-13,7,-4,STATIONARY_WATER)
B(-13,7,-3,STATIONARY_WATER)
B(-13,7,-2,STATIONARY_WATER)
B(-13,7,-1,STATIONARY_WATER)
B(-13,7,0,STATIONARY_WATER)
B(-13,7,1,STATIONARY_WATER)
B(-13,7,2,STATIONARY_WATER)
B(-13,7,3,STATIONARY_WATER)
B(-13,7,4,STATIONARY_WATER)
B(-13,7,5,STATIONARY_WATER)
B(-13,8,-4,STATIONARY_WATER)
B(-13,8,-3,STATIONARY_WATER)
B(-13,8,-2,STATIONARY_WATER)
B(-13,8,-1,STATIONARY_WATER)
B(-13,8,0,STATIONARY_WATER)
B(-13,8,1,STATIONARY_WATER)
B(-13,8,2,STATIONARY_WATER)
B(-13,8,3,STATIONARY_WATER)
B(-13,8,4,STATIONARY_WATER)
B(-13,9,-3,STATIONARY_WATER)
B(-13,9,-2,STATIONARY_WATER)
B(-13,9,-1,STATIONARY_WATER)
B(-13,9,0,STATIONARY_WATER)
B(-13,9,1,STATIONARY_WATER)
B(-13,9,2,STATIONARY_WATER)
B(-13,9,3,STATIONARY_WATER)
B(-13,10,-1,STATIONARY_WATER)
B(-13,10,0,STATIONARY_WATER)
B(-13,10,1,STATIONARY_WATER)
B(-12,0,-9,STATIONARY_WATER)
B(-12,0,-8,STATIONARY_WATER)
B(-12,0,-7,STATIONARY_WATER)
B(-12,0,-6,STATIONARY_WATER)
B(-12,0,-5,STATIONARY_WATER)
B(-12,0,-4,STATIONARY_WATER)
B(-12,0,-3,STATIONARY_WATER)
B(-12,0,-2,STATIONARY_WATER)
B(-12,0,-1,STATIONARY_WATER)
B(-12,0,0,STATIONARY_WATER)
B(-12,0,1,STATIONARY_WATER)
B(-12,0,2,STATIONARY_WATER)
B(-12,0,3,STATIONARY_WATER)
B(-12,0,4,STATIONARY_WATER)
B(-12,0,5,STATIONARY_WATER)
B(-12,0,6,STATIONARY_WATER)
B(-12,0,7,STATIONARY_WATER)
B(-12,0,8,STATIONARY_WATER)
B(-12,0,9,STATIONARY_WATER)
B(-12,1,-9,STATIONARY_WATER)
B(-12,1,-8,STATIONARY_WATER)
B(-12,1,-7,STATIONARY_WATER)
B(-12,1,-6,STATIONARY_WATER)
B(-12,1,-5,STATIONARY_WATER)
B(-12,1,-4,STATIONARY_WATER)
B(-12,1,-3,STATIONARY_WATER)
B(-12,1,-2,STATIONARY_WATER)
B(-12,1,-1,STATIONARY_WATER)
B(-12,1,0,STATIONARY_WATER)
B(-12,1,1,STATIONARY_WATER)
B(-12,1,2,STATIONARY_WATER)
B(-12,1,3,STATIONARY_WATER)
B(-12,1,4,STATIONARY_WATER)
B(-12,1,5,STATIONARY_WATER)
B(-12,1,6,STATIONARY_WATER)
B(-12,1,7,STATIONARY_WATER)
B(-12,1,8,STATIONARY_WATER)
B(-12,1,9,STATIONARY_WATER)
B(-12,2,-9,STATIONARY_WATER)
B(-12,2,-8,STATIONARY_WATER)
B(-12,2,-7,STATIONARY_WATER)
B(-12,2,-6,STATIONARY_WATER)
B(-12,2,-5,STATIONARY_WATER)
B(-12,2,-4,STATIONARY_WATER)
B(-12,2,-3,STATIONARY_WATER)
B(-12,2,-2,STATIONARY_WATER)
B(-12,2,-1,STATIONARY_WATER)
B(-12,2,0,STATIONARY_WATER)
B(-12,2,1,STATIONARY_WATER)
B(-12,2,2,STATIONARY_WATER)
B(-12,2,3,STATIONARY_WATER)
B(-12,2,4,STATIONARY_WATER)
B(-12,2,5,STATIONARY_WATER)
B(-12,2,6,STATIONARY_WATER)
B(-12,2,7,STATIONARY_WATER)
B(-12,2,8,STATIONARY_WATER)
B(-12,2,9,STATIONARY_WATER)
B(-12,3,-9,STATIONARY_WATER)
B(-12,3,-8,STATIONARY_WATER)
B(-12,3,-7,STATIONARY_WATER)
B(-12,3,-6,STATIONARY_WATER)
B(-12,3,-5,STATIONARY_WATER)
B(-12,3,-4,STATIONARY_WATER)
B(-12,3,-3,STATIONARY_WATER)
B(-12,3,-2,STATIONARY_WATER)
B(-12,3,-1,STATIONARY_WATER)
B(-12,3,0,STATIONARY_WATER)
B(-12,3,1,STATIONARY_WATER)
B(-12,3,2,STATIONARY_WATER)
B(-12,3,3,STATIONARY_WATER)
B(-12,3,4,STATIONARY_WATER)
B(-12,3,5,STATIONARY_WATER)
B(-12,3,6,STATIONARY_WATER)
B(-12,3,7,STATIONARY_WATER)
B(-12,3,8,STATIONARY_WATER)
B(-12,3,9,STATIONARY_WATER)
B(-12,4,-9,STATIONARY_WATER)
B(-12,4,-8,STATIONARY_WATER)
B(-12,4,-7,STATIONARY_WATER)
B(-12,4,-6,STATIONARY_WATER)
B(-12,4,-5,STATIONARY_WATER)
B(-12,4,-4,STATIONARY_WATER)
B(-12,4,-3,STATIONARY_WATER)
B(-12,4,-2,STATIONARY_WATER)
B(-12,4,-1,STATIONARY_WATER)
B(-12,4,0,STATIONARY_WATER)
B(-12,4,1,STATIONARY_WATER)
B(-12,4,2,STATIONARY_WATER)
B(-12,4,3,STATIONARY_WATER)
B(-12,4,4,STATIONARY_WATER)
B(-12,4,5,STATIONARY_WATER)
B(-12,4,6,STATIONARY_WATER)
B(-12,4,7,STATIONARY_WATER)
B(-12,4,8,STATIONARY_WATER)
B(-12,4,9,STATIONARY_WATER)
B(-12,5,-8,STATIONARY_WATER)
B(-12,5,-7,STATIONARY_WATER)
B(-12,5,-6,STATIONARY_WATER)
B(-12,5,-5,STATIONARY_WATER)
B(-12,5,-4,STATIONARY_WATER)
B(-12,5,-3,STATIONARY_WATER)
B(-12,5,-2,STATIONARY_WATER)
B(-12,5,-1,STATIONARY_WATER)
B(-12,5,0,STATIONARY_WATER)
B(-12,5,1,STATIONARY_WATER)
B(-12,5,2,STATIONARY_WATER)
B(-12,5,3,STATIONARY_WATER)
B(-12,5,4,STATIONARY_WATER)
B(-12,5,5,STATIONARY_WATER)
B(-12,5,6,STATIONARY_WATER)
B(-12,5,7,STATIONARY_WATER)
B(-12,5,8,STATIONARY_WATER)
B(-12,6,-8,STATIONARY_WATER)
B(-12,6,-7,STATIONARY_WATER)
B(-12,6,-6,STATIONARY_WATER)
B(-12,6,-5,STATIONARY_WATER)
B(-12,6,-4,STATIONARY_WATER)
B(-12,6,-3,STATIONARY_WATER)
B(-12,6,-2,STATIONARY_WATER)
B(-12,6,-1,STATIONARY_WATER)
B(-12,6,0,STATIONARY_WATER)
B(-12,6,1,STATIONARY_WATER)
B(-12,6,2,STATIONARY_WATER)
B(-12,6,3,STATIONARY_WATER)
B(-12,6,4,STATIONARY_WATER)
B(-12,6,5,STATIONARY_WATER)
B(-12,6,6,STATIONARY_WATER)
B(-12,6,7,STATIONARY_WATER)
B(-12,6,8,STATIONARY_WATER)
B(-12,7,-7,STATIONARY_WATER)
B(-12,7,-6,STATIONARY_WATER)
B(-12,7,-5,STATIONARY_WATER)
B(-12,7,-4,STATIONARY_WATER)
B(-12,7,-3,STATIONARY_WATER)
B(-12,7,-2,STATIONARY_WATER)
B(-12,7,-1,STATIONARY_WATER)
B(-12,7,0,STATIONARY_WATER)
B(-12,7,1,STATIONARY_WATER)
B(-12,7,2,STATIONARY_WATER)
B(-12,7,3,STATIONARY_WATER)
B(-12,7,4,STATIONARY_WATER)
B(-12,7,5,STATIONARY_WATER)
B(-12,7,6,STATIONARY_WATER)
B(-12,7,7,STATIONARY_WATER)
B(-12,8,-7,STATIONARY_WATER)
B(-12,8,-6,STATIONARY_WATER)
B(-12,8,-5,STATIONARY_WATER)
B(-12,8,-4,STATIONARY_WATER)
B(-12,8,-3,STATIONARY_WATER)
B(-12,8,-2,STATIONARY_WATER)
B(-12,8,-1,STATIONARY_WATER)
B(-12,8,0,STATIONARY_WATER)
B(-12,8,1,STATIONARY_WATER)
B(-12,8,2,STATIONARY_WATER)
B(-12,8,3,STATIONARY_WATER)
B(-12,8,4,STATIONARY_WATER)
B(-12,8,5,STATIONARY_WATER)
B(-12,8,6,STATIONARY_WATER)
B(-12,8,7,STATIONARY_WATER)
B(-12,9,-6,STATIONARY_WATER)
B(-12,9,-5,STATIONARY_WATER)
B(-12,9,-4,STATIONARY_WATER)
B(-12,9,-3,STATIONARY_WATER)
B(-12,9,-2,STATIONARY_WATER)
B(-12,9,-1,STATIONARY_WATER)
B(-12,9,0,STATIONARY_WATER)
B(-12,9,1,STATIONARY_WATER)
B(-12,9,2,STATIONARY_WATER)
B(-12,9,3,STATIONARY_WATER)
B(-12,9,4,STATIONARY_WATER)
B(-12,9,5,STATIONARY_WATER)
B(-12,9,6,STATIONARY_WATER)
B(-12,10,-5,STATIONARY_WATER)
B(-12,10,-4,STATIONARY_WATER)
B(-12,10,-3,STATIONARY_WATER)
B(-12,10,-2,STATIONARY_WATER)
B(-12,10,-1,STATIONARY_WATER)
B(-12,10,0,STATIONARY_WATER)
B(-12,10,1,STATIONARY_WATER)
B(-12,10,2,STATIONARY_WATER)
B(-12,10,3,STATIONARY_WATER)
B(-12,10,4,STATIONARY_WATER)
B(-12,10,5,STATIONARY_WATER)
B(-12,11,-3,STATIONARY_WATER)
B(-12,11,-2,STATIONARY_WATER)
B(-12,11,-1,STATIONARY_WATER)
B(-12,11,0,STATIONARY_WATER)
B(-12,11,1,STATIONARY_WATER)
B(-12,11,2,STATIONARY_WATER)
B(-12,11,3,STATIONARY_WATER)
B(-12,12,-1,STATIONARY_WATER)
B(-12,12,0,STATIONARY_WATER)
B(-12,12,1,STATIONARY_WATER)
B(-11,0,-10,STATIONARY_WATER)
B(-11,0,-9,STATIONARY_WATER)
B(-11,0,-8,STATIONARY_WATER)
B(-11,0,-7,STATIONARY_WATER)
B(-11,0,-6,STATIONARY_WATER)
B(-11,0,-5,STATIONARY_WATER)
B(-11,0,-4,STATIONARY_WATER)
B(-11,0,-3,STATIONARY_WATER)
B(-11,0,-2,STATIONARY_WATER)
B(-11,0,-1,STATIONARY_WATER)
B(-11,0,0,STATIONARY_WATER)
B(-11,0,1,STATIONARY_WATER)
B(-11,0,2,STATIONARY_WATER)
B(-11,0,3,STATIONARY_WATER)
B(-11,0,4,STATIONARY_WATER)
B(-11,0,5,STATIONARY_WATER)
B(-11,0,6,STATIONARY_WATER)
B(-11,0,7,STATIONARY_WATER)
B(-11,0,8,STATIONARY_WATER)
B(-11,0,9,STATIONARY_WATER)
B(-11,0,10,STATIONARY_WATER)
B(-11,1,-10,STATIONARY_WATER)
B(-11,1,-9,STATIONARY_WATER)
B(-11,1,-8,STATIONARY_WATER)
B(-11,1,-7,STATIONARY_WATER)
B(-11,1,-6,STATIONARY_WATER)
B(-11,1,-5,STATIONARY_WATER)
B(-11,1,-4,STATIONARY_WATER)
B(-11,1,-3,STATIONARY_WATER)
B(-11,1,-2,STATIONARY_WATER)
B(-11,1,-1,STATIONARY_WATER)
B(-11,1,0,STATIONARY_WATER)
B(-11,1,1,STATIONARY_WATER)
B(-11,1,2,STATIONARY_WATER)
B(-11,1,3,STATIONARY_WATER)
B(-11,1,4,STATIONARY_WATER)
B(-11,1,5,STATIONARY_WATER)
B(-11,1,6,STATIONARY_WATER)
B(-11,1,7,STATIONARY_WATER)
B(-11,1,8,STATIONARY_WATER)
B(-11,1,9,STATIONARY_WATER)
B(-11,1,10,STATIONARY_WATER)
B(-11,2,-10,STATIONARY_WATER)
B(-11,2,-9,STATIONARY_WATER)
B(-11,2,-8,STATIONARY_WATER)
B(-11,2,-7,STATIONARY_WATER)
B(-11,2,-6,STATIONARY_WATER)
B(-11,2,-5,STATIONARY_WATER)
B(-11,2,-4,STATIONARY_WATER)
B(-11,2,-3,STATIONARY_WATER)
B(-11,2,-2,STATIONARY_WATER)
B(-11,2,-1,STATIONARY_WATER)
B(-11,2,0,STATIONARY_WATER)
B(-11,2,1,STATIONARY_WATER)
B(-11,2,2,STATIONARY_WATER)
B(-11,2,3,STATIONARY_WATER)
B(-11,2,4,STATIONARY_WATER)
B(-11,2,5,STATIONARY_WATER)
B(-11,2,6,STATIONARY_WATER)
B(-11,2,7,STATIONARY_WATER)
B(-11,2,8,STATIONARY_WATER)
B(-11,2,9,STATIONARY_WATER)
B(-11,2,10,STATIONARY_WATER)
B(-11,3,-10,STATIONARY_WATER)
B(-11,3,-9,STATIONARY_WATER)
B(-11,3,-8,STATIONARY_WATER)
B(-11,3,-7,STATIONARY_WATER)
B(-11,3,-6,STATIONARY_WATER)
B(-11,3,-5,STATIONARY_WATER)
B(-11,3,-4,STATIONARY_WATER)
B(-11,3,-3,STATIONARY_WATER)
B(-11,3,-2,STATIONARY_WATER)
B(-11,3,-1,STATIONARY_WATER)
B(-11,3,0,STATIONARY_WATER)
B(-11,3,1,STATIONARY_WATER)
B(-11,3,2,STATIONARY_WATER)
B(-11,3,3,STATIONARY_WATER)
B(-11,3,4,STATIONARY_WATER)
B(-11,3,5,STATIONARY_WATER)
B(-11,3,6,STATIONARY_WATER)
B(-11,3,7,STATIONARY_WATER)
B(-11,3,8,STATIONARY_WATER)
B(-11,3,9,STATIONARY_WATER)
B(-11,3,10,STATIONARY_WATER)
B(-11,4,-10,STATIONARY_WATER)
B(-11,4,-9,STATIONARY_WATER)
B(-11,4,-8,STATIONARY_WATER)
B(-11,4,-7,STATIONARY_WATER)
B(-11,4,-6,STATIONARY_WATER)
B(-11,4,-5,STATIONARY_WATER)
B(-11,4,-4,STATIONARY_WATER)
B(-11,4,-3,STATIONARY_WATER)
B(-11,4,-2,STATIONARY_WATER)
B(-11,4,-1,STATIONARY_WATER)
B(-11,4,0,STATIONARY_WATER)
B(-11,4,1,STATIONARY_WATER)
B(-11,4,2,STATIONARY_WATER)
B(-11,4,3,STATIONARY_WATER)
B(-11,4,4,STATIONARY_WATER)
B(-11,4,5,STATIONARY_WATER)
B(-11,4,6,STATIONARY_WATER)
B(-11,4,7,STATIONARY_WATER)
B(-11,4,8,STATIONARY_WATER)
B(-11,4,9,STATIONARY_WATER)
B(-11,4,10,STATIONARY_WATER)
B(-11,5,-9,STATIONARY_WATER)
B(-11,5,-8,STATIONARY_WATER)
B(-11,5,-7,STATIONARY_WATER)
B(-11,5,-6,STATIONARY_WATER)
B(-11,5,-5,STATIONARY_WATER)
B(-11,5,-4,STATIONARY_WATER)
B(-11,5,-3,STATIONARY_WATER)
B(-11,5,-2,STATIONARY_WATER)
B(-11,5,-1,STATIONARY_WATER)
B(-11,5,0,STATIONARY_WATER)
B(-11,5,1,STATIONARY_WATER)
B(-11,5,2,STATIONARY_WATER)
B(-11,5,3,STATIONARY_WATER)
B(-11,5,4,STATIONARY_WATER)
B(-11,5,5,STATIONARY_WATER)
B(-11,5,6,STATIONARY_WATER)
B(-11,5,7,STATIONARY_WATER)
B(-11,5,8,STATIONARY_WATER)
B(-11,5,9,STATIONARY_WATER)
B(-11,6,-9,STATIONARY_WATER)
B(-11,6,-8,STATIONARY_WATER)
B(-11,6,-7,STATIONARY_WATER)
B(-11,6,-6,STATIONARY_WATER)
B(-11,6,-5,STATIONARY_WATER)
B(-11,6,-4,STATIONARY_WATER)
B(-11,6,-3,STATIONARY_WATER)
B(-11,6,-2,STATIONARY_WATER)
B(-11,6,-1,STATIONARY_WATER)
B(-11,6,0,STATIONARY_WATER)
B(-11,6,1,STATIONARY_WATER)
B(-11,6,2,STATIONARY_WATER)
B(-11,6,3,STATIONARY_WATER)
B(-11,6,4,STATIONARY_WATER)
B(-11,6,5,STATIONARY_WATER)
B(-11,6,6,STATIONARY_WATER)
B(-11,6,7,STATIONARY_WATER)
B(-11,6,8,STATIONARY_WATER)
B(-11,6,9,STATIONARY_WATER)
B(-11,7,-9,STATIONARY_WATER)
B(-11,7,-8,STATIONARY_WATER)
B(-11,7,-7,STATIONARY_WATER)
B(-11,7,-6,STATIONARY_WATER)
B(-11,7,-5,STATIONARY_WATER)
B(-11,7,-4,STATIONARY_WATER)
B(-11,7,-3,STATIONARY_WATER)
B(-11,7,-2,STATIONARY_WATER)
B(-11,7,-1,STATIONARY_WATER)
B(-11,7,0,STATIONARY_WATER)
B(-11,7,1,STATIONARY_WATER)
B(-11,7,2,STATIONARY_WATER)
B(-11,7,3,STATIONARY_WATER)
B(-11,7,4,STATIONARY_WATER)
B(-11,7,5,STATIONARY_WATER)
B(-11,7,6,STATIONARY_WATER)
B(-11,7,7,STATIONARY_WATER)
B(-11,7,8,STATIONARY_WATER)
B(-11,7,9,STATIONARY_WATER)
B(-11,8,-8,STATIONARY_WATER)
B(-11,8,-7,STATIONARY_WATER)
B(-11,8,-6,STATIONARY_WATER)
B(-11,8,-5,STATIONARY_WATER)
B(-11,8,-4,STATIONARY_WATER)
B(-11,8,-3,STATIONARY_WATER)
B(-11,8,-2,STATIONARY_WATER)
B(-11,8,-1,STATIONARY_WATER)
B(-11,8,0,STATIONARY_WATER)
B(-11,8,1,STATIONARY_WATER)
B(-11,8,2,STATIONARY_WATER)
B(-11,8,3,STATIONARY_WATER)
B(-11,8,4,STATIONARY_WATER)
B(-11,8,5,STATIONARY_WATER)
B(-11,8,6,STATIONARY_WATER)
B(-11,8,7,STATIONARY_WATER)
B(-11,8,8,STATIONARY_WATER)
B(-11,9,-7,STATIONARY_WATER)
B(-11,9,-6,STATIONARY_WATER)
B(-11,9,-5,STATIONARY_WATER)
B(-11,9,-4,STATIONARY_WATER)
B(-11,9,-3,STATIONARY_WATER)
B(-11,9,-2,STATIONARY_WATER)
B(-11,9,-1,STATIONARY_WATER)
B(-11,9,0,STATIONARY_WATER)
B(-11,9,1,STATIONARY_WATER)
B(-11,9,2,STATIONARY_WATER)
B(-11,9,3,STATIONARY_WATER)
B(-11,9,4,STATIONARY_WATER)
B(-11,9,5,STATIONARY_WATER)
B(-11,9,6,STATIONARY_WATER)
B(-11,9,7,STATIONARY_WATER)
B(-11,10,-7,STATIONARY_WATER)
B(-11,10,-6,STATIONARY_WATER)
B(-11,10,-5,STATIONARY_WATER)
B(-11,10,-4,STATIONARY_WATER)
B(-11,10,-3,STATIONARY_WATER)
B(-11,10,-2,STATIONARY_WATER)
B(-11,10,-1,STATIONARY_WATER)
B(-11,10,0,STATIONARY_WATER)
B(-11,10,1,STATIONARY_WATER)
B(-11,10,2,STATIONARY_WATER)
B(-11,10,3,STATIONARY_WATER)
B(-11,10,4,STATIONARY_WATER)
B(-11,10,5,STATIONARY_WATER)
B(-11,10,6,STATIONARY_WATER)
B(-11,10,7,STATIONARY_WATER)
B(-11,11,-6,STATIONARY_WATER)
B(-11,11,-5,STATIONARY_WATER)
B(-11,11,-4,STATIONARY_WATER)
B(-11,11,-3,STATIONARY_WATER)
B(-11,11,-2,STATIONARY_WATER)
B(-11,11,-1,STATIONARY_WATER)
B(-11,11,0,STATIONARY_WATER)
B(-11,11,1,STATIONARY_WATER)
B(-11,11,2,STATIONARY_WATER)
B(-11,11,3,STATIONARY_WATER)
B(-11,11,4,STATIONARY_WATER)
B(-11,11,5,STATIONARY_WATER)
B(-11,11,6,STATIONARY_WATER)
B(-11,12,-4,STATIONARY_WATER)
B(-11,12,-3,STATIONARY_WATER)
B(-11,12,-2,STATIONARY_WATER)
B(-11,12,-1,STATIONARY_WATER)
B(-11,12,0,STATIONARY_WATER)
B(-11,12,1,STATIONARY_WATER)
B(-11,12,2,STATIONARY_WATER)
B(-11,12,3,STATIONARY_WATER)
B(-11,12,4,STATIONARY_WATER)
B(-11,13,-2,STATIONARY_WATER)
B(-11,13,-1,STATIONARY_WATER)
B(-11,13,0,STATIONARY_WATER)
B(-11,13,1,STATIONARY_WATER)
B(-11,13,2,STATIONARY_WATER)
B(-10,0,-11,STATIONARY_WATER)
B(-10,0,-10,STATIONARY_WATER)
B(-10,0,-9,STATIONARY_WATER)
B(-10,0,-8,STATIONARY_WATER)
B(-10,0,-7,STATIONARY_WATER)
B(-10,0,-6,STATIONARY_WATER)
B(-10,0,-5,STATIONARY_WATER)
B(-10,0,-4,STATIONARY_WATER)
B(-10,0,-3,STATIONARY_WATER)
B(-10,0,-2,STATIONARY_WATER)
B(-10,0,-1,STATIONARY_WATER)
B(-10,0,0,STATIONARY_WATER)
B(-10,0,1,STATIONARY_WATER)
B(-10,0,2,STATIONARY_WATER)
B(-10,0,3,STATIONARY_WATER)
B(-10,0,4,STATIONARY_WATER)
B(-10,0,5,STATIONARY_WATER)
B(-10,0,6,STATIONARY_WATER)
B(-10,0,7,STATIONARY_WATER)
B(-10,0,8,STATIONARY_WATER)
B(-10,0,9,STATIONARY_WATER)
B(-10,0,10,STATIONARY_WATER)
B(-10,0,11,STATIONARY_WATER)
B(-10,1,-11,STATIONARY_WATER)
B(-10,1,-10,STATIONARY_WATER)
B(-10,1,-9,STATIONARY_WATER)
B(-10,1,-8,STATIONARY_WATER)
B(-10,1,-7,STATIONARY_WATER)
B(-10,1,-6,STATIONARY_WATER)
B(-10,1,-5,STATIONARY_WATER)
B(-10,1,-4,STATIONARY_WATER)
B(-10,1,-3,STATIONARY_WATER)
B(-10,1,-2,STATIONARY_WATER)
B(-10,1,-1,STATIONARY_WATER)
B(-10,1,0,STATIONARY_WATER)
B(-10,1,1,STATIONARY_WATER)
B(-10,1,2,STATIONARY_WATER)
B(-10,1,3,STATIONARY_WATER)
B(-10,1,4,STATIONARY_WATER)
B(-10,1,5,STATIONARY_WATER)
B(-10,1,6,STATIONARY_WATER)
B(-10,1,7,STATIONARY_WATER)
B(-10,1,8,STATIONARY_WATER)
B(-10,1,9,STATIONARY_WATER)
B(-10,1,10,STATIONARY_WATER)
B(-10,1,11,STATIONARY_WATER)
B(-10,2,-11,STATIONARY_WATER)
B(-10,2,-10,STATIONARY_WATER)
B(-10,2,-9,STATIONARY_WATER)
B(-10,2,-8,STATIONARY_WATER)
B(-10,2,-7,STATIONARY_WATER)
B(-10,2,-6,STATIONARY_WATER)
B(-10,2,-5,STATIONARY_WATER)
B(-10,2,-4,STATIONARY_WATER)
B(-10,2,-3,STATIONARY_WATER)
B(-10,2,-2,STATIONARY_WATER)
B(-10,2,-1,STATIONARY_WATER)
B(-10,2,0,STATIONARY_WATER)
B(-10,2,1,STATIONARY_WATER)
B(-10,2,2,STATIONARY_WATER)
B(-10,2,3,STATIONARY_WATER)
B(-10,2,4,STATIONARY_WATER)
B(-10,2,5,STATIONARY_WATER)
B(-10,2,6,STATIONARY_WATER)
B(-10,2,7,STATIONARY_WATER)
B(-10,2,8,STATIONARY_WATER)
B(-10,2,9,STATIONARY_WATER)
B(-10,2,10,STATIONARY_WATER)
B(-10,2,11,STATIONARY_WATER)
B(-10,3,-11,STATIONARY_WATER)
B(-10,3,-10,STATIONARY_WATER)
B(-10,3,-9,STATIONARY_WATER)
B(-10,3,-8,STATIONARY_WATER)
B(-10,3,-7,STATIONARY_WATER)
B(-10,3,-6,STATIONARY_WATER)
B(-10,3,-5,STATIONARY_WATER)
B(-10,3,-4,STATIONARY_WATER)
B(-10,3,-3,STATIONARY_WATER)
B(-10,3,-2,STATIONARY_WATER)
B(-10,3,-1,STATIONARY_WATER)
B(-10,3,0,STATIONARY_WATER)
B(-10,3,1,STATIONARY_WATER)
B(-10,3,2,STATIONARY_WATER)
B(-10,3,3,STATIONARY_WATER)
B(-10,3,4,STATIONARY_WATER)
B(-10,3,5,STATIONARY_WATER)
B(-10,3,6,STATIONARY_WATER)
B(-10,3,7,STATIONARY_WATER)
B(-10,3,8,STATIONARY_WATER)
B(-10,3,9,STATIONARY_WATER)
B(-10,3,10,STATIONARY_WATER)
B(-10,3,11,STATIONARY_WATER)
B(-10,4,-11,STATIONARY_WATER)
B(-10,4,-10,STATIONARY_WATER)
B(-10,4,-9,STATIONARY_WATER)
B(-10,4,-8,STATIONARY_WATER)
B(-10,4,-7,STATIONARY_WATER)
B(-10,4,-6,STATIONARY_WATER)
B(-10,4,-5,STATIONARY_WATER)
B(-10,4,-4,STATIONARY_WATER)
B(-10,4,-3,STATIONARY_WATER)
B(-10,4,-2,STATIONARY_WATER)
B(-10,4,-1,STATIONARY_WATER)
B(-10,4,0,STATIONARY_WATER)
B(-10,4,1,STATIONARY_WATER)
B(-10,4,2,STATIONARY_WATER)
B(-10,4,3,STATIONARY_WATER)
B(-10,4,4,STATIONARY_WATER)
B(-10,4,5,STATIONARY_WATER)
B(-10,4,6,STATIONARY_WATER)
B(-10,4,7,STATIONARY_WATER)
B(-10,4,8,STATIONARY_WATER)
B(-10,4,9,STATIONARY_WATER)
B(-10,4,10,STATIONARY_WATER)
B(-10,4,11,STATIONARY_WATER)
B(-10,5,-10,STATIONARY_WATER)
B(-10,5,-9,STATIONARY_WATER)
B(-10,5,-8,STATIONARY_WATER)
B(-10,5,-7,STATIONARY_WATER)
B(-10,5,-6,STATIONARY_WATER)
B(-10,5,-5,STATIONARY_WATER)
B(-10,5,-4,STATIONARY_WATER)
B(-10,5,-3,STATIONARY_WATER)
B(-10,5,-2,STATIONARY_WATER)
B(-10,5,-1,STATIONARY_WATER)
B(-10,5,0,STATIONARY_WATER)
B(-10,5,1,STATIONARY_WATER)
B(-10,5,2,STATIONARY_WATER)
B(-10,5,3,STATIONARY_WATER)
B(-10,5,4,STATIONARY_WATER)
B(-10,5,5,STATIONARY_WATER)
B(-10,5,6,STATIONARY_WATER)
B(-10,5,7,STATIONARY_WATER)
B(-10,5,8,STATIONARY_WATER)
B(-10,5,9,STATIONARY_WATER)
B(-10,5,10,STATIONARY_WATER)
B(-10,6,-10,STATIONARY_WATER)
B(-10,6,-9,STATIONARY_WATER)
B(-10,6,-8,STATIONARY_WATER)
B(-10,6,-7,STATIONARY_WATER)
B(-10,6,-6,STATIONARY_WATER)
B(-10,6,-5,STATIONARY_WATER)
B(-10,6,-4,STATIONARY_WATER)
B(-10,6,-3,STATIONARY_WATER)
B(-10,6,-2,STATIONARY_WATER)
B(-10,6,-1,STATIONARY_WATER)
B(-10,6,0,STATIONARY_WATER)
B(-10,6,1,STATIONARY_WATER)
B(-10,6,2,STATIONARY_WATER)
B(-10,6,3,STATIONARY_WATER)
B(-10,6,4,STATIONARY_WATER)
B(-10,6,5,STATIONARY_WATER)
B(-10,6,6,STATIONARY_WATER)
B(-10,6,7,STATIONARY_WATER)
B(-10,6,8,STATIONARY_WATER)
B(-10,6,9,STATIONARY_WATER)
B(-10,6,10,STATIONARY_WATER)
B(-10,7,-10,STATIONARY_WATER)
B(-10,7,-9,STATIONARY_WATER)
B(-10,7,-8,STATIONARY_WATER)
B(-10,7,-7,STATIONARY_WATER)
B(-10,7,-6,STATIONARY_WATER)
B(-10,7,-5,STATIONARY_WATER)
B(-10,7,-4,STATIONARY_WATER)
B(-10,7,-3,STATIONARY_WATER)
B(-10,7,-2,STATIONARY_WATER)
B(-10,7,-1,STATIONARY_WATER)
B(-10,7,0,STATIONARY_WATER)
B(-10,7,1,STATIONARY_WATER)
B(-10,7,2,STATIONARY_WATER)
B(-10,7,3,STATIONARY_WATER)
B(-10,7,4,STATIONARY_WATER)
B(-10,7,5,STATIONARY_WATER)
B(-10,7,6,STATIONARY_WATER)
B(-10,7,7,STATIONARY_WATER)
B(-10,7,8,STATIONARY_WATER)
B(-10,7,9,STATIONARY_WATER)
B(-10,7,10,STATIONARY_WATER)
B(-10,8,-9,STATIONARY_WATER)
B(-10,8,-8,STATIONARY_WATER)
B(-10,8,-7,STATIONARY_WATER)
B(-10,8,-6,STATIONARY_WATER)
B(-10,8,-5,STATIONARY_WATER)
B(-10,8,-4,STATIONARY_WATER)
B(-10,8,-3,STATIONARY_WATER)
B(-10,8,-2,STATIONARY_WATER)
B(-10,8,-1,STATIONARY_WATER)
B(-10,8,0,STATIONARY_WATER)
B(-10,8,1,STATIONARY_WATER)
B(-10,8,2,STATIONARY_WATER)
B(-10,8,3,STATIONARY_WATER)
B(-10,8,4,STATIONARY_WATER)
B(-10,8,5,STATIONARY_WATER)
B(-10,8,6,STATIONARY_WATER)
B(-10,8,7,STATIONARY_WATER)
B(-10,8,8,STATIONARY_WATER)
B(-10,8,9,STATIONARY_WATER)
B(-10,9,-9,STATIONARY_WATER)
B(-10,9,-8,STATIONARY_WATER)
B(-10,9,-7,STATIONARY_WATER)
B(-10,9,-6,STATIONARY_WATER)
B(-10,9,-5,STATIONARY_WATER)
B(-10,9,-4,STATIONARY_WATER)
B(-10,9,-3,STATIONARY_WATER)
B(-10,9,-2,STATIONARY_WATER)
B(-10,9,-1,STATIONARY_WATER)
B(-10,9,0,STATIONARY_WATER)
B(-10,9,1,STATIONARY_WATER)
B(-10,9,2,STATIONARY_WATER)
B(-10,9,3,STATIONARY_WATER)
B(-10,9,4,STATIONARY_WATER)
B(-10,9,5,STATIONARY_WATER)
B(-10,9,6,STATIONARY_WATER)
B(-10,9,7,STATIONARY_WATER)
B(-10,9,8,STATIONARY_WATER)
B(-10,9,9,STATIONARY_WATER)
B(-10,10,-8,STATIONARY_WATER)
B(-10,10,-7,STATIONARY_WATER)
B(-10,10,-6,STATIONARY_WATER)
B(-10,10,-5,STATIONARY_WATER)
B(-10,10,-4,STATIONARY_WATER)
B(-10,10,-3,STATIONARY_WATER)
B(-10,10,-2,STATIONARY_WATER)
B(-10,10,-1,STATIONARY_WATER)
B(-10,10,0,STATIONARY_WATER)
B(-10,10,1,STATIONARY_WATER)
B(-10,10,2,STATIONARY_WATER)
B(-10,10,3,STATIONARY_WATER)
B(-10,10,4,STATIONARY_WATER)
B(-10,10,5,STATIONARY_WATER)
B(-10,10,6,STATIONARY_WATER)
B(-10,10,7,STATIONARY_WATER)
B(-10,10,8,STATIONARY_WATER)
B(-10,11,-7,STATIONARY_WATER)
B(-10,11,-6,STATIONARY_WATER)
B(-10,11,-5,STATIONARY_WATER)
B(-10,11,-4,STATIONARY_WATER)
B(-10,11,-3,STATIONARY_WATER)
B(-10,11,-2,STATIONARY_WATER)
B(-10,11,-1,STATIONARY_WATER)
B(-10,11,0,STATIONARY_WATER)
B(-10,11,1,STATIONARY_WATER)
B(-10,11,2,STATIONARY_WATER)
B(-10,11,3,STATIONARY_WATER)
B(-10,11,4,STATIONARY_WATER)
B(-10,11,5,STATIONARY_WATER)
B(-10,11,6,STATIONARY_WATER)
B(-10,11,7,STATIONARY_WATER)
B(-10,12,-6,STATIONARY_WATER)
B(-10,12,-5,STATIONARY_WATER)
B(-10,12,-4,STATIONARY_WATER)
B(-10,12,-3,STATIONARY_WATER)
B(-10,12,-2,STATIONARY_WATER)
B(-10,12,-1,STATIONARY_WATER)
B(-10,12,0,STATIONARY_WATER)
B(-10,12,1,STATIONARY_WATER)
B(-10,12,2,STATIONARY_WATER)
B(-10,12,3,STATIONARY_WATER)
B(-10,12,4,STATIONARY_WATER)
B(-10,12,5,STATIONARY_WATER)
B(-10,12,6,STATIONARY_WATER)
B(-10,13,-5,STATIONARY_WATER)
B(-10,13,-4,STATIONARY_WATER)
B(-10,13,-3,STATIONARY_WATER)
B(-10,13,-2,STATIONARY_WATER)
B(-10,13,-1,STATIONARY_WATER)
B(-10,13,0,STATIONARY_WATER)
B(-10,13,1,STATIONARY_WATER)
B(-10,13,2,STATIONARY_WATER)
B(-10,13,3,STATIONARY_WATER)
B(-10,13,4,STATIONARY_WATER)
B(-10,13,5,STATIONARY_WATER)
B(-10,14,-3,STATIONARY_WATER)
B(-10,14,-2,STATIONARY_WATER)
B(-10,14,-1,STATIONARY_WATER)
B(-10,14,0,STATIONARY_WATER)
B(-10,14,1,STATIONARY_WATER)
B(-10,14,2,STATIONARY_WATER)
B(-10,14,3,STATIONARY_WATER)
B(-9,0,-12,STATIONARY_WATER)
B(-9,0,-11,STATIONARY_WATER)
B(-9,0,-10,STATIONARY_WATER)
B(-9,0,-9,STATIONARY_WATER)
B(-9,0,-8,STATIONARY_WATER)
B(-9,0,-7,STATIONARY_WATER)
B(-9,0,-6,STATIONARY_WATER)
B(-9,0,-5,STATIONARY_WATER)
B(-9,0,-4,STATIONARY_WATER)
B(-9,0,-3,STATIONARY_WATER)
B(-9,0,-2,STATIONARY_WATER)
B(-9,0,-1,STATIONARY_WATER)
B(-9,0,0,STATIONARY_WATER)
B(-9,0,1,STATIONARY_WATER)
B(-9,0,2,STATIONARY_WATER)
B(-9,0,3,STATIONARY_WATER)
B(-9,0,4,STATIONARY_WATER)
B(-9,0,5,STATIONARY_WATER)
B(-9,0,6,STATIONARY_WATER)
B(-9,0,7,STATIONARY_WATER)
B(-9,0,8,STATIONARY_WATER)
B(-9,0,9,STATIONARY_WATER)
B(-9,0,10,STATIONARY_WATER)
B(-9,0,11,STATIONARY_WATER)
B(-9,0,12,STATIONARY_WATER)
B(-9,1,-12,STATIONARY_WATER)
B(-9,1,-11,STATIONARY_WATER)
B(-9,1,-10,STATIONARY_WATER)
B(-9,1,-9,STATIONARY_WATER)
B(-9,1,-8,STATIONARY_WATER)
B(-9,1,-7,STATIONARY_WATER)
B(-9,1,-6,STATIONARY_WATER)
B(-9,1,-5,STATIONARY_WATER)
B(-9,1,-4,STATIONARY_WATER)
B(-9,1,-3,STATIONARY_WATER)
B(-9,1,-2,STATIONARY_WATER)
B(-9,1,-1,STATIONARY_WATER)
B(-9,1,0,STATIONARY_WATER)
B(-9,1,1,STATIONARY_WATER)
B(-9,1,2,STATIONARY_WATER)
B(-9,1,3,STATIONARY_WATER)
B(-9,1,4,STATIONARY_WATER)
B(-9,1,5,STATIONARY_WATER)
B(-9,1,6,STATIONARY_WATER)
B(-9,1,7,STATIONARY_WATER)
B(-9,1,8,STATIONARY_WATER)
B(-9,1,9,STATIONARY_WATER)
B(-9,1,10,STATIONARY_WATER)
B(-9,1,11,STATIONARY_WATER)
B(-9,1,12,STATIONARY_WATER)
B(-9,2,-12,STATIONARY_WATER)
B(-9,2,-11,STATIONARY_WATER)
B(-9,2,-10,STATIONARY_WATER)
B(-9,2,-9,STATIONARY_WATER)
B(-9,2,-8,STATIONARY_WATER)
B(-9,2,-7,STATIONARY_WATER)
B(-9,2,-6,STATIONARY_WATER)
B(-9,2,-5,STATIONARY_WATER)
B(-9,2,-4,STATIONARY_WATER)
B(-9,2,-3,STATIONARY_WATER)
B(-9,2,-2,STATIONARY_WATER)
B(-9,2,-1,STATIONARY_WATER)
B(-9,2,0,STATIONARY_WATER)
B(-9,2,1,STATIONARY_WATER)
B(-9,2,2,STATIONARY_WATER)
B(-9,2,3,STATIONARY_WATER)
B(-9,2,4,STATIONARY_WATER)
B(-9,2,5,STATIONARY_WATER)
B(-9,2,6,STATIONARY_WATER)
B(-9,2,7,STATIONARY_WATER)
B(-9,2,8,STATIONARY_WATER)
B(-9,2,9,STATIONARY_WATER)
B(-9,2,10,STATIONARY_WATER)
B(-9,2,11,STATIONARY_WATER)
B(-9,2,12,STATIONARY_WATER)
B(-9,3,-12,STATIONARY_WATER)
B(-9,3,-11,STATIONARY_WATER)
B(-9,3,-10,STATIONARY_WATER)
B(-9,3,-9,STATIONARY_WATER)
B(-9,3,-8,STATIONARY_WATER)
B(-9,3,-7,STATIONARY_WATER)
B(-9,3,-6,STATIONARY_WATER)
B(-9,3,-5,STATIONARY_WATER)
B(-9,3,-4,STATIONARY_WATER)
B(-9,3,-3,STATIONARY_WATER)
B(-9,3,-2,STATIONARY_WATER)
B(-9,3,-1,STATIONARY_WATER)
B(-9,3,0,STATIONARY_WATER)
B(-9,3,1,STATIONARY_WATER)
B(-9,3,2,STATIONARY_WATER)
B(-9,3,3,STATIONARY_WATER)
B(-9,3,4,STATIONARY_WATER)
B(-9,3,5,STATIONARY_WATER)
B(-9,3,6,STATIONARY_WATER)
B(-9,3,7,STATIONARY_WATER)
B(-9,3,8,STATIONARY_WATER)
B(-9,3,9,STATIONARY_WATER)
B(-9,3,10,STATIONARY_WATER)
B(-9,3,11,STATIONARY_WATER)
B(-9,3,12,STATIONARY_WATER)
B(-9,4,-12,STATIONARY_WATER)
B(-9,4,-11,STATIONARY_WATER)
B(-9,4,-10,STATIONARY_WATER)
B(-9,4,-9,STATIONARY_WATER)
B(-9,4,-8,STATIONARY_WATER)
B(-9,4,-7,STATIONARY_WATER)
B(-9,4,-6,STATIONARY_WATER)
B(-9,4,-5,STATIONARY_WATER)
B(-9,4,-4,STATIONARY_WATER)
B(-9,4,-3,STATIONARY_WATER)
B(-9,4,-2,STATIONARY_WATER)
B(-9,4,-1,STATIONARY_WATER)
B(-9,4,0,STATIONARY_WATER)
B(-9,4,1,STATIONARY_WATER)
B(-9,4,2,STATIONARY_WATER)
B(-9,4,3,STATIONARY_WATER)
B(-9,4,4,STATIONARY_WATER)
B(-9,4,5,STATIONARY_WATER)
B(-9,4,6,STATIONARY_WATER)
B(-9,4,7,STATIONARY_WATER)
B(-9,4,8,STATIONARY_WATER)
B(-9,4,9,STATIONARY_WATER)
B(-9,4,10,STATIONARY_WATER)
B(-9,4,11,STATIONARY_WATER)
B(-9,4,12,STATIONARY_WATER)
B(-9,5,-11,STATIONARY_WATER)
B(-9,5,-10,STATIONARY_WATER)
B(-9,5,-9,STATIONARY_WATER)
B(-9,5,-8,STATIONARY_WATER)
B(-9,5,-7,STATIONARY_WATER)
B(-9,5,-6,STATIONARY_WATER)
B(-9,5,-5,STATIONARY_WATER)
B(-9,5,-4,STATIONARY_WATER)
B(-9,5,-3,STATIONARY_WATER)
B(-9,5,-2,STATIONARY_WATER)
B(-9,5,-1,STATIONARY_WATER)
B(-9,5,0,STATIONARY_WATER)
B(-9,5,1,STATIONARY_WATER)
B(-9,5,2,STATIONARY_WATER)
B(-9,5,3,STATIONARY_WATER)
B(-9,5,4,STATIONARY_WATER)
B(-9,5,5,STATIONARY_WATER)
B(-9,5,6,STATIONARY_WATER)
B(-9,5,7,STATIONARY_WATER)
B(-9,5,8,STATIONARY_WATER)
B(-9,5,9,STATIONARY_WATER)
B(-9,5,10,STATIONARY_WATER)
B(-9,5,11,STATIONARY_WATER)
B(-9,6,-11,STATIONARY_WATER)
B(-9,6,-10,STATIONARY_WATER)
B(-9,6,-9,STATIONARY_WATER)
B(-9,6,-8,STATIONARY_WATER)
B(-9,6,-7,STATIONARY_WATER)
B(-9,6,-6,STATIONARY_WATER)
B(-9,6,-5,STATIONARY_WATER)
B(-9,6,-4,STATIONARY_WATER)
B(-9,6,-3,STATIONARY_WATER)
B(-9,6,-2,STATIONARY_WATER)
B(-9,6,-1,STATIONARY_WATER)
B(-9,6,0,STATIONARY_WATER)
B(-9,6,1,STATIONARY_WATER)
B(-9,6,2,STATIONARY_WATER)
B(-9,6,3,STATIONARY_WATER)
B(-9,6,4,STATIONARY_WATER)
B(-9,6,5,STATIONARY_WATER)
B(-9,6,6,STATIONARY_WATER)
B(-9,6,7,STATIONARY_WATER)
B(-9,6,8,STATIONARY_WATER)
B(-9,6,9,STATIONARY_WATER)
B(-9,6,10,STATIONARY_WATER)
B(-9,6,11,STATIONARY_WATER)
B(-9,7,-11,STATIONARY_WATER)
B(-9,7,-10,STATIONARY_WATER)
B(-9,7,-9,STATIONARY_WATER)
B(-9,7,-8,STATIONARY_WATER)
B(-9,7,-7,STATIONARY_WATER)
B(-9,7,-6,STATIONARY_WATER)
B(-9,7,-5,STATIONARY_WATER)
B(-9,7,-4,STATIONARY_WATER)
B(-9,7,-3,STATIONARY_WATER)
B(-9,7,-2,STATIONARY_WATER)
B(-9,7,-1,STATIONARY_WATER)
B(-9,7,0,STATIONARY_WATER)
B(-9,7,1,STATIONARY_WATER)
B(-9,7,2,STATIONARY_WATER)
B(-9,7,3,STATIONARY_WATER)
B(-9,7,4,STATIONARY_WATER)
B(-9,7,5,STATIONARY_WATER)
B(-9,7,6,STATIONARY_WATER)
B(-9,7,7,STATIONARY_WATER)
B(-9,7,8,STATIONARY_WATER)
B(-9,7,9,STATIONARY_WATER)
B(-9,7,10,STATIONARY_WATER)
B(-9,7,11,STATIONARY_WATER)
B(-9,8,-10,STATIONARY_WATER)
B(-9,8,-9,STATIONARY_WATER)
B(-9,8,-8,STATIONARY_WATER)
B(-9,8,-7,STATIONARY_WATER)
B(-9,8,-6,STATIONARY_WATER)
B(-9,8,-5,STATIONARY_WATER)
B(-9,8,-4,STATIONARY_WATER)
B(-9,8,-3,STATIONARY_WATER)
B(-9,8,-2,STATIONARY_WATER)
B(-9,8,-1,STATIONARY_WATER)
B(-9,8,0,STATIONARY_WATER)
B(-9,8,1,STATIONARY_WATER)
B(-9,8,2,STATIONARY_WATER)
B(-9,8,3,STATIONARY_WATER)
B(-9,8,4,STATIONARY_WATER)
B(-9,8,5,STATIONARY_WATER)
B(-9,8,6,STATIONARY_WATER)
B(-9,8,7,STATIONARY_WATER)
B(-9,8,8,STATIONARY_WATER)
B(-9,8,9,STATIONARY_WATER)
B(-9,8,10,STATIONARY_WATER)
B(-9,9,-10,STATIONARY_WATER)
B(-9,9,-9,STATIONARY_WATER)
B(-9,9,-8,STATIONARY_WATER)
B(-9,9,-7,STATIONARY_WATER)
B(-9,9,-6,STATIONARY_WATER)
B(-9,9,-5,STATIONARY_WATER)
B(-9,9,-4,STATIONARY_WATER)
B(-9,9,-3,STATIONARY_WATER)
B(-9,9,-2,STATIONARY_WATER)
B(-9,9,-1,STATIONARY_WATER)
B(-9,9,0,STATIONARY_WATER)
B(-9,9,1,STATIONARY_WATER)
B(-9,9,2,STATIONARY_WATER)
B(-9,9,3,STATIONARY_WATER)
B(-9,9,4,STATIONARY_WATER)
B(-9,9,5,STATIONARY_WATER)
B(-9,9,6,STATIONARY_WATER)
B(-9,9,7,STATIONARY_WATER)
B(-9,9,8,STATIONARY_WATER)
B(-9,9,9,STATIONARY_WATER)
B(-9,9,10,STATIONARY_WATER)
B(-9,10,-9,STATIONARY_WATER)
B(-9,10,-8,STATIONARY_WATER)
B(-9,10,-7,STATIONARY_WATER)
B(-9,10,-6,STATIONARY_WATER)
B(-9,10,-5,STATIONARY_WATER)
B(-9,10,-4,STATIONARY_WATER)
B(-9,10,-3,STATIONARY_WATER)
B(-9,10,-2,STATIONARY_WATER)
B(-9,10,-1,STATIONARY_WATER)
B(-9,10,0,STATIONARY_WATER)
B(-9,10,1,STATIONARY_WATER)
B(-9,10,2,STATIONARY_WATER)
B(-9,10,3,STATIONARY_WATER)
B(-9,10,4,STATIONARY_WATER)
B(-9,10,5,STATIONARY_WATER)
B(-9,10,6,STATIONARY_WATER)
B(-9,10,7,STATIONARY_WATER)
B(-9,10,8,STATIONARY_WATER)
B(-9,10,9,STATIONARY_WATER)
B(-9,11,-8,STATIONARY_WATER)
B(-9,11,-7,STATIONARY_WATER)
B(-9,11,-6,STATIONARY_WATER)
B(-9,11,-5,STATIONARY_WATER)
B(-9,11,-4,STATIONARY_WATER)
B(-9,11,-3,STATIONARY_WATER)
B(-9,11,-2,STATIONARY_WATER)
B(-9,11,-1,STATIONARY_WATER)
B(-9,11,0,STATIONARY_WATER)
B(-9,11,1,STATIONARY_WATER)
B(-9,11,2,STATIONARY_WATER)
B(-9,11,3,STATIONARY_WATER)
B(-9,11,4,STATIONARY_WATER)
B(-9,11,5,STATIONARY_WATER)
B(-9,11,6,STATIONARY_WATER)
B(-9,11,7,STATIONARY_WATER)
B(-9,11,8,STATIONARY_WATER)
B(-9,12,-7,STATIONARY_WATER)
B(-9,12,-6,STATIONARY_WATER)
B(-9,12,-5,STATIONARY_WATER)
B(-9,12,-4,STATIONARY_WATER)
B(-9,12,-3,STATIONARY_WATER)
B(-9,12,-2,STATIONARY_WATER)
B(-9,12,-1,STATIONARY_WATER)
B(-9,12,0,STATIONARY_WATER)
B(-9,12,1,STATIONARY_WATER)
B(-9,12,2,STATIONARY_WATER)
B(-9,12,3,STATIONARY_WATER)
B(-9,12,4,STATIONARY_WATER)
B(-9,12,5,STATIONARY_WATER)
B(-9,12,6,STATIONARY_WATER)
B(-9,12,7,STATIONARY_WATER)
B(-9,13,-6,STATIONARY_WATER)
B(-9,13,-5,STATIONARY_WATER)
B(-9,13,-4,STATIONARY_WATER)
B(-9,13,-3,STATIONARY_WATER)
B(-9,13,-2,STATIONARY_WATER)
B(-9,13,-1,STATIONARY_WATER)
B(-9,13,0,STATIONARY_WATER)
B(-9,13,1,STATIONARY_WATER)
B(-9,13,2,STATIONARY_WATER)
B(-9,13,3,STATIONARY_WATER)
B(-9,13,4,STATIONARY_WATER)
B(-9,13,5,STATIONARY_WATER)
B(-9,13,6,STATIONARY_WATER)
B(-9,14,-5,STATIONARY_WATER)
B(-9,14,-4,STATIONARY_WATER)
B(-9,14,-3,STATIONARY_WATER)
B(-9,14,-2,STATIONARY_WATER)
B(-9,14,-1,STATIONARY_WATER)
B(-9,14,0,STATIONARY_WATER)
B(-9,14,1,STATIONARY_WATER)
B(-9,14,2,STATIONARY_WATER)
B(-9,14,3,STATIONARY_WATER)
B(-9,14,4,STATIONARY_WATER)
B(-9,14,5,STATIONARY_WATER)
B(-9,15,-3,STATIONARY_WATER)
B(-9,15,-2,STATIONARY_WATER)
B(-9,15,-1,STATIONARY_WATER)
B(-9,15,0,STATIONARY_WATER)
B(-9,15,1,STATIONARY_WATER)
B(-9,15,2,STATIONARY_WATER)
B(-9,15,3,STATIONARY_WATER)
B(-8,0,-13,STATIONARY_WATER)
B(-8,0,-12,STATIONARY_WATER)
B(-8,0,-11,STATIONARY_WATER)
B(-8,0,-10,STATIONARY_WATER)
B(-8,0,-9,STATIONARY_WATER)
B(-8,0,-8,STATIONARY_WATER)
B(-8,0,-7,STATIONARY_WATER)
B(-8,0,-6,STATIONARY_WATER)
B(-8,0,-5,STATIONARY_WATER)
B(-8,0,-4,STATIONARY_WATER)
B(-8,0,-3,STATIONARY_WATER)
B(-8,0,-2,STATIONARY_WATER)
B(-8,0,-1,STATIONARY_WATER)
B(-8,0,0,STATIONARY_WATER)
B(-8,0,1,STATIONARY_WATER)
B(-8,0,2,STATIONARY_WATER)
B(-8,0,3,STATIONARY_WATER)
B(-8,0,4,STATIONARY_WATER)
B(-8,0,5,STATIONARY_WATER)
B(-8,0,6,STATIONARY_WATER)
B(-8,0,7,STATIONARY_WATER)
B(-8,0,8,STATIONARY_WATER)
B(-8,0,9,STATIONARY_WATER)
B(-8,0,10,STATIONARY_WATER)
B(-8,0,11,STATIONARY_WATER)
B(-8,0,12,STATIONARY_WATER)
B(-8,0,13,STATIONARY_WATER)
B(-8,1,-13,STATIONARY_WATER)
B(-8,1,-12,STATIONARY_WATER)
B(-8,1,-11,STATIONARY_WATER)
B(-8,1,-10,STATIONARY_WATER)
B(-8,1,-9,STATIONARY_WATER)
B(-8,1,-8,STATIONARY_WATER)
B(-8,1,-7,STATIONARY_WATER)
B(-8,1,-6,STATIONARY_WATER)
B(-8,1,-5,STATIONARY_WATER)
B(-8,1,-4,STATIONARY_WATER)
B(-8,1,-3,STATIONARY_WATER)
B(-8,1,-2,STATIONARY_WATER)
B(-8,1,-1,STATIONARY_WATER)
B(-8,1,0,STATIONARY_WATER)
B(-8,1,1,STATIONARY_WATER)
B(-8,1,2,STATIONARY_WATER)
B(-8,1,3,STATIONARY_WATER)
B(-8,1,4,STATIONARY_WATER)
B(-8,1,5,STATIONARY_WATER)
B(-8,1,6,STATIONARY_WATER)
B(-8,1,7,STATIONARY_WATER)
B(-8,1,8,STATIONARY_WATER)
B(-8,1,9,STATIONARY_WATER)
B(-8,1,10,STATIONARY_WATER)
B(-8,1,11,STATIONARY_WATER)
B(-8,1,12,STATIONARY_WATER)
B(-8,1,13,STATIONARY_WATER)
B(-8,2,-13,STATIONARY_WATER)
B(-8,2,-12,STATIONARY_WATER)
B(-8,2,-11,STATIONARY_WATER)
B(-8,2,-10,STATIONARY_WATER)
B(-8,2,-9,STATIONARY_WATER)
B(-8,2,-8,STATIONARY_WATER)
B(-8,2,-7,STATIONARY_WATER)
B(-8,2,-6,STATIONARY_WATER)
B(-8,2,-5,STATIONARY_WATER)
B(-8,2,-4,STATIONARY_WATER)
B(-8,2,-3,STATIONARY_WATER)
B(-8,2,-2,STATIONARY_WATER)
B(-8,2,-1,STATIONARY_WATER)
B(-8,2,0,STATIONARY_WATER)
B(-8,2,1,STATIONARY_WATER)
B(-8,2,2,STATIONARY_WATER)
B(-8,2,3,STATIONARY_WATER)
B(-8,2,4,STATIONARY_WATER)
B(-8,2,5,STATIONARY_WATER)
B(-8,2,6,STATIONARY_WATER)
B(-8,2,7,STATIONARY_WATER)
B(-8,2,8,STATIONARY_WATER)
B(-8,2,9,STATIONARY_WATER)
B(-8,2,10,STATIONARY_WATER)
B(-8,2,11,STATIONARY_WATER)
B(-8,2,12,STATIONARY_WATER)
B(-8,2,13,STATIONARY_WATER)
B(-8,3,-12,STATIONARY_WATER)
B(-8,3,-11,STATIONARY_WATER)
B(-8,3,-10,STATIONARY_WATER)
B(-8,3,-9,STATIONARY_WATER)
B(-8,3,-8,STATIONARY_WATER)
B(-8,3,-7,STATIONARY_WATER)
B(-8,3,-6,STATIONARY_WATER)
B(-8,3,-5,STATIONARY_WATER)
B(-8,3,-4,STATIONARY_WATER)
B(-8,3,-3,STATIONARY_WATER)
B(-8,3,-2,STATIONARY_WATER)
B(-8,3,-1,STATIONARY_WATER)
B(-8,3,0,STATIONARY_WATER)
B(-8,3,1,STATIONARY_WATER)
B(-8,3,2,STATIONARY_WATER)
B(-8,3,3,STATIONARY_WATER)
B(-8,3,4,STATIONARY_WATER)
B(-8,3,5,STATIONARY_WATER)
B(-8,3,6,STATIONARY_WATER)
B(-8,3,7,STATIONARY_WATER)
B(-8,3,8,STATIONARY_WATER)
B(-8,3,9,STATIONARY_WATER)
B(-8,3,10,STATIONARY_WATER)
B(-8,3,11,STATIONARY_WATER)
B(-8,3,12,STATIONARY_WATER)
B(-8,4,-12,STATIONARY_WATER)
B(-8,4,-11,STATIONARY_WATER)
B(-8,4,-10,STATIONARY_WATER)
B(-8,4,-9,STATIONARY_WATER)
B(-8,4,-8,STATIONARY_WATER)
B(-8,4,-7,STATIONARY_WATER)
B(-8,4,-6,STATIONARY_WATER)
B(-8,4,-5,STATIONARY_WATER)
B(-8,4,-4,STATIONARY_WATER)
B(-8,4,-3,STATIONARY_WATER)
B(-8,4,-2,STATIONARY_WATER)
B(-8,4,-1,STATIONARY_WATER)
B(-8,4,0,STATIONARY_WATER)
B(-8,4,1,STATIONARY_WATER)
B(-8,4,2,STATIONARY_WATER)
B(-8,4,3,STATIONARY_WATER)
B(-8,4,4,STATIONARY_WATER)
B(-8,4,5,STATIONARY_WATER)
B(-8,4,6,STATIONARY_WATER)
B(-8,4,7,STATIONARY_WATER)
B(-8,4,8,STATIONARY_WATER)
B(-8,4,9,STATIONARY_WATER)
B(-8,4,10,STATIONARY_WATER)
B(-8,4,11,STATIONARY_WATER)
B(-8,4,12,STATIONARY_WATER)
B(-8,5,-12,STATIONARY_WATER)
B(-8,5,-11,STATIONARY_WATER)
B(-8,5,-10,STATIONARY_WATER)
B(-8,5,-9,STATIONARY_WATER)
B(-8,5,-8,STATIONARY_WATER)
B(-8,5,-7,STATIONARY_WATER)
B(-8,5,-6,STATIONARY_WATER)
B(-8,5,-5,STATIONARY_WATER)
B(-8,5,-4,STATIONARY_WATER)
B(-8,5,-3,STATIONARY_WATER)
B(-8,5,-2,STATIONARY_WATER)
B(-8,5,-1,STATIONARY_WATER)
B(-8,5,0,STATIONARY_WATER)
B(-8,5,1,STATIONARY_WATER)
B(-8,5,2,STATIONARY_WATER)
B(-8,5,3,STATIONARY_WATER)
B(-8,5,4,STATIONARY_WATER)
B(-8,5,5,STATIONARY_WATER)
B(-8,5,6,STATIONARY_WATER)
B(-8,5,7,STATIONARY_WATER)
B(-8,5,8,STATIONARY_WATER)
B(-8,5,9,STATIONARY_WATER)
B(-8,5,10,STATIONARY_WATER)
B(-8,5,11,STATIONARY_WATER)
B(-8,5,12,STATIONARY_WATER)
B(-8,6,-12,STATIONARY_WATER)
B(-8,6,-11,STATIONARY_WATER)
B(-8,6,-10,STATIONARY_WATER)
B(-8,6,-9,STATIONARY_WATER)
B(-8,6,-8,STATIONARY_WATER)
B(-8,6,-7,STATIONARY_WATER)
B(-8,6,-6,STATIONARY_WATER)
B(-8,6,-5,STATIONARY_WATER)
B(-8,6,-4,STATIONARY_WATER)
B(-8,6,-3,STATIONARY_WATER)
B(-8,6,-2,STATIONARY_WATER)
B(-8,6,-1,STATIONARY_WATER)
B(-8,6,0,STATIONARY_WATER)
B(-8,6,1,STATIONARY_WATER)
B(-8,6,2,STATIONARY_WATER)
B(-8,6,3,STATIONARY_WATER)
B(-8,6,4,STATIONARY_WATER)
B(-8,6,5,STATIONARY_WATER)
B(-8,6,6,STATIONARY_WATER)
B(-8,6,7,STATIONARY_WATER)
B(-8,6,8,STATIONARY_WATER)
B(-8,6,9,STATIONARY_WATER)
B(-8,6,10,STATIONARY_WATER)
B(-8,6,11,STATIONARY_WATER)
B(-8,6,12,STATIONARY_WATER)
B(-8,7,-11,STATIONARY_WATER)
B(-8,7,-10,STATIONARY_WATER)
B(-8,7,-9,STATIONARY_WATER)
B(-8,7,-8,STATIONARY_WATER)
B(-8,7,-7,STATIONARY_WATER)
B(-8,7,-6,STATIONARY_WATER)
B(-8,7,-5,STATIONARY_WATER)
B(-8,7,-4,STATIONARY_WATER)
B(-8,7,-3,STATIONARY_WATER)
B(-8,7,-2,STATIONARY_WATER)
B(-8,7,-1,STATIONARY_WATER)
B(-8,7,0,STATIONARY_WATER)
B(-8,7,1,STATIONARY_WATER)
B(-8,7,2,STATIONARY_WATER)
B(-8,7,3,STATIONARY_WATER)
B(-8,7,4,STATIONARY_WATER)
B(-8,7,5,STATIONARY_WATER)
B(-8,7,6,STATIONARY_WATER)
B(-8,7,7,STATIONARY_WATER)
B(-8,7,8,STATIONARY_WATER)
B(-8,7,9,STATIONARY_WATER)
B(-8,7,10,STATIONARY_WATER)
B(-8,7,11,STATIONARY_WATER)
B(-8,8,-11,STATIONARY_WATER)
B(-8,8,-10,STATIONARY_WATER)
B(-8,8,-9,STATIONARY_WATER)
B(-8,8,-8,STATIONARY_WATER)
B(-8,8,-7,STATIONARY_WATER)
B(-8,8,-6,STATIONARY_WATER)
B(-8,8,-5,STATIONARY_WATER)
B(-8,8,-4,STATIONARY_WATER)
B(-8,8,-3,STATIONARY_WATER)
B(-8,8,-2,STATIONARY_WATER)
B(-8,8,-1,STATIONARY_WATER)
B(-8,8,0,STATIONARY_WATER)
B(-8,8,1,STATIONARY_WATER)
B(-8,8,2,STATIONARY_WATER)
B(-8,8,3,STATIONARY_WATER)
B(-8,8,4,STATIONARY_WATER)
B(-8,8,5,STATIONARY_WATER)
B(-8,8,6,STATIONARY_WATER)
B(-8,8,7,STATIONARY_WATER)
B(-8,8,8,STATIONARY_WATER)
B(-8,8,9,STATIONARY_WATER)
B(-8,8,10,STATIONARY_WATER)
B(-8,8,11,STATIONARY_WATER)
B(-8,9,-10,STATIONARY_WATER)
B(-8,9,-9,STATIONARY_WATER)
B(-8,9,-8,STATIONARY_WATER)
B(-8,9,-7,STATIONARY_WATER)
B(-8,9,-6,STATIONARY_WATER)
B(-8,9,-5,STATIONARY_WATER)
B(-8,9,-4,STATIONARY_WATER)
B(-8,9,-3,STATIONARY_WATER)
B(-8,9,-2,STATIONARY_WATER)
B(-8,9,-1,STATIONARY_WATER)
B(-8,9,0,STATIONARY_WATER)
B(-8,9,1,STATIONARY_WATER)
B(-8,9,2,STATIONARY_WATER)
B(-8,9,3,STATIONARY_WATER)
B(-8,9,4,STATIONARY_WATER)
B(-8,9,5,STATIONARY_WATER)
B(-8,9,6,STATIONARY_WATER)
B(-8,9,7,STATIONARY_WATER)
B(-8,9,8,STATIONARY_WATER)
B(-8,9,9,STATIONARY_WATER)
B(-8,9,10,STATIONARY_WATER)
B(-8,10,-10,STATIONARY_WATER)
B(-8,10,-9,STATIONARY_WATER)
B(-8,10,-8,STATIONARY_WATER)
B(-8,10,-7,STATIONARY_WATER)
B(-8,10,-6,STATIONARY_WATER)
B(-8,10,-5,STATIONARY_WATER)
B(-8,10,-4,STATIONARY_WATER)
B(-8,10,-3,STATIONARY_WATER)
B(-8,10,-2,STATIONARY_WATER)
B(-8,10,-1,STATIONARY_WATER)
B(-8,10,0,STATIONARY_WATER)
B(-8,10,1,STATIONARY_WATER)
B(-8,10,2,STATIONARY_WATER)
B(-8,10,3,STATIONARY_WATER)
B(-8,10,4,STATIONARY_WATER)
B(-8,10,5,STATIONARY_WATER)
B(-8,10,6,STATIONARY_WATER)
B(-8,10,7,STATIONARY_WATER)
B(-8,10,8,STATIONARY_WATER)
B(-8,10,9,STATIONARY_WATER)
B(-8,10,10,STATIONARY_WATER)
B(-8,11,-9,STATIONARY_WATER)
B(-8,11,-8,STATIONARY_WATER)
B(-8,11,-7,STATIONARY_WATER)
B(-8,11,-6,STATIONARY_WATER)
B(-8,11,-5,STATIONARY_WATER)
B(-8,11,-4,STATIONARY_WATER)
B(-8,11,-3,STATIONARY_WATER)
B(-8,11,-2,STATIONARY_WATER)
B(-8,11,-1,STATIONARY_WATER)
B(-8,11,0,STATIONARY_WATER)
B(-8,11,1,STATIONARY_WATER)
B(-8,11,2,STATIONARY_WATER)
B(-8,11,3,STATIONARY_WATER)
B(-8,11,4,STATIONARY_WATER)
B(-8,11,5,STATIONARY_WATER)
B(-8,11,6,STATIONARY_WATER)
B(-8,11,7,STATIONARY_WATER)
B(-8,11,8,STATIONARY_WATER)
B(-8,11,9,STATIONARY_WATER)
B(-8,12,-8,STATIONARY_WATER)
B(-8,12,-7,STATIONARY_WATER)
B(-8,12,-6,STATIONARY_WATER)
B(-8,12,-5,STATIONARY_WATER)
B(-8,12,-4,STATIONARY_WATER)
B(-8,12,-3,STATIONARY_WATER)
B(-8,12,-2,STATIONARY_WATER)
B(-8,12,-1,STATIONARY_WATER)
B(-8,12,0,STATIONARY_WATER)
B(-8,12,1,STATIONARY_WATER)
B(-8,12,2,STATIONARY_WATER)
B(-8,12,3,STATIONARY_WATER)
B(-8,12,4,STATIONARY_WATER)
B(-8,12,5,STATIONARY_WATER)
B(-8,12,6,STATIONARY_WATER)
B(-8,12,7,STATIONARY_WATER)
B(-8,12,8,STATIONARY_WATER)
B(-8,13,-7,STATIONARY_WATER)
B(-8,13,-6,STATIONARY_WATER)
B(-8,13,-5,STATIONARY_WATER)
B(-8,13,-4,STATIONARY_WATER)
B(-8,13,-3,STATIONARY_WATER)
B(-8,13,-2,STATIONARY_WATER)
B(-8,13,-1,STATIONARY_WATER)
B(-8,13,0,STATIONARY_WATER)
B(-8,13,1,STATIONARY_WATER)
B(-8,13,2,STATIONARY_WATER)
B(-8,13,3,STATIONARY_WATER)
B(-8,13,4,STATIONARY_WATER)
B(-8,13,5,STATIONARY_WATER)
B(-8,13,6,STATIONARY_WATER)
B(-8,13,7,STATIONARY_WATER)
B(-8,14,-6,STATIONARY_WATER)
B(-8,14,-5,STATIONARY_WATER)
B(-8,14,-4,STATIONARY_WATER)
B(-8,14,-3,STATIONARY_WATER)
B(-8,14,-2,STATIONARY_WATER)
B(-8,14,-1,STATIONARY_WATER)
B(-8,14,0,STATIONARY_WATER)
B(-8,14,1,STATIONARY_WATER)
B(-8,14,2,STATIONARY_WATER)
B(-8,14,3,STATIONARY_WATER)
B(-8,14,4,STATIONARY_WATER)
B(-8,14,5,STATIONARY_WATER)
B(-8,14,6,STATIONARY_WATER)
B(-8,15,-5,STATIONARY_WATER)
B(-8,15,-4,STATIONARY_WATER)
B(-8,15,-3,STATIONARY_WATER)
B(-8,15,-2,STATIONARY_WATER)
B(-8,15,-1,STATIONARY_WATER)
B(-8,15,0,STATIONARY_WATER)
B(-8,15,1,STATIONARY_WATER)
B(-8,15,2,STATIONARY_WATER)
B(-8,15,3,STATIONARY_WATER)
B(-8,15,4,STATIONARY_WATER)
B(-8,15,5,STATIONARY_WATER)
B(-8,16,-3,STATIONARY_WATER)
B(-8,16,-2,STATIONARY_WATER)
B(-8,16,-1,STATIONARY_WATER)
B(-8,16,0,STATIONARY_WATER)
B(-8,16,1,STATIONARY_WATER)
B(-8,16,2,STATIONARY_WATER)
B(-8,16,3,STATIONARY_WATER)
B(-7,0,-13,STATIONARY_WATER)
B(-7,0,-12,STATIONARY_WATER)
B(-7,0,-11,STATIONARY_WATER)
B(-7,0,-10,STATIONARY_WATER)
B(-7,0,-9,STATIONARY_WATER)
B(-7,0,-8,STATIONARY_WATER)
B(-7,0,-7,STATIONARY_WATER)
B(-7,0,-6,STATIONARY_WATER)
B(-7,0,-5,STATIONARY_WATER)
B(-7,0,-4,STATIONARY_WATER)
B(-7,0,-3,STATIONARY_WATER)
B(-7,0,-2,STATIONARY_WATER)
B(-7,0,-1,STATIONARY_WATER)
B(-7,0,0,STATIONARY_WATER)
B(-7,0,1,STATIONARY_WATER)
B(-7,0,2,STATIONARY_WATER)
B(-7,0,3,STATIONARY_WATER)
B(-7,0,4,STATIONARY_WATER)
B(-7,0,5,STATIONARY_WATER)
B(-7,0,6,STATIONARY_WATER)
B(-7,0,7,STATIONARY_WATER)
B(-7,0,8,STATIONARY_WATER)
B(-7,0,9,STATIONARY_WATER)
B(-7,0,10,STATIONARY_WATER)
B(-7,0,11,STATIONARY_WATER)
B(-7,0,12,STATIONARY_WATER)
B(-7,0,13,STATIONARY_WATER)
B(-7,1,-13,STATIONARY_WATER)
B(-7,1,-12,STATIONARY_WATER)
B(-7,1,-11,STATIONARY_WATER)
B(-7,1,-10,STATIONARY_WATER)
B(-7,1,-9,STATIONARY_WATER)
B(-7,1,-8,STATIONARY_WATER)
B(-7,1,-7,STATIONARY_WATER)
B(-7,1,-6,STATIONARY_WATER)
B(-7,1,-5,STATIONARY_WATER)
B(-7,1,-4,STATIONARY_WATER)
B(-7,1,-3,STATIONARY_WATER)
B(-7,1,-2,STATIONARY_WATER)
B(-7,1,-1,STATIONARY_WATER)
B(-7,1,0,STATIONARY_WATER)
B(-7,1,1,STATIONARY_WATER)
B(-7,1,2,STATIONARY_WATER)
B(-7,1,3,STATIONARY_WATER)
B(-7,1,4,STATIONARY_WATER)
B(-7,1,5,STATIONARY_WATER)
B(-7,1,6,STATIONARY_WATER)
B(-7,1,7,STATIONARY_WATER)
B(-7,1,8,STATIONARY_WATER)
B(-7,1,9,STATIONARY_WATER)
B(-7,1,10,STATIONARY_WATER)
B(-7,1,11,STATIONARY_WATER)
B(-7,1,12,STATIONARY_WATER)
B(-7,1,13,STATIONARY_WATER)
B(-7,2,-13,STATIONARY_WATER)
B(-7,2,-12,STATIONARY_WATER)
B(-7,2,-11,STATIONARY_WATER)
B(-7,2,-10,STATIONARY_WATER)
B(-7,2,-9,STATIONARY_WATER)
B(-7,2,-8,STATIONARY_WATER)
B(-7,2,-7,STATIONARY_WATER)
B(-7,2,-6,STATIONARY_WATER)
B(-7,2,-5,STATIONARY_WATER)
B(-7,2,-4,STATIONARY_WATER)
B(-7,2,-3,STATIONARY_WATER)
B(-7,2,-2,STATIONARY_WATER)
B(-7,2,-1,STATIONARY_WATER)
B(-7,2,0,STATIONARY_WATER)
B(-7,2,1,STATIONARY_WATER)
B(-7,2,2,STATIONARY_WATER)
B(-7,2,3,STATIONARY_WATER)
B(-7,2,4,STATIONARY_WATER)
B(-7,2,5,STATIONARY_WATER)
B(-7,2,6,STATIONARY_WATER)
B(-7,2,7,STATIONARY_WATER)
B(-7,2,8,STATIONARY_WATER)
B(-7,2,9,STATIONARY_WATER)
B(-7,2,10,STATIONARY_WATER)
B(-7,2,11,STATIONARY_WATER)
B(-7,2,12,STATIONARY_WATER)
B(-7,2,13,STATIONARY_WATER)
B(-7,3,-13,STATIONARY_WATER)
B(-7,3,-12,STATIONARY_WATER)
B(-7,3,-11,STATIONARY_WATER)
B(-7,3,-10,STATIONARY_WATER)
B(-7,3,-9,STATIONARY_WATER)
B(-7,3,-8,STATIONARY_WATER)
B(-7,3,-7,STATIONARY_WATER)
B(-7,3,-6,STATIONARY_WATER)
B(-7,3,-5,STATIONARY_WATER)
B(-7,3,-4,STATIONARY_WATER)
B(-7,3,-3,STATIONARY_WATER)
B(-7,3,-2,STATIONARY_WATER)
B(-7,3,-1,STATIONARY_WATER)
B(-7,3,0,STATIONARY_WATER)
B(-7,3,1,STATIONARY_WATER)
B(-7,3,2,STATIONARY_WATER)
B(-7,3,3,STATIONARY_WATER)
B(-7,3,4,STATIONARY_WATER)
B(-7,3,5,STATIONARY_WATER)
B(-7,3,6,STATIONARY_WATER)
B(-7,3,7,STATIONARY_WATER)
B(-7,3,8,STATIONARY_WATER)
B(-7,3,9,STATIONARY_WATER)
B(-7,3,10,STATIONARY_WATER)
B(-7,3,11,STATIONARY_WATER)
B(-7,3,12,STATIONARY_WATER)
B(-7,3,13,STATIONARY_WATER)
B(-7,4,-13,STATIONARY_WATER)
B(-7,4,-12,STATIONARY_WATER)
B(-7,4,-11,STATIONARY_WATER)
B(-7,4,-10,STATIONARY_WATER)
B(-7,4,-9,STATIONARY_WATER)
B(-7,4,-8,STATIONARY_WATER)
B(-7,4,-7,STATIONARY_WATER)
B(-7,4,-6,STATIONARY_WATER)
B(-7,4,-5,STATIONARY_WATER)
B(-7,4,-4,STATIONARY_WATER)
B(-7,4,-3,STATIONARY_WATER)
B(-7,4,-2,STATIONARY_WATER)
B(-7,4,-1,STATIONARY_WATER)
B(-7,4,0,STATIONARY_WATER)
B(-7,4,1,STATIONARY_WATER)
B(-7,4,2,STATIONARY_WATER)
B(-7,4,3,STATIONARY_WATER)
B(-7,4,4,STATIONARY_WATER)
B(-7,4,5,STATIONARY_WATER)
B(-7,4,6,STATIONARY_WATER)
B(-7,4,7,STATIONARY_WATER)
B(-7,4,8,STATIONARY_WATER)
B(-7,4,9,STATIONARY_WATER)
B(-7,4,10,STATIONARY_WATER)
B(-7,4,11,STATIONARY_WATER)
B(-7,4,12,STATIONARY_WATER)
B(-7,4,13,STATIONARY_WATER)
B(-7,5,-13,STATIONARY_WATER)
B(-7,5,-12,STATIONARY_WATER)
B(-7,5,-11,STATIONARY_WATER)
B(-7,5,-10,STATIONARY_WATER)
B(-7,5,-9,STATIONARY_WATER)
B(-7,5,-8,STATIONARY_WATER)
B(-7,5,-7,STATIONARY_WATER)
B(-7,5,-6,STATIONARY_WATER)
B(-7,5,-5,STATIONARY_WATER)
B(-7,5,-4,STATIONARY_WATER)
B(-7,5,-3,STATIONARY_WATER)
B(-7,5,-2,STATIONARY_WATER)
B(-7,5,-1,STATIONARY_WATER)
B(-7,5,0,STATIONARY_WATER)
B(-7,5,1,STATIONARY_WATER)
B(-7,5,2,STATIONARY_WATER)
B(-7,5,3,STATIONARY_WATER)
B(-7,5,4,STATIONARY_WATER)
B(-7,5,5,STATIONARY_WATER)
B(-7,5,6,STATIONARY_WATER)
B(-7,5,7,STATIONARY_WATER)
B(-7,5,8,STATIONARY_WATER)
B(-7,5,9,STATIONARY_WATER)
B(-7,5,10,STATIONARY_WATER)
B(-7,5,11,STATIONARY_WATER)
B(-7,5,12,STATIONARY_WATER)
B(-7,5,13,STATIONARY_WATER)
B(-7,6,-12,STATIONARY_WATER)
B(-7,6,-11,STATIONARY_WATER)
B(-7,6,-10,STATIONARY_WATER)
B(-7,6,-9,STATIONARY_WATER)
B(-7,6,-8,STATIONARY_WATER)
B(-7,6,-7,STATIONARY_WATER)
B(-7,6,-6,STATIONARY_WATER)
B(-7,6,-5,STATIONARY_WATER)
B(-7,6,-4,STATIONARY_WATER)
B(-7,6,-3,STATIONARY_WATER)
B(-7,6,-2,STATIONARY_WATER)
B(-7,6,-1,STATIONARY_WATER)
B(-7,6,0,STATIONARY_WATER)
B(-7,6,1,STATIONARY_WATER)
B(-7,6,2,STATIONARY_WATER)
B(-7,6,3,STATIONARY_WATER)
B(-7,6,4,STATIONARY_WATER)
B(-7,6,5,STATIONARY_WATER)
B(-7,6,6,STATIONARY_WATER)
B(-7,6,7,STATIONARY_WATER)
B(-7,6,8,STATIONARY_WATER)
B(-7,6,9,STATIONARY_WATER)
B(-7,6,10,STATIONARY_WATER)
B(-7,6,11,STATIONARY_WATER)
B(-7,6,12,STATIONARY_WATER)
B(-7,7,-12,STATIONARY_WATER)
B(-7,7,-11,STATIONARY_WATER)
B(-7,7,-10,STATIONARY_WATER)
B(-7,7,-9,STATIONARY_WATER)
B(-7,7,-8,STATIONARY_WATER)
B(-7,7,-7,STATIONARY_WATER)
B(-7,7,-6,STATIONARY_WATER)
B(-7,7,-5,STATIONARY_WATER)
B(-7,7,-4,STATIONARY_WATER)
B(-7,7,-3,STATIONARY_WATER)
B(-7,7,-2,STATIONARY_WATER)
B(-7,7,-1,STATIONARY_WATER)
B(-7,7,0,STATIONARY_WATER)
B(-7,7,1,STATIONARY_WATER)
B(-7,7,2,STATIONARY_WATER)
B(-7,7,3,STATIONARY_WATER)
B(-7,7,4,STATIONARY_WATER)
B(-7,7,5,STATIONARY_WATER)
B(-7,7,6,STATIONARY_WATER)
B(-7,7,7,STATIONARY_WATER)
B(-7,7,8,STATIONARY_WATER)
B(-7,7,9,STATIONARY_WATER)
B(-7,7,10,STATIONARY_WATER)
B(-7,7,11,STATIONARY_WATER)
B(-7,7,12,STATIONARY_WATER)
B(-7,8,-12,STATIONARY_WATER)
B(-7,8,-11,STATIONARY_WATER)
B(-7,8,-10,STATIONARY_WATER)
B(-7,8,-9,STATIONARY_WATER)
B(-7,8,-8,STATIONARY_WATER)
B(-7,8,-7,STATIONARY_WATER)
B(-7,8,-6,STATIONARY_WATER)
B(-7,8,-5,STATIONARY_WATER)
B(-7,8,-4,STATIONARY_WATER)
B(-7,8,-3,STATIONARY_WATER)
B(-7,8,-2,STATIONARY_WATER)
B(-7,8,-1,STATIONARY_WATER)
B(-7,8,0,STATIONARY_WATER)
B(-7,8,1,STATIONARY_WATER)
B(-7,8,2,STATIONARY_WATER)
B(-7,8,3,STATIONARY_WATER)
B(-7,8,4,STATIONARY_WATER)
B(-7,8,5,STATIONARY_WATER)
B(-7,8,6,STATIONARY_WATER)
B(-7,8,7,STATIONARY_WATER)
B(-7,8,8,STATIONARY_WATER)
B(-7,8,9,STATIONARY_WATER)
B(-7,8,10,STATIONARY_WATER)
B(-7,8,11,STATIONARY_WATER)
B(-7,8,12,STATIONARY_WATER)
B(-7,9,-11,STATIONARY_WATER)
B(-7,9,-10,STATIONARY_WATER)
B(-7,9,-9,STATIONARY_WATER)
B(-7,9,-8,STATIONARY_WATER)
B(-7,9,-7,STATIONARY_WATER)
B(-7,9,-6,STATIONARY_WATER)
B(-7,9,-5,STATIONARY_WATER)
B(-7,9,-4,STATIONARY_WATER)
B(-7,9,-3,STATIONARY_WATER)
B(-7,9,-2,STATIONARY_WATER)
B(-7,9,-1,STATIONARY_WATER)
B(-7,9,0,STATIONARY_WATER)
B(-7,9,1,STATIONARY_WATER)
B(-7,9,2,STATIONARY_WATER)
B(-7,9,3,STATIONARY_WATER)
B(-7,9,4,STATIONARY_WATER)
B(-7,9,5,STATIONARY_WATER)
B(-7,9,6,STATIONARY_WATER)
B(-7,9,7,STATIONARY_WATER)
B(-7,9,8,STATIONARY_WATER)
B(-7,9,9,STATIONARY_WATER)
B(-7,9,10,STATIONARY_WATER)
B(-7,9,11,STATIONARY_WATER)
B(-7,10,-11,STATIONARY_WATER)
B(-7,10,-10,STATIONARY_WATER)
B(-7,10,-9,STATIONARY_WATER)
B(-7,10,-8,STATIONARY_WATER)
B(-7,10,-7,STATIONARY_WATER)
B(-7,10,-6,STATIONARY_WATER)
B(-7,10,-5,STATIONARY_WATER)
B(-7,10,-4,STATIONARY_WATER)
B(-7,10,-3,STATIONARY_WATER)
B(-7,10,-2,STATIONARY_WATER)
B(-7,10,-1,STATIONARY_WATER)
B(-7,10,0,STATIONARY_WATER)
B(-7,10,1,STATIONARY_WATER)
B(-7,10,2,STATIONARY_WATER)
B(-7,10,3,STATIONARY_WATER)
B(-7,10,4,STATIONARY_WATER)
B(-7,10,5,STATIONARY_WATER)
B(-7,10,6,STATIONARY_WATER)
B(-7,10,7,STATIONARY_WATER)
B(-7,10,8,STATIONARY_WATER)
B(-7,10,9,STATIONARY_WATER)
B(-7,10,10,STATIONARY_WATER)
B(-7,10,11,STATIONARY_WATER)
B(-7,11,-10,STATIONARY_WATER)
B(-7,11,-9,STATIONARY_WATER)
B(-7,11,-8,STATIONARY_WATER)
B(-7,11,-7,STATIONARY_WATER)
B(-7,11,-6,STATIONARY_WATER)
B(-7,11,-5,STATIONARY_WATER)
B(-7,11,-4,STATIONARY_WATER)
B(-7,11,-3,STATIONARY_WATER)
B(-7,11,-2,STATIONARY_WATER)
B(-7,11,-1,STATIONARY_WATER)
B(-7,11,0,STATIONARY_WATER)
B(-7,11,1,STATIONARY_WATER)
B(-7,11,2,STATIONARY_WATER)
B(-7,11,3,STATIONARY_WATER)
B(-7,11,4,STATIONARY_WATER)
B(-7,11,5,STATIONARY_WATER)
B(-7,11,6,STATIONARY_WATER)
B(-7,11,7,STATIONARY_WATER)
B(-7,11,8,STATIONARY_WATER)
B(-7,11,9,STATIONARY_WATER)
B(-7,11,10,STATIONARY_WATER)
B(-7,12,-9,STATIONARY_WATER)
B(-7,12,-8,STATIONARY_WATER)
B(-7,12,-7,STATIONARY_WATER)
B(-7,12,-6,STATIONARY_WATER)
B(-7,12,-5,STATIONARY_WATER)
B(-7,12,-4,STATIONARY_WATER)
B(-7,12,-3,STATIONARY_WATER)
B(-7,12,-2,STATIONARY_WATER)
B(-7,12,-1,STATIONARY_WATER)
B(-7,12,0,STATIONARY_WATER)
B(-7,12,1,STATIONARY_WATER)
B(-7,12,2,STATIONARY_WATER)
B(-7,12,3,STATIONARY_WATER)
B(-7,12,4,STATIONARY_WATER)
B(-7,12,5,STATIONARY_WATER)
B(-7,12,6,STATIONARY_WATER)
B(-7,12,7,STATIONARY_WATER)
B(-7,12,8,STATIONARY_WATER)
B(-7,12,9,STATIONARY_WATER)
B(-7,13,-8,STATIONARY_WATER)
B(-7,13,-7,STATIONARY_WATER)
B(-7,13,-6,STATIONARY_WATER)
B(-7,13,-5,STATIONARY_WATER)
B(-7,13,-4,STATIONARY_WATER)
B(-7,13,-3,STATIONARY_WATER)
B(-7,13,-2,STATIONARY_WATER)
B(-7,13,-1,STATIONARY_WATER)
B(-7,13,0,STATIONARY_WATER)
B(-7,13,1,STATIONARY_WATER)
B(-7,13,2,STATIONARY_WATER)
B(-7,13,3,STATIONARY_WATER)
B(-7,13,4,STATIONARY_WATER)
B(-7,13,5,STATIONARY_WATER)
B(-7,13,6,STATIONARY_WATER)
B(-7,13,7,STATIONARY_WATER)
B(-7,13,8,STATIONARY_WATER)
B(-7,14,-7,STATIONARY_WATER)
B(-7,14,-6,STATIONARY_WATER)
B(-7,14,-5,STATIONARY_WATER)
B(-7,14,-4,STATIONARY_WATER)
B(-7,14,-3,STATIONARY_WATER)
B(-7,14,-2,STATIONARY_WATER)
B(-7,14,-1,STATIONARY_WATER)
B(-7,14,0,STATIONARY_WATER)
B(-7,14,1,STATIONARY_WATER)
B(-7,14,2,STATIONARY_WATER)
B(-7,14,3,STATIONARY_WATER)
B(-7,14,4,STATIONARY_WATER)
B(-7,14,5,STATIONARY_WATER)
B(-7,14,6,STATIONARY_WATER)
B(-7,14,7,STATIONARY_WATER)
B(-7,15,-6,STATIONARY_WATER)
B(-7,15,-5,STATIONARY_WATER)
B(-7,15,-4,STATIONARY_WATER)
B(-7,15,-3,STATIONARY_WATER)
B(-7,15,-2,STATIONARY_WATER)
B(-7,15,-1,STATIONARY_WATER)
B(-7,15,0,STATIONARY_WATER)
B(-7,15,1,STATIONARY_WATER)
B(-7,15,2,STATIONARY_WATER)
B(-7,15,3,STATIONARY_WATER)
B(-7,15,4,STATIONARY_WATER)
B(-7,15,5,STATIONARY_WATER)
B(-7,15,6,STATIONARY_WATER)
B(-7,16,-5,STATIONARY_WATER)
B(-7,16,-4,STATIONARY_WATER)
B(-7,16,-3,STATIONARY_WATER)
B(-7,16,-2,STATIONARY_WATER)
B(-7,16,-1,STATIONARY_WATER)
B(-7,16,0,STATIONARY_WATER)
B(-7,16,1,STATIONARY_WATER)
B(-7,16,2,STATIONARY_WATER)
B(-7,16,3,STATIONARY_WATER)
B(-7,16,4,STATIONARY_WATER)
B(-7,16,5,STATIONARY_WATER)
B(-7,17,-2,STATIONARY_WATER)
B(-7,17,-1,STATIONARY_WATER)
B(-7,17,0,STATIONARY_WATER)
B(-7,17,1,STATIONARY_WATER)
B(-7,17,2,STATIONARY_WATER)
B(-6,0,-14,STATIONARY_WATER)
B(-6,0,-13,STATIONARY_WATER)
B(-6,0,-12,STATIONARY_WATER)
B(-6,0,-11,STATIONARY_WATER)
B(-6,0,-10,STATIONARY_WATER)
B(-6,0,-9,STATIONARY_WATER)
B(-6,0,-8,STATIONARY_WATER)
B(-6,0,-7,STATIONARY_WATER)
B(-6,0,-6,STATIONARY_WATER)
B(-6,0,-5,STATIONARY_WATER)
B(-6,0,-4,STATIONARY_WATER)
B(-6,0,-3,STATIONARY_WATER)
B(-6,0,-2,STATIONARY_WATER)
B(-6,0,-1,STATIONARY_WATER)
B(-6,0,0,STATIONARY_WATER)
B(-6,0,1,STATIONARY_WATER)
B(-6,0,2,STATIONARY_WATER)
B(-6,0,3,STATIONARY_WATER)
B(-6,0,4,STATIONARY_WATER)
B(-6,0,5,STATIONARY_WATER)
B(-6,0,6,STATIONARY_WATER)
B(-6,0,7,STATIONARY_WATER)
B(-6,0,8,STATIONARY_WATER)
B(-6,0,9,STATIONARY_WATER)
B(-6,0,10,STATIONARY_WATER)
B(-6,0,11,STATIONARY_WATER)
B(-6,0,12,STATIONARY_WATER)
B(-6,0,13,STATIONARY_WATER)
B(-6,0,14,STATIONARY_WATER)
B(-6,1,-14,STATIONARY_WATER)
B(-6,1,-13,STATIONARY_WATER)
B(-6,1,-12,STATIONARY_WATER)
B(-6,1,-11,STATIONARY_WATER)
B(-6,1,-10,STATIONARY_WATER)
B(-6,1,-9,STATIONARY_WATER)
B(-6,1,-8,STATIONARY_WATER)
B(-6,1,-7,STATIONARY_WATER)
B(-6,1,-6,STATIONARY_WATER)
B(-6,1,-5,STATIONARY_WATER)
B(-6,1,-4,STATIONARY_WATER)
B(-6,1,-3,STATIONARY_WATER)
B(-6,1,-2,STATIONARY_WATER)
B(-6,1,-1,STATIONARY_WATER)
B(-6,1,0,STATIONARY_WATER)
B(-6,1,1,STATIONARY_WATER)
B(-6,1,2,STATIONARY_WATER)
B(-6,1,3,STATIONARY_WATER)
B(-6,1,4,STATIONARY_WATER)
B(-6,1,5,STATIONARY_WATER)
B(-6,1,6,STATIONARY_WATER)
B(-6,1,7,STATIONARY_WATER)
B(-6,1,8,STATIONARY_WATER)
B(-6,1,9,STATIONARY_WATER)
B(-6,1,10,STATIONARY_WATER)
B(-6,1,11,STATIONARY_WATER)
B(-6,1,12,STATIONARY_WATER)
B(-6,1,13,STATIONARY_WATER)
B(-6,1,14,STATIONARY_WATER)
B(-6,2,-14,STATIONARY_WATER)
B(-6,2,-13,STATIONARY_WATER)
B(-6,2,-12,STATIONARY_WATER)
B(-6,2,-11,STATIONARY_WATER)
B(-6,2,-10,STATIONARY_WATER)
B(-6,2,-9,STATIONARY_WATER)
B(-6,2,-8,STATIONARY_WATER)
B(-6,2,-7,STATIONARY_WATER)
B(-6,2,-6,STATIONARY_WATER)
B(-6,2,-5,STATIONARY_WATER)
B(-6,2,-4,STATIONARY_WATER)
B(-6,2,-3,STATIONARY_WATER)
B(-6,2,-2,STATIONARY_WATER)
B(-6,2,-1,STATIONARY_WATER)
B(-6,2,0,STATIONARY_WATER)
B(-6,2,1,STATIONARY_WATER)
B(-6,2,2,STATIONARY_WATER)
B(-6,2,3,STATIONARY_WATER)
B(-6,2,4,STATIONARY_WATER)
B(-6,2,5,STATIONARY_WATER)
B(-6,2,6,STATIONARY_WATER)
B(-6,2,7,STATIONARY_WATER)
B(-6,2,8,STATIONARY_WATER)
B(-6,2,9,STATIONARY_WATER)
B(-6,2,10,STATIONARY_WATER)
B(-6,2,11,STATIONARY_WATER)
B(-6,2,12,STATIONARY_WATER)
B(-6,2,13,STATIONARY_WATER)
B(-6,2,14,STATIONARY_WATER)
B(-6,3,-13,STATIONARY_WATER)
B(-6,3,-12,STATIONARY_WATER)
B(-6,3,-11,STATIONARY_WATER)
B(-6,3,-10,STATIONARY_WATER)
B(-6,3,-9,STATIONARY_WATER)
B(-6,3,-8,STATIONARY_WATER)
B(-6,3,-7,STATIONARY_WATER)
B(-6,3,-6,STATIONARY_WATER)
B(-6,3,-5,STATIONARY_WATER)
B(-6,3,-4,STATIONARY_WATER)
B(-6,3,-3,STATIONARY_WATER)
B(-6,3,-2,STATIONARY_WATER)
B(-6,3,-1,STATIONARY_WATER)
B(-6,3,0,STATIONARY_WATER)
B(-6,3,1,STATIONARY_WATER)
B(-6,3,2,STATIONARY_WATER)
B(-6,3,3,STATIONARY_WATER)
B(-6,3,4,STATIONARY_WATER)
B(-6,3,5,STATIONARY_WATER)
B(-6,3,6,STATIONARY_WATER)
B(-6,3,7,STATIONARY_WATER)
B(-6,3,8,STATIONARY_WATER)
B(-6,3,9,STATIONARY_WATER)
B(-6,3,10,STATIONARY_WATER)
B(-6,3,11,STATIONARY_WATER)
B(-6,3,12,STATIONARY_WATER)
B(-6,3,13,STATIONARY_WATER)
B(-6,4,-13,STATIONARY_WATER)
B(-6,4,-12,STATIONARY_WATER)
B(-6,4,-11,STATIONARY_WATER)
B(-6,4,-10,STATIONARY_WATER)
B(-6,4,-9,STATIONARY_WATER)
B(-6,4,-8,STATIONARY_WATER)
B(-6,4,-7,STATIONARY_WATER)
B(-6,4,-6,STATIONARY_WATER)
B(-6,4,-5,STATIONARY_WATER)
B(-6,4,-4,STATIONARY_WATER)
B(-6,4,-3,STATIONARY_WATER)
B(-6,4,-2,STATIONARY_WATER)
B(-6,4,-1,STATIONARY_WATER)
B(-6,4,0,STATIONARY_WATER)
B(-6,4,1,STATIONARY_WATER)
B(-6,4,2,STATIONARY_WATER)
B(-6,4,3,STATIONARY_WATER)
B(-6,4,4,STATIONARY_WATER)
B(-6,4,5,STATIONARY_WATER)
B(-6,4,6,STATIONARY_WATER)
B(-6,4,7,STATIONARY_WATER)
B(-6,4,8,STATIONARY_WATER)
B(-6,4,9,STATIONARY_WATER)
B(-6,4,10,STATIONARY_WATER)
B(-6,4,11,STATIONARY_WATER)
B(-6,4,12,STATIONARY_WATER)
B(-6,4,13,STATIONARY_WATER)
B(-6,5,-13,STATIONARY_WATER)
B(-6,5,-12,STATIONARY_WATER)
B(-6,5,-11,STATIONARY_WATER)
B(-6,5,-10,STATIONARY_WATER)
B(-6,5,-9,STATIONARY_WATER)
B(-6,5,-8,STATIONARY_WATER)
B(-6,5,-7,STATIONARY_WATER)
B(-6,5,-6,STATIONARY_WATER)
B(-6,5,-5,STATIONARY_WATER)
B(-6,5,-4,STATIONARY_WATER)
B(-6,5,-3,STATIONARY_WATER)
B(-6,5,-2,STATIONARY_WATER)
B(-6,5,-1,STATIONARY_WATER)
B(-6,5,0,STATIONARY_WATER)
B(-6,5,1,STATIONARY_WATER)
B(-6,5,2,STATIONARY_WATER)
B(-6,5,3,STATIONARY_WATER)
B(-6,5,4,STATIONARY_WATER)
B(-6,5,5,STATIONARY_WATER)
B(-6,5,6,STATIONARY_WATER)
B(-6,5,7,STATIONARY_WATER)
B(-6,5,8,STATIONARY_WATER)
B(-6,5,9,STATIONARY_WATER)
B(-6,5,10,STATIONARY_WATER)
B(-6,5,11,STATIONARY_WATER)
B(-6,5,12,STATIONARY_WATER)
B(-6,5,13,STATIONARY_WATER)
B(-6,6,-13,STATIONARY_WATER)
B(-6,6,-12,STATIONARY_WATER)
B(-6,6,-11,STATIONARY_WATER)
B(-6,6,-10,STATIONARY_WATER)
B(-6,6,-9,STATIONARY_WATER)
B(-6,6,-8,STATIONARY_WATER)
B(-6,6,-7,STATIONARY_WATER)
B(-6,6,-6,STATIONARY_WATER)
B(-6,6,-5,STATIONARY_WATER)
B(-6,6,-4,STATIONARY_WATER)
B(-6,6,-3,STATIONARY_WATER)
B(-6,6,-2,STATIONARY_WATER)
B(-6,6,-1,STATIONARY_WATER)
B(-6,6,0,STATIONARY_WATER)
B(-6,6,1,STATIONARY_WATER)
B(-6,6,2,STATIONARY_WATER)
B(-6,6,3,STATIONARY_WATER)
B(-6,6,4,STATIONARY_WATER)
B(-6,6,5,STATIONARY_WATER)
B(-6,6,6,STATIONARY_WATER)
B(-6,6,7,STATIONARY_WATER)
B(-6,6,8,STATIONARY_WATER)
B(-6,6,9,STATIONARY_WATER)
B(-6,6,10,STATIONARY_WATER)
B(-6,6,11,STATIONARY_WATER)
B(-6,6,12,STATIONARY_WATER)
B(-6,6,13,STATIONARY_WATER)
B(-6,7,-12,STATIONARY_WATER)
B(-6,7,-11,STATIONARY_WATER)
B(-6,7,-10,STATIONARY_WATER)
B(-6,7,-9,STATIONARY_WATER)
B(-6,7,-8,STATIONARY_WATER)
B(-6,7,-7,STATIONARY_WATER)
B(-6,7,-6,STATIONARY_WATER)
B(-6,7,-5,STATIONARY_WATER)
B(-6,7,-4,STATIONARY_WATER)
B(-6,7,-3,STATIONARY_WATER)
B(-6,7,-2,STATIONARY_WATER)
B(-6,7,-1,STATIONARY_WATER)
B(-6,7,0,STATIONARY_WATER)
B(-6,7,1,STATIONARY_WATER)
B(-6,7,2,STATIONARY_WATER)
B(-6,7,3,STATIONARY_WATER)
B(-6,7,4,STATIONARY_WATER)
B(-6,7,5,STATIONARY_WATER)
B(-6,7,6,STATIONARY_WATER)
B(-6,7,7,STATIONARY_WATER)
B(-6,7,8,STATIONARY_WATER)
B(-6,7,9,STATIONARY_WATER)
B(-6,7,10,STATIONARY_WATER)
B(-6,7,11,STATIONARY_WATER)
B(-6,7,12,STATIONARY_WATER)
B(-6,8,-12,STATIONARY_WATER)
B(-6,8,-11,STATIONARY_WATER)
B(-6,8,-10,STATIONARY_WATER)
B(-6,8,-9,STATIONARY_WATER)
B(-6,8,-8,STATIONARY_WATER)
B(-6,8,-7,STATIONARY_WATER)
B(-6,8,-6,STATIONARY_WATER)
B(-6,8,-5,STATIONARY_WATER)
B(-6,8,-4,STATIONARY_WATER)
B(-6,8,-3,STATIONARY_WATER)
B(-6,8,-2,STATIONARY_WATER)
B(-6,8,-1,STATIONARY_WATER)
B(-6,8,0,STATIONARY_WATER)
B(-6,8,1,STATIONARY_WATER)
B(-6,8,2,STATIONARY_WATER)
B(-6,8,3,STATIONARY_WATER)
B(-6,8,4,STATIONARY_WATER)
B(-6,8,5,STATIONARY_WATER)
B(-6,8,6,STATIONARY_WATER)
B(-6,8,7,STATIONARY_WATER)
B(-6,8,8,STATIONARY_WATER)
B(-6,8,9,STATIONARY_WATER)
B(-6,8,10,STATIONARY_WATER)
B(-6,8,11,STATIONARY_WATER)
B(-6,8,12,STATIONARY_WATER)
B(-6,9,-12,STATIONARY_WATER)
B(-6,9,-11,STATIONARY_WATER)
B(-6,9,-10,STATIONARY_WATER)
B(-6,9,-9,STATIONARY_WATER)
B(-6,9,-8,STATIONARY_WATER)
B(-6,9,-7,STATIONARY_WATER)
B(-6,9,-6,STATIONARY_WATER)
B(-6,9,-5,STATIONARY_WATER)
B(-6,9,-4,STATIONARY_WATER)
B(-6,9,-3,STATIONARY_WATER)
B(-6,9,-2,STATIONARY_WATER)
B(-6,9,-1,STATIONARY_WATER)
B(-6,9,0,STATIONARY_WATER)
B(-6,9,1,STATIONARY_WATER)
B(-6,9,2,STATIONARY_WATER)
B(-6,9,3,STATIONARY_WATER)
B(-6,9,4,STATIONARY_WATER)
B(-6,9,5,STATIONARY_WATER)
B(-6,9,6,STATIONARY_WATER)
B(-6,9,7,STATIONARY_WATER)
B(-6,9,8,STATIONARY_WATER)
B(-6,9,9,STATIONARY_WATER)
B(-6,9,10,STATIONARY_WATER)
B(-6,9,11,STATIONARY_WATER)
B(-6,9,12,STATIONARY_WATER)
B(-6,10,-11,STATIONARY_WATER)
B(-6,10,-10,STATIONARY_WATER)
B(-6,10,-9,STATIONARY_WATER)
B(-6,10,-8,STATIONARY_WATER)
B(-6,10,-7,STATIONARY_WATER)
B(-6,10,-6,STATIONARY_WATER)
B(-6,10,-5,STATIONARY_WATER)
B(-6,10,-4,STATIONARY_WATER)
B(-6,10,-3,STATIONARY_WATER)
B(-6,10,-2,STATIONARY_WATER)
B(-6,10,-1,STATIONARY_WATER)
B(-6,10,0,STATIONARY_WATER)
B(-6,10,1,STATIONARY_WATER)
B(-6,10,2,STATIONARY_WATER)
B(-6,10,3,STATIONARY_WATER)
B(-6,10,4,STATIONARY_WATER)
B(-6,10,5,STATIONARY_WATER)
B(-6,10,6,STATIONARY_WATER)
B(-6,10,7,STATIONARY_WATER)
B(-6,10,8,STATIONARY_WATER)
B(-6,10,9,STATIONARY_WATER)
B(-6,10,10,STATIONARY_WATER)
B(-6,10,11,STATIONARY_WATER)
B(-6,11,-11,STATIONARY_WATER)
B(-6,11,-10,STATIONARY_WATER)
B(-6,11,-9,STATIONARY_WATER)
B(-6,11,-8,STATIONARY_WATER)
B(-6,11,-7,STATIONARY_WATER)
B(-6,11,-6,STATIONARY_WATER)
B(-6,11,-5,STATIONARY_WATER)
B(-6,11,-4,STATIONARY_WATER)
B(-6,11,-3,STATIONARY_WATER)
B(-6,11,-2,STATIONARY_WATER)
B(-6,11,-1,STATIONARY_WATER)
B(-6,11,0,STATIONARY_WATER)
B(-6,11,1,STATIONARY_WATER)
B(-6,11,2,STATIONARY_WATER)
B(-6,11,3,STATIONARY_WATER)
B(-6,11,4,STATIONARY_WATER)
B(-6,11,5,STATIONARY_WATER)
B(-6,11,6,STATIONARY_WATER)
B(-6,11,7,STATIONARY_WATER)
B(-6,11,8,STATIONARY_WATER)
B(-6,11,9,STATIONARY_WATER)
B(-6,11,10,STATIONARY_WATER)
B(-6,11,11,STATIONARY_WATER)
B(-6,12,-10,STATIONARY_WATER)
B(-6,12,-9,STATIONARY_WATER)
B(-6,12,-8,STATIONARY_WATER)
B(-6,12,-7,STATIONARY_WATER)
B(-6,12,-6,STATIONARY_WATER)
B(-6,12,-5,STATIONARY_WATER)
B(-6,12,-4,STATIONARY_WATER)
B(-6,12,-3,STATIONARY_WATER)
B(-6,12,-2,STATIONARY_WATER)
B(-6,12,-1,STATIONARY_WATER)
B(-6,12,0,STATIONARY_WATER)
B(-6,12,1,STATIONARY_WATER)
B(-6,12,2,STATIONARY_WATER)
B(-6,12,3,STATIONARY_WATER)
B(-6,12,4,STATIONARY_WATER)
B(-6,12,5,STATIONARY_WATER)
B(-6,12,6,STATIONARY_WATER)
B(-6,12,7,STATIONARY_WATER)
B(-6,12,8,STATIONARY_WATER)
B(-6,12,9,STATIONARY_WATER)
B(-6,12,10,STATIONARY_WATER)
B(-6,13,-9,STATIONARY_WATER)
B(-6,13,-8,STATIONARY_WATER)
B(-6,13,-7,STATIONARY_WATER)
B(-6,13,-6,STATIONARY_WATER)
B(-6,13,-5,STATIONARY_WATER)
B(-6,13,-4,STATIONARY_WATER)
B(-6,13,-3,STATIONARY_WATER)
B(-6,13,-2,STATIONARY_WATER)
B(-6,13,-1,STATIONARY_WATER)
B(-6,13,0,STATIONARY_WATER)
B(-6,13,1,STATIONARY_WATER)
B(-6,13,2,STATIONARY_WATER)
B(-6,13,3,STATIONARY_WATER)
B(-6,13,4,STATIONARY_WATER)
B(-6,13,5,STATIONARY_WATER)
B(-6,13,6,STATIONARY_WATER)
B(-6,13,7,STATIONARY_WATER)
B(-6,13,8,STATIONARY_WATER)
B(-6,13,9,STATIONARY_WATER)
B(-6,14,-8,STATIONARY_WATER)
B(-6,14,-7,STATIONARY_WATER)
B(-6,14,-6,STATIONARY_WATER)
B(-6,14,-5,STATIONARY_WATER)
B(-6,14,-4,STATIONARY_WATER)
B(-6,14,-3,STATIONARY_WATER)
B(-6,14,-2,STATIONARY_WATER)
B(-6,14,-1,STATIONARY_WATER)
B(-6,14,0,STATIONARY_WATER)
B(-6,14,1,STATIONARY_WATER)
B(-6,14,2,STATIONARY_WATER)
B(-6,14,3,STATIONARY_WATER)
B(-6,14,4,STATIONARY_WATER)
B(-6,14,5,STATIONARY_WATER)
B(-6,14,6,STATIONARY_WATER)
B(-6,14,7,STATIONARY_WATER)
B(-6,14,8,STATIONARY_WATER)
B(-6,15,-7,STATIONARY_WATER)
B(-6,15,-6,STATIONARY_WATER)
B(-6,15,-5,STATIONARY_WATER)
B(-6,15,-4,STATIONARY_WATER)
B(-6,15,-3,STATIONARY_WATER)
B(-6,15,-2,STATIONARY_WATER)
B(-6,15,-1,STATIONARY_WATER)
B(-6,15,0,STATIONARY_WATER)
B(-6,15,1,STATIONARY_WATER)
B(-6,15,2,STATIONARY_WATER)
B(-6,15,3,STATIONARY_WATER)
B(-6,15,4,STATIONARY_WATER)
B(-6,15,5,STATIONARY_WATER)
B(-6,15,6,STATIONARY_WATER)
B(-6,15,7,STATIONARY_WATER)
B(-6,16,-6,STATIONARY_WATER)
B(-6,16,-5,STATIONARY_WATER)
B(-6,16,-4,STATIONARY_WATER)
B(-6,16,-3,STATIONARY_WATER)
B(-6,16,-2,STATIONARY_WATER)
B(-6,16,-1,STATIONARY_WATER)
B(-6,16,0,STATIONARY_WATER)
B(-6,16,1,STATIONARY_WATER)
B(-6,16,2,STATIONARY_WATER)
B(-6,16,3,STATIONARY_WATER)
B(-6,16,4,STATIONARY_WATER)
B(-6,16,5,STATIONARY_WATER)
B(-6,16,6,STATIONARY_WATER)
B(-6,17,-4,STATIONARY_WATER)
B(-6,17,-3,STATIONARY_WATER)
B(-6,17,-2,STATIONARY_WATER)
B(-6,17,-1,STATIONARY_WATER)
B(-6,17,0,STATIONARY_WATER)
B(-6,17,1,STATIONARY_WATER)
B(-6,17,2,STATIONARY_WATER)
B(-6,17,3,STATIONARY_WATER)
B(-6,17,4,STATIONARY_WATER)
B(-6,18,-1,STATIONARY_WATER)
B(-6,18,0,STATIONARY_WATER)
B(-6,18,1,STATIONARY_WATER)
B(-5,0,-14,STATIONARY_WATER)
B(-5,0,-13,STATIONARY_WATER)
B(-5,0,-12,STATIONARY_WATER)
B(-5,0,-11,STATIONARY_WATER)
B(-5,0,-10,STATIONARY_WATER)
B(-5,0,-9,STATIONARY_WATER)
B(-5,0,-8,STATIONARY_WATER)
B(-5,0,-7,STATIONARY_WATER)
B(-5,0,-6,STATIONARY_WATER)
B(-5,0,-5,STATIONARY_WATER)
B(-5,0,-4,STATIONARY_WATER)
B(-5,0,-3,STATIONARY_WATER)
B(-5,0,-2,STATIONARY_WATER)
B(-5,0,-1,STATIONARY_WATER)
B(-5,0,0,STATIONARY_WATER)
B(-5,0,1,STATIONARY_WATER)
B(-5,0,2,STATIONARY_WATER)
B(-5,0,3,STATIONARY_WATER)
B(-5,0,4,STATIONARY_WATER)
B(-5,0,5,STATIONARY_WATER)
B(-5,0,6,STATIONARY_WATER)
B(-5,0,7,STATIONARY_WATER)
B(-5,0,8,STATIONARY_WATER)
B(-5,0,9,STATIONARY_WATER)
B(-5,0,10,STATIONARY_WATER)
B(-5,0,11,STATIONARY_WATER)
B(-5,0,12,STATIONARY_WATER)
B(-5,0,13,STATIONARY_WATER)
B(-5,0,14,STATIONARY_WATER)
B(-5,1,-14,STATIONARY_WATER)
B(-5,1,-13,STATIONARY_WATER)
B(-5,1,-12,STATIONARY_WATER)
B(-5,1,-11,STATIONARY_WATER)
B(-5,1,-10,STATIONARY_WATER)
B(-5,1,-9,STATIONARY_WATER)
B(-5,1,-8,STATIONARY_WATER)
B(-5,1,-7,STATIONARY_WATER)
B(-5,1,-6,STATIONARY_WATER)
B(-5,1,-5,STATIONARY_WATER)
B(-5,1,-4,STATIONARY_WATER)
B(-5,1,-3,STATIONARY_WATER)
B(-5,1,-2,STATIONARY_WATER)
B(-5,1,-1,STATIONARY_WATER)
B(-5,1,0,STATIONARY_WATER)
B(-5,1,1,STATIONARY_WATER)
B(-5,1,2,STATIONARY_WATER)
B(-5,1,3,STATIONARY_WATER)
B(-5,1,4,STATIONARY_WATER)
B(-5,1,5,STATIONARY_WATER)
B(-5,1,6,STATIONARY_WATER)
B(-5,1,7,STATIONARY_WATER)
B(-5,1,8,STATIONARY_WATER)
B(-5,1,9,STATIONARY_WATER)
B(-5,1,10,STATIONARY_WATER)
B(-5,1,11,STATIONARY_WATER)
B(-5,1,12,STATIONARY_WATER)
B(-5,1,13,STATIONARY_WATER)
B(-5,1,14,STATIONARY_WATER)
B(-5,2,-14,STATIONARY_WATER)
B(-5,2,-13,STATIONARY_WATER)
B(-5,2,-12,STATIONARY_WATER)
B(-5,2,-11,STATIONARY_WATER)
B(-5,2,-10,STATIONARY_WATER)
B(-5,2,-9,STATIONARY_WATER)
B(-5,2,-8,STATIONARY_WATER)
B(-5,2,-7,STATIONARY_WATER)
B(-5,2,-6,STATIONARY_WATER)
B(-5,2,-5,STATIONARY_WATER)
B(-5,2,-4,STATIONARY_WATER)
B(-5,2,-3,STATIONARY_WATER)
B(-5,2,-2,STATIONARY_WATER)
B(-5,2,-1,STATIONARY_WATER)
B(-5,2,0,STATIONARY_WATER)
B(-5,2,1,STATIONARY_WATER)
B(-5,2,2,STATIONARY_WATER)
B(-5,2,3,STATIONARY_WATER)
B(-5,2,4,STATIONARY_WATER)
B(-5,2,5,STATIONARY_WATER)
B(-5,2,6,STATIONARY_WATER)
B(-5,2,7,STATIONARY_WATER)
B(-5,2,8,STATIONARY_WATER)
B(-5,2,9,STATIONARY_WATER)
B(-5,2,10,STATIONARY_WATER)
B(-5,2,11,STATIONARY_WATER)
B(-5,2,12,STATIONARY_WATER)
B(-5,2,13,STATIONARY_WATER)
B(-5,2,14,STATIONARY_WATER)
B(-5,3,-14,STATIONARY_WATER)
B(-5,3,-13,STATIONARY_WATER)
B(-5,3,-12,STATIONARY_WATER)
B(-5,3,-11,STATIONARY_WATER)
B(-5,3,-10,STATIONARY_WATER)
B(-5,3,-9,STATIONARY_WATER)
B(-5,3,-8,STATIONARY_WATER)
B(-5,3,-7,STATIONARY_WATER)
B(-5,3,-6,STATIONARY_WATER)
B(-5,3,-5,STATIONARY_WATER)
B(-5,3,-4,STATIONARY_WATER)
B(-5,3,-3,STATIONARY_WATER)
B(-5,3,-2,STATIONARY_WATER)
B(-5,3,-1,STATIONARY_WATER)
B(-5,3,0,STATIONARY_WATER)
B(-5,3,1,STATIONARY_WATER)
B(-5,3,2,STATIONARY_WATER)
B(-5,3,3,STATIONARY_WATER)
B(-5,3,4,STATIONARY_WATER)
B(-5,3,5,STATIONARY_WATER)
B(-5,3,6,STATIONARY_WATER)
B(-5,3,7,STATIONARY_WATER)
B(-5,3,8,STATIONARY_WATER)
B(-5,3,9,STATIONARY_WATER)
B(-5,3,10,STATIONARY_WATER)
B(-5,3,11,STATIONARY_WATER)
B(-5,3,12,STATIONARY_WATER)
B(-5,3,13,STATIONARY_WATER)
B(-5,3,14,STATIONARY_WATER)
B(-5,4,-14,STATIONARY_WATER)
B(-5,4,-13,STATIONARY_WATER)
B(-5,4,-12,STATIONARY_WATER)
B(-5,4,-11,STATIONARY_WATER)
B(-5,4,-10,STATIONARY_WATER)
B(-5,4,-9,STATIONARY_WATER)
B(-5,4,-8,STATIONARY_WATER)
B(-5,4,-7,STATIONARY_WATER)
B(-5,4,-6,STATIONARY_WATER)
B(-5,4,-5,STATIONARY_WATER)
B(-5,4,-4,STATIONARY_WATER)
B(-5,4,-3,STATIONARY_WATER)
B(-5,4,-2,STATIONARY_WATER)
B(-5,4,-1,STATIONARY_WATER)
B(-5,4,0,STATIONARY_WATER)
B(-5,4,1,STATIONARY_WATER)
B(-5,4,2,STATIONARY_WATER)
B(-5,4,3,STATIONARY_WATER)
B(-5,4,4,STATIONARY_WATER)
B(-5,4,5,STATIONARY_WATER)
B(-5,4,6,STATIONARY_WATER)
B(-5,4,7,STATIONARY_WATER)
B(-5,4,8,STATIONARY_WATER)
B(-5,4,9,STATIONARY_WATER)
B(-5,4,10,STATIONARY_WATER)
B(-5,4,11,STATIONARY_WATER)
B(-5,4,12,STATIONARY_WATER)
B(-5,4,13,STATIONARY_WATER)
B(-5,4,14,STATIONARY_WATER)
B(-5,5,-13,STATIONARY_WATER)
B(-5,5,-12,STATIONARY_WATER)
B(-5,5,-11,STATIONARY_WATER)
B(-5,5,-10,STATIONARY_WATER)
B(-5,5,-9,STATIONARY_WATER)
B(-5,5,-8,STATIONARY_WATER)
B(-5,5,-7,STATIONARY_WATER)
B(-5,5,-6,STATIONARY_WATER)
B(-5,5,-5,STATIONARY_WATER)
B(-5,5,-4,STATIONARY_WATER)
B(-5,5,-3,STATIONARY_WATER)
B(-5,5,-2,STATIONARY_WATER)
B(-5,5,-1,STATIONARY_WATER)
B(-5,5,0,STATIONARY_WATER)
B(-5,5,1,STATIONARY_WATER)
B(-5,5,2,STATIONARY_WATER)
B(-5,5,3,STATIONARY_WATER)
B(-5,5,4,STATIONARY_WATER)
B(-5,5,5,STATIONARY_WATER)
B(-5,5,6,STATIONARY_WATER)
B(-5,5,7,STATIONARY_WATER)
B(-5,5,8,STATIONARY_WATER)
B(-5,5,9,STATIONARY_WATER)
B(-5,5,10,STATIONARY_WATER)
B(-5,5,11,STATIONARY_WATER)
B(-5,5,12,STATIONARY_WATER)
B(-5,5,13,STATIONARY_WATER)
B(-5,6,-13,STATIONARY_WATER)
B(-5,6,-12,STATIONARY_WATER)
B(-5,6,-11,STATIONARY_WATER)
B(-5,6,-10,STATIONARY_WATER)
B(-5,6,-9,STATIONARY_WATER)
B(-5,6,-8,STATIONARY_WATER)
B(-5,6,-7,STATIONARY_WATER)
B(-5,6,-6,STATIONARY_WATER)
B(-5,6,-5,STATIONARY_WATER)
B(-5,6,-4,STATIONARY_WATER)
B(-5,6,-3,STATIONARY_WATER)
B(-5,6,-2,STATIONARY_WATER)
B(-5,6,-1,STATIONARY_WATER)
B(-5,6,0,STATIONARY_WATER)
B(-5,6,1,STATIONARY_WATER)
B(-5,6,2,STATIONARY_WATER)
B(-5,6,3,STATIONARY_WATER)
B(-5,6,4,STATIONARY_WATER)
B(-5,6,5,STATIONARY_WATER)
B(-5,6,6,STATIONARY_WATER)
B(-5,6,7,STATIONARY_WATER)
B(-5,6,8,STATIONARY_WATER)
B(-5,6,9,STATIONARY_WATER)
B(-5,6,10,STATIONARY_WATER)
B(-5,6,11,STATIONARY_WATER)
B(-5,6,12,STATIONARY_WATER)
B(-5,6,13,STATIONARY_WATER)
B(-5,7,-13,STATIONARY_WATER)
B(-5,7,-12,STATIONARY_WATER)
B(-5,7,-11,STATIONARY_WATER)
B(-5,7,-10,STATIONARY_WATER)
B(-5,7,-9,STATIONARY_WATER)
B(-5,7,-8,STATIONARY_WATER)
B(-5,7,-7,STATIONARY_WATER)
B(-5,7,-6,STATIONARY_WATER)
B(-5,7,-5,STATIONARY_WATER)
B(-5,7,-4,STATIONARY_WATER)
B(-5,7,-3,STATIONARY_WATER)
B(-5,7,-2,STATIONARY_WATER)
B(-5,7,-1,STATIONARY_WATER)
B(-5,7,0,STATIONARY_WATER)
B(-5,7,1,STATIONARY_WATER)
B(-5,7,2,STATIONARY_WATER)
B(-5,7,3,STATIONARY_WATER)
B(-5,7,4,STATIONARY_WATER)
B(-5,7,5,STATIONARY_WATER)
B(-5,7,6,STATIONARY_WATER)
B(-5,7,7,STATIONARY_WATER)
B(-5,7,8,STATIONARY_WATER)
B(-5,7,9,STATIONARY_WATER)
B(-5,7,10,STATIONARY_WATER)
B(-5,7,11,STATIONARY_WATER)
B(-5,7,12,STATIONARY_WATER)
B(-5,7,13,STATIONARY_WATER)
B(-5,8,-12,STATIONARY_WATER)
B(-5,8,-11,STATIONARY_WATER)
B(-5,8,-10,STATIONARY_WATER)
B(-5,8,-9,STATIONARY_WATER)
B(-5,8,-8,STATIONARY_WATER)
B(-5,8,-7,STATIONARY_WATER)
B(-5,8,-6,STATIONARY_WATER)
B(-5,8,-5,STATIONARY_WATER)
B(-5,8,-4,STATIONARY_WATER)
B(-5,8,-3,STATIONARY_WATER)
B(-5,8,-2,STATIONARY_WATER)
B(-5,8,-1,STATIONARY_WATER)
B(-5,8,0,STATIONARY_WATER)
B(-5,8,1,STATIONARY_WATER)
B(-5,8,2,STATIONARY_WATER)
B(-5,8,3,STATIONARY_WATER)
B(-5,8,4,STATIONARY_WATER)
B(-5,8,5,STATIONARY_WATER)
B(-5,8,6,STATIONARY_WATER)
B(-5,8,7,STATIONARY_WATER)
B(-5,8,8,STATIONARY_WATER)
B(-5,8,9,STATIONARY_WATER)
B(-5,8,10,STATIONARY_WATER)
B(-5,8,11,STATIONARY_WATER)
B(-5,8,12,STATIONARY_WATER)
B(-5,9,-12,STATIONARY_WATER)
B(-5,9,-11,STATIONARY_WATER)
B(-5,9,-10,STATIONARY_WATER)
B(-5,9,-9,STATIONARY_WATER)
B(-5,9,-8,STATIONARY_WATER)
B(-5,9,-7,STATIONARY_WATER)
B(-5,9,-6,STATIONARY_WATER)
B(-5,9,-5,STATIONARY_WATER)
B(-5,9,-4,STATIONARY_WATER)
B(-5,9,-3,STATIONARY_WATER)
B(-5,9,-2,STATIONARY_WATER)
B(-5,9,-1,STATIONARY_WATER)
B(-5,9,0,STATIONARY_WATER)
B(-5,9,1,STATIONARY_WATER)
B(-5,9,2,STATIONARY_WATER)
B(-5,9,3,STATIONARY_WATER)
B(-5,9,4,STATIONARY_WATER)
B(-5,9,5,STATIONARY_WATER)
B(-5,9,6,STATIONARY_WATER)
B(-5,9,7,STATIONARY_WATER)
B(-5,9,8,STATIONARY_WATER)
B(-5,9,9,STATIONARY_WATER)
B(-5,9,10,STATIONARY_WATER)
B(-5,9,11,STATIONARY_WATER)
B(-5,9,12,STATIONARY_WATER)
B(-5,10,-12,STATIONARY_WATER)
B(-5,10,-11,STATIONARY_WATER)
B(-5,10,-10,STATIONARY_WATER)
B(-5,10,-9,STATIONARY_WATER)
B(-5,10,-8,STATIONARY_WATER)
B(-5,10,-7,STATIONARY_WATER)
B(-5,10,-6,STATIONARY_WATER)
B(-5,10,-5,STATIONARY_WATER)
B(-5,10,-4,STATIONARY_WATER)
B(-5,10,-3,STATIONARY_WATER)
B(-5,10,-2,STATIONARY_WATER)
B(-5,10,-1,STATIONARY_WATER)
B(-5,10,0,STATIONARY_WATER)
B(-5,10,1,STATIONARY_WATER)
B(-5,10,2,STATIONARY_WATER)
B(-5,10,3,STATIONARY_WATER)
B(-5,10,4,STATIONARY_WATER)
B(-5,10,5,STATIONARY_WATER)
B(-5,10,6,STATIONARY_WATER)
B(-5,10,7,STATIONARY_WATER)
B(-5,10,8,STATIONARY_WATER)
B(-5,10,9,STATIONARY_WATER)
B(-5,10,10,STATIONARY_WATER)
B(-5,10,11,STATIONARY_WATER)
B(-5,10,12,STATIONARY_WATER)
B(-5,11,-11,STATIONARY_WATER)
B(-5,11,-10,STATIONARY_WATER)
B(-5,11,-9,STATIONARY_WATER)
B(-5,11,-8,STATIONARY_WATER)
B(-5,11,-7,STATIONARY_WATER)
B(-5,11,-6,STATIONARY_WATER)
B(-5,11,-5,STATIONARY_WATER)
B(-5,11,-4,STATIONARY_WATER)
B(-5,11,-3,STATIONARY_WATER)
B(-5,11,-2,STATIONARY_WATER)
B(-5,11,-1,STATIONARY_WATER)
B(-5,11,0,STATIONARY_WATER)
B(-5,11,1,STATIONARY_WATER)
B(-5,11,2,STATIONARY_WATER)
B(-5,11,3,STATIONARY_WATER)
B(-5,11,4,STATIONARY_WATER)
B(-5,11,5,STATIONARY_WATER)
B(-5,11,6,STATIONARY_WATER)
B(-5,11,7,STATIONARY_WATER)
B(-5,11,8,STATIONARY_WATER)
B(-5,11,9,STATIONARY_WATER)
B(-5,11,10,STATIONARY_WATER)
B(-5,11,11,STATIONARY_WATER)
B(-5,12,-10,STATIONARY_WATER)
B(-5,12,-9,STATIONARY_WATER)
B(-5,12,-8,STATIONARY_WATER)
B(-5,12,-7,STATIONARY_WATER)
B(-5,12,-6,STATIONARY_WATER)
B(-5,12,-5,STATIONARY_WATER)
B(-5,12,-4,STATIONARY_WATER)
B(-5,12,-3,STATIONARY_WATER)
B(-5,12,-2,STATIONARY_WATER)
B(-5,12,-1,STATIONARY_WATER)
B(-5,12,0,STATIONARY_WATER)
B(-5,12,1,STATIONARY_WATER)
B(-5,12,2,STATIONARY_WATER)
B(-5,12,3,STATIONARY_WATER)
B(-5,12,4,STATIONARY_WATER)
B(-5,12,5,STATIONARY_WATER)
B(-5,12,6,STATIONARY_WATER)
B(-5,12,7,STATIONARY_WATER)
B(-5,12,8,STATIONARY_WATER)
B(-5,12,9,STATIONARY_WATER)
B(-5,12,10,STATIONARY_WATER)
B(-5,13,-10,STATIONARY_WATER)
B(-5,13,-9,STATIONARY_WATER)
B(-5,13,-8,STATIONARY_WATER)
B(-5,13,-7,STATIONARY_WATER)
B(-5,13,-6,STATIONARY_WATER)
B(-5,13,-5,STATIONARY_WATER)
B(-5,13,-4,STATIONARY_WATER)
B(-5,13,-3,STATIONARY_WATER)
B(-5,13,-2,STATIONARY_WATER)
B(-5,13,-1,STATIONARY_WATER)
B(-5,13,0,STATIONARY_WATER)
B(-5,13,1,STATIONARY_WATER)
B(-5,13,2,STATIONARY_WATER)
B(-5,13,3,STATIONARY_WATER)
B(-5,13,4,STATIONARY_WATER)
B(-5,13,5,STATIONARY_WATER)
B(-5,13,6,STATIONARY_WATER)
B(-5,13,7,STATIONARY_WATER)
B(-5,13,8,STATIONARY_WATER)
B(-5,13,9,STATIONARY_WATER)
B(-5,13,10,STATIONARY_WATER)
B(-5,14,-9,STATIONARY_WATER)
B(-5,14,-8,STATIONARY_WATER)
B(-5,14,-7,STATIONARY_WATER)
B(-5,14,-6,STATIONARY_WATER)
B(-5,14,-5,STATIONARY_WATER)
B(-5,14,-4,STATIONARY_WATER)
B(-5,14,-3,STATIONARY_WATER)
B(-5,14,-2,STATIONARY_WATER)
B(-5,14,-1,STATIONARY_WATER)
B(-5,14,0,STATIONARY_WATER)
B(-5,14,1,STATIONARY_WATER)
B(-5,14,2,STATIONARY_WATER)
B(-5,14,3,STATIONARY_WATER)
B(-5,14,4,STATIONARY_WATER)
B(-5,14,5,STATIONARY_WATER)
B(-5,14,6,STATIONARY_WATER)
B(-5,14,7,STATIONARY_WATER)
B(-5,14,8,STATIONARY_WATER)
B(-5,14,9,STATIONARY_WATER)
B(-5,15,-8,STATIONARY_WATER)
B(-5,15,-7,STATIONARY_WATER)
B(-5,15,-6,STATIONARY_WATER)
B(-5,15,-5,STATIONARY_WATER)
B(-5,15,-4,STATIONARY_WATER)
B(-5,15,-3,STATIONARY_WATER)
B(-5,15,-2,STATIONARY_WATER)
B(-5,15,-1,STATIONARY_WATER)
B(-5,15,0,STATIONARY_WATER)
B(-5,15,1,STATIONARY_WATER)
B(-5,15,2,STATIONARY_WATER)
B(-5,15,3,STATIONARY_WATER)
B(-5,15,4,STATIONARY_WATER)
B(-5,15,5,STATIONARY_WATER)
B(-5,15,6,STATIONARY_WATER)
B(-5,15,7,STATIONARY_WATER)
B(-5,15,8,STATIONARY_WATER)
B(-5,16,-7,STATIONARY_WATER)
B(-5,16,-6,STATIONARY_WATER)
B(-5,16,-5,STATIONARY_WATER)
B(-5,16,-4,STATIONARY_WATER)
B(-5,16,-3,STATIONARY_WATER)
B(-5,16,-2,STATIONARY_WATER)
B(-5,16,-1,STATIONARY_WATER)
B(-5,16,0,STATIONARY_WATER)
B(-5,16,1,STATIONARY_WATER)
B(-5,16,2,STATIONARY_WATER)
B(-5,16,3,STATIONARY_WATER)
B(-5,16,4,STATIONARY_WATER)
B(-5,16,5,STATIONARY_WATER)
B(-5,16,6,STATIONARY_WATER)
B(-5,16,7,STATIONARY_WATER)
B(-5,17,-5,STATIONARY_WATER)
B(-5,17,-4,STATIONARY_WATER)
B(-5,17,-3,STATIONARY_WATER)
B(-5,17,-2,STATIONARY_WATER)
B(-5,17,-1,STATIONARY_WATER)
B(-5,17,0,STATIONARY_WATER)
B(-5,17,1,STATIONARY_WATER)
B(-5,17,2,STATIONARY_WATER)
B(-5,17,3,STATIONARY_WATER)
B(-5,17,4,STATIONARY_WATER)
B(-5,17,5,STATIONARY_WATER)
B(-5,18,-3,STATIONARY_WATER)
B(-5,18,-2,STATIONARY_WATER)
B(-5,18,-1,STATIONARY_WATER)
B(-5,18,0,STATIONARY_WATER)
B(-5,18,1,STATIONARY_WATER)
B(-5,18,2,STATIONARY_WATER)
B(-5,18,3,STATIONARY_WATER)
B(-4,0,-15,STATIONARY_WATER)
B(-4,0,-14,STATIONARY_WATER)
B(-4,0,-13,STATIONARY_WATER)
B(-4,0,-12,STATIONARY_WATER)
B(-4,0,-11,STATIONARY_WATER)
B(-4,0,-10,STATIONARY_WATER)
B(-4,0,-9,STATIONARY_WATER)
B(-4,0,-8,STATIONARY_WATER)
B(-4,0,-7,STATIONARY_WATER)
B(-4,0,-6,STATIONARY_WATER)
B(-4,0,-5,STATIONARY_WATER)
B(-4,0,-4,STATIONARY_WATER)
B(-4,0,-3,STATIONARY_WATER)
B(-4,0,-2,STATIONARY_WATER)
B(-4,0,-1,STATIONARY_WATER)
B(-4,0,0,STATIONARY_WATER)
B(-4,0,1,STATIONARY_WATER)
B(-4,0,2,STATIONARY_WATER)
B(-4,0,3,STATIONARY_WATER)
B(-4,0,4,STATIONARY_WATER)
B(-4,0,5,STATIONARY_WATER)
B(-4,0,6,STATIONARY_WATER)
B(-4,0,7,STATIONARY_WATER)
B(-4,0,8,STATIONARY_WATER)
B(-4,0,9,STATIONARY_WATER)
B(-4,0,10,STATIONARY_WATER)
B(-4,0,11,STATIONARY_WATER)
B(-4,0,12,STATIONARY_WATER)
B(-4,0,13,STATIONARY_WATER)
B(-4,0,14,STATIONARY_WATER)
B(-4,0,15,STATIONARY_WATER)
B(-4,1,-15,STATIONARY_WATER)
B(-4,1,-14,STATIONARY_WATER)
B(-4,1,-13,STATIONARY_WATER)
B(-4,1,-12,STATIONARY_WATER)
B(-4,1,-11,STATIONARY_WATER)
B(-4,1,-10,STATIONARY_WATER)
B(-4,1,-9,STATIONARY_WATER)
B(-4,1,-8,STATIONARY_WATER)
B(-4,1,-7,STATIONARY_WATER)
B(-4,1,-6,STATIONARY_WATER)
B(-4,1,-5,STATIONARY_WATER)
B(-4,1,-4,STATIONARY_WATER)
B(-4,1,-3,STATIONARY_WATER)
B(-4,1,-2,STATIONARY_WATER)
B(-4,1,-1,STATIONARY_WATER)
B(-4,1,0,STATIONARY_WATER)
B(-4,1,1,STATIONARY_WATER)
B(-4,1,2,STATIONARY_WATER)
B(-4,1,3,STATIONARY_WATER)
B(-4,1,4,STATIONARY_WATER)
B(-4,1,5,STATIONARY_WATER)
B(-4,1,6,STATIONARY_WATER)
B(-4,1,7,STATIONARY_WATER)
B(-4,1,8,STATIONARY_WATER)
B(-4,1,9,STATIONARY_WATER)
B(-4,1,10,STATIONARY_WATER)
B(-4,1,11,STATIONARY_WATER)
B(-4,1,12,STATIONARY_WATER)
B(-4,1,13,STATIONARY_WATER)
B(-4,1,14,STATIONARY_WATER)
B(-4,1,15,STATIONARY_WATER)
B(-4,2,-15,STATIONARY_WATER)
B(-4,2,-14,STATIONARY_WATER)
B(-4,2,-13,STATIONARY_WATER)
B(-4,2,-12,STATIONARY_WATER)
B(-4,2,-11,STATIONARY_WATER)
B(-4,2,-10,STATIONARY_WATER)
B(-4,2,-9,STATIONARY_WATER)
B(-4,2,-8,STATIONARY_WATER)
B(-4,2,-7,STATIONARY_WATER)
B(-4,2,-6,STATIONARY_WATER)
B(-4,2,-5,STATIONARY_WATER)
B(-4,2,-4,STATIONARY_WATER)
B(-4,2,-3,STATIONARY_WATER)
B(-4,2,-2,STATIONARY_WATER)
B(-4,2,-1,STATIONARY_WATER)
B(-4,2,0,STATIONARY_WATER)
B(-4,2,1,STATIONARY_WATER)
B(-4,2,2,STATIONARY_WATER)
B(-4,2,3,STATIONARY_WATER)
B(-4,2,4,STATIONARY_WATER)
B(-4,2,5,STATIONARY_WATER)
B(-4,2,6,STATIONARY_WATER)
B(-4,2,7,STATIONARY_WATER)
B(-4,2,8,STATIONARY_WATER)
B(-4,2,9,STATIONARY_WATER)
B(-4,2,10,STATIONARY_WATER)
B(-4,2,11,STATIONARY_WATER)
B(-4,2,12,STATIONARY_WATER)
B(-4,2,13,STATIONARY_WATER)
B(-4,2,14,STATIONARY_WATER)
B(-4,2,15,STATIONARY_WATER)
B(-4,3,-14,STATIONARY_WATER)
B(-4,3,-13,STATIONARY_WATER)
B(-4,3,-12,STATIONARY_WATER)
B(-4,3,-11,STATIONARY_WATER)
B(-4,3,-10,STATIONARY_WATER)
B(-4,3,-9,STATIONARY_WATER)
B(-4,3,-8,STATIONARY_WATER)
B(-4,3,-7,STATIONARY_WATER)
B(-4,3,-6,STATIONARY_WATER)
B(-4,3,-5,STATIONARY_WATER)
B(-4,3,-4,STATIONARY_WATER)
B(-4,3,-3,STATIONARY_WATER)
B(-4,3,-2,STATIONARY_WATER)
B(-4,3,-1,STATIONARY_WATER)
B(-4,3,0,STATIONARY_WATER)
B(-4,3,1,STATIONARY_WATER)
B(-4,3,2,STATIONARY_WATER)
B(-4,3,3,STATIONARY_WATER)
B(-4,3,4,STATIONARY_WATER)
B(-4,3,5,STATIONARY_WATER)
B(-4,3,6,STATIONARY_WATER)
B(-4,3,7,STATIONARY_WATER)
B(-4,3,8,STATIONARY_WATER)
B(-4,3,9,STATIONARY_WATER)
B(-4,3,10,STATIONARY_WATER)
B(-4,3,11,STATIONARY_WATER)
B(-4,3,12,STATIONARY_WATER)
B(-4,3,13,STATIONARY_WATER)
B(-4,3,14,STATIONARY_WATER)
B(-4,4,-14,STATIONARY_WATER)
B(-4,4,-13,STATIONARY_WATER)
B(-4,4,-12,STATIONARY_WATER)
B(-4,4,-11,STATIONARY_WATER)
B(-4,4,-10,STATIONARY_WATER)
B(-4,4,-9,STATIONARY_WATER)
B(-4,4,-8,STATIONARY_WATER)
B(-4,4,-7,STATIONARY_WATER)
B(-4,4,-6,STATIONARY_WATER)
B(-4,4,-5,STATIONARY_WATER)
B(-4,4,-4,STATIONARY_WATER)
B(-4,4,-3,STATIONARY_WATER)
B(-4,4,-2,STATIONARY_WATER)
B(-4,4,-1,STATIONARY_WATER)
B(-4,4,0,STATIONARY_WATER)
B(-4,4,1,STATIONARY_WATER)
B(-4,4,2,STATIONARY_WATER)
B(-4,4,3,STATIONARY_WATER)
B(-4,4,4,STATIONARY_WATER)
B(-4,4,5,STATIONARY_WATER)
B(-4,4,6,STATIONARY_WATER)
B(-4,4,7,STATIONARY_WATER)
B(-4,4,8,STATIONARY_WATER)
B(-4,4,9,STATIONARY_WATER)
B(-4,4,10,STATIONARY_WATER)
B(-4,4,11,STATIONARY_WATER)
B(-4,4,12,STATIONARY_WATER)
B(-4,4,13,STATIONARY_WATER)
B(-4,4,14,STATIONARY_WATER)
B(-4,5,-14,STATIONARY_WATER)
B(-4,5,-13,STATIONARY_WATER)
B(-4,5,-12,STATIONARY_WATER)
B(-4,5,-11,STATIONARY_WATER)
B(-4,5,-10,STATIONARY_WATER)
B(-4,5,-9,STATIONARY_WATER)
B(-4,5,-8,STATIONARY_WATER)
B(-4,5,-7,STATIONARY_WATER)
B(-4,5,-6,STATIONARY_WATER)
B(-4,5,-5,STATIONARY_WATER)
B(-4,5,-4,STATIONARY_WATER)
B(-4,5,-3,STATIONARY_WATER)
B(-4,5,-2,STATIONARY_WATER)
B(-4,5,-1,STATIONARY_WATER)
B(-4,5,0,STATIONARY_WATER)
B(-4,5,1,STATIONARY_WATER)
B(-4,5,2,STATIONARY_WATER)
B(-4,5,3,STATIONARY_WATER)
B(-4,5,4,STATIONARY_WATER)
B(-4,5,5,STATIONARY_WATER)
B(-4,5,6,STATIONARY_WATER)
B(-4,5,7,STATIONARY_WATER)
B(-4,5,8,STATIONARY_WATER)
B(-4,5,9,STATIONARY_WATER)
B(-4,5,10,STATIONARY_WATER)
B(-4,5,11,STATIONARY_WATER)
B(-4,5,12,STATIONARY_WATER)
B(-4,5,13,STATIONARY_WATER)
B(-4,5,14,STATIONARY_WATER)
B(-4,6,-14,STATIONARY_WATER)
B(-4,6,-13,STATIONARY_WATER)
B(-4,6,-12,STATIONARY_WATER)
B(-4,6,-11,STATIONARY_WATER)
B(-4,6,-10,STATIONARY_WATER)
B(-4,6,-9,STATIONARY_WATER)
B(-4,6,-8,STATIONARY_WATER)
B(-4,6,-7,STATIONARY_WATER)
B(-4,6,-6,STATIONARY_WATER)
B(-4,6,-5,STATIONARY_WATER)
B(-4,6,-4,STATIONARY_WATER)
B(-4,6,-3,STATIONARY_WATER)
B(-4,6,-2,STATIONARY_WATER)
B(-4,6,-1,STATIONARY_WATER)
B(-4,6,0,STATIONARY_WATER)
B(-4,6,1,STATIONARY_WATER)
B(-4,6,2,STATIONARY_WATER)
B(-4,6,3,STATIONARY_WATER)
B(-4,6,4,STATIONARY_WATER)
B(-4,6,5,STATIONARY_WATER)
B(-4,6,6,STATIONARY_WATER)
B(-4,6,7,STATIONARY_WATER)
B(-4,6,8,STATIONARY_WATER)
B(-4,6,9,STATIONARY_WATER)
B(-4,6,10,STATIONARY_WATER)
B(-4,6,11,STATIONARY_WATER)
B(-4,6,12,STATIONARY_WATER)
B(-4,6,13,STATIONARY_WATER)
B(-4,6,14,STATIONARY_WATER)
B(-4,7,-13,STATIONARY_WATER)
B(-4,7,-12,STATIONARY_WATER)
B(-4,7,-11,STATIONARY_WATER)
B(-4,7,-10,STATIONARY_WATER)
B(-4,7,-9,STATIONARY_WATER)
B(-4,7,-8,STATIONARY_WATER)
B(-4,7,-7,STATIONARY_WATER)
B(-4,7,-6,STATIONARY_WATER)
B(-4,7,-5,STATIONARY_WATER)
B(-4,7,-4,STATIONARY_WATER)
B(-4,7,-3,STATIONARY_WATER)
B(-4,7,-2,STATIONARY_WATER)
B(-4,7,-1,STATIONARY_WATER)
B(-4,7,0,STATIONARY_WATER)
B(-4,7,1,STATIONARY_WATER)
B(-4,7,2,STATIONARY_WATER)
B(-4,7,3,STATIONARY_WATER)
B(-4,7,4,STATIONARY_WATER)
B(-4,7,5,STATIONARY_WATER)
B(-4,7,6,STATIONARY_WATER)
B(-4,7,7,STATIONARY_WATER)
B(-4,7,8,STATIONARY_WATER)
B(-4,7,9,STATIONARY_WATER)
B(-4,7,10,STATIONARY_WATER)
B(-4,7,11,STATIONARY_WATER)
B(-4,7,12,STATIONARY_WATER)
B(-4,7,13,STATIONARY_WATER)
B(-4,8,-13,STATIONARY_WATER)
B(-4,8,-12,STATIONARY_WATER)
B(-4,8,-11,STATIONARY_WATER)
B(-4,8,-10,STATIONARY_WATER)
B(-4,8,-9,STATIONARY_WATER)
B(-4,8,-8,STATIONARY_WATER)
B(-4,8,-7,STATIONARY_WATER)
B(-4,8,-6,STATIONARY_WATER)
B(-4,8,-5,STATIONARY_WATER)
B(-4,8,-4,STATIONARY_WATER)
B(-4,8,-3,STATIONARY_WATER)
B(-4,8,-2,STATIONARY_WATER)
B(-4,8,-1,STATIONARY_WATER)
B(-4,8,0,STATIONARY_WATER)
B(-4,8,1,STATIONARY_WATER)
B(-4,8,2,STATIONARY_WATER)
B(-4,8,3,STATIONARY_WATER)
B(-4,8,4,STATIONARY_WATER)
B(-4,8,5,STATIONARY_WATER)
B(-4,8,6,STATIONARY_WATER)
B(-4,8,7,STATIONARY_WATER)
B(-4,8,8,STATIONARY_WATER)
B(-4,8,9,STATIONARY_WATER)
B(-4,8,10,STATIONARY_WATER)
B(-4,8,11,STATIONARY_WATER)
B(-4,8,12,STATIONARY_WATER)
B(-4,8,13,STATIONARY_WATER)
B(-4,9,-12,STATIONARY_WATER)
B(-4,9,-11,STATIONARY_WATER)
B(-4,9,-10,STATIONARY_WATER)
B(-4,9,-9,STATIONARY_WATER)
B(-4,9,-8,STATIONARY_WATER)
B(-4,9,-7,STATIONARY_WATER)
B(-4,9,-6,STATIONARY_WATER)
B(-4,9,-5,STATIONARY_WATER)
B(-4,9,-4,STATIONARY_WATER)
B(-4,9,-3,STATIONARY_WATER)
B(-4,9,-2,STATIONARY_WATER)
B(-4,9,-1,STATIONARY_WATER)
B(-4,9,0,STATIONARY_WATER)
B(-4,9,1,STATIONARY_WATER)
B(-4,9,2,STATIONARY_WATER)
B(-4,9,3,STATIONARY_WATER)
B(-4,9,4,STATIONARY_WATER)
B(-4,9,5,STATIONARY_WATER)
B(-4,9,6,STATIONARY_WATER)
B(-4,9,7,STATIONARY_WATER)
B(-4,9,8,STATIONARY_WATER)
B(-4,9,9,STATIONARY_WATER)
B(-4,9,10,STATIONARY_WATER)
B(-4,9,11,STATIONARY_WATER)
B(-4,9,12,STATIONARY_WATER)
B(-4,10,-12,STATIONARY_WATER)
B(-4,10,-11,STATIONARY_WATER)
B(-4,10,-10,STATIONARY_WATER)
B(-4,10,-9,STATIONARY_WATER)
B(-4,10,-8,STATIONARY_WATER)
B(-4,10,-7,STATIONARY_WATER)
B(-4,10,-6,STATIONARY_WATER)
B(-4,10,-5,STATIONARY_WATER)
B(-4,10,-4,STATIONARY_WATER)
B(-4,10,-3,STATIONARY_WATER)
B(-4,10,-2,STATIONARY_WATER)
B(-4,10,-1,STATIONARY_WATER)
B(-4,10,0,STATIONARY_WATER)
B(-4,10,1,STATIONARY_WATER)
B(-4,10,2,STATIONARY_WATER)
B(-4,10,3,STATIONARY_WATER)
B(-4,10,4,STATIONARY_WATER)
B(-4,10,5,STATIONARY_WATER)
B(-4,10,6,STATIONARY_WATER)
B(-4,10,7,STATIONARY_WATER)
B(-4,10,8,STATIONARY_WATER)
B(-4,10,9,STATIONARY_WATER)
B(-4,10,10,STATIONARY_WATER)
B(-4,10,11,STATIONARY_WATER)
B(-4,10,12,STATIONARY_WATER)
B(-4,11,-11,STATIONARY_WATER)
B(-4,11,-10,STATIONARY_WATER)
B(-4,11,-9,STATIONARY_WATER)
B(-4,11,-8,STATIONARY_WATER)
B(-4,11,-7,STATIONARY_WATER)
B(-4,11,-6,STATIONARY_WATER)
B(-4,11,-5,STATIONARY_WATER)
B(-4,11,-4,STATIONARY_WATER)
B(-4,11,-3,STATIONARY_WATER)
B(-4,11,-2,STATIONARY_WATER)
B(-4,11,-1,STATIONARY_WATER)
B(-4,11,0,STATIONARY_WATER)
B(-4,11,1,STATIONARY_WATER)
B(-4,11,2,STATIONARY_WATER)
B(-4,11,3,STATIONARY_WATER)
B(-4,11,4,STATIONARY_WATER)
B(-4,11,5,STATIONARY_WATER)
B(-4,11,6,STATIONARY_WATER)
B(-4,11,7,STATIONARY_WATER)
B(-4,11,8,STATIONARY_WATER)
B(-4,11,9,STATIONARY_WATER)
B(-4,11,10,STATIONARY_WATER)
B(-4,11,11,STATIONARY_WATER)
B(-4,12,-11,STATIONARY_WATER)
B(-4,12,-10,STATIONARY_WATER)
B(-4,12,-9,STATIONARY_WATER)
B(-4,12,-8,STATIONARY_WATER)
B(-4,12,-7,STATIONARY_WATER)
B(-4,12,-6,STATIONARY_WATER)
B(-4,12,-5,STATIONARY_WATER)
B(-4,12,-4,STATIONARY_WATER)
B(-4,12,-3,STATIONARY_WATER)
B(-4,12,-2,STATIONARY_WATER)
B(-4,12,-1,STATIONARY_WATER)
B(-4,12,0,STATIONARY_WATER)
B(-4,12,1,STATIONARY_WATER)
B(-4,12,2,STATIONARY_WATER)
B(-4,12,3,STATIONARY_WATER)
B(-4,12,4,STATIONARY_WATER)
B(-4,12,5,STATIONARY_WATER)
B(-4,12,6,STATIONARY_WATER)
B(-4,12,7,STATIONARY_WATER)
B(-4,12,8,STATIONARY_WATER)
B(-4,12,9,STATIONARY_WATER)
B(-4,12,10,STATIONARY_WATER)
B(-4,12,11,STATIONARY_WATER)
B(-4,13,-10,STATIONARY_WATER)
B(-4,13,-9,STATIONARY_WATER)
B(-4,13,-8,STATIONARY_WATER)
B(-4,13,-7,STATIONARY_WATER)
B(-4,13,-6,STATIONARY_WATER)
B(-4,13,-5,STATIONARY_WATER)
B(-4,13,-4,STATIONARY_WATER)
B(-4,13,-3,STATIONARY_WATER)
B(-4,13,-2,STATIONARY_WATER)
B(-4,13,-1,STATIONARY_WATER)
B(-4,13,0,STATIONARY_WATER)
B(-4,13,1,STATIONARY_WATER)
B(-4,13,2,STATIONARY_WATER)
B(-4,13,3,STATIONARY_WATER)
B(-4,13,4,STATIONARY_WATER)
B(-4,13,5,STATIONARY_WATER)
B(-4,13,6,STATIONARY_WATER)
B(-4,13,7,STATIONARY_WATER)
B(-4,13,8,STATIONARY_WATER)
B(-4,13,9,STATIONARY_WATER)
B(-4,13,10,STATIONARY_WATER)
B(-4,14,-9,STATIONARY_WATER)
B(-4,14,-8,STATIONARY_WATER)
B(-4,14,-7,STATIONARY_WATER)
B(-4,14,-6,STATIONARY_WATER)
B(-4,14,-5,STATIONARY_WATER)
B(-4,14,-4,STATIONARY_WATER)
B(-4,14,-3,STATIONARY_WATER)
B(-4,14,-2,STATIONARY_WATER)
B(-4,14,-1,STATIONARY_WATER)
B(-4,14,0,STATIONARY_WATER)
B(-4,14,1,STATIONARY_WATER)
B(-4,14,2,STATIONARY_WATER)
B(-4,14,3,STATIONARY_WATER)
B(-4,14,4,STATIONARY_WATER)
B(-4,14,5,STATIONARY_WATER)
B(-4,14,6,STATIONARY_WATER)
B(-4,14,7,STATIONARY_WATER)
B(-4,14,8,STATIONARY_WATER)
B(-4,14,9,STATIONARY_WATER)
B(-4,15,-8,STATIONARY_WATER)
B(-4,15,-7,STATIONARY_WATER)
B(-4,15,-6,STATIONARY_WATER)
B(-4,15,-5,STATIONARY_WATER)
B(-4,15,-4,STATIONARY_WATER)
B(-4,15,-3,STATIONARY_WATER)
B(-4,15,-2,STATIONARY_WATER)
B(-4,15,-1,STATIONARY_WATER)
B(-4,15,0,STATIONARY_WATER)
B(-4,15,1,STATIONARY_WATER)
B(-4,15,2,STATIONARY_WATER)
B(-4,15,3,STATIONARY_WATER)
B(-4,15,4,STATIONARY_WATER)
B(-4,15,5,STATIONARY_WATER)
B(-4,15,6,STATIONARY_WATER)
B(-4,15,7,STATIONARY_WATER)
B(-4,15,8,STATIONARY_WATER)
B(-4,16,-7,STATIONARY_WATER)
B(-4,16,-6,STATIONARY_WATER)
B(-4,16,-5,STATIONARY_WATER)
B(-4,16,-4,STATIONARY_WATER)
B(-4,16,-3,STATIONARY_WATER)
B(-4,16,-2,STATIONARY_WATER)
B(-4,16,-1,STATIONARY_WATER)
B(-4,16,0,STATIONARY_WATER)
B(-4,16,1,STATIONARY_WATER)
B(-4,16,2,STATIONARY_WATER)
B(-4,16,3,STATIONARY_WATER)
B(-4,16,4,STATIONARY_WATER)
B(-4,16,5,STATIONARY_WATER)
B(-4,16,6,STATIONARY_WATER)
B(-4,16,7,STATIONARY_WATER)
B(-4,17,-6,STATIONARY_WATER)
B(-4,17,-5,STATIONARY_WATER)
B(-4,17,-4,STATIONARY_WATER)
B(-4,17,-3,STATIONARY_WATER)
B(-4,17,-2,STATIONARY_WATER)
B(-4,17,-1,STATIONARY_WATER)
B(-4,17,0,STATIONARY_WATER)
B(-4,17,1,STATIONARY_WATER)
B(-4,17,2,STATIONARY_WATER)
B(-4,17,3,STATIONARY_WATER)
B(-4,17,4,STATIONARY_WATER)
B(-4,17,5,STATIONARY_WATER)
B(-4,17,6,STATIONARY_WATER)
B(-4,18,-4,STATIONARY_WATER)
B(-4,18,-3,STATIONARY_WATER)
B(-4,18,-2,STATIONARY_WATER)
B(-4,18,-1,STATIONARY_WATER)
B(-4,18,0,STATIONARY_WATER)
B(-4,18,1,STATIONARY_WATER)
B(-4,18,2,STATIONARY_WATER)
B(-4,18,3,STATIONARY_WATER)
B(-4,18,4,STATIONARY_WATER)
B(-3,0,-15,STATIONARY_WATER)
B(-3,0,-14,STATIONARY_WATER)
B(-3,0,-13,STATIONARY_WATER)
B(-3,0,-12,STATIONARY_WATER)
B(-3,0,-11,STATIONARY_WATER)
B(-3,0,-10,STATIONARY_WATER)
B(-3,0,-9,STATIONARY_WATER)
B(-3,0,-8,STATIONARY_WATER)
B(-3,0,-7,STATIONARY_WATER)
B(-3,0,-6,STATIONARY_WATER)
B(-3,0,-5,STATIONARY_WATER)
B(-3,0,-4,STATIONARY_WATER)
B(-3,0,-3,STATIONARY_WATER)
B(-3,0,-2,STATIONARY_WATER)
B(-3,0,-1,STATIONARY_WATER)
B(-3,0,0,STATIONARY_WATER)
B(-3,0,1,STATIONARY_WATER)
B(-3,0,2,STATIONARY_WATER)
B(-3,0,3,STATIONARY_WATER)
B(-3,0,4,STATIONARY_WATER)
B(-3,0,5,STATIONARY_WATER)
B(-3,0,6,STATIONARY_WATER)
B(-3,0,7,STATIONARY_WATER)
B(-3,0,8,STATIONARY_WATER)
B(-3,0,9,STATIONARY_WATER)
B(-3,0,10,STATIONARY_WATER)
B(-3,0,11,STATIONARY_WATER)
B(-3,0,12,STATIONARY_WATER)
B(-3,0,13,STATIONARY_WATER)
B(-3,0,14,STATIONARY_WATER)
B(-3,0,15,STATIONARY_WATER)
B(-3,1,-15,STATIONARY_WATER)
B(-3,1,-14,STATIONARY_WATER)
B(-3,1,-13,STATIONARY_WATER)
B(-3,1,-12,STATIONARY_WATER)
B(-3,1,-11,STATIONARY_WATER)
B(-3,1,-10,STATIONARY_WATER)
B(-3,1,-9,STATIONARY_WATER)
B(-3,1,-8,STATIONARY_WATER)
B(-3,1,-7,STATIONARY_WATER)
B(-3,1,-6,STATIONARY_WATER)
B(-3,1,-5,STATIONARY_WATER)
B(-3,1,-4,STATIONARY_WATER)
B(-3,1,-3,STATIONARY_WATER)
B(-3,1,-2,STATIONARY_WATER)
B(-3,1,-1,STATIONARY_WATER)
B(-3,1,0,STATIONARY_WATER)
B(-3,1,1,STATIONARY_WATER)
B(-3,1,2,STATIONARY_WATER)
B(-3,1,3,STATIONARY_WATER)
B(-3,1,4,STATIONARY_WATER)
B(-3,1,5,STATIONARY_WATER)
B(-3,1,6,STATIONARY_WATER)
B(-3,1,7,STATIONARY_WATER)
B(-3,1,8,STATIONARY_WATER)
B(-3,1,9,STATIONARY_WATER)
B(-3,1,10,STATIONARY_WATER)
B(-3,1,11,STATIONARY_WATER)
B(-3,1,12,STATIONARY_WATER)
B(-3,1,13,STATIONARY_WATER)
B(-3,1,14,STATIONARY_WATER)
B(-3,1,15,STATIONARY_WATER)
B(-3,2,-15,STATIONARY_WATER)
B(-3,2,-14,STATIONARY_WATER)
B(-3,2,-13,STATIONARY_WATER)
B(-3,2,-12,STATIONARY_WATER)
B(-3,2,-11,STATIONARY_WATER)
B(-3,2,-10,STATIONARY_WATER)
B(-3,2,-9,STATIONARY_WATER)
B(-3,2,-8,STATIONARY_WATER)
B(-3,2,-7,STATIONARY_WATER)
B(-3,2,-6,STATIONARY_WATER)
B(-3,2,-5,STATIONARY_WATER)
B(-3,2,-4,STATIONARY_WATER)
B(-3,2,-3,STATIONARY_WATER)
B(-3,2,-2,STATIONARY_WATER)
B(-3,2,-1,STATIONARY_WATER)
B(-3,2,0,STATIONARY_WATER)
B(-3,2,1,STATIONARY_WATER)
B(-3,2,2,STATIONARY_WATER)
B(-3,2,3,STATIONARY_WATER)
B(-3,2,4,STATIONARY_WATER)
B(-3,2,5,STATIONARY_WATER)
B(-3,2,6,STATIONARY_WATER)
B(-3,2,7,STATIONARY_WATER)
B(-3,2,8,STATIONARY_WATER)
B(-3,2,9,STATIONARY_WATER)
B(-3,2,10,STATIONARY_WATER)
B(-3,2,11,STATIONARY_WATER)
B(-3,2,12,STATIONARY_WATER)
B(-3,2,13,STATIONARY_WATER)
B(-3,2,14,STATIONARY_WATER)
B(-3,2,15,STATIONARY_WATER)
B(-3,3,-15,STATIONARY_WATER)
B(-3,3,-14,STATIONARY_WATER)
B(-3,3,-13,STATIONARY_WATER)
B(-3,3,-12,STATIONARY_WATER)
B(-3,3,-11,STATIONARY_WATER)
B(-3,3,-10,STATIONARY_WATER)
B(-3,3,-9,STATIONARY_WATER)
B(-3,3,-8,STATIONARY_WATER)
B(-3,3,-7,STATIONARY_WATER)
B(-3,3,-6,STATIONARY_WATER)
B(-3,3,-5,STATIONARY_WATER)
B(-3,3,-4,STATIONARY_WATER)
B(-3,3,-3,STATIONARY_WATER)
B(-3,3,-2,STATIONARY_WATER)
B(-3,3,-1,STATIONARY_WATER)
B(-3,3,0,STATIONARY_WATER)
B(-3,3,1,STATIONARY_WATER)
B(-3,3,2,STATIONARY_WATER)
B(-3,3,3,STATIONARY_WATER)
B(-3,3,4,STATIONARY_WATER)
B(-3,3,5,STATIONARY_WATER)
B(-3,3,6,STATIONARY_WATER)
B(-3,3,7,STATIONARY_WATER)
B(-3,3,8,STATIONARY_WATER)
B(-3,3,9,STATIONARY_WATER)
B(-3,3,10,STATIONARY_WATER)
B(-3,3,11,STATIONARY_WATER)
B(-3,3,12,STATIONARY_WATER)
B(-3,3,13,STATIONARY_WATER)
B(-3,3,14,STATIONARY_WATER)
B(-3,3,15,STATIONARY_WATER)
B(-3,4,-15,STATIONARY_WATER)
B(-3,4,-14,STATIONARY_WATER)
B(-3,4,-13,STATIONARY_WATER)
B(-3,4,-12,STATIONARY_WATER)
B(-3,4,-11,STATIONARY_WATER)
B(-3,4,-10,STATIONARY_WATER)
B(-3,4,-9,STATIONARY_WATER)
B(-3,4,-8,STATIONARY_WATER)
B(-3,4,-7,STATIONARY_WATER)
B(-3,4,-6,STATIONARY_WATER)
B(-3,4,-5,STATIONARY_WATER)
B(-3,4,-4,STATIONARY_WATER)
B(-3,4,-3,STATIONARY_WATER)
