
#######################################################################
# +-----------------------------------------------------------------+ #
# |                            BO3 object                           | #
# +-----------------------------------------------------------------+ #
#######################################################################

Author: LordSmellyPants

Description: No description given

Version: 3

SettingsMode: WriteWithoutComments


#######################################################################
# +-----------------------------------------------------------------+ #
# |                          Main settings                          | #
# +-----------------------------------------------------------------+ #
#######################################################################

Tree: false

Frequency: 1

Rarity: 3.0

RotateRandomly: true

SpawnHeight: randomY

SpawnHeightOffset: 0

SpawnHeightVariance: 0

##############################
# Height Limits for the BO3. #
##############################

MinHeight: 55

MaxHeight: 63

######################
# Extrusion settings #
######################

ExtrudeMode: None

ExtrudeThroughBlocks: AIR

MaxBranchDepth: 10

ExcludedBiomes: All


#######################################################################
# +-----------------------------------------------------------------+ #
# |                      Source block settings                      | #
# +-----------------------------------------------------------------+ #
#######################################################################

SourceBlocks: GRASS,DIRT,GRAVEL,SAND,SAND:1,SANDSTONE,STONE,STONE:1,STONE:3,STONE:5,DIRT:1,CLAY,HARD_CLAY,STAINED_CLAY,RED_ROSE,RED_ROSE:1,RED_ROSE:2,RED_ROSE:3,RED_ROSE:4,RED_ROSE:5,RED_ROSE:6,RED_ROSE:7,RED_ROSE:8,BROWN_MUSHROOM,RED_MUSHROOM,DOUBLE_PLANT,DOUBLE_PLANT:1,DOUBLE_PLANT:2,DOUBLE_PLANT:3,DOUBLE_PLANT:4,DOUBLE_PLANT:5,LONG_GRASS,LONG_GRASS:1,LONG_GRASS:2,DEAD_BUSH,COAL_ORE,IRON_ORE,GOLD_ORE,REDSTONE_ORE,DIAMOND_ORE,LAPIS_ORE,EMERALD_ORE,VINE,AIR,STATIONARY_WATER

MaxPercentageOutsideSourceBlock: 20

OutsideSourceBlock: placeAnyway


#######################################################################
# +-----------------------------------------------------------------+ #
# |                              Blocks                             | #
# +-----------------------------------------------------------------+ #
#######################################################################

B(-6,0,-1,STAINED_CLAY:1)
B(-6,0,0,STAINED_CLAY:1)
B(-6,1,-1,STAINED_CLAY:1)
B(-6,1,0,STAINED_CLAY:1)
B(-5,-1,-1,STAINED_CLAY:1)
B(-5,-1,0,STAINED_CLAY:1)
B(-5,0,-2,STAINED_CLAY:1)
B(-5,0,-1,STAINED_CLAY:1)
B(-5,0,0,STAINED_CLAY:1)
B(-5,0,1,STAINED_CLAY:1)
B(-5,1,-2,STAINED_CLAY:1)
B(-5,1,-1,STAINED_CLAY:1)
B(-5,1,0,STAINED_CLAY:1)
B(-5,1,1,STAINED_CLAY:1)
B(-5,2,-1,STAINED_CLAY:1)
B(-5,2,0,STAINED_CLAY:1)
B(-4,-2,-1,STAINED_CLAY:1)
B(-4,-2,0,STAINED_CLAY:1)
B(-4,-1,-2,STAINED_CLAY:1)
B(-4,-1,-1,STAINED_CLAY:1)
B(-4,-1,0,STAINED_CLAY:1)
B(-4,-1,1,STAINED_CLAY:1)
B(-4,0,-3,STAINED_CLAY:1)
B(-4,0,-2,STAINED_CLAY:1)
B(-4,0,-1,STAINED_CLAY:1)
B(-4,0,0,STAINED_CLAY:1)
B(-4,0,1,STAINED_CLAY:1)
B(-4,0,2,STAINED_CLAY:1)
B(-4,0,3,STAINED_CLAY:1)
B(-4,1,-3,STAINED_CLAY:1)
B(-4,1,-2,STAINED_CLAY:1)
B(-4,1,-1,STAINED_CLAY:1)
B(-4,1,0,STAINED_CLAY:1)
B(-4,1,1,STAINED_CLAY:1)
B(-4,1,2,STAINED_CLAY:1)
B(-4,1,3,STAINED_CLAY:1)
B(-4,2,-2,STAINED_CLAY:1)
B(-4,2,-1,STAINED_CLAY:1)
B(-4,2,0,STAINED_CLAY:1)
B(-4,2,1,STAINED_CLAY:1)
B(-4,3,-2,STAINED_CLAY:4)
B(-4,3,-1,STAINED_CLAY:4)
B(-4,3,0,STAINED_CLAY:4)
B(-4,4,0,STAINED_CLAY:4)
B(-3,-3,0,STAINED_CLAY:1)
B(-3,-2,-1,STAINED_CLAY:1)
B(-3,-2,0,STAINED_CLAY:1)
B(-3,-2,1,STAINED_CLAY:1)
B(-3,-1,-3,STAINED_CLAY:1)
B(-3,-1,-2,STAINED_CLAY:1)
B(-3,-1,-1,STAINED_CLAY:1)
B(-3,-1,0,STAINED_CLAY:1)
B(-3,-1,1,STAINED_CLAY:1)
B(-3,-1,2,STAINED_CLAY:1)
B(-3,-1,3,STAINED_CLAY:1)
B(-3,0,-4,STAINED_CLAY:1)
B(-3,0,-3,STAINED_CLAY:1)
B(-3,0,-2,STAINED_CLAY:1)
B(-3,0,-1,STAINED_CLAY:1)
B(-3,0,0,STAINED_CLAY:1)
B(-3,0,1,STAINED_CLAY:1)
B(-3,0,2,STAINED_CLAY:1)
B(-3,0,3,STAINED_CLAY:1)
B(-3,0,4,STAINED_CLAY:1)
B(-3,1,-4,STAINED_CLAY:1)
B(-3,1,-3,STAINED_CLAY:1)
B(-3,1,-2,STAINED_CLAY:1)
B(-3,1,-1,STAINED_CLAY:1)
B(-3,1,0,STAINED_CLAY:1)
B(-3,1,1,STAINED_CLAY:1)
B(-3,1,2,STAINED_CLAY:1)
B(-3,1,3,STAINED_CLAY:1)
B(-3,1,4,STAINED_CLAY:1)
B(-3,2,-3,STAINED_CLAY:1)
B(-3,2,-2,STAINED_CLAY:1)
B(-3,2,-1,STAINED_CLAY:1)
B(-3,2,0,STAINED_CLAY:1)
B(-3,2,1,STAINED_CLAY:1)
B(-3,2,2,STAINED_CLAY:1)
B(-3,2,3,STAINED_CLAY:1)
B(-3,3,-3,STAINED_CLAY:4)
B(-3,3,-2,STAINED_CLAY:4)
B(-3,3,-1,STAINED_CLAY:4)
B(-3,3,0,STAINED_CLAY:4)
B(-3,3,1,STAINED_CLAY:4)
B(-3,3,2,STAINED_CLAY:1)
B(-3,4,-2,STAINED_CLAY:4)
B(-3,4,-1,STAINED_CLAY:4)
B(-3,4,0,STAINED_CLAY:4)
B(-3,4,1,STAINED_CLAY:4)
B(-3,5,0,STAINED_CLAY:4)
B(-2,-4,0,STAINED_CLAY:1)
B(-2,-3,-1,STAINED_CLAY:1)
B(-2,-3,0,STAINED_CLAY:1)
B(-2,-3,1,STAINED_CLAY:1)
B(-2,-2,-2,STAINED_CLAY:1)
B(-2,-2,-1,STAINED_CLAY:1)
B(-2,-2,0,STAINED_CLAY:1)
B(-2,-2,1,STAINED_CLAY:1)
B(-2,-2,2,STAINED_CLAY:1)
B(-2,-2,3,STAINED_CLAY:1)
B(-2,-1,-4,STAINED_CLAY:1)
B(-2,-1,-3,STAINED_CLAY:1)
B(-2,-1,-2,STAINED_CLAY:1)
B(-2,-1,-1,STAINED_CLAY:1)
B(-2,-1,0,STAINED_CLAY:1)
B(-2,-1,1,STAINED_CLAY:1)
B(-2,-1,2,STAINED_CLAY:1)
B(-2,-1,3,STAINED_CLAY:1)
B(-2,-1,4,STAINED_CLAY:1)
B(-2,0,-4,STAINED_CLAY:1)
B(-2,0,-3,STAINED_CLAY:1)
B(-2,0,-2,STAINED_CLAY:1)
B(-2,0,-1,STAINED_CLAY:1)
B(-2,0,0,STAINED_CLAY:1)
B(-2,0,1,STAINED_CLAY:1)
B(-2,0,2,STAINED_CLAY:1)
B(-2,0,3,STAINED_CLAY:1)
B(-2,0,4,STAINED_CLAY:1)
B(-2,0,5,STAINED_CLAY:1)
B(-2,1,-4,STAINED_CLAY:1)
B(-2,1,-3,STAINED_CLAY:1)
B(-2,1,-2,STAINED_CLAY:1)
B(-2,1,-1,STAINED_CLAY:1)
B(-2,1,0,STAINED_CLAY:1)
B(-2,1,1,STAINED_CLAY:1)
B(-2,1,2,STAINED_CLAY:1)
B(-2,1,3,STAINED_CLAY:1)
B(-2,1,4,STAINED_CLAY:1)
B(-2,1,5,STAINED_CLAY:1)
B(-2,2,-4,STAINED_CLAY:1)
B(-2,2,-3,STAINED_CLAY:1)
B(-2,2,-2,STAINED_CLAY:1)
B(-2,2,-1,STAINED_CLAY:1)
B(-2,2,0,STAINED_CLAY:1)
B(-2,2,1,STAINED_CLAY:1)
B(-2,2,2,STAINED_CLAY:1)
B(-2,2,3,STAINED_CLAY:1)
B(-2,2,4,STAINED_CLAY:1)
B(-2,3,-3,STAINED_CLAY:1)
B(-2,3,-2,STAINED_CLAY:1)
B(-2,3,-1,STAINED_CLAY:1)
B(-2,3,0,STAINED_CLAY:1)
B(-2,3,1,STAINED_CLAY:1)
B(-2,3,2,STAINED_CLAY:1)
B(-2,3,3,STAINED_CLAY:1)
B(-2,3,4,STAINED_CLAY:1)
B(-2,4,-3,STAINED_CLAY:4)
B(-2,4,-2,STAINED_CLAY:1)
B(-2,4,-1,STAINED_CLAY:4)
B(-2,4,0,STAINED_CLAY:1)
B(-2,4,1,STAINED_CLAY:4)
B(-2,4,2,STAINED_CLAY:4)
B(-2,5,-2,STAINED_CLAY:1)
B(-2,5,-1,STAINED_CLAY:1)
B(-2,5,0,STAINED_CLAY:1)
B(-2,5,1,STAINED_CLAY:4)
B(-2,6,-1,HARD_CLAY)
B(-2,6,0,HARD_CLAY)
B(-1,-5,1,STAINED_CLAY:1)
B(-1,-4,0,STAINED_CLAY:1)
B(-1,-4,1,STAINED_CLAY:1)
B(-1,-4,2,STAINED_CLAY:1)
B(-1,-3,-2,STAINED_CLAY:1)
B(-1,-3,-1,STAINED_CLAY:1)
B(-1,-3,0,STAINED_CLAY:1)
B(-1,-3,1,STAINED_CLAY:1)
B(-1,-3,2,STAINED_CLAY:1)
B(-1,-3,3,STAINED_CLAY:1)
B(-1,-2,-3,STAINED_CLAY:1)
B(-1,-2,-2,STAINED_CLAY:1)
B(-1,-2,-1,STAINED_CLAY:1)
B(-1,-2,0,STAINED_CLAY:1)
B(-1,-2,1,STAINED_CLAY:1)
B(-1,-2,2,STAINED_CLAY:1)
B(-1,-2,3,STAINED_CLAY:1)
B(-1,-2,4,STAINED_CLAY:1)
B(-1,-1,-4,STAINED_CLAY:1)
B(-1,-1,-3,STAINED_CLAY:1)
B(-1,-1,-2,STAINED_CLAY:1)
B(-1,-1,-1,STAINED_CLAY:1)
B(-1,-1,0,STAINED_CLAY:1)
B(-1,-1,1,STAINED_CLAY:1)
B(-1,-1,2,STAINED_CLAY:1)
B(-1,-1,3,STAINED_CLAY:1)
B(-1,-1,4,STAINED_CLAY:1)
B(-1,-1,5,STAINED_CLAY:1)
B(-1,0,-4,STAINED_CLAY:1)
B(-1,0,-3,STAINED_CLAY:1)
B(-1,0,-2,STAINED_CLAY:1)
B(-1,0,-1,STAINED_CLAY:1)
B(-1,0,0,STAINED_CLAY:1)
B(-1,0,1,STAINED_CLAY:1)
B(-1,0,2,STAINED_CLAY:1)
B(-1,0,3,STAINED_CLAY:1)
B(-1,0,4,STAINED_CLAY:1)
B(-1,0,5,STAINED_CLAY:1)
B(-1,0,6,STAINED_CLAY:1)
B(-1,1,-4,STAINED_CLAY:1)
B(-1,1,-3,STAINED_CLAY:1)
B(-1,1,-2,STAINED_CLAY:1)
B(-1,1,-1,STAINED_CLAY:1)
B(-1,1,0,STAINED_CLAY:1)
B(-1,1,1,STAINED_CLAY:1)
B(-1,1,2,STAINED_CLAY:1)
B(-1,1,3,STAINED_CLAY:1)
B(-1,1,4,STAINED_CLAY:1)
B(-1,1,5,STAINED_CLAY:1)
B(-1,1,6,STAINED_CLAY:1)
B(-1,2,-4,STAINED_CLAY:1)
B(-1,2,-3,STAINED_CLAY:1)
B(-1,2,-2,STAINED_CLAY:1)
B(-1,2,-1,STAINED_CLAY:1)
B(-1,2,0,STAINED_CLAY:1)
B(-1,2,1,STAINED_CLAY:1)
B(-1,2,2,STAINED_CLAY:1)
B(-1,2,3,STAINED_CLAY:1)
B(-1,2,4,STAINED_CLAY:1)
B(-1,2,5,STAINED_CLAY:1)
B(-1,3,-4,STAINED_CLAY:1)
B(-1,3,-3,STAINED_CLAY:1)
B(-1,3,-2,STAINED_CLAY:1)
B(-1,3,-1,STAINED_CLAY:1)
B(-1,3,0,STAINED_CLAY:1)
B(-1,3,1,STAINED_CLAY:1)
B(-1,3,2,STAINED_CLAY:1)
B(-1,3,3,STAINED_CLAY:1)
B(-1,3,4,STAINED_CLAY:1)
B(-1,4,-4,STAINED_CLAY:4)
B(-1,4,-3,STAINED_CLAY:1)
B(-1,4,-2,STAINED_CLAY:1)
B(-1,4,-1,STAINED_CLAY:1)
B(-1,4,0,STAINED_CLAY:1)
B(-1,4,1,STAINED_CLAY:1)
B(-1,4,2,STAINED_CLAY:1)
B(-1,4,3,STAINED_CLAY:4)
B(-1,4,4,STAINED_CLAY:4)
B(-1,5,-3,STAINED_CLAY:1)
B(-1,5,-2,STAINED_CLAY:1)
B(-1,5,-1,STAINED_CLAY:1)
B(-1,5,0,STAINED_CLAY:1)
B(-1,5,1,STAINED_CLAY:1)
B(-1,5,2,STAINED_CLAY:4)
B(-1,5,3,STAINED_CLAY:4)
B(-1,5,4,STAINED_CLAY:4)
B(-1,6,-3,HARD_CLAY)
B(-1,6,-2,HARD_CLAY)
B(-1,6,-1,HARD_CLAY)
B(-1,6,0,HARD_CLAY)
B(-1,6,1,HARD_CLAY)
B(-1,6,2,HARD_CLAY)
B(-1,6,3,HARD_CLAY)
B(-1,7,-2,HARD_CLAY)
B(-1,7,-1,HARD_CLAY)
B(-1,7,0,HARD_CLAY)
B(-1,7,1,HARD_CLAY)
B(-1,7,2,HARD_CLAY)
B(-1,8,-2,HARD_CLAY)
B(-1,8,-1,STAINED_CLAY:1)
B(-1,8,0,STAINED_CLAY:1)
B(-1,8,1,STAINED_CLAY:1)
B(-1,9,-2,HARD_CLAY)
B(-1,9,-1,HARD_CLAY)
B(-1,9,0,HARD_CLAY)
B(-1,9,1,HARD_CLAY)
B(-1,10,0,HARD_CLAY)
B(-1,10,1,HARD_CLAY)
B(-1,11,1,STAINED_CLAY:1)
B(-1,12,1,HARD_CLAY)
B(-1,13,1,STAINED_CLAY:14)
B(-1,14,1,STAINED_CLAY:12)
B(-1,15,1,STAINED_CLAY:12)
B(-1,16,1,HARD_CLAY)
B(0,-5,0,STAINED_CLAY:1)
B(0,-5,1,STAINED_CLAY:1)
B(0,-4,-1,STAINED_CLAY:1)
B(0,-4,0,STAINED_CLAY:1)
B(0,-4,1,STAINED_CLAY:1)
B(0,-4,2,STAINED_CLAY:1)
B(0,-3,-2,STAINED_CLAY:1)
B(0,-3,-1,STAINED_CLAY:1)
B(0,-3,0,STAINED_CLAY:1)
B(0,-3,1,STAINED_CLAY:1)
B(0,-3,2,STAINED_CLAY:1)
B(0,-3,3,STAINED_CLAY:1)
B(0,-2,-3,STAINED_CLAY:1)
B(0,-2,-2,STAINED_CLAY:1)
B(0,-2,-1,STAINED_CLAY:1)
B(0,-2,0,STAINED_CLAY:1)
B(0,-2,1,STAINED_CLAY:1)
B(0,-2,2,STAINED_CLAY:1)
B(0,-2,3,STAINED_CLAY:1)
B(0,-2,4,STAINED_CLAY:1)
B(0,-1,-4,STAINED_CLAY:1)
B(0,-1,-3,STAINED_CLAY:1)
B(0,-1,-2,STAINED_CLAY:1)
B(0,-1,-1,STAINED_CLAY:1)
B(0,-1,0,STAINED_CLAY:1)
B(0,-1,1,STAINED_CLAY:1)
B(0,-1,2,STAINED_CLAY:1)
B(0,-1,3,STAINED_CLAY:1)
B(0,-1,4,STAINED_CLAY:1)
B(0,-1,5,STAINED_CLAY:1)
B(0,-1,6,STAINED_CLAY:1)
B(0,0,-4,STAINED_CLAY:1)
B(0,0,-3,STAINED_CLAY:1)
B(0,0,-2,STAINED_CLAY:1)
B(0,0,-1,STAINED_CLAY:1)
B(0,0,0,STAINED_CLAY:1)
B(0,0,1,STAINED_CLAY:1)
B(0,0,2,STAINED_CLAY:1)
B(0,0,3,STAINED_CLAY:1)
B(0,0,4,STAINED_CLAY:1)
B(0,0,5,STAINED_CLAY:1)
B(0,0,6,STAINED_CLAY:1)
B(0,1,-4,STAINED_CLAY:1)
B(0,1,-3,STAINED_CLAY:1)
B(0,1,-2,STAINED_CLAY:1)
B(0,1,-1,STAINED_CLAY:1)
B(0,1,0,STAINED_CLAY:1)
B(0,1,1,STAINED_CLAY:1)
B(0,1,2,STAINED_CLAY:1)
B(0,1,3,STAINED_CLAY:1)
B(0,1,4,STAINED_CLAY:1)
B(0,1,5,STAINED_CLAY:1)
B(0,1,6,STAINED_CLAY:1)
B(0,2,-4,STAINED_CLAY:1)
B(0,2,-3,STAINED_CLAY:1)
B(0,2,-2,STAINED_CLAY:1)
B(0,2,-1,STAINED_CLAY:1)
B(0,2,0,STAINED_CLAY:1)
B(0,2,1,STAINED_CLAY:1)
B(0,2,2,STAINED_CLAY:1)
B(0,2,3,STAINED_CLAY:1)
B(0,2,4,STAINED_CLAY:1)
B(0,2,5,STAINED_CLAY:1)
B(0,3,-3,STAINED_CLAY:4)
B(0,3,-2,STAINED_CLAY:1)
B(0,3,-1,STAINED_CLAY:1)
B(0,3,0,STAINED_CLAY:1)
B(0,3,1,STAINED_CLAY:1)
B(0,3,2,STAINED_CLAY:1)
B(0,3,3,STAINED_CLAY:1)
B(0,3,4,STAINED_CLAY:1)
B(0,3,5,STAINED_CLAY:1)
B(0,4,-3,STAINED_CLAY:4)
B(0,4,-2,STAINED_CLAY:1)
B(0,4,-1,STAINED_CLAY:1)
B(0,4,0,STAINED_CLAY:1)
B(0,4,1,STAINED_CLAY:1)
B(0,4,2,STAINED_CLAY:1)
B(0,4,3,STAINED_CLAY:1)
B(0,4,4,STAINED_CLAY:4)
B(0,5,-3,STAINED_CLAY:4)
B(0,5,-2,STAINED_CLAY:1)
B(0,5,-1,STAINED_CLAY:1)
B(0,5,0,STAINED_CLAY:1)
B(0,5,1,STAINED_CLAY:1)
B(0,5,2,STAINED_CLAY:1)
B(0,5,3,STAINED_CLAY:1)
B(0,5,4,STAINED_CLAY:4)
B(0,6,-2,HARD_CLAY)
B(0,6,-1,HARD_CLAY)
B(0,6,0,HARD_CLAY)
B(0,6,1,HARD_CLAY)
B(0,6,2,HARD_CLAY)
B(0,6,3,HARD_CLAY)
B(0,6,4,HARD_CLAY)
B(0,7,-2,HARD_CLAY)
B(0,7,-1,HARD_CLAY)
B(0,7,0,HARD_CLAY)
B(0,7,1,HARD_CLAY)
B(0,7,2,HARD_CLAY)
B(0,7,3,HARD_CLAY)
B(0,8,-2,HARD_CLAY)
B(0,8,-1,STAINED_CLAY:1)
B(0,8,0,STAINED_CLAY:1)
B(0,8,1,HARD_CLAY)
B(0,8,2,STAINED_CLAY:1)
B(0,9,-2,HARD_CLAY)
B(0,9,-1,HARD_CLAY)
B(0,9,0,HARD_CLAY)
B(0,9,1,HARD_CLAY)
B(0,9,2,HARD_CLAY)
B(0,10,-2,HARD_CLAY)
B(0,10,-1,HARD_CLAY)
B(0,10,0,HARD_CLAY)
B(0,10,1,HARD_CLAY)
B(0,10,2,HARD_CLAY)
B(0,11,-2,HARD_CLAY)
B(0,11,-1,STAINED_CLAY:1)
B(0,11,0,STAINED_CLAY:1)
B(0,11,1,STAINED_CLAY:1)
B(0,11,2,STAINED_CLAY:1)
B(0,12,-2,HARD_CLAY)
B(0,12,-1,HARD_CLAY)
B(0,12,0,HARD_CLAY)
B(0,12,1,HARD_CLAY)
B(0,12,2,HARD_CLAY)
B(0,13,-2,STAINED_CLAY:14)
B(0,13,-1,STAINED_CLAY:14)
B(0,13,0,STAINED_CLAY:14)
B(0,13,1,STAINED_CLAY:14)
B(0,13,2,STAINED_CLAY:14)
B(0,14,-2,STAINED_CLAY:12)
B(0,14,-1,STAINED_CLAY:12)
B(0,14,0,STAINED_CLAY:12)
B(0,14,1,STAINED_CLAY:12)
B(0,14,2,STAINED_CLAY:12)
B(0,15,-2,STAINED_CLAY:12)
B(0,15,-1,STAINED_CLAY:12)
B(0,15,0,STAINED_CLAY:12)
B(0,15,1,STAINED_CLAY:12)
B(0,15,2,STAINED_CLAY:12)
B(0,16,-2,HARD_CLAY)
B(0,16,-1,HARD_CLAY)
B(0,16,0,HARD_CLAY)
B(0,16,1,HARD_CLAY)
B(0,16,2,HARD_CLAY)
B(1,-5,0,STAINED_CLAY:1)
B(1,-5,1,STAINED_CLAY:1)
B(1,-5,2,STAINED_CLAY:1)
B(1,-4,-1,STAINED_CLAY:1)
B(1,-4,0,STAINED_CLAY:1)
B(1,-4,1,STAINED_CLAY:1)
B(1,-4,2,STAINED_CLAY:1)
B(1,-4,3,STAINED_CLAY:1)
B(1,-3,-1,STAINED_CLAY:1)
B(1,-3,0,STAINED_CLAY:1)
B(1,-3,1,STAINED_CLAY:1)
B(1,-3,2,STAINED_CLAY:1)
B(1,-3,3,STAINED_CLAY:1)
B(1,-2,-2,STAINED_CLAY:1)
B(1,-2,-1,STAINED_CLAY:1)
B(1,-2,0,STAINED_CLAY:1)
B(1,-2,1,STAINED_CLAY:1)
B(1,-2,2,STAINED_CLAY:1)
B(1,-2,3,STAINED_CLAY:1)
B(1,-2,4,STAINED_CLAY:1)
B(1,-1,-3,STAINED_CLAY:1)
B(1,-1,-2,STAINED_CLAY:1)
B(1,-1,-1,STAINED_CLAY:1)
B(1,-1,0,STAINED_CLAY:1)
B(1,-1,1,STAINED_CLAY:1)
B(1,-1,2,STAINED_CLAY:1)
B(1,-1,3,STAINED_CLAY:1)
B(1,-1,4,STAINED_CLAY:1)
B(1,-1,5,STAINED_CLAY:1)
B(1,0,-3,STAINED_CLAY:1)
B(1,0,-2,STAINED_CLAY:1)
B(1,0,-1,STAINED_CLAY:1)
B(1,0,0,STAINED_CLAY:1)
B(1,0,1,STAINED_CLAY:1)
B(1,0,2,STAINED_CLAY:1)
B(1,0,3,STAINED_CLAY:1)
B(1,0,4,STAINED_CLAY:1)
B(1,0,5,STAINED_CLAY:1)
B(1,0,6,STAINED_CLAY:1)
B(1,1,-3,STAINED_CLAY:1)
B(1,1,-2,STAINED_CLAY:1)
B(1,1,-1,STAINED_CLAY:1)
B(1,1,0,STAINED_CLAY:1)
B(1,1,1,STAINED_CLAY:1)
B(1,1,2,STAINED_CLAY:1)
B(1,1,3,STAINED_CLAY:1)
B(1,1,4,STAINED_CLAY:1)
B(1,1,5,STAINED_CLAY:1)
B(1,1,6,STAINED_CLAY:1)
B(1,2,-3,STAINED_CLAY:1)
B(1,2,-2,STAINED_CLAY:1)
B(1,2,-1,STAINED_CLAY:1)
B(1,2,0,STAINED_CLAY:1)
B(1,2,1,STAINED_CLAY:1)
B(1,2,2,STAINED_CLAY:1)
B(1,2,3,STAINED_CLAY:1)
B(1,2,4,STAINED_CLAY:1)
B(1,2,5,STAINED_CLAY:1)
B(1,2,6,STAINED_CLAY:1)
B(1,3,-3,STAINED_CLAY:4)
B(1,3,-2,STAINED_CLAY:1)
B(1,3,-1,STAINED_CLAY:1)
B(1,3,0,STAINED_CLAY:1)
B(1,3,1,STAINED_CLAY:1)
B(1,3,2,STAINED_CLAY:1)
B(1,3,3,STAINED_CLAY:1)
B(1,3,4,STAINED_CLAY:1)
B(1,3,5,STAINED_CLAY:1)
B(1,4,-2,STAINED_CLAY:4)
B(1,4,-1,STAINED_CLAY:1)
B(1,4,0,STAINED_CLAY:1)
B(1,4,1,STAINED_CLAY:1)
B(1,4,2,STAINED_CLAY:1)
B(1,4,3,STAINED_CLAY:1)
B(1,4,4,STAINED_CLAY:1)
B(1,4,5,STAINED_CLAY:4)
B(1,5,-2,STAINED_CLAY:4)
B(1,5,-1,STAINED_CLAY:1)
B(1,5,0,STAINED_CLAY:1)
B(1,5,1,STAINED_CLAY:1)
B(1,5,2,STAINED_CLAY:1)
B(1,5,3,STAINED_CLAY:1)
B(1,5,4,STAINED_CLAY:4)
B(1,6,-2,HARD_CLAY)
B(1,6,-1,HARD_CLAY)
B(1,6,0,HARD_CLAY)
B(1,6,1,HARD_CLAY)
B(1,6,2,HARD_CLAY)
B(1,6,3,HARD_CLAY)
B(1,6,4,HARD_CLAY)
B(1,7,-2,HARD_CLAY)
B(1,7,-1,HARD_CLAY)
B(1,7,0,HARD_CLAY)
B(1,7,1,HARD_CLAY)
B(1,7,2,HARD_CLAY)
B(1,7,3,HARD_CLAY)
B(1,7,4,HARD_CLAY)
B(1,8,-2,STAINED_CLAY:1)
B(1,8,-1,HARD_CLAY)
B(1,8,0,HARD_CLAY)
B(1,8,1,HARD_CLAY)
B(1,8,2,HARD_CLAY)
B(1,8,3,STAINED_CLAY:1)
B(1,9,-2,HARD_CLAY)
B(1,9,-1,HARD_CLAY)
B(1,9,0,HARD_CLAY)
B(1,9,1,HARD_CLAY)
B(1,9,2,HARD_CLAY)
B(1,9,3,HARD_CLAY)
B(1,10,-2,HARD_CLAY)
B(1,10,-1,HARD_CLAY)
B(1,10,0,HARD_CLAY)
B(1,10,1,HARD_CLAY)
B(1,10,2,HARD_CLAY)
B(1,10,3,HARD_CLAY)
B(1,11,-2,STAINED_CLAY:1)
B(1,11,-1,STAINED_CLAY:1)
B(1,11,0,STAINED_CLAY:1)
B(1,11,1,STAINED_CLAY:1)
B(1,11,2,STAINED_CLAY:1)
B(1,11,3,STAINED_CLAY:1)
B(1,12,-2,HARD_CLAY)
B(1,12,-1,HARD_CLAY)
B(1,12,0,HARD_CLAY)
B(1,12,1,HARD_CLAY)
B(1,12,2,HARD_CLAY)
B(1,12,3,HARD_CLAY)
B(1,13,-2,STAINED_CLAY:14)
B(1,13,-1,STAINED_CLAY:14)
B(1,13,0,STAINED_CLAY:14)
B(1,13,1,STAINED_CLAY:14)
B(1,13,2,STAINED_CLAY:14)
B(1,13,3,STAINED_CLAY:14)
B(1,14,-2,STAINED_CLAY:12)
B(1,14,-1,STAINED_CLAY:12)
B(1,14,0,STAINED_CLAY:12)
B(1,14,1,STAINED_CLAY:12)
B(1,14,2,STAINED_CLAY:12)
B(1,15,-2,STAINED_CLAY:12)
B(1,15,-1,STAINED_CLAY:12)
B(1,15,0,STAINED_CLAY:12)
B(1,15,1,STAINED_CLAY:12)
B(1,15,2,STAINED_CLAY:12)
B(1,16,-2,HARD_CLAY)
B(1,16,-1,HARD_CLAY)
B(1,16,0,HARD_CLAY)
B(1,16,1,HARD_CLAY)
B(1,16,2,HARD_CLAY)
B(2,-5,1,STAINED_CLAY:1)
B(2,-5,2,STAINED_CLAY:1)
B(2,-4,0,STAINED_CLAY:1)
B(2,-4,1,STAINED_CLAY:1)
B(2,-4,2,STAINED_CLAY:1)
B(2,-3,-1,STAINED_CLAY:1)
B(2,-3,0,STAINED_CLAY:1)
B(2,-3,1,STAINED_CLAY:1)
B(2,-3,2,STAINED_CLAY:1)
B(2,-3,3,STAINED_CLAY:1)
B(2,-2,-2,STAINED_CLAY:1)
B(2,-2,-1,STAINED_CLAY:1)
B(2,-2,0,STAINED_CLAY:1)
B(2,-2,1,STAINED_CLAY:1)
B(2,-2,2,STAINED_CLAY:1)
B(2,-2,3,STAINED_CLAY:1)
B(2,-2,4,STAINED_CLAY:1)
B(2,-1,-3,STAINED_CLAY:1)
B(2,-1,-2,STAINED_CLAY:1)
B(2,-1,-1,STAINED_CLAY:1)
B(2,-1,0,STAINED_CLAY:1)
B(2,-1,1,STAINED_CLAY:1)
B(2,-1,2,STAINED_CLAY:1)
B(2,-1,3,STAINED_CLAY:1)
B(2,-1,4,STAINED_CLAY:1)
B(2,-1,5,STAINED_CLAY:1)
B(2,0,-3,STAINED_CLAY:1)
B(2,0,-2,STAINED_CLAY:1)
B(2,0,-1,STAINED_CLAY:1)
B(2,0,0,STAINED_CLAY:1)
B(2,0,1,STAINED_CLAY:1)
B(2,0,2,STAINED_CLAY:1)
B(2,0,3,STAINED_CLAY:1)
B(2,0,4,STAINED_CLAY:1)
B(2,0,5,STAINED_CLAY:1)
B(2,0,6,STAINED_CLAY:1)
B(2,1,-3,STAINED_CLAY:1)
B(2,1,-2,STAINED_CLAY:1)
B(2,1,-1,STAINED_CLAY:1)
B(2,1,0,STAINED_CLAY:1)
B(2,1,1,STAINED_CLAY:1)
B(2,1,2,STAINED_CLAY:1)
B(2,1,3,STAINED_CLAY:1)
B(2,1,4,STAINED_CLAY:1)
B(2,1,5,STAINED_CLAY:1)
B(2,1,6,STAINED_CLAY:1)
B(2,2,-3,STAINED_CLAY:1)
B(2,2,-2,STAINED_CLAY:1)
B(2,2,-1,STAINED_CLAY:1)
B(2,2,0,STAINED_CLAY:1)
B(2,2,1,STAINED_CLAY:1)
B(2,2,2,STAINED_CLAY:1)
B(2,2,3,STAINED_CLAY:1)
B(2,2,4,STAINED_CLAY:1)
B(2,2,5,STAINED_CLAY:1)
B(2,2,6,STAINED_CLAY:1)
B(2,3,-3,STAINED_CLAY:4)
B(2,3,-2,STAINED_CLAY:1)
B(2,3,-1,STAINED_CLAY:1)
B(2,3,0,STAINED_CLAY:1)
B(2,3,1,STAINED_CLAY:1)
B(2,3,2,STAINED_CLAY:1)
B(2,3,3,STAINED_CLAY:1)
B(2,3,4,STAINED_CLAY:1)
B(2,3,5,STAINED_CLAY:1)
B(2,3,6,STAINED_CLAY:1)
B(2,4,-2,STAINED_CLAY:4)
B(2,4,-1,STAINED_CLAY:1)
B(2,4,0,STAINED_CLAY:1)
B(2,4,1,STAINED_CLAY:1)
B(2,4,2,STAINED_CLAY:1)
B(2,4,3,STAINED_CLAY:1)
B(2,4,4,STAINED_CLAY:1)
B(2,4,5,STAINED_CLAY:4)
B(2,4,6,STAINED_CLAY:4)
B(2,5,-1,STAINED_CLAY:1)
B(2,5,0,STAINED_CLAY:1)
B(2,5,1,STAINED_CLAY:1)
B(2,5,2,STAINED_CLAY:1)
B(2,5,3,STAINED_CLAY:1)
B(2,5,4,STAINED_CLAY:1)
B(2,5,5,STAINED_CLAY:4)
B(2,6,-1,HARD_CLAY)
B(2,6,0,HARD_CLAY)
B(2,6,1,HARD_CLAY)
B(2,6,2,HARD_CLAY)
B(2,6,3,HARD_CLAY)
B(2,6,4,HARD_CLAY)
B(2,7,-1,HARD_CLAY)
B(2,7,0,HARD_CLAY)
B(2,7,1,HARD_CLAY)
B(2,7,2,HARD_CLAY)
B(2,7,3,HARD_CLAY)
B(2,7,4,HARD_CLAY)
B(2,8,-1,HARD_CLAY)
B(2,8,0,HARD_CLAY)
B(2,8,1,HARD_CLAY)
B(2,8,2,HARD_CLAY)
B(2,8,3,HARD_CLAY)
B(2,8,4,STAINED_CLAY:1)
B(2,9,-1,HARD_CLAY)
B(2,9,0,HARD_CLAY)
B(2,9,1,HARD_CLAY)
B(2,9,2,HARD_CLAY)
B(2,9,3,HARD_CLAY)
B(2,9,4,HARD_CLAY)
B(2,10,-1,HARD_CLAY)
B(2,10,0,HARD_CLAY)
B(2,10,1,HARD_CLAY)
B(2,10,2,HARD_CLAY)
B(2,10,3,HARD_CLAY)
B(2,10,4,HARD_CLAY)
B(2,11,-1,HARD_CLAY)
B(2,11,0,STAINED_CLAY:1)
B(2,11,1,STAINED_CLAY:1)
B(2,11,2,STAINED_CLAY:1)
B(2,11,3,STAINED_CLAY:1)
B(2,11,4,STAINED_CLAY:1)
B(2,12,-1,HARD_CLAY)
B(2,12,0,HARD_CLAY)
B(2,12,1,HARD_CLAY)
B(2,12,2,HARD_CLAY)
B(2,12,3,HARD_CLAY)
B(2,12,4,HARD_CLAY)
B(2,13,-1,HARD_CLAY)
B(2,13,0,STAINED_CLAY:14)
B(2,13,1,STAINED_CLAY:14)
B(2,13,2,STAINED_CLAY:14)
B(2,13,3,STAINED_CLAY:14)
B(2,13,4,STAINED_CLAY:14)
B(2,14,-1,HARD_CLAY)
B(2,14,0,HARD_CLAY)
B(2,14,1,STAINED_CLAY:12)
B(2,14,2,STAINED_CLAY:12)
B(2,14,3,STAINED_CLAY:12)
B(2,14,4,STAINED_CLAY:12)
B(2,15,-1,HARD_CLAY)
B(2,15,0,STAINED_CLAY:12)
B(2,15,1,STAINED_CLAY:12)
B(2,15,2,STAINED_CLAY:12)
B(2,15,3,STAINED_CLAY:12)
B(2,16,-1,HARD_CLAY)
B(2,16,0,HARD_CLAY)
B(2,16,1,HARD_CLAY)
B(2,16,2,HARD_CLAY)
B(2,16,3,HARD_CLAY)
B(3,-4,1,STAINED_CLAY:1)
B(3,-4,2,STAINED_CLAY:1)
B(3,-3,-1,STAINED_CLAY:1)
B(3,-3,0,STAINED_CLAY:1)
B(3,-3,1,STAINED_CLAY:1)
B(3,-3,2,STAINED_CLAY:1)
B(3,-3,3,STAINED_CLAY:1)
B(3,-2,-2,STAINED_CLAY:1)
B(3,-2,-1,STAINED_CLAY:1)
B(3,-2,0,STAINED_CLAY:1)
B(3,-2,1,STAINED_CLAY:1)
B(3,-2,2,STAINED_CLAY:1)
B(3,-2,3,STAINED_CLAY:1)
B(3,-2,4,STAINED_CLAY:1)
B(3,-1,-3,STAINED_CLAY:1)
B(3,-1,-2,STAINED_CLAY:1)
B(3,-1,-1,STAINED_CLAY:1)
B(3,-1,0,STAINED_CLAY:1)
B(3,-1,1,STAINED_CLAY:1)
B(3,-1,2,STAINED_CLAY:1)
B(3,-1,3,STAINED_CLAY:1)
B(3,-1,4,STAINED_CLAY:1)
B(3,-1,5,STAINED_CLAY:1)
B(3,-1,6,STAINED_CLAY:1)
B(3,0,-3,STAINED_CLAY:1)
B(3,0,-2,STAINED_CLAY:1)
B(3,0,-1,STAINED_CLAY:1)
B(3,0,0,STAINED_CLAY:1)
B(3,0,1,STAINED_CLAY:1)
B(3,0,2,STAINED_CLAY:1)
B(3,0,3,STAINED_CLAY:1)
B(3,0,4,STAINED_CLAY:1)
B(3,0,5,STAINED_CLAY:1)
B(3,0,6,STAINED_CLAY:1)
B(3,1,-3,STAINED_CLAY:1)
B(3,1,-2,STAINED_CLAY:1)
B(3,1,-1,STAINED_CLAY:1)
B(3,1,0,STAINED_CLAY:1)
B(3,1,1,STAINED_CLAY:1)
B(3,1,2,STAINED_CLAY:1)
B(3,1,3,STAINED_CLAY:1)
B(3,1,4,STAINED_CLAY:1)
B(3,1,5,STAINED_CLAY:1)
B(3,1,6,STAINED_CLAY:1)
B(3,2,-3,STAINED_CLAY:1)
B(3,2,-2,STAINED_CLAY:1)
B(3,2,-1,STAINED_CLAY:1)
B(3,2,0,STAINED_CLAY:1)
B(3,2,1,STAINED_CLAY:1)
B(3,2,2,STAINED_CLAY:1)
B(3,2,3,STAINED_CLAY:1)
B(3,2,4,STAINED_CLAY:1)
B(3,2,5,STAINED_CLAY:1)
B(3,2,6,STAINED_CLAY:1)
B(3,3,-2,STAINED_CLAY:4)
B(3,3,-1,STAINED_CLAY:1)
B(3,3,0,STAINED_CLAY:1)
B(3,3,1,STAINED_CLAY:1)
B(3,3,2,STAINED_CLAY:1)
B(3,3,3,STAINED_CLAY:1)
B(3,3,4,STAINED_CLAY:1)
B(3,3,5,STAINED_CLAY:1)
B(3,3,6,STAINED_CLAY:1)
B(3,4,-1,STAINED_CLAY:4)
B(3,4,0,STAINED_CLAY:1)
B(3,4,1,STAINED_CLAY:1)
B(3,4,2,STAINED_CLAY:1)
B(3,4,3,STAINED_CLAY:1)
B(3,4,4,STAINED_CLAY:1)
B(3,4,5,STAINED_CLAY:1)
B(3,4,6,STAINED_CLAY:4)
B(3,5,-1,STAINED_CLAY:4)
B(3,5,0,STAINED_CLAY:1)
B(3,5,1,STAINED_CLAY:1)
B(3,5,2,STAINED_CLAY:1)
B(3,5,3,STAINED_CLAY:1)
B(3,5,4,STAINED_CLAY:1)
B(3,5,5,STAINED_CLAY:4)
B(3,6,-1,HARD_CLAY)
B(3,6,0,HARD_CLAY)
B(3,6,1,HARD_CLAY)
B(3,6,2,HARD_CLAY)
B(3,6,3,HARD_CLAY)
B(3,6,4,HARD_CLAY)
B(3,7,-1,HARD_CLAY)
B(3,7,0,HARD_CLAY)
B(3,7,1,HARD_CLAY)
B(3,7,2,HARD_CLAY)
B(3,7,3,HARD_CLAY)
B(3,7,4,HARD_CLAY)
B(3,8,-1,STAINED_CLAY:1)
B(3,8,0,STAINED_CLAY:1)
B(3,8,1,STAINED_CLAY:1)
B(3,8,2,STAINED_CLAY:1)
B(3,8,3,STAINED_CLAY:1)
B(3,9,-1,HARD_CLAY)
B(3,9,0,HARD_CLAY)
B(3,9,1,HARD_CLAY)
B(3,9,2,HARD_CLAY)
B(3,9,3,HARD_CLAY)
B(3,10,-1,HARD_CLAY)
B(3,10,0,HARD_CLAY)
B(3,10,1,HARD_CLAY)
B(3,10,2,HARD_CLAY)
B(3,10,3,HARD_CLAY)
B(3,11,-1,STAINED_CLAY:1)
B(3,11,0,STAINED_CLAY:1)
B(3,11,1,STAINED_CLAY:1)
B(3,11,2,STAINED_CLAY:1)
B(3,11,3,STAINED_CLAY:1)
B(3,12,-1,HARD_CLAY)
B(3,12,0,HARD_CLAY)
B(3,12,1,HARD_CLAY)
B(3,12,2,HARD_CLAY)
B(3,13,-1,STAINED_CLAY:14)
B(3,13,0,STAINED_CLAY:14)
B(3,13,1,STAINED_CLAY:14)
B(3,13,2,STAINED_CLAY:14)
B(3,14,0,STAINED_CLAY:12)
B(3,14,1,STAINED_CLAY:12)
B(3,14,2,STAINED_CLAY:12)
B(3,15,1,STAINED_CLAY:12)
B(3,15,2,STAINED_CLAY:12)
B(3,16,1,HARD_CLAY)
B(3,16,2,HARD_CLAY)
B(4,-4,2,STAINED_CLAY:1)
B(4,-3,1,STAINED_CLAY:1)
B(4,-3,2,STAINED_CLAY:1)
B(4,-3,3,STAINED_CLAY:1)
B(4,-2,-1,STAINED_CLAY:1)
B(4,-2,0,STAINED_CLAY:1)
B(4,-2,1,STAINED_CLAY:1)
B(4,-2,2,STAINED_CLAY:1)
B(4,-2,3,STAINED_CLAY:1)
B(4,-2,4,STAINED_CLAY:1)
B(4,-1,-2,STAINED_CLAY:1)
B(4,-1,-1,STAINED_CLAY:1)
B(4,-1,0,STAINED_CLAY:1)
B(4,-1,1,STAINED_CLAY:1)
B(4,-1,2,STAINED_CLAY:1)
B(4,-1,3,STAINED_CLAY:1)
B(4,-1,4,STAINED_CLAY:1)
B(4,-1,5,STAINED_CLAY:1)
B(4,0,-2,STAINED_CLAY:1)
B(4,0,-1,STAINED_CLAY:1)
B(4,0,0,STAINED_CLAY:1)
B(4,0,1,STAINED_CLAY:1)
B(4,0,2,STAINED_CLAY:1)
B(4,0,3,STAINED_CLAY:1)
B(4,0,4,STAINED_CLAY:1)
B(4,0,5,STAINED_CLAY:1)
B(4,0,6,STAINED_CLAY:1)
B(4,1,-2,STAINED_CLAY:1)
B(4,1,-1,STAINED_CLAY:1)
B(4,1,0,STAINED_CLAY:1)
B(4,1,1,STAINED_CLAY:1)
B(4,1,2,STAINED_CLAY:1)
B(4,1,3,STAINED_CLAY:1)
B(4,1,4,STAINED_CLAY:1)
B(4,1,5,STAINED_CLAY:1)
B(4,1,6,STAINED_CLAY:1)
B(4,2,-2,STAINED_CLAY:1)
B(4,2,-1,STAINED_CLAY:1)
B(4,2,0,STAINED_CLAY:1)
B(4,2,1,STAINED_CLAY:1)
B(4,2,2,STAINED_CLAY:1)
B(4,2,3,STAINED_CLAY:1)
B(4,2,4,STAINED_CLAY:1)
B(4,2,5,STAINED_CLAY:1)
B(4,2,6,STAINED_CLAY:1)
B(4,3,-1,STAINED_CLAY:4)
B(4,3,0,STAINED_CLAY:1)
B(4,3,1,STAINED_CLAY:1)
B(4,3,2,STAINED_CLAY:1)
B(4,3,3,STAINED_CLAY:1)
B(4,3,4,STAINED_CLAY:1)
B(4,3,5,STAINED_CLAY:1)
B(4,3,6,STAINED_CLAY:4)
B(4,4,0,STAINED_CLAY:4)
B(4,4,1,STAINED_CLAY:1)
B(4,4,2,STAINED_CLAY:1)
B(4,4,3,STAINED_CLAY:1)
B(4,4,4,STAINED_CLAY:1)
B(4,4,5,STAINED_CLAY:4)
B(4,5,0,STAINED_CLAY:4)
B(4,5,1,STAINED_CLAY:4)
B(4,5,2,STAINED_CLAY:1)
B(4,5,3,STAINED_CLAY:1)
B(4,5,4,STAINED_CLAY:4)
B(4,6,1,HARD_CLAY)
B(4,6,2,HARD_CLAY)
B(4,6,3,HARD_CLAY)
B(4,6,4,HARD_CLAY)
B(4,7,2,HARD_CLAY)
B(4,7,3,HARD_CLAY)
B(4,7,4,HARD_CLAY)
B(4,8,2,STAINED_CLAY:1)
B(4,8,3,STAINED_CLAY:1)
B(4,9,2,HARD_CLAY)
B(4,10,2,HARD_CLAY)
B(5,-3,2,STAINED_CLAY:1)
B(5,-3,3,STAINED_CLAY:1)
B(5,-2,1,STAINED_CLAY:1)
B(5,-2,2,STAINED_CLAY:1)
B(5,-2,3,STAINED_CLAY:1)
B(5,-2,4,STAINED_CLAY:1)
B(5,-1,0,STAINED_CLAY:1)
B(5,-1,1,STAINED_CLAY:1)
B(5,-1,2,STAINED_CLAY:1)
B(5,-1,3,STAINED_CLAY:1)
B(5,-1,4,STAINED_CLAY:1)
B(5,-1,5,STAINED_CLAY:1)
B(5,0,0,STAINED_CLAY:1)
B(5,0,1,STAINED_CLAY:1)
B(5,0,2,STAINED_CLAY:1)
B(5,0,3,STAINED_CLAY:1)
B(5,0,4,STAINED_CLAY:1)
B(5,0,5,STAINED_CLAY:1)
B(5,0,6,STAINED_CLAY:1)
B(5,1,0,STAINED_CLAY:1)
B(5,1,1,STAINED_CLAY:1)
B(5,1,2,STAINED_CLAY:1)
B(5,1,3,STAINED_CLAY:1)
B(5,1,4,STAINED_CLAY:1)
B(5,1,5,STAINED_CLAY:1)
B(5,1,6,STAINED_CLAY:1)
B(5,2,0,STAINED_CLAY:1)
B(5,2,1,STAINED_CLAY:1)
B(5,2,2,STAINED_CLAY:1)
B(5,2,3,STAINED_CLAY:1)
B(5,2,4,STAINED_CLAY:1)
B(5,2,5,STAINED_CLAY:1)
B(5,2,6,STAINED_CLAY:1)
B(5,3,1,STAINED_CLAY:1)
B(5,3,2,STAINED_CLAY:1)
B(5,3,3,STAINED_CLAY:1)
B(5,3,4,STAINED_CLAY:1)
B(5,3,5,STAINED_CLAY:4)
B(5,4,1,STAINED_CLAY:4)
B(5,4,2,STAINED_CLAY:1)
B(5,4,3,STAINED_CLAY:4)
B(5,4,4,STAINED_CLAY:4)
B(5,5,2,STAINED_CLAY:4)
B(5,5,3,STAINED_CLAY:4)
B(5,6,2,HARD_CLAY)
B(5,6,3,HARD_CLAY)
B(6,-3,3,STAINED_CLAY:1)
B(6,-2,2,STAINED_CLAY:1)
B(6,-2,3,STAINED_CLAY:1)
B(6,-2,4,STAINED_CLAY:1)
B(6,-1,2,STAINED_CLAY:1)
B(6,-1,3,STAINED_CLAY:1)
B(6,-1,4,STAINED_CLAY:1)
B(6,0,0,STAINED_CLAY:1)
B(6,0,1,STAINED_CLAY:1)
B(6,0,2,STAINED_CLAY:1)
B(6,0,3,STAINED_CLAY:1)
B(6,0,4,STAINED_CLAY:1)
B(6,0,5,STAINED_CLAY:1)
B(6,1,0,STAINED_CLAY:1)
B(6,1,1,STAINED_CLAY:1)
B(6,1,2,STAINED_CLAY:1)
B(6,1,3,STAINED_CLAY:1)
B(6,1,4,STAINED_CLAY:1)
B(6,1,5,STAINED_CLAY:1)
B(6,1,6,STAINED_CLAY:1)
B(6,2,1,STAINED_CLAY:1)
B(6,2,2,STAINED_CLAY:1)
B(6,2,3,STAINED_CLAY:1)
B(6,2,4,STAINED_CLAY:1)
B(6,2,5,STAINED_CLAY:1)
B(6,3,1,STAINED_CLAY:1)
B(6,3,2,STAINED_CLAY:1)
B(6,3,3,STAINED_CLAY:4)
B(6,3,4,STAINED_CLAY:1)
B(6,4,2,STAINED_CLAY:4)
B(7,-2,3,STAINED_CLAY:1)
B(7,-1,2,STAINED_CLAY:1)
B(7,-1,3,STAINED_CLAY:1)
B(7,-1,4,STAINED_CLAY:1)
B(7,0,1,STAINED_CLAY:1)
B(7,0,2,STAINED_CLAY:1)
B(7,0,3,STAINED_CLAY:1)
B(7,0,4,STAINED_CLAY:1)
B(7,1,1,STAINED_CLAY:1)
B(7,1,2,STAINED_CLAY:1)
B(7,1,3,STAINED_CLAY:1)
B(7,1,4,STAINED_CLAY:1)
B(7,2,1,STAINED_CLAY:1)
B(7,2,2,STAINED_CLAY:1)
B(7,2,3,STAINED_CLAY:1)
B(7,2,4,STAINED_CLAY:1)
B(7,3,2,STAINED_CLAY:1)

#######################################################################
# +-----------------------------------------------------------------+ #
# |                            BO3 checks                           | #
# +-----------------------------------------------------------------+ #
#######################################################################


#######################################################################
# +-----------------------------------------------------------------+ #
# |                             Branches                            | #
# +-----------------------------------------------------------------+ #
#######################################################################


#######################################################################
# +-----------------------------------------------------------------+ #
# |                         EntityFunctions                         | #
# +-----------------------------------------------------------------+ #
#######################################################################

