
#######################################################################
# +-----------------------------------------------------------------+ #
# |                            BO3 object                           | #
# +-----------------------------------------------------------------+ #
#######################################################################

# This is the config file of a custom object.
# If you add this object correctly to your BiomeConfigs, it will spawn in the world.

# This is the creator of this BO3 object
Author: LordSmellyPants

# A short description of this BO3 object
Description: No description given

# The BO3 version, don't change this! It can be used by external applications to do a version check.
Version: 3

# The settings mode, WriteAll, WriteWithoutComments or WriteDisable. See WorldConfig.
SettingsMode: WriteDisable


#######################################################################
# +-----------------------------------------------------------------+ #
# |                          Main settings                          | #
# +-----------------------------------------------------------------+ #
#######################################################################

# This needs to be set to true to spawn the object in the Tree and Sapling resources.
Tree: false

# The frequency of the BO3 from 1 to 200. Tries this many times to spawn this BO3 when using the CustomObject(...) resource.
# Ignored by Tree(..), Sapling(..) and CustomStructure(..)
Frequency: 1

# The rarity of the BO3 from 0 to 100. Each spawn attempt has rarity% chance to succeed when using the CustomObject(...) resource.
# Ignored by Tree(..), Sapling(..) and CustomStructure(..)
Rarity: 0.1

# If you set this to true, the BO3 will be placed with a random rotation.
RotateRandomly: true

# The spawn height of the BO3 - atMinY, randomY, highestBlock or highestSolidBlock.
SpawnHeight: highestSolidBlock

# The offset from the spawn height to spawn this BO3
# Ex. SpawnHeight = highestSolidBlock, SpawnHeightOffset = 3; This object will spawn 3 blocks above the highest solid block
SpawnHeightOffset: 0

# A random amount to offset the spawn location from the spawn offset height
# Ex. SpawnHeightOffset = 3, SpawnHeightVariance = 3; This object will spawn 3 to 6 blocks above the original spot it would have spawned
SpawnHeightVariance: 0

##############################
# Height Limits for the BO3. #
##############################

# When in randomY mode used as the minimum Y or in atMinY mode as the actual Y to spawn this BO3 at.
MinHeight: 0

# When in randomY mode used as the maximum Y to spawn this BO3 at.
MaxHeight: 91

######################
# Extrusion settings #
######################

# The style of extrusion you wish to use - BottomDown, TopUp, None (Default)
ExtrudeMode: None

# The blocks to extrude your BO3 through
ExtrudeThroughBlocks: AIR

# Objects can have other objects attacthed to it: branches. Branches can also
# have branches attached to it, which can also have branches, etc. This is the
# maximum branch depth for this objects.
MaxBranchDepth: 10

# When spawned with the UseWorld keyword, this BO3 should NOT spawn in the following biomes.
# If you write the BO3 name directly in the BiomeConfigs, this will be ignored.
ExcludedBiomes: All


#######################################################################
# +-----------------------------------------------------------------+ #
# |                      Source block settings                      | #
# +-----------------------------------------------------------------+ #
#######################################################################

# The B(s) the BO3 should spawn in.
SourceBlocks: AIR,GRASS,DIRT,GRAVEL,SAND,STONE,STONE:1,STONE:3,STONE:5,DIRT:1,CLAY,HARD_CLAY,38,38:1,38:2,38:3,38:4,38:5,38:6,38:7,38:8,39,40,175,175:1,175:2,175:3,175:4,175:5,31,31:1,31:2,32,STAINED_CLAY:14,STAINED_CLAY

# The maximum percentage of the BO3 that can be outside the SourceBlock.
# The BO3 won't be placed on a location with more blocks outside the SourceBlock than this percentage.
MaxPercentageOutsideSourceBlock: 5

# What to do when a block is about to be placed outside the SourceBlock? (dontPlace, placeAnyway)
OutsideSourceBlock: placeAnyway


#######################################################################
# +-----------------------------------------------------------------+ #
# |                              Blocks                             | #
# +-----------------------------------------------------------------+ #
#######################################################################

# All the blocks used in the BO3 are listed here. Possible blocks:
# B(x,y,z,id[.data][,nbtfile.nbt)
# RB(x,y,z,id[:data][,nbtfile.nbt],chance[,id[:data][,nbtfile.nbt],chance[,...]])
#  So RB(0,0,0,CHEST,chest.nbt,50,CHEST,anotherchest.nbt,100) will spawn a chest at
#  the BO3 origin, and give it a 50% chance to have the contents of chest.nbt, or, if that
#  fails, a 100% percent chance to have the contents of anotherchest.nbt.
# MinecraftObject(x,y,z,name)
#  Spawns an object in the Mojang NBT structure format. For example, 
#  MinecraftObject(0,0,0,minecraft:igloo/igloo_bottom)
#  spawns the bottom part of an igloo.
B(-19,-9,-8,STONE)
B(-19,-9,-7,STONE)
B(-19,-9,-6,STONE)
B(-19,-9,-5,STONE)
B(-19,-9,-4,STONE)
B(-19,-8,-8,STONE)
B(-19,-8,-7,STONE)
B(-19,-8,-6,STONE)
B(-19,-8,-5,STONE)
B(-19,-8,-4,STONE)
B(-19,-7,-9,STONE)
B(-19,-7,-8,STONE)
B(-19,-7,-7,STONE)
B(-19,-7,-6,STONE)
B(-19,-7,-5,STONE)
B(-19,-7,-4,STONE)
B(-19,-6,-10,STONE)
B(-19,-6,-9,STONE)
B(-19,-6,-8,STONE)
B(-19,-6,-7,STONE)
B(-19,-6,-6,STONE)
B(-19,-6,-5,STONE)
B(-19,-6,-4,STONE)
B(-19,-6,-3,STONE)
B(-19,-5,-13,STONE)
B(-19,-5,-12,STONE)
B(-19,-5,-11,STONE)
B(-19,-5,-10,STONE)
B(-19,-5,-9,STONE)
B(-19,-5,-8,STONE)
B(-19,-5,-7,STONE)
B(-19,-5,-6,STONE)
B(-19,-5,-5,STONE)
B(-19,-5,-4,STONE)
B(-19,-5,-3,STONE)
B(-19,-4,-13,STONE)
B(-19,-4,-12,STONE)
B(-19,-4,-11,STONE)
B(-19,-4,-10,STONE)
B(-19,-4,-9,STONE)
B(-19,-4,-8,STONE)
B(-19,-4,-7,STONE)
B(-19,-4,-6,STONE)
B(-19,-4,-5,STONE)
B(-19,-4,-4,STONE)
B(-19,-4,-3,STONE)
B(-19,-4,-2,STONE)
B(-19,-3,-14,STONE)
B(-19,-3,-13,STONE)
B(-19,-3,-12,STONE)
B(-19,-3,-11,STONE)
B(-19,-3,-10,STONE)
B(-19,-3,-9,STONE)
B(-19,-3,-8,STONE)
B(-19,-3,-7,STONE)
B(-19,-3,-6,STONE)
B(-19,-3,-5,STONE)
B(-19,-3,-4,STONE)
B(-19,-3,-3,STONE)
B(-19,-3,-2,STONE)
B(-19,-3,-1,STONE)
B(-19,-2,-14,STONE)
B(-19,-2,-13,STONE)
B(-19,-2,-12,STONE)
B(-19,-2,-11,STONE)
B(-19,-2,-10,STONE)
B(-19,-2,-9,STONE)
B(-19,-2,-8,STONE)
B(-19,-2,-7,STONE)
B(-19,-2,-6,STONE)
B(-19,-2,-5,STONE)
B(-19,-2,-4,STONE)
B(-19,-2,-3,STONE)
B(-19,-2,-2,STONE)
B(-19,-2,-1,STONE)
B(-19,-1,-13,STONE)
B(-19,-1,-12,STONE)
B(-19,-1,-11,STONE)
B(-19,-1,-10,STONE)
B(-19,-1,-9,STONE)
B(-19,-1,-8,STONE)
B(-19,-1,-7,STONE)
B(-19,-1,-6,STONE)
B(-19,-1,-5,STONE)
B(-19,-1,-4,STONE)
B(-19,-1,-3,STONE)
B(-19,-1,-2,STONE)
B(-19,0,-13,STONE)
B(-19,0,-12,STONE)
B(-19,0,-11,STONE)
B(-19,0,-10,STONE)
B(-19,0,-9,STONE)
B(-19,0,-8,STONE)
B(-19,0,-7,STONE)
B(-19,0,-6,STONE)
B(-19,0,-5,STONE)
B(-19,0,-4,STONE)
B(-19,0,-3,STONE)
B(-19,1,-10,STONE)
B(-19,1,-9,STONE)
B(-19,1,-8,STONE)
B(-19,1,-7,STONE)
B(-19,1,-6,STONE)
B(-19,1,-5,STONE)
B(-19,1,-4,STONE)
B(-19,1,-3,STONE)
B(-19,2,-9,STONE)
B(-19,2,-8,STONE)
B(-19,2,-7,STONE)
B(-19,2,-6,STONE)
B(-19,2,-5,STONE)
B(-19,2,-4,STONE)
B(-19,3,-8,STONE)
B(-19,3,-7,STONE)
B(-19,3,-6,STONE)
B(-19,3,-5,STONE)
B(-19,3,-4,STONE)
B(-19,4,-8,STONE)
B(-19,4,-7,STONE)
B(-19,4,-6,STONE)
B(-19,4,-5,STONE)
B(-19,4,-4,STONE)
B(-18,-10,-7,STONE)
B(-18,-10,-6,STONE)
B(-18,-10,-5,STONE)
B(-18,-10,-4,STONE)
B(-18,-9,-9,STONE)
B(-18,-9,-8,STONE)
B(-18,-9,-7,STONE)
B(-18,-9,-6,STONE)
B(-18,-9,-5,STONE)
B(-18,-9,-4,STONE)
B(-18,-8,-10,STONE)
B(-18,-8,-9,STONE)
B(-18,-8,-8,STONE)
B(-18,-8,-7,STONE)
B(-18,-8,-6,STONE)
B(-18,-8,-5,STONE)
B(-18,-8,-4,STONE)
B(-18,-8,-3,STONE)
B(-18,-7,-10,STONE)
B(-18,-7,-9,STONE)
B(-18,-7,-8,STONE)
B(-18,-7,-7,STONE)
B(-18,-7,-6,STONE)
B(-18,-7,-5,STONE)
B(-18,-7,-4,STONE)
B(-18,-7,-3,STONE)
B(-18,-6,-11,STONE)
B(-18,-6,-10,STONE)
B(-18,-6,-9,STONE)
B(-18,-6,-8,STONE)
B(-18,-6,-7,STONE)
B(-18,-6,-6,STONE)
B(-18,-6,-5,STONE)
B(-18,-6,-4,STONE)
B(-18,-6,-3,STONE)
B(-18,-6,-2,STONE)
B(-18,-5,-14,STONE)
B(-18,-5,-13,STONE)
B(-18,-5,-12,STONE)
B(-18,-5,-11,STONE)
B(-18,-5,-10,STONE)
B(-18,-5,-9,STONE)
B(-18,-5,-8,STONE)
B(-18,-5,-7,STONE)
B(-18,-5,-6,STONE)
B(-18,-5,-5,STONE)
B(-18,-5,-4,STONE)
B(-18,-5,-3,STONE)
B(-18,-5,-2,STONE)
B(-18,-4,-14,STONE)
B(-18,-4,-13,STONE)
B(-18,-4,-12,STONE)
B(-18,-4,-11,STONE)
B(-18,-4,-10,STONE)
B(-18,-4,-9,STONE)
B(-18,-4,-8,STONE)
B(-18,-4,-7,STONE)
B(-18,-4,-6,STONE)
B(-18,-4,-5,STONE)
B(-18,-4,-4,STONE)
B(-18,-4,-3,STONE)
B(-18,-4,-2,STONE)
B(-18,-4,-1,STONE)
B(-18,-3,-14,STONE)
B(-18,-3,-13,STONE)
B(-18,-3,-12,STONE)
B(-18,-3,-11,STONE)
B(-18,-3,-10,STONE)
B(-18,-3,-9,STONE)
B(-18,-3,-8,STONE)
B(-18,-3,-7,STONE)
B(-18,-3,-6,STONE)
B(-18,-3,-5,STONE)
B(-18,-3,-4,STONE)
B(-18,-3,-3,STONE)
B(-18,-3,-2,STONE)
B(-18,-3,-1,STONE)
B(-18,-3,0,STONE)
B(-18,-2,-14,STONE)
B(-18,-2,-13,STONE)
B(-18,-2,-12,STONE)
B(-18,-2,-11,STONE)
B(-18,-2,-10,STONE)
B(-18,-2,-9,STONE)
B(-18,-2,-8,STONE)
B(-18,-2,-7,STONE)
B(-18,-2,-6,STONE)
B(-18,-2,-5,STONE)
B(-18,-2,-4,STONE)
B(-18,-2,-3,STONE)
B(-18,-2,-2,STONE)
B(-18,-2,-1,STONE)
B(-18,-2,0,STONE)
B(-18,-1,-14,STONE)
B(-18,-1,-13,STONE)
B(-18,-1,-12,STONE)
B(-18,-1,-11,STONE)
B(-18,-1,-10,STONE)
B(-18,-1,-9,STONE)
B(-18,-1,-8,STONE)
B(-18,-1,-7,STONE)
B(-18,-1,-6,STONE)
B(-18,-1,-5,STONE)
B(-18,-1,-4,STONE)
B(-18,-1,-3,STONE)
B(-18,-1,-2,STONE)
B(-18,-1,-1,STONE)
B(-18,0,-14,STONE)
B(-18,0,-13,STONE)
B(-18,0,-12,STONE)
B(-18,0,-11,STONE)
B(-18,0,-10,STONE)
B(-18,0,-9,STONE)
B(-18,0,-8,STONE)
B(-18,0,-7,STONE)
B(-18,0,-6,STONE)
B(-18,0,-5,STONE)
B(-18,0,-4,STONE)
B(-18,0,-3,STONE)
B(-18,0,-2,STONE)
B(-18,1,-11,STONE)
B(-18,1,-10,STONE)
B(-18,1,-9,STONE)
B(-18,1,-8,STONE)
B(-18,1,-7,STONE)
B(-18,1,-6,STONE)
B(-18,1,-5,STONE)
B(-18,1,-4,STONE)
B(-18,1,-3,STONE)
B(-18,1,-2,STONE)
B(-18,2,-10,STONE)
B(-18,2,-9,STONE)
B(-18,2,-8,STONE)
B(-18,2,-7,STONE)
B(-18,2,-6,STONE)
B(-18,2,-5,STONE)
B(-18,2,-4,STONE)
B(-18,2,-3,STONE)
B(-18,3,-10,STONE)
B(-18,3,-9,STONE)
B(-18,3,-8,STONE)
B(-18,3,-7,STONE)
B(-18,3,-6,STONE)
B(-18,3,-5,STONE)
B(-18,3,-4,STONE)
B(-18,3,-3,STONE)
B(-18,4,-9,STONE)
B(-18,4,-8,STONE)
B(-18,4,-7,STONE)
B(-18,4,-6,STONE)
B(-18,4,-5,STONE)
B(-18,4,-4,STONE)
B(-18,5,-7,STONE)
B(-18,5,-6,STONE)
B(-18,5,-5,STONE)
B(-18,5,-4,STONE)
B(-17,-10,-8,STONE)
B(-17,-10,-7,STONE)
B(-17,-10,-6,STONE)
B(-17,-10,-5,STONE)
B(-17,-10,-4,STONE)
B(-17,-9,-10,STONE)
B(-17,-9,-9,STONE)
B(-17,-9,-8,STONE)
B(-17,-9,-7,STONE)
B(-17,-9,-6,STONE)
B(-17,-9,-5,STONE)
B(-17,-9,-4,STONE)
B(-17,-9,-3,STONE)
B(-17,-8,-10,STONE)
B(-17,-8,-9,STONE)
B(-17,-8,-8,STONE)
B(-17,-8,-7,STONE)
B(-17,-8,-6,STONE)
B(-17,-8,-5,STONE)
B(-17,-8,-4,STONE)
B(-17,-8,-3,STONE)
B(-17,-7,-10,STONE)
B(-17,-7,-9,STONE)
B(-17,-7,-8,STONE)
B(-17,-7,-7,STONE)
B(-17,-7,-6,STONE)
B(-17,-7,-5,STONE)
B(-17,-7,-4,STONE)
B(-17,-7,-3,STONE)
B(-17,-7,-2,STONE)
B(-17,-6,-11,STONE)
B(-17,-6,-10,STONE)
B(-17,-6,-9,STONE)
B(-17,-6,-8,STONE)
B(-17,-6,-7,STONE)
B(-17,-6,-6,STONE)
B(-17,-6,-5,STONE)
B(-17,-6,-4,STONE)
B(-17,-6,-3,STONE)
B(-17,-6,-2,STONE)
B(-17,-6,-1,STONE)
B(-17,-5,-14,STONE)
B(-17,-5,-13,STONE)
B(-17,-5,-12,STONE)
B(-17,-5,-11,STONE)
B(-17,-5,-10,STONE)
B(-17,-5,-9,STONE)
B(-17,-5,-8,STONE)
B(-17,-5,-7,STONE)
B(-17,-5,-6,STONE)
B(-17,-5,-5,STONE)
B(-17,-5,-4,STONE)
B(-17,-5,-3,STONE)
B(-17,-5,-2,STONE)
B(-17,-5,-1,STONE)
B(-17,-4,-14,STONE)
B(-17,-4,-13,STONE)
B(-17,-4,-12,STONE)
B(-17,-4,-11,STONE)
B(-17,-4,-10,STONE)
B(-17,-4,-9,STONE)
B(-17,-4,-8,STONE)
B(-17,-4,-7,STONE)
B(-17,-4,-6,STONE)
B(-17,-4,-5,STONE)
B(-17,-4,-4,STONE)
B(-17,-4,-3,STONE)
B(-17,-4,-2,STONE)
B(-17,-4,-1,STONE)
B(-17,-3,-14,STONE)
B(-17,-3,-13,STONE)
B(-17,-3,-12,STONE)
B(-17,-3,-11,STONE)
B(-17,-3,-10,STONE)
B(-17,-3,-9,STONE)
B(-17,-3,-8,STONE)
B(-17,-3,-7,STONE)
B(-17,-3,-6,STONE)
B(-17,-3,-5,STONE)
B(-17,-3,-4,STONE)
B(-17,-3,-3,STONE)
B(-17,-3,-2,STONE)
B(-17,-3,-1,STONE)
B(-17,-3,0,STONE)
B(-17,-3,6,STONE)
B(-17,-3,7,STONE)
B(-17,-3,8,STONE)
B(-17,-3,9,STONE)
B(-17,-2,-14,STONE)
B(-17,-2,-13,STONE)
B(-17,-2,-12,STONE)
B(-17,-2,-11,STONE)
B(-17,-2,-10,STONE)
B(-17,-2,-9,STONE)
B(-17,-2,-8,STONE)
B(-17,-2,-7,STONE)
B(-17,-2,-6,STONE)
B(-17,-2,-5,STONE)
B(-17,-2,-4,STONE)
B(-17,-2,-3,STONE)
B(-17,-2,-2,STONE)
B(-17,-2,-1,STONE)
B(-17,-2,0,STONE)
B(-17,-2,6,STONE)
B(-17,-2,7,STONE)
B(-17,-2,8,STONE)
B(-17,-2,9,STONE)
B(-17,-1,-14,STONE)
B(-17,-1,-13,STONE)
B(-17,-1,-12,STONE)
B(-17,-1,-11,STONE)
B(-17,-1,-10,STONE)
B(-17,-1,-9,STONE)
B(-17,-1,-8,STONE)
B(-17,-1,-7,STONE)
B(-17,-1,-6,STONE)
B(-17,-1,-5,STONE)
B(-17,-1,-4,STONE)
B(-17,-1,-3,STONE)
B(-17,-1,-2,STONE)
B(-17,-1,-1,STONE)
B(-17,0,-14,STONE)
B(-17,0,-13,STONE)
B(-17,0,-12,STONE)
B(-17,0,-11,STONE)
B(-17,0,-10,STONE)
B(-17,0,-9,STONE)
B(-17,0,-8,STONE)
B(-17,0,-7,STONE)
B(-17,0,-6,STONE)
B(-17,0,-5,STONE)
B(-17,0,-4,STONE)
B(-17,0,-3,STONE)
B(-17,0,-2,STONE)
B(-17,0,-1,STONE)
B(-17,1,-11,STONE)
B(-17,1,-10,STONE)
B(-17,1,-9,STONE)
B(-17,1,-8,STONE)
B(-17,1,-7,STONE)
B(-17,1,-6,STONE)
B(-17,1,-5,STONE)
B(-17,1,-4,STONE)
B(-17,1,-3,STONE)
B(-17,1,-2,STONE)
B(-17,1,-1,STONE)
B(-17,2,-10,STONE)
B(-17,2,-9,STONE)
B(-17,2,-8,STONE)
B(-17,2,-7,STONE)
B(-17,2,-6,STONE)
B(-17,2,-5,STONE)
B(-17,2,-4,STONE)
B(-17,2,-3,STONE)
B(-17,2,-2,STONE)
B(-17,3,-10,STONE)
B(-17,3,-9,STONE)
B(-17,3,-8,STONE)
B(-17,3,-7,STONE)
B(-17,3,-6,STONE)
B(-17,3,-5,STONE)
B(-17,3,-4,STONE)
B(-17,3,-3,STONE)
B(-17,4,-10,STONE)
B(-17,4,-9,STONE)
B(-17,4,-8,STONE)
B(-17,4,-7,STONE)
B(-17,4,-6,STONE)
B(-17,4,-5,STONE)
B(-17,4,-4,STONE)
B(-17,4,-3,STONE)
B(-17,5,-8,STONE)
B(-17,5,-7,STONE)
B(-17,5,-6,STONE)
B(-17,5,-5,STONE)
B(-17,5,-4,STONE)
B(-16,-11,-7,STONE)
B(-16,-11,-6,STONE)
B(-16,-11,-5,STONE)
B(-16,-11,-4,STONE)
B(-16,-11,-3,STONE)
B(-16,-10,-8,STONE)
B(-16,-10,-7,STONE)
B(-16,-10,-6,STONE)
B(-16,-10,-5,STONE)
B(-16,-10,-4,STONE)
B(-16,-10,-3,STONE)
B(-16,-9,-10,STONE)
B(-16,-9,-9,STONE)
B(-16,-9,-8,STONE)
B(-16,-9,-7,STONE)
B(-16,-9,-6,STONE)
B(-16,-9,-5,STONE)
B(-16,-9,-4,STONE)
B(-16,-9,-3,STONE)
B(-16,-8,-10,STONE)
B(-16,-8,-9,STONE)
B(-16,-8,-8,STONE)
B(-16,-8,-7,STONE)
B(-16,-8,-6,STONE)
B(-16,-8,-5,STONE)
B(-16,-8,-4,STONE)
B(-16,-8,-3,STONE)
B(-16,-8,-2,STONE)
B(-16,-7,-10,STONE)
B(-16,-7,-9,STONE)
B(-16,-7,-8,STONE)
B(-16,-7,-7,STONE)
B(-16,-7,-6,STONE)
B(-16,-7,-5,STONE)
B(-16,-7,-4,STONE)
B(-16,-7,-3,STONE)
B(-16,-7,-2,STONE)
B(-16,-7,-1,STONE)
B(-16,-6,-11,STONE)
B(-16,-6,-10,STONE)
B(-16,-6,-9,STONE)
B(-16,-6,-8,STONE)
B(-16,-6,-7,STONE)
B(-16,-6,-6,STONE)
B(-16,-6,-5,STONE)
B(-16,-6,-4,STONE)
B(-16,-6,-3,STONE)
B(-16,-6,-2,STONE)
B(-16,-6,-1,STONE)
B(-16,-5,-14,STONE)
B(-16,-5,-13,STONE)
B(-16,-5,-12,STONE)
B(-16,-5,-11,STONE)
B(-16,-5,-10,STONE)
B(-16,-5,-9,STONE)
B(-16,-5,-8,STONE)
B(-16,-5,-7,STONE)
B(-16,-5,-6,STONE)
B(-16,-5,-5,STONE)
B(-16,-5,-4,STONE)
B(-16,-5,-3,STONE)
B(-16,-5,-2,STONE)
B(-16,-5,-1,STONE)
B(-16,-5,0,STONE)
B(-16,-4,-14,STONE)
B(-16,-4,-13,STONE)
B(-16,-4,-12,STONE)
B(-16,-4,-11,STONE)
B(-16,-4,-10,STONE)
B(-16,-4,-9,STONE)
B(-16,-4,-8,STONE)
B(-16,-4,-7,STONE)
B(-16,-4,-6,STONE)
B(-16,-4,-5,STONE)
B(-16,-4,-4,STONE)
B(-16,-4,-3,STONE)
B(-16,-4,-2,STONE)
B(-16,-4,-1,STONE)
B(-16,-4,0,STONE)
B(-16,-4,6,STONE)
B(-16,-4,7,STONE)
B(-16,-4,8,STONE)
B(-16,-4,9,STONE)
B(-16,-3,-14,STONE)
B(-16,-3,-13,STONE)
B(-16,-3,-12,STONE)
B(-16,-3,-11,STONE)
B(-16,-3,-10,STONE)
B(-16,-3,-9,STONE)
B(-16,-3,-8,STONE)
B(-16,-3,-7,STONE)
B(-16,-3,-6,STONE)
B(-16,-3,-5,STONE)
B(-16,-3,-4,STONE)
B(-16,-3,-3,STONE)
B(-16,-3,-2,STONE)
B(-16,-3,-1,STONE)
B(-16,-3,0,STONE)
B(-16,-3,1,STONE)
B(-16,-3,5,STONE)
B(-16,-3,6,STONE)
B(-16,-3,7,STONE)
B(-16,-3,8,STONE)
B(-16,-3,9,STONE)
B(-16,-3,10,STONE)
B(-16,-2,-14,STONE)
B(-16,-2,-13,STONE)
B(-16,-2,-12,STONE)
B(-16,-2,-11,STONE)
B(-16,-2,-10,STONE)
B(-16,-2,-9,STONE)
B(-16,-2,-8,STONE)
B(-16,-2,-7,STONE)
B(-16,-2,-6,STONE)
B(-16,-2,-5,STONE)
B(-16,-2,-4,STONE)
B(-16,-2,-3,STONE)
B(-16,-2,-2,STONE)
B(-16,-2,-1,STONE)
B(-16,-2,0,STONE)
B(-16,-2,1,STONE)
B(-16,-2,5,STONE)
B(-16,-2,6,STONE)
B(-16,-2,7,STONE)
B(-16,-2,8,STONE)
B(-16,-2,9,STONE)
B(-16,-2,10,STONE)
B(-16,-1,-14,STONE)
B(-16,-1,-13,STONE)
B(-16,-1,-12,STONE)
B(-16,-1,-11,STONE)
B(-16,-1,-10,STONE)
B(-16,-1,-9,STONE)
B(-16,-1,-8,STONE)
B(-16,-1,-7,STONE)
B(-16,-1,-6,STONE)
B(-16,-1,-5,STONE)
B(-16,-1,-4,STONE)
B(-16,-1,-3,STONE)
B(-16,-1,-2,STONE)
B(-16,-1,-1,STONE)
B(-16,-1,0,STONE)
B(-16,-1,6,STONE)
B(-16,-1,7,STONE)
B(-16,-1,8,STONE)
B(-16,-1,9,STONE)
B(-16,0,-14,STONE)
B(-16,0,-13,STONE)
B(-16,0,-12,STONE)
B(-16,0,-11,STONE)
B(-16,0,-10,STONE)
B(-16,0,-9,STONE)
B(-16,0,-8,STONE)
B(-16,0,-7,STONE)
B(-16,0,-6,STONE)
B(-16,0,-5,STONE)
B(-16,0,-4,STONE)
B(-16,0,-3,STONE)
B(-16,0,-2,STONE)
B(-16,0,-1,STONE)
B(-16,0,0,STONE)
B(-16,1,-11,STONE)
B(-16,1,-10,STONE)
B(-16,1,-9,STONE)
B(-16,1,-8,STONE)
B(-16,1,-7,STONE)
B(-16,1,-6,STONE)
B(-16,1,-5,STONE)
B(-16,1,-4,STONE)
B(-16,1,-3,STONE)
B(-16,1,-2,STONE)
B(-16,1,-1,STONE)
B(-16,2,-10,STONE)
B(-16,2,-9,STONE)
B(-16,2,-8,STONE)
B(-16,2,-7,STONE)
B(-16,2,-6,STONE)
B(-16,2,-5,STONE)
B(-16,2,-4,STONE)
B(-16,2,-3,STONE)
B(-16,2,-2,STONE)
B(-16,2,-1,STONE)
B(-16,3,-10,STONE)
B(-16,3,-9,STONE)
B(-16,3,-8,STONE)
B(-16,3,-7,STONE)
B(-16,3,-6,STONE)
B(-16,3,-5,STONE)
B(-16,3,-4,STONE)
B(-16,3,-3,STONE)
B(-16,3,-2,STONE)
B(-16,4,-10,STONE)
B(-16,4,-9,STONE)
B(-16,4,-8,STONE)
B(-16,4,-7,STONE)
B(-16,4,-6,STONE)
B(-16,4,-5,STONE)
B(-16,4,-4,STONE)
B(-16,4,-3,STONE)
B(-16,5,-8,STONE)
B(-16,5,-7,STONE)
B(-16,5,-6,STONE)
B(-16,5,-5,STONE)
B(-16,5,-4,STONE)
B(-16,5,-3,STONE)
B(-16,6,-7,STONE)
B(-16,6,-6,STONE)
B(-16,6,-5,STONE)
B(-16,6,-4,STONE)
B(-16,6,-3,STONE)
B(-15,-12,-6,STONE)
B(-15,-12,-5,STONE)
B(-15,-12,-4,STONE)
B(-15,-12,-3,STONE)
B(-15,-11,-7,STONE)
B(-15,-11,-6,STONE)
B(-15,-11,-5,STONE)
B(-15,-11,-4,STONE)
B(-15,-11,-3,STONE)
B(-15,-11,-2,STONE)
B(-15,-11,-1,STONE)
B(-15,-10,-8,STONE)
B(-15,-10,-7,STONE)
B(-15,-10,-6,STONE)
B(-15,-10,-5,STONE)
B(-15,-10,-4,STONE)
B(-15,-10,-3,STONE)
B(-15,-10,-2,STONE)
B(-15,-10,-1,STONE)
B(-15,-9,-9,STONE)
B(-15,-9,-8,STONE)
B(-15,-9,-7,STONE)
B(-15,-9,-6,STONE)
B(-15,-9,-5,STONE)
B(-15,-9,-4,STONE)
B(-15,-9,-3,STONE)
B(-15,-9,-2,STONE)
B(-15,-9,-1,STONE)
B(-15,-8,-10,STONE)
B(-15,-8,-9,STONE)
B(-15,-8,-8,STONE)
B(-15,-8,-7,STONE)
B(-15,-8,-6,STONE)
B(-15,-8,-5,STONE)
B(-15,-8,-4,STONE)
B(-15,-8,-3,STONE)
B(-15,-8,-2,STONE)
B(-15,-8,-1,STONE)
B(-15,-7,-10,STONE)
B(-15,-7,-9,STONE)
B(-15,-7,-8,STONE)
B(-15,-7,-7,STONE)
B(-15,-7,-6,STONE)
B(-15,-7,-5,STONE)
B(-15,-7,-4,STONE)
B(-15,-7,-3,STONE)
B(-15,-7,-2,STONE)
B(-15,-7,-1,STONE)
B(-15,-7,0,STONE)
B(-15,-6,-11,STONE)
B(-15,-6,-10,STONE)
B(-15,-6,-9,STONE)
B(-15,-6,-8,STONE)
B(-15,-6,-7,STONE)
B(-15,-6,-6,STONE)
B(-15,-6,-5,STONE)
B(-15,-6,-4,STONE)
B(-15,-6,-3,STONE)
B(-15,-6,-2,STONE)
B(-15,-6,-1,STONE)
B(-15,-6,0,STONE)
B(-15,-6,1,STONE)
B(-15,-6,5,STONE)
B(-15,-6,6,STONE)
B(-15,-6,7,STONE)
B(-15,-6,8,STONE)
B(-15,-5,-14,STONE)
B(-15,-5,-13,STONE)
B(-15,-5,-12,STONE)
B(-15,-5,-11,STONE)
B(-15,-5,-10,STONE)
B(-15,-5,-9,STONE)
B(-15,-5,-8,STONE)
B(-15,-5,-7,STONE)
B(-15,-5,-6,STONE)
B(-15,-5,-5,STONE)
B(-15,-5,-4,STONE)
B(-15,-5,-3,STONE)
B(-15,-5,-2,STONE)
B(-15,-5,-1,STONE)
B(-15,-5,0,STONE)
B(-15,-5,1,STONE)
B(-15,-5,2,STONE)
B(-15,-5,3,STONE)
B(-15,-5,4,STONE)
B(-15,-5,5,STONE)
B(-15,-5,6,STONE)
B(-15,-5,7,STONE)
B(-15,-5,8,STONE)
B(-15,-5,9,STONE)
B(-15,-5,10,STONE)
B(-15,-4,-14,STONE)
B(-15,-4,-13,STONE)
B(-15,-4,-12,STONE)
B(-15,-4,-11,STONE)
B(-15,-4,-10,STONE)
B(-15,-4,-9,STONE)
B(-15,-4,-8,STONE)
B(-15,-4,-7,STONE)
B(-15,-4,-6,STONE)
B(-15,-4,-5,STONE)
B(-15,-4,-4,STONE)
B(-15,-4,-3,STONE)
B(-15,-4,-2,STONE)
B(-15,-4,-1,STONE)
B(-15,-4,0,STONE)
B(-15,-4,1,STONE)
B(-15,-4,2,STONE)
B(-15,-4,3,STONE)
B(-15,-4,4,STONE)
B(-15,-4,5,STONE)
B(-15,-4,6,STONE)
B(-15,-4,7,STONE)
B(-15,-4,8,STONE)
B(-15,-4,9,STONE)
B(-15,-4,10,STONE)
B(-15,-4,11,STONE)
B(-15,-3,-14,STONE)
B(-15,-3,-13,STONE)
B(-15,-3,-12,STONE)
B(-15,-3,-11,STONE)
B(-15,-3,-10,STONE)
B(-15,-3,-9,STONE)
B(-15,-3,-8,STONE)
B(-15,-3,-7,STONE)
B(-15,-3,-6,STONE)
B(-15,-3,-5,STONE)
B(-15,-3,-4,STONE)
B(-15,-3,-3,STONE)
B(-15,-3,-2,STONE)
B(-15,-3,-1,STONE)
B(-15,-3,0,STONE)
B(-15,-3,1,STONE)
B(-15,-3,2,STONE)
B(-15,-3,3,STONE)
B(-15,-3,4,STONE)
B(-15,-3,5,STONE)
B(-15,-3,6,STONE)
B(-15,-3,7,STONE)
B(-15,-3,8,STONE)
B(-15,-3,9,STONE)
B(-15,-3,10,STONE)
B(-15,-3,11,STONE)
B(-15,-3,12,STONE)
B(-15,-2,-14,STONE)
B(-15,-2,-13,STONE)
B(-15,-2,-12,STONE)
B(-15,-2,-11,STONE)
B(-15,-2,-10,STONE)
B(-15,-2,-9,STONE)
B(-15,-2,-8,STONE)
B(-15,-2,-7,STONE)
B(-15,-2,-6,STONE)
B(-15,-2,-5,STONE)
B(-15,-2,-4,STONE)
B(-15,-2,-3,STONE)
B(-15,-2,-2,STONE)
B(-15,-2,-1,STONE)
B(-15,-2,0,STONE)
B(-15,-2,1,STONE)
B(-15,-2,2,STONE)
B(-15,-2,3,STONE)
B(-15,-2,4,STONE)
B(-15,-2,5,STONE)
B(-15,-2,6,STONE)
B(-15,-2,7,STONE)
B(-15,-2,8,STONE)
B(-15,-2,9,STONE)
B(-15,-2,10,STONE)
B(-15,-2,11,STONE)
B(-15,-2,12,STONE)
B(-15,-1,-14,STONE)
B(-15,-1,-13,STONE)
B(-15,-1,-12,STONE)
B(-15,-1,-11,STONE)
B(-15,-1,-10,STONE)
B(-15,-1,-9,STONE)
B(-15,-1,-8,STONE)
B(-15,-1,-7,STONE)
B(-15,-1,-6,STONE)
B(-15,-1,-5,STONE)
B(-15,-1,-4,STONE)
B(-15,-1,-3,STONE)
B(-15,-1,-2,STONE)
B(-15,-1,-1,STONE)
B(-15,-1,0,STONE)
B(-15,-1,1,STONE)
B(-15,-1,2,STONE)
B(-15,-1,3,STONE)
B(-15,-1,4,STONE)
B(-15,-1,5,STONE)
B(-15,-1,6,STONE)
B(-15,-1,7,STONE)
B(-15,-1,8,STONE)
B(-15,-1,9,STONE)
B(-15,-1,10,STONE)
B(-15,-1,11,STONE)
B(-15,0,-14,STONE)
B(-15,0,-13,STONE)
B(-15,0,-12,STONE)
B(-15,0,-11,STONE)
B(-15,0,-10,STONE)
B(-15,0,-9,STONE)
B(-15,0,-8,STONE)
B(-15,0,-7,STONE)
B(-15,0,-6,STONE)
B(-15,0,-5,STONE)
B(-15,0,-4,STONE)
B(-15,0,-3,STONE)
B(-15,0,-2,STONE)
B(-15,0,-1,STONE)
B(-15,0,0,STONE)
B(-15,0,1,STONE)
B(-15,0,2,STONE)
B(-15,0,3,STONE)
B(-15,0,4,STONE)
B(-15,0,5,STONE)
B(-15,0,6,STONE)
B(-15,0,7,STONE)
B(-15,0,8,STONE)
B(-15,0,9,STONE)
B(-15,0,10,STONE)
B(-15,1,-11,STONE)
B(-15,1,-10,STONE)
B(-15,1,-9,STONE)
B(-15,1,-8,STONE)
B(-15,1,-7,STONE)
B(-15,1,-6,STONE)
B(-15,1,-5,STONE)
B(-15,1,-4,STONE)
B(-15,1,-3,STONE)
B(-15,1,-2,STONE)
B(-15,1,-1,STONE)
B(-15,1,0,STONE)
B(-15,1,1,STONE)
B(-15,1,5,STONE)
B(-15,1,6,STONE)
B(-15,1,7,STONE)
B(-15,1,8,STONE)
B(-15,2,-10,STONE)
B(-15,2,-9,STONE)
B(-15,2,-8,STONE)
B(-15,2,-7,STONE)
B(-15,2,-6,STONE)
B(-15,2,-5,STONE)
B(-15,2,-4,STONE)
B(-15,2,-3,STONE)
B(-15,2,-2,STONE)
B(-15,2,-1,STONE)
B(-15,2,0,STONE)
B(-15,3,-10,STONE)
B(-15,3,-9,STONE)
B(-15,3,-8,STONE)
B(-15,3,-7,STONE)
B(-15,3,-6,STONE)
B(-15,3,-5,STONE)
B(-15,3,-4,STONE)
B(-15,3,-3,STONE)
B(-15,3,-2,STONE)
B(-15,3,-1,STONE)
B(-15,4,-9,STONE)
B(-15,4,-8,STONE)
B(-15,4,-7,STONE)
B(-15,4,-6,STONE)
B(-15,4,-5,STONE)
B(-15,4,-4,STONE)
B(-15,4,-3,STONE)
B(-15,4,-2,STONE)
B(-15,4,-1,STONE)
B(-15,5,-8,STONE)
B(-15,5,-7,STONE)
B(-15,5,-6,STONE)
B(-15,5,-5,STONE)
B(-15,5,-4,STONE)
B(-15,5,-3,STONE)
B(-15,5,-2,STONE)
B(-15,5,-1,STONE)
B(-15,6,-7,STONE)
B(-15,6,-6,STONE)
B(-15,6,-5,STONE)
B(-15,6,-4,STONE)
B(-15,6,-3,STONE)
B(-15,6,-2,STONE)
B(-15,6,-1,STONE)
B(-15,7,-6,STONE)
B(-15,7,-5,STONE)
B(-15,7,-4,STONE)
B(-15,7,-3,STONE)
B(-14,-13,-6,STONE)
B(-14,-13,-5,STONE)
B(-14,-13,-4,STONE)
B(-14,-13,-3,STONE)
B(-14,-12,-7,STONE)
B(-14,-12,-6,STONE)
B(-14,-12,-5,STONE)
B(-14,-12,-4,STONE)
B(-14,-12,-3,STONE)
B(-14,-12,-2,STONE)
B(-14,-12,-1,STONE)
B(-14,-12,0,STONE)
B(-14,-11,-7,STONE)
B(-14,-11,-6,STONE)
B(-14,-11,-5,STONE)
B(-14,-11,-4,STONE)
B(-14,-11,-3,STONE)
B(-14,-11,-2,STONE)
B(-14,-11,-1,STONE)
B(-14,-11,0,STONE)
B(-14,-10,-8,STONE)
B(-14,-10,-7,STONE)
B(-14,-10,-6,STONE)
B(-14,-10,-5,STONE)
B(-14,-10,-4,STONE)
B(-14,-10,-3,STONE)
B(-14,-10,-2,STONE)
B(-14,-10,-1,STONE)
B(-14,-10,0,STONE)
B(-14,-9,-9,STONE)
B(-14,-9,-8,STONE)
B(-14,-9,-7,STONE)
B(-14,-9,-6,STONE)
B(-14,-9,-5,STONE)
B(-14,-9,-4,STONE)
B(-14,-9,-3,STONE)
B(-14,-9,-2,STONE)
B(-14,-9,-1,STONE)
B(-14,-9,0,STONE)
B(-14,-8,-10,STONE)
B(-14,-8,-9,STONE)
B(-14,-8,-8,STONE)
B(-14,-8,-7,STONE)
B(-14,-8,-6,STONE)
B(-14,-8,-5,STONE)
B(-14,-8,-4,STONE)
B(-14,-8,-3,STONE)
B(-14,-8,-2,STONE)
B(-14,-8,-1,STONE)
B(-14,-8,0,STONE)
B(-14,-8,5,STONE)
B(-14,-8,6,STONE)
B(-14,-7,-10,STONE)
B(-14,-7,-9,STONE)
B(-14,-7,-8,STONE)
B(-14,-7,-7,STONE)
B(-14,-7,-6,STONE)
B(-14,-7,-5,STONE)
B(-14,-7,-4,STONE)
B(-14,-7,-3,STONE)
B(-14,-7,-2,STONE)
B(-14,-7,-1,STONE)
B(-14,-7,0,STONE)
B(-14,-7,1,STONE)
B(-14,-7,5,STONE)
B(-14,-7,6,STONE)
B(-14,-7,7,STONE)
B(-14,-6,-11,STONE)
B(-14,-6,-10,STONE)
B(-14,-6,-9,STONE)
B(-14,-6,-8,STONE)
B(-14,-6,-7,STONE)
B(-14,-6,-6,STONE)
B(-14,-6,-5,STONE)
B(-14,-6,-4,STONE)
B(-14,-6,-3,STONE)
B(-14,-6,-2,STONE)
B(-14,-6,-1,STONE)
B(-14,-6,0,STONE)
B(-14,-6,1,STONE)
B(-14,-6,2,STONE)
B(-14,-6,4,STONE)
B(-14,-6,5,STONE)
B(-14,-6,6,STONE)
B(-14,-6,7,STONE)
B(-14,-6,8,STONE)
B(-14,-6,9,STONE)
B(-14,-6,10,STONE)
B(-14,-5,-14,STONE)
B(-14,-5,-13,STONE)
B(-14,-5,-12,STONE)
B(-14,-5,-11,STONE)
B(-14,-5,-10,STONE)
B(-14,-5,-9,STONE)
B(-14,-5,-8,STONE)
B(-14,-5,-7,STONE)
B(-14,-5,-6,STONE)
B(-14,-5,-5,STONE)
B(-14,-5,-4,STONE)
B(-14,-5,-3,STONE)
B(-14,-5,-2,STONE)
B(-14,-5,-1,STONE)
B(-14,-5,0,STONE)
B(-14,-5,1,STONE)
B(-14,-5,2,STONE)
B(-14,-5,3,STONE)
B(-14,-5,4,STONE)
B(-14,-5,5,STONE)
B(-14,-5,6,STONE)
B(-14,-5,7,STONE)
B(-14,-5,8,STONE)
B(-14,-5,9,STONE)
B(-14,-5,10,STONE)
B(-14,-4,-14,STONE)
B(-14,-4,-13,STONE)
B(-14,-4,-12,STONE)
B(-14,-4,-11,STONE)
B(-14,-4,-10,STONE)
B(-14,-4,-9,STONE)
B(-14,-4,-8,STONE)
B(-14,-4,-7,STONE)
B(-14,-4,-6,STONE)
B(-14,-4,-5,STONE)
B(-14,-4,-4,STONE)
B(-14,-4,-3,STONE)
B(-14,-4,-2,STONE)
B(-14,-4,-1,STONE)
B(-14,-4,0,STONE)
B(-14,-4,1,STONE)
B(-14,-4,2,STONE)
B(-14,-4,3,STONE)
B(-14,-4,4,STONE)
B(-14,-4,5,STONE)
B(-14,-4,6,STONE)
B(-14,-4,7,STONE)
B(-14,-4,8,STONE)
B(-14,-4,9,STONE)
B(-14,-4,10,STONE)
B(-14,-4,11,STONE)
B(-14,-3,-14,STONE)
B(-14,-3,-13,STONE)
B(-14,-3,-12,STONE)
B(-14,-3,-11,STONE)
B(-14,-3,-10,STONE)
B(-14,-3,-9,STONE)
B(-14,-3,-8,STONE)
B(-14,-3,-7,STONE)
B(-14,-3,-6,STONE)
B(-14,-3,-5,STONE)
B(-14,-3,-4,STONE)
B(-14,-3,-3,STONE)
B(-14,-3,-2,STONE)
B(-14,-3,-1,STONE)
B(-14,-3,0,STONE)
B(-14,-3,1,STONE)
B(-14,-3,2,STONE)
B(-14,-3,3,STONE)
B(-14,-3,4,STONE)
B(-14,-3,5,STONE)
B(-14,-3,6,STONE)
B(-14,-3,7,STONE)
B(-14,-3,8,STONE)
B(-14,-3,9,STONE)
B(-14,-3,10,STONE)
B(-14,-3,11,STONE)
B(-14,-3,12,STONE)
B(-14,-2,-14,STONE)
B(-14,-2,-13,STONE)
B(-14,-2,-12,STONE)
B(-14,-2,-11,STONE)
B(-14,-2,-10,STONE)
B(-14,-2,-9,STONE)
B(-14,-2,-8,STONE)
B(-14,-2,-7,STONE)
B(-14,-2,-6,STONE)
B(-14,-2,-5,STONE)
B(-14,-2,-4,STONE)
B(-14,-2,-3,STONE)
B(-14,-2,-2,STONE)
B(-14,-2,-1,STONE)
B(-14,-2,0,STONE)
B(-14,-2,1,STONE)
B(-14,-2,2,STONE)
B(-14,-2,3,STONE)
B(-14,-2,4,STONE)
B(-14,-2,5,STONE)
B(-14,-2,6,STONE)
B(-14,-2,7,STONE)
B(-14,-2,8,STONE)
B(-14,-2,9,STONE)
B(-14,-2,10,STONE)
B(-14,-2,11,STONE)
B(-14,-2,12,STONE)
B(-14,-1,-14,STONE)
B(-14,-1,-13,STONE)
B(-14,-1,-12,STONE)
B(-14,-1,-11,STONE)
B(-14,-1,-10,STONE)
B(-14,-1,-9,STONE)
B(-14,-1,-8,STONE)
B(-14,-1,-7,STONE)
B(-14,-1,-6,STONE)
B(-14,-1,-5,STONE)
B(-14,-1,-4,STONE)
B(-14,-1,-3,STONE)
B(-14,-1,-2,STONE)
B(-14,-1,-1,STONE)
B(-14,-1,0,STONE)
B(-14,-1,1,STONE)
B(-14,-1,2,STONE)
B(-14,-1,3,STONE)
B(-14,-1,4,STONE)
B(-14,-1,5,STONE)
B(-14,-1,6,STONE)
B(-14,-1,7,STONE)
B(-14,-1,8,STONE)
B(-14,-1,9,STONE)
B(-14,-1,10,STONE)
B(-14,-1,11,STONE)
B(-14,0,-14,STONE)
B(-14,0,-13,STONE)
B(-14,0,-12,STONE)
B(-14,0,-11,STONE)
B(-14,0,-10,STONE)
B(-14,0,-9,STONE)
B(-14,0,-8,STONE)
B(-14,0,-7,STONE)
B(-14,0,-6,STONE)
B(-14,0,-5,STONE)
B(-14,0,-4,STONE)
B(-14,0,-3,STONE)
B(-14,0,-2,STONE)
B(-14,0,-1,STONE)
B(-14,0,0,STONE)
B(-14,0,1,STONE)
B(-14,0,2,STONE)
B(-14,0,3,STONE)
B(-14,0,4,STONE)
B(-14,0,5,STONE)
B(-14,0,6,STONE)
B(-14,0,7,STONE)
B(-14,0,8,STONE)
B(-14,0,9,STONE)
B(-14,0,10,STONE)
B(-14,1,-11,STONE)
B(-14,1,-10,STONE)
B(-14,1,-9,STONE)
B(-14,1,-8,STONE)
B(-14,1,-7,STONE)
B(-14,1,-6,STONE)
B(-14,1,-5,STONE)
B(-14,1,-4,STONE)
B(-14,1,-3,STONE)
B(-14,1,-2,STONE)
B(-14,1,-1,STONE)
B(-14,1,0,STONE)
B(-14,1,1,STONE)
B(-14,1,2,STONE)
B(-14,1,4,STONE)
B(-14,1,5,STONE)
B(-14,1,6,STONE)
B(-14,1,7,STONE)
B(-14,1,8,STONE)
B(-14,1,9,STONE)
B(-14,1,10,STONE)
B(-14,2,-10,STONE)
B(-14,2,-9,STONE)
B(-14,2,-8,STONE)
B(-14,2,-7,STONE)
B(-14,2,-6,STONE)
B(-14,2,-5,STONE)
B(-14,2,-4,STONE)
B(-14,2,-3,STONE)
B(-14,2,-2,STONE)
B(-14,2,-1,STONE)
B(-14,2,0,STONE)
B(-14,2,1,STONE)
B(-14,2,5,STONE)
B(-14,2,6,STONE)
B(-14,2,7,STONE)
B(-14,3,-10,STONE)
B(-14,3,-9,STONE)
B(-14,3,-8,STONE)
B(-14,3,-7,STONE)
B(-14,3,-6,STONE)
B(-14,3,-5,STONE)
B(-14,3,-4,STONE)
B(-14,3,-3,STONE)
B(-14,3,-2,STONE)
B(-14,3,-1,STONE)
B(-14,3,0,STONE)
B(-14,3,5,STONE)
B(-14,3,6,STONE)
B(-14,4,-9,STONE)
B(-14,4,-8,STONE)
B(-14,4,-7,STONE)
B(-14,4,-6,STONE)
B(-14,4,-5,STONE)
B(-14,4,-4,STONE)
B(-14,4,-3,STONE)
B(-14,4,-2,STONE)
B(-14,4,-1,STONE)
B(-14,4,0,STONE)
B(-14,5,-8,STONE)
B(-14,5,-7,STONE)
B(-14,5,-6,STONE)
B(-14,5,-5,STONE)
B(-14,5,-4,STONE)
B(-14,5,-3,STONE)
B(-14,5,-2,STONE)
B(-14,5,-1,STONE)
B(-14,5,0,STONE)
B(-14,6,-7,STONE)
B(-14,6,-6,STONE)
B(-14,6,-5,STONE)
B(-14,6,-4,STONE)
B(-14,6,-3,STONE)
B(-14,6,-2,STONE)
B(-14,6,-1,STONE)
B(-14,6,0,STONE)
B(-14,7,-7,STONE)
B(-14,7,-6,STONE)
B(-14,7,-5,STONE)
B(-14,7,-4,STONE)
B(-14,7,-3,STONE)
B(-14,7,-2,STONE)
B(-14,7,-1,STONE)
B(-14,7,0,STONE)
B(-14,8,-6,STONE)
B(-14,8,-5,STONE)
B(-14,8,-4,STONE)
B(-14,8,-3,STONE)
B(-13,-15,-3,STONE)
B(-13,-15,-2,STONE)
B(-13,-15,-1,STONE)
B(-13,-14,-5,STONE)
B(-13,-14,-4,STONE)
B(-13,-14,-3,STONE)
B(-13,-14,-2,STONE)
B(-13,-14,-1,STONE)
B(-13,-14,0,STONE)
B(-13,-13,-6,STONE)
B(-13,-13,-5,STONE)
B(-13,-13,-4,STONE)
B(-13,-13,-3,STONE)
B(-13,-13,-2,STONE)
B(-13,-13,-1,STONE)
B(-13,-13,0,STONE)
B(-13,-13,1,STONE)
B(-13,-12,-7,STONE)
B(-13,-12,-6,STONE)
B(-13,-12,-5,STONE)
B(-13,-12,-4,STONE)
B(-13,-12,-3,STONE)
B(-13,-12,-2,STONE)
B(-13,-12,-1,STONE)
B(-13,-12,0,STONE)
B(-13,-12,1,STONE)
B(-13,-12,2,STONE)
B(-13,-11,-7,STONE)
B(-13,-11,-6,STONE)
B(-13,-11,-5,STONE)
B(-13,-11,-4,STONE)
B(-13,-11,-3,STONE)
B(-13,-11,-2,STONE)
B(-13,-11,-1,STONE)
B(-13,-11,0,STONE)
B(-13,-11,1,STONE)
B(-13,-11,2,STONE)
B(-13,-11,3,STONE)
B(-13,-10,-8,STONE)
B(-13,-10,-7,STONE)
B(-13,-10,-6,STONE)
B(-13,-10,-5,STONE)
B(-13,-10,-4,STONE)
B(-13,-10,-3,STONE)
B(-13,-10,-2,STONE)
B(-13,-10,-1,STONE)
B(-13,-10,0,STONE)
B(-13,-10,1,STONE)
B(-13,-10,2,STONE)
B(-13,-10,3,STONE)
B(-13,-10,4,STONE)
B(-13,-10,5,STONE)
B(-13,-9,-9,STONE)
B(-13,-9,-8,STONE)
B(-13,-9,-7,STONE)
B(-13,-9,-6,STONE)
B(-13,-9,-5,STONE)
B(-13,-9,-4,STONE)
B(-13,-9,-3,STONE)
B(-13,-9,-2,STONE)
B(-13,-9,-1,STONE)
B(-13,-9,0,STONE)
B(-13,-9,1,STONE)
B(-13,-9,2,STONE)
B(-13,-9,3,STONE)
B(-13,-9,4,STONE)
B(-13,-9,5,STONE)
B(-13,-9,6,STONE)
B(-13,-9,7,STONE)
B(-13,-9,8,STONE)
B(-13,-8,-10,STONE)
B(-13,-8,-9,STONE)
B(-13,-8,-8,STONE)
B(-13,-8,-7,STONE)
B(-13,-8,-6,STONE)
B(-13,-8,-5,STONE)
B(-13,-8,-4,STONE)
B(-13,-8,-3,STONE)
B(-13,-8,-2,STONE)
B(-13,-8,-1,STONE)
B(-13,-8,0,STONE)
B(-13,-8,1,STONE)
B(-13,-8,2,STONE)
B(-13,-8,3,STONE)
B(-13,-8,4,STONE)
B(-13,-8,5,STONE)
B(-13,-8,6,STONE)
B(-13,-8,7,STONE)
B(-13,-8,8,STONE)
B(-13,-8,9,STONE)
B(-13,-7,-10,STONE)
B(-13,-7,-9,STONE)
B(-13,-7,-8,STONE)
B(-13,-7,-7,STONE)
B(-13,-7,-6,STONE)
B(-13,-7,-5,STONE)
B(-13,-7,-4,STONE)
B(-13,-7,-3,STONE)
B(-13,-7,-2,STONE)
B(-13,-7,-1,STONE)
B(-13,-7,0,STONE)
B(-13,-7,1,STONE)
B(-13,-7,2,STONE)
B(-13,-7,3,STONE)
B(-13,-7,4,STONE)
B(-13,-7,5,STONE)
B(-13,-7,6,STONE)
B(-13,-7,7,STONE)
B(-13,-7,8,STONE)
B(-13,-7,9,STONE)
B(-13,-7,10,STONE)
B(-13,-6,-11,STONE)
B(-13,-6,-10,STONE)
B(-13,-6,-9,STONE)
B(-13,-6,-8,STONE)
B(-13,-6,-7,STONE)
B(-13,-6,-6,STONE)
B(-13,-6,-5,STONE)
B(-13,-6,-4,STONE)
B(-13,-6,-3,STONE)
B(-13,-6,-2,STONE)
B(-13,-6,-1,STONE)
B(-13,-6,0,STONE)
B(-13,-6,1,STONE)
B(-13,-6,2,STONE)
B(-13,-6,3,STONE)
B(-13,-6,4,STONE)
B(-13,-6,5,STONE)
B(-13,-6,6,STONE)
B(-13,-6,7,STONE)
B(-13,-6,8,STONE)
B(-13,-6,9,STONE)
B(-13,-6,10,STONE)
B(-13,-6,11,STONE)
B(-13,-5,-12,STONE)
B(-13,-5,-11,STONE)
B(-13,-5,-10,STONE)
B(-13,-5,-9,STONE)
B(-13,-5,-8,STONE)
B(-13,-5,-7,STONE)
B(-13,-5,-6,STONE)
B(-13,-5,-5,STONE)
B(-13,-5,-4,STONE)
B(-13,-5,-3,STONE)
B(-13,-5,-2,STONE)
B(-13,-5,-1,STONE)
B(-13,-5,0,STONE)
B(-13,-5,1,STONE)
B(-13,-5,2,STONE)
B(-13,-5,3,STONE)
B(-13,-5,4,STONE)
B(-13,-5,5,STONE)
B(-13,-5,6,STONE)
B(-13,-5,7,STONE)
B(-13,-5,8,STONE)
B(-13,-5,9,STONE)
B(-13,-5,10,STONE)
B(-13,-5,11,STONE)
B(-13,-4,-14,STONE)
B(-13,-4,-13,STONE)
B(-13,-4,-12,STONE)
B(-13,-4,-11,STONE)
B(-13,-4,-10,STONE)
B(-13,-4,-9,STONE)
B(-13,-4,-8,STONE)
B(-13,-4,-7,STONE)
B(-13,-4,-6,STONE)
B(-13,-4,-5,STONE)
B(-13,-4,-4,STONE)
B(-13,-4,-3,STONE)
B(-13,-4,-2,STONE)
B(-13,-4,-1,STONE)
B(-13,-4,0,STONE)
B(-13,-4,1,STONE)
B(-13,-4,2,STONE)
B(-13,-4,3,STONE)
B(-13,-4,4,STONE)
B(-13,-4,5,STONE)
B(-13,-4,6,STONE)
B(-13,-4,7,STONE)
B(-13,-4,8,STONE)
B(-13,-4,9,STONE)
B(-13,-4,10,STONE)
B(-13,-4,11,STONE)
B(-13,-3,-14,STONE)
B(-13,-3,-13,STONE)
B(-13,-3,-12,STONE)
B(-13,-3,-11,STONE)
B(-13,-3,-10,STONE)
B(-13,-3,-9,STONE)
B(-13,-3,-8,STONE)
B(-13,-3,-7,STONE)
B(-13,-3,-6,STONE)
B(-13,-3,-5,STONE)
B(-13,-3,-4,STONE)
B(-13,-3,-3,STONE)
B(-13,-3,-2,STONE)
B(-13,-3,-1,STONE)
B(-13,-3,0,STONE)
B(-13,-3,1,STONE)
B(-13,-3,2,STONE)
B(-13,-3,3,STONE)
B(-13,-3,4,STONE)
B(-13,-3,5,STONE)
B(-13,-3,6,STONE)
B(-13,-3,7,STONE)
B(-13,-3,8,STONE)
B(-13,-3,9,STONE)
B(-13,-3,10,STONE)
B(-13,-3,11,STONE)
B(-13,-3,12,STONE)
B(-13,-2,-14,STONE)
B(-13,-2,-13,STONE)
B(-13,-2,-12,STONE)
B(-13,-2,-11,STONE)
B(-13,-2,-10,STONE)
B(-13,-2,-9,STONE)
B(-13,-2,-8,STONE)
B(-13,-2,-7,STONE)
B(-13,-2,-6,STONE)
B(-13,-2,-5,STONE)
B(-13,-2,-4,STONE)
B(-13,-2,-3,STONE)
B(-13,-2,-2,STONE)
B(-13,-2,-1,STONE)
B(-13,-2,0,STONE)
B(-13,-2,1,STONE)
B(-13,-2,2,STONE)
B(-13,-2,3,STONE)
B(-13,-2,4,STONE)
B(-13,-2,5,STONE)
B(-13,-2,6,STONE)
B(-13,-2,7,STONE)
B(-13,-2,8,STONE)
B(-13,-2,9,STONE)
B(-13,-2,10,STONE)
B(-13,-2,11,STONE)
B(-13,-2,12,STONE)
B(-13,-1,-14,STONE)
B(-13,-1,-13,STONE)
B(-13,-1,-12,STONE)
B(-13,-1,-11,STONE)
B(-13,-1,-10,STONE)
B(-13,-1,-9,STONE)
B(-13,-1,-8,STONE)
B(-13,-1,-7,STONE)
B(-13,-1,-6,STONE)
B(-13,-1,-5,STONE)
B(-13,-1,-4,STONE)
B(-13,-1,-3,STONE)
B(-13,-1,-2,STONE)
B(-13,-1,-1,STONE)
B(-13,-1,0,STONE)
B(-13,-1,1,STONE)
B(-13,-1,2,STONE)
B(-13,-1,3,STONE)
B(-13,-1,4,STONE)
B(-13,-1,5,STONE)
B(-13,-1,6,STONE)
B(-13,-1,7,STONE)
B(-13,-1,8,STONE)
B(-13,-1,9,STONE)
B(-13,-1,10,STONE)
B(-13,-1,11,STONE)
B(-13,0,-12,STONE)
B(-13,0,-11,STONE)
B(-13,0,-10,STONE)
B(-13,0,-9,STONE)
B(-13,0,-8,STONE)
B(-13,0,-7,STONE)
B(-13,0,-6,STONE)
B(-13,0,-5,STONE)
B(-13,0,-4,STONE)
B(-13,0,-3,STONE)
B(-13,0,-2,STONE)
B(-13,0,-1,STONE)
B(-13,0,0,STONE)
B(-13,0,1,STONE)
B(-13,0,2,STONE)
B(-13,0,3,STONE)
B(-13,0,4,STONE)
B(-13,0,5,STONE)
B(-13,0,6,STONE)
B(-13,0,7,STONE)
B(-13,0,8,STONE)
B(-13,0,9,STONE)
B(-13,0,10,STONE)
B(-13,0,11,STONE)
B(-13,1,-11,STONE)
B(-13,1,-10,STONE)
B(-13,1,-9,STONE)
B(-13,1,-8,STONE)
B(-13,1,-7,STONE)
B(-13,1,-6,STONE)
B(-13,1,-5,STONE)
B(-13,1,-4,STONE)
B(-13,1,-3,STONE)
B(-13,1,-2,STONE)
B(-13,1,-1,STONE)
B(-13,1,0,STONE)
B(-13,1,1,STONE)
B(-13,1,2,STONE)
B(-13,1,3,STONE)
B(-13,1,4,STONE)
B(-13,1,5,STONE)
B(-13,1,6,STONE)
B(-13,1,7,STONE)
B(-13,1,8,STONE)
B(-13,1,9,STONE)
B(-13,1,10,STONE)
B(-13,1,11,STONE)
B(-13,2,-10,STONE)
B(-13,2,-9,STONE)
B(-13,2,-8,STONE)
B(-13,2,-7,STONE)
B(-13,2,-6,STONE)
B(-13,2,-5,STONE)
B(-13,2,-4,STONE)
B(-13,2,-3,STONE)
B(-13,2,-2,STONE)
B(-13,2,-1,STONE)
B(-13,2,0,STONE)
B(-13,2,1,STONE)
B(-13,2,2,STONE)
B(-13,2,3,STONE)
B(-13,2,4,STONE)
B(-13,2,5,STONE)
B(-13,2,6,STONE)
B(-13,2,7,STONE)
B(-13,2,8,STONE)
B(-13,2,9,STONE)
B(-13,2,10,STONE)
B(-13,3,-10,STONE)
B(-13,3,-9,STONE)
B(-13,3,-8,STONE)
B(-13,3,-7,STONE)
B(-13,3,-6,STONE)
B(-13,3,-5,STONE)
B(-13,3,-4,STONE)
B(-13,3,-3,STONE)
B(-13,3,-2,STONE)
B(-13,3,-1,STONE)
B(-13,3,0,STONE)
B(-13,3,1,STONE)
B(-13,3,2,STONE)
B(-13,3,3,STONE)
B(-13,3,4,STONE)
B(-13,3,5,STONE)
B(-13,3,6,STONE)
B(-13,3,7,STONE)
B(-13,3,8,STONE)
B(-13,3,9,STONE)
B(-13,4,-9,STONE)
B(-13,4,-8,STONE)
B(-13,4,-7,STONE)
B(-13,4,-6,STONE)
B(-13,4,-5,STONE)
B(-13,4,-4,STONE)
B(-13,4,-3,STONE)
B(-13,4,-2,STONE)
B(-13,4,-1,STONE)
B(-13,4,0,STONE)
B(-13,4,1,STONE)
B(-13,4,2,STONE)
B(-13,4,3,STONE)
B(-13,4,4,STONE)
B(-13,4,5,STONE)
B(-13,4,6,STONE)
B(-13,4,7,STONE)
B(-13,4,8,STONE)
B(-13,5,-8,STONE)
B(-13,5,-7,STONE)
B(-13,5,-6,STONE)
B(-13,5,-5,STONE)
B(-13,5,-4,STONE)
B(-13,5,-3,STONE)
B(-13,5,-2,STONE)
B(-13,5,-1,STONE)
B(-13,5,0,STONE)
B(-13,5,1,STONE)
B(-13,5,2,STONE)
B(-13,5,3,STONE)
B(-13,5,4,STONE)
B(-13,5,5,STONE)
B(-13,6,-7,STONE)
B(-13,6,-6,STONE)
B(-13,6,-5,STONE)
B(-13,6,-4,STONE)
B(-13,6,-3,STONE)
B(-13,6,-2,STONE)
B(-13,6,-1,STONE)
B(-13,6,0,STONE)
B(-13,6,1,STONE)
B(-13,6,2,STONE)
B(-13,6,3,STONE)
B(-13,7,-7,STONE)
B(-13,7,-6,STONE)
B(-13,7,-5,STONE)
B(-13,7,-4,STONE)
B(-13,7,-3,STONE)
B(-13,7,-2,STONE)
B(-13,7,-1,STONE)
B(-13,7,0,STONE)
B(-13,7,1,STONE)
B(-13,7,2,STONE)
B(-13,8,-6,STONE)
B(-13,8,-5,STONE)
B(-13,8,-4,STONE)
B(-13,8,-3,STONE)
B(-13,8,-2,STONE)
B(-13,8,-1,STONE)
B(-13,8,0,STONE)
B(-13,8,1,STONE)
B(-13,9,-5,STONE)
B(-13,9,-4,STONE)
B(-13,9,-3,STONE)
B(-13,9,-2,STONE)
B(-13,9,-1,STONE)
B(-13,9,0,STONE)
B(-13,10,-3,STONE)
B(-13,10,-2,STONE)
B(-13,10,-1,STONE)
B(-12,-15,-4,STONE)
B(-12,-15,-3,STONE)
B(-12,-15,-2,STONE)
B(-12,-15,-1,STONE)
B(-12,-15,0,STONE)
B(-12,-14,-5,STONE)
B(-12,-14,-4,STONE)
B(-12,-14,-3,STONE)
B(-12,-14,-2,STONE)
B(-12,-14,-1,STONE)
B(-12,-14,0,STONE)
B(-12,-14,1,STONE)
B(-12,-13,-6,STONE)
B(-12,-13,-5,STONE)
B(-12,-13,-4,STONE)
B(-12,-13,-3,STONE)
B(-12,-13,-2,STONE)
B(-12,-13,-1,STONE)
B(-12,-13,0,STONE)
B(-12,-13,1,STONE)
B(-12,-13,2,STONE)
B(-12,-12,-7,STONE)
B(-12,-12,-6,STONE)
B(-12,-12,-5,STONE)
B(-12,-12,-4,STONE)
B(-12,-12,-3,STONE)
B(-12,-12,-2,STONE)
B(-12,-12,-1,STONE)
B(-12,-12,0,STONE)
B(-12,-12,1,STONE)
B(-12,-12,2,STONE)
B(-12,-12,3,STONE)
B(-12,-11,-7,STONE)
B(-12,-11,-6,STONE)
B(-12,-11,-5,STONE)
B(-12,-11,-4,STONE)
B(-12,-11,-3,STONE)
B(-12,-11,-2,STONE)
B(-12,-11,-1,STONE)
B(-12,-11,0,STONE)
B(-12,-11,1,STONE)
B(-12,-11,2,STONE)
B(-12,-11,3,STONE)
B(-12,-11,4,STONE)
B(-12,-11,5,STONE)
B(-12,-10,-8,STONE)
B(-12,-10,-7,STONE)
B(-12,-10,-6,STONE)
B(-12,-10,-5,STONE)
B(-12,-10,-4,STONE)
B(-12,-10,-3,STONE)
B(-12,-10,-2,STONE)
B(-12,-10,-1,STONE)
B(-12,-10,0,STONE)
B(-12,-10,1,STONE)
B(-12,-10,2,STONE)
B(-12,-10,3,STONE)
B(-12,-10,4,STONE)
B(-12,-10,5,STONE)
B(-12,-10,6,STONE)
B(-12,-10,7,STONE)
B(-12,-9,-9,STONE)
B(-12,-9,-8,STONE)
B(-12,-9,-7,STONE)
B(-12,-9,-6,STONE)
B(-12,-9,-5,STONE)
B(-12,-9,-4,STONE)
B(-12,-9,-3,STONE)
B(-12,-9,-2,STONE)
B(-12,-9,-1,STONE)
B(-12,-9,0,STONE)
B(-12,-9,1,STONE)
B(-12,-9,2,STONE)
B(-12,-9,3,STONE)
B(-12,-9,4,STONE)
B(-12,-9,5,STONE)
B(-12,-9,6,STONE)
B(-12,-9,7,STONE)
B(-12,-9,8,STONE)
B(-12,-8,-9,STONE)
B(-12,-8,-8,STONE)
B(-12,-8,-7,STONE)
B(-12,-8,-6,STONE)
B(-12,-8,-5,STONE)
B(-12,-8,-4,STONE)
B(-12,-8,-3,STONE)
B(-12,-8,-2,STONE)
B(-12,-8,-1,STONE)
B(-12,-8,0,STONE)
B(-12,-8,1,STONE)
B(-12,-8,2,STONE)
B(-12,-8,3,STONE)
B(-12,-8,4,STONE)
B(-12,-8,5,STONE)
B(-12,-8,6,STONE)
B(-12,-8,7,STONE)
B(-12,-8,8,STONE)
B(-12,-8,9,STONE)
B(-12,-7,-10,STONE)
B(-12,-7,-9,STONE)
B(-12,-7,-8,STONE)
B(-12,-7,-7,STONE)
B(-12,-7,-6,STONE)
B(-12,-7,-5,STONE)
B(-12,-7,-4,STONE)
B(-12,-7,-3,STONE)
B(-12,-7,-2,STONE)
B(-12,-7,-1,STONE)
B(-12,-7,0,STONE)
B(-12,-7,1,STONE)
B(-12,-7,2,STONE)
B(-12,-7,3,STONE)
B(-12,-7,4,STONE)
B(-12,-7,5,STONE)
B(-12,-7,6,STONE)
B(-12,-7,7,STONE)
B(-12,-7,8,STONE)
B(-12,-7,9,STONE)
B(-12,-7,10,STONE)
B(-12,-7,11,STONE)
B(-12,-6,-11,STONE)
B(-12,-6,-10,STONE)
B(-12,-6,-9,STONE)
B(-12,-6,-8,STONE)
B(-12,-6,-7,STONE)
B(-12,-6,-6,STONE)
B(-12,-6,-5,STONE)
B(-12,-6,-4,STONE)
B(-12,-6,-3,STONE)
B(-12,-6,-2,STONE)
B(-12,-6,-1,STONE)
B(-12,-6,0,STONE)
B(-12,-6,1,STONE)
B(-12,-6,2,STONE)
B(-12,-6,3,STONE)
B(-12,-6,4,STONE)
B(-12,-6,5,STONE)
B(-12,-6,6,STONE)
B(-12,-6,7,STONE)
B(-12,-6,8,STONE)
B(-12,-6,9,STONE)
B(-12,-6,10,STONE)
B(-12,-6,11,STONE)
B(-12,-5,-12,STONE)
B(-12,-5,-11,STONE)
B(-12,-5,-10,STONE)
B(-12,-5,-9,STONE)
B(-12,-5,-8,STONE)
B(-12,-5,-7,STONE)
B(-12,-5,-6,STONE)
B(-12,-5,-5,STONE)
B(-12,-5,-4,STONE)
B(-12,-5,-3,STONE)
B(-12,-5,-2,STONE)
B(-12,-5,-1,STONE)
B(-12,-5,0,STONE)
B(-12,-5,1,STONE)
B(-12,-5,2,STONE)
B(-12,-5,3,STONE)
B(-12,-5,4,STONE)
B(-12,-5,5,STONE)
B(-12,-5,6,STONE)
B(-12,-5,7,STONE)
B(-12,-5,8,STONE)
B(-12,-5,9,STONE)
B(-12,-5,10,STONE)
B(-12,-5,11,STONE)
B(-12,-4,-13,STONE)
B(-12,-4,-12,STONE)
B(-12,-4,-11,STONE)
B(-12,-4,-10,STONE)
B(-12,-4,-9,STONE)
B(-12,-4,-8,STONE)
B(-12,-4,-7,STONE)
B(-12,-4,-6,STONE)
B(-12,-4,-5,STONE)
B(-12,-4,-4,STONE)
B(-12,-4,-3,STONE)
B(-12,-4,-2,STONE)
B(-12,-4,-1,STONE)
B(-12,-4,0,STONE)
B(-12,-4,1,STONE)
B(-12,-4,2,STONE)
B(-12,-4,3,STONE)
B(-12,-4,4,STONE)
B(-12,-4,5,STONE)
B(-12,-4,6,STONE)
B(-12,-4,7,STONE)
B(-12,-4,8,STONE)
B(-12,-4,9,STONE)
B(-12,-4,10,STONE)
B(-12,-4,11,STONE)
B(-12,-3,-13,STONE)
B(-12,-3,-12,STONE)
B(-12,-3,-11,STONE)
B(-12,-3,-10,STONE)
B(-12,-3,-9,STONE)
B(-12,-3,-8,STONE)
B(-12,-3,-7,STONE)
B(-12,-3,-6,STONE)
B(-12,-3,-5,STONE)
B(-12,-3,-4,STONE)
B(-12,-3,-3,STONE)
B(-12,-3,-2,STONE)
B(-12,-3,-1,STONE)
B(-12,-3,0,STONE)
B(-12,-3,1,STONE)
B(-12,-3,2,STONE)
B(-12,-3,3,STONE)
B(-12,-3,4,STONE)
B(-12,-3,5,STONE)
B(-12,-3,6,STONE)
B(-12,-3,7,STONE)
B(-12,-3,8,STONE)
B(-12,-3,9,STONE)
B(-12,-3,10,STONE)
B(-12,-3,11,STONE)
B(-12,-3,12,STONE)
B(-12,-2,-13,STONE)
B(-12,-2,-12,STONE)
B(-12,-2,-11,STONE)
B(-12,-2,-10,STONE)
B(-12,-2,-9,STONE)
B(-12,-2,-8,STONE)
B(-12,-2,-7,STONE)
B(-12,-2,-6,STONE)
B(-12,-2,-5,STONE)
B(-12,-2,-4,STONE)
B(-12,-2,-3,STONE)
B(-12,-2,-2,STONE)
B(-12,-2,-1,STONE)
B(-12,-2,0,STONE)
B(-12,-2,1,STONE)
B(-12,-2,2,STONE)
B(-12,-2,3,STONE)
B(-12,-2,4,STONE)
B(-12,-2,5,STONE)
B(-12,-2,6,STONE)
B(-12,-2,7,STONE)
B(-12,-2,8,STONE)
B(-12,-2,9,STONE)
B(-12,-2,10,STONE)
B(-12,-2,11,STONE)
B(-12,-2,12,STONE)
B(-12,-1,-13,STONE)
B(-12,-1,-12,STONE)
B(-12,-1,-11,STONE)
B(-12,-1,-10,STONE)
B(-12,-1,-9,STONE)
B(-12,-1,-8,STONE)
B(-12,-1,-7,STONE)
B(-12,-1,-6,STONE)
B(-12,-1,-5,STONE)
B(-12,-1,-4,STONE)
B(-12,-1,-3,STONE)
B(-12,-1,-2,STONE)
B(-12,-1,-1,STONE)
B(-12,-1,0,STONE)
B(-12,-1,1,STONE)
B(-12,-1,2,STONE)
B(-12,-1,3,STONE)
B(-12,-1,4,STONE)
B(-12,-1,5,STONE)
B(-12,-1,6,STONE)
B(-12,-1,7,STONE)
B(-12,-1,8,STONE)
B(-12,-1,9,STONE)
B(-12,-1,10,STONE)
B(-12,-1,11,STONE)
B(-12,0,-12,STONE)
B(-12,0,-11,STONE)
B(-12,0,-10,STONE)
B(-12,0,-9,STONE)
B(-12,0,-8,STONE)
B(-12,0,-7,STONE)
B(-12,0,-6,STONE)
B(-12,0,-5,STONE)
B(-12,0,-4,STONE)
B(-12,0,-3,STONE)
B(-12,0,-2,STONE)
B(-12,0,-1,STONE)
B(-12,0,0,STONE)
B(-12,0,1,STONE)
B(-12,0,2,STONE)
B(-12,0,3,STONE)
B(-12,0,4,STONE)
B(-12,0,5,STONE)
B(-12,0,6,STONE)
B(-12,0,7,STONE)
B(-12,0,8,STONE)
B(-12,0,9,STONE)
B(-12,0,10,STONE)
B(-12,0,11,STONE)
B(-12,1,-11,STONE)
B(-12,1,-10,STONE)
B(-12,1,-9,STONE)
B(-12,1,-8,STONE)
B(-12,1,-7,STONE)
B(-12,1,-6,STONE)
B(-12,1,-5,STONE)
B(-12,1,-4,STONE)
B(-12,1,-3,STONE)
B(-12,1,-2,STONE)
B(-12,1,-1,STONE)
B(-12,1,0,STONE)
B(-12,1,1,STONE)
B(-12,1,2,STONE)
B(-12,1,3,STONE)
B(-12,1,4,STONE)
B(-12,1,5,STONE)
B(-12,1,6,STONE)
B(-12,1,7,STONE)
B(-12,1,8,STONE)
B(-12,1,9,STONE)
B(-12,1,10,STONE)
B(-12,1,11,STONE)
B(-12,2,-10,STONE)
B(-12,2,-9,STONE)
B(-12,2,-8,STONE)
B(-12,2,-7,STONE)
B(-12,2,-6,STONE)
B(-12,2,-5,STONE)
B(-12,2,-4,STONE)
B(-12,2,-3,STONE)
B(-12,2,-2,STONE)
B(-12,2,-1,STONE)
B(-12,2,0,STONE)
B(-12,2,1,STONE)
B(-12,2,2,STONE)
B(-12,2,3,STONE)
B(-12,2,4,STONE)
B(-12,2,5,STONE)
B(-12,2,6,STONE)
B(-12,2,7,STONE)
B(-12,2,8,STONE)
B(-12,2,9,STONE)
B(-12,2,10,STONE)
B(-12,2,11,STONE)
B(-12,3,-9,STONE)
B(-12,3,-8,STONE)
B(-12,3,-7,STONE)
B(-12,3,-6,STONE)
B(-12,3,-5,STONE)
B(-12,3,-4,STONE)
B(-12,3,-3,STONE)
B(-12,3,-2,STONE)
B(-12,3,-1,STONE)
B(-12,3,0,STONE)
B(-12,3,1,STONE)
B(-12,3,2,STONE)
B(-12,3,3,STONE)
B(-12,3,4,STONE)
B(-12,3,5,STONE)
B(-12,3,6,STONE)
B(-12,3,7,STONE)
B(-12,3,8,STONE)
B(-12,3,9,STONE)
B(-12,4,-9,STONE)
B(-12,4,-8,STONE)
B(-12,4,-7,STONE)
B(-12,4,-6,STONE)
B(-12,4,-5,STONE)
B(-12,4,-4,STONE)
B(-12,4,-3,STONE)
B(-12,4,-2,STONE)
B(-12,4,-1,STONE)
B(-12,4,0,STONE)
B(-12,4,1,STONE)
B(-12,4,2,STONE)
B(-12,4,3,STONE)
B(-12,4,4,STONE)
B(-12,4,5,STONE)
B(-12,4,6,STONE)
B(-12,4,7,STONE)
B(-12,4,8,STONE)
B(-12,5,-8,STONE)
B(-12,5,-7,STONE)
B(-12,5,-6,STONE)
B(-12,5,-5,STONE)
B(-12,5,-4,STONE)
B(-12,5,-3,STONE)
B(-12,5,-2,STONE)
B(-12,5,-1,STONE)
B(-12,5,0,STONE)
B(-12,5,1,STONE)
B(-12,5,2,STONE)
B(-12,5,3,STONE)
B(-12,5,4,STONE)
B(-12,5,5,STONE)
B(-12,5,6,STONE)
B(-12,5,7,STONE)
B(-12,6,-7,STONE)
B(-12,6,-6,STONE)
B(-12,6,-5,STONE)
B(-12,6,-4,STONE)
B(-12,6,-3,STONE)
B(-12,6,-2,STONE)
B(-12,6,-1,STONE)
B(-12,6,0,STONE)
B(-12,6,1,STONE)
B(-12,6,2,STONE)
B(-12,6,3,STONE)
B(-12,6,4,STONE)
B(-12,6,5,STONE)
B(-12,7,-7,STONE)
B(-12,7,-6,STONE)
B(-12,7,-5,STONE)
B(-12,7,-4,STONE)
B(-12,7,-3,STONE)
B(-12,7,-2,STONE)
B(-12,7,-1,STONE)
B(-12,7,0,STONE)
B(-12,7,1,STONE)
B(-12,7,2,STONE)
B(-12,7,3,STONE)
B(-12,8,-6,STONE)
B(-12,8,-5,STONE)
B(-12,8,-4,STONE)
B(-12,8,-3,STONE)
B(-12,8,-2,STONE)
B(-12,8,-1,STONE)
B(-12,8,0,STONE)
B(-12,8,1,STONE)
B(-12,8,2,STONE)
B(-12,9,-5,STONE)
B(-12,9,-4,STONE)
B(-12,9,-3,STONE)
B(-12,9,-2,STONE)
B(-12,9,-1,STONE)
B(-12,9,0,STONE)
B(-12,9,1,STONE)
B(-12,10,-4,STONE)
B(-12,10,-3,STONE)
B(-12,10,-2,STONE)
B(-12,10,-1,STONE)
B(-12,10,0,STONE)
B(-11,-15,-4,STONE)
B(-11,-15,-3,STONE)
B(-11,-15,-2,STONE)
B(-11,-15,-1,STONE)
B(-11,-15,0,STONE)
B(-11,-14,-5,STONE)
B(-11,-14,-4,STONE)
B(-11,-14,-3,STONE)
B(-11,-14,-2,STONE)
B(-11,-14,-1,STONE)
B(-11,-14,0,STONE)
B(-11,-14,1,STONE)
B(-11,-14,2,STONE)
B(-11,-13,-6,STONE)
B(-11,-13,-5,STONE)
B(-11,-13,-4,STONE)
B(-11,-13,-3,STONE)
B(-11,-13,-2,STONE)
B(-11,-13,-1,STONE)
B(-11,-13,0,STONE)
B(-11,-13,1,STONE)
B(-11,-13,2,STONE)
B(-11,-13,3,STONE)
B(-11,-12,-7,STONE)
B(-11,-12,-6,STONE)
B(-11,-12,-5,STONE)
B(-11,-12,-4,STONE)
B(-11,-12,-3,STONE)
B(-11,-12,-2,STONE)
B(-11,-12,-1,STONE)
B(-11,-12,0,STONE)
B(-11,-12,1,STONE)
B(-11,-12,2,STONE)
B(-11,-12,3,STONE)
B(-11,-12,4,STONE)
B(-11,-12,5,STONE)
B(-11,-12,6,STONE)
B(-11,-11,-7,STONE)
B(-11,-11,-6,STONE)
B(-11,-11,-5,STONE)
B(-11,-11,-4,STONE)
B(-11,-11,-3,STONE)
B(-11,-11,-2,STONE)
B(-11,-11,-1,STONE)
B(-11,-11,0,STONE)
B(-11,-11,1,STONE)
B(-11,-11,2,STONE)
B(-11,-11,3,STONE)
B(-11,-11,4,STONE)
B(-11,-11,5,STONE)
B(-11,-11,6,STONE)
B(-11,-11,7,STONE)
B(-11,-10,-8,STONE)
B(-11,-10,-7,STONE)
B(-11,-10,-6,STONE)
B(-11,-10,-5,STONE)
B(-11,-10,-4,STONE)
B(-11,-10,-3,STONE)
B(-11,-10,-2,STONE)
B(-11,-10,-1,STONE)
B(-11,-10,0,STONE)
B(-11,-10,1,STONE)
B(-11,-10,2,STONE)
B(-11,-10,3,STONE)
B(-11,-10,4,STONE)
B(-11,-10,5,STONE)
B(-11,-10,6,STONE)
B(-11,-10,7,STONE)
B(-11,-10,8,STONE)
B(-11,-9,-8,STONE)
B(-11,-9,-7,STONE)
B(-11,-9,-6,STONE)
B(-11,-9,-5,STONE)
B(-11,-9,-4,STONE)
B(-11,-9,-3,STONE)
B(-11,-9,-2,STONE)
B(-11,-9,-1,STONE)
B(-11,-9,0,STONE)
B(-11,-9,1,STONE)
B(-11,-9,2,STONE)
B(-11,-9,3,STONE)
B(-11,-9,4,STONE)
B(-11,-9,5,STONE)
B(-11,-9,6,STONE)
B(-11,-9,7,STONE)
B(-11,-9,8,STONE)
B(-11,-9,9,STONE)
B(-11,-8,-9,STONE)
B(-11,-8,-8,STONE)
B(-11,-8,-7,STONE)
B(-11,-8,-6,STONE)
B(-11,-8,-5,STONE)
B(-11,-8,-4,STONE)
B(-11,-8,-3,STONE)
B(-11,-8,-2,STONE)
B(-11,-8,-1,STONE)
B(-11,-8,0,STONE)
B(-11,-8,1,STONE)
B(-11,-8,2,STONE)
B(-11,-8,3,STONE)
B(-11,-8,4,STONE)
B(-11,-8,5,STONE)
B(-11,-8,6,STONE)
B(-11,-8,7,STONE)
B(-11,-8,8,STONE)
B(-11,-8,9,STONE)
B(-11,-8,10,STONE)
B(-11,-7,-10,STONE)
B(-11,-7,-9,STONE)
B(-11,-7,-8,STONE)
B(-11,-7,-7,STONE)
B(-11,-7,-6,STONE)
B(-11,-7,-5,STONE)
B(-11,-7,-4,STONE)
B(-11,-7,-3,STONE)
B(-11,-7,-2,STONE)
B(-11,-7,-1,STONE)
B(-11,-7,0,STONE)
B(-11,-7,1,STONE)
B(-11,-7,2,STONE)
B(-11,-7,3,STONE)
B(-11,-7,4,STONE)
B(-11,-7,5,STONE)
B(-11,-7,6,STONE)
B(-11,-7,7,STONE)
B(-11,-7,8,STONE)
B(-11,-7,9,STONE)
B(-11,-7,10,STONE)
B(-11,-7,11,STONE)
B(-11,-6,-10,STONE)
B(-11,-6,-9,STONE)
B(-11,-6,-8,STONE)
B(-11,-6,-7,STONE)
B(-11,-6,-6,STONE)
B(-11,-6,-5,STONE)
B(-11,-6,-4,STONE)
B(-11,-6,-3,STONE)
B(-11,-6,-2,STONE)
B(-11,-6,-1,STONE)
B(-11,-6,0,STONE)
B(-11,-6,1,STONE)
B(-11,-6,2,STONE)
B(-11,-6,3,STONE)
B(-11,-6,4,STONE)
B(-11,-6,5,STONE)
B(-11,-6,6,STONE)
B(-11,-6,7,STONE)
B(-11,-6,8,STONE)
B(-11,-6,9,STONE)
B(-11,-6,10,STONE)
B(-11,-6,11,STONE)
B(-11,-5,-11,STONE)
B(-11,-5,-10,STONE)
B(-11,-5,-9,STONE)
B(-11,-5,-8,STONE)
B(-11,-5,-7,STONE)
B(-11,-5,-6,STONE)
B(-11,-5,-5,STONE)
B(-11,-5,-4,STONE)
B(-11,-5,-3,STONE)
B(-11,-5,-2,STONE)
B(-11,-5,-1,STONE)
B(-11,-5,0,STONE)
B(-11,-5,1,STONE)
B(-11,-5,2,STONE)
B(-11,-5,3,STONE)
B(-11,-5,4,STONE)
B(-11,-5,5,STONE)
B(-11,-5,6,STONE)
B(-11,-5,7,STONE)
B(-11,-5,8,STONE)
B(-11,-5,9,STONE)
B(-11,-5,10,STONE)
B(-11,-5,11,STONE)
B(-11,-4,-12,STONE)
B(-11,-4,-11,STONE)
B(-11,-4,-10,STONE)
B(-11,-4,-9,STONE)
B(-11,-4,-8,STONE)
B(-11,-4,-7,STONE)
B(-11,-4,-6,STONE)
B(-11,-4,-5,STONE)
B(-11,-4,-4,STONE)
B(-11,-4,-3,STONE)
B(-11,-4,-2,STONE)
B(-11,-4,-1,STONE)
B(-11,-4,0,STONE)
B(-11,-4,1,STONE)
B(-11,-4,2,STONE)
B(-11,-4,3,STONE)
B(-11,-4,4,STONE)
B(-11,-4,5,STONE)
B(-11,-4,6,STONE)
B(-11,-4,7,STONE)
B(-11,-4,8,STONE)
B(-11,-4,9,STONE)
B(-11,-4,10,STONE)
B(-11,-4,11,STONE)
B(-11,-4,12,STONE)
B(-11,-3,-12,STONE)
B(-11,-3,-11,STONE)
B(-11,-3,-10,STONE)
B(-11,-3,-9,STONE)
B(-11,-3,-8,STONE)
B(-11,-3,-7,STONE)
B(-11,-3,-6,STONE)
B(-11,-3,-5,STONE)
B(-11,-3,-4,STONE)
B(-11,-3,-3,STONE)
B(-11,-3,-2,STONE)
B(-11,-3,-1,STONE)
B(-11,-3,0,STONE)
B(-11,-3,1,STONE)
B(-11,-3,2,STONE)
B(-11,-3,3,STONE)
B(-11,-3,4,STONE)
B(-11,-3,5,STONE)
B(-11,-3,6,STONE)
B(-11,-3,7,STONE)
B(-11,-3,8,STONE)
B(-11,-3,9,STONE)
B(-11,-3,10,STONE)
B(-11,-3,11,STONE)
B(-11,-3,12,STONE)
B(-11,-2,-12,STONE)
B(-11,-2,-11,STONE)
B(-11,-2,-10,STONE)
B(-11,-2,-9,STONE)
B(-11,-2,-8,STONE)
B(-11,-2,-7,STONE)
B(-11,-2,-6,STONE)
B(-11,-2,-5,STONE)
B(-11,-2,-4,STONE)
B(-11,-2,-3,STONE)
B(-11,-2,-2,STONE)
B(-11,-2,-1,STONE)
B(-11,-2,0,STONE)
B(-11,-2,1,STONE)
B(-11,-2,2,STONE)
B(-11,-2,3,STONE)
B(-11,-2,4,STONE)
B(-11,-2,5,STONE)
B(-11,-2,6,STONE)
B(-11,-2,7,STONE)
B(-11,-2,8,STONE)
B(-11,-2,9,STONE)
B(-11,-2,10,STONE)
B(-11,-2,11,STONE)
B(-11,-2,12,STONE)
B(-11,-1,-12,STONE)
B(-11,-1,-11,STONE)
B(-11,-1,-10,STONE)
B(-11,-1,-9,STONE)
B(-11,-1,-8,STONE)
B(-11,-1,-7,STONE)
B(-11,-1,-6,STONE)
B(-11,-1,-5,STONE)
B(-11,-1,-4,STONE)
B(-11,-1,-3,STONE)
B(-11,-1,-2,STONE)
B(-11,-1,-1,STONE)
B(-11,-1,0,STONE)
B(-11,-1,1,STONE)
B(-11,-1,2,STONE)
B(-11,-1,3,STONE)
B(-11,-1,4,STONE)
B(-11,-1,5,STONE)
B(-11,-1,6,STONE)
B(-11,-1,7,STONE)
B(-11,-1,8,STONE)
B(-11,-1,9,STONE)
B(-11,-1,10,STONE)
B(-11,-1,11,STONE)
B(-11,-1,12,STONE)
B(-11,0,-11,STONE)
B(-11,0,-10,STONE)
B(-11,0,-9,STONE)
B(-11,0,-8,STONE)
B(-11,0,-7,STONE)
B(-11,0,-6,STONE)
B(-11,0,-5,STONE)
B(-11,0,-4,STONE)
B(-11,0,-3,STONE)
B(-11,0,-2,STONE)
B(-11,0,-1,STONE)
B(-11,0,0,STONE)
B(-11,0,1,STONE)
B(-11,0,2,STONE)
B(-11,0,3,STONE)
B(-11,0,4,STONE)
B(-11,0,5,STONE)
B(-11,0,6,STONE)
B(-11,0,7,STONE)
B(-11,0,8,STONE)
B(-11,0,9,STONE)
B(-11,0,10,STONE)
B(-11,0,11,STONE)
B(-11,1,-10,STONE)
B(-11,1,-9,STONE)
B(-11,1,-8,STONE)
B(-11,1,-7,STONE)
B(-11,1,-6,STONE)
B(-11,1,-5,STONE)
B(-11,1,-4,STONE)
B(-11,1,-3,STONE)
B(-11,1,-2,STONE)
B(-11,1,-1,STONE)
B(-11,1,0,STONE)
B(-11,1,1,STONE)
B(-11,1,2,STONE)
B(-11,1,3,STONE)
B(-11,1,4,STONE)
B(-11,1,5,STONE)
B(-11,1,6,STONE)
B(-11,1,7,STONE)
B(-11,1,8,STONE)
B(-11,1,9,STONE)
B(-11,1,10,STONE)
B(-11,1,11,STONE)
B(-11,2,-10,STONE)
B(-11,2,-9,STONE)
B(-11,2,-8,STONE)
B(-11,2,-7,STONE)
B(-11,2,-6,STONE)
B(-11,2,-5,STONE)
B(-11,2,-4,STONE)
B(-11,2,-3,STONE)
B(-11,2,-2,STONE)
B(-11,2,-1,STONE)
B(-11,2,0,STONE)
B(-11,2,1,STONE)
B(-11,2,2,STONE)
B(-11,2,3,STONE)
B(-11,2,4,STONE)
B(-11,2,5,STONE)
B(-11,2,6,STONE)
B(-11,2,7,STONE)
B(-11,2,8,STONE)
B(-11,2,9,STONE)
B(-11,2,10,STONE)
B(-11,2,11,STONE)
B(-11,3,-9,STONE)
B(-11,3,-8,STONE)
B(-11,3,-7,STONE)
B(-11,3,-6,STONE)
B(-11,3,-5,STONE)
B(-11,3,-4,STONE)
B(-11,3,-3,STONE)
B(-11,3,-2,STONE)
B(-11,3,-1,STONE)
B(-11,3,0,STONE)
B(-11,3,1,STONE)
B(-11,3,2,STONE)
B(-11,3,3,STONE)
B(-11,3,4,STONE)
B(-11,3,5,STONE)
B(-11,3,6,STONE)
B(-11,3,7,STONE)
B(-11,3,8,STONE)
B(-11,3,9,STONE)
B(-11,3,10,STONE)
B(-11,4,-8,STONE)
B(-11,4,-7,STONE)
B(-11,4,-6,STONE)
B(-11,4,-5,STONE)
B(-11,4,-4,STONE)
B(-11,4,-3,STONE)
B(-11,4,-2,STONE)
B(-11,4,-1,STONE)
B(-11,4,0,STONE)
B(-11,4,1,STONE)
B(-11,4,2,STONE)
B(-11,4,3,STONE)
B(-11,4,4,STONE)
B(-11,4,5,STONE)
B(-11,4,6,STONE)
B(-11,4,7,STONE)
B(-11,4,8,STONE)
B(-11,4,9,STONE)
B(-11,5,-8,STONE)
B(-11,5,-7,STONE)
B(-11,5,-6,STONE)
B(-11,5,-5,STONE)
B(-11,5,-4,STONE)
B(-11,5,-3,STONE)
B(-11,5,-2,STONE)
B(-11,5,-1,STONE)
B(-11,5,0,STONE)
B(-11,5,1,STONE)
B(-11,5,2,STONE)
B(-11,5,3,STONE)
B(-11,5,4,STONE)
B(-11,5,5,STONE)
B(-11,5,6,STONE)
B(-11,5,7,STONE)
B(-11,5,8,STONE)
B(-11,6,-7,STONE)
B(-11,6,-6,STONE)
B(-11,6,-5,STONE)
B(-11,6,-4,STONE)
B(-11,6,-3,STONE)
B(-11,6,-2,STONE)
B(-11,6,-1,STONE)
B(-11,6,0,STONE)
B(-11,6,1,STONE)
B(-11,6,2,STONE)
B(-11,6,3,STONE)
B(-11,6,4,STONE)
B(-11,6,5,STONE)
B(-11,6,6,STONE)
B(-11,6,7,STONE)
B(-11,7,-7,STONE)
B(-11,7,-6,STONE)
B(-11,7,-5,STONE)
B(-11,7,-4,STONE)
B(-11,7,-3,STONE)
B(-11,7,-2,STONE)
B(-11,7,-1,STONE)
B(-11,7,0,STONE)
B(-11,7,1,STONE)
B(-11,7,2,STONE)
B(-11,7,3,STONE)
B(-11,7,4,STONE)
B(-11,7,5,STONE)
B(-11,7,6,STONE)
B(-11,8,-6,STONE)
B(-11,8,-5,STONE)
B(-11,8,-4,STONE)
B(-11,8,-3,STONE)
B(-11,8,-2,STONE)
B(-11,8,-1,STONE)
B(-11,8,0,STONE)
B(-11,8,1,STONE)
B(-11,8,2,STONE)
B(-11,8,3,STONE)
B(-11,9,-5,STONE)
B(-11,9,-4,STONE)
B(-11,9,-3,STONE)
B(-11,9,-2,STONE)
B(-11,9,-1,STONE)
B(-11,9,0,STONE)
B(-11,9,1,STONE)
B(-11,9,2,STONE)
B(-11,10,-4,STONE)
B(-11,10,-3,STONE)
B(-11,10,-2,STONE)
B(-11,10,-1,STONE)
B(-11,10,0,STONE)
B(-10,-15,-4,STONE)
B(-10,-15,-3,STONE)
B(-10,-15,-2,STONE)
B(-10,-15,-1,STONE)
B(-10,-15,0,STONE)
B(-10,-15,1,STONE)
B(-10,-15,2,STONE)
B(-10,-14,-5,STONE)
B(-10,-14,-4,STONE)
B(-10,-14,-3,STONE)
B(-10,-14,-2,STONE)
B(-10,-14,-1,STONE)
B(-10,-14,0,STONE)
B(-10,-14,1,STONE)
B(-10,-14,2,STONE)
B(-10,-14,3,STONE)
B(-10,-14,4,STONE)
B(-10,-13,-6,STONE)
B(-10,-13,-5,STONE)
B(-10,-13,-4,STONE)
B(-10,-13,-3,STONE)
B(-10,-13,-2,STONE)
B(-10,-13,-1,STONE)
B(-10,-13,0,STONE)
B(-10,-13,1,STONE)
B(-10,-13,2,STONE)
B(-10,-13,3,STONE)
B(-10,-13,4,STONE)
B(-10,-13,5,STONE)
B(-10,-13,6,STONE)
B(-10,-12,-7,STONE)
B(-10,-12,-6,STONE)
B(-10,-12,-5,STONE)
B(-10,-12,-4,STONE)
B(-10,-12,-3,STONE)
B(-10,-12,-2,STONE)
B(-10,-12,-1,STONE)
B(-10,-12,0,STONE)
B(-10,-12,1,STONE)
B(-10,-12,2,STONE)
B(-10,-12,3,STONE)
B(-10,-12,4,STONE)
B(-10,-12,5,STONE)
B(-10,-12,6,STONE)
B(-10,-12,7,STONE)
B(-10,-11,-7,STONE)
B(-10,-11,-6,STONE)
B(-10,-11,-5,STONE)
B(-10,-11,-4,STONE)
B(-10,-11,-3,STONE)
B(-10,-11,-2,STONE)
B(-10,-11,-1,STONE)
B(-10,-11,0,STONE)
B(-10,-11,1,STONE)
B(-10,-11,2,STONE)
B(-10,-11,3,STONE)
B(-10,-11,4,STONE)
B(-10,-11,5,STONE)
B(-10,-11,6,STONE)
B(-10,-11,7,STONE)
B(-10,-11,8,STONE)
B(-10,-10,-8,STONE)
B(-10,-10,-7,STONE)
B(-10,-10,-6,STONE)
B(-10,-10,-5,STONE)
B(-10,-10,-4,STONE)
B(-10,-10,-3,STONE)
B(-10,-10,-2,STONE)
B(-10,-10,-1,STONE)
B(-10,-10,0,STONE)
B(-10,-10,1,STONE)
B(-10,-10,2,STONE)
B(-10,-10,3,STONE)
B(-10,-10,4,STONE)
B(-10,-10,5,STONE)
B(-10,-10,6,STONE)
B(-10,-10,7,STONE)
B(-10,-10,8,STONE)
B(-10,-9,-8,STONE)
B(-10,-9,-7,STONE)
B(-10,-9,-6,STONE)
B(-10,-9,-5,STONE)
B(-10,-9,-4,STONE)
B(-10,-9,-3,STONE)
B(-10,-9,-2,STONE)
B(-10,-9,-1,STONE)
B(-10,-9,0,STONE)
B(-10,-9,1,STONE)
B(-10,-9,2,STONE)
B(-10,-9,3,STONE)
B(-10,-9,4,STONE)
B(-10,-9,5,STONE)
B(-10,-9,6,STONE)
B(-10,-9,7,STONE)
B(-10,-9,8,STONE)
B(-10,-9,9,STONE)
B(-10,-8,-9,STONE)
B(-10,-8,-8,STONE)
B(-10,-8,-7,STONE)
B(-10,-8,-6,STONE)
B(-10,-8,-5,STONE)
B(-10,-8,-4,STONE)
B(-10,-8,-3,STONE)
B(-10,-8,-2,STONE)
B(-10,-8,-1,STONE)
B(-10,-8,0,STONE)
B(-10,-8,1,STONE)
B(-10,-8,2,STONE)
B(-10,-8,3,STONE)
B(-10,-8,4,STONE)
B(-10,-8,5,STONE)
B(-10,-8,6,STONE)
B(-10,-8,7,STONE)
B(-10,-8,8,STONE)
B(-10,-8,9,STONE)
B(-10,-8,10,STONE)
B(-10,-8,11,STONE)
B(-10,-7,-9,STONE)
B(-10,-7,-8,STONE)
B(-10,-7,-7,STONE)
B(-10,-7,-6,STONE)
B(-10,-7,-5,STONE)
B(-10,-7,-4,STONE)
B(-10,-7,-3,STONE)
B(-10,-7,-2,STONE)
B(-10,-7,-1,STONE)
B(-10,-7,0,STONE)
B(-10,-7,1,STONE)
B(-10,-7,2,STONE)
B(-10,-7,3,STONE)
B(-10,-7,4,STONE)
B(-10,-7,5,STONE)
B(-10,-7,6,STONE)
B(-10,-7,7,STONE)
B(-10,-7,8,STONE)
B(-10,-7,9,STONE)
B(-10,-7,10,STONE)
B(-10,-7,11,STONE)
B(-10,-6,-10,STONE)
B(-10,-6,-9,STONE)
B(-10,-6,-8,STONE)
B(-10,-6,-7,STONE)
B(-10,-6,-6,STONE)
B(-10,-6,-5,STONE)
B(-10,-6,-4,STONE)
B(-10,-6,-3,STONE)
B(-10,-6,-2,STONE)
B(-10,-6,-1,STONE)
B(-10,-6,0,STONE)
B(-10,-6,1,STONE)
B(-10,-6,2,STONE)
B(-10,-6,3,STONE)
B(-10,-6,4,STONE)
B(-10,-6,5,STONE)
B(-10,-6,6,STONE)
B(-10,-6,7,STONE)
B(-10,-6,8,STONE)
B(-10,-6,9,STONE)
B(-10,-6,10,STONE)
B(-10,-6,11,STONE)
B(-10,-5,-11,STONE)
B(-10,-5,-10,STONE)
B(-10,-5,-9,STONE)
B(-10,-5,-8,STONE)
B(-10,-5,-7,STONE)
B(-10,-5,-6,STONE)
B(-10,-5,-5,STONE)
B(-10,-5,-4,STONE)
B(-10,-5,-3,STONE)
B(-10,-5,-2,STONE)
B(-10,-5,-1,STONE)
B(-10,-5,0,STONE)
B(-10,-5,1,STONE)
B(-10,-5,2,STONE)
B(-10,-5,3,STONE)
B(-10,-5,4,STONE)
B(-10,-5,5,STONE)
B(-10,-5,6,STONE)
B(-10,-5,7,STONE)
B(-10,-5,8,STONE)
B(-10,-5,9,STONE)
B(-10,-5,10,STONE)
B(-10,-5,11,STONE)
B(-10,-5,12,STONE)
B(-10,-4,-12,STONE)
B(-10,-4,-11,STONE)
B(-10,-4,-10,STONE)
B(-10,-4,-9,STONE)
B(-10,-4,-8,STONE)
B(-10,-4,-7,STONE)
B(-10,-4,-6,STONE)
B(-10,-4,-5,STONE)
B(-10,-4,-4,STONE)
B(-10,-4,-3,STONE)
B(-10,-4,-2,STONE)
B(-10,-4,-1,STONE)
B(-10,-4,0,STONE)
B(-10,-4,1,STONE)
B(-10,-4,2,STONE)
B(-10,-4,3,STONE)
B(-10,-4,4,STONE)
B(-10,-4,5,STONE)
B(-10,-4,6,STONE)
B(-10,-4,7,STONE)
B(-10,-4,8,STONE)
B(-10,-4,9,STONE)
B(-10,-4,10,STONE)
B(-10,-4,11,STONE)
B(-10,-4,12,STONE)
B(-10,-3,-12,STONE)
B(-10,-3,-11,STONE)
B(-10,-3,-10,STONE)
B(-10,-3,-9,STONE)
B(-10,-3,-8,STONE)
B(-10,-3,-7,STONE)
B(-10,-3,-6,STONE)
B(-10,-3,-5,STONE)
B(-10,-3,-4,STONE)
B(-10,-3,-3,STONE)
B(-10,-3,-2,STONE)
B(-10,-3,-1,STONE)
B(-10,-3,0,STONE)
B(-10,-3,1,STONE)
B(-10,-3,2,STONE)
B(-10,-3,3,STONE)
B(-10,-3,4,STONE)
B(-10,-3,5,STONE)
B(-10,-3,6,STONE)
B(-10,-3,7,STONE)
B(-10,-3,8,STONE)
B(-10,-3,9,STONE)
B(-10,-3,10,STONE)
B(-10,-3,11,STONE)
B(-10,-3,12,STONE)
B(-10,-2,-12,STONE)
B(-10,-2,-11,STONE)
B(-10,-2,-10,STONE)
B(-10,-2,-9,STONE)
B(-10,-2,-8,STONE)
B(-10,-2,-7,STONE)
B(-10,-2,-6,STONE)
B(-10,-2,-5,STONE)
B(-10,-2,-4,STONE)
B(-10,-2,-3,STONE)
B(-10,-2,-2,STONE)
B(-10,-2,-1,STONE)
B(-10,-2,0,STONE)
B(-10,-2,1,STONE)
B(-10,-2,2,STONE)
B(-10,-2,3,STONE)
B(-10,-2,4,STONE)
B(-10,-2,5,STONE)
B(-10,-2,6,STONE)
B(-10,-2,7,STONE)
B(-10,-2,8,STONE)
B(-10,-2,9,STONE)
B(-10,-2,10,STONE)
B(-10,-2,11,STONE)
B(-10,-2,12,STONE)
B(-10,-1,-12,STONE)
B(-10,-1,-11,STONE)
B(-10,-1,-10,STONE)
B(-10,-1,-9,STONE)
B(-10,-1,-8,STONE)
B(-10,-1,-7,STONE)
B(-10,-1,-6,STONE)
B(-10,-1,-5,STONE)
B(-10,-1,-4,STONE)
B(-10,-1,-3,STONE)
B(-10,-1,-2,STONE)
B(-10,-1,-1,STONE)
B(-10,-1,0,STONE)
B(-10,-1,1,STONE)
B(-10,-1,2,STONE)
B(-10,-1,3,STONE)
B(-10,-1,4,STONE)
B(-10,-1,5,STONE)
B(-10,-1,6,STONE)
B(-10,-1,7,STONE)
B(-10,-1,8,STONE)
B(-10,-1,9,STONE)
B(-10,-1,10,STONE)
B(-10,-1,11,STONE)
B(-10,-1,12,STONE)
B(-10,0,-11,STONE)
B(-10,0,-10,STONE)
B(-10,0,-9,STONE)
B(-10,0,-8,STONE)
B(-10,0,-7,STONE)
B(-10,0,-6,STONE)
B(-10,0,-5,STONE)
B(-10,0,-4,STONE)
B(-10,0,-3,STONE)
B(-10,0,-2,STONE)
B(-10,0,-1,STONE)
B(-10,0,0,STONE)
B(-10,0,1,STONE)
B(-10,0,2,STONE)
B(-10,0,3,STONE)
B(-10,0,4,STONE)
B(-10,0,5,STONE)
B(-10,0,6,STONE)
B(-10,0,7,STONE)
B(-10,0,8,STONE)
B(-10,0,9,STONE)
B(-10,0,10,STONE)
B(-10,0,11,STONE)
B(-10,0,12,STONE)
B(-10,1,-10,STONE)
B(-10,1,-9,STONE)
B(-10,1,-8,STONE)
B(-10,1,-7,STONE)
B(-10,1,-6,STONE)
B(-10,1,-5,STONE)
B(-10,1,-4,STONE)
B(-10,1,-3,STONE)
B(-10,1,-2,STONE)
B(-10,1,-1,STONE)
B(-10,1,0,STONE)
B(-10,1,1,STONE)
B(-10,1,2,STONE)
B(-10,1,3,STONE)
B(-10,1,4,STONE)
B(-10,1,5,STONE)
B(-10,1,6,STONE)
B(-10,1,7,STONE)
B(-10,1,8,STONE)
B(-10,1,9,STONE)
B(-10,1,10,STONE)
B(-10,1,11,STONE)
B(-10,2,-9,STONE)
B(-10,2,-8,STONE)
B(-10,2,-7,STONE)
B(-10,2,-6,STONE)
B(-10,2,-5,STONE)
B(-10,2,-4,STONE)
B(-10,2,-3,STONE)
B(-10,2,-2,STONE)
B(-10,2,-1,STONE)
B(-10,2,0,STONE)
B(-10,2,1,STONE)
B(-10,2,2,STONE)
B(-10,2,3,STONE)
B(-10,2,4,STONE)
B(-10,2,5,STONE)
B(-10,2,6,STONE)
B(-10,2,7,STONE)
B(-10,2,8,STONE)
B(-10,2,9,STONE)
B(-10,2,10,STONE)
B(-10,2,11,STONE)
B(-10,3,-9,STONE)
B(-10,3,-8,STONE)
B(-10,3,-7,STONE)
B(-10,3,-6,STONE)
B(-10,3,-5,STONE)
B(-10,3,-4,STONE)
B(-10,3,-3,STONE)
B(-10,3,-2,STONE)
B(-10,3,-1,STONE)
B(-10,3,0,STONE)
B(-10,3,1,STONE)
B(-10,3,2,STONE)
B(-10,3,3,STONE)
B(-10,3,4,STONE)
B(-10,3,5,STONE)
B(-10,3,6,STONE)
B(-10,3,7,STONE)
B(-10,3,8,STONE)
B(-10,3,9,STONE)
B(-10,3,10,STONE)
B(-10,3,11,STONE)
B(-10,4,-8,STONE)
B(-10,4,-7,STONE)
B(-10,4,-6,STONE)
B(-10,4,-5,STONE)
B(-10,4,-4,STONE)
B(-10,4,-3,STONE)
B(-10,4,-2,STONE)
B(-10,4,-1,STONE)
B(-10,4,0,STONE)
B(-10,4,1,STONE)
B(-10,4,2,STONE)
B(-10,4,3,STONE)
B(-10,4,4,STONE)
B(-10,4,5,STONE)
B(-10,4,6,STONE)
B(-10,4,7,STONE)
B(-10,4,8,STONE)
B(-10,4,9,STONE)
B(-10,5,-8,STONE)
B(-10,5,-7,STONE)
B(-10,5,-6,STONE)
B(-10,5,-5,STONE)
B(-10,5,-4,STONE)
B(-10,5,-3,STONE)
B(-10,5,-2,STONE)
B(-10,5,-1,STONE)
B(-10,5,0,STONE)
B(-10,5,1,STONE)
B(-10,5,2,STONE)
B(-10,5,3,STONE)
B(-10,5,4,STONE)
B(-10,5,5,STONE)
B(-10,5,6,STONE)
B(-10,5,7,STONE)
B(-10,5,8,STONE)
B(-10,6,-7,STONE)
B(-10,6,-6,STONE)
B(-10,6,-5,STONE)
B(-10,6,-4,STONE)
B(-10,6,-3,STONE)
B(-10,6,-2,STONE)
B(-10,6,-1,STONE)
B(-10,6,0,STONE)
B(-10,6,1,STONE)
B(-10,6,2,STONE)
B(-10,6,3,STONE)
B(-10,6,4,STONE)
B(-10,6,5,STONE)
B(-10,6,6,STONE)
B(-10,6,7,STONE)
B(-10,6,8,STONE)
B(-10,7,-7,STONE)
B(-10,7,-6,STONE)
B(-10,7,-5,STONE)
B(-10,7,-4,STONE)
B(-10,7,-3,STONE)
B(-10,7,-2,STONE)
B(-10,7,-1,STONE)
B(-10,7,0,STONE)
B(-10,7,1,STONE)
B(-10,7,2,STONE)
B(-10,7,3,STONE)
B(-10,7,4,STONE)
B(-10,7,5,STONE)
B(-10,7,6,STONE)
B(-10,7,7,STONE)
B(-10,8,-6,STONE)
B(-10,8,-5,STONE)
B(-10,8,-4,STONE)
B(-10,8,-3,STONE)
B(-10,8,-2,STONE)
B(-10,8,-1,STONE)
B(-10,8,0,STONE)
B(-10,8,1,STONE)
B(-10,8,2,STONE)
B(-10,8,3,STONE)
B(-10,8,4,STONE)
B(-10,8,5,STONE)
B(-10,8,6,STONE)
B(-10,9,-5,STONE)
B(-10,9,-4,STONE)
B(-10,9,-3,STONE)
B(-10,9,-2,STONE)
B(-10,9,-1,STONE)
B(-10,9,0,STONE)
B(-10,9,1,STONE)
B(-10,9,2,STONE)
B(-10,9,3,STONE)
B(-10,9,4,STONE)
B(-10,10,-4,STONE)
B(-10,10,-3,STONE)
B(-10,10,-2,STONE)
B(-10,10,-1,STONE)
B(-10,10,0,STONE)
B(-10,10,1,STONE)
B(-10,10,2,STONE)
B(-9,-15,-4,STONE)
B(-9,-15,-3,STONE)
B(-9,-15,2,STONE)
B(-9,-14,-5,STONE)
B(-9,-14,-4,STONE)
B(-9,-14,-3,STONE)
B(-9,-14,-2,STONE)
B(-9,-14,-1,STONE)
B(-9,-14,0,STONE)
B(-9,-14,1,STONE)
B(-9,-14,2,STONE)
B(-9,-14,3,STONE)
B(-9,-14,4,STONE)
B(-9,-14,5,STONE)
B(-9,-13,-6,STONE)
B(-9,-13,-5,STONE)
B(-9,-13,-4,STONE)
B(-9,-13,-3,STONE)
B(-9,-13,-2,STONE)
B(-9,-13,-1,STONE)
B(-9,-13,0,STONE)
B(-9,-13,1,STONE)
B(-9,-13,2,STONE)
B(-9,-13,3,STONE)
B(-9,-13,4,STONE)
B(-9,-13,5,STONE)
B(-9,-13,6,STONE)
B(-9,-12,-7,STONE)
B(-9,-12,-6,STONE)
B(-9,-12,-5,STONE)
B(-9,-12,-4,STONE)
B(-9,-12,-3,STONE)
B(-9,-12,-2,STONE)
B(-9,-12,-1,STONE)
B(-9,-12,0,STONE)
B(-9,-12,1,STONE)
B(-9,-12,2,STONE)
B(-9,-12,3,STONE)
B(-9,-12,4,STONE)
B(-9,-12,5,STONE)
B(-9,-12,6,STONE)
B(-9,-12,7,STONE)
B(-9,-11,-7,STONE)
B(-9,-11,-6,STONE)
B(-9,-11,-5,STONE)
B(-9,-11,-4,STONE)
B(-9,-11,-3,STONE)
B(-9,-11,-2,STONE)
B(-9,-11,-1,STONE)
B(-9,-11,0,STONE)
B(-9,-11,1,STONE)
B(-9,-11,2,STONE)
B(-9,-11,3,STONE)
B(-9,-11,4,STONE)
B(-9,-11,5,STONE)
B(-9,-11,6,STONE)
B(-9,-11,7,STONE)
B(-9,-11,8,STONE)
B(-9,-10,-8,STONE)
B(-9,-10,-7,STONE)
B(-9,-10,-6,STONE)
B(-9,-10,-5,STONE)
B(-9,-10,-4,STONE)
B(-9,-10,-3,STONE)
B(-9,-10,-2,STONE)
B(-9,-10,-1,STONE)
B(-9,-10,0,STONE)
B(-9,-10,1,STONE)
B(-9,-10,2,STONE)
B(-9,-10,3,STONE)
B(-9,-10,4,STONE)
B(-9,-10,5,STONE)
B(-9,-10,6,STONE)
B(-9,-10,7,STONE)
B(-9,-10,8,STONE)
B(-9,-10,9,STONE)
B(-9,-9,-8,STONE)
B(-9,-9,-7,STONE)
B(-9,-9,-6,STONE)
B(-9,-9,-5,STONE)
B(-9,-9,-4,STONE)
B(-9,-9,-3,STONE)
B(-9,-9,-2,STONE)
B(-9,-9,-1,STONE)
B(-9,-9,0,STONE)
B(-9,-9,1,STONE)
B(-9,-9,2,STONE)
B(-9,-9,3,STONE)
B(-9,-9,4,STONE)
B(-9,-9,5,STONE)
B(-9,-9,6,STONE)
B(-9,-9,7,STONE)
B(-9,-9,8,STONE)
B(-9,-9,9,STONE)
B(-9,-9,10,STONE)
B(-9,-8,-9,STONE)
B(-9,-8,-8,STONE)
B(-9,-8,-7,STONE)
B(-9,-8,-6,STONE)
B(-9,-8,-5,STONE)
B(-9,-8,-4,STONE)
B(-9,-8,-3,STONE)
B(-9,-8,-2,STONE)
B(-9,-8,-1,STONE)
B(-9,-8,0,STONE)
B(-9,-8,1,STONE)
B(-9,-8,2,STONE)
B(-9,-8,3,STONE)
B(-9,-8,4,STONE)
B(-9,-8,5,STONE)
B(-9,-8,6,STONE)
B(-9,-8,7,STONE)
B(-9,-8,8,STONE)
B(-9,-8,9,STONE)
B(-9,-8,10,STONE)
B(-9,-8,11,STONE)
B(-9,-7,-9,STONE)
B(-9,-7,-8,STONE)
B(-9,-7,-7,STONE)
B(-9,-7,-6,STONE)
B(-9,-7,-5,STONE)
B(-9,-7,-4,STONE)
B(-9,-7,-3,STONE)
B(-9,-7,-2,STONE)
B(-9,-7,-1,STONE)
B(-9,-7,0,STONE)
B(-9,-7,1,STONE)
B(-9,-7,2,STONE)
B(-9,-7,3,STONE)
B(-9,-7,4,STONE)
B(-9,-7,5,STONE)
B(-9,-7,6,STONE)
B(-9,-7,7,STONE)
B(-9,-7,8,STONE)
B(-9,-7,9,STONE)
B(-9,-7,10,STONE)
B(-9,-7,11,STONE)
B(-9,-6,-10,STONE)
B(-9,-6,-9,STONE)
B(-9,-6,-8,STONE)
B(-9,-6,-7,STONE)
B(-9,-6,-6,STONE)
B(-9,-6,-5,STONE)
B(-9,-6,-4,STONE)
B(-9,-6,-3,STONE)
B(-9,-6,-2,STONE)
B(-9,-6,-1,STONE)
B(-9,-6,0,STONE)
B(-9,-6,1,STONE)
B(-9,-6,2,STONE)
B(-9,-6,3,STONE)
B(-9,-6,4,STONE)
B(-9,-6,5,STONE)
B(-9,-6,6,STONE)
B(-9,-6,7,STONE)
B(-9,-6,8,STONE)
B(-9,-6,9,STONE)
B(-9,-6,10,STONE)
B(-9,-6,11,STONE)
B(-9,-5,-10,STONE)
B(-9,-5,-9,STONE)
B(-9,-5,-8,STONE)
B(-9,-5,-7,STONE)
B(-9,-5,-6,STONE)
B(-9,-5,-5,STONE)
B(-9,-5,-4,STONE)
B(-9,-5,-3,STONE)
B(-9,-5,-2,STONE)
B(-9,-5,-1,STONE)
B(-9,-5,0,STONE)
B(-9,-5,1,STONE)
B(-9,-5,2,STONE)
B(-9,-5,3,STONE)
B(-9,-5,4,STONE)
B(-9,-5,5,STONE)
B(-9,-5,6,STONE)
B(-9,-5,7,STONE)
B(-9,-5,8,STONE)
B(-9,-5,9,STONE)
B(-9,-5,10,STONE)
B(-9,-5,11,STONE)
B(-9,-5,12,STONE)
B(-9,-4,-11,STONE)
B(-9,-4,-10,STONE)
B(-9,-4,-9,STONE)
B(-9,-4,-8,STONE)
B(-9,-4,-7,STONE)
B(-9,-4,-6,STONE)
B(-9,-4,-5,STONE)
B(-9,-4,-4,STONE)
B(-9,-4,-3,STONE)
B(-9,-4,-2,STONE)
B(-9,-4,-1,STONE)
B(-9,-4,0,STONE)
B(-9,-4,1,STONE)
B(-9,-4,2,STONE)
B(-9,-4,3,STONE)
B(-9,-4,4,STONE)
B(-9,-4,5,STONE)
B(-9,-4,6,STONE)
B(-9,-4,7,STONE)
B(-9,-4,8,STONE)
B(-9,-4,9,STONE)
B(-9,-4,10,STONE)
B(-9,-4,11,STONE)
B(-9,-4,12,STONE)
B(-9,-3,-11,STONE)
B(-9,-3,-10,STONE)
B(-9,-3,-9,STONE)
B(-9,-3,-8,STONE)
B(-9,-3,-7,STONE)
B(-9,-3,-6,STONE)
B(-9,-3,-5,STONE)
B(-9,-3,-4,STONE)
B(-9,-3,-3,STONE)
B(-9,-3,-2,STONE)
B(-9,-3,-1,STONE)
B(-9,-3,0,STONE)
B(-9,-3,1,STONE)
B(-9,-3,2,STONE)
B(-9,-3,3,STONE)
B(-9,-3,4,STONE)
B(-9,-3,5,STONE)
B(-9,-3,6,STONE)
B(-9,-3,7,STONE)
B(-9,-3,8,STONE)
B(-9,-3,9,STONE)
B(-9,-3,10,STONE)
B(-9,-3,11,STONE)
B(-9,-3,12,STONE)
B(-9,-3,13,STONE)
B(-9,-2,-11,STONE)
B(-9,-2,-10,STONE)
B(-9,-2,-9,STONE)
B(-9,-2,-8,STONE)
B(-9,-2,-7,STONE)
B(-9,-2,-6,STONE)
B(-9,-2,-5,STONE)
B(-9,-2,-4,STONE)
B(-9,-2,-3,STONE)
B(-9,-2,-2,STONE)
B(-9,-2,-1,STONE)
B(-9,-2,0,STONE)
B(-9,-2,1,STONE)
B(-9,-2,2,STONE)
B(-9,-2,3,STONE)
B(-9,-2,4,STONE)
B(-9,-2,5,STONE)
B(-9,-2,6,STONE)
B(-9,-2,7,STONE)
B(-9,-2,8,STONE)
B(-9,-2,9,STONE)
B(-9,-2,10,STONE)
B(-9,-2,11,STONE)
B(-9,-2,12,STONE)
B(-9,-2,13,STONE)
B(-9,-1,-11,STONE)
B(-9,-1,-10,STONE)
B(-9,-1,-9,STONE)
B(-9,-1,-8,STONE)
B(-9,-1,-7,STONE)
B(-9,-1,-6,STONE)
B(-9,-1,-5,STONE)
B(-9,-1,-4,STONE)
B(-9,-1,-3,STONE)
B(-9,-1,-2,STONE)
B(-9,-1,-1,STONE)
B(-9,-1,0,STONE)
B(-9,-1,1,STONE)
B(-9,-1,2,STONE)
B(-9,-1,3,STONE)
B(-9,-1,4,STONE)
B(-9,-1,5,STONE)
B(-9,-1,6,STONE)
B(-9,-1,7,STONE)
B(-9,-1,8,STONE)
B(-9,-1,9,STONE)
B(-9,-1,10,STONE)
B(-9,-1,11,STONE)
B(-9,-1,12,STONE)
B(-9,0,-10,STONE)
B(-9,0,-9,STONE)
B(-9,0,-8,STONE)
B(-9,0,-7,STONE)
B(-9,0,-6,STONE)
B(-9,0,-5,STONE)
B(-9,0,-4,STONE)
B(-9,0,-3,STONE)
B(-9,0,-2,STONE)
B(-9,0,-1,STONE)
B(-9,0,0,STONE)
B(-9,0,1,STONE)
B(-9,0,2,STONE)
B(-9,0,3,STONE)
B(-9,0,4,STONE)
B(-9,0,5,STONE)
B(-9,0,6,STONE)
B(-9,0,7,STONE)
B(-9,0,8,STONE)
B(-9,0,9,STONE)
B(-9,0,10,STONE)
B(-9,0,11,STONE)
B(-9,0,12,STONE)
B(-9,1,-10,STONE)
B(-9,1,-9,STONE)
B(-9,1,-8,STONE)
B(-9,1,-7,STONE)
B(-9,1,-6,STONE)
B(-9,1,-5,STONE)
B(-9,1,-4,STONE)
B(-9,1,-3,STONE)
B(-9,1,-2,STONE)
B(-9,1,-1,STONE)
B(-9,1,0,STONE)
B(-9,1,1,STONE)
B(-9,1,2,STONE)
B(-9,1,3,STONE)
B(-9,1,4,STONE)
B(-9,1,5,STONE)
B(-9,1,6,STONE)
B(-9,1,7,STONE)
B(-9,1,8,STONE)
B(-9,1,9,STONE)
B(-9,1,10,STONE)
B(-9,1,11,STONE)
B(-9,2,-9,STONE)
B(-9,2,-8,STONE)
B(-9,2,-7,STONE)
B(-9,2,-6,STONE)
B(-9,2,-5,STONE)
B(-9,2,-4,STONE)
B(-9,2,-3,STONE)
B(-9,2,-2,STONE)
B(-9,2,-1,STONE)
B(-9,2,0,STONE)
B(-9,2,1,STONE)
B(-9,2,2,STONE)
B(-9,2,3,STONE)
B(-9,2,4,STONE)
B(-9,2,5,STONE)
B(-9,2,6,STONE)
B(-9,2,7,STONE)
B(-9,2,8,STONE)
B(-9,2,9,STONE)
B(-9,2,10,STONE)
B(-9,2,11,STONE)
B(-9,3,-9,STONE)
B(-9,3,-8,STONE)
B(-9,3,-7,STONE)
B(-9,3,-6,STONE)
B(-9,3,-5,STONE)
B(-9,3,-4,STONE)
B(-9,3,-3,STONE)
B(-9,3,-2,STONE)
B(-9,3,-1,STONE)
B(-9,3,0,STONE)
B(-9,3,1,STONE)
B(-9,3,2,STONE)
B(-9,3,3,STONE)
B(-9,3,4,STONE)
B(-9,3,5,STONE)
B(-9,3,6,STONE)
B(-9,3,7,STONE)
B(-9,3,8,STONE)
B(-9,3,9,STONE)
B(-9,3,10,STONE)
B(-9,3,11,STONE)
B(-9,4,-8,STONE)
B(-9,4,-7,STONE)
B(-9,4,-6,STONE)
B(-9,4,-5,STONE)
B(-9,4,-4,STONE)
B(-9,4,-3,STONE)
B(-9,4,-2,STONE)
B(-9,4,-1,STONE)
B(-9,4,0,STONE)
B(-9,4,1,STONE)
B(-9,4,2,STONE)
B(-9,4,3,STONE)
B(-9,4,4,STONE)
B(-9,4,5,STONE)
B(-9,4,6,STONE)
B(-9,4,7,STONE)
B(-9,4,8,STONE)
B(-9,4,9,STONE)
B(-9,4,10,STONE)
B(-9,5,-8,STONE)
B(-9,5,-7,STONE)
B(-9,5,-6,STONE)
B(-9,5,-5,STONE)
B(-9,5,-4,STONE)
B(-9,5,-3,STONE)
B(-9,5,-2,STONE)
B(-9,5,-1,STONE)
B(-9,5,0,STONE)
B(-9,5,1,STONE)
B(-9,5,2,STONE)
B(-9,5,3,STONE)
B(-9,5,4,STONE)
B(-9,5,5,STONE)
B(-9,5,6,STONE)
B(-9,5,7,STONE)
B(-9,5,8,STONE)
B(-9,5,9,STONE)
B(-9,6,-7,STONE)
B(-9,6,-6,STONE)
B(-9,6,-5,STONE)
B(-9,6,-4,STONE)
B(-9,6,-3,STONE)
B(-9,6,-2,STONE)
B(-9,6,-1,STONE)
B(-9,6,0,STONE)
B(-9,6,1,STONE)
B(-9,6,2,STONE)
B(-9,6,3,STONE)
B(-9,6,4,STONE)
B(-9,6,5,STONE)
B(-9,6,6,STONE)
B(-9,6,7,STONE)
B(-9,6,8,STONE)
B(-9,7,-7,STONE)
B(-9,7,-6,STONE)
B(-9,7,-5,STONE)
B(-9,7,-4,STONE)
B(-9,7,-3,STONE)
B(-9,7,-2,STONE)
B(-9,7,-1,STONE)
B(-9,7,0,STONE)
B(-9,7,1,STONE)
B(-9,7,2,STONE)
B(-9,7,3,STONE)
B(-9,7,4,STONE)
B(-9,7,5,STONE)
B(-9,7,6,STONE)
B(-9,7,7,STONE)
B(-9,8,-6,STONE)
B(-9,8,-5,STONE)
B(-9,8,-4,STONE)
B(-9,8,-3,STONE)
B(-9,8,-2,STONE)
B(-9,8,-1,STONE)
B(-9,8,0,STONE)
B(-9,8,1,STONE)
B(-9,8,2,STONE)
B(-9,8,3,STONE)
B(-9,8,4,STONE)
B(-9,8,5,STONE)
B(-9,8,6,STONE)
B(-9,9,-5,STONE)
B(-9,9,-4,STONE)
B(-9,9,-3,STONE)
B(-9,9,-2,STONE)
B(-9,9,-1,STONE)
B(-9,9,0,STONE)
B(-9,9,1,STONE)
B(-9,9,2,STONE)
B(-9,9,3,STONE)
B(-9,9,4,STONE)
B(-9,9,5,STONE)
B(-9,10,-4,STONE)
B(-9,10,-3,STONE)
B(-9,10,2,STONE)
B(-8,-14,-5,STONE)
B(-8,-14,-4,STONE)
B(-8,-14,-3,STONE)
B(-8,-14,-2,STONE)
B(-8,-14,3,STONE)
B(-8,-14,4,STONE)
B(-8,-14,5,STONE)
B(-8,-14,6,STONE)
B(-8,-13,-6,STONE)
B(-8,-13,-5,STONE)
B(-8,-13,-4,STONE)
B(-8,-13,-3,STONE)
B(-8,-13,-2,STONE)
B(-8,-13,-1,STONE)
B(-8,-13,0,STONE)
B(-8,-13,1,STONE)
B(-8,-13,2,STONE)
B(-8,-13,3,STONE)
B(-8,-13,4,STONE)
B(-8,-13,5,STONE)
B(-8,-13,6,STONE)
B(-8,-13,7,STONE)
B(-8,-12,-7,STONE)
B(-8,-12,-6,STONE)
B(-8,-12,-5,STONE)
B(-8,-12,-4,STONE)
B(-8,-12,-3,STONE)
B(-8,-12,-2,STONE)
B(-8,-12,-1,STONE)
B(-8,-12,0,STONE)
B(-8,-12,1,STONE)
B(-8,-12,2,STONE)
B(-8,-12,3,STONE)
B(-8,-12,4,STONE)
B(-8,-12,5,STONE)
B(-8,-12,6,STONE)
B(-8,-12,7,STONE)
B(-8,-12,8,STONE)
B(-8,-11,-7,STONE)
B(-8,-11,-6,STONE)
B(-8,-11,-5,STONE)
B(-8,-11,-4,STONE)
B(-8,-11,-3,STONE)
B(-8,-11,-2,STONE)
B(-8,-11,-1,STONE)
B(-8,-11,0,STONE)
B(-8,-11,1,STONE)
B(-8,-11,2,STONE)
B(-8,-11,3,STONE)
B(-8,-11,4,STONE)
B(-8,-11,5,STONE)
B(-8,-11,6,STONE)
B(-8,-11,7,STONE)
B(-8,-11,8,STONE)
B(-8,-11,9,STONE)
B(-8,-10,-7,STONE)
B(-8,-10,-6,STONE)
B(-8,-10,-5,STONE)
B(-8,-10,-4,STONE)
B(-8,-10,-3,STONE)
B(-8,-10,-2,STONE)
B(-8,-10,-1,STONE)
B(-8,-10,0,STONE)
B(-8,-10,1,STONE)
B(-8,-10,2,STONE)
B(-8,-10,3,STONE)
B(-8,-10,4,STONE)
B(-8,-10,5,STONE)
B(-8,-10,6,STONE)
B(-8,-10,7,STONE)
B(-8,-10,8,STONE)
B(-8,-10,9,STONE)
B(-8,-9,-8,STONE)
B(-8,-9,-7,STONE)
B(-8,-9,-6,STONE)
B(-8,-9,-5,STONE)
B(-8,-9,-4,STONE)
B(-8,-9,-3,STONE)
B(-8,-9,-2,STONE)
B(-8,-9,-1,STONE)
B(-8,-9,0,STONE)
B(-8,-9,1,STONE)
B(-8,-9,2,STONE)
B(-8,-9,3,STONE)
B(-8,-9,4,STONE)
B(-8,-9,5,STONE)
B(-8,-9,6,STONE)
B(-8,-9,7,STONE)
B(-8,-9,8,STONE)
B(-8,-9,9,STONE)
B(-8,-9,10,STONE)
B(-8,-9,11,STONE)
B(-8,-8,-8,STONE)
B(-8,-8,-7,STONE)
B(-8,-8,-6,STONE)
B(-8,-8,-5,STONE)
B(-8,-8,-4,STONE)
B(-8,-8,-3,STONE)
B(-8,-8,-2,STONE)
B(-8,-8,-1,STONE)
B(-8,-8,0,STONE)
B(-8,-8,1,STONE)
B(-8,-8,2,STONE)
B(-8,-8,3,STONE)
B(-8,-8,4,STONE)
B(-8,-8,5,STONE)
B(-8,-8,6,STONE)
B(-8,-8,7,STONE)
B(-8,-8,8,STONE)
B(-8,-8,9,STONE)
B(-8,-8,10,STONE)
B(-8,-8,11,STONE)
B(-8,-7,-9,STONE)
B(-8,-7,-8,STONE)
B(-8,-7,-7,STONE)
B(-8,-7,-6,STONE)
B(-8,-7,-5,STONE)
B(-8,-7,-4,STONE)
B(-8,-7,-3,STONE)
B(-8,-7,-2,STONE)
B(-8,-7,-1,STONE)
B(-8,-7,0,STONE)
B(-8,-7,1,STONE)
B(-8,-7,2,STONE)
B(-8,-7,3,STONE)
B(-8,-7,4,STONE)
B(-8,-7,5,STONE)
B(-8,-7,6,STONE)
B(-8,-7,7,STONE)
B(-8,-7,8,STONE)
B(-8,-7,9,STONE)
B(-8,-7,10,STONE)
B(-8,-7,11,STONE)
B(-8,-6,-9,STONE)
B(-8,-6,-8,STONE)
B(-8,-6,-7,STONE)
B(-8,-6,-6,STONE)
B(-8,-6,-5,STONE)
B(-8,-6,-4,STONE)
B(-8,-6,-3,STONE)
B(-8,-6,-2,STONE)
B(-8,-6,-1,STONE)
B(-8,-6,0,STONE)
B(-8,-6,1,STONE)
B(-8,-6,2,STONE)
B(-8,-6,3,STONE)
B(-8,-6,4,STONE)
B(-8,-6,5,STONE)
B(-8,-6,6,STONE)
B(-8,-6,7,STONE)
B(-8,-6,8,STONE)
B(-8,-6,9,STONE)
B(-8,-6,10,STONE)
B(-8,-6,11,STONE)
B(-8,-6,12,STONE)
B(-8,-5,-10,STONE)
B(-8,-5,-9,STONE)
B(-8,-5,-8,STONE)
B(-8,-5,-7,STONE)
B(-8,-5,-6,STONE)
B(-8,-5,-5,STONE)
B(-8,-5,-4,STONE)
B(-8,-5,-3,STONE)
B(-8,-5,-2,STONE)
B(-8,-5,-1,STONE)
B(-8,-5,0,STONE)
B(-8,-5,1,STONE)
B(-8,-5,2,STONE)
B(-8,-5,3,STONE)
B(-8,-5,4,STONE)
B(-8,-5,5,STONE)
B(-8,-5,6,STONE)
B(-8,-5,7,STONE)
B(-8,-5,8,STONE)
B(-8,-5,9,STONE)
B(-8,-5,10,STONE)
B(-8,-5,11,STONE)
B(-8,-5,12,STONE)
B(-8,-4,-10,STONE)
B(-8,-4,-9,STONE)
B(-8,-4,-8,STONE)
B(-8,-4,-7,STONE)
B(-8,-4,-6,STONE)
B(-8,-4,-5,STONE)
B(-8,-4,-4,STONE)
B(-8,-4,-3,STONE)
B(-8,-4,-2,STONE)
B(-8,-4,-1,STONE)
B(-8,-4,0,STONE)
B(-8,-4,1,STONE)
B(-8,-4,2,STONE)
B(-8,-4,3,STONE)
B(-8,-4,4,STONE)
B(-8,-4,5,STONE)
B(-8,-4,6,STONE)
B(-8,-4,7,STONE)
B(-8,-4,8,STONE)
B(-8,-4,9,STONE)
B(-8,-4,10,STONE)
B(-8,-4,11,STONE)
B(-8,-4,12,STONE)
B(-8,-3,-10,STONE)
B(-8,-3,-9,STONE)
B(-8,-3,-8,STONE)
B(-8,-3,-7,STONE)
B(-8,-3,-6,STONE)
B(-8,-3,-5,STONE)
B(-8,-3,-4,STONE)
B(-8,-3,-3,STONE)
B(-8,-3,-2,STONE)
B(-8,-3,-1,STONE)
B(-8,-3,0,STONE)
B(-8,-3,1,STONE)
B(-8,-3,2,STONE)
B(-8,-3,3,STONE)
B(-8,-3,4,STONE)
B(-8,-3,5,STONE)
B(-8,-3,6,STONE)
B(-8,-3,7,STONE)
B(-8,-3,8,STONE)
B(-8,-3,9,STONE)
B(-8,-3,10,STONE)
B(-8,-3,11,STONE)
B(-8,-3,12,STONE)
B(-8,-3,13,STONE)
B(-8,-2,-10,STONE)
B(-8,-2,-9,STONE)
B(-8,-2,-8,STONE)
B(-8,-2,-7,STONE)
B(-8,-2,-6,STONE)
B(-8,-2,-5,STONE)
B(-8,-2,-4,STONE)
B(-8,-2,-3,STONE)
B(-8,-2,-2,STONE)
B(-8,-2,-1,STONE)
B(-8,-2,0,STONE)
B(-8,-2,1,STONE)
B(-8,-2,2,STONE)
B(-8,-2,3,STONE)
B(-8,-2,4,STONE)
B(-8,-2,5,STONE)
B(-8,-2,6,STONE)
B(-8,-2,7,STONE)
B(-8,-2,8,STONE)
B(-8,-2,9,STONE)
B(-8,-2,10,STONE)
B(-8,-2,11,STONE)
B(-8,-2,12,STONE)
B(-8,-2,13,STONE)
B(-8,-1,-10,STONE)
B(-8,-1,-9,STONE)
B(-8,-1,-8,STONE)
B(-8,-1,-7,STONE)
B(-8,-1,-6,STONE)
B(-8,-1,-5,STONE)
B(-8,-1,-4,STONE)
B(-8,-1,-3,STONE)
B(-8,-1,-2,STONE)
B(-8,-1,-1,STONE)
B(-8,-1,0,STONE)
B(-8,-1,1,STONE)
B(-8,-1,2,STONE)
B(-8,-1,3,STONE)
B(-8,-1,4,STONE)
B(-8,-1,5,STONE)
B(-8,-1,6,STONE)
B(-8,-1,7,STONE)
B(-8,-1,8,STONE)
B(-8,-1,9,STONE)
B(-8,-1,10,STONE)
B(-8,-1,11,STONE)
B(-8,-1,12,STONE)
B(-8,0,-10,STONE)
B(-8,0,-9,STONE)
B(-8,0,-8,STONE)
B(-8,0,-7,STONE)
B(-8,0,-6,STONE)
B(-8,0,-5,STONE)
B(-8,0,-4,STONE)
B(-8,0,-3,STONE)
B(-8,0,-2,STONE)
B(-8,0,-1,STONE)
B(-8,0,0,STONE)
B(-8,0,1,STONE)
B(-8,0,2,STONE)
B(-8,0,3,STONE)
B(-8,0,4,STONE)
B(-8,0,5,STONE)
B(-8,0,6,STONE)
B(-8,0,7,STONE)
B(-8,0,8,STONE)
B(-8,0,9,STONE)
B(-8,0,10,STONE)
B(-8,0,11,STONE)
B(-8,0,12,STONE)
B(-8,1,-9,STONE)
B(-8,1,-8,STONE)
B(-8,1,-7,STONE)
B(-8,1,-6,STONE)
B(-8,1,-5,STONE)
B(-8,1,-4,STONE)
B(-8,1,-3,STONE)
B(-8,1,-2,STONE)
B(-8,1,-1,STONE)
B(-8,1,0,STONE)
B(-8,1,1,STONE)
B(-8,1,2,STONE)
B(-8,1,3,STONE)
B(-8,1,4,STONE)
B(-8,1,5,STONE)
B(-8,1,6,STONE)
B(-8,1,7,STONE)
B(-8,1,8,STONE)
B(-8,1,9,STONE)
B(-8,1,10,STONE)
B(-8,1,11,STONE)
B(-8,1,12,STONE)
B(-8,2,-9,STONE)
B(-8,2,-8,STONE)
B(-8,2,-7,STONE)
B(-8,2,-6,STONE)
B(-8,2,-5,STONE)
B(-8,2,-4,STONE)
B(-8,2,-3,STONE)
B(-8,2,-2,STONE)
B(-8,2,-1,STONE)
B(-8,2,0,STONE)
B(-8,2,1,STONE)
B(-8,2,2,STONE)
B(-8,2,3,STONE)
B(-8,2,4,STONE)
B(-8,2,5,STONE)
B(-8,2,6,STONE)
B(-8,2,7,STONE)
B(-8,2,8,STONE)
B(-8,2,9,STONE)
B(-8,2,10,STONE)
B(-8,2,11,STONE)
B(-8,3,-8,STONE)
B(-8,3,-7,STONE)
B(-8,3,-6,STONE)
B(-8,3,-5,STONE)
B(-8,3,-4,STONE)
B(-8,3,-3,STONE)
B(-8,3,-2,STONE)
B(-8,3,-1,STONE)
B(-8,3,0,STONE)
B(-8,3,1,STONE)
B(-8,3,2,STONE)
B(-8,3,3,STONE)
B(-8,3,4,STONE)
B(-8,3,5,STONE)
B(-8,3,6,STONE)
B(-8,3,7,STONE)
B(-8,3,8,STONE)
B(-8,3,9,STONE)
B(-8,3,10,STONE)
B(-8,3,11,STONE)
B(-8,4,-8,STONE)
B(-8,4,-7,STONE)
B(-8,4,-6,STONE)
B(-8,4,-5,STONE)
B(-8,4,-4,STONE)
B(-8,4,-3,STONE)
B(-8,4,-2,STONE)
B(-8,4,-1,STONE)
B(-8,4,0,STONE)
B(-8,4,1,STONE)
B(-8,4,2,STONE)
B(-8,4,3,STONE)
B(-8,4,4,STONE)
B(-8,4,5,STONE)
B(-8,4,6,STONE)
B(-8,4,7,STONE)
B(-8,4,8,STONE)
B(-8,4,9,STONE)
B(-8,4,10,STONE)
B(-8,4,11,STONE)
B(-8,5,-7,STONE)
B(-8,5,-6,STONE)
B(-8,5,-5,STONE)
B(-8,5,-4,STONE)
B(-8,5,-3,STONE)
B(-8,5,-2,STONE)
B(-8,5,-1,STONE)
B(-8,5,0,STONE)
B(-8,5,1,STONE)
B(-8,5,2,STONE)
B(-8,5,3,STONE)
B(-8,5,4,STONE)
B(-8,5,5,STONE)
B(-8,5,6,STONE)
B(-8,5,7,STONE)
B(-8,5,8,STONE)
B(-8,5,9,STONE)
B(-8,6,-7,STONE)
B(-8,6,-6,STONE)
B(-8,6,-5,STONE)
B(-8,6,-4,STONE)
B(-8,6,-3,STONE)
B(-8,6,-2,STONE)
B(-8,6,-1,STONE)
B(-8,6,0,STONE)
B(-8,6,1,STONE)
B(-8,6,2,STONE)
B(-8,6,3,STONE)
B(-8,6,4,STONE)
B(-8,6,5,STONE)
B(-8,6,6,STONE)
B(-8,6,7,STONE)
B(-8,6,8,STONE)
B(-8,6,9,STONE)
B(-8,7,-7,STONE)
B(-8,7,-6,STONE)
B(-8,7,-5,STONE)
B(-8,7,-4,STONE)
B(-8,7,-3,STONE)
B(-8,7,-2,STONE)
B(-8,7,-1,STONE)
B(-8,7,0,STONE)
B(-8,7,1,STONE)
B(-8,7,2,STONE)
B(-8,7,3,STONE)
B(-8,7,4,STONE)
B(-8,7,5,STONE)
B(-8,7,6,STONE)
B(-8,7,7,STONE)
B(-8,7,8,STONE)
B(-8,8,-6,STONE)
B(-8,8,-5,STONE)
B(-8,8,-4,STONE)
B(-8,8,-3,STONE)
B(-8,8,-2,STONE)
B(-8,8,-1,STONE)
B(-8,8,0,STONE)
B(-8,8,1,STONE)
B(-8,8,2,STONE)
B(-8,8,3,STONE)
B(-8,8,4,STONE)
B(-8,8,5,STONE)
B(-8,8,6,STONE)
B(-8,8,7,STONE)
B(-8,9,-5,STONE)
B(-8,9,-4,STONE)
B(-8,9,-3,STONE)
B(-8,9,-2,STONE)
B(-8,9,3,STONE)
B(-8,9,4,STONE)
B(-8,9,5,STONE)
B(-8,9,6,STONE)
B(-7,-14,-5,STONE)
B(-7,-14,-4,STONE)
B(-7,-14,-3,STONE)
B(-7,-14,4,STONE)
B(-7,-14,5,STONE)
B(-7,-14,6,STONE)
B(-7,-13,-6,STONE)
B(-7,-13,-5,STONE)
B(-7,-13,-4,STONE)
B(-7,-13,-3,STONE)
B(-7,-13,-2,STONE)
B(-7,-13,-1,STONE)
B(-7,-13,0,STONE)
B(-7,-13,1,STONE)
B(-7,-13,2,STONE)
B(-7,-13,3,STONE)
B(-7,-13,4,STONE)
B(-7,-13,5,STONE)
B(-7,-13,6,STONE)
B(-7,-13,7,STONE)
B(-7,-12,-6,STONE)
B(-7,-12,-5,STONE)
B(-7,-12,-4,STONE)
B(-7,-12,-3,STONE)
B(-7,-12,-2,STONE)
B(-7,-12,-1,STONE)
B(-7,-12,0,STONE)
B(-7,-12,1,STONE)
B(-7,-12,2,STONE)
B(-7,-12,3,STONE)
B(-7,-12,4,STONE)
B(-7,-12,5,STONE)
B(-7,-12,6,STONE)
B(-7,-12,7,STONE)
B(-7,-12,8,STONE)
B(-7,-11,-7,STONE)
B(-7,-11,-6,STONE)
B(-7,-11,-5,STONE)
B(-7,-11,-4,STONE)
B(-7,-11,-3,STONE)
B(-7,-11,-2,STONE)
B(-7,-11,-1,STONE)
B(-7,-11,0,STONE)
B(-7,-11,1,STONE)
B(-7,-11,2,STONE)
B(-7,-11,3,STONE)
B(-7,-11,4,STONE)
B(-7,-11,5,STONE)
B(-7,-11,6,STONE)
B(-7,-11,7,STONE)
B(-7,-11,8,STONE)
B(-7,-11,9,STONE)
B(-7,-10,-7,STONE)
B(-7,-10,-6,STONE)
B(-7,-10,-5,STONE)
B(-7,-10,-4,STONE)
B(-7,-10,-3,STONE)
B(-7,-10,-2,STONE)
B(-7,-10,-1,STONE)
B(-7,-10,0,STONE)
B(-7,-10,1,STONE)
B(-7,-10,2,STONE)
B(-7,-10,3,STONE)
B(-7,-10,4,STONE)
B(-7,-10,5,STONE)
B(-7,-10,6,STONE)
B(-7,-10,7,STONE)
B(-7,-10,8,STONE)
B(-7,-10,9,STONE)
B(-7,-10,10,STONE)
B(-7,-9,-8,STONE)
B(-7,-9,-7,STONE)
B(-7,-9,-6,STONE)
B(-7,-9,-5,STONE)
B(-7,-9,-4,STONE)
B(-7,-9,-3,STONE)
B(-7,-9,-2,STONE)
B(-7,-9,-1,STONE)
B(-7,-9,0,STONE)
B(-7,-9,1,STONE)
B(-7,-9,2,STONE)
B(-7,-9,3,STONE)
B(-7,-9,4,STONE)
B(-7,-9,5,STONE)
B(-7,-9,6,STONE)
B(-7,-9,7,STONE)
B(-7,-9,8,STONE)
B(-7,-9,9,STONE)
B(-7,-9,10,STONE)
B(-7,-9,11,STONE)
B(-7,-8,-8,STONE)
B(-7,-8,-7,STONE)
B(-7,-8,-6,STONE)
B(-7,-8,-5,STONE)
B(-7,-8,-4,STONE)
B(-7,-8,-3,STONE)
B(-7,-8,-2,STONE)
B(-7,-8,-1,STONE)
B(-7,-8,0,STONE)
B(-7,-8,1,STONE)
B(-7,-8,2,STONE)
B(-7,-8,3,STONE)
B(-7,-8,4,STONE)
B(-7,-8,5,STONE)
B(-7,-8,6,STONE)
B(-7,-8,7,STONE)
B(-7,-8,8,STONE)
B(-7,-8,9,STONE)
B(-7,-8,10,STONE)
B(-7,-8,11,STONE)
B(-7,-7,-8,STONE)
B(-7,-7,-7,STONE)
B(-7,-7,-6,STONE)
B(-7,-7,-5,STONE)
B(-7,-7,-4,STONE)
B(-7,-7,-3,STONE)
B(-7,-7,-2,STONE)
B(-7,-7,-1,STONE)
B(-7,-7,0,STONE)
B(-7,-7,1,STONE)
B(-7,-7,2,STONE)
B(-7,-7,3,STONE)
B(-7,-7,4,STONE)
B(-7,-7,5,STONE)
B(-7,-7,6,STONE)
B(-7,-7,7,STONE)
B(-7,-7,8,STONE)
B(-7,-7,9,STONE)
B(-7,-7,10,STONE)
B(-7,-7,11,STONE)
B(-7,-6,-9,STONE)
B(-7,-6,-8,STONE)
B(-7,-6,-7,STONE)
B(-7,-6,-6,STONE)
B(-7,-6,-5,STONE)
B(-7,-6,-4,STONE)
B(-7,-6,-3,STONE)
B(-7,-6,-2,STONE)
B(-7,-6,-1,STONE)
B(-7,-6,0,STONE)
B(-7,-6,1,STONE)
B(-7,-6,2,STONE)
B(-7,-6,3,STONE)
B(-7,-6,4,STONE)
B(-7,-6,5,STONE)
B(-7,-6,6,STONE)
B(-7,-6,7,STONE)
B(-7,-6,8,STONE)
B(-7,-6,9,STONE)
B(-7,-6,10,STONE)
B(-7,-6,11,STONE)
B(-7,-6,12,STONE)
B(-7,-5,-9,STONE)
B(-7,-5,-8,STONE)
B(-7,-5,-7,STONE)
B(-7,-5,-6,STONE)
B(-7,-5,-5,STONE)
B(-7,-5,-4,STONE)
B(-7,-5,-3,STONE)
B(-7,-5,-2,STONE)
B(-7,-5,-1,STONE)
B(-7,-5,0,STONE)
B(-7,-5,1,STONE)
B(-7,-5,2,STONE)
B(-7,-5,3,STONE)
B(-7,-5,4,STONE)
B(-7,-5,5,STONE)
B(-7,-5,6,STONE)
B(-7,-5,7,STONE)
B(-7,-5,8,STONE)
B(-7,-5,9,STONE)
B(-7,-5,10,STONE)
B(-7,-5,11,STONE)
B(-7,-5,12,STONE)
B(-7,-4,-9,STONE)
B(-7,-4,-8,STONE)
B(-7,-4,-7,STONE)
B(-7,-4,-6,STONE)
B(-7,-4,-5,STONE)
B(-7,-4,-4,STONE)
B(-7,-4,-3,STONE)
B(-7,-4,-2,STONE)
B(-7,-4,-1,STONE)
B(-7,-4,0,STONE)
B(-7,-4,1,STONE)
B(-7,-4,2,STONE)
B(-7,-4,3,STONE)
B(-7,-4,4,STONE)
B(-7,-4,5,STONE)
B(-7,-4,6,STONE)
B(-7,-4,7,STONE)
B(-7,-4,8,STONE)
B(-7,-4,9,STONE)
B(-7,-4,10,STONE)
B(-7,-4,11,STONE)
B(-7,-4,12,STONE)
B(-7,-3,-9,STONE)
B(-7,-3,-8,STONE)
B(-7,-3,-7,STONE)
B(-7,-3,-6,STONE)
B(-7,-3,-5,STONE)
B(-7,-3,-4,STONE)
B(-7,-3,-3,STONE)
B(-7,-3,-2,STONE)
B(-7,-3,-1,STONE)
B(-7,-3,0,STONE)
B(-7,-3,1,STONE)
B(-7,-3,2,STONE)
B(-7,-3,3,STONE)
B(-7,-3,4,STONE)
B(-7,-3,5,STONE)
B(-7,-3,6,STONE)
B(-7,-3,7,STONE)
B(-7,-3,8,STONE)
B(-7,-3,9,STONE)
B(-7,-3,10,STONE)
B(-7,-3,11,STONE)
B(-7,-3,12,STONE)
B(-7,-3,13,STONE)
B(-7,-2,-9,STONE)
B(-7,-2,-8,STONE)
B(-7,-2,-7,STONE)
B(-7,-2,-6,STONE)
B(-7,-2,-5,STONE)
B(-7,-2,-4,STONE)
B(-7,-2,-3,STONE)
B(-7,-2,-2,STONE)
B(-7,-2,-1,STONE)
B(-7,-2,0,STONE)
B(-7,-2,1,STONE)
B(-7,-2,2,STONE)
B(-7,-2,3,STONE)
B(-7,-2,4,STONE)
B(-7,-2,5,STONE)
B(-7,-2,6,STONE)
B(-7,-2,7,STONE)
B(-7,-2,8,STONE)
B(-7,-2,9,STONE)
B(-7,-2,10,STONE)
B(-7,-2,11,STONE)
B(-7,-2,12,STONE)
B(-7,-2,13,STONE)
B(-7,-1,-9,STONE)
B(-7,-1,-8,STONE)
B(-7,-1,-7,STONE)
B(-7,-1,-6,STONE)
B(-7,-1,-5,STONE)
B(-7,-1,-4,STONE)
B(-7,-1,-3,STONE)
B(-7,-1,-2,STONE)
B(-7,-1,-1,STONE)
B(-7,-1,0,STONE)
B(-7,-1,1,STONE)
B(-7,-1,2,STONE)
B(-7,-1,3,STONE)
B(-7,-1,4,STONE)
B(-7,-1,5,STONE)
B(-7,-1,6,STONE)
B(-7,-1,7,STONE)
B(-7,-1,8,STONE)
B(-7,-1,9,STONE)
B(-7,-1,10,STONE)
B(-7,-1,11,STONE)
B(-7,-1,12,STONE)
B(-7,0,-9,STONE)
B(-7,0,-8,STONE)
B(-7,0,-7,STONE)
B(-7,0,-6,STONE)
B(-7,0,-5,STONE)
B(-7,0,-4,STONE)
B(-7,0,-3,STONE)
B(-7,0,-2,STONE)
B(-7,0,-1,STONE)
B(-7,0,0,STONE)
B(-7,0,1,STONE)
B(-7,0,2,STONE)
B(-7,0,3,STONE)
B(-7,0,4,STONE)
B(-7,0,5,STONE)
B(-7,0,6,STONE)
B(-7,0,7,STONE)
B(-7,0,8,STONE)
B(-7,0,9,STONE)
B(-7,0,10,STONE)
B(-7,0,11,STONE)
B(-7,0,12,STONE)
B(-7,1,-9,STONE)
B(-7,1,-8,STONE)
B(-7,1,-7,STONE)
B(-7,1,-6,STONE)
B(-7,1,-5,STONE)
B(-7,1,-4,STONE)
B(-7,1,-3,STONE)
B(-7,1,-2,STONE)
B(-7,1,-1,STONE)
B(-7,1,0,STONE)
B(-7,1,1,STONE)
B(-7,1,2,STONE)
B(-7,1,3,STONE)
B(-7,1,4,STONE)
B(-7,1,5,STONE)
B(-7,1,6,STONE)
B(-7,1,7,STONE)
B(-7,1,8,STONE)
B(-7,1,9,STONE)
B(-7,1,10,STONE)
B(-7,1,11,STONE)
B(-7,1,12,STONE)
B(-7,2,-8,STONE)
B(-7,2,-7,STONE)
B(-7,2,-6,STONE)
B(-7,2,-5,STONE)
B(-7,2,-4,STONE)
B(-7,2,-3,STONE)
B(-7,2,-2,STONE)
B(-7,2,-1,STONE)
B(-7,2,0,STONE)
B(-7,2,1,STONE)
B(-7,2,2,STONE)
B(-7,2,3,STONE)
B(-7,2,4,STONE)
B(-7,2,5,STONE)
B(-7,2,6,STONE)
B(-7,2,7,STONE)
B(-7,2,8,STONE)
B(-7,2,9,STONE)
B(-7,2,10,STONE)
B(-7,2,11,STONE)
B(-7,3,-8,STONE)
B(-7,3,-7,STONE)
B(-7,3,-6,STONE)
B(-7,3,-5,STONE)
B(-7,3,-4,STONE)
B(-7,3,-3,STONE)
B(-7,3,-2,STONE)
B(-7,3,-1,STONE)
B(-7,3,0,STONE)
B(-7,3,1,STONE)
B(-7,3,2,STONE)
B(-7,3,3,STONE)
B(-7,3,4,STONE)
B(-7,3,5,STONE)
B(-7,3,6,STONE)
B(-7,3,7,STONE)
B(-7,3,8,STONE)
B(-7,3,9,STONE)
B(-7,3,10,STONE)
B(-7,3,11,STONE)
B(-7,4,-8,STONE)
B(-7,4,-7,STONE)
B(-7,4,-6,STONE)
B(-7,4,-5,STONE)
B(-7,4,-4,STONE)
B(-7,4,-3,STONE)
B(-7,4,-2,STONE)
B(-7,4,-1,STONE)
B(-7,4,0,STONE)
B(-7,4,1,STONE)
B(-7,4,2,STONE)
B(-7,4,3,STONE)
B(-7,4,4,STONE)
B(-7,4,5,STONE)
B(-7,4,6,STONE)
B(-7,4,7,STONE)
B(-7,4,8,STONE)
B(-7,4,9,STONE)
B(-7,4,10,STONE)
B(-7,4,11,STONE)
B(-7,5,-7,STONE)
B(-7,5,-6,STONE)
B(-7,5,-5,STONE)
B(-7,5,-4,STONE)
B(-7,5,-3,STONE)
B(-7,5,-2,STONE)
B(-7,5,-1,STONE)
B(-7,5,0,STONE)
B(-7,5,1,STONE)
B(-7,5,2,STONE)
B(-7,5,3,STONE)
B(-7,5,4,STONE)
B(-7,5,5,STONE)
B(-7,5,6,STONE)
B(-7,5,7,STONE)
B(-7,5,8,STONE)
B(-7,5,9,STONE)
B(-7,5,10,STONE)
B(-7,6,-7,STONE)
B(-7,6,-6,STONE)
B(-7,6,-5,STONE)
B(-7,6,-4,STONE)
B(-7,6,-3,STONE)
B(-7,6,-2,STONE)
B(-7,6,-1,STONE)
B(-7,6,0,STONE)
B(-7,6,1,STONE)
B(-7,6,2,STONE)
B(-7,6,3,STONE)
B(-7,6,4,STONE)
B(-7,6,5,STONE)
B(-7,6,6,STONE)
B(-7,6,7,STONE)
B(-7,6,8,STONE)
B(-7,6,9,STONE)
B(-7,7,-6,STONE)
B(-7,7,-5,STONE)
B(-7,7,-4,STONE)
B(-7,7,-3,STONE)
B(-7,7,-2,STONE)
B(-7,7,-1,STONE)
B(-7,7,0,LAVA)
B(-7,7,1,LAVA)
B(-7,7,2,STONE)
B(-7,7,3,STONE)
B(-7,7,4,STONE)
B(-7,7,5,STONE)
B(-7,7,6,STONE)
B(-7,7,7,STONE)
B(-7,7,8,STONE)
B(-7,8,-6,STONE)
B(-7,8,-5,STONE)
B(-7,8,-4,STONE)
B(-7,8,-3,STONE)
B(-7,8,-2,STONE)
B(-7,8,-1,LAVA)
B(-7,8,0,LAVA)
B(-7,8,1,LAVA)
B(-7,8,2,LAVA)
B(-7,8,3,STONE)
B(-7,8,4,STONE)
B(-7,8,5,STONE)
B(-7,8,6,STONE)
B(-7,8,7,STONE)
B(-7,9,-5,STONE)
B(-7,9,-4,STONE)
B(-7,9,-3,STONE)
B(-7,9,4,STONE)
B(-7,9,5,STONE)
B(-7,9,6,STONE)
B(-6,-14,-5,STONE)
B(-6,-14,-4,STONE)
B(-6,-14,5,STONE)
B(-6,-14,6,STONE)
B(-6,-13,-6,STONE)
B(-6,-13,-5,STONE)
B(-6,-13,-4,STONE)
B(-6,-13,-3,STONE)
B(-6,-13,-2,STONE)
B(-6,-13,-1,STONE)
B(-6,-13,0,STONE)
B(-6,-13,1,STONE)
B(-6,-13,2,STONE)
B(-6,-13,3,STONE)
B(-6,-13,4,STONE)
B(-6,-13,5,STONE)
B(-6,-13,6,STONE)
B(-6,-13,7,STONE)
B(-6,-12,-6,STONE)
B(-6,-12,-5,STONE)
B(-6,-12,-4,STONE)
B(-6,-12,-3,STONE)
B(-6,-12,-2,STONE)
B(-6,-12,-1,STONE)
B(-6,-12,0,STONE)
B(-6,-12,1,STONE)
B(-6,-12,2,STONE)
B(-6,-12,3,STONE)
B(-6,-12,4,STONE)
B(-6,-12,5,STONE)
B(-6,-12,6,STONE)
B(-6,-12,7,STONE)
B(-6,-12,8,STONE)
B(-6,-11,-7,STONE)
B(-6,-11,-6,STONE)
B(-6,-11,-5,STONE)
B(-6,-11,-4,STONE)
B(-6,-11,-3,STONE)
B(-6,-11,-2,STONE)
B(-6,-11,-1,STONE)
B(-6,-11,0,STONE)
B(-6,-11,1,STONE)
B(-6,-11,2,STONE)
B(-6,-11,3,STONE)
B(-6,-11,4,STONE)
B(-6,-11,5,STONE)
B(-6,-11,6,STONE)
B(-6,-11,7,STONE)
B(-6,-11,8,STONE)
B(-6,-11,9,STONE)
B(-6,-10,-7,STONE)
B(-6,-10,-6,STONE)
B(-6,-10,-5,STONE)
B(-6,-10,-4,STONE)
B(-6,-10,-3,STONE)
B(-6,-10,-2,STONE)
B(-6,-10,-1,STONE)
B(-6,-10,0,STONE)
B(-6,-10,1,STONE)
B(-6,-10,2,STONE)
B(-6,-10,3,STONE)
B(-6,-10,4,STONE)
B(-6,-10,5,STONE)
B(-6,-10,6,STONE)
B(-6,-10,7,STONE)
B(-6,-10,8,STONE)
B(-6,-10,9,STONE)
B(-6,-10,10,STONE)
B(-6,-9,-7,STONE)
B(-6,-9,-6,STONE)
B(-6,-9,-5,STONE)
B(-6,-9,-4,STONE)
B(-6,-9,-3,STONE)
B(-6,-9,-2,STONE)
B(-6,-9,-1,STONE)
B(-6,-9,0,STONE)
B(-6,-9,1,STONE)
B(-6,-9,2,STONE)
B(-6,-9,3,STONE)
B(-6,-9,4,STONE)
B(-6,-9,5,STONE)
B(-6,-9,6,STONE)
B(-6,-9,7,STONE)
B(-6,-9,8,STONE)
B(-6,-9,9,STONE)
B(-6,-9,10,STONE)
B(-6,-9,11,STONE)
B(-6,-8,-8,STONE)
B(-6,-8,-7,STONE)
B(-6,-8,-6,STONE)
B(-6,-8,-5,STONE)
B(-6,-8,-4,STONE)
B(-6,-8,-3,STONE)
B(-6,-8,-2,STONE)
B(-6,-8,-1,STONE)
B(-6,-8,0,STONE)
B(-6,-8,1,STONE)
B(-6,-8,2,STONE)
B(-6,-8,3,STONE)
B(-6,-8,4,STONE)
B(-6,-8,5,STONE)
B(-6,-8,6,STONE)
B(-6,-8,7,STONE)
B(-6,-8,8,STONE)
B(-6,-8,9,STONE)
B(-6,-8,10,STONE)
B(-6,-8,11,STONE)
B(-6,-7,-8,STONE)
B(-6,-7,-7,STONE)
B(-6,-7,-6,STONE)
B(-6,-7,-5,STONE)
B(-6,-7,-4,STONE)
B(-6,-7,-3,STONE)
B(-6,-7,-2,STONE)
B(-6,-7,-1,STONE)
B(-6,-7,0,STONE)
B(-6,-7,1,STONE)
B(-6,-7,2,STONE)
B(-6,-7,3,STONE)
B(-6,-7,4,STONE)
B(-6,-7,5,STONE)
B(-6,-7,6,STONE)
B(-6,-7,7,STONE)
B(-6,-7,8,STONE)
B(-6,-7,9,STONE)
B(-6,-7,10,STONE)
B(-6,-7,11,STONE)
B(-6,-6,-8,STONE)
B(-6,-6,-7,STONE)
B(-6,-6,-6,STONE)
B(-6,-6,-5,STONE)
B(-6,-6,-4,STONE)
B(-6,-6,-3,STONE)
B(-6,-6,-2,STONE)
B(-6,-6,-1,STONE)
B(-6,-6,0,STONE)
B(-6,-6,1,STONE)
B(-6,-6,2,STONE)
B(-6,-6,3,STONE)
B(-6,-6,4,STONE)
B(-6,-6,5,STONE)
B(-6,-6,6,STONE)
B(-6,-6,7,STONE)
B(-6,-6,8,STONE)
B(-6,-6,9,STONE)
B(-6,-6,10,STONE)
B(-6,-6,11,STONE)
B(-6,-6,12,STONE)
B(-6,-5,-9,STONE)
B(-6,-5,-8,STONE)
B(-6,-5,-7,STONE)
B(-6,-5,-6,STONE)
B(-6,-5,-5,STONE)
B(-6,-5,-4,STONE)
B(-6,-5,-3,STONE)
B(-6,-5,-2,STONE)
B(-6,-5,-1,STONE)
B(-6,-5,0,STONE)
B(-6,-5,1,STONE)
B(-6,-5,2,STONE)
B(-6,-5,3,STONE)
B(-6,-5,4,STONE)
B(-6,-5,5,STONE)
B(-6,-5,6,STONE)
B(-6,-5,7,STONE)
B(-6,-5,8,STONE)
B(-6,-5,9,STONE)
B(-6,-5,10,STONE)
B(-6,-5,11,STONE)
B(-6,-5,12,STONE)
B(-6,-4,-9,STONE)
B(-6,-4,-8,STONE)
B(-6,-4,-7,STONE)
B(-6,-4,-6,STONE)
B(-6,-4,-5,STONE)
B(-6,-4,-4,STONE)
B(-6,-4,-3,STONE)
B(-6,-4,-2,STONE)
B(-6,-4,-1,STONE)
B(-6,-4,0,STONE)
B(-6,-4,1,STONE)
B(-6,-4,2,STONE)
B(-6,-4,3,STONE)
B(-6,-4,4,STONE)
B(-6,-4,5,STONE)
B(-6,-4,6,STONE)
B(-6,-4,7,STONE)
B(-6,-4,8,STONE)
B(-6,-4,9,STONE)
B(-6,-4,10,STONE)
B(-6,-4,11,STONE)
B(-6,-4,12,STONE)
B(-6,-4,13,STONE)
B(-6,-3,-9,STONE)
B(-6,-3,-8,STONE)
B(-6,-3,-7,STONE)
B(-6,-3,-6,STONE)
B(-6,-3,-5,STONE)
B(-6,-3,-4,STONE)
B(-6,-3,-3,STONE)
B(-6,-3,-2,STONE)
B(-6,-3,-1,STONE)
B(-6,-3,0,STONE)
B(-6,-3,1,STONE)
B(-6,-3,2,STONE)
B(-6,-3,3,STONE)
B(-6,-3,4,STONE)
B(-6,-3,5,STONE)
B(-6,-3,6,STONE)
B(-6,-3,7,STONE)
B(-6,-3,8,STONE)
B(-6,-3,9,STONE)
B(-6,-3,10,STONE)
B(-6,-3,11,STONE)
B(-6,-3,12,STONE)
B(-6,-3,13,STONE)
B(-6,-3,14,STONE)
B(-6,-2,-9,STONE)
B(-6,-2,-8,STONE)
B(-6,-2,-7,STONE)
B(-6,-2,-6,STONE)
B(-6,-2,-5,STONE)
B(-6,-2,-4,STONE)
B(-6,-2,-3,STONE)
B(-6,-2,-2,STONE)
B(-6,-2,-1,STONE)
B(-6,-2,0,STONE)
B(-6,-2,1,STONE)
B(-6,-2,2,STONE)
B(-6,-2,3,STONE)
B(-6,-2,4,STONE)
B(-6,-2,5,STONE)
B(-6,-2,6,STONE)
B(-6,-2,7,STONE)
B(-6,-2,8,STONE)
B(-6,-2,9,STONE)
B(-6,-2,10,STONE)
B(-6,-2,11,STONE)
B(-6,-2,12,STONE)
B(-6,-2,13,STONE)
B(-6,-2,14,STONE)
B(-6,-1,-9,STONE)
B(-6,-1,-8,STONE)
B(-6,-1,-7,STONE)
B(-6,-1,-6,STONE)
B(-6,-1,-5,STONE)
B(-6,-1,-4,STONE)
B(-6,-1,-3,STONE)
B(-6,-1,-2,STONE)
B(-6,-1,-1,STONE)
B(-6,-1,0,STONE)
B(-6,-1,1,STONE)
B(-6,-1,2,STONE)
B(-6,-1,3,STONE)
B(-6,-1,4,STONE)
B(-6,-1,5,STONE)
B(-6,-1,6,STONE)
B(-6,-1,7,STONE)
B(-6,-1,8,STONE)
B(-6,-1,9,STONE)
B(-6,-1,10,STONE)
B(-6,-1,11,STONE)
B(-6,-1,12,STONE)
B(-6,-1,13,STONE)
B(-6,0,-9,STONE)
B(-6,0,-8,STONE)
B(-6,0,-7,STONE)
B(-6,0,-6,STONE)
B(-6,0,-5,STONE)
B(-6,0,-4,STONE)
B(-6,0,-3,STONE)
B(-6,0,-2,STONE)
B(-6,0,-1,STONE)
B(-6,0,0,STONE)
B(-6,0,1,STONE)
B(-6,0,2,STONE)
B(-6,0,3,STONE)
B(-6,0,4,STONE)
B(-6,0,5,STONE)
B(-6,0,6,STONE)
B(-6,0,7,STONE)
B(-6,0,8,STONE)
B(-6,0,9,STONE)
B(-6,0,10,STONE)
B(-6,0,11,STONE)
B(-6,0,12,STONE)
B(-6,1,-8,STONE)
B(-6,1,-7,STONE)
B(-6,1,-6,STONE)
B(-6,1,-5,STONE)
B(-6,1,-4,STONE)
B(-6,1,-3,STONE)
B(-6,1,-2,STONE)
B(-6,1,-1,STONE)
B(-6,1,0,STONE)
B(-6,1,1,STONE)
B(-6,1,2,STONE)
B(-6,1,3,STONE)
B(-6,1,4,STONE)
B(-6,1,5,STONE)
B(-6,1,6,STONE)
B(-6,1,7,STONE)
B(-6,1,8,STONE)
B(-6,1,9,STONE)
B(-6,1,10,STONE)
B(-6,1,11,STONE)
B(-6,1,12,STONE)
B(-6,2,-8,STONE)
B(-6,2,-7,STONE)
B(-6,2,-6,STONE)
B(-6,2,-5,STONE)
B(-6,2,-4,STONE)
B(-6,2,-3,STONE)
B(-6,2,-2,STONE)
B(-6,2,-1,STONE)
B(-6,2,0,STONE)
B(-6,2,1,STONE)
B(-6,2,2,STONE)
B(-6,2,3,STONE)
B(-6,2,4,STONE)
B(-6,2,5,STONE)
B(-6,2,6,STONE)
B(-6,2,7,STONE)
B(-6,2,8,STONE)
B(-6,2,9,STONE)
B(-6,2,10,STONE)
B(-6,2,11,STONE)
B(-6,3,-8,STONE)
B(-6,3,-7,STONE)
B(-6,3,-6,STONE)
B(-6,3,-5,STONE)
B(-6,3,-4,STONE)
B(-6,3,-3,STONE)
B(-6,3,-2,STONE)
B(-6,3,-1,STONE)
B(-6,3,0,STONE)
B(-6,3,1,STONE)
B(-6,3,2,STONE)
B(-6,3,3,STONE)
B(-6,3,4,STONE)
B(-6,3,5,STONE)
B(-6,3,6,STONE)
B(-6,3,7,STONE)
B(-6,3,8,STONE)
B(-6,3,9,STONE)
B(-6,3,10,STONE)
B(-6,3,11,STONE)
B(-6,4,-7,STONE)
B(-6,4,-6,STONE)
B(-6,4,-5,STONE)
B(-6,4,-4,STONE)
B(-6,4,-3,STONE)
B(-6,4,-2,STONE)
B(-6,4,-1,STONE)
B(-6,4,0,STONE)
B(-6,4,1,STONE)
B(-6,4,2,STONE)
B(-6,4,3,STONE)
B(-6,4,4,STONE)
B(-6,4,5,STONE)
B(-6,4,6,STONE)
B(-6,4,7,STONE)
B(-6,4,8,STONE)
B(-6,4,9,STONE)
B(-6,4,10,STONE)
B(-6,4,11,STONE)
B(-6,5,-7,STONE)
B(-6,5,-6,STONE)
B(-6,5,-5,STONE)
B(-6,5,-4,STONE)
B(-6,5,-3,STONE)
B(-6,5,-2,STONE)
B(-6,5,-1,STONE)
B(-6,5,0,STONE)
B(-6,5,1,STONE)
B(-6,5,2,STONE)
B(-6,5,3,STONE)
B(-6,5,4,STONE)
B(-6,5,5,STONE)
B(-6,5,6,STONE)
B(-6,5,7,STONE)
B(-6,5,8,STONE)
B(-6,5,9,STONE)
B(-6,5,10,STONE)
B(-6,6,-7,STONE)
B(-6,6,-6,STONE)
B(-6,6,-5,STONE)
B(-6,6,-4,STONE)
B(-6,6,-3,STONE)
B(-6,6,-2,STONE)
B(-6,6,-1,STONE)
B(-6,6,0,LAVA)
B(-6,6,1,LAVA)
B(-6,6,2,LAVA)
B(-6,6,3,STONE)
B(-6,6,4,STONE)
B(-6,6,5,STONE)
B(-6,6,6,STONE)
B(-6,6,7,STONE)
B(-6,6,8,STONE)
B(-6,6,9,STONE)
B(-6,7,-6,STONE)
B(-6,7,-5,STONE)
B(-6,7,-4,STONE)
B(-6,7,-3,STONE)
B(-6,7,-2,STONE)
B(-6,7,-1,LAVA)
B(-6,7,0,LAVA)
B(-6,7,1,LAVA)
B(-6,7,2,LAVA)
B(-6,7,3,STONE)
B(-6,7,4,STONE)
B(-6,7,5,STONE)
B(-6,7,6,STONE)
B(-6,7,7,STONE)
B(-6,7,8,STONE)
B(-6,8,-6,STONE)
B(-6,8,-5,STONE)
B(-6,8,-4,STONE)
B(-6,8,-3,STONE)
B(-6,8,-2,LAVA)
B(-6,8,-1,LAVA)
B(-6,8,0,LAVA)
B(-6,8,1,LAVA)
B(-6,8,2,LAVA)
B(-6,8,3,LAVA)
B(-6,8,4,STONE)
B(-6,8,5,STONE)
B(-6,8,6,STONE)
B(-6,8,7,STONE)
B(-6,9,-5,STONE)
B(-6,9,-4,STONE)
B(-6,9,5,STONE)
B(-6,9,6,STONE)
B(-5,-14,-5,STONE)
B(-5,-14,-4,STONE)
B(-5,-14,6,STONE)
B(-5,-14,7,STONE)
B(-5,-13,-6,STONE)
B(-5,-13,-5,STONE)
B(-5,-13,-4,STONE)
B(-5,-13,-3,STONE)
B(-5,-13,-2,STONE)
B(-5,-13,-1,STONE)
B(-5,-13,0,STONE)
B(-5,-13,1,STONE)
B(-5,-13,2,STONE)
B(-5,-13,3,STONE)
B(-5,-13,4,STONE)
B(-5,-13,5,STONE)
B(-5,-13,6,STONE)
B(-5,-13,7,STONE)
B(-5,-13,8,STONE)
B(-5,-12,-6,STONE)
B(-5,-12,-5,STONE)
B(-5,-12,-4,STONE)
B(-5,-12,-3,STONE)
B(-5,-12,-2,STONE)
B(-5,-12,-1,STONE)
B(-5,-12,0,STONE)
B(-5,-12,1,STONE)
B(-5,-12,2,STONE)
B(-5,-12,3,STONE)
B(-5,-12,4,STONE)
B(-5,-12,5,STONE)
B(-5,-12,6,STONE)
B(-5,-12,7,STONE)
B(-5,-12,8,STONE)
B(-5,-11,-6,STONE)
B(-5,-11,-5,STONE)
B(-5,-11,-4,STONE)
B(-5,-11,-3,STONE)
B(-5,-11,-2,STONE)
B(-5,-11,-1,STONE)
B(-5,-11,0,STONE)
B(-5,-11,1,STONE)
B(-5,-11,2,STONE)
B(-5,-11,3,STONE)
B(-5,-11,4,STONE)
B(-5,-11,5,STONE)
B(-5,-11,6,STONE)
B(-5,-11,7,STONE)
B(-5,-11,8,STONE)
B(-5,-11,9,STONE)
B(-5,-10,-7,STONE)
B(-5,-10,-6,STONE)
B(-5,-10,-5,STONE)
B(-5,-10,-4,STONE)
B(-5,-10,-3,STONE)
B(-5,-10,-2,STONE)
B(-5,-10,-1,STONE)
B(-5,-10,0,STONE)
B(-5,-10,1,STONE)
B(-5,-10,2,STONE)
B(-5,-10,3,STONE)
B(-5,-10,4,STONE)
B(-5,-10,5,STONE)
B(-5,-10,6,STONE)
B(-5,-10,7,STONE)
B(-5,-10,8,STONE)
B(-5,-10,9,STONE)
B(-5,-10,10,STONE)
B(-5,-9,-7,STONE)
B(-5,-9,-6,STONE)
B(-5,-9,-5,STONE)
B(-5,-9,-4,STONE)
B(-5,-9,-3,STONE)
B(-5,-9,-2,STONE)
B(-5,-9,-1,STONE)
B(-5,-9,0,STONE)
B(-5,-9,1,STONE)
B(-5,-9,2,STONE)
B(-5,-9,3,STONE)
B(-5,-9,4,STONE)
B(-5,-9,5,STONE)
B(-5,-9,6,STONE)
B(-5,-9,7,STONE)
B(-5,-9,8,STONE)
B(-5,-9,9,STONE)
B(-5,-9,10,STONE)
B(-5,-9,11,STONE)
B(-5,-8,-7,STONE)
B(-5,-8,-6,STONE)
B(-5,-8,-5,STONE)
B(-5,-8,-4,STONE)
B(-5,-8,-3,STONE)
B(-5,-8,-2,STONE)
B(-5,-8,-1,STONE)
B(-5,-8,0,STONE)
B(-5,-8,1,STONE)
B(-5,-8,2,STONE)
B(-5,-8,3,STONE)
B(-5,-8,4,STONE)
B(-5,-8,5,STONE)
B(-5,-8,6,STONE)
B(-5,-8,7,STONE)
B(-5,-8,8,STONE)
B(-5,-8,9,STONE)
B(-5,-8,10,STONE)
B(-5,-8,11,STONE)
B(-5,-7,-8,STONE)
B(-5,-7,-7,STONE)
B(-5,-7,-6,STONE)
B(-5,-7,-5,STONE)
B(-5,-7,-4,STONE)
B(-5,-7,-3,STONE)
B(-5,-7,-2,STONE)
B(-5,-7,-1,STONE)
B(-5,-7,0,STONE)
B(-5,-7,1,STONE)
B(-5,-7,2,STONE)
B(-5,-7,3,STONE)
B(-5,-7,4,STONE)
B(-5,-7,5,STONE)
B(-5,-7,6,STONE)
B(-5,-7,7,STONE)
B(-5,-7,8,STONE)
B(-5,-7,9,STONE)
B(-5,-7,10,STONE)
B(-5,-7,11,STONE)
B(-5,-6,-8,STONE)
B(-5,-6,-7,STONE)
B(-5,-6,-6,STONE)
B(-5,-6,-5,STONE)
B(-5,-6,-4,STONE)
B(-5,-6,-3,STONE)
B(-5,-6,-2,STONE)
B(-5,-6,-1,STONE)
B(-5,-6,0,STONE)
B(-5,-6,1,STONE)
B(-5,-6,2,STONE)
B(-5,-6,3,STONE)
B(-5,-6,4,STONE)
B(-5,-6,5,STONE)
B(-5,-6,6,STONE)
B(-5,-6,7,STONE)
B(-5,-6,8,STONE)
B(-5,-6,9,STONE)
B(-5,-6,10,STONE)
B(-5,-6,11,STONE)
B(-5,-6,12,STONE)
B(-5,-5,-8,STONE)
B(-5,-5,-7,STONE)
B(-5,-5,-6,STONE)
B(-5,-5,-5,STONE)
B(-5,-5,-4,STONE)
B(-5,-5,-3,STONE)
B(-5,-5,-2,STONE)
B(-5,-5,-1,STONE)
B(-5,-5,0,STONE)
B(-5,-5,1,STONE)
B(-5,-5,2,STONE)
B(-5,-5,3,STONE)
B(-5,-5,4,STONE)
B(-5,-5,5,STONE)
B(-5,-5,6,STONE)
B(-5,-5,7,STONE)
B(-5,-5,8,STONE)
B(-5,-5,9,STONE)
B(-5,-5,10,STONE)
B(-5,-5,11,STONE)
B(-5,-5,12,STONE)
B(-5,-5,13,STONE)
B(-5,-4,-8,STONE)
B(-5,-4,-7,STONE)
B(-5,-4,-6,STONE)
B(-5,-4,-5,STONE)
B(-5,-4,-4,STONE)
B(-5,-4,-3,STONE)
B(-5,-4,-2,STONE)
B(-5,-4,-1,STONE)
B(-5,-4,0,STONE)
B(-5,-4,1,STONE)
B(-5,-4,2,STONE)
B(-5,-4,3,STONE)
B(-5,-4,4,STONE)
B(-5,-4,5,STONE)
B(-5,-4,6,STONE)
B(-5,-4,7,STONE)
B(-5,-4,8,STONE)
B(-5,-4,9,STONE)
B(-5,-4,10,STONE)
B(-5,-4,11,STONE)
B(-5,-4,12,STONE)
B(-5,-4,13,STONE)
B(-5,-3,-8,STONE)
B(-5,-3,-7,STONE)
B(-5,-3,-6,STONE)
B(-5,-3,-5,STONE)
B(-5,-3,-4,STONE)
B(-5,-3,-3,STONE)
B(-5,-3,-2,STONE)
B(-5,-3,-1,STONE)
B(-5,-3,0,STONE)
B(-5,-3,1,STONE)
B(-5,-3,2,STONE)
B(-5,-3,3,STONE)
B(-5,-3,4,STONE)
B(-5,-3,5,STONE)
B(-5,-3,6,STONE)
B(-5,-3,7,STONE)
B(-5,-3,8,STONE)
B(-5,-3,9,STONE)
B(-5,-3,10,STONE)
B(-5,-3,11,STONE)
B(-5,-3,12,STONE)
B(-5,-3,13,STONE)
B(-5,-3,14,STONE)
B(-5,-2,-8,STONE)
B(-5,-2,-7,STONE)
B(-5,-2,-6,STONE)
B(-5,-2,-5,STONE)
B(-5,-2,-4,STONE)
B(-5,-2,-3,STONE)
B(-5,-2,-2,STONE)
B(-5,-2,-1,STONE)
B(-5,-2,0,STONE)
B(-5,-2,1,STONE)
B(-5,-2,2,STONE)
B(-5,-2,3,STONE)
B(-5,-2,4,STONE)
B(-5,-2,5,STONE)
B(-5,-2,6,STONE)
B(-5,-2,7,STONE)
B(-5,-2,8,STONE)
B(-5,-2,9,STONE)
B(-5,-2,10,STONE)
B(-5,-2,11,STONE)
B(-5,-2,12,STONE)
B(-5,-2,13,STONE)
B(-5,-2,14,STONE)
B(-5,-1,-8,STONE)
B(-5,-1,-7,STONE)
B(-5,-1,-6,STONE)
B(-5,-1,-5,STONE)
B(-5,-1,-4,STONE)
B(-5,-1,-3,STONE)
B(-5,-1,-2,STONE)
B(-5,-1,-1,STONE)
B(-5,-1,0,STONE)
B(-5,-1,1,STONE)
B(-5,-1,2,STONE)
B(-5,-1,3,STONE)
B(-5,-1,4,STONE)
B(-5,-1,5,STONE)
B(-5,-1,6,STONE)
B(-5,-1,7,STONE)
B(-5,-1,8,STONE)
B(-5,-1,9,STONE)
B(-5,-1,10,STONE)
B(-5,-1,11,STONE)
B(-5,-1,12,STONE)
B(-5,-1,13,STONE)
B(-5,0,-8,STONE)
B(-5,0,-7,STONE)
B(-5,0,-6,STONE)
B(-5,0,-5,STONE)
B(-5,0,-4,STONE)
B(-5,0,-3,STONE)
B(-5,0,-2,STONE)
B(-5,0,-1,STONE)
B(-5,0,0,STONE)
B(-5,0,1,STONE)
B(-5,0,2,STONE)
B(-5,0,3,STONE)
B(-5,0,4,STONE)
B(-5,0,5,STONE)
B(-5,0,6,STONE)
B(-5,0,7,STONE)
B(-5,0,8,STONE)
B(-5,0,9,STONE)
B(-5,0,10,STONE)
B(-5,0,11,STONE)
B(-5,0,12,STONE)
B(-5,0,13,STONE)
B(-5,1,-8,STONE)
B(-5,1,-7,STONE)
B(-5,1,-6,STONE)
B(-5,1,-5,STONE)
B(-5,1,-4,STONE)
B(-5,1,-3,STONE)
B(-5,1,-2,STONE)
B(-5,1,-1,STONE)
B(-5,1,0,STONE)
B(-5,1,1,STONE)
B(-5,1,2,STONE)
B(-5,1,3,STONE)
B(-5,1,4,STONE)
B(-5,1,5,STONE)
B(-5,1,6,STONE)
B(-5,1,7,STONE)
B(-5,1,8,STONE)
B(-5,1,9,STONE)
B(-5,1,10,STONE)
B(-5,1,11,STONE)
B(-5,1,12,STONE)
B(-5,2,-8,STONE)
B(-5,2,-7,STONE)
B(-5,2,-6,STONE)
B(-5,2,-5,STONE)
B(-5,2,-4,STONE)
B(-5,2,-3,STONE)
B(-5,2,-2,STONE)
B(-5,2,-1,STONE)
B(-5,2,0,STONE)
B(-5,2,1,STONE)
B(-5,2,2,STONE)
B(-5,2,3,STONE)
B(-5,2,4,STONE)
B(-5,2,5,STONE)
B(-5,2,6,STONE)
B(-5,2,7,STONE)
B(-5,2,8,STONE)
B(-5,2,9,STONE)
B(-5,2,10,STONE)
B(-5,2,11,STONE)
B(-5,3,-7,STONE)
B(-5,3,-6,STONE)
B(-5,3,-5,STONE)
B(-5,3,-4,STONE)
B(-5,3,-3,STONE)
B(-5,3,-2,STONE)
B(-5,3,-1,STONE)
B(-5,3,0,STONE)
B(-5,3,1,STONE)
B(-5,3,2,STONE)
B(-5,3,3,STONE)
B(-5,3,4,STONE)
B(-5,3,5,STONE)
B(-5,3,6,STONE)
B(-5,3,7,STONE)
B(-5,3,8,STONE)
B(-5,3,9,STONE)
B(-5,3,10,STONE)
B(-5,3,11,STONE)
B(-5,4,-7,STONE)
B(-5,4,-6,STONE)
B(-5,4,-5,STONE)
B(-5,4,-4,STONE)
B(-5,4,-3,STONE)
B(-5,4,-2,STONE)
B(-5,4,-1,STONE)
B(-5,4,0,STONE)
B(-5,4,1,STONE)
B(-5,4,2,STONE)
B(-5,4,3,STONE)
B(-5,4,4,STONE)
B(-5,4,5,STONE)
B(-5,4,6,STONE)
B(-5,4,7,STONE)
B(-5,4,8,STONE)
B(-5,4,9,STONE)
B(-5,4,10,STONE)
B(-5,4,11,STONE)
B(-5,5,-7,STONE)
B(-5,5,-6,STONE)
B(-5,5,-5,STONE)
B(-5,5,-4,STONE)
B(-5,5,-3,STONE)
B(-5,5,-2,STONE)
B(-5,5,-1,STONE)
B(-5,5,0,STONE)
B(-5,5,1,LAVA)
B(-5,5,2,STONE)
B(-5,5,3,STONE)
B(-5,5,4,STONE)
B(-5,5,5,STONE)
B(-5,5,6,STONE)
B(-5,5,7,STONE)
B(-5,5,8,STONE)
B(-5,5,9,STONE)
B(-5,5,10,STONE)
B(-5,6,-6,STONE)
B(-5,6,-5,STONE)
B(-5,6,-4,STONE)
B(-5,6,-3,STONE)
B(-5,6,-2,STONE)
B(-5,6,-1,STONE)
B(-5,6,0,LAVA)
B(-5,6,1,LAVA)
B(-5,6,2,LAVA)
B(-5,6,3,STONE)
B(-5,6,4,STONE)
B(-5,6,5,STONE)
B(-5,6,6,STONE)
B(-5,6,7,STONE)
B(-5,6,8,STONE)
B(-5,6,9,STONE)
B(-5,7,-6,STONE)
B(-5,7,-5,STONE)
B(-5,7,-4,STONE)
B(-5,7,-3,STONE)
B(-5,7,-2,STONE)
B(-5,7,-1,LAVA)
B(-5,7,0,LAVA)
B(-5,7,1,LAVA)
B(-5,7,2,LAVA)
B(-5,7,3,LAVA)
B(-5,7,4,STONE)
B(-5,7,5,STONE)
B(-5,7,6,STONE)
B(-5,7,7,STONE)
B(-5,7,8,STONE)
B(-5,8,-6,STONE)
B(-5,8,-5,STONE)
B(-5,8,-4,STONE)
B(-5,8,-3,STONE)
B(-5,8,-2,LAVA)
B(-5,8,-1,LAVA)
B(-5,8,0,LAVA)
B(-5,8,1,LAVA)
B(-5,8,2,LAVA)
B(-5,8,3,LAVA)
B(-5,8,4,LAVA)
