[META]
version=2.0
spawnOnBlockType=9,1,2,3,12
spawnSunlight=True
spawnDarkness=True
spawnWater=True
spawnLava=False
underFill=False
randomRotation=True
dig=False
tree=False
branch=False
needsFoundation=False
rarity=1
collisionPercentage=99
spawnElevationMin=0
spawnElevationMax=52
spawnInBiome=Custom
[DATA]
-4,-15,-8:11.10
15,3,-8:11.10
15,4,-8:11.8
-1,15,-8:11.10
0,15,-8:11.10
0,16,-8:11.10
1,-19,-7:1.0
2,-19,-7:1.0
3,-19,-7:1.0
-1,-18,-7:1.0
0,-18,-7:1.0
1,-18,-7:1.0
2,-18,-7:1.0
3,-18,-7:1.0
4,-18,-7:1.0
-1,-17,-7:1.0
0,-17,-7:1.0
1,-17,-7:1.0
2,-17,-7:1.0
3,-17,-7:1.0
4,-17,-7:1.0
5,-17,-7:1.0
-2,-16,-7:49.0
-1,-16,-7:1.0
0,-16,-7:1.0
1,-16,-7:1.0
2,-16,-7:1.0
3,-16,-7:1.0
4,-16,-7:1.0
5,-16,-7:1.0
6,-16,-7:1.0
7,-16,-7:1.0
-4,-15,-7:11.10
-3,-15,-7:49.0
-2,-15,-7:1.0
-1,-15,-7:1.0
0,-15,-7:1.0
1,-15,-7:1.0
2,-15,-7:1.0
3,-15,-7:1.0
4,-15,-7:1.0
5,-15,-7:1.0
6,-15,-7:1.0
7,-15,-7:1.0
8,-15,-7:1.0
9,-15,-7:1.0
-8,-14,-7:1.0
-7,-14,-7:1.0
-6,-14,-7:1.0
-5,-14,-7:49.0
-4,-14,-7:49.0
-3,-14,-7:49.0
-2,-14,-7:1.0
-1,-14,-7:1.0
0,-14,-7:1.0
1,-14,-7:1.0
2,-14,-7:1.0
3,-14,-7:1.0
4,-14,-7:1.0
5,-14,-7:1.0
6,-14,-7:1.0
7,-14,-7:1.0
8,-14,-7:1.0
9,-14,-7:1.0
10,-14,-7:1.0
11,-14,-7:1.0
-8,-13,-7:1.0
-7,-13,-7:1.0
-6,-13,-7:1.0
-5,-13,-7:1.0
-4,-13,-7:49.0
-3,-13,-7:1.0
-2,-13,-7:1.0
-1,-13,-7:1.0
0,-13,-7:1.0
1,-13,-7:1.0
2,-13,-7:1.0
3,-13,-7:1.0
4,-13,-7:1.0
5,-13,-7:1.0
6,-13,-7:1.0
7,-13,-7:1.0
8,-13,-7:1.0
9,-13,-7:1.0
10,-13,-7:1.0
11,-13,-7:1.0
12,-13,-7:1.0
13,-13,-7:1.0
-9,-12,-7:1.0
-8,-12,-7:1.0
-7,-12,-7:1.0
-6,-12,-7:1.0
-5,-12,-7:1.0
-4,-12,-7:1.0
-3,-12,-7:1.0
-2,-12,-7:1.0
-1,-12,-7:1.0
0,-12,-7:1.0
1,-12,-7:1.0
2,-12,-7:1.0
3,-12,-7:1.0
4,-12,-7:1.0
5,-12,-7:1.0
6,-12,-7:1.0
7,-12,-7:1.0
8,-12,-7:1.0
9,-12,-7:1.0
10,-12,-7:1.0
11,-12,-7:1.0
12,-12,-7:1.0
13,-12,-7:1.0
14,-12,-7:1.0
-10,-11,-7:1.0
-9,-11,-7:1.0
-8,-11,-7:1.0
-7,-11,-7:1.0
-6,-11,-7:1.0
-5,-11,-7:1.0
-4,-11,-7:1.0
-3,-11,-7:1.0
-2,-11,-7:1.0
-1,-11,-7:1.0
0,-11,-7:1.0
1,-11,-7:1.0
2,-11,-7:1.0
3,-11,-7:1.0
4,-11,-7:1.0
5,-11,-7:1.0
6,-11,-7:1.0
7,-11,-7:1.0
8,-11,-7:1.0
9,-11,-7:1.0
10,-11,-7:1.0
11,-11,-7:1.0
12,-11,-7:1.0
13,-11,-7:1.0
14,-11,-7:1.0
-11,-10,-7:1.0
-10,-10,-7:1.0
-9,-10,-7:1.0
-8,-10,-7:1.0
-7,-10,-7:1.0
-6,-10,-7:1.0
-5,-10,-7:1.0
-4,-10,-7:1.0
-3,-10,-7:1.0
-2,-10,-7:1.0
-1,-10,-7:1.0
0,-10,-7:1.0
1,-10,-7:1.0
2,-10,-7:1.0
3,-10,-7:1.0
4,-10,-7:1.0
5,-10,-7:1.0
6,-10,-7:1.0
7,-10,-7:1.0
8,-10,-7:1.0
9,-10,-7:1.0
10,-10,-7:1.0
11,-10,-7:1.0
12,-10,-7:1.0
13,-10,-7:1.0
14,-10,-7:1.0
-11,-9,-7:1.0
-10,-9,-7:1.0
-9,-9,-7:1.0
-8,-9,-7:1.0
-7,-9,-7:1.0
-6,-9,-7:1.0
-5,-9,-7:1.0
-4,-9,-7:1.0
-3,-9,-7:1.0
-2,-9,-7:1.0
-1,-9,-7:1.0
0,-9,-7:1.0
1,-9,-7:1.0
2,-9,-7:1.0
3,-9,-7:1.0
4,-9,-7:1.0
5,-9,-7:1.0
6,-9,-7:1.0
7,-9,-7:1.0
8,-9,-7:1.0
9,-9,-7:1.0
10,-9,-7:1.0
11,-9,-7:1.0
12,-9,-7:1.0
13,-9,-7:1.0
14,-9,-7:1.0
15,-9,-7:1.0
-11,-8,-7:1.0
-10,-8,-7:1.0
-9,-8,-7:1.0
-8,-8,-7:1.0
-7,-8,-7:1.0
-6,-8,-7:1.0
-5,-8,-7:1.0
-4,-8,-7:1.0
-3,-8,-7:1.0
-2,-8,-7:1.0
-1,-8,-7:1.0
0,-8,-7:1.0
1,-8,-7:1.0
2,-8,-7:1.0
3,-8,-7:1.0
4,-8,-7:1.0
5,-8,-7:1.0
6,-8,-7:1.0
7,-8,-7:1.0
8,-8,-7:1.0
9,-8,-7:1.0
10,-8,-7:1.0
11,-8,-7:1.0
12,-8,-7:1.0
13,-8,-7:1.0
14,-8,-7:1.0
15,-8,-7:1.0
-11,-7,-7:1.0
-10,-7,-7:1.0
-9,-7,-7:1.0
-8,-7,-7:1.0
-7,-7,-7:1.0
-6,-7,-7:1.0
-5,-7,-7:1.0
-4,-7,-7:1.0
-3,-7,-7:1.0
-2,-7,-7:1.0
-1,-7,-7:1.0
0,-7,-7:1.0
1,-7,-7:1.0
2,-7,-7:1.0
3,-7,-7:1.0
4,-7,-7:1.0
5,-7,-7:1.0
6,-7,-7:1.0
7,-7,-7:1.0
8,-7,-7:1.0
9,-7,-7:1.0
10,-7,-7:1.0
11,-7,-7:1.0
12,-7,-7:1.0
13,-7,-7:1.0
14,-7,-7:1.0
15,-7,-7:1.0
-11,-6,-7:1.0
-10,-6,-7:1.0
-9,-6,-7:1.0
-8,-6,-7:1.0
-7,-6,-7:1.0
-6,-6,-7:1.0
-5,-6,-7:1.0
-4,-6,-7:1.0
-3,-6,-7:1.0
-2,-6,-7:1.0
-1,-6,-7:1.0
0,-6,-7:1.0
1,-6,-7:1.0
2,-6,-7:1.0
3,-6,-7:1.0
4,-6,-7:1.0
5,-6,-7:1.0
6,-6,-7:1.0
7,-6,-7:1.0
8,-6,-7:1.0
9,-6,-7:1.0
10,-6,-7:1.0
11,-6,-7:1.0
12,-6,-7:1.0
13,-6,-7:1.0
14,-6,-7:1.0
15,-6,-7:1.0
-12,-5,-7:1.0
-11,-5,-7:1.0
-10,-5,-7:1.0
-9,-5,-7:1.0
-8,-5,-7:1.0
-7,-5,-7:1.0
-6,-5,-7:1.0
-5,-5,-7:1.0
-4,-5,-7:1.0
-3,-5,-7:1.0
-2,-5,-7:1.0
-1,-5,-7:1.0
0,-5,-7:1.0
1,-5,-7:1.0
2,-5,-7:1.0
3,-5,-7:1.0
4,-5,-7:1.0
5,-5,-7:1.0
6,-5,-7:1.0
7,-5,-7:1.0
8,-5,-7:1.0
9,-5,-7:1.0
10,-5,-7:1.0
11,-5,-7:1.0
12,-5,-7:1.0
13,-5,-7:1.0
14,-5,-7:1.0
-14,-4,-7:1.0
-13,-4,-7:1.0
-12,-4,-7:1.0
-11,-4,-7:1.0
-10,-4,-7:1.0
-9,-4,-7:1.0
-8,-4,-7:1.0
-7,-4,-7:1.0
-6,-4,-7:1.0
-5,-4,-7:1.0
-4,-4,-7:1.0
-3,-4,-7:1.0
-2,-4,-7:1.0
-1,-4,-7:1.0
0,-4,-7:1.0
1,-4,-7:1.0
2,-4,-7:1.0
3,-4,-7:1.0
4,-4,-7:1.0
5,-4,-7:1.0
6,-4,-7:1.0
7,-4,-7:1.0
8,-4,-7:1.0
9,-4,-7:1.0
10,-4,-7:1.0
11,-4,-7:1.0
12,-4,-7:1.0
13,-4,-7:1.0
14,-4,-7:1.0
-14,-3,-7:1.0
-13,-3,-7:1.0
-12,-3,-7:1.0
-11,-3,-7:1.0
-10,-3,-7:1.0
-9,-3,-7:1.0
-8,-3,-7:1.0
-7,-3,-7:1.0
-6,-3,-7:1.0
-5,-3,-7:1.0
-4,-3,-7:1.0
-3,-3,-7:1.0
-2,-3,-7:1.0
-1,-3,-7:1.0
0,-3,-7:1.0
1,-3,-7:1.0
2,-3,-7:1.0
3,-3,-7:1.0
4,-3,-7:1.0
5,-3,-7:1.0
6,-3,-7:1.0
7,-3,-7:1.0
8,-3,-7:1.0
9,-3,-7:1.0
10,-3,-7:1.0
11,-3,-7:1.0
12,-3,-7:1.0
13,-3,-7:1.0
14,-3,-7:1.0
-14,-2,-7:1.0
-13,-2,-7:1.0
-12,-2,-7:1.0
-11,-2,-7:1.0
-10,-2,-7:1.0
-9,-2,-7:1.0
-8,-2,-7:1.0
-7,-2,-7:1.0
-6,-2,-7:1.0
-5,-2,-7:1.0
-4,-2,-7:1.0
-3,-2,-7:1.0
-2,-2,-7:1.0
-1,-2,-7:1.0
0,-2,-7:1.0
1,-2,-7:1.0
2,-2,-7:1.0
3,-2,-7:1.0
4,-2,-7:1.0
5,-2,-7:1.0
6,-2,-7:1.0
7,-2,-7:1.0
8,-2,-7:1.0
9,-2,-7:1.0
10,-2,-7:1.0
11,-2,-7:1.0
12,-2,-7:1.0
13,-2,-7:1.0
14,-2,-7:1.0
-14,-1,-7:1.0
-13,-1,-7:1.0
-12,-1,-7:1.0
-11,-1,-7:1.0
-10,-1,-7:1.0
-9,-1,-7:1.0
-8,-1,-7:1.0
-7,-1,-7:1.0
-6,-1,-7:1.0
-5,-1,-7:1.0
-4,-1,-7:1.0
-3,-1,-7:1.0
-2,-1,-7:1.0
-1,-1,-7:1.0
0,-1,-7:1.0
1,-1,-7:1.0
2,-1,-7:1.0
3,-1,-7:1.0
4,-1,-7:1.0
5,-1,-7:1.0
6,-1,-7:1.0
7,-1,-7:1.0
8,-1,-7:1.0
9,-1,-7:1.0
10,-1,-7:1.0
11,-1,-7:1.0
12,-1,-7:1.0
13,-1,-7:1.0
14,-1,-7:1.0
-13,0,-7:1.0
-12,0,-7:1.0
-11,0,-7:1.0
-10,0,-7:1.0
-9,0,-7:1.0
-8,0,-7:1.0
-7,0,-7:1.0
-6,0,-7:1.0
-5,0,-7:1.0
-4,0,-7:1.0
-3,0,-7:1.0
-2,0,-7:1.0
-1,0,-7:1.0
0,0,-7:1.0
1,0,-7:1.0
2,0,-7:1.0
3,0,-7:1.0
4,0,-7:1.0
5,0,-7:1.0
6,0,-7:1.0
7,0,-7:1.0
8,0,-7:1.0
9,0,-7:1.0
10,0,-7:1.0
11,0,-7:1.0
12,0,-7:1.0
13,0,-7:1.0
14,0,-7:1.0
-14,1,-7:1.0
-13,1,-7:1.0
-12,1,-7:1.0
-11,1,-7:1.0
-10,1,-7:1.0
-9,1,-7:1.0
-8,1,-7:1.0
-7,1,-7:1.0
-6,1,-7:1.0
-5,1,-7:1.0
-4,1,-7:1.0
-3,1,-7:1.0
-2,1,-7:1.0
-1,1,-7:1.0
0,1,-7:1.0
1,1,-7:1.0
2,1,-7:1.0
3,1,-7:1.0
4,1,-7:1.0
5,1,-7:1.0
6,1,-7:1.0
7,1,-7:1.0
8,1,-7:1.0
9,1,-7:1.0
10,1,-7:1.0
11,1,-7:1.0
12,1,-7:1.0
13,1,-7:1.0
14,1,-7:49.0
-14,2,-7:1.0
-13,2,-7:1.0
-12,2,-7:1.0
-11,2,-7:1.0
-10,2,-7:1.0
-9,2,-7:1.0
-8,2,-7:1.0
-7,2,-7:1.0
-6,2,-7:1.0
-5,2,-7:1.0
-4,2,-7:1.0
-3,2,-7:1.0
-2,2,-7:1.0
-1,2,-7:1.0
0,2,-7:1.0
1,2,-7:1.0
2,2,-7:1.0
3,2,-7:1.0
4,2,-7:1.0
5,2,-7:1.0
6,2,-7:1.0
7,2,-7:1.0
8,2,-7:1.0
9,2,-7:1.0
10,2,-7:1.0
11,2,-7:1.0
12,2,-7:1.0
13,2,-7:49.0
14,2,-7:49.0
-14,3,-7:1.0
-13,3,-7:1.0
-12,3,-7:1.0
-11,3,-7:1.0
-10,3,-7:1.0
-9,3,-7:1.0
-8,3,-7:1.0
-7,3,-7:1.0
-6,3,-7:1.0
-5,3,-7:1.0
-4,3,-7:1.0
-3,3,-7:1.0
-2,3,-7:1.0
-1,3,-7:1.0
0,3,-7:1.0
1,3,-7:1.0
2,3,-7:1.0
3,3,-7:1.0
4,3,-7:1.0
5,3,-7:1.0
6,3,-7:1.0
7,3,-7:1.0
8,3,-7:1.0
9,3,-7:1.0
10,3,-7:1.0
11,3,-7:1.0
12,3,-7:1.0
13,3,-7:49.0
14,3,-7:49.0
15,3,-7:11.10
-14,4,-7:1.0
-13,4,-7:1.0
-12,4,-7:1.0
-11,4,-7:1.0
-10,4,-7:1.0
-9,4,-7:1.0
-8,4,-7:1.0
-7,4,-7:1.0
-6,4,-7:1.0
-5,4,-7:1.0
-4,4,-7:1.0
-3,4,-7:1.0
-2,4,-7:1.0
-1,4,-7:1.0
0,4,-7:1.0
1,4,-7:1.0
2,4,-7:1.0
3,4,-7:1.0
4,4,-7:1.0
5,4,-7:1.0
6,4,-7:1.0
7,4,-7:1.0
8,4,-7:1.0
9,4,-7:1.0
10,4,-7:1.0
11,4,-7:1.0
12,4,-7:1.0
13,4,-7:1.0
14,4,-7:49.0
15,4,-7:11.0
16,4,-7:49.0
-14,5,-7:1.0
-13,5,-7:1.0
-12,5,-7:1.0
-11,5,-7:1.0
-10,5,-7:1.0
-9,5,-7:1.0
-8,5,-7:1.0
-7,5,-7:1.0
-6,5,-7:1.0
-5,5,-7:1.0
-4,5,-7:1.0
-3,5,-7:1.0
-2,5,-7:1.0
-1,5,-7:1.0
0,5,-7:1.0
1,5,-7:1.0
2,5,-7:1.0
3,5,-7:1.0
4,5,-7:1.0
5,5,-7:1.0
6,5,-7:1.0
7,5,-7:1.0
8,5,-7:1.0
9,5,-7:1.0
10,5,-7:1.0
11,5,-7:1.0
12,5,-7:1.0
13,5,-7:1.0
14,5,-7:1.0
15,5,-7:1.0
16,5,-7:49.0
-13,6,-7:1.0
-12,6,-7:1.0
-11,6,-7:1.0
-10,6,-7:1.0
-9,6,-7:1.0
-8,6,-7:1.0
-7,6,-7:1.0
-6,6,-7:1.0
-5,6,-7:1.0
-4,6,-7:1.0
-3,6,-7:1.0
-2,6,-7:1.0
-1,6,-7:1.0
0,6,-7:1.0
1,6,-7:1.0
2,6,-7:1.0
3,6,-7:1.0
4,6,-7:1.0
5,6,-7:1.0
6,6,-7:1.0
7,6,-7:1.0
8,6,-7:1.0
9,6,-7:1.0
10,6,-7:1.0
11,6,-7:1.0
12,6,-7:1.0
13,6,-7:1.0
14,6,-7:1.0
15,6,-7:1.0
-12,7,-7:1.0
-11,7,-7:1.0
-10,7,-7:1.0
-9,7,-7:1.0
-8,7,-7:1.0
-7,7,-7:1.0
-6,7,-7:1.0
-5,7,-7:1.0
-4,7,-7:1.0
-3,7,-7:1.0
-2,7,-7:1.0
-1,7,-7:1.0
0,7,-7:1.0
1,7,-7:1.0
2,7,-7:1.0
3,7,-7:1.0
4,7,-7:1.0
5,7,-7:1.0
6,7,-7:1.0
7,7,-7:1.0
8,7,-7:1.0
9,7,-7:1.0
10,7,-7:1.0
11,7,-7:1.0
12,7,-7:1.0
13,7,-7:1.0
14,7,-7:1.0
15,7,-7:1.0
-10,8,-7:1.0
-9,8,-7:1.0
-8,8,-7:1.0
-7,8,-7:1.0
-6,8,-7:1.0
-5,8,-7:1.0
-4,8,-7:1.0
-3,8,-7:1.0
-2,8,-7:1.0
-1,8,-7:1.0
0,8,-7:1.0
1,8,-7:1.0
2,8,-7:1.0
3,8,-7:1.0
4,8,-7:1.0
5,8,-7:1.0
6,8,-7:1.0
7,8,-7:1.0
8,8,-7:1.0
9,8,-7:1.0
10,8,-7:1.0
11,8,-7:1.0
12,8,-7:1.0
13,8,-7:1.0
14,8,-7:1.0
15,8,-7:1.0
-10,9,-7:1.0
-9,9,-7:1.0
-8,9,-7:1.0
-7,9,-7:1.0
-6,9,-7:1.0
-5,9,-7:1.0
-4,9,-7:1.0
-3,9,-7:1.0
-2,9,-7:1.0
-1,9,-7:1.0
0,9,-7:1.0
1,9,-7:1.0
2,9,-7:1.0
3,9,-7:1.0
4,9,-7:1.0
5,9,-7:1.0
6,9,-7:1.0
7,9,-7:1.0
8,9,-7:1.0
9,9,-7:1.0
10,9,-7:1.0
11,9,-7:1.0
12,9,-7:1.0
13,9,-7:1.0
14,9,-7:1.0
15,9,-7:1.0
-9,10,-7:1.0
-8,10,-7:1.0
-7,10,-7:1.0
-6,10,-7:1.0
-5,10,-7:1.0
-4,10,-7:1.0
-3,10,-7:1.0
-2,10,-7:1.0
-1,10,-7:1.0
0,10,-7:1.0
1,10,-7:1.0
2,10,-7:1.0
3,10,-7:1.0
4,10,-7:1.0
5,10,-7:1.0
6,10,-7:1.0
7,10,-7:1.0
8,10,-7:1.0
9,10,-7:1.0
10,10,-7:1.0
11,10,-7:1.0
12,10,-7:1.0
13,10,-7:1.0
-7,11,-7:1.0
-6,11,-7:1.0
-5,11,-7:1.0
-4,11,-7:1.0
-3,11,-7:1.0
-2,11,-7:1.0
-1,11,-7:1.0
0,11,-7:1.0
1,11,-7:1.0
2,11,-7:1.0
3,11,-7:1.0
4,11,-7:1.0
5,11,-7:1.0
6,11,-7:1.0
7,11,-7:1.0
8,11,-7:1.0
9,11,-7:1.0
10,11,-7:1.0
11,11,-7:1.0
-6,12,-7:1.0
-5,12,-7:1.0
-4,12,-7:1.0
-3,12,-7:1.0
-2,12,-7:1.0
-1,12,-7:1.0
0,12,-7:1.0
1,12,-7:1.0
2,12,-7:1.0
3,12,-7:1.0
4,12,-7:1.0
5,12,-7:1.0
6,12,-7:1.0
7,12,-7:1.0
8,12,-7:1.0
9,12,-7:1.0
10,12,-7:1.0
-4,13,-7:49.0
-3,13,-7:49.0
-2,13,-7:49.0
-1,13,-7:49.0
0,13,-7:49.0
1,13,-7:49.0
2,13,-7:1.0
3,13,-7:1.0
4,13,-7:1.0
5,13,-7:1.0
6,13,-7:1.0
7,13,-7:1.0
8,13,-7:1.0
9,13,-7:1.0
-3,14,-7:49.0
-2,14,-7:49.0
-1,14,-7:49.0
0,14,-7:49.0
1,14,-7:49.0
2,14,-7:49.0
3,14,-7:49.0
4,14,-7:49.0
5,14,-7:1.0
6,14,-7:1.0
7,14,-7:1.0
8,14,-7:1.0
-1,15,-7:11.10
0,15,-7:11.10
1,15,-7:49.0
2,15,-7:49.0
3,15,-7:49.0
4,15,-7:49.0
5,15,-7:1.0
6,15,-7:1.0
0,16,-7:11.2
1,-19,-6:13.0
2,-19,-6:13.0
3,-19,-6:13.0
-1,-18,-6:1.0
0,-18,-6:1.0
1,-18,-6:1.0
2,-18,-6:1.0
3,-18,-6:1.0
4,-18,-6:13.0
-1,-17,-6:1.0
0,-17,-6:1.0
1,-17,-6:1.0
2,-17,-6:1.0
3,-17,-6:1.0
4,-17,-6:1.0
5,-17,-6:13.0
-2,-16,-6:13.0
-1,-16,-6:1.0
0,-16,-6:1.0
1,-16,-6:1.0
2,-16,-6:1.0
3,-16,-6:1.0
4,-16,-6:1.0
5,-16,-6:1.0
6,-16,-6:1.0
7,-16,-6:13.0
-4,-15,-6:11.10
-3,-15,-6:49.0
-2,-15,-6:49.0
-1,-15,-6:1.0
0,-15,-6:1.0
1,-15,-6:1.0
2,-15,-6:1.0
3,-15,-6:1.0
4,-15,-6:1.0
5,-15,-6:1.0
6,-15,-6:1.0
7,-15,-6:1.0
8,-15,-6:1.0
9,-15,-6:1.0
-8,-14,-6:13.0
-7,-14,-6:13.0
-6,-14,-6:13.0
-5,-14,-6:49.0
-4,-14,-6:49.0
-3,-14,-6:49.0
-2,-14,-6:1.0
-1,-14,-6:1.0
0,-14,-6:1.0
1,-14,-6:1.0
2,-14,-6:1.0
3,-14,-6:1.0
4,-14,-6:1.0
5,-14,-6:1.0
6,-14,-6:1.0
7,-14,-6:1.0
8,-14,-6:1.0
9,-14,-6:1.0
10,-14,-6:1.0
11,-14,-6:1.0
-8,-13,-6:1.0
-7,-13,-6:1.0
-6,-13,-6:1.0
-5,-13,-6:49.0
-4,-13,-6:49.0
-3,-13,-6:49.0
-2,-13,-6:49.0
-1,-13,-6:1.0
0,-13,-6:1.0
1,-13,-6:1.0
2,-13,-6:1.0
3,-13,-6:1.0
4,-13,-6:1.0
5,-13,-6:1.0
6,-13,-6:1.0
7,-13,-6:1.0
8,-13,-6:1.0
9,-13,-6:1.0
10,-13,-6:1.0
11,-13,-6:1.0
12,-13,-6:1.0
13,-13,-6:1.0
-9,-12,-6:1.0
-8,-12,-6:1.0
-7,-12,-6:1.0
-6,-12,-6:1.0
-5,-12,-6:1.0
-4,-12,-6:1.0
-3,-12,-6:49.0
-2,-12,-6:1.0
-1,-12,-6:1.0
0,-12,-6:1.0
1,-12,-6:1.0
2,-12,-6:1.0
3,-12,-6:1.0
4,-12,-6:1.0
5,-12,-6:1.0
6,-12,-6:1.0
7,-12,-6:1.0
8,-12,-6:1.0
9,-12,-6:1.0
10,-12,-6:1.0
11,-12,-6:1.0
12,-12,-6:1.0
13,-12,-6:1.0
14,-12,-6:13.0
-10,-11,-6:1.0
-9,-11,-6:1.0
-8,-11,-6:1.0
-7,-11,-6:1.0
-6,-11,-6:1.0
-5,-11,-6:1.0
-4,-11,-6:1.0
-3,-11,-6:1.0
-2,-11,-6:1.0
-1,-11,-6:1.0
0,-11,-6:1.0
1,-11,-6:1.0
2,-11,-6:1.0
3,-11,-6:1.0
4,-11,-6:1.0
5,-11,-6:1.0
6,-11,-6:1.0
7,-11,-6:1.0
8,-11,-6:1.0
9,-11,-6:1.0
10,-11,-6:1.0
11,-11,-6:1.0
12,-11,-6:1.0
13,-11,-6:1.0
14,-11,-6:13.0
-11,-10,-6:13.0
-10,-10,-6:1.0
-9,-10,-6:1.0
-8,-10,-6:1.0
-7,-10,-6:1.0
-6,-10,-6:1.0
-5,-10,-6:1.0
-4,-10,-6:1.0
-3,-10,-6:1.0
-2,-10,-6:1.0
-1,-10,-6:1.0
0,-10,-6:1.0
1,-10,-6:1.0
2,-10,-6:1.0
3,-10,-6:1.0
4,-10,-6:1.0
5,-10,-6:1.0
6,-10,-6:1.0
7,-10,-6:1.0
8,-10,-6:1.0
9,-10,-6:1.0
10,-10,-6:1.0
11,-10,-6:1.0
12,-10,-6:1.0
13,-10,-6:1.0
14,-10,-6:1.0
-11,-9,-6:1.0
-10,-9,-6:1.0
-9,-9,-6:1.0
-8,-9,-6:1.0
-7,-9,-6:1.0
-6,-9,-6:1.0
-5,-9,-6:1.0
-4,-9,-6:1.0
-3,-9,-6:1.0
-2,-9,-6:1.0
-1,-9,-6:1.0
0,-9,-6:1.0
1,-9,-6:1.0
2,-9,-6:1.0
3,-9,-6:1.0
4,-9,-6:1.0
5,-9,-6:1.0
6,-9,-6:1.0
7,-9,-6:1.0
8,-9,-6:1.0
9,-9,-6:1.0
10,-9,-6:1.0
11,-9,-6:1.0
12,-9,-6:1.0
13,-9,-6:1.0
14,-9,-6:1.0
15,-9,-6:1.0
-11,-8,-6:1.0
-10,-8,-6:1.0
-9,-8,-6:1.0
-8,-8,-6:1.0
-7,-8,-6:1.0
-6,-8,-6:1.0
-5,-8,-6:1.0
-4,-8,-6:1.0
-3,-8,-6:1.0
-2,-8,-6:1.0
-1,-8,-6:1.0
0,-8,-6:1.0
1,-8,-6:1.0
2,-8,-6:1.0
3,-8,-6:1.0
4,-8,-6:1.0
5,-8,-6:1.0
6,-8,-6:1.0
7,-8,-6:1.0
8,-8,-6:1.0
9,-8,-6:1.0
10,-8,-6:1.0
11,-8,-6:1.0
12,-8,-6:1.0
13,-8,-6:1.0
14,-8,-6:1.0
15,-8,-6:1.0
-11,-7,-6:1.0
-10,-7,-6:1.0
-9,-7,-6:1.0
-8,-7,-6:1.0
-7,-7,-6:1.0
-6,-7,-6:1.0
-5,-7,-6:1.0
-4,-7,-6:1.0
-3,-7,-6:1.0
-2,-7,-6:1.0
-1,-7,-6:1.0
0,-7,-6:1.0
1,-7,-6:1.0
2,-7,-6:1.0
3,-7,-6:1.0
4,-7,-6:1.0
5,-7,-6:1.0
6,-7,-6:1.0
7,-7,-6:1.0
8,-7,-6:1.0
9,-7,-6:1.0
10,-7,-6:1.0
11,-7,-6:1.0
12,-7,-6:1.0
13,-7,-6:1.0
14,-7,-6:1.0
15,-7,-6:1.0
-11,-6,-6:1.0
-10,-6,-6:1.0
-9,-6,-6:1.0
-8,-6,-6:1.0
-7,-6,-6:1.0
-6,-6,-6:1.0
-5,-6,-6:1.0
-4,-6,-6:1.0
-3,-6,-6:1.0
-2,-6,-6:1.0
-1,-6,-6:1.0
0,-6,-6:1.0
1,-6,-6:1.0
2,-6,-6:1.0
3,-6,-6:1.0
4,-6,-6:1.0
5,-6,-6:1.0
6,-6,-6:1.0
7,-6,-6:1.0
8,-6,-6:1.0
9,-6,-6:1.0
10,-6,-6:1.0
11,-6,-6:1.0
12,-6,-6:1.0
13,-6,-6:1.0
14,-6,-6:1.0
15,-6,-6:1.0
-12,-5,-6:1.0
-11,-5,-6:1.0
-10,-5,-6:1.0
-9,-5,-6:1.0
-8,-5,-6:1.0
-7,-5,-6:1.0
-6,-5,-6:1.0
-5,-5,-6:1.0
-4,-5,-6:1.0
-3,-5,-6:1.0
-2,-5,-6:1.0
-1,-5,-6:1.0
0,-5,-6:1.0
1,-5,-6:1.0
2,-5,-6:1.0
3,-5,-6:1.0
4,-5,-6:1.0
5,-5,-6:1.0
6,-5,-6:1.0
7,-5,-6:1.0
8,-5,-6:1.0
9,-5,-6:1.0
10,-5,-6:1.0
11,-5,-6:1.0
12,-5,-6:1.0
13,-5,-6:1.0
14,-5,-6:1.0
-14,-4,-6:13.0
-13,-4,-6:1.0
-12,-4,-6:1.0
-11,-4,-6:1.0
-10,-4,-6:1.0
-9,-4,-6:1.0
-8,-4,-6:1.0
-7,-4,-6:1.0
-6,-4,-6:1.0
-5,-4,-6:1.0
-4,-4,-6:1.0
-3,-4,-6:1.0
-2,-4,-6:1.0
-1,-4,-6:1.0
0,-4,-6:1.0
1,-4,-6:1.0
2,-4,-6:1.0
3,-4,-6:1.0
4,-4,-6:1.0
5,-4,-6:1.0
6,-4,-6:1.0
7,-4,-6:1.0
8,-4,-6:1.0
9,-4,-6:1.0
10,-4,-6:1.0
11,-4,-6:1.0
12,-4,-6:1.0
13,-4,-6:1.0
14,-4,-6:1.0
-14,-3,-6:13.0
-13,-3,-6:1.0
-12,-3,-6:1.0
-11,-3,-6:1.0
-10,-3,-6:1.0
-9,-3,-6:1.0
-8,-3,-6:1.0
-7,-3,-6:1.0
-6,-3,-6:1.0
-5,-3,-6:1.0
-4,-3,-6:1.0
-3,-3,-6:1.0
-2,-3,-6:1.0
-1,-3,-6:1.0
0,-3,-6:11.0
1,-3,-6:11.0
2,-3,-6:11.0
3,-3,-6:1.0
4,-3,-6:1.0
5,-3,-6:1.0
6,-3,-6:1.0
7,-3,-6:1.0
8,-3,-6:1.0
9,-3,-6:1.0
10,-3,-6:1.0
11,-3,-6:1.0
12,-3,-6:1.0
13,-3,-6:1.0
14,-3,-6:1.0
-14,-2,-6:13.0
-13,-2,-6:1.0
-12,-2,-6:1.0
-11,-2,-6:1.0
-10,-2,-6:1.0
-9,-2,-6:1.0
-8,-2,-6:1.0
-7,-2,-6:1.0
-6,-2,-6:1.0
-5,-2,-6:1.0
-4,-2,-6:1.0
-3,-2,-6:1.0
-2,-2,-6:1.0
-1,-2,-6:1.0
0,-2,-6:11.0
1,-2,-6:11.0
2,-2,-6:11.0
3,-2,-6:1.0
4,-2,-6:1.0
5,-2,-6:1.0
6,-2,-6:1.0
7,-2,-6:1.0
8,-2,-6:1.0
9,-2,-6:1.0
10,-2,-6:1.0
11,-2,-6:1.0
12,-2,-6:1.0
13,-2,-6:1.0
14,-2,-6:1.0
-14,-1,-6:13.0
-13,-1,-6:1.0
-12,-1,-6:1.0
-11,-1,-6:1.0
-10,-1,-6:1.0
-9,-1,-6:1.0
-8,-1,-6:1.0
-7,-1,-6:1.0
-6,-1,-6:1.0
-5,-1,-6:1.0
-4,-1,-6:1.0
-3,-1,-6:1.0
-2,-1,-6:1.0
-1,-1,-6:1.0
0,-1,-6:11.0
1,-1,-6:11.0
2,-1,-6:11.0
3,-1,-6:1.0
4,-1,-6:1.0
5,-1,-6:1.0
6,-1,-6:1.0
7,-1,-6:1.0
8,-1,-6:1.0
9,-1,-6:1.0
10,-1,-6:1.0
11,-1,-6:1.0
12,-1,-6:1.0
13,-1,-6:1.0
14,-1,-6:1.0
-13,0,-6:1.0
-12,0,-6:1.0
-11,0,-6:1.0
-10,0,-6:1.0
-9,0,-6:1.0
-8,0,-6:1.0
-7,0,-6:1.0
-6,0,-6:1.0
-5,0,-6:1.0
-4,0,-6:1.0
-3,0,-6:1.0
-2,0,-6:1.0
-1,0,-6:1.0
0,0,-6:1.0
1,0,-6:1.0
2,0,-6:1.0
3,0,-6:1.0
4,0,-6:1.0
5,0,-6:1.0
6,0,-6:1.0
7,0,-6:1.0
8,0,-6:1.0
9,0,-6:1.0
10,0,-6:1.0
11,0,-6:1.0
12,0,-6:1.0
13,0,-6:1.0
14,0,-6:49.0
-14,1,-6:13.0
-13,1,-6:1.0
-12,1,-6:1.0
-11,1,-6:1.0
-10,1,-6:1.0
-9,1,-6:1.0
-8,1,-6:1.0
-7,1,-6:1.0
-6,1,-6:1.0
-5,1,-6:1.0
-4,1,-6:1.0
-3,1,-6:1.0
-2,1,-6:1.0
-1,1,-6:1.0
0,1,-6:1.0
1,1,-6:1.0
2,1,-6:1.0
3,1,-6:1.0
4,1,-6:1.0
5,1,-6:1.0
6,1,-6:1.0
7,1,-6:1.0
8,1,-6:1.0
9,1,-6:1.0
10,1,-6:1.0
11,1,-6:1.0
12,1,-6:1.0
13,1,-6:49.0
14,1,-6:49.0
-14,2,-6:13.0
-13,2,-6:1.0
-12,2,-6:1.0
-11,2,-6:1.0
-10,2,-6:1.0
-9,2,-6:1.0
-8,2,-6:1.0
-7,2,-6:1.0
-6,2,-6:1.0
-5,2,-6:1.0
-4,2,-6:1.0
-3,2,-6:1.0
-2,2,-6:1.0
-1,2,-6:1.0
0,2,-6:1.0
1,2,-6:1.0
2,2,-6:1.0
3,2,-6:1.0
4,2,-6:1.0
5,2,-6:1.0
6,2,-6:1.0
7,2,-6:1.0
8,2,-6:1.0
9,2,-6:1.0
10,2,-6:1.0
11,2,-6:1.0
12,2,-6:1.0
13,2,-6:49.0
14,2,-6:49.0
-14,3,-6:13.0
-13,3,-6:1.0
-12,3,-6:1.0
-11,3,-6:1.0
-10,3,-6:1.0
-9,3,-6:1.0
-8,3,-6:1.0
-7,3,-6:1.0
-6,3,-6:1.0
-5,3,-6:1.0
-4,3,-6:1.0
-3,3,-6:1.0
-2,3,-6:1.0
-1,3,-6:1.0
0,3,-6:1.0
1,3,-6:1.0
2,3,-6:1.0
3,3,-6:1.0
4,3,-6:1.0
5,3,-6:1.0
6,3,-6:1.0
7,3,-6:1.0
8,3,-6:1.0
9,3,-6:1.0
10,3,-6:1.0
11,3,-6:1.0
12,3,-6:1.0
13,3,-6:49.0
14,3,-6:49.0
15,3,-6:11.10
-14,4,-6:13.0
-13,4,-6:1.0
-12,4,-6:1.0
-11,4,-6:1.0
-10,4,-6:1.0
-9,4,-6:1.0
-8,4,-6:1.0
-7,4,-6:1.0
-6,4,-6:1.0
-5,4,-6:1.0
-4,4,-6:1.0
-3,4,-6:1.0
-2,4,-6:1.0
-1,4,-6:1.0
0,4,-6:1.0
1,4,-6:1.0
2,4,-6:1.0
3,4,-6:1.0
4,4,-6:1.0
5,4,-6:1.0
6,4,-6:1.0
7,4,-6:1.0
8,4,-6:1.0
9,4,-6:1.0
10,4,-6:1.0
11,4,-6:1.0
12,4,-6:1.0
13,4,-6:49.0
14,4,-6:49.0
15,4,-6:11.10
16,4,-6:49.0
-14,5,-6:13.0
-13,5,-6:1.0
-12,5,-6:1.0
-11,5,-6:1.0
-10,5,-6:1.0
-9,5,-6:1.0
-8,5,-6:1.0
-7,5,-6:1.0
-6,5,-6:1.0
-5,5,-6:1.0
-4,5,-6:1.0
-3,5,-6:1.0
-2,5,-6:1.0
-1,5,-6:1.0
0,5,-6:1.0
1,5,-6:1.0
2,5,-6:1.0
3,5,-6:1.0
4,5,-6:1.0
5,5,-6:1.0
6,5,-6:1.0
7,5,-6:1.0
8,5,-6:1.0
9,5,-6:1.0
10,5,-6:1.0
11,5,-6:1.0
12,5,-6:1.0
13,5,-6:1.0
14,5,-6:49.0
15,5,-6:49.0
16,5,-6:49.0
-13,6,-6:13.0
-12,6,-6:1.0
-11,6,-6:1.0
-10,6,-6:1.0
-9,6,-6:1.0
-8,6,-6:1.0
-7,6,-6:1.0
-6,6,-6:1.0
-5,6,-6:1.0
-4,6,-6:1.0
-3,6,-6:1.0
-2,6,-6:1.0
-1,6,-6:1.0
0,6,-6:1.0
1,6,-6:1.0
2,6,-6:1.0
3,6,-6:1.0
4,6,-6:1.0
5,6,-6:1.0
6,6,-6:1.0
7,6,-6:1.0
8,6,-6:1.0
9,6,-6:1.0
10,6,-6:1.0
11,6,-6:1.0
12,6,-6:1.0
13,6,-6:1.0
14,6,-6:1.0
15,6,-6:1.0
-12,7,-6:13.0
-11,7,-6:1.0
-10,7,-6:1.0
-9,7,-6:1.0
-8,7,-6:1.0
-7,7,-6:1.0
-6,7,-6:1.0
-5,7,-6:1.0
-4,7,-6:1.0
-3,7,-6:1.0
-2,7,-6:1.0
-1,7,-6:1.0
0,7,-6:1.0
1,7,-6:1.0
2,7,-6:1.0
3,7,-6:1.0
4,7,-6:1.0
5,7,-6:1.0
6,7,-6:1.0
7,7,-6:1.0
8,7,-6:1.0
9,7,-6:1.0
10,7,-6:1.0
11,7,-6:1.0
12,7,-6:1.0
13,7,-6:1.0
14,7,-6:1.0
15,7,-6:1.0
-10,8,-6:1.0
-9,8,-6:1.0
-8,8,-6:1.0
-7,8,-6:1.0
-6,8,-6:1.0
-5,8,-6:1.0
-4,8,-6:1.0
-3,8,-6:1.0
-2,8,-6:1.0
-1,8,-6:1.0
0,8,-6:1.0
1,8,-6:1.0
2,8,-6:1.0
3,8,-6:1.0
4,8,-6:1.0
5,8,-6:1.0
6,8,-6:1.0
7,8,-6:1.0
8,8,-6:1.0
9,8,-6:1.0
10,8,-6:1.0
11,8,-6:1.0
12,8,-6:1.0
13,8,-6:1.0
14,8,-6:1.0
15,8,-6:1.0
-10,9,-6:1.0
-9,9,-6:1.0
-8,9,-6:1.0
-7,9,-6:1.0
-6,9,-6:1.0
-5,9,-6:1.0
-4,9,-6:1.0
-3,9,-6:1.0
-2,9,-6:1.0
-1,9,-6:1.0
0,9,-6:1.0
1,9,-6:1.0
2,9,-6:1.0
3,9,-6:1.0
4,9,-6:1.0
5,9,-6:1.0
6,9,-6:1.0
7,9,-6:1.0
8,9,-6:1.0
9,9,-6:1.0
10,9,-6:1.0
11,9,-6:1.0
12,9,-6:1.0
13,9,-6:1.0
14,9,-6:1.0
15,9,-6:13.0
-9,10,-6:1.0
-8,10,-6:1.0
-7,10,-6:1.0
-6,10,-6:1.0
-5,10,-6:1.0
-4,10,-6:1.0
-3,10,-6:1.0
-2,10,-6:1.0
-1,10,-6:1.0
0,10,-6:1.0
1,10,-6:1.0
2,10,-6:1.0
3,10,-6:1.0
4,10,-6:1.0
5,10,-6:1.0
6,10,-6:1.0
7,10,-6:1.0
8,10,-6:1.0
9,10,-6:1.0
10,10,-6:1.0
11,10,-6:1.0
12,10,-6:1.0
13,10,-6:13.0
-7,11,-6:1.0
-6,11,-6:1.0
-5,11,-6:1.0
-4,11,-6:1.0
-3,11,-6:1.0
-2,11,-6:1.0
-1,11,-6:1.0
0,11,-6:1.0
1,11,-6:1.0
2,11,-6:1.0
3,11,-6:1.0
4,11,-6:1.0
5,11,-6:1.0
6,11,-6:1.0
7,11,-6:1.0
8,11,-6:1.0
9,11,-6:1.0
10,11,-6:1.0
11,11,-6:13.0
-6,12,-6:1.0
-5,12,-6:1.0
-4,12,-6:1.0
-3,12,-6:1.0
-2,12,-6:1.0
-1,12,-6:1.0
0,12,-6:49.0
1,12,-6:1.0
2,12,-6:1.0
3,12,-6:1.0
4,12,-6:1.0
5,12,-6:1.0
6,12,-6:1.0
7,12,-6:1.0
8,12,-6:1.0
9,12,-6:1.0
10,12,-6:13.0
-4,13,-6:13.0
-3,13,-6:49.0
-2,13,-6:49.0
-1,13,-6:49.0
0,13,-6:49.0
1,13,-6:49.0
2,13,-6:1.0
3,13,-6:1.0
4,13,-6:1.0
5,13,-6:1.0
6,13,-6:1.0
7,13,-6:1.0
8,13,-6:1.0
9,13,-6:13.0
-2,14,-6:49.0
-1,14,-6:49.0
0,14,-6:49.0
1,14,-6:49.0
2,14,-6:1.0
3,14,-6:49.0
4,14,-6:1.0
5,14,-6:1.0
6,14,-6:1.0
7,14,-6:1.0
8,14,-6:1.0
-1,15,-6:11.10
0,15,-6:11.10
2,15,-6:49.0
3,15,-6:49.0
4,15,-6:49.0
5,15,-6:13.0
6,15,-6:13.0
1,-19,-5:13.0
2,-19,-5:13.0
3,-19,-5:13.0
-1,-18,-5:13.0
0,-18,-5:1.0
1,-18,-5:1.0
2,-18,-5:1.0
3,-18,-5:1.0
4,-18,-5:13.0
-1,-17,-5:1.0
0,-17,-5:1.0
1,-17,-5:1.0
2,-17,-5:1.0
3,-17,-5:1.0
4,-17,-5:1.0
5,-17,-5:13.0
-2,-16,-5:49.0
-1,-16,-5:1.0
0,-16,-5:1.0
1,-16,-5:1.0
2,-16,-5:1.0
3,-16,-5:1.0
4,-16,-5:1.0
5,-16,-5:1.0
6,-16,-5:13.0
7,-16,-5:13.0
-4,-15,-5:11.2
-3,-15,-5:49.0
-2,-15,-5:49.0
-1,-15,-5:1.0
0,-15,-5:1.0
1,-15,-5:1.0
2,-15,-5:1.0
3,-15,-5:1.0
4,-15,-5:1.0
5,-15,-5:1.0
6,-15,-5:1.0
7,-15,-5:1.0
8,-15,-5:1.0
9,-15,-5:13.0
-8,-14,-5:13.0
-7,-14,-5:13.0
-6,-14,-5:13.0
-5,-14,-5:49.0
-4,-14,-5:11.0
-3,-14,-5:11.0
-2,-14,-5:49.0
-1,-14,-5:49.0
0,-14,-5:1.0
1,-14,-5:1.0
2,-14,-5:1.0
3,-14,-5:1.0
4,-14,-5:1.0
5,-14,-5:1.0
6,-14,-5:1.0
7,-14,-5:1.0
8,-14,-5:1.0
9,-14,-5:1.0
10,-14,-5:1.0
11,-14,-5:1.0
-8,-13,-5:1.0
-7,-13,-5:1.0
-6,-13,-5:1.0
-5,-13,-5:1.0
-4,-13,-5:49.0
-3,-13,-5:49.0
-2,-13,-5:49.0
-1,-13,-5:1.0
0,-13,-5:1.0
1,-13,-5:1.0
2,-13,-5:1.0
3,-13,-5:1.0
4,-13,-5:1.0
5,-13,-5:1.0
6,-13,-5:1.0
7,-13,-5:1.0
8,-13,-5:1.0
9,-13,-5:1.0
10,-13,-5:1.0
11,-13,-5:1.0
12,-13,-5:1.0
13,-13,-5:13.0
-9,-12,-5:1.0
-8,-12,-5:1.0
-7,-12,-5:1.0
-6,-12,-5:1.0
-5,-12,-5:1.0
-4,-12,-5:49.0
-3,-12,-5:49.0
-2,-12,-5:49.0
-1,-12,-5:1.0
0,-12,-5:1.0
1,-12,-5:1.0
2,-12,-5:1.0
3,-12,-5:1.0
4,-12,-5:1.0
5,-12,-5:1.0
6,-12,-5:1.0
7,-12,-5:1.0
8,-12,-5:1.0
9,-12,-5:1.0
10,-12,-5:1.0
11,-12,-5:1.0
12,-12,-5:1.0
13,-12,-5:1.0
14,-12,-5:13.0
-10,-11,-5:1.0
-9,-11,-5:1.0
-8,-11,-5:1.0
-7,-11,-5:1.0
-6,-11,-5:1.0
-5,-11,-5:1.0
-4,-11,-5:1.0
-3,-11,-5:1.0
-2,-11,-5:1.0
-1,-11,-5:1.0
0,-11,-5:1.0
1,-11,-5:1.0
2,-11,-5:1.0
3,-11,-5:1.0
4,-11,-5:1.0
5,-11,-5:1.0
6,-11,-5:1.0
7,-11,-5:1.0
8,-11,-5:1.0
9,-11,-5:1.0
10,-11,-5:1.0
11,-11,-5:1.0
12,-11,-5:1.0
13,-11,-5:1.0
14,-11,-5:13.0
-11,-10,-5:13.0
-10,-10,-5:1.0
-9,-10,-5:1.0
-8,-10,-5:1.0
-7,-10,-5:1.0
-6,-10,-5:1.0
-5,-10,-5:1.0
-4,-10,-5:1.0
-3,-10,-5:1.0
-2,-10,-5:1.0
-1,-10,-5:1.0
0,-10,-5:1.0
1,-10,-5:1.0
2,-10,-5:1.0
3,-10,-5:1.0
4,-10,-5:1.0
5,-10,-5:1.0
6,-10,-5:1.0
7,-10,-5:1.0
8,-10,-5:1.0
9,-10,-5:1.0
10,-10,-5:1.0
11,-10,-5:1.0
12,-10,-5:1.0
13,-10,-5:1.0
14,-10,-5:13.0
-11,-9,-5:1.0
-10,-9,-5:1.0
-9,-9,-5:1.0
-8,-9,-5:1.0
-7,-9,-5:1.0
-6,-9,-5:1.0
-5,-9,-5:1.0
-4,-9,-5:1.0
-3,-9,-5:1.0
-2,-9,-5:1.0
-1,-9,-5:1.0
0,-9,-5:1.0
1,-9,-5:1.0
2,-9,-5:1.0
3,-9,-5:1.0
4,-9,-5:1.0
5,-9,-5:1.0
6,-9,-5:1.0
7,-9,-5:1.0
8,-9,-5:1.0
9,-9,-5:1.0
10,-9,-5:1.0
11,-9,-5:1.0
12,-9,-5:1.0
13,-9,-5:1.0
14,-9,-5:1.0
15,-9,-5:13.0
-11,-8,-5:1.0
-10,-8,-5:1.0
-9,-8,-5:1.0
-8,-8,-5:1.0
-7,-8,-5:1.0
-6,-8,-5:1.0
-5,-8,-5:1.0
-4,-8,-5:1.0
-3,-8,-5:1.0
-2,-8,-5:1.0
-1,-8,-5:1.0
0,-8,-5:1.0
1,-8,-5:1.0
2,-8,-5:1.0
3,-8,-5:1.0
4,-8,-5:1.0
5,-8,-5:1.0
6,-8,-5:1.0
7,-8,-5:1.0
8,-8,-5:1.0
9,-8,-5:1.0
10,-8,-5:1.0
11,-8,-5:1.0
12,-8,-5:1.0
13,-8,-5:1.0
14,-8,-5:1.0
15,-8,-5:1.0
-11,-7,-5:1.0
-10,-7,-5:1.0
-9,-7,-5:1.0
-8,-7,-5:1.0
-7,-7,-5:1.0
-6,-7,-5:1.0
-5,-7,-5:1.0
-4,-7,-5:1.0
-3,-7,-5:1.0
-2,-7,-5:1.0
-1,-7,-5:1.0
0,-7,-5:1.0
1,-7,-5:1.0
2,-7,-5:1.0
3,-7,-5:1.0
4,-7,-5:1.0
5,-7,-5:1.0
6,-7,-5:1.0
7,-7,-5:1.0
8,-7,-5:1.0
9,-7,-5:1.0
10,-7,-5:1.0
11,-7,-5:1.0
12,-7,-5:1.0
13,-7,-5:1.0
14,-7,-5:1.0
15,-7,-5:1.0
-11,-6,-5:1.0
-10,-6,-5:1.0
-9,-6,-5:1.0
-8,-6,-5:1.0
-7,-6,-5:1.0
-6,-6,-5:1.0
-5,-6,-5:1.0
-4,-6,-5:1.0
-3,-6,-5:1.0
-2,-6,-5:1.0
-1,-6,-5:1.0
0,-6,-5:1.0
1,-6,-5:1.0
2,-6,-5:1.0
3,-6,-5:1.0
4,-6,-5:1.0
5,-6,-5:1.0
6,-6,-5:1.0
7,-6,-5:1.0
8,-6,-5:1.0
9,-6,-5:1.0
10,-6,-5:1.0
11,-6,-5:1.0
12,-6,-5:1.0
13,-6,-5:1.0
14,-6,-5:1.0
15,-6,-5:1.0
-12,-5,-5:1.0
-11,-5,-5:1.0
-10,-5,-5:1.0
-9,-5,-5:1.0
-8,-5,-5:1.0
-7,-5,-5:1.0
-6,-5,-5:1.0
-5,-5,-5:1.0
-4,-5,-5:1.0
-3,-5,-5:1.0
-2,-5,-5:1.0
-1,-5,-5:1.0
0,-5,-5:1.0
1,-5,-5:1.0
2,-5,-5:1.0
3,-5,-5:1.0
4,-5,-5:1.0
5,-5,-5:1.0
6,-5,-5:1.0
7,-5,-5:1.0
8,-5,-5:1.0
9,-5,-5:1.0
10,-5,-5:1.0
11,-5,-5:1.0
12,-5,-5:1.0
13,-5,-5:1.0
14,-5,-5:1.0
-14,-4,-5:13.0
-13,-4,-5:1.0
-12,-4,-5:1.0
-11,-4,-5:1.0
-10,-4,-5:1.0
-9,-4,-5:1.0
-8,-4,-5:1.0
-7,-4,-5:1.0
-6,-4,-5:1.0
-5,-4,-5:1.0
-4,-4,-5:1.0
-3,-4,-5:1.0
-2,-4,-5:1.0
-1,-4,-5:1.0
0,-4,-5:1.0
1,-4,-5:1.0
2,-4,-5:11.0
3,-4,-5:1.0
4,-4,-5:1.0
5,-4,-5:1.0
6,-4,-5:1.0
7,-4,-5:1.0
8,-4,-5:1.0
9,-4,-5:1.0
10,-4,-5:1.0
11,-4,-5:1.0
12,-4,-5:1.0
13,-4,-5:1.0
14,-4,-5:1.0
-14,-3,-5:13.0
-13,-3,-5:1.0
-12,-3,-5:1.0
-11,-3,-5:1.0
-10,-3,-5:1.0
-9,-3,-5:1.0
-8,-3,-5:1.0
-7,-3,-5:1.0
-6,-3,-5:1.0
-5,-3,-5:1.0
-4,-3,-5:1.0
-3,-3,-5:1.0
-2,-3,-5:1.0
-1,-3,-5:1.0
0,-3,-5:11.0
1,-3,-5:11.0
2,-3,-5:11.0
3,-3,-5:11.0
4,-3,-5:1.0
5,-3,-5:1.0
6,-3,-5:1.0
7,-3,-5:1.0
8,-3,-5:1.0
9,-3,-5:1.0
10,-3,-5:1.0
11,-3,-5:1.0
12,-3,-5:1.0
13,-3,-5:1.0
14,-3,-5:1.0
-14,-2,-5:13.0
-13,-2,-5:1.0
-12,-2,-5:1.0
-11,-2,-5:1.0
-10,-2,-5:1.0
-9,-2,-5:1.0
-8,-2,-5:1.0
-7,-2,-5:1.0
-6,-2,-5:1.0
-5,-2,-5:1.0
-4,-2,-5:1.0
-3,-2,-5:1.0
-2,-2,-5:1.0
-1,-2,-5:1.0
0,-2,-5:11.0
1,-2,-5:11.0
2,-2,-5:11.0
3,-2,-5:1.0
4,-2,-5:1.0
5,-2,-5:1.0
6,-2,-5:1.0
7,-2,-5:1.0
8,-2,-5:1.0
9,-2,-5:1.0
10,-2,-5:1.0
11,-2,-5:1.0
12,-2,-5:1.0
13,-2,-5:1.0
14,-2,-5:1.0
-14,-1,-5:13.0
-13,-1,-5:1.0
-12,-1,-5:1.0
-11,-1,-5:1.0
-10,-1,-5:1.0
-9,-1,-5:1.0
-8,-1,-5:1.0
-7,-1,-5:1.0
-6,-1,-5:1.0
-5,-1,-5:1.0
-4,-1,-5:1.0
-3,-1,-5:1.0
-2,-1,-5:1.0
-1,-1,-5:1.0
0,-1,-5:11.0
1,-1,-5:11.0
2,-1,-5:11.0
3,-1,-5:1.0
4,-1,-5:1.0
5,-1,-5:1.0
6,-1,-5:1.0
7,-1,-5:1.0
8,-1,-5:1.0
9,-1,-5:1.0
10,-1,-5:1.0
11,-1,-5:1.0
12,-1,-5:1.0
13,-1,-5:1.0
14,-1,-5:1.0
-13,0,-5:1.0
-12,0,-5:1.0
-11,0,-5:1.0
-10,0,-5:1.0
-9,0,-5:1.0
-8,0,-5:1.0
-7,0,-5:1.0
-6,0,-5:1.0
-5,0,-5:1.0
-4,0,-5:1.0
-3,0,-5:1.0
-2,0,-5:1.0
-1,0,-5:1.0
0,0,-5:1.0
1,0,-5:11.0
2,0,-5:11.0
3,0,-5:1.0
4,0,-5:1.0
5,0,-5:1.0
6,0,-5:1.0
7,0,-5:1.0
8,0,-5:1.0
9,0,-5:1.0
10,0,-5:1.0
11,0,-5:1.0
12,0,-5:1.0
13,0,-5:49.0
14,0,-5:49.0
-14,1,-5:13.0
-13,1,-5:1.0
-12,1,-5:1.0
-11,1,-5:1.0
-10,1,-5:1.0
-9,1,-5:1.0
-8,1,-5:1.0
-7,1,-5:1.0
-6,1,-5:1.0
-5,1,-5:1.0
-4,1,-5:1.0
-3,1,-5:1.0
-2,1,-5:1.0
-1,1,-5:1.0
0,1,-5:1.0
1,1,-5:1.0
2,1,-5:1.0
3,1,-5:1.0
4,1,-5:1.0
5,1,-5:1.0
6,1,-5:1.0
7,1,-5:1.0
8,1,-5:1.0
9,1,-5:1.0
10,1,-5:1.0
11,1,-5:1.0
12,1,-5:1.0
13,1,-5:49.0
14,1,-5:49.0
-14,2,-5:13.0
-13,2,-5:1.0
-12,2,-5:1.0
-11,2,-5:1.0
-10,2,-5:1.0
-9,2,-5:1.0
-8,2,-5:1.0
-7,2,-5:1.0
-6,2,-5:1.0
-5,2,-5:1.0
-4,2,-5:1.0
-3,2,-5:1.0
-2,2,-5:1.0
-1,2,-5:1.0
0,2,-5:1.0
1,2,-5:1.0
2,2,-5:1.0
3,2,-5:1.0
4,2,-5:1.0
5,2,-5:1.0
6,2,-5:1.0
7,2,-5:1.0
8,2,-5:1.0
9,2,-5:1.0
10,2,-5:1.0
11,2,-5:1.0
12,2,-5:1.0
13,2,-5:49.0
14,2,-5:49.0
-14,3,-5:13.0
-13,3,-5:1.0
-12,3,-5:1.0
-11,3,-5:1.0
-10,3,-5:1.0
-9,3,-5:1.0
-8,3,-5:1.0
-7,3,-5:1.0
-6,3,-5:1.0
-5,3,-5:1.0
-4,3,-5:1.0
-3,3,-5:1.0
-2,3,-5:1.0
-1,3,-5:1.0
0,3,-5:1.0
1,3,-5:1.0
2,3,-5:1.0
3,3,-5:1.0
4,3,-5:1.0
5,3,-5:1.0
6,3,-5:1.0
7,3,-5:1.0
8,3,-5:1.0
9,3,-5:1.0
10,3,-5:1.0
11,3,-5:1.0
12,3,-5:1.0
13,3,-5:49.0
14,3,-5:49.0
15,3,-5:11.10
-14,4,-5:13.0
-13,4,-5:1.0
-12,4,-5:1.0
-11,4,-5:1.0
-10,4,-5:1.0
-9,4,-5:1.0
-8,4,-5:1.0
-7,4,-5:1.0
-6,4,-5:1.0
-5,4,-5:1.0
-4,4,-5:1.0
-3,4,-5:1.0
-2,4,-5:1.0
-1,4,-5:1.0
0,4,-5:1.0
1,4,-5:1.0
2,4,-5:1.0
3,4,-5:1.0
4,4,-5:1.0
5,4,-5:1.0
6,4,-5:1.0
7,4,-5:1.0
8,4,-5:1.0
9,4,-5:1.0
10,4,-5:1.0
11,4,-5:1.0
12,4,-5:1.0
13,4,-5:49.0
14,4,-5:49.0
15,4,-5:11.10
-14,5,-5:13.0
-13,5,-5:13.0
-12,5,-5:1.0
-11,5,-5:1.0
-10,5,-5:1.0
-9,5,-5:1.0
-8,5,-5:1.0
-7,5,-5:1.0
-6,5,-5:1.0
-5,5,-5:1.0
-4,5,-5:1.0
-3,5,-5:1.0
-2,5,-5:1.0
-1,5,-5:1.0
0,5,-5:1.0
1,5,-5:1.0
2,5,-5:1.0
3,5,-5:1.0
4,5,-5:1.0
5,5,-5:1.0
6,5,-5:1.0
7,5,-5:1.0
8,5,-5:1.0
9,5,-5:1.0
10,5,-5:1.0
11,5,-5:1.0
12,5,-5:1.0
13,5,-5:49.0
14,5,-5:49.0
16,5,-5:49.0
-13,6,-5:13.0
-12,6,-5:13.0
-11,6,-5:1.0
-10,6,-5:1.0
-9,6,-5:1.0
-8,6,-5:1.0
-7,6,-5:1.0
-6,6,-5:1.0
-5,6,-5:1.0
-4,6,-5:1.0
-3,6,-5:1.0
-2,6,-5:1.0
-1,6,-5:1.0
0,6,-5:1.0
1,6,-5:1.0
2,6,-5:1.0
3,6,-5:1.0
4,6,-5:1.0
5,6,-5:1.0
6,6,-5:1.0
7,6,-5:1.0
8,6,-5:1.0
9,6,-5:1.0
10,6,-5:1.0
11,6,-5:1.0
12,6,-5:1.0
13,6,-5:1.0
14,6,-5:49.0
15,6,-5:49.0
-12,7,-5:13.0
-11,7,-5:13.0
-10,7,-5:1.0
-9,7,-5:1.0
-8,7,-5:1.0
-7,7,-5:1.0
-6,7,-5:1.0
-5,7,-5:1.0
-4,7,-5:1.0
-3,7,-5:1.0
-2,7,-5:1.0
-1,7,-5:1.0
0,7,-5:1.0
1,7,-5:1.0
2,7,-5:1.0
3,7,-5:1.0
4,7,-5:1.0
5,7,-5:1.0
6,7,-5:1.0
7,7,-5:1.0
8,7,-5:1.0
9,7,-5:1.0
10,7,-5:1.0
11,7,-5:1.0
12,7,-5:1.0
13,7,-5:1.0
14,7,-5:1.0
15,7,-5:49.0
-10,8,-5:1.0
-9,8,-5:1.0
-8,8,-5:1.0
-7,8,-5:1.0
-6,8,-5:1.0
-5,8,-5:1.0
-4,8,-5:1.0
-3,8,-5:1.0
-2,8,-5:1.0
-1,8,-5:1.0
0,8,-5:1.0
1,8,-5:1.0
2,8,-5:1.0
3,8,-5:1.0
4,8,-5:1.0
5,8,-5:1.0
6,8,-5:1.0
7,8,-5:1.0
8,8,-5:1.0
9,8,-5:1.0
10,8,-5:1.0
11,8,-5:1.0
12,8,-5:1.0
13,8,-5:1.0
14,8,-5:1.0
15,8,-5:13.0
-10,9,-5:1.0
-9,9,-5:1.0
-8,9,-5:1.0
-7,9,-5:1.0
-6,9,-5:1.0
-5,9,-5:1.0
-4,9,-5:1.0
-3,9,-5:1.0
-2,9,-5:1.0
-1,9,-5:1.0
0,9,-5:1.0
1,9,-5:1.0
2,9,-5:1.0
3,9,-5:1.0
4,9,-5:1.0
5,9,-5:1.0
6,9,-5:1.0
7,9,-5:1.0
8,9,-5:1.0
9,9,-5:1.0
10,9,-5:1.0
11,9,-5:1.0
12,9,-5:1.0
13,9,-5:1.0
14,9,-5:13.0
15,9,-5:13.0
-9,10,-5:13.0
-8,10,-5:1.0
-7,10,-5:1.0
-6,10,-5:1.0
-5,10,-5:1.0
-4,10,-5:1.0
-3,10,-5:1.0
-2,10,-5:1.0
-1,10,-5:1.0
0,10,-5:1.0
1,10,-5:1.0
2,10,-5:1.0
3,10,-5:1.0
4,10,-5:1.0
5,10,-5:1.0
6,10,-5:1.0
7,10,-5:1.0
8,10,-5:1.0
9,10,-5:1.0
10,10,-5:1.0
11,10,-5:1.0
12,10,-5:13.0
13,10,-5:13.0
-7,11,-5:1.0
-6,11,-5:1.0
-5,11,-5:1.0
-4,11,-5:1.0
-3,11,-5:1.0
-2,11,-5:1.0
-1,11,-5:1.0
0,11,-5:1.0
1,11,-5:1.0
2,11,-5:1.0
3,11,-5:1.0
4,11,-5:1.0
5,11,-5:1.0
6,11,-5:1.0
7,11,-5:1.0
8,11,-5:1.0
9,11,-5:1.0
10,11,-5:1.0
11,11,-5:13.0
-6,12,-5:1.0
-5,12,-5:1.0
-4,12,-5:1.0
-3,12,-5:1.0
-2,12,-5:1.0
-1,12,-5:49.0
0,12,-5:49.0
1,12,-5:49.0
2,12,-5:1.0
3,12,-5:1.0
4,12,-5:1.0
5,12,-5:1.0
6,12,-5:1.0
7,12,-5:1.0
8,12,-5:1.0
9,12,-5:13.0
10,12,-5:13.0
-4,13,-5:13.0
-3,13,-5:13.0
-2,13,-5:49.0
-1,13,-5:49.0
0,13,-5:49.0
1,13,-5:49.0
2,13,-5:1.0
3,13,-5:1.0
4,13,-5:1.0
5,13,-5:1.0
6,13,-5:1.0
7,13,-5:1.0
8,13,-5:1.0
9,13,-5:13.0
-2,14,-5:49.0
-1,14,-5:11.10
0,14,-5:11.10
1,14,-5:49.0
2,14,-5:13.0
3,14,-5:1.0
4,14,-5:1.0
5,14,-5:1.0
6,14,-5:1.0
7,14,-5:1.0
8,14,-5:13.0
-1,15,-5:11.2
0,15,-5:11.2
2,15,-5:13.0
3,15,-5:13.0
4,15,-5:13.0
5,15,-5:13.0
6,15,-5:13.0
-1,-18,-4:13.0
0,-18,-4:1.0
1,-18,-4:1.0
2,-18,-4:1.0
3,-18,-4:13.0
-1,-17,-4:1.0
0,-17,-4:1.0
1,-17,-4:1.0
2,-17,-4:1.0
3,-17,-4:1.0
4,-17,-4:13.0
-1,-16,-4:1.0
0,-16,-4:1.0
1,-16,-4:1.0
2,-16,-4:1.0
3,-16,-4:1.0
4,-16,-4:1.0
5,-16,-4:1.0
6,-16,-4:13.0
-2,-15,-4:49.0
-1,-15,-4:49.0
0,-15,-4:1.0
1,-15,-4:1.0
2,-15,-4:1.0
3,-15,-4:1.0
4,-15,-4:1.0
5,-15,-4:1.0
6,-15,-4:1.0
7,-15,-4:1.0
8,-15,-4:1.0
9,-15,-4:13.0
-5,-14,-4:13.0
-4,-14,-4:11.10
-3,-14,-4:11.10
-2,-14,-4:49.0
-1,-14,-4:49.0
0,-14,-4:1.0
1,-14,-4:1.0
2,-14,-4:1.0
3,-14,-4:1.0
4,-14,-4:1.0
5,-14,-4:1.0
6,-14,-4:1.0
7,-14,-4:1.0
8,-14,-4:1.0
9,-14,-4:1.0
10,-14,-4:1.0
11,-14,-4:1.0
-8,-13,-4:13.0
-7,-13,-4:1.0
-6,-13,-4:1.0
-5,-13,-4:1.0
-4,-13,-4:49.0
-3,-13,-4:49.0
-2,-13,-4:49.0
-1,-13,-4:49.0
0,-13,-4:1.0
1,-13,-4:1.0
2,-13,-4:1.0
3,-13,-4:1.0
4,-13,-4:1.0
5,-13,-4:1.0
6,-13,-4:1.0
7,-13,-4:1.0
8,-13,-4:1.0
9,-13,-4:1.0
10,-13,-4:1.0
11,-13,-4:1.0
12,-13,-4:1.0
13,-13,-4:13.0
-9,-12,-4:13.0
-8,-12,-4:1.0
-7,-12,-4:1.0
-6,-12,-4:1.0
-5,-12,-4:1.0
-4,-12,-4:1.0
-3,-12,-4:49.0
-2,-12,-4:1.0
-1,-12,-4:1.0
0,-12,-4:1.0
1,-12,-4:1.0
2,-12,-4:1.0
3,-12,-4:1.0
4,-12,-4:1.0
5,-12,-4:1.0
6,-12,-4:1.0
7,-12,-4:1.0
8,-12,-4:1.0
9,-12,-4:1.0
10,-12,-4:1.0
11,-12,-4:1.0
12,-12,-4:1.0
13,-12,-4:1.0
-10,-11,-4:1.0
-9,-11,-4:1.0
-8,-11,-4:1.0
-7,-11,-4:1.0
-6,-11,-4:1.0
-5,-11,-4:1.0
-4,-11,-4:1.0
-3,-11,-4:1.0
-2,-11,-4:1.0
-1,-11,-4:1.0
0,-11,-4:1.0
1,-11,-4:1.0
2,-11,-4:1.0
3,-11,-4:1.0
4,-11,-4:1.0
5,-11,-4:1.0
6,-11,-4:1.0
7,-11,-4:1.0
8,-11,-4:1.0
9,-11,-4:1.0
10,-11,-4:1.0
11,-11,-4:1.0
12,-11,-4:1.0
13,-11,-4:1.0
-10,-10,-4:1.0
-9,-10,-4:1.0
-8,-10,-4:1.0
-7,-10,-4:1.0
-6,-10,-4:1.0
-5,-10,-4:1.0
-4,-10,-4:1.0
-3,-10,-4:1.0
-2,-10,-4:1.0
-1,-10,-4:1.0
0,-10,-4:1.0
1,-10,-4:1.0
2,-10,-4:1.0
3,-10,-4:1.0
4,-10,-4:1.0
5,-10,-4:1.0
6,-10,-4:1.0
7,-10,-4:1.0
8,-10,-4:1.0
9,-10,-4:1.0
10,-10,-4:1.0
11,-10,-4:1.0
12,-10,-4:1.0
13,-10,-4:1.0
14,-10,-4:13.0
-11,-9,-4:1.0
-10,-9,-4:1.0
-9,-9,-4:1.0
-8,-9,-4:1.0
-7,-9,-4:1.0
-6,-9,-4:1.0
-5,-9,-4:1.0
-4,-9,-4:1.0
-3,-9,-4:1.0
-2,-9,-4:1.0
-1,-9,-4:1.0
0,-9,-4:1.0
1,-9,-4:1.0
2,-9,-4:1.0
3,-9,-4:1.0
4,-9,-4:1.0
5,-9,-4:1.0
6,-9,-4:1.0
7,-9,-4:1.0
8,-9,-4:1.0
9,-9,-4:1.0
10,-9,-4:1.0
11,-9,-4:1.0
12,-9,-4:1.0
13,-9,-4:1.0
14,-9,-4:1.0
15,-9,-4:13.0
-11,-8,-4:1.0
-10,-8,-4:1.0
-9,-8,-4:1.0
-8,-8,-4:1.0
-7,-8,-4:1.0
-6,-8,-4:1.0
-5,-8,-4:1.0
-4,-8,-4:1.0
-3,-8,-4:1.0
-2,-8,-4:1.0
-1,-8,-4:1.0
0,-8,-4:1.0
1,-8,-4:1.0
2,-8,-4:1.0
3,-8,-4:1.0
4,-8,-4:1.0
5,-8,-4:1.0
6,-8,-4:1.0
7,-8,-4:1.0
8,-8,-4:1.0
9,-8,-4:1.0
10,-8,-4:1.0
11,-8,-4:1.0
12,-8,-4:1.0
13,-8,-4:1.0
14,-8,-4:1.0
15,-8,-4:13.0
-11,-7,-4:1.0
-10,-7,-4:1.0
-9,-7,-4:1.0
-8,-7,-4:1.0
-7,-7,-4:1.0
-6,-7,-4:1.0
-5,-7,-4:1.0
-4,-7,-4:1.0
-3,-7,-4:1.0
-2,-7,-4:1.0
-1,-7,-4:1.0
0,-7,-4:1.0
1,-7,-4:1.0
2,-7,-4:1.0
3,-7,-4:1.0
4,-7,-4:1.0
5,-7,-4:1.0
6,-7,-4:1.0
7,-7,-4:1.0
8,-7,-4:1.0
9,-7,-4:1.0
10,-7,-4:1.0
11,-7,-4:1.0
12,-7,-4:1.0
13,-7,-4:1.0
14,-7,-4:1.0
15,-7,-4:13.0
-11,-6,-4:1.0
-10,-6,-4:1.0
-9,-6,-4:1.0
-8,-6,-4:1.0
-7,-6,-4:1.0
-6,-6,-4:1.0
-5,-6,-4:1.0
-4,-6,-4:1.0
-3,-6,-4:1.0
-2,-6,-4:1.0
-1,-6,-4:1.0
0,-6,-4:1.0
1,-6,-4:1.0
2,-6,-4:1.0
3,-6,-4:1.0
4,-6,-4:1.0
5,-6,-4:1.0
6,-6,-4:1.0
7,-6,-4:1.0
8,-6,-4:1.0
9,-6,-4:1.0
10,-6,-4:1.0
11,-6,-4:1.0
12,-6,-4:1.0
13,-6,-4:1.0
14,-6,-4:1.0
15,-6,-4:13.0
-12,-5,-4:13.0
-11,-5,-4:1.0
-10,-5,-4:1.0
-9,-5,-4:1.0
-8,-5,-4:1.0
-7,-5,-4:1.0
-6,-5,-4:1.0
-5,-5,-4:1.0
-4,-5,-4:1.0
-3,-5,-4:1.0
-2,-5,-4:1.0
-1,-5,-4:1.0
0,-5,-4:1.0
1,-5,-4:11.0
2,-5,-4:1.0
3,-5,-4:1.0
4,-5,-4:1.0
5,-5,-4:1.0
6,-5,-4:1.0
7,-5,-4:1.0
8,-5,-4:1.0
9,-5,-4:1.0
10,-5,-4:1.0
11,-5,-4:1.0
12,-5,-4:1.0
13,-5,-4:1.0
14,-5,-4:13.0
-13,-4,-4:13.0
-12,-4,-4:1.0
-11,-4,-4:1.0
-10,-4,-4:1.0
-9,-4,-4:1.0
-8,-4,-4:1.0
-7,-4,-4:1.0
-6,-4,-4:1.0
-5,-4,-4:1.0
-4,-4,-4:1.0
-3,-4,-4:1.0
-2,-4,-4:1.0
-1,-4,-4:1.0
0,-4,-4:11.0
1,-4,-4:11.0
2,-4,-4:11.0
3,-4,-4:11.0
4,-4,-4:11.0
5,-4,-4:1.0
6,-4,-4:1.0
7,-4,-4:1.0
8,-4,-4:1.0
9,-4,-4:1.0
10,-4,-4:1.0
11,-4,-4:1.0
12,-4,-4:1.0
13,-4,-4:1.0
14,-4,-4:13.0
-13,-3,-4:1.0
-12,-3,-4:1.0
-11,-3,-4:1.0
-10,-3,-4:1.0
-9,-3,-4:1.0
-8,-3,-4:1.0
-7,-3,-4:1.0
-6,-3,-4:1.0
-5,-3,-4:1.0
-4,-3,-4:1.0
-3,-3,-4:1.0
-2,-3,-4:1.0
-1,-3,-4:11.0
0,-3,-4:11.0
1,-3,-4:11.0
2,-3,-4:11.0
3,-3,-4:11.0
4,-3,-4:1.0
5,-3,-4:1.0
6,-3,-4:1.0
7,-3,-4:1.0
8,-3,-4:1.0
9,-3,-4:1.0
10,-3,-4:1.0
11,-3,-4:1.0
12,-3,-4:1.0
13,-3,-4:1.0
14,-3,-4:1.0
-13,-2,-4:1.0
-12,-2,-4:1.0
-11,-2,-4:1.0
-10,-2,-4:1.0
-9,-2,-4:1.0
-8,-2,-4:1.0
-7,-2,-4:1.0
-6,-2,-4:1.0
-5,-2,-4:1.0
-4,-2,-4:1.0
-3,-2,-4:1.0
-2,-2,-4:1.0
-1,-2,-4:11.0
0,-2,-4:11.0
1,-2,-4:11.0
2,-2,-4:11.0
3,-2,-4:11.0
4,-2,-4:11.0
5,-2,-4:1.0
6,-2,-4:1.0
7,-2,-4:1.0
8,-2,-4:1.0
9,-2,-4:1.0
10,-2,-4:1.0
11,-2,-4:1.0
12,-2,-4:1.0
13,-2,-4:1.0
14,-2,-4:1.0
-13,-1,-4:1.0
-12,-1,-4:1.0
-11,-1,-4:1.0
-10,-1,-4:1.0
-9,-1,-4:1.0
-8,-1,-4:1.0
-7,-1,-4:1.0
-6,-1,-4:1.0
-5,-1,-4:1.0
-4,-1,-4:1.0
-3,-1,-4:1.0
-2,-1,-4:11.0
-1,-1,-4:11.0
0,-1,-4:11.0
1,-1,-4:11.0
2,-1,-4:11.0
3,-1,-4:11.0
4,-1,-4:11.0
5,-1,-4:1.0
6,-1,-4:1.0
7,-1,-4:1.0
8,-1,-4:1.0
9,-1,-4:1.0
10,-1,-4:1.0
11,-1,-4:1.0
12,-1,-4:1.0
13,-1,-4:1.0
14,-1,-4:1.0
-13,0,-4:1.0
-12,0,-4:1.0
-11,0,-4:1.0
-10,0,-4:1.0
-9,0,-4:1.0
-8,0,-4:1.0
-7,0,-4:1.0
-6,0,-4:1.0
-5,0,-4:1.0
-4,0,-4:1.0
-3,0,-4:1.0
-2,0,-4:1.0
-1,0,-4:1.0
0,0,-4:11.0
1,0,-4:11.0
2,0,-4:11.0
3,0,-4:11.0
4,0,-4:1.0
5,0,-4:1.0
6,0,-4:1.0
7,0,-4:1.0
8,0,-4:1.0
9,0,-4:1.0
10,0,-4:1.0
11,0,-4:1.0
12,0,-4:1.0
13,0,-4:1.0
14,0,-4:49.0
-13,1,-4:1.0
-12,1,-4:1.0
-11,1,-4:1.0
-10,1,-4:1.0
-9,1,-4:1.0
-8,1,-4:1.0
-7,1,-4:1.0
-6,1,-4:1.0
-5,1,-4:1.0
-4,1,-4:1.0
-3,1,-4:1.0
-2,1,-4:1.0
-1,1,-4:11.0
0,1,-4:11.0
1,1,-4:11.0
2,1,-4:11.0
3,1,-4:1.0
4,1,-4:1.0
5,1,-4:1.0
6,1,-4:1.0
7,1,-4:1.0
8,1,-4:1.0
9,1,-4:1.0
10,1,-4:1.0
11,1,-4:1.0
12,1,-4:1.0
13,1,-4:49.0
14,1,-4:49.0
-13,2,-4:1.0
-12,2,-4:1.0
-11,2,-4:1.0
-10,2,-4:1.0
-9,2,-4:1.0
-8,2,-4:1.0
-7,2,-4:1.0
-6,2,-4:1.0
-5,2,-4:1.0
-4,2,-4:1.0
-3,2,-4:1.0
-2,2,-4:1.0
-1,2,-4:1.0
0,2,-4:1.0
1,2,-4:1.0
2,2,-4:1.0
3,2,-4:1.0
4,2,-4:1.0
5,2,-4:1.0
6,2,-4:1.0
7,2,-4:1.0
8,2,-4:1.0
9,2,-4:1.0
10,2,-4:1.0
11,2,-4:1.0
12,2,-4:1.0
13,2,-4:49.0
14,2,-4:49.0
-13,3,-4:1.0
-12,3,-4:1.0
-11,3,-4:1.0
-10,3,-4:1.0
-9,3,-4:1.0
-8,3,-4:1.0
-7,3,-4:1.0
-6,3,-4:1.0
-5,3,-4:1.0
-4,3,-4:1.0
-3,3,-4:1.0
-2,3,-4:1.0
-1,3,-4:1.0
0,3,-4:1.0
1,3,-4:1.0
2,3,-4:1.0
3,3,-4:1.0
4,3,-4:1.0
5,3,-4:1.0
6,3,-4:1.0
7,3,-4:1.0
8,3,-4:1.0
9,3,-4:1.0
10,3,-4:1.0
11,3,-4:1.0
12,3,-4:1.0
13,3,-4:49.0
14,3,-4:49.0
15,3,-4:11.10
-13,4,-4:13.0
-12,4,-4:1.0
-11,4,-4:1.0
-10,4,-4:1.0
-9,4,-4:1.0
-8,4,-4:1.0
-7,4,-4:1.0
-6,4,-4:1.0
-5,4,-4:1.0
-4,4,-4:1.0
-3,4,-4:1.0
-2,4,-4:1.0
-1,4,-4:1.0
0,4,-4:1.0
1,4,-4:1.0
2,4,-4:1.0
3,4,-4:1.0
4,4,-4:1.0
5,4,-4:1.0
6,4,-4:1.0
7,4,-4:1.0
8,4,-4:1.0
9,4,-4:1.0
10,4,-4:1.0
11,4,-4:1.0
12,4,-4:1.0
13,4,-4:49.0
14,4,-4:49.0
15,4,-4:11.10
-13,5,-4:13.0
-12,5,-4:13.0
-11,5,-4:1.0
-10,5,-4:1.0
-9,5,-4:1.0
-8,5,-4:1.0
-7,5,-4:1.0
-6,5,-4:1.0
-5,5,-4:1.0
-4,5,-4:1.0
-3,5,-4:1.0
-2,5,-4:1.0
-1,5,-4:1.0
0,5,-4:1.0
1,5,-4:1.0
2,5,-4:1.0
3,5,-4:1.0
4,5,-4:1.0
5,5,-4:1.0
6,5,-4:1.0
7,5,-4:1.0
8,5,-4:1.0
9,5,-4:1.0
10,5,-4:1.0
11,5,-4:1.0
12,5,-4:1.0
13,5,-4:1.0
14,5,-4:49.0
16,5,-4:49.0
-12,6,-4:13.0
-11,6,-4:13.0
-10,6,-4:1.0
-9,6,-4:1.0
-8,6,-4:1.0
-7,6,-4:1.0
-6,6,-4:1.0
-5,6,-4:1.0
-4,6,-4:1.0
-3,6,-4:1.0
-2,6,-4:1.0
-1,6,-4:1.0
0,6,-4:1.0
1,6,-4:1.0
2,6,-4:1.0
3,6,-4:1.0
4,6,-4:1.0
5,6,-4:1.0
6,6,-4:1.0
7,6,-4:1.0
8,6,-4:1.0
9,6,-4:1.0
10,6,-4:1.0
11,6,-4:1.0
12,6,-4:1.0
13,6,-4:1.0
14,6,-4:49.0
15,6,-4:49.0
-11,7,-4:13.0
-10,7,-4:1.0
-9,7,-4:1.0
-8,7,-4:1.0
-7,7,-4:1.0
-6,7,-4:1.0
-5,7,-4:1.0
-4,7,-4:1.0
-3,7,-4:1.0
-2,7,-4:1.0
-1,7,-4:1.0
0,7,-4:1.0
1,7,-4:1.0
2,7,-4:1.0
3,7,-4:1.0
4,7,-4:1.0
5,7,-4:1.0
6,7,-4:1.0
7,7,-4:1.0
8,7,-4:1.0
9,7,-4:1.0
10,7,-4:1.0
11,7,-4:1.0
12,7,-4:1.0
13,7,-4:1.0
14,7,-4:49.0
15,7,-4:49.0
-10,8,-4:1.0
-9,8,-4:1.0
-8,8,-4:1.0
-7,8,-4:1.0
-6,8,-4:1.0
-5,8,-4:1.0
-4,8,-4:1.0
-3,8,-4:1.0
-2,8,-4:1.0
-1,8,-4:1.0
0,8,-4:1.0
1,8,-4:1.0
2,8,-4:1.0
3,8,-4:1.0
4,8,-4:1.0
5,8,-4:1.0
6,8,-4:1.0
7,8,-4:1.0
8,8,-4:1.0
9,8,-4:1.0
10,8,-4:1.0
11,8,-4:1.0
12,8,-4:1.0
13,8,-4:1.0
14,8,-4:13.0
15,8,-4:13.0
-10,9,-4:13.0
-9,9,-4:1.0
-8,9,-4:1.0
-7,9,-4:1.0
-6,9,-4:1.0
-5,9,-4:1.0
-4,9,-4:1.0
-3,9,-4:1.0
-2,9,-4:1.0
-1,9,-4:1.0
0,9,-4:1.0
1,9,-4:1.0
2,9,-4:1.0
3,9,-4:1.0
4,9,-4:1.0
5,9,-4:1.0
6,9,-4:1.0
7,9,-4:1.0
8,9,-4:1.0
9,9,-4:1.0
10,9,-4:1.0
11,9,-4:1.0
12,9,-4:1.0
13,9,-4:13.0
14,9,-4:13.0
-9,10,-4:13.0
-8,10,-4:1.0
-7,10,-4:1.0
-6,10,-4:1.0
-5,10,-4:1.0
-4,10,-4:1.0
-3,10,-4:1.0
-2,10,-4:1.0
-1,10,-4:1.0
0,10,-4:1.0
1,10,-4:1.0
2,10,-4:1.0
3,10,-4:1.0
4,10,-4:1.0
5,10,-4:1.0
6,10,-4:1.0
7,10,-4:1.0
8,10,-4:1.0
9,10,-4:1.0
10,10,-4:1.0
11,10,-4:13.0
12,10,-4:13.0
-7,11,-4:1.0
-6,11,-4:1.0
-5,11,-4:1.0
-4,11,-4:1.0
-3,11,-4:1.0
-2,11,-4:1.0
-1,11,-4:1.0
0,11,-4:1.0
1,11,-4:1.0
2,11,-4:1.0
3,11,-4:1.0
4,11,-4:1.0
5,11,-4:1.0
6,11,-4:1.0
7,11,-4:1.0
8,11,-4:1.0
9,11,-4:1.0
10,11,-4:13.0
-6,12,-4:13.0
-5,12,-4:1.0
-4,12,-4:1.0
-3,12,-4:1.0
-2,12,-4:1.0
-1,12,-4:49.0
0,12,-4:49.0
1,12,-4:1.0
2,12,-4:1.0
3,12,-4:1.0
4,12,-4:1.0
5,12,-4:1.0
6,12,-4:1.0
7,12,-4:1.0
8,12,-4:1.0
9,12,-4:13.0
-3,13,-4:49.0
-2,13,-4:49.0
-1,13,-4:49.0
0,13,-4:49.0
1,13,-4:49.0
2,13,-4:1.0
3,13,-4:1.0
4,13,-4:1.0
5,13,-4:1.0
6,13,-4:1.0
7,13,-4:1.0
8,13,-4:13.0
-2,14,-4:49.0
-1,14,-4:11.10
0,14,-4:11.10
2,14,-4:13.0
3,14,-4:13.0
4,14,-4:1.0
5,14,-4:1.0
6,14,-4:1.0
7,14,-4:13.0
8,14,-4:13.0
0,-18,-3:13.0
1,-18,-3:13.0
2,-18,-3:13.0
3,-18,-3:13.0
-1,-17,-3:13.0
0,-17,-3:1.0
1,-17,-3:1.0
2,-17,-3:1.0
3,-17,-3:1.0
4,-17,-3:13.0
-1,-16,-3:1.0
0,-16,-3:1.0
1,-16,-3:1.0
2,-16,-3:1.0
3,-16,-3:1.0
4,-16,-3:1.0
5,-16,-3:13.0
-2,-15,-3:49.0
-1,-15,-3:49.0
0,-15,-3:1.0
1,-15,-3:1.0
2,-15,-3:1.0
3,-15,-3:1.0
4,-15,-3:1.0
5,-15,-3:1.0
6,-15,-3:1.0
7,-15,-3:1.0
8,-15,-3:13.0
-4,-14,-3:11.10
-3,-14,-3:11.10
-2,-14,-3:49.0
-1,-14,-3:49.0
0,-14,-3:1.0
1,-14,-3:1.0
2,-14,-3:1.0
3,-14,-3:1.0
4,-14,-3:1.0
5,-14,-3:1.0
6,-14,-3:1.0
7,-14,-3:1.0
8,-14,-3:1.0
9,-14,-3:1.0
10,-14,-3:1.0
11,-14,-3:13.0
-8,-13,-3:13.0
-7,-13,-3:1.0
-6,-13,-3:1.0
-5,-13,-3:49.0
-4,-13,-3:49.0
-3,-13,-3:49.0
-2,-13,-3:49.0
-1,-13,-3:1.0
0,-13,-3:1.0
1,-13,-3:1.0
2,-13,-3:1.0
3,-13,-3:1.0
4,-13,-3:1.0
5,-13,-3:1.0
6,-13,-3:1.0
7,-13,-3:1.0
8,-13,-3:1.0
9,-13,-3:1.0
10,-13,-3:1.0
11,-13,-3:1.0
12,-13,-3:1.0
-9,-12,-3:13.0
-8,-12,-3:1.0
-7,-12,-3:1.0
-6,-12,-3:1.0
-5,-12,-3:1.0
-4,-12,-3:49.0
-3,-12,-3:49.0
-2,-12,-3:49.0
-1,-12,-3:1.0
0,-12,-3:1.0
1,-12,-3:1.0
2,-12,-3:1.0
3,-12,-3:1.0
4,-12,-3:1.0
5,-12,-3:1.0
6,-12,-3:1.0
7,-12,-3:1.0
8,-12,-3:1.0
9,-12,-3:1.0
10,-12,-3:1.0
11,-12,-3:1.0
12,-12,-3:1.0
13,-12,-3:1.0
-10,-11,-3:1.0
-9,-11,-3:1.0
-8,-11,-3:1.0
-7,-11,-3:1.0
-6,-11,-3:1.0
-5,-11,-3:1.0
-4,-11,-3:1.0
-3,-11,-3:1.0
-2,-11,-3:1.0
-1,-11,-3:1.0
0,-11,-3:1.0
1,-11,-3:1.0
2,-11,-3:1.0
3,-11,-3:1.0
4,-11,-3:1.0
5,-11,-3:1.0
6,-11,-3:1.0
7,-11,-3:1.0
8,-11,-3:1.0
9,-11,-3:1.0
10,-11,-3:1.0
11,-11,-3:1.0
12,-11,-3:1.0
13,-11,-3:1.0
-10,-10,-3:1.0
-9,-10,-3:1.0
-8,-10,-3:1.0
-7,-10,-3:1.0
-6,-10,-3:1.0
-5,-10,-3:1.0
-4,-10,-3:1.0
-3,-10,-3:1.0
-2,-10,-3:1.0
-1,-10,-3:1.0
0,-10,-3:1.0
1,-10,-3:1.0
2,-10,-3:1.0
3,-10,-3:1.0
4,-10,-3:1.0
5,-10,-3:1.0
6,-10,-3:1.0
7,-10,-3:1.0
8,-10,-3:1.0
9,-10,-3:1.0
10,-10,-3:1.0
11,-10,-3:1.0
12,-10,-3:1.0
13,-10,-3:1.0
-11,-9,-3:13.0
-10,-9,-3:1.0
-9,-9,-3:1.0
-8,-9,-3:1.0
-7,-9,-3:1.0
-6,-9,-3:1.0
-5,-9,-3:1.0
-4,-9,-3:1.0
-3,-9,-3:1.0
-2,-9,-3:1.0
-1,-9,-3:1.0
0,-9,-3:1.0
1,-9,-3:1.0
2,-9,-3:1.0
3,-9,-3:1.0
4,-9,-3:1.0
5,-9,-3:1.0
6,-9,-3:1.0
7,-9,-3:1.0
8,-9,-3:1.0
9,-9,-3:1.0
10,-9,-3:1.0
11,-9,-3:1.0
12,-9,-3:1.0
13,-9,-3:1.0
14,-9,-3:13.0
-11,-8,-3:1.0
-10,-8,-3:1.0
-9,-8,-3:1.0
-8,-8,-3:1.0
-7,-8,-3:1.0
-6,-8,-3:1.0
-5,-8,-3:1.0
-4,-8,-3:1.0
-3,-8,-3:1.0
-2,-8,-3:1.0
-1,-8,-3:1.0
0,-8,-3:1.0
1,-8,-3:1.0
2,-8,-3:1.0
3,-8,-3:1.0
4,-8,-3:1.0
5,-8,-3:1.0
6,-8,-3:1.0
7,-8,-3:1.0
8,-8,-3:1.0
9,-8,-3:1.0
10,-8,-3:1.0
11,-8,-3:1.0
12,-8,-3:1.0
13,-8,-3:1.0
14,-8,-3:13.0
15,-8,-3:13.0
-11,-7,-3:1.0
-10,-7,-3:1.0
-9,-7,-3:1.0
-8,-7,-3:1.0
-7,-7,-3:1.0
-6,-7,-3:1.0
-5,-7,-3:1.0
-4,-7,-3:1.0
-3,-7,-3:1.0
-2,-7,-3:1.0
-1,-7,-3:1.0
0,-7,-3:1.0
1,-7,-3:1.0
2,-7,-3:1.0
3,-7,-3:1.0
4,-7,-3:1.0
5,-7,-3:1.0
6,-7,-3:1.0
7,-7,-3:1.0
8,-7,-3:1.0
9,-7,-3:1.0
10,-7,-3:1.0
11,-7,-3:1.0
12,-7,-3:1.0
13,-7,-3:1.0
14,-7,-3:13.0
15,-7,-3:13.0
-11,-6,-3:1.0
-10,-6,-3:1.0
-9,-6,-3:1.0
-8,-6,-3:1.0
-7,-6,-3:1.0
-6,-6,-3:1.0
-5,-6,-3:1.0
-4,-6,-3:1.0
-3,-6,-3:1.0
-2,-6,-3:1.0
-1,-6,-3:1.0
0,-6,-3:1.0
1,-6,-3:1.0
2,-6,-3:1.0
3,-6,-3:1.0
4,-6,-3:1.0
5,-6,-3:1.0
6,-6,-3:1.0
7,-6,-3:1.0
8,-6,-3:1.0
9,-6,-3:1.0
10,-6,-3:1.0
11,-6,-3:1.0
12,-6,-3:1.0
13,-6,-3:1.0
14,-6,-3:13.0
15,-6,-3:13.0
-12,-5,-3:13.0
-11,-5,-3:1.0
-10,-5,-3:1.0
-9,-5,-3:1.0
-8,-5,-3:1.0
-7,-5,-3:1.0
-6,-5,-3:1.0
-5,-5,-3:1.0
-4,-5,-3:1.0
-3,-5,-3:1.0
-2,-5,-3:1.0
-1,-5,-3:1.0
0,-5,-3:1.0
1,-5,-3:11.0
2,-5,-3:11.0
3,-5,-3:1.0
4,-5,-3:1.0
5,-5,-3:1.0
6,-5,-3:1.0
7,-5,-3:1.0
8,-5,-3:1.0
9,-5,-3:1.0
10,-5,-3:1.0
11,-5,-3:1.0
12,-5,-3:1.0
13,-5,-3:1.0
14,-5,-3:13.0
-13,-4,-3:13.0
-12,-4,-3:1.0
-11,-4,-3:1.0
-10,-4,-3:1.0
-9,-4,-3:1.0
-8,-4,-3:1.0
-7,-4,-3:1.0
-6,-4,-3:1.0
-5,-4,-3:1.0
-4,-4,-3:1.0
-3,-4,-3:1.0
-2,-4,-3:11.0
-1,-4,-3:11.0
0,-4,-3:11.0
1,-4,-3:11.0
2,-4,-3:11.0
3,-4,-3:11.0
4,-4,-3:11.0
5,-4,-3:1.0
6,-4,-3:1.0
7,-4,-3:1.0
8,-4,-3:1.0
9,-4,-3:1.0
10,-4,-3:1.0
11,-4,-3:1.0
12,-4,-3:1.0
13,-4,-3:1.0
14,-4,-3:13.0
-13,-3,-3:13.0
-12,-3,-3:1.0
-11,-3,-3:1.0
-10,-3,-3:1.0
-9,-3,-3:1.0
-8,-3,-3:1.0
-7,-3,-3:1.0
-6,-3,-3:1.0
-5,-3,-3:1.0
-4,-3,-3:1.0
-3,-3,-3:1.0
-2,-3,-3:11.0
-1,-3,-3:11.0
0,-3,-3:11.0
1,-3,-3:11.0
2,-3,-3:11.0
3,-3,-3:11.0
4,-3,-3:11.0
5,-3,-3:1.0
6,-3,-3:1.0
7,-3,-3:1.0
8,-3,-3:1.0
9,-3,-3:1.0
10,-3,-3:1.0
11,-3,-3:1.0
12,-3,-3:1.0
13,-3,-3:1.0
14,-3,-3:13.0
-13,-2,-3:1.0
-12,-2,-3:1.0
-11,-2,-3:1.0
-10,-2,-3:1.0
-9,-2,-3:1.0
-8,-2,-3:1.0
-7,-2,-3:1.0
-6,-2,-3:1.0
-5,-2,-3:1.0
-4,-2,-3:1.0
-3,-2,-3:1.0
-2,-2,-3:11.0
-1,-2,-3:11.0
0,-2,-3:11.0
1,-2,-3:11.0
2,-2,-3:11.0
3,-2,-3:11.0
4,-2,-3:11.0
5,-2,-3:1.0
6,-2,-3:1.0
7,-2,-3:1.0
8,-2,-3:1.0
9,-2,-3:1.0
10,-2,-3:1.0
11,-2,-3:1.0
12,-2,-3:1.0
13,-2,-3:1.0
14,-2,-3:1.0
-13,-1,-3:1.0
-12,-1,-3:1.0
-11,-1,-3:1.0
-10,-1,-3:1.0
-9,-1,-3:1.0
-8,-1,-3:1.0
-7,-1,-3:1.0
-6,-1,-3:1.0
-5,-1,-3:1.0
-4,-1,-3:1.0
-3,-1,-3:1.0
-2,-1,-3:11.0
-1,-1,-3:11.0
0,-1,-3:11.0
1,-1,-3:11.0
2,-1,-3:11.0
3,-1,-3:11.0
4,-1,-3:11.0
5,-1,-3:1.0
6,-1,-3:1.0
7,-1,-3:1.0
8,-1,-3:1.0
9,-1,-3:1.0
10,-1,-3:1.0
11,-1,-3:1.0
12,-1,-3:1.0
13,-1,-3:1.0
14,-1,-3:1.0
-13,0,-3:1.0
-12,0,-3:1.0
-11,0,-3:1.0
-10,0,-3:1.0
-9,0,-3:1.0
-8,0,-3:1.0
-7,0,-3:1.0
-6,0,-3:1.0
-5,0,-3:1.0
-4,0,-3:1.0
-3,0,-3:1.0
-2,0,-3:11.0
-1,0,-3:11.0
0,0,-3:11.0
1,0,-3:11.0
2,0,-3:11.0
3,0,-3:11.0
4,0,-3:1.0
5,0,-3:1.0
6,0,-3:1.0
7,0,-3:1.0
8,0,-3:1.0
9,0,-3:1.0
10,0,-3:1.0
11,0,-3:1.0
12,0,-3:1.0
13,0,-3:1.0
14,0,-3:1.0
-13,1,-3:1.0
-12,1,-3:1.0
-11,1,-3:1.0
-10,1,-3:1.0
-9,1,-3:1.0
-8,1,-3:1.0
-7,1,-3:1.0
-6,1,-3:1.0
-5,1,-3:1.0
-4,1,-3:1.0
-3,1,-3:1.0
-2,1,-3:1.0
-1,1,-3:11.0
0,1,-3:11.0
1,1,-3:11.0
2,1,-3:11.0
3,1,-3:11.0
4,1,-3:1.0
5,1,-3:1.0
6,1,-3:1.0
7,1,-3:1.0
8,1,-3:1.0
9,1,-3:1.0
10,1,-3:1.0
11,1,-3:1.0
12,1,-3:1.0
13,1,-3:49.0
14,1,-3:49.0
-13,2,-3:1.0
-12,2,-3:1.0
-11,2,-3:1.0
-10,2,-3:1.0
-9,2,-3:1.0
-8,2,-3:1.0
-7,2,-3:1.0
-6,2,-3:1.0
-5,2,-3:1.0
-4,2,-3:1.0
-3,2,-3:1.0
-2,2,-3:1.0
-1,2,-3:1.0
0,2,-3:1.0
1,2,-3:1.0
2,2,-3:1.0
3,2,-3:1.0
4,2,-3:1.0
5,2,-3:1.0
6,2,-3:1.0
7,2,-3:1.0
8,2,-3:1.0
9,2,-3:1.0
10,2,-3:1.0
11,2,-3:1.0
12,2,-3:1.0
13,2,-3:49.0
14,2,-3:49.0
-13,3,-3:13.0
-12,3,-3:1.0
-11,3,-3:1.0
-10,3,-3:1.0
-9,3,-3:1.0
-8,3,-3:1.0
-7,3,-3:1.0
-6,3,-3:1.0
-5,3,-3:1.0
-4,3,-3:1.0
-3,3,-3:1.0
-2,3,-3:1.0
-1,3,-3:1.0
0,3,-3:1.0
1,3,-3:1.0
2,3,-3:1.0
3,3,-3:1.0
4,3,-3:1.0
5,3,-3:1.0
6,3,-3:1.0
7,3,-3:1.0
8,3,-3:1.0
9,3,-3:1.0
10,3,-3:1.0
11,3,-3:1.0
12,3,-3:1.0
13,3,-3:49.0
14,3,-3:49.0
15,3,-3:11.10
-13,4,-3:13.0
-12,4,-3:13.0
-11,4,-3:1.0
-10,4,-3:1.0
-9,4,-3:1.0
-8,4,-3:1.0
-7,4,-3:1.0
-6,4,-3:1.0
-5,4,-3:1.0
-4,4,-3:1.0
-3,4,-3:1.0
-2,4,-3:1.0
-1,4,-3:1.0
0,4,-3:1.0
1,4,-3:1.0
2,4,-3:1.0
3,4,-3:1.0
4,4,-3:1.0
5,4,-3:1.0
6,4,-3:1.0
7,4,-3:1.0
8,4,-3:1.0
9,4,-3:1.0
10,4,-3:1.0
11,4,-3:1.0
12,4,-3:49.0
13,4,-3:49.0
14,4,-3:49.0
15,4,-3:11.10
-12,5,-3:13.0
-11,5,-3:13.0
-10,5,-3:1.0
-9,5,-3:1.0
-8,5,-3:1.0
-7,5,-3:1.0
-6,5,-3:1.0
-5,5,-3:1.0
-4,5,-3:1.0
-3,5,-3:1.0
-2,5,-3:1.0
-1,5,-3:1.0
0,5,-3:1.0
1,5,-3:1.0
2,5,-3:1.0
3,5,-3:1.0
4,5,-3:1.0
5,5,-3:1.0
6,5,-3:1.0
7,5,-3:1.0
8,5,-3:1.0
9,5,-3:1.0
10,5,-3:1.0
11,5,-3:1.0
12,5,-3:1.0
13,5,-3:49.0
14,5,-3:49.0
-11,6,-3:13.0
-10,6,-3:1.0
-9,6,-3:1.0
-8,6,-3:1.0
-7,6,-3:1.0
-6,6,-3:1.0
-5,6,-3:1.0
-4,6,-3:1.0
-3,6,-3:1.0
-2,6,-3:1.0
-1,6,-3:1.0
0,6,-3:1.0
1,6,-3:1.0
2,6,-3:1.0
3,6,-3:1.0
4,6,-3:1.0
5,6,-3:1.0
6,6,-3:1.0
7,6,-3:1.0
8,6,-3:1.0
9,6,-3:1.0
10,6,-3:1.0
11,6,-3:1.0
12,6,-3:1.0
13,6,-3:13.0
14,6,-3:49.0
-10,7,-3:1.0
-9,7,-3:1.0
-8,7,-3:1.0
-7,7,-3:1.0
-6,7,-3:1.0
-5,7,-3:1.0
-4,7,-3:1.0
-3,7,-3:1.0
-2,7,-3:1.0
-1,7,-3:1.0
0,7,-3:1.0
1,7,-3:1.0
2,7,-3:1.0
3,7,-3:1.0
4,7,-3:1.0
5,7,-3:1.0
6,7,-3:1.0
7,7,-3:1.0
8,7,-3:1.0
9,7,-3:1.0
10,7,-3:1.0
11,7,-3:1.0
12,7,-3:1.0
13,7,-3:13.0
14,7,-3:13.0
-10,8,-3:13.0
-9,8,-3:1.0
-8,8,-3:1.0
-7,8,-3:1.0
-6,8,-3:1.0
-5,8,-3:1.0
-4,8,-3:1.0
-3,8,-3:1.0
-2,8,-3:1.0
-1,8,-3:1.0
0,8,-3:1.0
1,8,-3:1.0
2,8,-3:1.0
3,8,-3:1.0
4,8,-3:1.0
5,8,-3:1.0
6,8,-3:1.0
7,8,-3:1.0
8,8,-3:1.0
9,8,-3:1.0
10,8,-3:1.0
11,8,-3:1.0
12,8,-3:1.0
13,8,-3:13.0
14,8,-3:13.0
-10,9,-3:13.0
-9,9,-3:1.0
-8,9,-3:1.0
-7,9,-3:1.0
-6,9,-3:1.0
-5,9,-3:1.0
-4,9,-3:1.0
-3,9,-3:1.0
-2,9,-3:1.0
-1,9,-3:1.0
0,9,-3:1.0
1,9,-3:1.0
2,9,-3:1.0
3,9,-3:1.0
4,9,-3:1.0
5,9,-3:1.0
6,9,-3:1.0
7,9,-3:1.0
8,9,-3:1.0
9,9,-3:1.0
10,9,-3:1.0
11,9,-3:1.0
12,9,-3:13.0
13,9,-3:13.0
-8,10,-3:1.0
-7,10,-3:1.0
-6,10,-3:1.0
-5,10,-3:1.0
-4,10,-3:1.0
-3,10,-3:1.0
-2,10,-3:1.0
-1,10,-3:1.0
0,10,-3:1.0
1,10,-3:1.0
2,10,-3:1.0
3,10,-3:1.0
4,10,-3:1.0
5,10,-3:1.0
6,10,-3:1.0
7,10,-3:1.0
8,10,-3:1.0
9,10,-3:1.0
10,10,-3:1.0
11,10,-3:13.0
-7,11,-3:13.0
-6,11,-3:1.0
-5,11,-3:1.0
-4,11,-3:1.0
-3,11,-3:1.0
-2,11,-3:1.0
-1,11,-3:1.0
0,11,-3:1.0
1,11,-3:49.0
2,11,-3:1.0
3,11,-3:1.0
4,11,-3:1.0
5,11,-3:1.0
6,11,-3:1.0
7,11,-3:1.0
8,11,-3:1.0
9,11,-3:1.0
10,11,-3:13.0
-6,12,-3:13.0
-5,12,-3:1.0
-4,12,-3:1.0
-3,12,-3:1.0
-2,12,-3:49.0
-1,12,-3:49.0
0,12,-3:49.0
1,12,-3:49.0
2,12,-3:49.0
3,12,-3:1.0
4,12,-3:1.0
5,12,-3:1.0
6,12,-3:1.0
7,12,-3:1.0
8,12,-3:1.0
-3,13,-3:13.0
-2,13,-3:49.0
-1,13,-3:49.0
0,13,-3:49.0
1,13,-3:49.0
2,13,-3:1.0
3,13,-3:1.0
4,13,-3:1.0
5,13,-3:1.0
6,13,-3:1.0
7,13,-3:13.0
8,13,-3:13.0
-1,14,-3:11.10
0,14,-3:11.10
3,14,-3:13.0
4,14,-3:13.0
5,14,-3:13.0
6,14,-3:13.0
7,14,-3:13.0
0,-18,-2:13.0
1,-18,-2:13.0
2,-18,-2:13.0
-1,-17,-2:13.0
0,-17,-2:13.0
1,-17,-2:1.0
2,-17,-2:1.0
3,-17,-2:13.0
-1,-16,-2:49.0
0,-16,-2:1.0
1,-16,-2:1.0
2,-16,-2:1.0
3,-16,-2:1.0
4,-16,-2:13.0
5,-16,-2:13.0
-2,-15,-2:49.0
-1,-15,-2:49.0
0,-15,-2:1.0
1,-15,-2:1.0
2,-15,-2:1.0
3,-15,-2:1.0
4,-15,-2:1.0
5,-15,-2:1.0
6,-15,-2:1.0
7,-15,-2:1.0
8,-15,-2:13.0
-4,-14,-2:11.10
-3,-14,-2:11.10
-2,-14,-2:49.0
-1,-14,-2:49.0
0,-14,-2:1.0
1,-14,-2:1.0
2,-14,-2:1.0
3,-14,-2:1.0
4,-14,-2:1.0
5,-14,-2:1.0
6,-14,-2:1.0
7,-14,-2:1.0
8,-14,-2:1.0
9,-14,-2:1.0
10,-14,-2:1.0
11,-14,-2:13.0
-7,-13,-2:13.0
-6,-13,-2:13.0
-5,-13,-2:49.0
-4,-13,-2:49.0
-3,-13,-2:49.0
-2,-13,-2:49.0
-1,-13,-2:49.0
0,-13,-2:1.0
1,-13,-2:1.0
2,-13,-2:1.0
3,-13,-2:1.0
4,-13,-2:1.0
5,-13,-2:1.0
6,-13,-2:1.0
7,-13,-2:1.0
8,-13,-2:1.0
9,-13,-2:1.0
10,-13,-2:1.0
11,-13,-2:1.0
12,-13,-2:13.0
-8,-12,-2:1.0
-7,-12,-2:1.0
-6,-12,-2:1.0
-5,-12,-2:49.0
-4,-12,-2:49.0
-3,-12,-2:49.0
-2,-12,-2:49.0
-1,-12,-2:1.0
0,-12,-2:1.0
1,-12,-2:1.0
2,-12,-2:1.0
3,-12,-2:1.0
4,-12,-2:1.0
5,-12,-2:1.0
6,-12,-2:1.0
7,-12,-2:1.0
8,-12,-2:1.0
9,-12,-2:1.0
10,-12,-2:1.0
11,-12,-2:1.0
12,-12,-2:1.0
13,-12,-2:1.0
-10,-11,-2:13.0
-9,-11,-2:1.0
-8,-11,-2:1.0
-7,-11,-2:1.0
-6,-11,-2:1.0
-5,-11,-2:1.0
-4,-11,-2:1.0
-3,-11,-2:1.0
-2,-11,-2:1.0
-1,-11,-2:1.0
0,-11,-2:1.0
1,-11,-2:1.0
2,-11,-2:1.0
3,-11,-2:1.0
4,-11,-2:1.0
5,-11,-2:1.0
6,-11,-2:1.0
7,-11,-2:1.0
8,-11,-2:1.0
9,-11,-2:1.0
10,-11,-2:1.0
11,-11,-2:1.0
12,-11,-2:1.0
13,-11,-2:1.0
-10,-10,-2:1.0
-9,-10,-2:1.0
-8,-10,-2:1.0
-7,-10,-2:1.0
-6,-10,-2:1.0
-5,-10,-2:1.0
-4,-10,-2:1.0
-3,-10,-2:1.0
-2,-10,-2:1.0
-1,-10,-2:1.0
0,-10,-2:1.0
1,-10,-2:1.0
2,-10,-2:1.0
3,-10,-2:1.0
4,-10,-2:1.0
5,-10,-2:1.0
6,-10,-2:1.0
7,-10,-2:1.0
8,-10,-2:1.0
9,-10,-2:1.0
10,-10,-2:1.0
11,-10,-2:1.0
12,-10,-2:1.0
13,-10,-2:1.0
-11,-9,-2:13.0
-10,-9,-2:1.0
-9,-9,-2:1.0
-8,-9,-2:1.0
-7,-9,-2:1.0
-6,-9,-2:1.0
-5,-9,-2:1.0
-4,-9,-2:1.0
-3,-9,-2:1.0
-2,-9,-2:1.0
-1,-9,-2:1.0
0,-9,-2:1.0
1,-9,-2:1.0
2,-9,-2:1.0
3,-9,-2:1.0
4,-9,-2:1.0
5,-9,-2:1.0
6,-9,-2:1.0
7,-9,-2:1.0
8,-9,-2:1.0
9,-9,-2:1.0
10,-9,-2:1.0
11,-9,-2:1.0
12,-9,-2:1.0
13,-9,-2:1.0
14,-9,-2:13.0
-11,-8,-2:1.0
-10,-8,-2:1.0
-9,-8,-2:1.0
-8,-8,-2:1.0
-7,-8,-2:1.0
-6,-8,-2:1.0
-5,-8,-2:1.0
-4,-8,-2:1.0
-3,-8,-2:1.0
-2,-8,-2:1.0
-1,-8,-2:1.0
0,-8,-2:1.0
1,-8,-2:1.0
2,-8,-2:1.0
3,-8,-2:1.0
4,-8,-2:1.0
5,-8,-2:1.0
6,-8,-2:1.0
7,-8,-2:1.0
8,-8,-2:1.0
9,-8,-2:1.0
10,-8,-2:1.0
11,-8,-2:1.0
12,-8,-2:1.0
13,-8,-2:1.0
14,-8,-2:13.0
-11,-7,-2:1.0
-10,-7,-2:1.0
-9,-7,-2:1.0
-8,-7,-2:1.0
-7,-7,-2:1.0
-6,-7,-2:1.0
-5,-7,-2:1.0
-4,-7,-2:1.0
-3,-7,-2:1.0
-2,-7,-2:1.0
-1,-7,-2:1.0
0,-7,-2:1.0
1,-7,-2:1.0
2,-7,-2:1.0
3,-7,-2:1.0
4,-7,-2:1.0
5,-7,-2:1.0
6,-7,-2:1.0
7,-7,-2:1.0
8,-7,-2:1.0
9,-7,-2:1.0
10,-7,-2:1.0
11,-7,-2:1.0
12,-7,-2:1.0
13,-7,-2:1.0
14,-7,-2:13.0
-11,-6,-2:1.0
-10,-6,-2:1.0
-9,-6,-2:1.0
-8,-6,-2:1.0
-7,-6,-2:1.0
-6,-6,-2:1.0
-5,-6,-2:1.0
-4,-6,-2:1.0
-3,-6,-2:1.0
-2,-6,-2:1.0
-1,-6,-2:1.0
0,-6,-2:11.0
1,-6,-2:11.0
2,-6,-2:11.0
3,-6,-2:11.0
4,-6,-2:11.0
5,-6,-2:1.0
6,-6,-2:1.0
7,-6,-2:1.0
8,-6,-2:1.0
9,-6,-2:1.0
10,-6,-2:1.0
11,-6,-2:1.0
12,-6,-2:1.0
13,-6,-2:1.0
14,-6,-2:13.0
-11,-5,-2:1.0
-10,-5,-2:1.0
-9,-5,-2:1.0
-8,-5,-2:1.0
-7,-5,-2:1.0
-6,-5,-2:1.0
-5,-5,-2:1.0
-4,-5,-2:1.0
-3,-5,-2:1.0
-2,-5,-2:11.0
-1,-5,-2:11.0
0,-5,-2:11.0
1,-5,-2:11.0
2,-5,-2:11.0
3,-5,-2:11.0
4,-5,-2:11.0
5,-5,-2:11.0
6,-5,-2:1.0
7,-5,-2:1.0
8,-5,-2:1.0
9,-5,-2:1.0
10,-5,-2:1.0
11,-5,-2:1.0
12,-5,-2:1.0
13,-5,-2:1.0
-12,-4,-2:1.0
-11,-4,-2:1.0
-10,-4,-2:1.0
-9,-4,-2:1.0
-8,-4,-2:1.0
-7,-4,-2:1.0
-6,-4,-2:1.0
-5,-4,-2:1.0
-4,-4,-2:1.0
-3,-4,-2:1.0
-2,-4,-2:11.0
-1,-4,-2:11.0
0,-4,-2:11.0
1,-4,-2:11.0
2,-4,-2:11.0
3,-4,-2:11.0
4,-4,-2:11.0
5,-4,-2:11.0
6,-4,-2:1.0
7,-4,-2:1.0
8,-4,-2:1.0
9,-4,-2:1.0
10,-4,-2:1.0
11,-4,-2:1.0
12,-4,-2:1.0
13,-4,-2:1.0
-13,-3,-2:13.0
-12,-3,-2:1.0
-11,-3,-2:1.0
-10,-3,-2:1.0
-9,-3,-2:1.0
-8,-3,-2:1.0
-7,-3,-2:1.0
-6,-3,-2:1.0
-5,-3,-2:1.0
-4,-3,-2:1.0
-3,-3,-2:11.0
-2,-3,-2:11.0
-1,-3,-2:11.0
0,-3,-2:11.0
1,-3,-2:11.0
2,-3,-2:11.0
3,-3,-2:11.0
4,-3,-2:11.0
5,-3,-2:11.0
6,-3,-2:11.0
7,-3,-2:1.0
8,-3,-2:1.0
9,-3,-2:1.0
10,-3,-2:1.0
11,-3,-2:1.0
12,-3,-2:1.0
13,-3,-2:1.0
14,-3,-2:13.0
-13,-2,-2:1.0
-12,-2,-2:1.0
-11,-2,-2:1.0
-10,-2,-2:1.0
-9,-2,-2:1.0
-8,-2,-2:1.0
-7,-2,-2:1.0
-6,-2,-2:1.0
-5,-2,-2:1.0
-4,-2,-2:1.0
-3,-2,-2:11.0
-2,-2,-2:11.0
-1,-2,-2:11.0
0,-2,-2:11.0
1,-2,-2:11.0
2,-2,-2:11.0
3,-2,-2:11.0
4,-2,-2:11.0
5,-2,-2:11.0
6,-2,-2:1.0
7,-2,-2:1.0
8,-2,-2:1.0
9,-2,-2:1.0
10,-2,-2:1.0
11,-2,-2:1.0
12,-2,-2:1.0
13,-2,-2:1.0
14,-2,-2:13.0
-13,-1,-2:1.0
-12,-1,-2:1.0
-11,-1,-2:1.0
-10,-1,-2:1.0
-9,-1,-2:1.0
-8,-1,-2:1.0
-7,-1,-2:1.0
-6,-1,-2:1.0
-5,-1,-2:1.0
-4,-1,-2:1.0
-3,-1,-2:11.0
-2,-1,-2:11.0
-1,-1,-2:11.0
0,-1,-2:11.0
1,-1,-2:11.0
2,-1,-2:11.0
3,-1,-2:11.0
4,-1,-2:11.0
5,-1,-2:11.0
6,-1,-2:1.0
7,-1,-2:1.0
8,-1,-2:1.0
9,-1,-2:1.0
10,-1,-2:1.0
11,-1,-2:1.0
12,-1,-2:1.0
13,-1,-2:1.0
14,-1,-2:13.0
-13,0,-2:1.0
-12,0,-2:1.0
-11,0,-2:1.0
-10,0,-2:1.0
-9,0,-2:1.0
-8,0,-2:1.0
-7,0,-2:1.0
-6,0,-2:1.0
-5,0,-2:1.0
-4,0,-2:1.0
-3,0,-2:1.0
-2,0,-2:11.0
-1,0,-2:11.0
0,0,-2:11.0
1,0,-2:11.0
2,0,-2:11.0
3,0,-2:11.0
4,0,-2:11.0
5,0,-2:11.0
6,0,-2:1.0
7,0,-2:1.0
8,0,-2:1.0
9,0,-2:1.0
10,0,-2:1.0
11,0,-2:1.0
12,0,-2:1.0
13,0,-2:1.0
14,0,-2:13.0
-13,1,-2:1.0
-12,1,-2:1.0
-11,1,-2:1.0
-10,1,-2:1.0
-9,1,-2:1.0
-8,1,-2:1.0
-7,1,-2:1.0
-6,1,-2:1.0
-5,1,-2:1.0
-4,1,-2:1.0
-3,1,-2:1.0
-2,1,-2:11.0
-1,1,-2:11.0
0,1,-2:11.0
1,1,-2:11.0
2,1,-2:11.0
3,1,-2:11.0
4,1,-2:11.0
5,1,-2:1.0
6,1,-2:1.0
7,1,-2:1.0
8,1,-2:1.0
9,1,-2:1.0
10,1,-2:1.0
11,1,-2:1.0
12,1,-2:1.0
13,1,-2:49.0
14,1,-2:49.0
-13,2,-2:1.0
-12,2,-2:1.0
-11,2,-2:1.0
-10,2,-2:1.0
-9,2,-2:1.0
-8,2,-2:1.0
-7,2,-2:1.0
-6,2,-2:1.0
-5,2,-2:1.0
-4,2,-2:1.0
-3,2,-2:1.0
-2,2,-2:1.0
-1,2,-2:1.0
0,2,-2:11.0
1,2,-2:11.0
2,2,-2:11.0
3,2,-2:11.0
4,2,-2:1.0
5,2,-2:1.0
6,2,-2:1.0
7,2,-2:1.0
8,2,-2:1.0
9,2,-2:1.0
10,2,-2:1.0
11,2,-2:1.0
12,2,-2:1.0
13,2,-2:49.0
14,2,-2:49.0
-13,3,-2:13.0
-12,3,-2:1.0
-11,3,-2:1.0
-10,3,-2:1.0
-9,3,-2:1.0
-8,3,-2:1.0
-7,3,-2:1.0
-6,3,-2:1.0
-5,3,-2:1.0
-4,3,-2:1.0
-3,3,-2:1.0
-2,3,-2:1.0
-1,3,-2:1.0
0,3,-2:1.0
1,3,-2:1.0
2,3,-2:1.0
3,3,-2:1.0
4,3,-2:1.0
5,3,-2:1.0
6,3,-2:1.0
7,3,-2:1.0
8,3,-2:1.0
9,3,-2:1.0
10,3,-2:1.0
11,3,-2:1.0
12,3,-2:49.0
13,3,-2:49.0
14,3,-2:11.0
15,3,-2:11.2
-12,4,-2:13.0
-11,4,-2:13.0
-10,4,-2:1.0
-9,4,-2:1.0
-8,4,-2:1.0
-7,4,-2:1.0
-6,4,-2:1.0
-5,4,-2:1.0
-4,4,-2:1.0
-3,4,-2:1.0
-2,4,-2:1.0
-1,4,-2:1.0
0,4,-2:1.0
1,4,-2:1.0
2,4,-2:1.0
3,4,-2:1.0
4,4,-2:1.0
5,4,-2:1.0
6,4,-2:1.0
7,4,-2:1.0
8,4,-2:1.0
9,4,-2:1.0
10,4,-2:1.0
11,4,-2:1.0
12,4,-2:49.0
13,4,-2:49.0
14,4,-2:11.0
15,4,-2:11.2
-11,5,-2:13.0
-10,5,-2:1.0
-9,5,-2:1.0
-8,5,-2:1.0
-7,5,-2:1.0
-6,5,-2:1.0
-5,5,-2:1.0
-4,5,-2:1.0
-3,5,-2:1.0
-2,5,-2:1.0
-1,5,-2:1.0
0,5,-2:1.0
1,5,-2:1.0
2,5,-2:1.0
3,5,-2:1.0
4,5,-2:1.0
5,5,-2:1.0
6,5,-2:1.0
7,5,-2:1.0
8,5,-2:1.0
9,5,-2:1.0
10,5,-2:1.0
11,5,-2:1.0
12,5,-2:49.0
13,5,-2:49.0
14,5,-2:49.0
-10,6,-2:1.0
-9,6,-2:1.0
-8,6,-2:1.0
-7,6,-2:1.0
-6,6,-2:1.0
-5,6,-2:1.0
-4,6,-2:1.0
-3,6,-2:1.0
-2,6,-2:1.0
-1,6,-2:1.0
0,6,-2:1.0
1,6,-2:1.0
2,6,-2:1.0
3,6,-2:1.0
4,6,-2:1.0
5,6,-2:1.0
6,6,-2:1.0
7,6,-2:1.0
8,6,-2:1.0
9,6,-2:1.0
10,6,-2:1.0
11,6,-2:1.0
12,6,-2:1.0
13,6,-2:49.0
-10,7,-2:1.0
-9,7,-2:1.0
-8,7,-2:1.0
-7,7,-2:1.0
-6,7,-2:1.0
-5,7,-2:1.0
-4,7,-2:1.0
-3,7,-2:1.0
-2,7,-2:1.0
-1,7,-2:1.0
0,7,-2:1.0
1,7,-2:1.0
2,7,-2:1.0
3,7,-2:1.0
4,7,-2:1.0
5,7,-2:1.0
6,7,-2:1.0
7,7,-2:1.0
8,7,-2:1.0
9,7,-2:1.0
10,7,-2:1.0
11,7,-2:1.0
12,7,-2:1.0
13,7,-2:13.0
-10,8,-2:13.0
-9,8,-2:1.0
-8,8,-2:1.0
-7,8,-2:1.0
-6,8,-2:1.0
-5,8,-2:1.0
-4,8,-2:1.0
-3,8,-2:1.0
-2,8,-2:1.0
-1,8,-2:1.0
0,8,-2:1.0
1,8,-2:1.0
2,8,-2:1.0
3,8,-2:1.0
4,8,-2:1.0
5,8,-2:1.0
6,8,-2:1.0
7,8,-2:1.0
8,8,-2:1.0
9,8,-2:1.0
10,8,-2:1.0
11,8,-2:1.0
12,8,-2:1.0
13,8,-2:13.0
-9,9,-2:13.0
-8,9,-2:1.0
-7,9,-2:1.0
-6,9,-2:1.0
-5,9,-2:1.0
-4,9,-2:1.0
-3,9,-2:1.0
-2,9,-2:1.0
-1,9,-2:1.0
0,9,-2:1.0
1,9,-2:1.0
2,9,-2:1.0
3,9,-2:1.0
4,9,-2:1.0
5,9,-2:1.0
6,9,-2:1.0
7,9,-2:1.0
8,9,-2:1.0
9,9,-2:1.0
10,9,-2:1.0
11,9,-2:1.0
12,9,-2:13.0
-8,10,-2:1.0
-7,10,-2:1.0
-6,10,-2:1.0
-5,10,-2:1.0
-4,10,-2:1.0
-3,10,-2:1.0
-2,10,-2:1.0
-1,10,-2:1.0
0,10,-2:1.0
1,10,-2:1.0
2,10,-2:1.0
3,10,-2:1.0
4,10,-2:1.0
5,10,-2:1.0
6,10,-2:1.0
7,10,-2:1.0
8,10,-2:1.0
9,10,-2:1.0
10,10,-2:1.0
-7,11,-2:13.0
-6,11,-2:1.0
-5,11,-2:1.0
-4,11,-2:1.0
-3,11,-2:1.0
-2,11,-2:1.0
-1,11,-2:1.0
0,11,-2:49.0
1,11,-2:49.0
2,11,-2:49.0
3,11,-2:1.0
4,11,-2:1.0
5,11,-2:1.0
6,11,-2:1.0
7,11,-2:1.0
8,11,-2:1.0
9,11,-2:1.0
-5,12,-2:13.0
-4,12,-2:1.0
-3,12,-2:1.0
-2,12,-2:49.0
-1,12,-2:49.0
0,12,-2:49.0
1,12,-2:49.0
2,12,-2:49.0
3,12,-2:1.0
4,12,-2:1.0
5,12,-2:1.0
6,12,-2:1.0
7,12,-2:1.0
8,12,-2:13.0
-2,13,-2:49.0
-1,13,-2:11.10
0,13,-2:11.10
1,13,-2:49.0
2,13,-2:49.0
3,13,-2:1.0
4,13,-2:1.0
5,13,-2:1.0
6,13,-2:13.0
7,13,-2:13.0
-1,14,-2:11.2
0,14,-2:11.2
4,14,-2:13.0
5,14,-2:13.0
6,14,-2:13.0
0,-17,-1:13.0
1,-17,-1:13.0
2,-17,-1:13.0
3,-17,-1:13.0
-1,-16,-1:13.0
0,-16,-1:1.0
1,-16,-1:1.0
2,-16,-1:1.0
3,-16,-1:1.0
4,-16,-1:13.0
-2,-15,-1:49.0
-1,-15,-1:49.0
0,-15,-1:1.0
1,-15,-1:1.0
2,-15,-1:1.0
3,-15,-1:1.0
4,-15,-1:1.0
5,-15,-1:1.0
6,-15,-1:1.0
7,-15,-1:13.0
-4,-14,-1:11.2
-3,-14,-1:11.10
-2,-14,-1:11.0
-1,-14,-1:49.0
0,-14,-1:1.0
1,-14,-1:1.0
2,-14,-1:1.0
3,-14,-1:1.0
4,-14,-1:1.0
5,-14,-1:1.0
6,-14,-1:1.0
7,-14,-1:1.0
8,-14,-1:1.0
9,-14,-1:1.0
10,-14,-1:1.0
-7,-13,-1:13.0
-6,-13,-1:13.0
-5,-13,-1:49.0
-4,-13,-1:11.0
-3,-13,-1:49.0
-2,-13,-1:49.0
-1,-13,-1:49.0
0,-13,-1:1.0
1,-13,-1:1.0
2,-13,-1:1.0
3,-13,-1:1.0
4,-13,-1:1.0
5,-13,-1:1.0
6,-13,-1:1.0
7,-13,-1:1.0
8,-13,-1:1.0
9,-13,-1:1.0
10,-13,-1:1.0
11,-13,-1:1.0
12,-13,-1:13.0
-8,-12,-1:1.0
-7,-12,-1:1.0
-6,-12,-1:1.0
-5,-12,-1:1.0
-4,-12,-1:49.0
-3,-12,-1:49.0
-2,-12,-1:49.0
-1,-12,-1:49.0
0,-12,-1:1.0
1,-12,-1:1.0
2,-12,-1:1.0
3,-12,-1:1.0
4,-12,-1:1.0
5,-12,-1:1.0
6,-12,-1:1.0
7,-12,-1:1.0
8,-12,-1:1.0
9,-12,-1:1.0
10,-12,-1:1.0
11,-12,-1:1.0
12,-12,-1:1.0
13,-12,-1:1.0
-10,-11,-1:13.0
-9,-11,-1:1.0
-8,-11,-1:1.0
-7,-11,-1:1.0
-6,-11,-1:1.0
-5,-11,-1:1.0
-4,-11,-1:1.0
-3,-11,-1:1.0
-2,-11,-1:1.0
-1,-11,-1:1.0
0,-11,-1:1.0
1,-11,-1:1.0
2,-11,-1:1.0
3,-11,-1:1.0
4,-11,-1:1.0
5,-11,-1:1.0
6,-11,-1:1.0
7,-11,-1:1.0
8,-11,-1:1.0
9,-11,-1:1.0
10,-11,-1:1.0
11,-11,-1:1.0
12,-11,-1:1.0
13,-11,-1:1.0
-10,-10,-1:1.0
-9,-10,-1:1.0
-8,-10,-1:1.0
-7,-10,-1:1.0
-6,-10,-1:1.0
-5,-10,-1:1.0
-4,-10,-1:1.0
-3,-10,-1:1.0
-2,-10,-1:1.0
-1,-10,-1:1.0
0,-10,-1:1.0
1,-10,-1:1.0
2,-10,-1:1.0
3,-10,-1:1.0
4,-10,-1:1.0
5,-10,-1:1.0
6,-10,-1:1.0
7,-10,-1:1.0
8,-10,-1:1.0
9,-10,-1:1.0
10,-10,-1:1.0
11,-10,-1:1.0
12,-10,-1:1.0
13,-10,-1:1.0
-10,-9,-1:1.0
-9,-9,-1:1.0
-8,-9,-1:1.0
-7,-9,-1:1.0
-6,-9,-1:1.0
-5,-9,-1:1.0
-4,-9,-1:1.0
-3,-9,-1:1.0
-2,-9,-1:1.0
-1,-9,-1:1.0
0,-9,-1:1.0
1,-9,-1:1.0
2,-9,-1:1.0
3,-9,-1:1.0
4,-9,-1:1.0
5,-9,-1:1.0
6,-9,-1:1.0
7,-9,-1:1.0
8,-9,-1:1.0
9,-9,-1:1.0
10,-9,-1:1.0
11,-9,-1:1.0
12,-9,-1:1.0
13,-9,-1:1.0
-11,-8,-1:1.0
-10,-8,-1:1.0
-9,-8,-1:1.0
-8,-8,-1:1.0
-7,-8,-1:1.0
-6,-8,-1:1.0
-5,-8,-1:1.0
-4,-8,-1:1.0
-3,-8,-1:1.0
-2,-8,-1:1.0
-1,-8,-1:1.0
0,-8,-1:1.0
1,-8,-1:1.0
2,-8,-1:1.0
3,-8,-1:1.0
4,-8,-1:1.0
5,-8,-1:1.0
6,-8,-1:1.0
7,-8,-1:1.0
8,-8,-1:1.0
9,-8,-1:1.0
10,-8,-1:1.0
11,-8,-1:1.0
12,-8,-1:1.0
13,-8,-1:1.0
-11,-7,-1:1.0
-10,-7,-1:1.0
-9,-7,-1:1.0
-8,-7,-1:1.0
-7,-7,-1:1.0
-6,-7,-1:1.0
-5,-7,-1:1.0
-4,-7,-1:1.0
-3,-7,-1:1.0
-2,-7,-1:1.0
-1,-7,-1:1.0
0,-7,-1:1.0
1,-7,-1:1.0
2,-7,-1:1.0
3,-7,-1:1.0
4,-7,-1:1.0
5,-7,-1:1.0
6,-7,-1:1.0
7,-7,-1:1.0
8,-7,-1:1.0
9,-7,-1:1.0
10,-7,-1:1.0
11,-7,-1:1.0
12,-7,-1:1.0
13,-7,-1:1.0
-11,-6,-1:1.0
-10,-6,-1:1.0
-9,-6,-1:1.0
-8,-6,-1:1.0
-7,-6,-1:1.0
-6,-6,-1:1.0
-5,-6,-1:1.0
-4,-6,-1:1.0
-3,-6,-1:1.0
-2,-6,-1:1.0
-1,-6,-1:1.0
0,-6,-1:11.0
1,-6,-1:11.0
2,-6,-1:11.0
3,-6,-1:11.0
4,-6,-1:11.0
5,-6,-1:1.0
6,-6,-1:1.0
7,-6,-1:1.0
8,-6,-1:1.0
9,-6,-1:1.0
10,-6,-1:1.0
11,-6,-1:1.0
12,-6,-1:1.0
13,-6,-1:1.0
-11,-5,-1:1.0
-10,-5,-1:1.0
-9,-5,-1:1.0
-8,-5,-1:1.0
-7,-5,-1:1.0
-6,-5,-1:1.0
-5,-5,-1:1.0
-4,-5,-1:1.0
-3,-5,-1:1.0
-2,-5,-1:11.0
-1,-5,-1:11.0
0,-5,-1:11.0
1,-5,-1:11.0
2,-5,-1:11.0
3,-5,-1:11.0
4,-5,-1:11.0
5,-5,-1:11.0
6,-5,-1:1.0
7,-5,-1:1.0
8,-5,-1:1.0
9,-5,-1:1.0
10,-5,-1:1.0
11,-5,-1:1.0
12,-5,-1:1.0
13,-5,-1:1.0
-12,-4,-1:1.0
-11,-4,-1:1.0
-10,-4,-1:1.0
-9,-4,-1:1.0
-8,-4,-1:1.0
-7,-4,-1:1.0
-6,-4,-1:1.0
-5,-4,-1:1.0
-4,-4,-1:1.0
-3,-4,-1:1.0
-2,-4,-1:11.0
-1,-4,-1:11.0
0,-4,-1:11.0
1,-4,-1:11.0
2,-4,-1:11.0
3,-4,-1:11.0
4,-4,-1:11.0
5,-4,-1:11.0
6,-4,-1:13.0
7,-4,-1:1.0
8,-4,-1:1.0
9,-4,-1:1.0
10,-4,-1:1.0
11,-4,-1:1.0
12,-4,-1:1.0
13,-4,-1:1.0
-12,-3,-1:1.0
-11,-3,-1:1.0
-10,-3,-1:1.0
-9,-3,-1:1.0
-8,-3,-1:1.0
-7,-3,-1:1.0
-6,-3,-1:1.0
-5,-3,-1:1.0
-4,-3,-1:1.0
-3,-3,-1:1.0
-2,-3,-1:11.0
-1,-3,-1:11.0
0,-3,-1:11.0
1,-3,-1:11.0
2,-3,-1:11.0
3,-3,-1:11.0
4,-3,-1:11.0
5,-3,-1:11.0
6,-3,-1:11.0
7,-3,-1:1.0
8,-3,-1:1.0
9,-3,-1:1.0
10,-3,-1:1.0
11,-3,-1:1.0
12,-3,-1:1.0
13,-3,-1:1.0
-13,-2,-1:13.0
-12,-2,-1:1.0
-11,-2,-1:1.0
-10,-2,-1:1.0
-9,-2,-1:1.0
-8,-2,-1:1.0
-7,-2,-1:1.0
-6,-2,-1:1.0
-5,-2,-1:1.0
-4,-2,-1:1.0
-3,-2,-1:11.0
-2,-2,-1:11.0
-1,-2,-1:11.0
0,-2,-1:11.0
1,-2,-1:11.0
2,-2,-1:11.0
3,-2,-1:11.0
4,-2,-1:11.0
5,-2,-1:11.0
6,-2,-1:1.0
7,-2,-1:1.0
8,-2,-1:1.0
9,-2,-1:1.0
10,-2,-1:1.0
11,-2,-1:1.0
12,-2,-1:1.0
13,-2,-1:1.0
14,-2,-1:13.0
-13,-1,-1:1.0
-12,-1,-1:1.0
-11,-1,-1:1.0
-10,-1,-1:1.0
-9,-1,-1:1.0
-8,-1,-1:1.0
-7,-1,-1:1.0
-6,-1,-1:1.0
-5,-1,-1:1.0
-4,-1,-1:1.0
-3,-1,-1:1.0
-2,-1,-1:11.0
-1,-1,-1:11.0
0,-1,-1:11.0
1,-1,-1:11.0
2,-1,-1:11.0
3,-1,-1:11.0
4,-1,-1:11.0
5,-1,-1:11.0
6,-1,-1:1.0
7,-1,-1:1.0
8,-1,-1:1.0
9,-1,-1:1.0
10,-1,-1:1.0
11,-1,-1:1.0
12,-1,-1:1.0
13,-1,-1:1.0
14,-1,-1:13.0
-13,0,-1:1.0
-12,0,-1:1.0
-11,0,-1:1.0
-10,0,-1:1.0
-9,0,-1:1.0
-8,0,-1:1.0
-7,0,-1:1.0
-6,0,-1:1.0
-5,0,-1:1.0
-4,0,-1:1.0
-3,0,-1:1.0
-2,0,-1:11.0
-1,0,-1:11.0
0,0,-1:11.0
1,0,-1:11.0
2,0,-1:11.0
3,0,-1:11.0
4,0,-1:11.0
5,0,-1:11.0
6,0,-1:1.0
7,0,-1:1.0
8,0,-1:1.0
9,0,-1:1.0
10,0,-1:1.0
11,0,-1:1.0
12,0,-1:1.0
13,0,-1:1.0
14,0,-1:13.0
-13,1,-1:1.0
-12,1,-1:1.0
-11,1,-1:1.0
-10,1,-1:1.0
-9,1,-1:1.0
-8,1,-1:1.0
-7,1,-1:1.0
-6,1,-1:1.0
-5,1,-1:1.0
-4,1,-1:1.0
-3,1,-1:1.0
-2,1,-1:1.0
-1,1,-1:11.0
0,1,-1:11.0
1,1,-1:11.0
2,1,-1:11.0
3,1,-1:11.0
4,1,-1:11.0
5,1,-1:1.0
6,1,-1:1.0
7,1,-1:1.0
8,1,-1:1.0
9,1,-1:1.0
10,1,-1:1.0
11,1,-1:1.0
12,1,-1:1.0
13,1,-1:49.0
14,1,-1:49.0
-13,2,-1:13.0
-12,2,-1:1.0
-11,2,-1:1.0
-10,2,-1:1.0
-9,2,-1:1.0
-8,2,-1:1.0
-7,2,-1:1.0
-6,2,-1:1.0
-5,2,-1:1.0
-4,2,-1:1.0
-3,2,-1:1.0
-2,2,-1:1.0
-1,2,-1:1.0
0,2,-1:1.0
1,2,-1:11.0
2,2,-1:11.0
3,2,-1:11.0
4,2,-1:1.0
5,2,-1:1.0
6,2,-1:1.0
7,2,-1:1.0
8,2,-1:1.0
9,2,-1:1.0
10,2,-1:1.0
11,2,-1:1.0
12,2,-1:49.0
13,2,-1:49.0
14,2,-1:49.0
-12,3,-1:13.0
-11,3,-1:1.0
-10,3,-1:1.0
-9,3,-1:1.0
-8,3,-1:1.0
-7,3,-1:1.0
-6,3,-1:1.0
-5,3,-1:1.0
-4,3,-1:1.0
-3,3,-1:1.0
-2,3,-1:1.0
-1,3,-1:1.0
0,3,-1:1.0
1,3,-1:1.0
2,3,-1:1.0
3,3,-1:1.0
4,3,-1:1.0
5,3,-1:1.0
6,3,-1:1.0
7,3,-1:1.0
8,3,-1:1.0
9,3,-1:1.0
10,3,-1:1.0
11,3,-1:1.0
12,3,-1:49.0
13,3,-1:49.0
14,3,-1:11.10
-11,4,-1:13.0
-10,4,-1:1.0
-9,4,-1:1.0
-8,4,-1:1.0
-7,4,-1:1.0
-6,4,-1:1.0
-5,4,-1:1.0
-4,4,-1:1.0
-3,4,-1:1.0
-2,4,-1:1.0
-1,4,-1:1.0
0,4,-1:1.0
1,4,-1:1.0
2,4,-1:1.0
3,4,-1:1.0
4,4,-1:1.0
5,4,-1:1.0
6,4,-1:1.0
7,4,-1:1.0
8,4,-1:1.0
9,4,-1:1.0
10,4,-1:1.0
11,4,-1:1.0
12,4,-1:49.0
13,4,-1:49.0
14,4,-1:11.10
-10,5,-1:1.0
-9,5,-1:1.0
-8,5,-1:1.0
-7,5,-1:1.0
-6,5,-1:1.0
-5,5,-1:1.0
-4,5,-1:1.0
-3,5,-1:1.0
-2,5,-1:1.0
-1,5,-1:1.0
0,5,-1:1.0
1,5,-1:1.0
2,5,-1:1.0
3,5,-1:1.0
4,5,-1:1.0
5,5,-1:1.0
6,5,-1:1.0
7,5,-1:1.0
8,5,-1:1.0
9,5,-1:1.0
10,5,-1:1.0
11,5,-1:1.0
12,5,-1:1.0
13,5,-1:49.0
-10,6,-1:13.0
-9,6,-1:1.0
-8,6,-1:1.0
-7,6,-1:1.0
-6,6,-1:1.0
-5,6,-1:1.0
-4,6,-1:1.0
-3,6,-1:1.0
-2,6,-1:1.0
-1,6,-1:1.0
0,6,-1:1.0
1,6,-1:1.0
2,6,-1:1.0
3,6,-1:1.0
4,6,-1:1.0
5,6,-1:1.0
6,6,-1:1.0
7,6,-1:1.0
8,6,-1:1.0
9,6,-1:1.0
10,6,-1:1.0
11,6,-1:1.0
12,6,-1:1.0
13,6,-1:13.0
-10,7,-1:13.0
-9,7,-1:1.0
-8,7,-1:1.0
-7,7,-1:1.0
-6,7,-1:1.0
-5,7,-1:1.0
-4,7,-1:1.0
-3,7,-1:1.0
-2,7,-1:1.0
-1,7,-1:1.0
0,7,-1:1.0
1,7,-1:1.0
2,7,-1:1.0
3,7,-1:1.0
4,7,-1:1.0
5,7,-1:1.0
6,7,-1:1.0
7,7,-1:1.0
8,7,-1:1.0
9,7,-1:1.0
10,7,-1:1.0
11,7,-1:1.0
12,7,-1:1.0
-9,8,-1:13.0
-8,8,-1:1.0
-7,8,-1:1.0
-6,8,-1:1.0
-5,8,-1:1.0
-4,8,-1:1.0
-3,8,-1:1.0
-2,8,-1:1.0
-1,8,-1:1.0
0,8,-1:1.0
1,8,-1:1.0
2,8,-1:1.0
3,8,-1:1.0
4,8,-1:1.0
5,8,-1:1.0
6,8,-1:1.0
7,8,-1:1.0
8,8,-1:1.0
9,8,-1:1.0
10,8,-1:1.0
11,8,-1:1.0
12,8,-1:13.0
-9,9,-1:13.0
-8,9,-1:1.0
-7,9,-1:1.0
-6,9,-1:1.0
-5,9,-1:1.0
-4,9,-1:1.0
-3,9,-1:1.0
-2,9,-1:1.0
-1,9,-1:1.0
0,9,-1:1.0
1,9,-1:1.0
2,9,-1:1.0
3,9,-1:1.0
4,9,-1:1.0
5,9,-1:1.0
6,9,-1:1.0
7,9,-1:1.0
8,9,-1:1.0
9,9,-1:1.0
10,9,-1:1.0
11,9,-1:13.0
-8,10,-1:13.0
-7,10,-1:1.0
-6,10,-1:1.0
-5,10,-1:1.0
-4,10,-1:1.0
-3,10,-1:1.0
-2,10,-1:1.0
-1,10,-1:1.0
0,10,-1:1.0
1,10,-1:1.0
2,10,-1:1.0
3,10,-1:1.0
4,10,-1:1.0
5,10,-1:1.0
6,10,-1:1.0
7,10,-1:1.0
8,10,-1:1.0
9,10,-1:1.0
10,10,-1:13.0
-6,11,-1:1.0
-5,11,-1:1.0
-4,11,-1:1.0
-3,11,-1:1.0
-2,11,-1:1.0
-1,11,-1:49.0
0,11,-1:49.0
1,11,-1:49.0
2,11,-1:1.0
3,11,-1:1.0
4,11,-1:1.0
5,11,-1:1.0
6,11,-1:1.0
7,11,-1:1.0
8,11,-1:1.0
9,11,-1:13.0
-5,12,-1:13.0
-4,12,-1:1.0
-3,12,-1:49.0
-2,12,-1:49.0
-1,12,-1:49.0
0,12,-1:49.0
1,12,-1:49.0
2,12,-1:49.0
3,12,-1:1.0
4,12,-1:1.0
5,12,-1:13.0
6,12,-1:13.0
7,12,-1:13.0
8,12,-1:13.0
-2,13,-1:49.0
-1,13,-1:11.10
0,13,-1:11.10
1,13,-1:49.0
2,13,-1:49.0
3,13,-1:13.0
4,13,-1:13.0
5,13,-1:13.0
6,13,-1:13.0
1,-17,0:13.0
2,-17,0:13.0
0,-16,0:13.0
1,-16,0:13.0
2,-16,0:13.0
3,-16,0:13.0
-1,-15,0:49.0
0,-15,0:1.0
1,-15,0:1.0
2,-15,0:1.0
3,-15,0:1.0
4,-15,0:1.0
5,-15,0:1.0
6,-15,0:1.0
7,-15,0:13.0
-3,-14,0:11.2
-2,-14,0:11.10
-1,-14,0:49.0
0,-14,0:49.0
1,-14,0:1.0
2,-14,0:1.0
3,-14,0:1.0
4,-14,0:1.0
5,-14,0:1.0
6,-14,0:1.0
7,-14,0:1.0
8,-14,0:1.0
9,-14,0:1.0
10,-14,0:13.0
-4,-13,0:11.2
-3,-13,0:11.0
-2,-13,0:49.0
-1,-13,0:49.0
0,-13,0:49.0
1,-13,0:1.0
2,-13,0:1.0
3,-13,0:1.0
4,-13,0:1.0
5,-13,0:1.0
6,-13,0:1.0
7,-13,0:1.0
8,-13,0:1.0
9,-13,0:1.0
10,-13,0:1.0
11,-13,0:13.0
-8,-12,0:13.0
-7,-12,0:1.0
-6,-12,0:1.0
-5,-12,0:1.0
-4,-12,0:49.0
-3,-12,0:49.0
-2,-12,0:49.0
-1,-12,0:49.0
0,-12,0:1.0
1,-12,0:1.0
2,-12,0:1.0
3,-12,0:1.0
4,-12,0:1.0
5,-12,0:1.0
6,-12,0:1.0
7,-12,0:1.0
8,-12,0:1.0
9,-12,0:1.0
10,-12,0:1.0
11,-12,0:1.0
12,-12,0:1.0
13,-12,0:13.0
-9,-11,0:1.0
-8,-11,0:1.0
-7,-11,0:1.0
-6,-11,0:1.0
-5,-11,0:1.0
-4,-11,0:1.0
-3,-11,0:49.0
-2,-11,0:1.0
-1,-11,0:1.0
0,-11,0:1.0
1,-11,0:1.0
2,-11,0:1.0
3,-11,0:1.0
4,-11,0:1.0
5,-11,0:1.0
6,-11,0:1.0
7,-11,0:1.0
8,-11,0:1.0
9,-11,0:1.0
10,-11,0:1.0
11,-11,0:1.0
12,-11,0:1.0
13,-11,0:1.0
-10,-10,0:1.0
-9,-10,0:1.0
-8,-10,0:1.0
-7,-10,0:1.0
-6,-10,0:1.0
-5,-10,0:1.0
-4,-10,0:1.0
-3,-10,0:1.0
-2,-10,0:1.0
-1,-10,0:1.0
0,-10,0:1.0
1,-10,0:1.0
2,-10,0:1.0
3,-10,0:1.0
4,-10,0:1.0
5,-10,0:1.0
6,-10,0:1.0
7,-10,0:1.0
8,-10,0:1.0
9,-10,0:1.0
10,-10,0:1.0
11,-10,0:1.0
12,-10,0:1.0
13,-10,0:1.0
-10,-9,0:1.0
-9,-9,0:1.0
-8,-9,0:1.0
-7,-9,0:1.0
-6,-9,0:1.0
-5,-9,0:1.0
-4,-9,0:1.0
-3,-9,0:1.0
-2,-9,0:1.0
-1,-9,0:1.0
0,-9,0:1.0
1,-9,0:1.0
2,-9,0:1.0
3,-9,0:1.0
4,-9,0:1.0
5,-9,0:1.0
6,-9,0:1.0
7,-9,0:1.0
8,-9,0:1.0
9,-9,0:1.0
10,-9,0:1.0
11,-9,0:1.0
12,-9,0:1.0
13,-9,0:1.0
-11,-8,0:1.0
-10,-8,0:1.0
-9,-8,0:1.0
-8,-8,0:1.0
-7,-8,0:1.0
-6,-8,0:1.0
-5,-8,0:1.0
-4,-8,0:1.0
-3,-8,0:1.0
-2,-8,0:1.0
-1,-8,0:1.0
0,-8,0:1.0
1,-8,0:1.0
2,-8,0:1.0
3,-8,0:1.0
4,-8,0:1.0
5,-8,0:1.0
6,-8,0:1.0
7,-8,0:1.0
8,-8,0:1.0
9,-8,0:1.0
10,-8,0:1.0
11,-8,0:1.0
12,-8,0:1.0
13,-8,0:1.0
-11,-7,0:1.0
-10,-7,0:1.0
-9,-7,0:1.0
-8,-7,0:1.0
-7,-7,0:1.0
-6,-7,0:1.0
-5,-7,0:1.0
-4,-7,0:1.0
-3,-7,0:1.0
-2,-7,0:1.0
-1,-7,0:1.0
0,-7,0:1.0
1,-7,0:1.0
2,-7,0:1.0
3,-7,0:1.0
4,-7,0:1.0
5,-7,0:1.0
6,-7,0:1.0
7,-7,0:1.0
8,-7,0:1.0
9,-7,0:1.0
10,-7,0:1.0
11,-7,0:1.0
12,-7,0:1.0
13,-7,0:1.0
-11,-6,0:1.0
-10,-6,0:1.0
-9,-6,0:1.0
-8,-6,0:1.0
-7,-6,0:1.0
-6,-6,0:1.0
-5,-6,0:1.0
-4,-6,0:1.0
-3,-6,0:1.0
-2,-6,0:1.0
-1,-6,0:1.0
0,-6,0:11.0
1,-6,0:11.0
2,-6,0:11.0
3,-6,0:11.0
4,-6,0:11.0
5,-6,0:1.0
6,-6,0:1.0
7,-6,0:1.0
8,-6,0:1.0
9,-6,0:1.0
10,-6,0:1.0
11,-6,0:1.0
12,-6,0:1.0
13,-6,0:1.0
-11,-5,0:1.0
-10,-5,0:1.0
-9,-5,0:1.0
-8,-5,0:1.0
-7,-5,0:1.0
-6,-5,0:1.0
-5,-5,0:1.0
-4,-5,0:1.0
-3,-5,0:1.0
-2,-5,0:1.0
-1,-5,0:11.0
0,-5,0:11.0
1,-5,0:11.0
2,-5,0:11.0
3,-5,0:11.0
4,-5,0:11.0
5,-5,0:11.0
6,-5,0:1.0
7,-5,0:1.0
8,-5,0:1.0
9,-5,0:1.0
10,-5,0:1.0
11,-5,0:1.0
12,-5,0:1.0
13,-5,0:1.0
-12,-4,0:13.0
-11,-4,0:1.0
-10,-4,0:1.0
-9,-4,0:1.0
-8,-4,0:1.0
-7,-4,0:1.0
-6,-4,0:1.0
-5,-4,0:1.0
-4,-4,0:1.0
-3,-4,0:1.0
-2,-4,0:11.0
-1,-4,0:11.0
0,-4,0:11.0
1,-4,0:11.0
2,-4,0:11.0
3,-4,0:11.0
4,-4,0:11.0
5,-4,0:11.0
6,-4,0:13.0
7,-4,0:1.0
8,-4,0:1.0
9,-4,0:1.0
10,-4,0:1.0
11,-4,0:1.0
12,-4,0:1.0
13,-4,0:1.0
-12,-3,0:1.0
-11,-3,0:1.0
-10,-3,0:1.0
-9,-3,0:1.0
-8,-3,0:1.0
-7,-3,0:1.0
-6,-3,0:1.0
-5,-3,0:1.0
-4,-3,0:1.0
-3,-3,0:1.0
-2,-3,0:11.0
-1,-3,0:11.0
0,-3,0:11.0
1,-3,0:11.0
2,-3,0:11.0
3,-3,0:11.0
4,-3,0:11.0
5,-3,0:11.0
6,-3,0:11.0
7,-3,0:1.0
8,-3,0:1.0
9,-3,0:1.0
10,-3,0:1.0
11,-3,0:1.0
12,-3,0:1.0
13,-3,0:1.0
-13,-2,0:13.0
-12,-2,0:1.0
-11,-2,0:1.0
-10,-2,0:1.0
-9,-2,0:1.0
-8,-2,0:1.0
-7,-2,0:1.0
-6,-2,0:1.0
-5,-2,0:1.0
-4,-2,0:1.0
-3,-2,0:1.0
-2,-2,0:11.0
-1,-2,0:11.0
0,-2,0:11.0
1,-2,0:11.0
2,-2,0:11.0
3,-2,0:11.0
4,-2,0:11.0
5,-2,0:11.0
6,-2,0:1.0
7,-2,0:1.0
8,-2,0:1.0
9,-2,0:1.0
10,-2,0:1.0
11,-2,0:1.0
12,-2,0:1.0
13,-2,0:1.0
-13,-1,0:1.0
-12,-1,0:1.0
-11,-1,0:1.0
-10,-1,0:1.0
-9,-1,0:1.0
-8,-1,0:1.0
-7,-1,0:1.0
-6,-1,0:1.0
-5,-1,0:1.0
-4,-1,0:1.0
-3,-1,0:1.0
-2,-1,0:11.0
-1,-1,0:11.0
0,-1,0:11.0
1,-1,0:11.0
2,-1,0:11.0
3,-1,0:11.0
4,-1,0:11.0
5,-1,0:11.0
6,-1,0:1.0
7,-1,0:1.0
8,-1,0:1.0
9,-1,0:1.0
10,-1,0:1.0
11,-1,0:1.0
12,-1,0:1.0
13,-1,0:1.0
-13,0,0:1.0
-12,0,0:1.0
-11,0,0:1.0
-10,0,0:1.0
-9,0,0:1.0
-8,0,0:1.0
-7,0,0:1.0
-6,0,0:1.0
-5,0,0:1.0
-4,0,0:1.0
-3,0,0:1.0
-2,0,0:11.0
-1,0,0:11.0
0,0,0:11.0
1,0,0:11.0
2,0,0:11.0
3,0,0:11.0
4,0,0:11.0
5,0,0:11.0
6,0,0:1.0
7,0,0:1.0
8,0,0:1.0
9,0,0:1.0
10,0,0:1.0
11,0,0:1.0
12,0,0:1.0
13,0,0:1.0
-13,1,0:13.0
-12,1,0:1.0
-11,1,0:1.0
-10,1,0:1.0
-9,1,0:1.0
-8,1,0:1.0
-7,1,0:1.0
-6,1,0:1.0
-5,1,0:1.0
-4,1,0:1.0
-3,1,0:1.0
-2,1,0:1.0
-1,1,0:11.0
0,1,0:11.0
1,1,0:11.0
2,1,0:11.0
3,1,0:11.0
4,1,0:11.0
5,1,0:11.0
6,1,0:1.0
7,1,0:1.0
8,1,0:1.0
9,1,0:1.0
10,1,0:1.0
11,1,0:1.0
12,1,0:49.0
13,1,0:49.0
-13,2,0:13.0
-12,2,0:13.0
-11,2,0:1.0
-10,2,0:1.0
-9,2,0:1.0
-8,2,0:1.0
-7,2,0:1.0
-6,2,0:1.0
-5,2,0:1.0
-4,2,0:1.0
-3,2,0:1.0
-2,2,0:1.0
-1,2,0:1.0
0,2,0:1.0
1,2,0:11.0
2,2,0:11.0
3,2,0:11.0
4,2,0:1.0
5,2,0:1.0
6,2,0:1.0
7,2,0:1.0
8,2,0:1.0
9,2,0:1.0
10,2,0:1.0
11,2,0:1.0
12,2,0:49.0
13,2,0:49.0
-12,3,0:13.0
-11,3,0:13.0
-10,3,0:1.0
-9,3,0:1.0
-8,3,0:1.0
-7,3,0:1.0
-6,3,0:1.0
-5,3,0:1.0
-4,3,0:1.0
-3,3,0:1.0
-2,3,0:1.0
-1,3,0:1.0
0,3,0:1.0
1,3,0:1.0
2,3,0:1.0
3,3,0:1.0
4,3,0:1.0
5,3,0:1.0
6,3,0:1.0
7,3,0:1.0
8,3,0:1.0
9,3,0:1.0
10,3,0:1.0
11,3,0:1.0
12,3,0:49.0
13,3,0:49.0
14,3,0:11.10
-10,4,0:1.0
-9,4,0:1.0
-8,4,0:1.0
-7,4,0:1.0
-6,4,0:1.0
-5,4,0:1.0
-4,4,0:1.0
-3,4,0:1.0
-2,4,0:1.0
-1,4,0:1.0
0,4,0:1.0
1,4,0:1.0
2,4,0:1.0
3,4,0:1.0
4,4,0:1.0
5,4,0:1.0
6,4,0:1.0
7,4,0:1.0
8,4,0:1.0
9,4,0:1.0
10,4,0:1.0
11,4,0:49.0
12,4,0:49.0
13,4,0:49.0
14,4,0:11.10
-10,5,0:13.0
-9,5,0:1.0
-8,5,0:1.0
-7,5,0:1.0
-6,5,0:1.0
-5,5,0:1.0
-4,5,0:1.0
-3,5,0:1.0
-2,5,0:1.0
-1,5,0:1.0
0,5,0:1.0
1,5,0:1.0
2,5,0:1.0
3,5,0:1.0
4,5,0:1.0
5,5,0:1.0
6,5,0:1.0
7,5,0:1.0
8,5,0:1.0
9,5,0:1.0
10,5,0:1.0
11,5,0:1.0
12,5,0:49.0
13,5,0:13.0
-10,6,0:13.0
-9,6,0:1.0
-8,6,0:1.0
-7,6,0:1.0
-6,6,0:1.0
-5,6,0:1.0
-4,6,0:1.0
-3,6,0:1.0
-2,6,0:1.0
-1,6,0:1.0
0,6,0:1.0
1,6,0:1.0
2,6,0:1.0
3,6,0:1.0
4,6,0:1.0
5,6,0:1.0
6,6,0:1.0
7,6,0:1.0
8,6,0:1.0
9,6,0:1.0
10,6,0:1.0
11,6,0:1.0
12,6,0:1.0
-10,7,0:13.0
-9,7,0:1.0
-8,7,0:1.0
-7,7,0:1.0
-6,7,0:1.0
-5,7,0:1.0
-4,7,0:1.0
-3,7,0:1.0
-2,7,0:1.0
-1,7,0:1.0
0,7,0:1.0
1,7,0:1.0
2,7,0:1.0
3,7,0:1.0
4,7,0:1.0
5,7,0:1.0
6,7,0:1.0
7,7,0:1.0
8,7,0:1.0
9,7,0:1.0
10,7,0:1.0
11,7,0:1.0
12,7,0:1.0
-9,8,0:13.0
-8,8,0:1.0
-7,8,0:1.0
-6,8,0:1.0
-5,8,0:1.0
-4,8,0:1.0
-3,8,0:1.0
-2,8,0:1.0
-1,8,0:1.0
0,8,0:1.0
1,8,0:1.0
2,8,0:1.0
3,8,0:1.0
4,8,0:1.0
5,8,0:1.0
6,8,0:1.0
7,8,0:1.0
8,8,0:1.0
9,8,0:1.0
10,8,0:1.0
11,8,0:1.0
12,8,0:13.0
-8,9,0:13.0
-7,9,0:1.0
-6,9,0:1.0
-5,9,0:1.0
-4,9,0:1.0
-3,9,0:1.0
-2,9,0:1.0
-1,9,0:1.0
0,9,0:1.0
1,9,0:1.0
2,9,0:1.0
3,9,0:1.0
4,9,0:1.0
5,9,0:1.0
6,9,0:1.0
7,9,0:1.0
8,9,0:1.0
9,9,0:1.0
10,9,0:1.0
11,9,0:13.0
-8,10,0:13.0
-7,10,0:13.0
-6,10,0:1.0
-5,10,0:1.0
-4,10,0:1.0
-3,10,0:1.0
-2,10,0:1.0
-1,10,0:1.0
0,10,0:1.0
1,10,0:1.0
2,10,0:1.0
3,10,0:1.0
4,10,0:1.0
5,10,0:1.0
6,10,0:1.0
7,10,0:1.0
8,10,0:1.0
9,10,0:13.0
10,10,0:13.0
-6,11,0:13.0
-5,11,0:1.0
-4,11,0:1.0
-3,11,0:1.0
-2,11,0:49.0
-1,11,0:49.0
0,11,0:49.0
1,11,0:1.0
2,11,0:1.0
3,11,0:1.0
4,11,0:1.0
5,11,0:1.0
6,11,0:1.0
7,11,0:1.0
8,11,0:13.0
9,11,0:13.0
-4,12,0:13.0
-3,12,0:1.0
-2,12,0:49.0
-1,12,0:49.0
0,12,0:49.0
1,12,0:49.0
2,12,0:13.0
3,12,0:13.0
4,12,0:13.0
5,12,0:13.0
6,12,0:13.0
7,12,0:13.0
-2,13,0:49.0
-1,13,0:11.10
0,13,0:11.10
1,13,0:49.0
2,13,0:49.0
3,13,0:13.0
4,13,0:13.0
5,13,0:13.0
0,-16,1:13.0
1,-16,1:13.0
2,-16,1:13.0
3,-16,1:13.0
-1,-15,1:49.0
0,-15,1:49.0
1,-15,1:1.0
2,-15,1:1.0
3,-15,1:1.0
4,-15,1:1.0
5,-15,1:1.0
6,-15,1:1.0
-2,-14,1:11.10
-1,-14,1:49.0
0,-14,1:49.0
1,-14,1:1.0
2,-14,1:1.0
3,-14,1:1.0
4,-14,1:1.0
5,-14,1:1.0
6,-14,1:1.0
7,-14,1:1.0
8,-14,1:1.0
9,-14,1:1.0
10,-14,1:13.0
-3,-13,1:11.10
-2,-13,1:49.0
-1,-13,1:49.0
0,-13,1:49.0
1,-13,1:1.0
2,-13,1:1.0
3,-13,1:1.0
4,-13,1:1.0
5,-13,1:1.0
6,-13,1:1.0
7,-13,1:1.0
8,-13,1:1.0
9,-13,1:1.0
10,-13,1:1.0
11,-13,1:13.0
-8,-12,1:13.0
-7,-12,1:1.0
-6,-12,1:1.0
-5,-12,1:1.0
-4,-12,1:49.0
-3,-12,1:49.0
-2,-12,1:49.0
-1,-12,1:49.0
0,-12,1:49.0
1,-12,1:1.0
2,-12,1:1.0
3,-12,1:1.0
4,-12,1:1.0
5,-12,1:1.0
6,-12,1:1.0
7,-12,1:1.0
8,-12,1:1.0
9,-12,1:1.0
10,-12,1:1.0
11,-12,1:1.0
12,-12,1:1.0
13,-12,1:13.0
-9,-11,1:1.0
-8,-11,1:1.0
-7,-11,1:1.0
-6,-11,1:1.0
-5,-11,1:1.0
-4,-11,1:49.0
-3,-11,1:49.0
-2,-11,1:49.0
-1,-11,1:1.0
0,-11,1:1.0
1,-11,1:1.0
2,-11,1:1.0
3,-11,1:1.0
4,-11,1:1.0
5,-11,1:1.0
6,-11,1:1.0
7,-11,1:1.0
8,-11,1:1.0
9,-11,1:1.0
10,-11,1:1.0
11,-11,1:1.0
12,-11,1:1.0
13,-11,1:1.0
-10,-10,1:1.0
-9,-10,1:1.0
-8,-10,1:1.0
-7,-10,1:1.0
-6,-10,1:1.0
-5,-10,1:1.0
-4,-10,1:1.0
-3,-10,1:1.0
-2,-10,1:1.0
-1,-10,1:1.0
0,-10,1:1.0
1,-10,1:1.0
2,-10,1:1.0
3,-10,1:1.0
4,-10,1:1.0
5,-10,1:1.0
6,-10,1:1.0
7,-10,1:1.0
8,-10,1:1.0
9,-10,1:1.0
10,-10,1:1.0
11,-10,1:1.0
12,-10,1:1.0
13,-10,1:1.0
-10,-9,1:1.0
-9,-9,1:1.0
-8,-9,1:1.0
-7,-9,1:1.0
-6,-9,1:1.0
-5,-9,1:1.0
-4,-9,1:1.0
-3,-9,1:1.0
-2,-9,1:1.0
-1,-9,1:1.0
0,-9,1:1.0
1,-9,1:1.0
2,-9,1:1.0
3,-9,1:1.0
4,-9,1:1.0
5,-9,1:1.0
6,-9,1:1.0
7,-9,1:1.0
8,-9,1:1.0
9,-9,1:1.0
10,-9,1:1.0
11,-9,1:1.0
12,-9,1:1.0
13,-9,1:1.0
-11,-8,1:1.0
-10,-8,1:1.0
-9,-8,1:1.0
-8,-8,1:1.0
-7,-8,1:1.0
-6,-8,1:1.0
-5,-8,1:1.0
-4,-8,1:1.0
-3,-8,1:1.0
-2,-8,1:1.0
-1,-8,1:1.0
0,-8,1:1.0
1,-8,1:1.0
2,-8,1:1.0
3,-8,1:1.0
4,-8,1:1.0
5,-8,1:1.0
6,-8,1:1.0
7,-8,1:1.0
8,-8,1:1.0
9,-8,1:1.0
10,-8,1:1.0
11,-8,1:1.0
12,-8,1:1.0
13,-8,1:1.0
-11,-7,1:1.0
-10,-7,1:1.0
-9,-7,1:1.0
-8,-7,1:1.0
-7,-7,1:1.0
-6,-7,1:1.0
-5,-7,1:1.0
-4,-7,1:1.0
-3,-7,1:1.0
-2,-7,1:1.0
-1,-7,1:1.0
0,-7,1:1.0
1,-7,1:1.0
2,-7,1:1.0
3,-7,1:1.0
4,-7,1:1.0
5,-7,1:1.0
6,-7,1:1.0
7,-7,1:1.0
8,-7,1:1.0
9,-7,1:1.0
10,-7,1:1.0
11,-7,1:1.0
12,-7,1:1.0
13,-7,1:1.0
-11,-6,1:1.0
-10,-6,1:1.0
-9,-6,1:1.0
-8,-6,1:1.0
-7,-6,1:1.0
-6,-6,1:1.0
-5,-6,1:1.0
-4,-6,1:1.0
-3,-6,1:1.0
-2,-6,1:1.0
-1,-6,1:1.0
0,-6,1:11.0
1,-6,1:11.0
2,-6,1:11.0
3,-6,1:11.0
4,-6,1:11.0
5,-6,1:1.0
6,-6,1:1.0
7,-6,1:1.0
8,-6,1:1.0
9,-6,1:1.0
10,-6,1:1.0
11,-6,1:1.0
12,-6,1:1.0
13,-6,1:13.0
-11,-5,1:1.0
-10,-5,1:1.0
-9,-5,1:1.0
-8,-5,1:1.0
-7,-5,1:1.0
-6,-5,1:1.0
-5,-5,1:1.0
-4,-5,1:1.0
-3,-5,1:1.0
-2,-5,1:1.0
-1,-5,1:11.0
0,-5,1:11.0
1,-5,1:11.0
2,-5,1:11.0
3,-5,1:11.0
4,-5,1:11.0
5,-5,1:11.0
6,-5,1:1.0
7,-5,1:1.0
8,-5,1:1.0
9,-5,1:1.0
10,-5,1:1.0
11,-5,1:1.0
12,-5,1:1.0
13,-5,1:1.0
-12,-4,1:13.0
-11,-4,1:1.0
-10,-4,1:1.0
-9,-4,1:1.0
-8,-4,1:1.0
-7,-4,1:1.0
-6,-4,1:1.0
-5,-4,1:1.0
-4,-4,1:1.0
-3,-4,1:1.0
-2,-4,1:11.0
-1,-4,1:11.0
0,-4,1:11.0
1,-4,1:11.0
2,-4,1:11.0
3,-4,1:11.0
4,-4,1:11.0
5,-4,1:11.0
6,-4,1:11.0
7,-4,1:1.0
8,-4,1:1.0
9,-4,1:1.0
10,-4,1:1.0
11,-4,1:1.0
12,-4,1:1.0
13,-4,1:1.0
-12,-3,1:1.0
-11,-3,1:1.0
-10,-3,1:1.0
-9,-3,1:1.0
-8,-3,1:1.0
-7,-3,1:1.0
-6,-3,1:1.0
-5,-3,1:1.0
-4,-3,1:1.0
-3,-3,1:1.0
-2,-3,1:11.0
-1,-3,1:11.0
0,-3,1:11.0
1,-3,1:11.0
2,-3,1:11.0
3,-3,1:11.0
4,-3,1:11.0
5,-3,1:11.0
6,-3,1:11.0
7,-3,1:1.0
8,-3,1:1.0
9,-3,1:1.0
10,-3,1:1.0
11,-3,1:1.0
12,-3,1:1.0
13,-3,1:1.0
-12,-2,1:1.0
-11,-2,1:1.0
-10,-2,1:1.0
-9,-2,1:1.0
-8,-2,1:1.0
-7,-2,1:1.0
-6,-2,1:1.0
-5,-2,1:1.0
-4,-2,1:1.0
-3,-2,1:1.0
-2,-2,1:11.0
-1,-2,1:11.0
0,-2,1:11.0
1,-2,1:11.0
2,-2,1:11.0
3,-2,1:11.0
4,-2,1:11.0
5,-2,1:11.0
6,-2,1:11.0
7,-2,1:1.0
8,-2,1:1.0
9,-2,1:1.0
10,-2,1:1.0
11,-2,1:1.0
12,-2,1:1.0
13,-2,1:1.0
-13,-1,1:1.0
-12,-1,1:1.0
-11,-1,1:1.0
-10,-1,1:1.0
-9,-1,1:1.0
-8,-1,1:1.0
-7,-1,1:1.0
-6,-1,1:1.0
-5,-1,1:1.0
-4,-1,1:1.0
-3,-1,1:1.0
-2,-1,1:11.0
-1,-1,1:11.0
0,-1,1:11.0
1,-1,1:11.0
2,-1,1:11.0
3,-1,1:11.0
4,-1,1:11.0
5,-1,1:11.0
6,-1,1:11.0
7,-1,1:1.0
8,-1,1:1.0
9,-1,1:1.0
10,-1,1:1.0
11,-1,1:1.0
12,-1,1:1.0
13,-1,1:1.0
-13,0,1:1.0
-12,0,1:1.0
-11,0,1:1.0
-10,0,1:1.0
-9,0,1:1.0
-8,0,1:1.0
-7,0,1:1.0
-6,0,1:1.0
-5,0,1:1.0
-4,0,1:1.0
-3,0,1:1.0
-2,0,1:1.0
-1,0,1:11.0
0,0,1:11.0
1,0,1:11.0
2,0,1:11.0
3,0,1:11.0
4,0,1:11.0
5,0,1:11.0
6,0,1:1.0
7,0,1:1.0
8,0,1:1.0
9,0,1:1.0
10,0,1:1.0
11,0,1:1.0
12,0,1:1.0
13,0,1:1.0
-13,1,1:13.0
-12,1,1:13.0
-11,1,1:1.0
-10,1,1:1.0
-9,1,1:1.0
-8,1,1:1.0
-7,1,1:1.0
-6,1,1:1.0
-5,1,1:1.0
-4,1,1:1.0
-3,1,1:1.0
-2,1,1:1.0
-1,1,1:1.0
0,1,1:11.0
1,1,1:11.0
2,1,1:11.0
3,1,1:11.0
4,1,1:11.0
5,1,1:11.0
6,1,1:1.0
7,1,1:1.0
8,1,1:1.0
9,1,1:1.0
10,1,1:1.0
11,1,1:1.0
12,1,1:1.0
13,1,1:49.0
-12,2,1:13.0
-11,2,1:1.0
-10,2,1:1.0
-9,2,1:1.0
-8,2,1:1.0
-7,2,1:1.0
-6,2,1:1.0
-5,2,1:1.0
-4,2,1:1.0
-3,2,1:1.0
-2,2,1:1.0
-1,2,1:1.0
0,2,1:1.0
1,2,1:11.0
2,2,1:11.0
3,2,1:11.0
4,2,1:1.0
5,2,1:1.0
6,2,1:1.0
7,2,1:1.0
8,2,1:1.0
9,2,1:1.0
10,2,1:1.0
11,2,1:1.0
12,2,1:49.0
13,2,1:49.0
-11,3,1:13.0
-10,3,1:13.0
-9,3,1:1.0
-8,3,1:1.0
-7,3,1:1.0
-6,3,1:1.0
-5,3,1:1.0
-4,3,1:1.0
-3,3,1:1.0
-2,3,1:1.0
-1,3,1:1.0
0,3,1:1.0
1,3,1:1.0
2,3,1:1.0
3,3,1:1.0
4,3,1:1.0
5,3,1:1.0
6,3,1:1.0
7,3,1:1.0
8,3,1:1.0
9,3,1:1.0
10,3,1:1.0
11,3,1:49.0
12,3,1:49.0
13,3,1:11.0
14,3,1:11.2
-10,4,1:13.0
-9,4,1:1.0
-8,4,1:1.0
-7,4,1:1.0
-6,4,1:1.0
-5,4,1:1.0
-4,4,1:1.0
-3,4,1:1.0
-2,4,1:1.0
-1,4,1:1.0
0,4,1:1.0
1,4,1:1.0
2,4,1:1.0
3,4,1:1.0
4,4,1:1.0
5,4,1:1.0
6,4,1:1.0
7,4,1:1.0
8,4,1:1.0
9,4,1:1.0
10,4,1:1.0
11,4,1:49.0
12,4,1:49.0
13,4,1:11.0
14,4,1:11.2
-10,5,1:13.0
-9,5,1:1.0
-8,5,1:1.0
-7,5,1:1.0
-6,5,1:1.0
-5,5,1:1.0
-4,5,1:1.0
-3,5,1:1.0
-2,5,1:1.0
-1,5,1:1.0
0,5,1:1.0
1,5,1:1.0
2,5,1:1.0
3,5,1:1.0
4,5,1:1.0
5,5,1:1.0
6,5,1:1.0
7,5,1:1.0
8,5,1:1.0
9,5,1:1.0
10,5,1:1.0
11,5,1:49.0
12,5,1:49.0
13,5,1:49.0
-9,6,1:1.0
-8,6,1:1.0
-7,6,1:1.0
-6,6,1:1.0
-5,6,1:1.0
-4,6,1:1.0
-3,6,1:1.0
-2,6,1:1.0
-1,6,1:1.0
0,6,1:1.0
1,6,1:1.0
2,6,1:1.0
3,6,1:1.0
4,6,1:1.0
5,6,1:1.0
6,6,1:1.0
7,6,1:1.0
8,6,1:1.0
9,6,1:1.0
10,6,1:1.0
11,6,1:49.0
12,6,1:49.0
-9,7,1:1.0
-8,7,1:1.0
-7,7,1:1.0
-6,7,1:1.0
-5,7,1:1.0
-4,7,1:1.0
-3,7,1:1.0
-2,7,1:1.0
-1,7,1:1.0
0,7,1:1.0
1,7,1:1.0
2,7,1:1.0
3,7,1:1.0
4,7,1:1.0
5,7,1:1.0
6,7,1:1.0
7,7,1:1.0
8,7,1:1.0
9,7,1:1.0
10,7,1:1.0
11,7,1:1.0
12,7,1:49.0
-8,8,1:1.0
-7,8,1:1.0
-6,8,1:1.0
-5,8,1:1.0
-4,8,1:1.0
-3,8,1:1.0
-2,8,1:1.0
-1,8,1:1.0
0,8,1:1.0
1,8,1:1.0
2,8,1:1.0
3,8,1:1.0
4,8,1:1.0
5,8,1:1.0
6,8,1:1.0
7,8,1:1.0
8,8,1:1.0
9,8,1:1.0
10,8,1:1.0
11,8,1:1.0
-8,9,1:13.0
-7,9,1:1.0
-6,9,1:1.0
-5,9,1:1.0
-4,9,1:1.0
-3,9,1:1.0
-2,9,1:1.0
-1,9,1:1.0
0,9,1:1.0
1,9,1:1.0
2,9,1:1.0
3,9,1:1.0
4,9,1:1.0
5,9,1:1.0
6,9,1:1.0
7,9,1:1.0
8,9,1:1.0
9,9,1:1.0
10,9,1:1.0
-7,10,1:13.0
-6,10,1:1.0
-5,10,1:1.0
-4,10,1:1.0
-3,10,1:1.0
-2,10,1:1.0
-1,10,1:1.0
0,10,1:49.0
1,10,1:1.0
2,10,1:1.0
3,10,1:1.0
4,10,1:1.0
5,10,1:1.0
6,10,1:1.0
7,10,1:1.0
8,10,1:1.0
9,10,1:13.0
-6,11,1:13.0
-5,11,1:1.0
-4,11,1:1.0
-3,11,1:1.0
-2,11,1:49.0
-1,11,1:49.0
0,11,1:49.0
1,11,1:49.0
2,11,1:1.0
3,11,1:1.0
4,11,1:1.0
5,11,1:1.0
6,11,1:1.0
7,11,1:13.0
8,11,1:13.0
-4,12,1:13.0
-3,12,1:49.0
-2,12,1:49.0
-1,12,1:49.0
0,12,1:49.0
1,12,1:13.0
2,12,1:13.0
3,12,1:13.0
4,12,1:13.0
-1,13,1:11.10
0,13,1:11.10
1,13,1:49.0
0,-15,2:1.0
1,-15,2:1.0
2,-15,2:1.0
3,-15,2:1.0
4,-15,2:1.0
5,-15,2:1.0
6,-15,2:1.0
-2,-14,2:11.2
-1,-14,2:49.0
0,-14,2:49.0
1,-14,2:1.0
2,-14,2:1.0
3,-14,2:1.0
4,-14,2:1.0
5,-14,2:1.0
6,-14,2:1.0
7,-14,2:1.0
8,-14,2:1.0
9,-14,2:1.0
-3,-13,2:11.10
-2,-13,2:11.0
-1,-13,2:49.0
0,-13,2:49.0
1,-13,2:1.0
2,-13,2:1.0
3,-13,2:1.0
4,-13,2:1.0
5,-13,2:1.0
6,-13,2:1.0
7,-13,2:1.0
8,-13,2:1.0
9,-13,2:1.0
10,-13,2:1.0
-7,-12,2:1.0
-6,-12,2:49.0
-5,-12,2:49.0
-4,-12,2:49.0
-3,-12,2:49.0
-2,-12,2:49.0
-1,-12,2:49.0
0,-12,2:1.0
1,-12,2:1.0
2,-12,2:1.0
3,-12,2:1.0
4,-12,2:1.0
5,-12,2:1.0
6,-12,2:1.0
7,-12,2:1.0
8,-12,2:1.0
9,-12,2:1.0
10,-12,2:1.0
11,-12,2:1.0
12,-12,2:1.0
-9,-11,2:1.0
-8,-11,2:1.0
-7,-11,2:1.0
-6,-11,2:1.0
-5,-11,2:49.0
-4,-11,2:49.0
-3,-11,2:49.0
-2,-11,2:49.0
-1,-11,2:1.0
0,-11,2:1.0
1,-11,2:1.0
2,-11,2:1.0
3,-11,2:1.0
4,-11,2:1.0
5,-11,2:1.0
6,-11,2:1.0
7,-11,2:1.0
8,-11,2:1.0
9,-11,2:1.0
10,-11,2:1.0
11,-11,2:1.0
12,-11,2:1.0
13,-11,2:1.0
-10,-10,2:1.0
-9,-10,2:1.0
-8,-10,2:1.0
-7,-10,2:1.0
-6,-10,2:1.0
-5,-10,2:1.0
-4,-10,2:1.0
-3,-10,2:1.0
-2,-10,2:1.0
-1,-10,2:1.0
0,-10,2:1.0
1,-10,2:1.0
2,-10,2:1.0
3,-10,2:1.0
4,-10,2:1.0
5,-10,2:1.0
6,-10,2:1.0
7,-10,2:1.0
8,-10,2:1.0
9,-10,2:1.0
10,-10,2:1.0
11,-10,2:1.0
12,-10,2:1.0
13,-10,2:1.0
-10,-9,2:1.0
-9,-9,2:1.0
-8,-9,2:1.0
-7,-9,2:1.0
-6,-9,2:1.0
-5,-9,2:1.0
-4,-9,2:1.0
-3,-9,2:1.0
-2,-9,2:1.0
-1,-9,2:1.0
0,-9,2:1.0
1,-9,2:1.0
2,-9,2:1.0
3,-9,2:1.0
4,-9,2:1.0
5,-9,2:1.0
6,-9,2:1.0
7,-9,2:1.0
8,-9,2:1.0
9,-9,2:1.0
10,-9,2:1.0
11,-9,2:1.0
12,-9,2:1.0
13,-9,2:1.0
-11,-8,2:13.0
-10,-8,2:1.0
-9,-8,2:1.0
-8,-8,2:1.0
-7,-8,2:1.0
-6,-8,2:1.0
-5,-8,2:1.0
-4,-8,2:1.0
-3,-8,2:1.0
-2,-8,2:1.0
-1,-8,2:1.0
0,-8,2:1.0
1,-8,2:1.0
2,-8,2:1.0
3,-8,2:1.0
4,-8,2:1.0
5,-8,2:1.0
6,-8,2:1.0
7,-8,2:1.0
8,-8,2:1.0
9,-8,2:1.0
10,-8,2:1.0
11,-8,2:1.0
12,-8,2:1.0
13,-8,2:1.0
-11,-7,2:1.0
-10,-7,2:1.0
-9,-7,2:1.0
-8,-7,2:1.0
-7,-7,2:1.0
-6,-7,2:1.0
-5,-7,2:1.0
-4,-7,2:1.0
-3,-7,2:1.0
-2,-7,2:1.0
-1,-7,2:1.0
0,-7,2:1.0
1,-7,2:1.0
2,-7,2:1.0
3,-7,2:1.0
4,-7,2:1.0
5,-7,2:1.0
6,-7,2:1.0
7,-7,2:1.0
8,-7,2:1.0
9,-7,2:1.0
10,-7,2:1.0
11,-7,2:1.0
12,-7,2:1.0
13,-7,2:13.0
-11,-6,2:1.0
-10,-6,2:1.0
-9,-6,2:1.0
-8,-6,2:1.0
-7,-6,2:1.0
-6,-6,2:1.0
-5,-6,2:1.0
-4,-6,2:1.0
-3,-6,2:1.0
-2,-6,2:1.0
-1,-6,2:1.0
0,-6,2:11.0
1,-6,2:11.0
2,-6,2:11.0
3,-6,2:11.0
4,-6,2:11.0
5,-6,2:1.0
6,-6,2:1.0
7,-6,2:1.0
8,-6,2:1.0
9,-6,2:1.0
10,-6,2:1.0
11,-6,2:1.0
12,-6,2:1.0
13,-6,2:13.0
-11,-5,2:1.0
-10,-5,2:1.0
-9,-5,2:1.0
-8,-5,2:1.0
-7,-5,2:1.0
-6,-5,2:1.0
-5,-5,2:1.0
-4,-5,2:1.0
-3,-5,2:1.0
-2,-5,2:1.0
-1,-5,2:11.0
0,-5,2:11.0
1,-5,2:11.0
2,-5,2:11.0
3,-5,2:11.0
4,-5,2:11.0
5,-5,2:11.0
6,-5,2:1.0
7,-5,2:1.0
8,-5,2:1.0
9,-5,2:1.0
10,-5,2:1.0
11,-5,2:1.0
12,-5,2:1.0
13,-5,2:13.0
-11,-4,2:1.0
-10,-4,2:1.0
-9,-4,2:1.0
-8,-4,2:1.0
-7,-4,2:1.0
-6,-4,2:1.0
-5,-4,2:1.0
-4,-4,2:1.0
-3,-4,2:1.0
-2,-4,2:11.0
-1,-4,2:11.0
0,-4,2:11.0
1,-4,2:11.0
2,-4,2:11.0
3,-4,2:11.0
4,-4,2:11.0
5,-4,2:11.0
6,-4,2:11.0
7,-4,2:1.0
8,-4,2:1.0
9,-4,2:1.0
10,-4,2:1.0
11,-4,2:1.0
12,-4,2:1.0
13,-4,2:1.0
-12,-3,2:13.0
-11,-3,2:1.0
-10,-3,2:1.0
-9,-3,2:1.0
-8,-3,2:1.0
-7,-3,2:1.0
-6,-3,2:1.0
-5,-3,2:1.0
-4,-3,2:1.0
-3,-3,2:1.0
-2,-3,2:11.0
-1,-3,2:11.0
0,-3,2:11.0
1,-3,2:11.0
2,-3,2:11.0
3,-3,2:11.0
4,-3,2:11.0
5,-3,2:11.0
6,-3,2:11.0
7,-3,2:1.0
8,-3,2:1.0
9,-3,2:1.0
10,-3,2:1.0
11,-3,2:1.0
12,-3,2:1.0
13,-3,2:1.0
-12,-2,2:1.0
-11,-2,2:1.0
-10,-2,2:1.0
-9,-2,2:1.0
-8,-2,2:1.0
-7,-2,2:1.0
-6,-2,2:1.0
-5,-2,2:1.0
-4,-2,2:1.0
-3,-2,2:1.0
-2,-2,2:11.0
-1,-2,2:11.0
0,-2,2:11.0
1,-2,2:11.0
2,-2,2:11.0
3,-2,2:11.0
4,-2,2:11.0
5,-2,2:11.0
6,-2,2:11.0
7,-2,2:1.0
8,-2,2:1.0
9,-2,2:1.0
10,-2,2:1.0
11,-2,2:1.0
12,-2,2:1.0
13,-2,2:1.0
-13,-1,2:13.0
-12,-1,2:1.0
-11,-1,2:1.0
-10,-1,2:1.0
-9,-1,2:1.0
-8,-1,2:1.0
-7,-1,2:1.0
-6,-1,2:1.0
-5,-1,2:1.0
-4,-1,2:1.0
-3,-1,2:1.0
-2,-1,2:1.0
-1,-1,2:11.0
0,-1,2:11.0
1,-1,2:11.0
2,-1,2:11.0
3,-1,2:11.0
4,-1,2:11.0
5,-1,2:11.0
6,-1,2:11.0
7,-1,2:1.0
8,-1,2:1.0
9,-1,2:1.0
10,-1,2:1.0
11,-1,2:1.0
12,-1,2:1.0
13,-1,2:1.0
-13,0,2:13.0
-12,0,2:1.0
-11,0,2:1.0
-10,0,2:1.0
-9,0,2:1.0
-8,0,2:1.0
-7,0,2:1.0
-6,0,2:1.0
-5,0,2:1.0
-4,0,2:1.0
-3,0,2:1.0
-2,0,2:1.0
-1,0,2:11.0
0,0,2:11.0
1,0,2:11.0
2,0,2:11.0
3,0,2:11.0
4,0,2:11.0
5,0,2:11.0
6,0,2:1.0
7,0,2:1.0
8,0,2:1.0
9,0,2:1.0
10,0,2:1.0
11,0,2:1.0
12,0,2:1.0
13,0,2:49.0
-12,1,2:13.0
-11,1,2:1.0
-10,1,2:1.0
-9,1,2:1.0
-8,1,2:1.0
-7,1,2:1.0
-6,1,2:1.0
-5,1,2:1.0
-4,1,2:1.0
-3,1,2:1.0
-2,1,2:1.0
-1,1,2:1.0
0,1,2:11.0
1,1,2:11.0
2,1,2:11.0
3,1,2:11.0
4,1,2:11.0
5,1,2:11.0
6,1,2:1.0
7,1,2:1.0
8,1,2:1.0
9,1,2:1.0
10,1,2:1.0
11,1,2:1.0
12,1,2:49.0
13,1,2:49.0
-11,2,2:13.0
-10,2,2:1.0
-9,2,2:1.0
-8,2,2:1.0
-7,2,2:1.0
-6,2,2:1.0
-5,2,2:1.0
-4,2,2:1.0
-3,2,2:1.0
-2,2,2:1.0
-1,2,2:1.0
0,2,2:1.0
1,2,2:11.0
2,2,2:11.0
3,2,2:11.0
4,2,2:1.0
5,2,2:1.0
6,2,2:1.0
7,2,2:1.0
8,2,2:1.0
9,2,2:1.0
10,2,2:1.0
11,2,2:1.0
12,2,2:49.0
13,2,2:49.0
-10,3,2:13.0
-9,3,2:1.0
-8,3,2:1.0
-7,3,2:1.0
-6,3,2:1.0
-5,3,2:1.0
-4,3,2:1.0
-3,3,2:1.0
-2,3,2:1.0
-1,3,2:1.0
0,3,2:1.0
1,3,2:1.0
2,3,2:1.0
3,3,2:1.0
4,3,2:1.0
5,3,2:1.0
6,3,2:1.0
7,3,2:1.0
8,3,2:1.0
9,3,2:1.0
10,3,2:1.0
11,3,2:49.0
12,3,2:49.0
13,3,2:11.10
-10,4,2:13.0
-9,4,2:1.0
-8,4,2:1.0
-7,4,2:1.0
-6,4,2:1.0
-5,4,2:1.0
-4,4,2:1.0
-3,4,2:1.0
-2,4,2:1.0
-1,4,2:1.0
0,4,2:1.0
1,4,2:1.0
2,4,2:1.0
3,4,2:1.0
4,4,2:1.0
5,4,2:1.0
6,4,2:1.0
7,4,2:1.0
8,4,2:1.0
9,4,2:1.0
10,4,2:1.0
11,4,2:49.0
12,4,2:49.0
13,4,2:11.10
-9,5,2:1.0
-8,5,2:1.0
-7,5,2:1.0
-6,5,2:1.0
-5,5,2:1.0
-4,5,2:1.0
-3,5,2:1.0
-2,5,2:1.0
-1,5,2:1.0
0,5,2:1.0
1,5,2:1.0
2,5,2:1.0
3,5,2:1.0
4,5,2:1.0
5,5,2:1.0
6,5,2:1.0
7,5,2:1.0
8,5,2:1.0
9,5,2:1.0
10,5,2:1.0
11,5,2:49.0
12,5,2:49.0
-9,6,2:13.0
-8,6,2:1.0
-7,6,2:1.0
-6,6,2:1.0
-5,6,2:1.0
-4,6,2:1.0
-3,6,2:1.0
-2,6,2:1.0
-1,6,2:1.0
0,6,2:1.0
1,6,2:1.0
2,6,2:1.0
3,6,2:1.0
4,6,2:1.0
5,6,2:1.0
6,6,2:1.0
7,6,2:1.0
8,6,2:1.0
9,6,2:1.0
10,6,2:1.0
11,6,2:49.0
12,6,2:49.0
-9,7,2:13.0
-8,7,2:1.0
-7,7,2:1.0
-6,7,2:1.0
-5,7,2:1.0
-4,7,2:1.0
-3,7,2:1.0
-2,7,2:1.0
-1,7,2:1.0
0,7,2:1.0
1,7,2:1.0
2,7,2:1.0
3,7,2:1.0
4,7,2:1.0
5,7,2:1.0
6,7,2:1.0
7,7,2:1.0
8,7,2:1.0
9,7,2:1.0
10,7,2:1.0
11,7,2:49.0
12,7,2:49.0
-8,8,2:1.0
-7,8,2:1.0
-6,8,2:1.0
-5,8,2:1.0
-4,8,2:1.0
-3,8,2:1.0
-2,8,2:1.0
-1,8,2:1.0
0,8,2:1.0
1,8,2:1.0
2,8,2:1.0
3,8,2:1.0
4,8,2:1.0
5,8,2:1.0
6,8,2:1.0
7,8,2:1.0
8,8,2:1.0
9,8,2:1.0
10,8,2:1.0
11,8,2:1.0
-7,9,2:1.0
-6,9,2:1.0
-5,9,2:1.0
-4,9,2:1.0
-3,9,2:1.0
-2,9,2:1.0
-1,9,2:1.0
0,9,2:1.0
1,9,2:1.0
2,9,2:1.0
3,9,2:1.0
4,9,2:1.0
5,9,2:1.0
6,9,2:1.0
7,9,2:1.0
8,9,2:1.0
9,9,2:1.0
10,9,2:1.0
-6,10,2:1.0
-5,10,2:1.0
-4,10,2:1.0
-3,10,2:1.0
-2,10,2:1.0
-1,10,2:49.0
0,10,2:49.0
1,10,2:49.0
2,10,2:1.0
3,10,2:1.0
4,10,2:1.0
5,10,2:1.0
6,10,2:1.0
7,10,2:1.0
8,10,2:1.0
-5,11,2:1.0
-4,11,2:1.0
-3,11,2:49.0
-2,11,2:49.0
-1,11,2:49.0
0,11,2:49.0
1,11,2:49.0
2,11,2:1.0
3,11,2:1.0
4,11,2:1.0
5,11,2:1.0
6,11,2:1.0
7,11,2:13.0
-3,12,2:49.0
-2,12,2:49.0
-1,12,2:11.10
0,12,2:11.10
1,12,2:49.0
2,12,2:13.0
-1,13,2:11.2
0,13,2:11.2
0,-15,3:49.0
1,-15,3:49.0
2,-15,3:1.0
3,-15,3:1.0
4,-15,3:1.0
5,-15,3:1.0
6,-15,3:13.0
-1,-14,3:49.0
0,-14,3:49.0
1,-14,3:49.0
2,-14,3:1.0
3,-14,3:1.0
4,-14,3:1.0
5,-14,3:1.0
6,-14,3:1.0
7,-14,3:1.0
8,-14,3:1.0
9,-14,3:13.0
-3,-13,3:11.2
-2,-13,3:11.10
-1,-13,3:13.0
0,-13,3:49.0
1,-13,3:1.0
2,-13,3:1.0
3,-13,3:1.0
4,-13,3:1.0
5,-13,3:1.0
6,-13,3:1.0
7,-13,3:1.0
8,-13,3:1.0
9,-13,3:1.0
10,-13,3:1.0
-7,-12,3:1.0
-6,-12,3:49.0
-5,-12,3:49.0
-4,-12,3:49.0
-3,-12,3:11.0
-2,-12,3:49.0
-1,-12,3:1.0
0,-12,3:1.0
1,-12,3:1.0
2,-12,3:1.0
3,-12,3:1.0
4,-12,3:1.0
5,-12,3:1.0
6,-12,3:1.0
7,-12,3:1.0
8,-12,3:1.0
9,-12,3:1.0
10,-12,3:1.0
11,-12,3:1.0
12,-12,3:1.0
-9,-11,3:1.0
-8,-11,3:1.0
-7,-11,3:1.0
-6,-11,3:49.0
-5,-11,3:49.0
-4,-11,3:49.0
-3,-11,3:49.0
-2,-11,3:49.0
-1,-11,3:49.0
0,-11,3:1.0
1,-11,3:1.0
2,-11,3:1.0
3,-11,3:1.0
4,-11,3:1.0
5,-11,3:1.0
6,-11,3:1.0
7,-11,3:1.0
8,-11,3:1.0
9,-11,3:1.0
10,-11,3:1.0
11,-11,3:1.0
12,-11,3:1.0
13,-11,3:13.0
-10,-10,3:1.0
-9,-10,3:1.0
-8,-10,3:1.0
-7,-10,3:1.0
-6,-10,3:1.0
-5,-10,3:1.0
-4,-10,3:1.0
-3,-10,3:1.0
-2,-10,3:49.0
-1,-10,3:1.0
0,-10,3:1.0
1,-10,3:1.0
2,-10,3:1.0
3,-10,3:1.0
4,-10,3:1.0
5,-10,3:1.0
6,-10,3:1.0
7,-10,3:1.0
8,-10,3:1.0
9,-10,3:1.0
10,-10,3:1.0
11,-10,3:1.0
12,-10,3:1.0
13,-10,3:13.0
-10,-9,3:1.0
-9,-9,3:1.0
-8,-9,3:1.0
-7,-9,3:1.0
-6,-9,3:1.0
-5,-9,3:1.0
-4,-9,3:1.0
-3,-9,3:1.0
-2,-9,3:1.0
-1,-9,3:1.0
0,-9,3:1.0
1,-9,3:1.0
2,-9,3:1.0
3,-9,3:1.0
4,-9,3:1.0
5,-9,3:1.0
6,-9,3:1.0
7,-9,3:1.0
8,-9,3:1.0
9,-9,3:1.0
10,-9,3:1.0
11,-9,3:1.0
12,-9,3:1.0
13,-9,3:13.0
-11,-8,3:13.0
-10,-8,3:1.0
-9,-8,3:1.0
-8,-8,3:1.0
-7,-8,3:1.0
-6,-8,3:1.0
-5,-8,3:1.0
-4,-8,3:1.0
-3,-8,3:1.0
-2,-8,3:1.0
-1,-8,3:1.0
0,-8,3:1.0
1,-8,3:1.0
2,-8,3:1.0
3,-8,3:1.0
4,-8,3:1.0
5,-8,3:1.0
6,-8,3:1.0
7,-8,3:1.0
8,-8,3:1.0
9,-8,3:1.0
10,-8,3:1.0
11,-8,3:1.0
12,-8,3:1.0
13,-8,3:13.0
-11,-7,3:1.0
-10,-7,3:1.0
-9,-7,3:1.0
-8,-7,3:1.0
-7,-7,3:1.0
-6,-7,3:1.0
-5,-7,3:1.0
-4,-7,3:1.0
-3,-7,3:1.0
-2,-7,3:1.0
-1,-7,3:1.0
0,-7,3:1.0
1,-7,3:1.0
2,-7,3:1.0
3,-7,3:1.0
4,-7,3:1.0
5,-7,3:1.0
6,-7,3:1.0
7,-7,3:1.0
8,-7,3:1.0
9,-7,3:1.0
10,-7,3:1.0
11,-7,3:1.0
12,-7,3:1.0
13,-7,3:13.0
-11,-6,3:1.0
-10,-6,3:1.0
-9,-6,3:1.0
-8,-6,3:1.0
-7,-6,3:1.0
-6,-6,3:1.0
-5,-6,3:1.0
-4,-6,3:1.0
-3,-6,3:1.0
-2,-6,3:1.0
-1,-6,3:1.0
0,-6,3:11.0
1,-6,3:11.0
2,-6,3:11.0
3,-6,3:11.0
4,-6,3:11.0
5,-6,3:1.0
6,-6,3:1.0
7,-6,3:1.0
8,-6,3:1.0
9,-6,3:1.0
10,-6,3:1.0
11,-6,3:1.0
12,-6,3:1.0
-11,-5,3:1.0
-10,-5,3:1.0
-9,-5,3:1.0
-8,-5,3:1.0
-7,-5,3:1.0
-6,-5,3:1.0
-5,-5,3:1.0
-4,-5,3:1.0
-3,-5,3:1.0
-2,-5,3:1.0
-1,-5,3:11.0
0,-5,3:11.0
1,-5,3:11.0
2,-5,3:11.0
3,-5,3:11.0
4,-5,3:11.0
5,-5,3:11.0
6,-5,3:1.0
7,-5,3:1.0
8,-5,3:1.0
9,-5,3:1.0
10,-5,3:1.0
11,-5,3:1.0
12,-5,3:1.0
13,-5,3:13.0
-11,-4,3:1.0
-10,-4,3:1.0
-9,-4,3:1.0
-8,-4,3:1.0
-7,-4,3:1.0
-6,-4,3:1.0
-5,-4,3:1.0
-4,-4,3:1.0
-3,-4,3:1.0
-2,-4,3:11.0
-1,-4,3:11.0
0,-4,3:11.0
1,-4,3:11.0
2,-4,3:11.0
3,-4,3:11.0
4,-4,3:11.0
5,-4,3:11.0
6,-4,3:11.0
7,-4,3:1.0
8,-4,3:1.0
9,-4,3:1.0
10,-4,3:1.0
11,-4,3:1.0
12,-4,3:1.0
13,-4,3:1.0
-12,-3,3:13.0
-11,-3,3:1.0
-10,-3,3:1.0
-9,-3,3:1.0
-8,-3,3:1.0
-7,-3,3:1.0
-6,-3,3:1.0
-5,-3,3:1.0
-4,-3,3:1.0
-3,-3,3:1.0
-2,-3,3:11.0
-1,-3,3:11.0
0,-3,3:11.0
1,-3,3:11.0
2,-3,3:11.0
3,-3,3:11.0
4,-3,3:11.0
5,-3,3:11.0
6,-3,3:11.0
7,-3,3:1.0
8,-3,3:1.0
9,-3,3:1.0
10,-3,3:1.0
11,-3,3:1.0
12,-3,3:1.0
13,-3,3:1.0
-12,-2,3:13.0
-11,-2,3:1.0
-10,-2,3:1.0
-9,-2,3:1.0
-8,-2,3:1.0
-7,-2,3:1.0
-6,-2,3:1.0
-5,-2,3:1.0
-4,-2,3:1.0
-3,-2,3:1.0
-2,-2,3:11.0
-1,-2,3:11.0
0,-2,3:11.0
1,-2,3:11.0
2,-2,3:11.0
3,-2,3:11.0
4,-2,3:11.0
5,-2,3:11.0
6,-2,3:11.0
7,-2,3:1.0
8,-2,3:1.0
9,-2,3:1.0
10,-2,3:1.0
11,-2,3:1.0
12,-2,3:1.0
13,-2,3:1.0
-13,-1,3:13.0
-12,-1,3:13.0
-11,-1,3:1.0
-10,-1,3:1.0
-9,-1,3:1.0
-8,-1,3:1.0
-7,-1,3:1.0
-6,-1,3:1.0
-5,-1,3:1.0
-4,-1,3:1.0
-3,-1,3:1.0
-2,-1,3:1.0
-1,-1,3:11.0
0,-1,3:11.0
1,-1,3:11.0
2,-1,3:11.0
3,-1,3:11.0
4,-1,3:11.0
5,-1,3:11.0
6,-1,3:1.0
7,-1,3:1.0
8,-1,3:1.0
9,-1,3:1.0
10,-1,3:1.0
11,-1,3:1.0
12,-1,3:1.0
13,-1,3:1.0
-13,0,3:13.0
-12,0,3:13.0
-11,0,3:1.0
-10,0,3:1.0
-9,0,3:1.0
-8,0,3:1.0
-7,0,3:1.0
-6,0,3:1.0
-5,0,3:1.0
-4,0,3:1.0
-3,0,3:1.0
-2,0,3:1.0
-1,0,3:11.0
0,0,3:11.0
1,0,3:11.0
2,0,3:11.0
3,0,3:11.0
4,0,3:11.0
5,0,3:11.0
6,0,3:1.0
7,0,3:1.0
8,0,3:1.0
9,0,3:1.0
10,0,3:1.0
11,0,3:1.0
12,0,3:49.0
13,0,3:49.0
-11,1,3:13.0
-10,1,3:1.0
-9,1,3:1.0
-8,1,3:1.0
-7,1,3:1.0
-6,1,3:1.0
-5,1,3:1.0
-4,1,3:1.0
-3,1,3:1.0
-2,1,3:1.0
-1,1,3:1.0
0,1,3:11.0
1,1,3:11.0
2,1,3:11.0
3,1,3:11.0
4,1,3:11.0
5,1,3:1.0
6,1,3:1.0
7,1,3:1.0
8,1,3:1.0
9,1,3:1.0
10,1,3:1.0
11,1,3:1.0
12,1,3:49.0
13,1,3:49.0
-11,2,3:13.0
-10,2,3:1.0
-9,2,3:1.0
-8,2,3:1.0
-7,2,3:1.0
-6,2,3:1.0
-5,2,3:1.0
-4,2,3:1.0
-3,2,3:1.0
-2,2,3:1.0
-1,2,3:1.0
0,2,3:1.0
1,2,3:11.0
2,2,3:11.0
3,2,3:11.0
4,2,3:1.0
5,2,3:1.0
6,2,3:1.0
7,2,3:1.0
8,2,3:1.0
9,2,3:1.0
10,2,3:1.0
11,2,3:49.0
12,2,3:49.0
-9,3,3:1.0
-8,3,3:1.0
-7,3,3:1.0
-6,3,3:1.0
-5,3,3:1.0
-4,3,3:1.0
-3,3,3:1.0
-2,3,3:1.0
-1,3,3:1.0
0,3,3:1.0
1,3,3:1.0
2,3,3:1.0
3,3,3:1.0
4,3,3:1.0
5,3,3:1.0
6,3,3:1.0
7,3,3:1.0
8,3,3:1.0
9,3,3:1.0
10,3,3:1.0
11,3,3:49.0
12,3,3:49.0
13,3,3:11.10
-9,4,3:13.0
-8,4,3:1.0
-7,4,3:1.0
-6,4,3:1.0
-5,4,3:1.0
-4,4,3:1.0
-3,4,3:1.0
-2,4,3:1.0
-1,4,3:1.0
0,4,3:1.0
1,4,3:1.0
2,4,3:1.0
3,4,3:1.0
4,4,3:1.0
5,4,3:1.0
6,4,3:1.0
7,4,3:1.0
8,4,3:1.0
9,4,3:1.0
10,4,3:1.0
11,4,3:49.0
12,4,3:49.0
13,4,3:11.10
-9,5,3:13.0
-8,5,3:1.0
-7,5,3:1.0
-6,5,3:1.0
-5,5,3:1.0
-4,5,3:1.0
-3,5,3:1.0
-2,5,3:1.0
-1,5,3:1.0
0,5,3:1.0
1,5,3:1.0
2,5,3:1.0
3,5,3:1.0
4,5,3:1.0
5,5,3:1.0
6,5,3:1.0
7,5,3:1.0
8,5,3:1.0
9,5,3:1.0
10,5,3:1.0
11,5,3:49.0
12,5,3:49.0
-9,6,3:13.0
-8,6,3:1.0
-7,6,3:1.0
-6,6,3:1.0
-5,6,3:1.0
-4,6,3:1.0
-3,6,3:1.0
-2,6,3:1.0
-1,6,3:1.0
0,6,3:1.0
1,6,3:1.0
2,6,3:1.0
3,6,3:1.0
4,6,3:1.0
5,6,3:1.0
6,6,3:1.0
7,6,3:1.0
8,6,3:1.0
9,6,3:1.0
10,6,3:1.0
11,6,3:49.0
12,6,3:49.0
-9,7,3:13.0
-8,7,3:13.0
-7,7,3:1.0
-6,7,3:1.0
-5,7,3:1.0
-4,7,3:1.0
-3,7,3:1.0
-2,7,3:1.0
-1,7,3:1.0
0,7,3:1.0
1,7,3:1.0
2,7,3:1.0
3,7,3:1.0
4,7,3:1.0
5,7,3:1.0
6,7,3:1.0
7,7,3:1.0
8,7,3:1.0
9,7,3:1.0
10,7,3:1.0
11,7,3:1.0
-8,8,3:13.0
-7,8,3:1.0
-6,8,3:1.0
-5,8,3:1.0
-4,8,3:1.0
-3,8,3:1.0
-2,8,3:1.0
-1,8,3:1.0
0,8,3:1.0
1,8,3:1.0
2,8,3:1.0
3,8,3:1.0
4,8,3:1.0
5,8,3:1.0
6,8,3:1.0
7,8,3:1.0
8,8,3:1.0
9,8,3:1.0
10,8,3:1.0
11,8,3:1.0
-7,9,3:1.0
-6,9,3:1.0
-5,9,3:1.0
-4,9,3:1.0
-3,9,3:1.0
-2,9,3:1.0
-1,9,3:1.0
0,9,3:1.0
1,9,3:1.0
2,9,3:1.0
3,9,3:1.0
4,9,3:1.0
5,9,3:1.0
6,9,3:1.0
7,9,3:1.0
8,9,3:1.0
9,9,3:1.0
10,9,3:1.0
-6,10,3:13.0
-5,10,3:49.0
-4,10,3:1.0
-3,10,3:1.0
-2,10,3:1.0
-1,10,3:1.0
0,10,3:49.0
1,10,3:1.0
2,10,3:1.0
3,10,3:1.0
4,10,3:1.0
5,10,3:1.0
6,10,3:1.0
7,10,3:1.0
8,10,3:1.0
-5,11,3:49.0
-4,11,3:49.0
-3,11,3:13.0
-2,11,3:49.0
-1,11,3:49.0
0,11,3:49.0
1,11,3:49.0
2,11,3:1.0
3,11,3:1.0
4,11,3:1.0
5,11,3:1.0
6,11,3:1.0
-2,12,3:49.0
-1,12,3:11.10
0,12,3:11.10
1,12,3:49.0
0,-15,4:49.0
1,-15,4:49.0
2,-15,4:13.0
3,-15,4:13.0
4,-15,4:13.0
5,-15,4:13.0
6,-15,4:13.0
0,-14,4:49.0
1,-14,4:49.0
2,-14,4:49.0
3,-14,4:1.0
4,-14,4:1.0
5,-14,4:1.0
6,-14,4:1.0
7,-14,4:13.0
8,-14,4:13.0
9,-14,4:13.0
-2,-13,4:11.2
-1,-13,4:49.0
0,-13,4:49.0
1,-13,4:49.0
2,-13,4:1.0
3,-13,4:1.0
4,-13,4:1.0
5,-13,4:1.0
6,-13,4:1.0
7,-13,4:1.0
8,-13,4:1.0
9,-13,4:1.0
10,-13,4:13.0
-7,-12,4:13.0
-6,-12,4:49.0
-3,-12,4:11.10
-2,-12,4:11.0
-1,-12,4:49.0
0,-12,4:49.0
1,-12,4:1.0
2,-12,4:1.0
3,-12,4:1.0
4,-12,4:1.0
5,-12,4:1.0
6,-12,4:1.0
7,-12,4:1.0
8,-12,4:1.0
9,-12,4:1.0
10,-12,4:1.0
11,-12,4:1.0
12,-12,4:13.0
-9,-11,4:1.0
-8,-11,4:1.0
-7,-11,4:1.0
-6,-11,4:1.0
-5,-11,4:49.0
-4,-11,4:49.0
-3,-11,4:49.0
-2,-11,4:49.0
-1,-11,4:49.0
0,-11,4:1.0
1,-11,4:1.0
2,-11,4:1.0
3,-11,4:1.0
4,-11,4:1.0
5,-11,4:1.0
6,-11,4:1.0
7,-11,4:1.0
8,-11,4:1.0
9,-11,4:1.0
10,-11,4:1.0
11,-11,4:1.0
12,-11,4:1.0
13,-11,4:13.0
-10,-10,4:1.0
-9,-10,4:1.0
-8,-10,4:1.0
-7,-10,4:1.0
-6,-10,4:1.0
-5,-10,4:1.0
-4,-10,4:49.0
-3,-10,4:49.0
-2,-10,4:49.0
-1,-10,4:49.0
0,-10,4:1.0
1,-10,4:1.0
2,-10,4:1.0
3,-10,4:1.0
4,-10,4:1.0
5,-10,4:1.0
6,-10,4:1.0
7,-10,4:1.0
8,-10,4:1.0
9,-10,4:1.0
10,-10,4:1.0
11,-10,4:1.0
12,-10,4:1.0
13,-10,4:13.0
-10,-9,4:1.0
-9,-9,4:1.0
-8,-9,4:1.0
-7,-9,4:1.0
-6,-9,4:1.0
-5,-9,4:1.0
-4,-9,4:1.0
-3,-9,4:1.0
-2,-9,4:1.0
-1,-9,4:1.0
0,-9,4:1.0
1,-9,4:1.0
2,-9,4:1.0
3,-9,4:1.0
4,-9,4:1.0
5,-9,4:1.0
6,-9,4:1.0
7,-9,4:1.0
8,-9,4:1.0
9,-9,4:1.0
10,-9,4:1.0
11,-9,4:1.0
12,-9,4:1.0
13,-9,4:13.0
-10,-8,4:1.0
-9,-8,4:1.0
-8,-8,4:1.0
-7,-8,4:1.0
-6,-8,4:1.0
-5,-8,4:1.0
-4,-8,4:1.0
-3,-8,4:1.0
-2,-8,4:1.0
-1,-8,4:1.0
0,-8,4:1.0
1,-8,4:1.0
2,-8,4:1.0
3,-8,4:1.0
4,-8,4:1.0
5,-8,4:1.0
6,-8,4:1.0
7,-8,4:1.0
8,-8,4:1.0
9,-8,4:1.0
10,-8,4:1.0
11,-8,4:1.0
12,-8,4:1.0
13,-8,4:13.0
-11,-7,4:1.0
-10,-7,4:1.0
-9,-7,4:1.0
-8,-7,4:1.0
-7,-7,4:1.0
-6,-7,4:1.0
-5,-7,4:1.0
-4,-7,4:1.0
-3,-7,4:1.0
-2,-7,4:1.0
-1,-7,4:1.0
0,-7,4:1.0
1,-7,4:1.0
2,-7,4:1.0
3,-7,4:1.0
4,-7,4:1.0
5,-7,4:1.0
6,-7,4:1.0
7,-7,4:1.0
8,-7,4:1.0
9,-7,4:1.0
10,-7,4:1.0
11,-7,4:1.0
12,-7,4:1.0
-11,-6,4:1.0
-10,-6,4:1.0
-9,-6,4:1.0
-8,-6,4:1.0
-7,-6,4:1.0
-6,-6,4:1.0
-5,-6,4:1.0
-4,-6,4:1.0
-3,-6,4:1.0
-2,-6,4:1.0
-1,-6,4:1.0
0,-6,4:11.0
1,-6,4:11.0
2,-6,4:11.0
3,-6,4:11.0
4,-6,4:11.0
5,-6,4:1.0
6,-6,4:1.0
7,-6,4:1.0
8,-6,4:1.0
9,-6,4:1.0
10,-6,4:1.0
11,-6,4:1.0
12,-6,4:1.0
-11,-5,4:1.0
-10,-5,4:1.0
-9,-5,4:1.0
-8,-5,4:1.0
-7,-5,4:1.0
-6,-5,4:1.0
-5,-5,4:1.0
-4,-5,4:1.0
-3,-5,4:1.0
-2,-5,4:1.0
-1,-5,4:11.0
0,-5,4:11.0
1,-5,4:11.0
2,-5,4:11.0
3,-5,4:11.0
4,-5,4:11.0
5,-5,4:11.0
6,-5,4:1.0
7,-5,4:1.0
8,-5,4:1.0
9,-5,4:1.0
10,-5,4:1.0
11,-5,4:1.0
12,-5,4:1.0
-11,-4,4:1.0
-10,-4,4:1.0
-9,-4,4:1.0
-8,-4,4:1.0
-7,-4,4:1.0
-6,-4,4:1.0
-5,-4,4:1.0
-4,-4,4:1.0
-3,-4,4:1.0
-2,-4,4:11.0
-1,-4,4:11.0
0,-4,4:11.0
1,-4,4:11.0
2,-4,4:11.0
3,-4,4:11.0
4,-4,4:11.0
5,-4,4:11.0
6,-4,4:1.0
7,-4,4:1.0
8,-4,4:1.0
9,-4,4:1.0
10,-4,4:1.0
11,-4,4:1.0
12,-4,4:1.0
13,-4,4:1.0
-11,-3,4:1.0
-10,-3,4:1.0
-9,-3,4:1.0
-8,-3,4:1.0
-7,-3,4:1.0
-6,-3,4:1.0
-5,-3,4:1.0
-4,-3,4:1.0
-3,-3,4:1.0
-2,-3,4:11.0
-1,-3,4:11.0
0,-3,4:11.0
1,-3,4:11.0
2,-3,4:11.0
3,-3,4:11.0
4,-3,4:11.0
5,-3,4:11.0
6,-3,4:11.0
7,-3,4:1.0
8,-3,4:1.0
9,-3,4:1.0
10,-3,4:1.0
11,-3,4:1.0
12,-3,4:1.0
13,-3,4:1.0
-12,-2,4:13.0
-11,-2,4:1.0
-10,-2,4:1.0
-9,-2,4:1.0
-8,-2,4:1.0
-7,-2,4:1.0
-6,-2,4:1.0
-5,-2,4:1.0
-4,-2,4:1.0
-3,-2,4:1.0
-2,-2,4:11.0
-1,-2,4:11.0
0,-2,4:11.0
1,-2,4:11.0
2,-2,4:11.0
3,-2,4:11.0
4,-2,4:11.0
5,-2,4:11.0
6,-2,4:1.0
7,-2,4:1.0
8,-2,4:1.0
9,-2,4:1.0
10,-2,4:1.0
11,-2,4:1.0
12,-2,4:1.0
13,-2,4:1.0
-12,-1,4:13.0
-11,-1,4:1.0
-10,-1,4:1.0
-9,-1,4:1.0
-8,-1,4:1.0
-7,-1,4:1.0
-6,-1,4:1.0
-5,-1,4:1.0
-4,-1,4:1.0
-3,-1,4:1.0
-2,-1,4:1.0
-1,-1,4:11.0
0,-1,4:11.0
1,-1,4:11.0
2,-1,4:11.0
3,-1,4:11.0
4,-1,4:11.0
5,-1,4:11.0
6,-1,4:1.0
7,-1,4:1.0
8,-1,4:1.0
9,-1,4:1.0
10,-1,4:1.0
11,-1,4:1.0
12,-1,4:1.0
13,-1,4:1.0
-12,0,4:13.0
-11,0,4:13.0
-10,0,4:1.0
-9,0,4:1.0
-8,0,4:1.0
-7,0,4:1.0
-6,0,4:1.0
-5,0,4:1.0
-4,0,4:1.0
-3,0,4:1.0
-2,0,4:1.0
-1,0,4:11.0
0,0,4:11.0
1,0,4:11.0
2,0,4:11.0
3,0,4:11.0
4,0,4:11.0
5,0,4:1.0
6,0,4:1.0
7,0,4:1.0
8,0,4:1.0
9,0,4:1.0
10,0,4:1.0
11,0,4:1.0
12,0,4:1.0
13,0,4:49.0
-11,1,4:13.0
-10,1,4:1.0
-9,1,4:1.0
-8,1,4:1.0
-7,1,4:1.0
-6,1,4:1.0
-5,1,4:1.0
-4,1,4:1.0
-3,1,4:1.0
-2,1,4:1.0
-1,1,4:1.0
0,1,4:11.0
1,1,4:11.0
2,1,4:11.0
3,1,4:11.0
4,1,4:1.0
5,1,4:1.0
6,1,4:1.0
7,1,4:1.0
8,1,4:1.0
9,1,4:1.0
10,1,4:1.0
11,1,4:1.0
12,1,4:49.0
-10,2,4:13.0
-9,2,4:1.0
-8,2,4:1.0
-7,2,4:1.0
-6,2,4:1.0
-5,2,4:1.0
-4,2,4:1.0
-3,2,4:1.0
-2,2,4:1.0
-1,2,4:1.0
0,2,4:1.0
1,2,4:11.0
2,2,4:11.0
3,2,4:1.0
4,2,4:1.0
5,2,4:1.0
6,2,4:1.0
7,2,4:1.0
8,2,4:1.0
9,2,4:1.0
10,2,4:1.0
11,2,4:49.0
12,2,4:49.0
-9,3,4:1.0
-8,3,4:1.0
-7,3,4:1.0
-6,3,4:1.0
-5,3,4:1.0
-4,3,4:1.0
-3,3,4:1.0
-2,3,4:1.0
-1,3,4:1.0
0,3,4:1.0
1,3,4:1.0
2,3,4:1.0
3,3,4:1.0
4,3,4:1.0
5,3,4:1.0
6,3,4:1.0
7,3,4:1.0
8,3,4:1.0
9,3,4:1.0
10,3,4:1.0
11,3,4:49.0
12,3,4:49.0
13,3,4:11.10
-9,4,4:13.0
-8,4,4:1.0
-7,4,4:1.0
-6,4,4:1.0
-5,4,4:1.0
-4,4,4:1.0
-3,4,4:1.0
-2,4,4:1.0
-1,4,4:1.0
0,4,4:1.0
1,4,4:1.0
2,4,4:1.0
3,4,4:1.0
4,4,4:1.0
5,4,4:1.0
6,4,4:1.0
7,4,4:1.0
8,4,4:1.0
9,4,4:1.0
10,4,4:1.0
11,4,4:49.0
12,4,4:49.0
13,4,4:11.10
-9,5,4:13.0
-8,5,4:1.0
-7,5,4:1.0
-6,5,4:1.0
-5,5,4:1.0
-4,5,4:1.0
-3,5,4:1.0
-2,5,4:1.0
-1,5,4:1.0
0,5,4:1.0
1,5,4:1.0
2,5,4:1.0
3,5,4:1.0
4,5,4:1.0
5,5,4:1.0
6,5,4:1.0
7,5,4:1.0
8,5,4:1.0
9,5,4:1.0
10,5,4:1.0
11,5,4:49.0
12,5,4:49.0
-8,6,4:13.0
-7,6,4:1.0
-6,6,4:1.0
-5,6,4:1.0
-4,6,4:1.0
-3,6,4:1.0
-2,6,4:1.0
-1,6,4:1.0
0,6,4:1.0
1,6,4:1.0
2,6,4:1.0
3,6,4:1.0
4,6,4:1.0
5,6,4:1.0
6,6,4:1.0
7,6,4:1.0
8,6,4:1.0
9,6,4:1.0
10,6,4:1.0
11,6,4:49.0
-8,7,4:13.0
-7,7,4:1.0
-6,7,4:1.0
-5,7,4:1.0
