
#######################################################################
# +-----------------------------------------------------------------+ #
# |                            BO3 object                           | #
# +-----------------------------------------------------------------+ #
#######################################################################

Author: Unknown

Description: Converted version of the BO2 OakForestLarge3

Version: 3

SettingsMode: WriteWithoutComments


#######################################################################
# +-----------------------------------------------------------------+ #
# |                          Main settings                          | #
# +-----------------------------------------------------------------+ #
#######################################################################

Tree: true

Frequency: 1

Rarity: 10.0

RotateRandomly: true

SpawnHeight: highestSolidBlock

SpawnHeightOffset: 0

SpawnHeightVariance: 0

##############################
# Height Limits for the BO3. #
##############################

MinHeight: 62

MaxHeight: 210

######################
# Extrusion settings #
######################

ExtrudeMode: None

ExtrudeThroughBlocks: AIR

MaxBranchDepth: 10

ExcludedBiomes: All


#######################################################################
# +-----------------------------------------------------------------+ #
# |                      Source block settings                      | #
# +-----------------------------------------------------------------+ #
#######################################################################

SourceBlocks: STONE:1,STONE:3,STONE:5,DIRT:1,DIRT,SAND,GRASS,DIRT:2,STATIONARY_WATER,HARD_CLAY,STAINED_CLAY,CLAY,SANDSTONE,SAND:1,AIR,STONE,GRAVEL,LONG_GRASS,LONG_GRASS:1,LONG_GRASS:2,DEAD_BUSH,YELLOW_FLOWER,RED_ROSE,BROWN_MUSHROOM,RED_MUSHROOM,biomesoplenty:plant_0,biomesoplenty:flower_0

MaxPercentageOutsideSourceBlock: 0

OutsideSourceBlock: placeAnyway

IsOTGPlus: false


#######################################################################
# +-----------------------------------------------------------------+ #
# |                              Blocks                             | #
# +-----------------------------------------------------------------+ #
#######################################################################

Block(-4,7,2,biomesoplenty:leaves_2:3)
Block(-4,6,2,biomesoplenty:leaves_2:3)
Block(-4,5,2,LOG_2:1)
Block(-4,4,2,biomesoplenty:leaves_2:3)
Block(1,8,-4,LOG_2:1)
Block(1,9,-4,biomesoplenty:leaves_2:3)
Block(1,6,-4,biomesoplenty:leaves_2:3)
Block(-2,13,-3,biomesoplenty:leaves_2:3)
Block(1,7,-4,LOG_2:1)
Block(-2,12,-3,biomesoplenty:leaves_2:3)
Block(-3,7,4,LOG_2:1)
Block(-3,6,4,LOG_2:1)
Block(-3,9,4,biomesoplenty:leaves_2:3)
Block(-3,8,4,biomesoplenty:leaves_2:3)
Block(-3,5,4,biomesoplenty:leaves_2:3)
Block(-4,13,-1,biomesoplenty:leaves_2:3)
Block(-4,12,-1,biomesoplenty:leaves_2:3)
Block(-3,10,2,biomesoplenty:leaves_2:3)
Block(-4,11,-1,biomesoplenty:leaves_2:3)
Block(-4,10,-1,LOG_2:1)
Block(-6,11,0,biomesoplenty:leaves_2:3)
Block(-3,12,2,biomesoplenty:leaves_2:3)
Block(-2,9,6,biomesoplenty:leaves_2:3)
Block(-3,11,2,biomesoplenty:leaves_2:3)
Block(-2,8,6,biomesoplenty:leaves_2:3)
Block(-2,11,-3,biomesoplenty:leaves_2:3)
Block(-2,10,-3,biomesoplenty:leaves_2:3)
Block(-3,4,-2,biomesoplenty:leaves_2:3)
Block(-3,5,-2,biomesoplenty:leaves_2:3)
Block(-3,6,-2,biomesoplenty:leaves_2:3)
Block(1,10,1,biomesoplenty:leaves_2:3)
Block(-3,7,-2,biomesoplenty:leaves_2:3)
Block(1,11,1,biomesoplenty:leaves_2:3)
Block(-3,8,-2,biomesoplenty:leaves_2:3)
Block(-3,9,-2,biomesoplenty:leaves_2:3)
Block(1,14,-1,biomesoplenty:leaves_2:3)
Block(-2,10,-4,biomesoplenty:leaves_2:3)
Block(-2,11,-4,biomesoplenty:leaves_2:3)
Block(-2,12,-4,biomesoplenty:leaves_2:3)
Block(-7,10,2,biomesoplenty:leaves_2:3)
Block(-4,5,1,biomesoplenty:leaves_2:3)
Block(1,9,-3,biomesoplenty:leaves_2:3)
Block(1,7,-3,biomesoplenty:leaves_2:3)
Block(1,8,-3,biomesoplenty:leaves_2:3)
Block(1,5,-3,biomesoplenty:leaves_2:3)
Block(-3,8,3,biomesoplenty:leaves_2:3)
Block(1,10,2,biomesoplenty:leaves_2:3)
Block(1,6,-3,LOG_2:1)
Block(-3,7,3,biomesoplenty:leaves_2:3)
Block(1,11,2,biomesoplenty:leaves_2:3)
Block(1,12,2,biomesoplenty:leaves_2:3)
Block(1,13,2,biomesoplenty:leaves_2:3)
Block(-3,4,3,biomesoplenty:leaves_2:3)
Block(1,13,-1,LOG_2:1)
Block(1,12,-1,biomesoplenty:leaves_2:3)
Block(-3,6,3,biomesoplenty:leaves_2:3)
Block(1,11,-1,biomesoplenty:leaves_2:3)
Block(-3,5,3,LOG_2:1)
Block(1,10,-1,LOG_2:1)
Block(-6,12,0,biomesoplenty:leaves_2:3)
Block(-6,13,0,biomesoplenty:leaves_2:3)
Block(-4,10,5,biomesoplenty:leaves_2:3)
Block(-2,9,5,LOG_2:1)
Block(-2,8,5,LOG_2:1)
Block(-4,11,5,biomesoplenty:leaves_2:3)
Block(-2,7,5,biomesoplenty:leaves_2:3)
Block(-3,7,-1,biomesoplenty:leaves_2:3)
Block(-3,8,-1,LOG_2:1)
Block(-3,9,-1,biomesoplenty:leaves_2:3)
Block(-3,11,3,biomesoplenty:leaves_2:3)
Block(-3,10,3,biomesoplenty:leaves_2:3)
Block(-4,8,4,biomesoplenty:leaves_2:3)
Block(-4,7,4,biomesoplenty:leaves_2:3)
Block(-4,6,4,biomesoplenty:leaves_2:3)
Block(0,5,0,biomesoplenty:leaves_2:3)
Block(0,4,0,biomesoplenty:leaves_2:3)
Block(0,6,0,biomesoplenty:leaves_2:3)
Block(-4,9,4,biomesoplenty:leaves_2:3)
Block(-2,13,0,biomesoplenty:leaves_2:3)
Block(-2,12,0,biomesoplenty:leaves_2:3)
Block(-2,14,0,biomesoplenty:leaves_2:3)
Block(-2,11,0,biomesoplenty:leaves_2:3)
Block(-2,10,0,biomesoplenty:leaves_2:3)
Block(-2,9,-5,biomesoplenty:leaves_2:3)
Block(-3,9,6,biomesoplenty:leaves_2:3)
Block(-3,8,6,biomesoplenty:leaves_2:3)
Block(1,8,-2,biomesoplenty:leaves_2:3)
Block(1,9,-2,biomesoplenty:leaves_2:3)
Block(1,6,-2,biomesoplenty:leaves_2:3)
Block(1,7,-2,biomesoplenty:leaves_2:3)
Block(-3,7,6,biomesoplenty:leaves_2:3)
Block(1,5,-2,biomesoplenty:leaves_2:3)
Block(-4,8,-1,biomesoplenty:leaves_2:3)
Block(-4,11,-3,biomesoplenty:leaves_2:3)
Block(-4,12,-3,biomesoplenty:leaves_2:3)
Block(-4,9,-1,LOG_2:1)
Block(-4,13,-3,biomesoplenty:leaves_2:3)
Block(-4,10,3,biomesoplenty:leaves_2:3)
Block(-5,7,1,biomesoplenty:leaves_2:3)
Block(-2,13,-4,biomesoplenty:leaves_2:3)
Block(-2,14,-4,biomesoplenty:leaves_2:3)
Block(-2,15,-4,biomesoplenty:leaves_2:3)
Block(2,9,-1,biomesoplenty:leaves_2:3)
Block(2,8,-1,biomesoplenty:leaves_2:3)
Block(2,7,-1,biomesoplenty:leaves_2:3)
Block(0,9,1,biomesoplenty:leaves_2:3)
Block(-6,10,1,biomesoplenty:leaves_2:3)
Block(-5,6,1,biomesoplenty:leaves_2:3)
Block(-4,9,3,biomesoplenty:leaves_2:3)
Block(-4,8,3,biomesoplenty:leaves_2:3)
Block(-4,7,3,biomesoplenty:leaves_2:3)
Block(-4,6,3,biomesoplenty:leaves_2:3)
Block(-4,10,4,biomesoplenty:leaves_2:3)
Block(-1,10,6,biomesoplenty:leaves_2:3)
Block(-4,5,3,biomesoplenty:leaves_2:3)
Block(-3,9,5,biomesoplenty:leaves_2:3)
Block(1,9,-1,biomesoplenty:leaves_2:3)
Block(-3,6,5,biomesoplenty:leaves_2:3)
Block(1,7,-1,biomesoplenty:leaves_2:3)
Block(1,8,-1,biomesoplenty:leaves_2:3)
Block(-3,8,5,biomesoplenty:leaves_2:3)
Block(1,6,-1,biomesoplenty:leaves_2:3)
Block(-3,7,5,biomesoplenty:leaves_2:3)
Block(-6,11,2,biomesoplenty:leaves_2:3)
Block(-6,10,2,biomesoplenty:leaves_2:3)
Block(-3,10,4,biomesoplenty:leaves_2:3)
Block(-2,9,7,biomesoplenty:leaves_2:3)
Block(-2,10,-5,biomesoplenty:leaves_2:3)
Block(-2,11,-5,biomesoplenty:leaves_2:3)
Block(-5,7,2,LOG_2:1)
Block(-5,6,2,LOG_2:1)
Block(-5,9,2,biomesoplenty:leaves_2:3)
Block(1,10,3,biomesoplenty:leaves_2:3)
Block(-5,8,2,biomesoplenty:leaves_2:3)
Block(1,11,3,biomesoplenty:leaves_2:3)
Block(2,8,-2,LOG_2:1)
Block(0,9,0,biomesoplenty:leaves_2:3)
Block(2,7,-2,LOG_2:1)
Block(2,6,-2,biomesoplenty:leaves_2:3)
Block(-5,5,2,biomesoplenty:leaves_2:3)
Block(2,9,-2,biomesoplenty:leaves_2:3)
Block(-4,9,6,biomesoplenty:leaves_2:3)
Block(0,8,-4,biomesoplenty:leaves_2:3)
Block(-4,8,6,biomesoplenty:leaves_2:3)
Block(0,7,-4,biomesoplenty:leaves_2:3)
Block(-4,11,2,biomesoplenty:leaves_2:3)
Block(-4,10,2,biomesoplenty:leaves_2:3)
Block(-2,9,-3,LOG_2:1)
Block(-2,8,-3,biomesoplenty:leaves_2:3)
Block(0,13,1,biomesoplenty:leaves_2:3)
Block(0,12,1,biomesoplenty:leaves_2:3)
Block(-5,10,5,biomesoplenty:leaves_2:3)
Block(0,9,-4,biomesoplenty:leaves_2:3)
Block(0,11,1,biomesoplenty:leaves_2:3)
Block(-2,5,-3,biomesoplenty:leaves_2:3)
Block(0,10,1,biomesoplenty:leaves_2:3)
Block(-2,4,-3,biomesoplenty:leaves_2:3)
Block(-4,6,-3,biomesoplenty:leaves_2:3)
Block(-4,5,-3,biomesoplenty:leaves_2:3)
Block(-6,9,1,biomesoplenty:leaves_2:3)
Block(-6,8,1,biomesoplenty:leaves_2:3)
Block(-5,6,3,biomesoplenty:leaves_2:3)
Block(-5,8,3,biomesoplenty:leaves_2:3)
Block(-1,10,-2,biomesoplenty:leaves_2:3)
Block(-5,7,3,biomesoplenty:leaves_2:3)
Block(-1,11,-2,LOG_2:1)
Block(4,7,2,biomesoplenty:leaves_2:3)
Block(4,6,2,biomesoplenty:leaves_2:3)
Block(-5,9,3,biomesoplenty:leaves_2:3)
Block(2,7,-3,biomesoplenty:leaves_2:3)
Block(-3,10,5,biomesoplenty:leaves_2:3)
Block(2,6,-3,biomesoplenty:leaves_2:3)
Block(2,9,-3,biomesoplenty:leaves_2:3)
Block(2,8,-3,biomesoplenty:leaves_2:3)
Block(-4,7,5,biomesoplenty:leaves_2:3)
Block(-4,9,5,LOG_2:1)
Block(-4,8,5,LOG_2:1)
Block(-2,12,-1,biomesoplenty:leaves_2:3)
Block(-2,13,-1,biomesoplenty:leaves_2:3)
Block(-2,10,-1,biomesoplenty:leaves_2:3)
Block(-3,9,7,biomesoplenty:leaves_2:3)
Block(-1,10,-1,LOG_2:1)
Block(-2,11,-1,biomesoplenty:leaves_2:3)
Block(-2,16,-1,biomesoplenty:leaves_2:3)
Block(-2,17,-1,biomesoplenty:leaves_2:3)
Block(-2,8,-4,biomesoplenty:leaves_2:3)
Block(-2,14,-1,biomesoplenty:leaves_2:3)
Block(-2,9,-4,LOG_2:1)
Block(-2,15,-1,biomesoplenty:leaves_2:3)
Block(-5,13,-2,biomesoplenty:leaves_2:3)
Block(2,10,1,biomesoplenty:leaves_2:3)
Block(-5,12,-2,biomesoplenty:leaves_2:3)
Block(-4,9,-2,biomesoplenty:leaves_2:3)
Block(-5,11,-2,biomesoplenty:leaves_2:3)
Block(-1,15,-1,LOG_2:1)
Block(-2,13,1,biomesoplenty:leaves_2:3)
Block(-1,16,-1,LOG_2:1)
Block(-1,17,-1,biomesoplenty:leaves_2:3)
Block(-6,9,2,LOG_2:1)
Block(-1,18,-1,biomesoplenty:leaves_2:3)
Block(-6,8,2,LOG_2:1)
Block(-2,10,1,biomesoplenty:leaves_2:3)
Block(-1,11,-1,LOG_2:1)
Block(-6,7,2,biomesoplenty:leaves_2:3)
Block(-1,12,-1,LOG_2:1)
Block(-6,6,2,biomesoplenty:leaves_2:3)
Block(-2,12,1,biomesoplenty:leaves_2:3)
Block(-1,13,-1,LOG_2:1)
Block(-2,11,1,biomesoplenty:leaves_2:3)
Block(-1,14,-1,LOG_2:1)
Block(0,13,0,biomesoplenty:leaves_2:3)
Block(0,12,0,biomesoplenty:leaves_2:3)
Block(-5,9,4,biomesoplenty:leaves_2:3)
Block(-5,8,4,biomesoplenty:leaves_2:3)
Block(-5,10,4,biomesoplenty:leaves_2:3)
Block(0,10,0,biomesoplenty:leaves_2:3)
Block(2,9,-4,biomesoplenty:leaves_2:3)
Block(2,8,-4,biomesoplenty:leaves_2:3)
Block(2,7,-4,biomesoplenty:leaves_2:3)
Block(0,4,-2,biomesoplenty:leaves_2:3)
Block(0,6,-2,biomesoplenty:leaves_2:3)
Block(0,5,-2,LOG_2:1)
Block(0,8,-2,biomesoplenty:leaves_2:3)
Block(0,7,-2,biomesoplenty:leaves_2:3)
Block(0,9,-2,biomesoplenty:leaves_2:3)
Block(-2,10,-2,biomesoplenty:leaves_2:3)
Block(2,13,0,biomesoplenty:leaves_2:3)
Block(2,14,0,biomesoplenty:leaves_2:3)
Block(2,15,0,biomesoplenty:leaves_2:3)
Block(-1,10,-3,biomesoplenty:leaves_2:3)
Block(-2,10,3,biomesoplenty:leaves_2:3)
Block(-1,12,-3,LOG_2:1)
Block(-2,9,-1,biomesoplenty:leaves_2:3)
Block(-1,11,-3,biomesoplenty:leaves_2:3)
Block(-2,4,-1,biomesoplenty:leaves_2:3)
Block(-2,3,-1,biomesoplenty:leaves_2:3)
Block(-2,8,-1,biomesoplenty:leaves_2:3)
Block(-2,7,-1,LOG_2:1)
Block(-2,6,-1,biomesoplenty:leaves_2:3)
Block(-2,5,-1,biomesoplenty:leaves_2:3)
Block(-3,10,6,biomesoplenty:leaves_2:3)
Block(-6,9,3,biomesoplenty:leaves_2:3)
Block(-6,8,3,biomesoplenty:leaves_2:3)
Block(-1,14,-3,biomesoplenty:leaves_2:3)
Block(-1,13,-3,biomesoplenty:leaves_2:3)
Block(-2,11,3,biomesoplenty:leaves_2:3)
Block(1,10,5,biomesoplenty:leaves_2:3)
Block(-5,8,5,biomesoplenty:leaves_2:3)
Block(-4,12,0,biomesoplenty:leaves_2:3)
Block(0,13,2,biomesoplenty:leaves_2:3)
Block(-4,13,0,biomesoplenty:leaves_2:3)
Block(0,14,2,biomesoplenty:leaves_2:3)
Block(-4,10,0,biomesoplenty:leaves_2:3)
Block(-5,9,5,biomesoplenty:leaves_2:3)
Block(-4,11,0,biomesoplenty:leaves_2:3)
Block(-3,10,-1,biomesoplenty:leaves_2:3)
Block(0,10,2,biomesoplenty:leaves_2:3)
Block(-3,11,-1,biomesoplenty:leaves_2:3)
Block(0,11,2,LOG_2:1)
Block(-4,14,-2,biomesoplenty:leaves_2:3)
Block(-3,12,-1,biomesoplenty:leaves_2:3)
Block(0,12,2,LOG_2:1)
Block(-4,13,-2,biomesoplenty:leaves_2:3)
Block(-4,12,-2,LOG_2:1)
Block(-3,13,-1,biomesoplenty:leaves_2:3)
Block(-4,11,-2,LOG_2:1)
Block(-4,10,-2,biomesoplenty:leaves_2:3)
Block(-5,12,-1,biomesoplenty:leaves_2:3)
Block(-5,11,-1,biomesoplenty:leaves_2:3)
Block(0,5,-3,biomesoplenty:leaves_2:3)
Block(-5,13,-1,biomesoplenty:leaves_2:3)
Block(0,7,-3,biomesoplenty:leaves_2:3)
Block(0,6,-3,biomesoplenty:leaves_2:3)
Block(0,9,-3,biomesoplenty:leaves_2:3)
Block(-5,10,-1,biomesoplenty:leaves_2:3)
Block(0,8,-3,biomesoplenty:leaves_2:3)
Block(-1,16,-2,biomesoplenty:leaves_2:3)
Block(-1,17,-2,biomesoplenty:leaves_2:3)
Block(-1,12,-2,biomesoplenty:leaves_2:3)
Block(-2,12,2,biomesoplenty:leaves_2:3)
Block(-1,13,-2,biomesoplenty:leaves_2:3)
Block(-2,10,2,LOG_2:1)
Block(-1,14,-2,biomesoplenty:leaves_2:3)
Block(-2,11,2,biomesoplenty:leaves_2:3)
Block(-1,15,-2,biomesoplenty:leaves_2:3)
Block(-2,9,-2,biomesoplenty:leaves_2:3)
Block(-2,8,-2,biomesoplenty:leaves_2:3)
Block(-4,12,1,biomesoplenty:leaves_2:3)
Block(-4,11,1,biomesoplenty:leaves_2:3)
Block(-2,3,-2,biomesoplenty:leaves_2:3)
Block(-7,9,2,biomesoplenty:leaves_2:3)
Block(-7,8,2,biomesoplenty:leaves_2:3)
Block(-2,7,-2,biomesoplenty:leaves_2:3)
Block(-2,6,-2,biomesoplenty:leaves_2:3)
Block(-2,5,-2,biomesoplenty:leaves_2:3)
Block(-2,4,-2,LOG_2:1)
Block(-4,10,1,biomesoplenty:leaves_2:3)
Block(-2,13,-2,biomesoplenty:leaves_2:3)
Block(-2,12,-2,biomesoplenty:leaves_2:3)
Block(-2,11,-2,biomesoplenty:leaves_2:3)
Block(1,9,4,biomesoplenty:leaves_2:3)
Block(1,8,4,biomesoplenty:leaves_2:3)
Block(1,7,4,biomesoplenty:leaves_2:3)
Block(1,6,4,LOG_2:1)
Block(1,5,4,LOG_2:1)
Block(1,4,4,biomesoplenty:leaves_2:3)
Block(-1,15,-4,biomesoplenty:leaves_2:3)
Block(-1,14,-4,LOG_2:1)
Block(-1,16,-4,biomesoplenty:leaves_2:3)
Block(2,9,2,biomesoplenty:leaves_2:3)
Block(2,8,2,biomesoplenty:leaves_2:3)
Block(2,5,2,LOG_2:1)
Block(2,4,2,biomesoplenty:leaves_2:3)
Block(2,7,2,biomesoplenty:leaves_2:3)
Block(2,6,2,LOG_2:1)
Block(-3,11,-2,biomesoplenty:leaves_2:3)
Block(-1,10,1,LOG_2:1)
Block(-3,13,-2,biomesoplenty:leaves_2:3)
Block(-1,11,1,biomesoplenty:leaves_2:3)
Block(-3,12,-2,biomesoplenty:leaves_2:3)
Block(-1,12,1,biomesoplenty:leaves_2:3)
Block(-1,5,0,biomesoplenty:leaves_2:3)
Block(-1,4,0,LOG_2:1)
Block(-1,7,0,biomesoplenty:leaves_2:3)
Block(-1,6,0,biomesoplenty:leaves_2:3)
Block(-1,9,0,LOG_2:1)
Block(-1,8,0,biomesoplenty:leaves_2:3)
Block(-1,9,-3,biomesoplenty:leaves_2:3)
Block(-1,8,-3,biomesoplenty:leaves_2:3)
Block(-1,7,-3,biomesoplenty:leaves_2:3)
Block(-5,10,2,biomesoplenty:leaves_2:3)
Block(1,3,3,biomesoplenty:leaves_2:3)
Block(0,5,-1,biomesoplenty:leaves_2:3)
Block(1,9,5,biomesoplenty:leaves_2:3)
Block(3,7,-2,biomesoplenty:leaves_2:3)
Block(1,8,5,LOG_2:1)
Block(0,7,-1,biomesoplenty:leaves_2:3)
Block(1,7,5,LOG_2:1)
Block(3,8,-2,biomesoplenty:leaves_2:3)
Block(0,6,-1,biomesoplenty:leaves_2:3)
Block(1,6,5,biomesoplenty:leaves_2:3)
Block(3,9,-2,biomesoplenty:leaves_2:3)
Block(1,5,5,biomesoplenty:leaves_2:3)
Block(0,9,-1,LOG_2:1)
Block(0,8,-1,biomesoplenty:leaves_2:3)
Block(-3,10,-3,biomesoplenty:leaves_2:3)
Block(2,8,3,biomesoplenty:leaves_2:3)
Block(2,7,3,biomesoplenty:leaves_2:3)
Block(2,4,3,biomesoplenty:leaves_2:3)
Block(2,6,3,biomesoplenty:leaves_2:3)
Block(2,5,3,biomesoplenty:leaves_2:3)
Block(0,10,3,biomesoplenty:leaves_2:3)
Block(0,11,3,biomesoplenty:leaves_2:3)
Block(0,12,3,biomesoplenty:leaves_2:3)
Block(0,13,3,biomesoplenty:leaves_2:3)
Block(-1,6,-2,biomesoplenty:leaves_2:3)
Block(3,7,1,biomesoplenty:leaves_2:3)
Block(0,16,-1,biomesoplenty:leaves_2:3)
Block(-1,5,-2,biomesoplenty:leaves_2:3)
Block(3,6,1,biomesoplenty:leaves_2:3)
Block(0,15,-1,biomesoplenty:leaves_2:3)
Block(-1,4,-2,biomesoplenty:leaves_2:3)
Block(0,17,-1,biomesoplenty:leaves_2:3)
Block(3,9,1,biomesoplenty:leaves_2:3)
Block(3,8,1,biomesoplenty:leaves_2:3)
Block(-5,12,1,biomesoplenty:leaves_2:3)
Block(-1,9,-2,biomesoplenty:leaves_2:3)
Block(-5,13,1,biomesoplenty:leaves_2:3)
Block(-1,8,-2,LOG_2:1)
Block(-1,7,-2,biomesoplenty:leaves_2:3)
Block(-1,10,-4,biomesoplenty:leaves_2:3)
Block(-2,10,4,biomesoplenty:leaves_2:3)
Block(-1,13,-4,LOG_2:1)
Block(-1,12,-4,biomesoplenty:leaves_2:3)
Block(-1,10,2,biomesoplenty:leaves_2:3)
Block(-3,12,-3,biomesoplenty:leaves_2:3)
Block(-3,11,-3,biomesoplenty:leaves_2:3)
Block(0,10,-1,biomesoplenty:leaves_2:3)
Block(-1,12,2,biomesoplenty:leaves_2:3)
Block(-1,11,2,biomesoplenty:leaves_2:3)
Block(0,12,-1,biomesoplenty:leaves_2:3)
Block(0,11,-1,biomesoplenty:leaves_2:3)
Block(-1,13,2,biomesoplenty:leaves_2:3)
Block(0,9,6,biomesoplenty:leaves_2:3)
Block(0,14,-1,biomesoplenty:leaves_2:3)
Block(0,13,-1,LOG_2:1)
Block(1,8,6,biomesoplenty:leaves_2:3)
Block(1,7,6,biomesoplenty:leaves_2:3)
Block(2,7,4,biomesoplenty:leaves_2:3)
Block(2,6,4,biomesoplenty:leaves_2:3)
Block(2,5,4,biomesoplenty:leaves_2:3)
Block(-1,3,2,biomesoplenty:leaves_2:3)
Block(3,6,2,biomesoplenty:leaves_2:3)
Block(3,5,2,biomesoplenty:leaves_2:3)
Block(-1,5,2,biomesoplenty:leaves_2:3)
Block(-1,4,2,biomesoplenty:leaves_2:3)
Block(-3,10,-4,biomesoplenty:leaves_2:3)
Block(-1,6,2,biomesoplenty:leaves_2:3)
Block(-3,11,-4,biomesoplenty:leaves_2:3)
Block(3,8,2,biomesoplenty:leaves_2:3)
Block(-1,9,2,biomesoplenty:leaves_2:3)
Block(3,7,2,biomesoplenty:leaves_2:3)
Block(-2,9,0,biomesoplenty:leaves_2:3)
Block(-2,8,0,biomesoplenty:leaves_2:3)
Block(-2,7,0,biomesoplenty:leaves_2:3)
Block(-2,4,0,biomesoplenty:leaves_2:3)
Block(1,10,-4,biomesoplenty:leaves_2:3)
Block(-1,15,0,biomesoplenty:leaves_2:3)
Block(-1,16,0,biomesoplenty:leaves_2:3)
Block(-1,17,0,biomesoplenty:leaves_2:3)
Block(-1,10,0,biomesoplenty:leaves_2:3)
Block(-1,11,0,biomesoplenty:leaves_2:3)
Block(-1,12,0,biomesoplenty:leaves_2:3)
Block(-1,13,0,biomesoplenty:leaves_2:3)
Block(-1,14,0,biomesoplenty:leaves_2:3)
Block(-1,13,-5,biomesoplenty:leaves_2:3)
Block(-5,10,3,biomesoplenty:leaves_2:3)
Block(-2,11,5,biomesoplenty:leaves_2:3)
Block(-1,14,-5,biomesoplenty:leaves_2:3)
Block(2,8,5,biomesoplenty:leaves_2:3)
Block(-2,10,5,biomesoplenty:leaves_2:3)
Block(2,7,5,biomesoplenty:leaves_2:3)
Block(2,9,5,biomesoplenty:leaves_2:3)
Block(-5,9,-1,biomesoplenty:leaves_2:3)
Block(-1,4,1,LOG_2:1)
Block(3,5,3,biomesoplenty:leaves_2:3)
Block(-1,3,1,biomesoplenty:leaves_2:3)
Block(-1,6,1,biomesoplenty:leaves_2:3)
Block(-1,5,1,biomesoplenty:leaves_2:3)
Block(3,7,3,biomesoplenty:leaves_2:3)
Block(3,6,3,biomesoplenty:leaves_2:3)
Block(-1,9,1,biomesoplenty:leaves_2:3)
Block(-1,9,-4,biomesoplenty:leaves_2:3)
Block(-1,8,-4,biomesoplenty:leaves_2:3)
Block(-1,15,-5,biomesoplenty:leaves_2:3)
Block(0,11,4,biomesoplenty:leaves_2:3)
Block(0,12,4,biomesoplenty:leaves_2:3)
Block(0,10,4,biomesoplenty:leaves_2:3)
Block(0,3,2,biomesoplenty:leaves_2:3)
Block(-3,11,-5,biomesoplenty:leaves_2:3)
Block(-1,10,4,biomesoplenty:leaves_2:3)
Block(-3,12,-5,biomesoplenty:leaves_2:3)
Block(0,5,2,biomesoplenty:leaves_2:3)
Block(1,8,0,biomesoplenty:leaves_2:3)
Block(0,4,2,LOG_2:1)
Block(-3,10,-5,LOG_2:1)
Block(2,14,-2,biomesoplenty:leaves_2:3)
Block(2,15,-2,biomesoplenty:leaves_2:3)
Block(2,13,-2,biomesoplenty:leaves_2:3)
Block(2,10,-2,biomesoplenty:leaves_2:3)
Block(1,12,-3,biomesoplenty:leaves_2:3)
Block(1,13,-3,biomesoplenty:leaves_2:3)
Block(1,14,-3,biomesoplenty:leaves_2:3)
Block(0,13,-4,biomesoplenty:leaves_2:3)
Block(-3,9,0,biomesoplenty:leaves_2:3)
Block(-3,8,0,biomesoplenty:leaves_2:3)
Block(0,14,-4,biomesoplenty:leaves_2:3)
Block(0,15,-4,biomesoplenty:leaves_2:3)
Block(-1,5,4,biomesoplenty:leaves_2:3)
Block(-1,7,4,biomesoplenty:leaves_2:3)
Block(-1,6,4,biomesoplenty:leaves_2:3)
Block(-2,9,2,biomesoplenty:leaves_2:3)
Block(-1,9,4,biomesoplenty:leaves_2:3)
Block(-1,8,4,biomesoplenty:leaves_2:3)
Block(-2,6,2,biomesoplenty:leaves_2:3)
Block(-2,5,2,biomesoplenty:leaves_2:3)
Block(-2,4,2,biomesoplenty:leaves_2:3)
Block(-2,3,2,biomesoplenty:leaves_2:3)
Block(0,6,3,biomesoplenty:leaves_2:3)
Block(0,5,3,biomesoplenty:leaves_2:3)
Block(0,9,3,biomesoplenty:leaves_2:3)
Block(0,4,1,biomesoplenty:leaves_2:3)
Block(1,9,1,biomesoplenty:leaves_2:3)
Block(1,8,1,biomesoplenty:leaves_2:3)
Block(0,6,1,biomesoplenty:leaves_2:3)
Block(1,7,1,biomesoplenty:leaves_2:3)
Block(0,5,1,biomesoplenty:leaves_2:3)
Block(1,6,1,biomesoplenty:leaves_2:3)
Block(-4,11,-5,biomesoplenty:leaves_2:3)
Block(-4,10,-5,biomesoplenty:leaves_2:3)
Block(-3,11,0,biomesoplenty:leaves_2:3)
Block(-3,12,0,biomesoplenty:leaves_2:3)
Block(-1,4,3,biomesoplenty:leaves_2:3)
Block(-3,10,0,biomesoplenty:leaves_2:3)
Block(-1,6,3,biomesoplenty:leaves_2:3)
Block(-1,10,5,biomesoplenty:leaves_2:3)
Block(-1,5,3,biomesoplenty:leaves_2:3)
Block(-3,11,-6,biomesoplenty:leaves_2:3)
Block(-3,13,0,biomesoplenty:leaves_2:3)
Block(-3,10,-6,biomesoplenty:leaves_2:3)
Block(-2,5,1,biomesoplenty:leaves_2:3)
Block(-2,4,1,LOG_2:1)
Block(-2,3,1,biomesoplenty:leaves_2:3)
Block(1,6,0,biomesoplenty:leaves_2:3)
Block(0,6,2,biomesoplenty:leaves_2:3)
Block(-6,10,3,biomesoplenty:leaves_2:3)
Block(0,9,2,biomesoplenty:leaves_2:3)
Block(-3,9,-5,biomesoplenty:leaves_2:3)
Block(-4,9,0,biomesoplenty:leaves_2:3)
Block(1,9,2,biomesoplenty:leaves_2:3)
Block(1,6,2,biomesoplenty:leaves_2:3)
Block(1,5,2,biomesoplenty:leaves_2:3)
Block(-5,11,1,biomesoplenty:leaves_2:3)
Block(2,7,0,biomesoplenty:leaves_2:3)
Block(2,6,0,biomesoplenty:leaves_2:3)
Block(2,9,0,biomesoplenty:leaves_2:3)
Block(2,8,0,biomesoplenty:leaves_2:3)
Block(-3,5,2,biomesoplenty:leaves_2:3)
Block(-3,4,2,LOG_2:1)
Block(-3,6,2,biomesoplenty:leaves_2:3)
Block(-3,3,2,biomesoplenty:leaves_2:3)
Block(-1,7,-1,LOG_2:1)
Block(-1,6,-1,LOG_2:1)
Block(-1,5,-1,LOG_2:1)
Block(-1,4,-1,LOG_2:1)
Block(-1,3,-1,LOG_2:1)
Block(-1,2,-1,LOG_2:1)
Block(-2,9,4,biomesoplenty:leaves_2:3)
Block(-1,1,-1,LOG_2:1)
Block(-2,8,4,biomesoplenty:leaves_2:3)
Block(1,13,0,biomesoplenty:leaves_2:3)
Block(-1,0,-1,LOG_2:1)
Block(-2,7,4,biomesoplenty:leaves_2:3)
Block(1,12,0,biomesoplenty:leaves_2:3)
Block(-2,6,4,biomesoplenty:leaves_2:3)
Block(-1,7,6,biomesoplenty:leaves_2:3)
Block(1,11,0,biomesoplenty:leaves_2:3)
Block(-2,5,4,biomesoplenty:leaves_2:3)
Block(1,10,0,biomesoplenty:leaves_2:3)
Block(-1,9,6,biomesoplenty:leaves_2:3)
Block(-1,8,6,biomesoplenty:leaves_2:3)
Block(2,14,-1,LOG_2:1)
Block(2,13,-1,biomesoplenty:leaves_2:3)
Block(-1,9,-1,LOG_2:1)
Block(2,16,-1,biomesoplenty:leaves_2:3)
Block(-1,8,-1,LOG_2:1)
Block(2,15,-1,biomesoplenty:leaves_2:3)
Block(2,10,-1,biomesoplenty:leaves_2:3)
Block(2,12,-1,biomesoplenty:leaves_2:3)
Block(2,11,-1,biomesoplenty:leaves_2:3)
Block(-3,5,-4,biomesoplenty:leaves_2:3)
Block(-3,6,-4,biomesoplenty:leaves_2:3)
Block(1,5,1,biomesoplenty:leaves_2:3)
Block(0,11,-3,biomesoplenty:leaves_2:3)
Block(0,12,-3,biomesoplenty:leaves_2:3)
Block(0,6,5,biomesoplenty:leaves_2:3)
Block(-3,9,-4,biomesoplenty:leaves_2:3)
Block(0,10,-3,biomesoplenty:leaves_2:3)
Block(0,8,5,biomesoplenty:leaves_2:3)
Block(0,7,5,biomesoplenty:leaves_2:3)
Block(0,13,-3,biomesoplenty:leaves_2:3)
Block(0,9,5,biomesoplenty:leaves_2:3)
Block(0,14,-3,biomesoplenty:leaves_2:3)
Block(-3,12,1,biomesoplenty:leaves_2:3)
Block(1,9,3,biomesoplenty:leaves_2:3)
Block(-3,10,1,biomesoplenty:leaves_2:3)
Block(1,8,3,biomesoplenty:leaves_2:3)
Block(-3,11,1,biomesoplenty:leaves_2:3)
Block(1,7,3,biomesoplenty:leaves_2:3)
Block(1,6,3,biomesoplenty:leaves_2:3)
Block(0,4,3,biomesoplenty:leaves_2:3)
Block(1,5,3,biomesoplenty:leaves_2:3)
Block(1,4,3,LOG_2:1)
Block(-5,14,0,biomesoplenty:leaves_2:3)
Block(-5,13,0,biomesoplenty:leaves_2:3)
Block(-5,12,0,LOG_2:1)
Block(-5,11,0,LOG_2:1)
Block(1,9,-5,biomesoplenty:leaves_2:3)
Block(1,7,-5,biomesoplenty:leaves_2:3)
Block(1,8,-5,biomesoplenty:leaves_2:3)
Block(2,9,1,biomesoplenty:leaves_2:3)
Block(2,6,1,biomesoplenty:leaves_2:3)
Block(2,5,1,biomesoplenty:leaves_2:3)
Block(-3,9,1,biomesoplenty:leaves_2:3)
Block(2,8,1,LOG_2:1)
Block(2,7,1,LOG_2:1)
Block(-1,11,3,biomesoplenty:leaves_2:3)
Block(-1,10,3,biomesoplenty:leaves_2:3)
Block(0,11,-2,biomesoplenty:leaves_2:3)
Block(0,10,-2,biomesoplenty:leaves_2:3)
Block(-1,12,3,biomesoplenty:leaves_2:3)
Block(0,13,-2,biomesoplenty:leaves_2:3)
Block(0,12,-2,biomesoplenty:leaves_2:3)
Block(-3,4,1,biomesoplenty:leaves_2:3)
Block(0,14,-2,biomesoplenty:leaves_2:3)
Block(-1,8,5,biomesoplenty:leaves_2:3)
Block(-2,6,3,biomesoplenty:leaves_2:3)
Block(-1,7,5,biomesoplenty:leaves_2:3)
Block(-2,5,3,biomesoplenty:leaves_2:3)
Block(-2,4,3,biomesoplenty:leaves_2:3)
Block(-1,9,5,biomesoplenty:leaves_2:3)
Block(1,10,-2,biomesoplenty:leaves_2:3)
Block(-3,4,-3,biomesoplenty:leaves_2:3)
Block(-5,10,0,biomesoplenty:leaves_2:3)
Block(1,11,-2,biomesoplenty:leaves_2:3)
Block(3,12,-1,biomesoplenty:leaves_2:3)
Block(-3,5,-3,LOG_2:1)
Block(1,12,-2,biomesoplenty:leaves_2:3)
Block(3,13,-1,biomesoplenty:leaves_2:3)
Block(-3,6,-3,biomesoplenty:leaves_2:3)
Block(1,13,-2,biomesoplenty:leaves_2:3)
Block(3,14,-1,biomesoplenty:leaves_2:3)
Block(-3,7,-3,biomesoplenty:leaves_2:3)
Block(1,14,-2,biomesoplenty:leaves_2:3)
Block(3,15,-1,biomesoplenty:leaves_2:3)
Block(1,4,2,biomesoplenty:leaves_2:3)
Block(0,5,4,biomesoplenty:leaves_2:3)
Block(-3,9,-3,biomesoplenty:leaves_2:3)
Block(0,7,4,biomesoplenty:leaves_2:3)
Block(0,6,4,biomesoplenty:leaves_2:3)
Block(0,9,4,biomesoplenty:leaves_2:3)
Block(0,8,4,biomesoplenty:leaves_2:3)

#######################################################################
# +-----------------------------------------------------------------+ #
# |                            BO3 checks                           | #
# +-----------------------------------------------------------------+ #
#######################################################################

BlockCheck(-1,-1,-1,GRASS,DIRT,DIRT:2)

#######################################################################
# +-----------------------------------------------------------------+ #
# |                             Branches                            | #
# +-----------------------------------------------------------------+ #
#######################################################################


#######################################################################
# +-----------------------------------------------------------------+ #
# |                             Entities                            | #
# +-----------------------------------------------------------------+ #
#######################################################################


#######################################################################
# +-----------------------------------------------------------------+ #
# |                            Particles                            | #
# +-----------------------------------------------------------------+ #
#######################################################################


#######################################################################
# +-----------------------------------------------------------------+ #
# |                             Spawners                            | #
# +-----------------------------------------------------------------+ #
#######################################################################


#######################################################################
# +-----------------------------------------------------------------+ #
# |                             ModData                             | #
# +-----------------------------------------------------------------+ #
#######################################################################

