
#######################################################################
# +-----------------------------------------------------------------+ #
# |                            BO3 object                           | #
# +-----------------------------------------------------------------+ #
#######################################################################

Author: Unknown

Description: Converted version of the BO2 OakForestSmall5

Version: 3

SettingsMode: WriteWithoutComments


#######################################################################
# +-----------------------------------------------------------------+ #
# |                          Main settings                          | #
# +-----------------------------------------------------------------+ #
#######################################################################

Tree: true

Frequency: 1

Rarity: 10.0

RotateRandomly: true

SpawnHeight: highestSolidBlock

SpawnHeightOffset: 0

SpawnHeightVariance: 0

##############################
# Height Limits for the BO3. #
##############################

MinHeight: 62

MaxHeight: 210

######################
# Extrusion settings #
######################

ExtrudeMode: None

ExtrudeThroughBlocks: AIR

MaxBranchDepth: 10

ExcludedBiomes: All


#######################################################################
# +-----------------------------------------------------------------+ #
# |                      Source block settings                      | #
# +-----------------------------------------------------------------+ #
#######################################################################

SourceBlocks: STONE:1,STONE:3,STONE:5,DIRT:1,DIRT,SAND,GRASS,DIRT:2,STATIONARY_WATER,HARD_CLAY,STAINED_CLAY,CLAY,SANDSTONE,SAND:1,AIR,STONE,GRAVEL,LONG_GRASS,LONG_GRASS:1,LONG_GRASS:2,DEAD_BUSH,YELLOW_FLOWER,RED_ROSE,BROWN_MUSHROOM,RED_MUSHROOM,biomesoplenty:plant_0,biomesoplenty:flower_0

MaxPercentageOutsideSourceBlock: 0

OutsideSourceBlock: placeAnyway

DoReplaceBlocks: true

IsOTGPlus: false


#######################################################################
# +-----------------------------------------------------------------+ #
# |                              Blocks                             | #
# +-----------------------------------------------------------------+ #
#######################################################################

Block(0,5,2,biomesoplenty:leaves_2:3)
Block(0,4,2,biomesoplenty:leaves_2:3)
Block(-3,3,0,biomesoplenty:leaves_2:3)
Block(-2,5,-3,biomesoplenty:leaves_2:3)
Block(-3,5,0,biomesoplenty:leaves_2:3)
Block(-3,4,0,biomesoplenty:leaves_2:3)
Block(-1,5,-3,biomesoplenty:leaves_2:3)
Block(-1,5,0,LOG_2:1)
Block(-1,4,0,LOG_2:1)
Block(-1,7,0,biomesoplenty:leaves_2:3)
Block(-1,6,0,biomesoplenty:leaves_2:3)
Block(2,4,1,biomesoplenty:leaves_2:3)
Block(-2,4,2,biomesoplenty:leaves_2:3)
Block(-1,-1,0,LOG_2:1)
Block(-1,-2,0,LOG_2:1)
Block(-1,-3,0,LOG_2:1)
Block(-3,5,-2,biomesoplenty:leaves_2:3)
Block(-1,1,0,LOG_2:1)
Block(-1,0,0,LOG_2:1)
Block(-1,3,0,LOG_2:1)
Block(-1,2,0,LOG_2:1)
Block(0,5,-1,biomesoplenty:leaves_2:3)
Block(0,4,-1,biomesoplenty:leaves_2:3)
Block(0,2,1,biomesoplenty:leaves_2:3)
Block(0,6,-1,biomesoplenty:leaves_2:3)
Block(0,4,1,biomesoplenty:leaves_2:3)
Block(0,3,1,biomesoplenty:leaves_2:3)
Block(0,5,1,biomesoplenty:leaves_2:3)
Block(0,3,-1,biomesoplenty:leaves_2:3)
Block(0,2,-1,biomesoplenty:leaves_2:3)
Block(1,5,-3,biomesoplenty:leaves_2:3)
Block(-1,6,-2,biomesoplenty:leaves_2:3)
Block(-1,5,-2,LOG_2:1)
Block(-1,4,-2,biomesoplenty:leaves_2:3)
Block(-1,4,3,biomesoplenty:leaves_2:3)
Block(-1,3,-2,biomesoplenty:leaves_2:3)
Block(-2,5,1,biomesoplenty:leaves_2:3)
Block(-2,4,1,biomesoplenty:leaves_2:3)
Block(-2,3,1,biomesoplenty:leaves_2:3)
Block(-1,7,-2,biomesoplenty:leaves_2:3)
Block(-3,4,-1,biomesoplenty:leaves_2:3)
Block(1,6,0,biomesoplenty:leaves_2:3)
Block(1,5,0,biomesoplenty:leaves_2:3)
Block(1,4,0,biomesoplenty:leaves_2:3)
Block(1,3,0,LOG_2:1)
Block(1,2,0,biomesoplenty:leaves_2:3)
Block(0,4,-2,biomesoplenty:leaves_2:3)
Block(0,3,0,LOG_2:1)
Block(0,2,0,LOG_2:1)
Block(0,5,-2,biomesoplenty:leaves_2:3)
Block(0,5,0,biomesoplenty:leaves_2:3)
Block(0,4,0,LOG_2:1)
Block(0,6,0,biomesoplenty:leaves_2:3)
Block(1,6,-2,biomesoplenty:leaves_2:3)
Block(2,6,0,biomesoplenty:leaves_2:3)
Block(1,4,-2,biomesoplenty:leaves_2:3)
Block(1,5,-2,biomesoplenty:leaves_2:3)
Block(-2,4,-1,biomesoplenty:leaves_2:3)
Block(1,3,-2,biomesoplenty:leaves_2:3)
Block(-2,3,-1,biomesoplenty:leaves_2:3)
Block(-2,6,-1,biomesoplenty:leaves_2:3)
Block(-2,5,-1,biomesoplenty:leaves_2:3)
Block(-1,3,2,biomesoplenty:leaves_2:3)
Block(-1,7,-1,biomesoplenty:leaves_2:3)
Block(-1,6,-1,biomesoplenty:leaves_2:3)
Block(-1,5,-1,biomesoplenty:leaves_2:3)
Block(-1,5,2,biomesoplenty:leaves_2:3)
Block(-1,4,-1,LOG_2:1)
Block(-1,4,2,biomesoplenty:leaves_2:3)
Block(-1,3,-1,LOG_2:1)
Block(-2,6,0,biomesoplenty:leaves_2:3)
Block(-2,5,0,biomesoplenty:leaves_2:3)
Block(-2,4,0,biomesoplenty:leaves_2:3)
Block(-2,3,0,LOG_2:1)
Block(2,5,-1,biomesoplenty:leaves_2:3)
Block(1,5,1,biomesoplenty:leaves_2:3)
Block(1,4,1,biomesoplenty:leaves_2:3)
Block(1,3,1,biomesoplenty:leaves_2:3)
Block(1,2,1,biomesoplenty:leaves_2:3)
Block(0,5,-3,biomesoplenty:leaves_2:3)
Block(0,4,-3,biomesoplenty:leaves_2:3)
Block(0,6,-3,biomesoplenty:leaves_2:3)
Block(1,5,-1,biomesoplenty:leaves_2:3)
Block(1,3,-1,biomesoplenty:leaves_2:3)
Block(1,4,-1,biomesoplenty:leaves_2:3)
Block(-2,6,-2,biomesoplenty:leaves_2:3)
Block(-3,4,1,biomesoplenty:leaves_2:3)
Block(-2,5,-2,biomesoplenty:leaves_2:3)
Block(-2,4,-2,biomesoplenty:leaves_2:3)
Block(-1,4,1,biomesoplenty:leaves_2:3)
Block(-1,3,1,LOG_2:1)
Block(-1,6,1,biomesoplenty:leaves_2:3)
Block(-1,5,1,biomesoplenty:leaves_2:3)
Block(2,3,0,biomesoplenty:leaves_2:3)
Block(2,5,0,biomesoplenty:leaves_2:3)
Block(2,4,-2,biomesoplenty:leaves_2:3)
Block(1,4,2,biomesoplenty:leaves_2:3)
Block(1,3,2,biomesoplenty:leaves_2:3)

#######################################################################
# +-----------------------------------------------------------------+ #
# |                            BO3 checks                           | #
# +-----------------------------------------------------------------+ #
#######################################################################

BlockCheck(-1,-1,0,GRASS,DIRT,DIRT:2)

#######################################################################
# +-----------------------------------------------------------------+ #
# |                             Branches                            | #
# +-----------------------------------------------------------------+ #
#######################################################################


#######################################################################
# +-----------------------------------------------------------------+ #
# |                             Entities                            | #
# +-----------------------------------------------------------------+ #
#######################################################################


#######################################################################
# +-----------------------------------------------------------------+ #
# |                            Particles                            | #
# +-----------------------------------------------------------------+ #
#######################################################################


#######################################################################
# +-----------------------------------------------------------------+ #
# |                             Spawners                            | #
# +-----------------------------------------------------------------+ #
#######################################################################


#######################################################################
# +-----------------------------------------------------------------+ #
# |                             ModData                             | #
# +-----------------------------------------------------------------+ #
#######################################################################

