
#######################################################################
# +-----------------------------------------------------------------+ #
# |                            BO3 object                           | #
# +-----------------------------------------------------------------+ #
#######################################################################

Author: Unknown

Description: Converted version of the BO2 OakForestSmall13

Version: 3

SettingsMode: WriteWithoutComments


#######################################################################
# +-----------------------------------------------------------------+ #
# |                          Main settings                          | #
# +-----------------------------------------------------------------+ #
#######################################################################

Tree: true

Frequency: 1

Rarity: 10.0

RotateRandomly: true

SpawnHeight: highestSolidBlock

SpawnHeightOffset: 0

SpawnHeightVariance: 0

##############################
# Height Limits for the BO3. #
##############################

MinHeight: 62

MaxHeight: 210

######################
# Extrusion settings #
######################

ExtrudeMode: None

ExtrudeThroughBlocks: AIR

MaxBranchDepth: 10

ExcludedBiomes: All


#######################################################################
# +-----------------------------------------------------------------+ #
# |                      Source block settings                      | #
# +-----------------------------------------------------------------+ #
#######################################################################

SourceBlocks: STONE:1,STONE:3,STONE:5,DIRT:1,DIRT,SAND,GRASS,DIRT:2,STATIONARY_WATER,HARD_CLAY,STAINED_CLAY,CLAY,SANDSTONE,SAND:1,AIR,STONE,GRAVEL,LONG_GRASS,LONG_GRASS:1,LONG_GRASS:2,DEAD_BUSH,YELLOW_FLOWER,RED_ROSE,BROWN_MUSHROOM,RED_MUSHROOM,biomesoplenty:plant_0,biomesoplenty:flower_0

MaxPercentageOutsideSourceBlock: 0

OutsideSourceBlock: placeAnyway

DoReplaceBlocks: true

IsOTGPlus: false


#######################################################################
# +-----------------------------------------------------------------+ #
# |                              Blocks                             | #
# +-----------------------------------------------------------------+ #
#######################################################################

Block(3,5,-3,biomesoplenty:leaves_2:3)
Block(1,6,-4,biomesoplenty:leaves_2:3)
Block(-2,12,-3,biomesoplenty:leaves_2:3)
Block(1,4,-4,biomesoplenty:leaves_2:3)
Block(2,5,2,biomesoplenty:leaves_2:3)
Block(1,5,-4,biomesoplenty:leaves_2:3)
Block(2,7,2,biomesoplenty:leaves_2:3)
Block(2,6,2,LOG_2:1)
Block(-1,10,1,biomesoplenty:leaves_2:3)
Block(-1,11,1,LOG_2:1)
Block(-1,12,1,biomesoplenty:leaves_2:3)
Block(-1,13,1,biomesoplenty:leaves_2:3)
Block(-1,5,-3,biomesoplenty:leaves_2:3)
Block(3,6,0,biomesoplenty:leaves_2:3)
Block(-1,7,0,LOG_2:1)
Block(-1,6,0,biomesoplenty:leaves_2:3)
Block(-1,8,0,biomesoplenty:leaves_2:3)
Block(3,9,0,biomesoplenty:leaves_2:3)
Block(1,10,1,biomesoplenty:leaves_2:3)
Block(1,11,1,LOG_2:1)
Block(1,12,1,biomesoplenty:leaves_2:3)
Block(1,13,1,biomesoplenty:leaves_2:3)
Block(3,11,2,biomesoplenty:leaves_2:3)
Block(1,14,1,biomesoplenty:leaves_2:3)
Block(3,12,2,biomesoplenty:leaves_2:3)
Block(0,5,-1,biomesoplenty:leaves_2:3)
Block(0,4,-1,biomesoplenty:leaves_2:3)
Block(0,7,-1,biomesoplenty:leaves_2:3)
Block(0,6,-1,biomesoplenty:leaves_2:3)
Block(1,14,-1,biomesoplenty:leaves_2:3)
Block(-4,7,1,biomesoplenty:leaves_2:3)
Block(3,4,-2,biomesoplenty:leaves_2:3)
Block(3,5,-2,biomesoplenty:leaves_2:3)
Block(2,7,3,biomesoplenty:leaves_2:3)
Block(1,5,-3,biomesoplenty:leaves_2:3)
Block(1,10,2,biomesoplenty:leaves_2:3)
Block(1,6,-3,biomesoplenty:leaves_2:3)
Block(1,11,2,biomesoplenty:leaves_2:3)
Block(1,3,-3,biomesoplenty:leaves_2:3)
Block(2,6,3,biomesoplenty:leaves_2:3)
Block(1,12,2,biomesoplenty:leaves_2:3)
Block(1,4,-3,LOG_2:1)
Block(2,5,3,biomesoplenty:leaves_2:3)
Block(1,13,2,biomesoplenty:leaves_2:3)
Block(1,13,-1,biomesoplenty:leaves_2:3)
Block(0,11,3,biomesoplenty:leaves_2:3)
Block(1,12,-1,biomesoplenty:leaves_2:3)
Block(1,11,-1,biomesoplenty:leaves_2:3)
Block(0,12,3,biomesoplenty:leaves_2:3)
Block(1,10,-1,biomesoplenty:leaves_2:3)
Block(3,7,1,biomesoplenty:leaves_2:3)
Block(-1,5,-2,biomesoplenty:leaves_2:3)
Block(3,6,1,biomesoplenty:leaves_2:3)
Block(5,11,1,biomesoplenty:leaves_2:3)
Block(3,5,1,biomesoplenty:leaves_2:3)
Block(4,11,-2,biomesoplenty:leaves_2:3)
Block(3,9,1,biomesoplenty:leaves_2:3)
Block(-1,7,-2,biomesoplenty:leaves_2:3)
Block(-1,12,-4,biomesoplenty:leaves_2:3)
Block(-3,7,-1,biomesoplenty:leaves_2:3)
Block(-3,8,-1,biomesoplenty:leaves_2:3)
Block(0,10,-1,biomesoplenty:leaves_2:3)
Block(4,12,-2,biomesoplenty:leaves_2:3)
Block(-1,12,2,biomesoplenty:leaves_2:3)
Block(-1,11,2,biomesoplenty:leaves_2:3)
Block(0,12,-1,biomesoplenty:leaves_2:3)
Block(0,11,-1,LOG_2:1)
Block(-5,7,0,biomesoplenty:leaves_2:3)
Block(0,14,-1,biomesoplenty:leaves_2:3)
Block(0,13,-1,biomesoplenty:leaves_2:3)
Block(0,5,0,biomesoplenty:leaves_2:3)
Block(0,4,0,biomesoplenty:leaves_2:3)
Block(0,7,0,LOG_2:1)
Block(0,6,0,biomesoplenty:leaves_2:3)
Block(-2,13,0,biomesoplenty:leaves_2:3)
Block(-2,12,0,biomesoplenty:leaves_2:3)
Block(-2,11,0,biomesoplenty:leaves_2:3)
Block(2,6,4,biomesoplenty:leaves_2:3)
Block(1,9,-2,biomesoplenty:leaves_2:3)
Block(1,6,-2,biomesoplenty:leaves_2:3)
Block(1,4,-2,LOG_2:1)
Block(1,5,-2,biomesoplenty:leaves_2:3)
Block(1,3,-2,biomesoplenty:leaves_2:3)
Block(3,6,2,biomesoplenty:leaves_2:3)
Block(3,5,2,biomesoplenty:leaves_2:3)
Block(-4,7,-1,biomesoplenty:leaves_2:3)
Block(2,12,3,biomesoplenty:leaves_2:3)
Block(-1,7,2,biomesoplenty:leaves_2:3)
Block(3,7,2,biomesoplenty:leaves_2:3)
Block(3,11,-3,biomesoplenty:leaves_2:3)
Block(4,13,0,biomesoplenty:leaves_2:3)
Block(3,10,-3,biomesoplenty:leaves_2:3)
Block(-2,8,0,biomesoplenty:leaves_2:3)
Block(4,11,0,LOG_2:1)
Block(-2,7,0,biomesoplenty:leaves_2:3)
Block(4,12,0,biomesoplenty:leaves_2:3)
Block(-2,6,0,biomesoplenty:leaves_2:3)
Block(4,10,0,biomesoplenty:leaves_2:3)
Block(1,12,-4,biomesoplenty:leaves_2:3)
Block(1,11,-4,biomesoplenty:leaves_2:3)
Block(2,5,-1,biomesoplenty:leaves_2:3)
Block(4,9,0,biomesoplenty:leaves_2:3)
Block(2,4,-1,biomesoplenty:leaves_2:3)
Block(2,9,-1,biomesoplenty:leaves_2:3)
Block(0,7,1,biomesoplenty:leaves_2:3)
Block(2,6,-1,biomesoplenty:leaves_2:3)
Block(-1,10,0,biomesoplenty:leaves_2:3)
Block(-1,11,0,biomesoplenty:leaves_2:3)
Block(-1,12,0,biomesoplenty:leaves_2:3)
Block(-1,13,0,biomesoplenty:leaves_2:3)
Block(-1,14,0,biomesoplenty:leaves_2:3)
Block(5,11,0,biomesoplenty:leaves_2:3)
Block(2,12,2,LOG_2:1)
Block(3,5,-4,biomesoplenty:leaves_2:3)
Block(5,10,0,biomesoplenty:leaves_2:3)
Block(2,11,2,biomesoplenty:leaves_2:3)
Block(2,13,2,biomesoplenty:leaves_2:3)
Block(2,10,2,biomesoplenty:leaves_2:3)
Block(4,12,1,biomesoplenty:leaves_2:3)
Block(4,10,1,biomesoplenty:leaves_2:3)
Block(4,11,1,biomesoplenty:leaves_2:3)
Block(1,9,-1,LOG_2:1)
Block(1,7,-1,biomesoplenty:leaves_2:3)
Block(2,11,-4,biomesoplenty:leaves_2:3)
Block(1,5,-1,biomesoplenty:leaves_2:3)
Block(1,6,-1,biomesoplenty:leaves_2:3)
Block(1,3,-1,biomesoplenty:leaves_2:3)
Block(1,4,-1,LOG_2:1)
Block(3,10,1,biomesoplenty:leaves_2:3)
Block(3,13,1,biomesoplenty:leaves_2:3)
Block(3,11,1,biomesoplenty:leaves_2:3)
Block(3,12,1,biomesoplenty:leaves_2:3)
Block(3,5,3,biomesoplenty:leaves_2:3)
Block(-1,6,1,biomesoplenty:leaves_2:3)
Block(-1,7,1,biomesoplenty:leaves_2:3)
Block(3,7,3,biomesoplenty:leaves_2:3)
Block(3,6,3,LOG_2:1)
Block(-1,5,-4,biomesoplenty:leaves_2:3)
Block(4,6,1,biomesoplenty:leaves_2:3)
Block(2,4,-2,biomesoplenty:leaves_2:3)
Block(1,12,3,biomesoplenty:leaves_2:3)
Block(1,11,3,biomesoplenty:leaves_2:3)
Block(0,12,4,biomesoplenty:leaves_2:3)
Block(2,6,-2,biomesoplenty:leaves_2:3)
Block(2,5,-2,biomesoplenty:leaves_2:3)
Block(2,9,-2,biomesoplenty:leaves_2:3)
Block(0,6,-4,biomesoplenty:leaves_2:3)
Block(0,5,-4,biomesoplenty:leaves_2:3)
Block(1,9,0,LOG_2:1)
Block(1,8,0,LOG_2:1)
Block(1,7,0,LOG_2:1)
Block(2,12,-2,biomesoplenty:leaves_2:3)
Block(2,13,-2,biomesoplenty:leaves_2:3)
Block(0,14,1,biomesoplenty:leaves_2:3)
Block(1,10,-3,biomesoplenty:leaves_2:3)
Block(2,10,-2,LOG_2:1)
Block(0,13,1,biomesoplenty:leaves_2:3)
Block(1,11,-3,biomesoplenty:leaves_2:3)
Block(2,11,-2,biomesoplenty:leaves_2:3)
Block(0,12,1,biomesoplenty:leaves_2:3)
Block(1,12,-3,biomesoplenty:leaves_2:3)
Block(1,12,4,biomesoplenty:leaves_2:3)
Block(1,13,-3,biomesoplenty:leaves_2:3)
Block(-3,7,0,biomesoplenty:leaves_2:3)
Block(0,12,-4,biomesoplenty:leaves_2:3)
Block(-3,6,0,biomesoplenty:leaves_2:3)
Block(-3,8,0,biomesoplenty:leaves_2:3)
Block(0,11,1,biomesoplenty:leaves_2:3)
Block(0,10,1,biomesoplenty:leaves_2:3)
Block(3,7,4,biomesoplenty:leaves_2:3)
Block(3,6,4,biomesoplenty:leaves_2:3)
Block(3,5,4,biomesoplenty:leaves_2:3)
Block(-2,7,2,biomesoplenty:leaves_2:3)
Block(4,5,2,biomesoplenty:leaves_2:3)
Block(-1,11,-2,biomesoplenty:leaves_2:3)
Block(4,7,2,biomesoplenty:leaves_2:3)
Block(4,6,2,biomesoplenty:leaves_2:3)
Block(2,6,-3,biomesoplenty:leaves_2:3)
Block(2,5,-3,biomesoplenty:leaves_2:3)
Block(2,4,-3,biomesoplenty:leaves_2:3)
Block(2,9,-3,biomesoplenty:leaves_2:3)
Block(0,5,-5,biomesoplenty:leaves_2:3)
Block(0,6,1,biomesoplenty:leaves_2:3)
Block(1,7,1,biomesoplenty:leaves_2:3)
Block(0,5,1,biomesoplenty:leaves_2:3)
Block(1,6,1,biomesoplenty:leaves_2:3)
Block(3,10,-2,biomesoplenty:leaves_2:3)
Block(3,11,-2,biomesoplenty:leaves_2:3)
Block(3,12,-2,biomesoplenty:leaves_2:3)
Block(-2,12,-1,biomesoplenty:leaves_2:3)
Block(-2,13,-1,biomesoplenty:leaves_2:3)
Block(-1,10,-1,biomesoplenty:leaves_2:3)
Block(-2,11,-1,biomesoplenty:leaves_2:3)
Block(2,11,1,biomesoplenty:leaves_2:3)
Block(2,10,1,biomesoplenty:leaves_2:3)
Block(-3,12,0,biomesoplenty:leaves_2:3)
Block(2,13,1,biomesoplenty:leaves_2:3)
Block(2,12,1,biomesoplenty:leaves_2:3)
Block(3,6,5,biomesoplenty:leaves_2:3)
Block(-2,8,1,biomesoplenty:leaves_2:3)
Block(-2,7,1,biomesoplenty:leaves_2:3)
Block(-2,6,1,biomesoplenty:leaves_2:3)
Block(-1,11,-1,biomesoplenty:leaves_2:3)
Block(4,11,2,biomesoplenty:leaves_2:3)
Block(-1,12,-1,biomesoplenty:leaves_2:3)
Block(-2,12,1,biomesoplenty:leaves_2:3)
Block(-1,13,-1,biomesoplenty:leaves_2:3)
Block(-2,11,1,biomesoplenty:leaves_2:3)
Block(0,14,0,biomesoplenty:leaves_2:3)
Block(0,13,0,biomesoplenty:leaves_2:3)
Block(2,11,-3,biomesoplenty:leaves_2:3)
Block(0,12,0,biomesoplenty:leaves_2:3)
Block(0,11,0,biomesoplenty:leaves_2:3)
Block(2,12,-3,biomesoplenty:leaves_2:3)
Block(4,6,3,biomesoplenty:leaves_2:3)
Block(4,5,3,biomesoplenty:leaves_2:3)
Block(2,10,-3,biomesoplenty:leaves_2:3)
Block(4,7,3,biomesoplenty:leaves_2:3)
Block(1,6,0,LOG_2:1)
Block(2,5,-4,biomesoplenty:leaves_2:3)
Block(1,5,0,LOG_2:1)
Block(0,6,2,biomesoplenty:leaves_2:3)
Block(2,4,-4,biomesoplenty:leaves_2:3)
Block(1,4,0,LOG_2:1)
Block(1,3,0,LOG_2:1)
Block(1,2,0,LOG_2:1)
Block(0,10,0,LOG_2:1)
Block(3,11,0,biomesoplenty:leaves_2:3)
Block(1,1,0,LOG_2:1)
Block(3,10,0,LOG_2:1)
Block(1,0,0,LOG_2:1)
Block(3,13,0,biomesoplenty:leaves_2:3)
Block(3,12,0,biomesoplenty:leaves_2:3)
Block(0,4,-2,biomesoplenty:leaves_2:3)
Block(2,10,0,biomesoplenty:leaves_2:3)
Block(0,6,-2,biomesoplenty:leaves_2:3)
Block(3,9,-1,biomesoplenty:leaves_2:3)
Block(2,11,0,biomesoplenty:leaves_2:3)
Block(0,5,-2,biomesoplenty:leaves_2:3)
Block(2,12,0,biomesoplenty:leaves_2:3)
Block(0,7,-2,biomesoplenty:leaves_2:3)
Block(1,7,2,biomesoplenty:leaves_2:3)
Block(1,6,2,biomesoplenty:leaves_2:3)
Block(1,5,2,biomesoplenty:leaves_2:3)
Block(-4,8,0,biomesoplenty:leaves_2:3)
Block(2,13,0,biomesoplenty:leaves_2:3)
Block(-4,7,0,biomesoplenty:leaves_2:3)
Block(2,14,0,biomesoplenty:leaves_2:3)
Block(3,5,-1,biomesoplenty:leaves_2:3)
Block(-4,6,0,biomesoplenty:leaves_2:3)
Block(-1,12,-3,biomesoplenty:leaves_2:3)
Block(-1,11,-3,biomesoplenty:leaves_2:3)
Block(2,7,0,biomesoplenty:leaves_2:3)
Block(2,6,0,biomesoplenty:leaves_2:3)
Block(2,9,0,LOG_2:1)
Block(-3,7,2,biomesoplenty:leaves_2:3)
Block(-2,8,-1,biomesoplenty:leaves_2:3)
Block(-2,7,-1,biomesoplenty:leaves_2:3)
Block(-2,6,-1,biomesoplenty:leaves_2:3)
Block(-1,7,-1,biomesoplenty:leaves_2:3)
Block(-1,6,-1,biomesoplenty:leaves_2:3)
Block(5,11,-1,biomesoplenty:leaves_2:3)
Block(5,12,-1,biomesoplenty:leaves_2:3)
Block(1,14,0,biomesoplenty:leaves_2:3)
Block(1,13,0,LOG_2:1)
Block(1,12,0,LOG_2:1)
Block(1,11,0,LOG_2:1)
Block(1,10,0,LOG_2:1)
Block(2,13,-1,biomesoplenty:leaves_2:3)
Block(-2,12,3,biomesoplenty:leaves_2:3)
Block(2,10,-1,biomesoplenty:leaves_2:3)
Block(2,12,-1,biomesoplenty:leaves_2:3)
Block(2,11,-1,biomesoplenty:leaves_2:3)
Block(0,13,2,biomesoplenty:leaves_2:3)
Block(4,6,4,biomesoplenty:leaves_2:3)
Block(2,5,-5,biomesoplenty:leaves_2:3)
Block(1,5,1,biomesoplenty:leaves_2:3)
Block(0,11,-3,biomesoplenty:leaves_2:3)
Block(1,4,1,biomesoplenty:leaves_2:3)
Block(0,10,2,biomesoplenty:leaves_2:3)
Block(0,12,-3,biomesoplenty:leaves_2:3)
Block(5,6,2,biomesoplenty:leaves_2:3)
Block(0,11,2,biomesoplenty:leaves_2:3)
Block(-3,12,-1,biomesoplenty:leaves_2:3)
Block(0,12,2,biomesoplenty:leaves_2:3)
Block(0,13,-3,biomesoplenty:leaves_2:3)
Block(-3,12,1,biomesoplenty:leaves_2:3)
Block(0,5,-3,biomesoplenty:leaves_2:3)
Block(0,4,-3,biomesoplenty:leaves_2:3)
Block(0,6,-3,biomesoplenty:leaves_2:3)
Block(1,6,3,biomesoplenty:leaves_2:3)
Block(4,10,-1,biomesoplenty:leaves_2:3)
Block(-1,12,-2,LOG_2:1)
Block(-2,12,2,biomesoplenty:leaves_2:3)
Block(-1,13,-2,biomesoplenty:leaves_2:3)
Block(-2,11,2,biomesoplenty:leaves_2:3)
Block(2,9,1,biomesoplenty:leaves_2:3)
Block(1,5,-5,biomesoplenty:leaves_2:3)
Block(2,6,1,LOG_2:1)
Block(2,5,1,biomesoplenty:leaves_2:3)
Block(2,7,1,biomesoplenty:leaves_2:3)
Block(-3,6,1,biomesoplenty:leaves_2:3)
Block(-1,11,3,biomesoplenty:leaves_2:3)
Block(4,13,-1,biomesoplenty:leaves_2:3)
Block(-3,8,1,biomesoplenty:leaves_2:3)
Block(0,11,-2,biomesoplenty:leaves_2:3)
Block(4,11,-1,biomesoplenty:leaves_2:3)
Block(-3,7,1,biomesoplenty:leaves_2:3)
Block(0,10,-2,biomesoplenty:leaves_2:3)
Block(4,12,-1,LOG_2:1)
Block(-1,12,3,biomesoplenty:leaves_2:3)
Block(-2,7,-2,biomesoplenty:leaves_2:3)
Block(0,13,-2,biomesoplenty:leaves_2:3)
Block(0,12,-2,biomesoplenty:leaves_2:3)
Block(0,14,-2,biomesoplenty:leaves_2:3)
Block(2,5,0,biomesoplenty:leaves_2:3)
Block(3,10,-1,biomesoplenty:leaves_2:3)
Block(2,4,0,biomesoplenty:leaves_2:3)
Block(3,11,-1,biomesoplenty:leaves_2:3)
Block(-2,12,-2,biomesoplenty:leaves_2:3)
Block(1,10,-2,biomesoplenty:leaves_2:3)
Block(-2,11,-2,biomesoplenty:leaves_2:3)
Block(1,11,-2,biomesoplenty:leaves_2:3)
Block(3,12,-1,biomesoplenty:leaves_2:3)
Block(1,12,-2,LOG_2:1)
Block(3,13,-1,biomesoplenty:leaves_2:3)
Block(1,13,-2,biomesoplenty:leaves_2:3)
Block(5,6,3,biomesoplenty:leaves_2:3)

#######################################################################
# +-----------------------------------------------------------------+ #
# |                            BO3 checks                           | #
# +-----------------------------------------------------------------+ #
#######################################################################

BlockCheck(1,-1,0,GRASS,DIRT,DIRT:2)

#######################################################################
# +-----------------------------------------------------------------+ #
# |                             Branches                            | #
# +-----------------------------------------------------------------+ #
#######################################################################


#######################################################################
# +-----------------------------------------------------------------+ #
# |                             Entities                            | #
# +-----------------------------------------------------------------+ #
#######################################################################


#######################################################################
# +-----------------------------------------------------------------+ #
# |                            Particles                            | #
# +-----------------------------------------------------------------+ #
#######################################################################


#######################################################################
# +-----------------------------------------------------------------+ #
# |                             Spawners                            | #
# +-----------------------------------------------------------------+ #
#######################################################################


#######################################################################
# +-----------------------------------------------------------------+ #
# |                             ModData                             | #
# +-----------------------------------------------------------------+ #
#######################################################################

