
#######################################################################
# +-----------------------------------------------------------------+ #
# |                            BO3 object                           | #
# +-----------------------------------------------------------------+ #
#######################################################################

Author: LordSmellyPants

Description: No description given

Version: 3

SettingsMode: WriteWithoutComments


#######################################################################
# +-----------------------------------------------------------------+ #
# |                          Main settings                          | #
# +-----------------------------------------------------------------+ #
#######################################################################

Tree: true

Frequency: 1

Rarity: 25.0

RotateRandomly: true

SpawnHeight: highestSolidBlock

SpawnHeightOffset: 0

SpawnHeightVariance: 0

##############################
# Height Limits for the BO3. #
##############################

MinHeight: 61

MaxHeight: 111

######################
# Extrusion settings #
######################

ExtrudeMode: None

ExtrudeThroughBlocks: AIR

MaxBranchDepth: 10

ExcludedBiomes: All


#######################################################################
# +-----------------------------------------------------------------+ #
# |                      Source block settings                      | #
# +-----------------------------------------------------------------+ #
#######################################################################

SourceBlocks: STONE:1,STONE:3,STONE:5,DIRT:1,DIRT,SAND,GRASS,DIRT:2,STATIONARY_WATER,HARD_CLAY,STAINED_CLAY,CLAY,SANDSTONE,SAND:1,AIR,STONE,GRAVEL,LONG_GRASS,LONG_GRASS:1,LONG_GRASS:2,DEAD_BUSH,YELLOW_FLOWER,RED_ROSE,BROWN_MUSHROOM,RED_MUSHROOM,biomesoplenty:plant_0:1,biomesoplenty:plant_0:2,biomesoplenty:plant_0:3,biomesoplenty:plant_0:4,biomesoplenty:plant_0:5,biomesoplenty:plant_0:6,biomesoplenty:plant_0:7,biomesoplenty:plant_0:8,biomesoplenty:plant_0:9,biomesoplenty:plant_0:10,biomesoplenty:plant_0:11,biomesoplenty:plant_0:12,biomesoplenty:plant_0:13,biomesoplenty:plant_0:14,biomesoplenty:flower_0:1,biomesoplenty:flower_0:2,biomesoplenty:flower_0:3,biomesoplenty:flower_0:4,biomesoplenty:flower_0:5,biomesoplenty:flower_0:6,biomesoplenty:flower_0:7,biomesoplenty:flower_0:8,biomesoplenty:flower_0:9,biomesoplenty:flower_0:10,biomesoplenty:flower_0:11,biomesoplenty:flower_0:12,biomesoplenty:flower_0:13,biomesoplenty:flower_0:14,biomesoplenty:plant_1,biomesoplenty:grass:0,biomesoplenty:grass:1,biomesoplenty:grass,biomesoplenty:grass:3,biomesoplenty:grass:4,biomesoplenty:grass:5,biomesoplenty:grass:6,biomesoplenty:grass:7,biomesoplenty:dirt,biomesoplenty:dirt:1,biomesoplenty:dirt:2,biomesoplenty:dirt:8,biomesoplenty:dirt:9,biomesoplenty:dirt:10,biomesoplenty:dried_sand,biomesoplenty:hard_ice,biomesoplenty:white_sand,biomesoplenty:white_sandstone,biomesoplenty:mud,biomesoplenty:ash_block

MaxPercentageOutsideSourceBlock: 0

OutsideSourceBlock: placeAnyway

DoReplaceBlocks: true

IsOTGPlus: false


#######################################################################
# +-----------------------------------------------------------------+ #
# |                              Blocks                             | #
# +-----------------------------------------------------------------+ #
#######################################################################

Block(-7,7,1,biomesoplenty:leaves_2:2)
Block(-7,8,2,biomesoplenty:leaves_2:2)
Block(-7,9,4,biomesoplenty:leaves_2:2)
Block(-7,9,5,biomesoplenty:leaves_2:2)
Block(-7,10,2,biomesoplenty:leaves_2:2)
Block(-7,10,3,biomesoplenty:leaves_2:2)
Block(-7,10,4,biomesoplenty:leaves_2:2)
Block(-7,11,3,biomesoplenty:leaves_2:2)
Block(-6,7,-4,biomesoplenty:leaves_2:2)
Block(-6,7,0,biomesoplenty:leaves_2:2)
Block(-6,7,1,biomesoplenty:leaves_2:2)
Block(-6,7,2,biomesoplenty:leaves_2:2)
Block(-6,7,3,biomesoplenty:leaves_2:2)
Block(-6,8,-5,biomesoplenty:leaves_2:2)
Block(-6,8,1,biomesoplenty:leaves_2:2)
Block(-6,8,2,biomesoplenty:leaves_2:2)
Block(-6,8,3,biomesoplenty:leaves_2:2)
Block(-6,8,4,biomesoplenty:leaves_2:2)
Block(-6,9,-2,biomesoplenty:leaves_2:2)
Block(-6,9,0,biomesoplenty:leaves_2:2)
Block(-6,9,2,biomesoplenty:leaves_2:2)
Block(-6,9,3,biomesoplenty:leaves_2:2)
Block(-6,9,4,biomesoplenty:leaves_2:2)
Block(-6,10,-7,biomesoplenty:leaves_2:2)
Block(-6,10,-5,biomesoplenty:leaves_2:2)
Block(-6,10,-4,biomesoplenty:leaves_2:2)
Block(-6,10,-2,biomesoplenty:leaves_2:2)
Block(-6,10,0,biomesoplenty:leaves_2:2)
Block(-6,10,1,biomesoplenty:leaves_2:2)
Block(-6,10,3,biomesoplenty:leaves_2:2)
Block(-6,10,4,biomesoplenty:leaves_2:2)
Block(-6,11,-5,biomesoplenty:leaves_2:2)
Block(-6,11,-2,biomesoplenty:leaves_2:2)
Block(-6,11,0,biomesoplenty:leaves_2:2)
Block(-6,11,3,biomesoplenty:leaves_2:2)
Block(-6,11,4,biomesoplenty:leaves_2:2)
Block(-5,7,-5,biomesoplenty:leaves_2:2)
Block(-5,7,-4,biomesoplenty:leaves_2:2)
Block(-5,7,1,biomesoplenty:leaves_2:2)
Block(-5,8,-6,biomesoplenty:leaves_2:2)
Block(-5,8,-5,biomesoplenty:leaves_2:2)
Block(-5,8,-4,biomesoplenty:leaves_2:2)
Block(-5,8,-1,biomesoplenty:leaves_2:2)
Block(-5,8,1,biomesoplenty:leaves_2:2)
Block(-5,8,2,biomesoplenty:log_0:5)
Block(-5,8,4,biomesoplenty:leaves_2:2)
Block(-5,9,-7,biomesoplenty:leaves_2:2)
Block(-5,9,-5,biomesoplenty:leaves_2:2)
Block(-5,9,-4,biomesoplenty:leaves_2:2)
Block(-5,9,-3,biomesoplenty:leaves_2:2)
Block(-5,9,-1,biomesoplenty:leaves_2:2)
Block(-5,9,1,biomesoplenty:leaves_2:2)
Block(-5,9,2,biomesoplenty:log_0:5)
Block(-5,9,3,biomesoplenty:log_0:5)
Block(-5,9,4,biomesoplenty:leaves_2:2)
Block(-5,9,5,biomesoplenty:leaves_2:2)
Block(-5,10,-8,biomesoplenty:leaves_2:2)
Block(-5,10,-7,biomesoplenty:leaves_2:2)
Block(-5,10,-5,biomesoplenty:leaves_2:2)
Block(-5,10,-4,biomesoplenty:leaves_2:2)
Block(-5,10,-2,biomesoplenty:leaves_2:2)
Block(-5,10,-1,biomesoplenty:leaves_2:2)
Block(-5,10,0,biomesoplenty:leaves_2:2)
Block(-5,10,2,biomesoplenty:leaves_2:2)
Block(-5,10,3,biomesoplenty:log_0:5)
Block(-5,10,4,biomesoplenty:leaves_2:2)
Block(-5,10,5,biomesoplenty:leaves_2:2)
Block(-5,11,-6,biomesoplenty:leaves_2:2)
Block(-5,11,-5,biomesoplenty:leaves_2:2)
Block(-5,11,-4,biomesoplenty:leaves_2:2)
Block(-5,11,-3,biomesoplenty:leaves_2:2)
Block(-5,11,-2,biomesoplenty:leaves_2:2)
Block(-5,11,0,biomesoplenty:leaves_2:2)
Block(-5,11,1,biomesoplenty:leaves_2:2)
Block(-5,11,2,biomesoplenty:leaves_2:2)
Block(-5,11,3,biomesoplenty:leaves_2:2)
Block(-5,12,-5,biomesoplenty:leaves_2:2)
Block(-5,12,3,biomesoplenty:leaves_2:2)
Block(-5,12,4,biomesoplenty:leaves_2:2)
Block(-5,13,-5,biomesoplenty:leaves_2:2)
Block(-4,6,-4,biomesoplenty:leaves_2:2)
Block(-4,6,1,biomesoplenty:log_0:5)
Block(-4,7,-5,biomesoplenty:leaves_2:2)
Block(-4,7,-4,biomesoplenty:leaves_2:2)
Block(-4,7,1,biomesoplenty:log_0:5)
Block(-4,7,3,biomesoplenty:leaves_2:2)
Block(-4,8,-6,biomesoplenty:leaves_2:2)
Block(-4,8,-4,biomesoplenty:log_0:5)
Block(-4,8,-2,biomesoplenty:leaves_2:2)
Block(-4,8,-1,biomesoplenty:leaves_2:2)
Block(-4,8,1,biomesoplenty:log_0:5)
Block(-4,8,2,biomesoplenty:log_0:5)
Block(-4,8,3,biomesoplenty:leaves_2:2)
Block(-4,8,4,biomesoplenty:leaves_2:2)
Block(-4,8,5,biomesoplenty:leaves_2:2)
Block(-4,9,-7,biomesoplenty:leaves_2:2)
Block(-4,9,-6,biomesoplenty:log_0:5)
Block(-4,9,-5,biomesoplenty:log_0:5)
Block(-4,9,-4,biomesoplenty:log_0:5)
Block(-4,9,-2,biomesoplenty:leaves_2:2)
Block(-4,9,-1,biomesoplenty:leaves_2:2)
Block(-4,9,0,biomesoplenty:leaves_2:2)
Block(-4,9,1,biomesoplenty:leaves_2:2)
Block(-4,9,2,biomesoplenty:leaves_2:2)
Block(-4,9,3,biomesoplenty:leaves_2:2)
Block(-4,9,4,biomesoplenty:leaves_2:2)
Block(-4,9,5,biomesoplenty:leaves_2:2)
Block(-4,9,6,biomesoplenty:leaves_2:2)
Block(-4,10,-7,biomesoplenty:leaves_2:2)
Block(-4,10,-6,biomesoplenty:log_0:5)
Block(-4,10,-4,biomesoplenty:leaves_2:2)
Block(-4,10,-1,biomesoplenty:leaves_2:2)
Block(-4,10,0,biomesoplenty:leaves_2:2)
Block(-4,10,1,biomesoplenty:leaves_2:2)
Block(-4,10,2,biomesoplenty:leaves_2:2)
Block(-4,10,4,biomesoplenty:leaves_2:2)
Block(-4,10,5,biomesoplenty:leaves_2:2)
Block(-4,10,6,biomesoplenty:leaves_2:2)
Block(-4,11,-8,biomesoplenty:leaves_2:2)
Block(-4,11,-6,biomesoplenty:leaves_2:2)
Block(-4,11,-5,biomesoplenty:leaves_2:2)
Block(-4,11,-4,biomesoplenty:leaves_2:2)
Block(-4,11,-3,biomesoplenty:leaves_2:2)
Block(-4,11,-2,biomesoplenty:leaves_2:2)
Block(-4,11,-1,biomesoplenty:leaves_2:2)
Block(-4,11,0,biomesoplenty:leaves_2:2)
Block(-4,11,1,biomesoplenty:leaves_2:2)
Block(-4,11,2,biomesoplenty:leaves_2:2)
Block(-4,11,3,biomesoplenty:leaves_2:2)
Block(-4,11,4,biomesoplenty:leaves_2:2)
Block(-4,11,5,biomesoplenty:leaves_2:2)
Block(-4,12,-7,biomesoplenty:leaves_2:2)
Block(-4,12,-5,biomesoplenty:leaves_2:2)
Block(-4,12,-4,biomesoplenty:leaves_2:2)
Block(-4,12,-3,biomesoplenty:leaves_2:2)
Block(-4,12,-2,biomesoplenty:leaves_2:2)
Block(-4,12,0,biomesoplenty:leaves_2:2)
Block(-4,12,2,biomesoplenty:leaves_2:2)
Block(-4,12,3,biomesoplenty:leaves_2:2)
Block(-4,13,-6,biomesoplenty:leaves_2:2)
Block(-4,13,-5,biomesoplenty:leaves_2:2)
Block(-4,13,-4,biomesoplenty:leaves_2:2)
Block(-4,14,-5,biomesoplenty:leaves_2:2)
Block(-3,5,0,biomesoplenty:log_0:5)
Block(-3,5,1,biomesoplenty:log_0:5)
Block(-3,6,1,biomesoplenty:log_0:5)
Block(-3,7,-4,biomesoplenty:log_0:5)
Block(-3,7,-3,biomesoplenty:log_0:5)
Block(-3,7,0,biomesoplenty:leaves_2:2)
Block(-3,7,2,biomesoplenty:leaves_2:2)
Block(-3,7,4,biomesoplenty:leaves_2:2)
Block(-3,8,-5,biomesoplenty:leaves_2:2)
Block(-3,8,-4,biomesoplenty:log_0:5)
Block(-3,8,-3,biomesoplenty:leaves_2:2)
Block(-3,8,0,biomesoplenty:leaves_2:2)
Block(-3,8,1,biomesoplenty:leaves_2:2)
Block(-3,8,2,biomesoplenty:leaves_2:2)
Block(-3,8,3,biomesoplenty:leaves_2:2)
Block(-3,8,4,biomesoplenty:leaves_2:2)
Block(-3,9,-6,biomesoplenty:leaves_2:2)
Block(-3,9,-5,biomesoplenty:log_0:5)
Block(-3,9,-3,biomesoplenty:leaves_2:2)
Block(-3,9,0,biomesoplenty:leaves_2:2)
Block(-3,9,1,biomesoplenty:leaves_2:2)
Block(-3,9,2,biomesoplenty:leaves_2:2)
Block(-3,9,3,biomesoplenty:leaves_2:2)
Block(-3,9,4,biomesoplenty:leaves_2:2)
Block(-3,9,5,biomesoplenty:leaves_2:2)
Block(-3,10,-8,biomesoplenty:leaves_2:2)
Block(-3,10,-7,biomesoplenty:leaves_2:2)
Block(-3,10,-6,biomesoplenty:leaves_2:2)
Block(-3,10,-5,biomesoplenty:leaves_2:2)
Block(-3,10,-4,biomesoplenty:leaves_2:2)
Block(-3,10,-2,biomesoplenty:leaves_2:2)
Block(-3,10,-1,biomesoplenty:leaves_2:2)
Block(-3,10,0,biomesoplenty:leaves_2:2)
Block(-3,10,1,biomesoplenty:leaves_2:2)
Block(-3,10,2,biomesoplenty:leaves_2:2)
Block(-3,10,3,biomesoplenty:leaves_2:2)
Block(-3,10,4,biomesoplenty:leaves_2:2)
Block(-3,10,5,biomesoplenty:leaves_2:2)
Block(-3,11,-9,biomesoplenty:leaves_2:2)
Block(-3,11,-8,biomesoplenty:leaves_2:2)
Block(-3,11,-7,biomesoplenty:leaves_2:2)
Block(-3,11,-6,biomesoplenty:leaves_2:2)
Block(-3,11,-5,biomesoplenty:leaves_2:2)
Block(-3,11,-3,biomesoplenty:leaves_2:2)
Block(-3,11,-2,biomesoplenty:leaves_2:2)
Block(-3,11,-1,biomesoplenty:leaves_2:2)
Block(-3,11,0,biomesoplenty:leaves_2:2)
Block(-3,11,1,biomesoplenty:leaves_2:2)
Block(-3,11,3,biomesoplenty:leaves_2:2)
Block(-3,11,4,biomesoplenty:leaves_2:2)
Block(-3,11,5,biomesoplenty:leaves_2:2)
Block(-3,12,-8,biomesoplenty:leaves_2:2)
Block(-3,12,-7,biomesoplenty:leaves_2:2)
Block(-3,12,-6,biomesoplenty:leaves_2:2)
Block(-3,12,-5,biomesoplenty:leaves_2:2)
Block(-3,12,-4,biomesoplenty:leaves_2:2)
Block(-3,12,-3,biomesoplenty:leaves_2:2)
Block(-3,12,-2,biomesoplenty:leaves_2:2)
Block(-3,12,-1,biomesoplenty:leaves_2:2)
Block(-3,12,0,biomesoplenty:leaves_2:2)
Block(-3,12,1,biomesoplenty:leaves_2:2)
Block(-3,12,2,biomesoplenty:leaves_2:2)
Block(-3,12,4,biomesoplenty:leaves_2:2)
Block(-3,13,-6,biomesoplenty:leaves_2:2)
Block(-3,13,-5,biomesoplenty:leaves_2:2)
Block(-3,13,-4,biomesoplenty:leaves_2:2)
Block(-3,13,-3,biomesoplenty:leaves_2:2)
Block(-3,13,-1,biomesoplenty:leaves_2:2)
Block(-3,13,0,biomesoplenty:leaves_2:2)
Block(-3,14,-5,biomesoplenty:leaves_2:2)
Block(-3,14,-4,biomesoplenty:leaves_2:2)
Block(-2,4,-1,biomesoplenty:log_0:5)
Block(-2,4,0,biomesoplenty:log_0:5)
Block(-2,5,0,biomesoplenty:log_0:5)
Block(-2,6,-3,biomesoplenty:log_0:5)
Block(-2,7,-3,biomesoplenty:log_0:5)
Block(-2,7,0,biomesoplenty:leaves_2:2)
Block(-2,7,1,biomesoplenty:leaves_2:2)
Block(-2,8,-4,biomesoplenty:leaves_2:2)
Block(-2,8,0,biomesoplenty:leaves_2:2)
Block(-2,8,2,biomesoplenty:leaves_2:2)
Block(-2,8,3,biomesoplenty:leaves_2:2)
Block(-2,9,-6,biomesoplenty:leaves_2:2)
Block(-2,9,-5,biomesoplenty:leaves_2:2)
Block(-2,9,-1,biomesoplenty:leaves_2:2)
Block(-2,9,0,biomesoplenty:leaves_2:2)
Block(-2,9,1,biomesoplenty:leaves_2:2)
Block(-2,9,2,biomesoplenty:leaves_2:2)
Block(-2,9,3,biomesoplenty:leaves_2:2)
Block(-2,9,4,biomesoplenty:leaves_2:2)
Block(-2,10,-7,biomesoplenty:leaves_2:2)
Block(-2,10,-6,biomesoplenty:leaves_2:2)
Block(-2,10,-5,biomesoplenty:log_0:5)
Block(-2,10,-4,biomesoplenty:leaves_2:2)
Block(-2,10,0,biomesoplenty:leaves_2:2)
Block(-2,10,2,biomesoplenty:leaves_2:2)
Block(-2,10,3,biomesoplenty:leaves_2:2)
Block(-2,10,4,biomesoplenty:leaves_2:2)
Block(-2,10,5,biomesoplenty:leaves_2:2)
Block(-2,11,-8,biomesoplenty:leaves_2:2)
Block(-2,11,-6,biomesoplenty:leaves_2:2)
Block(-2,11,-5,biomesoplenty:log_0:5)
Block(-2,11,-4,biomesoplenty:log_0:5)
Block(-2,11,-3,biomesoplenty:leaves_2:2)
Block(-2,11,-2,biomesoplenty:leaves_2:2)
Block(-2,11,-1,biomesoplenty:leaves_2:2)
Block(-2,11,0,biomesoplenty:leaves_2:2)
Block(-2,11,1,biomesoplenty:leaves_2:2)
Block(-2,11,3,biomesoplenty:leaves_2:2)
Block(-2,11,5,biomesoplenty:leaves_2:2)
Block(-2,12,-7,biomesoplenty:leaves_2:2)
Block(-2,12,-6,biomesoplenty:leaves_2:2)
Block(-2,12,-5,biomesoplenty:leaves_2:2)
Block(-2,12,-4,biomesoplenty:log_0:5)
Block(-2,12,-3,biomesoplenty:leaves_2:2)
Block(-2,12,-2,biomesoplenty:leaves_2:2)
Block(-2,12,-1,biomesoplenty:leaves_2:2)
Block(-2,12,0,biomesoplenty:leaves_2:2)
Block(-2,12,1,biomesoplenty:leaves_2:2)
Block(-2,12,3,biomesoplenty:leaves_2:2)
Block(-2,13,-7,biomesoplenty:leaves_2:2)
Block(-2,13,-6,biomesoplenty:leaves_2:2)
Block(-2,13,-5,biomesoplenty:leaves_2:2)
Block(-2,13,-4,biomesoplenty:log_0:5)
Block(-2,13,-3,biomesoplenty:log_0:5)
Block(-2,13,-2,biomesoplenty:leaves_2:2)
Block(-2,13,-1,biomesoplenty:leaves_2:2)
Block(-2,13,0,biomesoplenty:leaves_2:2)
Block(-2,13,1,biomesoplenty:leaves_2:2)
Block(-2,14,-6,biomesoplenty:leaves_2:2)
Block(-2,14,-5,biomesoplenty:leaves_2:2)
Block(-2,14,-4,biomesoplenty:leaves_2:2)
Block(-2,14,-3,biomesoplenty:leaves_2:2)
Block(-2,14,-2,biomesoplenty:leaves_2:2)
Block(-1,1,1,biomesoplenty:log_0:5)
Block(-1,2,0,biomesoplenty:log_0:5)
Block(-1,3,-2,biomesoplenty:log_0:5)
Block(-1,3,-1,biomesoplenty:log_0:5)
Block(-1,3,0,biomesoplenty:log_0:5)
Block(-1,4,-2,biomesoplenty:log_0:5)
Block(-1,4,-1,biomesoplenty:log_0:5)
Block(-1,5,-3,biomesoplenty:log_0:5)
Block(-1,5,-2,biomesoplenty:log_0:5)
Block(-1,6,-3,biomesoplenty:log_0:5)
Block(-1,9,-6,biomesoplenty:leaves_2:2)
Block(-1,9,-5,biomesoplenty:leaves_2:2)
Block(-1,9,-3,biomesoplenty:leaves_2:2)
Block(-1,9,2,biomesoplenty:leaves_2:2)
Block(-1,9,3,biomesoplenty:leaves_2:2)
Block(-1,10,-7,biomesoplenty:leaves_2:2)
Block(-1,10,-6,biomesoplenty:leaves_2:2)
Block(-1,10,-4,biomesoplenty:leaves_2:2)
Block(-1,10,-3,biomesoplenty:leaves_2:2)
Block(-1,10,-2,biomesoplenty:leaves_2:2)
Block(-1,10,0,biomesoplenty:leaves_2:2)
Block(-1,10,3,biomesoplenty:leaves_2:2)
Block(-1,11,-7,biomesoplenty:leaves_2:2)
Block(-1,11,-6,biomesoplenty:leaves_2:2)
Block(-1,11,-5,biomesoplenty:leaves_2:2)
Block(-1,11,-3,biomesoplenty:leaves_2:2)
Block(-1,11,-1,biomesoplenty:leaves_2:2)
Block(-1,11,0,biomesoplenty:leaves_2:2)
Block(-1,11,1,biomesoplenty:leaves_2:2)
Block(-1,11,2,biomesoplenty:leaves_2:2)
Block(-1,11,3,biomesoplenty:leaves_2:2)
Block(-1,11,5,biomesoplenty:leaves_2:2)
Block(-1,12,-6,biomesoplenty:leaves_2:2)
Block(-1,12,-5,biomesoplenty:leaves_2:2)
Block(-1,12,-4,biomesoplenty:leaves_2:2)
Block(-1,12,-3,biomesoplenty:leaves_2:2)
Block(-1,12,-2,biomesoplenty:leaves_2:2)
Block(-1,12,0,biomesoplenty:leaves_2:2)
Block(-1,12,1,biomesoplenty:leaves_2:2)
Block(-1,13,-6,biomesoplenty:leaves_2:2)
Block(-1,13,-5,biomesoplenty:leaves_2:2)
Block(-1,13,-3,biomesoplenty:leaves_2:2)
Block(-1,13,-2,biomesoplenty:leaves_2:2)
Block(-1,13,-1,biomesoplenty:leaves_2:2)
Block(-1,14,-4,biomesoplenty:leaves_2:2)
Block(-1,14,-3,biomesoplenty:leaves_2:2)
Block(0,-1,1,biomesoplenty:log_0:5)
Block(0,-1,2,biomesoplenty:log_0:5)
Block(0,0,0,biomesoplenty:log_0:5)
Block(0,0,1,biomesoplenty:log_0:5)
Block(0,1,-1,biomesoplenty:log_0:5)
Block(0,1,0,biomesoplenty:log_0:5)
Block(0,1,1,biomesoplenty:log_0:5)
Block(0,2,-1,biomesoplenty:log_0:5)
Block(0,2,0,biomesoplenty:log_0:5)
Block(0,2,1,biomesoplenty:log_0:5)
Block(0,3,-1,biomesoplenty:log_0:5)
Block(0,3,0,biomesoplenty:log_0:5)
Block(0,3,1,biomesoplenty:log_0:5)
Block(0,4,-2,biomesoplenty:log_0:5)
Block(0,4,1,biomesoplenty:log_0:5)
Block(0,10,-6,biomesoplenty:leaves_2:2)
Block(0,10,3,biomesoplenty:leaves_2:2)
Block(0,11,-6,biomesoplenty:leaves_2:2)
Block(0,11,-5,biomesoplenty:leaves_2:2)
Block(0,11,-4,biomesoplenty:leaves_2:2)
Block(0,11,-3,biomesoplenty:leaves_2:2)
Block(0,11,-1,biomesoplenty:leaves_2:2)
Block(0,11,0,biomesoplenty:leaves_2:2)
Block(0,11,1,biomesoplenty:leaves_2:2)
Block(0,11,2,biomesoplenty:leaves_2:2)
Block(0,12,-6,biomesoplenty:leaves_2:2)
Block(0,12,-5,biomesoplenty:leaves_2:2)
Block(0,12,-3,biomesoplenty:leaves_2:2)
Block(0,12,-2,biomesoplenty:leaves_2:2)
Block(0,12,0,biomesoplenty:leaves_2:2)
Block(0,12,2,biomesoplenty:leaves_2:2)
Block(0,13,-5,biomesoplenty:leaves_2:2)
Block(0,13,-3,biomesoplenty:leaves_2:2)
Block(0,14,-4,biomesoplenty:leaves_2:2)
Block(1,-1,1,biomesoplenty:log_0:5)
Block(1,-1,2,biomesoplenty:log_0:5)
Block(1,-1,3,biomesoplenty:log_0:5)
Block(1,0,0,biomesoplenty:log_0:5)
Block(1,0,1,biomesoplenty:log_0:5)
Block(1,0,2,biomesoplenty:log_0:5)
Block(1,1,-1,biomesoplenty:log_0:5)
Block(1,1,0,biomesoplenty:log_0:5)
Block(1,1,1,biomesoplenty:log_0:5)
Block(1,2,0,biomesoplenty:log_0:5)
Block(1,3,0,biomesoplenty:log_0:5)
Block(1,3,1,biomesoplenty:log_0:5)
Block(1,4,1,biomesoplenty:log_0:5)
Block(1,4,2,biomesoplenty:log_0:5)
Block(1,5,1,biomesoplenty:log_0:5)
Block(1,5,2,biomesoplenty:log_0:5)
Block(1,9,4,biomesoplenty:leaves_2:2)
Block(1,11,-7,biomesoplenty:leaves_2:2)
Block(1,11,-6,biomesoplenty:leaves_2:2)
Block(1,11,-5,biomesoplenty:leaves_2:2)
Block(1,11,0,biomesoplenty:leaves_2:2)
Block(1,11,5,biomesoplenty:leaves_2:2)
Block(1,12,-7,biomesoplenty:leaves_2:2)
Block(1,12,-6,biomesoplenty:leaves_2:2)
Block(1,12,-5,biomesoplenty:leaves_2:2)
Block(1,12,-3,biomesoplenty:leaves_2:2)
Block(1,12,-2,biomesoplenty:leaves_2:2)
Block(1,13,-6,biomesoplenty:leaves_2:2)
Block(1,13,-4,biomesoplenty:leaves_2:2)
Block(2,-1,1,biomesoplenty:log_0:5)
Block(2,-1,2,biomesoplenty:log_0:5)
Block(2,4,1,biomesoplenty:log_0:5)
Block(2,4,2,biomesoplenty:log_0:5)
Block(2,5,1,biomesoplenty:log_0:5)
Block(2,5,2,biomesoplenty:log_0:5)
Block(2,5,3,biomesoplenty:log_0:5)
Block(2,6,2,biomesoplenty:log_0:5)
Block(2,6,3,biomesoplenty:log_0:5)
Block(2,8,4,biomesoplenty:leaves_2:2)
Block(2,9,3,biomesoplenty:leaves_2:2)
Block(2,9,4,biomesoplenty:leaves_2:2)
Block(2,9,5,biomesoplenty:leaves_2:2)
Block(2,10,4,biomesoplenty:leaves_2:2)
Block(2,10,5,biomesoplenty:leaves_2:2)
Block(2,10,6,biomesoplenty:leaves_2:2)
Block(2,11,3,biomesoplenty:leaves_2:2)
Block(2,11,5,biomesoplenty:leaves_2:2)
Block(2,12,-6,biomesoplenty:leaves_2:2)
Block(2,12,-5,biomesoplenty:leaves_2:2)
Block(2,12,-4,biomesoplenty:leaves_2:2)
Block(2,13,-5,biomesoplenty:leaves_2:2)
Block(3,5,2,biomesoplenty:log_0:5)
Block(3,6,2,biomesoplenty:log_0:5)
Block(3,6,3,biomesoplenty:log_0:5)
Block(3,7,2,biomesoplenty:log_0:5)
Block(3,7,3,biomesoplenty:log_0:5)
Block(3,8,3,biomesoplenty:log_0:5)
Block(3,8,4,biomesoplenty:log_0:5)
Block(3,9,3,biomesoplenty:leaves_2:2)
Block(3,9,4,biomesoplenty:log_0:5)
Block(3,9,5,biomesoplenty:leaves_2:2)
Block(3,10,4,biomesoplenty:leaves_2:2)
Block(3,10,5,biomesoplenty:leaves_2:2)
Block(3,10,6,biomesoplenty:leaves_2:2)
Block(3,10,7,biomesoplenty:leaves_2:2)
Block(3,11,2,biomesoplenty:leaves_2:2)
Block(3,11,3,biomesoplenty:leaves_2:2)
Block(3,11,4,biomesoplenty:leaves_2:2)
Block(3,11,5,biomesoplenty:leaves_2:2)
Block(3,11,6,biomesoplenty:leaves_2:2)
Block(3,12,-5,biomesoplenty:leaves_2:2)
Block(3,12,3,biomesoplenty:leaves_2:2)
Block(3,12,4,biomesoplenty:leaves_2:2)
Block(4,5,1,biomesoplenty:log_0:5)
Block(4,5,2,biomesoplenty:log_0:5)
Block(4,6,0,biomesoplenty:log_0:5)
Block(4,6,1,biomesoplenty:log_0:5)
Block(4,7,2,biomesoplenty:log_0:5)
Block(4,8,2,biomesoplenty:log_0:5)
Block(4,8,3,biomesoplenty:leaves_2:2)
Block(4,9,4,biomesoplenty:log_0:5)
Block(4,9,6,biomesoplenty:leaves_2:2)
Block(4,10,2,biomesoplenty:leaves_2:2)
Block(4,10,4,biomesoplenty:log_0:5)
Block(4,10,5,biomesoplenty:log_0:5)
Block(4,10,6,biomesoplenty:leaves_2:2)
Block(4,11,0,biomesoplenty:leaves_2:2)
Block(4,11,1,biomesoplenty:leaves_2:2)
Block(4,11,2,biomesoplenty:leaves_2:2)
Block(4,11,3,biomesoplenty:leaves_2:2)
Block(4,11,4,biomesoplenty:leaves_2:2)
Block(4,11,5,biomesoplenty:leaves_2:2)
Block(4,11,6,biomesoplenty:leaves_2:2)
Block(4,12,-3,biomesoplenty:leaves_2:2)
Block(4,12,0,biomesoplenty:leaves_2:2)
Block(4,12,2,biomesoplenty:leaves_2:2)
Block(4,12,3,biomesoplenty:leaves_2:2)
Block(4,12,5,biomesoplenty:leaves_2:2)
Block(4,12,6,biomesoplenty:leaves_2:2)
Block(4,13,4,biomesoplenty:leaves_2:2)
Block(5,6,-1,biomesoplenty:log_0:5)
Block(5,6,0,biomesoplenty:log_0:5)
Block(5,7,-1,biomesoplenty:log_0:5)
Block(5,8,2,biomesoplenty:log_0:5)
Block(5,8,6,biomesoplenty:leaves_2:2)
Block(5,9,0,biomesoplenty:log_0:5)
Block(5,9,1,biomesoplenty:log_0:5)
Block(5,9,2,biomesoplenty:log_0:5)
Block(5,9,5,biomesoplenty:leaves_2:2)
Block(5,9,6,biomesoplenty:leaves_2:2)
Block(5,9,7,biomesoplenty:leaves_2:2)
Block(5,10,-4,biomesoplenty:leaves_2:2)
Block(5,10,0,biomesoplenty:log_0:5)
Block(5,10,3,biomesoplenty:leaves_2:2)
Block(5,10,5,biomesoplenty:log_0:5)
Block(5,10,6,biomesoplenty:leaves_2:2)
Block(5,11,-5,biomesoplenty:leaves_2:2)
Block(5,11,-1,biomesoplenty:leaves_2:2)
Block(5,11,0,biomesoplenty:leaves_2:2)
Block(5,11,1,biomesoplenty:leaves_2:2)
Block(5,11,2,biomesoplenty:leaves_2:2)
Block(5,11,3,biomesoplenty:leaves_2:2)
Block(5,11,5,biomesoplenty:log_0:5)
Block(5,11,7,biomesoplenty:leaves_2:2)
Block(5,12,-3,biomesoplenty:leaves_2:2)
Block(5,12,-2,biomesoplenty:leaves_2:2)
Block(5,12,0,biomesoplenty:leaves_2:2)
Block(5,12,1,biomesoplenty:leaves_2:2)
Block(5,12,3,biomesoplenty:leaves_2:2)
Block(5,12,4,biomesoplenty:leaves_2:2)
Block(5,12,6,biomesoplenty:leaves_2:2)
Block(5,13,-4,biomesoplenty:leaves_2:2)
Block(5,13,-2,biomesoplenty:leaves_2:2)
Block(5,13,-1,biomesoplenty:leaves_2:2)
Block(5,13,3,biomesoplenty:leaves_2:2)
Block(5,13,4,biomesoplenty:leaves_2:2)
Block(5,13,5,biomesoplenty:leaves_2:2)
Block(5,13,6,biomesoplenty:leaves_2:2)
Block(5,14,-3,biomesoplenty:leaves_2:2)
Block(5,14,-2,biomesoplenty:leaves_2:2)
Block(5,14,5,biomesoplenty:leaves_2:2)
Block(6,7,-2,biomesoplenty:log_0:5)
Block(6,7,-1,biomesoplenty:log_0:5)
Block(6,9,-3,biomesoplenty:leaves_2:2)
Block(6,9,2,biomesoplenty:leaves_2:2)
Block(6,9,5,biomesoplenty:leaves_2:2)
Block(6,10,-5,biomesoplenty:leaves_2:2)
Block(6,10,-4,biomesoplenty:leaves_2:2)
Block(6,10,-2,biomesoplenty:leaves_2:2)
Block(6,10,-1,biomesoplenty:log_0:5)
Block(6,10,0,biomesoplenty:log_0:5)
Block(6,10,4,biomesoplenty:leaves_2:2)
Block(6,10,6,biomesoplenty:leaves_2:2)
Block(6,10,7,biomesoplenty:leaves_2:2)
Block(6,10,8,biomesoplenty:leaves_2:2)
Block(6,11,-5,biomesoplenty:leaves_2:2)
Block(6,11,-4,biomesoplenty:leaves_2:2)
Block(6,11,-3,biomesoplenty:log_0:5)
Block(6,11,-2,biomesoplenty:log_0:5)
Block(6,11,-1,biomesoplenty:log_0:5)
Block(6,11,0,biomesoplenty:leaves_2:2)
Block(6,11,2,biomesoplenty:leaves_2:2)
Block(6,11,3,biomesoplenty:leaves_2:2)
Block(6,11,4,biomesoplenty:leaves_2:2)
Block(6,11,5,biomesoplenty:log_0:5)
Block(6,11,6,biomesoplenty:log_0:5)
Block(6,12,-5,biomesoplenty:leaves_2:2)
Block(6,12,-4,biomesoplenty:leaves_2:2)
Block(6,12,-3,biomesoplenty:leaves_2:2)
Block(6,12,-2,biomesoplenty:leaves_2:2)
Block(6,12,-1,biomesoplenty:leaves_2:2)
Block(6,12,0,biomesoplenty:leaves_2:2)
Block(6,12,1,biomesoplenty:leaves_2:2)
Block(6,12,2,biomesoplenty:leaves_2:2)
Block(6,12,3,biomesoplenty:leaves_2:2)
Block(6,12,4,biomesoplenty:leaves_2:2)
Block(6,12,5,biomesoplenty:leaves_2:2)
Block(6,12,6,biomesoplenty:leaves_2:2)
Block(6,13,-6,biomesoplenty:leaves_2:2)
Block(6,13,-5,biomesoplenty:leaves_2:2)
Block(6,13,-4,biomesoplenty:leaves_2:2)
Block(6,13,-3,biomesoplenty:leaves_2:2)
Block(6,13,-2,biomesoplenty:leaves_2:2)
Block(6,13,-1,biomesoplenty:leaves_2:2)
Block(6,13,0,biomesoplenty:leaves_2:2)
Block(6,13,2,biomesoplenty:leaves_2:2)
Block(6,13,4,biomesoplenty:leaves_2:2)
Block(6,13,5,biomesoplenty:leaves_2:2)
Block(6,14,-1,biomesoplenty:leaves_2:2)
Block(6,14,3,biomesoplenty:leaves_2:2)
Block(6,14,4,biomesoplenty:leaves_2:2)
Block(7,7,-2,biomesoplenty:log_0:5)
Block(7,8,-3,biomesoplenty:leaves_2:2)
Block(7,8,-2,biomesoplenty:log_0:5)
Block(7,8,-1,biomesoplenty:leaves_2:2)
Block(7,8,0,biomesoplenty:leaves_2:2)
Block(7,9,7,biomesoplenty:leaves_2:2)
Block(7,10,-3,biomesoplenty:leaves_2:2)
Block(7,10,-1,biomesoplenty:leaves_2:2)
Block(7,10,0,biomesoplenty:leaves_2:2)
Block(7,10,1,biomesoplenty:leaves_2:2)
Block(7,10,2,biomesoplenty:leaves_2:2)
Block(7,10,4,biomesoplenty:leaves_2:2)
Block(7,10,5,biomesoplenty:leaves_2:2)
Block(7,10,7,biomesoplenty:leaves_2:2)
Block(7,11,-6,biomesoplenty:leaves_2:2)
Block(7,11,-5,biomesoplenty:leaves_2:2)
Block(7,11,-4,biomesoplenty:leaves_2:2)
Block(7,11,-3,biomesoplenty:leaves_2:2)
Block(7,11,-2,biomesoplenty:leaves_2:2)
Block(7,11,-1,biomesoplenty:leaves_2:2)
Block(7,11,0,biomesoplenty:leaves_2:2)
Block(7,11,2,biomesoplenty:leaves_2:2)
Block(7,11,4,biomesoplenty:leaves_2:2)
Block(7,11,5,biomesoplenty:leaves_2:2)
Block(7,11,6,biomesoplenty:log_0:5)
Block(7,11,8,biomesoplenty:leaves_2:2)
Block(7,12,-5,biomesoplenty:leaves_2:2)
Block(7,12,-4,biomesoplenty:leaves_2:2)
Block(7,12,-3,biomesoplenty:leaves_2:2)
Block(7,12,-2,biomesoplenty:leaves_2:2)
Block(7,12,-1,biomesoplenty:leaves_2:2)
Block(7,12,0,biomesoplenty:leaves_2:2)
Block(7,12,1,biomesoplenty:leaves_2:2)
Block(7,12,2,biomesoplenty:leaves_2:2)
Block(7,12,4,biomesoplenty:leaves_2:2)
Block(7,12,5,biomesoplenty:leaves_2:2)
Block(7,12,7,biomesoplenty:leaves_2:2)
Block(7,13,-5,biomesoplenty:leaves_2:2)
Block(7,13,-4,biomesoplenty:leaves_2:2)
Block(7,13,-2,biomesoplenty:leaves_2:2)
Block(7,13,-1,biomesoplenty:leaves_2:2)
Block(7,13,0,biomesoplenty:leaves_2:2)
Block(7,13,1,biomesoplenty:leaves_2:2)
Block(7,13,3,biomesoplenty:leaves_2:2)
Block(7,13,4,biomesoplenty:leaves_2:2)
Block(7,13,5,biomesoplenty:leaves_2:2)
Block(7,13,6,biomesoplenty:leaves_2:2)
Block(7,14,-5,biomesoplenty:leaves_2:2)
Block(7,14,-2,biomesoplenty:leaves_2:2)
Block(7,14,2,biomesoplenty:leaves_2:2)
Block(7,14,4,biomesoplenty:leaves_2:2)
Block(7,14,5,biomesoplenty:leaves_2:2)
Block(7,14,6,biomesoplenty:leaves_2:2)
Block(7,15,3,biomesoplenty:leaves_2:2)
Block(8,6,-2,biomesoplenty:leaves_2:2)
Block(8,6,-1,biomesoplenty:leaves_2:2)
Block(8,7,-3,biomesoplenty:leaves_2:2)
Block(8,7,-2,biomesoplenty:leaves_2:2)
Block(8,7,-1,biomesoplenty:leaves_2:2)
Block(8,8,-4,biomesoplenty:leaves_2:2)
Block(8,8,-3,biomesoplenty:leaves_2:2)
Block(8,8,-2,biomesoplenty:log_0:5)
Block(8,8,0,biomesoplenty:leaves_2:2)
Block(8,8,1,biomesoplenty:leaves_2:2)
Block(8,9,-3,biomesoplenty:leaves_2:2)
Block(8,9,-2,biomesoplenty:leaves_2:2)
Block(8,9,1,biomesoplenty:leaves_2:2)
Block(8,10,-1,biomesoplenty:leaves_2:2)
Block(8,10,0,biomesoplenty:leaves_2:2)
Block(8,10,1,biomesoplenty:leaves_2:2)
Block(8,10,2,biomesoplenty:leaves_2:2)
Block(8,10,3,biomesoplenty:leaves_2:2)
Block(8,10,4,biomesoplenty:leaves_2:2)
Block(8,10,6,biomesoplenty:leaves_2:2)
Block(8,11,-3,biomesoplenty:leaves_2:2)
Block(8,11,-2,biomesoplenty:leaves_2:2)
Block(8,11,0,biomesoplenty:leaves_2:2)
Block(8,11,1,biomesoplenty:leaves_2:2)
Block(8,11,2,biomesoplenty:leaves_2:2)
Block(8,11,3,biomesoplenty:leaves_2:2)
Block(8,11,5,biomesoplenty:leaves_2:2)
Block(8,11,6,biomesoplenty:log_0:5)
Block(8,11,7,biomesoplenty:leaves_2:2)
Block(8,11,8,biomesoplenty:leaves_2:2)
Block(8,12,-5,biomesoplenty:leaves_2:2)
Block(8,12,-2,biomesoplenty:leaves_2:2)
Block(8,12,-1,biomesoplenty:leaves_2:2)
Block(8,12,0,biomesoplenty:leaves_2:2)
Block(8,12,1,biomesoplenty:leaves_2:2)
Block(8,12,2,biomesoplenty:leaves_2:2)
Block(8,12,4,biomesoplenty:leaves_2:2)
Block(8,12,5,biomesoplenty:leaves_2:2)
Block(8,12,6,biomesoplenty:leaves_2:2)
Block(8,12,7,biomesoplenty:leaves_2:2)
Block(8,13,-4,biomesoplenty:leaves_2:2)
Block(8,13,-2,biomesoplenty:leaves_2:2)
Block(8,13,-1,biomesoplenty:leaves_2:2)
Block(8,13,0,biomesoplenty:leaves_2:2)
Block(8,13,1,biomesoplenty:leaves_2:2)
Block(8,13,2,biomesoplenty:leaves_2:2)
Block(8,13,3,biomesoplenty:leaves_2:2)
Block(8,13,4,biomesoplenty:leaves_2:2)
Block(8,13,5,biomesoplenty:leaves_2:2)
Block(8,13,6,biomesoplenty:leaves_2:2)
Block(8,14,0,biomesoplenty:leaves_2:2)
Block(8,14,1,biomesoplenty:leaves_2:2)
Block(8,14,2,biomesoplenty:leaves_2:2)
Block(9,6,-2,biomesoplenty:leaves_2:2)
Block(9,7,-2,biomesoplenty:leaves_2:2)
Block(9,8,-3,biomesoplenty:leaves_2:2)
Block(9,8,-2,biomesoplenty:leaves_2:2)
Block(9,8,-1,biomesoplenty:leaves_2:2)
Block(9,8,0,biomesoplenty:leaves_2:2)
Block(9,9,-3,biomesoplenty:leaves_2:2)
Block(9,9,-2,biomesoplenty:leaves_2:2)
Block(9,9,-1,biomesoplenty:leaves_2:2)
Block(9,10,-2,biomesoplenty:leaves_2:2)
Block(9,10,0,biomesoplenty:leaves_2:2)
Block(9,10,6,biomesoplenty:leaves_2:2)
Block(9,11,0,biomesoplenty:leaves_2:2)
Block(9,11,2,biomesoplenty:leaves_2:2)
Block(9,11,3,biomesoplenty:leaves_2:2)
Block(9,11,5,biomesoplenty:leaves_2:2)
Block(9,11,6,biomesoplenty:leaves_2:2)
Block(9,11,7,biomesoplenty:leaves_2:2)
Block(9,12,-2,biomesoplenty:leaves_2:2)
Block(9,12,-1,biomesoplenty:leaves_2:2)
Block(9,12,0,biomesoplenty:leaves_2:2)
Block(9,12,1,biomesoplenty:leaves_2:2)
Block(9,12,2,biomesoplenty:leaves_2:2)
Block(9,12,5,biomesoplenty:leaves_2:2)
Block(9,12,6,biomesoplenty:leaves_2:2)
Block(9,13,1,biomesoplenty:leaves_2:2)
Block(9,13,2,biomesoplenty:leaves_2:2)
Block(9,13,3,biomesoplenty:leaves_2:2)
Block(9,13,6,biomesoplenty:leaves_2:2)
Block(9,14,0,biomesoplenty:leaves_2:2)
Block(9,14,2,biomesoplenty:leaves_2:2)
Block(9,14,3,biomesoplenty:leaves_2:2)
Block(9,15,2,biomesoplenty:leaves_2:2)
Block(9,15,3,biomesoplenty:leaves_2:2)
Block(10,7,-2,biomesoplenty:leaves_2:2)
Block(10,8,-4,biomesoplenty:leaves_2:2)
Block(10,8,-3,biomesoplenty:leaves_2:2)
Block(10,8,-2,biomesoplenty:leaves_2:2)
Block(10,8,-1,biomesoplenty:leaves_2:2)
Block(10,8,0,biomesoplenty:leaves_2:2)
Block(10,9,-2,biomesoplenty:leaves_2:2)
Block(10,9,-1,biomesoplenty:leaves_2:2)
Block(10,10,-2,biomesoplenty:leaves_2:2)
Block(10,10,-1,biomesoplenty:leaves_2:2)
Block(10,10,0,biomesoplenty:leaves_2:2)
Block(10,11,1,biomesoplenty:leaves_2:2)
Block(10,11,5,biomesoplenty:leaves_2:2)
Block(10,11,6,biomesoplenty:leaves_2:2)
Block(10,12,1,biomesoplenty:leaves_2:2)
Block(10,12,2,biomesoplenty:leaves_2:2)
Block(10,12,6,biomesoplenty:leaves_2:2)
Block(10,13,1,biomesoplenty:leaves_2:2)
Block(10,13,2,biomesoplenty:leaves_2:2)
Block(10,14,3,biomesoplenty:leaves_2:2)
Block(11,8,-2,biomesoplenty:leaves_2:2)
Block(11,8,-1,biomesoplenty:leaves_2:2)
Block(11,9,-2,biomesoplenty:leaves_2:2)

#######################################################################
# +-----------------------------------------------------------------+ #
# |                            BO3 checks                           | #
# +-----------------------------------------------------------------+ #
#######################################################################

BlockCheck(0,-1,0,GRASS,biomesoplenty:grass:0,biomesoplenty:grass:1,biomesoplenty:grass,biomesoplenty:grass:3,biomesoplenty:grass:4,biomesoplenty:grass:5,biomesoplenty:grass:6,biomesoplenty:grass:7)

#######################################################################
# +-----------------------------------------------------------------+ #
# |                             Branches                            | #
# +-----------------------------------------------------------------+ #
#######################################################################


#######################################################################
# +-----------------------------------------------------------------+ #
# |                             Entities                            | #
# +-----------------------------------------------------------------+ #
#######################################################################


#######################################################################
# +-----------------------------------------------------------------+ #
# |                            Particles                            | #
# +-----------------------------------------------------------------+ #
#######################################################################


#######################################################################
# +-----------------------------------------------------------------+ #
# |                             Spawners                            | #
# +-----------------------------------------------------------------+ #
#######################################################################


#######################################################################
# +-----------------------------------------------------------------+ #
# |                             ModData                             | #
# +-----------------------------------------------------------------+ #
#######################################################################

