#######################################################################
# +-----------------------------------------------------------------+ #
# |                            BO3 object                           | #
# +-----------------------------------------------------------------+ #
#######################################################################

# The descriptions in this file are true only for TerrainControl. They are not true for the Minecraft Worlds mod!
# Minecraft Worlds completely reimplemented BO3s, check the MCW documentation on the mc/mctcp forums for how to use BO3s with MCW
# or watch the video's on my YT channel at https://www.youtube.com/user/PeeGee85. You can check out the "Editing and importing schematics & BO3s" 
# series of video's, in part 2 I explain BO3s. 

# This is the config file of a custom object.
# If you add this object correctly to your BiomeConfigs, it will spawn in the world.

# This is the creator of this BO3 object
Author: LordSmellyPants

# A short description of this BO3 object


# The BO3 version, don't change this! It can be used by external applications to do a version check.
Version: 3

# The settings mode, WriteAll, WriteWithoutComments or WriteDisable. See WorldConfig.
SettingsMode: WriteDisable

#######################################################################
# +-----------------------------------------------------------------+ #
# |                          Main settings                          | #
# +-----------------------------------------------------------------+ #
#######################################################################

# This needs to be set to true to spawn the object in the Tree and Sapling resources.
Tree: false

# The frequency of the BO3 from 1 to 200. Tries this many times to spawn this BO3 when using the CustomObject(...) resource.
# Ignored by Tree(..), Sapling(..) and CustomStructure(..)
Frequency: 40

# The rarity of the BO3 from 0 to 100. Each spawn attempt has rarity% chance to succeed when using the CustomObject(...) resource.
# Ignored by Tree(..), Sapling(..) and CustomStructure(..)
Rarity: 100.0

# If you set this to true, the BO3 will be placed with a random rotation.
RotateRandomly: true

# The spawn height of the BO3 - randomY, highestBlock or highestSolidBlock.
SpawnHeight: randomY

# The height limits for the BO3.
MinHeight: 0

MaxHeight: 256

# Objects can have other objects attached to it: branches. Branches can also
# have branches attached to it, which can also have branches, etc. This is the
# maximum branch depth for this objects.
MaxBranchDepth: 10

# When spawned with the UseWorld keyword, this BO3 should NOT spawn in the following biomes.
# If you writer.write the BO3 name directly in the BiomeConfigs, this will be ignored.
ExcludedBiomes: All

#######################################################################
# +-----------------------------------------------------------------+ #
# |                      Source block settings                      | #
# +-----------------------------------------------------------------+ #
#######################################################################

# The B(s) the BO3 should spawn in.
SourceBlocks: AIR

# The maximum percentage of the BO3 that can be outside the SourceBlock.
# The BO3 won't be placed on a location with more blocks outside the SourceBlock than this percentage.
MaxPercentageOutsideSourceBlock: 100

# What to do when a block is about to be placed outside the SourceBlock? (dontPlace, placeAnyway)
OutsideSourceBlock: placeAnyway

#######################################################################
# +-----------------------------------------------------------------+ #
# |                              Blocks                             | #
# +-----------------------------------------------------------------+ #
#######################################################################

# All the blocks used in the BO3 are listed here. Possible blocks:
# B(x,y,z,id[.data][,nbtfile.nbt)
# RB(x,y,z,id[:data][,nbtfile.nbt],chance[,id[:data][,nbtfile.nbt],chance[,...]])
# So RB(0,0,0,CHEST,chest.nbt,50,CHEST,anotherchest.nbt,100) will spawn a chest at
# the BO3 origin, and give it a 50% chance to have the contents of chest.nbt, or, if that
# fails, a 100% percent chance to have the contents of anotherchest.nbt.

B(0,40,3,3)
B(0,40,4,3)
B(0,40,5,1)
B(0,40,6,1)
B(0,40,7,1)
B(0,41,3,3)
B(0,41,4,3)
B(0,41,5,1)
B(0,41,6,1)
B(0,41,7,1)
B(0,41,8,1)
B(0,42,3,2)
B(0,42,4,3)
B(0,42,5,3)
B(0,42,6,1)
B(0,42,7,1)
B(0,42,8,1)
B(0,43,4,2)
B(0,43,5,3)
B(0,43,6,3)
B(0,43,7,1)
B(0,43,8,1)
B(0,44,5,3)
B(0,44,6,3)
B(0,44,7,3)
B(0,44,8,1)
B(0,45,5,2)
B(0,45,6,3)
B(0,45,7,3)
B(0,45,8,3)
B(0,46,6,2)
B(0,46,7,3)
B(0,46,8,3)
B(0,47,7,2)
B(0,47,8,3)
B(0,48,8,2)
B(1,39,2,1)
B(1,39,3,1)
B(1,39,4,1)
B(1,39,5,1)
B(1,39,6,1)
B(1,40,1,1)
B(1,40,2,1)
B(1,40,3,1)
B(1,40,4,1)
B(1,40,5,1)
B(1,40,6,1)
B(1,40,7,1)
B(1,40,8,1)
B(1,41,0,3)
B(1,41,1,3)
B(1,41,2,1)
B(1,41,3,1)
B(1,41,4,1)
B(1,41,5,1)
B(1,41,6,1)
B(1,41,7,1)
B(1,41,8,1)
B(1,42,0,3)
B(1,42,1,3)
B(1,42,2,3)
B(1,42,3,3)
B(1,42,4,1)
B(1,42,5,1)
B(1,42,6,1)
B(1,42,7,1)
B(1,42,8,1)
B(1,43,0,2)
B(1,43,1,3)
B(1,43,2,3)
B(1,43,3,3)
B(1,43,4,3)
B(1,43,5,3)
B(1,43,6,1)
B(1,43,7,1)
B(1,43,8,1)
B(1,44,1,2)
B(1,44,2,3)
B(1,44,3,3)
B(1,44,4,3)
B(1,44,5,3)
B(1,44,6,3)
B(1,44,7,3)
B(1,44,8,1)
B(1,45,2,2)
B(1,45,3,2)
B(1,45,4,3)
B(1,45,5,3)
B(1,45,6,3)
B(1,45,7,3)
B(1,45,8,3)
B(1,46,4,2)
B(1,46,5,2)
B(1,46,6,3)
B(1,46,7,3)
B(1,46,8,3)
B(1,47,6,2)
B(1,47,7,2)
B(1,47,8,3)
B(1,48,8,2)
B(2,13,-7,1)
B(2,37,3,1)
B(2,37,4,1)
B(2,37,5,1)
B(2,38,0,1)
B(2,38,1,1)
B(2,38,2,1)
B(2,38,3,1)
B(2,38,4,1)
B(2,38,5,1)
B(2,38,6,1)
B(2,38,7,1)
B(2,39,-1,1)
B(2,39,0,1)
B(2,39,1,1)
B(2,39,2,1)
B(2,39,3,1)
B(2,39,4,1)
B(2,39,5,1)
B(2,39,6,1)
B(2,39,7,1)
B(2,39,8,1)
B(2,40,-1,3)
B(2,40,0,1)
B(2,40,1,1)
B(2,40,2,1)
B(2,40,3,1)
B(2,40,4,1)
B(2,40,5,1)
B(2,40,6,1)
B(2,40,7,1)
B(2,40,8,1)
B(2,41,-1,3)
B(2,41,0,3)
B(2,41,1,1)
B(2,41,2,1)
B(2,41,3,1)
B(2,41,4,1)
B(2,41,5,1)
B(2,41,6,1)
B(2,41,7,1)
B(2,41,8,1)
B(2,42,-1,3)
B(2,42,0,3)
B(2,42,1,3)
B(2,42,2,3)
B(2,42,3,1)
B(2,42,4,1)
B(2,42,5,1)
B(2,42,6,1)
B(2,42,7,1)
B(2,42,8,1)
B(2,43,-1,2)
B(2,43,0,3)
B(2,43,1,3)
B(2,43,2,3)
B(2,43,3,3)
B(2,43,4,1)
B(2,43,5,1)
B(2,43,6,1)
B(2,43,7,1)
B(2,43,8,1)
B(2,44,0,2)
B(2,44,1,3)
B(2,44,2,3)
B(2,44,3,3)
B(2,44,4,3)
B(2,44,5,3)
B(2,44,6,3)
B(2,44,7,1)
B(2,44,8,1)
B(2,45,1,2)
B(2,45,2,2)
B(2,45,3,3)
B(2,45,4,3)
B(2,45,5,3)
B(2,45,6,3)
B(2,45,7,3)
B(2,45,8,1)
B(2,46,3,2)
B(2,46,4,3)
B(2,46,5,3)
B(2,46,6,3)
B(2,46,7,3)
B(2,46,8,3)
B(2,47,4,2)
B(2,47,5,2)
B(2,47,6,2)
B(2,47,7,3)
B(2,47,8,3)
B(2,48,7,2)
B(2,48,8,3)
B(2,49,8,2)
B(3,11,-7,1)
B(3,12,-7,1)
B(3,12,-6,1)
B(3,13,-7,1)
B(3,13,-6,1)
B(3,14,-7,1)
B(3,15,-7,1)
B(3,16,-7,1)
B(3,17,-7,1)
B(3,33,-4,1)
B(3,33,-3,1)
B(3,33,-2,1)
B(3,34,-4,1)
B(3,34,-3,1)
B(3,34,-2,1)
B(3,34,-1,1)
B(3,34,0,1)
B(3,35,-5,1)
B(3,35,-4,1)
B(3,35,-3,1)
B(3,35,-2,1)
B(3,35,-1,1)
B(3,35,0,1)
B(3,35,1,1)
B(3,35,2,1)
B(3,35,3,1)
B(3,36,-5,3)
B(3,36,-4,1)
B(3,36,-3,1)
B(3,36,-2,1)
B(3,36,-1,1)
B(3,36,0,1)
B(3,36,1,1)
B(3,36,2,1)
B(3,36,3,1)
B(3,36,4,1)
B(3,36,5,1)
B(3,37,-5,3)
B(3,37,-4,3)
B(3,37,-3,1)
B(3,37,-2,1)
B(3,37,-1,1)
B(3,37,0,1)
B(3,37,1,1)
B(3,37,2,1)
B(3,37,3,1)
B(3,37,4,1)
B(3,37,5,1)
B(3,37,6,1)
B(3,38,-5,3)
B(3,38,-4,3)
B(3,38,-3,1)
B(3,38,-2,1)
B(3,38,-1,1)
B(3,38,0,1)
B(3,38,1,1)
B(3,38,2,1)
B(3,38,3,1)
B(3,38,4,1)
B(3,38,5,1)
B(3,38,6,1)
B(3,38,7,1)
B(3,38,8,1)
B(3,39,-5,2)
B(3,39,-4,3)
B(3,39,-3,3)
B(3,39,-2,1)
B(3,39,-1,1)
B(3,39,0,1)
B(3,39,1,1)
B(3,39,2,1)
B(3,39,3,1)
B(3,39,4,1)
B(3,39,5,1)
B(3,39,6,1)
B(3,39,7,1)
B(3,39,8,1)
B(3,40,-4,2)
B(3,40,-3,3)
B(3,40,-2,3)
B(3,40,-1,1)
B(3,40,0,1)
B(3,40,1,1)
B(3,40,2,1)
B(3,40,3,1)
B(3,40,4,1)
B(3,40,5,1)
B(3,40,6,1)
B(3,40,7,1)
B(3,40,8,1)
B(3,41,-3,3)
B(3,41,-2,3)
B(3,41,-1,3)
B(3,41,0,1)
B(3,41,1,1)
B(3,41,2,1)
B(3,41,3,1)
B(3,41,4,1)
B(3,41,5,1)
B(3,41,6,1)
B(3,41,7,1)
B(3,41,8,1)
B(3,42,-3,2)
B(3,42,-2,3)
B(3,42,-1,3)
B(3,42,0,3)
B(3,42,1,3)
B(3,42,2,1)
B(3,42,3,1)
B(3,42,4,1)
B(3,42,5,1)
B(3,42,6,1)
B(3,42,7,1)
B(3,42,8,1)
B(3,43,-2,2)
B(3,43,-1,3)
B(3,43,0,3)
B(3,43,1,3)
B(3,43,2,1)
B(3,43,3,1)
B(3,43,4,1)
B(3,43,5,1)
B(3,43,6,1)
B(3,43,7,1)
B(3,43,8,1)
B(3,44,-1,2)
B(3,44,0,3)
B(3,44,1,3)
B(3,44,2,3)
B(3,44,3,1)
B(3,44,4,1)
B(3,44,5,1)
B(3,44,6,1)
B(3,44,7,1)
B(3,44,8,1)
B(3,45,0,2)
B(3,45,1,2)
B(3,45,2,3)
B(3,45,3,3)
B(3,45,4,3)
B(3,45,5,1)
B(3,45,6,1)
B(3,45,7,1)
B(3,45,8,1)
B(3,46,2,3)
B(3,46,3,3)
B(3,46,4,3)
B(3,46,5,3)
B(3,46,6,3)
B(3,46,7,1)
B(3,46,8,1)
B(3,47,2,2)
B(3,47,3,3)
B(3,47,4,3)
B(3,47,5,3)
B(3,47,6,3)
B(3,47,7,3)
B(3,47,8,1)
B(3,48,3,2)
B(3,48,4,2)
B(3,48,5,3)
B(3,48,6,3)
B(3,48,7,3)
B(3,48,8,3)
B(3,49,5,2)
B(3,49,6,2)
B(3,49,7,3)
B(3,49,8,3)
B(3,50,7,2)
B(3,50,8,3)
B(3,51,8,2)
B(4,8,-7,1)
B(4,9,-7,1)
B(4,10,-7,1)
B(4,11,-7,1)
B(4,11,-6,1)
B(4,12,-7,1)
B(4,12,-6,1)
B(4,12,-5,1)
B(4,13,-7,1)
B(4,13,-6,1)
B(4,13,-5,1)
B(4,14,-7,1)
B(4,14,-6,1)
B(4,14,-5,1)
B(4,15,-7,1)
B(4,15,-6,1)
B(4,16,-7,1)
B(4,16,-6,1)
B(4,16,-5,1)
B(4,16,-4,1)
B(4,17,-7,1)
B(4,17,-6,1)
B(4,17,-5,1)
B(4,17,-4,1)
B(4,18,-7,1)
B(4,18,-6,1)
B(4,18,-5,1)
B(4,19,-7,1)
B(4,19,-6,1)
B(4,19,-5,1)
B(4,20,-7,1)
B(4,20,-6,1)
B(4,20,-5,1)
B(4,21,-7,1)
B(4,21,-6,1)
B(4,21,-5,1)
B(4,22,-7,1)
B(4,22,-6,1)
B(4,22,-5,1)
B(4,23,-7,1)
B(4,23,-6,1)
B(4,23,-5,1)
B(4,24,-7,1)
B(4,24,-6,1)
B(4,24,-5,1)
B(4,25,-7,1)
B(4,25,-6,1)
B(4,25,-5,1)
B(4,26,-7,1)
B(4,26,-6,1)
B(4,26,-5,1)
B(4,26,-4,1)
B(4,26,-3,1)
B(4,27,-7,1)
B(4,27,-6,1)
B(4,27,-5,1)
B(4,27,-4,1)
B(4,27,-3,1)
B(4,27,-2,1)
B(4,28,-7,1)
B(4,28,-6,1)
B(4,28,-5,1)
B(4,28,-4,1)
B(4,28,-3,1)
B(4,28,-2,1)
B(4,29,-7,1)
B(4,29,-6,1)
B(4,29,-5,1)
B(4,29,-4,1)
B(4,29,-3,1)
B(4,29,-2,1)
B(4,29,-1,1)
B(4,30,-7,1)
B(4,30,-6,1)
B(4,30,-5,1)
B(4,30,-4,1)
B(4,30,-3,1)
B(4,30,-2,1)
B(4,30,-1,1)
B(4,31,-7,1)
B(4,31,-6,1)
B(4,31,-5,1)
B(4,31,-4,1)
B(4,31,-3,1)
B(4,31,-2,1)
B(4,31,-1,1)
B(4,31,0,1)
B(4,32,-7,2)
B(4,32,-4,1)
B(4,32,-3,1)
B(4,32,-2,1)
B(4,32,-1,1)
B(4,32,0,1)
B(4,33,-4,1)
B(4,33,-3,1)
B(4,33,-2,1)
B(4,33,-1,1)
B(4,33,0,1)
B(4,33,1,1)
B(4,33,2,1)
B(4,33,3,1)
B(4,34,-7,3)
B(4,34,-6,1)
B(4,34,-5,1)
B(4,34,-4,1)
B(4,34,-3,1)
B(4,34,-2,1)
B(4,34,-1,1)
B(4,34,0,1)
B(4,34,1,1)
B(4,34,2,1)
B(4,34,3,1)
B(4,34,4,1)
B(4,34,5,1)
B(4,35,-7,2)
B(4,35,-6,3)
B(4,35,-5,1)
B(4,35,-4,1)
B(4,35,-3,1)
B(4,35,-2,1)
B(4,35,-1,1)
B(4,35,0,1)
B(4,35,1,1)
B(4,35,2,1)
B(4,35,3,1)
B(4,35,4,1)
B(4,35,5,1)
B(4,35,6,1)
B(4,36,-6,3)
B(4,36,-5,1)
B(4,36,-4,1)
B(4,36,-3,1)
B(4,36,-2,1)
B(4,36,-1,1)
B(4,36,0,1)
B(4,36,1,1)
B(4,36,2,1)
B(4,36,3,1)
B(4,36,4,1)
B(4,36,5,1)
B(4,36,6,1)
B(4,36,7,1)
B(4,37,-6,3)
B(4,37,-5,1)
B(4,37,-4,1)
B(4,37,-3,1)
B(4,37,-2,1)
B(4,37,-1,1)
B(4,37,0,1)
B(4,37,1,1)
B(4,37,2,1)
B(4,37,3,1)
B(4,37,4,1)
B(4,37,5,1)
B(4,37,6,1)
B(4,37,7,1)
B(4,37,8,1)
B(4,38,-6,2)
B(4,38,-5,3)
B(4,38,-4,3)
B(4,38,-3,1)
B(4,38,-2,1)
B(4,38,-1,1)
B(4,38,0,1)
B(4,38,1,1)
B(4,38,2,1)
B(4,38,3,1)
B(4,38,4,1)
B(4,38,5,1)
B(4,38,6,1)
B(4,38,7,1)
B(4,38,8,1)
B(4,39,-5,3)
B(4,39,-4,3)
B(4,39,-3,1)
B(4,39,-2,1)
B(4,39,-1,1)
B(4,39,0,1)
B(4,39,1,1)
B(4,39,2,1)
B(4,39,3,1)
B(4,39,4,1)
B(4,39,5,1)
B(4,39,6,1)
B(4,39,7,1)
B(4,39,8,1)
B(4,40,-5,3)
B(4,40,-4,3)
B(4,40,-3,3)
B(4,40,-2,1)
B(4,40,-1,1)
B(4,40,0,1)
B(4,40,1,1)
B(4,40,2,1)
B(4,40,3,1)
B(4,40,4,1)
B(4,40,5,1)
B(4,40,6,1)
B(4,40,7,1)
B(4,40,8,1)
B(4,41,-5,2)
B(4,41,-4,2)
B(4,41,-3,3)
B(4,41,-2,1)
B(4,41,-1,1)
B(4,41,0,1)
B(4,41,1,1)
B(4,41,2,1)
B(4,41,3,1)
B(4,41,4,1)
B(4,41,5,1)
B(4,41,6,1)
B(4,41,7,1)
B(4,41,8,1)
B(4,42,-3,3)
B(4,42,-2,3)
B(4,42,-1,1)
B(4,42,0,1)
B(4,42,1,1)
B(4,42,2,1)
B(4,42,3,1)
B(4,42,4,1)
B(4,42,5,1)
B(4,42,6,1)
B(4,42,7,1)
B(4,42,8,1)
B(4,43,-3,2)
B(4,43,-2,3)
B(4,43,-1,3)
B(4,43,0,3)
B(4,43,1,1)
B(4,43,2,1)
B(4,43,3,1)
B(4,43,4,1)
B(4,43,5,1)
B(4,43,6,1)
B(4,43,7,1)
B(4,43,8,1)
B(4,44,-2,3)
B(4,44,-1,3)
B(4,44,0,3)
B(4,44,1,3)
B(4,44,2,1)
B(4,44,3,1)
B(4,44,4,1)
B(4,44,5,1)
B(4,44,6,1)
B(4,44,7,1)
B(4,44,8,1)
B(4,45,-2,2)
B(4,45,-1,3)
B(4,45,0,3)
B(4,45,1,3)
B(4,45,2,3)
B(4,45,3,3)
B(4,45,4,1)
B(4,45,5,1)
B(4,45,6,1)
B(4,45,7,1)
B(4,45,8,1)
B(4,46,-1,2)
B(4,46,0,2)
B(4,46,1,3)
B(4,46,2,3)
B(4,46,3,3)
B(4,46,4,3)
B(4,46,5,1)
B(4,46,6,1)
B(4,46,7,1)
B(4,46,8,1)
B(4,47,1,2)
B(4,47,2,3)
B(4,47,3,3)
B(4,47,4,3)
B(4,47,5,3)
B(4,47,6,3)
B(4,47,7,1)
B(4,47,8,1)
B(4,48,2,2)
B(4,48,3,2)
B(4,48,4,3)
B(4,48,5,3)
B(4,48,6,3)
B(4,48,7,3)
B(4,48,8,1)
B(4,49,4,2)
B(4,49,5,3)
B(4,49,6,3)
B(4,49,7,3)
B(4,49,8,3)
B(4,50,5,2)
B(4,50,6,2)
B(4,50,7,3)
B(4,50,8,3)
B(4,51,7,2)
B(4,51,8,3)
B(4,52,8,2)
B(5,7,-7,1)
B(5,8,-7,1)
B(5,8,-6,1)
B(5,8,-5,1)
B(5,9,-7,1)
B(5,9,-6,1)
B(5,9,-5,1)
B(5,10,-7,1)
B(5,10,-6,1)
B(5,10,-5,1)
B(5,11,-7,1)
B(5,11,-6,1)
B(5,11,-5,1)
B(5,12,-7,1)
B(5,12,-6,1)
B(5,12,-5,1)
B(5,12,-4,1)
B(5,13,-7,1)
B(5,13,-6,1)
B(5,13,-5,1)
B(5,13,-4,1)
B(5,14,-7,1)
B(5,14,-6,1)
B(5,14,-5,1)
B(5,14,-4,1)
B(5,15,-7,1)
B(5,15,-6,1)
B(5,15,-5,1)
B(5,15,-4,1)
B(5,16,-7,1)
B(5,16,-6,1)
B(5,16,-5,1)
B(5,16,-4,1)
B(5,17,-7,1)
B(5,17,-6,1)
B(5,17,-5,1)
B(5,17,-4,1)
B(5,18,-7,1)
B(5,18,-6,1)
B(5,18,-5,1)
B(5,18,-4,1)
B(5,19,-7,1)
B(5,19,-6,1)
B(5,19,-5,1)
B(5,19,-4,1)
B(5,20,-7,1)
B(5,20,-6,1)
B(5,20,-5,1)
B(5,20,-4,1)
B(5,21,-7,1)
B(5,21,-6,1)
B(5,21,-5,1)
B(5,21,-4,1)
B(5,22,-7,1)
B(5,22,-6,1)
B(5,22,-5,1)
B(5,22,-4,1)
B(5,23,-7,1)
B(5,23,-6,1)
B(5,23,-5,1)
B(5,23,-4,1)
B(5,24,-7,1)
B(5,24,-6,1)
B(5,24,-5,1)
B(5,24,-4,1)
B(5,24,-3,1)
B(5,25,-7,1)
B(5,25,-6,1)
B(5,25,-5,1)
B(5,25,-4,1)
B(5,25,-3,1)
B(5,25,-2,1)
B(5,26,-7,1)
B(5,26,-6,1)
B(5,26,-5,1)
B(5,26,-4,1)
B(5,26,-3,1)
B(5,26,-2,1)
B(5,27,-7,1)
B(5,27,-6,1)
B(5,27,-5,1)
B(5,27,-4,1)
B(5,27,-3,1)
B(5,27,-2,1)
B(5,27,-1,1)
B(5,28,-7,1)
B(5,28,-6,1)
B(5,28,-5,1)
B(5,28,-4,1)
B(5,28,-3,1)
B(5,28,-2,1)
B(5,28,-1,1)
B(5,28,0,1)
B(5,29,-7,1)
B(5,29,-6,1)
B(5,29,-5,1)
B(5,29,-4,1)
B(5,29,-3,1)
B(5,29,-2,1)
B(5,29,-1,1)
B(5,29,0,1)
B(5,29,1,1)
B(5,30,-7,1)
B(5,30,-6,1)
B(5,30,-5,1)
B(5,30,-4,1)
B(5,30,-3,1)
B(5,30,-2,1)
B(5,30,-1,1)
B(5,30,0,1)
B(5,30,1,1)
B(5,31,-7,1)
B(5,31,-6,1)
B(5,31,-5,1)
B(5,31,-4,1)
B(5,31,-3,1)
B(5,31,-2,1)
B(5,31,-1,1)
B(5,31,0,1)
B(5,31,1,1)
B(5,31,2,1)
B(5,32,-7,1)
B(5,32,-6,1)
B(5,32,-5,1)
B(5,32,-4,1)
B(5,32,-3,1)
B(5,32,-2,1)
B(5,32,-1,1)
B(5,32,0,1)
B(5,32,1,1)
B(5,32,2,1)
B(5,32,3,1)
B(5,33,-7,1)
B(5,33,-6,1)
B(5,33,-5,1)
B(5,33,-4,1)
B(5,33,-3,1)
B(5,33,-2,1)
B(5,33,-1,1)
B(5,33,0,1)
B(5,33,1,1)
B(5,33,2,1)
B(5,33,3,1)
B(5,33,4,1)
B(5,34,-7,1)
B(5,34,-6,1)
B(5,34,-5,1)
B(5,34,-4,1)
B(5,34,-3,1)
B(5,34,-2,1)
B(5,34,-1,1)
B(5,34,0,1)
B(5,34,1,1)
B(5,34,2,1)
B(5,34,3,1)
B(5,34,4,1)
B(5,34,5,1)
B(5,34,6,1)
B(5,35,-7,3)
B(5,35,-6,1)
B(5,35,-5,1)
B(5,35,-4,1)
B(5,35,-3,1)
B(5,35,-2,1)
B(5,35,-1,1)
B(5,35,0,1)
B(5,35,1,1)
B(5,35,2,1)
B(5,35,3,1)
B(5,35,4,1)
B(5,35,5,1)
B(5,35,6,1)
B(5,35,7,1)
B(5,36,-7,3)
B(5,36,-6,1)
B(5,36,-5,1)
B(5,36,-4,1)
B(5,36,-3,1)
B(5,36,-2,1)
B(5,36,-1,1)
B(5,36,0,1)
B(5,36,1,1)
B(5,36,2,1)
B(5,36,3,1)
B(5,36,4,1)
B(5,36,5,1)
B(5,36,6,1)
B(5,36,7,1)
B(5,37,-7,3)
B(5,37,-6,3)
B(5,37,-5,1)
B(5,37,-4,1)
B(5,37,-3,1)
B(5,37,-2,1)
B(5,37,-1,1)
B(5,37,0,1)
B(5,37,1,1)
B(5,37,2,1)
B(5,37,3,1)
B(5,37,4,1)
B(5,37,5,1)
B(5,37,6,1)
B(5,37,7,1)
B(5,37,8,1)
B(5,38,-7,2)
B(5,38,-6,3)
B(5,38,-5,3)
B(5,38,-4,1)
B(5,38,-3,1)
B(5,38,-2,1)
B(5,38,-1,1)
B(5,38,0,1)
B(5,38,1,1)
B(5,38,2,1)
B(5,38,3,1)
B(5,38,4,1)
B(5,38,5,1)
B(5,38,6,1)
B(5,38,7,1)
B(5,38,8,1)
B(5,39,-6,3)
B(5,39,-5,3)
B(5,39,-4,1)
B(5,39,-3,1)
B(5,39,-2,1)
B(5,39,-1,1)
B(5,39,0,1)
B(5,39,1,1)
B(5,39,2,1)
B(5,39,3,1)
B(5,39,4,1)
B(5,39,5,1)
B(5,39,6,1)
B(5,39,7,1)
B(5,39,8,1)
B(5,40,-6,2)
B(5,40,-5,3)
B(5,40,-4,3)
B(5,40,-3,1)
B(5,40,-2,1)
B(5,40,-1,1)
B(5,40,0,1)
B(5,40,1,1)
B(5,40,2,1)
B(5,40,3,1)
B(5,40,4,1)
B(5,40,5,1)
B(5,40,6,1)
B(5,40,7,1)
B(5,40,8,1)
B(5,41,-5,2)
B(5,41,-4,3)
B(5,41,-3,3)
B(5,41,-2,1)
B(5,41,-1,1)
B(5,41,0,1)
B(5,41,1,1)
B(5,41,2,1)
B(5,41,3,1)
B(5,41,4,1)
B(5,41,5,1)
B(5,41,6,1)
B(5,41,7,1)
B(5,41,8,1)
B(5,42,-4,3)
B(5,42,-3,3)
B(5,42,-2,1)
B(5,42,-1,1)
B(5,42,0,1)
B(5,42,1,1)
B(5,42,2,1)
B(5,42,3,1)
B(5,42,4,1)
B(5,42,5,1)
B(5,42,6,1)
B(5,42,7,1)
B(5,42,8,1)
B(5,43,-4,2)
B(5,43,-3,3)
B(5,43,-2,3)
B(5,43,-1,3)
B(5,43,0,1)
B(5,43,1,1)
B(5,43,2,1)
B(5,43,3,1)
B(5,43,4,1)
B(5,43,5,1)
B(5,43,6,1)
B(5,43,7,1)
B(5,43,8,1)
B(5,44,-3,2)
B(5,44,-2,3)
B(5,44,-1,3)
B(5,44,0,1)
B(5,44,1,1)
B(5,44,2,1)
B(5,44,3,1)
B(5,44,4,1)
B(5,44,5,1)
B(5,44,6,1)
B(5,44,7,1)
B(5,44,8,1)
B(5,45,-2,3)
B(5,45,-1,3)
B(5,45,0,3)
B(5,45,1,3)
B(5,45,2,3)
B(5,45,3,1)
B(5,45,4,1)
B(5,45,5,1)
B(5,45,6,1)
B(5,45,7,1)
B(5,45,8,1)
B(5,46,-2,2)
B(5,46,-1,2)
B(5,46,0,3)
B(5,46,1,3)
B(5,46,2,3)
B(5,46,3,3)
B(5,46,4,3)
B(5,46,5,1)
B(5,46,6,1)
B(5,46,7,1)
B(5,46,8,1)
B(5,47,0,3)
B(5,47,1,3)
B(5,47,2,3)
B(5,47,3,3)
B(5,47,4,3)
B(5,47,5,3)
B(5,47,6,1)
B(5,47,7,1)
B(5,47,8,1)
B(5,48,0,2)
B(5,48,1,2)
B(5,48,2,2)
B(5,48,3,3)
B(5,48,4,3)
B(5,48,5,3)
B(5,48,6,3)
B(5,48,7,1)
B(5,48,8,1)
B(5,49,3,2)
B(5,49,4,2)
B(5,49,5,3)
B(5,49,6,3)
B(5,49,7,3)
B(5,49,8,3)
B(5,50,5,2)
B(5,50,6,3)
B(5,50,7,3)
B(5,50,8,3)
B(5,51,6,2)
B(5,51,7,3)
B(5,51,8,3)
B(5,52,7,2)
B(5,52,8,2)
B(6,7,-7,1)
B(6,7,-6,1)
B(6,8,-7,1)
B(6,8,-6,1)
B(6,8,-5,1)
B(6,9,-7,1)
B(6,9,-6,1)
B(6,9,-5,1)
B(6,10,-7,1)
B(6,10,-6,1)
B(6,10,-5,1)
B(6,11,-7,1)
B(6,11,-6,1)
B(6,11,-5,1)
B(6,12,-7,1)
B(6,12,-6,1)
B(6,12,-5,1)
B(6,12,-4,1)
B(6,13,-7,1)
B(6,13,-6,1)
B(6,13,-5,1)
B(6,13,-4,1)
B(6,14,-7,1)
B(6,14,-6,1)
B(6,14,-5,1)
B(6,14,-4,1)
B(6,14,-3,1)
B(6,15,-7,1)
B(6,15,-6,1)
B(6,15,-5,1)
B(6,15,-4,1)
B(6,15,-3,1)
B(6,16,-7,1)
B(6,16,-6,1)
B(6,16,-5,1)
B(6,16,-4,1)
B(6,16,-3,1)
B(6,17,-7,1)
B(6,17,-6,1)
B(6,17,-5,1)
B(6,17,-4,1)
B(6,17,-3,1)
B(6,18,-7,1)
B(6,18,-6,1)
B(6,18,-5,1)
B(6,18,-4,1)
B(6,18,-3,1)
B(6,19,-7,1)
B(6,19,-6,1)
B(6,19,-5,1)
B(6,19,-4,1)
B(6,19,-3,1)
B(6,20,-7,1)
B(6,20,-6,1)
B(6,20,-5,1)
B(6,20,-4,1)
B(6,20,-3,1)
B(6,21,-7,1)
B(6,21,-6,1)
B(6,21,-5,1)
B(6,21,-4,1)
B(6,21,-3,1)
B(6,21,-2,1)
B(6,22,-7,1)
B(6,22,-6,1)
B(6,22,-5,1)
B(6,22,-4,1)
B(6,22,-3,1)
B(6,22,-2,1)
B(6,23,-7,1)
B(6,23,-6,1)
B(6,23,-5,1)
B(6,23,-4,1)
B(6,23,-3,1)
B(6,23,-2,1)
B(6,24,-7,1)
B(6,24,-6,1)
B(6,24,-5,1)
B(6,24,-4,1)
B(6,24,-3,1)
B(6,24,-2,1)
B(6,24,-1,1)
B(6,25,-7,1)
B(6,25,-6,1)
B(6,25,-5,1)
B(6,25,-4,1)
B(6,25,-3,1)
B(6,25,-2,1)
B(6,25,-1,1)
B(6,25,0,1)
B(6,26,-7,1)
B(6,26,-6,1)
B(6,26,-5,1)
B(6,26,-4,1)
B(6,26,-3,1)
B(6,26,-2,1)
B(6,26,-1,1)
B(6,26,0,1)
B(6,26,1,1)
B(6,27,-7,1)
B(6,27,-6,1)
B(6,27,-5,1)
B(6,27,-4,1)
B(6,27,-3,1)
B(6,27,-2,1)
B(6,27,-1,1)
B(6,27,0,1)
B(6,27,1,1)
B(6,28,-7,1)
B(6,28,-6,1)
B(6,28,-5,1)
B(6,28,-4,1)
B(6,28,-3,1)
B(6,28,-2,1)
B(6,28,-1,1)
B(6,28,0,1)
B(6,28,1,1)
B(6,29,-7,1)
B(6,29,-6,1)
B(6,29,-5,1)
B(6,29,-4,1)
B(6,29,-3,1)
B(6,29,-2,1)
B(6,29,-1,1)
B(6,29,0,1)
B(6,29,1,1)
B(6,29,2,1)
B(6,30,-7,1)
B(6,30,-6,1)
B(6,30,-5,1)
B(6,30,-4,1)
B(6,30,-3,1)
B(6,30,-2,1)
B(6,30,-1,1)
B(6,30,0,1)
B(6,30,1,1)
B(6,30,2,1)
B(6,31,-7,1)
B(6,31,-6,1)
B(6,31,-5,1)
B(6,31,-4,1)
B(6,31,-3,1)
B(6,31,-2,1)
B(6,31,-1,1)
B(6,31,0,1)
B(6,31,1,1)
B(6,31,2,1)
B(6,31,3,1)
B(6,32,-7,1)
B(6,32,-6,1)
B(6,32,-5,1)
B(6,32,-4,1)
B(6,32,-3,1)
B(6,32,-2,1)
B(6,32,-1,1)
B(6,32,0,1)
B(6,32,1,1)
B(6,32,2,1)
B(6,32,3,1)
B(6,32,4,1)
B(6,33,-7,1)
B(6,33,-6,1)
B(6,33,-5,1)
B(6,33,-4,1)
B(6,33,-3,1)
B(6,33,-2,1)
B(6,33,-1,1)
B(6,33,0,1)
B(6,33,1,1)
B(6,33,2,1)
B(6,33,3,1)
B(6,33,4,1)
B(6,33,5,1)
B(6,33,6,1)
B(6,34,-7,1)
B(6,34,-6,1)
B(6,34,-5,1)
B(6,34,-4,1)
B(6,34,-3,1)
B(6,34,-2,1)
B(6,34,-1,1)
B(6,34,0,1)
B(6,34,1,1)
B(6,34,2,1)
B(6,34,3,1)
B(6,34,4,1)
B(6,34,5,1)
B(6,34,6,1)
B(6,34,7,1)
B(6,35,-7,1)
B(6,35,-6,1)
B(6,35,-5,1)
B(6,35,-4,1)
B(6,35,-3,1)
B(6,35,-2,1)
B(6,35,-1,1)
B(6,35,0,1)
B(6,35,1,1)
B(6,35,2,1)
B(6,35,3,1)
B(6,35,4,1)
B(6,35,5,1)
B(6,35,6,1)
B(6,35,7,1)
B(6,36,-7,3)
B(6,36,-6,1)
B(6,36,-5,1)
B(6,36,-4,1)
B(6,36,-3,1)
B(6,36,-2,1)
B(6,36,-1,1)
B(6,36,0,1)
B(6,36,1,1)
B(6,36,2,1)
B(6,36,3,1)
B(6,36,4,1)
B(6,36,5,1)
B(6,36,6,1)
B(6,36,7,1)
B(6,37,-7,3)
B(6,37,-6,1)
B(6,37,-5,1)
B(6,37,-4,1)
B(6,37,-3,1)
B(6,37,-2,1)
B(6,37,-1,1)
B(6,37,0,1)
B(6,37,1,1)
B(6,37,2,1)
B(6,37,3,1)
B(6,37,4,1)
B(6,37,5,1)
B(6,37,6,1)
B(6,37,7,1)
B(6,37,8,1)
B(6,38,-7,3)
B(6,38,-6,3)
B(6,38,-5,1)
B(6,38,-4,1)
B(6,38,-3,1)
B(6,38,-2,1)
B(6,38,-1,1)
B(6,38,0,1)
B(6,38,1,1)
B(6,38,2,1)
B(6,38,3,1)
B(6,38,4,1)
B(6,38,5,1)
B(6,38,6,1)
B(6,38,7,1)
B(6,38,8,1)
B(6,39,-7,2)
B(6,39,-6,3)
B(6,39,-5,3)
B(6,39,-4,1)
B(6,39,-3,1)
B(6,39,-2,1)
B(6,39,-1,1)
B(6,39,0,1)
B(6,39,1,1)
B(6,39,2,1)
B(6,39,3,1)
B(6,39,4,1)
B(6,39,5,1)
B(6,39,6,1)
B(6,39,7,1)
B(6,39,8,1)
B(6,40,-6,3)
B(6,40,-5,3)
B(6,40,-4,1)
B(6,40,-3,1)
B(6,40,-2,1)
B(6,40,-1,1)
B(6,40,0,1)
B(6,40,1,1)
B(6,40,2,1)
B(6,40,3,1)
B(6,40,4,1)
B(6,40,5,1)
B(6,40,6,1)
B(6,40,7,1)
B(6,40,8,1)
B(6,41,-6,2)
B(6,41,-5,3)
B(6,41,-4,3)
B(6,41,-3,1)
B(6,41,-2,1)
B(6,41,-1,1)
B(6,41,0,1)
B(6,41,1,1)
B(6,41,2,1)
B(6,41,3,1)
B(6,41,4,1)
B(6,41,5,1)
B(6,41,6,1)
B(6,41,7,1)
B(6,41,8,1)
B(6,42,-5,2)
B(6,42,-4,3)
B(6,42,-3,3)
B(6,42,-2,1)
B(6,42,-1,1)
B(6,42,0,1)
B(6,42,1,1)
B(6,42,2,1)
B(6,42,3,1)
B(6,42,4,1)
B(6,42,5,1)
B(6,42,6,1)
B(6,42,7,1)
B(6,42,8,1)
B(6,43,-4,3)
B(6,43,-3,3)
B(6,43,-2,1)
B(6,43,-1,1)
B(6,43,0,1)
B(6,43,1,1)
B(6,43,2,1)
B(6,43,3,1)
B(6,43,4,1)
B(6,43,5,1)
B(6,43,6,1)
B(6,43,7,1)
B(6,43,8,1)
B(6,44,-4,2)
B(6,44,-3,3)
B(6,44,-2,3)
B(6,44,-1,3)
B(6,44,0,1)
B(6,44,1,1)
B(6,44,2,1)
B(6,44,3,1)
B(6,44,4,1)
B(6,44,5,1)
B(6,44,6,1)
B(6,44,7,1)
B(6,44,8,1)
B(6,45,-3,2)
B(6,45,-2,3)
B(6,45,-1,3)
B(6,45,0,3)
B(6,45,1,3)
B(6,45,2,1)
B(6,45,3,1)
B(6,45,4,1)
B(6,45,5,1)
B(6,45,6,1)
B(6,45,7,1)
B(6,45,8,1)
B(6,46,-2,3)
B(6,46,-1,3)
B(6,46,0,3)
B(6,46,1,3)
B(6,46,2,3)
B(6,46,3,3)
B(6,46,4,1)
B(6,46,5,1)
B(6,46,6,1)
B(6,46,7,1)
B(6,46,8,1)
B(6,47,-2,2)
B(6,47,-1,2)
B(6,47,0,3)
B(6,47,1,3)
B(6,47,2,3)
B(6,47,3,3)
B(6,47,4,3)
B(6,47,5,1)
B(6,47,6,1)
B(6,47,7,1)
B(6,47,8,1)
B(6,48,0,2)
B(6,48,1,2)
B(6,48,2,3)
B(6,48,3,3)
B(6,48,4,3)
B(6,48,5,3)
B(6,48,6,1)
B(6,48,7,1)
B(6,48,8,1)
B(6,49,2,2)
B(6,49,3,2)
B(6,49,4,3)
B(6,49,5,3)
B(6,49,6,3)
B(6,49,7,3)
B(6,49,8,1)
B(6,50,4,2)
B(6,50,5,3)
B(6,50,6,3)
B(6,50,7,3)
B(6,50,8,3)
B(6,51,5,2)
B(6,51,6,3)
B(6,51,7,3)
B(6,51,8,3)
B(6,52,6,2)
B(6,52,7,2)
B(6,52,8,3)
B(6,53,8,2)
B(7,6,-7,1)
B(7,6,-6,1)
B(7,7,-7,1)
B(7,7,-6,1)
B(7,7,-5,1)
B(7,8,-7,1)
B(7,8,-6,1)
B(7,8,-5,1)
B(7,8,-4,1)
B(7,9,-7,1)
B(7,9,-6,1)
B(7,9,-5,1)
B(7,10,-7,1)
B(7,10,-6,1)
B(7,10,-5,1)
B(7,11,-7,1)
B(7,11,-6,1)
B(7,11,-5,1)
B(7,12,-7,1)
B(7,12,-6,1)
B(7,12,-5,1)
B(7,12,-4,1)
B(7,13,-7,1)
B(7,13,-6,1)
B(7,13,-5,1)
B(7,13,-4,1)
B(7,14,-7,1)
B(7,14,-6,1)
B(7,14,-5,1)
B(7,14,-4,1)
B(7,14,-3,1)
B(7,15,-7,1)
B(7,15,-6,1)
B(7,15,-5,1)
B(7,15,-4,1)
B(7,15,-3,1)
B(7,16,-7,1)
B(7,16,-6,1)
B(7,16,-5,1)
B(7,16,-4,1)
B(7,16,-3,1)
B(7,17,-7,1)
B(7,17,-6,1)
B(7,17,-5,1)
B(7,17,-4,1)
B(7,17,-3,1)
B(7,17,-2,1)
B(7,17,-1,1)
B(7,18,-7,1)
B(7,18,-6,1)
B(7,18,-5,1)
B(7,18,-4,1)
B(7,18,-3,1)
B(7,18,-2,1)
B(7,18,-1,1)
B(7,19,-7,1)
B(7,19,-6,1)
B(7,19,-5,1)
B(7,19,-4,1)
B(7,19,-3,1)
B(7,19,-2,1)
B(7,19,-1,1)
B(7,20,-7,1)
B(7,20,-6,1)
B(7,20,-5,1)
B(7,20,-4,1)
B(7,20,-3,1)
B(7,20,-2,1)
B(7,21,-7,1)
B(7,21,-6,1)
B(7,21,-5,1)
B(7,21,-4,1)
B(7,21,-3,1)
B(7,21,-2,1)
B(7,22,-7,1)
B(7,22,-6,1)
B(7,22,-5,1)
B(7,22,-4,1)
B(7,22,-3,1)
B(7,22,-2,1)
B(7,22,-1,1)
B(7,23,-7,1)
B(7,23,-6,1)
B(7,23,-5,1)
B(7,23,-4,1)
B(7,23,-3,1)
B(7,23,-2,1)
B(7,23,-1,1)
B(7,24,-7,1)
B(7,24,-6,1)
B(7,24,-5,1)
B(7,24,-4,1)
B(7,24,-3,1)
B(7,24,-2,1)
B(7,24,-1,1)
B(7,24,0,1)
B(7,25,-7,1)
B(7,25,-6,1)
B(7,25,-5,1)
B(7,25,-4,1)
B(7,25,-3,1)
B(7,25,-2,1)
B(7,25,-1,1)
B(7,25,0,1)
B(7,25,1,1)
B(7,25,2,1)
B(7,26,-7,1)
B(7,26,-6,1)
B(7,26,-5,1)
B(7,26,-4,1)
B(7,26,-3,1)
B(7,26,-2,1)
B(7,26,-1,1)
B(7,26,0,1)
B(7,26,1,1)
B(7,26,2,1)
B(7,27,-7,1)
B(7,27,-6,1)
B(7,27,-5,1)
B(7,27,-4,1)
B(7,27,-3,1)
B(7,27,-2,1)
B(7,27,-1,1)
B(7,27,0,1)
B(7,27,1,1)
B(7,27,2,1)
B(7,28,-7,1)
B(7,28,-6,1)
B(7,28,-5,1)
B(7,28,-4,1)
B(7,28,-3,1)
B(7,28,-2,1)
B(7,28,-1,1)
B(7,28,0,1)
B(7,28,1,1)
B(7,28,2,1)
B(7,29,-7,1)
B(7,29,-6,1)
B(7,29,-5,1)
B(7,29,-4,1)
B(7,29,-3,1)
B(7,29,-2,1)
B(7,29,-1,1)
B(7,29,0,1)
B(7,29,1,1)
B(7,29,2,1)
B(7,30,-7,1)
B(7,30,-6,1)
B(7,30,-5,1)
B(7,30,-4,1)
B(7,30,-3,1)
B(7,30,-2,1)
B(7,30,-1,1)
B(7,30,0,1)
B(7,30,1,1)
B(7,30,2,1)
B(7,30,3,1)
B(7,31,-7,1)
B(7,31,-6,1)
B(7,31,-5,1)
B(7,31,-4,1)
B(7,31,-3,1)
B(7,31,-2,1)
B(7,31,-1,1)
B(7,31,0,1)
B(7,31,1,1)
B(7,31,2,1)
B(7,31,3,1)
B(7,32,-7,1)
B(7,32,-6,1)
B(7,32,-5,1)
B(7,32,-4,1)
B(7,32,-3,1)
B(7,32,-2,1)
B(7,32,-1,1)
B(7,32,0,1)
B(7,32,1,1)
B(7,32,2,1)
B(7,32,3,1)
B(7,32,4,1)
B(7,32,5,1)
B(7,33,-7,1)
B(7,33,-6,1)
B(7,33,-5,1)
B(7,33,-4,1)
B(7,33,-3,1)
B(7,33,-2,1)
B(7,33,-1,1)
B(7,33,0,1)
B(7,33,1,1)
B(7,33,2,1)
B(7,33,3,1)
B(7,33,4,1)
B(7,33,5,1)
B(7,33,6,1)
B(7,34,-7,1)
B(7,34,-6,1)
B(7,34,-5,1)
B(7,34,-4,1)
B(7,34,-3,1)
B(7,34,-2,1)
B(7,34,-1,1)
B(7,34,0,1)
B(7,34,1,1)
B(7,34,2,1)
B(7,34,3,1)
B(7,34,4,1)
B(7,34,5,1)
B(7,34,6,1)
B(7,34,7,1)
B(7,35,-7,1)
B(7,35,-6,1)
B(7,35,-5,1)
B(7,35,-4,1)
B(7,35,-3,1)
B(7,35,-2,1)
B(7,35,-1,1)
B(7,35,0,1)
B(7,35,1,1)
B(7,35,2,1)
B(7,35,3,1)
B(7,35,4,1)
B(7,35,5,1)
B(7,35,6,1)
B(7,35,7,1)
B(7,36,-7,1)
B(7,36,-6,1)
B(7,36,-5,1)
B(7,36,-4,1)
B(7,36,-3,1)
B(7,36,-2,1)
B(7,36,-1,1)
B(7,36,0,1)
B(7,36,1,1)
B(7,36,2,1)
B(7,36,3,1)
B(7,36,4,1)
B(7,36,5,1)
B(7,36,6,1)
B(7,36,7,1)
B(7,36,8,1)
B(7,37,-7,1)
B(7,37,-6,1)
B(7,37,-5,1)
B(7,37,-4,1)
B(7,37,-3,1)
B(7,37,-2,1)
B(7,37,-1,1)
B(7,37,0,1)
B(7,37,1,1)
B(7,37,2,1)
B(7,37,3,1)
B(7,37,4,1)
B(7,37,5,1)
B(7,37,6,1)
B(7,37,7,1)
B(7,37,8,1)
B(7,38,-7,3)
B(7,38,-6,1)
B(7,38,-5,1)
B(7,38,-4,1)
B(7,38,-3,1)
B(7,38,-2,1)
B(7,38,-1,1)
B(7,38,0,1)
B(7,38,1,1)
B(7,38,2,1)
B(7,38,3,1)
B(7,38,4,1)
B(7,38,5,1)
B(7,38,6,1)
B(7,38,7,1)
B(7,38,8,1)
B(7,39,-7,3)
B(7,39,-6,3)
B(7,39,-5,1)
B(7,39,-4,1)
B(7,39,-3,1)
B(7,39,-2,1)
B(7,39,-1,1)
B(7,39,0,1)
B(7,39,1,1)
B(7,39,2,1)
B(7,39,3,1)
B(7,39,4,1)
B(7,39,5,1)
B(7,39,6,1)
B(7,39,7,1)
B(7,39,8,1)
B(7,40,-7,3)
B(7,40,-6,3)
B(7,40,-5,3)
B(7,40,-4,1)
B(7,40,-3,1)
B(7,40,-2,1)
B(7,40,-1,1)
B(7,40,0,1)
B(7,40,1,1)
B(7,40,2,1)
B(7,40,3,1)
B(7,40,4,1)
B(7,40,5,1)
B(7,40,6,1)
B(7,40,7,1)
B(7,40,8,1)
B(7,41,-7,2)
B(7,41,-6,3)
B(7,41,-5,3)
B(7,41,-4,1)
B(7,41,-3,1)
B(7,41,-2,1)
B(7,41,-1,1)
B(7,41,0,1)
B(7,41,1,1)
B(7,41,2,1)
B(7,41,3,1)
B(7,41,4,1)
B(7,41,5,1)
B(7,41,6,1)
B(7,41,7,1)
B(7,41,8,1)
B(7,42,-6,2)
B(7,42,-5,3)
B(7,42,-4,1)
B(7,42,-3,1)
B(7,42,-2,1)
B(7,42,-1,1)
B(7,42,0,1)
B(7,42,1,1)
B(7,42,2,1)
B(7,42,3,1)
B(7,42,4,1)
B(7,42,5,1)
B(7,42,6,1)
B(7,42,7,1)
B(7,42,8,1)
B(7,43,-5,2)
B(7,43,-4,3)
B(7,43,-3,3)
B(7,43,-2,1)
B(7,43,-1,1)
B(7,43,0,1)
B(7,43,1,1)
B(7,43,2,1)
B(7,43,3,1)
B(7,43,4,1)
B(7,43,5,1)
B(7,43,6,1)
B(7,43,7,1)
B(7,43,8,1)
B(7,44,-4,3)
B(7,44,-3,3)
B(7,44,-2,3)
B(7,44,-1,3)
B(7,44,0,1)
B(7,44,1,1)
B(7,44,2,1)
B(7,44,3,1)
B(7,44,4,1)
B(7,44,5,1)
B(7,44,6,1)
B(7,44,7,1)
B(7,44,8,1)
B(7,45,-4,3)
B(7,45,-3,3)
B(7,45,-2,3)
B(7,45,-1,3)
B(7,45,0,3)
B(7,45,1,3)
B(7,45,2,1)
B(7,45,3,1)
B(7,45,4,1)
B(7,45,5,1)
B(7,45,6,1)
B(7,45,7,1)
B(7,45,8,1)
B(7,46,-4,2)
B(7,46,-3,2)
B(7,46,-2,3)
B(7,46,-1,3)
B(7,46,0,3)
B(7,46,1,3)
B(7,46,2,3)
B(7,46,3,3)
B(7,46,4,1)
B(7,46,5,1)
B(7,46,6,1)
B(7,46,7,1)
B(7,46,8,1)
B(7,47,-2,2)
B(7,47,-1,2)
B(7,47,0,3)
B(7,47,1,3)
B(7,47,2,3)
B(7,47,3,3)
B(7,47,4,3)
B(7,47,5,1)
B(7,47,6,1)
B(7,47,7,1)
B(7,47,8,1)
B(7,48,0,2)
B(7,48,1,2)
B(7,48,2,3)
B(7,48,3,3)
B(7,48,4,3)
B(7,48,5,3)
B(7,48,6,1)
B(7,48,7,1)
B(7,48,8,1)
B(7,49,2,2)
B(7,49,3,2)
B(7,49,4,3)
B(7,49,5,3)
B(7,49,6,3)
B(7,49,7,3)
B(7,49,8,1)
B(7,50,4,2)
B(7,50,5,3)
B(7,50,6,3)
B(7,50,7,3)
B(7,50,8,3)
B(7,51,5,2)
B(7,51,6,3)
B(7,51,7,3)
B(7,51,8,3)
B(7,52,6,2)
B(7,52,7,2)
B(7,52,8,3)
B(7,53,8,2)

# 

#######################################################################
# +-----------------------------------------------------------------+ #
# |                            BO3 checks                           | #
# +-----------------------------------------------------------------+ #
#######################################################################

# Require a condition at a certain location in order for the BO3 to be spawned.
# BlockCheck(x,y,z,BlockName[,BlockName[,...]]) - one of the blocks must be at the location
# BlockCheckNot(x,y,z,BlockName[,BlockName[,...]]) - all the blocks must not be at the location
# LightCheck(x,y,z,minLightLevel,maxLightLevel) - light must be between min and max (inclusive)

# You can use "Solid" as a BlockName for matching all solid blocks or "All" to match all blocks that aren't air.

# Examples:
#   BlockCheck(0,-1,0,GRASS,DIRT,biomesoplenty:grass:0,biomesoplenty:grass:1,biomesoplenty:grass:2,biomesoplenty:grass:3,biomesoplenty:grass:4,biomesoplenty:grass:5,biomesoplenty:grass:6,biomesoplenty:grass:7,biomesoplenty:dirt:0,biomesoplenty:dirt:1,biomesoplenty:dirt:2,biomesoplenty:dirt:3,biomesoplenty:dirt:4,biomesoplenty:dirt:5,biomesoplenty:dirt:6,biomesoplenty:dirt:7,biomesoplenty:dirt:8,biomesoplenty:dirt:9,biomesoplenty:dirt:10,biomesoplenty:dried_sand:0,biomesoplenty:hard_ice:0,biomesoplenty:white_sand:0,biomesoplenty:white_sandstone:0,biomesoplenty:mud:0,biomesoplenty:ash_block:0)  Require grass or dirt just below the object
#   BlockCheck(0,-1,0,Solid)       Require any solid block just below the object
#   BlockCheck(0,-1,0,WOOL)        Require any type of wool just below the object
#   BlockCheck(0,-1,0,WOOL:0)      Require white wool just below the object
#   BlockCheckNot(0,0,0,WOOL:0)   Require that there is no white wool below the object
#   LightCheck(0,0,0,0,1)          Require almost complete darkness just below the object

#######################################################################
# +-----------------------------------------------------------------+ #
# |                             Branches                            | #
# +-----------------------------------------------------------------+ #
#######################################################################

# Branches are objects that will spawn when this object spawns when it is used in
# the CustomStructure resource. Branches can also have branches, making complex
# structures possible. See the wiki for more details.

# Regular Branches spawn each branch with an independent chance of spawning.
# Branch(x,y,z,branchName,rotation,chance[,anotherBranchName,rotation,chance[,...]][IndividualChance])
# branchName - name of the object to spawn.
# rotation - NORTH, SOUTH, EAST or WEST.
# IndividualChance - The chance each branch has to spawn, assumed to be 100 when left blank

# WBR(x,y,z,branchName,rotation,chance[,anotherBranchName,rotation,chance[,...]][MaxChanceOutOf])
# MaxChanceOutOf - The chance all branches have to spawn out of, assumed to be 100 when left blank
Branch(16,0,0,hugearchC1R1,NORTH,100)
Branch(0,0,16,hugearchC0R2,NORTH,100)
