
#######################################################################
# +-----------------------------------------------------------------+ #
# |                            BO3 object                           | #
# +-----------------------------------------------------------------+ #
#######################################################################

Author: Unknown

Description: Converted version of the BO2 OakForestLarge2

Version: 3

SettingsMode: WriteWithoutComments


#######################################################################
# +-----------------------------------------------------------------+ #
# |                          Main settings                          | #
# +-----------------------------------------------------------------+ #
#######################################################################

Tree: true

Frequency: 1

Rarity: 10.0

RotateRandomly: true

SpawnHeight: highestSolidBlock

SpawnHeightOffset: 0

SpawnHeightVariance: 0

##############################
# Height Limits for the BO3. #
##############################

MinHeight: 62

MaxHeight: 210

######################
# Extrusion settings #
######################

ExtrudeMode: None

ExtrudeThroughBlocks: AIR

MaxBranchDepth: 10

ExcludedBiomes: All


#######################################################################
# +-----------------------------------------------------------------+ #
# |                      Source block settings                      | #
# +-----------------------------------------------------------------+ #
#######################################################################

SourceBlocks: STONE:1,STONE:3,STONE:5,DIRT:1,DIRT,SAND,GRASS,DIRT:2,STATIONARY_WATER,HARD_CLAY,STAINED_CLAY,CLAY,SANDSTONE,SAND:1,AIR,STONE,GRAVEL,LONG_GRASS,LONG_GRASS:1,LONG_GRASS:2,DEAD_BUSH,YELLOW_FLOWER,RED_ROSE,BROWN_MUSHROOM,RED_MUSHROOM,biomesoplenty:plant_0,biomesoplenty:flower_0

MaxPercentageOutsideSourceBlock: 0

OutsideSourceBlock: placeAnyway

DoReplaceBlocks: true

IsOTGPlus: false


#######################################################################
# +-----------------------------------------------------------------+ #
# |                              Blocks                             | #
# +-----------------------------------------------------------------+ #
#######################################################################

Block(-4,9,2,biomesoplenty:leaves_3:2)
Block(2,10,4,biomesoplenty:leaves_3:2)
Block(-4,5,2,biomesoplenty:leaves_3:2)
Block(-4,4,2,biomesoplenty:leaves_3:2)
Block(-3,7,4,biomesoplenty:leaves_3:2)
Block(-3,6,4,biomesoplenty:leaves_3:2)
Block(-3,9,4,biomesoplenty:leaves_3:2)
Block(-3,8,4,biomesoplenty:leaves_3:2)
Block(-3,5,4,biomesoplenty:leaves_3:2)
Block(-3,4,4,biomesoplenty:leaves_3:2)
Block(-3,10,2,biomesoplenty:leaves_3:2)
Block(-4,11,-1,biomesoplenty:leaves_3:2)
Block(-3,13,2,biomesoplenty:leaves_3:2)
Block(-3,12,2,biomesoplenty:leaves_3:2)
Block(-2,9,6,biomesoplenty:leaves_3:2)
Block(-3,11,2,biomesoplenty:leaves_3:2)
Block(-2,8,6,biomesoplenty:leaves_3:2)
Block(-1,11,7,biomesoplenty:leaves_3:2)
Block(-1,10,7,biomesoplenty:leaves_3:2)
Block(-2,11,-3,biomesoplenty:leaves_3:2)
Block(-3,5,-2,biomesoplenty:leaves_3:2)
Block(-3,6,-2,biomesoplenty:leaves_3:2)
Block(-3,7,-2,biomesoplenty:leaves_3:2)
Block(-3,8,-2,biomesoplenty:leaves_3:2)
Block(1,12,1,biomesoplenty:leaves_3:2)
Block(-3,9,-2,biomesoplenty:leaves_3:2)
Block(-7,11,2,biomesoplenty:leaves_3:2)
Block(-7,10,2,biomesoplenty:leaves_3:2)
Block(-4,4,1,biomesoplenty:leaves_3:2)
Block(1,8,-3,biomesoplenty:leaves_3:2)
Block(-3,8,3,biomesoplenty:leaves_3:2)
Block(-3,7,3,biomesoplenty:leaves_3:2)
Block(-5,10,7,biomesoplenty:leaves_3:2)
Block(1,12,2,biomesoplenty:leaves_3:2)
Block(-3,9,3,biomesoplenty:log_3)
Block(-3,4,3,biomesoplenty:log_3)
Block(-3,6,3,biomesoplenty:leaves_3:2)
Block(-3,5,3,biomesoplenty:leaves_3:2)
Block(-2,9,5,biomesoplenty:leaves_3:2)
Block(-2,8,5,biomesoplenty:leaves_3:2)
Block(-2,7,5,biomesoplenty:leaves_3:2)
Block(-2,6,5,biomesoplenty:leaves_3:2)
Block(-2,5,5,biomesoplenty:leaves_3:2)
Block(-3,5,-1,biomesoplenty:leaves_3:2)
Block(-3,6,-1,biomesoplenty:log_3)
Block(-3,7,-1,biomesoplenty:leaves_3:2)
Block(-3,8,-1,biomesoplenty:leaves_3:2)
Block(-3,9,-1,biomesoplenty:leaves_3:2)
Block(-3,11,3,biomesoplenty:leaves_3:2)
Block(-3,10,3,biomesoplenty:leaves_3:2)
Block(-5,7,0,biomesoplenty:leaves_3:2)
Block(-5,6,0,biomesoplenty:leaves_3:2)
Block(-4,8,4,biomesoplenty:leaves_3:2)
Block(-4,7,4,biomesoplenty:leaves_3:2)
Block(-4,6,4,biomesoplenty:leaves_3:2)
Block(-3,13,3,biomesoplenty:leaves_3:2)
Block(-4,5,4,biomesoplenty:log_3)
Block(-3,12,3,biomesoplenty:leaves_3:2)
Block(0,7,0,biomesoplenty:log_3)
Block(0,6,0,biomesoplenty:leaves_3:2)
Block(-4,9,4,biomesoplenty:leaves_3:2)
Block(-2,13,0,biomesoplenty:leaves_3:2)
Block(-2,12,0,biomesoplenty:leaves_3:2)
Block(-4,4,4,biomesoplenty:leaves_3:2)
Block(-2,11,0,biomesoplenty:leaves_3:2)
Block(-2,10,0,biomesoplenty:log_3)
Block(-3,9,6,biomesoplenty:leaves_3:2)
Block(-3,8,6,biomesoplenty:leaves_3:2)
Block(1,8,-2,biomesoplenty:leaves_3:2)
Block(1,9,-2,biomesoplenty:leaves_3:2)
Block(-3,4,6,biomesoplenty:leaves_3:2)
Block(1,7,-2,biomesoplenty:leaves_3:2)
Block(-2,7,-5,biomesoplenty:leaves_3:2)
Block(-3,6,6,biomesoplenty:leaves_3:2)
Block(-2,8,-5,biomesoplenty:leaves_3:2)
Block(-1,12,5,biomesoplenty:leaves_3:2)
Block(-4,8,-1,biomesoplenty:leaves_3:2)
Block(-4,7,-1,biomesoplenty:leaves_3:2)
Block(-4,9,-1,biomesoplenty:leaves_3:2)
Block(-4,10,3,biomesoplenty:leaves_3:2)
Block(-4,6,-1,biomesoplenty:leaves_3:2)
Block(-4,11,3,biomesoplenty:leaves_3:2)
Block(-4,12,3,biomesoplenty:leaves_3:2)
Block(0,8,1,biomesoplenty:leaves_3:2)
Block(2,9,-1,biomesoplenty:leaves_3:2)
Block(0,7,1,biomesoplenty:leaves_3:2)
Block(2,8,-1,biomesoplenty:leaves_3:2)
Block(2,7,-1,biomesoplenty:leaves_3:2)
Block(0,9,1,biomesoplenty:leaves_3:2)
Block(-6,10,1,biomesoplenty:leaves_3:2)
Block(-6,11,1,biomesoplenty:leaves_3:2)
Block(-4,9,3,biomesoplenty:leaves_3:2)
Block(-4,8,3,biomesoplenty:leaves_3:2)
Block(-4,6,3,biomesoplenty:leaves_3:2)
Block(-4,10,4,biomesoplenty:leaves_3:2)
Block(-4,11,4,biomesoplenty:leaves_3:2)
Block(-1,11,6,biomesoplenty:leaves_3:2)
Block(-1,10,6,biomesoplenty:leaves_3:2)
Block(-4,12,4,biomesoplenty:leaves_3:2)
Block(-4,5,3,biomesoplenty:leaves_3:2)
Block(-4,4,3,biomesoplenty:leaves_3:2)
Block(-3,9,5,biomesoplenty:leaves_3:2)
Block(1,9,-1,biomesoplenty:leaves_3:2)
Block(-3,6,5,biomesoplenty:leaves_3:2)
Block(1,7,-1,biomesoplenty:leaves_3:2)
Block(-3,5,5,biomesoplenty:leaves_3:2)
Block(1,8,-1,biomesoplenty:log_3)
Block(-3,8,5,biomesoplenty:log_3)
Block(-2,7,-6,biomesoplenty:leaves_3:2)
Block(-3,7,5,biomesoplenty:leaves_3:2)
Block(-3,4,5,biomesoplenty:leaves_3:2)
Block(-6,11,2,biomesoplenty:leaves_3:2)
Block(-3,12,4,biomesoplenty:log_3)
Block(-6,10,2,biomesoplenty:leaves_3:2)
Block(-3,11,4,biomesoplenty:leaves_3:2)
Block(-3,10,4,biomesoplenty:leaves_3:2)
Block(-6,12,2,biomesoplenty:leaves_3:2)
Block(-2,9,7,biomesoplenty:leaves_3:2)
Block(-3,13,4,biomesoplenty:leaves_3:2)
Block(1,10,3,biomesoplenty:leaves_3:2)
Block(2,8,-2,biomesoplenty:leaves_3:2)
Block(0,9,0,biomesoplenty:leaves_3:2)
Block(0,8,0,biomesoplenty:leaves_3:2)
Block(-5,4,2,biomesoplenty:leaves_3:2)
Block(-4,6,6,biomesoplenty:leaves_3:2)
Block(-4,9,6,biomesoplenty:log_3)
Block(-4,8,6,biomesoplenty:leaves_3:2)
Block(0,7,-4,biomesoplenty:leaves_3:2)
Block(-4,7,6,biomesoplenty:leaves_3:2)
Block(-4,11,2,biomesoplenty:leaves_3:2)
Block(-4,10,2,biomesoplenty:log_3)
Block(-2,9,-3,biomesoplenty:leaves_3:2)
Block(2,7,6,biomesoplenty:leaves_3:2)
Block(-2,8,-3,biomesoplenty:leaves_3:2)
Block(-3,9,8,biomesoplenty:leaves_3:2)
Block(0,13,1,biomesoplenty:leaves_3:2)
Block(-2,7,-3,biomesoplenty:log_3)
Block(1,10,4,biomesoplenty:leaves_3:2)
Block(0,12,1,biomesoplenty:leaves_3:2)
Block(-2,6,-3,biomesoplenty:leaves_3:2)
Block(2,9,6,biomesoplenty:leaves_3:2)
Block(2,8,6,biomesoplenty:leaves_3:2)
Block(-4,6,-3,biomesoplenty:leaves_3:2)
Block(-4,8,-3,biomesoplenty:leaves_3:2)
Block(-4,7,-3,biomesoplenty:leaves_3:2)
Block(3,8,4,biomesoplenty:leaves_3:2)
Block(3,7,4,biomesoplenty:leaves_3:2)
Block(3,9,4,biomesoplenty:leaves_3:2)
Block(-5,6,3,biomesoplenty:leaves_3:2)
Block(-5,5,3,biomesoplenty:leaves_3:2)
Block(-1,10,-2,biomesoplenty:leaves_3:2)
Block(-1,11,-2,biomesoplenty:leaves_3:2)
Block(-5,9,3,biomesoplenty:leaves_3:2)
Block(4,8,2,biomesoplenty:leaves_3:2)
Block(-3,11,5,biomesoplenty:leaves_3:2)
Block(-3,12,5,biomesoplenty:leaves_3:2)
Block(-5,4,3,biomesoplenty:leaves_3:2)
Block(2,8,-3,biomesoplenty:leaves_3:2)
Block(-4,7,5,biomesoplenty:leaves_3:2)
Block(-4,6,5,biomesoplenty:leaves_3:2)
Block(-4,5,5,biomesoplenty:leaves_3:2)
Block(-4,4,5,biomesoplenty:leaves_3:2)
Block(0,7,-5,biomesoplenty:leaves_3:2)
Block(-4,9,5,biomesoplenty:leaves_3:2)
Block(-4,8,5,biomesoplenty:leaves_3:2)
Block(-3,8,7,biomesoplenty:leaves_3:2)
Block(-2,12,-1,biomesoplenty:leaves_3:2)
Block(-2,10,-1,biomesoplenty:leaves_3:2)
Block(-3,9,7,biomesoplenty:leaves_3:2)
Block(-1,10,-1,biomesoplenty:leaves_3:2)
Block(-2,11,-1,biomesoplenty:log_3)
Block(-2,6,-4,biomesoplenty:leaves_3:2)
Block(-2,7,-4,biomesoplenty:leaves_3:2)
Block(-2,8,-4,biomesoplenty:log_3)
Block(-2,9,-4,biomesoplenty:leaves_3:2)
Block(2,7,7,biomesoplenty:leaves_3:2)
Block(-4,7,-2,biomesoplenty:log_3)
Block(-4,6,-2,biomesoplenty:leaves_3:2)
Block(-4,8,-2,biomesoplenty:leaves_3:2)
Block(3,7,5,biomesoplenty:leaves_3:2)
Block(-2,13,1,biomesoplenty:leaves_3:2)
Block(3,9,5,biomesoplenty:leaves_3:2)
Block(-1,7,-6,biomesoplenty:leaves_3:2)
Block(3,8,5,biomesoplenty:leaves_3:2)
Block(-2,10,1,biomesoplenty:leaves_3:2)
Block(-1,11,-1,biomesoplenty:leaves_3:2)
Block(-1,12,-1,biomesoplenty:leaves_3:2)
Block(-2,12,1,biomesoplenty:leaves_3:2)
Block(-2,11,1,biomesoplenty:leaves_3:2)
Block(-5,5,4,biomesoplenty:leaves_3:2)
Block(-5,4,4,biomesoplenty:leaves_3:2)
Block(-5,7,4,biomesoplenty:leaves_3:2)
Block(0,12,0,biomesoplenty:leaves_3:2)
Block(-5,6,4,biomesoplenty:leaves_3:2)
Block(0,11,0,biomesoplenty:leaves_3:2)
Block(-5,9,4,biomesoplenty:leaves_3:2)
Block(-5,8,4,biomesoplenty:leaves_3:2)
Block(4,8,3,biomesoplenty:leaves_3:2)
Block(-5,10,4,biomesoplenty:leaves_3:2)
Block(-4,12,2,biomesoplenty:leaves_3:2)
Block(0,10,0,biomesoplenty:leaves_3:2)
Block(3,8,-1,biomesoplenty:leaves_3:2)
Block(0,8,-2,biomesoplenty:leaves_3:2)
Block(0,7,-2,biomesoplenty:leaves_3:2)
Block(0,9,-2,biomesoplenty:leaves_3:2)
Block(-2,10,-2,biomesoplenty:leaves_3:2)
Block(-2,10,3,biomesoplenty:log_3)
Block(-2,9,-1,biomesoplenty:leaves_3:2)
Block(-1,11,-3,biomesoplenty:leaves_3:2)
Block(-2,8,-1,biomesoplenty:leaves_3:2)
Block(-2,7,-1,biomesoplenty:leaves_3:2)
Block(-2,6,-1,biomesoplenty:log_3)
Block(-2,5,-1,biomesoplenty:leaves_3:2)
Block(3,8,6,biomesoplenty:leaves_3:2)
Block(3,7,6,biomesoplenty:leaves_3:2)
Block(-2,13,3,biomesoplenty:log_3)
Block(-6,6,3,biomesoplenty:leaves_3:2)
Block(-4,7,-5,biomesoplenty:leaves_3:2)
Block(-2,14,3,biomesoplenty:leaves_3:2)
Block(-2,11,3,biomesoplenty:log_3)
Block(-6,4,3,biomesoplenty:leaves_3:2)
Block(-2,12,3,biomesoplenty:log_3)
Block(1,11,5,biomesoplenty:leaves_3:2)
Block(-5,6,5,biomesoplenty:log_3)
Block(-5,5,5,biomesoplenty:leaves_3:2)
Block(1,10,5,biomesoplenty:leaves_3:2)
Block(-5,8,5,biomesoplenty:leaves_3:2)
Block(-5,7,5,biomesoplenty:leaves_3:2)
Block(-5,9,5,biomesoplenty:leaves_3:2)
Block(-5,10,6,biomesoplenty:leaves_3:2)
Block(-4,11,0,biomesoplenty:leaves_3:2)
Block(4,8,4,biomesoplenty:leaves_3:2)
Block(-3,10,-1,biomesoplenty:leaves_3:2)
Block(-3,11,-1,biomesoplenty:leaves_3:2)
Block(-3,12,-1,biomesoplenty:leaves_3:2)
Block(0,12,2,biomesoplenty:leaves_3:2)
Block(-4,11,-2,biomesoplenty:leaves_3:2)
Block(0,7,-3,biomesoplenty:leaves_3:2)
Block(-4,9,7,biomesoplenty:leaves_3:2)
Block(-4,8,7,biomesoplenty:leaves_3:2)
Block(-4,6,7,biomesoplenty:leaves_3:2)
Block(0,8,-3,biomesoplenty:leaves_3:2)
Block(-5,9,7,biomesoplenty:leaves_3:2)
Block(-1,12,-2,biomesoplenty:leaves_3:2)
Block(-2,12,2,biomesoplenty:log_3)
Block(-2,13,2,biomesoplenty:leaves_3:2)
Block(-2,10,2,biomesoplenty:leaves_3:2)
Block(-2,9,-2,biomesoplenty:leaves_3:2)
Block(-2,8,-2,biomesoplenty:leaves_3:2)
Block(-4,12,1,biomesoplenty:leaves_3:2)
Block(-4,11,1,biomesoplenty:leaves_3:2)
Block(-2,7,-2,biomesoplenty:leaves_3:2)
Block(-2,6,-2,biomesoplenty:log_3)
Block(-2,5,-2,biomesoplenty:leaves_3:2)
Block(-4,7,-4,biomesoplenty:leaves_3:2)
Block(-4,10,1,biomesoplenty:leaves_3:2)
Block(-6,9,4,biomesoplenty:leaves_3:2)
Block(-6,7,4,biomesoplenty:leaves_3:2)
Block(-6,6,4,biomesoplenty:leaves_3:2)
Block(-6,5,4,biomesoplenty:leaves_3:2)
Block(-2,12,-2,biomesoplenty:leaves_3:2)
Block(-2,11,-2,biomesoplenty:leaves_3:2)
Block(-5,7,6,biomesoplenty:leaves_3:2)
Block(-5,6,6,biomesoplenty:leaves_3:2)
Block(-5,9,6,biomesoplenty:leaves_3:2)
Block(-5,8,6,biomesoplenty:leaves_3:2)
Block(4,8,5,biomesoplenty:leaves_3:2)
Block(-4,9,8,biomesoplenty:leaves_3:2)
Block(1,9,4,biomesoplenty:leaves_3:2)
Block(1,8,4,biomesoplenty:leaves_3:2)
Block(1,7,4,biomesoplenty:leaves_3:2)
Block(1,6,4,biomesoplenty:leaves_3:2)
Block(1,5,4,biomesoplenty:leaves_3:2)
Block(-5,9,8,biomesoplenty:leaves_3:2)
Block(-2,13,4,biomesoplenty:leaves_3:2)
Block(-2,12,4,biomesoplenty:leaves_3:2)
Block(2,9,2,biomesoplenty:leaves_3:2)
Block(2,8,2,biomesoplenty:leaves_3:2)
Block(2,7,2,biomesoplenty:leaves_3:2)
Block(-6,9,6,biomesoplenty:leaves_3:2)
Block(-3,11,-2,biomesoplenty:leaves_3:2)
Block(-5,6,-2,biomesoplenty:leaves_3:2)
Block(-3,10,-2,biomesoplenty:leaves_3:2)
Block(-1,10,1,biomesoplenty:leaves_3:2)
Block(-1,11,1,biomesoplenty:leaves_3:2)
Block(-3,12,-2,biomesoplenty:leaves_3:2)
Block(-1,12,1,biomesoplenty:leaves_3:2)
Block(-1,13,1,biomesoplenty:log_3)
Block(-5,7,-2,biomesoplenty:leaves_3:2)
Block(-1,14,1,biomesoplenty:leaves_3:2)
Block(-5,8,-2,biomesoplenty:leaves_3:2)
Block(-1,5,0,biomesoplenty:leaves_3:2)
Block(3,8,0,biomesoplenty:leaves_3:2)
Block(-1,7,0,biomesoplenty:leaves_3:2)
Block(-1,6,0,biomesoplenty:leaves_3:2)
Block(-1,9,0,biomesoplenty:leaves_3:2)
Block(-1,8,0,biomesoplenty:leaves_3:2)
Block(-6,9,5,biomesoplenty:leaves_3:2)
Block(-6,7,5,biomesoplenty:leaves_3:2)
Block(-6,6,5,biomesoplenty:leaves_3:2)
Block(-1,9,-3,biomesoplenty:leaves_3:2)
Block(-1,8,-3,biomesoplenty:leaves_3:2)
Block(-1,7,-3,biomesoplenty:leaves_3:2)
Block(-1,6,-3,biomesoplenty:leaves_3:2)
Block(-5,10,2,biomesoplenty:leaves_3:2)
Block(-5,11,2,biomesoplenty:log_3)
Block(-5,12,2,biomesoplenty:leaves_3:2)
Block(-5,6,7,biomesoplenty:leaves_3:2)
Block(0,8,7,biomesoplenty:leaves_3:2)
Block(1,9,5,biomesoplenty:leaves_3:2)
Block(1,8,5,biomesoplenty:leaves_3:2)
Block(0,7,-1,biomesoplenty:leaves_3:2)
Block(1,7,5,biomesoplenty:log_3)
Block(0,6,-1,biomesoplenty:leaves_3:2)
Block(1,6,5,biomesoplenty:leaves_3:2)
Block(1,5,5,biomesoplenty:leaves_3:2)
Block(0,9,-1,biomesoplenty:leaves_3:2)
Block(0,8,-1,biomesoplenty:leaves_3:2)
Block(2,8,3,biomesoplenty:log_3)
Block(2,7,3,biomesoplenty:leaves_3:2)
Block(2,9,3,biomesoplenty:leaves_3:2)
Block(2,6,3,biomesoplenty:leaves_3:2)
Block(-6,9,7,biomesoplenty:leaves_3:2)
Block(0,10,3,biomesoplenty:leaves_3:2)
Block(-7,6,4,biomesoplenty:leaves_3:2)
Block(0,12,3,biomesoplenty:leaves_3:2)
Block(-5,7,-3,biomesoplenty:leaves_3:2)
Block(-1,6,-2,biomesoplenty:leaves_3:2)
Block(-7,9,5,biomesoplenty:leaves_3:2)
Block(3,8,1,biomesoplenty:leaves_3:2)
Block(-6,7,6,biomesoplenty:leaves_3:2)
Block(-6,6,6,biomesoplenty:leaves_3:2)
Block(-5,12,1,biomesoplenty:leaves_3:2)
Block(-1,9,-2,biomesoplenty:leaves_3:2)
Block(-1,8,-2,biomesoplenty:leaves_3:2)
Block(-1,7,-2,biomesoplenty:leaves_3:2)
Block(-2,11,4,biomesoplenty:leaves_3:2)
Block(-2,10,4,biomesoplenty:log_3)
Block(-1,10,2,biomesoplenty:leaves_3:2)
Block(-3,11,-3,biomesoplenty:leaves_3:2)
Block(0,10,-1,biomesoplenty:leaves_3:2)
Block(-1,12,2,biomesoplenty:leaves_3:2)
Block(-1,11,2,biomesoplenty:leaves_3:2)
Block(0,7,6,biomesoplenty:leaves_3:2)
Block(0,6,6,biomesoplenty:leaves_3:2)
Block(0,11,-1,biomesoplenty:leaves_3:2)
Block(-1,13,2,biomesoplenty:leaves_3:2)
Block(0,9,6,biomesoplenty:leaves_3:2)
Block(0,8,6,biomesoplenty:leaves_3:2)
Block(1,8,6,biomesoplenty:log_3)
Block(1,7,6,biomesoplenty:leaves_3:2)
Block(1,6,6,biomesoplenty:leaves_3:2)
Block(1,9,6,biomesoplenty:leaves_3:2)
Block(2,7,4,biomesoplenty:leaves_3:2)
Block(2,6,4,biomesoplenty:leaves_3:2)
Block(2,9,4,biomesoplenty:leaves_3:2)
Block(2,8,4,biomesoplenty:leaves_3:2)
Block(-6,9,8,biomesoplenty:leaves_3:2)
Block(-7,6,5,biomesoplenty:leaves_3:2)
Block(0,11,5,biomesoplenty:leaves_3:2)
Block(0,10,5,biomesoplenty:leaves_3:2)
Block(-1,5,2,biomesoplenty:leaves_3:2)
Block(-1,7,2,biomesoplenty:leaves_3:2)
Block(-7,9,6,biomesoplenty:leaves_3:2)
Block(-1,6,2,biomesoplenty:leaves_3:2)
Block(3,9,2,biomesoplenty:leaves_3:2)
Block(3,8,2,biomesoplenty:leaves_3:2)
Block(-1,9,2,biomesoplenty:leaves_3:2)
Block(-1,8,2,biomesoplenty:leaves_3:2)
Block(-6,6,7,biomesoplenty:leaves_3:2)
Block(-2,9,0,biomesoplenty:leaves_3:2)
Block(-2,8,0,biomesoplenty:leaves_3:2)
Block(-2,7,0,biomesoplenty:leaves_3:2)
Block(-1,8,-5,biomesoplenty:leaves_3:2)
Block(-2,6,0,biomesoplenty:log_3)
Block(-1,7,-5,biomesoplenty:leaves_3:2)
Block(-2,5,0,biomesoplenty:leaves_3:2)
Block(-2,11,6,biomesoplenty:leaves_3:2)
Block(-2,10,6,biomesoplenty:leaves_3:2)
Block(-1,10,0,biomesoplenty:leaves_3:2)
Block(-1,11,0,biomesoplenty:leaves_3:2)
Block(-1,12,0,biomesoplenty:leaves_3:2)
Block(-1,13,0,biomesoplenty:leaves_3:2)
Block(1,7,7,biomesoplenty:leaves_3:2)
Block(1,8,7,biomesoplenty:leaves_3:2)
Block(2,6,5,biomesoplenty:leaves_3:2)
Block(-5,11,3,biomesoplenty:leaves_3:2)
Block(-5,10,3,biomesoplenty:leaves_3:2)
Block(-2,11,5,biomesoplenty:leaves_3:2)
Block(2,8,5,biomesoplenty:leaves_3:2)
Block(-2,10,5,biomesoplenty:leaves_3:2)
Block(2,7,5,biomesoplenty:leaves_3:2)
Block(-5,12,3,biomesoplenty:leaves_3:2)
Block(-5,6,-1,biomesoplenty:leaves_3:2)
Block(-5,7,-1,biomesoplenty:leaves_3:2)
Block(-7,6,6,biomesoplenty:leaves_3:2)
Block(2,9,5,biomesoplenty:leaves_3:2)
Block(-5,8,-1,biomesoplenty:leaves_3:2)
Block(-1,6,1,biomesoplenty:log_3)
Block(-1,5,1,biomesoplenty:leaves_3:2)
Block(-1,8,1,biomesoplenty:leaves_3:2)
Block(3,9,3,biomesoplenty:leaves_3:2)
Block(-1,7,1,biomesoplenty:leaves_3:2)
Block(3,8,3,biomesoplenty:leaves_3:2)
Block(3,7,3,biomesoplenty:leaves_3:2)
Block(-1,9,1,biomesoplenty:leaves_3:2)
Block(-7,9,7,biomesoplenty:leaves_3:2)
Block(-1,8,-4,biomesoplenty:leaves_3:2)
Block(-1,7,-4,biomesoplenty:leaves_3:2)
Block(0,11,4,biomesoplenty:leaves_3:2)
Block(0,10,4,biomesoplenty:leaves_3:2)
Block(1,9,0,biomesoplenty:leaves_3:2)
Block(-1,10,4,biomesoplenty:leaves_3:2)
Block(0,5,2,biomesoplenty:leaves_3:2)
Block(1,8,0,biomesoplenty:leaves_3:2)
Block(1,7,0,biomesoplenty:leaves_3:2)
Block(-6,7,-2,biomesoplenty:leaves_3:2)
Block(-3,7,0,biomesoplenty:leaves_3:2)
Block(-3,6,0,biomesoplenty:leaves_3:2)
Block(-3,9,0,biomesoplenty:leaves_3:2)
Block(-3,8,0,biomesoplenty:leaves_3:2)
Block(-3,5,0,biomesoplenty:leaves_3:2)
Block(-3,4,0,biomesoplenty:leaves_3:2)
Block(-4,10,7,biomesoplenty:leaves_3:2)
Block(-1,5,4,biomesoplenty:leaves_3:2)
Block(-1,7,4,biomesoplenty:leaves_3:2)
Block(-1,6,4,biomesoplenty:leaves_3:2)
Block(-2,9,2,biomesoplenty:log_3)
Block(-2,8,2,biomesoplenty:leaves_3:2)
Block(-1,9,4,biomesoplenty:leaves_3:2)
Block(-2,7,2,biomesoplenty:leaves_3:2)
Block(-1,8,4,biomesoplenty:leaves_3:2)
Block(-2,6,2,biomesoplenty:leaves_3:2)
Block(-2,5,2,biomesoplenty:log_3)
Block(0,6,3,biomesoplenty:leaves_3:2)
Block(0,5,3,biomesoplenty:leaves_3:2)
Block(-3,7,-6,biomesoplenty:leaves_3:2)
Block(0,8,3,biomesoplenty:leaves_3:2)
Block(-1,11,4,biomesoplenty:leaves_3:2)
Block(0,7,3,biomesoplenty:leaves_3:2)
Block(-1,12,4,biomesoplenty:leaves_3:2)
Block(0,10,6,biomesoplenty:leaves_3:2)
Block(0,9,3,biomesoplenty:leaves_3:2)
Block(0,11,6,biomesoplenty:leaves_3:2)
Block(1,9,1,biomesoplenty:leaves_3:2)
Block(1,8,1,biomesoplenty:leaves_3:2)
Block(0,6,1,biomesoplenty:leaves_3:2)
Block(1,7,1,biomesoplenty:leaves_3:2)
Block(1,6,1,biomesoplenty:leaves_3:2)
Block(-6,7,-1,biomesoplenty:leaves_3:2)
Block(-3,11,0,biomesoplenty:leaves_3:2)
Block(-3,12,0,biomesoplenty:leaves_3:2)
Block(-3,10,0,biomesoplenty:leaves_3:2)
Block(-1,6,3,biomesoplenty:leaves_3:2)
Block(-1,10,5,biomesoplenty:leaves_3:2)
Block(-1,5,3,biomesoplenty:log_3)
Block(-1,11,5,biomesoplenty:log_3)
Block(-1,8,3,biomesoplenty:leaves_3:2)
Block(-1,7,3,biomesoplenty:leaves_3:2)
Block(-2,9,1,biomesoplenty:log_3)
Block(-2,8,1,biomesoplenty:leaves_3:2)
Block(-1,9,3,biomesoplenty:leaves_3:2)
Block(-2,7,1,biomesoplenty:leaves_3:2)
Block(-2,6,1,biomesoplenty:log_3)
Block(-2,5,1,biomesoplenty:leaves_3:2)
Block(1,6,0,biomesoplenty:leaves_3:2)
Block(0,7,2,biomesoplenty:leaves_3:2)
Block(0,6,2,biomesoplenty:leaves_3:2)
Block(-3,7,-5,biomesoplenty:leaves_3:2)
Block(-6,10,3,biomesoplenty:leaves_3:2)
Block(-3,8,-5,biomesoplenty:leaves_3:2)
Block(0,9,2,biomesoplenty:leaves_3:2)
Block(0,8,2,biomesoplenty:leaves_3:2)
Block(-6,11,3,biomesoplenty:leaves_3:2)
Block(1,9,2,biomesoplenty:leaves_3:2)
Block(-4,10,6,biomesoplenty:leaves_3:2)
Block(1,8,2,biomesoplenty:leaves_3:2)
Block(1,7,2,biomesoplenty:leaves_3:2)
Block(1,6,2,biomesoplenty:leaves_3:2)
Block(-4,8,0,biomesoplenty:leaves_3:2)
Block(-4,7,0,biomesoplenty:leaves_3:2)
Block(-4,6,0,biomesoplenty:leaves_3:2)
Block(-5,10,1,biomesoplenty:leaves_3:2)
Block(-5,11,1,biomesoplenty:leaves_3:2)
Block(2,7,0,biomesoplenty:leaves_3:2)
Block(-3,9,2,biomesoplenty:leaves_3:2)
Block(-3,8,2,biomesoplenty:leaves_3:2)
Block(2,9,0,biomesoplenty:leaves_3:2)
Block(2,8,0,biomesoplenty:leaves_3:2)
Block(-3,5,2,biomesoplenty:leaves_3:2)
Block(-3,4,2,biomesoplenty:leaves_3:2)
Block(-3,7,2,biomesoplenty:leaves_3:2)
Block(-3,6,2,biomesoplenty:leaves_3:2)
Block(-1,7,-1,biomesoplenty:leaves_3:2)
Block(-1,6,-1,biomesoplenty:leaves_3:2)
Block(-1,5,-1,biomesoplenty:leaves_3:2)
Block(-2,9,4,biomesoplenty:leaves_3:2)
Block(-2,8,4,biomesoplenty:leaves_3:2)
Block(-2,7,4,biomesoplenty:log_3)
Block(-2,6,4,biomesoplenty:leaves_3:2)
Block(-2,5,4,biomesoplenty:leaves_3:2)
Block(-1,8,6,biomesoplenty:leaves_3:2)
Block(-1,9,-1,biomesoplenty:leaves_3:2)
Block(-1,8,-1,biomesoplenty:leaves_3:2)
Block(-3,7,-4,biomesoplenty:leaves_3:2)
Block(-3,8,-4,biomesoplenty:leaves_3:2)
Block(0,6,5,biomesoplenty:leaves_3:2)
Block(0,5,5,biomesoplenty:leaves_3:2)
Block(0,8,5,biomesoplenty:leaves_3:2)
Block(0,7,5,biomesoplenty:leaves_3:2)
Block(0,9,5,biomesoplenty:leaves_3:2)
Block(-3,12,1,biomesoplenty:leaves_3:2)
Block(1,9,3,biomesoplenty:leaves_3:2)
Block(-3,10,1,biomesoplenty:leaves_3:2)
Block(1,8,3,biomesoplenty:leaves_3:2)
Block(-3,11,1,biomesoplenty:leaves_3:2)
Block(1,7,3,biomesoplenty:log_3)
Block(1,6,3,biomesoplenty:leaves_3:2)
Block(1,5,3,biomesoplenty:leaves_3:2)
Block(-5,11,0,biomesoplenty:leaves_3:2)
Block(2,9,1,biomesoplenty:leaves_3:2)
Block(-3,9,1,biomesoplenty:leaves_3:2)
Block(2,8,1,biomesoplenty:leaves_3:2)
Block(2,7,1,biomesoplenty:leaves_3:2)
Block(-3,6,1,biomesoplenty:leaves_3:2)
Block(-1,11,3,biomesoplenty:leaves_3:2)
Block(-3,5,1,biomesoplenty:leaves_3:2)
Block(-1,10,3,biomesoplenty:leaves_3:2)
Block(-3,8,1,biomesoplenty:leaves_3:2)
Block(0,11,-2,biomesoplenty:leaves_3:2)
Block(-1,13,3,biomesoplenty:leaves_3:2)
Block(-1,12,3,biomesoplenty:leaves_3:2)
Block(-3,4,1,biomesoplenty:leaves_3:2)
Block(0,10,7,biomesoplenty:leaves_3:2)
Block(-1,6,5,biomesoplenty:leaves_3:2)
Block(-2,9,3,biomesoplenty:log_3)
Block(-1,5,5,biomesoplenty:leaves_3:2)
Block(-2,8,3,biomesoplenty:log_3)
Block(-2,7,3,biomesoplenty:log_3)
Block(-1,8,5,biomesoplenty:leaves_3:2)
Block(-2,6,3,biomesoplenty:log_3)
Block(-2,5,3,biomesoplenty:log_3)
Block(-2,4,3,biomesoplenty:log_3)
Block(-1,9,5,biomesoplenty:leaves_3:2)
Block(-2,3,3,biomesoplenty:log_3)
Block(-2,2,3,biomesoplenty:log_3)
Block(-2,1,3,biomesoplenty:log_3)
Block(-2,0,3,biomesoplenty:log_3)
Block(-5,10,0,biomesoplenty:leaves_3:2)
Block(-3,6,-3,biomesoplenty:leaves_3:2)
Block(-3,7,-3,biomesoplenty:leaves_3:2)
Block(0,5,4,biomesoplenty:leaves_3:2)
Block(-3,8,-3,biomesoplenty:leaves_3:2)
Block(-3,9,-3,biomesoplenty:leaves_3:2)
Block(0,7,4,biomesoplenty:leaves_3:2)
Block(0,6,4,biomesoplenty:log_3)
Block(0,9,4,biomesoplenty:leaves_3:2)
Block(0,8,4,biomesoplenty:leaves_3:2)

#######################################################################
# +-----------------------------------------------------------------+ #
# |                            BO3 checks                           | #
# +-----------------------------------------------------------------+ #
#######################################################################

BlockCheck(-2,-1,3,GRASS,DIRT,DIRT:2)

#######################################################################
# +-----------------------------------------------------------------+ #
# |                             Branches                            | #
# +-----------------------------------------------------------------+ #
#######################################################################


#######################################################################
# +-----------------------------------------------------------------+ #
# |                             Entities                            | #
# +-----------------------------------------------------------------+ #
#######################################################################


#######################################################################
# +-----------------------------------------------------------------+ #
# |                            Particles                            | #
# +-----------------------------------------------------------------+ #
#######################################################################


#######################################################################
# +-----------------------------------------------------------------+ #
# |                             Spawners                            | #
# +-----------------------------------------------------------------+ #
#######################################################################


#######################################################################
# +-----------------------------------------------------------------+ #
# |                             ModData                             | #
# +-----------------------------------------------------------------+ #
#######################################################################

