
#######################################################################
# +-----------------------------------------------------------------+ #
# |                            BO3 object                           | #
# +-----------------------------------------------------------------+ #
#######################################################################

Author: LordSmellyPants

Description: No description given

Version: 3

SettingsMode: WriteWithoutComments


#######################################################################
# +-----------------------------------------------------------------+ #
# |                          Main settings                          | #
# +-----------------------------------------------------------------+ #
#######################################################################

Tree: false

Frequency: 10

Rarity: 100.0

RotateRandomly: true

SpawnHeight: randomY

SpawnHeightOffset: 0

SpawnHeightVariance: 0

##############################
# Height Limits for the BO3. #
##############################

MinHeight: 61

MaxHeight: 111

######################
# Extrusion settings #
######################

ExtrudeMode: None

ExtrudeThroughBlocks: AIR

MaxBranchDepth: 10

ExcludedBiomes: All


#######################################################################
# +-----------------------------------------------------------------+ #
# |                      Source block settings                      | #
# +-----------------------------------------------------------------+ #
#######################################################################

SourceBlocks: AIR

MaxPercentageOutsideSourceBlock: 100

OutsideSourceBlock: placeAnyway

DoReplaceBlocks: true

IsOTGPlus: false


#######################################################################
# +-----------------------------------------------------------------+ #
# |                              Blocks                             | #
# +-----------------------------------------------------------------+ #
#######################################################################

Block(-3,-1,3,STONE)
Block(-2,-2,0,STONE)
Block(-3,-2,3,STONE)
Block(-2,-1,0,STONE)
Block(-4,0,2,STONE)
Block(1,4,-4,STONE)
Block(1,5,-4,STONE)
Block(1,2,-4,STONE)
Block(1,3,-4,STONE)
Block(1,0,-4,STONE)
Block(1,1,-4,STONE)
Block(-4,-1,-3,STONE)
Block(-4,-2,-3,STONE)
Block(4,-1,0,STONE)
Block(4,-2,0,STONE)
Block(-3,0,-2,STONE)
Block(-3,1,-2,STONE)
Block(-3,2,-2,STONE)
Block(-3,3,-2,STONE)
Block(-3,4,-2,STONE)
Block(1,10,1,STONE)
Block(-2,-1,-4,STONE)
Block(1,11,1,STONE)
Block(-2,-2,-4,STONE)
Block(-4,-2,-2,STONE)
Block(-4,-1,-2,STONE)
Block(4,-2,1,STONE)
Block(4,-1,1,STONE)
Block(-4,0,1,STONE)
Block(1,7,-3,STONE)
Block(1,8,-3,STONE)
Block(1,5,-3,STONE)
Block(1,10,2,STONE)
Block(1,6,-3,STONE)
Block(1,3,-3,STONE)
Block(1,4,-3,STONE)
Block(1,1,-3,STONE)
Block(1,13,-1,STONE)
Block(1,2,-3,STONE)
Block(1,12,-1,STONE)
Block(1,11,-1,STONE)
Block(1,0,-3,STONE)
Block(1,10,-1,STONE)
Block(-3,0,3,STONE)
Block(1,-1,-2,STONE)
Block(1,-2,-2,STONE)
Block(-3,0,-1,STONE)
Block(-3,1,-1,STONE)
Block(3,-2,-1,STONE)
Block(-3,2,-1,STONE)
Block(-3,3,-1,STONE)
Block(-3,4,-1,STONE)
Block(3,-1,-1,STONE)
Block(1,-2,3,STONE)
Block(1,-1,3,STONE)
Block(-5,0,0,STONE)
Block(2,-1,4,STONE)
Block(0,1,0,STONE)
Block(2,-2,4,STONE)
Block(5,-1,2,STONE)
Block(0,0,0,STONE)
Block(5,-2,2,STONE)
Block(0,3,0,STONE)
Block(0,2,0,STONE)
Block(0,5,0,STONE)
Block(0,4,0,STONE)
Block(0,7,0,STONE)
Block(0,6,0,STONE)
Block(0,-1,1,STONE)
Block(1,8,-2,STONE)
Block(1,9,-2,STONE)
Block(1,6,-2,STONE)
Block(1,7,-2,STONE)
Block(1,-1,4,STONE)
Block(1,4,-2,STONE)
Block(-4,-2,-1,STONE)
Block(0,-2,1,STONE)
Block(1,5,-2,STONE)
Block(-4,-1,-1,STONE)
Block(1,2,-2,STONE)
Block(1,-2,4,STONE)
Block(1,3,-2,STONE)
Block(1,0,-2,STONE)
Block(1,1,-2,STONE)
Block(2,-2,-5,STONE)
Block(2,1,-1,STONE)
Block(2,-1,-5,STONE)
Block(2,0,-1,STONE)
Block(2,5,-1,STONE)
Block(2,4,-1,STONE)
Block(2,3,-1,STONE)
Block(2,2,-1,STONE)
Block(-4,0,-1,STONE)
Block(0,8,1,STONE)
Block(2,9,-1,STONE)
Block(0,7,1,STONE)
Block(2,8,-1,STONE)
Block(2,7,-1,STONE)
Block(2,6,-1,STONE)
Block(0,9,1,STONE)
Block(-4,1,-1,STONE)
Block(1,-2,-1,STONE)
Block(1,-1,-1,STONE)
Block(2,10,2,STONE)
Block(1,9,-1,STONE)
Block(1,7,-1,STONE)
Block(1,8,-1,STONE)
Block(1,5,-1,STONE)
Block(1,6,-1,STONE)
Block(1,3,-1,STONE)
Block(1,4,-1,STONE)
Block(1,1,-1,STONE)
Block(1,2,-1,STONE)
Block(1,0,-1,STONE)
Block(5,-2,1,STONE)
Block(5,-1,1,STONE)
Block(4,-2,2,STONE)
Block(-1,-1,-1,STONE)
Block(-1,-2,-1,STONE)
Block(4,-1,2,STONE)
Block(-2,-2,1,STONE)
Block(-2,-1,1,STONE)
Block(2,0,-2,STONE)
Block(2,4,-2,STONE)
Block(2,3,-2,STONE)
Block(0,-2,0,STONE)
Block(2,2,-2,STONE)
Block(0,-1,0,STONE)
Block(2,1,-2,STONE)
Block(2,8,-2,STONE)
Block(0,9,0,STONE)
Block(2,7,-2,STONE)
Block(0,8,0,STONE)
Block(2,9,-2,STONE)
Block(0,2,-4,STONE)
Block(0,1,-4,STONE)
Block(0,4,-4,STONE)
Block(0,3,-4,STONE)
Block(4,0,1,STONE)
Block(0,0,-4,STONE)
Block(4,2,1,STONE)
Block(4,1,1,STONE)
Block(0,13,1,STONE)
Block(0,12,1,STONE)
Block(-2,2,-3,STONE)
Block(-2,1,-3,STONE)
Block(-2,0,-3,STONE)
Block(0,11,1,STONE)
Block(3,0,3,STONE)
Block(0,10,1,STONE)
Block(-2,4,-3,STONE)
Block(-2,3,-3,STONE)
Block(2,-1,3,STONE)
Block(-4,2,-3,STONE)
Block(-4,1,-3,STONE)
Block(-2,-1,3,STONE)
Block(-2,-2,3,STONE)
Block(-1,-2,-3,STONE)
Block(2,-2,3,STONE)
Block(-1,-1,-3,STONE)
Block(-1,-1,0,STONE)
Block(-1,-2,0,STONE)
Block(2,3,-3,STONE)
Block(2,2,-3,STONE)
Block(0,-1,2,STONE)
Block(2,1,-3,STONE)
Block(0,-2,2,STONE)
Block(2,0,-3,STONE)
Block(-4,0,-3,STONE)
Block(2,4,-3,STONE)
Block(-3,-1,-1,STONE)
Block(-3,-2,-1,STONE)
Block(0,1,-5,STONE)
Block(0,0,-5,STONE)
Block(0,2,-5,STONE)
Block(-1,-2,-2,STONE)
Block(-2,-2,2,STONE)
Block(-2,-1,2,STONE)
Block(2,-2,2,STONE)
Block(2,-1,2,STONE)
Block(-1,-1,-2,STONE)
Block(4,0,2,STONE)
Block(-1,10,-1,STONE)
Block(-2,2,-4,STONE)
Block(-2,0,-4,STONE)
Block(-2,1,-4,STONE)
Block(-1,11,-1,STONE)
Block(-1,12,-1,STONE)
Block(0,14,0,STONE)
Block(0,13,0,STONE)
Block(0,12,0,STONE)
Block(0,11,0,STONE)
Block(-2,-2,-2,STONE)
Block(2,0,-4,STONE)
Block(-2,-1,-2,STONE)
Block(-4,1,-2,STONE)
Block(-4,0,-2,STONE)
Block(0,10,0,STONE)
Block(-5,-1,-3,STONE)
Block(0,4,-2,STONE)
Block(3,7,-1,STONE)
Block(-5,-2,-3,STONE)
Block(5,0,1,STONE)
Block(0,3,-2,STONE)
Block(3,8,-1,STONE)
Block(2,10,0,STONE)
Block(0,6,-2,STONE)
Block(3,9,-1,STONE)
Block(2,11,0,STONE)
Block(0,5,-2,STONE)
Block(2,12,0,STONE)
Block(-2,0,-1,STONE)
Block(0,8,-2,STONE)
Block(0,7,-2,STONE)
Block(0,9,-2,STONE)
Block(3,0,-1,STONE)
Block(3,1,-1,STONE)
Block(-2,-2,4,STONE)
Block(3,2,-1,STONE)
Block(-1,-1,-4,STONE)
Block(-2,-1,4,STONE)
Block(0,0,-2,STONE)
Block(3,3,-1,STONE)
Block(3,4,-1,STONE)
Block(0,2,-2,STONE)
Block(-1,-2,-4,STONE)
Block(0,1,-2,STONE)
Block(-2,-1,-3,STONE)
Block(-2,-2,-3,STONE)
Block(-2,4,-1,STONE)
Block(-2,3,-1,STONE)
Block(-2,2,-1,STONE)
Block(-2,1,-1,STONE)
Block(-3,-1,-2,STONE)
Block(-2,7,-1,STONE)
Block(-3,-2,-2,STONE)
Block(2,0,-5,STONE)
Block(0,10,2,STONE)
Block(0,3,-3,STONE)
Block(0,2,-3,STONE)
Block(0,5,-3,STONE)
Block(0,4,-3,STONE)
Block(0,7,-3,STONE)
Block(0,6,-3,STONE)
Block(0,9,-3,STONE)
Block(0,8,-3,STONE)
Block(0,1,-3,STONE)
Block(0,0,-3,STONE)
Block(0,-1,3,STONE)
Block(0,-2,3,STONE)
Block(-2,3,-2,STONE)
Block(-2,2,-2,STONE)
Block(-2,1,-2,STONE)
Block(-2,0,-2,STONE)
Block(-2,7,-2,STONE)
Block(-2,6,-2,STONE)
Block(-2,5,-2,STONE)
Block(-2,4,-2,STONE)
Block(-5,-1,-2,STONE)
Block(2,-1,1,STONE)
Block(-5,-2,-2,STONE)
Block(2,-2,1,STONE)
Block(-4,-2,2,STONE)
Block(-4,-1,2,STONE)
Block(-3,-2,-3,STONE)
Block(-3,-1,-3,STONE)
Block(-5,0,-2,STONE)
Block(3,0,-3,STONE)
Block(2,-1,0,STONE)
Block(2,-2,0,STONE)
Block(2,9,2,STONE)
Block(2,5,2,STONE)
Block(2,4,2,STONE)
Block(2,6,2,STONE)
Block(-1,10,1,STONE)
Block(-1,11,1,STONE)
Block(3,-2,3,STONE)
Block(3,-1,3,STONE)
Block(-1,5,0,STONE)
Block(3,8,0,STONE)
Block(-1,5,-3,STONE)
Block(-1,4,-3,STONE)
Block(-1,4,0,STONE)
Block(3,7,0,STONE)
Block(-1,3,-3,STONE)
Block(3,6,0,STONE)
Block(-1,7,0,STONE)
Block(-1,2,-3,STONE)
Block(3,5,0,STONE)
Block(-1,6,0,STONE)
Block(-1,1,-3,STONE)
Block(-1,9,0,STONE)
Block(-1,0,-3,STONE)
Block(-1,8,0,STONE)
Block(2,2,1,STONE)
Block(2,1,1,STONE)
Block(2,4,1,STONE)
Block(2,3,1,STONE)
Block(-1,8,-3,STONE)
Block(2,-2,-1,STONE)
Block(2,0,1,STONE)
Block(2,-1,-1,STONE)
Block(-4,-2,0,STONE)
Block(-4,-1,0,STONE)
Block(1,3,3,STONE)
Block(1,2,3,STONE)
Block(1,1,3,STONE)
Block(1,0,3,STONE)
Block(0,-1,-3,STONE)
Block(-1,1,0,STONE)
Block(0,-2,-3,STONE)
Block(-1,0,0,STONE)
Block(-1,3,0,STONE)
Block(-1,2,0,STONE)
Block(0,5,-1,STONE)
Block(0,-2,-2,STONE)
Block(0,4,-1,STONE)
Block(0,7,-1,STONE)
Block(0,6,-1,STONE)
Block(0,9,-1,STONE)
Block(-5,0,-3,STONE)
Block(0,8,-1,STONE)
Block(3,0,-2,STONE)
Block(3,1,-2,STONE)
Block(-5,-2,-1,STONE)
Block(0,1,-1,STONE)
Block(-5,-1,-1,STONE)
Block(0,0,-1,STONE)
Block(0,3,-1,STONE)
Block(0,2,-1,STONE)
Block(-4,-2,1,STONE)
Block(-4,-1,1,STONE)
Block(2,4,3,STONE)
Block(2,3,3,STONE)
Block(3,0,0,STONE)
Block(-3,-1,-4,STONE)
Block(-1,-1,3,STONE)
Block(3,4,0,STONE)
Block(3,3,0,STONE)
Block(-3,-2,-4,STONE)
Block(0,-1,-2,STONE)
Block(3,2,0,STONE)
Block(-1,-2,3,STONE)
Block(3,1,0,STONE)
Block(-1,6,-2,STONE)
Block(-1,5,-2,STONE)
Block(-1,4,-2,STONE)
Block(3,5,1,STONE)
Block(-1,3,-2,STONE)
Block(3,4,1,STONE)
Block(-1,2,-2,STONE)
Block(-1,1,-2,STONE)
Block(-1,0,-2,STONE)
Block(2,1,2,STONE)
Block(2,0,2,STONE)
Block(2,3,2,STONE)
Block(2,2,2,STONE)
Block(-1,9,-2,STONE)
Block(-1,-1,-5,STONE)
Block(-1,8,-2,STONE)
Block(-1,-2,-5,STONE)
Block(-1,7,-2,STONE)
Block(0,-1,4,STONE)
Block(0,-2,4,STONE)
Block(1,2,4,STONE)
Block(-1,10,2,STONE)
Block(1,1,4,STONE)
Block(1,0,4,STONE)
Block(0,10,-1,STONE)
Block(0,12,-1,STONE)
Block(3,-2,4,STONE)
Block(0,11,-1,STONE)
Block(3,-1,4,STONE)
Block(0,14,-1,STONE)
Block(0,13,-1,STONE)
Block(-1,-2,1,STONE)
Block(3,-2,-4,STONE)
Block(3,-1,-4,STONE)
Block(2,2,4,STONE)
Block(3,3,1,STONE)
Block(3,2,1,STONE)
Block(3,1,1,STONE)
Block(-1,-1,1,STONE)
Block(3,0,1,STONE)
Block(-1,3,2,STONE)
Block(-1,2,2,STONE)
Block(-1,2,-5,STONE)
Block(-1,1,-5,STONE)
Block(3,4,2,STONE)
Block(-1,5,2,STONE)
Block(-1,0,-5,STONE)
Block(3,3,2,STONE)
Block(-1,4,2,STONE)
Block(-1,6,2,STONE)
Block(2,0,3,STONE)
Block(-2,9,0,STONE)
Block(2,2,3,STONE)
Block(-2,8,0,STONE)
Block(2,1,3,STONE)
Block(-2,7,0,STONE)
Block(-2,5,0,STONE)
Block(-2,4,0,STONE)
Block(-2,3,0,STONE)
Block(-2,2,0,STONE)
Block(-2,1,0,STONE)
Block(4,4,0,STONE)
Block(3,-2,2,STONE)
Block(-2,0,0,STONE)
Block(-1,10,0,STONE)
Block(-1,11,0,STONE)
Block(3,-1,2,STONE)
Block(-1,1,2,STONE)
Block(-1,0,2,STONE)
Block(-5,0,-1,STONE)
Block(4,1,0,STONE)
Block(4,0,0,STONE)
Block(4,3,0,STONE)
Block(-2,-2,-1,STONE)
Block(-2,-1,-1,STONE)
Block(3,2,2,STONE)
Block(3,1,2,STONE)
Block(3,0,2,STONE)
Block(0,-2,-1,STONE)
Block(-1,4,1,STONE)
Block(0,-1,-1,STONE)
Block(-1,3,-4,STONE)
Block(-1,3,1,STONE)
Block(-1,2,-4,STONE)
Block(-1,6,1,STONE)
Block(-1,1,-4,STONE)
Block(-1,5,1,STONE)
Block(-3,-1,0,STONE)
Block(-1,0,-4,STONE)
Block(-1,8,1,STONE)
Block(-3,-2,0,STONE)
Block(-1,7,1,STONE)
Block(-1,9,1,STONE)
Block(2,1,4,STONE)
Block(2,0,4,STONE)
Block(4,4,1,STONE)
Block(4,3,1,STONE)
Block(-1,0,1,STONE)
Block(-1,-2,2,STONE)
Block(-1,2,1,STONE)
Block(-1,-1,2,STONE)
Block(-1,1,1,STONE)
Block(-3,1,0,STONE)
Block(0,1,2,STONE)
Block(-3,0,0,STONE)
Block(0,0,2,STONE)
Block(0,3,2,STONE)
Block(0,2,2,STONE)
Block(1,9,0,STONE)
Block(0,5,2,STONE)
Block(1,8,0,STONE)
Block(0,4,2,STONE)
Block(1,7,0,STONE)
Block(4,-2,3,STONE)
Block(4,-1,3,STONE)
Block(2,10,-2,STONE)
Block(-3,3,0,STONE)
Block(-3,2,0,STONE)
Block(-3,4,0,STONE)
Block(-1,0,4,STONE)
Block(1,-2,0,STONE)
Block(1,-1,0,STONE)
Block(5,-1,-1,STONE)
Block(5,-2,-1,STONE)
Block(-2,3,2,STONE)
Block(-2,2,2,STONE)
Block(-2,1,2,STONE)
Block(-2,0,2,STONE)
Block(3,-1,-3,STONE)
Block(1,-2,-4,STONE)
Block(3,-2,-3,STONE)
Block(1,-1,-4,STONE)
Block(0,6,3,STONE)
Block(0,5,3,STONE)
Block(0,0,1,STONE)
Block(0,2,1,STONE)
Block(0,1,1,STONE)
Block(-3,-2,1,STONE)
Block(5,-1,0,STONE)
Block(0,4,1,STONE)
Block(1,9,1,STONE)
Block(0,3,1,STONE)
Block(1,8,1,STONE)
Block(0,6,1,STONE)
Block(1,7,1,STONE)
Block(-3,-1,1,STONE)
Block(0,5,1,STONE)
Block(1,6,1,STONE)
Block(5,-2,0,STONE)
Block(-5,-2,0,STONE)
Block(2,-2,-4,STONE)
Block(-5,-1,0,STONE)
Block(2,-1,-4,STONE)
Block(3,-1,1,STONE)
Block(3,-2,1,STONE)
Block(1,-1,-5,STONE)
Block(1,-2,-5,STONE)
Block(4,0,-2,STONE)
Block(4,-1,-1,STONE)
Block(4,-2,-1,STONE)
Block(4,1,-2,STONE)
Block(-1,2,3,STONE)
Block(-1,1,3,STONE)
Block(-1,4,3,STONE)
Block(-1,3,3,STONE)
Block(-2,6,1,STONE)
Block(-2,5,1,STONE)
Block(-2,4,1,STONE)
Block(-2,3,1,STONE)
Block(-2,2,1,STONE)
Block(-2,1,1,STONE)
Block(-2,0,1,STONE)
Block(1,6,0,STONE)
Block(0,7,2,STONE)
Block(1,5,0,STONE)
Block(0,6,2,STONE)
Block(1,4,0,STONE)
Block(0,9,2,STONE)
Block(1,3,0,STONE)
Block(0,8,2,STONE)
Block(1,2,0,STONE)
Block(1,1,0,STONE)
Block(0,-2,-5,STONE)
Block(1,0,0,STONE)
Block(-1,0,3,STONE)
Block(0,-1,-5,STONE)
Block(1,9,2,STONE)
Block(5,-2,-2,STONE)
Block(0,1,4,STONE)
Block(1,8,2,STONE)
Block(5,-1,-2,STONE)
Block(0,0,4,STONE)
Block(1,7,2,STONE)
Block(1,6,2,STONE)
Block(0,2,4,STONE)
Block(1,5,2,STONE)
Block(1,-2,-3,STONE)
Block(-4,2,0,STONE)
Block(-4,1,0,STONE)
Block(2,-2,-2,STONE)
Block(2,-1,-2,STONE)
Block(-4,0,0,STONE)
Block(2,7,0,STONE)
Block(2,6,0,STONE)
Block(2,9,0,STONE)
Block(1,-1,-3,STONE)
Block(2,8,0,STONE)
Block(4,-2,-3,STONE)
Block(4,-1,-3,STONE)
Block(0,-2,-4,STONE)
Block(-3,1,2,STONE)
Block(4,0,-1,STONE)
Block(-3,0,2,STONE)
Block(0,-1,-4,STONE)
Block(-3,2,2,STONE)
Block(-1,7,-1,STONE)
Block(-1,6,-1,STONE)
Block(-1,5,-1,STONE)
Block(-1,4,-1,STONE)
Block(-1,3,-1,STONE)
Block(-1,2,-1,STONE)
Block(-3,-2,2,STONE)
Block(-1,1,-1,STONE)
Block(1,13,0,STONE)
Block(-3,-1,2,STONE)
Block(-1,0,-1,STONE)
Block(1,12,0,STONE)
Block(1,11,0,STONE)
Block(1,10,0,STONE)
Block(-1,9,-1,STONE)
Block(-2,0,4,STONE)
Block(-1,8,-1,STONE)
Block(2,10,-1,STONE)
Block(-3,0,-4,STONE)
Block(-3,1,-4,STONE)
Block(2,11,-1,STONE)
Block(-3,2,-4,STONE)
Block(1,5,1,STONE)
Block(1,4,1,STONE)
Block(1,-1,1,STONE)
Block(1,3,1,STONE)
Block(1,-2,1,STONE)
Block(1,2,1,STONE)
Block(0,10,-3,STONE)
Block(1,1,1,STONE)
Block(1,0,1,STONE)
Block(-1,-1,4,STONE)
Block(-1,-2,4,STONE)
Block(-3,0,1,STONE)
Block(0,0,3,STONE)
Block(0,2,3,STONE)
Block(0,1,3,STONE)
Block(0,4,3,STONE)
Block(1,5,3,STONE)
Block(0,3,3,STONE)
Block(1,4,3,STONE)
Block(2,9,1,STONE)
Block(2,6,1,STONE)
Block(2,5,1,STONE)
Block(3,-1,-2,STONE)
Block(2,8,1,STONE)
Block(1,1,-5,STONE)
Block(3,-2,-2,STONE)
Block(2,7,1,STONE)
Block(1,-1,2,STONE)
Block(1,0,-5,STONE)
Block(1,-2,2,STONE)
Block(0,11,-2,STONE)
Block(0,10,-2,STONE)
Block(-3,2,1,STONE)
Block(-3,1,1,STONE)
Block(-3,3,1,STONE)
Block(2,3,0,STONE)
Block(2,2,0,STONE)
Block(2,5,0,STONE)
Block(3,10,-1,STONE)
Block(2,4,0,STONE)
Block(2,-1,-3,STONE)
Block(2,1,0,STONE)
Block(-2,1,3,STONE)
Block(2,-2,-3,STONE)
Block(2,0,0,STONE)
Block(-2,0,3,STONE)
Block(3,-1,0,STONE)
Block(-3,0,-3,STONE)
Block(-3,1,-3,STONE)
Block(-3,2,-3,STONE)
Block(3,-2,0,STONE)
Block(1,10,-2,STONE)
Block(-3,3,-3,STONE)
Block(1,11,-2,STONE)
Block(1,12,-2,STONE)
Block(1,4,2,STONE)
Block(4,-1,-2,STONE)
Block(1,3,2,STONE)
Block(1,2,2,STONE)
Block(1,1,2,STONE)
Block(1,0,2,STONE)
Block(4,-2,-2,STONE)

#######################################################################
# +-----------------------------------------------------------------+ #
# |                            BO3 checks                           | #
# +-----------------------------------------------------------------+ #
#######################################################################

BlockCheck(0,1,0,AIR)
BlockCheck(0,0,0,AIR)
BlockCheck(0,-1,0,STONE)
LightCheck(0,0,0,0,2)

#######################################################################
# +-----------------------------------------------------------------+ #
# |                             Branches                            | #
# +-----------------------------------------------------------------+ #
#######################################################################


#######################################################################
# +-----------------------------------------------------------------+ #
# |                             Entities                            | #
# +-----------------------------------------------------------------+ #
#######################################################################


#######################################################################
# +-----------------------------------------------------------------+ #
# |                            Particles                            | #
# +-----------------------------------------------------------------+ #
#######################################################################


#######################################################################
# +-----------------------------------------------------------------+ #
# |                             Spawners                            | #
# +-----------------------------------------------------------------+ #
#######################################################################


#######################################################################
# +-----------------------------------------------------------------+ #
# |                             ModData                             | #
# +-----------------------------------------------------------------+ #
#######################################################################

