[META]
version=2.0
spawnOnBlockType=1
spawnSunlight=True
spawnDarkness=True
spawnWater=False
spawnLava=False
underFill=True
randomRotation=True
dig=True
tree=False
branch=False
needsFoundation=True
rarity=200
collisionPercentage=2
spawnElevationMin=80
spawnElevationMax=250
spawnInBiome=Custom
[DATA]
-2,1,0:1
-1,1,0:1
-1,0,0:1
-1,-1,0:1
0,-1,0:1
0,0,0:1
-1,1,1:1
-1,0,1:1
0,0,1:1
0,-1,1:1
0,0,2:1
-1,1,-1:1
-1,0,-1:1
0,0,-1:1
0,-1,-1:1
-1,-1,-1:1
-2,1,-1:1
-2,0,-1:1
-1,1,-2:1
-2,1,-2:1
-1,0,-2:1
0,0,-2:1
0,-1,-2:1
-1,-1,-2:1
-1,0,-3:1
0,0,-3:1
0,-1,-3:1
-1,-1,-3:1
-1,-2,-3:1
1,-1,-3:1
-1,1,-3:1
-2,0,-3:1
-2,1,-3:1
0,0,-4:1
-1,-1,-4:1
-1,-2,-4:1
-1,0,-4:1
-2,0,-4:1
-2,1,-4:1
-1,1,-4:1
0,1,-4:1
0,-1,-4:1
1,-1,-4:1
1,0,-4:1
0,-2,-4:1
2,0,-4:1
0,0,-5:1
-1,0,-5:1
-1,-1,-5:1
0,-1,-5:1
0,1,-5:1
1,1,-5:1
1,0,-5:1
1,-1,-5:1
1,-2,-5:1
0,-2,-5:1
0,-3,-5:1
2,0,-5:1
2,-1,-5:1
0,0,-6:1
0,-1,-6:1
