[META]
version=2.0
spawnOnBlockType=1
spawnSunlight=True
spawnDarkness=True
spawnWater=False
spawnLava=False
underFill=True
randomRotation=True
dig=True
tree=False
branch=False
needsFoundation=True
rarity=25
collisionPercentage=2
spawnElevationMin=80
spawnElevationMax=250
spawnInBiome=Custom
[DATA]
1,-2,0:1
1,-3,0:1
2,-2,0:1
-1,0,0:1
0,0,0:1
0,1,0:1
1,1,0:1
0,1,1:1
0,0,1:1
1,-2,1:1
0,0,2:1
1,1,-1:1
0,1,-1:1
0,0,-1:1
0,-1,-1:1
-1,-1,-1:1
-1,0,-1:1
1,-2,-1:1
2,-2,-1:1
1,-3,-1:1
1,-1,-1:1
0,0,-2:1
0,-1,-2:1
1,-1,-2:1
1,0,-2:1
2,-1,-2:1
2,-2,-2:1
1,-2,-2:1
0,-2,-2:1
1,-3,-2:1
1,1,-2:1
0,1,-2:1
-1,0,-2:1
-1,-1,-2:1
0,0,-3:1
0,-1,-3:1
1,-1,-3:1
2,-1,-3:1
2,0,-3:1
1,0,-3:1
1,1,-3:1
0,1,-3:1
-1,0,-3:1
-1,-1,-3:1
1,-2,-3:1
1,-3,-3:1
2,-2,-3:1
0,-2,-3:1
-1,0,-4:1
-1,-1,-4:1
0,-1,-4:1
1,-1,-4:1
1,-2,-4:1
1,-3,-4:1
2,-1,-4:1
2,-2,-4:1
2,0,-4:1
1,0,-4:1
1,1,-4:1
0,1,-4:1
0,0,-4:1
0,-2,-4:1
-1,0,-5:1
-1,-1,-5:1
0,-1,-5:1
0,0,-5:1
1,0,-5:1
1,-1,-5:1
2,0,-5:1
2,-1,-5:1
0,-2,-5:1
1,-2,-5:1
1,-3,-5:1
-1,-2,-5:1
1,1,-5:1
1,2,-5:1
0,1,-5:1
0,1,-6:1
0,0,-6:1
0,-1,-6:1
0,-2,-6:1
-1,-2,-6:1
-1,-1,-6:1
-1,0,-6:1
-1,1,-6:1
1,0,-6:1
1,1,-6:1
1,2,-6:1
1,-1,-6:1
1,-2,-6:1
1,-3,-6:1
2,-2,-6:1
2,-1,-6:1
2,0,-6:1
2,1,-6:1
0,2,-7:1
1,2,-7:1
1,1,-7:1
2,1,-7:1
2,0,-7:1
2,-1,-7:1
2,-2,-7:1
1,-2,-7:1
1,-1,-7:1
1,0,-7:1
0,1,-7:1
0,0,-7:1
-1,0,-7:1
-1,-1,-7:1
0,-1,-7:1
0,-2,-7:1
-1,-2,-7:1
-2,0,-7:1
-2,-1,-7:1
-1,1,-7:1
1,-3,-7:1
0,-3,-7:1
0,1,-8:1
0,0,-8:1
-1,0,-8:1
-1,-1,-8:1
0,-1,-8:1
0,-2,-8:1
1,-2,-8:1
1,-1,-8:1
1,0,-8:1
1,1,-8:1
0,2,-8:1
-1,1,-8:1
0,1,-9:1
0,0,-9:1
0,-1,-9:1
0,-2,-9:1
1,0,-9:1
1,1,-9:1
1,-1,-9:1
-1,-1,-9:1
-1,0,-9:1
-1,1,-9:1
0,2,-9:1
1,-2,-9:1
-1,-1,-10:1
-1,0,-10:1
-1,1,-10:1
0,2,-10:1
0,1,-10:1
0,0,-10:1
1,0,-10:1
1,1,-10:1
1,-1,-10:1
0,-1,-10:1
1,-2,-10:1
0,-2,-10:1
0,-1,-11:1
0,1,-11:1
0,0,-11:1
-1,0,-11:1
0,0,-12:1
