
#######################################################################
# +-----------------------------------------------------------------+ #
# |                            BO3 object                           | #
# +-----------------------------------------------------------------+ #
#######################################################################

# This is the config file of a custom object.
# If you add this object correctly to your BiomeConfigs, it will spawn in the world.

# This is the creator of this BO3 object
Author: LordSmellyPants

# A short description of this BO3 object
Description: No description given

# The BO3 version, don't change this! It can be used by external applications to do a version check.
Version: 3

# The settings mode, WriteAll, WriteWithoutComments or WriteDisable. See WorldConfig.
SettingsMode: WriteDisable


#######################################################################
# +-----------------------------------------------------------------+ #
# |                          Main settings                          | #
# +-----------------------------------------------------------------+ #
#######################################################################

# This needs to be set to true to spawn the object in the Tree and Sapling resources.
Tree: false

# The frequency of the BO3 from 1 to 200. Tries this many times to spawn this BO3 when using the CustomObject(...) resource.
# Ignored by Tree(..), Sapling(..) and CustomStructure(..)
Frequency: 1

# The rarity of the BO3 from 0 to 100. Each spawn attempt has rarity% chance to succeed when using the CustomObject(...) resource.
# Ignored by Tree(..), Sapling(..) and CustomStructure(..)
Rarity: 100.0

# If you set this to true, the BO3 will be placed with a random rotation.
RotateRandomly: true

# The spawn height of the BO3 - atMinY, randomY, highestBlock or highestSolidBlock.
SpawnHeight: highestSolidBlock

# The offset from the spawn height to spawn this BO3
# Ex. SpawnHeight = highestSolidBlock, SpawnHeightOffset = 3; This object will spawn 3 blocks above the highest solid block
SpawnHeightOffset: 0

# A random amount to offset the spawn location from the spawn offset height
# Ex. SpawnHeightOffset = 3, SpawnHeightVariance = 3; This object will spawn 3 to 6 blocks above the original spot it would have spawned
SpawnHeightVariance: 0

##############################
# Height Limits for the BO3. #
##############################

# When in randomY mode used as the minimum Y or in atMinY mode as the actual Y to spawn this BO3 at.
MinHeight: 0

# When in randomY mode used as the maximum Y to spawn this BO3 at.
MaxHeight: 256

######################
# Extrusion settings #
######################

# The style of extrusion you wish to use - BottomDown, TopUp, None (Default)
ExtrudeMode: None

# The blocks to extrude your BO3 through
ExtrudeThroughBlocks: AIR

# Objects can have other objects attacthed to it: branches. Branches can also
# have branches attached to it, which can also have branches, etc. This is the
# maximum branch depth for this objects.
MaxBranchDepth: 10

# When spawned with the UseWorld keyword, this BO3 should NOT spawn in the following biomes.
# If you write the BO3 name directly in the BiomeConfigs, this will be ignored.
ExcludedBiomes: All


#######################################################################
# +-----------------------------------------------------------------+ #
# |                      Source block settings                      | #
# +-----------------------------------------------------------------+ #
#######################################################################

# The B(s) the BO3 should spawn in.
SourceBlocks: AIR

# The maximum percentage of the BO3 that can be outside the SourceBlock.
# The BO3 won't be placed on a location with more blocks outside the SourceBlock than this percentage.
MaxPercentageOutsideSourceBlock: 100

# What to do when a block is about to be placed outside the SourceBlock? (dontPlace, placeAnyway)
OutsideSourceBlock: placeAnyway


#######################################################################
# +-----------------------------------------------------------------+ #
# |                              Blocks                             | #
# +-----------------------------------------------------------------+ #
#######################################################################

# All the blocks used in the BO3 are listed here. Possible blocks:
# B(x,y,z,id[.data][,nbtfile.nbt)
# RB(x,y,z,id[:data][,nbtfile.nbt],chance[,id[:data][,nbtfile.nbt],chance[,...]])
#  So RB(0,0,0,CHEST,chest.nbt,50,CHEST,anotherchest.nbt,100) will spawn a chest at
#  the BO3 origin, and give it a 50% chance to have the contents of chest.nbt, or, if that
#  fails, a 100% percent chance to have the contents of anotherchest.nbt.
# MinecraftObject(x,y,z,name)
#  Spawns an object in the Mojang NBT structure format. For example, 
#  MinecraftObject(0,0,0,minecraft:igloo/igloo_bottom)
#  spawns the bottom part of an igloo.
B(-7,-24,-7,COBBLESTONE)
B(-7,-24,-6,COBBLESTONE)
B(-7,-24,-5,COBBLESTONE)
B(-7,-24,-4,COBBLESTONE)
B(-7,-24,-3,COBBLESTONE)
B(-7,-24,-2,COBBLESTONE)
B(-7,-24,-1,COBBLESTONE)
B(-7,-24,0,COBBLESTONE)
B(-7,-24,1,COBBLESTONE)
B(-7,-24,2,COBBLESTONE)
B(-7,-24,3,COBBLESTONE)
B(-7,-24,4,COBBLESTONE)
B(-7,-24,5,COBBLESTONE)
B(-7,-24,6,COBBLESTONE)
B(-7,-24,7,COBBLESTONE)
B(-7,-23,-7,COBBLESTONE)
B(-7,-23,-6,COBBLESTONE)
B(-7,-23,-5,COBBLESTONE)
B(-7,-23,-4,COBBLESTONE)
B(-7,-23,-3,COBBLESTONE)
B(-7,-23,-2,COBBLESTONE)
B(-7,-23,-1,COBBLESTONE)
B(-7,-23,0,COBBLESTONE)
B(-7,-23,1,COBBLESTONE)
B(-7,-23,2,COBBLESTONE)
B(-7,-23,3,COBBLESTONE)
B(-7,-23,4,COBBLESTONE)
B(-7,-23,5,COBBLESTONE)
B(-7,-23,6,COBBLESTONE)
B(-7,-23,7,COBBLESTONE)
B(-7,-22,-7,COBBLESTONE)
B(-7,-22,-6,COBBLESTONE)
B(-7,-22,-5,COBBLESTONE)
B(-7,-22,-4,COBBLESTONE)
B(-7,-22,-3,COBBLESTONE)
B(-7,-22,-2,COBBLESTONE)
B(-7,-22,-1,COBBLESTONE)
B(-7,-22,0,COBBLESTONE)
B(-7,-22,1,COBBLESTONE)
B(-7,-22,2,COBBLESTONE)
B(-7,-22,3,COBBLESTONE)
B(-7,-22,4,COBBLESTONE)
B(-7,-22,5,COBBLESTONE)
B(-7,-22,6,COBBLESTONE)
B(-7,-22,7,COBBLESTONE)
B(-7,-21,-7,COBBLESTONE)
B(-7,-21,-6,COBBLESTONE)
B(-7,-21,-5,COBBLESTONE)
B(-7,-21,-4,COBBLESTONE)
B(-7,-21,-3,COBBLESTONE)
B(-7,-21,-2,COBBLESTONE)
B(-7,-21,-1,COBBLESTONE)
B(-7,-21,0,COBBLESTONE)
B(-7,-21,1,COBBLESTONE)
B(-7,-21,2,COBBLESTONE)
B(-7,-21,3,COBBLESTONE)
B(-7,-21,4,COBBLESTONE)
B(-7,-21,5,COBBLESTONE)
B(-7,-21,6,COBBLESTONE)
B(-7,-21,7,COBBLESTONE)
B(-7,-20,-7,COBBLESTONE)
B(-7,-20,-6,COBBLESTONE)
B(-7,-20,-5,COBBLESTONE)
B(-7,-20,-4,COBBLESTONE)
B(-7,-20,-3,COBBLESTONE)
B(-7,-20,-2,COBBLESTONE)
B(-7,-20,-1,COBBLESTONE)
B(-7,-20,0,COBBLESTONE)
B(-7,-20,1,COBBLESTONE)
B(-7,-20,2,COBBLESTONE)
B(-7,-20,3,COBBLESTONE)
B(-7,-20,4,COBBLESTONE)
B(-7,-20,5,COBBLESTONE)
B(-7,-20,6,COBBLESTONE)
B(-7,-20,7,COBBLESTONE)
B(-7,-19,-7,COBBLESTONE)
B(-7,-19,-6,COBBLESTONE)
B(-7,-19,-5,COBBLESTONE)
B(-7,-19,-4,COBBLESTONE)
B(-7,-19,-3,COBBLESTONE)
B(-7,-19,-2,COBBLESTONE)
B(-7,-19,-1,COBBLESTONE)
B(-7,-19,0,COBBLESTONE)
B(-7,-19,1,COBBLESTONE)
B(-7,-19,2,COBBLESTONE)
B(-7,-19,3,COBBLESTONE)
B(-7,-19,4,COBBLESTONE)
B(-7,-19,5,COBBLESTONE)
B(-7,-19,6,COBBLESTONE)
B(-7,-19,7,COBBLESTONE)
B(-7,-18,-7,COBBLESTONE)
B(-7,-18,-6,COBBLESTONE)
B(-7,-18,-5,COBBLESTONE)
B(-7,-18,-4,COBBLESTONE)
B(-7,-18,-3,COBBLESTONE)
B(-7,-18,-2,COBBLESTONE)
B(-7,-18,-1,COBBLESTONE)
B(-7,-18,0,COBBLESTONE)
B(-7,-18,1,COBBLESTONE)
B(-7,-18,2,COBBLESTONE)
B(-7,-18,3,COBBLESTONE)
B(-7,-18,4,COBBLESTONE)
B(-7,-18,5,COBBLESTONE)
B(-7,-18,6,COBBLESTONE)
B(-7,-18,7,COBBLESTONE)
B(-7,-17,-7,COBBLESTONE)
B(-7,-17,-6,COBBLESTONE)
B(-7,-17,-5,COBBLESTONE)
B(-7,-17,-4,COBBLESTONE)
B(-7,-17,-3,COBBLESTONE)
B(-7,-17,-2,COBBLESTONE)
B(-7,-17,-1,COBBLESTONE)
B(-7,-17,0,COBBLESTONE)
B(-7,-17,1,COBBLESTONE)
B(-7,-17,2,COBBLESTONE)
B(-7,-17,3,COBBLESTONE)
B(-7,-17,4,COBBLESTONE)
B(-7,-17,5,COBBLESTONE)
B(-7,-17,6,COBBLESTONE)
B(-7,-17,7,COBBLESTONE)
B(-7,-16,-7,COBBLESTONE)
B(-7,-16,-6,COBBLESTONE)
B(-7,-16,-5,COBBLESTONE)
B(-7,-16,-4,COBBLESTONE)
B(-7,-16,-3,COBBLESTONE)
B(-7,-16,-2,COBBLESTONE)
B(-7,-16,-1,COBBLESTONE)
B(-7,-16,0,COBBLESTONE)
B(-7,-16,1,COBBLESTONE)
B(-7,-16,2,COBBLESTONE)
B(-7,-16,3,COBBLESTONE)
B(-7,-16,4,COBBLESTONE)
B(-7,-16,5,COBBLESTONE)
B(-7,-16,6,COBBLESTONE)
B(-7,-16,7,COBBLESTONE)
B(-7,-15,-7,COBBLESTONE)
B(-7,-15,-6,COBBLESTONE)
B(-7,-15,-5,COBBLESTONE)
B(-7,-15,-4,COBBLESTONE)
B(-7,-15,-3,COBBLESTONE)
B(-7,-15,-2,COBBLESTONE)
B(-7,-15,-1,COBBLESTONE)
B(-7,-15,0,COBBLESTONE)
B(-7,-15,1,COBBLESTONE)
B(-7,-15,2,COBBLESTONE)
B(-7,-15,3,COBBLESTONE)
B(-7,-15,4,COBBLESTONE)
B(-7,-15,5,COBBLESTONE)
B(-7,-15,6,COBBLESTONE)
B(-7,-15,7,COBBLESTONE)
B(-7,-14,-7,COBBLESTONE)
B(-7,-14,-6,COBBLESTONE)
B(-7,-14,-5,COBBLESTONE)
B(-7,-14,-4,COBBLESTONE)
B(-7,-14,-3,COBBLESTONE)
B(-7,-14,-2,COBBLESTONE)
B(-7,-14,-1,COBBLESTONE)
B(-7,-14,0,COBBLESTONE)
B(-7,-14,1,COBBLESTONE)
B(-7,-14,2,COBBLESTONE)
B(-7,-14,3,COBBLESTONE)
B(-7,-14,4,COBBLESTONE)
B(-7,-14,5,COBBLESTONE)
B(-7,-14,6,COBBLESTONE)
B(-7,-14,7,COBBLESTONE)
B(-7,-13,-7,COBBLESTONE)
B(-7,-13,-6,COBBLESTONE)
B(-7,-13,-5,COBBLESTONE)
B(-7,-13,-4,COBBLESTONE)
B(-7,-13,-3,COBBLESTONE)
B(-7,-13,-2,COBBLESTONE)
B(-7,-13,-1,COBBLESTONE)
B(-7,-13,0,COBBLESTONE)
B(-7,-13,1,COBBLESTONE)
B(-7,-13,2,COBBLESTONE)
B(-7,-13,3,COBBLESTONE)
B(-7,-13,4,COBBLESTONE)
B(-7,-13,5,COBBLESTONE)
B(-7,-13,6,COBBLESTONE)
B(-7,-13,7,COBBLESTONE)
B(-7,-12,-5,COBBLESTONE)
B(-7,-12,-4,COBBLESTONE)
B(-7,-12,-3,COBBLESTONE)
B(-7,-12,3,COBBLESTONE)
B(-7,-12,4,COBBLESTONE)
B(-7,-12,5,COBBLESTONE)
B(-7,-11,-5,COBBLESTONE)
B(-7,-11,-4,COBBLESTONE)
B(-7,-11,-3,COBBLESTONE)
B(-7,-11,3,COBBLESTONE)
B(-7,-11,4,COBBLESTONE)
B(-7,-11,5,COBBLESTONE)
B(-7,-10,-5,COBBLESTONE)
B(-7,-10,-4,COBBLESTONE)
B(-7,-10,-3,COBBLESTONE)
B(-7,-10,3,COBBLESTONE)
B(-7,-10,4,COBBLESTONE)
B(-7,-10,5,COBBLESTONE)
B(-7,-9,-5,COBBLESTONE)
B(-7,-9,-4,COBBLESTONE)
B(-7,-9,-3,COBBLESTONE)
B(-7,-9,3,COBBLESTONE)
B(-7,-9,4,COBBLESTONE)
B(-7,-9,5,COBBLESTONE)
B(-7,-8,-5,COBBLESTONE)
B(-7,-8,-4,COBBLESTONE)
B(-7,-8,-3,COBBLESTONE)
B(-7,-8,3,COBBLESTONE)
B(-7,-8,4,COBBLESTONE)
B(-7,-8,5,COBBLESTONE)
B(-7,-7,-5,COBBLESTONE)
B(-7,-7,-4,COBBLESTONE)
B(-7,-7,-3,COBBLESTONE)
B(-7,-7,3,COBBLESTONE)
B(-7,-7,4,COBBLESTONE)
B(-7,-7,5,COBBLESTONE)
B(-7,-6,-5,COBBLESTONE)
B(-7,-6,-4,COBBLESTONE)
B(-7,-6,-3,COBBLESTONE)
B(-7,-6,3,COBBLESTONE)
B(-7,-6,4,COBBLESTONE)
B(-7,-6,5,COBBLESTONE)
B(-7,-5,-5,COBBLESTONE)
B(-7,-5,-4,COBBLESTONE)
B(-7,-5,-3,COBBLESTONE)
B(-7,-5,3,COBBLESTONE)
B(-7,-5,4,COBBLESTONE)
B(-7,-5,5,COBBLESTONE)
B(-7,-4,-5,COBBLESTONE)
B(-7,-4,-4,COBBLESTONE)
B(-7,-4,-3,COBBLESTONE)
B(-7,-4,3,COBBLESTONE)
B(-7,-4,4,COBBLESTONE)
B(-7,-4,5,COBBLESTONE)
B(-7,-3,-5,COBBLESTONE)
B(-7,-3,-4,COBBLESTONE)
B(-7,-3,-3,COBBLESTONE)
B(-7,-3,3,COBBLESTONE)
B(-7,-3,4,COBBLESTONE)
B(-7,-3,5,COBBLESTONE)
B(-7,-2,-5,COBBLESTONE)
B(-7,-2,-4,COBBLESTONE)
B(-7,-2,-3,COBBLESTONE)
B(-7,-2,3,COBBLESTONE)
B(-7,-2,4,COBBLESTONE)
B(-7,-2,5,COBBLESTONE)
B(-7,-1,-5,COBBLESTONE)
B(-7,-1,-4,COBBLESTONE)
B(-7,-1,-3,COBBLESTONE)
B(-7,-1,3,COBBLESTONE)
B(-7,-1,4,COBBLESTONE)
B(-7,-1,5,COBBLESTONE)
B(-7,0,-7,AIR)
B(-7,0,-6,AIR)
B(-7,0,-5,SMOOTH_BRICK)
B(-7,0,-4,AIR)
B(-7,0,-3,SMOOTH_BRICK)
B(-7,0,-2,AIR)
B(-7,0,-1,AIR)
B(-7,0,0,AIR)
B(-7,0,1,AIR)
B(-7,0,2,AIR)
B(-7,0,3,SMOOTH_BRICK)
B(-7,0,4,AIR)
B(-7,0,5,SMOOTH_BRICK)
B(-7,0,6,AIR)
B(-7,0,7,AIR)
B(-7,1,-7,AIR)
B(-7,1,-6,AIR)
B(-7,1,-5,SMOOTH_BRICK)
B(-7,1,-4,AIR)
B(-7,1,-3,SMOOTH_BRICK)
B(-7,1,-2,AIR)
B(-7,1,-1,AIR)
B(-7,1,0,AIR)
B(-7,1,1,AIR)
B(-7,1,2,AIR)
B(-7,1,3,SMOOTH_BRICK)
B(-7,1,4,AIR)
B(-7,1,5,SMOOTH_BRICK)
B(-7,1,6,AIR)
B(-7,1,7,AIR)
B(-7,2,-7,AIR)
B(-7,2,-6,AIR)
B(-7,2,-5,SMOOTH_BRICK)
B(-7,2,-4,SMOOTH_BRICK:3)
B(-7,2,-3,SMOOTH_BRICK)
B(-7,2,-2,AIR)
B(-7,2,-1,AIR)
B(-7,2,0,AIR)
B(-7,2,1,AIR)
B(-7,2,2,AIR)
B(-7,2,3,SMOOTH_BRICK)
B(-7,2,4,SMOOTH_BRICK:3)
B(-7,2,5,SMOOTH_BRICK)
B(-7,2,6,AIR)
B(-7,2,7,AIR)
B(-7,3,-7,AIR)
B(-7,3,-6,STEP:8)
B(-7,3,-5,SMOOTH_BRICK)
B(-7,3,-4,AIR)
B(-7,3,-3,SMOOTH_BRICK)
B(-7,3,-2,STEP:8)
B(-7,3,-1,AIR)
B(-7,3,0,AIR)
B(-7,3,1,AIR)
B(-7,3,2,STEP:8)
B(-7,3,3,SMOOTH_BRICK)
B(-7,3,4,AIR)
B(-7,3,5,SMOOTH_BRICK)
B(-7,3,6,STEP:8)
B(-7,3,7,AIR)
B(-7,4,-7,AIR)
B(-7,4,-6,STEP:5)
B(-7,4,-5,SMOOTH_STAIRS:0)
B(-7,4,-4,AIR)
B(-7,4,-3,SMOOTH_STAIRS:0)
B(-7,4,-2,STEP:5)
B(-7,4,-1,AIR)
B(-7,4,0,AIR)
B(-7,4,1,AIR)
B(-7,4,2,STEP:5)
B(-7,4,3,SMOOTH_STAIRS:0)
B(-7,4,4,AIR)
B(-7,4,5,SMOOTH_STAIRS:0)
B(-7,4,6,STEP:5)
B(-7,4,7,AIR)
B(-7,5,-7,AIR)
B(-7,5,-6,AIR)
B(-7,5,-5,AIR)
B(-7,5,-4,AIR)
B(-7,5,-3,AIR)
B(-7,5,-2,AIR)
B(-7,5,-1,AIR)
B(-7,5,0,AIR)
B(-7,5,1,AIR)
B(-7,5,2,AIR)
B(-7,5,3,AIR)
B(-7,5,4,AIR)
B(-7,5,5,AIR)
B(-7,5,6,AIR)
B(-7,5,7,AIR)
B(-7,6,-7,AIR)
B(-7,6,-6,AIR)
B(-7,6,-5,AIR)
B(-7,6,-4,AIR)
B(-7,6,-3,AIR)
B(-7,6,-2,AIR)
B(-7,6,-1,AIR)
B(-7,6,0,AIR)
B(-7,6,1,AIR)
B(-7,6,2,AIR)
B(-7,6,3,AIR)
B(-7,6,4,AIR)
B(-7,6,5,AIR)
B(-7,6,6,AIR)
B(-7,6,7,AIR)
B(-7,7,-7,AIR)
B(-7,7,-6,AIR)
B(-7,7,-5,AIR)
B(-7,7,-4,AIR)
B(-7,7,-3,AIR)
B(-7,7,-2,AIR)
B(-7,7,-1,AIR)
B(-7,7,0,AIR)
B(-7,7,1,AIR)
B(-7,7,2,AIR)
B(-7,7,3,AIR)
B(-7,7,4,AIR)
B(-7,7,5,AIR)
B(-7,7,6,AIR)
B(-7,7,7,AIR)
B(-7,8,-7,AIR)
B(-7,8,-6,AIR)
B(-7,8,-5,AIR)
B(-7,8,-4,AIR)
B(-7,8,-3,AIR)
B(-7,8,-2,AIR)
B(-7,8,-1,AIR)
B(-7,8,0,AIR)
B(-7,8,1,AIR)
B(-7,8,2,AIR)
B(-7,8,3,AIR)
B(-7,8,4,AIR)
B(-7,8,5,AIR)
B(-7,8,6,AIR)
B(-7,8,7,AIR)
B(-7,9,-7,AIR)
B(-7,9,-6,AIR)
B(-7,9,-5,AIR)
B(-7,9,-4,AIR)
B(-7,9,-3,AIR)
B(-7,9,-2,AIR)
B(-7,9,-1,AIR)
B(-7,9,0,AIR)
B(-7,9,1,AIR)
B(-7,9,2,AIR)
B(-7,9,3,AIR)
B(-7,9,4,AIR)
B(-7,9,5,AIR)
B(-7,9,6,AIR)
B(-7,9,7,AIR)
B(-7,10,-7,AIR)
B(-7,10,-6,AIR)
B(-7,10,-5,AIR)
B(-7,10,-4,AIR)
B(-7,10,-3,AIR)
B(-7,10,-2,AIR)
B(-7,10,-1,AIR)
B(-7,10,0,AIR)
B(-7,10,1,AIR)
B(-7,10,2,AIR)
B(-7,10,3,AIR)
B(-7,10,4,AIR)
B(-7,10,5,AIR)
B(-7,10,6,AIR)
B(-7,10,7,AIR)
B(-7,11,-7,AIR)
B(-7,11,-6,STEP:13)
B(-7,11,-5,SMOOTH_STAIRS:4)
B(-7,11,-4,AIR)
B(-7,11,-3,SMOOTH_STAIRS:4)
B(-7,11,-2,STEP:13)
B(-7,11,-1,AIR)
B(-7,11,0,AIR)
B(-7,11,1,AIR)
B(-7,11,2,STEP:13)
B(-7,11,3,SMOOTH_STAIRS:4)
B(-7,11,4,AIR)
B(-7,11,5,SMOOTH_STAIRS:4)
B(-7,11,6,STEP:13)
B(-7,11,7,AIR)
B(-7,12,-7,STEP:8)
B(-7,12,-6,SMOOTH_BRICK)
B(-7,12,-5,SMOOTH_BRICK)
B(-7,12,-4,SMOOTH_BRICK)
B(-7,12,-3,SMOOTH_BRICK)
B(-7,12,-2,SMOOTH_BRICK)
B(-7,12,-1,STEP:8)
B(-7,12,0,AIR)
B(-7,12,1,STEP:8)
B(-7,12,2,SMOOTH_BRICK)
B(-7,12,3,SMOOTH_BRICK)
B(-7,12,4,SMOOTH_BRICK)
B(-7,12,5,SMOOTH_BRICK)
B(-7,12,6,SMOOTH_BRICK)
B(-7,12,7,STEP:8)
B(-7,13,-7,STONE:6)
B(-7,13,-6,STEP)
B(-7,13,-5,STONE:6)
B(-7,13,-4,STEP)
B(-7,13,-3,STONE:6)
B(-7,13,-2,STEP)
B(-7,13,-1,STONE:6)
B(-7,13,0,AIR)
B(-7,13,1,STONE:6)
B(-7,13,2,STEP)
B(-7,13,3,STONE:6)
B(-7,13,4,STEP)
B(-7,13,5,STONE:6)
B(-7,13,6,STEP)
B(-7,13,7,STONE:6)
B(-6,-24,-7,COBBLESTONE)
B(-6,-24,-6,COBBLESTONE)
B(-6,-24,-5,COBBLESTONE)
B(-6,-24,-4,COBBLESTONE)
B(-6,-24,-3,COBBLESTONE)
B(-6,-24,-2,COBBLESTONE)
B(-6,-24,-1,COBBLESTONE)
B(-6,-24,0,COBBLESTONE)
B(-6,-24,1,COBBLESTONE)
B(-6,-24,2,COBBLESTONE)
B(-6,-24,3,COBBLESTONE)
B(-6,-24,4,COBBLESTONE)
B(-6,-24,5,COBBLESTONE)
B(-6,-24,6,COBBLESTONE)
B(-6,-24,7,COBBLESTONE)
B(-6,-23,-7,COBBLESTONE)
B(-6,-23,-6,SMOOTH_BRICK)
B(-6,-23,-5,COBBLESTONE)
B(-6,-23,-4,COBBLESTONE)
B(-6,-23,-3,COBBLESTONE)
B(-6,-23,-2,COBBLESTONE)
B(-6,-23,-1,COBBLESTONE)
B(-6,-23,0,COBBLESTONE)
B(-6,-23,1,COBBLESTONE)
B(-6,-23,2,COBBLESTONE)
B(-6,-23,3,COBBLESTONE)
B(-6,-23,4,COBBLESTONE)
B(-6,-23,5,COBBLESTONE)
B(-6,-23,6,SMOOTH_BRICK)
B(-6,-23,7,COBBLESTONE)
B(-6,-22,-7,COBBLESTONE)
B(-6,-22,-6,SMOOTH_BRICK)
B(-6,-22,-5,COBBLESTONE)
B(-6,-22,-4,COBBLESTONE)
B(-6,-22,-3,COBBLESTONE)
B(-6,-22,-2,COBBLESTONE)
B(-6,-22,-1,COBBLESTONE)
B(-6,-22,0,COBBLESTONE)
B(-6,-22,1,COBBLESTONE)
B(-6,-22,2,COBBLESTONE)
B(-6,-22,3,COBBLESTONE)
B(-6,-22,4,COBBLESTONE)
B(-6,-22,5,COBBLESTONE)
B(-6,-22,6,SMOOTH_BRICK)
B(-6,-22,7,COBBLESTONE)
B(-6,-21,-7,COBBLESTONE)
B(-6,-21,-6,SMOOTH_BRICK)
B(-6,-21,-5,COBBLESTONE)
B(-6,-21,-4,COBBLESTONE)
B(-6,-21,-3,COBBLESTONE)
B(-6,-21,-2,COBBLESTONE)
B(-6,-21,-1,COBBLESTONE)
B(-6,-21,0,COBBLESTONE)
B(-6,-21,1,COBBLESTONE)
B(-6,-21,2,COBBLESTONE)
B(-6,-21,3,COBBLESTONE)
B(-6,-21,4,COBBLESTONE)
B(-6,-21,5,COBBLESTONE)
B(-6,-21,6,SMOOTH_BRICK)
B(-6,-21,7,COBBLESTONE)
B(-6,-20,-7,COBBLESTONE)
B(-6,-20,-6,SMOOTH_BRICK)
B(-6,-20,-5,AIR)
B(-6,-20,-4,AIR)
B(-6,-20,-3,AIR)
B(-6,-20,-2,AIR)
B(-6,-20,-1,AIR)
B(-6,-20,0,AIR)
B(-6,-20,1,AIR)
B(-6,-20,2,AIR)
B(-6,-20,3,WEB)
B(-6,-20,4,AIR)
B(-6,-20,5,AIR)
B(-6,-20,6,SMOOTH_BRICK)
B(-6,-20,7,COBBLESTONE)
B(-6,-19,-7,COBBLESTONE)
B(-6,-19,-6,SMOOTH_BRICK)
B(-6,-19,-5,AIR)
B(-6,-19,-4,AIR)
B(-6,-19,-3,AIR)
B(-6,-19,-2,AIR)
B(-6,-19,-1,AIR)
B(-6,-19,0,AIR)
B(-6,-19,1,AIR)
B(-6,-19,2,AIR)
B(-6,-19,3,AIR)
B(-6,-19,4,AIR)
B(-6,-19,5,AIR)
B(-6,-19,6,SMOOTH_BRICK)
B(-6,-19,7,COBBLESTONE)
B(-6,-18,-7,COBBLESTONE)
B(-6,-18,-6,SMOOTH_BRICK)
B(-6,-18,-5,AIR)
B(-6,-18,-4,AIR)
B(-6,-18,-3,AIR)
B(-6,-18,-2,AIR)
B(-6,-18,-1,AIR)
B(-6,-18,0,AIR)
B(-6,-18,1,AIR)
B(-6,-18,2,AIR)
B(-6,-18,3,AIR)
B(-6,-18,4,AIR)
B(-6,-18,5,AIR)
B(-6,-18,6,SMOOTH_BRICK)
B(-6,-18,7,COBBLESTONE)
B(-6,-17,-7,COBBLESTONE)
B(-6,-17,-6,SMOOTH_BRICK)
B(-6,-17,-5,AIR)
B(-6,-17,-4,AIR)
B(-6,-17,-3,AIR)
B(-6,-17,-2,AIR)
B(-6,-17,-1,AIR)
B(-6,-17,0,WEB)
B(-6,-17,1,AIR)
B(-6,-17,2,AIR)
B(-6,-17,3,AIR)
B(-6,-17,4,AIR)
B(-6,-17,5,AIR)
B(-6,-17,6,SMOOTH_BRICK)
B(-6,-17,7,COBBLESTONE)
B(-6,-16,-7,COBBLESTONE)
B(-6,-16,-6,SMOOTH_BRICK)
B(-6,-16,-5,AIR)
B(-6,-16,-4,AIR)
B(-6,-16,-3,AIR)
B(-6,-16,-2,AIR)
B(-6,-16,-1,AIR)
B(-6,-16,0,COBBLESTONE)
B(-6,-16,1,AIR)
B(-6,-16,2,AIR)
B(-6,-16,3,AIR)
B(-6,-16,4,AIR)
B(-6,-16,5,AIR)
B(-6,-16,6,SMOOTH_BRICK)
B(-6,-16,7,COBBLESTONE)
B(-6,-15,-7,COBBLESTONE)
B(-6,-15,-6,SMOOTH_BRICK)
B(-6,-15,-5,AIR)
B(-6,-15,-4,SMOOTH_BRICK)
B(-6,-15,-3,AIR)
B(-6,-15,-2,SMOOTH_BRICK)
B(-6,-15,-1,STONE:6)
B(-6,-15,0,STONE:6)
B(-6,-15,1,STONE:6)
B(-6,-15,2,SMOOTH_BRICK)
B(-6,-15,3,AIR)
B(-6,-15,4,SMOOTH_BRICK)
B(-6,-15,5,AIR)
B(-6,-15,6,SMOOTH_BRICK)
B(-6,-15,7,COBBLESTONE)
B(-6,-14,-7,COBBLESTONE)
B(-6,-14,-6,SMOOTH_BRICK)
B(-6,-14,-5,SMOOTH_BRICK)
B(-6,-14,-4,SMOOTH_BRICK)
B(-6,-14,-3,SMOOTH_BRICK)
B(-6,-14,-2,SMOOTH_BRICK)
B(-6,-14,-1,SMOOTH_BRICK)
B(-6,-14,0,SMOOTH_BRICK)
B(-6,-14,1,SMOOTH_BRICK)
B(-6,-14,2,SMOOTH_BRICK)
B(-6,-14,3,SMOOTH_BRICK)
B(-6,-14,4,SMOOTH_BRICK)
B(-6,-14,5,SMOOTH_BRICK)
B(-6,-14,6,SMOOTH_BRICK)
B(-6,-14,7,COBBLESTONE)
B(-6,-13,-7,COBBLESTONE)
B(-6,-13,-6,COBBLESTONE)
B(-6,-13,-5,COBBLESTONE)
B(-6,-13,-4,COBBLESTONE)
B(-6,-13,-3,COBBLESTONE)
B(-6,-13,-2,COBBLESTONE)
B(-6,-13,-1,COBBLESTONE)
B(-6,-13,0,COBBLESTONE)
B(-6,-13,1,COBBLESTONE)
B(-6,-13,2,COBBLESTONE)
B(-6,-13,3,COBBLESTONE)
B(-6,-13,4,COBBLESTONE)
B(-6,-13,5,COBBLESTONE)
B(-6,-13,6,COBBLESTONE)
B(-6,-13,7,COBBLESTONE)
B(-6,-12,-6,COBBLESTONE)
B(-6,-12,-5,COBBLESTONE)
B(-6,-12,-4,COBBLESTONE)
B(-6,-12,-3,COBBLESTONE)
B(-6,-12,-2,COBBLESTONE)
B(-6,-12,2,COBBLESTONE)
B(-6,-12,3,COBBLESTONE)
B(-6,-12,4,COBBLESTONE)
B(-6,-12,5,COBBLESTONE)
B(-6,-12,6,COBBLESTONE)
B(-6,-11,-6,COBBLESTONE)
B(-6,-11,-5,COBBLESTONE)
B(-6,-11,-4,COBBLESTONE)
B(-6,-11,-3,COBBLESTONE)
B(-6,-11,-2,COBBLESTONE)
B(-6,-11,2,COBBLESTONE)
B(-6,-11,3,COBBLESTONE)
B(-6,-11,4,COBBLESTONE)
B(-6,-11,5,COBBLESTONE)
B(-6,-11,6,COBBLESTONE)
B(-6,-10,-6,COBBLESTONE)
B(-6,-10,-5,COBBLESTONE)
B(-6,-10,-4,COBBLESTONE)
B(-6,-10,-3,COBBLESTONE)
B(-6,-10,-2,COBBLESTONE)
B(-6,-10,2,COBBLESTONE)
B(-6,-10,3,COBBLESTONE)
B(-6,-10,4,COBBLESTONE)
B(-6,-10,5,COBBLESTONE)
B(-6,-10,6,COBBLESTONE)
B(-6,-9,-6,COBBLESTONE)
B(-6,-9,-5,COBBLESTONE)
B(-6,-9,-4,COBBLESTONE)
B(-6,-9,-3,COBBLESTONE)
B(-6,-9,-2,COBBLESTONE)
B(-6,-9,2,COBBLESTONE)
B(-6,-9,3,COBBLESTONE)
B(-6,-9,4,COBBLESTONE)
B(-6,-9,5,COBBLESTONE)
B(-6,-9,6,COBBLESTONE)
B(-6,-8,-6,COBBLESTONE)
B(-6,-8,-5,COBBLESTONE)
B(-6,-8,-4,COBBLESTONE)
B(-6,-8,-3,COBBLESTONE)
B(-6,-8,-2,COBBLESTONE)
B(-6,-8,2,COBBLESTONE)
B(-6,-8,3,COBBLESTONE)
B(-6,-8,4,COBBLESTONE)
B(-6,-8,5,COBBLESTONE)
B(-6,-8,6,COBBLESTONE)
B(-6,-7,-6,COBBLESTONE)
B(-6,-7,-5,COBBLESTONE)
B(-6,-7,-4,COBBLESTONE)
B(-6,-7,-3,COBBLESTONE)
B(-6,-7,-2,COBBLESTONE)
B(-6,-7,2,COBBLESTONE)
B(-6,-7,3,COBBLESTONE)
B(-6,-7,4,COBBLESTONE)
B(-6,-7,5,COBBLESTONE)
B(-6,-7,6,COBBLESTONE)
B(-6,-6,-6,COBBLESTONE)
B(-6,-6,-5,COBBLESTONE)
B(-6,-6,-4,COBBLESTONE)
B(-6,-6,-3,COBBLESTONE)
B(-6,-6,-2,COBBLESTONE)
B(-6,-6,2,COBBLESTONE)
B(-6,-6,3,COBBLESTONE)
B(-6,-6,4,COBBLESTONE)
B(-6,-6,5,COBBLESTONE)
B(-6,-6,6,COBBLESTONE)
B(-6,-5,-6,COBBLESTONE)
B(-6,-5,-5,COBBLESTONE)
B(-6,-5,-4,COBBLESTONE)
B(-6,-5,-3,COBBLESTONE)
B(-6,-5,-2,COBBLESTONE)
B(-6,-5,2,COBBLESTONE)
B(-6,-5,3,COBBLESTONE)
B(-6,-5,4,COBBLESTONE)
B(-6,-5,5,COBBLESTONE)
B(-6,-5,6,COBBLESTONE)
B(-6,-4,-6,COBBLESTONE)
B(-6,-4,-5,COBBLESTONE)
B(-6,-4,-4,COBBLESTONE)
B(-6,-4,-3,COBBLESTONE)
B(-6,-4,-2,COBBLESTONE)
B(-6,-4,2,COBBLESTONE)
B(-6,-4,3,COBBLESTONE)
B(-6,-4,4,COBBLESTONE)
B(-6,-4,5,COBBLESTONE)
B(-6,-4,6,COBBLESTONE)
B(-6,-3,-6,COBBLESTONE)
B(-6,-3,-5,COBBLESTONE)
B(-6,-3,-4,COBBLESTONE)
B(-6,-3,-3,COBBLESTONE)
B(-6,-3,-2,COBBLESTONE)
B(-6,-3,2,COBBLESTONE)
B(-6,-3,3,COBBLESTONE)
B(-6,-3,4,COBBLESTONE)
B(-6,-3,5,COBBLESTONE)
B(-6,-3,6,COBBLESTONE)
B(-6,-2,-6,COBBLESTONE)
B(-6,-2,-5,COBBLESTONE)
B(-6,-2,-4,COBBLESTONE)
B(-6,-2,-3,COBBLESTONE)
B(-6,-2,-2,COBBLESTONE)
B(-6,-2,2,COBBLESTONE)
B(-6,-2,3,COBBLESTONE)
B(-6,-2,4,COBBLESTONE)
B(-6,-2,5,COBBLESTONE)
B(-6,-2,6,COBBLESTONE)
B(-6,-1,-6,COBBLESTONE)
B(-6,-1,-5,COBBLESTONE)
B(-6,-1,-4,COBBLESTONE)
B(-6,-1,-3,COBBLESTONE)
B(-6,-1,-2,COBBLESTONE)
B(-6,-1,2,COBBLESTONE)
B(-6,-1,3,COBBLESTONE)
B(-6,-1,4,COBBLESTONE)
B(-6,-1,5,COBBLESTONE)
B(-6,-1,6,COBBLESTONE)
B(-6,0,-7,AIR)
B(-6,0,-6,STONE:6)
B(-6,0,-5,SMOOTH_BRICK)
B(-6,0,-4,SMOOTH_BRICK)
B(-6,0,-3,SMOOTH_BRICK)
B(-6,0,-2,STONE:6)
B(-6,0,-1,AIR)
B(-6,0,0,AIR)
B(-6,0,1,AIR)
B(-6,0,2,STONE:6)
B(-6,0,3,SMOOTH_BRICK)
B(-6,0,4,SMOOTH_BRICK)
B(-6,0,5,SMOOTH_BRICK)
B(-6,0,6,STONE:6)
B(-6,0,7,AIR)
B(-6,1,-7,AIR)
B(-6,1,-6,STEP)
B(-6,1,-5,SMOOTH_BRICK)
B(-6,1,-4,SMOOTH_BRICK)
B(-6,1,-3,SMOOTH_BRICK)
B(-6,1,-2,STEP)
B(-6,1,-1,AIR)
B(-6,1,0,AIR)
B(-6,1,1,AIR)
B(-6,1,2,STEP)
B(-6,1,3,SMOOTH_BRICK)
B(-6,1,4,SMOOTH_BRICK)
B(-6,1,5,SMOOTH_BRICK)
B(-6,1,6,STEP)
B(-6,1,7,AIR)
B(-6,2,-7,AIR)
B(-6,2,-6,AIR)
B(-6,2,-5,SMOOTH_BRICK)
B(-6,2,-4,SMOOTH_BRICK)
B(-6,2,-3,SMOOTH_BRICK)
B(-6,2,-2,AIR)
B(-6,2,-1,AIR)
B(-6,2,0,AIR)
B(-6,2,1,AIR)
B(-6,2,2,AIR)
B(-6,2,3,SMOOTH_BRICK)
B(-6,2,4,SMOOTH_BRICK)
B(-6,2,5,SMOOTH_BRICK)
B(-6,2,6,AIR)
B(-6,2,7,AIR)
B(-6,3,-7,STEP:8)
B(-6,3,-6,STEP:8)
B(-6,3,-5,SMOOTH_BRICK)
B(-6,3,-4,SMOOTH_BRICK)
B(-6,3,-3,SMOOTH_BRICK)
B(-6,3,-2,STEP:8)
B(-6,3,-1,STEP:8)
B(-6,3,0,AIR)
B(-6,3,1,STEP:8)
B(-6,3,2,STEP:8)
B(-6,3,3,SMOOTH_BRICK)
B(-6,3,4,SMOOTH_BRICK)
B(-6,3,5,SMOOTH_BRICK)
B(-6,3,6,STEP:8)
B(-6,3,7,STEP:8)
B(-6,4,-7,STEP:5)
B(-6,4,-6,DOUBLE_STEP:5)
B(-6,4,-5,SMOOTH_BRICK)
B(-6,4,-4,SMOOTH_BRICK)
B(-6,4,-3,SMOOTH_BRICK)
B(-6,4,-2,DOUBLE_STEP:5)
B(-6,4,-1,STEP:5)
B(-6,4,0,AIR)
B(-6,4,1,STEP:5)
B(-6,4,2,DOUBLE_STEP:5)
B(-6,4,3,SMOOTH_BRICK)
B(-6,4,4,SMOOTH_BRICK)
B(-6,4,5,SMOOTH_BRICK)
B(-6,4,6,DOUBLE_STEP:5)
B(-6,4,7,STEP:5)
B(-6,5,-7,AIR)
B(-6,5,-6,AIR)
B(-6,5,-5,SMOOTH_BRICK)
B(-6,5,-4,SMOOTH_STAIRS:0)
B(-6,5,-3,SMOOTH_BRICK)
B(-6,5,-2,AIR)
B(-6,5,-1,AIR)
B(-6,5,0,AIR)
B(-6,5,1,AIR)
B(-6,5,2,AIR)
B(-6,5,3,SMOOTH_BRICK)
B(-6,5,4,SMOOTH_STAIRS:0)
B(-6,5,5,SMOOTH_BRICK)
B(-6,5,6,AIR)
B(-6,5,7,AIR)
B(-6,6,-7,AIR)
B(-6,6,-6,AIR)
B(-6,6,-5,SMOOTH_BRICK)
B(-6,6,-4,AIR)
B(-6,6,-3,SMOOTH_BRICK)
B(-6,6,-2,AIR)
B(-6,6,-1,AIR)
B(-6,6,0,AIR)
B(-6,6,1,AIR)
B(-6,6,2,AIR)
B(-6,6,3,SMOOTH_BRICK)
B(-6,6,4,AIR)
B(-6,6,5,SMOOTH_BRICK)
B(-6,6,6,AIR)
B(-6,6,7,AIR)
B(-6,7,-7,AIR)
B(-6,7,-6,AIR)
B(-6,7,-5,SMOOTH_BRICK)
B(-6,7,-4,AIR)
B(-6,7,-3,SMOOTH_BRICK)
B(-6,7,-2,AIR)
B(-6,7,-1,AIR)
B(-6,7,0,AIR)
B(-6,7,1,AIR)
B(-6,7,2,AIR)
B(-6,7,3,SMOOTH_BRICK)
B(-6,7,4,AIR)
B(-6,7,5,SMOOTH_BRICK)
B(-6,7,6,AIR)
B(-6,7,7,AIR)
B(-6,8,-7,AIR)
B(-6,8,-6,AIR)
B(-6,8,-5,SMOOTH_BRICK)
B(-6,8,-4,AIR)
B(-6,8,-3,SMOOTH_BRICK)
B(-6,8,-2,AIR)
B(-6,8,-1,AIR)
B(-6,8,0,AIR)
B(-6,8,1,AIR)
B(-6,8,2,AIR)
B(-6,8,3,SMOOTH_BRICK)
B(-6,8,4,AIR)
B(-6,8,5,SMOOTH_BRICK)
B(-6,8,6,AIR)
B(-6,8,7,AIR)
B(-6,9,-7,AIR)
B(-6,9,-6,AIR)
B(-6,9,-5,SMOOTH_BRICK)
B(-6,9,-4,AIR)
B(-6,9,-3,SMOOTH_BRICK)
B(-6,9,-2,AIR)
B(-6,9,-1,AIR)
B(-6,9,0,AIR)
B(-6,9,1,AIR)
B(-6,9,2,AIR)
B(-6,9,3,SMOOTH_BRICK)
B(-6,9,4,AIR)
B(-6,9,5,SMOOTH_BRICK)
B(-6,9,6,AIR)
B(-6,9,7,AIR)
B(-6,10,-7,AIR)
B(-6,10,-6,STEP:8)
B(-6,10,-5,SMOOTH_BRICK)
B(-6,10,-4,STEP:8)
B(-6,10,-3,SMOOTH_BRICK)
B(-6,10,-2,STEP:8)
B(-6,10,-1,AIR)
B(-6,10,0,AIR)
B(-6,10,1,AIR)
B(-6,10,2,STEP:8)
B(-6,10,3,SMOOTH_BRICK)
B(-6,10,4,STEP:8)
B(-6,10,5,SMOOTH_BRICK)
B(-6,10,6,STEP:8)
B(-6,10,7,AIR)
B(-6,11,-7,STEP:13)
B(-6,11,-6,SMOOTH_BRICK)
B(-6,11,-5,SMOOTH_BRICK)
B(-6,11,-4,STONE:6)
B(-6,11,-3,SMOOTH_BRICK)
B(-6,11,-2,SMOOTH_BRICK)
B(-6,11,-1,STEP:13)
B(-6,11,0,AIR)
B(-6,11,1,STEP:13)
B(-6,11,2,SMOOTH_BRICK)
B(-6,11,3,SMOOTH_BRICK)
B(-6,11,4,STONE:6)
B(-6,11,5,SMOOTH_BRICK)
B(-6,11,6,SMOOTH_BRICK)
B(-6,11,7,STEP:13)
B(-6,12,-7,SMOOTH_BRICK)
B(-6,12,-6,STEP)
B(-6,12,-5,STEP)
B(-6,12,-4,SMOOTH_BRICK)
B(-6,12,-3,STEP)
B(-6,12,-2,STEP)
B(-6,12,-1,SMOOTH_STAIRS:2)
B(-6,12,0,AIR)
B(-6,12,1,SMOOTH_STAIRS)
B(-6,12,2,STEP)
B(-6,12,3,STEP)
B(-6,12,4,SMOOTH_BRICK)
B(-6,12,5,STEP)
B(-6,12,6,STEP)
B(-6,12,7,SMOOTH_BRICK)
B(-6,13,-7,STEP)
B(-6,13,-6,AIR)
B(-6,13,-5,AIR)
B(-6,13,-4,AIR)
B(-6,13,-3,AIR)
B(-6,13,-2,AIR)
B(-6,13,-1,AIR)
B(-6,13,0,AIR)
B(-6,13,1,AIR)
B(-6,13,2,AIR)
B(-6,13,3,AIR)
B(-6,13,4,AIR)
B(-6,13,5,AIR)
B(-6,13,6,AIR)
B(-6,13,7,STEP)
B(-5,-24,-7,COBBLESTONE)
B(-5,-24,-6,COBBLESTONE)
B(-5,-24,-5,COBBLESTONE)
B(-5,-24,-4,COBBLESTONE)
B(-5,-24,-3,COBBLESTONE)
B(-5,-24,-2,COBBLESTONE)
B(-5,-24,-1,COBBLESTONE)
B(-5,-24,0,COBBLESTONE)
B(-5,-24,1,COBBLESTONE)
B(-5,-24,2,COBBLESTONE)
B(-5,-24,3,COBBLESTONE)
B(-5,-24,4,COBBLESTONE)
B(-5,-24,5,COBBLESTONE)
B(-5,-24,6,COBBLESTONE)
B(-5,-24,7,COBBLESTONE)
B(-5,-23,-7,COBBLESTONE)
B(-5,-23,-6,COBBLESTONE)
B(-5,-23,-5,WOOD)
B(-5,-23,-4,WOOD)
B(-5,-23,-3,WOOD)
B(-5,-23,-2,WOOD)
B(-5,-23,-1,WOOD)
B(-5,-23,0,WOOD)
B(-5,-23,1,WOOD)
B(-5,-23,2,STONE:6)
B(-5,-23,3,WOOD)
B(-5,-23,4,WOOD)
B(-5,-23,5,WOOD)
B(-5,-23,6,WOOD)
B(-5,-23,7,COBBLESTONE)
B(-5,-22,-7,COBBLESTONE)
B(-5,-22,-6,COBBLESTONE)
B(-5,-22,-5,AIR)
B(-5,-22,-4,AIR)
B(-5,-22,-3,AIR)
B(-5,-22,-2,AIR)
B(-5,-22,-1,AIR)
B(-5,-22,0,AIR)
B(-5,-22,1,AIR)
B(-5,-22,2,AIR)
B(-5,-22,3,AIR)
B(-5,-22,4,AIR)
B(-5,-22,5,AIR)
B(-5,-22,6,STEP:3)
B(-5,-22,7,COBBLESTONE)
B(-5,-21,-7,COBBLESTONE)
B(-5,-21,-6,COBBLESTONE)
B(-5,-21,-5,AIR)
B(-5,-21,-4,AIR)
B(-5,-21,-3,AIR)
B(-5,-21,-2,AIR)
B(-5,-21,-1,AIR)
B(-5,-21,0,AIR)
B(-5,-21,1,AIR)
B(-5,-21,2,AIR)
B(-5,-21,3,AIR)
B(-5,-21,4,AIR)
B(-5,-21,5,AIR)
B(-5,-21,6,AIR)
B(-5,-21,7,COBBLESTONE)
B(-5,-20,-7,COBBLESTONE)
B(-5,-20,-6,AIR)
B(-5,-20,-5,AIR)
B(-5,-20,-4,AIR)
B(-5,-20,-3,AIR)
B(-5,-20,-2,AIR)
B(-5,-20,-1,AIR)
B(-5,-20,0,AIR)
B(-5,-20,1,AIR)
B(-5,-20,2,AIR)
B(-5,-20,3,AIR)
B(-5,-20,4,AIR)
B(-5,-20,5,AIR)
B(-5,-20,6,AIR)
B(-5,-20,7,COBBLESTONE)
B(-5,-19,-7,COBBLESTONE)
B(-5,-19,-6,AIR)
B(-5,-19,-5,AIR)
B(-5,-19,-4,AIR)
B(-5,-19,-3,AIR)
B(-5,-19,-2,AIR)
B(-5,-19,-1,AIR)
B(-5,-19,0,AIR)
B(-5,-19,1,AIR)
B(-5,-19,2,AIR)
B(-5,-19,3,AIR)
B(-5,-19,4,AIR)
B(-5,-19,5,AIR)
B(-5,-19,6,AIR)
B(-5,-19,7,COBBLESTONE)
B(-5,-18,-7,COBBLESTONE)
B(-5,-18,-6,AIR)
B(-5,-18,-5,AIR)
B(-5,-18,-4,AIR)
B(-5,-18,-3,AIR)
B(-5,-18,-2,AIR)
B(-5,-18,-1,AIR)
B(-5,-18,0,AIR)
B(-5,-18,1,AIR)
B(-5,-18,2,AIR)
B(-5,-18,3,AIR)
B(-5,-18,4,AIR)
B(-5,-18,5,AIR)
B(-5,-18,6,AIR)
B(-5,-18,7,COBBLESTONE)
B(-5,-17,-7,COBBLESTONE)
B(-5,-17,-6,AIR)
B(-5,-17,-5,AIR)
B(-5,-17,-4,AIR)
B(-5,-17,-3,AIR)
B(-5,-17,-2,AIR)
B(-5,-17,-1,AIR)
B(-5,-17,0,AIR)
B(-5,-17,1,AIR)
B(-5,-17,2,AIR)
B(-5,-17,3,AIR)
B(-5,-17,4,AIR)
B(-5,-17,5,AIR)
B(-5,-17,6,AIR)
B(-5,-17,7,COBBLESTONE)
B(-5,-16,-7,COBBLESTONE)
B(-5,-16,-6,AIR)
B(-5,-16,-5,AIR)
B(-5,-16,-4,AIR)
B(-5,-16,-3,AIR)
B(-5,-16,-2,AIR)
B(-5,-16,-1,AIR)
B(-5,-16,0,COBBLESTONE)
B(-5,-16,1,AIR)
B(-5,-16,2,AIR)
B(-5,-16,3,AIR)
B(-5,-16,4,AIR)
B(-5,-16,5,AIR)
B(-5,-16,6,AIR)
B(-5,-16,7,COBBLESTONE)
B(-5,-15,-7,COBBLESTONE)
B(-5,-15,-6,AIR)
B(-5,-15,-5,AIR)
B(-5,-15,-4,AIR)
B(-5,-15,-3,AIR)
B(-5,-15,-2,AIR)
B(-5,-15,-1,AIR)
B(-5,-15,0,AIR)
B(-5,-15,1,AIR)
B(-5,-15,2,AIR)
B(-5,-15,3,AIR)
B(-5,-15,4,AIR)
B(-5,-15,5,AIR)
B(-5,-15,6,AIR)
B(-5,-15,7,COBBLESTONE)
B(-5,-14,-7,COBBLESTONE)
B(-5,-14,-6,SMOOTH_BRICK)
B(-5,-14,-5,SMOOTH_BRICK)
B(-5,-14,-4,SMOOTH_BRICK)
B(-5,-14,-3,AIR)
B(-5,-14,-2,AIR)
B(-5,-14,-1,AIR)
B(-5,-14,0,AIR)
B(-5,-14,1,AIR)
B(-5,-14,2,AIR)
B(-5,-14,3,AIR)
B(-5,-14,4,SMOOTH_BRICK)
B(-5,-14,5,SMOOTH_BRICK)
B(-5,-14,6,SMOOTH_BRICK)
B(-5,-14,7,COBBLESTONE)
B(-5,-13,-7,COBBLESTONE)
B(-5,-13,-6,COBBLESTONE)
B(-5,-13,-5,COBBLESTONE)
B(-5,-13,-4,COBBLESTONE)
B(-5,-13,-3,COBBLESTONE)
B(-5,-13,-2,COBBLESTONE)
B(-5,-13,-1,COBBLESTONE)
B(-5,-13,0,COBBLESTONE)
B(-5,-13,1,COBBLESTONE)
B(-5,-13,2,COBBLESTONE)
B(-5,-13,3,COBBLESTONE)
B(-5,-13,4,COBBLESTONE)
B(-5,-13,5,COBBLESTONE)
B(-5,-13,6,COBBLESTONE)
B(-5,-13,7,COBBLESTONE)
B(-5,-12,-7,COBBLESTONE)
B(-5,-12,-6,COBBLESTONE)
B(-5,-12,-5,COBBLESTONE)
B(-5,-12,-4,COBBLESTONE)
B(-5,-12,-3,COBBLESTONE)
B(-5,-12,-2,COBBLESTONE)
B(-5,-12,-1,COBBLESTONE)
B(-5,-12,1,COBBLESTONE)
B(-5,-12,2,COBBLESTONE)
B(-5,-12,3,COBBLESTONE)
B(-5,-12,4,COBBLESTONE)
B(-5,-12,5,COBBLESTONE)
B(-5,-12,6,COBBLESTONE)
B(-5,-12,7,COBBLESTONE)
B(-5,-11,-7,COBBLESTONE)
B(-5,-11,-6,COBBLESTONE)
B(-5,-11,-5,COBBLESTONE)
B(-5,-11,-4,COBBLESTONE)
B(-5,-11,-3,COBBLESTONE)
B(-5,-11,-2,COBBLESTONE)
B(-5,-11,-1,COBBLESTONE)
B(-5,-11,1,COBBLESTONE)
B(-5,-11,2,COBBLESTONE)
B(-5,-11,3,COBBLESTONE)
B(-5,-11,4,COBBLESTONE)
B(-5,-11,5,COBBLESTONE)
B(-5,-11,6,COBBLESTONE)
B(-5,-11,7,COBBLESTONE)
B(-5,-10,-7,COBBLESTONE)
B(-5,-10,-6,COBBLESTONE)
B(-5,-10,-5,COBBLESTONE)
B(-5,-10,-4,COBBLESTONE)
B(-5,-10,-3,COBBLESTONE)
B(-5,-10,-2,COBBLESTONE)
B(-5,-10,-1,COBBLESTONE)
B(-5,-10,1,COBBLESTONE)
B(-5,-10,2,COBBLESTONE)
B(-5,-10,3,COBBLESTONE)
B(-5,-10,4,COBBLESTONE)
B(-5,-10,5,COBBLESTONE)
B(-5,-10,6,COBBLESTONE)
B(-5,-10,7,COBBLESTONE)
B(-5,-9,-7,COBBLESTONE)
B(-5,-9,-6,COBBLESTONE)
B(-5,-9,-5,COBBLESTONE)
B(-5,-9,-4,COBBLESTONE)
B(-5,-9,-3,COBBLESTONE)
B(-5,-9,-2,COBBLESTONE)
B(-5,-9,-1,COBBLESTONE)
B(-5,-9,1,COBBLESTONE)
B(-5,-9,2,COBBLESTONE)
B(-5,-9,3,COBBLESTONE)
B(-5,-9,4,COBBLESTONE)
B(-5,-9,5,COBBLESTONE)
B(-5,-9,6,COBBLESTONE)
B(-5,-9,7,COBBLESTONE)
B(-5,-8,-7,COBBLESTONE)
B(-5,-8,-6,COBBLESTONE)
B(-5,-8,-5,COBBLESTONE)
B(-5,-8,-4,COBBLESTONE)
B(-5,-8,-3,COBBLESTONE)
B(-5,-8,-2,COBBLESTONE)
B(-5,-8,-1,COBBLESTONE)
B(-5,-8,1,COBBLESTONE)
B(-5,-8,2,COBBLESTONE)
B(-5,-8,3,COBBLESTONE)
B(-5,-8,4,COBBLESTONE)
B(-5,-8,5,COBBLESTONE)
B(-5,-8,6,COBBLESTONE)
B(-5,-8,7,COBBLESTONE)
B(-5,-7,-7,COBBLESTONE)
B(-5,-7,-6,COBBLESTONE)
B(-5,-7,-5,COBBLESTONE)
B(-5,-7,-4,COBBLESTONE)
B(-5,-7,-3,COBBLESTONE)
B(-5,-7,-2,COBBLESTONE)
B(-5,-7,-1,COBBLESTONE)
B(-5,-7,1,COBBLESTONE)
B(-5,-7,2,COBBLESTONE)
B(-5,-7,3,COBBLESTONE)
B(-5,-7,4,COBBLESTONE)
B(-5,-7,5,COBBLESTONE)
B(-5,-7,6,COBBLESTONE)
B(-5,-7,7,COBBLESTONE)
B(-5,-6,-7,COBBLESTONE)
B(-5,-6,-6,COBBLESTONE)
B(-5,-6,-5,COBBLESTONE)
B(-5,-6,-4,COBBLESTONE)
B(-5,-6,-3,COBBLESTONE)
B(-5,-6,-2,COBBLESTONE)
B(-5,-6,-1,COBBLESTONE)
B(-5,-6,1,COBBLESTONE)
B(-5,-6,2,COBBLESTONE)
B(-5,-6,3,COBBLESTONE)
B(-5,-6,4,COBBLESTONE)
B(-5,-6,5,COBBLESTONE)
B(-5,-6,6,COBBLESTONE)
B(-5,-6,7,COBBLESTONE)
B(-5,-5,-7,COBBLESTONE)
B(-5,-5,-6,COBBLESTONE)
B(-5,-5,-5,COBBLESTONE)
B(-5,-5,-4,COBBLESTONE)
B(-5,-5,-3,COBBLESTONE)
B(-5,-5,-2,COBBLESTONE)
B(-5,-5,-1,COBBLESTONE)
B(-5,-5,1,COBBLESTONE)
B(-5,-5,2,COBBLESTONE)
B(-5,-5,3,COBBLESTONE)
B(-5,-5,4,COBBLESTONE)
B(-5,-5,5,COBBLESTONE)
B(-5,-5,6,COBBLESTONE)
B(-5,-5,7,COBBLESTONE)
B(-5,-4,-7,COBBLESTONE)
B(-5,-4,-6,COBBLESTONE)
B(-5,-4,-5,COBBLESTONE)
B(-5,-4,-4,COBBLESTONE)
B(-5,-4,-3,COBBLESTONE)
B(-5,-4,-2,COBBLESTONE)
B(-5,-4,-1,COBBLESTONE)
B(-5,-4,1,COBBLESTONE)
B(-5,-4,2,COBBLESTONE)
B(-5,-4,3,COBBLESTONE)
B(-5,-4,4,COBBLESTONE)
B(-5,-4,5,COBBLESTONE)
B(-5,-4,6,COBBLESTONE)
B(-5,-4,7,COBBLESTONE)
B(-5,-3,-7,COBBLESTONE)
B(-5,-3,-6,COBBLESTONE)
B(-5,-3,-5,COBBLESTONE)
B(-5,-3,-4,COBBLESTONE)
B(-5,-3,-3,COBBLESTONE)
B(-5,-3,-2,COBBLESTONE)
B(-5,-3,-1,COBBLESTONE)
B(-5,-3,1,COBBLESTONE)
B(-5,-3,2,COBBLESTONE)
B(-5,-3,3,COBBLESTONE)
B(-5,-3,4,COBBLESTONE)
B(-5,-3,5,COBBLESTONE)
B(-5,-3,6,COBBLESTONE)
B(-5,-3,7,COBBLESTONE)
B(-5,-2,-7,COBBLESTONE)
B(-5,-2,-6,COBBLESTONE)
B(-5,-2,-5,COBBLESTONE)
B(-5,-2,-4,COBBLESTONE)
B(-5,-2,-3,COBBLESTONE)
B(-5,-2,-2,COBBLESTONE)
B(-5,-2,-1,COBBLESTONE)
B(-5,-2,1,COBBLESTONE)
B(-5,-2,2,COBBLESTONE)
B(-5,-2,3,COBBLESTONE)
B(-5,-2,4,COBBLESTONE)
B(-5,-2,5,COBBLESTONE)
B(-5,-2,6,COBBLESTONE)
B(-5,-2,7,COBBLESTONE)
B(-5,-1,-7,COBBLESTONE)
B(-5,-1,-6,COBBLESTONE)
B(-5,-1,-5,STONE:6)
B(-5,-1,-4,STONE:6)
B(-5,-1,-3,STONE:6)
B(-5,-1,-2,COBBLESTONE)
B(-5,-1,-1,COBBLESTONE)
B(-5,-1,1,COBBLESTONE)
B(-5,-1,2,COBBLESTONE)
B(-5,-1,3,STONE:6)
B(-5,-1,4,STONE:6)
B(-5,-1,5,STONE:6)
B(-5,-1,6,COBBLESTONE)
B(-5,-1,7,COBBLESTONE)
B(-5,0,-7,SMOOTH_BRICK)
B(-5,0,-6,SMOOTH_BRICK)
B(-5,0,-5,AIR)
B(-5,0,-4,AIR)
B(-5,0,-3,AIR)
B(-5,0,-2,SMOOTH_BRICK)
B(-5,0,-1,SMOOTH_BRICK)
B(-5,0,0,AIR)
B(-5,0,1,SMOOTH_BRICK)
B(-5,0,2,SMOOTH_BRICK)
B(-5,0,3,AIR)
B(-5,0,4,AIR)
B(-5,0,5,AIR)
B(-5,0,6,SMOOTH_BRICK)
B(-5,0,7,SMOOTH_BRICK)
B(-5,1,-7,SMOOTH_BRICK)
B(-5,1,-6,SMOOTH_BRICK)
B(-5,1,-5,AIR)
B(-5,1,-4,AIR)
B(-5,1,-3,AIR)
B(-5,1,-2,SMOOTH_BRICK)
B(-5,1,-1,SMOOTH_BRICK)
B(-5,1,0,AIR)
B(-5,1,1,SMOOTH_BRICK)
B(-5,1,2,SMOOTH_BRICK)
B(-5,1,3,AIR)
B(-5,1,4,AIR)
B(-5,1,5,AIR)
B(-5,1,6,SMOOTH_BRICK)
B(-5,1,7,SMOOTH_BRICK)
B(-5,2,-7,SMOOTH_BRICK)
B(-5,2,-6,SMOOTH_BRICK)
B(-5,2,-5,AIR)
B(-5,2,-4,AIR)
B(-5,2,-3,AIR)
B(-5,2,-2,SMOOTH_BRICK)
B(-5,2,-1,SMOOTH_BRICK)
B(-5,2,0,AIR)
B(-5,2,1,SMOOTH_BRICK)
B(-5,2,2,SMOOTH_BRICK)
B(-5,2,3,AIR)
B(-5,2,4,AIR)
B(-5,2,5,AIR)
B(-5,2,6,SMOOTH_BRICK)
B(-5,2,7,SMOOTH_BRICK)
B(-5,3,-7,SMOOTH_BRICK)
B(-5,3,-6,SMOOTH_BRICK)
B(-5,3,-5,AIR)
B(-5,3,-4,AIR)
B(-5,3,-3,AIR)
B(-5,3,-2,SMOOTH_BRICK)
B(-5,3,-1,SMOOTH_BRICK)
B(-5,3,0,AIR)
B(-5,3,1,SMOOTH_BRICK)
B(-5,3,2,SMOOTH_BRICK)
B(-5,3,3,AIR)
B(-5,3,4,AIR)
B(-5,3,5,AIR)
B(-5,3,6,SMOOTH_BRICK)
B(-5,3,7,SMOOTH_BRICK)
B(-5,4,-7,SMOOTH_STAIRS:2)
B(-5,4,-6,SMOOTH_BRICK)
B(-5,4,-5,AIR)
B(-5,4,-4,AIR)
B(-5,4,-3,AIR)
B(-5,4,-2,SMOOTH_BRICK)
B(-5,4,-1,SMOOTH_STAIRS)
B(-5,4,0,AIR)
B(-5,4,1,SMOOTH_STAIRS:2)
B(-5,4,2,SMOOTH_BRICK)
B(-5,4,3,AIR)
B(-5,4,4,AIR)
B(-5,4,5,AIR)
B(-5,4,6,SMOOTH_BRICK)
B(-5,4,7,SMOOTH_STAIRS)
B(-5,5,-7,AIR)
B(-5,5,-6,SMOOTH_BRICK)
B(-5,5,-5,SMOOTH_STAIRS:5)
B(-5,5,-4,SMOOTH_STAIRS:5)
B(-5,5,-3,SMOOTH_STAIRS:5)
B(-5,5,-2,SMOOTH_BRICK)
B(-5,5,-1,AIR)
B(-5,5,0,AIR)
B(-5,5,1,AIR)
B(-5,5,2,SMOOTH_BRICK)
B(-5,5,3,SMOOTH_STAIRS:5)
B(-5,5,4,SMOOTH_STAIRS:5)
B(-5,5,5,SMOOTH_STAIRS:6)
B(-5,5,6,SMOOTH_BRICK)
B(-5,5,7,AIR)
B(-5,6,-7,AIR)
B(-5,6,-6,SMOOTH_BRICK)
B(-5,6,-5,SMOOTH_BRICK)
B(-5,6,-4,SMOOTH_BRICK)
B(-5,6,-3,SMOOTH_BRICK)
B(-5,6,-2,SMOOTH_BRICK)
B(-5,6,-1,AIR)
B(-5,6,0,AIR)
B(-5,6,1,AIR)
B(-5,6,2,SMOOTH_BRICK)
B(-5,6,3,SMOOTH_BRICK)
B(-5,6,4,SMOOTH_BRICK)
B(-5,6,5,SMOOTH_BRICK)
B(-5,6,6,SMOOTH_BRICK)
B(-5,6,7,AIR)
B(-5,7,-7,AIR)
B(-5,7,-6,SMOOTH_BRICK)
B(-5,7,-5,SMOOTH_BRICK)
B(-5,7,-4,SMOOTH_BRICK)
B(-5,7,-3,SMOOTH_BRICK)
B(-5,7,-2,SMOOTH_BRICK)
B(-5,7,-1,AIR)
B(-5,7,0,AIR)
B(-5,7,1,AIR)
B(-5,7,2,SMOOTH_BRICK)
B(-5,7,3,SMOOTH_BRICK)
B(-5,7,4,SMOOTH_BRICK)
B(-5,7,5,SMOOTH_BRICK)
B(-5,7,6,SMOOTH_BRICK)
B(-5,7,7,AIR)
B(-5,8,-7,AIR)
B(-5,8,-6,SMOOTH_BRICK)
B(-5,8,-5,SMOOTH_BRICK)
B(-5,8,-4,SMOOTH_BRICK)
B(-5,8,-3,SMOOTH_BRICK)
B(-5,8,-2,SMOOTH_BRICK)
B(-5,8,-1,AIR)
B(-5,8,0,AIR)
B(-5,8,1,AIR)
B(-5,8,2,SMOOTH_BRICK)
B(-5,8,3,SMOOTH_BRICK)
B(-5,8,4,SMOOTH_BRICK)
B(-5,8,5,SMOOTH_BRICK)
B(-5,8,6,SMOOTH_BRICK)
B(-5,8,7,AIR)
B(-5,9,-7,AIR)
B(-5,9,-6,SMOOTH_BRICK)
B(-5,9,-5,SMOOTH_BRICK)
B(-5,9,-4,SMOOTH_BRICK)
B(-5,9,-3,SMOOTH_BRICK)
B(-5,9,-2,SMOOTH_BRICK)
B(-5,9,-1,AIR)
B(-5,9,0,AIR)
B(-5,9,1,AIR)
B(-5,9,2,SMOOTH_BRICK)
B(-5,9,3,SMOOTH_BRICK)
B(-5,9,4,SMOOTH_BRICK)
B(-5,9,5,SMOOTH_BRICK)
B(-5,9,6,SMOOTH_BRICK)
B(-5,9,7,AIR)
B(-5,10,-7,AIR)
B(-5,10,-6,SMOOTH_BRICK)
B(-5,10,-5,SMOOTH_BRICK)
B(-5,10,-4,SMOOTH_BRICK)
B(-5,10,-3,SMOOTH_BRICK)
B(-5,10,-2,SMOOTH_BRICK)
B(-5,10,-1,AIR)
B(-5,10,0,AIR)
B(-5,10,1,AIR)
B(-5,10,2,SMOOTH_BRICK)
B(-5,10,3,SMOOTH_BRICK)
B(-5,10,4,SMOOTH_BRICK)
B(-5,10,5,SMOOTH_BRICK)
B(-5,10,6,SMOOTH_BRICK)
B(-5,10,7,AIR)
B(-5,11,-7,SMOOTH_STAIRS:6)
B(-5,11,-6,SMOOTH_BRICK)
B(-5,11,-5,SMOOTH_BRICK)
B(-5,11,-4,SMOOTH_BRICK)
B(-5,11,-3,SMOOTH_BRICK)
B(-5,11,-2,SMOOTH_BRICK)
B(-5,11,-1,SMOOTH_STAIRS:7)
B(-5,11,0,AIR)
B(-5,11,1,SMOOTH_STAIRS:6)
B(-5,11,2,SMOOTH_BRICK)
B(-5,11,3,SMOOTH_BRICK)
B(-5,11,4,SMOOTH_BRICK)
B(-5,11,5,SMOOTH_BRICK)
B(-5,11,6,SMOOTH_BRICK)
B(-5,11,7,SMOOTH_STAIRS:7)
B(-5,12,-7,SMOOTH_BRICK)
B(-5,12,-6,STEP)
B(-5,12,-5,AIR)
B(-5,12,-4,AIR)
B(-5,12,-3,AIR)
B(-5,12,-2,STEP)
B(-5,12,-1,SMOOTH_STAIRS:2)
B(-5,12,0,AIR)
B(-5,12,1,SMOOTH_STAIRS)
B(-5,12,2,STEP)
B(-5,12,3,AIR)
B(-5,12,4,AIR)
B(-5,12,5,AIR)
B(-5,12,6,STEP)
B(-5,12,7,SMOOTH_BRICK)
B(-5,13,-7,STONE:6)
B(-5,13,-6,AIR)
B(-5,13,-5,AIR)
B(-5,13,-4,AIR)
B(-5,13,-3,AIR)
B(-5,13,-2,AIR)
B(-5,13,-1,AIR)
B(-5,13,0,AIR)
B(-5,13,1,AIR)
B(-5,13,2,AIR)
B(-5,13,3,AIR)
B(-5,13,4,AIR)
B(-5,13,5,AIR)
B(-5,13,6,AIR)
B(-5,13,7,STONE:6)
B(-4,-24,-7,COBBLESTONE)
B(-4,-24,-6,COBBLESTONE)
B(-4,-24,-5,COBBLESTONE)
B(-4,-24,-4,COBBLESTONE)
B(-4,-24,-3,COBBLESTONE)
B(-4,-24,-2,COBBLESTONE)
B(-4,-24,-1,COBBLESTONE)
B(-4,-24,0,COBBLESTONE)
B(-4,-24,1,COBBLESTONE)
B(-4,-24,2,COBBLESTONE)
B(-4,-24,3,COBBLESTONE)
B(-4,-24,4,COBBLESTONE)
B(-4,-24,5,COBBLESTONE)
B(-4,-24,6,COBBLESTONE)
B(-4,-24,7,COBBLESTONE)
B(-4,-23,-7,COBBLESTONE)
B(-4,-23,-6,COBBLESTONE)
B(-4,-23,-5,WOOD)
B(-4,-23,-4,WOOD)
B(-4,-23,-3,WOOD)
B(-4,-23,-2,WOOD)
B(-4,-23,-1,WOOD)
B(-4,-23,0,WOOD)
B(-4,-23,1,WOOD)
B(-4,-23,2,STONE:6)
B(-4,-23,3,WOOD)
B(-4,-23,4,WOOD)
B(-4,-23,5,WOOD)
B(-4,-23,6,WOOD)
B(-4,-23,7,COBBLESTONE)
B(-4,-22,-7,COBBLESTONE)
B(-4,-22,-6,COBBLESTONE)
B(-4,-22,-5,WEB)
B(-4,-22,-4,AIR)
B(-4,-22,-3,AIR)
B(-4,-22,-2,WEB)
B(-4,-22,-1,AIR)
B(-4,-22,0,WEB)
B(-4,-22,1,WEB)
B(-4,-22,2,AIR)
B(-4,-22,3,WEB)
B(-4,-22,4,AIR)
B(-4,-22,5,AIR)
RB(-4,-22,6,FURNACE:4,../../nbt/Misc/Furnace.nbt,30,FURNACE,../../nbt/Misc/Furnace2.nbt,30,FURNACE,../../nbt/Misc/Furnace3.nbt,100)
B(-4,-22,7,COBBLESTONE)
B(-4,-21,-7,COBBLESTONE)
B(-4,-21,-6,COBBLESTONE)
B(-4,-21,-5,AIR)
B(-4,-21,-4,AIR)
B(-4,-21,-3,AIR)
B(-4,-21,-2,AIR)
B(-4,-21,-1,AIR)
B(-4,-21,0,AIR)
B(-4,-21,1,AIR)
B(-4,-21,2,AIR)
B(-4,-21,3,AIR)
B(-4,-21,4,AIR)
B(-4,-21,5,AIR)
B(-4,-21,6,COBBLE_WALL)
B(-4,-21,7,COBBLESTONE)
B(-4,-20,-7,COBBLESTONE)
B(-4,-20,-6,AIR)
B(-4,-20,-5,AIR)
B(-4,-20,-4,AIR)
B(-4,-20,-3,AIR)
B(-4,-20,-2,AIR)
B(-4,-20,-1,AIR)
B(-4,-20,0,AIR)
B(-4,-20,1,AIR)
B(-4,-20,2,AIR)
B(-4,-20,3,AIR)
B(-4,-20,4,AIR)
B(-4,-20,5,AIR)
B(-4,-20,6,COBBLE_WALL)
B(-4,-20,7,COBBLESTONE)
B(-4,-19,-7,COBBLESTONE)
B(-4,-19,-6,AIR)
B(-4,-19,-5,AIR)
B(-4,-19,-4,AIR)
B(-4,-19,-3,AIR)
B(-4,-19,-2,AIR)
B(-4,-19,-1,AIR)
B(-4,-19,0,AIR)
B(-4,-19,1,AIR)
B(-4,-19,2,AIR)
B(-4,-19,3,AIR)
B(-4,-19,4,AIR)
B(-4,-19,5,AIR)
B(-4,-19,6,COBBLE_WALL)
B(-4,-19,7,COBBLESTONE)
B(-4,-18,-7,COBBLESTONE)
B(-4,-18,-6,AIR)
B(-4,-18,-5,AIR)
B(-4,-18,-4,AIR)
B(-4,-18,-3,AIR)
B(-4,-18,-2,AIR)
B(-4,-18,-1,AIR)
B(-4,-18,0,AIR)
B(-4,-18,1,AIR)
B(-4,-18,2,AIR)
B(-4,-18,3,AIR)
B(-4,-18,4,AIR)
B(-4,-18,5,AIR)
B(-4,-18,6,COBBLESTONE)
B(-4,-18,7,COBBLESTONE)
B(-4,-17,-7,COBBLESTONE)
B(-4,-17,-6,AIR)
B(-4,-17,-5,AIR)
B(-4,-17,-4,AIR)
B(-4,-17,-3,AIR)
B(-4,-17,-2,AIR)
B(-4,-17,-1,AIR)
B(-4,-17,0,AIR)
B(-4,-17,1,AIR)
B(-4,-17,2,AIR)
B(-4,-17,3,AIR)
B(-4,-17,4,AIR)
B(-4,-17,5,AIR)
B(-4,-17,6,COBBLESTONE)
B(-4,-17,7,COBBLESTONE)
B(-4,-16,-7,COBBLESTONE)
B(-4,-16,-6,AIR)
B(-4,-16,-5,AIR)
B(-4,-16,-4,AIR)
B(-4,-16,-3,AIR)
B(-4,-16,-2,AIR)
B(-4,-16,-1,AIR)
B(-4,-16,0,COBBLESTONE)
B(-4,-16,1,AIR)
B(-4,-16,2,AIR)
B(-4,-16,3,AIR)
B(-4,-16,4,AIR)
B(-4,-16,5,AIR)
B(-4,-16,6,COBBLESTONE)
B(-4,-16,7,COBBLESTONE)
B(-4,-15,-7,COBBLESTONE)
B(-4,-15,-6,SMOOTH_BRICK)
B(-4,-15,-5,AIR)
B(-4,-15,-4,AIR)
B(-4,-15,-3,AIR)
B(-4,-15,-2,AIR)
B(-4,-15,-1,AIR)
B(-4,-15,0,AIR)
B(-4,-15,1,AIR)
B(-4,-15,2,AIR)
B(-4,-15,3,AIR)
B(-4,-15,4,AIR)
B(-4,-15,5,AIR)
B(-4,-15,6,SMOOTH_BRICK)
B(-4,-15,7,COBBLESTONE)
B(-4,-14,-7,COBBLESTONE)
B(-4,-14,-6,SMOOTH_BRICK)
B(-4,-14,-5,SMOOTH_BRICK)
B(-4,-14,-4,AIR)
B(-4,-14,-3,AIR)
B(-4,-14,-2,AIR)
B(-4,-14,-1,AIR)
B(-4,-14,0,AIR)
B(-4,-14,1,AIR)
B(-4,-14,2,AIR)
B(-4,-14,3,AIR)
B(-4,-14,4,AIR)
B(-4,-14,5,SMOOTH_BRICK)
B(-4,-14,6,SMOOTH_BRICK)
B(-4,-14,7,COBBLESTONE)
B(-4,-13,-7,COBBLESTONE)
B(-4,-13,-6,COBBLESTONE)
B(-4,-13,-5,COBBLESTONE)
B(-4,-13,-4,COBBLESTONE)
B(-4,-13,-3,COBBLESTONE)
B(-4,-13,-2,COBBLESTONE)
B(-4,-13,-1,COBBLESTONE)
B(-4,-13,0,COBBLESTONE)
B(-4,-13,1,COBBLESTONE)
B(-4,-13,2,COBBLESTONE)
B(-4,-13,3,COBBLESTONE)
B(-4,-13,4,COBBLESTONE)
B(-4,-13,5,COBBLESTONE)
B(-4,-13,6,COBBLESTONE)
B(-4,-13,7,COBBLESTONE)
B(-4,-12,-7,COBBLESTONE)
B(-4,-12,-6,COBBLESTONE)
B(-4,-12,-5,COBBLESTONE)
B(-4,-12,-4,COBBLESTONE)
B(-4,-12,-3,COBBLESTONE)
B(-4,-12,-2,COBBLESTONE)
B(-4,-12,-1,COBBLESTONE)
B(-4,-12,0,COBBLESTONE)
B(-4,-12,1,COBBLESTONE)
B(-4,-12,2,COBBLESTONE)
B(-4,-12,3,COBBLESTONE)
B(-4,-12,4,COBBLESTONE)
B(-4,-12,5,COBBLESTONE)
B(-4,-12,6,COBBLESTONE)
B(-4,-12,7,COBBLESTONE)
B(-4,-11,-7,COBBLESTONE)
B(-4,-11,-6,COBBLESTONE)
B(-4,-11,-5,COBBLESTONE)
B(-4,-11,-4,COBBLESTONE)
B(-4,-11,-3,COBBLESTONE)
B(-4,-11,-2,COBBLESTONE)
B(-4,-11,-1,COBBLESTONE)
B(-4,-11,0,COBBLESTONE)
B(-4,-11,1,COBBLESTONE)
B(-4,-11,2,COBBLESTONE)
B(-4,-11,3,COBBLESTONE)
B(-4,-11,4,COBBLESTONE)
B(-4,-11,5,COBBLESTONE)
B(-4,-11,6,COBBLESTONE)
B(-4,-11,7,COBBLESTONE)
B(-4,-10,-7,COBBLESTONE)
B(-4,-10,-6,COBBLESTONE)
B(-4,-10,-5,COBBLESTONE)
B(-4,-10,-4,COBBLESTONE)
B(-4,-10,-3,COBBLESTONE)
B(-4,-10,-2,COBBLESTONE)
B(-4,-10,-1,COBBLESTONE)
B(-4,-10,0,COBBLESTONE)
B(-4,-10,1,COBBLESTONE)
B(-4,-10,2,COBBLESTONE)
B(-4,-10,3,COBBLESTONE)
B(-4,-10,4,COBBLESTONE)
B(-4,-10,5,COBBLESTONE)
B(-4,-10,6,COBBLESTONE)
B(-4,-10,7,COBBLESTONE)
B(-4,-9,-7,COBBLESTONE)
B(-4,-9,-6,COBBLESTONE)
B(-4,-9,-5,COBBLESTONE)
B(-4,-9,-4,COBBLESTONE)
B(-4,-9,-3,COBBLESTONE)
B(-4,-9,-2,COBBLESTONE)
B(-4,-9,-1,COBBLESTONE)
B(-4,-9,0,COBBLESTONE)
B(-4,-9,1,COBBLESTONE)
B(-4,-9,2,COBBLESTONE)
B(-4,-9,3,COBBLESTONE)
B(-4,-9,4,COBBLESTONE)
B(-4,-9,5,COBBLESTONE)
B(-4,-9,6,COBBLESTONE)
B(-4,-9,7,COBBLESTONE)
B(-4,-8,-7,COBBLESTONE)
B(-4,-8,-6,COBBLESTONE)
B(-4,-8,-5,COBBLESTONE)
B(-4,-8,-4,COBBLESTONE)
B(-4,-8,-3,COBBLESTONE)
B(-4,-8,-2,COBBLESTONE)
B(-4,-8,-1,COBBLESTONE)
B(-4,-8,0,COBBLESTONE)
B(-4,-8,1,COBBLESTONE)
B(-4,-8,2,COBBLESTONE)
B(-4,-8,3,COBBLESTONE)
B(-4,-8,4,COBBLESTONE)
B(-4,-8,5,COBBLESTONE)
B(-4,-8,6,COBBLESTONE)
B(-4,-8,7,COBBLESTONE)
B(-4,-7,-7,COBBLESTONE)
B(-4,-7,-6,COBBLESTONE)
B(-4,-7,-5,COBBLESTONE)
B(-4,-7,-4,COBBLESTONE)
B(-4,-7,-3,COBBLESTONE)
B(-4,-7,-2,COBBLESTONE)
B(-4,-7,-1,COBBLESTONE)
B(-4,-7,0,COBBLESTONE)
B(-4,-7,1,COBBLESTONE)
B(-4,-7,2,COBBLESTONE)
B(-4,-7,3,COBBLESTONE)
B(-4,-7,4,COBBLESTONE)
B(-4,-7,5,COBBLESTONE)
B(-4,-7,6,COBBLESTONE)
B(-4,-7,7,COBBLESTONE)
B(-4,-6,-7,COBBLESTONE)
B(-4,-6,-6,COBBLESTONE)
B(-4,-6,-5,COBBLESTONE)
B(-4,-6,-4,COBBLESTONE)
B(-4,-6,-3,COBBLESTONE)
B(-4,-6,-2,COBBLESTONE)
B(-4,-6,-1,COBBLESTONE)
B(-4,-6,0,COBBLESTONE)
B(-4,-6,1,COBBLESTONE)
B(-4,-6,2,COBBLESTONE)
B(-4,-6,3,COBBLESTONE)
B(-4,-6,4,COBBLESTONE)
B(-4,-6,5,COBBLESTONE)
B(-4,-6,6,COBBLESTONE)
B(-4,-6,7,COBBLESTONE)
B(-4,-5,-7,COBBLESTONE)
B(-4,-5,-6,COBBLESTONE)
B(-4,-5,-5,COBBLESTONE)
B(-4,-5,-4,COBBLESTONE)
B(-4,-5,-3,COBBLESTONE)
B(-4,-5,-2,COBBLESTONE)
B(-4,-5,-1,COBBLESTONE)
B(-4,-5,0,COBBLESTONE)
B(-4,-5,1,COBBLESTONE)
B(-4,-5,2,COBBLESTONE)
B(-4,-5,3,COBBLESTONE)
B(-4,-5,4,COBBLESTONE)
B(-4,-5,5,COBBLESTONE)
B(-4,-5,6,COBBLESTONE)
B(-4,-5,7,COBBLESTONE)
B(-4,-4,-7,COBBLESTONE)
B(-4,-4,-6,COBBLESTONE)
B(-4,-4,-5,COBBLESTONE)
B(-4,-4,-4,COBBLESTONE)
B(-4,-4,-3,COBBLESTONE)
B(-4,-4,-2,COBBLESTONE)
B(-4,-4,-1,COBBLESTONE)
B(-4,-4,0,COBBLESTONE)
B(-4,-4,1,COBBLESTONE)
B(-4,-4,2,COBBLESTONE)
B(-4,-4,3,COBBLESTONE)
B(-4,-4,4,COBBLESTONE)
B(-4,-4,5,COBBLESTONE)
B(-4,-4,6,COBBLESTONE)
B(-4,-4,7,COBBLESTONE)
B(-4,-3,-7,COBBLESTONE)
B(-4,-3,-6,COBBLESTONE)
B(-4,-3,-5,COBBLESTONE)
B(-4,-3,-4,COBBLESTONE)
B(-4,-3,-3,COBBLESTONE)
B(-4,-3,-2,COBBLESTONE)
B(-4,-3,-1,COBBLESTONE)
B(-4,-3,0,COBBLESTONE)
B(-4,-3,1,COBBLESTONE)
B(-4,-3,2,COBBLESTONE)
B(-4,-3,3,COBBLESTONE)
B(-4,-3,4,COBBLESTONE)
B(-4,-3,5,COBBLESTONE)
B(-4,-3,6,COBBLESTONE)
B(-4,-3,7,COBBLESTONE)
B(-4,-2,-7,COBBLESTONE)
B(-4,-2,-6,COBBLESTONE)
B(-4,-2,-5,COBBLESTONE)
B(-4,-2,-4,COBBLESTONE)
B(-4,-2,-3,COBBLESTONE)
B(-4,-2,-2,COBBLESTONE)
B(-4,-2,-1,COBBLESTONE)
B(-4,-2,0,COBBLESTONE)
B(-4,-2,1,COBBLESTONE)
B(-4,-2,2,COBBLESTONE)
B(-4,-2,3,COBBLESTONE)
B(-4,-2,4,COBBLESTONE)
B(-4,-2,5,COBBLESTONE)
B(-4,-2,6,COBBLESTONE)
B(-4,-2,7,COBBLESTONE)
B(-4,-1,-7,COBBLESTONE)
B(-4,-1,-6,COBBLESTONE)
B(-4,-1,-5,STONE:6)
B(-4,-1,-4,STONE:6)
B(-4,-1,-3,STONE:6)
B(-4,-1,-2,COBBLESTONE)
B(-4,-1,-1,COBBLESTONE)
B(-4,-1,0,COBBLESTONE)
B(-4,-1,1,COBBLESTONE)
B(-4,-1,2,COBBLESTONE)
B(-4,-1,3,STONE:6)
B(-4,-1,4,STONE:6)
B(-4,-1,5,STONE:6)
B(-4,-1,6,COBBLESTONE)
B(-4,-1,7,COBBLESTONE)
B(-4,0,-7,AIR)
B(-4,0,-6,IRON_DOOR_BLOCK)
B(-4,0,-5,STONE_PLATE)
B(-4,0,-4,AIR)
B(-4,0,-3,AIR)
B(-4,0,-2,SMOOTH_BRICK)
B(-4,0,-1,SMOOTH_BRICK)
B(-4,0,0,SMOOTH_BRICK)
B(-4,0,1,SMOOTH_BRICK)
B(-4,0,2,SMOOTH_BRICK)
B(-4,0,3,AIR)
B(-4,0,4,AIR)
Entity(-4,0,4,ArmorStand,1,ArmorStandCommon3.txt)
B(-4,0,5,AIR)
B(-4,0,6,SMOOTH_BRICK)
B(-4,0,7,AIR)
B(-4,1,-7,AIR)
B(-4,1,-6,IRON_DOOR_BLOCK:9)
B(-4,1,-5,AIR)
B(-4,1,-4,AIR)
B(-4,1,-3,AIR)
B(-4,1,-2,SMOOTH_BRICK)
B(-4,1,-1,SMOOTH_BRICK)
B(-4,1,0,SMOOTH_BRICK)
B(-4,1,1,SMOOTH_BRICK)
B(-4,1,2,SMOOTH_BRICK)
B(-4,1,3,AIR)
B(-4,1,4,AIR)
B(-4,1,5,AIR)
B(-4,1,6,SMOOTH_BRICK)
B(-4,1,7,AIR)
B(-4,2,-7,SMOOTH_BRICK:3)
B(-4,2,-6,SMOOTH_BRICK)
B(-4,2,-5,AIR)
B(-4,2,-4,AIR)
B(-4,2,-3,AIR)
B(-4,2,-2,SMOOTH_BRICK)
B(-4,2,-1,SMOOTH_BRICK:3)
B(-4,2,0,SMOOTH_BRICK)
B(-4,2,1,SMOOTH_BRICK:3)
B(-4,2,2,SMOOTH_BRICK)
B(-4,2,3,AIR)
B(-4,2,4,AIR)
B(-4,2,5,AIR)
B(-4,2,6,SMOOTH_BRICK)
B(-4,2,7,SMOOTH_BRICK:3)
B(-4,3,-7,AIR)
B(-4,3,-6,SMOOTH_BRICK)
B(-4,3,-5,AIR)
B(-4,3,-4,AIR)
B(-4,3,-3,AIR)
B(-4,3,-2,SMOOTH_BRICK)
B(-4,3,-1,SMOOTH_BRICK)
B(-4,3,0,SMOOTH_BRICK)
B(-4,3,1,SMOOTH_BRICK)
B(-4,3,2,SMOOTH_BRICK)
B(-4,3,3,AIR)
B(-4,3,4,AIR)
B(-4,3,5,AIR)
B(-4,3,6,SMOOTH_BRICK)
B(-4,3,7,AIR)
B(-4,4,-7,AIR)
B(-4,4,-6,SMOOTH_BRICK)
B(-4,4,-5,AIR)
B(-4,4,-4,AIR)
B(-4,4,-3,AIR)
B(-4,4,-2,SMOOTH_BRICK)
B(-4,4,-1,SMOOTH_BRICK)
B(-4,4,0,SMOOTH_BRICK)
B(-4,4,1,SMOOTH_BRICK)
B(-4,4,2,SMOOTH_BRICK)
B(-4,4,3,AIR)
B(-4,4,4,AIR)
B(-4,4,5,AIR)
B(-4,4,6,SMOOTH_BRICK)
B(-4,4,7,AIR)
B(-4,5,-7,AIR)
B(-4,5,-6,SMOOTH_STAIRS:2)
B(-4,5,-5,SMOOTH_STAIRS:7)
B(-4,5,-4,AIR)
B(-4,5,-3,SMOOTH_STAIRS:6)
B(-4,5,-2,SMOOTH_BRICK)
B(-4,5,-1,SMOOTH_BRICK)
B(-4,5,0,SMOOTH_BRICK)
B(-4,5,1,SMOOTH_BRICK)
B(-4,5,2,SMOOTH_BRICK)
B(-4,5,3,SMOOTH_STAIRS:7)
B(-4,5,4,AIR)
B(-4,5,5,SMOOTH_STAIRS:6)
B(-4,5,6,SMOOTH_STAIRS)
B(-4,5,7,AIR)
B(-4,6,-7,AIR)
B(-4,6,-6,AIR)
B(-4,6,-5,SMOOTH_BRICK)
B(-4,6,-4,AIR)
B(-4,6,-3,SMOOTH_BRICK)
B(-4,6,-2,SMOOTH_BRICK)
B(-4,6,-1,SMOOTH_BRICK)
B(-4,6,0,IRON_FENCE)
B(-4,6,1,SMOOTH_BRICK)
B(-4,6,2,SMOOTH_BRICK)
B(-4,6,3,SMOOTH_BRICK)
B(-4,6,4,AIR)
B(-4,6,5,SMOOTH_BRICK)
B(-4,6,6,AIR)
B(-4,6,7,AIR)
B(-4,7,-7,AIR)
B(-4,7,-6,AIR)
B(-4,7,-5,SMOOTH_BRICK)
B(-4,7,-4,AIR)
B(-4,7,-3,SMOOTH_BRICK)
B(-4,7,-2,SMOOTH_BRICK)
B(-4,7,-1,SMOOTH_BRICK)
B(-4,7,0,IRON_FENCE)
B(-4,7,1,SMOOTH_BRICK)
B(-4,7,2,SMOOTH_BRICK)
B(-4,7,3,SMOOTH_BRICK)
B(-4,7,4,AIR)
B(-4,7,5,SMOOTH_BRICK)
B(-4,7,6,AIR)
B(-4,7,7,AIR)
B(-4,8,-7,AIR)
B(-4,8,-6,AIR)
B(-4,8,-5,SMOOTH_BRICK)
B(-4,8,-4,AIR)
B(-4,8,-3,SMOOTH_BRICK)
B(-4,8,-2,SMOOTH_BRICK)
B(-4,8,-1,SMOOTH_BRICK)
B(-4,8,0,IRON_FENCE)
B(-4,8,1,SMOOTH_BRICK)
B(-4,8,2,SMOOTH_BRICK)
B(-4,8,3,SMOOTH_BRICK)
B(-4,8,4,AIR)
B(-4,8,5,SMOOTH_BRICK)
B(-4,8,6,AIR)
B(-4,8,7,AIR)
B(-4,9,-7,AIR)
B(-4,9,-6,AIR)
B(-4,9,-5,SMOOTH_BRICK)
B(-4,9,-4,REDSTONE_LAMP_ON)
B(-4,9,-3,SMOOTH_BRICK)
B(-4,9,-2,SMOOTH_BRICK)
B(-4,9,-1,SMOOTH_BRICK)
B(-4,9,0,IRON_FENCE)
B(-4,9,1,SMOOTH_BRICK)
B(-4,9,2,SMOOTH_BRICK)
B(-4,9,3,SMOOTH_BRICK)
B(-4,9,4,REDSTONE_LAMP_ON)
B(-4,9,5,SMOOTH_BRICK)
B(-4,9,6,AIR)
B(-4,9,7,AIR)
B(-4,10,-7,AIR)
B(-4,10,-6,STEP:8)
B(-4,10,-5,SMOOTH_BRICK)
B(-4,10,-4,LEVER:13)
B(-4,10,-3,SMOOTH_BRICK)
B(-4,10,-2,SMOOTH_BRICK)
B(-4,10,-1,SMOOTH_BRICK)
B(-4,10,0,SMOOTH_BRICK)
B(-4,10,1,SMOOTH_BRICK)
B(-4,10,2,SMOOTH_BRICK)
B(-4,10,3,SMOOTH_BRICK)
B(-4,10,4,LEVER:14)
B(-4,10,5,SMOOTH_BRICK)
B(-4,10,6,STEP:8)
B(-4,10,7,AIR)
B(-4,11,-7,AIR)
B(-4,11,-6,STONE:6)
B(-4,11,-5,SMOOTH_BRICK)
B(-4,11,-4,SMOOTH_BRICK:3)
B(-4,11,-3,SMOOTH_BRICK)
B(-4,11,-2,STONE:6)
B(-4,11,-1,STONE:6)
B(-4,11,0,SMOOTH_BRICK)
B(-4,11,1,STONE:6)
B(-4,11,2,STONE:6)
B(-4,11,3,SMOOTH_BRICK)
B(-4,11,4,SMOOTH_BRICK:3)
B(-4,11,5,SMOOTH_BRICK)
B(-4,11,6,STONE:6)
B(-4,11,7,AIR)
B(-4,12,-7,SMOOTH_BRICK)
B(-4,12,-6,SMOOTH_BRICK)
B(-4,12,-5,AIR)
B(-4,12,-4,AIR)
B(-4,12,-3,AIR)
B(-4,12,-2,AIR)
B(-4,12,-1,STONE:6)
B(-4,12,0,SMOOTH_BRICK:3)
B(-4,12,1,STONE:6)
B(-4,12,2,AIR)
B(-4,12,3,AIR)
B(-4,12,4,AIR)
B(-4,12,5,AIR)
B(-4,12,6,SMOOTH_BRICK)
B(-4,12,7,SMOOTH_BRICK)
B(-4,13,-7,STEP)
B(-4,13,-6,AIR)
B(-4,13,-5,AIR)
B(-4,13,-4,AIR)
B(-4,13,-3,AIR)
B(-4,13,-2,AIR)
B(-4,13,-1,STEP)
B(-4,13,0,STEP)
B(-4,13,1,STEP)
B(-4,13,2,AIR)
B(-4,13,3,AIR)
B(-4,13,4,AIR)
B(-4,13,5,AIR)
B(-4,13,6,AIR)
B(-4,13,7,STEP)
B(-3,-24,-7,COBBLESTONE)
B(-3,-24,-6,COBBLESTONE)
B(-3,-24,-5,COBBLESTONE)
B(-3,-24,-4,COBBLESTONE)
B(-3,-24,-3,COBBLESTONE)
B(-3,-24,-2,COBBLESTONE)
B(-3,-24,-1,COBBLESTONE)
B(-3,-24,0,COBBLESTONE)
B(-3,-24,1,COBBLESTONE)
B(-3,-24,2,COBBLESTONE)
B(-3,-24,3,COBBLESTONE)
B(-3,-24,4,COBBLESTONE)
B(-3,-24,5,COBBLESTONE)
B(-3,-24,6,COBBLESTONE)
B(-3,-24,7,COBBLESTONE)
B(-3,-23,-7,COBBLESTONE)
B(-3,-23,-6,COBBLESTONE)
B(-3,-23,-5,WOOD)
B(-3,-23,-4,WOOD)
B(-3,-23,-3,COBBLESTONE)
B(-3,-23,-2,WOOD)
B(-3,-23,-1,WOOD)
B(-3,-23,0,WOOD)
B(-3,-23,1,WOOD)
B(-3,-23,2,STONE:6)
B(-3,-23,3,WOOD)
B(-3,-23,4,WOOD)
B(-3,-23,5,WOOD)
B(-3,-23,6,WOOD)
B(-3,-23,7,COBBLESTONE)
B(-3,-22,-7,COBBLESTONE)
B(-3,-22,-6,SMOOTH_BRICK)
B(-3,-22,-5,WEB)
B(-3,-22,-4,WEB)
B(-3,-22,-3,COBBLESTONE)
B(-3,-22,-2,AIR)
B(-3,-22,-1,AIR)
B(-3,-22,0,AIR)
B(-3,-22,1,AIR)
B(-3,-22,2,AIR)
B(-3,-22,3,AIR)
B(-3,-22,4,AIR)
B(-3,-22,5,AIR)
B(-3,-22,6,AIR)
B(-3,-22,7,COBBLESTONE)
B(-3,-21,-7,COBBLESTONE)
B(-3,-21,-6,SMOOTH_BRICK)
B(-3,-21,-5,AIR)
B(-3,-21,-4,AIR)
B(-3,-21,-3,COBBLESTONE)
B(-3,-21,-2,AIR)
B(-3,-21,-1,AIR)
B(-3,-21,0,AIR)
B(-3,-21,1,AIR)
B(-3,-21,2,AIR)
B(-3,-21,3,AIR)
B(-3,-21,4,AIR)
B(-3,-21,5,AIR)
B(-3,-21,6,AIR)
B(-3,-21,7,COBBLESTONE)
B(-3,-20,-7,COBBLESTONE)
B(-3,-20,-6,SMOOTH_BRICK)
B(-3,-20,-5,AIR)
B(-3,-20,-4,AIR)
B(-3,-20,-3,COBBLESTONE)
B(-3,-20,-2,AIR)
B(-3,-20,-1,AIR)
B(-3,-20,0,AIR)
B(-3,-20,1,AIR)
B(-3,-20,2,AIR)
B(-3,-20,3,AIR)
B(-3,-20,4,AIR)
B(-3,-20,5,AIR)
B(-3,-20,6,AIR)
B(-3,-20,7,COBBLESTONE)
B(-3,-19,-7,COBBLESTONE)
B(-3,-19,-6,SMOOTH_BRICK)
B(-3,-19,-5,AIR)
B(-3,-19,-4,AIR)
B(-3,-19,-3,COBBLESTONE)
B(-3,-19,-2,AIR)
B(-3,-19,-1,AIR)
B(-3,-19,0,AIR)
B(-3,-19,1,AIR)
B(-3,-19,2,AIR)
B(-3,-19,3,AIR)
B(-3,-19,4,AIR)
B(-3,-19,5,AIR)
B(-3,-19,6,AIR)
B(-3,-19,7,COBBLESTONE)
B(-3,-18,-7,COBBLESTONE)
B(-3,-18,-6,SMOOTH_BRICK)
B(-3,-18,-5,AIR)
B(-3,-18,-4,AIR)
B(-3,-18,-3,COBBLESTONE)
B(-3,-18,-2,AIR)
B(-3,-18,-1,AIR)
B(-3,-18,0,AIR)
B(-3,-18,1,AIR)
B(-3,-18,2,AIR)
B(-3,-18,3,AIR)
B(-3,-18,4,AIR)
B(-3,-18,5,AIR)
B(-3,-18,6,AIR)
B(-3,-18,7,COBBLESTONE)
B(-3,-17,-7,COBBLESTONE)
B(-3,-17,-6,SMOOTH_BRICK)
B(-3,-17,-5,AIR)
B(-3,-17,-4,AIR)
B(-3,-17,-3,COBBLESTONE)
B(-3,-17,-2,AIR)
B(-3,-17,-1,AIR)
B(-3,-17,0,AIR)
B(-3,-17,1,AIR)
B(-3,-17,2,AIR)
B(-3,-17,3,AIR)
B(-3,-17,4,AIR)
B(-3,-17,5,AIR)
B(-3,-17,6,AIR)
B(-3,-17,7,COBBLESTONE)
B(-3,-16,-7,COBBLESTONE)
B(-3,-16,-6,SMOOTH_BRICK)
B(-3,-16,-5,AIR)
B(-3,-16,-4,AIR)
B(-3,-16,-3,COBBLESTONE)
B(-3,-16,-2,AIR)
B(-3,-16,-1,AIR)
B(-3,-16,0,COBBLESTONE)
B(-3,-16,1,AIR)
B(-3,-16,2,AIR)
B(-3,-16,3,AIR)
B(-3,-16,4,AIR)
B(-3,-16,5,AIR)
B(-3,-16,6,AIR)
B(-3,-16,7,COBBLESTONE)
B(-3,-15,-7,COBBLESTONE)
B(-3,-15,-6,SMOOTH_BRICK)
B(-3,-15,-5,AIR)
B(-3,-15,-4,AIR)
B(-3,-15,-3,COBBLESTONE)
B(-3,-15,-2,AIR)
B(-3,-15,-1,AIR)
B(-3,-15,0,AIR)
B(-3,-15,1,AIR)
B(-3,-15,2,AIR)
B(-3,-15,3,AIR)
B(-3,-15,4,AIR)
B(-3,-15,5,AIR)
B(-3,-15,6,AIR)
B(-3,-15,7,COBBLESTONE)
B(-3,-14,-7,COBBLESTONE)
B(-3,-14,-6,SMOOTH_BRICK)
B(-3,-14,-5,AIR)
B(-3,-14,-4,AIR)
B(-3,-14,-3,COBBLESTONE)
B(-3,-14,-2,WEB)
B(-3,-14,-1,AIR)
B(-3,-14,0,AIR)
B(-3,-14,1,AIR)
B(-3,-14,2,AIR)
B(-3,-14,3,AIR)
B(-3,-14,4,AIR)
B(-3,-14,5,AIR)
B(-3,-14,6,SMOOTH_BRICK)
B(-3,-14,7,COBBLESTONE)
B(-3,-13,-7,COBBLESTONE)
B(-3,-13,-6,COBBLESTONE)
B(-3,-13,-5,COBBLESTONE)
B(-3,-13,-4,COBBLESTONE)
B(-3,-13,-3,COBBLESTONE)
B(-3,-13,-2,COBBLESTONE)
B(-3,-13,-1,COBBLESTONE)
B(-3,-13,0,COBBLESTONE)
B(-3,-13,1,COBBLESTONE)
B(-3,-13,2,COBBLESTONE)
B(-3,-13,3,COBBLESTONE)
B(-3,-13,4,COBBLESTONE)
B(-3,-13,5,COBBLESTONE)
B(-3,-13,6,COBBLESTONE)
B(-3,-13,7,COBBLESTONE)
B(-3,-12,-7,COBBLESTONE)
B(-3,-12,-6,COBBLESTONE)
B(-3,-12,-5,COBBLESTONE)
B(-3,-12,-4,COBBLESTONE)
B(-3,-12,-3,COBBLESTONE)
B(-3,-12,-2,COBBLESTONE)
B(-3,-12,-1,COBBLESTONE)
B(-3,-12,0,COBBLESTONE)
B(-3,-12,1,COBBLESTONE)
B(-3,-12,2,COBBLESTONE)
B(-3,-12,3,COBBLESTONE)
B(-3,-12,4,COBBLESTONE)
B(-3,-12,5,COBBLESTONE)
B(-3,-12,6,COBBLESTONE)
B(-3,-12,7,COBBLESTONE)
B(-3,-11,-7,COBBLESTONE)
B(-3,-11,-6,COBBLESTONE)
B(-3,-11,-5,COBBLESTONE)
B(-3,-11,-4,COBBLESTONE)
B(-3,-11,-3,COBBLESTONE)
B(-3,-11,-2,COBBLESTONE)
B(-3,-11,-1,COBBLESTONE)
B(-3,-11,0,COBBLESTONE)
B(-3,-11,1,COBBLESTONE)
B(-3,-11,2,COBBLESTONE)
B(-3,-11,3,COBBLESTONE)
B(-3,-11,4,COBBLESTONE)
B(-3,-11,5,COBBLESTONE)
B(-3,-11,6,COBBLESTONE)
B(-3,-11,7,COBBLESTONE)
B(-3,-10,-7,COBBLESTONE)
B(-3,-10,-6,COBBLESTONE)
B(-3,-10,-5,COBBLESTONE)
B(-3,-10,-4,COBBLESTONE)
B(-3,-10,-3,COBBLESTONE)
B(-3,-10,-2,COBBLESTONE)
B(-3,-10,-1,COBBLESTONE)
B(-3,-10,0,COBBLESTONE)
B(-3,-10,1,COBBLESTONE)
B(-3,-10,2,COBBLESTONE)
B(-3,-10,3,COBBLESTONE)
B(-3,-10,4,COBBLESTONE)
B(-3,-10,5,COBBLESTONE)
B(-3,-10,6,COBBLESTONE)
B(-3,-10,7,COBBLESTONE)
B(-3,-9,-7,COBBLESTONE)
B(-3,-9,-6,COBBLESTONE)
B(-3,-9,-5,COBBLESTONE)
B(-3,-9,-4,COBBLESTONE)
B(-3,-9,-3,COBBLESTONE)
B(-3,-9,-2,COBBLESTONE)
B(-3,-9,-1,COBBLESTONE)
B(-3,-9,0,COBBLESTONE)
B(-3,-9,1,COBBLESTONE)
B(-3,-9,2,COBBLESTONE)
B(-3,-9,3,COBBLESTONE)
B(-3,-9,4,COBBLESTONE)
B(-3,-9,5,COBBLESTONE)
B(-3,-9,6,COBBLESTONE)
B(-3,-9,7,COBBLESTONE)
B(-3,-8,-7,COBBLESTONE)
B(-3,-8,-6,COBBLESTONE)
B(-3,-8,-5,COBBLESTONE)
B(-3,-8,-4,COBBLESTONE)
B(-3,-8,-3,COBBLESTONE)
B(-3,-8,-2,COBBLESTONE)
B(-3,-8,-1,COBBLESTONE)
B(-3,-8,0,COBBLESTONE)
B(-3,-8,1,COBBLESTONE)
B(-3,-8,2,COBBLESTONE)
B(-3,-8,3,COBBLESTONE)
B(-3,-8,4,COBBLESTONE)
B(-3,-8,5,COBBLESTONE)
B(-3,-8,6,COBBLESTONE)
B(-3,-8,7,COBBLESTONE)
B(-3,-7,-7,COBBLESTONE)
B(-3,-7,-6,COBBLESTONE)
B(-3,-7,-5,COBBLESTONE)
B(-3,-7,-4,COBBLESTONE)
B(-3,-7,-3,COBBLESTONE)
B(-3,-7,-2,COBBLESTONE)
B(-3,-7,-1,COBBLESTONE)
B(-3,-7,0,COBBLESTONE)
B(-3,-7,1,COBBLESTONE)
B(-3,-7,2,COBBLESTONE)
B(-3,-7,3,COBBLESTONE)
B(-3,-7,4,COBBLESTONE)
B(-3,-7,5,COBBLESTONE)
B(-3,-7,6,COBBLESTONE)
B(-3,-7,7,COBBLESTONE)
B(-3,-6,-7,COBBLESTONE)
B(-3,-6,-6,COBBLESTONE)
B(-3,-6,-5,COBBLESTONE)
B(-3,-6,-4,COBBLESTONE)
B(-3,-6,-3,COBBLESTONE)
B(-3,-6,-2,COBBLESTONE)
B(-3,-6,-1,COBBLESTONE)
B(-3,-6,0,COBBLESTONE)
B(-3,-6,1,COBBLESTONE)
B(-3,-6,2,COBBLESTONE)
B(-3,-6,3,COBBLESTONE)
B(-3,-6,4,COBBLESTONE)
B(-3,-6,5,COBBLESTONE)
B(-3,-6,6,COBBLESTONE)
B(-3,-6,7,COBBLESTONE)
B(-3,-5,-7,COBBLESTONE)
B(-3,-5,-6,COBBLESTONE)
B(-3,-5,-5,COBBLESTONE)
B(-3,-5,-4,COBBLESTONE)
B(-3,-5,-3,COBBLESTONE)
B(-3,-5,-2,COBBLESTONE)
B(-3,-5,-1,COBBLESTONE)
B(-3,-5,0,COBBLESTONE)
B(-3,-5,1,COBBLESTONE)
B(-3,-5,2,COBBLESTONE)
B(-3,-5,3,COBBLESTONE)
B(-3,-5,4,COBBLESTONE)
B(-3,-5,5,COBBLESTONE)
B(-3,-5,6,COBBLESTONE)
B(-3,-5,7,COBBLESTONE)
B(-3,-4,-7,COBBLESTONE)
B(-3,-4,-6,COBBLESTONE)
B(-3,-4,-5,COBBLESTONE)
B(-3,-4,-4,COBBLESTONE)
B(-3,-4,-3,COBBLESTONE)
B(-3,-4,-2,COBBLESTONE)
B(-3,-4,-1,COBBLESTONE)
B(-3,-4,0,COBBLESTONE)
B(-3,-4,1,COBBLESTONE)
B(-3,-4,2,COBBLESTONE)
B(-3,-4,3,COBBLESTONE)
B(-3,-4,4,COBBLESTONE)
B(-3,-4,5,COBBLESTONE)
B(-3,-4,6,COBBLESTONE)
B(-3,-4,7,COBBLESTONE)
B(-3,-3,-7,COBBLESTONE)
B(-3,-3,-6,COBBLESTONE)
B(-3,-3,-5,COBBLESTONE)
B(-3,-3,-4,COBBLESTONE)
B(-3,-3,-3,COBBLESTONE)
B(-3,-3,-2,COBBLESTONE)
B(-3,-3,-1,COBBLESTONE)
B(-3,-3,0,COBBLESTONE)
B(-3,-3,1,COBBLESTONE)
B(-3,-3,2,COBBLESTONE)
B(-3,-3,3,COBBLESTONE)
B(-3,-3,4,COBBLESTONE)
B(-3,-3,5,COBBLESTONE)
B(-3,-3,6,COBBLESTONE)
B(-3,-3,7,COBBLESTONE)
B(-3,-2,-7,COBBLESTONE)
B(-3,-2,-6,COBBLESTONE)
B(-3,-2,-5,COBBLESTONE)
B(-3,-2,-4,COBBLESTONE)
B(-3,-2,-3,COBBLESTONE)
B(-3,-2,-2,COBBLESTONE)
B(-3,-2,-1,COBBLESTONE)
B(-3,-2,0,COBBLESTONE)
B(-3,-2,1,COBBLESTONE)
B(-3,-2,2,COBBLESTONE)
B(-3,-2,3,COBBLESTONE)
B(-3,-2,4,COBBLESTONE)
B(-3,-2,5,COBBLESTONE)
B(-3,-2,6,COBBLESTONE)
B(-3,-2,7,COBBLESTONE)
B(-3,-1,-7,COBBLESTONE)
B(-3,-1,-6,COBBLESTONE)
B(-3,-1,-5,STONE:6)
B(-3,-1,-4,STONE:6)
B(-3,-1,-3,STONE:6)
B(-3,-1,-2,STEP:8)
B(-3,-1,-1,COBBLESTONE)
B(-3,-1,0,STEP:8)
B(-3,-1,1,COBBLESTONE)
B(-3,-1,2,STEP:8)
B(-3,-1,3,STONE:6)
B(-3,-1,4,STONE:6)
B(-3,-1,5,STONE:6)
B(-3,-1,6,COBBLESTONE)
B(-3,-1,7,COBBLESTONE)
B(-3,0,-7,SMOOTH_BRICK)
B(-3,0,-6,SMOOTH_BRICK)
B(-3,0,-5,AIR)
B(-3,0,-4,AIR)
B(-3,0,-3,AIR)
B(-3,0,-2,AIR)
B(-3,0,-1,SMOOTH_BRICK)
B(-3,0,0,STEP)
B(-3,0,1,SMOOTH_BRICK)
B(-3,0,2,AIR)
B(-3,0,3,AIR)
Entity(-3,0,3,Zombie,1,Zombie.txt)
B(-3,0,4,AIR)
B(-3,0,5,AIR)
B(-3,0,6,SMOOTH_BRICK)
B(-3,0,7,SMOOTH_BRICK)
B(-3,1,-7,SMOOTH_BRICK)
B(-3,1,-6,SMOOTH_BRICK)
B(-3,1,-5,AIR)
B(-3,1,-4,AIR)
B(-3,1,-3,AIR)
B(-3,1,-2,AIR)
B(-3,1,-1,SMOOTH_BRICK)
B(-3,1,0,AIR)
B(-3,1,1,SMOOTH_BRICK)
B(-3,1,2,AIR)
B(-3,1,3,AIR)
B(-3,1,4,AIR)
B(-3,1,5,AIR)
B(-3,1,6,SMOOTH_BRICK)
B(-3,1,7,SMOOTH_BRICK)
B(-3,2,-7,SMOOTH_BRICK)
B(-3,2,-6,SMOOTH_BRICK)
B(-3,2,-5,AIR)
B(-3,2,-4,AIR)
B(-3,2,-3,AIR)
B(-3,2,-2,SMOOTH_BRICK)
B(-3,2,-1,SMOOTH_BRICK)
B(-3,2,0,AIR)
B(-3,2,1,SMOOTH_BRICK)
B(-3,2,2,SMOOTH_BRICK)
B(-3,2,3,AIR)
B(-3,2,4,AIR)
B(-3,2,5,AIR)
B(-3,2,6,SMOOTH_BRICK)
B(-3,2,7,SMOOTH_BRICK)
B(-3,3,-7,SMOOTH_BRICK)
B(-3,3,-6,SMOOTH_BRICK)
B(-3,3,-5,AIR)
B(-3,3,-4,AIR)
B(-3,3,-3,AIR)
B(-3,3,-2,SMOOTH_BRICK)
B(-3,3,-1,SMOOTH_BRICK)
B(-3,3,0,AIR)
B(-3,3,1,SMOOTH_BRICK)
B(-3,3,2,SMOOTH_BRICK)
B(-3,3,3,AIR)
B(-3,3,4,AIR)
B(-3,3,5,AIR)
B(-3,3,6,SMOOTH_BRICK)
B(-3,3,7,SMOOTH_BRICK)
B(-3,4,-7,SMOOTH_STAIRS:2)
B(-3,4,-6,SMOOTH_BRICK)
B(-3,4,-5,AIR)
B(-3,4,-4,AIR)
B(-3,4,-3,AIR)
B(-3,4,-2,SMOOTH_BRICK)
B(-3,4,-1,SMOOTH_STAIRS)
B(-3,4,0,AIR)
B(-3,4,1,SMOOTH_STAIRS:2)
B(-3,4,2,SMOOTH_BRICK)
B(-3,4,3,AIR)
B(-3,4,4,AIR)
B(-3,4,5,AIR)
B(-3,4,6,SMOOTH_BRICK)
B(-3,4,7,SMOOTH_STAIRS)
B(-3,5,-7,AIR)
B(-3,5,-6,SMOOTH_BRICK)
B(-3,5,-5,SMOOTH_STAIRS:4)
B(-3,5,-4,SMOOTH_STAIRS:4)
B(-3,5,-3,SMOOTH_STAIRS:4)
B(-3,5,-2,SMOOTH_BRICK)
B(-3,5,-1,AIR)
B(-3,5,0,AIR)
B(-3,5,1,AIR)
B(-3,5,2,SMOOTH_BRICK)
B(-3,5,3,SMOOTH_STAIRS:7)
B(-3,5,4,SMOOTH_STAIRS:4)
B(-3,5,5,SMOOTH_STAIRS:6)
B(-3,5,6,SMOOTH_BRICK)
B(-3,5,7,AIR)
B(-3,6,-7,AIR)
B(-3,6,-6,SMOOTH_BRICK)
B(-3,6,-5,SMOOTH_BRICK)
B(-3,6,-4,SMOOTH_BRICK)
B(-3,6,-3,SMOOTH_BRICK)
B(-3,6,-2,AIR)
B(-3,6,-1,AIR)
B(-3,6,0,AIR)
B(-3,6,1,AIR)
B(-3,6,2,AIR)
B(-3,6,3,SMOOTH_BRICK)
B(-3,6,4,SMOOTH_BRICK)
B(-3,6,5,SMOOTH_BRICK)
B(-3,6,6,SMOOTH_BRICK)
B(-3,6,7,AIR)
B(-3,7,-7,AIR)
B(-3,7,-6,SMOOTH_BRICK)
B(-3,7,-5,SMOOTH_BRICK)
B(-3,7,-4,SMOOTH_BRICK)
B(-3,7,-3,SMOOTH_BRICK)
B(-3,7,-2,AIR)
B(-3,7,-1,AIR)
B(-3,7,0,AIR)
B(-3,7,1,AIR)
B(-3,7,2,AIR)
B(-3,7,3,SMOOTH_BRICK)
B(-3,7,4,SMOOTH_BRICK)
B(-3,7,5,SMOOTH_BRICK)
B(-3,7,6,SMOOTH_BRICK)
B(-3,7,7,AIR)
B(-3,8,-7,AIR)
B(-3,8,-6,SMOOTH_BRICK)
B(-3,8,-5,SMOOTH_BRICK)
B(-3,8,-4,SMOOTH_BRICK)
B(-3,8,-3,SMOOTH_BRICK)
B(-3,8,-2,STEP:8)
B(-3,8,-1,AIR)
B(-3,8,0,AIR)
B(-3,8,1,AIR)
B(-3,8,2,STEP:8)
B(-3,8,3,SMOOTH_BRICK)
B(-3,8,4,SMOOTH_BRICK)
B(-3,8,5,SMOOTH_BRICK)
B(-3,8,6,SMOOTH_BRICK)
B(-3,8,7,AIR)
B(-3,9,-7,AIR)
B(-3,9,-6,SMOOTH_BRICK)
B(-3,9,-5,SMOOTH_BRICK)
B(-3,9,-4,SMOOTH_BRICK)
B(-3,9,-3,SMOOTH_BRICK)
B(-3,9,-2,SMOOTH_BRICK)
B(-3,9,-1,AIR)
B(-3,9,0,AIR)
B(-3,9,1,AIR)
B(-3,9,2,SMOOTH_BRICK)
B(-3,9,3,SMOOTH_BRICK)
B(-3,9,4,SMOOTH_BRICK)
B(-3,9,5,SMOOTH_BRICK)
B(-3,9,6,SMOOTH_BRICK)
B(-3,9,7,AIR)
B(-3,10,-7,AIR)
B(-3,10,-6,SMOOTH_BRICK)
B(-3,10,-5,SMOOTH_BRICK)
B(-3,10,-4,SMOOTH_BRICK)
B(-3,10,-3,SMOOTH_BRICK)
B(-3,10,-2,SMOOTH_BRICK)
B(-3,10,-1,AIR)
B(-3,10,0,AIR)
B(-3,10,1,AIR)
B(-3,10,2,SMOOTH_BRICK)
B(-3,10,3,SMOOTH_BRICK)
B(-3,10,4,SMOOTH_BRICK)
B(-3,10,5,SMOOTH_BRICK)
B(-3,10,6,SMOOTH_BRICK)
B(-3,10,7,AIR)
B(-3,11,-7,SMOOTH_STAIRS:6)
B(-3,11,-6,SMOOTH_BRICK)
B(-3,11,-5,SMOOTH_BRICK)
B(-3,11,-4,SMOOTH_BRICK)
B(-3,11,-3,SMOOTH_BRICK)
B(-3,11,-2,SMOOTH_BRICK)
B(-3,11,-1,SMOOTH_STAIRS:7)
B(-3,11,0,SMOOTH_BRICK)
B(-3,11,1,SMOOTH_STAIRS:6)
B(-3,11,2,SMOOTH_BRICK)
B(-3,11,3,SMOOTH_BRICK)
B(-3,11,4,SMOOTH_BRICK)
B(-3,11,5,SMOOTH_BRICK)
B(-3,11,6,SMOOTH_BRICK)
B(-3,11,7,SMOOTH_STAIRS:7)
B(-3,12,-7,SMOOTH_BRICK)
B(-3,12,-6,STEP)
RB(-3,12,-5,TRAPPED_CHEST:3,../../nbt/Chests/TrappedChest1.nbt,15,TRAPPED_CHEST:3,../../nbt/Chests/TrappedChest2.nbt,15,TRAPPED_CHEST:3,../../nbt/Chests/TrappedChest3.nbt,15,TRAPPED_CHEST:3,../../nbt/Chests/TrappedChest4.nbt,15,TRAPPED_CHEST:3,../../nbt/Chests/TrappedChest5.nbt,15,TRAPPED_CHEST:3,../../nbt/Chests/TrappedChest6.nbt,15,TRAPPED_CHEST:3,../../nbt/Chests/TrappedChest7.nbt,15,TRAPPED_CHEST:3,../../nbt/Chests/TrappedChest8.nbt,100)
B(-3,12,-4,AIR)
B(-3,12,-3,AIR)
B(-3,12,-2,AIR)
B(-3,12,-1,AIR)
B(-3,12,0,AIR)
B(-3,12,1,AIR)
B(-3,12,2,AIR)
B(-3,12,3,AIR)
B(-3,12,4,AIR)
B(-3,12,5,AIR)
B(-3,12,6,STEP)
B(-3,12,7,SMOOTH_BRICK)
B(-3,13,-7,STONE:6)
B(-3,13,-6,AIR)
B(-3,13,-5,AIR)
B(-3,13,-4,AIR)
B(-3,13,-3,AIR)
B(-3,13,-2,AIR)
B(-3,13,-1,AIR)
B(-3,13,0,AIR)
B(-3,13,1,AIR)
B(-3,13,2,AIR)
B(-3,13,3,AIR)
B(-3,13,4,AIR)
B(-3,13,5,AIR)
B(-3,13,6,AIR)
B(-3,13,7,STONE:6)
B(-2,-24,-7,COBBLESTONE)
B(-2,-24,-6,COBBLESTONE)
B(-2,-24,-5,COBBLESTONE)
B(-2,-24,-4,COBBLESTONE)
B(-2,-24,-3,COBBLESTONE)
B(-2,-24,-2,COBBLESTONE)
B(-2,-24,-1,COBBLESTONE)
B(-2,-24,0,COBBLESTONE)
B(-2,-24,1,COBBLESTONE)
B(-2,-24,2,COBBLESTONE)
B(-2,-24,3,COBBLESTONE)
B(-2,-24,4,COBBLESTONE)
B(-2,-24,5,COBBLESTONE)
B(-2,-24,6,COBBLESTONE)
B(-2,-24,7,COBBLESTONE)
B(-2,-23,-7,COBBLESTONE)
B(-2,-23,-6,COBBLESTONE)
B(-2,-23,-5,WOOD)
B(-2,-23,-4,WOOD)
B(-2,-23,-3,WOOD)
B(-2,-23,-2,WOOD)
B(-2,-23,-1,WOOD)
B(-2,-23,0,WOOD)
B(-2,-23,1,WOOD)
B(-2,-23,2,STONE:6)
B(-2,-23,3,WOOD)
B(-2,-23,4,DOUBLE_STEP:3)
B(-2,-23,5,WOOD)
B(-2,-23,6,WOOD)
B(-2,-23,7,COBBLESTONE)
B(-2,-22,-7,COBBLESTONE)
B(-2,-22,-6,COBBLESTONE)
B(-2,-22,-5,WEB)
B(-2,-22,-4,AIR)
B(-2,-22,-3,WEB)
B(-2,-22,-2,AIR)
B(-2,-22,-1,AIR)
B(-2,-22,0,WEB)
B(-2,-22,1,AIR)
B(-2,-22,2,WEB)
B(-2,-22,3,GRAVEL)
B(-2,-22,4,STEP:3)
B(-2,-22,5,GRAVEL)
B(-2,-22,6,AIR)
B(-2,-22,7,COBBLESTONE)
B(-2,-21,-7,COBBLESTONE)
B(-2,-21,-6,COBBLESTONE)
B(-2,-21,-5,WEB)
B(-2,-21,-4,AIR)
B(-2,-21,-3,WEB)
B(-2,-21,-2,AIR)
B(-2,-21,-1,AIR)
B(-2,-21,0,WEB)
B(-2,-21,1,AIR)
B(-2,-21,2,AIR)
B(-2,-21,3,WEB)
B(-2,-21,4,AIR)
B(-2,-21,5,AIR)
B(-2,-21,6,AIR)
B(-2,-21,7,COBBLESTONE)
B(-2,-20,-7,COBBLESTONE)
RB(-2,-20,-6,CHEST:3,../../nbt/VanillaLoot/simple_dungeon.nbt,50,CHEST:3,../../nbt/VanillaLoot/stronghold_crossing.nbt,100)
B(-2,-20,-5,WEB)
B(-2,-20,-4,AIR)
B(-2,-20,-3,AIR)
B(-2,-20,-2,AIR)
B(-2,-20,-1,AIR)
B(-2,-20,0,AIR)
B(-2,-20,1,AIR)
B(-2,-20,2,AIR)
B(-2,-20,3,AIR)
B(-2,-20,4,AIR)
B(-2,-20,5,AIR)
B(-2,-20,6,AIR)
B(-2,-20,7,COBBLESTONE)
B(-2,-19,-7,COBBLESTONE)
B(-2,-19,-6,AIR)
B(-2,-19,-5,AIR)
B(-2,-19,-4,AIR)
B(-2,-19,-3,AIR)
B(-2,-19,-2,AIR)
B(-2,-19,-1,AIR)
B(-2,-19,0,AIR)
B(-2,-19,1,AIR)
B(-2,-19,2,AIR)
B(-2,-19,3,AIR)
B(-2,-19,4,AIR)
B(-2,-19,5,AIR)
B(-2,-19,6,AIR)
B(-2,-19,7,COBBLESTONE)
B(-2,-18,-7,COBBLESTONE)
B(-2,-18,-6,SMOOTH_BRICK)
B(-2,-18,-5,WEB)
B(-2,-18,-4,AIR)
B(-2,-18,-3,AIR)
B(-2,-18,-2,AIR)
B(-2,-18,-1,AIR)
B(-2,-18,0,AIR)
B(-2,-18,1,AIR)
B(-2,-18,2,AIR)
B(-2,-18,3,AIR)
B(-2,-18,4,AIR)
B(-2,-18,5,AIR)
B(-2,-18,6,AIR)
B(-2,-18,7,COBBLESTONE)
B(-2,-17,-7,COBBLESTONE)
RB(-2,-17,-6,CHEST:3,../../nbt/VanillaLoot/simple_dungeon.nbt,50,CHEST:3,../../nbt/VanillaLoot/stronghold_crossing.nbt,100)
B(-2,-17,-5,AIR)
B(-2,-17,-4,AIR)
B(-2,-17,-3,AIR)
B(-2,-17,-2,AIR)
B(-2,-17,-1,AIR)
B(-2,-17,0,AIR)
B(-2,-17,1,AIR)
B(-2,-17,2,AIR)
B(-2,-17,3,AIR)
B(-2,-17,4,AIR)
B(-2,-17,5,AIR)
B(-2,-17,6,AIR)
B(-2,-17,7,COBBLESTONE)
B(-2,-16,-7,COBBLESTONE)
B(-2,-16,-6,AIR)
B(-2,-16,-5,AIR)
B(-2,-16,-4,AIR)
B(-2,-16,-3,AIR)
B(-2,-16,-2,AIR)
B(-2,-16,-1,AIR)
B(-2,-16,0,COBBLESTONE)
B(-2,-16,1,AIR)
B(-2,-16,2,AIR)
B(-2,-16,3,AIR)
B(-2,-16,4,AIR)
B(-2,-16,5,AIR)
B(-2,-16,6,AIR)
B(-2,-16,7,COBBLESTONE)
B(-2,-15,-7,COBBLESTONE)
B(-2,-15,-6,SMOOTH_STAIRS)
B(-2,-15,-5,AIR)
B(-2,-15,-4,AIR)
B(-2,-15,-3,AIR)
B(-2,-15,-2,AIR)
B(-2,-15,-1,AIR)
B(-2,-15,0,AIR)
B(-2,-15,1,AIR)
B(-2,-15,2,AIR)
B(-2,-15,3,AIR)
B(-2,-15,4,AIR)
B(-2,-15,5,AIR)
B(-2,-15,6,SMOOTH_BRICK)
B(-2,-15,7,COBBLESTONE)
B(-2,-14,-7,COBBLESTONE)
B(-2,-14,-6,SMOOTH_BRICK)
B(-2,-14,-5,AIR)
B(-2,-14,-4,AIR)
B(-2,-14,-3,AIR)
B(-2,-14,-2,AIR)
B(-2,-14,-1,AIR)
B(-2,-14,0,AIR)
B(-2,-14,1,AIR)
B(-2,-14,2,AIR)
B(-2,-14,3,AIR)
B(-2,-14,4,AIR)
B(-2,-14,5,AIR)
B(-2,-14,6,SMOOTH_BRICK)
B(-2,-14,7,COBBLESTONE)
B(-2,-13,-7,COBBLESTONE)
B(-2,-13,-6,COBBLESTONE)
B(-2,-13,-5,COBBLESTONE)
B(-2,-13,-4,COBBLESTONE)
B(-2,-13,-3,COBBLESTONE)
B(-2,-13,-2,COBBLESTONE)
B(-2,-13,-1,COBBLESTONE)
B(-2,-13,0,COBBLESTONE)
B(-2,-13,1,COBBLESTONE)
B(-2,-13,2,COBBLESTONE)
B(-2,-13,3,COBBLESTONE)
B(-2,-13,4,COBBLESTONE)
B(-2,-13,5,COBBLESTONE)
B(-2,-13,6,COBBLESTONE)
B(-2,-13,7,COBBLESTONE)
B(-2,-12,-6,COBBLESTONE)
B(-2,-12,-5,COBBLESTONE)
B(-2,-12,-4,COBBLESTONE)
B(-2,-12,-3,COBBLESTONE)
B(-2,-12,-2,COBBLESTONE)
B(-2,-12,-1,COBBLESTONE)
B(-2,-12,0,COBBLESTONE)
B(-2,-12,1,COBBLESTONE)
B(-2,-12,2,COBBLESTONE)
B(-2,-12,3,COBBLESTONE)
B(-2,-12,4,COBBLESTONE)
B(-2,-12,5,COBBLESTONE)
B(-2,-12,6,COBBLESTONE)
B(-2,-11,-6,COBBLESTONE)
B(-2,-11,-5,COBBLESTONE)
B(-2,-11,-4,COBBLESTONE)
B(-2,-11,-3,COBBLESTONE)
B(-2,-11,-2,COBBLESTONE)
B(-2,-11,-1,COBBLESTONE)
B(-2,-11,0,COBBLESTONE)
B(-2,-11,1,COBBLESTONE)
B(-2,-11,2,COBBLESTONE)
B(-2,-11,3,COBBLESTONE)
B(-2,-11,4,COBBLESTONE)
B(-2,-11,5,COBBLESTONE)
B(-2,-11,6,COBBLESTONE)
B(-2,-10,-6,COBBLESTONE)
B(-2,-10,-5,COBBLESTONE)
B(-2,-10,-4,COBBLESTONE)
B(-2,-10,-3,COBBLESTONE)
B(-2,-10,-2,COBBLESTONE)
B(-2,-10,-1,COBBLESTONE)
B(-2,-10,0,COBBLESTONE)
B(-2,-10,1,COBBLESTONE)
B(-2,-10,2,COBBLESTONE)
B(-2,-10,3,COBBLESTONE)
B(-2,-10,4,COBBLESTONE)
B(-2,-10,5,COBBLESTONE)
B(-2,-10,6,COBBLESTONE)
B(-2,-9,-6,COBBLESTONE)
B(-2,-9,-5,COBBLESTONE)
B(-2,-9,-4,COBBLESTONE)
B(-2,-9,-3,COBBLESTONE)
B(-2,-9,-2,COBBLESTONE)
B(-2,-9,-1,COBBLESTONE)
B(-2,-9,0,COBBLESTONE)
B(-2,-9,1,COBBLESTONE)
B(-2,-9,2,COBBLESTONE)
B(-2,-9,3,COBBLESTONE)
B(-2,-9,4,COBBLESTONE)
B(-2,-9,5,COBBLESTONE)
B(-2,-9,6,COBBLESTONE)
B(-2,-8,-6,COBBLESTONE)
B(-2,-8,-5,COBBLESTONE)
B(-2,-8,-4,COBBLESTONE)
B(-2,-8,-3,COBBLESTONE)
B(-2,-8,-2,COBBLESTONE)
B(-2,-8,-1,COBBLESTONE)
B(-2,-8,0,COBBLESTONE)
B(-2,-8,1,COBBLESTONE)
B(-2,-8,2,COBBLESTONE)
B(-2,-8,3,COBBLESTONE)
B(-2,-8,4,COBBLESTONE)
B(-2,-8,5,COBBLESTONE)
B(-2,-8,6,COBBLESTONE)
B(-2,-7,-6,COBBLESTONE)
B(-2,-7,-5,COBBLESTONE)
B(-2,-7,-4,COBBLESTONE)
B(-2,-7,-3,COBBLESTONE)
B(-2,-7,-2,COBBLESTONE)
B(-2,-7,-1,COBBLESTONE)
B(-2,-7,0,COBBLESTONE)
B(-2,-7,1,COBBLESTONE)
B(-2,-7,2,COBBLESTONE)
B(-2,-7,3,COBBLESTONE)
B(-2,-7,4,COBBLESTONE)
B(-2,-7,5,COBBLESTONE)
B(-2,-7,6,COBBLESTONE)
B(-2,-6,-6,COBBLESTONE)
B(-2,-6,-5,COBBLESTONE)
B(-2,-6,-4,COBBLESTONE)
B(-2,-6,-3,COBBLESTONE)
B(-2,-6,-2,COBBLESTONE)
B(-2,-6,-1,COBBLESTONE)
B(-2,-6,0,COBBLESTONE)
B(-2,-6,1,COBBLESTONE)
B(-2,-6,2,COBBLESTONE)
B(-2,-6,3,COBBLESTONE)
B(-2,-6,4,COBBLESTONE)
B(-2,-6,5,COBBLESTONE)
B(-2,-6,6,COBBLESTONE)
B(-2,-5,-6,COBBLESTONE)
B(-2,-5,-5,COBBLESTONE)
B(-2,-5,-4,COBBLESTONE)
B(-2,-5,-3,COBBLESTONE)
B(-2,-5,-2,COBBLESTONE)
B(-2,-5,-1,COBBLESTONE)
B(-2,-5,0,COBBLESTONE)
B(-2,-5,1,COBBLESTONE)
B(-2,-5,2,COBBLESTONE)
B(-2,-5,3,COBBLESTONE)
B(-2,-5,4,COBBLESTONE)
B(-2,-5,5,COBBLESTONE)
B(-2,-5,6,COBBLESTONE)
B(-2,-4,-6,COBBLESTONE)
B(-2,-4,-5,COBBLESTONE)
B(-2,-4,-4,COBBLESTONE)
B(-2,-4,-3,COBBLESTONE)
B(-2,-4,-2,COBBLESTONE)
B(-2,-4,-1,COBBLESTONE)
B(-2,-4,0,COBBLESTONE)
B(-2,-4,1,COBBLESTONE)
B(-2,-4,2,COBBLESTONE)
B(-2,-4,3,COBBLESTONE)
B(-2,-4,4,COBBLESTONE)
B(-2,-4,5,COBBLESTONE)
B(-2,-4,6,COBBLESTONE)
B(-2,-3,-6,COBBLESTONE)
B(-2,-3,-5,COBBLESTONE)
B(-2,-3,-4,COBBLESTONE)
B(-2,-3,-3,COBBLESTONE)
B(-2,-3,-2,COBBLESTONE)
B(-2,-3,-1,COBBLESTONE)
B(-2,-3,0,COBBLESTONE)
B(-2,-3,1,COBBLESTONE)
B(-2,-3,2,COBBLESTONE)
B(-2,-3,3,COBBLESTONE)
B(-2,-3,4,COBBLESTONE)
B(-2,-3,5,COBBLESTONE)
B(-2,-3,6,COBBLESTONE)
B(-2,-2,-6,COBBLESTONE)
B(-2,-2,-5,COBBLESTONE)
B(-2,-2,-4,COBBLESTONE)
B(-2,-2,-3,COBBLESTONE)
B(-2,-2,-2,COBBLESTONE)
B(-2,-2,-1,COBBLESTONE)
B(-2,-2,0,COBBLESTONE)
B(-2,-2,1,COBBLESTONE)
B(-2,-2,2,COBBLESTONE)
B(-2,-2,3,COBBLESTONE)
B(-2,-2,4,COBBLESTONE)
B(-2,-2,5,COBBLESTONE)
B(-2,-2,6,COBBLESTONE)
B(-2,-1,-6,COBBLESTONE)
B(-2,-1,-5,COBBLESTONE)
B(-2,-1,-4,COBBLESTONE)
B(-2,-1,-3,STEP:8)
B(-2,-1,-2,STONE:6)
B(-2,-1,-1,STONE:6)
B(-2,-1,0,STONE:6)
B(-2,-1,1,STONE:6)
B(-2,-1,2,STONE:6)
B(-2,-1,3,STEP:8)
B(-2,-1,4,COBBLESTONE)
B(-2,-1,5,COBBLESTONE)
B(-2,-1,6,COBBLESTONE)
B(-2,0,-7,AIR)
B(-2,0,-6,STONE:6)
B(-2,0,-5,SMOOTH_BRICK)
B(-2,0,-4,SMOOTH_BRICK)
B(-2,0,-3,AIR)
B(-2,0,-2,AIR)
B(-2,0,-1,AIR)
B(-2,0,0,AIR)
B(-2,0,1,AIR)
B(-2,0,2,AIR)
B(-2,0,3,AIR)
B(-2,0,4,SMOOTH_BRICK)
B(-2,0,5,SMOOTH_BRICK)
B(-2,0,6,STONE:6)
B(-2,0,7,AIR)
B(-2,1,-7,AIR)
B(-2,1,-6,STEP)
B(-2,1,-5,SMOOTH_BRICK)
B(-2,1,-4,SMOOTH_BRICK)
B(-2,1,-3,AIR)
B(-2,1,-2,AIR)
B(-2,1,-1,AIR)
B(-2,1,0,AIR)
B(-2,1,1,AIR)
B(-2,1,2,AIR)
B(-2,1,3,AIR)
B(-2,1,4,SMOOTH_BRICK)
B(-2,1,5,SMOOTH_BRICK)
B(-2,1,6,STEP)
B(-2,1,7,AIR)
B(-2,2,-7,AIR)
B(-2,2,-6,AIR)
B(-2,2,-5,SMOOTH_BRICK)
B(-2,2,-4,SMOOTH_BRICK)
B(-2,2,-3,SMOOTH_BRICK)
B(-2,2,-2,SMOOTH_BRICK)
B(-2,2,-1,AIR)
B(-2,2,0,AIR)
B(-2,2,1,AIR)
B(-2,2,2,SMOOTH_BRICK)
B(-2,2,3,SMOOTH_BRICK)
B(-2,2,4,SMOOTH_BRICK)
B(-2,2,5,SMOOTH_BRICK)
B(-2,2,6,AIR)
B(-2,2,7,AIR)
B(-2,3,-7,STEP:8)
B(-2,3,-6,STEP:8)
B(-2,3,-5,SMOOTH_BRICK)
B(-2,3,-4,SMOOTH_BRICK)
B(-2,3,-3,SMOOTH_BRICK)
B(-2,3,-2,COBBLE_WALL)
B(-2,3,-1,AIR)
B(-2,3,0,AIR)
B(-2,3,1,AIR)
B(-2,3,2,COBBLE_WALL)
B(-2,3,3,SMOOTH_BRICK)
B(-2,3,4,SMOOTH_BRICK)
B(-2,3,5,SMOOTH_BRICK)
B(-2,3,6,STEP:8)
B(-2,3,7,STEP:8)
B(-2,4,-7,STEP:5)
B(-2,4,-6,DOUBLE_STEP:5)
B(-2,4,-5,SMOOTH_BRICK)
B(-2,4,-4,SMOOTH_BRICK)
B(-2,4,-3,SMOOTH_BRICK)
B(-2,4,-2,COBBLE_WALL)
B(-2,4,-1,AIR)
B(-2,4,0,AIR)
B(-2,4,1,AIR)
B(-2,4,2,COBBLE_WALL)
B(-2,4,3,SMOOTH_BRICK)
B(-2,4,4,SMOOTH_BRICK)
B(-2,4,5,SMOOTH_BRICK)
B(-2,4,6,DOUBLE_STEP:5)
B(-2,4,7,STEP:5)
B(-2,5,-7,AIR)
B(-2,5,-6,AIR)
B(-2,5,-5,SMOOTH_BRICK)
B(-2,5,-4,SMOOTH_BRICK)
B(-2,5,-3,SMOOTH_BRICK)
B(-2,5,-2,AIR)
B(-2,5,-1,AIR)
B(-2,5,0,AIR)
B(-2,5,1,AIR)
B(-2,5,2,AIR)
B(-2,5,3,SMOOTH_BRICK)
B(-2,5,4,SMOOTH_BRICK)
B(-2,5,5,SMOOTH_BRICK)
B(-2,5,6,AIR)
B(-2,5,7,AIR)
B(-2,6,-7,AIR)
B(-2,6,-6,AIR)
B(-2,6,-5,SMOOTH_BRICK)
B(-2,6,-4,SMOOTH_BRICK)
B(-2,6,-3,AIR)
B(-2,6,-2,AIR)
B(-2,6,-1,AIR)
B(-2,6,0,AIR)
B(-2,6,1,AIR)
B(-2,6,2,AIR)
B(-2,6,3,AIR)
B(-2,6,4,SMOOTH_BRICK)
B(-2,6,5,SMOOTH_BRICK)
B(-2,6,6,AIR)
B(-2,6,7,AIR)
B(-2,7,-7,AIR)
B(-2,7,-6,AIR)
B(-2,7,-5,SMOOTH_BRICK)
B(-2,7,-4,SMOOTH_BRICK)
B(-2,7,-3,AIR)
B(-2,7,-2,AIR)
B(-2,7,-1,AIR)
B(-2,7,0,AIR)
B(-2,7,1,AIR)
B(-2,7,2,AIR)
B(-2,7,3,AIR)
B(-2,7,4,SMOOTH_BRICK)
B(-2,7,5,SMOOTH_BRICK)
B(-2,7,6,AIR)
B(-2,7,7,AIR)
B(-2,8,-7,AIR)
B(-2,8,-6,AIR)
B(-2,8,-5,SMOOTH_BRICK)
B(-2,8,-4,SMOOTH_BRICK)
B(-2,8,-3,STEP:8)
B(-2,8,-2,AIR)
B(-2,8,-1,AIR)
B(-2,8,0,AIR)
B(-2,8,1,AIR)
B(-2,8,2,AIR)
B(-2,8,3,STEP:8)
B(-2,8,4,SMOOTH_BRICK)
B(-2,8,5,SMOOTH_BRICK)
B(-2,8,6,AIR)
B(-2,8,7,AIR)
B(-2,9,-7,AIR)
B(-2,9,-6,AIR)
B(-2,9,-5,SMOOTH_BRICK)
B(-2,9,-4,SMOOTH_BRICK)
B(-2,9,-3,SMOOTH_BRICK)
B(-2,9,-2,AIR)
B(-2,9,-1,AIR)
B(-2,9,0,AIR)
B(-2,9,1,AIR)
B(-2,9,2,AIR)
B(-2,9,3,SMOOTH_BRICK)
B(-2,9,4,SMOOTH_BRICK)
B(-2,9,5,SMOOTH_BRICK)
B(-2,9,6,AIR)
B(-2,9,7,AIR)
B(-2,10,-7,AIR)
B(-2,10,-6,STEP:8)
B(-2,10,-5,SMOOTH_BRICK)
B(-2,10,-4,SMOOTH_BRICK)
B(-2,10,-3,SMOOTH_BRICK)
B(-2,10,-2,STEP:8)
B(-2,10,-1,AIR)
B(-2,10,0,AIR)
B(-2,10,1,AIR)
B(-2,10,2,STEP:8)
B(-2,10,3,SMOOTH_BRICK)
B(-2,10,4,SMOOTH_BRICK)
B(-2,10,5,SMOOTH_BRICK)
B(-2,10,6,STEP:8)
B(-2,10,7,AIR)
B(-2,11,-7,STEP:13)
B(-2,11,-6,SMOOTH_BRICK)
B(-2,11,-5,SMOOTH_BRICK)
B(-2,11,-4,STONE:6)
B(-2,11,-3,SMOOTH_BRICK)
B(-2,11,-2,SMOOTH_BRICK)
B(-2,11,-1,STEP:13)
B(-2,11,0,SMOOTH_BRICK)
B(-2,11,1,STEP:13)
B(-2,11,2,SMOOTH_BRICK)
B(-2,11,3,SMOOTH_BRICK)
B(-2,11,4,STONE:6)
B(-2,11,5,SMOOTH_BRICK)
B(-2,11,6,SMOOTH_BRICK)
B(-2,11,7,STEP:13)
B(-2,12,-7,SMOOTH_BRICK)
B(-2,12,-6,STEP)
B(-2,12,-5,STEP)
B(-2,12,-4,AIR)
B(-2,12,-3,AIR)
B(-2,12,-2,AIR)
B(-2,12,-1,AIR)
B(-2,12,0,AIR)
B(-2,12,1,AIR)
B(-2,12,2,AIR)
B(-2,12,3,AIR)
B(-2,12,4,AIR)
B(-2,12,5,STEP)
B(-2,12,6,STEP)
B(-2,12,7,SMOOTH_BRICK)
B(-2,13,-7,STEP)
B(-2,13,-6,AIR)
B(-2,13,-5,AIR)
B(-2,13,-4,AIR)
B(-2,13,-3,AIR)
B(-2,13,-2,AIR)
B(-2,13,-1,AIR)
B(-2,13,0,AIR)
B(-2,13,1,AIR)
B(-2,13,2,AIR)
B(-2,13,3,AIR)
B(-2,13,4,AIR)
B(-2,13,5,AIR)
B(-2,13,6,AIR)
B(-2,13,7,STEP)
B(-1,-24,-7,COBBLESTONE)
B(-1,-24,-6,COBBLESTONE)
B(-1,-24,-5,COBBLESTONE)
B(-1,-24,-4,COBBLESTONE)
B(-1,-24,-3,COBBLESTONE)
B(-1,-24,-2,COBBLESTONE)
B(-1,-24,-1,COBBLESTONE)
B(-1,-24,0,COBBLESTONE)
B(-1,-24,1,COBBLESTONE)
B(-1,-24,2,COBBLESTONE)
B(-1,-24,3,COBBLESTONE)
B(-1,-24,4,COBBLESTONE)
B(-1,-24,5,COBBLESTONE)
B(-1,-24,6,COBBLESTONE)
B(-1,-24,7,COBBLESTONE)
B(-1,-23,-7,COBBLESTONE)
B(-1,-23,-6,COBBLESTONE)
B(-1,-23,-5,WOOD)
B(-1,-23,-4,WOOD)
B(-1,-23,-3,WOOD)
B(-1,-23,-2,WOOD)
B(-1,-23,-1,WOOD)
B(-1,-23,0,WOOD)
B(-1,-23,1,STONE:6)
B(-1,-23,2,STONE:6)
B(-1,-23,3,STONE:6)
B(-1,-23,4,WOOD)
B(-1,-23,5,COBBLESTONE)
B(-1,-23,6,COBBLESTONE)
B(-1,-23,7,COBBLESTONE)
B(-1,-22,-7,COBBLESTONE)
B(-1,-22,-6,COBBLESTONE)
B(-1,-22,-5,WEB)
B(-1,-22,-4,WEB)
B(-1,-22,-3,WEB)
B(-1,-22,-2,WEB)
B(-1,-22,-1,AIR)
B(-1,-22,0,AIR)
B(-1,-22,1,AIR)
B(-1,-22,2,AIR)
B(-1,-22,3,AIR)
B(-1,-22,4,STEP:3)
B(-1,-22,5,COBBLESTONE)
B(-1,-22,6,COBBLESTONE)
B(-1,-22,7,COBBLESTONE)
B(-1,-21,-7,COBBLESTONE)
B(-1,-21,-6,COBBLESTONE)
B(-1,-21,-5,AIR)
B(-1,-21,-4,AIR)
B(-1,-21,-3,AIR)
B(-1,-21,-2,AIR)
B(-1,-21,-1,AIR)
B(-1,-21,0,AIR)
B(-1,-21,1,AIR)
B(-1,-21,2,AIR)
B(-1,-21,3,AIR)
B(-1,-21,4,AIR)
B(-1,-21,5,COBBLESTONE)
B(-1,-21,6,STEP:3)
B(-1,-21,7,COBBLESTONE)
B(-1,-20,-7,COBBLESTONE)
B(-1,-20,-6,CHEST:3)
B(-1,-20,-5,AIR)
B(-1,-20,-4,AIR)
B(-1,-20,-3,AIR)
B(-1,-20,-2,AIR)
B(-1,-20,-1,AIR)
B(-1,-20,0,AIR)
B(-1,-20,1,AIR)
B(-1,-20,2,AIR)
B(-1,-20,3,AIR)
B(-1,-20,4,AIR)
B(-1,-20,5,COBBLESTONE)
B(-1,-20,6,AIR)
B(-1,-20,7,COBBLESTONE)
B(-1,-19,-7,COBBLESTONE)
B(-1,-19,-6,WEB)
B(-1,-19,-5,AIR)
B(-1,-19,-4,AIR)
B(-1,-19,-3,AIR)
B(-1,-19,-2,AIR)
B(-1,-19,-1,AIR)
B(-1,-19,0,AIR)
B(-1,-19,1,AIR)
B(-1,-19,2,AIR)
B(-1,-19,3,STEP:11)
B(-1,-19,4,AIR)
B(-1,-19,5,COBBLESTONE)
B(-1,-19,6,COBBLESTONE)
B(-1,-19,7,COBBLESTONE)
B(-1,-18,-7,COBBLESTONE)
B(-1,-18,-6,SMOOTH_STAIRS:5)
B(-1,-18,-5,AIR)
B(-1,-18,-4,AIR)
B(-1,-18,-3,AIR)
B(-1,-18,-2,AIR)
B(-1,-18,-1,AIR)
B(-1,-18,0,AIR)
B(-1,-18,1,AIR)
B(-1,-18,2,AIR)
B(-1,-18,3,AIR)
B(-1,-18,4,COBBLESTONE)
B(-1,-18,5,COBBLESTONE)
B(-1,-18,6,COBBLESTONE)
B(-1,-18,7,COBBLESTONE)
B(-1,-17,-7,COBBLESTONE)
B(-1,-17,-6,CHEST:3)
B(-1,-17,-5,AIR)
B(-1,-17,-4,AIR)
B(-1,-17,-3,AIR)
B(-1,-17,-2,AIR)
B(-1,-17,-1,AIR)
B(-1,-17,0,AIR)
B(-1,-17,1,AIR)
B(-1,-17,2,AIR)
B(-1,-17,3,AIR)
B(-1,-17,4,AIR)
B(-1,-17,5,COBBLESTONE)
B(-1,-17,6,STEP:11)
B(-1,-17,7,COBBLESTONE)
B(-1,-16,-7,COBBLESTONE)
B(-1,-16,-6,AIR)
B(-1,-16,-5,AIR)
B(-1,-16,-4,AIR)
B(-1,-16,-3,AIR)
B(-1,-16,-2,AIR)
B(-1,-16,-1,AIR)
B(-1,-16,0,COBBLESTONE)
B(-1,-16,1,AIR)
B(-1,-16,2,AIR)
B(-1,-16,3,AIR)
B(-1,-16,4,AIR)
B(-1,-16,5,COBBLESTONE)
B(-1,-16,6,COBBLESTONE)
B(-1,-16,7,COBBLESTONE)
B(-1,-15,-7,COBBLESTONE)
B(-1,-15,-6,STONE:6)
B(-1,-15,-5,AIR)
B(-1,-15,-4,AIR)
B(-1,-15,-3,AIR)
B(-1,-15,-2,AIR)
B(-1,-15,-1,AIR)
B(-1,-15,0,AIR)
B(-1,-15,1,AIR)
B(-1,-15,2,AIR)
B(-1,-15,3,COBBLESTONE)
B(-1,-15,4,AIR)
B(-1,-15,5,COBBLESTONE)
B(-1,-15,6,COBBLESTONE)
B(-1,-15,7,COBBLESTONE)
B(-1,-14,-7,COBBLESTONE)
B(-1,-14,-6,SMOOTH_BRICK)
B(-1,-14,-5,AIR)
B(-1,-14,-4,AIR)
B(-1,-14,-3,AIR)
B(-1,-14,-2,AIR)
B(-1,-14,-1,AIR)
B(-1,-14,0,AIR)
B(-1,-14,1,AIR)
B(-1,-14,2,AIR)
B(-1,-14,3,COBBLESTONE)
B(-1,-14,4,COBBLESTONE)
B(-1,-14,5,COBBLESTONE)
B(-1,-14,6,COBBLESTONE)
B(-1,-14,7,COBBLESTONE)
B(-1,-13,-7,COBBLESTONE)
B(-1,-13,-6,COBBLESTONE)
B(-1,-13,-5,COBBLESTONE)
B(-1,-13,-4,COBBLESTONE)
B(-1,-13,-3,COBBLESTONE)
B(-1,-13,-2,COBBLESTONE)
B(-1,-13,-1,COBBLESTONE)
B(-1,-13,0,COBBLESTONE)
B(-1,-13,1,COBBLESTONE)
B(-1,-13,2,COBBLESTONE)
B(-1,-13,3,COBBLESTONE)
B(-1,-13,4,COBBLESTONE)
B(-1,-13,5,COBBLESTONE)
B(-1,-13,6,COBBLESTONE)
B(-1,-13,7,COBBLESTONE)
B(-1,-12,-5,COBBLESTONE)
B(-1,-12,-4,COBBLESTONE)
B(-1,-12,-3,COBBLESTONE)
B(-1,-12,-2,COBBLESTONE)
B(-1,-12,-1,COBBLESTONE)
B(-1,-12,0,COBBLESTONE)
B(-1,-12,1,COBBLESTONE)
B(-1,-12,2,COBBLESTONE)
B(-1,-12,3,COBBLESTONE)
B(-1,-12,4,COBBLESTONE)
B(-1,-12,5,COBBLESTONE)
B(-1,-11,-5,COBBLESTONE)
B(-1,-11,-4,COBBLESTONE)
B(-1,-11,-3,COBBLESTONE)
B(-1,-11,-2,COBBLESTONE)
B(-1,-11,-1,COBBLESTONE)
B(-1,-11,0,COBBLESTONE)
B(-1,-11,1,COBBLESTONE)
B(-1,-11,2,COBBLESTONE)
B(-1,-11,3,COBBLESTONE)
B(-1,-11,4,COBBLESTONE)
B(-1,-11,5,COBBLESTONE)
B(-1,-10,-5,COBBLESTONE)
B(-1,-10,-4,COBBLESTONE)
B(-1,-10,-3,COBBLESTONE)
B(-1,-10,-2,COBBLESTONE)
B(-1,-10,-1,COBBLESTONE)
B(-1,-10,0,COBBLESTONE)
B(-1,-10,1,COBBLESTONE)
B(-1,-10,2,COBBLESTONE)
B(-1,-10,3,COBBLESTONE)
B(-1,-10,4,COBBLESTONE)
B(-1,-10,5,COBBLESTONE)
B(-1,-9,-5,COBBLESTONE)
B(-1,-9,-4,COBBLESTONE)
B(-1,-9,-3,COBBLESTONE)
B(-1,-9,-2,COBBLESTONE)
B(-1,-9,-1,COBBLESTONE)
B(-1,-9,0,COBBLESTONE)
B(-1,-9,1,COBBLESTONE)
B(-1,-9,2,COBBLESTONE)
B(-1,-9,3,COBBLESTONE)
B(-1,-9,4,COBBLESTONE)
B(-1,-9,5,COBBLESTONE)
B(-1,-8,-5,COBBLESTONE)
B(-1,-8,-4,COBBLESTONE)
B(-1,-8,-3,COBBLESTONE)
B(-1,-8,-2,COBBLESTONE)
B(-1,-8,-1,COBBLESTONE)
B(-1,-8,0,COBBLESTONE)
B(-1,-8,1,COBBLESTONE)
B(-1,-8,2,COBBLESTONE)
B(-1,-8,3,COBBLESTONE)
B(-1,-8,4,COBBLESTONE)
B(-1,-8,5,COBBLESTONE)
B(-1,-7,-5,COBBLESTONE)
B(-1,-7,-4,COBBLESTONE)
B(-1,-7,-3,COBBLESTONE)
B(-1,-7,-2,COBBLESTONE)
B(-1,-7,-1,COBBLESTONE)
B(-1,-7,0,COBBLESTONE)
B(-1,-7,1,COBBLESTONE)
B(-1,-7,2,COBBLESTONE)
B(-1,-7,3,COBBLESTONE)
B(-1,-7,4,COBBLESTONE)
B(-1,-7,5,COBBLESTONE)
B(-1,-6,-5,COBBLESTONE)
B(-1,-6,-4,COBBLESTONE)
B(-1,-6,-3,COBBLESTONE)
B(-1,-6,-2,COBBLESTONE)
B(-1,-6,-1,COBBLESTONE)
B(-1,-6,0,COBBLESTONE)
B(-1,-6,1,COBBLESTONE)
B(-1,-6,2,COBBLESTONE)
B(-1,-6,3,COBBLESTONE)
B(-1,-6,4,COBBLESTONE)
B(-1,-6,5,COBBLESTONE)
B(-1,-5,-5,COBBLESTONE)
B(-1,-5,-4,COBBLESTONE)
B(-1,-5,-3,COBBLESTONE)
B(-1,-5,-2,COBBLESTONE)
B(-1,-5,-1,COBBLESTONE)
B(-1,-5,0,COBBLESTONE)
B(-1,-5,1,COBBLESTONE)
B(-1,-5,2,COBBLESTONE)
B(-1,-5,3,COBBLESTONE)
B(-1,-5,4,COBBLESTONE)
B(-1,-5,5,COBBLESTONE)
B(-1,-4,-5,COBBLESTONE)
B(-1,-4,-4,COBBLESTONE)
B(-1,-4,-3,COBBLESTONE)
B(-1,-4,-2,COBBLESTONE)
B(-1,-4,-1,COBBLESTONE)
B(-1,-4,0,COBBLESTONE)
B(-1,-4,1,COBBLESTONE)
B(-1,-4,2,COBBLESTONE)
B(-1,-4,3,COBBLESTONE)
B(-1,-4,4,COBBLESTONE)
B(-1,-4,5,COBBLESTONE)
B(-1,-3,-5,COBBLESTONE)
B(-1,-3,-4,COBBLESTONE)
B(-1,-3,-3,COBBLESTONE)
B(-1,-3,-2,COBBLESTONE)
B(-1,-3,-1,COBBLESTONE)
B(-1,-3,0,COBBLESTONE)
B(-1,-3,1,COBBLESTONE)
B(-1,-3,2,COBBLESTONE)
B(-1,-3,3,COBBLESTONE)
B(-1,-3,4,COBBLESTONE)
B(-1,-3,5,COBBLESTONE)
B(-1,-2,-5,COBBLESTONE)
B(-1,-2,-4,COBBLESTONE)
B(-1,-2,-3,COBBLESTONE)
B(-1,-2,-2,COBBLESTONE)
B(-1,-2,-1,COBBLESTONE)
B(-1,-2,0,COBBLESTONE)
B(-1,-2,1,COBBLESTONE)
B(-1,-2,2,COBBLESTONE)
B(-1,-2,3,COBBLESTONE)
B(-1,-2,4,COBBLESTONE)
B(-1,-2,5,COBBLESTONE)
B(-1,-1,-5,COBBLESTONE)
B(-1,-1,-4,COBBLESTONE)
B(-1,-1,-3,COBBLESTONE)
B(-1,-1,-2,STONE:6)
B(-1,-1,-1,STEP:8)
B(-1,-1,0,STEP:8)
B(-1,-1,1,STEP:8)
B(-1,-1,2,STONE:6)
B(-1,-1,3,COBBLESTONE)
B(-1,-1,4,COBBLESTONE)
B(-1,-1,5,COBBLESTONE)
B(-1,0,-7,AIR)
B(-1,0,-6,AIR)
B(-1,0,-5,SMOOTH_BRICK)
B(-1,0,-4,SMOOTH_BRICK)
B(-1,0,-3,SMOOTH_BRICK)
B(-1,0,-2,AIR)
B(-1,0,-1,AIR)
B(-1,0,0,AIR)
B(-1,0,1,AIR)
B(-1,0,2,AIR)
B(-1,0,3,SMOOTH_BRICK)
B(-1,0,4,SMOOTH_BRICK)
B(-1,0,5,SMOOTH_BRICK)
B(-1,0,6,AIR)
B(-1,0,7,AIR)
B(-1,1,-7,AIR)
B(-1,1,-6,AIR)
B(-1,1,-5,SMOOTH_BRICK)
B(-1,1,-4,SMOOTH_BRICK)
B(-1,1,-3,SMOOTH_BRICK)
B(-1,1,-2,AIR)
B(-1,1,-1,AIR)
B(-1,1,0,AIR)
B(-1,1,1,AIR)
B(-1,1,2,AIR)
B(-1,1,3,SMOOTH_BRICK)
B(-1,1,4,SMOOTH_BRICK)
B(-1,1,5,SMOOTH_BRICK)
B(-1,1,6,AIR)
B(-1,1,7,AIR)
B(-1,2,-7,AIR)
B(-1,2,-6,AIR)
B(-1,2,-5,SMOOTH_BRICK)
B(-1,2,-4,SMOOTH_BRICK:3)
B(-1,2,-3,SMOOTH_BRICK)
B(-1,2,-2,AIR)
B(-1,2,-1,AIR)
B(-1,2,0,AIR)
B(-1,2,1,AIR)
B(-1,2,2,STEP:5)
B(-1,2,3,SMOOTH_BRICK)
B(-1,2,4,SMOOTH_BRICK:3)
B(-1,2,5,SMOOTH_BRICK)
B(-1,2,6,AIR)
B(-1,2,7,AIR)
B(-1,3,-7,AIR)
B(-1,3,-6,STEP:8)
B(-1,3,-5,SMOOTH_BRICK)
B(-1,3,-4,SMOOTH_BRICK)
B(-1,3,-3,SMOOTH_BRICK)
B(-1,3,-2,AIR)
B(-1,3,-1,AIR)
B(-1,3,0,AIR)
B(-1,3,1,AIR)
B(-1,3,2,AIR)
B(-1,3,3,SMOOTH_BRICK)
B(-1,3,4,SMOOTH_BRICK)
B(-1,3,5,SMOOTH_BRICK)
B(-1,3,6,STEP:8)
B(-1,3,7,AIR)
B(-1,4,-7,AIR)
B(-1,4,-6,STEP:5)
B(-1,4,-5,SMOOTH_STAIRS:1)
B(-1,4,-4,SMOOTH_BRICK)
B(-1,4,-3,SMOOTH_STAIRS:1)
B(-1,4,-2,AIR)
B(-1,4,-1,AIR)
B(-1,4,0,AIR)
B(-1,4,1,AIR)
B(-1,4,2,AIR)
B(-1,4,3,SMOOTH_STAIRS:1)
B(-1,4,4,SMOOTH_BRICK)
B(-1,4,5,SMOOTH_STAIRS:1)
B(-1,4,6,STEP:5)
B(-1,4,7,AIR)
B(-1,5,-7,AIR)
B(-1,5,-6,AIR)
B(-1,5,-5,AIR)
B(-1,5,-4,SMOOTH_BRICK)
B(-1,5,-3,AIR)
B(-1,5,-2,AIR)
B(-1,5,-1,AIR)
B(-1,5,0,AIR)
B(-1,5,1,AIR)
B(-1,5,2,AIR)
B(-1,5,3,AIR)
B(-1,5,4,SMOOTH_BRICK)
B(-1,5,5,AIR)
B(-1,5,6,AIR)
B(-1,5,7,AIR)
B(-1,6,-7,AIR)
B(-1,6,-6,AIR)
B(-1,6,-5,AIR)
B(-1,6,-4,SMOOTH_BRICK)
B(-1,6,-3,AIR)
B(-1,6,-2,AIR)
B(-1,6,-1,AIR)
B(-1,6,0,AIR)
B(-1,6,1,AIR)
B(-1,6,2,AIR)
B(-1,6,3,AIR)
B(-1,6,4,SMOOTH_BRICK)
B(-1,6,5,AIR)
B(-1,6,6,AIR)
B(-1,6,7,AIR)
B(-1,7,-7,AIR)
B(-1,7,-6,AIR)
B(-1,7,-5,AIR)
B(-1,7,-4,SMOOTH_BRICK)
B(-1,7,-3,AIR)
B(-1,7,-2,AIR)
B(-1,7,-1,AIR)
B(-1,7,0,AIR)
B(-1,7,1,AIR)
B(-1,7,2,AIR)
B(-1,7,3,AIR)
B(-1,7,4,SMOOTH_BRICK)
B(-1,7,5,AIR)
B(-1,7,6,AIR)
B(-1,7,7,AIR)
B(-1,8,-7,AIR)
B(-1,8,-6,AIR)
B(-1,8,-5,AIR)
B(-1,8,-4,SMOOTH_BRICK)
B(-1,8,-3,AIR)
B(-1,8,-2,AIR)
B(-1,8,-1,AIR)
B(-1,8,0,AIR)
B(-1,8,1,AIR)
B(-1,8,2,AIR)
B(-1,8,3,AIR)
B(-1,8,4,SMOOTH_BRICK)
B(-1,8,5,AIR)
B(-1,8,6,AIR)
B(-1,8,7,AIR)
B(-1,9,-7,AIR)
B(-1,9,-6,AIR)
B(-1,9,-5,AIR)
B(-1,9,-4,SMOOTH_BRICK)
B(-1,9,-3,AIR)
B(-1,9,-2,AIR)
B(-1,9,-1,AIR)
B(-1,9,0,AIR)
B(-1,9,1,AIR)
B(-1,9,2,AIR)
B(-1,9,3,AIR)
B(-1,9,4,SMOOTH_BRICK)
B(-1,9,5,AIR)
B(-1,9,6,AIR)
B(-1,9,7,AIR)
B(-1,10,-7,AIR)
B(-1,10,-6,AIR)
B(-1,10,-5,AIR)
B(-1,10,-4,SMOOTH_BRICK)
B(-1,10,-3,AIR)
B(-1,10,-2,AIR)
B(-1,10,-1,COBBLE_WALL)
B(-1,10,0,AIR)
B(-1,10,1,COBBLE_WALL)
B(-1,10,2,AIR)
B(-1,10,3,AIR)
B(-1,10,4,SMOOTH_BRICK)
B(-1,10,5,AIR)
B(-1,10,6,AIR)
B(-1,10,7,AIR)
B(-1,11,-7,AIR)
B(-1,11,-6,STEP:13)
B(-1,11,-5,SMOOTH_STAIRS:5)
B(-1,11,-4,STONE:6)
B(-1,11,-3,SMOOTH_STAIRS:5)
B(-1,11,-2,STEP:13)
B(-1,11,-1,STONE:6)
B(-1,11,0,SMOOTH_BRICK)
B(-1,11,1,STONE:6)
B(-1,11,2,STEP:13)
B(-1,11,3,SMOOTH_STAIRS:5)
B(-1,11,4,STONE:6)
B(-1,11,5,SMOOTH_STAIRS:5)
B(-1,11,6,STEP:13)
B(-1,11,7,AIR)
B(-1,12,-7,STEP:8)
B(-1,12,-6,SMOOTH_STAIRS:0)
B(-1,12,-5,SMOOTH_STAIRS:0)
B(-1,12,-4,STONE:6)
B(-1,12,-3,AIR)
B(-1,12,-2,AIR)
B(-1,12,-1,AIR)
B(-1,12,0,AIR)
B(-1,12,1,AIR)
B(-1,12,2,AIR)
B(-1,12,3,AIR)
B(-1,12,4,STONE:6)
B(-1,12,5,SMOOTH_STAIRS:0)
B(-1,12,6,SMOOTH_STAIRS:0)
B(-1,12,7,STEP:8)
B(-1,13,-7,STONE:6)
B(-1,13,-6,AIR)
B(-1,13,-5,AIR)
B(-1,13,-4,STEP)
B(-1,13,-3,AIR)
B(-1,13,-2,AIR)
B(-1,13,-1,AIR)
B(-1,13,0,AIR)
B(-1,13,1,AIR)
B(-1,13,2,AIR)
B(-1,13,3,AIR)
B(-1,13,4,STEP)
B(-1,13,5,AIR)
B(-1,13,6,AIR)
B(-1,13,7,STONE:6)
B(0,-24,-7,COBBLESTONE)
B(0,-24,-6,COBBLESTONE)
B(0,-24,-5,COBBLESTONE)
B(0,-24,-4,COBBLESTONE)
B(0,-24,-3,COBBLESTONE)
B(0,-24,-2,COBBLESTONE)
B(0,-24,-1,COBBLESTONE)
B(0,-24,0,COBBLESTONE)
B(0,-24,1,COBBLESTONE)
B(0,-24,2,COBBLESTONE)
B(0,-24,3,COBBLESTONE)
B(0,-24,4,COBBLESTONE)
B(0,-24,5,COBBLESTONE)
B(0,-24,6,COBBLESTONE)
B(0,-24,7,COBBLESTONE)
B(0,-23,-7,COBBLESTONE)
B(0,-23,-6,COBBLESTONE)
B(0,-23,-5,STONE:6)
B(0,-23,-4,STONE:6)
B(0,-23,-3,STONE:6)
B(0,-23,-2,STONE:6)
B(0,-23,-1,STONE:6)
B(0,-23,0,STONE:6)
B(0,-23,1,STONE:6)
B(0,-23,2,SMOOTH_BRICK:3)
B(0,-23,3,STONE:6)
B(0,-23,4,STONE:6)
B(0,-23,5,COBBLESTONE)
B(0,-23,6,COBBLESTONE)
B(0,-23,7,COBBLESTONE)
B(0,-22,-7,COBBLESTONE)
B(0,-22,-6,STONE:6)
B(0,-22,-5,WEB)
B(0,-22,-4,AIR)
B(0,-22,-3,MOB_SPAWNER,../../nbt/Spawner/Spider.nbt)
B(0,-22,-2,AIR)
B(0,-22,-1,WEB)
B(0,-22,0,AIR)
B(0,-22,1,WEB)
B(0,-22,2,WEB)
B(0,-22,3,STEP:3)
B(0,-22,4,WEB)
B(0,-22,5,COBBLESTONE)
B(0,-22,6,COBBLESTONE)
B(0,-22,7,COBBLESTONE)
B(0,-21,-7,COBBLESTONE)
B(0,-21,-6,STONE:6)
B(0,-21,-5,WEB)
B(0,-21,-4,AIR)
B(0,-21,-3,WEB)
B(0,-21,-2,AIR)
B(0,-21,-1,WEB)
B(0,-21,0,AIR)
B(0,-21,1,AIR)
B(0,-21,2,AIR)
B(0,-21,3,AIR)
B(0,-21,4,AIR)
B(0,-21,5,COBBLESTONE)
B(0,-21,6,COBBLESTONE)
B(0,-21,7,COBBLESTONE)
B(0,-20,-7,COBBLESTONE)
B(0,-20,-6,STONE:6)
B(0,-20,-5,AIR)
B(0,-20,-4,AIR)
B(0,-20,-3,AIR)
B(0,-20,-2,AIR)
B(0,-20,-1,AIR)
B(0,-20,0,AIR)
B(0,-20,1,AIR)
B(0,-20,2,AIR)
B(0,-20,3,AIR)
B(0,-20,4,COBBLESTONE)
B(0,-20,5,COBBLESTONE)
B(0,-20,6,COBBLESTONE)
B(0,-20,7,COBBLESTONE)
B(0,-19,-7,COBBLESTONE)
B(0,-19,-6,STONE:6)
B(0,-19,-5,AIR)
B(0,-19,-4,AIR)
B(0,-19,-3,AIR)
B(0,-19,-2,AIR)
B(0,-19,-1,AIR)
B(0,-19,0,AIR)
B(0,-19,1,AIR)
B(0,-19,2,LADDER)
B(0,-19,3,COBBLESTONE)
B(0,-19,4,COBBLESTONE)
B(0,-19,5,COBBLESTONE)
B(0,-19,6,COBBLESTONE)
B(0,-19,7,COBBLESTONE)
B(0,-18,-7,COBBLESTONE)
B(0,-18,-6,STONE:6)
B(0,-18,-5,WEB)
B(0,-18,-4,AIR)
B(0,-18,-3,AIR)
B(0,-18,-2,AIR)
B(0,-18,-1,AIR)
B(0,-18,0,AIR)
B(0,-18,1,AIR)
B(0,-18,2,AIR)
B(0,-18,3,AIR)
B(0,-18,4,DOUBLE_STEP:3)
B(0,-18,5,COBBLESTONE)
B(0,-18,6,COBBLESTONE)
B(0,-18,7,COBBLESTONE)
B(0,-17,-7,COBBLESTONE)
B(0,-17,-6,STONE:6)
B(0,-17,-5,AIR)
B(0,-17,-4,AIR)
B(0,-17,-3,AIR)
B(0,-17,-2,AIR)
B(0,-17,-1,AIR)
B(0,-17,0,AIR)
B(0,-17,1,AIR)
B(0,-17,2,AIR)
B(0,-17,3,COBBLESTONE)
B(0,-17,4,COBBLESTONE)
B(0,-17,5,COBBLESTONE)
B(0,-17,6,COBBLESTONE)
B(0,-17,7,COBBLESTONE)
B(0,-16,-7,COBBLESTONE)
B(0,-16,-6,STONE:6)
B(0,-16,-5,AIR)
B(0,-16,-4,AIR)
B(0,-16,-3,AIR)
B(0,-16,-2,AIR)
B(0,-16,-1,AIR)
B(0,-16,0,COBBLESTONE)
B(0,-16,1,AIR)
B(0,-16,2,WEB)
B(0,-16,3,COBBLESTONE)
B(0,-16,4,COBBLESTONE)
B(0,-16,5,COBBLESTONE)
B(0,-16,6,COBBLESTONE)
B(0,-16,7,COBBLESTONE)
B(0,-15,-7,COBBLESTONE)
B(0,-15,-6,STONE:6)
B(0,-15,-5,AIR)
B(0,-15,-4,AIR)
B(0,-15,-3,AIR)
B(0,-15,-2,AIR)
B(0,-15,-1,AIR)
B(0,-15,0,AIR)
B(0,-15,1,AIR)
B(0,-15,2,LADDER)
B(0,-15,3,COBBLESTONE)
B(0,-15,4,COBBLESTONE)
B(0,-15,5,COBBLESTONE)
B(0,-15,6,COBBLESTONE)
B(0,-15,7,COBBLESTONE)
B(0,-14,-7,COBBLESTONE)
B(0,-14,-6,SMOOTH_BRICK)
B(0,-14,-5,AIR)
B(0,-14,-4,AIR)
B(0,-14,-3,AIR)
B(0,-14,-2,AIR)
B(0,-14,-1,AIR)
B(0,-14,0,AIR)
B(0,-14,1,AIR)
B(0,-14,2,LADDER)
B(0,-14,3,COBBLESTONE)
B(0,-14,4,COBBLESTONE)
B(0,-14,5,COBBLESTONE)
B(0,-14,6,COBBLESTONE)
B(0,-14,7,COBBLESTONE)
B(0,-13,-7,COBBLESTONE)
B(0,-13,-6,COBBLESTONE)
B(0,-13,-5,COBBLESTONE)
B(0,-13,-4,COBBLESTONE)
B(0,-13,-3,COBBLESTONE)
B(0,-13,-2,COBBLESTONE)
B(0,-13,-1,COBBLESTONE)
B(0,-13,0,COBBLESTONE)
B(0,-13,1,COBBLESTONE)
B(0,-13,2,AIR)
B(0,-13,3,COBBLESTONE)
B(0,-13,4,COBBLESTONE)
B(0,-13,5,COBBLESTONE)
B(0,-13,6,COBBLESTONE)
B(0,-13,7,COBBLESTONE)
B(0,-12,-4,COBBLESTONE)
B(0,-12,-3,COBBLESTONE)
B(0,-12,-2,COBBLESTONE)
B(0,-12,-1,COBBLESTONE)
B(0,-12,0,COBBLESTONE)
B(0,-12,1,COBBLESTONE)
B(0,-12,2,LADDER)
B(0,-12,3,COBBLESTONE)
B(0,-12,4,COBBLESTONE)
B(0,-12,5,AIR)
B(0,-11,-4,COBBLESTONE)
B(0,-11,-3,COBBLESTONE)
B(0,-11,-2,COBBLESTONE)
B(0,-11,-1,COBBLESTONE)
B(0,-11,0,COBBLESTONE)
B(0,-11,1,COBBLESTONE)
B(0,-11,2,LADDER)
B(0,-11,3,COBBLESTONE)
B(0,-11,4,COBBLESTONE)
B(0,-11,5,AIR)
B(0,-10,-4,COBBLESTONE)
B(0,-10,-3,COBBLESTONE)
B(0,-10,-2,COBBLESTONE)
B(0,-10,-1,COBBLESTONE)
B(0,-10,0,COBBLESTONE)
B(0,-10,1,COBBLESTONE)
B(0,-10,2,AIR)
B(0,-10,3,COBBLESTONE)
B(0,-10,4,COBBLESTONE)
B(0,-10,5,AIR)
B(0,-9,-4,COBBLESTONE)
B(0,-9,-3,COBBLESTONE)
B(0,-9,-2,COBBLESTONE)
B(0,-9,-1,COBBLESTONE)
B(0,-9,0,COBBLESTONE)
B(0,-9,1,COBBLESTONE)
B(0,-9,2,LADDER)
B(0,-9,3,COBBLESTONE)
B(0,-9,4,COBBLESTONE)
B(0,-9,5,AIR)
B(0,-8,-4,COBBLESTONE)
B(0,-8,-3,COBBLESTONE)
B(0,-8,-2,COBBLESTONE)
B(0,-8,-1,COBBLESTONE)
B(0,-8,0,COBBLESTONE)
B(0,-8,1,COBBLESTONE)
B(0,-8,2,LADDER)
B(0,-8,3,COBBLESTONE)
B(0,-8,4,COBBLESTONE)
B(0,-8,5,AIR)
B(0,-7,-4,COBBLESTONE)
B(0,-7,-3,COBBLESTONE)
B(0,-7,-2,COBBLESTONE)
B(0,-7,-1,COBBLESTONE)
B(0,-7,0,COBBLESTONE)
B(0,-7,1,COBBLESTONE)
B(0,-7,2,LADDER)
B(0,-7,3,COBBLESTONE)
B(0,-7,4,COBBLESTONE)
B(0,-7,5,AIR)
B(0,-6,-4,COBBLESTONE)
B(0,-6,-3,COBBLESTONE)
B(0,-6,-2,COBBLESTONE)
B(0,-6,-1,COBBLESTONE)
B(0,-6,0,COBBLESTONE)
B(0,-6,1,COBBLESTONE)
B(0,-6,2,LADDER)
B(0,-6,3,COBBLESTONE)
B(0,-6,4,COBBLESTONE)
B(0,-6,5,AIR)
B(0,-5,-4,COBBLESTONE)
B(0,-5,-3,COBBLESTONE)
B(0,-5,-2,COBBLESTONE)
B(0,-5,-1,COBBLESTONE)
B(0,-5,0,COBBLESTONE)
B(0,-5,1,COBBLESTONE)
B(0,-5,2,LADDER)
B(0,-5,3,COBBLESTONE)
B(0,-5,4,COBBLESTONE)
B(0,-5,5,AIR)
B(0,-4,-4,COBBLESTONE)
B(0,-4,-3,COBBLESTONE)
B(0,-4,-2,COBBLESTONE)
B(0,-4,-1,COBBLESTONE)
B(0,-4,0,COBBLESTONE)
B(0,-4,1,COBBLESTONE)
B(0,-4,2,LADDER)
B(0,-4,3,COBBLESTONE)
B(0,-4,4,COBBLESTONE)
B(0,-4,5,AIR)
B(0,-3,-4,COBBLESTONE)
B(0,-3,-3,COBBLESTONE)
B(0,-3,-2,COBBLESTONE)
B(0,-3,-1,COBBLESTONE)
B(0,-3,0,COBBLESTONE)
B(0,-3,1,COBBLESTONE)
B(0,-3,2,LADDER)
B(0,-3,3,COBBLESTONE)
B(0,-3,4,COBBLESTONE)
B(0,-3,5,AIR)
B(0,-2,-4,COBBLESTONE)
B(0,-2,-3,COBBLESTONE)
B(0,-2,-2,COBBLESTONE)
B(0,-2,-1,COBBLESTONE)
B(0,-2,0,COBBLESTONE)
B(0,-2,1,COBBLESTONE)
B(0,-2,2,AIR)
B(0,-2,3,COBBLESTONE)
B(0,-2,4,COBBLESTONE)
B(0,-2,5,AIR)
B(0,-1,-4,COBBLESTONE)
B(0,-1,-3,COBBLESTONE)
B(0,-1,-2,STONE:6)
B(0,-1,-1,STEP:8)
B(0,-1,0,SMOOTH_BRICK:3)
B(0,-1,1,DOUBLE_STEP)
B(0,-1,2,AIR)
B(0,-1,3,STONE:6)
B(0,-1,4,COBBLESTONE)
B(0,0,-7,AIR)
B(0,0,-6,AIR)
B(0,0,-5,AIR)
B(0,0,-4,SMOOTH_BRICK)
B(0,0,-3,SMOOTH_BRICK)
B(0,0,-2,LADDER:3)
B(0,0,-1,AIR)
B(0,0,0,AIR)
B(0,0,1,AIR)
B(0,0,2,WEB)
B(0,0,3,SMOOTH_BRICK)
B(0,0,4,SMOOTH_BRICK)
B(0,0,5,AIR)
B(0,0,6,AIR)
B(0,0,7,AIR)
B(0,1,-7,AIR)
B(0,1,-6,AIR)
B(0,1,-5,AIR)
B(0,1,-4,SMOOTH_BRICK)
B(0,1,-3,SMOOTH_BRICK)
B(0,1,-2,LADDER:3)
B(0,1,-1,AIR)
B(0,1,0,AIR)
B(0,1,1,AIR)
B(0,1,2,AIR)
B(0,1,3,SMOOTH_BRICK:3)
B(0,1,4,SMOOTH_BRICK)
B(0,1,5,AIR)
B(0,1,6,AIR)
B(0,1,7,AIR)
B(0,2,-7,AIR)
B(0,2,-6,AIR)
B(0,2,-5,AIR)
B(0,2,-4,SMOOTH_BRICK)
B(0,2,-3,SMOOTH_BRICK)
B(0,2,-2,LADDER:3)
B(0,2,-1,AIR)
B(0,2,0,AIR)
B(0,2,1,AIR)
B(0,2,2,STEP:5)
B(0,2,3,SMOOTH_BRICK)
B(0,2,4,SMOOTH_BRICK)
B(0,2,5,AIR)
B(0,2,6,AIR)
B(0,2,7,AIR)
B(0,3,-7,AIR)
B(0,3,-6,AIR)
B(0,3,-5,AIR)
B(0,3,-4,SMOOTH_BRICK)
B(0,3,-3,SMOOTH_BRICK)
B(0,3,-2,LADDER:3)
B(0,3,-1,AIR)
B(0,3,0,AIR)
B(0,3,1,AIR)
B(0,3,2,AIR)
B(0,3,3,SMOOTH_BRICK)
B(0,3,4,SMOOTH_BRICK)
B(0,3,5,AIR)
B(0,3,6,AIR)
B(0,3,7,AIR)
B(0,4,-7,AIR)
B(0,4,-6,AIR)
B(0,4,-5,AIR)
B(0,4,-4,SMOOTH_BRICK)
B(0,4,-3,SMOOTH_BRICK)
B(0,4,-2,LADDER:3)
B(0,4,-1,AIR)
B(0,4,0,AIR)
B(0,4,1,AIR)
B(0,4,2,AIR)
B(0,4,3,SMOOTH_BRICK)
B(0,4,4,SMOOTH_BRICK)
B(0,4,5,AIR)
B(0,4,6,AIR)
B(0,4,7,AIR)
B(0,5,-7,AIR)
B(0,5,-6,AIR)
B(0,5,-5,AIR)
B(0,5,-4,SMOOTH_BRICK)
B(0,5,-3,SMOOTH_BRICK)
B(0,5,-2,LADDER:3)
B(0,5,-1,AIR)
B(0,5,0,AIR)
B(0,5,1,AIR)
B(0,5,2,AIR)
B(0,5,3,SMOOTH_BRICK)
B(0,5,4,SMOOTH_BRICK)
B(0,5,5,AIR)
B(0,5,6,AIR)
B(0,5,7,AIR)
B(0,6,-7,AIR)
B(0,6,-6,AIR)
B(0,6,-5,AIR)
B(0,6,-4,AIR)
B(0,6,-3,SMOOTH_BRICK)
B(0,6,-2,LADDER:3)
B(0,6,-1,AIR)
B(0,6,0,AIR)
B(0,6,1,AIR)
B(0,6,2,AIR)
B(0,6,3,SMOOTH_BRICK)
B(0,6,4,AIR)
B(0,6,5,AIR)
B(0,6,6,AIR)
B(0,6,7,AIR)
B(0,7,-7,AIR)
B(0,7,-6,AIR)
B(0,7,-5,AIR)
B(0,7,-4,AIR)
B(0,7,-3,SMOOTH_BRICK)
B(0,7,-2,LADDER:3)
B(0,7,-1,AIR)
B(0,7,0,AIR)
B(0,7,1,AIR)
B(0,7,2,AIR)
B(0,7,3,SMOOTH_BRICK)
B(0,7,4,AIR)
B(0,7,5,AIR)
B(0,7,6,AIR)
B(0,7,7,AIR)
B(0,8,-7,AIR)
B(0,8,-6,AIR)
B(0,8,-5,AIR)
B(0,8,-4,AIR)
B(0,8,-3,SMOOTH_BRICK)
B(0,8,-2,LADDER:3)
B(0,8,-1,AIR)
B(0,8,0,AIR)
B(0,8,1,AIR)
B(0,8,2,AIR)
B(0,8,3,SMOOTH_BRICK)
B(0,8,4,AIR)
B(0,8,5,AIR)
B(0,8,6,AIR)
B(0,8,7,AIR)
B(0,9,-7,AIR)
B(0,9,-6,AIR)
B(0,9,-5,AIR)
B(0,9,-4,AIR)
B(0,9,-3,SMOOTH_BRICK)
B(0,9,-2,LADDER:3)
B(0,9,-1,AIR)
B(0,9,0,AIR)
B(0,9,1,AIR)
B(0,9,2,AIR)
B(0,9,3,SMOOTH_BRICK)
B(0,9,4,AIR)
B(0,9,5,AIR)
B(0,9,6,AIR)
B(0,9,7,AIR)
B(0,10,-7,AIR)
B(0,10,-6,AIR)
B(0,10,-5,AIR)
B(0,10,-4,SMOOTH_BRICK)
B(0,10,-3,SMOOTH_BRICK)
B(0,10,-2,LADDER:3)
B(0,10,-1,AIR)
B(0,10,0,AIR)
B(0,10,1,AIR)
B(0,10,2,SMOOTH_STAIRS:6)
B(0,10,3,SMOOTH_BRICK)
B(0,10,4,SMOOTH_BRICK)
B(0,10,5,AIR)
B(0,10,6,AIR)
B(0,10,7,AIR)
B(0,11,-7,AIR)
B(0,11,-6,AIR)
B(0,11,-5,AIR)
B(0,11,-4,SMOOTH_BRICK)
B(0,11,-3,SMOOTH_BRICK)
B(0,11,-2,LADDER:3)
B(0,11,-1,SMOOTH_BRICK)
B(0,11,0,SMOOTH_BRICK:3)
B(0,11,1,SMOOTH_BRICK)
B(0,11,2,SMOOTH_BRICK)
B(0,11,3,SMOOTH_BRICK)
B(0,11,4,SMOOTH_BRICK)
B(0,11,5,AIR)
B(0,11,6,AIR)
B(0,11,7,AIR)
B(0,12,-7,AIR)
B(0,12,-6,AIR)
B(0,12,-5,AIR)
B(0,12,-4,SMOOTH_BRICK:3)
B(0,12,-3,AIR)
B(0,12,-2,AIR)
B(0,12,-1,AIR)
B(0,12,0,AIR)
B(0,12,1,AIR)
B(0,12,2,AIR)
Entity(0,12,2,Spider,1,Spider.txt)
B(0,12,3,AIR)
B(0,12,4,SMOOTH_BRICK:3)
B(0,12,5,AIR)
B(0,12,6,AIR)
B(0,12,7,AIR)
B(0,13,-7,AIR)
B(0,13,-6,AIR)
B(0,13,-5,AIR)
B(0,13,-4,STEP)
B(0,13,-3,AIR)
B(0,13,-2,AIR)
B(0,13,-1,AIR)
B(0,13,0,AIR)
B(0,13,1,AIR)
B(0,13,2,AIR)
B(0,13,3,AIR)
B(0,13,4,STEP)
B(0,13,5,AIR)
B(0,13,6,AIR)
B(0,13,7,AIR)
B(1,-24,-7,COBBLESTONE)
B(1,-24,-6,COBBLESTONE)
B(1,-24,-5,COBBLESTONE)
B(1,-24,-4,COBBLESTONE)
B(1,-24,-3,COBBLESTONE)
B(1,-24,-2,COBBLESTONE)
B(1,-24,-1,COBBLESTONE)
B(1,-24,0,COBBLESTONE)
B(1,-24,1,COBBLESTONE)
B(1,-24,2,COBBLESTONE)
B(1,-24,3,COBBLESTONE)
B(1,-24,4,COBBLESTONE)
B(1,-24,5,COBBLESTONE)
B(1,-24,6,COBBLESTONE)
B(1,-24,7,COBBLESTONE)
B(1,-23,-7,COBBLESTONE)
B(1,-23,-6,COBBLESTONE)
B(1,-23,-5,WOOD)
B(1,-23,-4,WOOD)
B(1,-23,-3,WOOD)
B(1,-23,-2,WOOD)
B(1,-23,-1,WOOD)
B(1,-23,0,WOOD)
B(1,-23,1,STONE:6)
B(1,-23,2,STONE:6)
B(1,-23,3,STONE:6)
B(1,-23,4,WOOD)
B(1,-23,5,COBBLESTONE)
B(1,-23,6,COBBLESTONE)
B(1,-23,7,COBBLESTONE)
B(1,-22,-7,COBBLESTONE)
B(1,-22,-6,STEP:11)
B(1,-22,-5,WEB)
B(1,-22,-4,WEB)
B(1,-22,-3,WEB)
B(1,-22,-2,WEB)
B(1,-22,-1,WEB)
B(1,-22,0,AIR)
B(1,-22,1,AIR)
B(1,-22,2,WEB)
B(1,-22,3,AIR)
B(1,-22,4,COBBLESTONE)
B(1,-22,5,COBBLESTONE)
B(1,-22,6,COBBLESTONE)
B(1,-22,7,COBBLESTONE)
B(1,-21,-7,COBBLESTONE)
B(1,-21,-6,COBBLESTONE)
B(1,-21,-5,WEB)
B(1,-21,-4,AIR)
B(1,-21,-3,WEB)
B(1,-21,-2,WEB)
B(1,-21,-1,WEB)
B(1,-21,0,AIR)
B(1,-21,1,AIR)
B(1,-21,2,AIR)
B(1,-21,3,AIR)
B(1,-21,4,COBBLESTONE)
B(1,-21,5,COBBLESTONE)
B(1,-21,6,COBBLESTONE)
B(1,-21,7,COBBLESTONE)
B(1,-20,-7,COBBLESTONE)
B(1,-20,-6,AIR)
B(1,-20,-5,WEB)
B(1,-20,-4,AIR)
B(1,-20,-3,AIR)
B(1,-20,-2,AIR)
B(1,-20,-1,AIR)
B(1,-20,0,AIR)
B(1,-20,1,AIR)
B(1,-20,2,AIR)
B(1,-20,3,AIR)
B(1,-20,4,AIR)
B(1,-20,5,COBBLESTONE)
B(1,-20,6,COBBLESTONE)
B(1,-20,7,COBBLESTONE)
B(1,-19,-7,COBBLESTONE)
B(1,-19,-6,AIR)
B(1,-19,-5,AIR)
B(1,-19,-4,AIR)
B(1,-19,-3,AIR)
B(1,-19,-2,AIR)
B(1,-19,-1,AIR)
B(1,-19,0,AIR)
B(1,-19,1,AIR)
B(1,-19,2,AIR)
B(1,-19,3,AIR)
B(1,-19,4,COBBLESTONE)
B(1,-19,5,STEP:3)
B(1,-19,6,AIR)
B(1,-19,7,COBBLESTONE)
B(1,-18,-7,COBBLESTONE)
B(1,-18,-6,SMOOTH_BRICK)
B(1,-18,-5,AIR)
B(1,-18,-4,AIR)
B(1,-18,-3,AIR)
B(1,-18,-2,AIR)
B(1,-18,-1,AIR)
B(1,-18,0,AIR)
B(1,-18,1,AIR)
B(1,-18,2,AIR)
B(1,-18,3,AIR)
B(1,-18,4,STEP:11)
B(1,-18,5,STEP:11)
B(1,-18,6,COBBLESTONE)
B(1,-18,7,COBBLESTONE)
B(1,-17,-7,COBBLESTONE)
RB(1,-17,-6,CHEST:3,../../nbt/VanillaLoot/simple_dungeon.nbt,50,CHEST:3,../../nbt/VanillaLoot/stronghold_crossing.nbt,100)
B(1,-17,-5,AIR)
B(1,-17,-4,AIR)
B(1,-17,-3,AIR)
B(1,-17,-2,AIR)
B(1,-17,-1,AIR)
B(1,-17,0,AIR)
B(1,-17,1,AIR)
B(1,-17,2,AIR)
B(1,-17,3,STEP:11)
B(1,-17,4,COBBLESTONE)
B(1,-17,5,COBBLESTONE)
B(1,-17,6,COBBLESTONE)
B(1,-17,7,COBBLESTONE)
B(1,-16,-7,COBBLESTONE)
B(1,-16,-6,WEB)
B(1,-16,-5,AIR)
B(1,-16,-4,AIR)
B(1,-16,-3,AIR)
B(1,-16,-2,AIR)
B(1,-16,-1,AIR)
B(1,-16,0,COBBLESTONE)
B(1,-16,1,AIR)
B(1,-16,2,AIR)
B(1,-16,3,AIR)
B(1,-16,4,STEP:11)
B(1,-16,5,COBBLESTONE)
B(1,-16,6,COBBLESTONE)
B(1,-16,7,COBBLESTONE)
B(1,-15,-7,COBBLESTONE)
B(1,-15,-6,STONE:6)
B(1,-15,-5,AIR)
B(1,-15,-4,AIR)
B(1,-15,-3,AIR)
B(1,-15,-2,AIR)
B(1,-15,-1,AIR)
B(1,-15,0,AIR)
B(1,-15,1,AIR)
B(1,-15,2,AIR)
B(1,-15,3,COBBLESTONE)
B(1,-15,4,COBBLESTONE)
B(1,-15,5,COBBLESTONE)
B(1,-15,6,COBBLESTONE)
B(1,-15,7,COBBLESTONE)
B(1,-14,-7,COBBLESTONE)
B(1,-14,-6,SMOOTH_BRICK)
B(1,-14,-5,AIR)
B(1,-14,-4,AIR)
B(1,-14,-3,AIR)
B(1,-14,-2,AIR)
B(1,-14,-1,AIR)
B(1,-14,0,AIR)
B(1,-14,1,AIR)
B(1,-14,2,WEB)
B(1,-14,3,COBBLESTONE)
B(1,-14,4,COBBLESTONE)
B(1,-14,5,COBBLESTONE)
B(1,-14,6,COBBLESTONE)
B(1,-14,7,COBBLESTONE)
B(1,-13,-7,COBBLESTONE)
B(1,-13,-6,COBBLESTONE)
B(1,-13,-5,COBBLESTONE)
B(1,-13,-4,COBBLESTONE)
B(1,-13,-3,COBBLESTONE)
B(1,-13,-2,COBBLESTONE)
B(1,-13,-1,COBBLESTONE)
B(1,-13,0,COBBLESTONE)
B(1,-13,1,COBBLESTONE)
B(1,-13,2,COBBLESTONE)
B(1,-13,3,COBBLESTONE)
B(1,-13,4,COBBLESTONE)
B(1,-13,5,COBBLESTONE)
B(1,-13,6,COBBLESTONE)
B(1,-13,7,COBBLESTONE)
B(1,-12,-5,COBBLESTONE)
B(1,-12,-4,COBBLESTONE)
B(1,-12,-3,COBBLESTONE)
B(1,-12,-2,COBBLESTONE)
B(1,-12,-1,COBBLESTONE)
B(1,-12,0,COBBLESTONE)
B(1,-12,1,COBBLESTONE)
B(1,-12,2,COBBLESTONE)
B(1,-12,3,COBBLESTONE)
B(1,-12,4,COBBLESTONE)
B(1,-12,5,COBBLESTONE)
B(1,-11,-5,COBBLESTONE)
B(1,-11,-4,COBBLESTONE)
B(1,-11,-3,COBBLESTONE)
B(1,-11,-2,COBBLESTONE)
B(1,-11,-1,COBBLESTONE)
B(1,-11,0,COBBLESTONE)
B(1,-11,1,COBBLESTONE)
B(1,-11,2,COBBLESTONE)
B(1,-11,3,COBBLESTONE)
B(1,-11,4,COBBLESTONE)
B(1,-11,5,COBBLESTONE)
B(1,-10,-5,COBBLESTONE)
B(1,-10,-4,COBBLESTONE)
B(1,-10,-3,COBBLESTONE)
B(1,-10,-2,COBBLESTONE)
B(1,-10,-1,COBBLESTONE)
B(1,-10,0,COBBLESTONE)
B(1,-10,1,COBBLESTONE)
B(1,-10,2,COBBLESTONE)
B(1,-10,3,COBBLESTONE)
B(1,-10,4,COBBLESTONE)
B(1,-10,5,COBBLESTONE)
B(1,-9,-5,COBBLESTONE)
B(1,-9,-4,COBBLESTONE)
B(1,-9,-3,COBBLESTONE)
B(1,-9,-2,COBBLESTONE)
B(1,-9,-1,COBBLESTONE)
B(1,-9,0,COBBLESTONE)
B(1,-9,1,COBBLESTONE)
B(1,-9,2,COBBLESTONE)
B(1,-9,3,COBBLESTONE)
B(1,-9,4,COBBLESTONE)
B(1,-9,5,COBBLESTONE)
B(1,-8,-5,COBBLESTONE)
B(1,-8,-4,COBBLESTONE)
B(1,-8,-3,COBBLESTONE)
B(1,-8,-2,COBBLESTONE)
B(1,-8,-1,COBBLESTONE)
B(1,-8,0,COBBLESTONE)
B(1,-8,1,COBBLESTONE)
B(1,-8,2,COBBLESTONE)
B(1,-8,3,COBBLESTONE)
B(1,-8,4,COBBLESTONE)
B(1,-8,5,COBBLESTONE)
B(1,-7,-5,COBBLESTONE)
B(1,-7,-4,COBBLESTONE)
B(1,-7,-3,COBBLESTONE)
B(1,-7,-2,COBBLESTONE)
B(1,-7,-1,COBBLESTONE)
B(1,-7,0,COBBLESTONE)
B(1,-7,1,COBBLESTONE)
B(1,-7,2,COBBLESTONE)
B(1,-7,3,COBBLESTONE)
B(1,-7,4,COBBLESTONE)
B(1,-7,5,COBBLESTONE)
B(1,-6,-5,COBBLESTONE)
B(1,-6,-4,COBBLESTONE)
B(1,-6,-3,COBBLESTONE)
B(1,-6,-2,COBBLESTONE)
B(1,-6,-1,COBBLESTONE)
B(1,-6,0,COBBLESTONE)
B(1,-6,1,COBBLESTONE)
B(1,-6,2,COBBLESTONE)
B(1,-6,3,COBBLESTONE)
B(1,-6,4,COBBLESTONE)
B(1,-6,5,COBBLESTONE)
B(1,-5,-5,COBBLESTONE)
B(1,-5,-4,COBBLESTONE)
B(1,-5,-3,COBBLESTONE)
B(1,-5,-2,COBBLESTONE)
B(1,-5,-1,COBBLESTONE)
B(1,-5,0,COBBLESTONE)
B(1,-5,1,COBBLESTONE)
B(1,-5,2,COBBLESTONE)
B(1,-5,3,COBBLESTONE)
B(1,-5,4,COBBLESTONE)
B(1,-5,5,COBBLESTONE)
B(1,-4,-5,COBBLESTONE)
B(1,-4,-4,COBBLESTONE)
B(1,-4,-3,COBBLESTONE)
B(1,-4,-2,COBBLESTONE)
B(1,-4,-1,COBBLESTONE)
B(1,-4,0,COBBLESTONE)
B(1,-4,1,COBBLESTONE)
B(1,-4,2,COBBLESTONE)
B(1,-4,3,COBBLESTONE)
B(1,-4,4,COBBLESTONE)
B(1,-4,5,COBBLESTONE)
B(1,-3,-5,COBBLESTONE)
B(1,-3,-4,COBBLESTONE)
B(1,-3,-3,COBBLESTONE)
B(1,-3,-2,COBBLESTONE)
B(1,-3,-1,COBBLESTONE)
B(1,-3,0,COBBLESTONE)
B(1,-3,1,COBBLESTONE)
B(1,-3,2,COBBLESTONE)
B(1,-3,3,COBBLESTONE)
B(1,-3,4,COBBLESTONE)
B(1,-3,5,COBBLESTONE)
B(1,-2,-5,COBBLESTONE)
B(1,-2,-4,COBBLESTONE)
B(1,-2,-3,COBBLESTONE)
B(1,-2,-2,COBBLESTONE)
B(1,-2,-1,COBBLESTONE)
B(1,-2,0,COBBLESTONE)
B(1,-2,1,COBBLESTONE)
B(1,-2,2,COBBLESTONE)
B(1,-2,3,COBBLESTONE)
B(1,-2,4,COBBLESTONE)
B(1,-2,5,COBBLESTONE)
B(1,-1,-5,COBBLESTONE)
B(1,-1,-4,COBBLESTONE)
B(1,-1,-3,COBBLESTONE)
B(1,-1,-2,STONE:6)
B(1,-1,-1,STEP:8)
B(1,-1,0,STEP:8)
B(1,-1,1,STEP:8)
B(1,-1,2,STONE:6)
B(1,-1,3,COBBLESTONE)
B(1,-1,4,COBBLESTONE)
B(1,-1,5,COBBLESTONE)
B(1,0,-7,AIR)
B(1,0,-6,AIR)
B(1,0,-5,SMOOTH_BRICK)
B(1,0,-4,SMOOTH_BRICK)
B(1,0,-3,SMOOTH_BRICK)
B(1,0,-2,AIR)
B(1,0,-1,AIR)
B(1,0,0,AIR)
B(1,0,1,AIR)
B(1,0,2,AIR)
B(1,0,3,SMOOTH_BRICK)
B(1,0,4,SMOOTH_BRICK)
B(1,0,5,SMOOTH_BRICK)
B(1,0,6,AIR)
B(1,0,7,AIR)
B(1,1,-7,AIR)
B(1,1,-6,AIR)
B(1,1,-5,SMOOTH_BRICK)
B(1,1,-4,SMOOTH_BRICK)
B(1,1,-3,SMOOTH_BRICK)
B(1,1,-2,AIR)
B(1,1,-1,AIR)
B(1,1,0,AIR)
B(1,1,1,AIR)
B(1,1,2,AIR)
B(1,1,3,SMOOTH_BRICK)
B(1,1,4,SMOOTH_BRICK)
B(1,1,5,SMOOTH_BRICK)
B(1,1,6,AIR)
B(1,1,7,AIR)
B(1,2,-7,AIR)
B(1,2,-6,AIR)
B(1,2,-5,SMOOTH_BRICK)
B(1,2,-4,SMOOTH_BRICK:3)
B(1,2,-3,SMOOTH_BRICK)
B(1,2,-2,AIR)
B(1,2,-1,AIR)
B(1,2,0,AIR)
B(1,2,1,AIR)
B(1,2,2,STEP:5)
B(1,2,3,SMOOTH_BRICK)
B(1,2,4,SMOOTH_BRICK:3)
B(1,2,5,SMOOTH_BRICK)
