
#######################################################################
# +-----------------------------------------------------------------+ #
# |                            BO3 object                           | #
# +-----------------------------------------------------------------+ #
#######################################################################

# This is the config file of a custom object.
# If you add this object correctly to your BiomeConfigs, it will spawn in the world.

# This is the creator of this BO3 object
Author: LordSmellyPants

# A short description of this BO3 object
Description: No description given

# The BO3 version, don't change this! It can be used by external applications to do a version check.
Version: 3

# The settings mode, WriteAll, WriteWithoutComments or WriteDisable. See WorldConfig.
SettingsMode: WriteDisable


#######################################################################
# +-----------------------------------------------------------------+ #
# |                          Main settings                          | #
# +-----------------------------------------------------------------+ #
#######################################################################

# This needs to be set to true to spawn the object in the Tree and Sapling resources.
Tree: false

# The frequency of the BO3 from 1 to 200. Tries this many times to spawn this BO3 when using the CustomObject(...) resource.
# Ignored by Tree(..), Sapling(..) and CustomStructure(..)
Frequency: 1

# The rarity of the BO3 from 0 to 100. Each spawn attempt has rarity% chance to succeed when using the CustomObject(...) resource.
# Ignored by Tree(..), Sapling(..) and CustomStructure(..)
Rarity: 100.0

# If you set this to true, the BO3 will be placed with a random rotation.
RotateRandomly: true

# The spawn height of the BO3 - atMinY, randomY, highestBlock or highestSolidBlock.
SpawnHeight: highestSolidBlock

# The offset from the spawn height to spawn this BO3
# Ex. SpawnHeight = highestSolidBlock, SpawnHeightOffset = 3; This object will spawn 3 blocks above the highest solid block
SpawnHeightOffset: 0

# A random amount to offset the spawn location from the spawn offset height
# Ex. SpawnHeightOffset = 3, SpawnHeightVariance = 3; This object will spawn 3 to 6 blocks above the original spot it would have spawned
SpawnHeightVariance: 0

##############################
# Height Limits for the BO3. #
##############################

# When in randomY mode used as the minimum Y or in atMinY mode as the actual Y to spawn this BO3 at.
MinHeight: 0

# When in randomY mode used as the maximum Y to spawn this BO3 at.
MaxHeight: 46

######################
# Extrusion settings #
######################

# The style of extrusion you wish to use - BottomDown, TopUp, None (Default)
ExtrudeMode: None

# The blocks to extrude your BO3 through
ExtrudeThroughBlocks: AIR

# Objects can have other objects attacthed to it: branches. Branches can also
# have branches attached to it, which can also have branches, etc. This is the
# maximum branch depth for this objects.
MaxBranchDepth: 10

# When spawned with the UseWorld keyword, this BO3 should NOT spawn in the following biomes.
# If you write the BO3 name directly in the BiomeConfigs, this will be ignored.
ExcludedBiomes: All


#######################################################################
# +-----------------------------------------------------------------+ #
# |                      Source block settings                      | #
# +-----------------------------------------------------------------+ #
#######################################################################

# The B(s) the BO3 should spawn in.
SourceBlocks: AIR

# The maximum percentage of the BO3 that can be outside the SourceBlock.
# The BO3 won't be placed on a location with more blocks outside the SourceBlock than this percentage.
MaxPercentageOutsideSourceBlock: 100

# What to do when a block is about to be placed outside the SourceBlock? (dontPlace, placeAnyway)
OutsideSourceBlock: placeAnyway


#######################################################################
# +-----------------------------------------------------------------+ #
# |                              Blocks                             | #
# +-----------------------------------------------------------------+ #
#######################################################################

# All the blocks used in the BO3 are listed here. Possible blocks:
# B(x,y,z,id[.data][,nbtfile.nbt)
# RB(x,y,z,id[:data][,nbtfile.nbt],chance[,id[:data][,nbtfile.nbt],chance[,...]])
#  So RB(0,0,0,CHEST,chest.nbt,50,CHEST,anotherchest.nbt,100) will spawn a chest at
#  the BO3 origin, and give it a 50% chance to have the contents of chest.nbt, or, if that
#  fails, a 100% percent chance to have the contents of anotherchest.nbt.
# MinecraftObject(x,y,z,name)
#  Spawns an object in the Mojang NBT structure format. For example, 
#  MinecraftObject(0,0,0,minecraft:igloo/igloo_bottom)
#  spawns the bottom part of an igloo.
B(-13,-10,11,PRISMARINE)
B(-13,-10,12,PRISMARINE)
B(-13,-9,11,PRISMARINE)
B(-13,-9,12,PRISMARINE)
B(-13,-9,14,PRISMARINE)
B(-13,-8,10,PRISMARINE)
B(-13,-8,11,PRISMARINE)
B(-13,-8,12,PRISMARINE)
B(-13,-8,13,PRISMARINE)
B(-13,-8,14,PRISMARINE)
B(-13,-7,10,PRISMARINE)
B(-13,-7,11,PRISMARINE)
B(-13,-7,12,PRISMARINE)
B(-13,-7,13,PRISMARINE)
B(-13,-7,14,SAND:1)
B(-13,-6,10,PRISMARINE)
B(-13,-6,11,PRISMARINE)
B(-13,-6,12,PRISMARINE)
B(-13,-6,13,SAND:1)
B(-13,-6,14,SAND:1)
B(-13,-5,10,PRISMARINE)
B(-13,-5,11,PRISMARINE)
B(-13,-5,12,PRISMARINE)
B(-13,-5,13,SAND:1)
B(-13,-5,14,SAND:1)
B(-13,-4,10,PRISMARINE)
B(-13,-4,11,PRISMARINE)
B(-13,-4,12,PRISMARINE)
B(-13,-4,13,PRISMARINE)
B(-13,-4,14,SAND:1)
B(-13,-3,9,PRISMARINE)
B(-13,-3,10,PRISMARINE)
B(-13,-3,11,PRISMARINE)
B(-13,-3,12,PRISMARINE)
B(-13,-3,13,PRISMARINE)
B(-13,-3,14,PRISMARINE)
B(-13,-2,10,PRISMARINE)
B(-13,-2,11,PRISMARINE)
B(-13,-2,12,PRISMARINE)
B(-13,-2,13,PRISMARINE)
B(-13,-2,14,PRISMARINE)
B(-13,-1,11,PRISMARINE)
B(-13,-1,12,PRISMARINE)
B(-13,-1,13,PRISMARINE)
B(-13,-1,14,PRISMARINE)
B(-13,0,12,PRISMARINE)
B(-12,-11,11,PRISMARINE)
B(-12,-11,12,PRISMARINE)
B(-12,-11,13,PRISMARINE)
B(-12,-10,10,PRISMARINE)
B(-12,-10,11,PRISMARINE)
B(-12,-10,12,PRISMARINE)
B(-12,-10,13,PRISMARINE)
B(-12,-10,14,PRISMARINE)
B(-12,-10,16,PRISMARINE)
B(-12,-9,10,PRISMARINE)
B(-12,-9,11,PRISMARINE)
B(-12,-9,12,PRISMARINE)
B(-12,-9,13,PRISMARINE)
B(-12,-9,14,PRISMARINE)
B(-12,-9,15,PRISMARINE)
B(-12,-9,16,PRISMARINE)
B(-12,-8,10,PRISMARINE)
B(-12,-8,11,PRISMARINE)
B(-12,-8,12,PRISMARINE)
B(-12,-8,13,PRISMARINE)
B(-12,-8,14,PRISMARINE)
B(-12,-8,15,PRISMARINE)
B(-12,-8,16,SAND:1)
B(-12,-7,9,PRISMARINE)
B(-12,-7,10,PRISMARINE)
B(-12,-7,11,PRISMARINE)
B(-12,-7,12,PRISMARINE)
B(-12,-7,13,PRISMARINE)
B(-12,-7,14,PRISMARINE)
B(-12,-7,15,SAND:1)
B(-12,-7,16,SAND:1)
B(-12,-6,9,PRISMARINE)
B(-12,-6,10,PRISMARINE)
B(-12,-6,11,PRISMARINE)
B(-12,-6,12,PRISMARINE)
B(-12,-6,13,PRISMARINE)
B(-12,-6,14,PRISMARINE)
B(-12,-6,15,SAND:1)
B(-12,-6,16,SAND:1)
B(-12,-5,8,PRISMARINE)
B(-12,-5,9,PRISMARINE)
B(-12,-5,10,PRISMARINE)
B(-12,-5,11,PRISMARINE)
B(-12,-5,12,PRISMARINE)
B(-12,-5,13,PRISMARINE)
B(-12,-5,14,PRISMARINE)
B(-12,-5,15,SAND:1)
B(-12,-5,16,SAND:1)
B(-12,-4,8,PRISMARINE)
B(-12,-4,9,PRISMARINE)
B(-12,-4,10,PRISMARINE)
B(-12,-4,11,PRISMARINE)
B(-12,-4,12,PRISMARINE)
B(-12,-4,13,PRISMARINE)
B(-12,-4,14,PRISMARINE)
B(-12,-4,15,SAND:1)
B(-12,-4,16,SAND:1)
B(-12,-3,7,PRISMARINE)
B(-12,-3,8,PRISMARINE)
B(-12,-3,9,PRISMARINE)
B(-12,-3,10,PRISMARINE)
B(-12,-3,11,PRISMARINE)
B(-12,-3,12,PRISMARINE)
B(-12,-3,13,PRISMARINE)
B(-12,-3,14,PRISMARINE)
B(-12,-3,15,SAND:1)
B(-12,-3,16,SAND:1)
B(-12,-2,7,PRISMARINE)
B(-12,-2,8,PRISMARINE)
B(-12,-2,9,PRISMARINE)
B(-12,-2,10,PRISMARINE)
B(-12,-2,11,PRISMARINE)
B(-12,-2,12,PRISMARINE)
B(-12,-2,13,PRISMARINE)
B(-12,-2,14,PRISMARINE)
B(-12,-2,15,PRISMARINE)
B(-12,-2,16,SAND:1)
B(-12,-1,8,PRISMARINE)
B(-12,-1,9,PRISMARINE)
B(-12,-1,10,PRISMARINE)
B(-12,-1,11,PRISMARINE)
B(-12,-1,12,PRISMARINE)
B(-12,-1,13,PRISMARINE)
B(-12,-1,14,PRISMARINE)
B(-12,-1,15,PRISMARINE)
B(-12,-1,16,PRISMARINE)
B(-12,0,10,PRISMARINE)
B(-12,0,11,PRISMARINE)
B(-12,0,12,PRISMARINE)
B(-12,0,13,PRISMARINE)
B(-12,0,14,PRISMARINE)
B(-12,1,10,PRISMARINE)
B(-12,1,11,PRISMARINE)
B(-12,1,12,PRISMARINE)
B(-12,2,11,PRISMARINE)
B(-11,-12,11,PRISMARINE)
B(-11,-12,12,PRISMARINE)
B(-11,-12,13,PRISMARINE)
B(-11,-12,16,PRISMARINE)
B(-11,-11,8,PRISMARINE)
B(-11,-11,9,PRISMARINE)
B(-11,-11,10,PRISMARINE)
B(-11,-11,11,PRISMARINE)
B(-11,-11,12,PRISMARINE)
B(-11,-11,13,PRISMARINE)
B(-11,-11,14,PRISMARINE)
B(-11,-11,15,PRISMARINE)
B(-11,-11,16,PRISMARINE)
B(-11,-10,7,PRISMARINE)
B(-11,-10,8,PRISMARINE)
B(-11,-10,9,PRISMARINE)
B(-11,-10,10,PRISMARINE)
B(-11,-10,11,PRISMARINE)
B(-11,-10,12,PRISMARINE)
B(-11,-10,13,PRISMARINE)
B(-11,-10,14,PRISMARINE)
B(-11,-10,15,PRISMARINE)
B(-11,-10,16,PRISMARINE)
B(-11,-10,17,PRISMARINE)
B(-11,-9,7,PRISMARINE)
B(-11,-9,8,PRISMARINE)
B(-11,-9,9,PRISMARINE)
B(-11,-9,10,PRISMARINE)
B(-11,-9,11,PRISMARINE)
B(-11,-9,12,PRISMARINE)
B(-11,-9,13,PRISMARINE)
B(-11,-9,14,PRISMARINE)
B(-11,-9,15,PRISMARINE)
B(-11,-9,16,PRISMARINE)
B(-11,-9,17,PRISMARINE)
B(-11,-8,7,PRISMARINE)
B(-11,-8,8,PRISMARINE)
B(-11,-8,9,PRISMARINE)
B(-11,-8,10,PRISMARINE)
B(-11,-8,11,PRISMARINE)
B(-11,-8,12,PRISMARINE)
B(-11,-8,13,PRISMARINE)
B(-11,-8,14,PRISMARINE)
B(-11,-8,15,PRISMARINE)
B(-11,-8,16,PRISMARINE)
B(-11,-8,17,PRISMARINE)
B(-11,-7,6,PRISMARINE)
B(-11,-7,7,PRISMARINE)
B(-11,-7,8,PRISMARINE)
B(-11,-7,9,PRISMARINE)
B(-11,-7,10,PRISMARINE)
B(-11,-7,11,PRISMARINE)
B(-11,-7,12,PRISMARINE)
B(-11,-7,13,PRISMARINE)
B(-11,-7,14,PRISMARINE)
B(-11,-7,15,PRISMARINE)
B(-11,-7,16,PRISMARINE)
B(-11,-7,17,PRISMARINE)
B(-11,-6,6,PRISMARINE)
B(-11,-6,7,PRISMARINE)
B(-11,-6,8,PRISMARINE)
B(-11,-6,9,PRISMARINE)
B(-11,-6,10,PRISMARINE)
B(-11,-6,11,PRISMARINE)
B(-11,-6,12,PRISMARINE)
B(-11,-6,13,PRISMARINE)
B(-11,-6,14,PRISMARINE)
B(-11,-6,15,PRISMARINE)
B(-11,-6,16,PRISMARINE)
B(-11,-6,17,PRISMARINE)
B(-11,-5,5,PRISMARINE)
B(-11,-5,6,PRISMARINE)
B(-11,-5,7,PRISMARINE)
B(-11,-5,8,PRISMARINE)
B(-11,-5,9,PRISMARINE)
B(-11,-5,10,PRISMARINE)
B(-11,-5,11,PRISMARINE)
B(-11,-5,12,PRISMARINE)
B(-11,-5,13,PRISMARINE)
B(-11,-5,14,PRISMARINE)
B(-11,-5,15,PRISMARINE)
B(-11,-5,16,PRISMARINE)
B(-11,-5,17,PRISMARINE)
B(-11,-4,5,PRISMARINE)
B(-11,-4,6,PRISMARINE)
B(-11,-4,7,PRISMARINE)
B(-11,-4,8,PRISMARINE)
B(-11,-4,9,PRISMARINE)
B(-11,-4,10,PRISMARINE)
B(-11,-4,11,PRISMARINE)
B(-11,-4,12,PRISMARINE)
B(-11,-4,13,PRISMARINE)
B(-11,-4,14,PRISMARINE)
B(-11,-4,15,PRISMARINE)
B(-11,-4,16,PRISMARINE)
B(-11,-4,17,PRISMARINE)
B(-11,-3,6,PRISMARINE)
B(-11,-3,7,PRISMARINE)
B(-11,-3,8,PRISMARINE)
B(-11,-3,9,PRISMARINE)
B(-11,-3,10,PRISMARINE)
B(-11,-3,11,PRISMARINE)
B(-11,-3,12,PRISMARINE)
B(-11,-3,13,PRISMARINE)
B(-11,-3,14,PRISMARINE)
B(-11,-3,15,PRISMARINE)
B(-11,-3,16,PRISMARINE)
B(-11,-3,17,PRISMARINE)
B(-11,-2,6,PRISMARINE)
B(-11,-2,7,PRISMARINE)
B(-11,-2,8,PRISMARINE)
B(-11,-2,9,PRISMARINE)
B(-11,-2,10,PRISMARINE)
B(-11,-2,11,PRISMARINE)
B(-11,-2,12,PRISMARINE)
B(-11,-2,13,PRISMARINE)
B(-11,-2,14,PRISMARINE)
B(-11,-2,15,PRISMARINE)
B(-11,-2,16,PRISMARINE)
B(-11,-2,17,PRISMARINE)
B(-11,-1,7,PRISMARINE)
B(-11,-1,8,PRISMARINE)
B(-11,-1,9,PRISMARINE)
B(-11,-1,10,PRISMARINE)
B(-11,-1,11,PRISMARINE)
B(-11,-1,12,PRISMARINE)
B(-11,-1,13,PRISMARINE)
B(-11,-1,14,PRISMARINE)
B(-11,-1,15,PRISMARINE)
B(-11,-1,16,PRISMARINE)
B(-11,-1,17,PRISMARINE)
B(-11,0,8,PRISMARINE)
B(-11,0,9,PRISMARINE)
B(-11,0,10,PRISMARINE)
B(-11,0,11,PRISMARINE)
B(-11,0,12,PRISMARINE)
B(-11,0,13,PRISMARINE)
B(-11,0,14,PRISMARINE)
B(-11,0,15,PRISMARINE)
B(-11,0,16,PRISMARINE)
B(-11,0,17,PRISMARINE)
B(-11,1,10,PRISMARINE)
B(-11,1,11,PRISMARINE)
B(-11,1,12,PRISMARINE)
B(-11,1,13,PRISMARINE)
B(-11,1,15,PRISMARINE)
B(-11,2,11,PRISMARINE)
B(-11,3,11,PRISMARINE)
B(-11,4,11,PRISMARINE)
B(-10,-14,8,PRISMARINE)
B(-10,-14,9,PRISMARINE)
B(-10,-14,10,PRISMARINE)
B(-10,-14,11,PRISMARINE)
B(-10,-14,12,PRISMARINE)
B(-10,-14,13,PRISMARINE)
B(-10,-14,14,PRISMARINE)
B(-10,-14,15,PRISMARINE)
B(-10,-13,8,PRISMARINE)
B(-10,-13,9,PRISMARINE)
B(-10,-13,10,PRISMARINE)
B(-10,-13,11,PRISMARINE)
B(-10,-13,12,PRISMARINE)
B(-10,-13,13,PRISMARINE)
B(-10,-13,14,PRISMARINE)
B(-10,-13,15,PRISMARINE)
B(-10,-12,8,PRISMARINE)
B(-10,-12,9,PRISMARINE)
B(-10,-12,10,PRISMARINE)
B(-10,-12,11,PRISMARINE)
B(-10,-12,12,PRISMARINE)
B(-10,-12,13,PRISMARINE)
B(-10,-12,14,PRISMARINE)
B(-10,-12,15,PRISMARINE)
B(-10,-12,16,PRISMARINE)
B(-10,-12,17,PRISMARINE)
B(-10,-11,7,PRISMARINE)
B(-10,-11,8,PRISMARINE)
B(-10,-11,9,PRISMARINE)
B(-10,-11,10,PRISMARINE)
B(-10,-11,11,PRISMARINE)
B(-10,-11,12,PRISMARINE)
B(-10,-11,13,PRISMARINE)
B(-10,-11,14,PRISMARINE)
B(-10,-11,15,PRISMARINE)
B(-10,-11,16,PRISMARINE)
B(-10,-11,17,PRISMARINE)
B(-10,-10,6,PRISMARINE)
B(-10,-10,7,PRISMARINE)
B(-10,-10,8,PRISMARINE)
B(-10,-10,9,PRISMARINE)
B(-10,-10,10,PRISMARINE)
B(-10,-10,11,PRISMARINE)
B(-10,-10,12,PRISMARINE)
B(-10,-10,13,PRISMARINE)
B(-10,-10,14,PRISMARINE)
B(-10,-10,15,PRISMARINE)
B(-10,-10,16,PRISMARINE)
B(-10,-10,17,PRISMARINE)
B(-10,-9,6,PRISMARINE)
B(-10,-9,7,PRISMARINE)
B(-10,-9,8,PRISMARINE)
B(-10,-9,9,PRISMARINE)
B(-10,-9,10,PRISMARINE)
B(-10,-9,11,PRISMARINE)
B(-10,-9,12,PRISMARINE)
B(-10,-9,13,PRISMARINE)
B(-10,-9,14,PRISMARINE)
B(-10,-9,15,PRISMARINE)
B(-10,-9,16,PRISMARINE)
B(-10,-9,17,PRISMARINE)
B(-10,-8,6,PRISMARINE)
B(-10,-8,7,PRISMARINE)
B(-10,-8,8,PRISMARINE)
B(-10,-8,9,PRISMARINE)
B(-10,-8,10,PRISMARINE)
B(-10,-8,11,PRISMARINE)
B(-10,-8,12,PRISMARINE)
B(-10,-8,13,PRISMARINE)
B(-10,-8,14,PRISMARINE)
B(-10,-8,15,PRISMARINE)
B(-10,-8,16,PRISMARINE)
B(-10,-8,17,PRISMARINE)
B(-10,-7,5,PRISMARINE)
B(-10,-7,6,PRISMARINE)
B(-10,-7,7,PRISMARINE)
B(-10,-7,8,PRISMARINE)
B(-10,-7,9,PRISMARINE)
B(-10,-7,10,PRISMARINE)
B(-10,-7,11,PRISMARINE)
B(-10,-7,12,PRISMARINE)
B(-10,-7,13,PRISMARINE)
B(-10,-7,14,PRISMARINE)
B(-10,-7,15,PRISMARINE)
B(-10,-7,16,PRISMARINE)
B(-10,-7,17,PRISMARINE)
B(-10,-6,3,PRISMARINE)
B(-10,-6,4,PRISMARINE)
B(-10,-6,5,PRISMARINE)
B(-10,-6,6,PRISMARINE)
B(-10,-6,7,PRISMARINE)
B(-10,-6,8,PRISMARINE)
B(-10,-6,9,PRISMARINE)
B(-10,-6,10,PRISMARINE)
B(-10,-6,11,PRISMARINE)
B(-10,-6,12,PRISMARINE)
B(-10,-6,13,PRISMARINE)
B(-10,-6,14,PRISMARINE)
B(-10,-6,15,PRISMARINE)
B(-10,-6,16,PRISMARINE)
B(-10,-6,17,PRISMARINE)
B(-10,-5,2,PRISMARINE)
B(-10,-5,3,PRISMARINE)
B(-10,-5,4,PRISMARINE)
B(-10,-5,5,PRISMARINE)
B(-10,-5,6,PRISMARINE)
B(-10,-5,7,PRISMARINE)
B(-10,-5,8,PRISMARINE)
B(-10,-5,9,PRISMARINE)
B(-10,-5,10,PRISMARINE)
B(-10,-5,11,PRISMARINE)
B(-10,-5,12,PRISMARINE)
B(-10,-5,13,PRISMARINE)
B(-10,-5,14,PRISMARINE)
B(-10,-5,15,PRISMARINE)
B(-10,-5,16,PRISMARINE)
B(-10,-5,17,PRISMARINE)
B(-10,-4,2,PRISMARINE)
B(-10,-4,3,PRISMARINE)
B(-10,-4,4,PRISMARINE)
B(-10,-4,5,PRISMARINE)
B(-10,-4,6,PRISMARINE)
B(-10,-4,7,PRISMARINE)
B(-10,-4,8,PRISMARINE)
B(-10,-4,9,PRISMARINE)
B(-10,-4,10,PRISMARINE)
B(-10,-4,11,PRISMARINE)
B(-10,-4,12,PRISMARINE)
B(-10,-4,13,PRISMARINE)
B(-10,-4,14,PRISMARINE)
B(-10,-4,15,PRISMARINE)
B(-10,-4,16,PRISMARINE)
B(-10,-4,17,PRISMARINE)
B(-10,-3,3,PRISMARINE)
B(-10,-3,4,PRISMARINE)
B(-10,-3,5,PRISMARINE)
B(-10,-3,6,PRISMARINE)
B(-10,-3,7,PRISMARINE)
B(-10,-3,8,PRISMARINE)
B(-10,-3,9,PRISMARINE)
B(-10,-3,10,PRISMARINE)
B(-10,-3,11,PRISMARINE)
B(-10,-3,12,PRISMARINE)
B(-10,-3,13,PRISMARINE)
B(-10,-3,14,PRISMARINE)
B(-10,-3,15,PRISMARINE)
B(-10,-3,16,PRISMARINE)
B(-10,-3,17,PRISMARINE)
B(-10,-3,18,PRISMARINE)
B(-10,-2,4,PRISMARINE)
B(-10,-2,5,PRISMARINE)
B(-10,-2,6,PRISMARINE)
B(-10,-2,7,PRISMARINE)
B(-10,-2,8,PRISMARINE)
B(-10,-2,9,PRISMARINE)
B(-10,-2,10,PRISMARINE)
B(-10,-2,11,PRISMARINE)
B(-10,-2,12,PRISMARINE)
B(-10,-2,13,PRISMARINE)
B(-10,-2,14,PRISMARINE)
B(-10,-2,15,PRISMARINE)
B(-10,-2,16,PRISMARINE)
B(-10,-2,17,PRISMARINE)
B(-10,-2,18,PRISMARINE)
B(-10,-1,5,PRISMARINE)
B(-10,-1,6,PRISMARINE)
B(-10,-1,7,PRISMARINE)
B(-10,-1,8,PRISMARINE)
B(-10,-1,9,PRISMARINE)
B(-10,-1,10,PRISMARINE)
B(-10,-1,11,PRISMARINE)
B(-10,-1,12,PRISMARINE)
B(-10,-1,13,PRISMARINE)
B(-10,-1,14,PRISMARINE)
B(-10,-1,15,PRISMARINE)
B(-10,-1,16,PRISMARINE)
B(-10,-1,17,PRISMARINE)
B(-10,-1,18,PRISMARINE)
B(-10,0,7,PRISMARINE)
B(-10,0,8,PRISMARINE)
B(-10,0,9,PRISMARINE)
B(-10,0,10,PRISMARINE)
B(-10,0,11,PRISMARINE)
B(-10,0,12,PRISMARINE)
B(-10,0,13,PRISMARINE)
B(-10,0,14,PRISMARINE)
B(-10,0,15,PRISMARINE)
B(-10,0,16,PRISMARINE)
B(-10,0,17,PRISMARINE)
B(-10,0,18,PRISMARINE)
B(-10,1,8,PRISMARINE)
B(-10,1,9,PRISMARINE)
B(-10,1,10,PRISMARINE)
B(-10,1,12,PRISMARINE)
B(-10,1,13,PRISMARINE)
B(-10,1,14,PRISMARINE)
B(-10,1,15,PRISMARINE)
B(-10,1,16,PRISMARINE)
B(-10,1,18,PRISMARINE)
B(-10,2,12,PRISMARINE)
B(-10,2,13,PRISMARINE)
B(-10,2,14,PRISMARINE)
B(-10,2,15,PRISMARINE)
B(-9,-17,12,PRISMARINE)
B(-9,-17,13,PRISMARINE)
B(-9,-17,14,PRISMARINE)
B(-9,-17,15,PRISMARINE)
B(-9,-17,16,PRISMARINE)
B(-9,-16,12,PRISMARINE)
B(-9,-16,13,PRISMARINE)
B(-9,-16,14,PRISMARINE)
B(-9,-16,15,PRISMARINE)
B(-9,-16,16,PRISMARINE)
B(-9,-15,8,PRISMARINE)
B(-9,-15,9,PRISMARINE)
B(-9,-15,10,PRISMARINE)
B(-9,-15,11,PRISMARINE)
B(-9,-15,12,PRISMARINE)
B(-9,-15,13,PRISMARINE)
B(-9,-15,14,PRISMARINE)
B(-9,-15,15,PRISMARINE)
B(-9,-15,16,PRISMARINE)
B(-9,-14,7,PRISMARINE)
B(-9,-14,8,SAND:1)
B(-9,-14,9,SAND:1)
B(-9,-14,10,PRISMARINE)
B(-9,-14,11,PRISMARINE)
B(-9,-14,12,PRISMARINE)
B(-9,-14,13,PRISMARINE)
B(-9,-14,14,PRISMARINE)
B(-9,-14,15,PRISMARINE)
B(-9,-14,16,PRISMARINE)
B(-9,-13,7,PRISMARINE)
B(-9,-13,8,PRISMARINE)
B(-9,-13,9,PRISMARINE)
B(-9,-13,10,PRISMARINE)
B(-9,-13,11,SAND:1)
B(-9,-13,12,PRISMARINE)
B(-9,-13,13,PRISMARINE)
B(-9,-13,14,PRISMARINE)
B(-9,-13,15,PRISMARINE)
B(-9,-13,16,PRISMARINE)
B(-9,-13,17,PRISMARINE)
B(-9,-12,7,PRISMARINE)
B(-9,-12,8,PRISMARINE)
B(-9,-12,9,PRISMARINE)
B(-9,-12,10,PRISMARINE)
B(-9,-12,11,SAND:1)
B(-9,-12,12,PRISMARINE)
B(-9,-12,13,PRISMARINE)
B(-9,-12,14,PRISMARINE)
B(-9,-12,15,PRISMARINE)
B(-9,-12,16,PRISMARINE)
B(-9,-12,17,PRISMARINE)
B(-9,-11,3,PRISMARINE)
B(-9,-11,4,PRISMARINE)
B(-9,-11,5,PRISMARINE)
B(-9,-11,6,PRISMARINE)
B(-9,-11,7,PRISMARINE)
B(-9,-11,8,PRISMARINE)
B(-9,-11,9,PRISMARINE)
B(-9,-11,10,PRISMARINE)
B(-9,-11,11,SAND:1)
B(-9,-11,12,PRISMARINE)
B(-9,-11,13,PRISMARINE)
B(-9,-11,14,PRISMARINE)
B(-9,-11,15,PRISMARINE)
B(-9,-11,16,PRISMARINE)
B(-9,-11,17,PRISMARINE)
B(-9,-11,18,PRISMARINE)
B(-9,-10,3,PRISMARINE)
B(-9,-10,4,PRISMARINE)
B(-9,-10,5,PRISMARINE)
B(-9,-10,6,PRISMARINE)
B(-9,-10,7,PRISMARINE)
B(-9,-10,8,PRISMARINE)
B(-9,-10,9,PRISMARINE)
B(-9,-10,10,PRISMARINE)
B(-9,-10,11,PRISMARINE)
B(-9,-10,12,PRISMARINE)
B(-9,-10,13,PRISMARINE)
B(-9,-10,14,PRISMARINE)
B(-9,-10,15,PRISMARINE)
B(-9,-10,16,PRISMARINE)
B(-9,-10,17,PRISMARINE)
B(-9,-10,18,PRISMARINE)
B(-9,-9,3,PRISMARINE)
B(-9,-9,4,PRISMARINE)
B(-9,-9,5,PRISMARINE)
B(-9,-9,6,PRISMARINE)
B(-9,-9,7,PRISMARINE)
B(-9,-9,8,PRISMARINE)
B(-9,-9,9,PRISMARINE)
B(-9,-9,10,PRISMARINE)
B(-9,-9,11,PRISMARINE)
B(-9,-9,12,PRISMARINE)
B(-9,-9,13,PRISMARINE)
B(-9,-9,14,PRISMARINE)
B(-9,-9,15,PRISMARINE)
B(-9,-9,16,PRISMARINE)
B(-9,-9,17,PRISMARINE)
B(-9,-9,18,PRISMARINE)
B(-9,-8,2,PRISMARINE)
B(-9,-8,3,PRISMARINE)
B(-9,-8,4,PRISMARINE)
B(-9,-8,5,PRISMARINE)
B(-9,-8,6,PRISMARINE)
B(-9,-8,7,PRISMARINE)
B(-9,-8,8,PRISMARINE)
B(-9,-8,9,PRISMARINE)
B(-9,-8,10,PRISMARINE)
B(-9,-8,11,PRISMARINE)
B(-9,-8,12,PRISMARINE)
B(-9,-8,13,PRISMARINE)
B(-9,-8,14,PRISMARINE)
B(-9,-8,15,PRISMARINE)
B(-9,-8,16,PRISMARINE)
B(-9,-8,17,PRISMARINE)
B(-9,-8,18,PRISMARINE)
B(-9,-7,1,PRISMARINE)
B(-9,-7,2,PRISMARINE)
B(-9,-7,3,PRISMARINE)
B(-9,-7,4,PRISMARINE)
B(-9,-7,5,PRISMARINE)
B(-9,-7,6,PRISMARINE)
B(-9,-7,7,PRISMARINE)
B(-9,-7,8,PRISMARINE)
B(-9,-7,9,PRISMARINE)
B(-9,-7,10,PRISMARINE)
B(-9,-7,11,PRISMARINE)
B(-9,-7,12,PRISMARINE)
B(-9,-7,13,PRISMARINE)
B(-9,-7,14,PRISMARINE)
B(-9,-7,15,PRISMARINE)
B(-9,-7,16,PRISMARINE)
B(-9,-7,17,PRISMARINE)
B(-9,-7,18,PRISMARINE)
B(-9,-6,1,PRISMARINE)
B(-9,-6,2,PRISMARINE)
B(-9,-6,3,PRISMARINE)
B(-9,-6,4,PRISMARINE)
B(-9,-6,5,PRISMARINE)
B(-9,-6,6,PRISMARINE)
B(-9,-6,7,PRISMARINE)
B(-9,-6,8,PRISMARINE)
B(-9,-6,9,PRISMARINE)
B(-9,-6,10,PRISMARINE)
B(-9,-6,11,PRISMARINE)
B(-9,-6,12,PRISMARINE)
B(-9,-6,13,PRISMARINE)
B(-9,-6,14,PRISMARINE)
B(-9,-6,15,PRISMARINE)
B(-9,-6,16,PRISMARINE)
B(-9,-6,17,PRISMARINE)
B(-9,-6,18,PRISMARINE)
B(-9,-5,0,PRISMARINE)
B(-9,-5,1,PRISMARINE)
B(-9,-5,2,PRISMARINE)
B(-9,-5,3,PRISMARINE)
B(-9,-5,4,PRISMARINE)
B(-9,-5,5,PRISMARINE)
B(-9,-5,6,PRISMARINE)
B(-9,-5,7,PRISMARINE)
B(-9,-5,8,PRISMARINE)
B(-9,-5,9,PRISMARINE)
B(-9,-5,10,PRISMARINE)
B(-9,-5,11,PRISMARINE)
B(-9,-5,12,PRISMARINE)
B(-9,-5,13,PRISMARINE)
B(-9,-5,14,PRISMARINE)
B(-9,-5,15,PRISMARINE)
B(-9,-5,16,PRISMARINE)
B(-9,-5,17,PRISMARINE)
B(-9,-5,18,PRISMARINE)
B(-9,-4,0,PRISMARINE)
B(-9,-4,1,PRISMARINE)
B(-9,-4,2,PRISMARINE)
B(-9,-4,3,PRISMARINE)
B(-9,-4,4,PRISMARINE)
B(-9,-4,5,PRISMARINE)
B(-9,-4,6,PRISMARINE)
B(-9,-4,7,PRISMARINE)
B(-9,-4,8,PRISMARINE)
B(-9,-4,9,PRISMARINE)
B(-9,-4,10,PRISMARINE)
B(-9,-4,11,PRISMARINE)
B(-9,-4,12,PRISMARINE)
B(-9,-4,13,PRISMARINE)
B(-9,-4,14,PRISMARINE)
B(-9,-4,15,PRISMARINE)
B(-9,-4,16,PRISMARINE)
B(-9,-4,17,PRISMARINE)
B(-9,-4,18,PRISMARINE)
B(-9,-4,19,PRISMARINE)
B(-9,-3,0,PRISMARINE)
B(-9,-3,1,PRISMARINE)
B(-9,-3,2,PRISMARINE)
B(-9,-3,3,PRISMARINE)
B(-9,-3,4,PRISMARINE)
B(-9,-3,5,PRISMARINE)
B(-9,-3,6,PRISMARINE)
B(-9,-3,7,PRISMARINE)
B(-9,-3,8,PRISMARINE)
B(-9,-3,9,PRISMARINE)
B(-9,-3,10,PRISMARINE)
B(-9,-3,11,PRISMARINE)
B(-9,-3,12,PRISMARINE)
B(-9,-3,13,PRISMARINE)
B(-9,-3,14,PRISMARINE)
B(-9,-3,15,PRISMARINE)
B(-9,-3,16,PRISMARINE)
B(-9,-3,17,PRISMARINE)
B(-9,-3,18,PRISMARINE)
B(-9,-3,19,PRISMARINE)
B(-9,-2,2,PRISMARINE)
B(-9,-2,3,PRISMARINE)
B(-9,-2,4,PRISMARINE)
B(-9,-2,5,PRISMARINE)
B(-9,-2,6,PRISMARINE)
B(-9,-2,7,PRISMARINE)
B(-9,-2,8,PRISMARINE)
B(-9,-2,9,PRISMARINE)
B(-9,-2,10,PRISMARINE)
B(-9,-2,11,PRISMARINE)
B(-9,-2,12,PRISMARINE)
B(-9,-2,13,PRISMARINE)
B(-9,-2,14,PRISMARINE)
B(-9,-2,15,PRISMARINE)
B(-9,-2,16,PRISMARINE)
B(-9,-2,17,PRISMARINE)
B(-9,-2,18,PRISMARINE)
B(-9,-2,19,PRISMARINE)
B(-9,-1,3,PRISMARINE)
B(-9,-1,4,PRISMARINE)
B(-9,-1,5,PRISMARINE)
B(-9,-1,6,PRISMARINE)
B(-9,-1,7,PRISMARINE)
B(-9,-1,8,PRISMARINE)
B(-9,-1,9,PRISMARINE)
B(-9,-1,10,PRISMARINE)
B(-9,-1,11,PRISMARINE)
B(-9,-1,12,PRISMARINE)
B(-9,-1,13,PRISMARINE)
B(-9,-1,14,PRISMARINE)
B(-9,-1,15,PRISMARINE)
B(-9,-1,16,PRISMARINE)
B(-9,-1,17,PRISMARINE)
B(-9,-1,18,PRISMARINE)
B(-9,-1,19,PRISMARINE)
B(-9,0,6,PRISMARINE)
B(-9,0,7,PRISMARINE)
B(-9,0,8,PRISMARINE)
B(-9,0,9,PRISMARINE)
B(-9,0,10,PRISMARINE)
B(-9,0,11,PRISMARINE)
B(-9,0,12,PRISMARINE)
B(-9,0,13,PRISMARINE)
B(-9,0,14,PRISMARINE)
B(-9,0,15,PRISMARINE)
B(-9,0,16,PRISMARINE)
B(-9,0,17,PRISMARINE)
B(-9,0,18,PRISMARINE)
B(-9,0,19,PRISMARINE)
B(-9,1,7,PRISMARINE)
B(-9,1,8,PRISMARINE)
B(-9,1,9,PRISMARINE)
B(-9,1,10,PRISMARINE)
B(-9,1,11,PRISMARINE)
B(-9,1,12,PRISMARINE)
B(-9,1,13,PRISMARINE)
B(-9,1,14,PRISMARINE)
B(-9,1,15,PRISMARINE)
B(-9,1,16,PRISMARINE)
B(-9,1,17,PRISMARINE)
B(-9,1,18,PRISMARINE)
B(-9,2,8,SPONGE:1)
B(-9,2,9,PRISMARINE)
B(-9,2,10,PRISMARINE)
B(-9,2,11,PRISMARINE)
B(-9,2,12,PRISMARINE)
B(-9,2,13,PRISMARINE)
B(-9,2,14,PRISMARINE)
B(-9,2,15,PRISMARINE)
B(-9,2,16,PRISMARINE)
B(-9,2,17,PRISMARINE)
B(-9,3,11,PRISMARINE)
B(-9,3,12,PRISMARINE)
B(-9,3,15,PRISMARINE)
B(-9,3,16,PRISMARINE)
B(-8,-18,12,PRISMARINE)
B(-8,-18,13,PRISMARINE)
B(-8,-18,14,PRISMARINE)
B(-8,-18,15,PRISMARINE)
B(-8,-18,16,PRISMARINE)
B(-8,-17,8,PRISMARINE)
B(-8,-17,9,PRISMARINE)
B(-8,-17,10,PRISMARINE)
B(-8,-17,11,PRISMARINE)
B(-8,-17,12,PRISMARINE)
B(-8,-17,13,PRISMARINE)
B(-8,-17,14,PRISMARINE)
B(-8,-17,15,PRISMARINE)
B(-8,-17,16,PRISMARINE)
B(-8,-17,17,PRISMARINE)
B(-8,-16,7,PRISMARINE)
B(-8,-16,8,PRISMARINE)
B(-8,-16,9,PRISMARINE)
B(-8,-16,10,PRISMARINE)
B(-8,-16,11,PRISMARINE)
B(-8,-16,12,SAND:1)
B(-8,-16,13,PRISMARINE)
B(-8,-16,14,PRISMARINE)
B(-8,-16,15,PRISMARINE)
B(-8,-16,16,PRISMARINE)
B(-8,-16,17,PRISMARINE)
B(-8,-15,7,PRISMARINE)
B(-8,-15,8,PRISMARINE)
B(-8,-15,9,SAND:1)
B(-8,-15,10,PRISMARINE)
B(-8,-15,11,PRISMARINE)
B(-8,-15,12,SAND:1)
B(-8,-15,13,SAND)
B(-8,-15,14,PRISMARINE)
B(-8,-15,15,PRISMARINE)
B(-8,-15,16,PRISMARINE)
B(-8,-15,17,PRISMARINE)
B(-8,-14,7,PRISMARINE)
B(-8,-14,8,SAND:1)
B(-8,-14,9,SAND:1)
B(-8,-14,10,SAND:1)
B(-8,-14,11,PRISMARINE)
B(-8,-14,12,SAND:1)
B(-8,-14,13,SAND:1)
B(-8,-14,14,PRISMARINE)
B(-8,-14,15,PRISMARINE)
B(-8,-14,16,PRISMARINE)
B(-8,-14,17,PRISMARINE)
B(-8,-13,5,PRISMARINE)
B(-8,-13,6,PRISMARINE)
B(-8,-13,7,PRISMARINE)
B(-8,-13,8,SAND:1)
B(-8,-13,9,SAND:1)
B(-8,-13,10,SAND:1)
B(-8,-13,11,PRISMARINE)
B(-8,-13,12,PRISMARINE)
B(-8,-13,13,PRISMARINE)
B(-8,-13,14,PRISMARINE)
B(-8,-13,15,PRISMARINE)
B(-8,-13,16,PRISMARINE)
B(-8,-13,17,PRISMARINE)
B(-8,-13,18,PRISMARINE)
B(-8,-12,3,PRISMARINE)
B(-8,-12,4,PRISMARINE)
B(-8,-12,5,PRISMARINE)
B(-8,-12,6,PRISMARINE)
B(-8,-12,7,PRISMARINE)
B(-8,-12,8,SAND:1)
B(-8,-12,9,PRISMARINE)
B(-8,-12,10,PRISMARINE)
B(-8,-12,11,PRISMARINE)
B(-8,-12,12,PRISMARINE)
B(-8,-12,13,PRISMARINE)
B(-8,-12,14,PRISMARINE)
B(-8,-12,15,PRISMARINE)
B(-8,-12,16,PRISMARINE)
B(-8,-12,17,PRISMARINE)
B(-8,-12,18,PRISMARINE)
B(-8,-11,2,PRISMARINE)
B(-8,-11,3,PRISMARINE)
B(-8,-11,4,PRISMARINE)
B(-8,-11,5,PRISMARINE)
B(-8,-11,6,PRISMARINE)
B(-8,-11,7,PRISMARINE)
B(-8,-11,8,PRISMARINE)
B(-8,-11,9,PRISMARINE)
B(-8,-11,10,PRISMARINE)
B(-8,-11,11,PRISMARINE)
B(-8,-11,12,PRISMARINE)
B(-8,-11,13,PRISMARINE)
B(-8,-11,14,PRISMARINE)
B(-8,-11,15,PRISMARINE)
B(-8,-11,16,PRISMARINE)
B(-8,-11,17,PRISMARINE)
B(-8,-11,18,PRISMARINE)
B(-8,-11,19,PRISMARINE)
B(-8,-10,1,PRISMARINE)
B(-8,-10,2,PRISMARINE)
B(-8,-10,3,PRISMARINE)
B(-8,-10,4,PRISMARINE)
B(-8,-10,5,PRISMARINE)
B(-8,-10,6,PRISMARINE)
B(-8,-10,7,PRISMARINE)
B(-8,-10,8,PRISMARINE)
B(-8,-10,9,PRISMARINE)
B(-8,-10,10,PRISMARINE)
B(-8,-10,11,PRISMARINE)
B(-8,-10,12,PRISMARINE)
B(-8,-10,13,PRISMARINE)
B(-8,-10,14,PRISMARINE)
B(-8,-10,15,PRISMARINE)
B(-8,-10,16,PRISMARINE)
B(-8,-10,17,PRISMARINE)
B(-8,-10,18,PRISMARINE)
B(-8,-10,19,PRISMARINE)
B(-8,-9,0,PRISMARINE)
B(-8,-9,1,PRISMARINE)
B(-8,-9,2,PRISMARINE)
B(-8,-9,3,PRISMARINE)
B(-8,-9,4,PRISMARINE)
B(-8,-9,5,PRISMARINE)
B(-8,-9,6,PRISMARINE)
B(-8,-9,7,PRISMARINE)
B(-8,-9,8,PRISMARINE)
B(-8,-9,9,PRISMARINE)
B(-8,-9,10,PRISMARINE)
B(-8,-9,11,PRISMARINE)
B(-8,-9,12,PRISMARINE)
B(-8,-9,13,PRISMARINE)
B(-8,-9,14,PRISMARINE)
B(-8,-9,15,PRISMARINE)
B(-8,-9,16,PRISMARINE)
B(-8,-9,17,PRISMARINE)
B(-8,-9,18,PRISMARINE)
B(-8,-9,19,PRISMARINE)
B(-8,-8,0,PRISMARINE)
B(-8,-8,1,PRISMARINE)
B(-8,-8,2,PRISMARINE)
B(-8,-8,3,PRISMARINE)
B(-8,-8,4,PRISMARINE)
B(-8,-8,5,PRISMARINE)
B(-8,-8,6,PRISMARINE)
B(-8,-8,7,PRISMARINE)
B(-8,-8,8,PRISMARINE)
B(-8,-8,9,PRISMARINE)
B(-8,-8,10,PRISMARINE)
B(-8,-8,11,PRISMARINE)
B(-8,-8,12,PRISMARINE)
B(-8,-8,13,PRISMARINE)
B(-8,-8,14,PRISMARINE)
B(-8,-8,15,PRISMARINE)
B(-8,-8,16,PRISMARINE)
B(-8,-8,17,PRISMARINE)
B(-8,-8,18,PRISMARINE)
B(-8,-8,19,PRISMARINE)
B(-8,-7,0,PRISMARINE)
B(-8,-7,1,PRISMARINE)
B(-8,-7,2,PRISMARINE)
B(-8,-7,3,PRISMARINE)
B(-8,-7,4,PRISMARINE)
B(-8,-7,5,PRISMARINE)
B(-8,-7,6,PRISMARINE)
B(-8,-7,7,PRISMARINE)
B(-8,-7,8,PRISMARINE)
B(-8,-7,9,PRISMARINE)
B(-8,-7,10,PRISMARINE)
B(-8,-7,11,PRISMARINE)
B(-8,-7,12,PRISMARINE)
B(-8,-7,13,PRISMARINE)
B(-8,-7,14,PRISMARINE)
B(-8,-7,15,PRISMARINE)
B(-8,-7,16,PRISMARINE)
B(-8,-7,17,PRISMARINE)
B(-8,-7,18,PRISMARINE)
B(-8,-7,19,PRISMARINE)
B(-8,-6,-1,PRISMARINE)
B(-8,-6,0,PRISMARINE)
B(-8,-6,1,PRISMARINE)
B(-8,-6,2,PRISMARINE)
B(-8,-6,3,PRISMARINE)
B(-8,-6,4,PRISMARINE)
B(-8,-6,5,PRISMARINE)
B(-8,-6,6,PRISMARINE)
B(-8,-6,7,PRISMARINE)
B(-8,-6,8,PRISMARINE)
B(-8,-6,9,PRISMARINE)
B(-8,-6,10,PRISMARINE)
B(-8,-6,11,PRISMARINE)
B(-8,-6,12,PRISMARINE)
B(-8,-6,13,PRISMARINE)
B(-8,-6,14,PRISMARINE)
B(-8,-6,15,PRISMARINE)
B(-8,-6,16,PRISMARINE)
B(-8,-6,17,PRISMARINE)
B(-8,-6,18,PRISMARINE)
B(-8,-6,19,PRISMARINE)
B(-8,-5,-2,PRISMARINE)
B(-8,-5,-1,PRISMARINE)
B(-8,-5,0,PRISMARINE)
B(-8,-5,1,PRISMARINE)
B(-8,-5,2,PRISMARINE)
B(-8,-5,3,PRISMARINE)
B(-8,-5,4,PRISMARINE)
B(-8,-5,5,PRISMARINE)
B(-8,-5,6,PRISMARINE)
B(-8,-5,7,PRISMARINE)
B(-8,-5,8,PRISMARINE)
B(-8,-5,9,PRISMARINE)
B(-8,-5,10,PRISMARINE)
B(-8,-5,11,PRISMARINE)
B(-8,-5,12,PRISMARINE)
B(-8,-5,13,PRISMARINE)
B(-8,-5,14,PRISMARINE)
B(-8,-5,15,PRISMARINE)
B(-8,-5,16,PRISMARINE)
B(-8,-5,17,PRISMARINE)
B(-8,-5,18,PRISMARINE)
B(-8,-5,19,PRISMARINE)
B(-8,-4,-2,PRISMARINE)
B(-8,-4,-1,PRISMARINE)
B(-8,-4,0,PRISMARINE)
B(-8,-4,1,PRISMARINE)
B(-8,-4,2,PRISMARINE)
B(-8,-4,3,PRISMARINE)
B(-8,-4,4,PRISMARINE)
B(-8,-4,5,PRISMARINE)
B(-8,-4,6,PRISMARINE)
B(-8,-4,7,PRISMARINE)
B(-8,-4,8,PRISMARINE)
B(-8,-4,9,PRISMARINE)
B(-8,-4,10,PRISMARINE)
B(-8,-4,11,PRISMARINE)
B(-8,-4,12,PRISMARINE)
B(-8,-4,13,PRISMARINE)
B(-8,-4,14,PRISMARINE)
B(-8,-4,15,PRISMARINE)
B(-8,-4,16,PRISMARINE)
B(-8,-4,17,PRISMARINE)
B(-8,-4,18,PRISMARINE)
B(-8,-4,19,PRISMARINE)
B(-8,-3,-3,PRISMARINE)
B(-8,-3,-2,PRISMARINE)
B(-8,-3,-1,PRISMARINE)
B(-8,-3,0,PRISMARINE)
B(-8,-3,1,PRISMARINE)
B(-8,-3,2,PRISMARINE)
B(-8,-3,3,PRISMARINE)
B(-8,-3,4,PRISMARINE)
B(-8,-3,5,PRISMARINE)
B(-8,-3,6,PRISMARINE)
B(-8,-3,7,PRISMARINE)
B(-8,-3,8,PRISMARINE)
B(-8,-3,9,PRISMARINE)
B(-8,-3,10,PRISMARINE)
B(-8,-3,11,PRISMARINE)
B(-8,-3,12,PRISMARINE)
B(-8,-3,13,PRISMARINE)
B(-8,-3,14,PRISMARINE)
B(-8,-3,15,PRISMARINE)
B(-8,-3,16,PRISMARINE)
B(-8,-3,17,PRISMARINE)
B(-8,-3,18,PRISMARINE)
B(-8,-3,19,PRISMARINE)
B(-8,-2,-3,PRISMARINE)
B(-8,-2,-2,PRISMARINE)
B(-8,-2,-1,PRISMARINE)
B(-8,-2,0,PRISMARINE)
B(-8,-2,1,PRISMARINE)
B(-8,-2,2,PRISMARINE)
B(-8,-2,3,PRISMARINE)
B(-8,-2,4,PRISMARINE)
B(-8,-2,5,PRISMARINE)
B(-8,-2,6,PRISMARINE)
B(-8,-2,7,PRISMARINE)
B(-8,-2,8,PRISMARINE)
B(-8,-2,9,PRISMARINE)
B(-8,-2,10,PRISMARINE)
B(-8,-2,11,PRISMARINE)
B(-8,-2,12,PRISMARINE)
B(-8,-2,13,PRISMARINE)
B(-8,-2,14,PRISMARINE)
B(-8,-2,15,PRISMARINE)
B(-8,-2,16,PRISMARINE)
B(-8,-2,17,PRISMARINE)
B(-8,-2,18,PRISMARINE)
B(-8,-2,19,PRISMARINE)
B(-8,-1,0,PRISMARINE)
B(-8,-1,2,PRISMARINE)
B(-8,-1,3,PRISMARINE)
B(-8,-1,4,PRISMARINE)
B(-8,-1,5,PRISMARINE)
B(-8,-1,6,PRISMARINE)
B(-8,-1,7,PRISMARINE)
B(-8,-1,8,PRISMARINE)
B(-8,-1,9,PRISMARINE)
B(-8,-1,10,PRISMARINE)
B(-8,-1,11,PRISMARINE)
B(-8,-1,12,PRISMARINE)
B(-8,-1,13,PRISMARINE)
B(-8,-1,14,PRISMARINE)
B(-8,-1,15,PRISMARINE)
B(-8,-1,16,PRISMARINE)
B(-8,-1,17,PRISMARINE)
B(-8,-1,18,PRISMARINE)
B(-8,-1,19,PRISMARINE)
B(-8,0,2,PRISMARINE)
B(-8,0,4,PRISMARINE)
B(-8,0,5,PRISMARINE)
B(-8,0,6,PRISMARINE)
B(-8,0,7,PRISMARINE)
B(-8,0,8,PRISMARINE)
B(-8,0,9,PRISMARINE)
B(-8,0,10,PRISMARINE)
B(-8,0,11,PRISMARINE)
B(-8,0,12,PRISMARINE)
B(-8,0,13,PRISMARINE)
B(-8,0,14,PRISMARINE)
B(-8,0,15,PRISMARINE)
B(-8,0,16,PRISMARINE)
B(-8,0,17,PRISMARINE)
B(-8,0,18,PRISMARINE)
B(-8,0,19,PRISMARINE)
B(-8,1,5,PRISMARINE)
B(-8,1,6,PRISMARINE)
B(-8,1,7,PRISMARINE)
B(-8,1,8,PRISMARINE)
B(-8,1,9,PRISMARINE)
B(-8,1,10,PRISMARINE)
B(-8,1,11,PRISMARINE)
B(-8,1,12,PRISMARINE)
B(-8,1,13,PRISMARINE)
B(-8,1,14,PRISMARINE)
B(-8,1,15,SAND:1)
B(-8,1,16,PRISMARINE)
B(-8,1,17,PRISMARINE)
B(-8,1,18,PRISMARINE)
B(-8,2,7,PRISMARINE)
B(-8,2,8,PRISMARINE)
B(-8,2,9,PRISMARINE)
B(-8,2,10,PRISMARINE)
B(-8,2,11,PRISMARINE)
B(-8,2,12,PRISMARINE)
B(-8,2,13,PRISMARINE)
B(-8,2,14,PRISMARINE)
B(-8,2,15,PRISMARINE)
B(-8,2,16,PRISMARINE)
B(-8,2,17,PRISMARINE)
B(-8,2,18,PRISMARINE)
B(-8,3,7,PRISMARINE)
B(-8,3,10,PRISMARINE)
B(-8,3,11,PRISMARINE)
B(-8,3,12,PRISMARINE)
B(-8,3,13,PRISMARINE)
B(-8,3,14,PRISMARINE)
B(-8,3,15,PRISMARINE)
B(-8,3,16,PRISMARINE)
B(-8,3,17,SPONGE:1)
B(-8,3,18,PRISMARINE)
B(-8,4,12,PRISMARINE)
B(-8,4,14,PRISMARINE)
B(-8,5,14,PRISMARINE)
B(-7,-19,14,PRISMARINE)
B(-7,-19,15,PRISMARINE)
B(-7,-18,8,PRISMARINE)
B(-7,-18,9,PRISMARINE)
B(-7,-18,10,PRISMARINE)
B(-7,-18,11,PRISMARINE)
B(-7,-18,12,PRISMARINE)
B(-7,-18,13,PRISMARINE)
B(-7,-18,14,PRISMARINE)
B(-7,-18,15,PRISMARINE)
B(-7,-18,16,PRISMARINE)
B(-7,-17,6,PRISMARINE)
B(-7,-17,7,PRISMARINE)
B(-7,-17,8,PRISMARINE)
B(-7,-17,9,PRISMARINE)
B(-7,-17,10,PRISMARINE)
B(-7,-17,11,PRISMARINE)
B(-7,-17,12,PRISMARINE)
B(-7,-17,13,SAND)
B(-7,-17,14,SAND)
B(-7,-17,15,PRISMARINE)
B(-7,-17,16,PRISMARINE)
B(-7,-17,17,PRISMARINE)
B(-7,-16,6,PRISMARINE)
B(-7,-16,7,PRISMARINE)
RB(-7,-16,8,CHEST,../../Structures/nbt/Chests/Epic1.nbt,25,CHEST,../../Structures/nbt/Chests/Epic2.nbt,25,CHEST,../../Structures/nbt/Chests/Epic3.nbt,25,CHEST,../../Structures/nbt/Chests/Epic4.nbt,25,CHEST,../../Structures/nbt/Chests/Epic5.nbt,25,CHEST,../../Structures/nbt/Chests/Epic6.nbt,25,CHEST,../../Structures/nbt/Chests/Epic7.nbt,25,CHEST,../../Structures/nbt/Chests/Epic8.nbt,25,CHEST,../../Structures/nbt/Chests/Epic9.nbt,25,CHEST,../../Structures/nbt/Chests/Epic10.nbt,25,CHEST,../../Structures/nbt/Chests/Epic11.nbt,25,CHEST,../../Structures/nbt/Chests/Epic12.nbt,25,CHEST,../../Structures/nbt/Chests/Epic13.nbt,25,CHEST,../../Structures/nbt/Chests/Epic14.nbt,25,CHEST,../../Structures/nbt/Chests/Epic15.nbt,100)
B(-7,-16,9,SAND)
B(-7,-16,10,SAND)
B(-7,-16,11,SAND:1)
B(-7,-16,12,SAND:1)
B(-7,-16,13,SAND:1)
B(-7,-16,14,SAND:1)
B(-7,-16,15,SAND:1)
B(-7,-16,16,SAND:1)
B(-7,-16,17,PRISMARINE)
B(-7,-15,5,PRISMARINE)
B(-7,-15,6,PRISMARINE)
B(-7,-15,7,PRISMARINE)
B(-7,-15,8,SAND:1)
B(-7,-15,9,SAND:1)
B(-7,-15,10,SAND:1)
B(-7,-15,11,SAND:1)
B(-7,-15,12,SAND:1)
B(-7,-15,13,SAND:1)
B(-7,-15,14,SAND:1)
B(-7,-15,15,SAND:1)
B(-7,-15,16,SAND:1)
B(-7,-15,17,PRISMARINE)
B(-7,-14,4,PRISMARINE)
B(-7,-14,5,PRISMARINE)
B(-7,-14,6,PRISMARINE)
B(-7,-14,7,PRISMARINE)
B(-7,-14,8,SAND:1)
B(-7,-14,9,SAND:1)
B(-7,-14,10,SAND:1)
B(-7,-14,11,SAND:1)
B(-7,-14,12,SAND:1)
B(-7,-14,13,SAND:1)
B(-7,-14,14,SAND:1)
B(-7,-14,15,SAND:1)
B(-7,-14,16,PRISMARINE)
B(-7,-14,17,PRISMARINE)
B(-7,-13,1,PRISMARINE)
B(-7,-13,3,PRISMARINE)
B(-7,-13,4,PRISMARINE)
B(-7,-13,5,PRISMARINE)
B(-7,-13,6,PRISMARINE)
B(-7,-13,7,SAND:1)
B(-7,-13,8,SAND:1)
B(-7,-13,9,SAND:1)
B(-7,-13,10,SAND:1)
B(-7,-13,11,SAND:1)
B(-7,-13,12,SAND:1)
B(-7,-13,13,SAND:1)
B(-7,-13,14,PRISMARINE)
B(-7,-13,15,PRISMARINE)
B(-7,-13,16,PRISMARINE)
B(-7,-13,17,PRISMARINE)
B(-7,-12,0,PRISMARINE)
B(-7,-12,1,PRISMARINE)
B(-7,-12,2,PRISMARINE)
B(-7,-12,3,PRISMARINE)
B(-7,-12,4,PRISMARINE)
B(-7,-12,5,PRISMARINE)
B(-7,-12,6,PRISMARINE)
B(-7,-12,7,SAND:1)
B(-7,-12,8,SAND:1)
B(-7,-12,9,PRISMARINE)
B(-7,-12,10,PRISMARINE)
B(-7,-12,11,PRISMARINE)
B(-7,-12,12,PRISMARINE)
B(-7,-12,13,PRISMARINE)
B(-7,-12,14,PRISMARINE)
B(-7,-12,15,PRISMARINE)
B(-7,-12,16,PRISMARINE)
B(-7,-12,17,PRISMARINE)
B(-7,-12,18,PRISMARINE)
B(-7,-11,0,PRISMARINE)
B(-7,-11,1,PRISMARINE)
B(-7,-11,2,PRISMARINE)
B(-7,-11,3,PRISMARINE)
B(-7,-11,4,PRISMARINE)
B(-7,-11,5,PRISMARINE)
B(-7,-11,6,PRISMARINE)
B(-7,-11,7,PRISMARINE)
B(-7,-11,8,PRISMARINE)
B(-7,-11,9,PRISMARINE)
B(-7,-11,10,PRISMARINE)
B(-7,-11,11,PRISMARINE)
B(-7,-11,12,PRISMARINE)
B(-7,-11,13,PRISMARINE)
B(-7,-11,14,PRISMARINE)
B(-7,-11,15,PRISMARINE)
B(-7,-11,16,PRISMARINE)
B(-7,-11,17,PRISMARINE)
B(-7,-11,18,PRISMARINE)
B(-7,-11,19,PRISMARINE)
B(-7,-10,0,PRISMARINE)
B(-7,-10,1,PRISMARINE)
B(-7,-10,2,PRISMARINE)
B(-7,-10,3,PRISMARINE)
B(-7,-10,4,PRISMARINE)
B(-7,-10,5,PRISMARINE)
B(-7,-10,6,PRISMARINE)
B(-7,-10,7,PRISMARINE)
B(-7,-10,8,PRISMARINE)
B(-7,-10,9,PRISMARINE)
B(-7,-10,10,PRISMARINE)
B(-7,-10,11,PRISMARINE)
B(-7,-10,12,PRISMARINE)
B(-7,-10,13,PRISMARINE)
B(-7,-10,14,PRISMARINE)
B(-7,-10,15,PRISMARINE)
B(-7,-10,16,PRISMARINE)
B(-7,-10,17,PRISMARINE)
B(-7,-10,18,PRISMARINE)
B(-7,-10,19,PRISMARINE)
B(-7,-9,-1,PRISMARINE)
B(-7,-9,0,PRISMARINE)
B(-7,-9,1,PRISMARINE)
B(-7,-9,2,PRISMARINE)
B(-7,-9,3,PRISMARINE)
B(-7,-9,4,PRISMARINE)
B(-7,-9,5,PRISMARINE)
B(-7,-9,6,PRISMARINE)
B(-7,-9,7,PRISMARINE)
B(-7,-9,8,PRISMARINE)
B(-7,-9,9,PRISMARINE)
B(-7,-9,10,PRISMARINE)
B(-7,-9,11,PRISMARINE)
B(-7,-9,12,PRISMARINE)
B(-7,-9,13,PRISMARINE)
B(-7,-9,14,PRISMARINE)
B(-7,-9,15,PRISMARINE)
B(-7,-9,16,PRISMARINE)
B(-7,-9,17,PRISMARINE)
B(-7,-9,18,PRISMARINE)
B(-7,-9,19,PRISMARINE)
B(-7,-8,-1,PRISMARINE)
B(-7,-8,0,PRISMARINE)
B(-7,-8,1,PRISMARINE)
B(-7,-8,2,PRISMARINE)
B(-7,-8,3,PRISMARINE)
B(-7,-8,4,PRISMARINE)
B(-7,-8,5,PRISMARINE)
B(-7,-8,6,PRISMARINE)
B(-7,-8,7,SAND:1)
B(-7,-8,8,SAND:1)
B(-7,-8,9,SAND:1)
B(-7,-8,10,PRISMARINE)
B(-7,-8,11,PRISMARINE)
B(-7,-8,12,PRISMARINE)
B(-7,-8,13,PRISMARINE)
B(-7,-8,14,PRISMARINE)
B(-7,-8,15,PRISMARINE)
B(-7,-8,16,PRISMARINE)
B(-7,-8,17,PRISMARINE)
B(-7,-8,18,PRISMARINE)
B(-7,-8,19,PRISMARINE)
B(-7,-7,-1,PRISMARINE)
B(-7,-7,0,PRISMARINE)
B(-7,-7,1,PRISMARINE)
B(-7,-7,2,PRISMARINE)
B(-7,-7,3,PRISMARINE)
B(-7,-7,4,PRISMARINE)
B(-7,-7,5,PRISMARINE)
B(-7,-7,6,PRISMARINE)
B(-7,-7,7,SAND:1)
B(-7,-7,8,SAND:1)
B(-7,-7,9,PRISMARINE)
B(-7,-7,10,PRISMARINE)
B(-7,-7,11,PRISMARINE)
B(-7,-7,12,PRISMARINE)
B(-7,-7,13,PRISMARINE)
B(-7,-7,14,PRISMARINE)
B(-7,-7,15,PRISMARINE)
B(-7,-7,16,PRISMARINE)
B(-7,-7,17,PRISMARINE)
B(-7,-7,18,PRISMARINE)
B(-7,-7,19,PRISMARINE)
B(-7,-7,20,PRISMARINE)
B(-7,-6,-2,PRISMARINE)
B(-7,-6,-1,PRISMARINE)
B(-7,-6,0,PRISMARINE)
B(-7,-6,1,PRISMARINE)
B(-7,-6,2,PRISMARINE)
B(-7,-6,3,PRISMARINE)
B(-7,-6,4,PRISMARINE)
B(-7,-6,5,PRISMARINE)
B(-7,-6,6,PRISMARINE)
B(-7,-6,7,PRISMARINE)
B(-7,-6,8,PRISMARINE)
B(-7,-6,9,PRISMARINE)
B(-7,-6,10,PRISMARINE)
B(-7,-6,11,PRISMARINE)
B(-7,-6,12,PRISMARINE)
B(-7,-6,13,PRISMARINE)
B(-7,-6,14,PRISMARINE)
B(-7,-6,15,PRISMARINE)
B(-7,-6,16,PRISMARINE)
B(-7,-6,17,PRISMARINE)
B(-7,-6,18,PRISMARINE)
B(-7,-6,19,PRISMARINE)
B(-7,-6,20,PRISMARINE)
B(-7,-5,-3,PRISMARINE)
B(-7,-5,-2,PRISMARINE)
B(-7,-5,-1,PRISMARINE)
B(-7,-5,0,PRISMARINE)
B(-7,-5,1,PRISMARINE)
B(-7,-5,2,PRISMARINE)
B(-7,-5,3,PRISMARINE)
B(-7,-5,4,PRISMARINE)
B(-7,-5,5,PRISMARINE)
B(-7,-5,6,PRISMARINE)
B(-7,-5,7,PRISMARINE)
B(-7,-5,8,PRISMARINE)
B(-7,-5,9,PRISMARINE)
B(-7,-5,10,PRISMARINE)
B(-7,-5,11,PRISMARINE)
B(-7,-5,12,PRISMARINE)
B(-7,-5,13,PRISMARINE)
B(-7,-5,14,PRISMARINE)
B(-7,-5,15,PRISMARINE)
B(-7,-5,16,PRISMARINE)
B(-7,-5,17,PRISMARINE)
B(-7,-5,18,PRISMARINE)
B(-7,-5,19,PRISMARINE)
B(-7,-5,20,PRISMARINE)
B(-7,-4,-4,PRISMARINE)
B(-7,-4,-3,PRISMARINE)
B(-7,-4,-2,PRISMARINE)
B(-7,-4,-1,PRISMARINE)
B(-7,-4,0,PRISMARINE)
B(-7,-4,1,PRISMARINE)
B(-7,-4,2,PRISMARINE)
B(-7,-4,3,PRISMARINE)
B(-7,-4,4,PRISMARINE)
B(-7,-4,5,PRISMARINE)
B(-7,-4,6,PRISMARINE)
B(-7,-4,7,PRISMARINE)
B(-7,-4,8,PRISMARINE)
B(-7,-4,9,PRISMARINE)
B(-7,-4,10,PRISMARINE)
B(-7,-4,11,PRISMARINE)
B(-7,-4,12,PRISMARINE)
B(-7,-4,13,PRISMARINE)
B(-7,-4,14,PRISMARINE)
B(-7,-4,15,PRISMARINE)
B(-7,-4,16,PRISMARINE)
B(-7,-4,17,PRISMARINE)
B(-7,-4,18,PRISMARINE)
B(-7,-4,19,PRISMARINE)
B(-7,-4,20,PRISMARINE)
B(-7,-3,-4,PRISMARINE)
B(-7,-3,-3,PRISMARINE)
B(-7,-3,-2,PRISMARINE)
B(-7,-3,-1,PRISMARINE)
B(-7,-3,0,PRISMARINE)
B(-7,-3,1,PRISMARINE)
B(-7,-3,2,PRISMARINE)
B(-7,-3,3,PRISMARINE)
B(-7,-3,4,PRISMARINE)
B(-7,-3,5,PRISMARINE)
B(-7,-3,6,PRISMARINE)
B(-7,-3,7,PRISMARINE)
B(-7,-3,8,PRISMARINE)
B(-7,-3,9,PRISMARINE)
B(-7,-3,10,PRISMARINE)
B(-7,-3,11,PRISMARINE)
B(-7,-3,12,PRISMARINE)
B(-7,-3,13,PRISMARINE)
B(-7,-3,14,PRISMARINE)
B(-7,-3,15,PRISMARINE)
B(-7,-3,16,PRISMARINE)
B(-7,-3,17,PRISMARINE)
B(-7,-3,18,PRISMARINE)
B(-7,-3,19,PRISMARINE)
B(-7,-3,20,PRISMARINE)
B(-7,-2,-4,PRISMARINE)
B(-7,-2,-3,PRISMARINE)
B(-7,-2,-2,PRISMARINE)
B(-7,-2,-1,PRISMARINE)
B(-7,-2,0,PRISMARINE)
B(-7,-2,1,PRISMARINE)
B(-7,-2,2,PRISMARINE)
B(-7,-2,3,PRISMARINE)
B(-7,-2,4,PRISMARINE)
B(-7,-2,5,PRISMARINE)
B(-7,-2,6,PRISMARINE)
B(-7,-2,7,PRISMARINE)
B(-7,-2,8,PRISMARINE)
B(-7,-2,9,PRISMARINE)
B(-7,-2,10,PRISMARINE)
B(-7,-2,11,PRISMARINE)
B(-7,-2,12,PRISMARINE)
B(-7,-2,13,PRISMARINE)
B(-7,-2,14,PRISMARINE)
B(-7,-2,15,PRISMARINE)
B(-7,-2,16,PRISMARINE)
B(-7,-2,17,PRISMARINE)
B(-7,-2,18,PRISMARINE)
B(-7,-2,19,PRISMARINE)
B(-7,-2,20,PRISMARINE)
B(-7,-1,-2,PRISMARINE)
B(-7,-1,-1,PRISMARINE)
B(-7,-1,0,PRISMARINE)
B(-7,-1,1,PRISMARINE)
B(-7,-1,2,PRISMARINE)
B(-7,-1,3,PRISMARINE)
B(-7,-1,4,PRISMARINE)
B(-7,-1,5,PRISMARINE)
B(-7,-1,6,PRISMARINE)
B(-7,-1,7,PRISMARINE)
B(-7,-1,8,PRISMARINE)
B(-7,-1,9,PRISMARINE)
B(-7,-1,10,PRISMARINE)
B(-7,-1,11,PRISMARINE)
B(-7,-1,12,PRISMARINE)
B(-7,-1,13,PRISMARINE)
B(-7,-1,14,PRISMARINE)
B(-7,-1,15,PRISMARINE)
B(-7,-1,16,PRISMARINE)
B(-7,-1,17,PRISMARINE)
B(-7,-1,18,PRISMARINE)
B(-7,-1,19,PRISMARINE)
B(-7,-1,20,PRISMARINE)
B(-7,0,1,PRISMARINE)
B(-7,0,2,PRISMARINE)
B(-7,0,3,PRISMARINE)
B(-7,0,4,PRISMARINE)
B(-7,0,5,PRISMARINE)
B(-7,0,6,PRISMARINE)
B(-7,0,7,PRISMARINE)
B(-7,0,8,PRISMARINE)
B(-7,0,9,PRISMARINE)
B(-7,0,10,PRISMARINE)
B(-7,0,11,PRISMARINE)
B(-7,0,12,PRISMARINE)
B(-7,0,13,PRISMARINE)
B(-7,0,14,PRISMARINE)
B(-7,0,15,PRISMARINE)
B(-7,0,16,PRISMARINE)
B(-7,0,17,PRISMARINE)
B(-7,0,18,PRISMARINE)
B(-7,0,19,PRISMARINE)
B(-7,0,20,PRISMARINE)
B(-7,1,2,PRISMARINE)
B(-7,1,3,PRISMARINE)
B(-7,1,4,PRISMARINE)
B(-7,1,5,PRISMARINE)
B(-7,1,6,PRISMARINE)
B(-7,1,7,PRISMARINE)
B(-7,1,8,PRISMARINE)
B(-7,1,9,PRISMARINE)
B(-7,1,10,PRISMARINE)
B(-7,1,11,PRISMARINE)
B(-7,1,12,PRISMARINE)
B(-7,1,13,PRISMARINE)
B(-7,1,14,PRISMARINE)
B(-7,1,15,PRISMARINE)
B(-7,1,16,PRISMARINE)
B(-7,1,17,PRISMARINE)
B(-7,1,18,PRISMARINE)
B(-7,1,19,PRISMARINE)
B(-7,2,3,PRISMARINE)
B(-7,2,5,PRISMARINE)
B(-7,2,6,PRISMARINE)
B(-7,2,7,PRISMARINE)
B(-7,2,8,PRISMARINE)
B(-7,2,9,PRISMARINE)
B(-7,2,10,PRISMARINE)
B(-7,2,11,PRISMARINE)
B(-7,2,12,PRISMARINE)
B(-7,2,13,PRISMARINE)
B(-7,2,14,PRISMARINE)
B(-7,2,15,PRISMARINE)
B(-7,2,16,PRISMARINE)
B(-7,2,17,PRISMARINE)
B(-7,2,18,PRISMARINE)
B(-7,3,3,SPONGE:1)
B(-7,3,6,PRISMARINE)
B(-7,3,7,PRISMARINE)
B(-7,3,8,PRISMARINE)
B(-7,3,9,PRISMARINE)
B(-7,3,10,PRISMARINE)
B(-7,3,11,PRISMARINE)
B(-7,3,12,PRISMARINE)
B(-7,3,13,PRISMARINE)
B(-7,3,14,PRISMARINE)
B(-7,3,15,PRISMARINE)
B(-7,3,16,PRISMARINE)
B(-7,3,17,PRISMARINE)
B(-7,3,18,PRISMARINE)
B(-7,4,7,PRISMARINE)
B(-7,4,8,PRISMARINE)
B(-7,4,9,PRISMARINE)
B(-7,4,10,PRISMARINE)
B(-7,4,14,PRISMARINE)
B(-7,4,15,PRISMARINE)
B(-7,5,7,PRISMARINE)
B(-7,5,9,PRISMARINE)
B(-7,5,14,PRISMARINE)
B(-7,6,14,PRISMARINE)
B(-7,7,14,PRISMARINE)
B(-6,-21,14,PRISMARINE)
B(-6,-21,15,PRISMARINE)
B(-6,-20,13,PRISMARINE)
B(-6,-20,14,PRISMARINE)
B(-6,-20,15,PRISMARINE)
B(-6,-19,9,PRISMARINE)
B(-6,-19,10,PRISMARINE)
B(-6,-19,11,PRISMARINE)
B(-6,-19,12,PRISMARINE)
B(-6,-19,13,PRISMARINE)
B(-6,-19,14,PRISMARINE)
B(-6,-19,15,PRISMARINE)
B(-6,-18,3,PRISMARINE)
B(-6,-18,7,PRISMARINE)
B(-6,-18,8,PRISMARINE)
B(-6,-18,9,PRISMARINE)
B(-6,-18,10,PRISMARINE)
B(-6,-18,11,PRISMARINE)
B(-6,-18,12,PRISMARINE)
B(-6,-18,13,PRISMARINE)
B(-6,-18,14,PRISMARINE)
B(-6,-18,15,PRISMARINE)
B(-6,-18,16,PRISMARINE)
B(-6,-18,17,PRISMARINE)
B(-6,-17,2,PRISMARINE)
B(-6,-17,3,PRISMARINE)
B(-6,-17,4,PRISMARINE)
B(-6,-17,5,PRISMARINE)
B(-6,-17,6,PRISMARINE)
B(-6,-17,7,PRISMARINE)
B(-6,-17,8,PRISMARINE)
B(-6,-17,9,PRISMARINE)
B(-6,-17,10,PRISMARINE)
B(-6,-17,11,PRISMARINE)
B(-6,-17,12,SAND)
B(-6,-17,13,SAND)
B(-6,-17,14,SAND)
B(-6,-17,15,SAND)
B(-6,-17,16,PRISMARINE)
B(-6,-17,17,PRISMARINE)
B(-6,-17,18,PRISMARINE)
B(-6,-16,2,PRISMARINE)
B(-6,-16,3,PRISMARINE)
B(-6,-16,4,PRISMARINE)
B(-6,-16,5,PRISMARINE)
B(-6,-16,6,PRISMARINE)
B(-6,-16,7,PRISMARINE)
B(-6,-16,8,PRISMARINE)
B(-6,-16,9,SAND)
B(-6,-16,10,SAND:1)
B(-6,-16,11,SAND:1)
B(-6,-16,12,SAND:1)
B(-6,-16,13,SAND:1)
B(-6,-16,14,SAND:1)
B(-6,-16,15,SAND:1)
B(-6,-16,16,SAND:1)
B(-6,-16,17,SAND:1)
B(-6,-16,18,PRISMARINE)
B(-6,-15,1,PRISMARINE)
B(-6,-15,2,PRISMARINE)
B(-6,-15,3,PRISMARINE)
B(-6,-15,4,PRISMARINE)
B(-6,-15,5,PRISMARINE)
B(-6,-15,6,PRISMARINE)
B(-6,-15,7,SAND:1)
B(-6,-15,8,PRISMARINE)
B(-6,-15,9,SAND:1)
B(-6,-15,10,SAND:1)
B(-6,-15,11,SAND:1)
B(-6,-15,12,SAND:1)
B(-6,-15,13,SAND:1)
B(-6,-15,14,SAND:1)
B(-6,-15,15,SAND:1)
B(-6,-15,16,SAND:1)
B(-6,-15,17,PRISMARINE)
B(-6,-15,18,PRISMARINE)
B(-6,-14,0,PRISMARINE)
B(-6,-14,1,PRISMARINE)
B(-6,-14,2,PRISMARINE)
B(-6,-14,3,PRISMARINE)
B(-6,-14,4,PRISMARINE)
B(-6,-14,5,PRISMARINE)
B(-6,-14,6,PRISMARINE)
B(-6,-14,7,SAND:1)
B(-6,-14,8,SAND:1)
B(-6,-14,9,SAND:1)
B(-6,-14,10,SAND:1)
B(-6,-14,11,SAND:1)
B(-6,-14,12,SAND:1)
B(-6,-14,13,SAND:1)
B(-6,-14,14,SAND:1)
B(-6,-14,15,SAND:1)
B(-6,-14,16,SAND:1)
B(-6,-14,17,PRISMARINE)
B(-6,-14,18,PRISMARINE)
B(-6,-13,0,PRISMARINE)
B(-6,-13,1,PRISMARINE)
B(-6,-13,2,PRISMARINE)
B(-6,-13,3,PRISMARINE)
B(-6,-13,4,PRISMARINE)
B(-6,-13,5,PRISMARINE)
B(-6,-13,6,PRISMARINE)
B(-6,-13,7,SAND:1)
B(-6,-13,8,SAND:1)
B(-6,-13,9,SAND:1)
B(-6,-13,10,SAND:1)
B(-6,-13,11,SAND:1)
B(-6,-13,12,SAND:1)
B(-6,-13,13,SAND:1)
B(-6,-13,14,SAND:1)
B(-6,-13,15,SAND:1)
B(-6,-13,16,PRISMARINE)
B(-6,-13,17,PRISMARINE)
B(-6,-13,18,PRISMARINE)
B(-6,-12,0,PRISMARINE)
B(-6,-12,1,PRISMARINE)
B(-6,-12,2,PRISMARINE)
B(-6,-12,3,PRISMARINE)
B(-6,-12,4,PRISMARINE)
B(-6,-12,5,PRISMARINE)
B(-6,-12,6,PRISMARINE)
B(-6,-12,7,SAND:1)
B(-6,-12,8,SAND:1)
B(-6,-12,9,SAND:1)
B(-6,-12,10,PRISMARINE)
B(-6,-12,11,SAND:1)
B(-6,-12,12,SAND:1)
B(-6,-12,13,SAND:1)
B(-6,-12,14,SAND:1)
B(-6,-12,15,PRISMARINE)
B(-6,-12,16,PRISMARINE)
B(-6,-12,17,PRISMARINE)
B(-6,-12,18,PRISMARINE)
B(-6,-12,19,PRISMARINE)
B(-6,-11,0,PRISMARINE)
B(-6,-11,1,PRISMARINE)
B(-6,-11,2,PRISMARINE)
B(-6,-11,3,PRISMARINE)
B(-6,-11,4,PRISMARINE)
B(-6,-11,5,PRISMARINE)
B(-6,-11,6,PRISMARINE)
B(-6,-11,7,PRISMARINE)
B(-6,-11,8,PRISMARINE)
B(-6,-11,9,PRISMARINE)
B(-6,-11,10,PRISMARINE)
B(-6,-11,11,SAND:1)
B(-6,-11,12,SAND:1)
B(-6,-11,13,PRISMARINE)
B(-6,-11,14,PRISMARINE)
B(-6,-11,15,PRISMARINE)
B(-6,-11,16,PRISMARINE)
B(-6,-11,17,PRISMARINE)
B(-6,-11,18,PRISMARINE)
B(-6,-11,19,PRISMARINE)
B(-6,-11,20,PRISMARINE)
B(-6,-10,-1,PRISMARINE)
B(-6,-10,0,PRISMARINE)
B(-6,-10,1,PRISMARINE)
B(-6,-10,2,PRISMARINE)
B(-6,-10,3,PRISMARINE)
B(-6,-10,4,PRISMARINE)
B(-6,-10,5,PRISMARINE)
B(-6,-10,6,PRISMARINE)
B(-6,-10,7,PRISMARINE)
B(-6,-10,8,PRISMARINE:1)
B(-6,-10,9,PRISMARINE)
B(-6,-10,10,PRISMARINE)
B(-6,-10,11,PRISMARINE)
B(-6,-10,12,PRISMARINE)
B(-6,-10,13,PRISMARINE)
B(-6,-10,14,PRISMARINE)
B(-6,-10,15,PRISMARINE)
B(-6,-10,16,PRISMARINE)
B(-6,-10,17,PRISMARINE)
B(-6,-10,18,PRISMARINE)
B(-6,-10,19,PRISMARINE)
B(-6,-10,20,PRISMARINE)
B(-6,-9,-1,PRISMARINE)
B(-6,-9,0,PRISMARINE)
B(-6,-9,1,PRISMARINE)
B(-6,-9,2,PRISMARINE)
B(-6,-9,3,PRISMARINE)
B(-6,-9,4,PRISMARINE)
B(-6,-9,5,PRISMARINE)
B(-6,-9,6,PRISMARINE)
B(-6,-9,7,PRISMARINE)
B(-6,-9,8,SAND:1)
B(-6,-9,9,PRISMARINE)
B(-6,-9,10,PRISMARINE)
B(-6,-9,11,PRISMARINE)
B(-6,-9,12,PRISMARINE)
B(-6,-9,13,PRISMARINE)
B(-6,-9,14,PRISMARINE)
B(-6,-9,15,PRISMARINE)
B(-6,-9,16,PRISMARINE)
B(-6,-9,17,PRISMARINE)
B(-6,-9,18,PRISMARINE)
B(-6,-9,19,PRISMARINE)
B(-6,-9,20,PRISMARINE)
B(-6,-8,-1,PRISMARINE)
B(-6,-8,0,PRISMARINE)
B(-6,-8,1,PRISMARINE)
B(-6,-8,2,PRISMARINE)
B(-6,-8,3,PRISMARINE)
B(-6,-8,4,PRISMARINE)
B(-6,-8,5,PRISMARINE)
B(-6,-8,6,PRISMARINE)
B(-6,-8,7,SAND:1)
B(-6,-8,8,SAND:1)
B(-6,-8,9,SAND:1)
B(-6,-8,10,SAND:1)
B(-6,-8,11,SAND:1)
B(-6,-8,12,PRISMARINE)
B(-6,-8,13,PRISMARINE)
B(-6,-8,14,PRISMARINE)
B(-6,-8,15,PRISMARINE)
B(-6,-8,16,PRISMARINE)
B(-6,-8,17,PRISMARINE)
B(-6,-8,18,PRISMARINE)
B(-6,-8,19,PRISMARINE)
B(-6,-8,20,PRISMARINE)
B(-6,-7,-2,PRISMARINE)
B(-6,-7,-1,PRISMARINE)
B(-6,-7,0,PRISMARINE)
B(-6,-7,1,PRISMARINE)
B(-6,-7,2,PRISMARINE)
B(-6,-7,3,PRISMARINE)
B(-6,-7,4,PRISMARINE)
B(-6,-7,5,PRISMARINE)
B(-6,-7,6,PRISMARINE)
B(-6,-7,7,SAND:1)
B(-6,-7,8,SAND:1)
B(-6,-7,9,SAND:1)
B(-6,-7,10,SAND:1)
B(-6,-7,11,PRISMARINE)
B(-6,-7,12,PRISMARINE)
B(-6,-7,13,PRISMARINE)
B(-6,-7,14,PRISMARINE)
B(-6,-7,15,PRISMARINE)
B(-6,-7,16,PRISMARINE)
B(-6,-7,17,PRISMARINE)
B(-6,-7,18,PRISMARINE)
B(-6,-7,19,PRISMARINE)
B(-6,-7,20,PRISMARINE)
B(-6,-7,21,PRISMARINE)
B(-6,-6,-2,PRISMARINE)
B(-6,-6,-1,PRISMARINE)
B(-6,-6,0,PRISMARINE)
B(-6,-6,1,PRISMARINE)
B(-6,-6,2,PRISMARINE)
B(-6,-6,3,PRISMARINE)
B(-6,-6,4,PRISMARINE)
B(-6,-6,5,PRISMARINE)
B(-6,-6,6,PRISMARINE)
B(-6,-6,7,SAND:1)
B(-6,-6,8,SAND:1)
B(-6,-6,9,SAND:1)
B(-6,-6,10,PRISMARINE)
B(-6,-6,11,PRISMARINE)
B(-6,-6,12,PRISMARINE)
B(-6,-6,13,PRISMARINE)
B(-6,-6,14,PRISMARINE)
B(-6,-6,15,PRISMARINE)
B(-6,-6,16,PRISMARINE)
B(-6,-6,17,PRISMARINE)
B(-6,-6,18,PRISMARINE)
B(-6,-6,19,PRISMARINE)
B(-6,-6,20,PRISMARINE)
B(-6,-6,21,PRISMARINE)
B(-6,-5,-3,PRISMARINE)
B(-6,-5,-2,PRISMARINE)
B(-6,-5,-1,PRISMARINE)
B(-6,-5,0,PRISMARINE)
B(-6,-5,1,PRISMARINE)
B(-6,-5,2,PRISMARINE)
B(-6,-5,3,PRISMARINE)
B(-6,-5,4,PRISMARINE)
B(-6,-5,5,PRISMARINE)
B(-6,-5,6,PRISMARINE)
B(-6,-5,7,PRISMARINE)
B(-6,-5,8,PRISMARINE)
B(-6,-5,9,PRISMARINE)
B(-6,-5,10,PRISMARINE)
B(-6,-5,11,PRISMARINE)
B(-6,-5,12,PRISMARINE)
B(-6,-5,13,PRISMARINE)
B(-6,-5,14,PRISMARINE)
B(-6,-5,15,PRISMARINE)
B(-6,-5,16,PRISMARINE)
B(-6,-5,17,PRISMARINE)
B(-6,-5,18,PRISMARINE)
B(-6,-5,19,PRISMARINE)
B(-6,-5,20,PRISMARINE)
B(-6,-5,21,PRISMARINE)
B(-6,-4,-4,PRISMARINE)
B(-6,-4,-3,PRISMARINE)
B(-6,-4,-2,PRISMARINE)
B(-6,-4,-1,PRISMARINE)
B(-6,-4,0,PRISMARINE)
B(-6,-4,1,PRISMARINE)
B(-6,-4,2,PRISMARINE)
B(-6,-4,3,PRISMARINE)
B(-6,-4,4,PRISMARINE)
B(-6,-4,5,PRISMARINE)
B(-6,-4,6,SAND:1)
B(-6,-4,7,SAND:1)
B(-6,-4,8,SAND:1)
B(-6,-4,9,PRISMARINE)
B(-6,-4,10,PRISMARINE)
B(-6,-4,11,PRISMARINE)
B(-6,-4,12,PRISMARINE)
B(-6,-4,13,PRISMARINE)
B(-6,-4,14,PRISMARINE)
B(-6,-4,15,PRISMARINE)
B(-6,-4,16,PRISMARINE)
B(-6,-4,17,PRISMARINE)
B(-6,-4,18,PRISMARINE)
B(-6,-4,19,PRISMARINE)
B(-6,-4,20,PRISMARINE)
B(-6,-3,-4,PRISMARINE)
B(-6,-3,-3,PRISMARINE)
B(-6,-3,-2,SAND:1)
B(-6,-3,-1,PRISMARINE)
B(-6,-3,0,PRISMARINE)
B(-6,-3,1,PRISMARINE)
B(-6,-3,2,PRISMARINE)
B(-6,-3,3,PRISMARINE)
B(-6,-3,4,PRISMARINE)
B(-6,-3,5,PRISMARINE)
B(-6,-3,6,SAND:1)
B(-6,-3,7,SAND:1)
B(-6,-3,8,SAND:1)
B(-6,-3,9,SAND:1)
B(-6,-3,10,SAND:1)
B(-6,-3,11,SAND:1)
B(-6,-3,12,PRISMARINE)
B(-6,-3,13,PRISMARINE)
B(-6,-3,14,PRISMARINE)
B(-6,-3,15,PRISMARINE)
B(-6,-3,16,PRISMARINE)
B(-6,-3,17,PRISMARINE)
B(-6,-3,18,PRISMARINE)
B(-6,-3,19,PRISMARINE)
B(-6,-3,20,PRISMARINE)
B(-6,-3,21,PRISMARINE)
B(-6,-2,-4,PRISMARINE)
B(-6,-2,-3,SAND:1)
B(-6,-2,-2,SAND:1)
B(-6,-2,-1,SAND:1)
B(-6,-2,0,SAND:1)
B(-6,-2,1,PRISMARINE)
B(-6,-2,2,PRISMARINE)
B(-6,-2,3,PRISMARINE)
B(-6,-2,4,PRISMARINE)
B(-6,-2,5,PRISMARINE)
B(-6,-2,6,PRISMARINE)
B(-6,-2,7,SAND:1)
B(-6,-2,8,SAND:1)
B(-6,-2,9,PRISMARINE)
B(-6,-2,10,SAND:1)
B(-6,-2,11,PRISMARINE)
B(-6,-2,12,PRISMARINE)
B(-6,-2,13,PRISMARINE)
B(-6,-2,14,PRISMARINE)
B(-6,-2,15,PRISMARINE)
B(-6,-2,16,PRISMARINE)
B(-6,-2,17,PRISMARINE)
B(-6,-2,18,PRISMARINE)
B(-6,-2,19,PRISMARINE)
B(-6,-2,20,PRISMARINE)
B(-6,-1,-4,PRISMARINE)
B(-6,-1,-3,PRISMARINE)
B(-6,-1,-2,SAND:1)
B(-6,-1,-1,SAND:1)
B(-6,-1,0,SAND:1)
B(-6,-1,1,SAND:1)
B(-6,-1,2,PRISMARINE)
B(-6,-1,3,PRISMARINE)
B(-6,-1,4,PRISMARINE)
B(-6,-1,5,PRISMARINE)
B(-6,-1,6,PRISMARINE)
B(-6,-1,7,PRISMARINE)
B(-6,-1,8,PRISMARINE)
B(-6,-1,9,PRISMARINE)
B(-6,-1,10,PRISMARINE)
B(-6,-1,11,PRISMARINE)
B(-6,-1,12,PRISMARINE)
B(-6,-1,13,PRISMARINE)
B(-6,-1,14,PRISMARINE)
B(-6,-1,15,PRISMARINE)
B(-6,-1,16,PRISMARINE)
B(-6,-1,17,PRISMARINE)
B(-6,-1,18,PRISMARINE)
B(-6,-1,19,PRISMARINE)
B(-6,-1,20,PRISMARINE)
B(-6,0,-2,PRISMARINE)
B(-6,0,-1,PRISMARINE)
B(-6,0,0,PRISMARINE)
B(-6,0,1,PRISMARINE)
B(-6,0,2,PRISMARINE)
B(-6,0,3,PRISMARINE)
B(-6,0,4,PRISMARINE)
B(-6,0,5,PRISMARINE)
B(-6,0,6,PRISMARINE)
B(-6,0,7,PRISMARINE)
B(-6,0,8,PRISMARINE)
B(-6,0,9,PRISMARINE)
B(-6,0,10,PRISMARINE)
B(-6,0,11,PRISMARINE)
B(-6,0,12,PRISMARINE)
B(-6,0,13,PRISMARINE)
B(-6,0,14,PRISMARINE)
B(-6,0,15,PRISMARINE)
B(-6,0,16,PRISMARINE)
B(-6,0,17,PRISMARINE)
B(-6,0,18,PRISMARINE)
B(-6,0,19,PRISMARINE)
B(-6,0,20,PRISMARINE)
B(-6,1,1,PRISMARINE)
B(-6,1,2,PRISMARINE)
B(-6,1,3,PRISMARINE)
B(-6,1,4,PRISMARINE)
B(-6,1,5,PRISMARINE)
B(-6,1,6,PRISMARINE)
B(-6,1,7,PRISMARINE)
B(-6,1,8,PRISMARINE)
B(-6,1,9,PRISMARINE)
B(-6,1,10,PRISMARINE)
B(-6,1,11,PRISMARINE)
B(-6,1,12,PRISMARINE)
B(-6,1,13,PRISMARINE)
B(-6,1,14,PRISMARINE)
B(-6,1,15,PRISMARINE)
B(-6,1,16,PRISMARINE)
B(-6,1,17,PRISMARINE)
B(-6,1,18,PRISMARINE)
B(-6,1,19,PRISMARINE)
B(-6,1,20,PRISMARINE)
B(-6,2,1,PRISMARINE)
B(-6,2,2,PRISMARINE)
B(-6,2,3,PRISMARINE)
B(-6,2,4,PRISMARINE)
B(-6,2,5,PRISMARINE)
B(-6,2,6,PRISMARINE)
B(-6,2,7,PRISMARINE)
B(-6,2,8,PRISMARINE)
B(-6,2,9,PRISMARINE)
B(-6,2,10,PRISMARINE)
B(-6,2,11,PRISMARINE)
B(-6,2,12,PRISMARINE)
B(-6,2,13,PRISMARINE)
B(-6,2,14,PRISMARINE)
B(-6,2,15,PRISMARINE)
B(-6,2,16,PRISMARINE)
B(-6,2,17,PRISMARINE)
B(-6,2,18,PRISMARINE)
B(-6,2,19,PRISMARINE)
B(-6,3,2,PRISMARINE)
B(-6,3,3,PRISMARINE)
B(-6,3,4,PRISMARINE)
B(-6,3,5,PRISMARINE)
B(-6,3,6,PRISMARINE)
B(-6,3,7,PRISMARINE)
B(-6,3,8,PRISMARINE)
B(-6,3,9,PRISMARINE)
B(-6,3,10,PRISMARINE)
B(-6,3,11,PRISMARINE)
B(-6,3,12,PRISMARINE)
B(-6,3,13,PRISMARINE)
B(-6,3,14,PRISMARINE)
B(-6,3,15,PRISMARINE)
B(-6,3,16,PRISMARINE)
B(-6,3,17,PRISMARINE)
B(-6,3,18,PRISMARINE)
B(-6,4,2,PRISMARINE)
B(-6,4,4,PRISMARINE)
B(-6,4,5,PRISMARINE)
B(-6,4,6,PRISMARINE)
B(-6,4,7,PRISMARINE)
B(-6,4,8,PRISMARINE)
B(-6,4,9,PRISMARINE)
B(-6,4,10,PRISMARINE)
B(-6,4,11,PRISMARINE)
B(-6,4,12,PRISMARINE)
B(-6,4,13,PRISMARINE)
B(-6,4,18,PRISMARINE)
B(-6,5,6,PRISMARINE)
B(-6,5,7,PRISMARINE)
B(-6,5,8,PRISMARINE)
B(-6,5,9,PRISMARINE)
B(-6,5,10,PRISMARINE)
B(-6,5,11,PRISMARINE)
B(-6,5,18,PRISMARINE)
B(-6,6,7,PRISMARINE)
B(-6,6,8,PRISMARINE)
B(-6,6,9,PRISMARINE)
B(-6,6,10,PRISMARINE)
B(-6,7,7,PRISMARINE)
B(-6,7,8,PRISMARINE)
B(-6,7,9,PRISMARINE)
B(-6,8,7,SPONGE:1)
B(-6,8,8,PRISMARINE)
B(-6,8,9,PRISMARINE)
B(-6,9,8,PRISMARINE)
B(-5,-21,10,PRISMARINE)
B(-5,-21,12,PRISMARINE)
B(-5,-21,15,PRISMARINE)
B(-5,-20,10,PRISMARINE)
B(-5,-20,11,PRISMARINE)
B(-5,-20,12,PRISMARINE)
B(-5,-20,13,PRISMARINE)
B(-5,-20,14,PRISMARINE)
B(-5,-20,15,PRISMARINE)
B(-5,-19,8,PRISMARINE)
B(-5,-19,9,PRISMARINE)
B(-5,-19,10,PRISMARINE)
B(-5,-19,11,PRISMARINE)
B(-5,-19,12,PRISMARINE)
B(-5,-19,13,PRISMARINE)
B(-5,-19,14,PRISMARINE)
B(-5,-19,15,PRISMARINE)
B(-5,-19,16,PRISMARINE)
B(-5,-18,3,PRISMARINE)
B(-5,-18,4,PRISMARINE)
B(-5,-18,5,PRISMARINE)
B(-5,-18,6,PRISMARINE)
B(-5,-18,7,PRISMARINE)
B(-5,-18,8,PRISMARINE)
B(-5,-18,9,PRISMARINE)
B(-5,-18,10,PRISMARINE)
B(-5,-18,11,PRISMARINE)
B(-5,-18,12,PRISMARINE)
B(-5,-18,13,PRISMARINE)
B(-5,-18,14,PRISMARINE)
B(-5,-18,15,PRISMARINE)
B(-5,-18,16,PRISMARINE)
B(-5,-18,17,PRISMARINE)
B(-5,-17,2,PRISMARINE)
B(-5,-17,3,PRISMARINE)
B(-5,-17,4,PRISMARINE)
B(-5,-17,5,PRISMARINE)
B(-5,-17,6,PRISMARINE)
B(-5,-17,7,PRISMARINE)
B(-5,-17,8,PRISMARINE)
B(-5,-17,9,PRISMARINE)
B(-5,-17,10,PRISMARINE)
B(-5,-17,11,SAND)
B(-5,-17,12,SAND:1)
B(-5,-17,13,SAND:1)
B(-5,-17,14,SAND:1)
B(-5,-17,15,SAND)
B(-5,-17,16,SAND)
B(-5,-17,17,PRISMARINE)
B(-5,-17,18,PRISMARINE)
B(-5,-16,1,PRISMARINE)
B(-5,-16,2,PRISMARINE)
B(-5,-16,3,PRISMARINE)
B(-5,-16,4,PRISMARINE)
B(-5,-16,5,PRISMARINE)
B(-5,-16,6,SAND:1)
B(-5,-16,7,PRISMARINE)
B(-5,-16,8,PRISMARINE)
B(-5,-16,9,PRISMARINE)
B(-5,-16,10,SAND:1)
B(-5,-16,11,SAND:1)
B(-5,-16,12,BONE_BLOCK:0)
B(-5,-16,13,SAND:1)
B(-5,-16,14,BONE_BLOCK:0)
B(-5,-16,15,SAND:1)
B(-5,-16,16,BONE_BLOCK:0)
B(-5,-16,17,SAND:1)
B(-5,-16,18,PRISMARINE)
B(-5,-16,19,PRISMARINE)
B(-5,-15,1,PRISMARINE)
B(-5,-15,2,PRISMARINE)
B(-5,-15,3,PRISMARINE)
B(-5,-15,4,PRISMARINE)
B(-5,-15,5,SAND:1)
B(-5,-15,6,SAND:1)
B(-5,-15,7,SAND:1)
B(-5,-15,8,PRISMARINE)
B(-5,-15,9,SAND:1)
B(-5,-15,10,SAND:1)
B(-5,-15,11,SAND:1)
B(-5,-15,12,SAND:1)
B(-5,-15,13,SAND:1)
B(-5,-15,14,SAND:1)
B(-5,-15,15,SAND:1)
B(-5,-15,16,SAND:1)
B(-5,-15,17,SAND:1)
B(-5,-15,18,PRISMARINE)
B(-5,-15,19,PRISMARINE)
B(-5,-14,1,PRISMARINE)
B(-5,-14,2,PRISMARINE)
B(-5,-14,3,PRISMARINE)
B(-5,-14,4,PRISMARINE)
B(-5,-14,5,SAND:1)
B(-5,-14,6,SAND:1)
B(-5,-14,7,SAND:1)
B(-5,-14,8,PRISMARINE)
B(-5,-14,9,SAND:1)
B(-5,-14,10,SAND:1)
B(-5,-14,11,SAND:1)
B(-5,-14,12,SAND:1)
B(-5,-14,13,SAND:1)
B(-5,-14,14,SAND:1)
B(-5,-14,15,SAND:1)
B(-5,-14,16,SAND:1)
B(-5,-14,17,PRISMARINE)
B(-5,-14,18,PRISMARINE)
B(-5,-14,19,PRISMARINE)
B(-5,-13,-1,PRISMARINE)
B(-5,-13,0,PRISMARINE)
B(-5,-13,1,PRISMARINE)
B(-5,-13,2,PRISMARINE)
B(-5,-13,3,PRISMARINE)
B(-5,-13,4,PRISMARINE)
B(-5,-13,5,SAND:1)
B(-5,-13,6,SAND:1)
B(-5,-13,7,SAND:1)
RB(-5,-13,8,SEA_LANTERN,75,PRISMARINE,100)
B(-5,-13,9,SAND:1)
B(-5,-13,10,SAND:1)
B(-5,-13,11,SAND:1)
B(-5,-13,12,SAND:1)
B(-5,-13,13,SAND:1)
B(-5,-13,14,SAND:1)
B(-5,-13,15,SAND:1)
B(-5,-13,16,SAND:1)
B(-5,-13,17,PRISMARINE)
B(-5,-13,18,PRISMARINE)
B(-5,-13,19,PRISMARINE)
B(-5,-12,-1,PRISMARINE)
B(-5,-12,0,PRISMARINE)
B(-5,-12,1,PRISMARINE)
B(-5,-12,2,PRISMARINE)
B(-5,-12,3,PRISMARINE)
B(-5,-12,4,PRISMARINE)
B(-5,-12,5,PRISMARINE)
B(-5,-12,6,PRISMARINE)
B(-5,-12,7,SAND:1)
B(-5,-12,8,SAND:1)
B(-5,-12,9,SAND:1)
B(-5,-12,10,PRISMARINE)
B(-5,-12,11,PRISMARINE)
B(-5,-12,12,SAND:1)
B(-5,-12,13,SAND:1)
B(-5,-12,14,SAND:1)
B(-5,-12,15,SAND:1)
B(-5,-12,16,PRISMARINE)
B(-5,-12,17,PRISMARINE)
B(-5,-12,18,PRISMARINE)
B(-5,-12,19,PRISMARINE)
B(-5,-12,20,PRISMARINE)
B(-5,-11,-1,PRISMARINE)
B(-5,-11,0,PRISMARINE)
B(-5,-11,1,PRISMARINE)
B(-5,-11,2,PRISMARINE)
B(-5,-11,3,PRISMARINE)
B(-5,-11,4,PRISMARINE)
B(-5,-11,5,PRISMARINE)
B(-5,-11,6,PRISMARINE)
B(-5,-11,7,PRISMARINE)
B(-5,-11,8,PRISMARINE)
B(-5,-11,9,PRISMARINE)
B(-5,-11,10,PRISMARINE)
B(-5,-11,11,PRISMARINE)
B(-5,-11,12,SAND:1)
B(-5,-11,13,SAND:1)
B(-5,-11,14,PRISMARINE)
B(-5,-11,15,PRISMARINE)
B(-5,-11,16,PRISMARINE)
B(-5,-11,17,PRISMARINE)
B(-5,-11,18,PRISMARINE)
B(-5,-11,19,PRISMARINE)
B(-5,-11,20,PRISMARINE)
B(-5,-10,-2,PRISMARINE)
B(-5,-10,-1,PRISMARINE)
B(-5,-10,0,PRISMARINE)
B(-5,-10,1,PRISMARINE)
B(-5,-10,2,PRISMARINE)
B(-5,-10,3,PRISMARINE)
B(-5,-10,4,PRISMARINE)
B(-5,-10,5,PRISMARINE)
B(-5,-10,6,PRISMARINE)
B(-5,-10,7,PRISMARINE)
B(-5,-10,8,PRISMARINE:1)
B(-5,-10,9,PRISMARINE)
B(-5,-10,10,PRISMARINE)
B(-5,-10,11,PRISMARINE)
B(-5,-10,12,PRISMARINE)
B(-5,-10,13,PRISMARINE)
B(-5,-10,14,PRISMARINE)
B(-5,-10,15,PRISMARINE)
B(-5,-10,16,PRISMARINE)
B(-5,-10,17,PRISMARINE)
B(-5,-10,18,PRISMARINE)
B(-5,-10,19,PRISMARINE:1)
B(-5,-10,20,PRISMARINE)
B(-5,-10,21,PRISMARINE)
B(-5,-9,-2,PRISMARINE)
B(-5,-9,-1,PRISMARINE)
B(-5,-9,0,PRISMARINE)
B(-5,-9,1,PRISMARINE)
B(-5,-9,2,PRISMARINE)
B(-5,-9,3,PRISMARINE:1)
B(-5,-9,4,PRISMARINE:2)
B(-5,-9,5,SAND:1)
B(-5,-9,6,PRISMARINE)
B(-5,-9,7,PRISMARINE)
B(-5,-9,8,SAND:1)
B(-5,-9,9,SAND:1)
B(-5,-9,10,PRISMARINE)
B(-5,-9,11,PRISMARINE)
B(-5,-9,12,PRISMARINE:2)
B(-5,-9,13,PRISMARINE:1)
RB(-5,-9,14,CHEST,../../Structures/nbt/VanillaLoot/simple_dungeon.nbt,50,CHEST,../../Structures/nbt/VanillaLoot/desert_pyramid.nbt,100)
B(-5,-9,15,PRISMARINE:1)
B(-5,-9,16,SAND:1)
B(-5,-9,17,PRISMARINE:1)
B(-5,-9,18,PRISMARINE)
B(-5,-9,19,PRISMARINE:1)
B(-5,-9,20,PRISMARINE)
B(-5,-9,21,PRISMARINE)
B(-5,-8,-2,PRISMARINE)
B(-5,-8,-1,PRISMARINE)
B(-5,-8,0,PRISMARINE)
B(-5,-8,1,PRISMARINE)
B(-5,-8,2,PRISMARINE)
B(-5,-8,3,PRISMARINE:1)
B(-5,-8,4,PRISMARINE:2)
B(-5,-8,5,SAND:1)
B(-5,-8,6,SAND:1)
B(-5,-8,7,SAND:1)
B(-5,-8,8,SAND:1)
B(-5,-8,9,SAND:1)
B(-5,-8,10,SAND:1)
B(-5,-8,11,SAND:1)
B(-5,-8,12,PRISMARINE:2)
B(-5,-8,13,PRISMARINE:1)
B(-5,-8,14,SAND:1)
B(-5,-8,15,PRISMARINE:1)
B(-5,-8,16,SAND:1)
B(-5,-8,17,PRISMARINE:1)
B(-5,-8,18,PRISMARINE)
B(-5,-8,19,SPONGE:1)
B(-5,-8,20,PRISMARINE:1)
B(-5,-8,21,PRISMARINE)
B(-5,-7,-2,PRISMARINE)
B(-5,-7,-1,PRISMARINE)
B(-5,-7,0,PRISMARINE)
B(-5,-7,1,PRISMARINE)
B(-5,-7,2,PRISMARINE)
B(-5,-7,3,PRISMARINE:1)
B(-5,-7,4,PRISMARINE:2)
B(-5,-7,5,PRISMARINE:2)
B(-5,-7,6,SAND:1)
B(-5,-7,7,SAND:1)
B(-5,-7,8,SAND:1)
B(-5,-7,9,SAND:1)
B(-5,-7,10,SAND:1)
B(-5,-7,11,PRISMARINE:2)
B(-5,-7,12,PRISMARINE:2)
B(-5,-7,13,PRISMARINE:1)
B(-5,-7,14,SAND:1)
B(-5,-7,15,PRISMARINE:1)
B(-5,-7,16,SAND:1)
B(-5,-7,17,PRISMARINE:1)
B(-5,-7,18,SAND:1)
B(-5,-7,19,SAND:1)
B(-5,-7,20,SPONGE:1)
B(-5,-7,21,PRISMARINE:1)
B(-5,-6,-3,PRISMARINE)
B(-5,-6,-2,PRISMARINE)
B(-5,-6,-1,PRISMARINE)
B(-5,-6,0,PRISMARINE)
B(-5,-6,1,PRISMARINE)
B(-5,-6,2,PRISMARINE)
B(-5,-6,3,PRISMARINE:1)
B(-5,-6,4,PRISMARINE:2)
B(-5,-6,5,PRISMARINE:2)
B(-5,-6,6,PRISMARINE:2)
B(-5,-6,7,SAND:1)
B(-5,-6,8,SAND:1)
B(-5,-6,9,SAND:1)
B(-5,-6,10,PRISMARINE:2)
B(-5,-6,11,PRISMARINE:2)
B(-5,-6,12,PRISMARINE:2)
B(-5,-6,13,PRISMARINE:1)
B(-5,-6,14,SAND:1)
B(-5,-6,15,PRISMARINE:1)
B(-5,-6,16,SAND:1)
B(-5,-6,17,PRISMARINE:1)
B(-5,-6,18,SAND:1)
B(-5,-6,19,PRISMARINE)
B(-5,-6,20,SAND:1)
B(-5,-6,21,PRISMARINE)
B(-5,-5,-4,PRISMARINE)
B(-5,-5,-3,PRISMARINE)
B(-5,-5,-2,PRISMARINE)
B(-5,-5,-1,PRISMARINE)
B(-5,-5,0,PRISMARINE)
B(-5,-5,1,PRISMARINE)
B(-5,-5,2,PRISMARINE)
B(-5,-5,3,PRISMARINE:1)
B(-5,-5,4,PRISMARINE:2)
B(-5,-5,5,PRISMARINE:2)
B(-5,-5,6,PRISMARINE:2)
B(-5,-5,7,PRISMARINE:2)
B(-5,-5,8,PRISMARINE:2)
B(-5,-5,9,PRISMARINE:2)
B(-5,-5,10,PRISMARINE:2)
B(-5,-5,11,PRISMARINE:2)
B(-5,-5,12,PRISMARINE:2)
B(-5,-5,13,PRISMARINE:1)
B(-5,-5,14,SAND:1)
B(-5,-5,15,PRISMARINE:1)
B(-5,-5,16,SAND:1)
B(-5,-5,17,PRISMARINE:1)
B(-5,-5,18,SAND:1)
B(-5,-5,19,SAND:1)
B(-5,-5,20,SAND:1)
B(-5,-5,21,PRISMARINE:1)
B(-5,-4,-5,PRISMARINE)
B(-5,-4,-4,PRISMARINE)
B(-5,-4,-3,PRISMARINE:1)
B(-5,-4,-2,PRISMARINE:1)
B(-5,-4,-1,PRISMARINE:1)
B(-5,-4,0,PRISMARINE:1)
B(-5,-4,1,PRISMARINE:1)
B(-5,-4,2,PRISMARINE:1)
B(-5,-4,3,PRISMARINE:1)
B(-5,-4,4,PRISMARINE:1)
B(-5,-4,5,PRISMARINE:1)
B(-5,-4,6,SPONGE:1)
B(-5,-4,7,SAND:1)
B(-5,-4,8,SAND:1)
B(-5,-4,9,PRISMARINE:1)
B(-5,-4,10,PRISMARINE:1)
B(-5,-4,11,PRISMARINE:1)
B(-5,-4,12,PRISMARINE:1)
B(-5,-4,13,PRISMARINE:1)
B(-5,-4,14,SAND:1)
B(-5,-4,15,PRISMARINE:1)
B(-5,-4,16,SAND:1)
B(-5,-4,17,PRISMARINE:1)
B(-5,-4,18,SAND:1)
B(-5,-4,19,SAND:1)
B(-5,-4,20,PRISMARINE:1)
B(-5,-4,21,PRISMARINE)
B(-5,-3,-4,PRISMARINE)
B(-5,-3,-3,PRISMARINE:1)
B(-5,-3,-2,SAND:1)
B(-5,-3,-1,SAND:1)
B(-5,-3,0,SAND:1)
B(-5,-3,1,SAND:1)
B(-5,-3,2,SAND:1)
B(-5,-3,3,SAND:1)
B(-5,-3,4,SAND:1)
B(-5,-3,5,SAND:1)
B(-5,-3,6,SAND:1)
B(-5,-3,7,SAND:1)
B(-5,-3,8,SAND:1)
B(-5,-3,9,SPONGE:1)
B(-5,-3,10,SAND:1)
B(-5,-3,11,SAND:1)
B(-5,-3,12,SAND:1)
B(-5,-3,13,PRISMARINE:1)
B(-5,-3,14,PRISMARINE:1)
B(-5,-3,15,PRISMARINE:1)
B(-5,-3,16,PRISMARINE:1)
B(-5,-3,17,PRISMARINE:1)
B(-5,-3,18,PRISMARINE:1)
B(-5,-3,19,PRISMARINE:1)
B(-5,-3,20,PRISMARINE)
B(-5,-3,21,PRISMARINE)
B(-5,-2,-4,PRISMARINE)
B(-5,-2,-3,PRISMARINE:1)
B(-5,-2,-2,SAND:1)
B(-5,-2,-1,SAND:1)
B(-5,-2,0,SAND:1)
B(-5,-2,1,SAND:1)
B(-5,-2,2,SAND:1)
B(-5,-2,3,SAND:1)
B(-5,-2,4,SAND:1)
B(-5,-2,5,SAND:1)
B(-5,-2,6,PRISMARINE:1)
B(-5,-2,7,SAND:1)
B(-5,-2,8,SAND:1)
B(-5,-2,9,PRISMARINE)
B(-5,-2,10,SAND:1)
B(-5,-2,11,SAND:1)
B(-5,-2,12,SAND:1)
B(-5,-2,13,PRISMARINE:1)
B(-5,-2,14,PRISMARINE)
B(-5,-2,15,SAND:1)
B(-5,-2,16,SAND:1)
B(-5,-2,17,SAND:1)
B(-5,-2,18,PRISMARINE)
B(-5,-2,19,PRISMARINE:1)
B(-5,-2,20,PRISMARINE)
B(-5,-2,21,PRISMARINE)
B(-5,-1,-4,PRISMARINE)
B(-5,-1,-3,PRISMARINE:1)
B(-5,-1,-2,SAND:1)
B(-5,-1,-1,SAND:1)
B(-5,-1,0,SAND:1)
B(-5,-1,1,SAND:1)
B(-5,-1,2,SAND:1)
B(-5,-1,3,SAND:1)
B(-5,-1,4,SAND:1)
B(-5,-1,5,SAND:1)
B(-5,-1,6,PRISMARINE:1)
B(-5,-1,7,SAND:1)
B(-5,-1,8,SAND:1)
B(-5,-1,9,PRISMARINE)
B(-5,-1,10,PRISMARINE)
B(-5,-1,11,SAND:1)
B(-5,-1,12,SAND:1)
B(-5,-1,13,PRISMARINE:1)
B(-5,-1,14,SAND:1)
B(-5,-1,15,SAND:1)
B(-5,-1,16,SAND:1)
B(-5,-1,17,SAND:1)
B(-5,-1,18,PRISMARINE)
B(-5,-1,19,PRISMARINE:1)
B(-5,-1,20,PRISMARINE)
B(-5,0,-3,PRISMARINE)
B(-5,0,-2,PRISMARINE)
B(-5,0,-1,PRISMARINE)
B(-5,0,0,PRISMARINE)
B(-5,0,1,PRISMARINE)
B(-5,0,2,PRISMARINE)
B(-5,0,3,PRISMARINE)
B(-5,0,4,PRISMARINE)
B(-5,0,5,PRISMARINE)
B(-5,0,6,PRISMARINE)
B(-5,0,7,PRISMARINE)
B(-5,0,8,PRISMARINE)
B(-5,0,9,PRISMARINE)
B(-5,0,10,PRISMARINE)
B(-5,0,11,PRISMARINE)
B(-5,0,12,PRISMARINE)
B(-5,0,13,PRISMARINE)
B(-5,0,14,PRISMARINE)
B(-5,0,15,PRISMARINE)
B(-5,0,16,PRISMARINE)
B(-5,0,17,PRISMARINE)
B(-5,0,18,PRISMARINE)
B(-5,0,19,PRISMARINE)
B(-5,0,20,PRISMARINE)
B(-5,1,-2,PRISMARINE)
B(-5,1,0,PRISMARINE)
B(-5,1,1,PRISMARINE)
B(-5,1,2,PRISMARINE)
B(-5,1,3,PRISMARINE)
B(-5,1,4,PRISMARINE)
B(-5,1,5,PRISMARINE)
B(-5,1,6,PRISMARINE)
B(-5,1,7,PRISMARINE)
B(-5,1,8,PRISMARINE)
B(-5,1,9,PRISMARINE)
B(-5,1,10,PRISMARINE)
B(-5,1,11,PRISMARINE)
B(-5,1,12,PRISMARINE)
B(-5,1,13,PRISMARINE)
B(-5,1,14,PRISMARINE)
B(-5,1,15,PRISMARINE)
B(-5,1,16,PRISMARINE)
B(-5,1,17,PRISMARINE)
B(-5,1,18,PRISMARINE)
B(-5,1,19,PRISMARINE)
B(-5,1,20,PRISMARINE)
B(-5,2,1,PRISMARINE)
B(-5,2,2,PRISMARINE)
B(-5,2,3,PRISMARINE)
B(-5,2,4,PRISMARINE)
B(-5,2,5,PRISMARINE)
B(-5,2,6,PRISMARINE)
B(-5,2,7,PRISMARINE)
B(-5,2,8,PRISMARINE)
B(-5,2,9,PRISMARINE)
B(-5,2,10,PRISMARINE)
B(-5,2,11,PRISMARINE)
B(-5,2,12,PRISMARINE)
B(-5,2,13,PRISMARINE)
B(-5,2,14,PRISMARINE)
B(-5,2,15,PRISMARINE)
B(-5,2,16,PRISMARINE)
B(-5,2,17,PRISMARINE)
B(-5,2,18,PRISMARINE)
B(-5,2,19,PRISMARINE)
B(-5,3,1,PRISMARINE)
B(-5,3,2,PRISMARINE)
B(-5,3,3,PRISMARINE)
B(-5,3,4,PRISMARINE)
B(-5,3,5,PRISMARINE)
B(-5,3,6,PRISMARINE)
B(-5,3,7,PRISMARINE)
B(-5,3,8,PRISMARINE)
B(-5,3,9,PRISMARINE)
B(-5,3,10,PRISMARINE)
B(-5,3,11,PRISMARINE)
B(-5,3,12,PRISMARINE)
B(-5,3,13,PRISMARINE)
B(-5,3,14,PRISMARINE)
B(-5,3,15,PRISMARINE)
B(-5,3,16,PRISMARINE)
B(-5,3,17,PRISMARINE)
B(-5,3,18,PRISMARINE)
B(-5,4,3,PRISMARINE)
B(-5,4,4,PRISMARINE)
B(-5,4,5,PRISMARINE)
B(-5,4,6,PRISMARINE)
B(-5,4,7,PRISMARINE)
B(-5,4,8,PRISMARINE)
B(-5,4,9,PRISMARINE)
B(-5,4,10,PRISMARINE)
B(-5,4,11,PRISMARINE)
B(-5,4,12,PRISMARINE)
B(-5,4,13,PRISMARINE)
B(-5,4,14,PRISMARINE)
B(-5,4,17,PRISMARINE)
B(-5,5,3,PRISMARINE)
B(-5,5,4,PRISMARINE)
B(-5,5,5,PRISMARINE)
B(-5,5,6,PRISMARINE)
B(-5,5,7,PRISMARINE)
B(-5,5,8,PRISMARINE)
B(-5,5,9,PRISMARINE)
B(-5,5,10,PRISMARINE)
B(-5,5,11,PRISMARINE)
B(-5,5,12,PRISMARINE)
B(-5,5,13,PRISMARINE)
B(-5,6,4,PRISMARINE)
B(-5,6,5,PRISMARINE)
B(-5,6,6,PRISMARINE)
B(-5,6,7,PRISMARINE)
B(-5,6,8,PRISMARINE)
B(-5,6,9,PRISMARINE)
B(-5,6,10,PRISMARINE)
B(-5,6,11,SPONGE:1)
B(-5,7,5,PRISMARINE)
B(-5,7,6,PRISMARINE)
B(-5,7,7,PRISMARINE)
B(-5,7,8,PRISMARINE)
B(-5,7,9,PRISMARINE)
B(-5,7,10,PRISMARINE)
B(-5,8,6,PRISMARINE)
B(-5,8,7,PRISMARINE)
B(-5,8,8,PRISMARINE)
B(-5,8,9,PRISMARINE)
B(-5,9,7,PRISMARINE)
B(-5,9,8,PRISMARINE)
B(-5,9,9,PRISMARINE)
B(-5,10,8,PRISMARINE)
B(-5,10,9,PRISMARINE)
B(-4,-20,10,PRISMARINE)
B(-4,-20,11,PRISMARINE)
B(-4,-20,12,PRISMARINE)
B(-4,-20,13,PRISMARINE)
B(-4,-20,14,PRISMARINE)
B(-4,-20,15,PRISMARINE)
B(-4,-19,3,PRISMARINE)
B(-4,-19,4,PRISMARINE)
B(-4,-19,5,PRISMARINE)
B(-4,-19,6,PRISMARINE)
B(-4,-19,7,PRISMARINE)
B(-4,-19,8,PRISMARINE)
B(-4,-19,9,PRISMARINE)
B(-4,-19,10,PRISMARINE)
B(-4,-19,11,PRISMARINE)
B(-4,-19,12,PRISMARINE)
B(-4,-19,13,PRISMARINE)
B(-4,-19,14,PRISMARINE)
B(-4,-19,15,PRISMARINE)
B(-4,-19,16,PRISMARINE)
B(-4,-18,2,PRISMARINE)
B(-4,-18,3,PRISMARINE)
B(-4,-18,4,PRISMARINE)
B(-4,-18,5,PRISMARINE)
B(-4,-18,6,PRISMARINE)
B(-4,-18,7,SAND)
B(-4,-18,8,PRISMARINE)
B(-4,-18,9,PRISMARINE)
B(-4,-18,10,PRISMARINE)
B(-4,-18,11,PRISMARINE)
B(-4,-18,12,PRISMARINE)
B(-4,-18,13,PRISMARINE)
B(-4,-18,14,PRISMARINE)
B(-4,-18,15,PRISMARINE)
B(-4,-18,16,PRISMARINE)
B(-4,-18,17,PRISMARINE)
B(-4,-17,2,PRISMARINE)
B(-4,-17,3,PRISMARINE)
B(-4,-17,4,PRISMARINE)
B(-4,-17,5,PRISMARINE)
B(-4,-17,6,SAND:1)
B(-4,-17,7,SAND:1)
B(-4,-17,8,PRISMARINE)
B(-4,-17,9,PRISMARINE)
B(-4,-17,10,SAND:1)
B(-4,-17,11,SAND:1)
B(-4,-17,12,BONE_BLOCK)
B(-4,-17,13,SAND:1)
B(-4,-17,14,BONE_BLOCK)
B(-4,-17,15,SAND:1)
B(-4,-17,16,BONE_BLOCK)
B(-4,-17,17,SAND)
B(-4,-17,18,PRISMARINE)
B(-4,-16,1,PRISMARINE)
B(-4,-16,2,PRISMARINE)
B(-4,-16,3,PRISMARINE)
B(-4,-16,4,SAND:1)
B(-4,-16,5,SAND:1)
B(-4,-16,6,SAND:1)
B(-4,-16,7,SAND:1)
B(-4,-16,8,PRISMARINE)
B(-4,-16,9,SAND:1)
B(-4,-16,10,SAND:1)
B(-4,-16,11,SAND:1)
B(-4,-16,12,SAND:1)
B(-4,-16,13,SAND:1)
B(-4,-16,14,SAND:1)
B(-4,-16,15,SAND:1)
B(-4,-16,16,SAND:1)
B(-4,-16,17,SAND:1)
B(-4,-16,18,PRISMARINE)
B(-4,-15,-2,PRISMARINE)
B(-4,-15,1,PRISMARINE)
B(-4,-15,2,PRISMARINE)
B(-4,-15,3,SAND:1)
B(-4,-15,4,SAND:1)
B(-4,-15,5,SAND:1)
B(-4,-15,6,SAND:1)
B(-4,-15,7,SAND:1)
B(-4,-15,8,PRISMARINE)
B(-4,-15,9,SAND:1)
B(-4,-15,10,SAND:1)
B(-4,-15,11,SAND:1)
B(-4,-15,12,SAND:1)
B(-4,-15,13,SAND:1)
B(-4,-15,14,SAND:1)
B(-4,-15,15,SAND:1)
B(-4,-15,16,SAND:1)
B(-4,-15,17,SAND:1)
B(-4,-15,18,PRISMARINE)
B(-4,-15,19,PRISMARINE)
B(-4,-14,-2,PRISMARINE)
B(-4,-14,-1,PRISMARINE)
B(-4,-14,0,PRISMARINE)
B(-4,-14,1,PRISMARINE)
B(-4,-14,2,SAND:1)
B(-4,-14,3,SAND:1)
B(-4,-14,4,SAND:1)
B(-4,-14,5,SAND:1)
B(-4,-14,6,SAND:1)
B(-4,-14,7,SAND:1)
B(-4,-14,8,SAND:1)
B(-4,-14,9,SAND:1)
B(-4,-14,10,SAND:1)
B(-4,-14,11,SAND:1)
B(-4,-14,12,SAND:1)
B(-4,-14,13,SAND:1)
B(-4,-14,14,SAND:1)
B(-4,-14,15,SAND:1)
B(-4,-14,16,SAND:1)
B(-4,-14,17,PRISMARINE)
B(-4,-14,18,PRISMARINE)
B(-4,-14,19,PRISMARINE)
B(-4,-13,-3,PRISMARINE)
B(-4,-13,-2,PRISMARINE)
B(-4,-13,-1,SAND:1)
B(-4,-13,0,SAND:1)
B(-4,-13,1,PRISMARINE)
B(-4,-13,2,PRISMARINE)
B(-4,-13,3,SAND:1)
B(-4,-13,4,SAND:1)
B(-4,-13,5,SAND:1)
B(-4,-13,6,SAND:1)
B(-4,-13,7,SAND:1)
B(-4,-13,8,SAND:1)
B(-4,-13,9,SAND:1)
B(-4,-13,10,SAND:1)
B(-4,-13,11,SAND:1)
B(-4,-13,12,SAND:1)
B(-4,-13,13,SAND:1)
B(-4,-13,14,SAND:1)
B(-4,-13,15,SAND:1)
B(-4,-13,16,SAND:1)
B(-4,-13,17,PRISMARINE)
B(-4,-13,18,PRISMARINE)
B(-4,-13,19,PRISMARINE)
B(-4,-13,20,PRISMARINE)
B(-4,-12,-3,PRISMARINE)
B(-4,-12,-2,PRISMARINE)
B(-4,-12,-1,PRISMARINE)
B(-4,-12,0,PRISMARINE)
B(-4,-12,1,PRISMARINE)
B(-4,-12,2,PRISMARINE)
B(-4,-12,3,PRISMARINE)
B(-4,-12,4,PRISMARINE)
B(-4,-12,5,SAND:1)
B(-4,-12,6,SAND:1)
B(-4,-12,7,SAND:1)
B(-4,-12,8,SAND:1)
B(-4,-12,9,SAND:1)
B(-4,-12,10,SAND:1)
B(-4,-12,11,PRISMARINE)
B(-4,-12,12,SAND:1)
B(-4,-12,13,SAND:1)
B(-4,-12,14,SAND:1)
B(-4,-12,15,SAND:1)
B(-4,-12,16,SAND:1)
B(-4,-12,17,PRISMARINE)
B(-4,-12,18,PRISMARINE)
B(-4,-12,19,PRISMARINE)
B(-4,-12,20,PRISMARINE)
B(-4,-11,-3,PRISMARINE)
B(-4,-11,-2,PRISMARINE)
B(-4,-11,-1,PRISMARINE)
B(-4,-11,0,PRISMARINE)
B(-4,-11,1,PRISMARINE)
B(-4,-11,2,PRISMARINE)
B(-4,-11,3,PRISMARINE)
B(-4,-11,4,PRISMARINE)
B(-4,-11,5,PRISMARINE)
B(-4,-11,6,PRISMARINE)
B(-4,-11,7,PRISMARINE)
B(-4,-11,8,PRISMARINE)
B(-4,-11,9,PRISMARINE)
B(-4,-11,10,PRISMARINE)
B(-4,-11,11,PRISMARINE)
B(-4,-11,12,PRISMARINE)
B(-4,-11,13,PRISMARINE)
B(-4,-11,14,PRISMARINE)
B(-4,-11,15,PRISMARINE)
B(-4,-11,16,PRISMARINE)
B(-4,-11,17,PRISMARINE)
B(-4,-11,18,PRISMARINE)
B(-4,-11,19,PRISMARINE)
B(-4,-11,20,PRISMARINE)
B(-4,-11,21,PRISMARINE)
B(-4,-10,-3,PRISMARINE)
B(-4,-10,-2,PRISMARINE)
B(-4,-10,-1,PRISMARINE)
B(-4,-10,0,PRISMARINE)
B(-4,-10,1,PRISMARINE)
B(-4,-10,2,PRISMARINE)
B(-4,-10,3,PRISMARINE)
B(-4,-10,4,PRISMARINE:1)
B(-4,-10,5,PRISMARINE:1)
B(-4,-10,6,PRISMARINE:1)
B(-4,-10,7,PRISMARINE:1)
B(-4,-10,8,PRISMARINE:1)
B(-4,-10,9,PRISMARINE:1)
B(-4,-10,10,PRISMARINE)
B(-4,-10,11,PRISMARINE:1)
B(-4,-10,12,PRISMARINE:1)
B(-4,-10,13,PRISMARINE)
B(-4,-10,14,PRISMARINE:2)
B(-4,-10,15,PRISMARINE:2)
B(-4,-10,16,PRISMARINE:2)
B(-4,-10,17,PRISMARINE:2)
B(-4,-10,18,PRISMARINE)
B(-4,-10,19,PRISMARINE:1)
B(-4,-10,20,PRISMARINE)
B(-4,-10,21,PRISMARINE)
B(-4,-9,-3,PRISMARINE)
B(-4,-9,-2,PRISMARINE)
B(-4,-9,-1,PRISMARINE)
B(-4,-9,0,PRISMARINE)
B(-4,-9,1,PRISMARINE)
B(-4,-9,2,PRISMARINE)
B(-4,-9,3,PRISMARINE:2)
B(-4,-9,4,SAND:1)
B(-4,-9,5,SAND:1)
B(-4,-9,6,SAND:1)
B(-4,-9,7,SAND:1)
B(-4,-9,8,SAND:1)
B(-4,-9,9,SAND:1)
B(-4,-9,10,SAND:1)
B(-4,-9,11,SAND:1)
B(-4,-9,12,SAND:1)
B(-4,-9,13,PRISMARINE:2)
B(-4,-9,14,SAND:1)
B(-4,-9,15,SAND:1)
B(-4,-9,16,SAND:1)
B(-4,-9,17,SAND:1)
B(-4,-9,18,PRISMARINE)
B(-4,-9,19,PRISMARINE:1)
B(-4,-9,20,PRISMARINE)
B(-4,-9,21,PRISMARINE)
B(-4,-8,-3,PRISMARINE)
B(-4,-8,-2,PRISMARINE)
B(-4,-8,-1,PRISMARINE)
B(-4,-8,0,PRISMARINE)
B(-4,-8,1,PRISMARINE)
B(-4,-8,2,PRISMARINE)
B(-4,-8,3,PRISMARINE:2)
B(-4,-8,4,SAND:1)
B(-4,-8,5,SAND:1)
B(-4,-8,6,SAND:1)
B(-4,-8,7,SAND:1)
B(-4,-8,8,SAND:1)
B(-4,-8,9,SAND:1)
B(-4,-8,10,SAND:1)
B(-4,-8,11,SAND:1)
B(-4,-8,12,SAND:1)
B(-4,-8,13,PRISMARINE:2)
B(-4,-8,14,SAND:1)
B(-4,-8,15,SAND:1)
B(-4,-8,16,SAND:1)
B(-4,-8,17,SAND:1)
B(-4,-8,18,SAND:1)
B(-4,-8,19,SPONGE:1)
B(-4,-8,20,PRISMARINE:1)
B(-4,-8,21,PRISMARINE)
B(-4,-7,-3,PRISMARINE)
B(-4,-7,-2,PRISMARINE)
B(-4,-7,-1,PRISMARINE)
B(-4,-7,0,PRISMARINE)
B(-4,-7,1,PRISMARINE)
B(-4,-7,2,PRISMARINE)
B(-4,-7,3,PRISMARINE:2)
B(-4,-7,4,SAND:1)
B(-4,-7,5,SAND:1)
B(-4,-7,6,SAND:1)
B(-4,-7,7,SAND:1)
B(-4,-7,8,SAND:1)
B(-4,-7,9,SAND:1)
B(-4,-7,10,SAND:1)
B(-4,-7,11,SAND:1)
B(-4,-7,12,SAND:1)
B(-4,-7,13,PRISMARINE:2)
B(-4,-7,14,SAND:1)
B(-4,-7,15,SAND:1)
B(-4,-7,16,SAND:1)
B(-4,-7,17,SAND:1)
B(-4,-7,18,SAND:1)
B(-4,-7,19,SAND:1)
B(-4,-7,20,SAND:1)
B(-4,-7,21,PRISMARINE:1)
B(-4,-7,22,PRISMARINE)
B(-4,-6,-3,PRISMARINE)
B(-4,-6,-2,PRISMARINE)
B(-4,-6,-1,PRISMARINE)
B(-4,-6,0,PRISMARINE)
B(-4,-6,1,PRISMARINE)
B(-4,-6,2,PRISMARINE)
B(-4,-6,3,PRISMARINE:2)
B(-4,-6,4,PRISMARINE:2)
B(-4,-6,5,SAND:1)
B(-4,-6,6,SAND:1)
B(-4,-6,7,SAND:1)
B(-4,-6,8,SAND:1)
B(-4,-6,9,SAND:1)
B(-4,-6,10,SAND:1)
B(-4,-6,11,SAND:1)
B(-4,-6,12,PRISMARINE:2)
B(-4,-6,13,PRISMARINE:2)
B(-4,-6,14,SAND:1)
B(-4,-6,15,SAND:1)
B(-4,-6,16,SAND:1)
B(-4,-6,17,SAND:1)
B(-4,-6,18,SAND:1)
B(-4,-6,19,SAND:1)
B(-4,-6,20,SAND:1)
B(-4,-6,21,PRISMARINE)
B(-4,-5,-4,PRISMARINE)
B(-4,-5,-3,PRISMARINE)
B(-4,-5,-2,PRISMARINE)
B(-4,-5,-1,PRISMARINE)
B(-4,-5,0,PRISMARINE)
B(-4,-5,1,PRISMARINE)
B(-4,-5,2,PRISMARINE)
B(-4,-5,3,PRISMARINE:2)
B(-4,-5,4,PRISMARINE:2)
B(-4,-5,5,PRISMARINE:2)
B(-4,-5,6,PRISMARINE:2)
B(-4,-5,7,PRISMARINE:2)
B(-4,-5,8,PRISMARINE:2)
B(-4,-5,9,PRISMARINE:2)
B(-4,-5,10,PRISMARINE:2)
B(-4,-5,11,PRISMARINE:2)
B(-4,-5,12,PRISMARINE:2)
B(-4,-5,13,PRISMARINE:2)
B(-4,-5,14,SAND:1)
B(-4,-5,15,SAND:1)
B(-4,-5,16,SAND:1)
B(-4,-5,17,SAND:1)
B(-4,-5,18,SAND:1)
B(-4,-5,19,SAND:1)
B(-4,-5,20,SAND:1)
B(-4,-5,21,PRISMARINE:1)
B(-4,-4,-5,PRISMARINE)
B(-4,-4,-4,PRISMARINE)
B(-4,-4,-3,PRISMARINE:1)
B(-4,-4,-2,PRISMARINE)
B(-4,-4,-1,PRISMARINE)
B(-4,-4,0,PRISMARINE)
B(-4,-4,1,PRISMARINE)
B(-4,-4,2,PRISMARINE)
B(-4,-4,3,PRISMARINE:1)
B(-4,-4,4,PRISMARINE)
B(-4,-4,5,PRISMARINE)
B(-4,-4,6,PRISMARINE)
B(-4,-4,7,PRISMARINE)
B(-4,-4,8,SPONGE:1)
B(-4,-4,9,PRISMARINE)
B(-4,-4,10,PRISMARINE)
B(-4,-4,11,PRISMARINE)
B(-4,-4,12,PRISMARINE)
B(-4,-4,13,PRISMARINE:1)
B(-4,-4,14,SAND:1)
B(-4,-4,15,SAND:1)
B(-4,-4,16,SAND:1)
B(-4,-4,17,SAND:1)
B(-4,-4,18,SAND:1)
B(-4,-4,19,SAND:1)
B(-4,-4,20,PRISMARINE:1)
B(-4,-4,21,PRISMARINE)
B(-4,-3,-5,PRISMARINE)
B(-4,-3,-4,SAND:1)
B(-4,-3,-3,SAND:1)
B(-4,-3,-2,SPONGE:1)
B(-4,-3,-1,SAND:1)
B(-4,-3,0,SAND:1)
B(-4,-3,1,SAND:1)
B(-4,-3,2,SAND:1)
B(-4,-3,3,SAND:1)
B(-4,-3,4,SAND:1)
B(-4,-3,5,SAND:1)
B(-4,-3,6,SAND:1)
B(-4,-3,7,PRISMARINE)
B(-4,-3,8,SAND:1)
B(-4,-3,9,SAND:1)
B(-4,-3,10,SAND:1)
B(-4,-3,11,SAND:1)
B(-4,-3,12,SAND:1)
B(-4,-3,13,SAND:1)
B(-4,-3,14,SAND:1)
B(-4,-3,15,SAND:1)
B(-4,-3,16,SAND:1)
B(-4,-3,17,SAND:1)
B(-4,-3,18,SAND:1)
B(-4,-3,19,PRISMARINE:1)
B(-4,-3,20,PRISMARINE)
B(-4,-3,21,PRISMARINE)
B(-4,-3,22,PRISMARINE)
B(-4,-2,-4,PRISMARINE)
B(-4,-2,-3,SAND:1)
B(-4,-2,-2,SAND:1)
B(-4,-2,-1,SAND:1)
B(-4,-2,0,SAND:1)
B(-4,-2,1,SAND:1)
B(-4,-2,2,SAND:1)
B(-4,-2,3,SAND:1)
B(-4,-2,4,SAND:1)
B(-4,-2,5,SAND:1)
B(-4,-2,6,SAND:1)
B(-4,-2,7,SPONGE:1)
B(-4,-2,8,SAND:1)
B(-4,-2,9,SAND:1)
B(-4,-2,10,SAND:1)
B(-4,-2,11,SAND:1)
B(-4,-2,12,SAND:1)
B(-4,-2,13,SAND:1)
B(-4,-2,14,SAND:1)
B(-4,-2,15,SAND:1)
B(-4,-2,16,SAND:1)
B(-4,-2,17,SAND:1)
B(-4,-2,18,SAND:1)
B(-4,-2,19,PRISMARINE)
B(-4,-2,20,PRISMARINE)
B(-4,-2,21,PRISMARINE)
B(-4,-1,-4,PRISMARINE)
B(-4,-1,-3,SAND:1)
B(-4,-1,-2,SAND:1)
B(-4,-1,-1,SAND:1)
B(-4,-1,0,SAND:1)
B(-4,-1,1,SAND:1)
B(-4,-1,2,SAND:1)
B(-4,-1,3,SAND:1)
B(-4,-1,4,SAND:1)
B(-4,-1,5,SAND:1)
B(-4,-1,6,PRISMARINE:1)
B(-4,-1,7,SAND:1)
B(-4,-1,8,SAND:1)
B(-4,-1,9,SAND:1)
B(-4,-1,10,PRISMARINE)
B(-4,-1,11,SAND:1)
B(-4,-1,12,SAND:1)
B(-4,-1,13,PRISMARINE:1)
B(-4,-1,14,SAND:1)
B(-4,-1,15,SAND:1)
B(-4,-1,16,PRISMARINE)
B(-4,-1,17,SAND:1)
B(-4,-1,18,PRISMARINE)
B(-4,-1,19,PRISMARINE)
B(-4,-1,20,PRISMARINE)
B(-4,0,-3,PRISMARINE)
B(-4,0,-2,PRISMARINE)
B(-4,0,-1,PRISMARINE)
B(-4,0,0,PRISMARINE)
B(-4,0,1,PRISMARINE)
B(-4,0,2,PRISMARINE)
B(-4,0,3,PRISMARINE)
B(-4,0,4,PRISMARINE)
B(-4,0,5,PRISMARINE)
B(-4,0,6,PRISMARINE)
B(-4,0,7,PRISMARINE)
B(-4,0,8,PRISMARINE)
B(-4,0,9,PRISMARINE)
B(-4,0,10,PRISMARINE)
B(-4,0,11,PRISMARINE)
B(-4,0,12,PRISMARINE)
B(-4,0,13,PRISMARINE)
B(-4,0,14,PRISMARINE)
B(-4,0,15,PRISMARINE)
B(-4,0,16,PRISMARINE)
B(-4,0,17,PRISMARINE)
B(-4,0,18,PRISMARINE)
B(-4,0,19,PRISMARINE)
B(-4,0,20,PRISMARINE)
B(-4,1,-3,PRISMARINE)
B(-4,1,-2,PRISMARINE:1)
B(-4,1,-1,PRISMARINE)
B(-4,1,0,PRISMARINE)
B(-4,1,1,PRISMARINE)
B(-4,1,2,PRISMARINE)
B(-4,1,3,PRISMARINE)
B(-4,1,4,PRISMARINE)
B(-4,1,5,PRISMARINE)
B(-4,1,6,PRISMARINE)
B(-4,1,7,PRISMARINE)
B(-4,1,8,PRISMARINE)
B(-4,1,9,PRISMARINE)
B(-4,1,10,PRISMARINE)
B(-4,1,11,PRISMARINE)
B(-4,1,12,PRISMARINE)
B(-4,1,13,PRISMARINE)
B(-4,1,14,PRISMARINE)
B(-4,1,15,PRISMARINE)
B(-4,1,16,PRISMARINE)
B(-4,1,17,PRISMARINE)
B(-4,1,18,PRISMARINE)
B(-4,1,19,PRISMARINE)
B(-4,1,20,PRISMARINE)
B(-4,2,-2,PRISMARINE:1)
B(-4,2,0,PRISMARINE)
B(-4,2,1,PRISMARINE)
B(-4,2,2,PRISMARINE)
B(-4,2,3,PRISMARINE)
B(-4,2,4,PRISMARINE)
B(-4,2,5,PRISMARINE)
B(-4,2,6,PRISMARINE)
B(-4,2,7,PRISMARINE)
B(-4,2,8,PRISMARINE)
B(-4,2,9,PRISMARINE)
B(-4,2,10,PRISMARINE)
B(-4,2,11,PRISMARINE)
B(-4,2,12,PRISMARINE)
B(-4,2,13,PRISMARINE)
B(-4,2,14,PRISMARINE)
B(-4,2,15,PRISMARINE)
B(-4,2,16,PRISMARINE)
B(-4,2,17,PRISMARINE)
B(-4,2,18,PRISMARINE)
B(-4,2,19,PRISMARINE)
B(-4,3,-2,PRISMARINE:1)
B(-4,3,1,PRISMARINE)
B(-4,3,2,SPONGE:1)
B(-4,3,3,PRISMARINE)
B(-4,3,4,PRISMARINE)
B(-4,3,5,PRISMARINE)
B(-4,3,6,PRISMARINE)
B(-4,3,7,PRISMARINE)
B(-4,3,8,PRISMARINE)
B(-4,3,9,PRISMARINE)
B(-4,3,10,PRISMARINE)
B(-4,3,11,PRISMARINE)
B(-4,3,12,PRISMARINE)
B(-4,3,13,PRISMARINE)
B(-4,3,14,PRISMARINE)
B(-4,3,15,PRISMARINE)
B(-4,3,16,PRISMARINE)
B(-4,3,17,PRISMARINE)
B(-4,4,-2,PRISMARINE:1)
B(-4,4,2,PRISMARINE)
B(-4,4,3,PRISMARINE)
B(-4,4,4,PRISMARINE)
B(-4,4,5,PRISMARINE)
B(-4,4,6,PRISMARINE)
B(-4,4,7,PRISMARINE)
B(-4,4,8,PRISMARINE)
B(-4,4,9,PRISMARINE)
B(-4,4,10,PRISMARINE)
B(-4,4,11,PRISMARINE)
B(-4,4,12,PRISMARINE)
B(-4,4,13,PRISMARINE)
B(-4,4,14,PRISMARINE)
B(-4,4,15,PRISMARINE)
RB(-4,5,-2,SEA_LANTERN,75,PRISMARINE,100)
B(-4,5,3,PRISMARINE)
B(-4,5,4,PRISMARINE)
B(-4,5,5,PRISMARINE)
B(-4,5,6,PRISMARINE)
B(-4,5,7,PRISMARINE)
B(-4,5,8,PRISMARINE)
B(-4,5,9,PRISMARINE)
B(-4,5,10,PRISMARINE)
B(-4,5,11,PRISMARINE)
B(-4,5,12,PRISMARINE)
B(-4,5,13,PRISMARINE)
B(-4,5,14,PRISMARINE)
B(-4,6,3,PRISMARINE)
B(-4,6,4,PRISMARINE)
B(-4,6,5,PRISMARINE)
B(-4,6,6,PRISMARINE)
B(-4,6,7,PRISMARINE)
B(-4,6,8,PRISMARINE)
B(-4,6,9,PRISMARINE)
B(-4,6,10,PRISMARINE)
B(-4,6,11,PRISMARINE)
B(-4,6,12,PRISMARINE)
B(-4,6,13,PRISMARINE)
B(-4,6,14,PRISMARINE)
B(-4,7,3,PRISMARINE)
B(-4,7,4,PRISMARINE)
B(-4,7,5,PRISMARINE)
B(-4,7,6,PRISMARINE)
B(-4,7,7,PRISMARINE)
B(-4,7,8,PRISMARINE)
B(-4,7,9,PRISMARINE)
B(-4,7,10,PRISMARINE)
B(-4,7,11,PRISMARINE)
B(-4,7,12,PRISMARINE)
B(-4,7,13,PRISMARINE)
B(-4,8,4,PRISMARINE)
B(-4,8,5,PRISMARINE)
B(-4,8,6,PRISMARINE)
B(-4,8,7,PRISMARINE)
B(-4,8,8,PRISMARINE)
B(-4,8,9,PRISMARINE)
B(-4,8,10,PRISMARINE)
B(-4,8,11,PRISMARINE)
B(-4,8,13,PRISMARINE)
B(-4,9,5,PRISMARINE)
B(-4,9,6,PRISMARINE)
B(-4,9,7,PRISMARINE)
B(-4,9,8,PRISMARINE)
B(-4,9,9,PRISMARINE)
B(-4,9,10,PRISMARINE)
B(-4,9,13,PRISMARINE)
B(-4,10,5,PRISMARINE)
B(-4,10,7,PRISMARINE)
B(-4,10,8,PRISMARINE)
B(-4,10,9,PRISMARINE)
B(-4,10,13,PRISMARINE)
B(-4,11,8,PRISMARINE)
B(-4,11,9,PRISMARINE)
B(-3,-20,4,PRISMARINE)
B(-3,-20,5,PRISMARINE)
B(-3,-20,6,PRISMARINE)
B(-3,-20,13,PRISMARINE)
B(-3,-20,14,PRISMARINE)
B(-3,-20,15,PRISMARINE)
B(-3,-19,1,PRISMARINE)
B(-3,-19,2,PRISMARINE)
B(-3,-19,3,PRISMARINE)
B(-3,-19,4,PRISMARINE)
B(-3,-19,5,PRISMARINE)
B(-3,-19,6,PRISMARINE)
B(-3,-19,7,PRISMARINE)
B(-3,-19,8,PRISMARINE)
B(-3,-19,9,PRISMARINE)
B(-3,-19,10,PRISMARINE)
B(-3,-19,11,PRISMARINE)
B(-3,-19,12,PRISMARINE)
B(-3,-19,13,PRISMARINE)
B(-3,-19,14,PRISMARINE)
B(-3,-19,15,PRISMARINE)
B(-3,-19,16,PRISMARINE)
B(-3,-18,0,PRISMARINE)
B(-3,-18,1,PRISMARINE)
B(-3,-18,2,PRISMARINE)
B(-3,-18,3,PRISMARINE)
B(-3,-18,4,PRISMARINE)
B(-3,-18,5,SAND:1)
B(-3,-18,6,SAND)
B(-3,-18,7,SAND)
B(-3,-18,8,SAND)
B(-3,-18,9,PRISMARINE)
B(-3,-18,10,PRISMARINE)
B(-3,-18,11,PRISMARINE)
B(-3,-18,12,PRISMARINE)
B(-3,-18,13,PRISMARINE)
B(-3,-18,14,PRISMARINE)
B(-3,-18,15,PRISMARINE)
B(-3,-18,16,PRISMARINE)
B(-3,-18,17,PRISMARINE)
B(-3,-17,-1,PRISMARINE)
B(-3,-17,0,PRISMARINE)
B(-3,-17,1,PRISMARINE)
B(-3,-17,2,PRISMARINE)
B(-3,-17,3,SAND:1)
B(-3,-17,4,SAND:1)
B(-3,-17,5,SAND:1)
B(-3,-17,6,SAND:1)
B(-3,-17,7,SAND:1)
B(-3,-17,8,SAND:1)
B(-3,-17,9,SAND:1)
B(-3,-17,10,SAND:1)
B(-3,-17,11,SAND:1)
B(-3,-17,12,BONE_BLOCK:8)
B(-3,-17,13,BONE_BLOCK:8)
B(-3,-17,14,BONE_BLOCK:8)
B(-3,-17,15,BONE_BLOCK:8)
B(-3,-17,16,BONE_BLOCK:8)
B(-3,-17,17,PRISMARINE)
B(-3,-16,-2,PRISMARINE)
B(-3,-16,-1,PRISMARINE)
B(-3,-16,0,PRISMARINE)
B(-3,-16,1,PRISMARINE)
B(-3,-16,2,PRISMARINE)
B(-3,-16,3,SAND:1)
B(-3,-16,4,SAND:1)
B(-3,-16,5,SAND:1)
B(-3,-16,6,SAND:1)
B(-3,-16,7,SAND:1)
B(-3,-16,8,SAND:1)
B(-3,-16,9,SAND:1)
B(-3,-16,10,SAND:1)
B(-3,-16,11,SAND:1)
B(-3,-16,12,SAND:1)
B(-3,-16,13,SAND:1)
B(-3,-16,14,SAND:1)
B(-3,-16,15,SAND:1)
B(-3,-16,16,SAND:1)
B(-3,-16,17,SAND:1)
B(-3,-16,18,PRISMARINE)
B(-3,-15,-3,PRISMARINE)
B(-3,-15,-2,PRISMARINE)
B(-3,-15,-1,PRISMARINE)
B(-3,-15,0,PRISMARINE)
B(-3,-15,1,SAND:1)
B(-3,-15,2,SAND:1)
B(-3,-15,3,SAND:1)
B(-3,-15,4,SAND:1)
B(-3,-15,5,SAND:1)
B(-3,-15,6,SAND:1)
B(-3,-15,7,SAND:1)
B(-3,-15,8,SAND:1)
B(-3,-15,9,SAND:1)
B(-3,-15,10,SAND:1)
B(-3,-15,11,SAND:1)
B(-3,-15,12,SAND:1)
B(-3,-15,13,SAND:1)
B(-3,-15,14,SAND:1)
B(-3,-15,15,SAND:1)
B(-3,-15,16,SAND:1)
B(-3,-15,17,SAND:1)
B(-3,-15,18,PRISMARINE)
B(-3,-14,-3,PRISMARINE)
B(-3,-14,-2,SAND:1)
B(-3,-14,-1,SAND:1)
B(-3,-14,0,SAND:1)
B(-3,-14,1,SAND:1)
B(-3,-14,2,SAND:1)
B(-3,-14,3,SAND:1)
B(-3,-14,4,SAND:1)
B(-3,-14,5,SAND:1)
B(-3,-14,6,SAND:1)
B(-3,-14,7,SAND:1)
B(-3,-14,8,SAND:1)
B(-3,-14,9,SAND:1)
B(-3,-14,10,SAND:1)
B(-3,-14,11,SAND:1)
B(-3,-14,12,SAND:1)
B(-3,-14,13,SAND:1)
B(-3,-14,14,SAND:1)
B(-3,-14,15,SAND:1)
B(-3,-14,16,SAND:1)
B(-3,-14,17,SAND:1)
B(-3,-14,18,PRISMARINE)
B(-3,-13,-4,PRISMARINE)
B(-3,-13,-3,SAND:1)
B(-3,-13,-2,SAND:1)
B(-3,-13,-1,SAND:1)
B(-3,-13,0,SAND:1)
B(-3,-13,1,SAND:1)
B(-3,-13,2,SAND:1)
B(-3,-13,3,SAND:1)
B(-3,-13,4,SAND:1)
B(-3,-13,5,SAND:1)
B(-3,-13,6,SAND:1)
B(-3,-13,7,SAND:1)
B(-3,-13,8,SAND:1)
B(-3,-13,9,SAND:1)
B(-3,-13,10,SAND:1)
B(-3,-13,11,SAND:1)
B(-3,-13,12,SAND:1)
B(-3,-13,13,SAND:1)
B(-3,-13,14,SAND:1)
B(-3,-13,15,SAND:1)
B(-3,-13,16,SAND:1)
B(-3,-13,17,PRISMARINE)
B(-3,-13,18,PRISMARINE)
B(-3,-13,19,PRISMARINE)
B(-3,-12,-4,PRISMARINE)
B(-3,-12,-3,SAND:1)
B(-3,-12,-2,SAND:1)
B(-3,-12,-1,SAND:1)
B(-3,-12,0,SAND:1)
B(-3,-12,1,PRISMARINE)
B(-3,-12,2,PRISMARINE)
B(-3,-12,3,PRISMARINE)
B(-3,-12,4,PRISMARINE)
B(-3,-12,5,SAND:1)
B(-3,-12,6,SAND:1)
B(-3,-12,7,SAND:1)
B(-3,-12,8,SAND:1)
B(-3,-12,9,SAND:1)
B(-3,-12,10,SAND:1)
B(-3,-12,11,PRISMARINE)
B(-3,-12,12,PRISMARINE)
B(-3,-12,13,SAND:1)
B(-3,-12,14,SAND:1)
B(-3,-12,15,SAND:1)
B(-3,-12,16,PRISMARINE)
B(-3,-12,17,PRISMARINE)
B(-3,-12,18,PRISMARINE)
B(-3,-12,19,PRISMARINE)
B(-3,-12,20,PRISMARINE)
B(-3,-11,-4,PRISMARINE)
B(-3,-11,-3,SAND:1)
B(-3,-11,-2,PRISMARINE)
B(-3,-11,-1,PRISMARINE)
B(-3,-11,0,PRISMARINE)
B(-3,-11,1,PRISMARINE)
B(-3,-11,2,PRISMARINE)
B(-3,-11,3,PRISMARINE)
B(-3,-11,4,PRISMARINE)
B(-3,-11,5,PRISMARINE)
B(-3,-11,6,PRISMARINE)
B(-3,-11,7,PRISMARINE)
B(-3,-11,8,PRISMARINE)
B(-3,-11,9,PRISMARINE)
B(-3,-11,10,PRISMARINE)
B(-3,-11,11,PRISMARINE)
B(-3,-11,12,PRISMARINE)
B(-3,-11,13,PRISMARINE)
B(-3,-11,14,PRISMARINE)
B(-3,-11,15,PRISMARINE)
B(-3,-11,16,PRISMARINE)
B(-3,-11,17,PRISMARINE)
B(-3,-11,18,PRISMARINE)
B(-3,-11,19,PRISMARINE)
B(-3,-11,20,PRISMARINE)
B(-3,-10,-4,PRISMARINE)
B(-3,-10,-3,PRISMARINE)
B(-3,-10,-2,PRISMARINE)
B(-3,-10,-1,PRISMARINE)
B(-3,-10,0,PRISMARINE)
B(-3,-10,1,PRISMARINE)
B(-3,-10,2,PRISMARINE)
B(-3,-10,3,PRISMARINE)
B(-3,-10,4,PRISMARINE:1)
B(-3,-10,5,PRISMARINE:2)
B(-3,-10,6,PRISMARINE)
B(-3,-10,7,PRISMARINE:2)
B(-3,-10,8,PRISMARINE)
B(-3,-10,9,PRISMARINE:2)
B(-3,-10,10,PRISMARINE)
B(-3,-10,11,PRISMARINE:2)
B(-3,-10,12,PRISMARINE:1)
B(-3,-10,13,PRISMARINE)
B(-3,-10,14,PRISMARINE)
B(-3,-10,15,PRISMARINE)
B(-3,-10,16,PRISMARINE)
B(-3,-10,17,PRISMARINE)
B(-3,-10,18,PRISMARINE)
B(-3,-10,19,PRISMARINE:1)
B(-3,-10,20,PRISMARINE)
B(-3,-9,-4,PRISMARINE)
B(-3,-9,-3,PRISMARINE)
B(-3,-9,-2,PRISMARINE)
B(-3,-9,-1,PRISMARINE)
B(-3,-9,0,SAND:1)
B(-3,-9,1,SAND:1)
B(-3,-9,2,SPONGE:1)
B(-3,-9,3,SAND:1)
B(-3,-9,4,SAND:1)
B(-3,-9,5,SAND:1)
B(-3,-9,6,SAND:1)
B(-3,-9,7,SAND:1)
B(-3,-9,8,SAND:1)
B(-3,-9,9,SAND:1)
B(-3,-9,10,SAND:1)
B(-3,-9,11,SAND:1)
B(-3,-9,12,SAND:1)
B(-3,-9,13,PRISMARINE)
B(-3,-9,14,SAND:1)
B(-3,-9,15,SAND:1)
B(-3,-9,16,SAND:1)
B(-3,-9,17,SAND:1)
B(-3,-9,18,PRISMARINE)
B(-3,-9,19,PRISMARINE:1)
B(-3,-9,20,PRISMARINE)
B(-3,-9,21,PRISMARINE)
B(-3,-8,-4,PRISMARINE)
B(-3,-8,-3,PRISMARINE)
B(-3,-8,-2,PRISMARINE)
B(-3,-8,-1,PRISMARINE)
B(-3,-8,0,PRISMARINE)
B(-3,-8,1,SAND:1)
B(-3,-8,2,SAND:1)
B(-3,-8,3,SAND:1)
B(-3,-8,4,SAND:1)
B(-3,-8,5,SAND:1)
B(-3,-8,6,SAND:1)
B(-3,-8,7,SAND:1)
B(-3,-8,8,SAND:1)
B(-3,-8,9,SAND:1)
B(-3,-8,10,SAND:1)
B(-3,-8,11,SAND:1)
B(-3,-8,12,SAND:1)
B(-3,-8,13,SAND:1)
B(-3,-8,14,SAND:1)
B(-3,-8,15,SAND:1)
B(-3,-8,16,SAND:1)
B(-3,-8,17,SAND:1)
B(-3,-8,18,SAND:1)
B(-3,-8,19,SAND:1)
B(-3,-8,20,PRISMARINE:2)
B(-3,-8,21,PRISMARINE)
B(-3,-8,22,PRISMARINE)
B(-3,-7,-4,PRISMARINE)
B(-3,-7,-3,PRISMARINE)
B(-3,-7,-2,PRISMARINE)
B(-3,-7,-1,PRISMARINE)
B(-3,-7,0,PRISMARINE)
B(-3,-7,1,PRISMARINE)
B(-3,-7,2,PRISMARINE)
B(-3,-7,3,PRISMARINE:2)
B(-3,-7,4,SAND:1)
B(-3,-7,5,SAND:1)
B(-3,-7,6,SAND:1)
B(-3,-7,7,SAND:1)
B(-3,-7,8,SAND:1)
B(-3,-7,9,SAND:1)
B(-3,-7,10,SAND:1)
B(-3,-7,11,SAND:1)
B(-3,-7,12,SAND:1)
B(-3,-7,13,PRISMARINE:2)
B(-3,-7,14,SAND:1)
B(-3,-7,15,SAND:1)
B(-3,-7,16,SAND:1)
B(-3,-7,17,SAND:1)
B(-3,-7,18,SAND:1)
B(-3,-7,19,SAND:1)
B(-3,-7,20,SAND:1)
B(-3,-7,21,PRISMARINE:1)
B(-3,-7,22,PRISMARINE)
B(-3,-6,-4,PRISMARINE)
B(-3,-6,-3,PRISMARINE)
B(-3,-6,-2,PRISMARINE)
B(-3,-6,-1,PRISMARINE)
B(-3,-6,0,PRISMARINE)
B(-3,-6,1,PRISMARINE)
B(-3,-6,2,PRISMARINE)
B(-3,-6,3,PRISMARINE:2)
B(-3,-6,4,SAND:1)
B(-3,-6,5,SAND:1)
B(-3,-6,6,SAND:1)
B(-3,-6,7,SAND:1)
B(-3,-6,8,SAND:1)
B(-3,-6,9,SAND:1)
B(-3,-6,10,SAND:1)
B(-3,-6,11,SAND:1)
B(-3,-6,12,SAND:1)
B(-3,-6,13,PRISMARINE:2)
B(-3,-6,14,SAND:1)
B(-3,-6,15,SAND:1)
B(-3,-6,16,SAND:1)
B(-3,-6,17,SAND:1)
B(-3,-6,18,SAND:1)
B(-3,-6,19,SAND:1)
B(-3,-6,20,SAND:1)
B(-3,-6,21,PRISMARINE)
B(-3,-5,-4,PRISMARINE)
B(-3,-5,-3,PRISMARINE)
B(-3,-5,-2,PRISMARINE)
B(-3,-5,-1,PRISMARINE)
B(-3,-5,0,PRISMARINE)
B(-3,-5,1,PRISMARINE)
B(-3,-5,2,PRISMARINE)
B(-3,-5,3,PRISMARINE:2)
B(-3,-5,4,PRISMARINE:2)
B(-3,-5,5,PRISMARINE)
B(-3,-5,6,PRISMARINE)
B(-3,-5,7,PRISMARINE)
B(-3,-5,8,PRISMARINE:2)
B(-3,-5,9,SAND:1)
B(-3,-5,10,SAND:1)
B(-3,-5,11,PRISMARINE)
B(-3,-5,12,PRISMARINE:2)
B(-3,-5,13,PRISMARINE:2)
B(-3,-5,14,SAND:1)
B(-3,-5,15,SAND:1)
B(-3,-5,16,SAND:1)
B(-3,-5,17,SAND:1)
B(-3,-5,18,SAND:1)
B(-3,-5,19,SAND:1)
B(-3,-5,20,SAND:1)
B(-3,-5,21,PRISMARINE:1)
B(-3,-5,22,PRISMARINE)
B(-3,-4,-5,PRISMARINE)
B(-3,-4,-4,PRISMARINE)
B(-3,-4,-3,PRISMARINE:1)
B(-3,-4,-2,PRISMARINE)
B(-3,-4,-1,PRISMARINE)
B(-3,-4,0,PRISMARINE)
B(-3,-4,1,SAND:1)
B(-3,-4,2,SAND:1)
B(-3,-4,3,PRISMARINE:1)
B(-3,-4,4,PRISMARINE)
B(-3,-4,5,PRISMARINE)
B(-3,-4,6,PRISMARINE)
B(-3,-4,7,PRISMARINE)
B(-3,-4,8,PRISMARINE)
B(-3,-4,9,PRISMARINE)
B(-3,-4,10,PRISMARINE)
B(-3,-4,11,PRISMARINE)
B(-3,-4,12,PRISMARINE)
B(-3,-4,13,PRISMARINE:1)
B(-3,-4,14,SAND:1)
B(-3,-4,15,SAND:1)
B(-3,-4,16,SAND:1)
B(-3,-4,17,SAND:1)
B(-3,-4,18,SAND:1)
B(-3,-4,19,SAND:1)
B(-3,-4,20,PRISMARINE:1)
B(-3,-4,21,PRISMARINE)
B(-3,-4,22,PRISMARINE)
B(-3,-3,-5,PRISMARINE)
B(-3,-3,-4,SAND:1)
B(-3,-3,-3,SAND:1)
B(-3,-3,-2,SAND:1)
B(-3,-3,-1,SAND:1)
B(-3,-3,0,SAND:1)
B(-3,-3,1,SAND:1)
B(-3,-3,2,SAND:1)
B(-3,-3,3,SAND:1)
B(-3,-3,4,SAND:1)
B(-3,-3,5,SAND:1)
B(-3,-3,6,SAND:1)
B(-3,-3,7,SAND:1)
B(-3,-3,8,SAND:1)
B(-3,-3,9,PRISMARINE)
B(-3,-3,10,SAND:1)
B(-3,-3,11,SAND:1)
B(-3,-3,12,SAND:1)
B(-3,-3,13,SAND:1)
B(-3,-3,14,SAND:1)
B(-3,-3,15,SAND:1)
B(-3,-3,16,SAND:1)
B(-3,-3,17,SAND:1)
B(-3,-3,18,SAND:1)
B(-3,-3,19,PRISMARINE:1)
B(-3,-3,20,PRISMARINE)
B(-3,-3,21,PRISMARINE)
B(-3,-3,22,PRISMARINE)
B(-3,-2,-5,PRISMARINE)
B(-3,-2,-4,SAND:1)
B(-3,-2,-3,SAND:1)
B(-3,-2,-2,SAND:1)
B(-3,-2,-1,SAND:1)
B(-3,-2,0,SAND:1)
B(-3,-2,1,SAND:1)
B(-3,-2,2,SAND:1)
B(-3,-2,3,SAND:1)
B(-3,-2,4,SAND:1)
B(-3,-2,5,SAND:1)
B(-3,-2,6,SAND:1)
B(-3,-2,7,SAND:1)
B(-3,-2,8,SAND:1)
B(-3,-2,9,SAND:1)
B(-3,-2,10,SAND:1)
B(-3,-2,11,SAND:1)
B(-3,-2,12,SAND:1)
B(-3,-2,13,SAND:1)
B(-3,-2,14,SAND:1)
B(-3,-2,15,SAND:1)
B(-3,-2,16,SAND:1)
B(-3,-2,17,SAND:1)
B(-3,-2,18,SAND:1)
B(-3,-2,19,PRISMARINE)
B(-3,-2,20,PRISMARINE)
B(-3,-2,21,PRISMARINE)
B(-3,-1,-4,PRISMARINE)
B(-3,-1,-3,SAND:1)
B(-3,-1,-2,SAND:1)
B(-3,-1,-1,SAND:1)
B(-3,-1,0,SAND:1)
B(-3,-1,1,SAND:1)
B(-3,-1,2,SAND:1)
B(-3,-1,3,SAND:1)
B(-3,-1,4,SAND:1)
B(-3,-1,5,SAND:1)
B(-3,-1,6,PRISMARINE:1)
B(-3,-1,7,SAND:1)
B(-3,-1,8,SAND:1)
B(-3,-1,9,SAND:1)
B(-3,-1,10,SAND:1)
B(-3,-1,11,SAND:1)
B(-3,-1,12,SAND:1)
B(-3,-1,13,PRISMARINE:1)
B(-3,-1,14,SAND:1)
B(-3,-1,15,SAND:1)
B(-3,-1,16,SAND:1)
B(-3,-1,17,SAND:1)
B(-3,-1,18,SAND:1)
B(-3,-1,19,PRISMARINE)
B(-3,-1,20,PRISMARINE)
B(-3,-1,21,PRISMARINE)
B(-3,0,-3,PRISMARINE)
B(-3,0,-2,PRISMARINE)
B(-3,0,-1,PRISMARINE)
B(-3,0,0,SAND:1)
B(-3,0,1,SAND:1)
B(-3,0,2,PRISMARINE)
B(-3,0,3,SAND:1)
B(-3,0,4,PRISMARINE)
B(-3,0,5,PRISMARINE)
B(-3,0,6,PRISMARINE)
B(-3,0,7,PRISMARINE)
B(-3,0,8,PRISMARINE)
B(-3,0,9,PRISMARINE)
B(-3,0,10,PRISMARINE)
B(-3,0,11,PRISMARINE)
B(-3,0,12,PRISMARINE)
B(-3,0,13,PRISMARINE)
B(-3,0,14,PRISMARINE)
B(-3,0,15,PRISMARINE)
B(-3,0,16,PRISMARINE)
B(-3,0,17,PRISMARINE)
B(-3,0,18,PRISMARINE)
B(-3,0,19,PRISMARINE)
B(-3,0,20,PRISMARINE)
B(-3,1,-2,PRISMARINE)
B(-3,1,-1,PRISMARINE)
B(-3,1,0,PRISMARINE)
B(-3,1,1,PRISMARINE)
B(-3,1,2,PRISMARINE)
B(-3,1,3,PRISMARINE)
B(-3,1,4,PRISMARINE)
B(-3,1,5,PRISMARINE)
B(-3,1,6,PRISMARINE)
B(-3,1,7,PRISMARINE)
B(-3,1,8,PRISMARINE)
B(-3,1,9,PRISMARINE)
B(-3,1,10,PRISMARINE)
B(-3,1,11,PRISMARINE)
B(-3,1,12,PRISMARINE)
B(-3,1,13,PRISMARINE)
B(-3,1,14,PRISMARINE)
B(-3,1,15,PRISMARINE)
B(-3,1,16,PRISMARINE)
B(-3,1,17,PRISMARINE)
B(-3,1,18,PRISMARINE)
B(-3,1,19,PRISMARINE)
B(-3,2,0,PRISMARINE:1)
B(-3,2,1,PRISMARINE)
B(-3,2,2,PRISMARINE)
B(-3,2,3,PRISMARINE)
B(-3,2,4,PRISMARINE)
B(-3,2,5,PRISMARINE)
B(-3,2,6,PRISMARINE)
B(-3,2,7,PRISMARINE)
B(-3,2,8,PRISMARINE)
B(-3,2,9,PRISMARINE)
B(-3,2,10,PRISMARINE)
B(-3,2,11,PRISMARINE)
B(-3,2,12,PRISMARINE)
B(-3,2,13,PRISMARINE)
B(-3,2,14,PRISMARINE)
B(-3,2,15,PRISMARINE)
B(-3,2,16,PRISMARINE)
B(-3,2,17,PRISMARINE)
B(-3,2,18,PRISMARINE)
B(-3,3,0,PRISMARINE:1)
B(-3,3,1,PRISMARINE)
B(-3,3,2,PRISMARINE)
B(-3,3,3,PRISMARINE)
B(-3,3,4,PRISMARINE)
B(-3,3,5,PRISMARINE)
B(-3,3,6,PRISMARINE)
B(-3,3,7,PRISMARINE)
B(-3,3,8,PRISMARINE)
B(-3,3,9,PRISMARINE)
B(-3,3,10,PRISMARINE)
B(-3,3,11,PRISMARINE)
B(-3,3,12,PRISMARINE)
B(-3,3,13,PRISMARINE)
B(-3,3,14,PRISMARINE)
B(-3,3,15,PRISMARINE)
B(-3,3,16,PRISMARINE)
B(-3,3,17,PRISMARINE)
B(-3,4,0,PRISMARINE:1)
B(-3,4,1,PRISMARINE:1)
B(-3,4,2,PRISMARINE:1)
B(-3,4,3,PRISMARINE)
B(-3,4,4,PRISMARINE)
B(-3,4,5,PRISMARINE)
B(-3,4,6,PRISMARINE)
B(-3,4,7,PRISMARINE)
B(-3,4,8,PRISMARINE)
B(-3,4,9,PRISMARINE)
B(-3,4,10,PRISMARINE)
B(-3,4,11,PRISMARINE)
B(-3,4,12,PRISMARINE)
B(-3,4,13,PRISMARINE)
B(-3,4,14,PRISMARINE)
B(-3,4,15,PRISMARINE)
B(-3,4,16,PRISMARINE)
B(-3,5,2,PRISMARINE:1)
B(-3,5,3,PRISMARINE:1)
B(-3,5,4,PRISMARINE)
B(-3,5,5,PRISMARINE)
B(-3,5,6,PRISMARINE)
B(-3,5,7,PRISMARINE)
B(-3,5,8,PRISMARINE)
B(-3,5,9,PRISMARINE)
B(-3,5,10,PRISMARINE)
B(-3,5,11,PRISMARINE)
B(-3,5,12,PRISMARINE)
B(-3,5,13,PRISMARINE)
B(-3,5,14,PRISMARINE)
B(-3,5,15,PRISMARINE)
B(-3,6,2,PRISMARINE:1)
B(-3,6,3,PRISMARINE:1)
B(-3,6,4,PRISMARINE:1)
B(-3,6,5,PRISMARINE)
B(-3,6,6,PRISMARINE)
B(-3,6,7,PRISMARINE)
B(-3,6,8,PRISMARINE)
B(-3,6,9,PRISMARINE)
B(-3,6,10,PRISMARINE)
B(-3,6,11,SAND:1)
B(-3,6,12,PRISMARINE)
B(-3,6,13,PRISMARINE)
B(-3,6,14,PRISMARINE)
B(-3,7,3,PRISMARINE)
B(-3,7,4,PRISMARINE)
B(-3,7,5,PRISMARINE)
B(-3,7,6,PRISMARINE)
B(-3,7,7,PRISMARINE)
B(-3,7,8,PRISMARINE)
B(-3,7,9,PRISMARINE)
B(-3,7,10,PRISMARINE)
B(-3,7,11,PRISMARINE)
B(-3,7,12,PRISMARINE)
B(-3,7,13,PRISMARINE)
B(-3,8,4,PRISMARINE)
B(-3,8,5,SPONGE:1)
B(-3,8,6,PRISMARINE)
B(-3,8,7,PRISMARINE)
B(-3,8,8,PRISMARINE)
B(-3,8,9,PRISMARINE)
B(-3,8,10,PRISMARINE)
B(-3,8,11,PRISMARINE)
B(-3,8,12,PRISMARINE)
B(-3,8,13,PRISMARINE)
B(-3,9,6,PRISMARINE)
B(-3,9,7,PRISMARINE)
B(-3,9,8,PRISMARINE)
B(-3,9,9,PRISMARINE)
B(-3,9,10,PRISMARINE)
B(-3,9,11,PRISMARINE)
B(-3,10,7,PRISMARINE)
B(-3,10,8,PRISMARINE)
B(-3,10,9,PRISMARINE)
B(-3,10,10,PRISMARINE)
B(-3,10,11,PRISMARINE)
B(-3,11,7,PRISMARINE)
B(-3,11,8,PRISMARINE)
B(-3,11,9,PRISMARINE)
B(-3,11,10,PRISMARINE)
B(-3,12,8,PRISMARINE)
B(-3,12,9,PRISMARINE)
B(-3,12,10,PRISMARINE)
B(-3,13,9,PRISMARINE)
B(-3,13,10,PRISMARINE)
B(-3,14,10,PRISMARINE)
B(-2,-21,14,PRISMARINE)
B(-2,-20,4,PRISMARINE)
B(-2,-20,5,PRISMARINE)
B(-2,-20,14,PRISMARINE)
B(-2,-20,15,PRISMARINE)
B(-2,-19,1,PRISMARINE)
B(-2,-19,2,PRISMARINE)
B(-2,-19,3,PRISMARINE)
B(-2,-19,4,PRISMARINE)
B(-2,-19,5,PRISMARINE)
B(-2,-19,6,PRISMARINE)
B(-2,-19,7,PRISMARINE)
B(-2,-19,8,PRISMARINE)
B(-2,-19,9,PRISMARINE)
B(-2,-19,10,PRISMARINE)
B(-2,-19,11,PRISMARINE)
B(-2,-19,12,PRISMARINE)
B(-2,-19,13,PRISMARINE)
B(-2,-19,14,PRISMARINE)
B(-2,-19,15,PRISMARINE)
B(-2,-19,16,PRISMARINE)
B(-2,-18,0,PRISMARINE)
B(-2,-18,1,PRISMARINE)
B(-2,-18,2,PRISMARINE)
B(-2,-18,3,PRISMARINE)
B(-2,-18,4,PRISMARINE)
B(-2,-18,5,SAND:1)
B(-2,-18,6,SAND:1)
B(-2,-18,7,PRISMARINE)
B(-2,-18,8,SAND:1)
B(-2,-18,9,SAND:1)
B(-2,-18,10,PRISMARINE)
B(-2,-18,11,PRISMARINE)
B(-2,-18,12,PRISMARINE)
B(-2,-18,13,PRISMARINE)
B(-2,-18,14,PRISMARINE)
B(-2,-18,15,PRISMARINE)
B(-2,-18,16,PRISMARINE)
B(-2,-17,-1,PRISMARINE)
B(-2,-17,0,PRISMARINE)
B(-2,-17,1,PRISMARINE)
B(-2,-17,2,PRISMARINE)
B(-2,-17,3,SAND:1)
B(-2,-17,4,SAND:1)
B(-2,-17,5,SAND:1)
B(-2,-17,6,SAND:1)
B(-2,-17,7,SAND:1)
B(-2,-17,8,SAND:1)
B(-2,-17,9,SAND:1)
B(-2,-17,10,SAND:1)
B(-2,-17,11,SAND:1)
B(-2,-17,12,BONE_BLOCK)
B(-2,-17,13,SAND:1)
B(-2,-17,14,BONE_BLOCK)
B(-2,-17,15,SAND:1)
B(-2,-17,16,BONE_BLOCK)
B(-2,-17,17,PRISMARINE)
B(-2,-16,-1,PRISMARINE)
B(-2,-16,0,PRISMARINE)
B(-2,-16,1,SAND:1)
B(-2,-16,2,SAND:1)
B(-2,-16,3,SAND:1)
B(-2,-16,4,SAND:1)
B(-2,-16,5,SAND:1)
B(-2,-16,6,SAND:1)
B(-2,-16,7,SAND:1)
B(-2,-16,8,SAND:1)
B(-2,-16,9,SAND:1)
B(-2,-16,10,SAND:1)
B(-2,-16,11,SAND:1)
B(-2,-16,12,SAND:1)
B(-2,-16,13,SAND:1)
B(-2,-16,14,SAND:1)
B(-2,-16,15,SAND:1)
B(-2,-16,16,SAND:1)
B(-2,-16,17,SAND:1)
B(-2,-16,18,PRISMARINE)
B(-2,-15,-2,PRISMARINE)
B(-2,-15,-1,PRISMARINE)
B(-2,-15,0,SAND:1)
B(-2,-15,1,SAND:1)
B(-2,-15,2,SAND:1)
B(-2,-15,3,SAND:1)
B(-2,-15,4,SAND:1)
B(-2,-15,5,SAND:1)
B(-2,-15,6,SAND:1)
B(-2,-15,7,SAND:1)
B(-2,-15,8,SAND:1)
B(-2,-15,9,SAND:1)
B(-2,-15,10,SAND:1)
B(-2,-15,11,SAND:1)
B(-2,-15,12,SAND:1)
B(-2,-15,13,SAND:1)
B(-2,-15,14,SAND:1)
B(-2,-15,15,SAND:1)
B(-2,-15,16,SAND:1)
B(-2,-15,17,SAND:1)
B(-2,-15,18,PRISMARINE)
B(-2,-14,-3,PRISMARINE)
B(-2,-14,-2,PRISMARINE)
B(-2,-14,-1,SAND:1)
B(-2,-14,0,SAND:1)
B(-2,-14,1,SAND:1)
B(-2,-14,2,SAND:1)
B(-2,-14,3,SAND:1)
B(-2,-14,4,SAND:1)
B(-2,-14,5,SAND:1)
B(-2,-14,6,SAND:1)
B(-2,-14,7,SAND:1)
B(-2,-14,8,SAND:1)
B(-2,-14,9,SAND:1)
B(-2,-14,10,SAND:1)
B(-2,-14,11,SAND:1)
B(-2,-14,12,SAND:1)
B(-2,-14,13,SAND:1)
B(-2,-14,14,SAND:1)
B(-2,-14,15,SAND:1)
B(-2,-14,16,SAND:1)
B(-2,-14,17,PRISMARINE)
B(-2,-14,18,PRISMARINE)
B(-2,-13,-3,PRISMARINE)
B(-2,-13,-2,SAND:1)
B(-2,-13,-1,SAND:1)
B(-2,-13,0,SAND:1)
B(-2,-13,1,SAND:1)
B(-2,-13,2,SAND:1)
B(-2,-13,3,SAND:1)
B(-2,-13,4,SAND:1)
B(-2,-13,5,SAND:1)
B(-2,-13,6,SAND:1)
B(-2,-13,7,SAND:1)
B(-2,-13,8,SAND:1)
B(-2,-13,9,SAND:1)
B(-2,-13,10,SAND:1)
B(-2,-13,11,SAND:1)
B(-2,-13,12,SAND:1)
B(-2,-13,13,SAND:1)
B(-2,-13,14,SAND:1)
B(-2,-13,15,SAND:1)
B(-2,-13,16,SAND:1)
B(-2,-13,17,PRISMARINE)
B(-2,-13,18,PRISMARINE)
B(-2,-12,-3,PRISMARINE)
B(-2,-12,-2,SAND:1)
B(-2,-12,-1,SAND:1)
B(-2,-12,0,SAND:1)
B(-2,-12,1,PRISMARINE)
B(-2,-12,2,PRISMARINE)
B(-2,-12,3,PRISMARINE)
B(-2,-12,4,SAND:1)
B(-2,-12,5,SAND:1)
B(-2,-12,6,SAND:1)
B(-2,-12,7,SAND:1)
B(-2,-12,8,SAND:1)
B(-2,-12,9,SAND:1)
B(-2,-12,10,SAND:1)
B(-2,-12,11,PRISMARINE)
B(-2,-12,12,PRISMARINE)
B(-2,-12,13,SAND:1)
B(-2,-12,14,SAND:1)
B(-2,-12,15,PRISMARINE)
B(-2,-12,16,PRISMARINE)
B(-2,-12,17,PRISMARINE)
B(-2,-12,18,PRISMARINE)
B(-2,-12,19,PRISMARINE)
B(-2,-11,-3,PRISMARINE)
B(-2,-11,-2,SAND:1)
B(-2,-11,-1,SAND:1)
B(-2,-11,0,SAND:1)
B(-2,-11,1,PRISMARINE)
B(-2,-11,2,PRISMARINE)
B(-2,-11,3,PRISMARINE)
B(-2,-11,4,PRISMARINE)
B(-2,-11,5,PRISMARINE)
B(-2,-11,6,PRISMARINE)
B(-2,-11,7,PRISMARINE)
B(-2,-11,8,PRISMARINE)
B(-2,-11,9,PRISMARINE)
B(-2,-11,10,PRISMARINE)
B(-2,-11,11,PRISMARINE)
B(-2,-11,12,PRISMARINE)
B(-2,-11,13,PRISMARINE)
B(-2,-11,14,PRISMARINE)
B(-2,-11,15,PRISMARINE)
B(-2,-11,16,PRISMARINE)
B(-2,-11,17,PRISMARINE)
B(-2,-11,18,PRISMARINE)
B(-2,-11,19,PRISMARINE)
B(-2,-11,20,PRISMARINE)
B(-2,-10,-3,PRISMARINE)
B(-2,-10,-2,SAND:1)
B(-2,-10,-1,SAND:1)
B(-2,-10,0,PRISMARINE)
B(-2,-10,1,PRISMARINE)
B(-2,-10,2,PRISMARINE)
B(-2,-10,3,PRISMARINE)
B(-2,-10,4,PRISMARINE:1)
B(-2,-10,5,PRISMARINE)
B(-2,-10,6,PRISMARINE:2)
B(-2,-10,7,PRISMARINE)
B(-2,-10,8,PRISMARINE:2)
B(-2,-10,9,PRISMARINE)
B(-2,-10,10,PRISMARINE:2)
B(-2,-10,11,PRISMARINE)
B(-2,-10,12,PRISMARINE:1)
B(-2,-10,13,PRISMARINE)
B(-2,-10,14,PRISMARINE)
B(-2,-10,15,PRISMARINE)
B(-2,-10,16,PRISMARINE)
B(-2,-10,17,PRISMARINE)
B(-2,-10,18,PRISMARINE)
B(-2,-10,19,PRISMARINE:1)
B(-2,-10,20,PRISMARINE)
B(-2,-9,-4,PRISMARINE)
B(-2,-9,-3,PRISMARINE)
B(-2,-9,-2,SAND:1)
B(-2,-9,-1,SAND:1)
B(-2,-9,0,PRISMARINE)
B(-2,-9,1,SAND:1)
B(-2,-9,2,SAND:1)
B(-2,-9,3,SAND:1)
B(-2,-9,4,SAND:1)
B(-2,-9,5,SAND:1)
B(-2,-9,6,SAND:1)
B(-2,-9,7,SAND:1)
B(-2,-9,8,SAND:1)
B(-2,-9,9,SAND:1)
B(-2,-9,10,SAND:1)
B(-2,-9,11,SAND:1)
B(-2,-9,12,SAND:1)
B(-2,-9,13,SAND:1)
B(-2,-9,14,SAND:1)
B(-2,-9,15,SAND:1)
B(-2,-9,16,SAND:1)
B(-2,-9,17,SAND:1)
B(-2,-9,18,SAND:1)
B(-2,-9,19,PRISMARINE:1)
B(-2,-9,20,PRISMARINE)
B(-2,-8,-5,PRISMARINE)
B(-2,-8,-4,PRISMARINE)
B(-2,-8,-3,PRISMARINE)
B(-2,-8,-2,SAND:1)
B(-2,-8,-1,SAND:1)
B(-2,-8,0,PRISMARINE)
B(-2,-8,1,SAND:1)
B(-2,-8,2,SAND:1)
B(-2,-8,3,SAND:1)
B(-2,-8,4,SAND:1)
B(-2,-8,5,SAND:1)
B(-2,-8,6,SAND:1)
B(-2,-8,7,SAND:1)
B(-2,-8,8,SAND:1)
B(-2,-8,9,SAND:1)
B(-2,-8,10,SAND:1)
B(-2,-8,11,SAND:1)
B(-2,-8,12,SAND:1)
B(-2,-8,13,SAND:1)
B(-2,-8,14,SAND:1)
B(-2,-8,15,SAND:1)
B(-2,-8,16,SAND:1)
B(-2,-8,17,SAND:1)
B(-2,-8,18,SAND:1)
B(-2,-8,19,SAND:1)
B(-2,-8,20,PRISMARINE:1)
B(-2,-8,21,PRISMARINE)
B(-2,-7,-5,PRISMARINE)
B(-2,-7,-4,PRISMARINE)
B(-2,-7,-3,PRISMARINE)
B(-2,-7,-2,SAND:1)
B(-2,-7,-1,SAND:1)
B(-2,-7,0,PRISMARINE)
B(-2,-7,1,SAND:1)
B(-2,-7,2,SAND:1)
B(-2,-7,3,SAND:1)
B(-2,-7,4,SAND:1)
B(-2,-7,5,SAND:1)
B(-2,-7,6,SAND:1)
B(-2,-7,7,SAND:1)
B(-2,-7,8,SAND:1)
B(-2,-7,9,SAND:1)
B(-2,-7,10,SAND:1)
B(-2,-7,11,SAND:1)
B(-2,-7,12,SAND:1)
B(-2,-7,13,SAND:1)
B(-2,-7,14,SAND:1)
B(-2,-7,15,SAND:1)
B(-2,-7,16,SAND:1)
B(-2,-7,17,SAND:1)
B(-2,-7,18,SAND:1)
B(-2,-7,19,SAND:1)
B(-2,-7,20,PRISMARINE:1)
B(-2,-7,21,PRISMARINE:1)
B(-2,-7,22,PRISMARINE)
B(-2,-6,-5,PRISMARINE)
B(-2,-6,-4,PRISMARINE)
B(-2,-6,-3,PRISMARINE)
B(-2,-6,-2,SAND:1)
B(-2,-6,-1,PRISMARINE)
B(-2,-6,0,PRISMARINE)
B(-2,-6,1,PRISMARINE)
B(-2,-6,2,PRISMARINE)
B(-2,-6,3,PRISMARINE:2)
B(-2,-6,4,SAND:1)
B(-2,-6,5,SAND:1)
B(-2,-6,6,PRISMARINE)
B(-2,-6,7,SAND:1)
B(-2,-6,8,SAND:1)
B(-2,-6,9,SAND:1)
B(-2,-6,10,SAND:1)
B(-2,-6,11,SAND:1)
B(-2,-6,12,SAND:1)
B(-2,-6,13,PRISMARINE:2)
B(-2,-6,14,SAND:1)
B(-2,-6,15,SAND:1)
B(-2,-6,16,SAND:1)
B(-2,-6,17,SAND:1)
B(-2,-6,18,SAND:1)
B(-2,-6,19,SAND:1)
B(-2,-6,20,SAND:1)
B(-2,-6,21,SAND:1)
B(-2,-6,22,PRISMARINE)
B(-2,-5,-5,PRISMARINE)
B(-2,-5,-4,PRISMARINE)
B(-2,-5,-3,PRISMARINE)
B(-2,-5,-2,PRISMARINE)
B(-2,-5,-1,PRISMARINE)
B(-2,-5,0,PRISMARINE)
B(-2,-5,1,PRISMARINE)
B(-2,-5,2,PRISMARINE)
B(-2,-5,3,PRISMARINE:2)
B(-2,-5,4,PRISMARINE:2)
B(-2,-5,5,PRISMARINE)
B(-2,-5,6,PRISMARINE)
B(-2,-5,7,PRISMARINE)
B(-2,-5,8,PRISMARINE:2)
B(-2,-5,9,PRISMARINE)
B(-2,-5,10,PRISMARINE)
B(-2,-5,11,PRISMARINE)
B(-2,-5,12,PRISMARINE:2)
B(-2,-5,13,PRISMARINE:2)
B(-2,-5,14,SAND:1)
B(-2,-5,15,SAND:1)
B(-2,-5,16,SAND:1)
B(-2,-5,17,SAND:1)
B(-2,-5,18,SAND:1)
B(-2,-5,19,SAND:1)
B(-2,-5,20,PRISMARINE:1)
B(-2,-5,21,PRISMARINE:1)
B(-2,-5,22,PRISMARINE)
B(-2,-4,-5,PRISMARINE)
B(-2,-4,-4,PRISMARINE)
B(-2,-4,-3,PRISMARINE:1)
B(-2,-4,-2,PRISMARINE)
B(-2,-4,-1,PRISMARINE:2)
B(-2,-4,0,PRISMARINE:2)
B(-2,-4,1,SAND:1)
B(-2,-4,2,SAND:1)
B(-2,-4,3,PRISMARINE:1)
B(-2,-4,4,PRISMARINE)
B(-2,-4,5,PRISMARINE)
B(-2,-4,6,PRISMARINE:2)
B(-2,-4,7,PRISMARINE:1)
B(-2,-4,8,PRISMARINE:2)
B(-2,-4,9,PRISMARINE:1)
B(-2,-4,10,PRISMARINE:2)
B(-2,-4,11,PRISMARINE)
B(-2,-4,12,PRISMARINE)
B(-2,-4,13,PRISMARINE:1)
B(-2,-4,14,SAND:1)
B(-2,-4,15,SAND:1)
B(-2,-4,16,SAND:1)
B(-2,-4,17,SAND:1)
B(-2,-4,18,SAND:1)
B(-2,-4,19,PRISMARINE:1)
B(-2,-4,20,PRISMARINE:1)
B(-2,-4,21,PRISMARINE)
B(-2,-4,22,PRISMARINE)
B(-2,-3,-5,PRISMARINE)
B(-2,-3,-4,SAND:1)
B(-2,-3,-3,SAND:1)
B(-2,-3,-2,SAND:1)
B(-2,-3,-1,SAND:1)
B(-2,-3,0,SAND:1)
B(-2,-3,1,SAND:1)
B(-2,-3,2,SAND:1)
B(-2,-3,3,SAND:1)
B(-2,-3,4,SAND:1)
B(-2,-3,5,SAND:1)
B(-2,-3,6,PRISMARINE:1)
B(-2,-3,7,PRISMARINE:1)
B(-2,-3,8,PRISMARINE:1)
B(-2,-3,9,PRISMARINE:1)
B(-2,-3,10,PRISMARINE:1)
B(-2,-3,11,SAND:1)
B(-2,-3,12,SAND:1)
B(-2,-3,13,SAND:1)
B(-2,-3,14,SAND:1)
B(-2,-3,15,SAND:1)
B(-2,-3,16,SAND:1)
B(-2,-3,17,SAND:1)
B(-2,-3,18,PRISMARINE:1)
B(-2,-3,19,PRISMARINE:1)
B(-2,-3,20,PRISMARINE)
B(-2,-3,21,PRISMARINE)
B(-2,-3,22,PRISMARINE)
B(-2,-2,-5,PRISMARINE)
B(-2,-2,-4,SAND:1)
B(-2,-2,-3,SAND:1)
B(-2,-2,-2,SAND:1)
B(-2,-2,-1,SAND:1)
B(-2,-2,0,SAND:1)
