#######################################################################
# +-----------------------------------------------------------------+ #
# |                            BO3 object                           | #
# +-----------------------------------------------------------------+ #
#######################################################################

# The descriptions in this file are true only for TerrainControl. They are not true for the Minecraft Worlds mod!
# Minecraft Worlds completely reimplemented BO3s, check the MCW documentation on the mc/mctcp forums for how to use BO3s with MCW
# or watch the video's on my YT channel at https://www.youtube.com/user/PeeGee85. You can check out the "Editing and importing schematics & BO3s" 
# series of video's, in part 2 I explain BO3s. 

# This is the config file of a custom object.
# If you add this object correctly to your BiomeConfigs, it will spawn in the world.

# This is the creator of this BO3 object
Author: Unknown

# A short description of this BO3 object
Description: This BO3 was converted from a schematic using the MineCraft Worlds Editor. Unfortunately the author and description information for the schematic could not be found. If you know who the author of the schematic is then please tell the author of this BO3!

# The BO3 version, don't change this! It can be used by external applications to do a version check.
Version: 3

# The settings mode, WriteAll, WriteWithoutComments or WriteDisable. See WorldConfig.
SettingsMode: WriteDisable

#######################################################################
# +-----------------------------------------------------------------+ #
# |                          Main settings                          | #
# +-----------------------------------------------------------------+ #
#######################################################################

# This needs to be set to true to spawn the object in the Tree and Sapling resources.
Tree: false

# The frequency of the BO3 from 1 to 200. Tries this many times to spawn this BO3 when using the CustomObject(...) resource.
# Ignored by Tree(..), Sapling(..) and CustomStructure(..)
Frequency: 1

# The rarity of the BO3 from 0 to 100. Each spawn attempt has rarity% chance to succeed when using the CustomObject(...) resource.
# Ignored by Tree(..), Sapling(..) and CustomStructure(..)
Rarity: 100.0

# If you set this to true, the BO3 will be placed with a random rotation.
RotateRandomly: false

# The spawn height of the BO3 - randomY, highestBlock or highestSolidBlock.
SpawnHeight: randomY

# The height limits for the BO3.
MinHeight: 0

MaxHeight: 256

# Objects can have other objects attached to it: branches. Branches can also
# have branches attached to it, which can also have branches, etc. This is the
# maximum branch depth for this objects.
MaxBranchDepth: 10

# When spawned with the UseWorld keyword, this BO3 should NOT spawn in the following biomes.
# If you writer.write the BO3 name directly in the BiomeConfigs, this will be ignored.
ExcludedBiomes: All

#######################################################################
# +-----------------------------------------------------------------+ #
# |                      Source block settings                      | #
# +-----------------------------------------------------------------+ #
#######################################################################

# The B(s) the BO3 should spawn in.
SourceBlocks: AIR

# The maximum percentage of the BO3 that can be outside the SourceBlock.
# The BO3 won't be placed on a location with more blocks outside the SourceBlock than this percentage.
MaxPercentageOutsideSourceBlock: 100

# What to do when a block is about to be placed outside the SourceBlock? (dontPlace, placeAnyway)
OutsideSourceBlock: placeAnyway

#######################################################################
# +-----------------------------------------------------------------+ #
# |                              Blocks                             | #
# +-----------------------------------------------------------------+ #
#######################################################################

# All the blocks used in the BO3 are listed here. Possible blocks:
# B(x,y,z,id[.data][,nbtfile.nbt)
# RB(x,y,z,id[:data][,nbtfile.nbt],chance[,id[:data][,nbtfile.nbt],chance[,...]])
# So RB(0,0,0,CHEST,chest.nbt,50,CHEST,anotherchest.nbt,100) will spawn a chest at
# the BO3 origin, and give it a 50% chance to have the contents of chest.nbt, or, if that
# fails, a 100% percent chance to have the contents of anotherchest.nbt.

B(-8,0,-7,179)
B(-8,0,-6,179)
B(-8,0,-5,179)
B(-8,0,-4,179)
B(-8,0,-3,179)
B(-8,0,-2,179)
B(-8,0,-1,179)
B(-8,0,0,179)
B(-8,0,1,179)
B(-8,0,2,179)
B(-8,0,3,179)
B(-8,0,4,179)
B(-8,0,5,179)
B(-8,0,6,179)
B(-8,0,7,179)
B(-8,0,8,179)
B(-8,1,-7,179)
B(-8,1,-6,179)
B(-8,1,-5,179)
B(-8,1,-4,179)
B(-8,1,-3,179)
B(-8,1,-2,179)
B(-8,1,-1,179)
B(-8,1,0,179)
B(-8,1,1,179)
B(-8,1,2,179)
B(-8,1,3,179)
B(-8,1,4,179)
B(-8,1,5,179)
B(-8,1,6,179)
B(-8,1,7,179)
B(-8,1,8,179)
B(-8,2,-7,179)
B(-8,2,-6,179)
B(-8,2,-5,179)
B(-8,2,-4,179)
B(-8,2,-3,179)
B(-8,2,-2,179)
B(-8,2,-1,179)
B(-8,2,0,179)
B(-8,2,1,179)
B(-8,2,2,179)
B(-8,2,3,179)
B(-8,2,4,179)
B(-8,2,5,179)
B(-8,2,6,179)
B(-8,2,7,179)
B(-8,2,8,179)
B(-8,3,-7,179)
B(-8,3,-6,179)
B(-8,3,-5,179)
B(-8,3,-4,179)
B(-8,3,-3,179)
B(-8,3,-2,179)
B(-8,3,-1,179)
B(-8,3,0,179)
B(-8,3,1,179)
B(-8,3,2,179)
B(-8,3,3,179)
B(-8,3,4,179)
B(-8,3,5,179)
B(-8,3,6,179)
B(-8,3,7,179)
B(-8,3,8,179)
B(-8,4,-7,179)
B(-8,4,-6,179)
B(-8,4,-5,179)
B(-8,4,-4,179)
B(-8,4,-3,179)
B(-8,4,-2,179)
B(-8,4,-1,179)
B(-8,4,0,179)
B(-8,4,1,179)
B(-8,4,2,179)
B(-8,4,3,179)
B(-8,4,4,179)
B(-8,4,5,179)
B(-8,4,6,179)
B(-8,4,7,179)
B(-8,4,8,179)
B(-8,5,-7,179)
B(-8,5,-6,179)
B(-8,5,-5,179)
B(-8,5,-4,179)
B(-8,5,-3,179)
B(-8,5,-2,179)
B(-8,5,-1,179)
B(-8,5,0,179)
B(-8,5,1,179)
B(-8,5,2,179)
B(-8,5,3,179)
B(-8,5,4,179)
B(-8,5,5,179)
B(-8,5,6,179)
B(-8,5,7,179)
B(-8,5,8,179)
B(-8,6,-7,179)
B(-8,6,-6,179)
B(-8,6,-5,179)
B(-8,6,-4,179)
B(-8,6,-3,179)
B(-8,6,-2,179)
B(-8,6,-1,179)
B(-8,6,0,179)
B(-8,6,1,179)
B(-8,6,2,179)
B(-8,6,3,179)
B(-8,6,4,179)
B(-8,6,5,179)
B(-8,6,6,179)
B(-8,6,7,179)
B(-8,6,8,179)
B(-8,7,-7,179)
B(-8,7,-6,179)
B(-8,7,-5,179)
B(-8,7,-4,179)
B(-8,7,-3,179)
B(-8,7,-2,179)
B(-8,7,-1,179)
B(-8,7,0,179)
B(-8,7,1,179)
B(-8,7,2,179)
B(-8,7,3,179)
B(-8,7,4,179)
B(-8,7,5,179)
B(-8,7,6,179)
B(-8,7,7,179)
B(-8,7,8,179)
B(-8,8,-7,179)
B(-8,8,-6,179)
B(-8,8,-5,179)
B(-8,8,-4,179)
B(-8,8,-3,179)
B(-8,8,-2,179)
B(-8,8,-1,179)
B(-8,8,0,179)
B(-8,8,1,179)
B(-8,8,2,179)
B(-8,8,3,179)
B(-8,8,4,179)
B(-8,8,5,179)
B(-8,8,6,179)
B(-8,8,7,179)
B(-8,8,8,179)
B(-8,9,-7,179)
B(-8,9,-6,179)
B(-8,9,-5,179)
B(-8,9,-4,179)
B(-8,9,-3,179)
B(-8,9,-2,179)
B(-8,9,-1,179)
B(-8,9,0,179)
B(-8,9,1,179)
B(-8,9,2,179)
B(-8,9,3,179)
B(-8,9,4,179)
B(-8,9,5,179)
B(-8,9,6,179)
B(-8,9,7,179)
B(-8,9,8,179)
B(-8,10,-7,179)
B(-8,10,-6,179)
B(-8,10,-5,179)
B(-8,10,-4,179)
B(-8,10,-3,179)
B(-8,10,-2,179)
B(-8,10,-1,179)
B(-8,10,0,179)
B(-8,10,1,179)
B(-8,10,2,179)
B(-8,10,3,179)
B(-8,10,4,179)
B(-8,10,5,179)
B(-8,10,6,179)
B(-8,10,7,179)
B(-8,10,8,179)
B(-8,11,-7,179)
B(-8,11,-6,179)
B(-8,11,-5,179)
B(-8,11,-4,179)
B(-8,11,-3,179)
B(-8,11,-2,179)
B(-8,11,-1,179)
B(-8,11,0,179)
B(-8,11,1,179)
B(-8,11,2,179)
B(-8,11,3,179)
B(-8,11,4,179)
B(-8,11,5,179)
B(-8,11,6,179)
B(-8,11,7,179)
B(-8,11,8,179)
B(-8,12,-7,179)
B(-8,12,-6,179)
B(-8,12,-5,179)
B(-8,12,-4,179)
B(-8,12,-3,179)
B(-8,12,-2,179)
B(-8,12,-1,179)
B(-8,12,0,179)
B(-8,12,1,179)
B(-8,12,2,179)
B(-8,12,3,179)
B(-8,12,4,179)
B(-8,12,5,179)
B(-8,12,6,179)
B(-8,12,7,179)
B(-8,12,8,179)
B(-8,13,-7,179)
B(-8,13,-6,179)
B(-8,13,-5,179)
B(-8,13,-4,179)
B(-8,13,-3,179)
B(-8,13,-2,179)
B(-8,13,-1,179)
B(-8,13,0,179)
B(-8,13,1,179)
B(-8,13,2,179)
B(-8,13,3,179)
B(-8,13,4,179)
B(-8,13,5,179)
B(-8,13,6,179)
B(-8,13,7,179)
B(-8,13,8,179)
B(-8,14,-7,179)
B(-8,14,-6,179)
B(-8,14,-5,179)
B(-8,14,-4,179)
B(-8,14,-3,179)
B(-8,14,-2,179)
B(-8,14,-1,179)
B(-8,14,0,179)
B(-8,14,1,179)
B(-8,14,2,179)
B(-8,14,3,179)
B(-8,14,4,179)
B(-8,14,5,179)
B(-8,14,6,179)
B(-8,14,7,179)
B(-8,14,8,179)
B(-8,15,-7,179)
B(-8,15,-6,179)
B(-8,15,-5,179)
B(-8,15,-4,179)
B(-8,15,-3,179)
B(-8,15,-2,179)
B(-8,15,-1,179)
B(-8,15,0,179)
B(-8,15,1,179)
B(-8,15,2,179)
B(-8,15,3,179)
B(-8,15,4,179)
B(-8,15,5,179)
B(-8,15,6,179)
B(-8,15,7,179)
B(-8,15,8,179)
B(-8,16,-7,179)
B(-8,16,-6,179)
B(-8,16,-5,179)
B(-8,16,-4,179)
B(-8,16,-3,179)
B(-8,16,-2,179)
B(-8,16,-1,179)
B(-8,16,0,179)
B(-8,16,1,179)
B(-8,16,2,179)
B(-8,16,3,179)
B(-8,16,4,179)
B(-8,16,5,179)
B(-8,16,6,179)
B(-8,16,7,179)
B(-8,16,8,179)
B(-8,17,-7,179)
B(-8,17,-6,179)
B(-8,17,-5,179)
B(-8,17,-4,179)
B(-8,17,-3,179)
B(-8,17,-2,179)
B(-8,17,-1,179)
B(-8,17,0,179)
B(-8,17,1,179)
B(-8,17,2,179)
B(-8,17,3,179)
B(-8,17,4,179)
B(-8,17,5,179)
B(-8,17,6,179)
B(-8,17,7,179)
B(-8,17,8,179)
B(-8,18,-7,179)
B(-8,18,-6,179)
B(-8,18,-5,179)
B(-8,18,-4,179)
B(-8,18,-3,179)
B(-8,18,-2,179)
B(-8,18,-1,179)
B(-8,18,0,179)
B(-8,18,1,179)
B(-8,18,2,179)
B(-8,18,3,179)
B(-8,18,4,179)
B(-8,18,5,179)
B(-8,18,6,179)
B(-8,18,7,179)
B(-8,18,8,179)
B(-8,19,-7,179)
B(-8,19,-6,179)
B(-8,19,-5,179)
B(-8,19,-4,179)
B(-8,19,-3,179)
B(-8,19,-2,179)
B(-8,19,-1,179)
B(-8,19,0,179)
B(-8,19,1,179)
B(-8,19,2,179)
B(-8,19,3,179)
B(-8,19,4,179)
B(-8,19,5,179)
B(-8,19,6,179)
B(-8,19,7,179)
B(-8,19,8,179)
B(-8,20,-7,179)
B(-8,20,-6,179)
B(-8,20,-5,179)
B(-8,20,-4,179)
B(-8,20,-3,179)
B(-8,20,-2,179)
B(-8,20,-1,179)
B(-8,20,0,179)
B(-8,20,1,179)
B(-8,20,2,179)
B(-8,20,3,179)
B(-8,20,4,179)
B(-8,20,5,179)
B(-8,20,6,179)
B(-8,20,7,179)
B(-8,20,8,179)
B(-8,21,-7,179)
B(-8,21,-6,179)
B(-8,21,-5,179)
B(-8,21,-4,179)
B(-8,21,-3,179)
B(-8,21,-2,179)
B(-8,21,-1,179)
B(-8,21,0,179)
B(-8,21,1,179)
B(-8,21,2,179)
B(-8,21,3,179)
B(-8,21,4,179)
B(-8,21,5,179)
B(-8,21,6,179)
B(-8,21,7,179)
B(-8,21,8,179)
B(-8,22,-7,179)
B(-8,22,-6,179)
B(-8,22,-5,179)
B(-8,22,-4,179)
B(-8,22,-3,179)
B(-8,22,-2,179)
B(-8,22,-1,179)
B(-8,22,0,179)
B(-8,22,1,179)
B(-8,22,2,179)
B(-8,22,3,179)
B(-8,22,4,179)
B(-8,22,5,179)
B(-8,22,6,179)
B(-8,22,7,179)
B(-8,22,8,179)
B(-8,23,-7,179)
B(-8,23,-6,179)
B(-8,23,-5,179)
B(-8,23,-4,179)
B(-8,23,-3,179)
B(-8,23,-2,179)
B(-8,23,-1,179)
B(-8,23,0,179)
B(-8,23,1,179)
B(-8,23,2,179)
B(-8,23,3,179)
B(-8,23,4,179)
B(-8,23,5,179)
B(-8,23,6,179)
B(-8,23,7,179)
B(-8,23,8,179)
B(-7,0,-7,179)
B(-7,0,-6,179)
B(-7,0,-5,179)
B(-7,0,-4,179)
B(-7,0,-3,179)
B(-7,0,-2,179)
B(-7,0,-1,179)
B(-7,0,0,179)
B(-7,0,1,179)
B(-7,0,2,179)
B(-7,0,3,179)
B(-7,0,4,179)
B(-7,0,5,179)
B(-7,0,6,179)
B(-7,0,7,179)
B(-7,0,8,179)
B(-7,1,-7,179)
B(-7,1,-6,179)
B(-7,1,-5,179)
B(-7,1,-4,179)
B(-7,1,-3,179)
B(-7,1,-2,179)
B(-7,1,-1,179)
B(-7,1,0,179)
B(-7,1,1,179)
B(-7,1,2,179)
B(-7,1,3,179)
B(-7,1,4,179)
B(-7,1,5,179)
B(-7,1,6,179)
B(-7,1,7,179)
B(-7,1,8,179)
B(-7,2,-7,179)
B(-7,2,-6,179)
B(-7,2,-5,179)
B(-7,2,-4,179)
B(-7,2,-3,179)
B(-7,2,-2,179)
B(-7,2,-1,179)
B(-7,2,0,179)
B(-7,2,1,179)
B(-7,2,2,179)
B(-7,2,3,179)
B(-7,2,4,179)
B(-7,2,5,179)
B(-7,2,6,179)
B(-7,2,7,179)
B(-7,2,8,179)
B(-7,3,-7,179)
B(-7,3,-6,179)
B(-7,3,-5,179)
B(-7,3,-4,179)
B(-7,3,-3,179)
B(-7,3,-2,179)
B(-7,3,-1,179)
B(-7,3,0,179)
B(-7,3,1,179)
B(-7,3,2,179)
B(-7,3,3,179)
B(-7,3,4,179)
B(-7,3,5,179)
B(-7,3,6,179)
B(-7,3,7,179)
B(-7,3,8,179)
B(-7,4,-7,179)
B(-7,4,-6,179)
B(-7,4,-5,179)
B(-7,4,-4,179)
B(-7,4,-3,179)
B(-7,4,-2,179)
B(-7,4,-1,179)
B(-7,4,0,179)
B(-7,4,1,179)
B(-7,4,2,179)
B(-7,4,3,179)
B(-7,4,4,179)
B(-7,4,5,179)
B(-7,4,6,179)
B(-7,4,7,179)
B(-7,4,8,179)
B(-7,5,-7,179)
B(-7,5,-6,179)
B(-7,5,-5,179)
B(-7,5,-4,179)
B(-7,5,-3,179)
B(-7,5,-2,179)
B(-7,5,-1,179)
B(-7,5,0,179)
B(-7,5,1,179)
B(-7,5,2,179)
B(-7,5,3,179)
B(-7,5,4,179)
B(-7,5,5,179)
B(-7,5,6,179)
B(-7,5,7,179)
B(-7,5,8,179)
B(-7,6,-7,179)
B(-7,6,-6,179)
B(-7,6,-5,179)
B(-7,6,-4,179)
B(-7,6,-3,179)
B(-7,6,-2,179)
B(-7,6,-1,179)
B(-7,6,0,179)
B(-7,6,1,179)
B(-7,6,2,179)
B(-7,6,3,179)
B(-7,6,4,179)
B(-7,6,5,179)
B(-7,6,6,179)
B(-7,6,7,179)
B(-7,6,8,179)
B(-7,7,-7,179)
B(-7,7,-6,179)
B(-7,7,-5,179)
B(-7,7,-4,179)
B(-7,7,-3,179)
B(-7,7,-2,179)
B(-7,7,-1,179)
B(-7,7,0,179)
B(-7,7,1,179)
B(-7,7,2,179)
B(-7,7,3,179)
B(-7,7,4,179)
B(-7,7,5,179)
B(-7,7,6,179)
B(-7,7,7,179)
B(-7,7,8,179)
B(-7,8,-7,179)
B(-7,8,-6,179)
B(-7,8,-5,179)
B(-7,8,-4,179)
B(-7,8,-3,179)
B(-7,8,-2,179)
B(-7,8,-1,179)
B(-7,8,0,179)
B(-7,8,1,179)
B(-7,8,2,179)
B(-7,8,3,179)
B(-7,8,4,179)
B(-7,8,5,179)
B(-7,8,6,179)
B(-7,8,7,179)
B(-7,8,8,179)
B(-7,9,-7,179)
B(-7,9,-6,179)
B(-7,9,-5,179)
B(-7,9,-4,179)
B(-7,9,-3,179)
B(-7,9,-2,179)
B(-7,9,-1,179)
B(-7,9,0,179)
B(-7,9,1,179)
B(-7,9,2,179)
B(-7,9,3,179)
B(-7,9,4,179)
B(-7,9,5,179)
B(-7,9,6,179)
B(-7,9,7,179)
B(-7,9,8,179)
B(-7,10,-7,179)
B(-7,10,-6,179)
B(-7,10,-5,179)
B(-7,10,-4,179)
B(-7,10,-3,179)
B(-7,10,-2,179)
B(-7,10,-1,179)
B(-7,10,0,179)
B(-7,10,1,179)
B(-7,10,2,179)
B(-7,10,3,179)
B(-7,10,4,179)
B(-7,10,5,179)
B(-7,10,6,179)
B(-7,10,7,179)
B(-7,10,8,179)
B(-7,11,-7,179)
B(-7,11,-6,179)
B(-7,11,-5,179)
B(-7,11,-4,179)
B(-7,11,-3,179)
B(-7,11,-2,179)
B(-7,11,-1,179)
B(-7,11,0,179)
B(-7,11,1,179)
B(-7,11,2,179)
B(-7,11,3,179)
B(-7,11,4,179)
B(-7,11,5,179)
B(-7,11,6,179)
B(-7,11,7,179)
B(-7,11,8,179)
B(-7,12,-7,179)
B(-7,12,-6,179)
B(-7,12,-5,179)
B(-7,12,-4,179)
B(-7,12,-3,179)
B(-7,12,-2,179)
B(-7,12,-1,179)
B(-7,12,0,179)
B(-7,12,1,179)
B(-7,12,2,179)
B(-7,12,3,179)
B(-7,12,4,179)
B(-7,12,5,179)
B(-7,12,6,179)
B(-7,12,7,179)
B(-7,12,8,179)
B(-7,13,-7,179)
B(-7,13,-6,179)
B(-7,13,-5,179)
B(-7,13,-4,179)
B(-7,13,-3,179)
B(-7,13,-2,179)
B(-7,13,-1,179)
B(-7,13,0,179)
B(-7,13,1,179)
B(-7,13,2,179)
B(-7,13,3,179)
B(-7,13,4,179)
B(-7,13,5,179)
B(-7,13,6,179)
B(-7,13,7,179)
B(-7,13,8,179)
B(-7,14,-7,179)
B(-7,14,-6,179)
B(-7,14,-5,179)
B(-7,14,-4,179)
B(-7,14,-3,179)
B(-7,14,-2,179)
B(-7,14,-1,179)
B(-7,14,0,179)
B(-7,14,1,179)
B(-7,14,2,179)
B(-7,14,3,179)
B(-7,14,4,179)
B(-7,14,5,179)
B(-7,14,6,179)
B(-7,14,7,179)
B(-7,14,8,179)
B(-7,15,-7,179)
B(-7,15,-6,179)
B(-7,15,-5,179)
B(-7,15,-4,179)
B(-7,15,-3,179)
B(-7,15,-2,179)
B(-7,15,-1,179)
B(-7,15,0,179)
B(-7,15,1,179)
B(-7,15,2,179)
B(-7,15,3,179)
B(-7,15,4,179)
B(-7,15,5,179)
B(-7,15,6,179)
B(-7,15,7,179)
B(-7,15,8,179)
B(-7,16,-7,179)
B(-7,16,-6,179)
B(-7,16,-5,179)
B(-7,16,-4,179)
B(-7,16,-3,179)
B(-7,16,-2,179)
B(-7,16,-1,179)
B(-7,16,0,179)
B(-7,16,1,179)
B(-7,16,2,179)
B(-7,16,3,179)
B(-7,16,4,179)
B(-7,16,5,179)
B(-7,16,6,179)
B(-7,16,7,179)
B(-7,16,8,179)
B(-7,17,-7,179)
B(-7,17,-6,179)
B(-7,17,-5,179)
B(-7,17,-4,179)
B(-7,17,-3,179)
B(-7,17,-2,179)
B(-7,17,-1,179)
B(-7,17,0,179)
B(-7,17,1,179)
B(-7,17,2,179)
B(-7,17,3,179)
B(-7,17,4,179)
B(-7,17,5,179)
B(-7,17,6,179)
B(-7,17,7,179)
B(-7,17,8,179)
B(-7,18,-7,179)
B(-7,18,-6,179)
B(-7,18,-5,179)
B(-7,18,-4,179)
B(-7,18,-3,179)
B(-7,18,-2,179)
B(-7,18,-1,179)
B(-7,18,0,179)
B(-7,18,1,179)
B(-7,18,2,179)
B(-7,18,3,179)
B(-7,18,4,179)
B(-7,18,5,179)
B(-7,18,6,179)
B(-7,18,7,179)
B(-7,18,8,179)
B(-7,19,-7,179)
B(-7,19,-6,179)
B(-7,19,-5,179)
B(-7,19,-4,179)
B(-7,19,-3,179)
B(-7,19,-2,179)
B(-7,19,-1,179)
B(-7,19,0,179)
B(-7,19,1,179)
B(-7,19,2,179)
B(-7,19,3,179)
B(-7,19,4,179)
B(-7,19,5,179)
B(-7,19,6,179)
B(-7,19,7,179)
B(-7,19,8,179)
B(-7,20,-7,179)
B(-7,20,-6,179)
B(-7,20,-5,179)
B(-7,20,-4,179)
B(-7,20,-3,179)
B(-7,20,-2,179)
B(-7,20,-1,179)
B(-7,20,0,179)
B(-7,20,1,179)
B(-7,20,2,179)
B(-7,20,3,179)
B(-7,20,4,179)
B(-7,20,5,179)
B(-7,20,6,179)
B(-7,20,7,179)
B(-7,20,8,179)
B(-7,21,-7,179)
B(-7,21,-6,179)
B(-7,21,-5,179)
B(-7,21,-4,179)
B(-7,21,-3,179)
B(-7,21,-2,179)
B(-7,21,-1,179)
B(-7,21,0,179)
B(-7,21,1,179)
B(-7,21,2,179)
B(-7,21,3,179)
B(-7,21,4,179)
B(-7,21,5,179)
B(-7,21,6,179)
B(-7,21,7,179)
B(-7,21,8,179)
B(-7,22,-7,179)
B(-7,22,-6,179)
B(-7,22,-5,179)
B(-7,22,-4,179)
B(-7,22,-3,179)
B(-7,22,-2,179)
B(-7,22,-1,179)
B(-7,22,0,179)
B(-7,22,1,179)
B(-7,22,2,179)
B(-7,22,3,179)
B(-7,22,4,179)
B(-7,22,5,179)
B(-7,22,6,179)
B(-7,22,7,179)
B(-7,22,8,179)
B(-7,23,-7,179)
B(-7,23,-6,179)
B(-7,23,-5,179)
B(-7,23,-4,179)
B(-7,23,-3,179)
B(-7,23,-2,179)
B(-7,23,-1,179)
B(-7,23,0,179)
B(-7,23,1,179)
B(-7,23,2,179)
B(-7,23,3,179)
B(-7,23,4,179)
B(-7,23,5,179)
B(-7,23,6,179)
B(-7,23,7,179)
B(-7,23,8,179)
B(-7,24,-7,180:0)
B(-7,24,-6,180:0)
B(-7,24,-5,180:0)
B(-7,24,-4,180:0)
B(-7,24,-3,180:0)
B(-7,24,-2,180:0)
B(-7,24,-1,180:0)
B(-7,24,0,180:0)
B(-7,24,1,180:0)
B(-7,24,2,180:0)
B(-7,24,3,180:0)
B(-7,24,4,180:0)
B(-7,24,5,180:0)
B(-7,24,6,180:0)
B(-7,24,7,180:0)
B(-6,0,-7,179)
B(-6,0,-6,179)
B(-6,0,-5,179)
B(-6,0,-4,179)
B(-6,0,-3,179)
B(-6,0,-2,179)
B(-6,0,-1,179)
B(-6,0,0,179)
B(-6,0,1,179)
B(-6,0,2,179)
B(-6,0,3,179)
B(-6,0,4,179)
B(-6,0,5,179)
B(-6,0,6,179)
B(-6,0,7,179)
B(-6,0,8,179)
B(-6,1,-7,179)
B(-6,1,-6,179)
B(-6,1,-5,179)
B(-6,1,-4,179)
B(-6,1,-3,179)
B(-6,1,-2,179)
B(-6,1,-1,179)
B(-6,1,0,179)
B(-6,1,1,179)
B(-6,1,2,179)
B(-6,1,3,179)
B(-6,1,4,179)
B(-6,1,5,179)
B(-6,1,6,179)
B(-6,1,7,179)
B(-6,1,8,179)
B(-6,2,-7,179)
B(-6,2,-6,179)
B(-6,2,-5,179)
B(-6,2,-4,179)
B(-6,2,-3,179)
B(-6,2,-2,179)
B(-6,2,-1,179)
B(-6,2,0,179)
B(-6,2,1,179)
B(-6,2,2,179)
B(-6,2,3,179)
B(-6,2,4,179)
B(-6,2,5,179)
B(-6,2,6,179)
B(-6,2,7,179)
B(-6,2,8,179)
B(-6,3,-7,179)
B(-6,3,-6,179)
B(-6,3,-5,179)
B(-6,3,-4,179)
B(-6,3,-3,179)
B(-6,3,-2,179)
B(-6,3,-1,179)
B(-6,3,0,179)
B(-6,3,1,179)
B(-6,3,2,179)
B(-6,3,3,179)
B(-6,3,4,179)
B(-6,3,5,179)
B(-6,3,6,179)
B(-6,3,7,179)
B(-6,3,8,179)
B(-6,4,-7,179)
B(-6,4,-6,179)
B(-6,4,-5,179)
B(-6,4,-4,179)
B(-6,4,-3,179)
B(-6,4,-2,179)
B(-6,4,-1,179)
B(-6,4,0,179)
B(-6,4,1,179)
B(-6,4,2,179)
B(-6,4,3,179)
B(-6,4,4,179)
B(-6,4,5,179)
B(-6,4,6,179)
B(-6,4,7,179)
B(-6,4,8,179)
B(-6,5,-7,179)
B(-6,5,-6,179)
B(-6,5,-5,179)
B(-6,5,-4,179)
B(-6,5,-3,179)
B(-6,5,-2,179)
B(-6,5,-1,179)
B(-6,5,0,179)
B(-6,5,1,179)
B(-6,5,2,179)
B(-6,5,3,179)
B(-6,5,4,179)
B(-6,5,5,179)
B(-6,5,6,179)
B(-6,5,7,179)
B(-6,5,8,179)
B(-6,6,-7,179)
B(-6,6,-6,179)
B(-6,6,-5,179)
B(-6,6,-4,179)
B(-6,6,-3,179)
B(-6,6,-2,179)
B(-6,6,-1,179)
B(-6,6,0,179)
B(-6,6,1,179)
B(-6,6,2,179)
B(-6,6,3,179)
B(-6,6,4,179)
B(-6,6,5,179)
B(-6,6,6,179)
B(-6,6,7,179)
B(-6,6,8,179)
B(-6,7,-7,179)
B(-6,7,-6,179)
B(-6,7,-5,179)
B(-6,7,-4,179)
B(-6,7,-3,179)
B(-6,7,-2,179)
B(-6,7,-1,179)
B(-6,7,0,179)
B(-6,7,1,179)
B(-6,7,2,179)
B(-6,7,3,179)
B(-6,7,4,179)
B(-6,7,5,179)
B(-6,7,6,179)
B(-6,7,7,179)
B(-6,7,8,179)
B(-6,8,-7,179)
B(-6,8,-6,179)
B(-6,8,-5,179)
B(-6,8,-4,179)
B(-6,8,-3,179)
B(-6,8,-2,179)
B(-6,8,-1,179)
B(-6,8,0,179)
B(-6,8,1,179)
B(-6,8,2,179)
B(-6,8,3,179)
B(-6,8,4,179)
B(-6,8,5,179)
B(-6,8,6,179)
B(-6,8,7,179)
B(-6,8,8,179)
B(-6,9,-7,179)
B(-6,9,-6,179)
B(-6,9,-5,179)
B(-6,9,-4,179)
B(-6,9,-3,179)
B(-6,9,-2,179)
B(-6,9,-1,179)
B(-6,9,0,179)
B(-6,9,1,179)
B(-6,9,2,179)
B(-6,9,3,179)
B(-6,9,4,179)
B(-6,9,5,179)
B(-6,9,6,179)
B(-6,9,7,179)
B(-6,9,8,179)
B(-6,10,-7,179)
B(-6,10,-6,179)
B(-6,10,-5,179)
B(-6,10,-4,179)
B(-6,10,-3,179)
B(-6,10,-2,179)
B(-6,10,-1,179)
B(-6,10,0,179)
B(-6,10,1,179)
B(-6,10,2,179)
B(-6,10,3,179)
B(-6,10,4,179)
B(-6,10,5,179)
B(-6,10,6,179)
B(-6,10,7,179)
B(-6,10,8,179)
B(-6,11,-7,179)
B(-6,11,-6,179)
B(-6,11,-5,179)
B(-6,11,-4,179)
B(-6,11,-3,179)
B(-6,11,-2,179)
B(-6,11,-1,179)
B(-6,11,0,179)
B(-6,11,1,179)
B(-6,11,2,179)
B(-6,11,3,179)
B(-6,11,4,179)
B(-6,11,5,179)
B(-6,11,6,179)
B(-6,11,7,179)
B(-6,11,8,179)
B(-6,12,-7,179)
B(-6,12,-6,179)
B(-6,12,-5,179)
B(-6,12,-4,179)
B(-6,12,-3,179)
B(-6,12,-2,179)
B(-6,12,-1,179)
B(-6,12,0,179)
B(-6,12,1,179)
B(-6,12,2,179)
B(-6,12,3,179)
B(-6,12,4,179)
B(-6,12,5,179)
B(-6,12,6,179)
B(-6,12,7,179)
B(-6,12,8,179)
B(-6,13,-7,179)
B(-6,13,-6,179)
B(-6,13,-5,179)
B(-6,13,-4,179)
B(-6,13,-3,179)
B(-6,13,-2,179)
B(-6,13,-1,179)
B(-6,13,0,179)
B(-6,13,1,179)
B(-6,13,2,179)
B(-6,13,3,179)
B(-6,13,4,179)
B(-6,13,5,179)
B(-6,13,6,179)
B(-6,13,7,179)
B(-6,13,8,179)
B(-6,14,-7,179)
B(-6,14,-6,179)
B(-6,14,-5,179)
B(-6,14,-4,179)
B(-6,14,-3,179)
B(-6,14,-2,179)
B(-6,14,-1,179)
B(-6,14,0,179)
B(-6,14,1,179)
B(-6,14,2,179)
B(-6,14,3,179)
B(-6,14,4,179)
B(-6,14,5,179)
B(-6,14,6,179)
B(-6,14,7,179)
B(-6,14,8,179)
B(-6,15,-7,179)
B(-6,15,-6,179)
B(-6,15,-5,179)
B(-6,15,-4,179)
B(-6,15,-3,179)
B(-6,15,-2,179)
B(-6,15,-1,179)
B(-6,15,0,179)
B(-6,15,1,179)
B(-6,15,2,179)
B(-6,15,3,179)
B(-6,15,4,179)
B(-6,15,5,179)
B(-6,15,6,179)
B(-6,15,7,179)
B(-6,15,8,179)
B(-6,16,-7,179)
B(-6,16,-6,179)
B(-6,16,-5,179)
B(-6,16,-4,179)
B(-6,16,-3,179)
B(-6,16,-2,179)
B(-6,16,-1,179)
B(-6,16,0,179)
B(-6,16,1,179)
B(-6,16,2,179)
B(-6,16,3,179)
B(-6,16,4,179)
B(-6,16,5,179)
B(-6,16,6,179)
B(-6,16,7,179)
B(-6,16,8,179)
B(-6,17,-7,179)
B(-6,17,-6,179)
B(-6,17,-5,179)
B(-6,17,-4,179)
B(-6,17,-3,179)
B(-6,17,-2,179)
B(-6,17,-1,179)
B(-6,17,0,179)
B(-6,17,1,179)
B(-6,17,2,179)
B(-6,17,3,179)
B(-6,17,4,179)
B(-6,17,5,179)
B(-6,17,6,179)
B(-6,17,7,179)
B(-6,17,8,179)
B(-6,18,-7,179)
B(-6,18,-6,179)
B(-6,18,-5,179)
B(-6,18,-4,179)
B(-6,18,-3,179)
B(-6,18,-2,179)
B(-6,18,-1,179)
B(-6,18,0,179)
B(-6,18,1,179)
B(-6,18,2,179)
B(-6,18,3,179)
B(-6,18,4,179)
B(-6,18,5,179)
B(-6,18,6,179)
B(-6,18,7,179)
B(-6,18,8,179)
B(-6,19,-7,179)
B(-6,19,-6,179)
B(-6,19,-5,179)
B(-6,19,-4,179)
B(-6,19,-3,179)
B(-6,19,-2,179)
B(-6,19,-1,179)
B(-6,19,0,179)
B(-6,19,1,179)
B(-6,19,2,179)
B(-6,19,3,179)
B(-6,19,4,179)
B(-6,19,5,179)
B(-6,19,6,179)
B(-6,19,7,179)
B(-6,19,8,179)
B(-6,20,-7,179)
B(-6,20,-6,179)
B(-6,20,-5,179)
B(-6,20,-4,179)
B(-6,20,-3,179)
B(-6,20,-2,179)
B(-6,20,-1,179)
B(-6,20,0,179)
B(-6,20,1,179)
B(-6,20,2,179)
B(-6,20,3,179)
B(-6,20,4,179)
B(-6,20,5,179)
B(-6,20,6,179)
B(-6,20,7,179)
B(-6,20,8,179)
B(-6,21,-7,179)
B(-6,21,-6,179)
B(-6,21,-5,179)
B(-6,21,-4,179)
B(-6,21,-3,179)
B(-6,21,-2,179)
B(-6,21,-1,179)
B(-6,21,0,179)
B(-6,21,1,179)
B(-6,21,2,179)
B(-6,21,3,179)
B(-6,21,4,179)
B(-6,21,5,179)
B(-6,21,6,179)
B(-6,21,7,179)
B(-6,21,8,179)
B(-6,22,-7,179)
B(-6,22,-6,179)
B(-6,22,-5,179)
B(-6,22,-4,179)
B(-6,22,-3,179)
B(-6,22,-2,179)
B(-6,22,-1,179)
B(-6,22,0,179)
B(-6,22,1,179)
B(-6,22,2,179)
B(-6,22,3,179)
B(-6,22,4,179)
B(-6,22,5,179)
B(-6,22,6,179)
B(-6,22,7,179)
B(-6,22,8,179)
B(-6,23,-7,179)
B(-6,23,-6,179)
B(-6,23,-5,179)
B(-6,23,-4,179)
B(-6,23,-3,179)
B(-6,23,-2,179)
B(-6,23,-1,179)
B(-6,23,0,179)
B(-6,23,1,179)
B(-6,23,2,179)
B(-6,23,3,179)
B(-6,23,4,179)
B(-6,23,5,179)
B(-6,23,6,179)
B(-6,23,7,179)
B(-6,23,8,179)
B(-6,24,-7,179)
B(-6,24,-6,179)
B(-6,24,-5,179)
B(-6,24,-4,179)
B(-6,24,-3,179)
B(-6,24,-2,179)
B(-6,24,-1,179)
B(-6,24,0,179)
B(-6,24,1,179)
B(-6,24,2,179)
B(-6,24,3,179)
B(-6,24,4,179)
B(-6,24,5,179)
B(-6,24,6,179)
B(-6,24,7,180:3)
B(-6,25,-7,159:14)
B(-6,25,-6,159:14)
B(-6,25,-5,159:14)
B(-6,25,-4,159:14)
B(-6,25,-3,159:14)
B(-6,25,-2,159:14)
B(-6,25,-1,159:14)
B(-6,25,0,159:14)
B(-6,25,1,159:14)
B(-6,25,2,159:14)
B(-6,25,3,159:14)
B(-6,25,4,159:14)
B(-6,25,5,159:14)
B(-6,25,6,179:2)
B(-6,26,-7,180:0)
B(-6,26,-6,180:0)
B(-6,26,-5,180:0)
B(-6,26,-4,180:0)
B(-6,26,-3,180:0)
B(-6,26,-2,180:0)
B(-6,26,-1,180:0)
B(-6,26,0,180:0)
B(-6,26,1,180:0)
B(-6,26,2,180:0)
B(-6,26,3,180:0)
B(-6,26,4,180:0)
B(-6,26,5,180:0)
B(-6,26,6,180:0)
B(-5,0,-7,179)
B(-5,0,-6,179)
B(-5,0,-5,179)
B(-5,0,-4,179)
B(-5,0,-3,179)
B(-5,0,-2,179)
B(-5,0,-1,179)
B(-5,0,0,179)
B(-5,0,1,179)
B(-5,0,2,179)
B(-5,0,3,179)
B(-5,0,4,179)
B(-5,0,5,179)
B(-5,0,6,179)
B(-5,0,7,179)
B(-5,0,8,179)
B(-5,1,-7,179)
B(-5,1,-6,179)
B(-5,1,-5,179)
B(-5,1,-4,179)
B(-5,1,-3,179)
B(-5,1,-2,179)
B(-5,1,-1,179)
B(-5,1,0,179)
B(-5,1,1,179)
B(-5,1,2,179)
B(-5,1,3,179)
B(-5,1,4,179)
B(-5,1,5,179)
B(-5,1,6,179)
B(-5,1,7,179)
B(-5,1,8,179)
B(-5,2,-7,179)
B(-5,2,-6,179)
B(-5,2,-5,179)
B(-5,2,-4,179)
B(-5,2,-3,179)
B(-5,2,-2,179)
B(-5,2,-1,179)
B(-5,2,0,179)
B(-5,2,1,179)
B(-5,2,2,179)
B(-5,2,3,179)
B(-5,2,4,179)
B(-5,2,5,179)
B(-5,2,6,179)
B(-5,2,7,179)
B(-5,2,8,179)
B(-5,3,-7,179)
B(-5,3,-6,179)
B(-5,3,-5,179)
B(-5,3,-4,179)
B(-5,3,-3,179)
B(-5,3,-2,179)
B(-5,3,-1,179)
B(-5,3,0,179)
B(-5,3,1,179)
B(-5,3,2,179)
B(-5,3,3,179)
B(-5,3,4,179)
B(-5,3,5,179)
B(-5,3,6,179)
B(-5,3,7,179)
B(-5,3,8,179)
B(-5,4,-7,179)
B(-5,4,-6,179)
B(-5,4,-5,179)
B(-5,4,-4,179)
B(-5,4,-3,179)
B(-5,4,-2,179)
B(-5,4,-1,179)
B(-5,4,0,179)
B(-5,4,1,179)
B(-5,4,2,179)
B(-5,4,3,179)
B(-5,4,4,179)
B(-5,4,5,179)
B(-5,4,6,179)
B(-5,4,7,179)
B(-5,4,8,179)
B(-5,5,-7,179)
B(-5,5,-6,179)
B(-5,5,-5,179)
B(-5,5,-4,179)
B(-5,5,-3,179)
B(-5,5,-2,179)
B(-5,5,-1,179)
B(-5,5,0,179)
B(-5,5,1,179)
B(-5,5,2,179)
B(-5,5,3,179)
B(-5,5,4,179)
B(-5,5,5,179)
B(-5,5,6,179)
B(-5,5,7,179)
B(-5,5,8,179)
B(-5,6,-7,179)
B(-5,6,-6,179)
B(-5,6,-5,179)
B(-5,6,-4,179)
B(-5,6,-3,179)
B(-5,6,-2,179)
B(-5,6,-1,179)
B(-5,6,0,179)
B(-5,6,1,179)
B(-5,6,2,179)
B(-5,6,3,179)
B(-5,6,4,179)
B(-5,6,5,179)
B(-5,6,6,179)
B(-5,6,7,179)
B(-5,6,8,179)
B(-5,7,-7,179)
B(-5,7,-6,179)
B(-5,7,-5,179)
B(-5,7,-4,179)
B(-5,7,-3,179)
B(-5,7,-2,179)
B(-5,7,-1,179)
B(-5,7,0,179)
B(-5,7,1,179)
B(-5,7,2,179)
B(-5,7,3,179)
B(-5,7,4,179)
B(-5,7,5,179)
B(-5,7,6,179)
B(-5,7,7,179)
B(-5,7,8,179)
B(-5,8,-7,179)
B(-5,8,-6,179)
B(-5,8,-5,179)
B(-5,8,-4,179)
B(-5,8,-3,179)
B(-5,8,-2,179)
B(-5,8,-1,179)
B(-5,8,0,179)
B(-5,8,1,179)
B(-5,8,2,179)
B(-5,8,3,179)
B(-5,8,4,179)
B(-5,8,5,179)
B(-5,8,6,179)
B(-5,8,7,179)
B(-5,8,8,179)
B(-5,9,-7,179)
B(-5,9,-6,179)
B(-5,9,-5,179)
B(-5,9,-4,179)
B(-5,9,-3,179)
B(-5,9,-2,179)
B(-5,9,-1,179)
B(-5,9,0,179)
B(-5,9,1,179)
B(-5,9,2,179)
B(-5,9,3,179)
B(-5,9,4,179)
B(-5,9,5,179)
B(-5,9,6,179)
B(-5,9,7,179)
B(-5,9,8,179)
B(-5,10,-7,179)
B(-5,10,-6,179)
B(-5,10,-5,179)
B(-5,10,-4,179)
B(-5,10,-3,179)
B(-5,10,-2,179)
B(-5,10,-1,179)
B(-5,10,0,179)
B(-5,10,1,179)
B(-5,10,2,179)
B(-5,10,3,179)
B(-5,10,4,179)
B(-5,10,5,179)
B(-5,10,6,179)
B(-5,10,7,179)
B(-5,10,8,179)
B(-5,11,-7,179)
B(-5,11,-6,179)
B(-5,11,-5,179)
B(-5,11,-4,179)
B(-5,11,-3,179)
B(-5,11,-2,179)
B(-5,11,-1,179)
B(-5,11,0,179)
B(-5,11,1,179)
B(-5,11,2,179)
B(-5,11,3,179)
B(-5,11,4,179)
B(-5,11,5,179)
B(-5,11,6,179)
B(-5,11,7,179)
B(-5,11,8,179)
B(-5,12,-7,179)
B(-5,12,-6,179)
B(-5,12,-5,179)
B(-5,12,-4,179)
B(-5,12,-3,179)
B(-5,12,-2,179)
B(-5,12,-1,179)
B(-5,12,0,179)
B(-5,12,1,179)
B(-5,12,2,179)
B(-5,12,3,179)
B(-5,12,4,179)
B(-5,12,5,179)
B(-5,12,6,179)
B(-5,12,7,179)
B(-5,12,8,179)
B(-5,13,-7,87)
B(-5,13,-6,87)
B(-5,13,-5,179)
B(-5,13,-4,179)
B(-5,13,-3,179)
B(-5,13,-2,87)
B(-5,13,-1,87)
B(-5,13,0,179)
B(-5,13,1,179)
B(-5,13,2,179)
B(-5,13,3,179)
B(-5,13,4,179)
B(-5,13,5,179)
B(-5,13,6,179)
B(-5,13,7,179)
B(-5,13,8,179)
B(-5,14,-7,51:15)
B(-5,14,-6,51:15)
B(-5,14,-5,AIR)
B(-5,14,-4,179)
B(-5,14,-3,AIR)
B(-5,14,-2,51:15)
B(-5,14,-1,51:15)
B(-5,14,0,AIR)
B(-5,14,1,179)
B(-5,14,2,179)
B(-5,14,3,179)
B(-5,14,4,179)
B(-5,14,5,179)
B(-5,14,6,179)
B(-5,14,7,179)
B(-5,14,8,179)
B(-5,15,-7,AIR)
B(-5,15,-6,AIR)
B(-5,15,-5,AIR)
B(-5,15,-4,179)
B(-5,15,-3,AIR)
B(-5,15,-2,AIR)
B(-5,15,-1,AIR)
B(-5,15,0,AIR)
B(-5,15,1,179)
B(-5,15,2,179)
B(-5,15,3,179)
B(-5,15,4,179)
B(-5,15,5,179)
B(-5,15,6,179)
B(-5,15,7,179)
B(-5,15,8,179)
B(-5,16,-7,AIR)
B(-5,16,-6,AIR)
B(-5,16,-5,180:6)
B(-5,16,-4,179)
B(-5,16,-3,180:7)
B(-5,16,-2,AIR)
B(-5,16,-1,AIR)
B(-5,16,0,180:6)
B(-5,16,1,179)
B(-5,16,2,179)
B(-5,16,3,179)
B(-5,16,4,179)
B(-5,16,5,179)
B(-5,16,6,179)
B(-5,16,7,179)
B(-5,16,8,179)
B(-5,17,-7,180:7)
B(-5,17,-6,180:6)
B(-5,17,-5,179)
B(-5,17,-4,179)
B(-5,17,-3,179)
B(-5,17,-2,180:7)
B(-5,17,-1,180:6)
B(-5,17,0,179)
B(-5,17,1,179)
B(-5,17,2,179)
B(-5,17,3,179)
B(-5,17,4,179)
B(-5,17,5,179)
B(-5,17,6,179)
B(-5,17,7,179)
B(-5,17,8,179)
B(-5,18,-7,179)
B(-5,18,-6,179)
B(-5,18,-5,179)
B(-5,18,-4,179)
B(-5,18,-3,179)
B(-5,18,-2,179)
B(-5,18,-1,179)
B(-5,18,0,179)
B(-5,18,1,179)
B(-5,18,2,179)
B(-5,18,3,179)
B(-5,18,4,179)
B(-5,18,5,179)
B(-5,18,6,179)
B(-5,18,7,179)
B(-5,18,8,179)
B(-5,19,-7,179)
B(-5,19,-6,179)
B(-5,19,-5,179)
B(-5,19,-4,179)
B(-5,19,-3,179)
B(-5,19,-2,179)
B(-5,19,-1,179)
B(-5,19,0,179)
B(-5,19,1,179)
B(-5,19,2,179)
B(-5,19,3,179)
B(-5,19,4,179)
B(-5,19,5,179)
B(-5,19,6,179)
B(-5,19,7,179)
B(-5,19,8,179)
B(-5,20,-7,179)
B(-5,20,-6,179)
B(-5,20,-5,179)
B(-5,20,-4,179)
B(-5,20,-3,179)
B(-5,20,-2,179)
B(-5,20,-1,179)
B(-5,20,0,179)
B(-5,20,1,179)
B(-5,20,2,179)
B(-5,20,3,179)
B(-5,20,4,179)
B(-5,20,5,179)
B(-5,20,6,179)
B(-5,20,7,179)
B(-5,20,8,179)
B(-5,21,-7,179)
B(-5,21,-6,179)
B(-5,21,-5,179)
B(-5,21,-4,179)
B(-5,21,-3,179)
B(-5,21,-2,179)
B(-5,21,-1,179)
B(-5,21,0,179)
B(-5,21,1,179)
B(-5,21,2,179)
B(-5,21,3,179)
B(-5,21,4,179)
B(-5,21,5,179)
B(-5,21,6,179)
B(-5,21,7,179)
B(-5,21,8,179)
B(-5,22,-7,179)
B(-5,22,-6,179)
B(-5,22,-5,179)
B(-5,22,-4,179)
B(-5,22,-3,179)
B(-5,22,-2,179)
B(-5,22,-1,179)
B(-5,22,0,179)
B(-5,22,1,179)
B(-5,22,2,179)
B(-5,22,3,179)
B(-5,22,4,179)
B(-5,22,5,179)
B(-5,22,6,179)
B(-5,22,7,179)
B(-5,22,8,179)
B(-5,23,-7,179)
B(-5,23,-6,179)
B(-5,23,-5,179)
B(-5,23,-4,179)
B(-5,23,-3,179)
B(-5,23,-2,179)
B(-5,23,-1,179)
B(-5,23,0,179)
B(-5,23,1,179)
B(-5,23,2,179)
B(-5,23,3,179)
B(-5,23,4,179)
B(-5,23,5,179)
B(-5,23,6,179)
B(-5,23,7,179)
B(-5,23,8,179)
B(-5,24,-7,179)
B(-5,24,-6,179)
B(-5,24,-5,179)
B(-5,24,-4,179)
B(-5,24,-3,179)
B(-5,24,-2,179)
B(-5,24,-1,179)
B(-5,24,0,179)
B(-5,24,1,179)
B(-5,24,2,179)
B(-5,24,3,179)
B(-5,24,4,179)
B(-5,24,5,179)
B(-5,24,6,179)
B(-5,24,7,180:3)
B(-5,25,-7,159:14)
B(-5,25,-6,159:14)
B(-5,25,-5,159:14)
B(-5,25,-4,159:14)
B(-5,25,-3,159:14)
B(-5,25,-2,159:14)
B(-5,25,-1,159:14)
B(-5,25,0,159:14)
B(-5,25,1,159:14)
B(-5,25,2,159:14)
B(-5,25,3,159:14)
B(-5,25,4,159:14)
B(-5,25,5,159:14)
B(-5,25,6,159:14)
B(-5,26,-7,179)
B(-5,26,-6,159:14)
B(-5,26,-5,179)
B(-5,26,-4,159:14)
B(-5,26,-3,179)
B(-5,26,-2,159:14)
B(-5,26,-1,179)
B(-5,26,0,159:14)
B(-5,26,1,179)
B(-5,26,2,179)
B(-5,26,3,159:14)
B(-5,26,4,179)
B(-5,26,5,179)
B(-5,26,6,180:3)
B(-5,27,-7,182)
B(-5,27,-5,182)
B(-5,27,-3,182)
B(-5,27,-1,182)
B(-5,27,1,182)
B(-5,27,2,182)
B(-5,27,4,182)
B(-5,27,5,179)
B(-5,28,5,179)
B(-5,29,5,179:1)
B(-4,0,-7,179)
B(-4,0,-6,179)
B(-4,0,-5,179)
B(-4,0,-4,179)
B(-4,0,-3,179)
B(-4,0,-2,179)
B(-4,0,-1,179)
B(-4,0,0,179)
B(-4,0,1,179)
B(-4,0,2,179)
B(-4,0,3,179)
B(-4,0,4,179)
B(-4,0,5,179)
B(-4,0,6,179)
B(-4,0,7,179)
B(-4,0,8,179)
B(-4,1,-7,179)
B(-4,1,-6,179)
B(-4,1,-5,179)
B(-4,1,-4,179)
B(-4,1,-3,179)
B(-4,1,-2,179)
B(-4,1,-1,179)
B(-4,1,0,179)
B(-4,1,1,179)
B(-4,1,2,179)
B(-4,1,3,179)
B(-4,1,4,179)
B(-4,1,5,179)
B(-4,1,6,179)
B(-4,1,7,179)
B(-4,1,8,179)
B(-4,2,-7,179)
B(-4,2,-6,179)
B(-4,2,-5,179)
B(-4,2,-4,179)
B(-4,2,-3,179)
B(-4,2,-2,179)
B(-4,2,-1,179)
B(-4,2,0,179)
B(-4,2,1,179)
B(-4,2,2,179)
B(-4,2,3,179)
B(-4,2,4,179)
B(-4,2,5,179)
B(-4,2,6,179)
B(-4,2,7,179)
B(-4,2,8,179)
B(-4,3,-7,179)
B(-4,3,-6,179)
B(-4,3,-5,179)
B(-4,3,-4,179)
B(-4,3,-3,179)
B(-4,3,-2,179)
B(-4,3,-1,179)
B(-4,3,0,179)
B(-4,3,1,179)
B(-4,3,2,179)
B(-4,3,3,179)
B(-4,3,4,179)
B(-4,3,5,179)
B(-4,3,6,179)
B(-4,3,7,179)
B(-4,3,8,179)
B(-4,4,-7,179)
B(-4,4,-6,179)
B(-4,4,-5,179)
B(-4,4,-4,179)
B(-4,4,-3,179)
B(-4,4,-2,179)
B(-4,4,-1,179)
B(-4,4,0,179)
B(-4,4,1,179)
B(-4,4,2,179)
B(-4,4,3,179)
B(-4,4,4,179)
B(-4,4,5,179)
B(-4,4,6,179)
B(-4,4,7,179)
B(-4,4,8,179)
B(-4,5,-7,179)
B(-4,5,-6,179)
B(-4,5,-5,179)
B(-4,5,-4,179)
B(-4,5,-3,179)
B(-4,5,-2,179)
B(-4,5,-1,179)
B(-4,5,0,179)
B(-4,5,1,179)
B(-4,5,2,179)
B(-4,5,3,179)
B(-4,5,4,179)
B(-4,5,5,179)
B(-4,5,6,179)
B(-4,5,7,179)
B(-4,5,8,179)
B(-4,6,-7,179)
B(-4,6,-6,179)
B(-4,6,-5,179)
B(-4,6,-4,179)
B(-4,6,-3,179)
B(-4,6,-2,179)
B(-4,6,-1,179)
B(-4,6,0,179)
B(-4,6,1,179)
B(-4,6,2,179)
B(-4,6,3,179)
B(-4,6,4,179)
B(-4,6,5,179)
B(-4,6,6,179)
B(-4,6,7,179)
B(-4,6,8,179)
B(-4,7,-7,159:14)
B(-4,7,-6,159:14)
B(-4,7,-5,159:14)
B(-4,7,-4,159:14)
B(-4,7,-3,159:14)
B(-4,7,-2,159:14)
B(-4,7,-1,179)
B(-4,7,0,179)
B(-4,7,1,179)
B(-4,7,2,179)
B(-4,7,3,179)
B(-4,7,4,179)
B(-4,7,5,179)
B(-4,7,6,179)
B(-4,7,7,179)
B(-4,7,8,179)
B(-4,8,-7,159:14)
B(-4,8,-6,159:14)
B(-4,8,-5,159:14)
B(-4,8,-4,159:14)
B(-4,8,-3,159:14)
B(-4,8,-2,159:14)
B(-4,8,-1,179)
B(-4,8,0,179)
B(-4,8,1,179)
B(-4,8,2,179)
B(-4,8,3,179)
B(-4,8,4,179)
B(-4,8,5,179)
B(-4,8,6,179)
B(-4,8,7,179)
B(-4,8,8,179)
B(-4,9,-7,159:14)
B(-4,9,-6,159:14)
B(-4,9,-5,159:14)
B(-4,9,-4,159:14)
B(-4,9,-3,159:14)
B(-4,9,-2,159:14)
B(-4,9,-1,179)
B(-4,9,0,179)
B(-4,9,1,179)
B(-4,9,2,179)
B(-4,9,3,179)
B(-4,9,4,179)
B(-4,9,5,179)
B(-4,9,6,179)
B(-4,9,7,179)
B(-4,9,8,179)
B(-4,10,-7,159:14)
B(-4,10,-6,159:14)
B(-4,10,-5,159:14)
B(-4,10,-4,159:14)
B(-4,10,-3,159:14)
B(-4,10,-2,159:14)
B(-4,10,-1,179)
B(-4,10,0,179)
B(-4,10,1,179)
B(-4,10,2,179)
B(-4,10,3,179)
B(-4,10,4,179)
B(-4,10,5,179)
B(-4,10,6,179)
B(-4,10,7,179)
B(-4,10,8,179)
B(-4,11,-7,159:14)
B(-4,11,-6,159:14)
B(-4,11,-5,159:14)
B(-4,11,-4,159:14)
B(-4,11,-3,159:14)
B(-4,11,-2,159:14)
B(-4,11,-1,179)
B(-4,11,0,179)
B(-4,11,1,179)
B(-4,11,2,179)
B(-4,11,3,179)
B(-4,11,4,179)
B(-4,11,5,179)
B(-4,11,6,179)
B(-4,11,7,179)
B(-4,11,8,179)
B(-4,12,-7,179)
B(-4,12,-6,179)
B(-4,12,-5,179)
B(-4,12,-4,179)
B(-4,12,-3,179)
B(-4,12,-2,179)
B(-4,12,-1,179)
B(-4,12,0,179)
B(-4,12,1,179)
B(-4,12,2,179)
B(-4,12,3,179)
B(-4,12,4,179)
B(-4,12,5,179)
B(-4,12,6,179)
B(-4,12,7,179)
B(-4,12,8,179)
B(-4,13,-7,179)
B(-4,13,-6,179)
B(-4,13,-5,179)
B(-4,13,-4,179)
B(-4,13,-3,179)
B(-4,13,-2,179)
B(-4,13,-1,179)
B(-4,13,0,179)
B(-4,13,1,179)
B(-4,13,2,179)
B(-4,13,3,179)
B(-4,13,4,179)
B(-4,13,5,179)
B(-4,13,6,179)
B(-4,13,7,179)
B(-4,13,8,179)
B(-4,14,-7,AIR)
B(-4,14,-6,AIR)
B(-4,14,-5,AIR)
B(-4,14,-4,179)
B(-4,14,-3,AIR)
B(-4,14,-2,AIR)
B(-4,14,-1,AIR)
B(-4,14,0,AIR)
B(-4,14,1,179)
B(-4,14,2,AIR)
B(-4,14,3,AIR)
B(-4,14,4,AIR)
B(-4,14,5,179)
B(-4,14,6,179)
B(-4,14,7,179)
B(-4,14,8,179)
B(-4,15,-7,AIR)
B(-4,15,-6,AIR)
B(-4,15,-5,AIR)
B(-4,15,-4,179)
B(-4,15,-3,AIR)
B(-4,15,-2,AIR)
B(-4,15,-1,AIR)
B(-4,15,0,AIR)
B(-4,15,1,179)
B(-4,15,2,AIR)
B(-4,15,3,AIR)
B(-4,15,4,AIR)
B(-4,15,5,179)
B(-4,15,6,179)
B(-4,15,7,179)
B(-4,15,8,179)
B(-4,16,-7,AIR)
B(-4,16,-6,AIR)
B(-4,16,-5,180:6)
B(-4,16,-4,179)
B(-4,16,-3,180:7)
B(-4,16,-2,AIR)
B(-4,16,-1,AIR)
B(-4,16,0,180:6)
B(-4,16,1,179)
B(-4,16,2,180:7)
B(-4,16,3,AIR)
B(-4,16,4,AIR)
B(-4,16,5,179)
B(-4,16,6,179)
B(-4,16,7,179)
B(-4,16,8,179)
B(-4,17,-7,180:7)
B(-4,17,-6,180:6)
B(-4,17,-5,179)
B(-4,17,-4,179)
B(-4,17,-3,179)
B(-4,17,-2,180:7)
B(-4,17,-1,180:6)
B(-4,17,0,179)
B(-4,17,1,179)
B(-4,17,2,179)
B(-4,17,3,180:7)
B(-4,17,4,180:6)
B(-4,17,5,179)
B(-4,17,6,179)
B(-4,17,7,179)
B(-4,17,8,179)
B(-4,18,-7,179)
B(-4,18,-6,179)
B(-4,18,-5,179)
B(-4,18,-4,179)
B(-4,18,-3,179)
B(-4,18,-2,179)
B(-4,18,-1,179)
B(-4,18,0,179)
B(-4,18,1,179)
B(-4,18,2,179)
B(-4,18,3,179)
B(-4,18,4,179)
B(-4,18,5,179)
B(-4,18,6,179)
B(-4,18,7,179)
B(-4,18,8,179)
B(-4,19,-7,179)
B(-4,19,-6,179)
B(-4,19,-5,179)
B(-4,19,-4,179)
B(-4,19,-3,179)
B(-4,19,-2,179)
B(-4,19,-1,179)
B(-4,19,0,179)
B(-4,19,1,179)
B(-4,19,2,179)
B(-4,19,3,179)
B(-4,19,4,179)
B(-4,19,5,179)
B(-4,19,6,179)
B(-4,19,7,179)
B(-4,19,8,179)
B(-4,20,-7,179)
B(-4,20,-6,179)
B(-4,20,-5,179)
B(-4,20,-4,179)
B(-4,20,-3,179)
B(-4,20,-2,179)
B(-4,20,-1,179)
B(-4,20,0,179)
B(-4,20,1,179)
B(-4,20,2,179)
B(-4,20,3,179)
B(-4,20,4,179)
B(-4,20,5,179)
B(-4,20,6,179)
B(-4,20,7,179)
B(-4,20,8,179)
B(-4,21,-7,179)
B(-4,21,-6,179)
B(-4,21,-5,179)
B(-4,21,-4,179:2)
B(-4,21,-3,AIR)
B(-4,21,-2,AIR)
B(-4,21,-1,179:2)
B(-4,21,0,AIR)
B(-4,21,1,AIR)
B(-4,21,2,AIR)
B(-4,21,3,179:2)
B(-4,21,4,AIR)
B(-4,21,5,AIR)
B(-4,21,6,179:2)
B(-4,21,7,179)
B(-4,21,8,179)
B(-4,22,-7,179)
B(-4,22,-6,179)
B(-4,22,-5,179)
B(-4,22,-4,159:1)
B(-4,22,-3,AIR)
B(-4,22,-2,AIR)
B(-4,22,-1,159:1)
B(-4,22,0,AIR)
B(-4,22,1,AIR)
B(-4,22,2,AIR)
B(-4,22,3,159:1)
B(-4,22,4,AIR)
B(-4,22,5,AIR)
B(-4,22,6,159:1)
B(-4,22,7,179)
B(-4,22,8,179)
B(-4,23,-7,179)
B(-4,23,-6,179)
B(-4,23,-5,179)
B(-4,23,-4,159:1)
B(-4,23,-3,AIR)
B(-4,23,-2,AIR)
B(-4,23,-1,159:1)
B(-4,23,0,AIR)
B(-4,23,1,AIR)
B(-4,23,2,AIR)
B(-4,23,3,159:1)
B(-4,23,4,AIR)
B(-4,23,5,AIR)
B(-4,23,6,159:1)
B(-4,23,7,179)
B(-4,23,8,179)
B(-4,24,-7,179)
B(-4,24,-6,179)
B(-4,24,-5,179)
B(-4,24,-4,179:1)
B(-4,24,-3,180:5)
B(-4,24,-2,180:5)
B(-4,24,-1,179:1)
B(-4,24,0,180:5)
B(-4,24,1,180:5)
B(-4,24,2,180:5)
B(-4,24,3,179:1)
B(-4,24,4,180:5)
B(-4,24,5,180:5)
B(-4,24,6,179:1)
B(-4,24,7,180:3)
B(-4,25,-7,179)
B(-4,25,-6,179)
B(-4,25,-5,179)
B(-4,25,-4,179)
B(-4,25,-3,179)
B(-4,25,-2,179)
B(-4,25,-1,179)
B(-4,25,0,179)
B(-4,25,1,179)
B(-4,25,2,179)
B(-4,25,3,179)
B(-4,25,4,179)
B(-4,25,5,159:14)
B(-4,25,6,159:14)
B(-4,26,-7,179)
B(-4,26,-6,179)
B(-4,26,-5,179)
B(-4,26,-4,179)
B(-4,26,-3,179)
B(-4,26,-2,179)
B(-4,26,-1,179)
B(-4,26,0,179)
B(-4,26,1,179)
B(-4,26,2,179)
B(-4,26,3,179)
B(-4,26,4,179)
B(-4,26,5,179)
B(-4,26,6,180:3)
B(-4,27,-7,182)
B(-4,27,-6,182)
B(-4,27,-5,182)
B(-4,27,-4,182)
B(-4,27,-3,182)
B(-4,27,-2,182)
B(-4,27,-1,182)
B(-4,27,0,182)
B(-4,27,1,182)
B(-4,27,2,182)
B(-4,27,3,182)
B(-4,27,4,182)
B(-4,27,5,182)
B(-3,0,-7,179)
B(-3,0,-6,179)
B(-3,0,-5,179)
B(-3,0,-4,179)
B(-3,0,-3,179)
B(-3,0,-2,179)
B(-3,0,-1,179)
B(-3,0,0,179)
B(-3,0,1,179)
B(-3,0,2,179)
B(-3,0,3,179)
B(-3,0,4,179)
B(-3,0,5,179)
B(-3,0,6,179)
B(-3,0,7,179)
B(-3,0,8,179)
B(-3,1,-7,24)
B(-3,1,-6,179)
B(-3,1,-5,179)
B(-3,1,-4,179)
B(-3,1,-3,179)
B(-3,1,-2,179)
B(-3,1,-1,179)
B(-3,1,0,179)
B(-3,1,1,9)
B(-3,1,2,9)
B(-3,1,3,179)
B(-3,1,4,179)
B(-3,1,5,179)
B(-3,1,6,179)
B(-3,1,7,179)
B(-3,1,8,179)
B(-3,2,-7,24)
B(-3,2,-6,179)
B(-3,2,-5,179)
B(-3,2,-4,179)
B(-3,2,-3,179)
B(-3,2,-2,179)
B(-3,2,-1,179)
B(-3,2,0,179)
B(-3,2,1,AIR)
B(-3,2,2,AIR)
B(-3,2,3,179)
B(-3,2,4,179)
B(-3,2,5,179)
B(-3,2,6,179)
B(-3,2,7,179)
B(-3,2,8,179)
B(-3,3,-7,24)
B(-3,3,-6,179)
B(-3,3,-5,179)
B(-3,3,-4,179)
B(-3,3,-3,179)
B(-3,3,-2,179)
B(-3,3,-1,179)
B(-3,3,0,179)
B(-3,3,1,AIR)
B(-3,3,2,AIR)
B(-3,3,3,179)
B(-3,3,4,179)
B(-3,3,5,179)
B(-3,3,6,179)
B(-3,3,7,179)
B(-3,3,8,179)
B(-3,4,-7,179)
B(-3,4,-6,179)
B(-3,4,-5,179)
B(-3,4,-4,179)
B(-3,4,-3,179)
B(-3,4,-2,179)
B(-3,4,-1,179)
B(-3,4,0,179)
B(-3,4,1,AIR)
B(-3,4,2,AIR)
B(-3,4,3,179)
B(-3,4,4,179)
B(-3,4,5,179)
B(-3,4,6,179)
B(-3,4,7,179)
B(-3,4,8,179)
B(-3,5,-7,179)
B(-3,5,-6,179)
B(-3,5,-5,179)
B(-3,5,-4,179)
B(-3,5,-3,179)
B(-3,5,-2,179)
B(-3,5,-1,179)
B(-3,5,0,179)
B(-3,5,1,AIR)
B(-3,5,2,AIR)
B(-3,5,3,179)
B(-3,5,4,179)
B(-3,5,5,179)
B(-3,5,6,179)
B(-3,5,7,179)
B(-3,5,8,179)
B(-3,6,-7,179)
B(-3,6,-6,179)
B(-3,6,-5,179)
B(-3,6,-4,179)
B(-3,6,-3,179)
B(-3,6,-2,179)
B(-3,6,-1,179)
B(-3,6,0,179)
B(-3,6,1,AIR)
B(-3,6,2,AIR)
B(-3,6,3,179)
B(-3,6,4,179)
B(-3,6,5,179)
B(-3,6,6,179)
B(-3,6,7,179)
B(-3,6,8,179)
B(-3,7,-7,180:3)
B(-3,7,-6,180:2)
B(-3,7,-5,179)
B(-3,7,-4,179)
B(-3,7,-3,180:3)
B(-3,7,-2,180:2)
B(-3,7,-1,179)
B(-3,7,0,179)
B(-3,7,1,AIR)
B(-3,7,2,AIR)
B(-3,7,3,179)
B(-3,7,4,179)
B(-3,7,5,179)
B(-3,7,6,179)
B(-3,7,7,179)
B(-3,7,8,179)
B(-3,8,-7,AIR)
B(-3,8,-6,AIR)
B(-3,8,-5,179)
B(-3,8,-4,179)
B(-3,8,-3,AIR)
B(-3,8,-2,AIR)
B(-3,8,-1,179)
B(-3,8,0,179)
B(-3,8,1,AIR)
B(-3,8,2,AIR)
B(-3,8,3,179)
B(-3,8,4,179)
B(-3,8,5,179)
B(-3,8,6,179)
B(-3,8,7,179)
B(-3,8,8,179)
B(-3,9,-7,AIR)
B(-3,9,-6,AIR)
B(-3,9,-5,179)
B(-3,9,-4,179)
B(-3,9,-3,AIR)
B(-3,9,-2,AIR)
B(-3,9,-1,179)
B(-3,9,0,179)
B(-3,9,1,AIR)
B(-3,9,2,AIR)
B(-3,9,3,179)
B(-3,9,4,179)
B(-3,9,5,179)
B(-3,9,6,179)
B(-3,9,7,179)
B(-3,9,8,179)
B(-3,10,-7,AIR)
B(-3,10,-6,AIR)
B(-3,10,-5,179)
B(-3,10,-4,179)
B(-3,10,-3,AIR)
B(-3,10,-2,AIR)
B(-3,10,-1,179)
B(-3,10,0,179)
B(-3,10,1,AIR)
B(-3,10,2,AIR)
B(-3,10,3,179)
B(-3,10,4,179)
B(-3,10,5,179)
B(-3,10,6,179)
B(-3,10,7,179)
B(-3,10,8,179)
B(-3,11,-7,180:7)
B(-3,11,-6,180:6)
B(-3,11,-5,179)
B(-3,11,-4,179)
B(-3,11,-3,180:7)
B(-3,11,-2,180:6)
B(-3,11,-1,179)
B(-3,11,0,179)
B(-3,11,1,179)
B(-3,11,2,179)
B(-3,11,3,179)
B(-3,11,4,179)
B(-3,11,5,179)
B(-3,11,6,179)
B(-3,11,7,179)
B(-3,11,8,179)
B(-3,12,-7,179)
B(-3,12,-6,179)
B(-3,12,-5,179)
B(-3,12,-4,179)
B(-3,12,-3,179)
B(-3,12,-2,179)
B(-3,12,-1,179)
B(-3,12,0,179)
B(-3,12,1,179)
B(-3,12,2,179)
B(-3,12,3,179)
B(-3,12,4,179)
B(-3,12,5,179)
B(-3,12,6,179)
B(-3,12,7,179)
B(-3,12,8,179)
B(-3,13,-7,180:1)
B(-3,13,-6,180:1)
B(-3,13,-5,180:1)
B(-3,13,-4,180:1)
B(-3,13,-3,180:1)
B(-3,13,-2,180:1)
B(-3,13,-1,180:1)
B(-3,13,0,180:1)
B(-3,13,1,180:1)
B(-3,13,2,180:1)
B(-3,13,3,180:1)
B(-3,13,4,180:1)
B(-3,13,5,179)
B(-3,13,6,179)
B(-3,13,7,179)
B(-3,13,8,179)
B(-3,14,-7,AIR)
B(-3,14,-6,AIR)
B(-3,14,-5,AIR)
B(-3,14,-4,AIR)
B(-3,14,-3,AIR)
B(-3,14,-2,AIR)
B(-3,14,-1,AIR)
B(-3,14,0,AIR)
B(-3,14,1,AIR)
B(-3,14,2,AIR)
B(-3,14,3,AIR)
B(-3,14,4,AIR)
B(-3,14,5,179)
B(-3,14,6,179)
B(-3,14,7,179)
B(-3,14,8,179)
B(-3,15,-7,AIR)
B(-3,15,-6,AIR)
B(-3,15,-5,AIR)
B(-3,15,-4,AIR)
B(-3,15,-3,AIR)
B(-3,15,-2,AIR)
B(-3,15,-1,AIR)
B(-3,15,0,AIR)
B(-3,15,1,AIR)
B(-3,15,2,AIR)
B(-3,15,3,AIR)
B(-3,15,4,AIR)
B(-3,15,5,179)
B(-3,15,6,179)
B(-3,15,7,179)
B(-3,15,8,179)
B(-3,16,-7,AIR)
B(-3,16,-6,AIR)
B(-3,16,-5,AIR)
B(-3,16,-4,AIR)
B(-3,16,-3,AIR)
B(-3,16,-2,AIR)
B(-3,16,-1,AIR)
B(-3,16,0,AIR)
B(-3,16,1,AIR)
B(-3,16,2,AIR)
B(-3,16,3,AIR)
B(-3,16,4,AIR)
B(-3,16,5,179)
B(-3,16,6,179)
B(-3,16,7,179)
B(-3,16,8,179)
B(-3,17,-7,AIR)
B(-3,17,-6,AIR)
B(-3,17,-5,AIR)
B(-3,17,-4,AIR)
B(-3,17,-3,AIR)
B(-3,17,-2,AIR)
B(-3,17,-1,AIR)
B(-3,17,0,AIR)
B(-3,17,1,AIR)
B(-3,17,2,AIR)
B(-3,17,3,AIR)
B(-3,17,4,AIR)
B(-3,17,5,179)
B(-3,17,6,179)
B(-3,17,7,179)
B(-3,17,8,179)
B(-3,18,-7,180:5)
B(-3,18,-6,180:5)
B(-3,18,-5,180:5)
B(-3,18,-4,180:5)
B(-3,18,-3,180:5)
B(-3,18,-2,180:5)
B(-3,18,-1,180:5)
B(-3,18,0,180:5)
B(-3,18,1,180:5)
B(-3,18,2,180:5)
B(-3,18,3,180:5)
B(-3,18,4,180:5)
B(-3,18,5,179)
B(-3,18,6,179)
B(-3,18,7,179)
B(-3,18,8,179)
B(-3,19,-7,179)
B(-3,19,-6,179)
B(-3,19,-5,179)
B(-3,19,-4,179)
B(-3,19,-3,179)
B(-3,19,-2,179)
B(-3,19,-1,179)
B(-3,19,0,179)
B(-3,19,1,179)
B(-3,19,2,179)
B(-3,19,3,179)
B(-3,19,4,179)
B(-3,19,5,179)
B(-3,19,6,179)
B(-3,19,7,179)
B(-3,19,8,179)
B(-3,20,-7,179)
B(-3,20,-6,179)
B(-3,20,-5,179)
B(-3,20,-4,179)
B(-3,20,-3,179)
B(-3,20,-2,179)
B(-3,20,-1,179)
B(-3,20,0,179)
B(-3,20,1,179)
B(-3,20,2,179)
B(-3,20,3,179)
B(-3,20,4,179)
B(-3,20,5,179)
B(-3,20,6,179)
B(-3,20,7,179)
B(-3,20,8,179)
B(-3,21,-7,179)
B(-3,21,-6,179)
B(-3,21,-5,179)
B(-3,21,-4,AIR)
B(-3,21,-3,AIR)
B(-3,21,-2,AIR)
B(-3,21,-1,AIR)
B(-3,21,0,AIR)
B(-3,21,1,AIR)
B(-3,21,2,AIR)
B(-3,21,3,AIR)
B(-3,21,4,AIR)
B(-3,21,5,AIR)
B(-3,21,6,AIR)
B(-3,21,7,179)
B(-3,21,8,179)
B(-3,22,-7,179)
B(-3,22,-6,179)
B(-3,22,-5,179)
B(-3,22,-4,AIR)
B(-3,22,-3,AIR)
B(-3,22,-2,AIR)
B(-3,22,-1,AIR)
B(-3,22,0,AIR)
B(-3,22,1,AIR)
B(-3,22,2,AIR)
B(-3,22,3,AIR)
B(-3,22,4,AIR)
B(-3,22,5,AIR)
B(-3,22,6,AIR)
B(-3,22,7,179)
B(-3,22,8,179)
B(-3,23,-7,179)
B(-3,23,-6,179)
B(-3,23,-5,179)
B(-3,23,-4,AIR)
B(-3,23,-3,AIR)
B(-3,23,-2,AIR)
B(-3,23,-1,AIR)
B(-3,23,0,AIR)
B(-3,23,1,AIR)
B(-3,23,2,AIR)
B(-3,23,3,AIR)
B(-3,23,4,AIR)
B(-3,23,5,AIR)
B(-3,23,6,AIR)
B(-3,23,7,179)
B(-3,23,8,179)
B(-3,24,-7,179)
B(-3,24,-6,179)
B(-3,24,-5,179)
B(-3,24,-4,180:7)
B(-3,24,-3,AIR)
B(-3,24,-2,AIR)
B(-3,24,-1,AIR)
B(-3,24,0,AIR)
B(-3,24,1,AIR)
B(-3,24,2,AIR)
B(-3,24,3,AIR)
B(-3,24,4,AIR)
B(-3,24,5,AIR)
B(-3,24,6,180:6)
B(-3,24,7,180:3)
B(-3,25,-7,179)
B(-3,25,-6,179)
B(-3,25,-5,179)
B(-3,25,-4,179)
B(-3,25,-3,179)
B(-3,25,-2,179)
B(-3,25,-1,179)
B(-3,25,0,179)
B(-3,25,1,179)
B(-3,25,2,179)
B(-3,25,3,179)
B(-3,25,4,179)
B(-3,25,5,159:14)
B(-3,25,6,159:14)
B(-3,26,-7,179)
B(-3,26,-6,179)
B(-3,26,-5,179)
B(-3,26,-4,179)
B(-3,26,-3,179)
B(-3,26,-2,179)
B(-3,26,-1,179)
B(-3,26,0,179)
B(-3,26,1,179)
B(-3,26,2,179)
B(-3,26,3,179)
B(-3,26,4,179)
B(-3,26,5,159:14)
B(-3,26,6,180:3)
B(-3,27,-7,179)
B(-3,27,-6,179)
B(-3,27,-5,179)
B(-3,27,-4,179)
B(-3,27,-3,179)
B(-3,27,-2,179)
B(-3,27,-1,179)
B(-3,27,0,179)
B(-3,27,1,179)
B(-3,27,2,179)
B(-3,27,3,179)
B(-3,27,4,182)
B(-2,0,-7,24)
B(-2,0,-6,179)
B(-2,0,-5,179)
B(-2,0,-4,179)
B(-2,0,-3,179)
B(-2,0,-2,179)
B(-2,0,-1,179)
B(-2,0,0,179)
B(-2,0,1,179)
B(-2,0,2,179)
B(-2,0,3,179)
B(-2,0,4,179)
B(-2,0,5,179)
B(-2,0,6,179)
B(-2,0,7,179)
B(-2,0,8,179)
B(-2,1,-7,24:2)
B(-2,1,-6,24:2)
B(-2,1,-5,AIR)
B(-2,1,-4,AIR)
B(-2,1,-3,AIR)
B(-2,1,-2,AIR)
B(-2,1,-1,AIR)
B(-2,1,0,179)
B(-2,1,1,9)
B(-2,1,2,9)
B(-2,1,3,179)
B(-2,1,4,179)
B(-2,1,5,179)
B(-2,1,6,179)
B(-2,1,7,179)
B(-2,1,8,179)
B(-2,2,-7,AIR)
B(-2,2,-6,24)
B(-2,2,-5,AIR)
B(-2,2,-4,AIR)
B(-2,2,-3,AIR)
B(-2,2,-2,AIR)
B(-2,2,-1,AIR)
B(-2,2,0,AIR)
B(-2,2,1,AIR)
B(-2,2,2,AIR)
B(-2,2,3,179)
B(-2,2,4,9:9)
B(-2,2,5,179)
B(-2,2,6,179)
B(-2,2,7,179)
B(-2,2,8,179)
B(-2,3,-7,AIR)
B(-2,3,-6,24)
B(-2,3,-5,AIR)
B(-2,3,-4,AIR)
B(-2,3,-3,AIR)
B(-2,3,-2,AIR)
B(-2,3,-1,AIR)
B(-2,3,0,AIR)
B(-2,3,1,AIR)
B(-2,3,2,AIR)
B(-2,3,3,179)
B(-2,3,4,9:9)
B(-2,3,5,179)
B(-2,3,6,179)
B(-2,3,7,179)
B(-2,3,8,179)
B(-2,4,-7,24)
B(-2,4,-6,AIR)
B(-2,4,-5,AIR)
B(-2,4,-4,AIR)
B(-2,4,-3,AIR)
B(-2,4,-2,AIR)
B(-2,4,-1,AIR)
B(-2,4,0,AIR)
B(-2,4,1,AIR)
B(-2,4,2,AIR)
B(-2,4,3,AIR)
B(-2,4,4,9:9)
B(-2,4,5,179)
B(-2,4,6,179)
B(-2,4,7,179)
B(-2,4,8,179)
B(-2,5,-7,AIR)
B(-2,5,-6,AIR)
B(-2,5,-5,AIR)
B(-2,5,-4,AIR)
B(-2,5,-3,AIR)
B(-2,5,-2,AIR)
B(-2,5,-1,AIR)
B(-2,5,0,AIR)
B(-2,5,1,AIR)
B(-2,5,2,AIR)
B(-2,5,3,AIR)
B(-2,5,4,9:9)
B(-2,5,5,179)
B(-2,5,6,179)
B(-2,5,7,179)
B(-2,5,8,179)
B(-2,6,-7,AIR)
B(-2,6,-6,AIR)
B(-2,6,-5,AIR)
B(-2,6,-4,AIR)
B(-2,6,-3,AIR)
B(-2,6,-2,AIR)
B(-2,6,-1,AIR)
B(-2,6,0,AIR)
B(-2,6,1,AIR)
B(-2,6,2,AIR)
B(-2,6,3,AIR)
B(-2,6,4,9:1)
B(-2,6,5,9:9)
B(-2,6,6,179)
B(-2,6,7,179)
B(-2,6,8,179)
B(-2,7,-7,AIR)
B(-2,7,-6,AIR)
B(-2,7,-5,AIR)
B(-2,7,-4,AIR)
B(-2,7,-3,AIR)
B(-2,7,-2,AIR)
B(-2,7,-1,AIR)
B(-2,7,0,AIR)
B(-2,7,1,AIR)
B(-2,7,2,AIR)
B(-2,7,3,AIR)
B(-2,7,4,AIR)
B(-2,7,5,9:9)
B(-2,7,6,179)
B(-2,7,7,179)
B(-2,7,8,179)
B(-2,8,-7,AIR)
B(-2,8,-6,AIR)
B(-2,8,-5,AIR)
B(-2,8,-4,AIR)
B(-2,8,-3,AIR)
B(-2,8,-2,AIR)
B(-2,8,-1,AIR)
B(-2,8,0,AIR)
B(-2,8,1,AIR)
B(-2,8,2,AIR)
B(-2,8,3,AIR)
B(-2,8,4,AIR)
B(-2,8,5,9:1)
B(-2,8,6,9:9)
B(-2,8,7,179)
B(-2,8,8,179)
B(-2,9,-7,AIR)
B(-2,9,-6,AIR)
B(-2,9,-5,AIR)
B(-2,9,-4,AIR)
B(-2,9,-3,AIR)
B(-2,9,-2,AIR)
B(-2,9,-1,AIR)
B(-2,9,0,AIR)
B(-2,9,1,AIR)
B(-2,9,2,AIR)
B(-2,9,3,AIR)
B(-2,9,4,AIR)
B(-2,9,5,AIR)
B(-2,9,6,9:1)
B(-2,9,7,179)
B(-2,9,8,179)
B(-2,10,-7,AIR)
B(-2,10,-6,AIR)
B(-2,10,-5,AIR)
B(-2,10,-4,AIR)
B(-2,10,-3,AIR)
B(-2,10,-2,AIR)
B(-2,10,-1,AIR)
B(-2,10,0,AIR)
B(-2,10,1,AIR)
B(-2,10,2,AIR)
B(-2,10,3,179)
B(-2,10,4,179)
B(-2,10,5,179)
B(-2,10,6,179)
B(-2,10,7,179)
B(-2,10,8,179)
B(-2,11,-7,AIR)
B(-2,11,-6,AIR)
B(-2,11,-5,AIR)
B(-2,11,-4,AIR)
B(-2,11,-3,AIR)
B(-2,11,-2,AIR)
B(-2,11,-1,AIR)
B(-2,11,0,AIR)
B(-2,11,1,AIR)
B(-2,11,2,179)
B(-2,11,3,179)
B(-2,11,4,179)
B(-2,11,5,179)
B(-2,11,6,179)
B(-2,11,7,179)
B(-2,11,8,179)
B(-2,12,-7,AIR)
B(-2,12,-6,AIR)
B(-2,12,-5,AIR)
B(-2,12,-4,AIR)
B(-2,12,-3,AIR)
B(-2,12,-2,AIR)
B(-2,12,-1,AIR)
B(-2,12,0,AIR)
B(-2,12,1,AIR)
B(-2,12,2,179)
B(-2,12,3,179)
B(-2,12,4,179)
B(-2,12,5,179)
B(-2,12,6,179)
B(-2,12,7,179)
B(-2,12,8,179)
B(-2,13,-7,AIR)
B(-2,13,-6,AIR)
B(-2,13,-5,AIR)
B(-2,13,-4,AIR)
B(-2,13,-3,AIR)
B(-2,13,-2,AIR)
B(-2,13,-1,AIR)
B(-2,13,0,AIR)
B(-2,13,1,AIR)
B(-2,13,2,AIR)
B(-2,13,3,AIR)
B(-2,13,4,AIR)
B(-2,13,5,AIR)
B(-2,13,6,179)
B(-2,13,7,179)
B(-2,13,8,179)
B(-2,14,-7,AIR)
B(-2,14,-6,AIR)
B(-2,14,-5,AIR)
B(-2,14,-4,AIR)
B(-2,14,-3,AIR)
B(-2,14,-2,AIR)
B(-2,14,-1,AIR)
B(-2,14,0,AIR)
B(-2,14,1,AIR)
B(-2,14,2,AIR)
B(-2,14,3,AIR)
B(-2,14,4,AIR)
B(-2,14,5,AIR)
B(-2,14,6,179)
B(-2,14,7,179)
B(-2,14,8,179)
B(-2,15,-7,AIR)
B(-2,15,-6,AIR)
B(-2,15,-5,AIR)
B(-2,15,-4,AIR)
B(-2,15,-3,AIR)
B(-2,15,-2,AIR)
B(-2,15,-1,AIR)
B(-2,15,0,AIR)
B(-2,15,1,AIR)
B(-2,15,2,AIR)
B(-2,15,3,AIR)
B(-2,15,4,AIR)
B(-2,15,5,AIR)
B(-2,15,6,179)
B(-2,15,7,179)
B(-2,15,8,179)
B(-2,16,-7,AIR)
B(-2,16,-6,AIR)
B(-2,16,-5,AIR)
B(-2,16,-4,AIR)
B(-2,16,-3,AIR)
B(-2,16,-2,AIR)
B(-2,16,-1,AIR)
B(-2,16,0,AIR)
B(-2,16,1,AIR)
B(-2,16,2,AIR)
B(-2,16,3,AIR)
B(-2,16,4,AIR)
B(-2,16,5,AIR)
B(-2,16,6,179)
B(-2,16,7,179)
B(-2,16,8,179)
B(-2,17,-7,AIR)
B(-2,17,-6,AIR)
B(-2,17,-5,AIR)
B(-2,17,-4,AIR)
B(-2,17,-3,AIR)
B(-2,17,-2,AIR)
B(-2,17,-1,AIR)
B(-2,17,0,AIR)
B(-2,17,1,AIR)
B(-2,17,2,AIR)
B(-2,17,3,AIR)
B(-2,17,4,AIR)
B(-2,17,5,AIR)
B(-2,17,6,179)
B(-2,17,7,179)
B(-2,17,8,179)
B(-2,18,-7,180:4)
B(-2,18,-6,180:4)
B(-2,18,-5,180:4)
B(-2,18,-4,180:4)
B(-2,18,-3,180:4)
B(-2,18,-2,180:4)
B(-2,18,-1,180:4)
B(-2,18,0,180:4)
B(-2,18,1,180:4)
B(-2,18,2,180:4)
B(-2,18,3,180:4)
B(-2,18,4,180:4)
B(-2,18,5,180:6)
B(-2,18,6,179)
B(-2,18,7,179)
B(-2,18,8,179)
B(-2,19,-7,179)
B(-2,19,-6,179)
B(-2,19,-5,179)
B(-2,19,-4,179)
B(-2,19,-3,179)
B(-2,19,-2,179)
B(-2,19,-1,179)
B(-2,19,0,179)
B(-2,19,1,179)
B(-2,19,2,179)
B(-2,19,3,179)
B(-2,19,4,179)
B(-2,19,5,179)
B(-2,19,6,179)
B(-2,19,7,179)
B(-2,19,8,179)
B(-2,20,-7,AIR)
B(-2,20,-6,AIR)
B(-2,20,-5,179)
B(-2,20,-4,179)
B(-2,20,-3,179)
B(-2,20,-2,11)
B(-2,20,-1,11)
B(-2,20,0,11)
B(-2,20,1,11)
B(-2,20,2,11)
B(-2,20,3,11)
B(-2,20,4,11)
B(-2,20,5,179)
B(-2,20,6,179)
B(-2,20,7,179)
B(-2,20,8,179)
B(-2,21,-7,AIR)
B(-2,21,-6,AIR)
B(-2,21,-5,179)
B(-2,21,-4,AIR)
B(-2,21,-3,AIR)
B(-2,21,-2,AIR)
B(-2,21,-1,AIR)
B(-2,21,0,AIR)
B(-2,21,1,AIR)
B(-2,21,2,AIR)
B(-2,21,3,AIR)
B(-2,21,4,AIR)
B(-2,21,5,AIR)
B(-2,21,6,AIR)
B(-2,21,7,179)
B(-2,21,8,179)
B(-2,22,-7,179)
B(-2,22,-6,179)
B(-2,22,-5,179)
B(-2,22,-4,AIR)
B(-2,22,-3,AIR)
B(-2,22,-2,AIR)
B(-2,22,-1,AIR)
B(-2,22,0,AIR)
B(-2,22,1,AIR)
B(-2,22,2,AIR)
B(-2,22,3,AIR)
B(-2,22,4,AIR)
B(-2,22,5,AIR)
B(-2,22,6,AIR)
B(-2,22,7,179)
B(-2,22,8,179)
B(-2,23,-7,179)
B(-2,23,-6,AIR)
B(-2,23,-5,179)
B(-2,23,-4,AIR)
B(-2,23,-3,AIR)
B(-2,23,-2,AIR)
B(-2,23,-1,AIR)
B(-2,23,0,AIR)
B(-2,23,1,AIR)
B(-2,23,2,AIR)
B(-2,23,3,AIR)
B(-2,23,4,AIR)
B(-2,23,5,AIR)
B(-2,23,6,AIR)
B(-2,23,7,179)
B(-2,23,8,179)
B(-2,24,-7,AIR)
B(-2,24,-6,AIR)
B(-2,24,-5,179)
B(-2,24,-4,180:7)
B(-2,24,-3,AIR)
B(-2,24,-2,AIR)
B(-2,24,-1,AIR)
B(-2,24,0,AIR)
B(-2,24,1,AIR)
B(-2,24,2,AIR)
B(-2,24,3,AIR)
B(-2,24,4,AIR)
B(-2,24,5,AIR)
B(-2,24,6,180:6)
B(-2,24,7,180:3)
B(-2,25,-7,179)
B(-2,25,-6,179)
B(-2,25,-5,179)
B(-2,25,-4,179)
B(-2,25,-3,179)
B(-2,25,-2,179)
B(-2,25,-1,179)
B(-2,25,0,179)
B(-2,25,1,179)
B(-2,25,2,179)
B(-2,25,3,179)
B(-2,25,4,179)
B(-2,25,5,159:14)
B(-2,25,6,159:14)
B(-2,26,-7,179)
B(-2,26,-6,179)
B(-2,26,-5,179)
B(-2,26,-4,159:14)
B(-2,26,-3,179)
B(-2,26,-2,179)
B(-2,26,-1,179)
B(-2,26,0,179)
B(-2,26,1,179)
B(-2,26,2,179)
B(-2,26,3,179)
B(-2,26,4,179)
B(-2,26,5,179)
B(-2,26,6,180:3)
B(-2,27,-7,AIR)
B(-2,27,-6,AIR)
B(-2,27,-5,AIR)
B(-2,27,-4,AIR)
B(-2,27,-3,AIR)
B(-2,27,-2,AIR)
B(-2,27,-1,AIR)
B(-2,27,0,AIR)
B(-2,27,1,AIR)
B(-2,27,2,AIR)
B(-2,27,3,179)
B(-2,27,4,182)
B(-2,27,5,182)
B(-2,28,-7,179:2)
B(-2,28,-6,179:1)
B(-2,28,-5,179:2)
B(-2,28,-4,179:1)
B(-2,28,-3,179:2)
B(-2,28,-2,179:1)
B(-2,28,-1,179:2)
B(-2,28,0,179:1)
B(-2,28,1,179:2)
B(-2,28,2,179:2)
B(-2,29,-7,179)
B(-2,29,-6,179)
B(-2,29,-5,179)
B(-2,29,-4,179)
B(-2,29,-3,179)
B(-2,29,-2,179)
B(-2,29,-1,179)
B(-2,29,0,179)
B(-2,29,1,179)
B(-2,29,2,182)
B(-1,0,-7,24)
B(-1,0,-6,179)
B(-1,0,-5,179)
B(-1,0,-4,179)
B(-1,0,-3,179)
B(-1,0,-2,179)
B(-1,0,-1,179)
B(-1,0,0,179)
B(-1,0,1,179)
B(-1,0,2,179)
B(-1,0,3,179)
B(-1,0,4,179)
B(-1,0,5,179)
B(-1,0,6,179)
B(-1,0,7,179)
B(-1,0,8,179)
B(-1,1,-7,24)
B(-1,1,-6,AIR)
B(-1,1,-5,AIR)
B(-1,1,-4,AIR)
B(-1,1,-3,AIR)
B(-1,1,-2,AIR)
B(-1,1,-1,AIR)
B(-1,1,0,179)
B(-1,1,1,9)
B(-1,1,2,9)
B(-1,1,3,9)
B(-1,1,4,9:9)
B(-1,1,5,179)
B(-1,1,6,179)
B(-1,1,7,179)
B(-1,1,8,179)
B(-1,2,-7,24)
B(-1,2,-6,76:3)
B(-1,2,-5,AIR)
B(-1,2,-4,AIR)
B(-1,2,-3,AIR)
B(-1,2,-2,AIR)
B(-1,2,-1,AIR)
B(-1,2,0,AIR)
B(-1,2,1,AIR)
B(-1,2,2,AIR)
B(-1,2,3,AIR)
B(-1,2,4,9:9)
B(-1,2,5,179)
B(-1,2,6,179)
B(-1,2,7,179)
B(-1,2,8,179)
B(-1,3,-7,24)
B(-1,3,-6,24)
B(-1,3,-5,AIR)
B(-1,3,-4,AIR)
B(-1,3,-3,AIR)
B(-1,3,-2,AIR)
B(-1,3,-1,AIR)
B(-1,3,0,AIR)
B(-1,3,1,AIR)
B(-1,3,2,AIR)
B(-1,3,3,179)
B(-1,3,4,9:9)
B(-1,3,5,179)
B(-1,3,6,179)
B(-1,3,7,179)
B(-1,3,8,179)
B(-1,4,-7,24)
B(-1,4,-6,AIR)
B(-1,4,-5,AIR)
B(-1,4,-4,AIR)
B(-1,4,-3,AIR)
B(-1,4,-2,AIR)
B(-1,4,-1,AIR)
B(-1,4,0,AIR)
B(-1,4,1,AIR)
B(-1,4,2,AIR)
B(-1,4,3,179)
B(-1,4,4,9:9)
B(-1,4,5,179)
B(-1,4,6,179)
B(-1,4,7,179)
B(-1,4,8,179)
B(-1,5,-7,AIR)
B(-1,5,-6,AIR)
B(-1,5,-5,AIR)
B(-1,5,-4,AIR)
B(-1,5,-3,AIR)
B(-1,5,-2,AIR)
B(-1,5,-1,AIR)
B(-1,5,0,AIR)
B(-1,5,1,AIR)
B(-1,5,2,AIR)
B(-1,5,3,AIR)
B(-1,5,4,9:9)
B(-1,5,5,179)
B(-1,5,6,179)
B(-1,5,7,179)
B(-1,5,8,179)
B(-1,6,-7,AIR)
B(-1,6,-6,AIR)
B(-1,6,-5,AIR)
B(-1,6,-4,AIR)
B(-1,6,-3,AIR)
B(-1,6,-2,AIR)
B(-1,6,-1,AIR)
B(-1,6,0,AIR)
B(-1,6,1,AIR)
B(-1,6,2,AIR)
B(-1,6,3,AIR)
B(-1,6,4,9:9)
B(-1,6,5,179)
B(-1,6,6,179)
B(-1,6,7,179)
B(-1,6,8,179)
B(-1,7,-7,AIR)
B(-1,7,-6,AIR)
B(-1,7,-5,AIR)
B(-1,7,-4,AIR)
B(-1,7,-3,AIR)
B(-1,7,-2,AIR)
B(-1,7,-1,AIR)
B(-1,7,0,AIR)
B(-1,7,1,AIR)
B(-1,7,2,AIR)
B(-1,7,3,AIR)
B(-1,7,4,9:1)
B(-1,7,5,9:9)
B(-1,7,6,179)
B(-1,7,7,179)
B(-1,7,8,179)
B(-1,8,-7,AIR)
B(-1,8,-6,AIR)
B(-1,8,-5,AIR)
B(-1,8,-4,AIR)
B(-1,8,-3,AIR)
B(-1,8,-2,AIR)
B(-1,8,-1,AIR)
B(-1,8,0,AIR)
B(-1,8,1,AIR)
B(-1,8,2,AIR)
B(-1,8,3,AIR)
B(-1,8,4,AIR)
B(-1,8,5,9:9)
B(-1,8,6,179)
B(-1,8,7,179)
B(-1,8,8,179)
B(-1,9,-7,AIR)
B(-1,9,-6,AIR)
B(-1,9,-5,AIR)
B(-1,9,-4,AIR)
B(-1,9,-3,AIR)
B(-1,9,-2,AIR)
B(-1,9,-1,AIR)
B(-1,9,0,AIR)
B(-1,9,1,AIR)
B(-1,9,2,AIR)
B(-1,9,3,AIR)
B(-1,9,4,AIR)
B(-1,9,5,9:1)
B(-1,9,6,9:9)
B(-1,9,7,179)
B(-1,9,8,179)
B(-1,10,-7,AIR)
B(-1,10,-6,AIR)
B(-1,10,-5,AIR)
B(-1,10,-4,AIR)
B(-1,10,-3,AIR)
B(-1,10,-2,AIR)
B(-1,10,-1,AIR)
B(-1,10,0,AIR)
B(-1,10,1,AIR)
B(-1,10,2,AIR)
B(-1,10,3,AIR)
B(-1,10,4,AIR)
B(-1,10,5,AIR)
B(-1,10,6,9:1)
B(-1,10,7,179)
B(-1,10,8,179)
B(-1,11,-7,AIR)
B(-1,11,-6,AIR)
B(-1,11,-5,AIR)
B(-1,11,-4,AIR)
B(-1,11,-3,AIR)
B(-1,11,-2,AIR)
B(-1,11,-1,AIR)
B(-1,11,0,AIR)
B(-1,11,1,AIR)
B(-1,11,2,AIR)
B(-1,11,3,179)
B(-1,11,4,179)
B(-1,11,5,179)
B(-1,11,6,179)
B(-1,11,7,179)
B(-1,11,8,179)
B(-1,12,-7,AIR)
B(-1,12,-6,AIR)
B(-1,12,-5,AIR)
B(-1,12,-4,AIR)
B(-1,12,-3,AIR)
B(-1,12,-2,AIR)
B(-1,12,-1,AIR)
B(-1,12,0,AIR)
B(-1,12,1,AIR)
B(-1,12,2,179)
B(-1,12,3,179)
B(-1,12,4,9)
B(-1,12,5,9)
B(-1,12,6,179)
B(-1,12,7,179)
B(-1,12,8,179)
B(-1,13,-7,AIR)
B(-1,13,-6,AIR)
B(-1,13,-5,AIR)
B(-1,13,-4,AIR)
B(-1,13,-3,AIR)
B(-1,13,-2,AIR)
B(-1,13,-1,AIR)
B(-1,13,0,AIR)
B(-1,13,1,AIR)
B(-1,13,2,AIR)
B(-1,13,3,AIR)
B(-1,13,4,AIR)
B(-1,13,5,AIR)
B(-1,13,6,179)
B(-1,13,7,179)
B(-1,13,8,179)
B(-1,14,-7,AIR)
B(-1,14,-6,AIR)
B(-1,14,-5,AIR)
B(-1,14,-4,AIR)
B(-1,14,-3,AIR)
B(-1,14,-2,AIR)
B(-1,14,-1,AIR)
B(-1,14,0,AIR)
B(-1,14,1,AIR)
B(-1,14,2,AIR)
B(-1,14,3,AIR)
B(-1,14,4,AIR)
B(-1,14,5,AIR)
B(-1,14,6,179)
B(-1,14,7,179)
B(-1,14,8,179)
B(-1,15,-7,AIR)
B(-1,15,-6,AIR)
B(-1,15,-5,AIR)
B(-1,15,-4,AIR)
B(-1,15,-3,AIR)
B(-1,15,-2,AIR)
B(-1,15,-1,AIR)
B(-1,15,0,AIR)
B(-1,15,1,AIR)
B(-1,15,2,AIR)
B(-1,15,3,AIR)
B(-1,15,4,AIR)
B(-1,15,5,AIR)
B(-1,15,6,179)
B(-1,15,7,179)
B(-1,15,8,179)
B(-1,16,-7,AIR)
B(-1,16,-6,AIR)
B(-1,16,-5,AIR)
B(-1,16,-4,AIR)
B(-1,16,-3,AIR)
B(-1,16,-2,AIR)
B(-1,16,-1,AIR)
B(-1,16,0,AIR)
B(-1,16,1,AIR)
B(-1,16,2,AIR)
B(-1,16,3,AIR)
B(-1,16,4,AIR)
B(-1,16,5,AIR)
B(-1,16,6,179)
B(-1,16,7,179)
B(-1,16,8,179)
B(-1,17,-7,AIR)
B(-1,17,-6,AIR)
B(-1,17,-5,AIR)
B(-1,17,-4,AIR)
B(-1,17,-3,AIR)
B(-1,17,-2,AIR)
B(-1,17,-1,AIR)
B(-1,17,0,AIR)
B(-1,17,1,AIR)
B(-1,17,2,AIR)
B(-1,17,3,AIR)
B(-1,17,4,AIR)
B(-1,17,5,AIR)
B(-1,17,6,179)
B(-1,17,7,179)
B(-1,17,8,179)
B(-1,18,-7,159:14)
B(-1,18,-6,159:14)
B(-1,18,-5,159:14)
B(-1,18,-4,159:14)
B(-1,18,-3,159:14)
B(-1,18,-2,159:14)
B(-1,18,-1,159:14)
B(-1,18,0,180:7)
B(-1,18,1,180:5)
B(-1,18,2,180:5)
B(-1,18,3,180:5)
B(-1,18,4,180:5)
B(-1,18,5,180:6)
B(-1,18,6,179)
B(-1,18,7,179)
B(-1,18,8,179)
B(-1,19,-7,179)
B(-1,19,-6,179)
B(-1,19,-5,179)
B(-1,19,-4,179)
B(-1,19,-3,179)
B(-1,19,-2,179)
B(-1,19,-1,179)
B(-1,19,0,179)
B(-1,19,1,179)
B(-1,19,2,179)
B(-1,19,3,179)
B(-1,19,4,179)
B(-1,19,5,179)
B(-1,19,6,179)
B(-1,19,7,179)
B(-1,19,8,179)
B(-1,20,-7,AIR)
B(-1,20,-6,AIR)
B(-1,20,-5,179)
B(-1,20,-4,179:2)
B(-1,20,-3,179:2)
B(-1,20,-2,179:2)
B(-1,20,-1,179:2)
B(-1,20,0,179:2)
B(-1,20,1,179:2)
B(-1,20,2,179:2)
B(-1,20,3,179:2)
B(-1,20,4,179:2)
B(-1,20,5,179)
B(-1,20,6,179)
B(-1,20,7,179)
B(-1,20,8,179)
B(-1,21,-7,AIR)
B(-1,21,-6,AIR)
B(-1,21,-5,179)
B(-1,21,-4,159:1)
B(-1,21,-3,AIR)
B(-1,21,-2,AIR)
B(-1,21,-1,AIR)
B(-1,21,0,AIR)
B(-1,21,1,AIR)
B(-1,21,2,AIR)
B(-1,21,3,AIR)
B(-1,21,4,AIR)
B(-1,21,5,AIR)
B(-1,21,6,159:1)
B(-1,21,7,179)
B(-1,21,8,179)
B(-1,22,-7,179)
B(-1,22,-6,179)
B(-1,22,-5,179)
B(-1,22,-4,159:1)
B(-1,22,-3,AIR)
B(-1,22,-2,AIR)
B(-1,22,-1,AIR)
B(-1,22,0,AIR)
B(-1,22,1,AIR)
B(-1,22,2,AIR)
B(-1,22,3,AIR)
B(-1,22,4,AIR)
B(-1,22,5,AIR)
B(-1,22,6,159:1)
B(-1,22,7,179)
B(-1,22,8,179)
B(-1,23,-7,179)
B(-1,23,-6,179)
B(-1,23,-5,179)
B(-1,23,-4,159:1)
B(-1,23,-3,AIR)
B(-1,23,-2,AIR)
B(-1,23,-1,AIR)
B(-1,23,0,AIR)
B(-1,23,1,AIR)
B(-1,23,2,AIR)
B(-1,23,3,AIR)
B(-1,23,4,AIR)
B(-1,23,5,AIR)
B(-1,23,6,159:1)
B(-1,23,7,179)
B(-1,23,8,179)
B(-1,24,-7,179)
B(-1,24,-6,179)
B(-1,24,-5,179)
B(-1,24,-4,179:1)
B(-1,24,-3,AIR)
B(-1,24,-2,AIR)
B(-1,24,-1,AIR)
B(-1,24,0,AIR)
B(-1,24,1,AIR)
B(-1,24,2,AIR)
B(-1,24,3,AIR)
B(-1,24,4,AIR)
B(-1,24,5,AIR)
B(-1,24,6,179:1)
B(-1,24,7,180:3)
B(-1,25,-7,179)
B(-1,25,-6,179)
B(-1,25,-5,179)
B(-1,25,-4,179)
B(-1,25,-3,179)
B(-1,25,-2,179)
B(-1,25,-1,179)
B(-1,25,0,179)
B(-1,25,1,179)
B(-1,25,2,179)
B(-1,25,3,179)
B(-1,25,4,179)
B(-1,25,5,159:14)
B(-1,25,6,159:14)
B(-1,26,-7,159:14)
B(-1,26,-6,159:14)
B(-1,26,-5,159:14)
B(-1,26,-4,159:14)
B(-1,26,-3,159:14)
B(-1,26,-2,159:14)
B(-1,26,-1,159:14)
B(-1,26,0,159:14)
B(-1,26,1,159:14)
B(-1,26,2,159:14)
B(-1,26,3,179)
B(-1,26,4,179)
B(-1,26,5,179)
B(-1,26,6,180:3)
B(-1,27,-7,AIR)
B(-1,27,-6,AIR)
B(-1,27,-5,AIR)
B(-1,27,-4,AIR)
B(-1,27,-3,AIR)
B(-1,27,-2,AIR)
B(-1,27,-1,AIR)
B(-1,27,0,AIR)
B(-1,27,1,AIR)
B(-1,27,2,AIR)
B(-1,27,3,179)
B(-1,27,4,182)
B(-1,27,5,182)
B(-1,28,-7,AIR)
B(-1,28,-6,AIR)
B(-1,28,-5,AIR)
B(-1,28,-4,AIR)
B(-1,28,-3,AIR)
B(-1,28,-2,AIR)
B(-1,28,-1,AIR)
B(-1,28,0,AIR)
B(-1,28,1,AIR)
B(-1,28,2,179:2)
B(-1,29,-7,179)
B(-1,29,-6,179)
B(-1,29,-5,179)
B(-1,29,-4,179)
B(-1,29,-3,179)
B(-1,29,-2,179)
B(-1,29,-1,179)
B(-1,29,0,179)
B(-1,29,1,179)
B(-1,29,2,179)
B(-1,30,-7,179)
B(-1,30,-6,179)
B(-1,30,-5,179)
B(-1,30,-4,179)
B(-1,30,-3,179)
B(-1,30,-2,179)
B(-1,30,-1,179)
B(-1,30,0,179)
B(-1,30,1,182)
B(0,0,-7,24)
B(0,0,-6,179)
B(0,0,-5,179)
B(0,0,-4,179)
B(0,0,-3,179)
B(0,0,-2,179)
B(0,0,-1,179)
B(0,0,0,179)
B(0,0,1,179)
B(0,0,2,179)
B(0,0,3,179)
B(0,0,4,179)
B(0,0,5,179)
B(0,0,6,179)
B(0,0,7,179)
B(0,0,8,179)
B(0,1,-7,11)
B(0,1,-6,24:2)
B(0,1,-5,AIR)
B(0,1,-4,AIR)
B(0,1,-3,AIR)
B(0,1,-2,AIR)
B(0,1,-1,AIR)
B(0,1,0,179)
B(0,1,1,9)
B(0,1,2,9)
B(0,1,3,9)
B(0,1,4,9:9)
B(0,1,5,179)
B(0,1,6,179)
B(0,1,7,179)
B(0,1,8,179)
B(0,2,-7,AIR)
B(0,2,-6,24)
B(0,2,-5,AIR)
B(0,2,-4,AIR)
B(0,2,-3,AIR)
B(0,2,-2,AIR)
B(0,2,-1,AIR)
B(0,2,0,AIR)
B(0,2,1,AIR)
B(0,2,2,AIR)
B(0,2,3,AIR)
B(0,2,4,9:9)
B(0,2,5,179)
B(0,2,6,179)
B(0,2,7,179)
B(0,2,8,179)
B(0,3,-7,AIR)
B(0,3,-6,24)
B(0,3,-5,AIR)
B(0,3,-4,AIR)
B(0,3,-3,AIR)
B(0,3,-2,AIR)
B(0,3,-1,AIR)
B(0,3,0,AIR)
B(0,3,1,AIR)
B(0,3,2,AIR)
B(0,3,3,AIR)
B(0,3,4,9:9)
B(0,3,5,179)
B(0,3,6,179)
B(0,3,7,179)
B(0,3,8,179)
B(0,4,-7,24)
B(0,4,-6,AIR)
B(0,4,-5,AIR)
B(0,4,-4,AIR)
B(0,4,-3,AIR)
B(0,4,-2,AIR)
B(0,4,-1,AIR)
B(0,4,0,AIR)
B(0,4,1,AIR)
B(0,4,2,AIR)
B(0,4,3,179)
B(0,4,4,9:9)
B(0,4,5,179)
B(0,4,6,179)
B(0,4,7,179)
B(0,4,8,179)
B(0,5,-7,AIR)
B(0,5,-6,AIR)
B(0,5,-5,AIR)
B(0,5,-4,AIR)
B(0,5,-3,AIR)
B(0,5,-2,AIR)
B(0,5,-1,AIR)
B(0,5,0,AIR)
B(0,5,1,AIR)
B(0,5,2,AIR)
B(0,5,3,179)
B(0,5,4,9:9)
B(0,5,5,179)
B(0,5,6,179)
B(0,5,7,179)
B(0,5,8,179)
B(0,6,-7,AIR)
B(0,6,-6,AIR)
B(0,6,-5,AIR)
B(0,6,-4,AIR)
B(0,6,-3,AIR)
B(0,6,-2,AIR)
B(0,6,-1,AIR)
B(0,6,0,AIR)
B(0,6,1,AIR)
B(0,6,2,AIR)
B(0,6,3,AIR)
B(0,6,4,9:9)
B(0,6,5,179)
B(0,6,6,179)
B(0,6,7,179)
B(0,6,8,179)
B(0,7,-7,AIR)
B(0,7,-6,AIR)
B(0,7,-5,AIR)
B(0,7,-4,AIR)
B(0,7,-3,AIR)
B(0,7,-2,AIR)
B(0,7,-1,AIR)
B(0,7,0,AIR)
B(0,7,1,AIR)
B(0,7,2,AIR)
B(0,7,3,AIR)
B(0,7,4,9:9)
B(0,7,5,179)
B(0,7,6,179)
B(0,7,7,179)
B(0,7,8,179)
B(0,8,-7,AIR)
B(0,8,-6,AIR)
B(0,8,-5,AIR)
B(0,8,-4,AIR)
B(0,8,-3,AIR)
B(0,8,-2,AIR)
B(0,8,-1,AIR)
B(0,8,0,AIR)
B(0,8,1,AIR)
B(0,8,2,AIR)
B(0,8,3,AIR)
B(0,8,4,9:1)
B(0,8,5,9:9)
B(0,8,6,179)
B(0,8,7,179)
B(0,8,8,179)
B(0,9,-7,AIR)
B(0,9,-6,AIR)
B(0,9,-5,AIR)
B(0,9,-4,AIR)
B(0,9,-3,AIR)
B(0,9,-2,AIR)
B(0,9,-1,AIR)
B(0,9,0,AIR)
B(0,9,1,AIR)
B(0,9,2,AIR)
B(0,9,3,AIR)
B(0,9,4,AIR)
B(0,9,5,9:9)
B(0,9,6,9:8)
B(0,9,7,179)
B(0,9,8,179)
B(0,10,-7,AIR)
B(0,10,-6,AIR)
B(0,10,-5,AIR)
B(0,10,-4,AIR)
B(0,10,-3,AIR)
B(0,10,-2,AIR)
B(0,10,-1,AIR)
B(0,10,0,AIR)
B(0,10,1,AIR)
B(0,10,2,AIR)
B(0,10,3,AIR)
B(0,10,4,AIR)
B(0,10,5,9:1)
B(0,10,6,9:8)
B(0,10,7,179)
B(0,10,8,179)
B(0,11,-7,AIR)
B(0,11,-6,AIR)
B(0,11,-5,AIR)
B(0,11,-4,AIR)
B(0,11,-3,AIR)
B(0,11,-2,AIR)
B(0,11,-1,AIR)
B(0,11,0,AIR)
B(0,11,1,AIR)
B(0,11,2,AIR)
B(0,11,3,AIR)
B(0,11,4,179)
B(0,11,5,179)
B(0,11,6,9:8)
B(0,11,7,179)
B(0,11,8,179)
B(0,12,-7,AIR)
B(0,12,-6,AIR)
B(0,12,-5,AIR)
B(0,12,-4,AIR)
B(0,12,-3,AIR)
B(0,12,-2,AIR)
B(0,12,-1,AIR)
B(0,12,0,AIR)
B(0,12,1,AIR)
B(0,12,2,AIR)
B(0,12,3,179)
B(0,12,4,9)
B(0,12,5,9)
B(0,12,6,9:8)
B(0,12,7,179)
B(0,12,8,179)
B(0,13,-7,AIR)
B(0,13,-6,AIR)
B(0,13,-5,AIR)
B(0,13,-4,AIR)
B(0,13,-3,AIR)
B(0,13,-2,AIR)
B(0,13,-1,AIR)
B(0,13,0,AIR)
B(0,13,1,AIR)
B(0,13,2,AIR)
B(0,13,3,AIR)
B(0,13,4,AIR)
B(0,13,5,AIR)
B(0,13,6,9:8)
B(0,13,7,179)
B(0,13,8,179)
B(0,14,-7,AIR)
B(0,14,-6,AIR)
B(0,14,-5,AIR)
B(0,14,-4,AIR)
B(0,14,-3,AIR)
B(0,14,-2,AIR)
B(0,14,-1,AIR)
B(0,14,0,AIR)
B(0,14,1,AIR)
B(0,14,2,AIR)
B(0,14,3,AIR)
B(0,14,4,AIR)
B(0,14,5,AIR)
B(0,14,6,9:8)
B(0,14,7,179)
B(0,14,8,179)
B(0,15,-7,AIR)
B(0,15,-6,AIR)
B(0,15,-5,AIR)
B(0,15,-4,AIR)
B(0,15,-3,AIR)
B(0,15,-2,AIR)
B(0,15,-1,AIR)
B(0,15,0,AIR)
B(0,15,1,AIR)
B(0,15,2,AIR)
B(0,15,3,AIR)
B(0,15,4,AIR)
B(0,15,5,AIR)
B(0,15,6,9:8)
B(0,15,7,179)
B(0,15,8,179)
B(0,16,-7,AIR)
B(0,16,-6,AIR)
B(0,16,-5,AIR)
B(0,16,-4,AIR)
B(0,16,-3,AIR)
B(0,16,-2,AIR)
B(0,16,-1,AIR)
B(0,16,0,AIR)
B(0,16,1,AIR)
B(0,16,2,AIR)
B(0,16,3,AIR)
B(0,16,4,AIR)
B(0,16,5,AIR)
B(0,16,6,9:8)
B(0,16,7,179)
B(0,16,8,179)
B(0,17,-7,AIR)
B(0,17,-6,AIR)
B(0,17,-5,AIR)
B(0,17,-4,AIR)
B(0,17,-3,AIR)
B(0,17,-2,AIR)
B(0,17,-1,AIR)
B(0,17,0,AIR)
B(0,17,1,AIR)
B(0,17,2,AIR)
B(0,17,3,AIR)
B(0,17,4,AIR)
B(0,17,5,AIR)
B(0,17,6,9:8)
B(0,17,7,179)
B(0,17,8,179)
B(0,18,-7,179)
B(0,18,-6,179)
B(0,18,-5,179)
B(0,18,-4,179)
B(0,18,-3,179)
B(0,18,-2,179)
B(0,18,-1,159:14)
B(0,18,0,180:7)
B(0,18,1,AIR)
B(0,18,2,AIR)
B(0,18,3,AIR)
B(0,18,4,AIR)
B(0,18,5,AIR)
B(0,18,6,9:8)
B(0,18,7,179)
B(0,18,8,179)
B(0,19,-7,179)
B(0,19,-6,179)
B(0,19,-5,179)
B(0,19,-4,179)
B(0,19,-3,179)
B(0,19,-2,179)
B(0,19,-1,179)
B(0,19,0,179)
B(0,19,1,159:14)
B(0,19,2,159:14)
B(0,19,3,159:14)
B(0,19,4,159:14)
B(0,19,5,159:14)
B(0,19,6,9)
B(0,19,7,179)
B(0,19,8,179)
B(0,20,-7,AIR)
B(0,20,-6,AIR)
B(0,20,-5,179)
B(0,20,-4,AIR)
B(0,20,-3,AIR)
B(0,20,-2,AIR)
B(0,20,-1,AIR)
B(0,20,0,AIR)
B(0,20,1,AIR)
B(0,20,2,AIR)
B(0,20,3,AIR)
B(0,20,4,AIR)
B(0,20,5,179:2)
B(0,20,6,9)
B(0,20,7,179)
B(0,20,8,179)
B(0,21,-7,AIR)
B(0,21,-6,AIR)
B(0,21,-5,179)
B(0,21,-4,AIR)
B(0,21,-3,AIR)
B(0,21,-2,AIR)
B(0,21,-1,AIR)
B(0,21,0,AIR)
B(0,21,1,AIR)
B(0,21,2,AIR)
B(0,21,3,AIR)
B(0,21,4,AIR)
B(0,21,5,AIR)
B(0,21,6,AIR)
B(0,21,7,179)
B(0,21,8,179)
B(0,22,-7,179)
B(0,22,-6,AIR)
B(0,22,-5,179)
B(0,22,-4,AIR)
B(0,22,-3,AIR)
B(0,22,-2,AIR)
B(0,22,-1,AIR)
B(0,22,0,AIR)
B(0,22,1,AIR)
B(0,22,2,AIR)
B(0,22,3,AIR)
B(0,22,4,AIR)
B(0,22,5,AIR)
B(0,22,6,AIR)
B(0,22,7,179)
B(0,22,8,179)
B(0,23,-7,179)
B(0,23,-6,179)
B(0,23,-5,179)
B(0,23,-4,AIR)
B(0,23,-3,AIR)
B(0,23,-2,AIR)
B(0,23,-1,AIR)
B(0,23,0,AIR)
B(0,23,1,AIR)
B(0,23,2,AIR)
B(0,23,3,AIR)
B(0,23,4,AIR)
B(0,23,5,AIR)
B(0,23,6,AIR)
B(0,23,7,179)
B(0,23,8,179)
B(0,24,-7,180:2)
B(0,24,-6,179)
B(0,24,-5,179)
B(0,24,-4,180:7)
B(0,24,-3,AIR)
B(0,24,-2,AIR)
B(0,24,-1,AIR)
B(0,24,0,AIR)
B(0,24,1,AIR)
B(0,24,2,AIR)
B(0,24,3,AIR)
B(0,24,4,AIR)
B(0,24,5,AIR)
B(0,24,6,180:6)
B(0,24,7,180:3)
B(0,25,-7,AIR)
B(0,25,-6,180:2)
B(0,25,-5,179)
B(0,25,-4,179)
B(0,25,-3,179)
B(0,25,-2,179)
B(0,25,-1,179)
B(0,25,0,179)
B(0,25,1,179)
B(0,25,2,179)
B(0,25,3,179)
B(0,25,4,179)
B(0,25,5,159:14)
B(0,25,6,159:14)
B(0,26,-7,AIR)
B(0,26,-6,AIR)
B(0,26,-5,180:2)
B(0,26,-4,159:14)
B(0,26,-3,179)
B(0,26,-2,179)
B(0,26,-1,179)
B(0,26,0,179)
B(0,26,1,179)
B(0,26,2,179)
B(0,26,3,179)
B(0,26,4,179)
B(0,26,5,159:14)
B(0,26,6,180:3)
B(0,27,-7,AIR)
B(0,27,-6,AIR)
B(0,27,-5,AIR)
B(0,27,-4,AIR)
B(0,27,-3,AIR)
B(0,27,-2,AIR)
B(0,27,-1,AIR)
B(0,27,0,AIR)
B(0,27,1,AIR)
B(0,27,2,AIR)
B(0,27,3,179)
B(0,27,4,182)
B(0,28,-7,AIR)
B(0,28,-6,AIR)
B(0,28,-5,AIR)
B(0,28,-4,AIR)
B(0,28,-3,AIR)
B(0,28,-2,AIR)
B(0,28,-1,AIR)
B(0,28,0,AIR)
B(0,28,1,AIR)
B(0,28,2,179:1)
B(0,29,-7,AIR)
B(0,29,-6,AIR)
B(0,29,-5,AIR)
B(0,29,-4,AIR)
B(0,29,-3,AIR)
B(0,29,-2,AIR)
B(0,29,-1,AIR)
B(0,29,0,AIR)
B(0,29,1,179)
B(0,29,2,179)
B(0,30,-7,179)
B(0,30,-6,179)
B(0,30,-5,179)
B(0,30,-4,179)
B(0,30,-3,179)
B(0,30,-2,179)
B(0,30,-1,179)
B(0,30,0,179)
B(0,30,1,179)
B(0,31,-7,179)
B(0,31,-6,179)
B(0,31,-5,179)
B(0,31,-4,179)
B(0,31,-3,179)
B(0,31,-2,179)
B(0,31,-1,179)
B(0,31,0,179)
B(0,32,-7,182)
B(0,32,-6,182)
B(0,32,-5,182)
B(0,32,-4,182)
B(0,32,-3,182)
B(0,32,-2,182)
B(0,32,-1,182)
B(1,0,-7,24)
B(1,0,-6,179)
B(1,0,-5,179)
B(1,0,-4,179)
B(1,0,-3,179)
B(1,0,-2,179)
B(1,0,-1,179)
B(1,0,0,179)
B(1,0,1,179)
B(1,0,2,179)
B(1,0,3,179)
B(1,0,4,179)
B(1,0,5,179)
B(1,0,6,179)
B(1,0,7,179)
B(1,0,8,179)
B(1,1,-7,24)
B(1,1,-6,AIR)
B(1,1,-5,AIR)
B(1,1,-4,AIR)
B(1,1,-3,AIR)
B(1,1,-2,AIR)
B(1,1,-1,AIR)
B(1,1,0,179)
B(1,1,1,9)
B(1,1,2,9)
B(1,1,3,9)
B(1,1,4,9:9)
B(1,1,5,179)
B(1,1,6,179)
B(1,1,7,179)
B(1,1,8,179)
B(1,2,-7,24)
B(1,2,-6,76:3)
B(1,2,-5,AIR)
B(1,2,-4,AIR)
B(1,2,-3,AIR)
B(1,2,-2,AIR)
B(1,2,-1,AIR)
B(1,2,0,AIR)
B(1,2,1,AIR)
B(1,2,2,AIR)
B(1,2,3,AIR)
B(1,2,4,9:9)
B(1,2,5,179)
B(1,2,6,179)
B(1,2,7,179)
B(1,2,8,179)
B(1,3,-7,24)
B(1,3,-6,24)
B(1,3,-5,AIR)
B(1,3,-4,AIR)
B(1,3,-3,AIR)
B(1,3,-2,AIR)
B(1,3,-1,AIR)
B(1,3,0,AIR)
B(1,3,1,AIR)
B(1,3,2,AIR)
B(1,3,3,AIR)
B(1,3,4,9:9)
B(1,3,5,179)
B(1,3,6,179)
B(1,3,7,179)
B(1,3,8,179)
B(1,4,-7,24)
B(1,4,-6,AIR)
B(1,4,-5,AIR)
B(1,4,-4,AIR)
B(1,4,-3,AIR)
B(1,4,-2,AIR)
B(1,4,-1,AIR)
B(1,4,0,AIR)
B(1,4,1,AIR)
B(1,4,2,AIR)
B(1,4,3,179)
B(1,4,4,9:9)
B(1,4,5,179)
B(1,4,6,179)
B(1,4,7,179)
B(1,4,8,179)
B(1,5,-7,AIR)
B(1,5,-6,AIR)
B(1,5,-5,AIR)
B(1,5,-4,AIR)
B(1,5,-3,AIR)
B(1,5,-2,AIR)
B(1,5,-1,AIR)
B(1,5,0,AIR)
B(1,5,1,AIR)
B(1,5,2,AIR)
B(1,5,3,179)
B(1,5,4,9:9)
B(1,5,5,179)
B(1,5,6,179)
B(1,5,7,179)
B(1,5,8,179)
B(1,6,-7,AIR)
B(1,6,-6,AIR)
B(1,6,-5,AIR)
B(1,6,-4,AIR)
B(1,6,-3,AIR)
B(1,6,-2,AIR)
B(1,6,-1,AIR)
B(1,6,0,AIR)
B(1,6,1,AIR)
B(1,6,2,AIR)
B(1,6,3,AIR)
B(1,6,4,9:9)
B(1,6,5,179)
B(1,6,6,179)
B(1,6,7,179)
B(1,6,8,179)
B(1,7,-7,AIR)
B(1,7,-6,AIR)
B(1,7,-5,AIR)
B(1,7,-4,AIR)
B(1,7,-3,AIR)
B(1,7,-2,AIR)
B(1,7,-1,AIR)
B(1,7,0,AIR)
B(1,7,1,AIR)
B(1,7,2,AIR)
B(1,7,3,AIR)
B(1,7,4,9:9)
B(1,7,5,179)
B(1,7,6,179)
B(1,7,7,179)
B(1,7,8,179)
B(1,8,-7,AIR)
B(1,8,-6,AIR)
B(1,8,-5,AIR)
B(1,8,-4,AIR)
B(1,8,-3,AIR)
B(1,8,-2,AIR)
B(1,8,-1,AIR)
B(1,8,0,AIR)
B(1,8,1,AIR)
B(1,8,2,AIR)
B(1,8,3,AIR)
B(1,8,4,9:1)
B(1,8,5,9:9)
B(1,8,6,179)
B(1,8,7,179)
B(1,8,8,179)
B(1,9,-7,AIR)
B(1,9,-6,AIR)
B(1,9,-5,AIR)
B(1,9,-4,AIR)
B(1,9,-3,AIR)
B(1,9,-2,AIR)
B(1,9,-1,AIR)
B(1,9,0,AIR)
B(1,9,1,AIR)
B(1,9,2,AIR)
B(1,9,3,AIR)
B(1,9,4,AIR)
B(1,9,5,9:9)
B(1,9,6,9:8)
B(1,9,7,179)
B(1,9,8,179)
B(1,10,-7,AIR)
B(1,10,-6,AIR)
B(1,10,-5,AIR)
B(1,10,-4,AIR)
B(1,10,-3,AIR)
B(1,10,-2,AIR)
B(1,10,-1,AIR)
B(1,10,0,AIR)
B(1,10,1,AIR)
B(1,10,2,AIR)
B(1,10,3,AIR)
B(1,10,4,AIR)
B(1,10,5,9:1)
B(1,10,6,9:8)
B(1,10,7,179)
B(1,10,8,179)
B(1,11,-7,AIR)
B(1,11,-6,AIR)
B(1,11,-5,AIR)
B(1,11,-4,AIR)
B(1,11,-3,AIR)
B(1,11,-2,AIR)
B(1,11,-1,AIR)
B(1,11,0,AIR)
B(1,11,1,AIR)
B(1,11,2,AIR)
B(1,11,3,AIR)
B(1,11,4,179)
B(1,11,5,179)
B(1,11,6,9:8)
B(1,11,7,179)
B(1,11,8,179)
B(1,12,-7,AIR)
B(1,12,-6,AIR)
B(1,12,-5,AIR)
B(1,12,-4,AIR)
B(1,12,-3,AIR)
B(1,12,-2,AIR)
B(1,12,-1,AIR)
B(1,12,0,AIR)
B(1,12,1,AIR)
B(1,12,2,AIR)
B(1,12,3,179)
B(1,12,4,9)
B(1,12,5,9)
B(1,12,6,9:8)
B(1,12,7,179)
B(1,12,8,179)
B(1,13,-7,AIR)
B(1,13,-6,AIR)
B(1,13,-5,AIR)
B(1,13,-4,AIR)
B(1,13,-3,AIR)
B(1,13,-2,AIR)
B(1,13,-1,AIR)
B(1,13,0,AIR)
B(1,13,1,AIR)
B(1,13,2,AIR)
B(1,13,3,AIR)
B(1,13,4,AIR)
B(1,13,5,AIR)
B(1,13,6,9:8)
B(1,13,7,179)
B(1,13,8,179)
B(1,14,-7,AIR)
B(1,14,-6,AIR)
B(1,14,-5,AIR)
B(1,14,-4,AIR)
B(1,14,-3,AIR)
B(1,14,-2,AIR)
B(1,14,-1,AIR)
B(1,14,0,AIR)
B(1,14,1,AIR)
B(1,14,2,AIR)
B(1,14,3,AIR)
B(1,14,4,AIR)
B(1,14,5,AIR)
B(1,14,6,9:8)
B(1,14,7,179)
B(1,14,8,179)
B(1,15,-7,AIR)
B(1,15,-6,AIR)
B(1,15,-5,AIR)
B(1,15,-4,AIR)
B(1,15,-3,AIR)
B(1,15,-2,AIR)
B(1,15,-1,AIR)
B(1,15,0,AIR)
B(1,15,1,AIR)
B(1,15,2,AIR)
B(1,15,3,AIR)
B(1,15,4,AIR)
B(1,15,5,AIR)
B(1,15,6,9:8)
B(1,15,7,179)
B(1,15,8,179)
B(1,16,-7,AIR)
B(1,16,-6,AIR)
B(1,16,-5,AIR)
B(1,16,-4,AIR)
B(1,16,-3,AIR)
B(1,16,-2,AIR)
B(1,16,-1,AIR)
B(1,16,0,AIR)
B(1,16,1,AIR)
B(1,16,2,AIR)
B(1,16,3,AIR)
B(1,16,4,AIR)
B(1,16,5,AIR)
B(1,16,6,9:8)
B(1,16,7,179)
B(1,16,8,179)
B(1,17,-7,AIR)
B(1,17,-6,AIR)
B(1,17,-5,AIR)
B(1,17,-4,AIR)
B(1,17,-3,AIR)
B(1,17,-2,AIR)
B(1,17,-1,AIR)
B(1,17,0,AIR)
B(1,17,1,AIR)
B(1,17,2,AIR)
B(1,17,3,AIR)
B(1,17,4,AIR)
B(1,17,5,AIR)
B(1,17,6,9:8)
B(1,17,7,179)
B(1,17,8,179)
B(1,18,-7,179)
B(1,18,-6,179)
B(1,18,-5,179)
B(1,18,-4,179)
B(1,18,-3,179)
B(1,18,-2,179)
B(1,18,-1,159:14)
B(1,18,0,180:7)
B(1,18,1,AIR)
B(1,18,2,AIR)
B(1,18,3,AIR)
B(1,18,4,AIR)
B(1,18,5,AIR)
B(1,18,6,9:8)
B(1,18,7,179)
B(1,18,8,179)
B(1,19,-7,179)
B(1,19,-6,179)
B(1,19,-5,179)
B(1,19,-4,179)
B(1,19,-3,179)
B(1,19,-2,179)
B(1,19,-1,179)
B(1,19,0,179)
B(1,19,1,159:14)
B(1,19,2,159:14)
B(1,19,3,159:14)
B(1,19,4,159:14)
B(1,19,5,159:14)
B(1,19,6,9)
B(1,19,7,179)
B(1,19,8,179)
B(1,20,-7,AIR)
B(1,20,-6,AIR)
B(1,20,-5,179)
B(1,20,-4,AIR)
B(1,20,-3,AIR)
B(1,20,-2,AIR)
B(1,20,-1,AIR)
B(1,20,0,AIR)
B(1,20,1,AIR)
B(1,20,2,AIR)
B(1,20,3,AIR)
B(1,20,4,AIR)
B(1,20,5,179:2)
B(1,20,6,9)
B(1,20,7,179)
B(1,20,8,179)
B(1,21,-7,AIR)
B(1,21,-6,AIR)
B(1,21,-5,179)
B(1,21,-4,AIR)
B(1,21,-3,AIR)
B(1,21,-2,AIR)
B(1,21,-1,AIR)
B(1,21,0,AIR)
B(1,21,1,AIR)
B(1,21,2,AIR)
B(1,21,3,AIR)
B(1,21,4,AIR)
B(1,21,5,AIR)
B(1,21,6,AIR)
B(1,21,7,179)
B(1,21,8,179)
B(1,22,-7,179)
B(1,22,-6,AIR)
B(1,22,-5,179)
B(1,22,-4,AIR)
B(1,22,-3,AIR)
B(1,22,-2,AIR)
B(1,22,-1,AIR)
B(1,22,0,AIR)
B(1,22,1,AIR)
B(1,22,2,AIR)
B(1,22,3,AIR)
B(1,22,4,AIR)
B(1,22,5,AIR)
B(1,22,6,AIR)
B(1,22,7,179)
B(1,22,8,179)
B(1,23,-7,179)
B(1,23,-6,179)
B(1,23,-5,179)
B(1,23,-4,AIR)
B(1,23,-3,AIR)
B(1,23,-2,AIR)
B(1,23,-1,AIR)
B(1,23,0,AIR)
B(1,23,1,AIR)
B(1,23,2,AIR)
B(1,23,3,AIR)
B(1,23,4,AIR)
B(1,23,5,AIR)
B(1,23,6,AIR)
B(1,23,7,179)
B(1,23,8,179)
B(1,24,-7,180:2)
B(1,24,-6,179)
B(1,24,-5,179)
B(1,24,-4,180:7)
B(1,24,-3,AIR)
B(1,24,-2,AIR)
B(1,24,-1,AIR)
B(1,24,0,AIR)
B(1,24,1,AIR)
B(1,24,2,AIR)
B(1,24,3,AIR)
B(1,24,4,AIR)
B(1,24,5,AIR)
B(1,24,6,180:6)
B(1,24,7,180:3)
B(1,25,-7,AIR)
B(1,25,-6,180:2)
B(1,25,-5,179)
B(1,25,-4,179)
B(1,25,-3,179)
B(1,25,-2,179)
B(1,25,-1,179)
B(1,25,0,179)
B(1,25,1,179)
B(1,25,2,179)
B(1,25,3,179)
B(1,25,4,179)
B(1,25,5,159:14)
B(1,25,6,159:14)
B(1,26,-7,AIR)
B(1,26,-6,AIR)
B(1,26,-5,180:2)
B(1,26,-4,159:14)
B(1,26,-3,179)
B(1,26,-2,179)
B(1,26,-1,179)
B(1,26,0,179)
B(1,26,1,179)
B(1,26,2,179)
B(1,26,3,179)
B(1,26,4,179)
B(1,26,5,159:14)
B(1,26,6,180:3)
B(1,27,-7,AIR)
B(1,27,-6,AIR)
B(1,27,-5,AIR)
B(1,27,-4,AIR)
B(1,27,-3,AIR)
B(1,27,-2,AIR)
B(1,27,-1,AIR)
B(1,27,0,AIR)
B(1,27,1,AIR)
B(1,27,2,AIR)
B(1,27,3,179)
B(1,27,4,182)
B(1,28,-7,AIR)
B(1,28,-6,AIR)
B(1,28,-5,AIR)
B(1,28,-4,AIR)
B(1,28,-3,AIR)
B(1,28,-2,AIR)
B(1,28,-1,AIR)
B(1,28,0,AIR)
B(1,28,1,AIR)
B(1,28,2,179:1)
B(1,29,-7,AIR)
B(1,29,-6,AIR)
B(1,29,-5,AIR)
B(1,29,-4,AIR)
B(1,29,-3,AIR)
B(1,29,-2,AIR)
B(1,29,-1,AIR)
B(1,29,0,AIR)
B(1,29,1,179)
B(1,29,2,179)
B(1,30,-7,AIR)
B(1,30,-6,AIR)
B(1,30,-5,AIR)
B(1,30,-4,AIR)
B(1,30,-3,AIR)
B(1,30,-2,AIR)
B(1,30,-1,AIR)
B(1,30,0,179)
B(1,30,1,179)
B(1,31,-7,179)
B(1,31,-6,179)
B(1,31,-5,179)
B(1,31,-4,179)
B(1,31,-3,179)
B(1,31,-2,179)
B(1,31,-1,179)
B(1,31,0,179)
B(1,32,-7,179)
B(1,32,-6,179)
B(1,32,-5,179)
B(1,32,-4,179)
B(1,32,-3,179)
B(1,32,-2,179)
B(1,32,-1,179)
B(1,32,0,182)
B(2,0,-7,24)
B(2,0,-6,179)
B(2,0,-5,179)
B(2,0,-4,179)
B(2,0,-3,179)
B(2,0,-2,179)
B(2,0,-1,179)
B(2,0,0,179)
B(2,0,1,179)
B(2,0,2,179)
B(2,0,3,179)
B(2,0,4,179)
B(2,0,5,179)
B(2,0,6,179)
B(2,0,7,179)
B(2,0,8,179)
B(2,1,-7,11)
B(2,1,-6,24:2)
B(2,1,-5,AIR)
B(2,1,-4,AIR)
B(2,1,-3,AIR)
B(2,1,-2,AIR)
B(2,1,-1,AIR)
B(2,1,0,179)
B(2,1,1,9)
B(2,1,2,9)
B(2,1,3,9)
B(2,1,4,9:9)
B(2,1,5,179)
B(2,1,6,179)
B(2,1,7,179)
B(2,1,8,179)
B(2,2,-7,AIR)
B(2,2,-6,24)
B(2,2,-5,AIR)
B(2,2,-4,AIR)
B(2,2,-3,AIR)
B(2,2,-2,AIR)
B(2,2,-1,AIR)
B(2,2,0,AIR)
B(2,2,1,AIR)
B(2,2,2,AIR)
B(2,2,3,AIR)
B(2,2,4,9:9)
B(2,2,5,179)
B(2,2,6,179)
B(2,2,7,179)
B(2,2,8,179)
B(2,3,-7,AIR)
B(2,3,-6,24)
B(2,3,-5,AIR)
B(2,3,-4,AIR)
B(2,3,-3,AIR)
B(2,3,-2,AIR)
B(2,3,-1,AIR)
B(2,3,0,AIR)
B(2,3,1,AIR)
B(2,3,2,AIR)
B(2,3,3,179)
B(2,3,4,9:9)
B(2,3,5,179)
B(2,3,6,179)
B(2,3,7,179)
B(2,3,8,179)
B(2,4,-7,24)
B(2,4,-6,AIR)
B(2,4,-5,AIR)
B(2,4,-4,AIR)
B(2,4,-3,AIR)
B(2,4,-2,AIR)
B(2,4,-1,AIR)
B(2,4,0,AIR)
B(2,4,1,AIR)
B(2,4,2,AIR)
B(2,4,3,179)
B(2,4,4,9:9)
B(2,4,5,179)
B(2,4,6,179)
B(2,4,7,179)
B(2,4,8,179)
B(2,5,-7,AIR)
B(2,5,-6,AIR)
B(2,5,-5,AIR)
B(2,5,-4,AIR)
B(2,5,-3,AIR)
B(2,5,-2,AIR)
B(2,5,-1,AIR)
B(2,5,0,AIR)
B(2,5,1,AIR)
B(2,5,2,AIR)
B(2,5,3,AIR)
B(2,5,4,9:9)
B(2,5,5,179)
B(2,5,6,179)
B(2,5,7,179)
B(2,5,8,179)
B(2,6,-7,AIR)
B(2,6,-6,AIR)
B(2,6,-5,AIR)
B(2,6,-4,AIR)
B(2,6,-3,AIR)
B(2,6,-2,AIR)
B(2,6,-1,AIR)
B(2,6,0,AIR)
B(2,6,1,AIR)
B(2,6,2,AIR)
B(2,6,3,AIR)
B(2,6,4,9:9)
B(2,6,5,179)
B(2,6,6,179)
B(2,6,7,179)
B(2,6,8,179)
B(2,7,-7,AIR)
B(2,7,-6,AIR)
B(2,7,-5,AIR)
B(2,7,-4,AIR)
B(2,7,-3,AIR)
B(2,7,-2,AIR)
B(2,7,-1,AIR)
B(2,7,0,AIR)
B(2,7,1,AIR)
B(2,7,2,AIR)
B(2,7,3,AIR)
B(2,7,4,9:1)
B(2,7,5,9:9)
B(2,7,6,179)
B(2,7,7,179)
B(2,7,8,179)
B(2,8,-7,AIR)
B(2,8,-6,AIR)
B(2,8,-5,AIR)
B(2,8,-4,AIR)
B(2,8,-3,AIR)
B(2,8,-2,AIR)
B(2,8,-1,AIR)
B(2,8,0,AIR)
B(2,8,1,AIR)
B(2,8,2,AIR)
B(2,8,3,AIR)
B(2,8,4,AIR)
B(2,8,5,9:9)
B(2,8,6,179)
B(2,8,7,179)
B(2,8,8,179)
B(2,9,-7,AIR)
B(2,9,-6,AIR)
B(2,9,-5,AIR)
B(2,9,-4,AIR)
B(2,9,-3,AIR)
B(2,9,-2,AIR)
B(2,9,-1,AIR)
B(2,9,0,AIR)
B(2,9,1,AIR)
B(2,9,2,AIR)
B(2,9,3,AIR)
B(2,9,4,AIR)
B(2,9,5,9:1)
B(2,9,6,9:9)
B(2,9,7,179)
B(2,9,8,179)
B(2,10,-7,AIR)
B(2,10,-6,AIR)
B(2,10,-5,AIR)
B(2,10,-4,AIR)
B(2,10,-3,AIR)
B(2,10,-2,AIR)
B(2,10,-1,AIR)
B(2,10,0,AIR)
B(2,10,1,AIR)
B(2,10,2,AIR)
B(2,10,3,AIR)
B(2,10,4,AIR)
B(2,10,5,AIR)
B(2,10,6,9:1)
B(2,10,7,179)
B(2,10,8,179)
B(2,11,-7,AIR)
B(2,11,-6,AIR)
B(2,11,-5,AIR)
B(2,11,-4,AIR)
B(2,11,-3,AIR)
B(2,11,-2,AIR)
B(2,11,-1,AIR)
B(2,11,0,AIR)
B(2,11,1,AIR)
B(2,11,2,AIR)
B(2,11,3,179)
B(2,11,4,179)
B(2,11,5,179)
B(2,11,6,179)
B(2,11,7,179)
B(2,11,8,179)
B(2,12,-7,AIR)
B(2,12,-6,AIR)
B(2,12,-5,AIR)
B(2,12,-4,AIR)
B(2,12,-3,AIR)
B(2,12,-2,AIR)
B(2,12,-1,AIR)
B(2,12,0,AIR)
B(2,12,1,AIR)
B(2,12,2,179)
B(2,12,3,179)
B(2,12,4,9)
B(2,12,5,9)
B(2,12,6,179)
B(2,12,7,179)
B(2,12,8,179)
B(2,13,-7,AIR)
B(2,13,-6,AIR)
B(2,13,-5,AIR)
B(2,13,-4,AIR)
B(2,13,-3,AIR)
B(2,13,-2,AIR)
B(2,13,-1,AIR)
B(2,13,0,AIR)
B(2,13,1,AIR)
B(2,13,2,AIR)
B(2,13,3,AIR)
B(2,13,4,AIR)
B(2,13,5,AIR)
B(2,13,6,179)
B(2,13,7,179)
B(2,13,8,179)
B(2,14,-7,AIR)
B(2,14,-6,AIR)
B(2,14,-5,AIR)
B(2,14,-4,AIR)
B(2,14,-3,AIR)
B(2,14,-2,AIR)
B(2,14,-1,AIR)
B(2,14,0,AIR)
B(2,14,1,AIR)
B(2,14,2,AIR)
B(2,14,3,AIR)
B(2,14,4,AIR)
B(2,14,5,AIR)
B(2,14,6,179)
B(2,14,7,179)
B(2,14,8,179)
B(2,15,-7,AIR)
B(2,15,-6,AIR)
B(2,15,-5,AIR)
B(2,15,-4,AIR)
B(2,15,-3,AIR)
B(2,15,-2,AIR)
B(2,15,-1,AIR)
B(2,15,0,AIR)
B(2,15,1,AIR)
B(2,15,2,AIR)
B(2,15,3,AIR)
B(2,15,4,AIR)
B(2,15,5,AIR)
B(2,15,6,179)
B(2,15,7,179)
B(2,15,8,179)
B(2,16,-7,AIR)
B(2,16,-6,AIR)
B(2,16,-5,AIR)
B(2,16,-4,AIR)
B(2,16,-3,AIR)
B(2,16,-2,AIR)
B(2,16,-1,AIR)
B(2,16,0,AIR)
B(2,16,1,AIR)
B(2,16,2,AIR)
B(2,16,3,AIR)
B(2,16,4,AIR)
B(2,16,5,AIR)
B(2,16,6,179)
B(2,16,7,179)
B(2,16,8,179)
B(2,17,-7,AIR)
B(2,17,-6,AIR)
B(2,17,-5,AIR)
B(2,17,-4,AIR)
B(2,17,-3,AIR)
B(2,17,-2,AIR)
B(2,17,-1,AIR)
B(2,17,0,AIR)
B(2,17,1,AIR)
B(2,17,2,AIR)
B(2,17,3,AIR)
B(2,17,4,AIR)
B(2,17,5,AIR)
B(2,17,6,179)
B(2,17,7,179)
B(2,17,8,179)
B(2,18,-7,179)
B(2,18,-6,179)
B(2,18,-5,179)
B(2,18,-4,179)
B(2,18,-3,179)
B(2,18,-2,179)
B(2,18,-1,159:14)
B(2,18,0,180:7)
B(2,18,1,AIR)
B(2,18,2,AIR)
B(2,18,3,AIR)
B(2,18,4,AIR)
B(2,18,5,180:6)
B(2,18,6,179)
B(2,18,7,179)
B(2,18,8,179)
B(2,19,-7,179)
B(2,19,-6,179)
B(2,19,-5,179)
B(2,19,-4,179)
B(2,19,-3,179)
B(2,19,-2,179)
B(2,19,-1,179)
B(2,19,0,179)
B(2,19,1,159:14)
B(2,19,2,159:14)
B(2,19,3,179)
B(2,19,4,179)
B(2,19,5,179)
B(2,19,6,179)
B(2,19,7,179)
B(2,19,8,179)
B(2,20,-7,179)
B(2,20,-6,179)
B(2,20,-5,179)
B(2,20,-4,AIR)
B(2,20,-3,179:2)
B(2,20,-2,AIR)
B(2,20,-1,AIR)
B(2,20,0,179:2)
B(2,20,1,AIR)
B(2,20,2,AIR)
B(2,20,3,179:2)
B(2,20,4,AIR)
B(2,20,5,179:2)
B(2,20,6,179:2)
B(2,20,7,179)
B(2,20,8,179)
B(2,21,-7,179)
B(2,21,-6,179)
B(2,21,-5,179)
B(2,21,-4,AIR)
B(2,21,-3,159:1)
B(2,21,-2,AIR)
B(2,21,-1,AIR)
B(2,21,0,159:1)
B(2,21,1,AIR)
B(2,21,2,AIR)
B(2,21,3,159:1)
B(2,21,4,AIR)
B(2,21,5,AIR)
B(2,21,6,159:1)
B(2,21,7,179)
B(2,21,8,179)
B(2,22,-7,179)
B(2,22,-6,179)
B(2,22,-5,179)
B(2,22,-4,AIR)
B(2,22,-3,159:1)
B(2,22,-2,AIR)
B(2,22,-1,AIR)
B(2,22,0,159:1)
B(2,22,1,AIR)
B(2,22,2,AIR)
B(2,22,3,159:1)
B(2,22,4,AIR)
B(2,22,5,AIR)
B(2,22,6,159:1)
B(2,22,7,179)
B(2,22,8,179)
B(2,23,-7,179)
B(2,23,-6,179)
B(2,23,-5,179)
B(2,23,-4,AIR)
B(2,23,-3,179:1)
B(2,23,-2,AIR)
B(2,23,-1,AIR)
B(2,23,0,179:1)
B(2,23,1,AIR)
B(2,23,2,AIR)
B(2,23,3,179:1)
B(2,23,4,AIR)
B(2,23,5,AIR)
B(2,23,6,159:1)
B(2,23,7,179)
B(2,23,8,179)
B(2,24,-7,180:2)
B(2,24,-6,179)
B(2,24,-5,179)
B(2,24,-4,180:7)
RB(2,24,-3,CHEST,../../nbt/VanillaLoot/desert_pyramid.nbt,50,CHEST,../../nbt/VanillaLoot/desert_pyramid.nbt,100)
B(2,24,-2,AIR)
B(2,24,-1,AIR)
B(2,24,0,AIR)
B(2,24,1,AIR)
B(2,24,2,AIR)
B(2,24,3,AIR)
B(2,24,4,AIR)
B(2,24,5,30)
B(2,24,6,179:1)
B(2,24,7,180:3)
B(2,25,-7,AIR)
B(2,25,-6,180:2)
B(2,25,-5,179)
B(2,25,-4,179)
B(2,25,-3,182)
B(2,25,-2,179)
B(2,25,-1,179)
B(2,25,0,179)
B(2,25,1,179)
B(2,25,2,179)
B(2,25,3,179)
B(2,25,4,179)
B(2,25,5,159:14)
B(2,25,6,159:14)
B(2,26,-7,AIR)
B(2,26,-6,AIR)
B(2,26,-5,180:2)
B(2,26,-4,159:14)
B(2,26,-3,179)
B(2,26,-2,179)
B(2,26,-1,179)
B(2,26,0,179)
B(2,26,1,179)
B(2,26,2,179)
B(2,26,3,179)
B(2,26,4,179)
B(2,26,5,159:14)
B(2,26,6,180:3)
B(2,27,-7,AIR)
B(2,27,-6,AIR)
B(2,27,-5,AIR)
B(2,27,-4,AIR)
B(2,27,-3,AIR)
B(2,27,-2,AIR)
B(2,27,-1,AIR)
B(2,27,0,AIR)
B(2,27,1,AIR)
B(2,27,2,AIR)
B(2,27,3,179)
B(2,27,4,182)
B(2,28,-7,AIR)
B(2,28,-6,AIR)
B(2,28,-5,AIR)
B(2,28,-4,AIR)
B(2,28,-3,AIR)
B(2,28,-2,AIR)
B(2,28,-1,AIR)
B(2,28,0,AIR)
B(2,28,1,AIR)
B(2,28,2,179:1)
B(2,29,-7,AIR)
B(2,29,-6,AIR)
B(2,29,-5,AIR)
B(2,29,-4,AIR)
B(2,29,-3,AIR)
B(2,29,-2,AIR)
B(2,29,-1,AIR)
B(2,29,0,AIR)
B(2,29,1,179)
B(2,29,2,179)
B(2,30,-7,AIR)
B(2,30,-6,AIR)
B(2,30,-5,AIR)
B(2,30,-4,AIR)
B(2,30,-3,AIR)
B(2,30,-2,AIR)
B(2,30,-1,AIR)
B(2,30,0,179)
B(2,30,1,179)
B(2,31,-7,AIR)
B(2,31,-6,AIR)
B(2,31,-5,AIR)
B(2,31,-4,AIR)
B(2,31,-3,AIR)
B(2,31,-2,AIR)
B(2,31,-1,179)
B(2,31,0,179)
B(2,32,-7,179)
B(2,32,-6,179)
B(2,32,-5,179)
B(2,32,-4,179)
B(2,32,-3,179)
B(2,32,-2,179)
B(2,32,-1,179)
B(2,32,0,182)
B(2,33,-7,179)
B(2,33,-6,179)
B(2,33,-5,179)
B(2,33,-4,179)
B(2,33,-3,179)
B(2,33,-2,182)
B(3,0,-7,24)
B(3,0,-6,179)
B(3,0,-5,179)
B(3,0,-4,179)
B(3,0,-3,179)
B(3,0,-2,179)
B(3,0,-1,179)
B(3,0,0,179)
B(3,0,1,179)
B(3,0,2,179)
B(3,0,3,179)
B(3,0,4,179)
B(3,0,5,179)
B(3,0,6,179)
B(3,0,7,179)
B(3,0,8,179)
B(3,1,-7,24)
B(3,1,-6,AIR)
B(3,1,-5,AIR)
B(3,1,-4,AIR)
B(3,1,-3,AIR)
B(3,1,-2,AIR)
B(3,1,-1,AIR)
B(3,1,0,179)
B(3,1,1,9)
B(3,1,2,9)
B(3,1,3,179)
B(3,1,4,9:9)
B(3,1,5,179)
B(3,1,6,179)
B(3,1,7,179)
B(3,1,8,179)
B(3,2,-7,24)
B(3,2,-6,76:3)
B(3,2,-5,AIR)
B(3,2,-4,AIR)
B(3,2,-3,AIR)
B(3,2,-2,AIR)
B(3,2,-1,AIR)
B(3,2,0,AIR)
B(3,2,1,AIR)
B(3,2,2,AIR)
B(3,2,3,179)
B(3,2,4,9:9)
B(3,2,5,179)
B(3,2,6,179)
B(3,2,7,179)
B(3,2,8,179)
B(3,3,-7,24)
B(3,3,-6,24)
B(3,3,-5,AIR)
B(3,3,-4,AIR)
B(3,3,-3,AIR)
B(3,3,-2,AIR)
B(3,3,-1,AIR)
B(3,3,0,AIR)
B(3,3,1,AIR)
B(3,3,2,AIR)
B(3,3,3,179)
B(3,3,4,9:9)
B(3,3,5,179)
B(3,3,6,179)
B(3,3,7,179)
B(3,3,8,179)
B(3,4,-7,24)
B(3,4,-6,AIR)
B(3,4,-5,AIR)
B(3,4,-4,AIR)
B(3,4,-3,AIR)
B(3,4,-2,AIR)
B(3,4,-1,AIR)
B(3,4,0,AIR)
B(3,4,1,AIR)
B(3,4,2,AIR)
B(3,4,3,AIR)
B(3,4,4,9:9)
B(3,4,5,179)
B(3,4,6,179)
B(3,4,7,179)
B(3,4,8,179)
B(3,5,-7,AIR)
B(3,5,-6,AIR)
B(3,5,-5,AIR)
B(3,5,-4,AIR)
B(3,5,-3,AIR)
B(3,5,-2,AIR)
B(3,5,-1,AIR)
B(3,5,0,AIR)
B(3,5,1,AIR)
B(3,5,2,AIR)
B(3,5,3,AIR)
B(3,5,4,9:9)
B(3,5,5,179)
B(3,5,6,179)
B(3,5,7,179)
B(3,5,8,179)
B(3,6,-7,AIR)
B(3,6,-6,AIR)
B(3,6,-5,AIR)
B(3,6,-4,AIR)
B(3,6,-3,AIR)
B(3,6,-2,AIR)
B(3,6,-1,AIR)
B(3,6,0,AIR)
B(3,6,1,AIR)
B(3,6,2,AIR)
B(3,6,3,AIR)
B(3,6,4,9:1)
B(3,6,5,9:9)
B(3,6,6,179)
B(3,6,7,179)
B(3,6,8,179)
B(3,7,-7,AIR)
B(3,7,-6,AIR)
B(3,7,-5,AIR)
B(3,7,-4,AIR)
B(3,7,-3,AIR)
B(3,7,-2,AIR)
B(3,7,-1,AIR)
B(3,7,0,AIR)
B(3,7,1,AIR)
B(3,7,2,AIR)
B(3,7,3,AIR)
B(3,7,4,AIR)
B(3,7,5,9:9)
B(3,7,6,179)
B(3,7,7,179)
B(3,7,8,179)
B(3,8,-7,AIR)
B(3,8,-6,AIR)
B(3,8,-5,AIR)
B(3,8,-4,AIR)
B(3,8,-3,AIR)
B(3,8,-2,AIR)
B(3,8,-1,AIR)
B(3,8,0,AIR)
B(3,8,1,AIR)
B(3,8,2,AIR)
B(3,8,3,AIR)
B(3,8,4,AIR)
B(3,8,5,9:1)
B(3,8,6,9:9)
B(3,8,7,179)
B(3,8,8,179)
B(3,9,-7,AIR)
B(3,9,-6,AIR)
B(3,9,-5,AIR)
B(3,9,-4,AIR)
B(3,9,-3,AIR)
B(3,9,-2,AIR)
B(3,9,-1,AIR)
B(3,9,0,AIR)
B(3,9,1,AIR)
B(3,9,2,AIR)
B(3,9,3,AIR)
B(3,9,4,AIR)
B(3,9,5,AIR)
B(3,9,6,9:1)
B(3,9,7,179)
B(3,9,8,179)
B(3,10,-7,AIR)
B(3,10,-6,AIR)
B(3,10,-5,AIR)
B(3,10,-4,AIR)
B(3,10,-3,AIR)
B(3,10,-2,AIR)
B(3,10,-1,AIR)
B(3,10,0,AIR)
B(3,10,1,AIR)
B(3,10,2,AIR)
B(3,10,3,179)
B(3,10,4,179)
B(3,10,5,179)
B(3,10,6,179)
B(3,10,7,179)
B(3,10,8,179)
B(3,11,-7,AIR)
B(3,11,-6,AIR)
B(3,11,-5,AIR)
B(3,11,-4,AIR)
B(3,11,-3,AIR)
B(3,11,-2,AIR)
B(3,11,-1,AIR)
B(3,11,0,AIR)
B(3,11,1,AIR)
B(3,11,2,179)
B(3,11,3,179)
B(3,11,4,179)
B(3,11,5,179)
B(3,11,6,179)
B(3,11,7,179)
B(3,11,8,179)
B(3,12,-7,AIR)
B(3,12,-6,AIR)
B(3,12,-5,AIR)
B(3,12,-4,AIR)
B(3,12,-3,AIR)
B(3,12,-2,AIR)
B(3,12,-1,AIR)
B(3,12,0,AIR)
B(3,12,1,179)
B(3,12,2,179)
B(3,12,3,179)
B(3,12,4,9)
B(3,12,5,9)
B(3,12,6,9:8)
B(3,12,7,179)
B(3,12,8,179)
B(3,13,-7,AIR)
B(3,13,-6,AIR)
B(3,13,-5,AIR)
B(3,13,-4,AIR)
B(3,13,-3,AIR)
B(3,13,-2,AIR)
B(3,13,-1,AIR)
B(3,13,0,AIR)
B(3,13,1,AIR)
B(3,13,2,AIR)
B(3,13,3,AIR)
B(3,13,4,AIR)
B(3,13,5,AIR)
B(3,13,6,9:8)
B(3,13,7,179)
B(3,13,8,179)
B(3,14,-7,AIR)
B(3,14,-6,AIR)
B(3,14,-5,AIR)
B(3,14,-4,AIR)
B(3,14,-3,AIR)
B(3,14,-2,AIR)
B(3,14,-1,AIR)
B(3,14,0,AIR)
B(3,14,1,AIR)
B(3,14,2,AIR)
B(3,14,3,AIR)
B(3,14,4,AIR)
B(3,14,5,AIR)
B(3,14,6,9:8)
B(3,14,7,179)
B(3,14,8,179)
B(3,15,-7,AIR)
B(3,15,-6,AIR)
B(3,15,-5,AIR)
B(3,15,-4,AIR)
B(3,15,-3,AIR)
B(3,15,-2,AIR)
B(3,15,-1,AIR)
B(3,15,0,AIR)
B(3,15,1,AIR)
B(3,15,2,AIR)
B(3,15,3,AIR)
B(3,15,4,AIR)
B(3,15,5,AIR)
B(3,15,6,9:8)
B(3,15,7,179)
B(3,15,8,179)
B(3,16,-7,AIR)
B(3,16,-6,AIR)
B(3,16,-5,AIR)
B(3,16,-4,AIR)
B(3,16,-3,AIR)
B(3,16,-2,AIR)
B(3,16,-1,AIR)
B(3,16,0,AIR)
B(3,16,1,AIR)
B(3,16,2,AIR)
B(3,16,3,AIR)
B(3,16,4,AIR)
B(3,16,5,AIR)
B(3,16,6,9:8)
B(3,16,7,179)
B(3,16,8,179)
B(3,17,-7,AIR)
B(3,17,-6,AIR)
B(3,17,-5,AIR)
B(3,17,-4,AIR)
B(3,17,-3,AIR)
B(3,17,-2,AIR)
B(3,17,-1,AIR)
B(3,17,0,AIR)
B(3,17,1,AIR)
B(3,17,2,AIR)
B(3,17,3,AIR)
B(3,17,4,AIR)
B(3,17,5,AIR)
B(3,17,6,9:8)
B(3,17,7,179)
B(3,17,8,179)
B(3,18,-7,179)
B(3,18,-6,179)
B(3,18,-5,179)
B(3,18,-4,179)
B(3,18,-3,179)
B(3,18,-2,179)
B(3,18,-1,159:14)
B(3,18,0,180:7)
B(3,18,1,AIR)
B(3,18,2,AIR)
B(3,18,3,AIR)
B(3,18,4,AIR)
B(3,18,5,AIR)
B(3,18,6,9:8)
B(3,18,7,179)
B(3,18,8,179)
B(3,19,-7,179)
B(3,19,-6,179)
B(3,19,-5,179)
B(3,19,-4,179)
B(3,19,-3,179)
B(3,19,-2,179)
B(3,19,-1,179)
B(3,19,0,179)
B(3,19,1,159:14)
B(3,19,2,159:14)
B(3,19,3,159:14)
B(3,19,4,159:14)
B(3,19,5,159:14)
B(3,19,6,9)
B(3,19,7,179)
B(3,19,8,179)
B(3,20,-7,AIR)
B(3,20,-6,AIR)
B(3,20,-5,179)
B(3,20,-4,AIR)
B(3,20,-3,AIR)
B(3,20,-2,AIR)
B(3,20,-1,AIR)
B(3,20,0,AIR)
B(3,20,1,AIR)
B(3,20,2,AIR)
B(3,20,3,AIR)
B(3,20,4,AIR)
B(3,20,5,179:2)
B(3,20,6,9)
B(3,20,7,179)
B(3,20,8,179)
B(3,21,-7,AIR)
B(3,21,-6,AIR)
B(3,21,-5,179)
B(3,21,-4,AIR)
B(3,21,-3,AIR)
B(3,21,-2,AIR)
B(3,21,-1,AIR)
B(3,21,0,AIR)
B(3,21,1,AIR)
B(3,21,2,AIR)
B(3,21,3,AIR)
B(3,21,4,AIR)
B(3,21,5,AIR)
B(3,21,6,AIR)
B(3,21,7,179)
B(3,21,8,179)
B(3,22,-7,AIR)
B(3,22,-6,AIR)
B(3,22,-5,179)
B(3,22,-4,AIR)
B(3,22,-3,AIR)
B(3,22,-2,AIR)
B(3,22,-1,AIR)
B(3,22,0,AIR)
B(3,22,1,AIR)
B(3,22,2,AIR)
B(3,22,3,AIR)
B(3,22,4,AIR)
B(3,22,5,AIR)
B(3,22,6,AIR)
B(3,22,7,179)
B(3,22,8,179)
B(3,23,-7,AIR)
B(3,23,-6,30)
B(3,23,-5,179)
B(3,23,-4,AIR)
B(3,23,-3,AIR)
B(3,23,-2,AIR)
B(3,23,-1,AIR)
B(3,23,0,AIR)
B(3,23,1,AIR)
B(3,23,2,AIR)
B(3,23,3,AIR)
B(3,23,4,AIR)
B(3,23,5,AIR)
B(3,23,6,AIR)
B(3,23,7,179)
B(3,23,8,179)
B(3,24,-7,AIR)
B(3,24,-6,179)
B(3,24,-5,179)
B(3,24,-4,180:7)
B(3,24,-3,AIR)
B(3,24,-2,AIR)
B(3,24,-1,AIR)
B(3,24,0,AIR)
B(3,24,1,AIR)
B(3,24,2,AIR)
B(3,24,3,AIR)
B(3,24,4,AIR)
B(3,24,5,AIR)
B(3,24,6,180:6)
B(3,24,7,180:3)
B(3,25,-7,179)
B(3,25,-6,179)
B(3,25,-5,179)
B(3,25,-4,179)
B(3,25,-3,179)
B(3,25,-2,179)
B(3,25,-1,179)
B(3,25,0,179)
B(3,25,1,179)
B(3,25,2,179)
B(3,25,3,179)
B(3,25,4,179)
B(3,25,5,159:14)
B(3,25,6,159:14)
B(3,26,-7,159:14)
B(3,26,-6,159:14)
B(3,26,-5,159:14)
B(3,26,-4,159:14)
B(3,26,-3,159:14)
B(3,26,-2,159:14)
B(3,26,-1,159:14)
B(3,26,0,159:14)
B(3,26,1,159:14)
B(3,26,2,159:14)
B(3,26,3,179)
B(3,26,4,179)
B(3,26,5,179)
B(3,26,6,180:3)
B(3,27,-7,AIR)
B(3,27,-6,AIR)
B(3,27,-5,AIR)
B(3,27,-4,AIR)
B(3,27,-3,AIR)
B(3,27,-2,AIR)
B(3,27,-1,AIR)
B(3,27,0,AIR)
B(3,27,1,AIR)
B(3,27,2,AIR)
B(3,27,3,179)
B(3,27,4,182)
B(3,27,5,182)
B(3,28,-7,AIR)
B(3,28,-6,AIR)
B(3,28,-5,AIR)
B(3,28,-4,AIR)
B(3,28,-3,AIR)
B(3,28,-2,AIR)
B(3,28,-1,AIR)
B(3,28,0,AIR)
B(3,28,1,AIR)
B(3,28,2,179:2)
B(3,29,-7,AIR)
B(3,29,-6,AIR)
B(3,29,-5,AIR)
B(3,29,-4,AIR)
B(3,29,-3,AIR)
B(3,29,-2,AIR)
B(3,29,-1,AIR)
B(3,29,0,AIR)
B(3,29,1,179)
B(3,29,2,179)
B(3,30,-7,AIR)
B(3,30,-6,AIR)
B(3,30,-5,AIR)
B(3,30,-4,AIR)
B(3,30,-3,AIR)
B(3,30,-2,AIR)
B(3,30,-1,AIR)
B(3,30,0,179)
B(3,30,1,179)
B(3,31,-7,AIR)
B(3,31,-6,AIR)
B(3,31,-5,AIR)
B(3,31,-4,AIR)
B(3,31,-3,AIR)
B(3,31,-2,AIR)
B(3,31,-1,179)
B(3,31,0,179)
B(3,32,-7,AIR)
B(3,32,-6,AIR)
B(3,32,-5,AIR)
B(3,32,-4,AIR)
B(3,32,-3,AIR)
B(3,32,-2,179)
B(3,32,-1,179)
B(3,32,0,182)
B(3,33,-7,179)
B(3,33,-6,179)
B(3,33,-5,179)
B(3,33,-4,179)
B(3,33,-3,179)
B(3,33,-2,179)
B(3,34,-7,179)
B(3,34,-6,179)
B(3,34,-5,179)
B(3,34,-4,179)
B(3,34,-3,179)
B(4,0,-7,24)
B(4,0,-6,179)
B(4,0,-5,179)
B(4,0,-4,179)
B(4,0,-3,179)
B(4,0,-2,179)
B(4,0,-1,179)
B(4,0,0,179)
B(4,0,1,179)
B(4,0,2,179)
B(4,0,3,179)
B(4,0,4,179)
B(4,0,5,179)
B(4,0,6,179)
B(4,0,7,179)
B(4,0,8,179)
B(4,1,-7,24:2)
B(4,1,-6,24:2)
B(4,1,-5,AIR)
B(4,1,-4,AIR)
B(4,1,-3,AIR)
B(4,1,-2,AIR)
B(4,1,-1,AIR)
B(4,1,0,179)
B(4,1,1,9)
B(4,1,2,179)
B(4,1,3,179)
B(4,1,4,179)
B(4,1,5,179)
B(4,1,6,179)
B(4,1,7,179)
B(4,1,8,179)
B(4,2,-7,AIR)
B(4,2,-6,24)
B(4,2,-5,AIR)
B(4,2,-4,AIR)
B(4,2,-3,AIR)
B(4,2,-2,AIR)
B(4,2,-1,AIR)
B(4,2,0,AIR)
B(4,2,1,AIR)
B(4,2,2,179)
B(4,2,3,179)
B(4,2,4,179)
B(4,2,5,179)
B(4,2,6,179)
B(4,2,7,179)
B(4,2,8,179)
B(4,3,-7,AIR)
B(4,3,-6,24)
B(4,3,-5,AIR)
B(4,3,-4,AIR)
B(4,3,-3,AIR)
B(4,3,-2,AIR)
B(4,3,-1,AIR)
B(4,3,0,AIR)
B(4,3,1,AIR)
B(4,3,2,179)
B(4,3,3,179)
B(4,3,4,179)
B(4,3,5,179)
B(4,3,6,179)
B(4,3,7,179)
B(4,3,8,179)
B(4,4,-7,24)
B(4,4,-6,AIR)
B(4,4,-5,AIR)
B(4,4,-4,AIR)
B(4,4,-3,AIR)
B(4,4,-2,AIR)
B(4,4,-1,AIR)
B(4,4,0,AIR)
B(4,4,1,AIR)
B(4,4,2,179)
B(4,4,3,179)
B(4,4,4,179)
B(4,4,5,179)
B(4,4,6,179)
B(4,4,7,179)
B(4,4,8,179)
B(4,5,-7,AIR)
B(4,5,-6,AIR)
B(4,5,-5,AIR)
B(4,5,-4,AIR)
B(4,5,-3,AIR)
B(4,5,-2,AIR)
B(4,5,-1,AIR)
B(4,5,0,AIR)
B(4,5,1,AIR)
B(4,5,2,179)
B(4,5,3,179)
B(4,5,4,179)
B(4,5,5,179)
B(4,5,6,179)
B(4,5,7,179)
B(4,5,8,179)
B(4,6,-7,AIR)
B(4,6,-6,AIR)
B(4,6,-5,AIR)
B(4,6,-4,AIR)
B(4,6,-3,AIR)
B(4,6,-2,AIR)
B(4,6,-1,AIR)
B(4,6,0,AIR)
B(4,6,1,AIR)
B(4,6,2,179)
B(4,6,3,179)
B(4,6,4,179)
B(4,6,5,179)
B(4,6,6,179)
B(4,6,7,179)
B(4,6,8,179)
B(4,7,-7,AIR)
B(4,7,-6,AIR)
B(4,7,-5,AIR)
B(4,7,-4,AIR)
B(4,7,-3,AIR)
B(4,7,-2,AIR)
B(4,7,-1,AIR)
B(4,7,0,AIR)
B(4,7,1,AIR)
B(4,7,2,179)
B(4,7,3,179)
B(4,7,4,179)
B(4,7,5,179)
B(4,7,6,179)
B(4,7,7,179)
B(4,7,8,179)
B(4,8,-7,AIR)
B(4,8,-6,AIR)
B(4,8,-5,AIR)
B(4,8,-4,AIR)
B(4,8,-3,AIR)
B(4,8,-2,AIR)
B(4,8,-1,AIR)
B(4,8,0,AIR)
B(4,8,1,AIR)
B(4,8,2,179)
B(4,8,3,179)
B(4,8,4,179)
B(4,8,5,179)
B(4,8,6,179)
B(4,8,7,179)
B(4,8,8,179)
B(4,9,-7,AIR)
B(4,9,-6,AIR)
B(4,9,-5,AIR)
B(4,9,-4,AIR)
B(4,9,-3,AIR)
B(4,9,-2,AIR)
B(4,9,-1,AIR)
B(4,9,0,AIR)
B(4,9,1,AIR)
B(4,9,2,179)
B(4,9,3,179)
B(4,9,4,179)
B(4,9,5,179)
B(4,9,6,179)
B(4,9,7,179)
B(4,9,8,179)
B(4,10,-7,AIR)
B(4,10,-6,AIR)
B(4,10,-5,AIR)
B(4,10,-4,AIR)
B(4,10,-3,AIR)
B(4,10,-2,AIR)
B(4,10,-1,AIR)
B(4,10,0,AIR)
B(4,10,1,AIR)
B(4,10,2,179)
B(4,10,3,179)
B(4,10,4,179)
B(4,10,5,179)
B(4,10,6,179)
B(4,10,7,179)
B(4,10,8,179)
B(4,11,-7,AIR)
B(4,11,-6,AIR)
B(4,11,-5,AIR)
B(4,11,-4,AIR)
B(4,11,-3,AIR)
B(4,11,-2,AIR)
B(4,11,-1,AIR)
B(4,11,0,AIR)
B(4,11,1,179)
B(4,11,2,179)
B(4,11,3,179)
B(4,11,4,179)
B(4,11,5,179)
B(4,11,6,179)
B(4,11,7,179)
B(4,11,8,179)
B(4,12,-7,AIR)
B(4,12,-6,AIR)
B(4,12,-5,AIR)
B(4,12,-4,AIR)
B(4,12,-3,AIR)
B(4,12,-2,AIR)
B(4,12,-1,AIR)
B(4,12,0,AIR)
B(4,12,1,179)
B(4,12,2,87)
B(4,12,3,179)
B(4,12,4,9)
B(4,12,5,9)
B(4,12,6,9:8)
B(4,12,7,179)
B(4,12,8,179)
B(4,13,-7,AIR)
B(4,13,-6,AIR)
B(4,13,-5,AIR)
B(4,13,-4,AIR)
B(4,13,-3,AIR)
B(4,13,-2,AIR)
B(4,13,-1,AIR)
B(4,13,0,AIR)
B(4,13,1,AIR)
B(4,13,2,51:15)
B(4,13,3,AIR)
B(4,13,4,AIR)
B(4,13,5,AIR)
B(4,13,6,9:8)
B(4,13,7,179)
B(4,13,8,179)
B(4,14,-7,AIR)
B(4,14,-6,AIR)
B(4,14,-5,AIR)
B(4,14,-4,AIR)
B(4,14,-3,AIR)
B(4,14,-2,AIR)
B(4,14,-1,AIR)
B(4,14,0,AIR)
B(4,14,1,AIR)
B(4,14,2,AIR)
B(4,14,3,AIR)
B(4,14,4,AIR)
B(4,14,5,AIR)
B(4,14,6,9:8)
B(4,14,7,179)
B(4,14,8,179)
B(4,15,-7,AIR)
B(4,15,-6,AIR)
B(4,15,-5,AIR)
B(4,15,-4,AIR)
B(4,15,-3,AIR)
B(4,15,-2,AIR)
B(4,15,-1,AIR)
B(4,15,0,AIR)
B(4,15,1,AIR)
B(4,15,2,AIR)
B(4,15,3,AIR)
B(4,15,4,AIR)
B(4,15,5,AIR)
B(4,15,6,9:8)
B(4,15,7,179)
B(4,15,8,179)
B(4,16,-7,AIR)
B(4,16,-6,AIR)
B(4,16,-5,AIR)
B(4,16,-4,AIR)
B(4,16,-3,AIR)
B(4,16,-2,AIR)
B(4,16,-1,AIR)
B(4,16,0,AIR)
B(4,16,1,AIR)
B(4,16,2,AIR)
B(4,16,3,AIR)
B(4,16,4,AIR)
B(4,16,5,AIR)
B(4,16,6,9:8)
B(4,16,7,179)
B(4,16,8,179)
B(4,17,-7,AIR)
B(4,17,-6,AIR)
B(4,17,-5,AIR)
B(4,17,-4,AIR)
B(4,17,-3,AIR)
B(4,17,-2,AIR)
B(4,17,-1,AIR)
B(4,17,0,AIR)
B(4,17,1,AIR)
B(4,17,2,AIR)
B(4,17,3,AIR)
B(4,17,4,AIR)
B(4,17,5,AIR)
B(4,17,6,9:8)
B(4,17,7,179)
B(4,17,8,179)
B(4,18,-7,179)
B(4,18,-6,179)
B(4,18,-5,179)
B(4,18,-4,179)
B(4,18,-3,179)
B(4,18,-2,179)
B(4,18,-1,159:14)
B(4,18,0,180:7)
B(4,18,1,AIR)
B(4,18,2,AIR)
B(4,18,3,AIR)
B(4,18,4,AIR)
B(4,18,5,AIR)
B(4,18,6,9:8)
B(4,18,7,179)
B(4,18,8,179)
B(4,19,-7,179)
B(4,19,-6,179)
B(4,19,-5,179)
B(4,19,-4,179)
B(4,19,-3,179)
B(4,19,-2,179)
B(4,19,-1,179)
B(4,19,0,179)
B(4,19,1,159:14)
B(4,19,2,159:14)
B(4,19,3,159:14)
B(4,19,4,159:14)
B(4,19,5,159:14)
B(4,19,6,9)
B(4,19,7,179)
B(4,19,8,179)
B(4,20,-7,AIR)
B(4,20,-6,AIR)
B(4,20,-5,179)
B(4,20,-4,AIR)
B(4,20,-3,AIR)
B(4,20,-2,AIR)
B(4,20,-1,AIR)
B(4,20,0,AIR)
B(4,20,1,AIR)
B(4,20,2,AIR)
B(4,20,3,AIR)
B(4,20,4,AIR)
B(4,20,5,179:2)
B(4,20,6,9)
B(4,20,7,179)
B(4,20,8,179)
B(4,21,-7,AIR)
B(4,21,-6,AIR)
B(4,21,-5,179)
B(4,21,-4,AIR)
B(4,21,-3,AIR)
B(4,21,-2,AIR)
B(4,21,-1,AIR)
B(4,21,0,AIR)
B(4,21,1,AIR)
B(4,21,2,AIR)
B(4,21,3,AIR)
B(4,21,4,AIR)
B(4,21,5,AIR)
B(4,21,6,AIR)
B(4,21,7,179)
B(4,21,8,179)
B(4,22,-7,AIR)
B(4,22,-6,AIR)
B(4,22,-5,179)
B(4,22,-4,AIR)
B(4,22,-3,AIR)
B(4,22,-2,AIR)
B(4,22,-1,AIR)
B(4,22,0,AIR)
B(4,22,1,AIR)
B(4,22,2,AIR)
B(4,22,3,AIR)
B(4,22,4,AIR)
B(4,22,5,AIR)
B(4,22,6,AIR)
B(4,22,7,179)
B(4,22,8,179)
B(4,23,-7,AIR)
B(4,23,-6,AIR)
B(4,23,-5,179)
B(4,23,-4,AIR)
B(4,23,-3,AIR)
B(4,23,-2,AIR)
B(4,23,-1,AIR)
B(4,23,0,AIR)
B(4,23,1,AIR)
B(4,23,2,AIR)
B(4,23,3,AIR)
B(4,23,4,AIR)
B(4,23,5,AIR)
B(4,23,6,AIR)
B(4,23,7,179)
B(4,23,8,179)
B(4,24,-7,AIR)
B(4,24,-6,179)
B(4,24,-5,179)
B(4,24,-4,180:7)
B(4,24,-3,AIR)
B(4,24,-2,AIR)
B(4,24,-1,AIR)
B(4,24,0,AIR)
B(4,24,1,AIR)
B(4,24,2,AIR)
B(4,24,3,AIR)
B(4,24,4,AIR)
B(4,24,5,AIR)
B(4,24,6,180:6)
B(4,24,7,180:3)
B(4,25,-7,179)
B(4,25,-6,179)
B(4,25,-5,179)
B(4,25,-4,179)
B(4,25,-3,179)
B(4,25,-2,179)
B(4,25,-1,179)
B(4,25,0,179)
B(4,25,1,179)
B(4,25,2,179)
B(4,25,3,179)
B(4,25,4,179)
B(4,25,5,159:14)
B(4,25,6,159:14)
B(4,26,-7,159:14)
B(4,26,-6,179)
B(4,26,-5,179)
B(4,26,-4,179)
B(4,26,-3,179)
B(4,26,-2,179)
B(4,26,-1,179)
B(4,26,0,179)
B(4,26,1,179)
B(4,26,2,179)
B(4,26,3,179)
B(4,26,4,179)
B(4,26,5,179)
B(4,26,6,180:3)
B(4,27,-7,AIR)
B(4,27,-6,179:2)
B(4,27,-5,AIR)
B(4,27,-4,AIR)
B(4,27,-3,AIR)
B(4,27,-2,AIR)
B(4,27,-1,AIR)
B(4,27,0,AIR)
B(4,27,1,AIR)
B(4,27,2,AIR)
B(4,27,3,179)
B(4,27,4,182)
B(4,27,5,181)
B(4,28,-7,AIR)
B(4,28,-6,179:2)
B(4,28,-5,AIR)
B(4,28,-4,AIR)
B(4,28,-3,AIR)
B(4,28,-2,AIR)
B(4,28,-1,AIR)
B(4,28,0,AIR)
B(4,28,1,AIR)
B(4,28,2,179:2)
B(4,28,3,182)
B(4,28,5,179:1)
B(4,29,-7,AIR)
B(4,29,-6,159:1)
B(4,29,-5,AIR)
B(4,29,-4,AIR)
B(4,29,-3,AIR)
B(4,29,-2,AIR)
B(4,29,-1,AIR)
B(4,29,0,AIR)
B(4,29,1,179)
B(4,29,2,179)
B(4,30,-7,AIR)
B(4,30,-6,159:1)
B(4,30,-5,AIR)
B(4,30,-4,AIR)
B(4,30,-3,AIR)
B(4,30,-2,AIR)
B(4,30,-1,AIR)
B(4,30,0,179)
B(4,30,1,179)
B(4,31,-7,AIR)
B(4,31,-6,159:1)
B(4,31,-5,AIR)
B(4,31,-4,AIR)
B(4,31,-3,AIR)
B(4,31,-2,AIR)
B(4,31,-1,179)
B(4,31,0,179)
B(4,32,-7,AIR)
B(4,32,-6,159:1)
B(4,32,-5,AIR)
B(4,32,-4,AIR)
B(4,32,-3,AIR)
B(4,32,-2,179)
B(4,32,-1,179)
B(4,32,0,182)
B(4,33,-7,AIR)
B(4,33,-6,179:1)
B(4,33,-5,AIR)
B(4,33,-4,AIR)
B(4,33,-3,179)
B(4,33,-2,179)
B(4,34,-7,179)
B(4,34,-6,179)
B(4,34,-5,179)
B(4,34,-4,179)
B(4,34,-3,179)
B(4,35,-7,182:8)
B(4,35,-6,182:8)
B(4,35,-5,182:8)
B(4,35,-4,182:8)
B(4,36,-7,182)
B(4,36,-6,182)
B(4,36,-5,182)
B(4,36,-4,182)
B(5,0,-7,179)
B(5,0,-6,179)
B(5,0,-5,179)
B(5,0,-4,179)
B(5,0,-3,179)
B(5,0,-2,179)
B(5,0,-1,179)
B(5,0,0,179)
B(5,0,1,179)
B(5,0,2,179)
B(5,0,3,179)
B(5,0,4,179)
B(5,0,5,179)
B(5,0,6,179)
B(5,0,7,179)
B(5,0,8,179)
B(5,1,-7,24)
B(5,1,-6,AIR)
B(5,1,-5,AIR)
B(5,1,-4,AIR)
B(5,1,-3,AIR)
B(5,1,-2,AIR)
B(5,1,-1,AIR)
B(5,1,0,179)
B(5,1,1,9)
B(5,1,2,9)
B(5,1,3,179)
B(5,1,4,9:9)
B(5,1,5,179)
B(5,1,6,179)
B(5,1,7,179)
B(5,1,8,179)
B(5,2,-7,24)
B(5,2,-6,76:3)
B(5,2,-5,AIR)
B(5,2,-4,AIR)
B(5,2,-3,AIR)
B(5,2,-2,AIR)
B(5,2,-1,AIR)
B(5,2,0,AIR)
B(5,2,1,AIR)
B(5,2,2,AIR)
B(5,2,3,179)
B(5,2,4,9:9)
B(5,2,5,179)
B(5,2,6,179)
B(5,2,7,179)
B(5,2,8,179)
B(5,3,-7,24)
B(5,3,-6,24)
B(5,3,-5,AIR)
B(5,3,-4,AIR)
B(5,3,-3,AIR)
B(5,3,-2,AIR)
B(5,3,-1,AIR)
B(5,3,0,AIR)
B(5,3,1,AIR)
B(5,3,2,AIR)
B(5,3,3,179)
B(5,3,4,9:9)
B(5,3,5,179)
B(5,3,6,179)
B(5,3,7,179)
B(5,3,8,179)
B(5,4,-7,24)
B(5,4,-6,24)
B(5,4,-5,AIR)
B(5,4,-4,AIR)
B(5,4,-3,AIR)
B(5,4,-2,AIR)
B(5,4,-1,AIR)
B(5,4,0,AIR)
B(5,4,1,AIR)
B(5,4,2,AIR)
B(5,4,3,AIR)
B(5,4,4,9:9)
B(5,4,5,179)
B(5,4,6,179)
B(5,4,7,179)
B(5,4,8,179)
B(5,5,-7,AIR)
B(5,5,-6,AIR)
B(5,5,-5,AIR)
B(5,5,-4,AIR)
B(5,5,-3,AIR)
B(5,5,-2,AIR)
B(5,5,-1,AIR)
B(5,5,0,AIR)
B(5,5,1,AIR)
B(5,5,2,AIR)
B(5,5,3,AIR)
B(5,5,4,9:9)
B(5,5,5,179)
B(5,5,6,179)
B(5,5,7,179)
B(5,5,8,179)
B(5,6,-7,AIR)
B(5,6,-6,AIR)
B(5,6,-5,AIR)
B(5,6,-4,AIR)
B(5,6,-3,AIR)
B(5,6,-2,AIR)
B(5,6,-1,AIR)
B(5,6,0,AIR)
B(5,6,1,AIR)
B(5,6,2,AIR)
B(5,6,3,AIR)
B(5,6,4,9:1)
B(5,6,5,9:9)
B(5,6,6,179)
B(5,6,7,179)
B(5,6,8,179)
B(5,7,-7,AIR)
B(5,7,-6,AIR)
B(5,7,-5,AIR)
B(5,7,-4,AIR)
B(5,7,-3,AIR)
B(5,7,-2,AIR)
B(5,7,-1,AIR)
B(5,7,0,AIR)
B(5,7,1,AIR)
B(5,7,2,AIR)
B(5,7,3,AIR)
B(5,7,4,AIR)
B(5,7,5,9:9)
B(5,7,6,179)
B(5,7,7,179)
B(5,7,8,179)
B(5,8,-7,AIR)
B(5,8,-6,AIR)
B(5,8,-5,AIR)
B(5,8,-4,AIR)
B(5,8,-3,AIR)
B(5,8,-2,AIR)
B(5,8,-1,AIR)
B(5,8,0,AIR)
B(5,8,1,AIR)
B(5,8,2,AIR)
B(5,8,3,AIR)
B(5,8,4,AIR)
B(5,8,5,9:1)
B(5,8,6,9:9)
B(5,8,7,179)
B(5,8,8,179)
B(5,9,-7,AIR)
B(5,9,-6,AIR)
B(5,9,-5,AIR)
B(5,9,-4,AIR)
B(5,9,-3,AIR)
B(5,9,-2,AIR)
B(5,9,-1,AIR)
B(5,9,0,AIR)
B(5,9,1,AIR)
B(5,9,2,AIR)
B(5,9,3,AIR)
B(5,9,4,AIR)
B(5,9,5,AIR)
B(5,9,6,9:1)
B(5,9,7,179)
B(5,9,8,179)
B(5,10,-7,AIR)
B(5,10,-6,AIR)
B(5,10,-5,AIR)
B(5,10,-4,AIR)
B(5,10,-3,AIR)
B(5,10,-2,AIR)
B(5,10,-1,AIR)
B(5,10,0,AIR)
B(5,10,1,AIR)
B(5,10,2,AIR)
B(5,10,3,179)
B(5,10,4,179)
B(5,10,5,179)
B(5,10,6,179)
B(5,10,7,179)
B(5,10,8,179)
B(5,11,-7,AIR)
B(5,11,-6,AIR)
B(5,11,-5,AIR)
B(5,11,-4,AIR)
B(5,11,-3,AIR)
B(5,11,-2,AIR)
B(5,11,-1,AIR)
B(5,11,0,AIR)
B(5,11,1,AIR)
B(5,11,2,179)
B(5,11,3,179)
B(5,11,4,179)
B(5,11,5,179)
B(5,11,6,179)
B(5,11,7,179)
B(5,11,8,179)
B(5,12,-7,AIR)
B(5,12,-6,AIR)
B(5,12,-5,AIR)
B(5,12,-4,AIR)
B(5,12,-3,AIR)
B(5,12,-2,AIR)
B(5,12,-1,AIR)
B(5,12,0,AIR)
B(5,12,1,179)
B(5,12,2,179)
B(5,12,3,179)
B(5,12,4,9)
B(5,12,5,9)
B(5,12,6,179)
B(5,12,7,179)
B(5,12,8,179)
B(5,13,-7,AIR)
B(5,13,-6,AIR)
B(5,13,-5,AIR)
B(5,13,-4,AIR)
B(5,13,-3,AIR)
B(5,13,-2,AIR)
B(5,13,-1,AIR)
B(5,13,0,AIR)
B(5,13,1,AIR)
B(5,13,2,AIR)
B(5,13,3,AIR)
B(5,13,4,AIR)
B(5,13,5,AIR)
B(5,13,6,179)
B(5,13,7,179)
B(5,13,8,179)
B(5,14,-7,AIR)
B(5,14,-6,AIR)
B(5,14,-5,AIR)
B(5,14,-4,AIR)
B(5,14,-3,AIR)
B(5,14,-2,AIR)
B(5,14,-1,AIR)
B(5,14,0,AIR)
B(5,14,1,AIR)
B(5,14,2,AIR)
B(5,14,3,AIR)
B(5,14,4,AIR)
B(5,14,5,AIR)
B(5,14,6,179)
B(5,14,7,179)
B(5,14,8,179)
B(5,15,-7,AIR)
B(5,15,-6,AIR)
B(5,15,-5,AIR)
B(5,15,-4,AIR)
B(5,15,-3,AIR)
B(5,15,-2,AIR)
B(5,15,-1,AIR)
B(5,15,0,AIR)
B(5,15,1,AIR)
B(5,15,2,AIR)
B(5,15,3,AIR)
B(5,15,4,AIR)
B(5,15,5,AIR)
B(5,15,6,179)
B(5,15,7,179)
B(5,15,8,179)
B(5,16,-7,AIR)
B(5,16,-6,AIR)
B(5,16,-5,AIR)
B(5,16,-4,AIR)
B(5,16,-3,AIR)
B(5,16,-2,AIR)
B(5,16,-1,AIR)
B(5,16,0,AIR)
B(5,16,1,AIR)
B(5,16,2,AIR)
B(5,16,3,AIR)
B(5,16,4,AIR)
B(5,16,5,AIR)
B(5,16,6,179)
B(5,16,7,179)
B(5,16,8,179)
B(5,17,-7,AIR)
B(5,17,-6,AIR)
B(5,17,-5,AIR)
B(5,17,-4,AIR)
B(5,17,-3,AIR)
B(5,17,-2,AIR)
B(5,17,-1,AIR)
B(5,17,0,AIR)
B(5,17,1,AIR)
B(5,17,2,AIR)
B(5,17,3,AIR)
B(5,17,4,AIR)
B(5,17,5,AIR)
B(5,17,6,179)
B(5,17,7,179)
B(5,17,8,179)
B(5,18,-7,159:14)
B(5,18,-6,159:14)
B(5,18,-5,159:14)
B(5,18,-4,159:14)
B(5,18,-3,159:14)
B(5,18,-2,159:14)
B(5,18,-1,159:14)
B(5,18,0,180:7)
B(5,18,1,AIR)
B(5,18,2,AIR)
B(5,18,3,AIR)
B(5,18,4,AIR)
B(5,18,5,180:6)
B(5,18,6,179)
B(5,18,7,179)
B(5,18,8,179)
B(5,19,-7,179)
B(5,19,-6,179)
B(5,19,-5,179)
B(5,19,-4,179)
B(5,19,-3,179)
B(5,19,-2,179)
B(5,19,-1,179)
B(5,19,0,179)
B(5,19,1,159:14)
B(5,19,2,159:14)
B(5,19,3,179)
B(5,19,4,179)
B(5,19,5,179)
B(5,19,6,179)
B(5,19,7,179)
B(5,19,8,179)
B(5,20,-7,AIR)
B(5,20,-6,AIR)
B(5,20,-5,179)
B(5,20,-4,AIR)
B(5,20,-3,179:2)
B(5,20,-2,AIR)
B(5,20,-1,AIR)
B(5,20,0,179:2)
B(5,20,1,AIR)
B(5,20,2,AIR)
B(5,20,3,179:2)
B(5,20,4,179:2)
B(5,20,5,179:2)
B(5,20,6,179:2)
B(5,20,7,179)
B(5,20,8,179)
B(5,21,-7,AIR)
B(5,21,-6,AIR)
B(5,21,-5,179)
B(5,21,-4,AIR)
B(5,21,-3,159:1)
B(5,21,-2,AIR)
B(5,21,-1,AIR)
B(5,21,0,159:1)
B(5,21,1,AIR)
B(5,21,2,AIR)
B(5,21,3,159:1)
B(5,21,4,AIR)
B(5,21,5,AIR)
B(5,21,6,159:1)
B(5,21,7,179)
B(5,21,8,179)
B(5,22,-7,AIR)
B(5,22,-6,AIR)
B(5,22,-5,179)
B(5,22,-4,AIR)
B(5,22,-3,159:1)
B(5,22,-2,AIR)
B(5,22,-1,AIR)
B(5,22,0,159:1)
B(5,22,1,AIR)
B(5,22,2,AIR)
B(5,22,3,159:1)
B(5,22,4,AIR)
B(5,22,5,AIR)
B(5,22,6,159:1)
B(5,22,7,179)
B(5,22,8,179)
B(5,23,-7,AIR)
B(5,23,-6,AIR)
B(5,23,-5,179)
B(5,23,-4,AIR)
B(5,23,-3,179:1)
B(5,23,-2,AIR)
B(5,23,-1,AIR)
B(5,23,0,179:1)
B(5,23,1,AIR)
B(5,23,2,AIR)
B(5,23,3,179:1)
B(5,23,4,AIR)
B(5,23,5,AIR)
B(5,23,6,159:1)
B(5,23,7,179)
B(5,23,8,179)
B(5,24,-7,AIR)
B(5,24,-6,179)
B(5,24,-5,179)
B(5,24,-4,180:7)
B(5,24,-3,AIR)
B(5,24,-2,AIR)
B(5,24,-1,AIR)
B(5,24,0,AIR)
B(5,24,1,AIR)
B(5,24,2,AIR)
B(5,24,3,AIR)
B(5,24,4,AIR)
B(5,24,5,AIR)
B(5,24,6,179:1)
B(5,24,7,180:3)
B(5,25,-7,179)
B(5,25,-6,179)
B(5,25,-5,179)
B(5,25,-4,179)
B(5,25,-3,179)
B(5,25,-2,179)
B(5,25,-1,179)
B(5,25,0,179)
B(5,25,1,179)
B(5,25,2,179)
B(5,25,3,179)
B(5,25,4,179)
B(5,25,5,159:14)
B(5,25,6,179:2)
B(5,26,-7,159:14)
B(5,26,-6,159:14)
B(5,26,-5,179)
B(5,26,-4,179)
B(5,26,-3,179)
B(5,26,-2,179)
B(5,26,-1,179)
B(5,26,0,179)
B(5,26,1,179)
B(5,26,2,179)
B(5,26,3,179)
B(5,26,4,179)
B(5,26,5,179)
B(5,26,6,180:3)
B(5,27,-7,AIR)
B(5,27,-6,AIR)
B(5,27,-5,AIR)
B(5,27,-4,AIR)
B(5,27,-3,AIR)
B(5,27,-2,AIR)
B(5,27,-1,AIR)
B(5,27,0,AIR)
B(5,27,1,AIR)
B(5,27,2,179)
B(5,27,3,179)
B(5,27,4,182)
B(5,27,5,182)
B(5,28,-7,AIR)
B(5,28,-6,AIR)
B(5,28,-5,AIR)
B(5,28,-4,AIR)
B(5,28,-3,AIR)
B(5,28,-2,AIR)
B(5,28,-1,AIR)
B(5,28,0,AIR)
B(5,28,1,AIR)
B(5,28,2,179:2)
B(5,28,3,179)
B(5,29,-7,AIR)
B(5,29,-6,AIR)
B(5,29,-5,AIR)
B(5,29,-4,AIR)
B(5,29,-3,AIR)
B(5,29,-2,AIR)
B(5,29,-1,AIR)
B(5,29,0,AIR)
B(5,29,1,179)
B(5,29,2,179)
B(5,29,3,180:0)
B(5,30,-7,AIR)
B(5,30,-6,AIR)
B(5,30,-5,AIR)
B(5,30,-4,AIR)
B(5,30,-3,AIR)
B(5,30,-2,AIR)
B(5,30,-1,AIR)
B(5,30,0,179)
B(5,30,1,179)
B(5,30,2,182)
B(5,31,-7,AIR)
B(5,31,-6,AIR)
B(5,31,-5,AIR)
B(5,31,-4,AIR)
B(5,31,-3,AIR)
B(5,31,-2,AIR)
B(5,31,-1,179)
B(5,31,0,179)
B(5,31,1,182)
B(5,32,-7,AIR)
B(5,32,-6,AIR)
B(5,32,-5,AIR)
B(5,32,-4,AIR)
B(5,32,-3,AIR)
B(5,32,-2,179)
B(5,32,-1,179)
B(5,32,0,182)
B(5,33,-7,AIR)
B(5,33,-6,AIR)
B(5,33,-5,AIR)
B(5,33,-4,AIR)
B(5,33,-3,179)
B(5,33,-2,179)
B(5,34,-7,AIR)
B(5,34,-6,AIR)
B(5,34,-5,AIR)
B(5,34,-4,179)
B(5,34,-3,179)
B(5,35,-7,159:14)
B(5,35,-6,159:14)
B(5,35,-5,159:14)
B(5,35,-4,182:8)
B(5,36,-7,159:14)
B(5,36,-6,159:14)
B(5,36,-5,159:14)
B(5,36,-4,182)
B(5,37,-7,182)
B(5,37,-6,182)
B(5,37,-5,182)
B(6,0,-7,179)
B(6,0,-6,179)
B(6,0,-5,179)
B(6,0,-4,179)
B(6,0,-3,179)
B(6,0,-2,179)
B(6,0,-1,179)
B(6,0,0,179)
B(6,0,1,179)
B(6,0,2,179)
B(6,0,3,179)
B(6,0,4,179)
B(6,0,5,179)
B(6,0,6,179)
B(6,0,7,179)
B(6,0,8,179)
B(6,1,-7,24:2)
