
#######################################################################
# +-----------------------------------------------------------------+ #
# |                            BO3 object                           | #
# +-----------------------------------------------------------------+ #
#######################################################################

Author: LordSmellyPants

Description: No description given

Version: 3

SettingsMode: WriteWithoutComments


#######################################################################
# +-----------------------------------------------------------------+ #
# |                          Main settings                          | #
# +-----------------------------------------------------------------+ #
#######################################################################

Tree: true

Frequency: 0

Rarity: 100.0

RotateRandomly: true

SpawnHeight: highestSolidBlock

SpawnHeightOffset: 0

SpawnHeightVariance: 0

##############################
# Height Limits for the BO3. #
##############################

MinHeight: 0

MaxHeight: 40

######################
# Extrusion settings #
######################

ExtrudeMode: BottomDown

ExtrudeThroughBlocks: AIR

MaxBranchDepth: 10

ExcludedBiomes: All


#######################################################################
# +-----------------------------------------------------------------+ #
# |                      Source block settings                      | #
# +-----------------------------------------------------------------+ #
#######################################################################

SourceBlocks: AIR

MaxPercentageOutsideSourceBlock: 0

OutsideSourceBlock: placeAnyway

DoReplaceBlocks: true

IsOTGPlus: false


#######################################################################
# +-----------------------------------------------------------------+ #
# |                              Blocks                             | #
# +-----------------------------------------------------------------+ #
#######################################################################

Block(-2,0,-1,CONCRETE:5)
Block(-2,0,0,CONCRETE:5)
Block(-2,1,0,CONCRETE:5)
Block(-1,0,-2,CONCRETE:5)
Block(-1,0,-1,CONCRETE:5)
Block(-1,0,0,CONCRETE:5)
Block(-1,0,1,CONCRETE:5)
Block(-1,1,-1,CONCRETE:5)
Block(-1,1,0,CONCRETE:5)
Block(-1,1,1,CONCRETE:5)
Block(-1,2,-1,CONCRETE:5)
Block(-1,2,0,CONCRETE:5)
Block(-1,2,1,CONCRETE:13)
Block(-1,3,0,CONCRETE:13)
Block(0,0,-2,CONCRETE:5)
Block(0,0,-1,CONCRETE:5)
Block(0,0,0,CONCRETE:5)
Block(0,0,1,CONCRETE:5)
Block(0,0,2,CONCRETE:5)
Block(0,1,-2,CONCRETE:5)
Block(0,1,-1,CONCRETE:5)
Block(0,1,0,CONCRETE:5)
Block(0,1,1,CONCRETE:5)
Block(0,1,2,CONCRETE:5)
Block(0,2,-2,CONCRETE:5)
Block(0,2,-1,CONCRETE:5)
Block(0,2,0,CONCRETE:5)
Block(0,2,1,CONCRETE:5)
Block(0,2,2,CONCRETE:5)
Block(0,3,-1,CONCRETE:13)
Block(0,3,0,CONCRETE:5)
Block(0,3,1,CONCRETE:13)
Block(0,4,-1,CONCRETE:5)
Block(0,4,0,CONCRETE:5)
Block(0,4,1,CONCRETE:5)
Block(1,0,-2,CONCRETE:5)
Block(1,0,-1,CONCRETE:5)
Block(1,0,0,CONCRETE:5)
Block(1,0,1,CONCRETE:5)
Block(1,0,2,CONCRETE:5)
Block(1,1,-2,CONCRETE:5)
Block(1,1,-1,CONCRETE:5)
Block(1,1,0,CONCRETE:5)
Block(1,1,1,CONCRETE:5)
Block(1,1,2,CONCRETE:5)
Block(1,2,-2,CONCRETE:5)
Block(1,2,-1,CONCRETE:5)
Block(1,2,0,CONCRETE:5)
Block(1,2,1,CONCRETE:5)
Block(1,2,2,CONCRETE:5)
Block(1,3,-2,CONCRETE:5)
Block(1,3,-1,CONCRETE:5)
Block(1,3,0,CONCRETE:5)
Block(1,3,1,CONCRETE:5)
Block(1,3,2,CONCRETE:5)
Block(1,4,-2,CONCRETE:13)
Block(1,4,-1,CONCRETE:5)
Block(1,4,0,CONCRETE:5)
Block(1,4,1,CONCRETE:13)
Block(1,5,-1,CONCRETE:5)
Block(1,5,0,CONCRETE:5)
Block(2,0,-1,CONCRETE:5)
Block(2,0,0,CONCRETE:5)
Block(2,0,1,CONCRETE:5)
Block(2,1,-1,CONCRETE:5)
Block(2,1,0,CONCRETE:5)
Block(2,1,1,CONCRETE:5)
Block(2,2,-2,CONCRETE:5)
Block(2,2,-1,CONCRETE:5)
Block(2,2,0,CONCRETE:5)
Block(2,2,1,CONCRETE:5)
Block(2,3,-2,CONCRETE:5)
Block(2,3,-1,CONCRETE:5)
Block(2,3,0,CONCRETE:5)
Block(2,3,1,CONCRETE:5)
Block(2,4,-2,CONCRETE:5)
Block(2,4,-1,CONCRETE:5)
Block(2,4,0,CONCRETE:5)
Block(2,4,1,CONCRETE:5)
Block(2,5,-2,CONCRETE:13)
Block(2,5,-1,CONCRETE:5)
Block(2,5,0,CONCRETE:5)
Block(2,5,1,CONCRETE:5)
Block(2,6,-1,CONCRETE:5)
Block(2,6,0,CONCRETE:5)
Block(3,2,-1,CONCRETE:5)
Block(3,2,0,CONCRETE:5)
Block(3,3,-2,CONCRETE:5)
Block(3,3,-1,CONCRETE:5)
Block(3,3,0,CONCRETE:5)
Block(3,3,1,CONCRETE:5)
Block(3,4,-3,CONCRETE:5)
Block(3,4,-2,CONCRETE:5)
Block(3,4,-1,CONCRETE:5)
Block(3,4,0,CONCRETE:5)
Block(3,4,1,CONCRETE:13)
Block(3,5,-3,CONCRETE:13)
Block(3,5,-2,CONCRETE:5)
Block(3,5,-1,CONCRETE:5)
Block(3,5,0,CONCRETE:5)
Block(3,5,1,CONCRETE:5)
Block(3,6,-2,CONCRETE:5)
Block(3,6,-1,CONCRETE:5)
Block(3,6,0,CONCRETE:5)
Block(3,7,-1,CONCRETE:5)
Block(3,7,0,CONCRETE:5)
Block(4,3,-2,CONCRETE:5)
Block(4,3,-1,CONCRETE:5)
Block(4,3,0,CONCRETE:5)
Block(4,4,-2,CONCRETE:13)
Block(4,4,-1,CONCRETE:5)
Block(4,4,0,CONCRETE:5)
Block(4,5,-3,CONCRETE:5)
Block(4,5,-2,CONCRETE:5)
Block(4,5,-1,CONCRETE:5)
Block(4,5,0,CONCRETE:5)
Block(4,5,1,CONCRETE:13)
Block(4,6,-2,CONCRETE:5)
Block(4,6,-1,CONCRETE:5)
Block(4,6,0,CONCRETE:5)
Block(4,6,1,CONCRETE:5)
Block(4,7,-2,CONCRETE:5)
Block(4,7,-1,CONCRETE:5)
Block(4,7,0,CONCRETE:5)
Block(4,7,1,CONCRETE:13)
Block(4,8,0,CONCRETE:5)
Block(4,13,4,CONCRETE:4)
Block(4,14,5,CONCRETE:4)
Block(4,15,5,CONCRETE:4)
Block(4,16,5,CONCRETE:4)
Block(4,16,6,CONCRETE:4)
Block(4,17,5,CONCRETE:4)
Block(4,17,6,CONCRETE:4)
Block(4,18,6,CONCRETE:4)
Block(4,19,6,CONCRETE:4)
Block(5,4,-2,CONCRETE:5)
Block(5,4,-1,CONCRETE:5)
Block(5,4,0,CONCRETE:5)
Block(5,5,-2,CONCRETE:5)
Block(5,5,-1,CONCRETE:5)
Block(5,5,0,CONCRETE:5)
Block(5,5,1,CONCRETE:5)
Block(5,6,-2,CONCRETE:5)
Block(5,6,-1,CONCRETE:5)
Block(5,6,0,CONCRETE:5)
Block(5,6,1,CONCRETE:5)
Block(5,7,-2,CONCRETE:5)
Block(5,7,-1,CONCRETE:5)
Block(5,7,0,CONCRETE:5)
Block(5,7,1,CONCRETE:5)
Block(5,7,2,CONCRETE:5)
Block(5,8,-1,CONCRETE:5)
Block(5,8,0,CONCRETE:5)
Block(5,8,1,CONCRETE:5)
Block(5,8,2,CONCRETE:5)
Block(5,9,1,CONCRETE:5)
Block(5,9,2,CONCRETE:5)
Block(5,11,4,CONCRETE:13)
Block(5,12,3,CONCRETE:5)
Block(5,12,4,CONCRETE:4)
Block(5,12,5,CONCRETE:4)
Block(5,13,3,CONCRETE:4)
Block(5,13,4,CONCRETE:5)
Block(5,13,5,CONCRETE:4)
Block(5,14,4,CONCRETE:4)
Block(5,14,5,CONCRETE:5)
Block(5,14,6,CONCRETE:4)
Block(5,15,5,CONCRETE:4)
Block(5,15,6,CONCRETE:4)
Block(5,16,5,CONCRETE:4)
Block(5,16,6,CONCRETE:4)
Block(5,17,6,CONCRETE:4)
Block(6,5,-1,CONCRETE:5)
Block(6,5,0,CONCRETE:5)
Block(6,6,-1,CONCRETE:5)
Block(6,6,0,CONCRETE:5)
Block(6,6,1,CONCRETE:5)
Block(6,6,2,CONCRETE:5)
Block(6,7,-1,CONCRETE:5)
Block(6,7,0,CONCRETE:5)
Block(6,7,1,CONCRETE:5)
Block(6,7,2,CONCRETE:5)
Block(6,8,-1,CONCRETE:5)
Block(6,8,0,CONCRETE:5)
Block(6,8,1,CONCRETE:5)
Block(6,8,2,CONCRETE:5)
Block(6,8,3,CONCRETE:13)
Block(6,9,1,CONCRETE:5)
Block(6,9,2,CONCRETE:5)
Block(6,9,3,CONCRETE:5)
Block(6,9,4,CONCRETE:5)
Block(6,10,2,CONCRETE:13)
Block(6,10,3,CONCRETE:13)
Block(6,10,4,CONCRETE:13)
Block(6,11,2,CONCRETE:5)
Block(6,11,3,CONCRETE:5)
Block(6,11,4,CONCRETE:5)
Block(6,11,5,CONCRETE:4)
Block(6,12,3,CONCRETE:5)
Block(6,12,4,CONCRETE:5)
Block(6,12,5,CONCRETE:4)
Block(6,13,3,CONCRETE:5)
Block(6,13,4,CONCRETE:5)
Block(6,13,5,CONCRETE:5)
Block(6,13,6,CONCRETE:4)
Block(6,14,4,CONCRETE:4)
Block(6,14,5,CONCRETE:4)
Block(7,6,0,CONCRETE:13)
Block(7,6,1,CONCRETE:5)
Block(7,7,-1,CONCRETE:5)
Block(7,7,0,CONCRETE:5)
Block(7,7,1,CONCRETE:5)
Block(7,7,2,CONCRETE:5)
Block(7,8,0,CONCRETE:5)
Block(7,8,1,CONCRETE:5)
Block(7,8,2,CONCRETE:5)
Block(7,8,3,CONCRETE:13)
Block(7,9,1,CONCRETE:5)
Block(7,9,2,CONCRETE:5)
Block(7,9,3,CONCRETE:5)
Block(7,9,4,CONCRETE:5)
Block(7,10,2,CONCRETE:5)
Block(7,10,3,CONCRETE:5)
Block(7,10,4,CONCRETE:13)
Block(7,11,2,CONCRETE:5)
Block(7,11,3,CONCRETE:5)
Block(7,11,4,CONCRETE:5)
Block(7,12,3,CONCRETE:5)
Block(7,12,4,CONCRETE:5)
Block(7,12,5,CONCRETE:4)
Block(7,13,4,CONCRETE:4)
Block(7,13,5,CONCRETE:4)
Block(8,7,0,CONCRETE:13)
Block(8,7,1,CONCRETE:5)
Block(8,8,1,CONCRETE:5)
Block(8,8,2,CONCRETE:5)
Block(8,9,2,CONCRETE:5)
Block(8,9,3,CONCRETE:5)
Block(8,10,3,CONCRETE:13)
Block(8,11,3,CONCRETE:5)
Block(8,11,4,CONCRETE:5)
Block(8,12,4,CONCRETE:5)
Block(9,0,14,STAINED_CLAY:5)
Block(9,1,14,STAINED_CLAY:5)
Block(9,2,14,STAINED_CLAY:5)
Block(9,3,14,STAINED_CLAY:5)
Block(9,4,14,STAINED_CLAY:5)
Block(13,0,14,STONE:0)

#######################################################################
# +-----------------------------------------------------------------+ #
# |                            BO3 checks                           | #
# +-----------------------------------------------------------------+ #
#######################################################################

BlockCheck(0,-1,0,GRASS,DIRT)

#######################################################################
# +-----------------------------------------------------------------+ #
# |                             Branches                            | #
# +-----------------------------------------------------------------+ #
#######################################################################


#######################################################################
# +-----------------------------------------------------------------+ #
# |                             Entities                            | #
# +-----------------------------------------------------------------+ #
#######################################################################


#######################################################################
# +-----------------------------------------------------------------+ #
# |                            Particles                            | #
# +-----------------------------------------------------------------+ #
#######################################################################


#######################################################################
# +-----------------------------------------------------------------+ #
# |                             Spawners                            | #
# +-----------------------------------------------------------------+ #
#######################################################################


#######################################################################
# +-----------------------------------------------------------------+ #
# |                             ModData                             | #
# +-----------------------------------------------------------------+ #
#######################################################################

