
#######################################################################
# +-----------------------------------------------------------------+ #
# |                            BO3 object                           | #
# +-----------------------------------------------------------------+ #
#######################################################################

Author: LordSmellyPants

Description: No description given

Version: 3

SettingsMode: WriteWithoutComments


#######################################################################
# +-----------------------------------------------------------------+ #
# |                          Main settings                          | #
# +-----------------------------------------------------------------+ #
#######################################################################

Tree: true

Frequency: 0

Rarity: 100.0

RotateRandomly: true

SpawnHeight: highestSolidBlock

SpawnHeightOffset: 0

SpawnHeightVariance: 0

##############################
# Height Limits for the BO3. #
##############################

MinHeight: 0

MaxHeight: 40

######################
# Extrusion settings #
######################

ExtrudeMode: BottomDown

ExtrudeThroughBlocks: AIR

MaxBranchDepth: 10

ExcludedBiomes: All


#######################################################################
# +-----------------------------------------------------------------+ #
# |                      Source block settings                      | #
# +-----------------------------------------------------------------+ #
#######################################################################

SourceBlocks: AIR

MaxPercentageOutsideSourceBlock: 0

OutsideSourceBlock: placeAnyway

DoReplaceBlocks: true

IsOTGPlus: false


#######################################################################
# +-----------------------------------------------------------------+ #
# |                              Blocks                             | #
# +-----------------------------------------------------------------+ #
#######################################################################

Block(-5,0,-2,CONCRETE:5)
Block(-5,0,-1,CONCRETE:5)
Block(-5,0,0,CONCRETE:5)
Block(-5,1,-1,CONCRETE:5)
Block(-4,0,-3,CONCRETE:5)
Block(-4,0,-2,CONCRETE:5)
Block(-4,0,-1,CONCRETE:5)
Block(-4,0,0,CONCRETE:5)
Block(-4,1,-2,CONCRETE:13)
Block(-4,1,-1,CONCRETE:5)
Block(-4,1,0,CONCRETE:5)
Block(-3,0,-3,CONCRETE:5)
Block(-3,0,-2,CONCRETE:5)
Block(-3,0,-1,CONCRETE:5)
Block(-3,0,0,CONCRETE:5)
Block(-3,0,1,CONCRETE:5)
Block(-3,1,-2,CONCRETE:5)
Block(-3,1,-1,CONCRETE:5)
Block(-3,1,0,CONCRETE:5)
Block(-3,1,1,CONCRETE:5)
Block(-3,2,-1,CONCRETE:5)
Block(-3,2,0,CONCRETE:13)
Block(-2,0,-3,CONCRETE:5)
Block(-2,0,-2,CONCRETE:5)
Block(-2,0,-1,CONCRETE:5)
Block(-2,0,0,CONCRETE:5)
Block(-2,0,1,CONCRETE:5)
Block(-2,1,-3,CONCRETE:5)
Block(-2,1,-2,CONCRETE:5)
Block(-2,1,-1,CONCRETE:5)
Block(-2,1,0,CONCRETE:5)
Block(-2,1,1,CONCRETE:5)
Block(-2,2,-2,CONCRETE:13)
Block(-2,2,-1,CONCRETE:5)
Block(-2,2,0,CONCRETE:5)
Block(-2,2,1,CONCRETE:13)
Block(-2,3,-1,CONCRETE:5)
Block(-2,3,0,CONCRETE:5)
Block(-1,0,-3,CONCRETE:5)
Block(-1,0,-2,CONCRETE:5)
Block(-1,0,-1,CONCRETE:5)
Block(-1,0,0,CONCRETE:5)
Block(-1,0,1,CONCRETE:5)
Block(-1,0,2,CONCRETE:5)
Block(-1,1,-2,CONCRETE:5)
Block(-1,1,-1,CONCRETE:5)
Block(-1,1,0,CONCRETE:5)
Block(-1,1,1,CONCRETE:5)
Block(-1,1,2,CONCRETE:5)
Block(-1,2,-2,CONCRETE:13)
Block(-1,2,-1,CONCRETE:5)
Block(-1,2,0,CONCRETE:5)
Block(-1,2,1,CONCRETE:5)
Block(-1,2,2,CONCRETE:5)
Block(-1,3,-1,CONCRETE:5)
Block(-1,3,0,CONCRETE:5)
Block(-1,3,1,CONCRETE:13)
Block(-1,4,0,CONCRETE:5)
Block(0,0,-2,CONCRETE:5)
Block(0,0,-1,CONCRETE:5)
Block(0,0,0,CONCRETE:5)
Block(0,0,1,CONCRETE:13)
Block(0,1,-2,CONCRETE:5)
Block(0,1,-1,CONCRETE:5)
Block(0,1,0,CONCRETE:5)
Block(0,1,1,CONCRETE:5)
Block(0,2,-1,CONCRETE:13)
Block(0,2,0,CONCRETE:5)
Block(0,2,1,CONCRETE:13)
Block(0,3,-1,CONCRETE:5)
Block(0,3,0,CONCRETE:5)
Block(0,3,1,CONCRETE:5)
Block(0,4,-1,CONCRETE:5)
Block(0,4,0,CONCRETE:5)
Block(0,4,1,CONCRETE:13)
Block(0,5,-1,CONCRETE:5)
Block(0,5,0,CONCRETE:5)
Block(0,5,1,CONCRETE:13)
Block(0,6,0,CONCRETE:5)
Block(0,7,-1,CONCRETE:5)
Block(0,7,0,CONCRETE:5)
Block(1,0,0,CONCRETE:5)
Block(1,1,0,CONCRETE:5)
Block(1,2,-1,CONCRETE:5)
Block(1,2,0,CONCRETE:5)
Block(1,2,1,CONCRETE:13)
Block(1,3,-1,CONCRETE:5)
Block(1,3,0,CONCRETE:5)
Block(1,3,1,CONCRETE:5)
Block(1,4,-1,CONCRETE:13)
Block(1,4,0,CONCRETE:5)
Block(1,4,1,CONCRETE:5)
Block(1,5,-1,CONCRETE:5)
Block(1,5,0,CONCRETE:5)
Block(1,5,1,CONCRETE:5)
Block(1,6,-1,CONCRETE:5)
Block(1,6,0,CONCRETE:5)
Block(1,6,1,CONCRETE:5)
Block(1,7,-1,CONCRETE:5)
Block(1,7,0,CONCRETE:5)
Block(1,7,1,CONCRETE:5)
Block(1,8,-1,CONCRETE:4)
Block(1,8,0,CONCRETE:4)
Block(1,9,-1,CONCRETE:4)
Block(1,9,0,CONCRETE:4)
Block(2,4,0,CONCRETE:13)
Block(2,4,1,CONCRETE:5)
Block(2,5,-1,CONCRETE:13)
Block(2,5,0,CONCRETE:5)
Block(2,5,1,CONCRETE:5)
Block(2,6,-1,CONCRETE:5)
Block(2,6,0,CONCRETE:5)
Block(2,6,1,CONCRETE:13)
Block(2,7,-2,CONCRETE:5)
Block(2,7,-1,CONCRETE:5)
Block(2,7,0,CONCRETE:5)
Block(2,7,1,CONCRETE:5)
Block(2,8,-2,CONCRETE:4)
Block(2,8,-1,CONCRETE:5)
Block(2,8,0,CONCRETE:5)
Block(2,8,1,CONCRETE:4)
Block(2,9,-2,CONCRETE:4)
Block(2,9,-1,CONCRETE:5)
Block(2,9,0,CONCRETE:4)
Block(2,10,-1,CONCRETE:4)
Block(3,5,0,CONCRETE:5)
Block(3,6,-1,CONCRETE:5)
Block(3,6,0,CONCRETE:5)
Block(3,7,-1,CONCRETE:5)
Block(3,7,0,CONCRETE:5)
Block(3,7,1,CONCRETE:4)
Block(3,8,-1,CONCRETE:4)
Block(3,8,0,CONCRETE:4)
Block(3,8,1,CONCRETE:4)
Block(3,9,-1,CONCRETE:4)
Block(3,9,0,CONCRETE:4)
Block(3,10,-2,CONCRETE:4)
Block(3,10,-1,CONCRETE:5)
Block(3,10,0,CONCRETE:4)
Block(3,11,-2,CONCRETE:4)
Block(3,11,-1,CONCRETE:4)
Block(3,12,-2,CONCRETE:4)
Block(3,12,-1,CONCRETE:4)
Block(4,10,-1,CONCRETE:4)
Block(4,11,-1,CONCRETE:4)
Block(4,12,-2,CONCRETE:4)
Block(4,12,-1,CONCRETE:4)
Block(4,13,-2,CONCRETE:4)
Block(4,14,-2,CONCRETE:4)

#######################################################################
# +-----------------------------------------------------------------+ #
# |                            BO3 checks                           | #
# +-----------------------------------------------------------------+ #
#######################################################################

BlockCheck(0,-1,0,GRASS,DIRT)

#######################################################################
# +-----------------------------------------------------------------+ #
# |                             Branches                            | #
# +-----------------------------------------------------------------+ #
#######################################################################


#######################################################################
# +-----------------------------------------------------------------+ #
# |                             Entities                            | #
# +-----------------------------------------------------------------+ #
#######################################################################


#######################################################################
# +-----------------------------------------------------------------+ #
# |                            Particles                            | #
# +-----------------------------------------------------------------+ #
#######################################################################


#######################################################################
# +-----------------------------------------------------------------+ #
# |                             Spawners                            | #
# +-----------------------------------------------------------------+ #
#######################################################################


#######################################################################
# +-----------------------------------------------------------------+ #
# |                             ModData                             | #
# +-----------------------------------------------------------------+ #
#######################################################################

