
#######################################################################
# +-----------------------------------------------------------------+ #
# |                            BO3 object                           | #
# +-----------------------------------------------------------------+ #
#######################################################################

Author: LordSmellyPants

Description: No description given

Version: 3

SettingsMode: WriteWithoutComments


#######################################################################
# +-----------------------------------------------------------------+ #
# |                          Main settings                          | #
# +-----------------------------------------------------------------+ #
#######################################################################

Tree: true

Frequency: 0

Rarity: 100.0

RotateRandomly: true

SpawnHeight: highestSolidBlock

SpawnHeightOffset: 0

SpawnHeightVariance: 10

##############################
# Height Limits for the BO3. #
##############################

MinHeight: 0

MaxHeight: 40

######################
# Extrusion settings #
######################

ExtrudeMode: BottomDown

ExtrudeThroughBlocks: AIR

MaxBranchDepth: 10

ExcludedBiomes: All


#######################################################################
# +-----------------------------------------------------------------+ #
# |                      Source block settings                      | #
# +-----------------------------------------------------------------+ #
#######################################################################

SourceBlocks: AIR

MaxPercentageOutsideSourceBlock: 0

OutsideSourceBlock: placeAnyway

DoReplaceBlocks: true

IsOTGPlus: false


#######################################################################
# +-----------------------------------------------------------------+ #
# |                              Blocks                             | #
# +-----------------------------------------------------------------+ #
#######################################################################

Block(-5,8,-3,CONCRETE:13)
Block(-5,8,-2,CONCRETE:13)
Block(-5,9,-3,CONCRETE:13)
Block(-5,9,-2,CONCRETE:13)
Block(-5,10,-3,CONCRETE:13)
Block(-5,13,-3,CONCRETE:13)
Block(-5,14,-4,CONCRETE:13)
Block(-5,17,-4,CONCRETE:13)
Block(-4,1,-4,CONCRETE:13)
Block(-4,4,-4,CONCRETE:13)
Block(-4,8,-2,CONCRETE:13)
Block(-4,9,-2,CONCRETE:13)
Block(-4,13,-4,CONCRETE:13)
Block(-4,13,-3,CONCRETE:13)
Block(-4,14,-4,CONCRETE:13)
Block(-4,14,-3,CONCRETE:13)
Block(-4,17,-4,CONCRETE:13)
Block(-4,17,-3,CONCRETE:13)
Block(-4,18,-4,CONCRETE:13)
Block(-4,18,-3,CONCRETE:13)
Block(-3,1,-4,CONCRETE:13)
Block(-3,1,-3,CONCRETE:13)
Block(-3,4,-4,CONCRETE:13)
Block(-3,4,-3,CONCRETE:13)
Block(-3,5,-4,CONCRETE:13)
Block(-3,5,-3,CONCRETE:13)
Block(-3,8,-2,CONCRETE:13)
Block(-3,8,-1,CONCRETE:13)
Block(-3,9,-2,CONCRETE:13)
Block(-3,9,-1,CONCRETE:13)
Block(-3,13,-3,CONCRETE:13)
Block(-3,13,-2,CONCRETE:13)
Block(-3,17,-3,CONCRETE:13)
Block(-3,17,-2,CONCRETE:13)
Block(-3,18,-3,CONCRETE:13)
Block(-3,18,-2,CONCRETE:13)
Block(-3,21,-3,CONCRETE:13)
Block(-3,21,-2,CONCRETE:13)
Block(-2,1,-3,CONCRETE:13)
Block(-2,1,-2,CONCRETE:13)
Block(-2,4,-3,CONCRETE:13)
Block(-2,4,-2,CONCRETE:13)
Block(-2,4,-1,CONCRETE:13)
Block(-2,5,-3,CONCRETE:13)
Block(-2,5,-2,CONCRETE:13)
Block(-2,5,-1,CONCRETE:13)
Block(-2,8,-1,CONCRETE:13)
Block(-2,8,0,CONCRETE:13)
Block(-2,9,-1,CONCRETE:13)
Block(-2,12,-2,CONCRETE:13)
Block(-2,12,-1,CONCRETE:13)
Block(-2,13,-2,CONCRETE:13)
Block(-2,13,-1,CONCRETE:13)
Block(-2,17,-2,CONCRETE:13)
Block(-2,17,-1,CONCRETE:13)
Block(-2,21,-2,CONCRETE:13)
Block(-2,21,-1,CONCRETE:13)
Block(-2,22,-2,CONCRETE:13)
Block(-1,1,-2,CONCRETE:13)
Block(-1,1,-1,CONCRETE:13)
Block(-1,4,-1,CONCRETE:13)
Block(-1,4,0,CONCRETE:5)
Block(-1,4,1,CONCRETE:13)
Block(-1,5,-1,CONCRETE:13)
Block(-1,5,0,CONCRETE:5)
Block(-1,5,1,CONCRETE:13)
Block(-1,6,0,CONCRETE:5)
Block(-1,7,0,CONCRETE:5)
Block(-1,8,0,CONCRETE:5)
Block(-1,8,1,CONCRETE:13)
Block(-1,9,0,CONCRETE:5)
Block(-1,9,1,CONCRETE:13)
Block(-1,10,0,CONCRETE:5)
Block(-1,11,0,CONCRETE:5)
Block(-1,12,-1,CONCRETE:13)
Block(-1,12,0,CONCRETE:13)
Block(-1,13,-1,CONCRETE:13)
Block(-1,13,0,CONCRETE:13)
Block(-1,13,1,CONCRETE:13)
Block(-1,16,-1,CONCRETE:13)
Block(-1,16,0,CONCRETE:13)
Block(-1,17,-2,CONCRETE:13)
Block(-1,17,-1,CONCRETE:13)
Block(-1,17,0,CONCRETE:13)
Block(-1,20,-1,CONCRETE:13)
Block(-1,20,0,CONCRETE:13)
Block(-1,21,-1,CONCRETE:13)
Block(-1,21,0,CONCRETE:13)
Block(0,0,0,CONCRETE:5)
Block(0,1,-1,CONCRETE:13)
Block(0,1,0,CONCRETE:5)
Block(0,2,0,CONCRETE:5)
Block(0,3,0,CONCRETE:5)
Block(0,4,1,CONCRETE:13)
Block(0,4,2,CONCRETE:13)
Block(0,5,1,CONCRETE:13)
Block(0,5,2,CONCRETE:13)
Block(0,8,1,CONCRETE:13)
Block(0,8,2,CONCRETE:13)
Block(0,9,1,CONCRETE:13)
Block(0,12,-1,CONCRETE:13)
Block(0,12,0,CONCRETE:5)
Block(0,12,1,CONCRETE:13)
Block(0,13,-1,CONCRETE:13)
Block(0,13,0,CONCRETE:5)
Block(0,14,0,CONCRETE:5)
Block(0,15,0,CONCRETE:5)
Block(0,16,-1,CONCRETE:13)
Block(0,16,0,CONCRETE:5)
Block(0,16,1,CONCRETE:13)
Block(0,16,2,CONCRETE:13)
Block(0,17,-1,CONCRETE:13)
Block(0,17,0,CONCRETE:5)
Block(0,17,1,CONCRETE:13)
Block(0,17,2,CONCRETE:13)
Block(0,18,0,CONCRETE:5)
Block(0,19,1,CONCRETE:5)
Block(0,20,0,CONCRETE:13)
Block(0,20,1,CONCRETE:5)
Block(0,20,2,CONCRETE:13)
Block(0,21,0,CONCRETE:13)
Block(0,21,1,CONCRETE:5)
Block(0,21,2,CONCRETE:13)
Block(0,22,1,CONCRETE:5)
Block(0,23,1,CONCRETE:5)
Block(0,24,1,CONCRETE:5)
Block(1,7,2,CONCRETE:13)
Block(1,8,2,CONCRETE:13)
Block(1,11,2,CONCRETE:13)
Block(1,12,1,CONCRETE:13)
Block(1,12,2,CONCRETE:13)
Block(1,16,2,CONCRETE:13)
Block(1,17,2,CONCRETE:13)
Block(1,19,0,CONCRETE:5)
Block(1,20,0,CONCRETE:5)
Block(1,20,2,CONCRETE:13)
Block(1,21,0,CONCRETE:5)
Block(1,21,2,CONCRETE:13)
Block(1,22,0,CONCRETE:5)
Block(1,23,0,CONCRETE:5)
Block(1,27,-2,CONCRETE:13)
Block(1,28,-3,CONCRETE:13)
Block(1,28,-2,CONCRETE:13)
Block(2,11,2,CONCRETE:13)
Block(2,12,2,CONCRETE:13)
Block(2,24,0,CONCRETE:5)
Block(2,25,0,CONCRETE:5)
Block(2,26,-1,CONCRETE:13)
Block(2,26,0,CONCRETE:5)
Block(2,26,1,CONCRETE:13)
Block(2,26,2,CONCRETE:13)
Block(2,27,-3,CONCRETE:13)
Block(2,27,-2,CONCRETE:13)
Block(2,27,-1,CONCRETE:13)
Block(2,27,0,CONCRETE:13)
Block(2,27,1,CONCRETE:13)
Block(2,28,-2,CONCRETE:13)
Block(2,28,-1,CONCRETE:13)
Block(3,25,2,CONCRETE:13)
Block(3,26,2,CONCRETE:13)
Block(3,27,-1,CONCRETE:13)
Block(3,27,0,CONCRETE:5)
Block(3,28,0,CONCRETE:5)
Block(3,28,1,CONCRETE:13)
Block(4,29,-4,CONCRETE:13)
Block(4,29,0,CONCRETE:5)
Block(4,29,1,CONCRETE:13)
Block(4,29,2,CONCRETE:13)
Block(4,30,-3,CONCRETE:13)
Block(4,30,-2,CONCRETE:13)
Block(4,30,-1,CONCRETE:13)
Block(5,28,2,CONCRETE:13)
Block(5,29,2,CONCRETE:13)
Block(5,30,-2,CONCRETE:13)
Block(5,30,-1,CONCRETE:13)
Block(5,30,0,CONCRETE:5)
Block(5,30,1,CONCRETE:13)
Block(5,30,2,CONCRETE:13)
Block(5,31,-2,CONCRETE:13)
Block(5,31,-1,CONCRETE:13)
Block(5,46,1,STAINED_CLAY:4)
Block(5,47,0,CONCRETE:5)
Block(5,48,0,CONCRETE:5)
Block(5,49,-2,STAINED_CLAY:4)
Block(5,49,-1,STAINED_CLAY:4)
Block(5,49,0,CONCRETE:5)
Block(5,49,1,STAINED_CLAY:4)
Block(5,49,2,STAINED_CLAY:4)
Block(5,50,0,STAINED_CLAY:4)
Block(5,50,1,STAINED_CLAY:4)
Block(6,31,0,CONCRETE:5)
Block(6,45,-1,STAINED_CLAY:4)
Block(6,45,0,STAINED_CLAY:4)
Block(6,45,1,STAINED_CLAY:4)
Block(6,46,-3,STAINED_CLAY:4)
Block(6,46,-2,STAINED_CLAY:4)
Block(6,46,-1,STAINED_CLAY:4)
Block(6,46,0,CONCRETE:5)
Block(6,46,1,STAINED_CLAY:4)
Block(6,46,2,STAINED_CLAY:4)
Block(6,49,-3,STAINED_CLAY:4)
Block(6,49,-2,STAINED_CLAY:4)
Block(6,49,-1,STAINED_CLAY:4)
Block(6,49,1,STAINED_CLAY:4)
Block(6,49,2,STAINED_CLAY:4)
Block(6,50,-2,STAINED_CLAY:4)
Block(6,50,-1,STAINED_CLAY:4)
Block(6,50,0,CONCRETE:5)
Block(6,50,1,STAINED_CLAY:4)
Block(6,50,2,STAINED_CLAY:4)
Block(6,51,0,CONCRETE:5)
Block(6,51,1,STAINED_CLAY:4)
Block(7,31,0,CONCRETE:5)
Block(7,44,0,CONCRETE:5)
Block(7,52,0,CONCRETE:5)
Block(8,32,0,CONCRETE:5)
Block(8,32,1,CONCRETE:13)
Block(8,33,0,CONCRETE:13)
Block(8,41,1,CONCRETE:1)
Block(8,42,-1,CONCRETE:1)
Block(8,42,0,CONCRETE:1)
Block(8,42,1,CONCRETE:1)
Block(8,42,2,CONCRETE:1)
Block(8,43,-1,CONCRETE:1)
Block(8,43,0,CONCRETE:5)
Block(8,43,1,CONCRETE:1)
Block(8,43,2,CONCRETE:1)
Block(8,44,-1,CONCRETE:1)
Block(8,44,0,CONCRETE:1)
Block(8,44,1,CONCRETE:1)
Block(8,52,0,CONCRETE:5)
Block(9,31,-4,CONCRETE:13)
Block(9,31,2,CONCRETE:13)
Block(9,32,-3,CONCRETE:13)
Block(9,32,-2,CONCRETE:13)
Block(9,32,-1,CONCRETE:13)
Block(9,32,0,CONCRETE:5)
Block(9,32,1,CONCRETE:13)
Block(9,32,2,CONCRETE:13)
Block(9,33,-1,CONCRETE:13)
Block(9,33,0,CONCRETE:13)
Block(9,39,-1,CONCRETE:1)
Block(9,40,-1,CONCRETE:1)
Block(9,40,1,CONCRETE:1)
Block(9,41,-2,CONCRETE:1)
Block(9,41,-1,CONCRETE:1)
Block(9,41,0,CONCRETE:1)
Block(9,41,1,CONCRETE:1)
Block(9,42,-3,CONCRETE:1)
Block(9,42,-2,CONCRETE:1)
Block(9,42,-1,CONCRETE:1)
Block(9,42,0,CONCRETE:1)
Block(9,42,1,CONCRETE:1)
Block(9,42,2,CONCRETE:1)
Block(9,43,-3,CONCRETE:1)
Block(9,43,-2,CONCRETE:1)
Block(9,43,-1,CONCRETE:1)
Block(9,43,0,CONCRETE:5)
Block(9,43,1,CONCRETE:1)
Block(9,43,2,CONCRETE:1)
Block(9,44,-2,CONCRETE:1)
Block(9,44,-1,CONCRETE:1)
Block(9,44,0,CONCRETE:1)
Block(9,44,1,CONCRETE:1)
Block(9,44,2,CONCRETE:1)
Block(9,45,-1,CONCRETE:1)
Block(9,45,0,CONCRETE:1)
Block(9,45,1,CONCRETE:1)
Block(9,52,1,STAINED_CLAY:4)
Block(9,52,2,STAINED_CLAY:4)
Block(9,53,0,CONCRETE:5)
Block(10,31,-4,CONCRETE:13)
Block(10,32,-3,CONCRETE:13)
Block(10,32,-2,CONCRETE:13)
Block(10,32,-1,CONCRETE:13)
Block(10,32,0,CONCRETE:5)
Block(10,32,1,CONCRETE:13)
Block(10,32,2,CONCRETE:13)
Block(10,33,-2,CONCRETE:13)
Block(10,33,-1,CONCRETE:13)
Block(10,33,0,CONCRETE:13)
Block(10,41,-1,CONCRETE:1)
Block(10,41,0,CONCRETE:1)
Block(10,41,1,CONCRETE:1)
Block(10,42,-2,CONCRETE:1)
Block(10,42,-1,CONCRETE:1)
Block(10,42,0,CONCRETE:1)
Block(10,42,1,CONCRETE:1)
Block(10,42,2,CONCRETE:1)
Block(10,43,-2,CONCRETE:1)
Block(10,43,-1,CONCRETE:1)
Block(10,43,0,CONCRETE:1)
Block(10,43,1,CONCRETE:1)
Block(10,43,2,CONCRETE:1)
Block(10,44,-2,CONCRETE:1)
Block(10,44,-1,CONCRETE:1)
Block(10,44,0,CONCRETE:1)
Block(10,44,1,CONCRETE:1)
Block(10,44,2,CONCRETE:1)
Block(10,45,-1,CONCRETE:1)
Block(10,45,0,CONCRETE:1)
Block(10,45,1,CONCRETE:1)
Block(10,51,-4,STAINED_CLAY:4)
Block(10,52,-4,STAINED_CLAY:4)
Block(10,52,-3,STAINED_CLAY:4)
Block(10,52,1,STAINED_CLAY:4)
Block(10,52,2,STAINED_CLAY:4)
Block(10,53,-3,STAINED_CLAY:4)
Block(10,53,-2,STAINED_CLAY:4)
Block(10,53,-1,STAINED_CLAY:4)
Block(10,53,0,CONCRETE:5)
Block(10,53,1,STAINED_CLAY:4)
Block(11,33,0,CONCRETE:5)
Block(11,41,-2,CONCRETE:1)
Block(11,41,-1,CONCRETE:1)
Block(11,41,0,CONCRETE:1)
Block(11,41,1,CONCRETE:1)
Block(11,42,-2,CONCRETE:1)
Block(11,42,-1,CONCRETE:1)
Block(11,42,0,CONCRETE:1)
Block(11,42,1,CONCRETE:1)
Block(11,42,2,CONCRETE:1)
Block(11,43,-2,CONCRETE:1)
Block(11,43,-1,CONCRETE:1)
Block(11,43,0,CONCRETE:1)
Block(11,43,1,CONCRETE:1)
Block(11,43,2,CONCRETE:1)
Block(11,44,-2,CONCRETE:1)
Block(11,44,-1,CONCRETE:1)
Block(11,44,0,CONCRETE:1)
Block(11,44,1,CONCRETE:1)
Block(11,44,2,CONCRETE:1)
Block(11,45,-1,CONCRETE:1)
Block(11,45,0,CONCRETE:1)
Block(11,45,1,CONCRETE:1)
Block(11,52,-1,STAINED_CLAY:4)
Block(11,53,-1,STAINED_CLAY:4)
Block(11,53,0,CONCRETE:5)
Block(12,33,0,CONCRETE:5)
Block(12,41,0,CONCRETE:1)
Block(12,42,-2,CONCRETE:1)
Block(12,42,-1,CONCRETE:1)
Block(12,42,0,CONCRETE:1)
Block(12,42,1,CONCRETE:1)
Block(12,43,-2,CONCRETE:1)
Block(12,43,-1,CONCRETE:1)
Block(12,43,0,CONCRETE:1)
Block(12,43,1,CONCRETE:1)
Block(12,43,2,CONCRETE:1)
Block(12,44,-2,CONCRETE:1)
Block(12,44,-1,CONCRETE:1)
Block(12,44,0,CONCRETE:1)
Block(12,44,1,CONCRETE:1)
Block(12,44,2,CONCRETE:1)
Block(12,52,0,CONCRETE:5)
Block(13,34,-4,CONCRETE:13)
Block(13,34,-3,CONCRETE:13)
Block(13,34,0,CONCRETE:5)
Block(13,34,1,CONCRETE:13)
Block(13,34,2,CONCRETE:13)
Block(13,35,-2,CONCRETE:13)
Block(13,35,-1,CONCRETE:13)
Block(13,35,0,CONCRETE:13)
Block(13,42,1,CONCRETE:1)
Block(13,52,0,CONCRETE:5)
Block(14,33,-4,CONCRETE:13)
Block(14,34,-4,CONCRETE:13)
Block(14,34,-3,CONCRETE:13)
Block(14,34,2,CONCRETE:13)
Block(14,35,-3,CONCRETE:13)
Block(14,35,-2,CONCRETE:13)
Block(14,35,-1,CONCRETE:13)
Block(14,35,0,CONCRETE:5)
Block(14,35,1,CONCRETE:13)
Block(14,35,2,CONCRETE:13)
Block(14,36,-2,CONCRETE:13)
Block(14,36,-1,CONCRETE:13)
Block(14,36,0,CONCRETE:13)
Block(14,36,1,CONCRETE:13)
Block(14,50,-4,STAINED_CLAY:4)
Block(14,50,-3,STAINED_CLAY:4)
Block(14,50,-2,STAINED_CLAY:4)
Block(14,50,1,STAINED_CLAY:4)
Block(14,50,2,STAINED_CLAY:4)
Block(14,51,-2,STAINED_CLAY:4)
Block(14,51,-1,STAINED_CLAY:4)
Block(14,51,0,CONCRETE:5)
Block(14,51,1,STAINED_CLAY:4)
Block(14,51,2,STAINED_CLAY:4)
Block(15,36,0,CONCRETE:5)
Block(15,37,0,CONCRETE:5)
Block(15,38,-4,STAINED_CLAY:4)
Block(15,38,-3,STAINED_CLAY:4)
Block(15,38,1,STAINED_CLAY:4)
Block(15,38,2,STAINED_CLAY:4)
Block(15,39,1,STAINED_CLAY:4)
Block(15,46,2,STAINED_CLAY:4)
Block(15,47,2,STAINED_CLAY:4)
Block(15,49,0,CONCRETE:5)
Block(15,50,-2,STAINED_CLAY:4)
Block(15,50,-1,STAINED_CLAY:4)
Block(15,50,0,CONCRETE:5)
Block(15,50,1,STAINED_CLAY:4)
Block(15,51,-2,STAINED_CLAY:4)
Block(16,38,-4,STAINED_CLAY:4)
Block(16,38,-3,STAINED_CLAY:4)
Block(16,38,-2,STAINED_CLAY:4)
Block(16,38,-1,STAINED_CLAY:4)
Block(16,38,0,CONCRETE:5)
Block(16,38,1,STAINED_CLAY:4)
Block(16,38,2,STAINED_CLAY:4)
Block(16,39,-3,STAINED_CLAY:4)
Block(16,39,-2,STAINED_CLAY:4)
Block(16,39,-1,STAINED_CLAY:4)
Block(16,39,0,CONCRETE:5)
Block(16,39,1,STAINED_CLAY:4)
Block(16,39,2,STAINED_CLAY:4)
Block(16,40,0,CONCRETE:5)
Block(16,42,-3,STAINED_CLAY:4)
Block(16,42,-2,STAINED_CLAY:4)
Block(16,42,-1,STAINED_CLAY:4)
Block(16,42,2,STAINED_CLAY:4)
Block(16,43,-1,STAINED_CLAY:4)
Block(16,43,0,STAINED_CLAY:4)
Block(16,46,-2,STAINED_CLAY:4)
Block(16,46,0,CONCRETE:5)
Block(16,46,1,STAINED_CLAY:4)
Block(16,46,2,STAINED_CLAY:4)
Block(16,47,-3,STAINED_CLAY:4)
Block(16,47,-2,STAINED_CLAY:4)
Block(16,47,-1,STAINED_CLAY:4)
Block(16,47,0,CONCRETE:5)
Block(16,47,1,STAINED_CLAY:4)
Block(16,47,2,STAINED_CLAY:4)
Block(16,48,-1,STAINED_CLAY:4)
Block(16,48,0,CONCRETE:5)
Block(17,41,0,CONCRETE:5)
Block(17,42,-2,STAINED_CLAY:4)
Block(17,42,-1,STAINED_CLAY:4)
Block(17,42,0,CONCRETE:5)
Block(17,42,1,STAINED_CLAY:4)
Block(17,42,2,STAINED_CLAY:4)
Block(17,43,-1,STAINED_CLAY:4)
Block(17,43,0,CONCRETE:5)
Block(17,43,1,STAINED_CLAY:4)
Block(17,43,2,STAINED_CLAY:4)
Block(17,44,0,CONCRETE:5)
Block(17,45,0,CONCRETE:5)

#######################################################################
# +-----------------------------------------------------------------+ #
# |                            BO3 checks                           | #
# +-----------------------------------------------------------------+ #
#######################################################################

BlockCheck(0,-1,0,GRASS,DIRT)

#######################################################################
# +-----------------------------------------------------------------+ #
# |                             Branches                            | #
# +-----------------------------------------------------------------+ #
#######################################################################


#######################################################################
# +-----------------------------------------------------------------+ #
# |                             Entities                            | #
# +-----------------------------------------------------------------+ #
#######################################################################


#######################################################################
# +-----------------------------------------------------------------+ #
# |                            Particles                            | #
# +-----------------------------------------------------------------+ #
#######################################################################


#######################################################################
# +-----------------------------------------------------------------+ #
# |                             Spawners                            | #
# +-----------------------------------------------------------------+ #
#######################################################################


#######################################################################
# +-----------------------------------------------------------------+ #
# |                             ModData                             | #
# +-----------------------------------------------------------------+ #
#######################################################################

