
#######################################################################
# +-----------------------------------------------------------------+ #
# |                            BO3 object                           | #
# +-----------------------------------------------------------------+ #
#######################################################################

Author: LordSmellyPants

Description: No description given

Version: 3

SettingsMode: WriteWithoutComments


#######################################################################
# +-----------------------------------------------------------------+ #
# |                          Main settings                          | #
# +-----------------------------------------------------------------+ #
#######################################################################

Tree: true

Frequency: 0

Rarity: 100.0

RotateRandomly: false

SpawnHeight: highestSolidBlock

SpawnHeightOffset: 0

SpawnHeightVariance: 0

##############################
# Height Limits for the BO3. #
##############################

MinHeight: 0

MaxHeight: 30

######################
# Extrusion settings #
######################

ExtrudeMode: BottomDown

ExtrudeThroughBlocks: AIR

MaxBranchDepth: 10

ExcludedBiomes: All


#######################################################################
# +-----------------------------------------------------------------+ #
# |                      Source block settings                      | #
# +-----------------------------------------------------------------+ #
#######################################################################

SourceBlocks: AIR

MaxPercentageOutsideSourceBlock: 100

OutsideSourceBlock: placeAnyway

DoReplaceBlocks: true

IsOTGPlus: false


#######################################################################
# +-----------------------------------------------------------------+ #
# |                              Blocks                             | #
# +-----------------------------------------------------------------+ #
#######################################################################

Block(-2,29,7,minecraft:red_glazed_terracotta:0)
Block(-2,30,6,minecraft:red_glazed_terracotta:0)
Block(-2,30,7,minecraft:red_glazed_terracotta:0)
Block(-2,30,8,minecraft:red_glazed_terracotta:0)
Block(-2,31,7,minecraft:red_glazed_terracotta:0)
Block(-2,35,2,minecraft:red_glazed_terracotta:0)
Block(-2,36,1,minecraft:red_glazed_terracotta:0)
Block(-2,36,2,minecraft:red_glazed_terracotta:0)
Block(-2,36,3,minecraft:red_glazed_terracotta:0)
Block(-2,37,2,minecraft:red_glazed_terracotta:0)
Block(-1,19,6,minecraft:red_glazed_terracotta:0)
Block(-1,20,5,minecraft:red_glazed_terracotta:0)
Block(-1,20,6,minecraft:red_glazed_terracotta:0)
Block(-1,20,7,minecraft:red_glazed_terracotta:0)
Block(-1,21,6,minecraft:red_glazed_terracotta:0)
Block(-1,28,7,minecraft:red_glazed_terracotta:0)
Block(-1,29,6,minecraft:red_glazed_terracotta:0)
Block(-1,29,7,minecraft:red_glazed_terracotta:0)
Block(-1,29,8,minecraft:red_glazed_terracotta:0)
Block(-1,30,5,minecraft:red_glazed_terracotta:0)
Block(-1,30,6,minecraft:red_glazed_terracotta:0)
Block(-1,30,7,minecraft:red_glazed_terracotta:0)
Block(-1,30,8,minecraft:red_glazed_terracotta:0)
Block(-1,30,9,minecraft:red_glazed_terracotta:0)
Block(-1,31,6,minecraft:red_glazed_terracotta:0)
Block(-1,31,7,minecraft:red_glazed_terracotta:0)
Block(-1,31,8,minecraft:red_glazed_terracotta:0)
Block(-1,32,7,minecraft:red_glazed_terracotta:0)
Block(-1,34,2,minecraft:red_glazed_terracotta:0)
Block(-1,35,1,minecraft:red_glazed_terracotta:0)
Block(-1,35,2,minecraft:red_glazed_terracotta:0)
Block(-1,35,3,minecraft:red_glazed_terracotta:0)
Block(-1,36,0,minecraft:red_glazed_terracotta:0)
Block(-1,36,1,minecraft:red_glazed_terracotta:0)
Block(-1,36,2,minecraft:red_glazed_terracotta:0)
Block(-1,36,3,minecraft:red_glazed_terracotta:0)
Block(-1,36,4,minecraft:red_glazed_terracotta:0)
Block(-1,37,1,minecraft:red_glazed_terracotta:0)
Block(-1,37,2,minecraft:red_glazed_terracotta:0)
Block(-1,37,3,minecraft:red_glazed_terracotta:0)
Block(-1,38,2,minecraft:red_glazed_terracotta:0)
Block(0,17,6,CONCRETE:15)
Block(0,18,6,CONCRETE:15)
Block(0,19,5,minecraft:red_glazed_terracotta:0)
Block(0,19,6,minecraft:red_glazed_terracotta:0)
Block(0,19,7,minecraft:red_glazed_terracotta:0)
Block(0,20,5,minecraft:red_glazed_terracotta:0)
Block(0,20,7,minecraft:red_glazed_terracotta:0)
Block(0,21,5,minecraft:red_glazed_terracotta:0)
Block(0,21,6,minecraft:red_glazed_terracotta:0)
Block(0,21,7,minecraft:red_glazed_terracotta:0)
Block(0,28,6,CONCRETE:15)
Block(0,28,7,CONCRETE:15)
Block(0,28,8,minecraft:red_glazed_terracotta:0)
Block(0,29,5,minecraft:red_glazed_terracotta:0)
Block(0,29,6,minecraft:red_glazed_terracotta:0)
Block(0,29,7,CONCRETE:15)
Block(0,29,8,minecraft:red_glazed_terracotta:0)
Block(0,29,9,minecraft:red_glazed_terracotta:0)
Block(0,30,5,minecraft:red_glazed_terracotta:0)
Block(0,30,6,minecraft:red_glazed_terracotta:0)
Block(0,30,7,minecraft:red_glazed_terracotta:0)
Block(0,30,8,minecraft:red_glazed_terracotta:0)
Block(0,30,9,minecraft:red_glazed_terracotta:0)
Block(0,31,5,minecraft:red_glazed_terracotta:0)
Block(0,31,6,minecraft:red_glazed_terracotta:0)
Block(0,31,7,minecraft:red_glazed_terracotta:0)
Block(0,31,8,minecraft:red_glazed_terracotta:0)
Block(0,31,9,minecraft:red_glazed_terracotta:0)
Block(0,32,6,minecraft:red_glazed_terracotta:0)
Block(0,32,7,minecraft:red_glazed_terracotta:0)
Block(0,32,8,minecraft:red_glazed_terracotta:0)
Block(0,34,1,minecraft:red_glazed_terracotta:0)
Block(0,34,2,minecraft:red_glazed_terracotta:0)
Block(0,34,3,CONCRETE:15)
Block(0,35,0,minecraft:red_glazed_terracotta:0)
Block(0,35,1,minecraft:red_glazed_terracotta:0)
Block(0,35,2,CONCRETE:15)
Block(0,35,3,minecraft:red_glazed_terracotta:0)
Block(0,35,4,minecraft:red_glazed_terracotta:0)
Block(0,36,0,minecraft:red_glazed_terracotta:0)
Block(0,36,1,minecraft:red_glazed_terracotta:0)
Block(0,36,2,minecraft:red_glazed_terracotta:0)
Block(0,36,3,minecraft:red_glazed_terracotta:0)
Block(0,36,4,minecraft:red_glazed_terracotta:0)
Block(0,37,0,minecraft:red_glazed_terracotta:0)
Block(0,37,1,minecraft:red_glazed_terracotta:0)
Block(0,37,2,minecraft:red_glazed_terracotta:0)
Block(0,37,3,minecraft:red_glazed_terracotta:0)
Block(0,37,4,minecraft:red_glazed_terracotta:0)
Block(0,38,1,minecraft:red_glazed_terracotta:0)
Block(0,38,2,minecraft:red_glazed_terracotta:0)
Block(0,38,3,minecraft:red_glazed_terracotta:0)
Block(1,16,5,CONCRETE:15)
Block(1,16,6,CONCRETE:15)
Block(1,17,6,CONCRETE:15)
Block(1,19,6,minecraft:red_glazed_terracotta:0)
Block(1,20,5,minecraft:red_glazed_terracotta:0)
Block(1,20,6,minecraft:red_glazed_terracotta:0)
Block(1,20,7,minecraft:red_glazed_terracotta:0)
Block(1,21,6,minecraft:red_glazed_terracotta:0)
Block(1,27,5,CONCRETE:15)
Block(1,27,6,CONCRETE:15)
Block(1,28,6,CONCRETE:15)
Block(1,28,7,minecraft:red_glazed_terracotta:0)
Block(1,29,6,minecraft:red_glazed_terracotta:0)
Block(1,29,7,minecraft:red_glazed_terracotta:0)
Block(1,29,8,minecraft:red_glazed_terracotta:0)
Block(1,30,5,minecraft:red_glazed_terracotta:0)
Block(1,30,6,minecraft:red_glazed_terracotta:0)
Block(1,30,7,minecraft:red_glazed_terracotta:0)
Block(1,30,8,minecraft:red_glazed_terracotta:0)
Block(1,30,9,minecraft:red_glazed_terracotta:0)
Block(1,31,6,minecraft:red_glazed_terracotta:0)
Block(1,31,7,minecraft:red_glazed_terracotta:0)
Block(1,31,8,minecraft:red_glazed_terracotta:0)
Block(1,32,7,minecraft:red_glazed_terracotta:0)
Block(1,33,3,CONCRETE:15)
Block(1,34,2,minecraft:red_glazed_terracotta:0)
Block(1,34,3,CONCRETE:15)
Block(1,35,1,minecraft:red_glazed_terracotta:0)
Block(1,35,2,minecraft:red_glazed_terracotta:0)
Block(1,35,3,minecraft:red_glazed_terracotta:0)
Block(1,36,0,minecraft:red_glazed_terracotta:0)
Block(1,36,1,minecraft:red_glazed_terracotta:0)
Block(1,36,2,minecraft:red_glazed_terracotta:0)
Block(1,36,3,minecraft:red_glazed_terracotta:0)
Block(1,36,4,minecraft:red_glazed_terracotta:0)
Block(1,37,1,minecraft:red_glazed_terracotta:0)
Block(1,37,2,minecraft:red_glazed_terracotta:0)
Block(1,37,3,minecraft:red_glazed_terracotta:0)
Block(1,38,2,minecraft:red_glazed_terracotta:0)
Block(2,10,4,CONCRETE:15)
Block(2,11,4,CONCRETE:15)
Block(2,15,4,minecraft:red_glazed_terracotta:0)
Block(2,16,4,minecraft:red_glazed_terracotta:0)
Block(2,16,5,CONCRETE:15)
Block(2,17,4,CONCRETE:15)
Block(2,18,4,CONCRETE:15)
Block(2,19,4,CONCRETE:15)
Block(2,20,4,CONCRETE:15)
Block(2,21,4,minecraft:red_glazed_terracotta:0)
Block(2,22,4,minecraft:red_glazed_terracotta:0)
Block(2,23,3,CONCRETE:15)
Block(2,23,4,minecraft:red_glazed_terracotta:0)
Block(2,24,4,CONCRETE:15)
Block(2,25,4,CONCRETE:15)
Block(2,26,4,CONCRETE:15)
Block(2,27,4,minecraft:red_glazed_terracotta:0)
Block(2,27,5,minecraft:red_glazed_terracotta:0)
Block(2,28,4,minecraft:red_glazed_terracotta:0)
Block(2,29,4,CONCRETE:15)
Block(2,29,7,minecraft:red_glazed_terracotta:0)
Block(2,30,4,CONCRETE:15)
Block(2,30,6,minecraft:red_glazed_terracotta:0)
Block(2,30,7,minecraft:red_glazed_terracotta:0)
Block(2,30,8,minecraft:red_glazed_terracotta:0)
Block(2,31,4,CONCRETE:15)
Block(2,31,7,minecraft:red_glazed_terracotta:0)
Block(2,32,4,CONCRETE:15)
Block(2,33,3,CONCRETE:15)
Block(2,33,4,CONCRETE:15)
Block(2,35,2,minecraft:red_glazed_terracotta:0)
Block(2,36,1,minecraft:red_glazed_terracotta:0)
Block(2,36,2,minecraft:red_glazed_terracotta:0)
Block(2,36,3,minecraft:red_glazed_terracotta:0)
Block(2,37,2,minecraft:red_glazed_terracotta:0)
Block(3,2,3,CONCRETE:15)
Block(3,2,4,CONCRETE:15)
Block(3,3,3,CONCRETE:15)
Block(3,3,4,CONCRETE:15)
Block(3,4,4,CONCRETE:15)
Block(3,5,4,CONCRETE:15)
Block(3,6,4,CONCRETE:15)
Block(3,7,4,CONCRETE:15)
Block(3,8,4,CONCRETE:15)
Block(3,9,4,CONCRETE:15)
Block(3,10,4,CONCRETE:15)
Block(3,11,4,CONCRETE:15)
Block(3,12,4,CONCRETE:15)
Block(3,13,4,minecraft:red_glazed_terracotta:0)
Block(3,13,5,CONCRETE:15)
Block(3,14,4,CONCRETE:15)
Block(3,14,5,minecraft:red_glazed_terracotta:0)
Block(3,15,4,CONCRETE:15)
Block(3,15,5,CONCRETE:15)
Block(3,16,4,CONCRETE:15)
Block(3,16,5,CONCRETE:15)
Block(3,17,4,CONCRETE:15)
Block(3,18,4,CONCRETE:15)
Block(3,19,4,CONCRETE:15)
Block(3,23,2,minecraft:red_glazed_terracotta:0)
Block(3,23,3,minecraft:red_glazed_terracotta:0)
Block(3,24,2,CONCRETE:15)
Block(3,27,1,minecraft:red_glazed_terracotta:0)
Block(3,28,0,minecraft:red_glazed_terracotta:0)
Block(3,28,1,minecraft:red_glazed_terracotta:0)
Block(3,28,2,minecraft:red_glazed_terracotta:0)
Block(3,29,1,minecraft:red_glazed_terracotta:0)
Block(3,31,4,minecraft:red_glazed_terracotta:0)
Block(3,32,4,CONCRETE:15)
Block(3,33,4,CONCRETE:15)
Block(3,33,5,CONCRETE:15)
Block(4,2,3,CONCRETE:15)
Block(4,2,4,CONCRETE:15)
Block(4,3,3,CONCRETE:15)
Block(4,3,4,CONCRETE:15)
Block(4,4,4,CONCRETE:15)
Block(4,5,4,CONCRETE:15)
Block(4,15,3,CONCRETE:15)
Block(4,15,4,CONCRETE:15)
Block(4,16,3,CONCRETE:15)
Block(4,16,4,CONCRETE:15)
Block(4,18,2,minecraft:red_glazed_terracotta:0)
Block(4,19,1,minecraft:red_glazed_terracotta:0)
Block(4,19,2,minecraft:red_glazed_terracotta:0)
Block(4,19,3,minecraft:red_glazed_terracotta:0)
Block(4,20,2,minecraft:red_glazed_terracotta:0)
Block(4,24,2,minecraft:red_glazed_terracotta:0)
Block(4,25,1,minecraft:red_glazed_terracotta:0)
Block(4,25,2,CONCRETE:15)
Block(4,26,1,minecraft:red_glazed_terracotta:0)
Block(4,27,0,minecraft:red_glazed_terracotta:0)
Block(4,27,1,minecraft:red_glazed_terracotta:0)
Block(4,27,2,minecraft:red_glazed_terracotta:0)
Block(4,28,0,minecraft:red_glazed_terracotta:0)
Block(4,28,2,minecraft:red_glazed_terracotta:0)
Block(4,29,0,minecraft:red_glazed_terracotta:0)
Block(4,29,1,minecraft:red_glazed_terracotta:0)
Block(4,29,2,minecraft:red_glazed_terracotta:0)
Block(4,33,5,CONCRETE:15)
Block(4,34,5,minecraft:red_glazed_terracotta:0)
Block(4,34,6,CONCRETE:15)
Block(4,38,7,minecraft:red_glazed_terracotta:0)
Block(4,39,6,minecraft:red_glazed_terracotta:0)
Block(4,39,7,minecraft:red_glazed_terracotta:0)
Block(4,39,8,minecraft:red_glazed_terracotta:0)
Block(4,40,7,minecraft:red_glazed_terracotta:0)
Block(5,16,2,CONCRETE:15)
Block(5,16,3,CONCRETE:15)
Block(5,17,2,CONCRETE:15)
Block(5,18,1,minecraft:red_glazed_terracotta:0)
Block(5,18,2,CONCRETE:15)
Block(5,18,3,minecraft:red_glazed_terracotta:0)
Block(5,19,1,minecraft:red_glazed_terracotta:0)
Block(5,19,3,minecraft:red_glazed_terracotta:0)
Block(5,20,1,minecraft:red_glazed_terracotta:0)
Block(5,20,2,minecraft:red_glazed_terracotta:0)
Block(5,20,3,minecraft:red_glazed_terracotta:0)
Block(5,27,1,minecraft:red_glazed_terracotta:0)
Block(5,28,0,minecraft:red_glazed_terracotta:0)
Block(5,28,1,minecraft:red_glazed_terracotta:0)
Block(5,28,2,minecraft:red_glazed_terracotta:0)
Block(5,29,1,minecraft:red_glazed_terracotta:0)
Block(5,34,6,CONCRETE:15)
Block(5,35,6,CONCRETE:15)
Block(5,36,6,minecraft:red_glazed_terracotta:0)
Block(5,36,7,minecraft:red_glazed_terracotta:0)
Block(5,37,7,minecraft:red_glazed_terracotta:0)
Block(5,38,6,minecraft:red_glazed_terracotta:0)
Block(5,38,7,minecraft:red_glazed_terracotta:0)
Block(5,38,8,minecraft:red_glazed_terracotta:0)
Block(5,39,5,minecraft:red_glazed_terracotta:0)
Block(5,39,6,minecraft:red_glazed_terracotta:0)
Block(5,39,7,minecraft:red_glazed_terracotta:0)
Block(5,39,8,minecraft:red_glazed_terracotta:0)
Block(5,39,9,minecraft:red_glazed_terracotta:0)
Block(5,40,6,minecraft:red_glazed_terracotta:0)
Block(5,40,7,minecraft:red_glazed_terracotta:0)
Block(5,40,8,minecraft:red_glazed_terracotta:0)
Block(5,41,7,minecraft:red_glazed_terracotta:0)
Block(6,18,2,minecraft:red_glazed_terracotta:0)
Block(6,19,1,minecraft:red_glazed_terracotta:0)
Block(6,19,2,minecraft:red_glazed_terracotta:0)
Block(6,19,3,minecraft:red_glazed_terracotta:0)
Block(6,20,2,minecraft:red_glazed_terracotta:0)
Block(6,37,6,minecraft:red_glazed_terracotta:0)
Block(6,37,7,minecraft:red_glazed_terracotta:0)
Block(6,37,8,minecraft:red_glazed_terracotta:0)
Block(6,38,5,minecraft:red_glazed_terracotta:0)
Block(6,38,6,minecraft:red_glazed_terracotta:0)
Block(6,38,7,minecraft:red_glazed_terracotta:0)
Block(6,38,8,minecraft:red_glazed_terracotta:0)
Block(6,38,9,minecraft:red_glazed_terracotta:0)
Block(6,39,5,minecraft:red_glazed_terracotta:0)
Block(6,39,6,minecraft:red_glazed_terracotta:0)
Block(6,39,7,minecraft:red_glazed_terracotta:0)
Block(6,39,8,minecraft:red_glazed_terracotta:0)
Block(6,39,9,minecraft:red_glazed_terracotta:0)
Block(6,40,5,minecraft:red_glazed_terracotta:0)
Block(6,40,6,minecraft:red_glazed_terracotta:0)
Block(6,40,7,minecraft:red_glazed_terracotta:0)
Block(6,40,8,minecraft:red_glazed_terracotta:0)
Block(6,40,9,minecraft:red_glazed_terracotta:0)
Block(6,41,6,minecraft:red_glazed_terracotta:0)
Block(6,41,7,minecraft:red_glazed_terracotta:0)
Block(6,41,8,minecraft:red_glazed_terracotta:0)
Block(7,37,7,minecraft:red_glazed_terracotta:0)
Block(7,38,6,minecraft:red_glazed_terracotta:0)
Block(7,38,7,minecraft:red_glazed_terracotta:0)
Block(7,38,8,minecraft:red_glazed_terracotta:0)
Block(7,39,5,minecraft:red_glazed_terracotta:0)
Block(7,39,6,minecraft:red_glazed_terracotta:0)
Block(7,39,7,minecraft:red_glazed_terracotta:0)
Block(7,39,8,minecraft:red_glazed_terracotta:0)
Block(7,39,9,minecraft:red_glazed_terracotta:0)
Block(7,40,6,minecraft:red_glazed_terracotta:0)
Block(7,40,7,minecraft:red_glazed_terracotta:0)
Block(7,40,8,minecraft:red_glazed_terracotta:0)
Block(7,41,7,minecraft:red_glazed_terracotta:0)
Block(8,38,7,minecraft:red_glazed_terracotta:0)
Block(8,39,6,minecraft:red_glazed_terracotta:0)
Block(8,39,7,minecraft:red_glazed_terracotta:0)
Block(8,39,8,minecraft:red_glazed_terracotta:0)
Block(8,40,7,minecraft:red_glazed_terracotta:0)

#######################################################################
# +-----------------------------------------------------------------+ #
# |                            BO3 checks                           | #
# +-----------------------------------------------------------------+ #
#######################################################################


#######################################################################
# +-----------------------------------------------------------------+ #
# |                             Branches                            | #
# +-----------------------------------------------------------------+ #
#######################################################################


#######################################################################
# +-----------------------------------------------------------------+ #
# |                             Entities                            | #
# +-----------------------------------------------------------------+ #
#######################################################################


#######################################################################
# +-----------------------------------------------------------------+ #
# |                            Particles                            | #
# +-----------------------------------------------------------------+ #
#######################################################################


#######################################################################
# +-----------------------------------------------------------------+ #
# |                             Spawners                            | #
# +-----------------------------------------------------------------+ #
#######################################################################


#######################################################################
# +-----------------------------------------------------------------+ #
# |                             ModData                             | #
# +-----------------------------------------------------------------+ #
#######################################################################

