
#######################################################################
# +-----------------------------------------------------------------+ #
# |                            BO3 object                           | #
# +-----------------------------------------------------------------+ #
#######################################################################

Author: LordSmellyPants

Description: No description given

Version: 3

SettingsMode: WriteWithoutComments


#######################################################################
# +-----------------------------------------------------------------+ #
# |                          Main settings                          | #
# +-----------------------------------------------------------------+ #
#######################################################################

Tree: true

Frequency: 0

Rarity: 100.0

RotateRandomly: false

SpawnHeight: highestSolidBlock

SpawnHeightOffset: 0

SpawnHeightVariance: 0

##############################
# Height Limits for the BO3. #
##############################

MinHeight: 0

MaxHeight: 30

######################
# Extrusion settings #
######################

ExtrudeMode: BottomDown

ExtrudeThroughBlocks: AIR

MaxBranchDepth: 10

ExcludedBiomes: All


#######################################################################
# +-----------------------------------------------------------------+ #
# |                      Source block settings                      | #
# +-----------------------------------------------------------------+ #
#######################################################################

SourceBlocks: AIR

MaxPercentageOutsideSourceBlock: 100

OutsideSourceBlock: placeAnyway

DoReplaceBlocks: true

IsOTGPlus: false


#######################################################################
# +-----------------------------------------------------------------+ #
# |                              Blocks                             | #
# +-----------------------------------------------------------------+ #
#######################################################################

Block(-4,23,4,minecraft:red_glazed_terracotta:0)
Block(-4,24,3,minecraft:red_glazed_terracotta:0)
Block(-4,24,4,minecraft:red_glazed_terracotta:0)
Block(-4,24,5,minecraft:red_glazed_terracotta:0)
Block(-4,25,4,minecraft:red_glazed_terracotta:0)
Block(-4,29,-1,minecraft:red_glazed_terracotta:0)
Block(-4,30,-2,minecraft:red_glazed_terracotta:0)
Block(-4,30,-1,minecraft:red_glazed_terracotta:0)
Block(-4,30,0,minecraft:red_glazed_terracotta:0)
Block(-4,31,-1,minecraft:red_glazed_terracotta:0)
Block(-3,22,4,minecraft:red_glazed_terracotta:0)
Block(-3,23,3,minecraft:red_glazed_terracotta:0)
Block(-3,23,4,minecraft:red_glazed_terracotta:0)
Block(-3,23,5,minecraft:red_glazed_terracotta:0)
Block(-3,24,2,minecraft:red_glazed_terracotta:0)
Block(-3,24,3,minecraft:red_glazed_terracotta:0)
Block(-3,24,4,minecraft:red_glazed_terracotta:0)
Block(-3,24,5,minecraft:red_glazed_terracotta:0)
Block(-3,24,6,minecraft:red_glazed_terracotta:0)
Block(-3,25,3,minecraft:red_glazed_terracotta:0)
Block(-3,25,4,minecraft:red_glazed_terracotta:0)
Block(-3,25,5,minecraft:red_glazed_terracotta:0)
Block(-3,26,4,minecraft:red_glazed_terracotta:0)
Block(-3,28,-1,minecraft:red_glazed_terracotta:0)
Block(-3,29,-2,minecraft:red_glazed_terracotta:0)
Block(-3,29,-1,minecraft:red_glazed_terracotta:0)
Block(-3,29,0,minecraft:red_glazed_terracotta:0)
Block(-3,30,-3,minecraft:red_glazed_terracotta:0)
Block(-3,30,-2,minecraft:red_glazed_terracotta:0)
Block(-3,30,-1,minecraft:red_glazed_terracotta:0)
Block(-3,30,0,minecraft:red_glazed_terracotta:0)
Block(-3,30,1,minecraft:red_glazed_terracotta:0)
Block(-3,31,-2,minecraft:red_glazed_terracotta:0)
Block(-3,31,-1,minecraft:red_glazed_terracotta:0)
Block(-3,31,0,minecraft:red_glazed_terracotta:0)
Block(-3,32,-1,minecraft:red_glazed_terracotta:0)
Block(-2,10,-1,minecraft:red_glazed_terracotta:0)
Block(-2,11,-2,minecraft:red_glazed_terracotta:0)
Block(-2,11,-1,minecraft:red_glazed_terracotta:0)
Block(-2,11,0,minecraft:red_glazed_terracotta:0)
Block(-2,12,-1,minecraft:red_glazed_terracotta:0)
Block(-2,21,4,CONCRETE:15)
Block(-2,22,3,minecraft:red_glazed_terracotta:0)
Block(-2,22,4,CONCRETE:15)
Block(-2,22,5,minecraft:red_glazed_terracotta:0)
Block(-2,23,2,minecraft:red_glazed_terracotta:0)
Block(-2,23,3,minecraft:red_glazed_terracotta:0)
Block(-2,23,4,CONCRETE:15)
Block(-2,23,5,minecraft:red_glazed_terracotta:0)
Block(-2,23,6,minecraft:red_glazed_terracotta:0)
Block(-2,24,2,minecraft:red_glazed_terracotta:0)
Block(-2,24,3,minecraft:red_glazed_terracotta:0)
Block(-2,24,5,minecraft:red_glazed_terracotta:0)
Block(-2,24,6,minecraft:red_glazed_terracotta:0)
Block(-2,25,2,minecraft:red_glazed_terracotta:0)
Block(-2,25,3,minecraft:red_glazed_terracotta:0)
Block(-2,25,4,minecraft:red_glazed_terracotta:0)
Block(-2,25,5,minecraft:red_glazed_terracotta:0)
Block(-2,25,6,minecraft:red_glazed_terracotta:0)
Block(-2,26,3,minecraft:red_glazed_terracotta:0)
Block(-2,26,4,minecraft:red_glazed_terracotta:0)
Block(-2,26,5,minecraft:red_glazed_terracotta:0)
Block(-2,27,-1,CONCRETE:15)
Block(-2,28,-2,minecraft:red_glazed_terracotta:0)
Block(-2,28,-1,CONCRETE:15)
Block(-2,28,0,minecraft:red_glazed_terracotta:0)
Block(-2,29,-3,minecraft:red_glazed_terracotta:0)
Block(-2,29,-2,minecraft:red_glazed_terracotta:0)
Block(-2,29,-1,CONCRETE:15)
Block(-2,29,0,minecraft:red_glazed_terracotta:0)
Block(-2,29,1,minecraft:red_glazed_terracotta:0)
Block(-2,30,-3,minecraft:red_glazed_terracotta:0)
Block(-2,30,-2,minecraft:red_glazed_terracotta:0)
Block(-2,30,1,minecraft:red_glazed_terracotta:0)
Block(-2,31,-3,minecraft:red_glazed_terracotta:0)
Block(-2,31,-2,minecraft:red_glazed_terracotta:0)
Block(-2,31,-1,minecraft:red_glazed_terracotta:0)
Block(-2,31,0,minecraft:red_glazed_terracotta:0)
Block(-2,31,1,minecraft:red_glazed_terracotta:0)
Block(-2,32,-2,minecraft:red_glazed_terracotta:0)
Block(-2,32,-1,minecraft:red_glazed_terracotta:0)
Block(-2,32,0,minecraft:red_glazed_terracotta:0)
Block(-1,9,-1,CONCRETE:15)
Block(-1,10,-2,minecraft:red_glazed_terracotta:0)
Block(-1,10,-1,CONCRETE:15)
Block(-1,10,0,minecraft:red_glazed_terracotta:0)
Block(-1,11,-2,minecraft:red_glazed_terracotta:0)
Block(-1,11,-1,minecraft:red_glazed_terracotta:0)
Block(-1,11,0,minecraft:red_glazed_terracotta:0)
Block(-1,12,-2,minecraft:red_glazed_terracotta:0)
Block(-1,12,-1,minecraft:red_glazed_terracotta:0)
Block(-1,12,0,minecraft:red_glazed_terracotta:0)
Block(-1,20,2,CONCRETE:15)
Block(-1,20,3,CONCRETE:15)
Block(-1,21,3,CONCRETE:15)
Block(-1,21,4,CONCRETE:15)
Block(-1,22,4,minecraft:red_glazed_terracotta:0)
Block(-1,23,3,minecraft:red_glazed_terracotta:0)
Block(-1,23,4,minecraft:red_glazed_terracotta:0)
Block(-1,23,5,minecraft:red_glazed_terracotta:0)
Block(-1,24,2,minecraft:red_glazed_terracotta:0)
Block(-1,24,3,minecraft:red_glazed_terracotta:0)
Block(-1,24,4,minecraft:red_glazed_terracotta:0)
Block(-1,24,5,minecraft:red_glazed_terracotta:0)
Block(-1,24,6,minecraft:red_glazed_terracotta:0)
Block(-1,25,3,minecraft:red_glazed_terracotta:0)
Block(-1,25,4,minecraft:red_glazed_terracotta:0)
Block(-1,25,5,minecraft:red_glazed_terracotta:0)
Block(-1,26,0,CONCRETE:15)
Block(-1,26,4,minecraft:red_glazed_terracotta:0)
Block(-1,27,-1,CONCRETE:15)
Block(-1,27,0,CONCRETE:15)
Block(-1,28,-1,minecraft:red_glazed_terracotta:0)
Block(-1,29,-2,minecraft:red_glazed_terracotta:0)
Block(-1,29,-1,minecraft:red_glazed_terracotta:0)
Block(-1,29,0,minecraft:red_glazed_terracotta:0)
Block(-1,30,-3,minecraft:red_glazed_terracotta:0)
Block(-1,30,-2,minecraft:red_glazed_terracotta:0)
Block(-1,30,0,minecraft:red_glazed_terracotta:0)
Block(-1,30,1,minecraft:red_glazed_terracotta:0)
Block(-1,31,-2,minecraft:red_glazed_terracotta:0)
Block(-1,31,-1,minecraft:red_glazed_terracotta:0)
Block(-1,31,0,minecraft:red_glazed_terracotta:0)
Block(-1,32,-1,minecraft:red_glazed_terracotta:0)
Block(0,7,0,CONCRETE:15)
Block(0,7,1,CONCRETE:15)
Block(0,8,0,CONCRETE:15)
Block(0,10,-1,minecraft:red_glazed_terracotta:0)
Block(0,11,-2,minecraft:red_glazed_terracotta:0)
Block(0,11,-1,minecraft:red_glazed_terracotta:0)
Block(0,11,0,minecraft:red_glazed_terracotta:0)
Block(0,12,-1,minecraft:red_glazed_terracotta:0)
Block(0,18,2,CONCRETE:15)
Block(0,19,2,CONCRETE:15)
Block(0,20,1,CONCRETE:15)
Block(0,20,2,CONCRETE:15)
Block(0,21,1,CONCRETE:15)
Block(0,22,1,CONCRETE:15)
Block(0,23,1,CONCRETE:15)
Block(0,23,4,minecraft:red_glazed_terracotta:0)
Block(0,24,1,CONCRETE:15)
Block(0,24,3,minecraft:red_glazed_terracotta:0)
Block(0,24,4,minecraft:red_glazed_terracotta:0)
Block(0,24,5,minecraft:red_glazed_terracotta:0)
Block(0,25,1,CONCRETE:15)
Block(0,25,4,minecraft:red_glazed_terracotta:0)
Block(0,26,0,CONCRETE:15)
Block(0,26,1,CONCRETE:15)
Block(0,27,1,CONCRETE:15)
Block(0,29,-1,minecraft:red_glazed_terracotta:0)
Block(0,30,-2,minecraft:red_glazed_terracotta:0)
Block(0,30,-1,minecraft:red_glazed_terracotta:0)
Block(0,30,0,minecraft:red_glazed_terracotta:0)
Block(0,31,-1,minecraft:red_glazed_terracotta:0)
Block(0,31,3,minecraft:red_glazed_terracotta:0)
Block(0,32,2,minecraft:red_glazed_terracotta:0)
Block(0,32,3,minecraft:red_glazed_terracotta:0)
Block(0,32,4,minecraft:red_glazed_terracotta:0)
Block(0,33,3,minecraft:red_glazed_terracotta:0)
Block(1,1,1,CONCRETE:15)
Block(1,2,1,CONCRETE:15)
Block(1,3,1,CONCRETE:15)
Block(1,4,1,CONCRETE:15)
Block(1,5,1,CONCRETE:15)
Block(1,6,1,CONCRETE:15)
Block(1,7,1,CONCRETE:15)
Block(1,13,1,CONCRETE:15)
Block(1,13,2,CONCRETE:15)
Block(1,14,2,CONCRETE:15)
Block(1,15,2,minecraft:red_glazed_terracotta:0)
Block(1,16,2,CONCRETE:15)
Block(1,17,1,CONCRETE:15)
Block(1,17,2,CONCRETE:15)
Block(1,18,2,CONCRETE:15)
Block(1,27,1,CONCRETE:15)
Block(1,27,2,CONCRETE:15)
Block(1,28,2,CONCRETE:15)
Block(1,30,3,minecraft:red_glazed_terracotta:0)
Block(1,31,2,minecraft:red_glazed_terracotta:0)
Block(1,31,3,minecraft:red_glazed_terracotta:0)
Block(1,31,4,minecraft:red_glazed_terracotta:0)
Block(1,32,1,minecraft:red_glazed_terracotta:0)
Block(1,32,2,minecraft:red_glazed_terracotta:0)
Block(1,32,3,minecraft:red_glazed_terracotta:0)
Block(1,32,4,minecraft:red_glazed_terracotta:0)
Block(1,32,5,minecraft:red_glazed_terracotta:0)
Block(1,33,2,minecraft:red_glazed_terracotta:0)
Block(1,33,3,minecraft:red_glazed_terracotta:0)
Block(1,33,4,minecraft:red_glazed_terracotta:0)
Block(1,34,3,minecraft:red_glazed_terracotta:0)
Block(2,7,1,CONCRETE:15)
Block(2,8,1,CONCRETE:15)
Block(2,9,1,CONCRETE:15)
Block(2,10,1,CONCRETE:15)
Block(2,11,1,CONCRETE:15)
Block(2,12,1,CONCRETE:15)
Block(2,13,1,CONCRETE:15)
Block(2,13,3,CONCRETE:15)
Block(2,15,4,minecraft:red_glazed_terracotta:0)
Block(2,16,3,minecraft:red_glazed_terracotta:0)
Block(2,16,4,minecraft:red_glazed_terracotta:0)
Block(2,16,5,minecraft:red_glazed_terracotta:0)
Block(2,17,0,CONCRETE:15)
Block(2,17,1,minecraft:red_glazed_terracotta:0)
Block(2,17,4,minecraft:red_glazed_terracotta:0)
Block(2,28,2,CONCRETE:15)
Block(2,29,2,CONCRETE:15)
Block(2,30,2,CONCRETE:15)
Block(2,30,3,CONCRETE:15)
Block(2,30,4,minecraft:red_glazed_terracotta:0)
Block(2,31,1,minecraft:red_glazed_terracotta:0)
Block(2,31,2,minecraft:red_glazed_terracotta:0)
Block(2,31,3,CONCRETE:15)
Block(2,31,4,minecraft:red_glazed_terracotta:0)
Block(2,31,5,minecraft:red_glazed_terracotta:0)
Block(2,32,1,minecraft:red_glazed_terracotta:0)
Block(2,32,2,minecraft:red_glazed_terracotta:0)
Block(2,32,4,minecraft:red_glazed_terracotta:0)
Block(2,32,5,minecraft:red_glazed_terracotta:0)
Block(2,33,1,minecraft:red_glazed_terracotta:0)
Block(2,33,2,minecraft:red_glazed_terracotta:0)
Block(2,33,3,minecraft:red_glazed_terracotta:0)
Block(2,33,4,minecraft:red_glazed_terracotta:0)
Block(2,33,5,minecraft:red_glazed_terracotta:0)
Block(2,34,2,minecraft:red_glazed_terracotta:0)
Block(2,34,3,minecraft:red_glazed_terracotta:0)
Block(2,34,4,minecraft:red_glazed_terracotta:0)
Block(3,14,4,CONCRETE:15)
Block(3,15,3,minecraft:red_glazed_terracotta:0)
Block(3,15,4,CONCRETE:15)
Block(3,15,5,minecraft:red_glazed_terracotta:0)
Block(3,16,3,minecraft:red_glazed_terracotta:0)
Block(3,16,5,minecraft:red_glazed_terracotta:0)
Block(3,17,0,CONCRETE:15)
Block(3,17,3,minecraft:red_glazed_terracotta:0)
Block(3,17,4,minecraft:red_glazed_terracotta:0)
Block(3,17,5,minecraft:red_glazed_terracotta:0)
Block(3,18,0,CONCRETE:15)
Block(3,21,0,minecraft:red_glazed_terracotta:0)
Block(3,22,-1,minecraft:red_glazed_terracotta:0)
Block(3,22,0,minecraft:red_glazed_terracotta:0)
Block(3,22,1,minecraft:red_glazed_terracotta:0)
Block(3,23,0,minecraft:red_glazed_terracotta:0)
Block(3,30,3,minecraft:red_glazed_terracotta:0)
Block(3,31,2,minecraft:red_glazed_terracotta:0)
Block(3,31,3,minecraft:red_glazed_terracotta:0)
Block(3,31,4,minecraft:red_glazed_terracotta:0)
Block(3,32,1,minecraft:red_glazed_terracotta:0)
Block(3,32,2,minecraft:red_glazed_terracotta:0)
Block(3,32,3,minecraft:red_glazed_terracotta:0)
Block(3,32,4,minecraft:red_glazed_terracotta:0)
Block(3,32,5,minecraft:red_glazed_terracotta:0)
Block(3,33,2,minecraft:red_glazed_terracotta:0)
Block(3,33,3,minecraft:red_glazed_terracotta:0)
Block(3,33,4,minecraft:red_glazed_terracotta:0)
Block(3,34,3,minecraft:red_glazed_terracotta:0)
Block(4,15,4,minecraft:red_glazed_terracotta:0)
Block(4,16,3,minecraft:red_glazed_terracotta:0)
Block(4,16,4,minecraft:red_glazed_terracotta:0)
Block(4,16,5,minecraft:red_glazed_terracotta:0)
Block(4,17,4,minecraft:red_glazed_terracotta:0)
Block(4,18,0,CONCRETE:15)
Block(4,19,0,CONCRETE:15)
Block(4,20,0,minecraft:red_glazed_terracotta:0)
Block(4,21,-1,minecraft:red_glazed_terracotta:0)
Block(4,21,0,CONCRETE:15)
Block(4,21,1,minecraft:red_glazed_terracotta:0)
Block(4,22,-1,minecraft:red_glazed_terracotta:0)
Block(4,22,1,minecraft:red_glazed_terracotta:0)
Block(4,23,-1,minecraft:red_glazed_terracotta:0)
Block(4,23,0,minecraft:red_glazed_terracotta:0)
Block(4,23,1,minecraft:red_glazed_terracotta:0)
Block(4,31,3,minecraft:red_glazed_terracotta:0)
Block(4,32,2,minecraft:red_glazed_terracotta:0)
Block(4,32,3,minecraft:red_glazed_terracotta:0)
Block(4,32,4,minecraft:red_glazed_terracotta:0)
Block(4,33,3,minecraft:red_glazed_terracotta:0)
Block(5,21,0,minecraft:red_glazed_terracotta:0)
Block(5,22,-1,minecraft:red_glazed_terracotta:0)
Block(5,22,0,minecraft:red_glazed_terracotta:0)
Block(5,22,1,minecraft:red_glazed_terracotta:0)
Block(5,23,0,minecraft:red_glazed_terracotta:0)

#######################################################################
# +-----------------------------------------------------------------+ #
# |                            BO3 checks                           | #
# +-----------------------------------------------------------------+ #
#######################################################################


#######################################################################
# +-----------------------------------------------------------------+ #
# |                             Branches                            | #
# +-----------------------------------------------------------------+ #
#######################################################################


#######################################################################
# +-----------------------------------------------------------------+ #
# |                             Entities                            | #
# +-----------------------------------------------------------------+ #
#######################################################################


#######################################################################
# +-----------------------------------------------------------------+ #
# |                            Particles                            | #
# +-----------------------------------------------------------------+ #
#######################################################################


#######################################################################
# +-----------------------------------------------------------------+ #
# |                             Spawners                            | #
# +-----------------------------------------------------------------+ #
#######################################################################


#######################################################################
# +-----------------------------------------------------------------+ #
# |                             ModData                             | #
# +-----------------------------------------------------------------+ #
#######################################################################

