
#######################################################################
# +-----------------------------------------------------------------+ #
# |                            BO3 object                           | #
# +-----------------------------------------------------------------+ #
#######################################################################

Author: MC_Pitman

Description: No description given

Version: 3

SettingsMode: WriteWithoutComments


#######################################################################
# +-----------------------------------------------------------------+ #
# |                          Main settings                          | #
# +-----------------------------------------------------------------+ #
#######################################################################

Tree: true

Frequency: 1

Rarity: 20.0

RotateRandomly: true

SpawnHeight: highestSolidBlock

SpawnHeightOffset: 0

SpawnHeightVariance: 0

##############################
# Height Limits for the BO3. #
##############################

MinHeight: 62

MaxHeight: 255

######################
# Extrusion settings #
######################

ExtrudeMode: None

ExtrudeThroughBlocks: AIR

MaxBranchDepth: 10

ExcludedBiomes: All


#######################################################################
# +-----------------------------------------------------------------+ #
# |                      Source block settings                      | #
# +-----------------------------------------------------------------+ #
#######################################################################

SourceBlocks: AIR

MaxPercentageOutsideSourceBlock: 0

OutsideSourceBlock: placeAnyway

DoReplaceBlocks: true

IsOTGPlus: false


#######################################################################
# +-----------------------------------------------------------------+ #
# |                              Blocks                             | #
# +-----------------------------------------------------------------+ #
#######################################################################

Block(-5,5,2,VINE:8)
Block(-5,6,2,VINE:8)
Block(-5,7,2,VINE:8)
Block(-5,8,-1,LEAVES:3)
Block(-5,8,0,LEAVES:3)
Block(-5,8,1,LEAVES:3)
Block(-5,8,2,VINE:8)
Block(-5,9,0,LEAVES:3)
Block(-5,13,0,LEAVES:3)
Block(-5,13,1,LEAVES:3)
Block(-5,14,0,LEAVES:3)
Block(-4,1,-1,VINE:8)
Block(-4,2,-1,VINE:8)
Block(-4,3,-1,VINE:8)
Block(-4,8,-2,LEAVES:3)
Block(-4,8,-1,LEAVES:3)
Block(-4,8,0,LEAVES:3)
Block(-4,8,1,LEAVES:3)
Block(-4,8,2,LEAVES:3)
Block(-4,8,3,VINE:4)
Block(-4,9,-1,LEAVES:3)
Block(-4,9,0,LEAVES:3)
Block(-4,9,1,LEAVES:3)
Block(-4,9,2,VINE:8)
Block(-4,10,0,LEAVES:3)
Block(-4,13,-1,LEAVES:3)
Block(-4,13,0,LEAVES:3)
Block(-4,13,1,LEAVES:3)
Block(-4,13,2,LEAVES:3)
Block(-4,14,-1,LEAVES:3)
Block(-4,14,0,LEAVES:3)
Block(-4,14,1,LEAVES:3)
Block(-4,15,0,LEAVES:3)
Block(-3,3,-1,HUGE_MUSHROOM_2:1)
Block(-3,3,0,HUGE_MUSHROOM_2:7)
Block(-3,4,-1,VINE:8)
Block(-3,8,-3,LEAVES:3)
Block(-3,8,-2,LEAVES:3)
Block(-3,8,-1,LEAVES:3)
Block(-3,8,0,LEAVES:3)
Block(-3,8,1,LEAVES:3)
Block(-3,8,2,LEAVES:3)
Block(-3,8,3,LEAVES:3)
Block(-3,9,-2,LEAVES:3)
Block(-3,9,-1,LEAVES:3)
Block(-3,9,0,LOG:3)
Block(-3,9,1,LEAVES:3)
Block(-3,9,2,LEAVES:3)
Block(-3,10,-2,VINE:1)
Block(-3,10,-1,LEAVES:3)
Block(-3,10,0,LEAVES:3)
Block(-3,10,1,LEAVES:3)
Block(-3,10,2,VINE:4)
Block(-3,11,-1,LEAVES:3)
Block(-3,13,-2,LEAVES:3)
Block(-3,13,-1,LEAVES:3)
Block(-3,13,0,LEAVES:3)
Block(-3,13,1,LEAVES:3)
Block(-3,13,2,LEAVES:3)
Block(-3,13,3,LEAVES:3)
Block(-3,14,-2,LEAVES:3)
Block(-3,14,-1,LEAVES:3)
Block(-3,14,0,LEAVES:3)
Block(-3,14,1,LEAVES:3)
Block(-3,14,2,LEAVES:3)
Block(-3,15,-1,LEAVES:3)
Block(-3,15,0,LEAVES:3)
Block(-3,15,1,LEAVES:3)
Block(-2,-1,0,VINE:8)
Block(-2,0,0,VINE:8)
Block(-2,0,1,VINE:8)
Block(-2,1,0,VINE:8)
Block(-2,1,1,VINE:8)
Block(-2,2,0,VINE:8)
Block(-2,2,1,VINE:8)
Block(-2,3,-2,HUGE_MUSHROOM_2:1)
Block(-2,3,-1,HUGE_MUSHROOM_2)
Block(-2,3,0,HUGE_MUSHROOM_2)
Block(-2,3,1,HUGE_MUSHROOM_2:7)
Block(-2,4,-1,HUGE_MUSHROOM_2:1)
Block(-2,4,0,HUGE_MUSHROOM_2:7)
Block(-2,4,1,VINE:8)
Block(-2,5,0,VINE:8)
Block(-2,5,1,VINE:8)
Block(-2,6,0,VINE:8)
Block(-2,6,1,VINE:8)
Block(-2,7,0,VINE:8)
Block(-2,7,1,HUGE_MUSHROOM_2:1)
Block(-2,7,2,HUGE_MUSHROOM_2:7)
Block(-2,8,-2,LEAVES:3)
Block(-2,8,-1,LEAVES:3)
Block(-2,8,0,LOG:3)
Block(-2,8,1,LEAVES:3)
Block(-2,8,2,LEAVES:3)
Block(-2,9,-1,LEAVES:3)
Block(-2,9,0,LEAVES:3)
Block(-2,9,1,LEAVES:3)
Block(-2,10,0,LEAVES:3)
Block(-2,10,1,VINE:8)
Block(-2,11,-2,LEAVES:3)
Block(-2,11,-1,LEAVES:3)
Block(-2,11,0,LEAVES:3)
Block(-2,11,1,VINE:8)
Block(-2,12,-1,LEAVES:3)
Block(-2,12,1,VINE:8)
Block(-2,13,-3,LEAVES:3)
Block(-2,13,-2,LEAVES:3)
Block(-2,13,-1,LEAVES:3)
Block(-2,13,0,LEAVES:3)
Block(-2,13,1,LEAVES:3)
Block(-2,13,2,LEAVES:3)
Block(-2,13,3,LEAVES:3)
Block(-2,13,4,LEAVES:3)
Block(-2,14,-3,LEAVES:3)
Block(-2,14,-2,LEAVES:3)
Block(-2,14,-1,LEAVES:3)
Block(-2,14,0,LEAVES:3)
Block(-2,14,1,LEAVES:3)
Block(-2,14,2,LEAVES:3)
Block(-2,14,3,LEAVES:3)
Block(-2,15,-2,LEAVES:3)
Block(-2,15,-1,LEAVES:3)
Block(-2,15,0,LEAVES:3)
Block(-2,15,1,LEAVES:3)
Block(-2,15,2,LEAVES:3)
Block(-1,-2,0,LOG:3)
Block(-1,-2,1,LOG:3)
Block(-1,-1,-1,VINE:1)
Block(-1,-1,0,LOG:3)
Block(-1,-1,1,LOG:3)
Block(-1,-1,2,VINE:4)
Block(-1,0,-1,VINE:1)
Block(-1,0,0,LOG:3)
Block(-1,0,1,LOG:3)
Block(-1,0,2,VINE:4)
Block(-1,1,-1,VINE:1)
Block(-1,1,0,LOG:3)
Block(-1,1,1,LOG:3)
Block(-1,1,2,VINE:4)
Block(-1,2,-1,VINE:1)
Block(-1,2,0,LOG:3)
Block(-1,2,1,LOG:3)
Block(-1,2,2,VINE:4)
Block(-1,3,-2,HUGE_MUSHROOM_2:3)
Block(-1,3,-1,HUGE_MUSHROOM_2)
Block(-1,3,0,LOG:3)
Block(-1,3,1,LOG:3)
Block(-1,3,2,VINE:4)
Block(-1,4,-1,HUGE_MUSHROOM_2:3)
Block(-1,4,0,LOG:3)
Block(-1,4,1,LOG:3)
Block(-1,4,2,VINE:4)
Block(-1,5,-1,VINE:1)
Block(-1,5,0,LOG:3)
Block(-1,5,1,LOG:3)
Block(-1,5,2,VINE:4)
Block(-1,6,-1,VINE:1)
Block(-1,6,0,LOG:3)
Block(-1,6,1,LOG:3)
Block(-1,6,2,VINE:4)
Block(-1,6,4,VINE:4)
Block(-1,7,-1,VINE:1)
Block(-1,7,0,LOG:3)
Block(-1,7,1,LOG:3)
Block(-1,7,2,HUGE_MUSHROOM_2)
Block(-1,7,3,HUGE_MUSHROOM_2:7)
Block(-1,7,4,VINE:4)
Block(-1,8,-2,LEAVES:3)
Block(-1,8,-1,LEAVES:3)
Block(-1,8,0,LOG:3)
Block(-1,8,1,LOG:3)
Block(-1,8,2,HUGE_MUSHROOM_2:7)
Block(-1,8,3,VINE:4)
Block(-1,9,0,LOG:3)
Block(-1,9,1,LOG:3)
Block(-1,9,2,VINE:4)
Block(-1,10,0,LOG:3)
Block(-1,10,1,LOG:3)
Block(-1,10,2,VINE:4)
Block(-1,11,-3,LEAVES:3)
Block(-1,11,-2,LEAVES:3)
Block(-1,11,-1,LOG:3)
Block(-1,11,0,LOG:3)
Block(-1,11,1,LOG:3)
Block(-1,11,2,VINE:4)
Block(-1,12,-2,LEAVES:3)
Block(-1,12,-1,LEAVES:3)
Block(-1,12,0,LOG:3)
Block(-1,12,1,LOG:3)
Block(-1,12,2,VINE:4)
Block(-1,13,-4,LEAVES:3)
Block(-1,13,-3,LEAVES:3)
Block(-1,13,-2,LEAVES:3)
Block(-1,13,-1,LEAVES:3)
Block(-1,13,0,LOG:3)
Block(-1,13,1,LOG:3)
Block(-1,13,2,LEAVES:3)
Block(-1,13,3,LEAVES:3)
Block(-1,13,4,LEAVES:3)
Block(-1,13,5,LEAVES:3)
Block(-1,14,-4,LEAVES:3)
Block(-1,14,-3,LEAVES:3)
Block(-1,14,-2,LEAVES:3)
Block(-1,14,-1,LEAVES:3)
Block(-1,14,0,LOG:3)
Block(-1,14,1,LEAVES:3)
Block(-1,14,2,LEAVES:3)
Block(-1,14,3,LEAVES:3)
Block(-1,14,4,LEAVES:3)
Block(-1,15,-3,LEAVES:3)
Block(-1,15,-2,LEAVES:3)
Block(-1,15,-1,LEAVES:3)
Block(-1,15,0,LEAVES:3)
Block(-1,15,1,LEAVES:3)
Block(-1,15,2,LEAVES:3)
Block(-1,15,3,LEAVES:3)
Block(0,-2,0,LOG:3)
Block(0,-2,1,LOG:3)
Block(0,-1,0,LOG:3)
Block(0,-1,1,LOG:3)
Block(0,0,0,LOG:3)
Block(0,0,1,LOG:3)
Block(0,1,-1,VINE:1)
Block(0,1,0,LOG:3)
Block(0,1,1,LOG:3)
Block(0,1,2,VINE:4)
Block(0,2,-1,VINE:1)
Block(0,2,0,LOG:3)
Block(0,2,1,LOG:3)
Block(0,2,2,VINE:4)
Block(0,3,-1,HUGE_MUSHROOM_2:3)
Block(0,3,0,LOG:3)
Block(0,3,1,LOG:3)
Block(0,3,2,VINE:4)
Block(0,4,-1,VINE:1)
Block(0,4,0,LOG:3)
Block(0,4,1,LOG:3)
Block(0,4,2,VINE:4)
Block(0,5,-1,VINE:1)
Block(0,5,0,LOG:3)
Block(0,5,1,LOG:3)
Block(0,5,2,VINE:4)
Block(0,6,-1,VINE:1)
Block(0,6,0,LOG:3)
Block(0,6,1,LOG:3)
Block(0,6,2,VINE:4)
Block(0,7,-1,VINE:1)
Block(0,7,0,LOG:3)
Block(0,7,1,LOG:3)
Block(0,7,2,HUGE_MUSHROOM_2)
Block(0,7,3,HUGE_MUSHROOM_2:9)
Block(0,8,-1,VINE:1)
Block(0,8,0,LOG:3)
Block(0,8,1,LOG:3)
Block(0,8,2,HUGE_MUSHROOM_2:9)
Block(0,9,-1,VINE:1)
Block(0,9,0,LOG:3)
Block(0,9,1,LOG:3)
Block(0,9,2,VINE:4)
Block(0,10,-1,VINE:1)
Block(0,10,0,LOG:3)
Block(0,10,1,LOG:3)
Block(0,10,2,VINE:4)
Block(0,11,-2,LEAVES:3)
Block(0,11,-1,LEAVES:3)
Block(0,11,0,LOG:3)
Block(0,11,1,LOG:3)
Block(0,11,2,VINE:4)
Block(0,12,-1,LEAVES:3)
Block(0,12,0,LOG:3)
Block(0,12,1,LOG:3)
Block(0,13,-5,LEAVES:3)
Block(0,13,-4,LEAVES:3)
Block(0,13,-3,LEAVES:3)
Block(0,13,-2,LEAVES:3)
Block(0,13,-1,LEAVES:3)
Block(0,13,0,LOG:3)
Block(0,13,1,LOG:3)
Block(0,13,2,LEAVES:3)
Block(0,13,3,LEAVES:3)
Block(0,13,4,LEAVES:3)
Block(0,13,5,LEAVES:3)
Block(0,14,-3,LEAVES:3)
Block(0,14,-2,LEAVES:3)
Block(0,14,-1,LEAVES:3)
Block(0,14,0,LEAVES:3)
Block(0,14,1,LEAVES:3)
Block(0,14,2,LEAVES:3)
Block(0,14,3,LEAVES:3)
Block(0,14,4,LEAVES:3)
Block(0,15,-2,LEAVES:3)
Block(0,15,-1,LEAVES:3)
Block(0,15,0,LEAVES:3)
Block(0,15,1,LEAVES:3)
Block(0,15,2,LEAVES:3)
Block(0,15,3,LEAVES:3)
Block(1,-2,1,VINE:2)
Block(1,-1,0,VINE:2)
Block(1,-1,1,VINE:2)
Block(1,0,0,VINE:2)
Block(1,0,1,VINE:2)
Block(1,1,0,VINE:2)
Block(1,1,1,VINE:2)
Block(1,2,0,VINE:2)
Block(1,2,1,VINE:2)
Block(1,3,0,VINE:2)
Block(1,3,1,VINE:2)
Block(1,4,0,VINE:2)
Block(1,4,1,VINE:2)
Block(1,5,0,VINE:2)
Block(1,5,1,VINE:2)
Block(1,6,0,VINE:2)
Block(1,6,1,VINE:2)
Block(1,7,0,VINE:2)
Block(1,7,1,HUGE_MUSHROOM_2:3)
Block(1,7,2,HUGE_MUSHROOM_2:9)
Block(1,8,0,VINE:2)
Block(1,8,1,VINE:2)
Block(1,9,0,VINE:2)
Block(1,9,1,VINE:2)
Block(1,10,0,VINE:2)
Block(1,10,1,VINE:2)
Block(1,11,-1,LEAVES:3)
Block(1,11,0,VINE:2)
Block(1,11,1,VINE:2)
Block(1,12,0,VINE:2)
Block(1,12,1,VINE:2)
Block(1,13,-3,LEAVES:3)
Block(1,13,-2,LEAVES:3)
Block(1,13,-1,LEAVES:3)
Block(1,13,0,LEAVES:3)
Block(1,13,1,LEAVES:3)
Block(1,13,2,LEAVES:3)
Block(1,13,3,LEAVES:3)
Block(1,13,4,LEAVES:3)
Block(1,14,-2,LEAVES:3)
Block(1,14,-1,LEAVES:3)
Block(1,14,0,LEAVES:3)
Block(1,14,1,LEAVES:3)
Block(1,14,2,LEAVES:3)
Block(1,14,3,LEAVES:3)
Block(1,15,-1,LEAVES:3)
Block(1,15,0,LEAVES:3)
Block(1,15,1,LEAVES:3)
Block(1,15,2,LEAVES:3)
Block(2,7,1,VINE:2)
Block(2,13,-2,LEAVES:3)
Block(2,13,-1,LEAVES:3)
Block(2,13,0,LEAVES:3)
Block(2,13,1,LEAVES:3)
Block(2,13,2,LEAVES:3)
Block(2,13,3,LEAVES:3)
Block(2,14,-1,LEAVES:3)
Block(2,14,0,LEAVES:3)
Block(2,14,1,LEAVES:3)
Block(2,14,2,LEAVES:3)
Block(2,15,0,LEAVES:3)
Block(2,15,1,LEAVES:3)
Block(3,13,-2,LEAVES:3)
Block(3,13,-1,LEAVES:3)
Block(3,13,0,LEAVES:3)
Block(3,13,1,LEAVES:3)
Block(3,13,2,LEAVES:3)
Block(3,14,0,LEAVES:3)
Block(3,14,1,LEAVES:3)
Block(4,13,-1,LEAVES:3)
Block(4,13,0,LEAVES:3)
Block(4,13,1,LEAVES:3)

#######################################################################
# +-----------------------------------------------------------------+ #
# |                            BO3 checks                           | #
# +-----------------------------------------------------------------+ #
#######################################################################

BlockCheck(0,-1,0,GRASS,DIRT,DIRT:2,HARD_CLAY,STAINED_CLAY,CLAY,SANDSTONE,SAND:1,SAND,biomesoplenty:grass:0,biomesoplenty:grass:1,biomesoplenty:grass,biomesoplenty:grass:3,biomesoplenty:grass:4,biomesoplenty:grass:5,biomesoplenty:grass:6,biomesoplenty:grass:7)

#######################################################################
# +-----------------------------------------------------------------+ #
# |                             Branches                            | #
# +-----------------------------------------------------------------+ #
#######################################################################


#######################################################################
# +-----------------------------------------------------------------+ #
# |                             Entities                            | #
# +-----------------------------------------------------------------+ #
#######################################################################


#######################################################################
# +-----------------------------------------------------------------+ #
# |                            Particles                            | #
# +-----------------------------------------------------------------+ #
#######################################################################


#######################################################################
# +-----------------------------------------------------------------+ #
# |                             Spawners                            | #
# +-----------------------------------------------------------------+ #
#######################################################################


#######################################################################
# +-----------------------------------------------------------------+ #
# |                             ModData                             | #
# +-----------------------------------------------------------------+ #
#######################################################################

