
#######################################################################
# +-----------------------------------------------------------------+ #
# |                            BO3 object                           | #
# +-----------------------------------------------------------------+ #
#######################################################################

Author: Unknown

Description: This BO3 was converted from a schematic using the MineCraft Worlds Editor. Unfortunately the author and description information for the schematic could not be found. If you know who the author of the schematic is then please tell the author of this BO3!

Version: 3

SettingsMode: WriteWithoutComments


#######################################################################
# +-----------------------------------------------------------------+ #
# |                          Main settings                          | #
# +-----------------------------------------------------------------+ #
#######################################################################

Tree: false

Frequency: 40

Rarity: 100.0

RotateRandomly: false

SpawnHeight: highestBlock

SpawnHeightOffset: 0

SpawnHeightVariance: 0

##############################
# Height Limits for the BO3. #
##############################

MinHeight: 0

MaxHeight: 256

######################
# Extrusion settings #
######################

ExtrudeMode: None

ExtrudeThroughBlocks: AIR

MaxBranchDepth: 10

ExcludedBiomes: All


#######################################################################
# +-----------------------------------------------------------------+ #
# |                      Source block settings                      | #
# +-----------------------------------------------------------------+ #
#######################################################################

SourceBlocks: AIR

MaxPercentageOutsideSourceBlock: 100

OutsideSourceBlock: placeAnyway


#######################################################################
# +-----------------------------------------------------------------+ #
# |                              Blocks                             | #
# +-----------------------------------------------------------------+ #
#######################################################################

B(-8,5,-4,WOOL)
B(-8,5,-3,WOOL)
B(-8,5,-2,WOOL)
B(-8,6,-5,WOOL)
B(-8,6,-4,WOOL)
B(-8,6,-3,WOOL)
B(-8,6,-2,WOOL)
B(-8,6,-1,WOOL)
B(-8,7,-6,WOOL)
B(-8,7,-5,WOOL)
B(-8,7,-4,WOOL)
B(-8,7,-3,WOOL)
B(-8,7,-2,WOOL)
B(-8,7,-1,WOOL)
B(-8,7,0,WOOL)
B(-8,7,1,WOOL)
B(-8,7,2,WOOL)
B(-8,8,-5,WOOL)
B(-8,8,-4,WOOL)
B(-8,8,-3,WOOL)
B(-8,8,-2,WOOL)
B(-8,8,-1,WOOL)
B(-8,8,0,WOOL)
B(-8,8,1,WOOL)
B(-8,9,-5,WOOL)
B(-8,9,-4,WOOL)
B(-8,9,-3,WOOL)
B(-8,9,-2,WOOL)
B(-8,9,-1,WOOL)
B(-8,9,0,WOOL)
B(-8,9,1,WOOL)
B(-8,10,-5,WOOL)
B(-8,10,-4,WOOL)
B(-8,10,-3,WOOL)
B(-8,10,-2,WOOL)
B(-8,10,-1,WOOL)
B(-8,10,0,WOOL)
B(-8,10,1,WOOL)
B(-8,11,-5,WOOL)
B(-8,11,-4,WOOL)
B(-8,11,-3,WOOL)
B(-8,11,-2,WOOL)
B(-8,11,-1,WOOL)
B(-8,11,0,WOOL)
B(-8,11,1,WOOL)
B(-8,11,2,WOOL)
B(-8,12,-5,WOOL)
B(-8,12,-4,WOOL)
B(-8,12,-3,WOOL)
B(-8,12,-2,WOOL)
B(-8,12,-1,WOOL)
B(-8,12,0,WOOL)
B(-8,12,1,WOOL)
B(-8,12,2,WOOL)
B(-8,13,-5,WOOL)
B(-8,13,-4,WOOL)
B(-8,13,-3,WOOL)
B(-8,13,-2,WOOL)
B(-8,13,-1,WOOL)
B(-8,13,0,WOOL)
B(-8,13,1,WOOL)
B(-8,13,2,WOOL)
B(-8,14,-5,WOOL)
B(-8,14,-4,WOOL)
B(-8,14,-3,WOOL)
B(-8,14,-2,WOOL)
B(-8,14,-1,WOOL)
B(-8,14,0,WOOL)
B(-8,14,1,WOOL)
B(-8,14,2,WOOL)
B(-8,15,-5,WOOL)
B(-8,15,-4,WOOL)
B(-8,15,-3,WOOL)
B(-8,15,-2,WOOL)
B(-8,15,-1,WOOL)
B(-8,15,0,WOOL)
B(-8,15,1,WOOL)
B(-8,16,-5,WOOL)
B(-8,16,-4,WOOL)
B(-8,16,-3,WOOL)
B(-8,16,-2,WOOL)
B(-8,16,-1,WOOL)
B(-8,16,0,WOOL)
B(-8,16,1,WOOL)
B(-8,17,-6,WOOL)
B(-8,17,-5,WOOL)
B(-8,17,-4,WOOL)
B(-8,17,-3,WOOL)
B(-8,17,-2,WOOL)
B(-8,17,-1,WOOL)
B(-8,17,0,WOOL)
B(-8,17,1,WOOL)
B(-8,17,2,WOOL)
B(-8,18,-5,WOOL)
B(-8,18,-4,WOOL)
B(-8,18,-3,WOOL)
B(-8,18,-2,WOOL)
B(-8,18,-1,WOOL)
B(-8,18,0,WOOL)
B(-8,18,1,WOOL)
B(-8,19,-6,WOOL)
B(-8,19,-5,WOOL)
B(-8,19,-4,WOOL)
B(-8,19,-3,WOOL)
B(-8,19,-2,WOOL)
B(-8,19,-1,WOOL)
B(-8,19,0,WOOL)
B(-8,19,1,WOOL)
B(-8,19,2,WOOL)
B(-8,20,-6,WOOL)
B(-8,20,-5,WOOL)
B(-8,20,-4,WOOL)
B(-8,20,-3,WOOL)
B(-8,20,-2,WOOL)
B(-8,20,-1,WOOL)
B(-8,20,0,WOOL)
B(-8,20,1,WOOL)
B(-8,20,2,WOOL)
B(-8,21,-6,WOOL)
B(-8,21,-5,WOOL)
B(-8,21,-4,WOOL)
B(-8,21,-3,WOOL)
B(-8,21,-2,WOOL)
B(-8,21,-1,WOOL)
B(-8,21,0,WOOL)
B(-8,21,1,WOOL)
B(-8,21,2,WOOL)
B(-8,22,-6,WOOL)
B(-8,22,-5,WOOL)
B(-8,22,-4,WOOL)
B(-8,22,-3,WOOL)
B(-8,22,-2,WOOL)
B(-8,22,-1,WOOL)
B(-8,22,0,WOOL)
B(-8,22,1,WOOL)
B(-8,22,2,WOOL)
B(-8,23,-5,WOOL)
B(-8,23,-4,WOOL)
B(-8,23,-3,WOOL)
B(-8,23,-2,WOOL)
B(-8,23,-1,WOOL)
B(-8,23,0,WOOL)
B(-8,23,1,WOOL)
B(-8,24,-5,WOOL)
B(-8,24,-4,WOOL)
B(-8,24,-3,WOOL)
B(-8,24,-2,WOOL)
B(-8,24,-1,WOOL)
B(-8,24,0,WOOL)
B(-8,24,1,WOOL)
B(-8,25,-5,WOOL)
B(-8,25,-4,WOOL)
B(-8,25,-3,WOOL)
B(-8,25,-2,WOOL)
B(-8,25,-1,WOOL)
B(-8,25,0,WOOL)
B(-8,25,1,WOOL)
B(-8,25,2,WOOL)
B(-8,26,-5,WOOL)
B(-8,26,-4,WOOL)
B(-8,26,-3,WOOL)
B(-8,26,-2,WOOL)
B(-8,26,-1,WOOL)
B(-8,26,0,WOOL)
B(-8,26,1,WOOL)
B(-8,26,2,WOOL)
B(-8,27,-5,WOOL)
B(-8,27,-4,WOOL)
B(-8,27,-3,WOOL)
B(-8,27,-2,WOOL)
B(-8,27,-1,WOOL)
B(-8,27,0,WOOL)
B(-8,27,1,WOOL)
B(-8,28,-5,WOOL)
B(-8,28,-4,WOOL)
B(-8,28,-3,WOOL)
B(-8,28,-2,WOOL)
B(-8,28,-1,WOOL)
B(-8,28,0,WOOL)
B(-8,28,1,WOOL)
B(-8,29,-5,WOOL)
B(-8,29,-4,WOOL)
B(-8,29,-3,WOOL)
B(-8,29,-2,WOOL)
B(-8,29,-1,WOOL)
B(-8,29,0,WOOL)
B(-8,29,1,WOOL)
B(-8,30,-5,WOOL)
B(-8,30,-4,WOOL)
B(-8,30,-3,WOOL)
B(-8,30,-2,WOOL)
B(-8,30,-1,WOOL)
B(-8,30,0,WOOL)
B(-8,30,1,WOOL)
B(-8,31,-5,WOOL)
B(-8,31,-4,WOOL)
B(-8,31,-3,WOOL)
B(-8,31,-2,WOOL)
B(-8,31,-1,WOOL)
B(-8,31,0,WOOL)
B(-8,31,1,WOOL)
B(-8,32,-5,WOOL)
B(-8,32,-4,WOOL)
B(-8,32,-3,WOOL)
B(-8,32,-2,WOOL)
B(-8,32,-1,WOOL)
B(-8,32,0,WOOL)
B(-8,32,1,WOOL)
B(-8,33,-5,WOOL)
B(-8,33,-4,WOOL)
B(-8,33,-3,WOOL)
B(-8,33,-2,WOOL)
B(-8,33,-1,WOOL)
B(-8,33,0,WOOL)
B(-8,33,1,WOOL)
B(-8,34,-5,WOOL)
B(-8,34,-4,WOOL)
B(-8,34,-3,WOOL)
B(-8,34,-2,WOOL)
B(-8,34,-1,WOOL)
B(-8,34,0,WOOL)
B(-8,34,1,WOOL)
B(-8,35,-5,WOOL)
B(-8,35,-4,WOOL)
B(-8,35,-3,WOOL)
B(-8,35,-2,WOOL)
B(-8,35,-1,WOOL)
B(-8,35,0,WOOL)
B(-8,35,1,WOOL)
B(-8,35,2,WOOL)
B(-8,36,-5,WOOL)
B(-8,36,-4,WOOL)
B(-8,36,-3,WOOL)
B(-8,36,-2,WOOL)
B(-8,36,-1,WOOL)
B(-8,36,0,WOOL)
B(-8,36,1,WOOL)
B(-8,36,2,WOOL)
B(-8,37,-4,WOOL)
B(-8,37,-3,WOOL)
B(-8,37,-2,WOOL)
B(-8,37,-1,WOOL)
B(-8,37,0,WOOL)
B(-8,37,1,WOOL)
B(-8,38,-5,WOOL)
B(-8,38,-4,WOOL)
B(-8,38,-3,WOOL)
B(-8,38,-2,WOOL)
B(-8,38,-1,WOOL)
B(-8,38,0,WOOL)
B(-8,38,1,WOOL)
B(-8,38,2,WOOL)
B(-8,39,-6,WOOL)
B(-8,39,-5,WOOL)
B(-8,39,-4,WOOL)
B(-8,39,-3,WOOL)
B(-8,39,-2,WOOL)
B(-8,39,-1,WOOL)
B(-8,39,0,WOOL)
B(-8,39,1,WOOL)
B(-8,39,2,WOOL)
B(-8,40,-6,WOOL)
B(-8,40,-5,WOOL)
B(-8,40,-4,WOOL)
B(-8,40,-3,WOOL)
B(-8,40,-2,WOOL)
B(-8,40,-1,WOOL)
B(-8,40,0,WOOL)
B(-8,40,1,WOOL)
B(-8,40,2,WOOL)
B(-8,41,-6,WOOL)
B(-8,41,-5,WOOL)
B(-8,41,-4,WOOL)
B(-8,41,-3,WOOL)
B(-8,41,-2,WOOL)
B(-8,41,-1,WOOL)
B(-8,41,0,WOOL)
B(-8,41,1,WOOL)
B(-8,41,2,WOOL)
B(-8,42,-6,WOOL)
B(-8,42,-5,WOOL)
B(-8,42,-4,WOOL)
B(-8,42,-3,WOOL)
B(-8,42,-2,WOOL)
B(-8,42,-1,WOOL)
B(-8,42,0,WOOL)
B(-8,42,1,WOOL)
B(-8,42,2,WOOL)
B(-8,43,-6,WOOL)
B(-8,43,-5,WOOL)
B(-8,43,-4,WOOL)
B(-8,43,-3,WOOL)
B(-8,43,-2,WOOL)
B(-8,43,-1,WOOL)
B(-8,43,0,WOOL)
B(-8,43,1,WOOL)
B(-8,43,2,WOOL)
B(-8,44,-6,WOOL)
B(-8,44,-5,WOOL)
B(-8,44,-4,WOOL)
B(-8,44,-3,WOOL)
B(-8,44,-2,WOOL)
B(-8,44,-1,WOOL)
B(-8,44,0,WOOL)
B(-8,44,1,WOOL)
B(-8,44,2,WOOL)
B(-7,5,-5,WOOL)
B(-7,5,-4,WOOL)
B(-7,5,-3,WOOL)
B(-7,5,-2,WOOL)
B(-7,6,-5,WOOL)
B(-7,6,-4,WOOL)
B(-7,6,-3,WOOL)
B(-7,6,-2,WOOL)
B(-7,7,-5,WOOL)
B(-7,7,-4,WOOL)
B(-7,7,-3,WOOL)
B(-7,7,-2,WOOL)
B(-7,7,-1,WOOL)
B(-7,7,0,WOOL)
B(-7,7,1,WOOL)
B(-7,7,2,WOOL)
B(-7,8,-4,WOOL)
B(-7,8,-3,WOOL)
B(-7,8,-2,WOOL)
B(-7,8,-1,WOOL)
B(-7,8,0,WOOL)
B(-7,8,1,WOOL)
B(-7,9,-4,WOOL)
B(-7,9,-3,WOOL)
B(-7,9,-2,WOOL)
B(-7,9,-1,WOOL)
B(-7,9,0,WOOL)
B(-7,9,1,WOOL)
B(-7,10,-4,WOOL)
B(-7,10,-3,WOOL)
B(-7,10,-2,WOOL)
B(-7,10,-1,WOOL)
B(-7,10,0,WOOL)
B(-7,10,1,WOOL)
B(-7,11,-5,WOOL)
B(-7,11,-4,WOOL)
B(-7,11,-3,WOOL)
B(-7,11,-2,WOOL)
B(-7,11,-1,WOOL)
B(-7,11,0,WOOL)
B(-7,11,1,WOOL)
B(-7,12,-5,WOOL)
B(-7,12,-4,WOOL)
B(-7,12,-3,WOOL)
B(-7,12,-2,WOOL)
B(-7,12,-1,WOOL)
B(-7,12,0,WOOL)
B(-7,12,1,WOOL)
B(-7,12,2,WOOL)
B(-7,13,-5,WOOL)
B(-7,13,-4,WOOL)
B(-7,13,-3,WOOL)
B(-7,13,-2,WOOL)
B(-7,13,-1,WOOL)
B(-7,13,0,WOOL)
B(-7,13,1,WOOL)
B(-7,13,2,WOOL)
B(-7,14,-5,WOOL)
B(-7,14,-4,WOOL)
B(-7,14,-3,WOOL)
B(-7,14,-2,WOOL)
B(-7,14,-1,WOOL)
B(-7,14,0,WOOL)
B(-7,14,1,WOOL)
B(-7,14,2,WOOL)
B(-7,15,-5,WOOL)
B(-7,15,-4,WOOL)
B(-7,15,-3,WOOL)
B(-7,15,-2,WOOL)
B(-7,15,-1,WOOL)
B(-7,15,0,WOOL)
B(-7,15,1,WOOL)
B(-7,16,-5,WOOL)
B(-7,16,-4,WOOL)
B(-7,16,-3,WOOL)
B(-7,16,-2,WOOL)
B(-7,16,-1,WOOL)
B(-7,16,0,WOOL)
B(-7,16,1,WOOL)
B(-7,17,-6,WOOL)
B(-7,17,-5,WOOL)
B(-7,17,-4,WOOL)
B(-7,17,-3,WOOL)
B(-7,17,-2,WOOL)
B(-7,17,-1,WOOL)
B(-7,17,0,WOOL)
B(-7,17,1,WOOL)
B(-7,17,2,WOOL)
B(-7,18,-5,WOOL)
B(-7,18,-4,WOOL)
B(-7,18,-3,WOOL)
B(-7,18,-2,WOOL)
B(-7,18,-1,WOOL)
B(-7,18,0,WOOL)
B(-7,18,1,WOOL)
B(-7,19,-6,WOOL)
B(-7,19,-5,WOOL)
B(-7,19,-4,WOOL)
B(-7,19,-3,WOOL)
B(-7,19,-2,WOOL)
B(-7,19,-1,WOOL)
B(-7,19,0,WOOL)
B(-7,19,1,WOOL)
B(-7,19,2,WOOL)
B(-7,20,-6,WOOL)
B(-7,20,-5,WOOL)
B(-7,20,-4,WOOL)
B(-7,20,-3,WOOL)
B(-7,20,-2,WOOL)
B(-7,20,-1,WOOL)
B(-7,20,0,WOOL)
B(-7,20,1,WOOL)
B(-7,20,2,WOOL)
B(-7,21,-6,WOOL)
B(-7,21,-5,WOOL)
B(-7,21,-4,WOOL)
B(-7,21,-3,WOOL)
B(-7,21,-2,WOOL)
B(-7,21,-1,WOOL)
B(-7,21,0,WOOL)
B(-7,21,1,WOOL)
B(-7,21,2,WOOL)
B(-7,22,-6,WOOL)
B(-7,22,-5,WOOL)
B(-7,22,-4,WOOL)
B(-7,22,-3,WOOL)
B(-7,22,-2,WOOL)
B(-7,22,-1,WOOL)
B(-7,22,0,WOOL)
B(-7,22,1,WOOL)
B(-7,22,2,WOOL)
B(-7,23,-5,WOOL)
B(-7,23,-4,WOOL)
B(-7,23,-3,WOOL)
B(-7,23,-2,WOOL)
B(-7,23,-1,WOOL)
B(-7,23,0,WOOL)
B(-7,23,1,WOOL)
B(-7,24,-5,WOOL)
B(-7,24,-4,WOOL)
B(-7,24,-3,WOOL)
B(-7,24,-2,WOOL)
B(-7,24,-1,WOOL)
B(-7,24,0,WOOL)
B(-7,24,1,WOOL)
B(-7,25,-5,WOOL)
B(-7,25,-4,WOOL)
B(-7,25,-3,WOOL)
B(-7,25,-2,WOOL)
B(-7,25,-1,WOOL)
B(-7,25,0,WOOL)
B(-7,25,1,WOOL)
B(-7,26,-5,WOOL)
B(-7,26,-4,WOOL)
B(-7,26,-3,WOOL)
B(-7,26,-2,WOOL)
B(-7,26,-1,WOOL)
B(-7,26,0,WOOL)
B(-7,26,1,WOOL)
B(-7,27,-5,WOOL)
B(-7,27,-4,WOOL)
B(-7,27,-3,WOOL)
B(-7,27,-2,WOOL)
B(-7,27,-1,WOOL)
B(-7,27,0,WOOL)
B(-7,27,1,WOOL)
B(-7,28,-5,WOOL)
B(-7,28,-4,WOOL)
B(-7,28,-3,WOOL)
B(-7,28,-2,WOOL)
B(-7,28,-1,WOOL)
B(-7,28,0,WOOL)
B(-7,28,1,WOOL)
B(-7,29,-5,WOOL)
B(-7,29,-4,WOOL)
B(-7,29,-3,WOOL)
B(-7,29,-2,WOOL)
B(-7,29,-1,WOOL)
B(-7,29,0,WOOL)
B(-7,29,1,WOOL)
B(-7,30,-5,WOOL)
B(-7,30,-4,WOOL)
B(-7,30,-3,WOOL)
B(-7,30,-2,WOOL)
B(-7,30,-1,WOOL)
B(-7,30,0,WOOL)
B(-7,30,1,WOOL)
B(-7,31,-5,WOOL)
B(-7,31,-4,WOOL)
B(-7,31,-3,WOOL)
B(-7,31,-2,WOOL)
B(-7,31,-1,WOOL)
B(-7,31,0,WOOL)
B(-7,31,1,WOOL)
B(-7,32,-5,WOOL)
B(-7,32,-4,WOOL)
B(-7,32,-3,WOOL)
B(-7,32,-2,WOOL)
B(-7,32,-1,WOOL)
B(-7,32,0,WOOL)
B(-7,32,1,WOOL)
B(-7,33,-5,WOOL)
B(-7,33,-4,WOOL)
B(-7,33,-3,WOOL)
B(-7,33,-2,WOOL)
B(-7,33,-1,WOOL)
B(-7,33,0,WOOL)
B(-7,33,1,WOOL)
B(-7,34,-5,WOOL)
B(-7,34,-4,WOOL)
B(-7,34,-3,WOOL)
B(-7,34,-2,WOOL)
B(-7,34,-1,WOOL)
B(-7,34,0,WOOL)
B(-7,34,1,WOOL)
B(-7,35,-5,WOOL)
B(-7,35,-4,WOOL)
B(-7,35,-3,WOOL)
B(-7,35,-2,WOOL)
B(-7,35,-1,WOOL)
B(-7,35,0,WOOL)
B(-7,35,1,WOOL)
B(-7,35,2,WOOL)
B(-7,36,-5,WOOL)
B(-7,36,-4,WOOL)
B(-7,36,-3,WOOL)
B(-7,36,-2,WOOL)
B(-7,36,-1,WOOL)
B(-7,36,0,WOOL)
B(-7,36,1,WOOL)
B(-7,36,2,WOOL)
B(-7,37,-4,WOOL)
B(-7,37,-3,WOOL)
B(-7,37,-2,WOOL)
B(-7,37,-1,WOOL)
B(-7,37,0,WOOL)
B(-7,38,-5,WOOL)
B(-7,38,-4,WOOL)
B(-7,38,-3,WOOL)
B(-7,38,-2,WOOL)
B(-7,38,-1,WOOL)
B(-7,38,0,WOOL)
B(-7,38,1,WOOL)
B(-7,39,-6,WOOL)
B(-7,39,-5,WOOL)
B(-7,39,-4,WOOL)
B(-7,39,-3,WOOL)
B(-7,39,-2,WOOL)
B(-7,39,-1,WOOL)
B(-7,39,0,WOOL)
B(-7,39,1,WOOL)
B(-7,39,2,WOOL)
B(-7,40,-6,WOOL)
B(-7,40,-5,WOOL)
B(-7,40,-4,WOOL)
B(-7,40,-3,WOOL)
B(-7,40,-2,WOOL)
B(-7,40,-1,WOOL)
B(-7,40,0,WOOL)
B(-7,40,1,WOOL)
B(-7,40,2,WOOL)
B(-7,41,-6,WOOL)
B(-7,41,-5,WOOL)
B(-7,41,-4,WOOL)
B(-7,41,-3,WOOL)
B(-7,41,-2,WOOL)
B(-7,41,-1,WOOL)
B(-7,41,0,WOOL)
B(-7,41,1,WOOL)
B(-7,41,2,WOOL)
B(-7,42,-6,WOOL)
B(-7,42,-5,WOOL)
B(-7,42,-4,WOOL)
B(-7,42,-3,WOOL)
B(-7,42,-2,WOOL)
B(-7,42,-1,WOOL)
B(-7,42,0,WOOL)
B(-7,42,1,WOOL)
B(-7,42,2,WOOL)
B(-7,43,-5,WOOL)
B(-7,43,-4,WOOL)
B(-7,43,-3,WOOL)
B(-7,43,-2,WOOL)
B(-7,43,-1,WOOL)
B(-7,43,0,WOOL)
B(-7,43,1,WOOL)
B(-7,43,2,WOOL)
B(-7,44,-5,WOOL)
B(-7,44,-4,WOOL)
B(-7,44,-3,WOOL)
B(-7,44,-2,WOOL)
B(-7,44,-1,WOOL)
B(-7,44,0,WOOL)
B(-7,44,1,WOOL)
B(-7,44,2,WOOL)
B(-6,5,-5,WOOL)
B(-6,5,-4,WOOL)
B(-6,5,-3,WOOL)
B(-6,5,-2,WOOL)
B(-6,6,-5,WOOL)
B(-6,6,-4,WOOL)
B(-6,6,-3,WOOL)
B(-6,6,-2,WOOL)
B(-6,7,-5,WOOL)
B(-6,7,-4,WOOL)
B(-6,7,-3,WOOL)
B(-6,7,-2,WOOL)
B(-6,7,-1,WOOL)
B(-6,7,0,WOOL)
B(-6,7,1,WOOL)
B(-6,8,-5,WOOL)
B(-6,8,-4,WOOL)
B(-6,8,-3,WOOL)
B(-6,8,-2,WOOL)
B(-6,8,-1,WOOL)
B(-6,8,0,WOOL)
B(-6,9,-4,WOOL)
B(-6,9,-3,WOOL)
B(-6,9,-2,WOOL)
B(-6,9,-1,WOOL)
B(-6,9,0,WOOL)
B(-6,10,-4,WOOL)
B(-6,10,-3,WOOL)
B(-6,10,-2,WOOL)
B(-6,10,-1,WOOL)
B(-6,10,0,WOOL)
B(-6,11,-5,WOOL)
B(-6,11,-4,WOOL)
B(-6,11,-3,WOOL)
B(-6,11,-2,WOOL)
B(-6,11,-1,WOOL)
B(-6,11,0,WOOL)
B(-6,11,1,WOOL)
B(-6,12,-5,WOOL)
B(-6,12,-4,WOOL)
B(-6,12,-3,WOOL)
B(-6,12,-2,WOOL)
B(-6,12,-1,WOOL)
B(-6,12,0,WOOL)
B(-6,12,1,WOOL)
B(-6,13,-5,WOOL)
B(-6,13,-4,WOOL)
B(-6,13,-3,WOOL)
B(-6,13,-2,WOOL)
B(-6,13,-1,WOOL)
B(-6,13,0,WOOL)
B(-6,13,1,WOOL)
B(-6,14,-5,WOOL)
B(-6,14,-4,WOOL)
B(-6,14,-3,WOOL)
B(-6,14,-2,WOOL)
B(-6,14,-1,WOOL)
B(-6,14,0,WOOL)
B(-6,14,1,WOOL)
B(-6,15,-4,WOOL)
B(-6,15,-3,WOOL)
B(-6,15,-2,WOOL)
B(-6,15,-1,WOOL)
B(-6,15,0,WOOL)
B(-6,15,1,WOOL)
B(-6,16,-4,WOOL)
B(-6,16,-3,WOOL)
B(-6,16,-2,WOOL)
B(-6,16,-1,WOOL)
B(-6,16,0,WOOL)
B(-6,16,1,WOOL)
B(-6,17,-5,WOOL)
B(-6,17,-4,WOOL)
B(-6,17,-3,WOOL)
B(-6,17,-2,WOOL)
B(-6,17,-1,WOOL)
B(-6,17,0,WOOL)
B(-6,17,1,WOOL)
B(-6,17,2,WOOL)
B(-6,18,-4,WOOL)
B(-6,18,-3,WOOL)
B(-6,18,-2,WOOL)
B(-6,18,-1,WOOL)
B(-6,18,0,WOOL)
B(-6,18,1,WOOL)
B(-6,19,-5,WOOL)
B(-6,19,-4,WOOL)
B(-6,19,-3,WOOL)
B(-6,19,-2,WOOL)
B(-6,19,-1,WOOL)
B(-6,19,0,WOOL)
B(-6,19,1,WOOL)
B(-6,19,2,WOOL)
B(-6,20,-5,WOOL)
B(-6,20,-4,WOOL)
B(-6,20,-3,WOOL)
B(-6,20,-2,WOOL)
B(-6,20,-1,WOOL)
B(-6,20,0,WOOL)
B(-6,20,1,WOOL)
B(-6,20,2,WOOL)
B(-6,21,-5,WOOL)
B(-6,21,-4,WOOL)
B(-6,21,-3,WOOL)
B(-6,21,-2,WOOL)
B(-6,21,-1,WOOL)
B(-6,21,0,WOOL)
B(-6,21,1,WOOL)
B(-6,21,2,WOOL)
B(-6,22,-5,WOOL)
B(-6,22,-4,WOOL)
B(-6,22,-3,WOOL)
B(-6,22,-2,WOOL)
B(-6,22,-1,WOOL)
B(-6,22,0,WOOL)
B(-6,22,1,WOOL)
B(-6,22,2,WOOL)
B(-6,23,-4,WOOL)
B(-6,23,-3,WOOL)
B(-6,23,-2,WOOL)
B(-6,23,-1,WOOL)
B(-6,23,0,WOOL)
B(-6,23,1,WOOL)
B(-6,24,-4,WOOL)
B(-6,24,-3,WOOL)
B(-6,24,-2,WOOL)
B(-6,24,-1,WOOL)
B(-6,24,0,WOOL)
B(-6,24,1,WOOL)
B(-6,25,-4,WOOL)
B(-6,25,-3,WOOL)
B(-6,25,-2,WOOL)
B(-6,25,-1,WOOL)
B(-6,25,0,WOOL)
B(-6,25,1,WOOL)
B(-6,26,-4,WOOL)
B(-6,26,-3,WOOL)
B(-6,26,-2,WOOL)
B(-6,26,-1,WOOL)
B(-6,26,0,WOOL)
B(-6,26,1,WOOL)
B(-6,27,-4,WOOL)
B(-6,27,-3,WOOL)
B(-6,27,-2,WOOL)
B(-6,27,-1,WOOL)
B(-6,27,0,WOOL)
B(-6,27,1,WOOL)
B(-6,28,-4,WOOL)
B(-6,28,-3,WOOL)
B(-6,28,-2,WOOL)
B(-6,28,-1,WOOL)
B(-6,28,0,WOOL)
B(-6,28,1,WOOL)
B(-6,29,-4,WOOL)
B(-6,29,-3,WOOL)
B(-6,29,-2,WOOL)
B(-6,29,-1,WOOL)
B(-6,29,0,WOOL)
B(-6,29,1,WOOL)
B(-6,30,-4,WOOL)
B(-6,30,-3,WOOL)
B(-6,30,-2,WOOL)
B(-6,30,-1,WOOL)
B(-6,30,0,WOOL)
B(-6,30,1,WOOL)
B(-6,31,-4,WOOL)
B(-6,31,-3,WOOL)
B(-6,31,-2,WOOL)
B(-6,31,-1,WOOL)
B(-6,31,0,WOOL)
B(-6,31,1,WOOL)
B(-6,32,-4,WOOL)
B(-6,32,-3,WOOL)
B(-6,32,-2,WOOL)
B(-6,32,-1,WOOL)
B(-6,32,0,WOOL)
B(-6,32,1,WOOL)
B(-6,33,-4,WOOL)
B(-6,33,-3,WOOL)
B(-6,33,-2,WOOL)
B(-6,33,-1,WOOL)
B(-6,33,0,WOOL)
B(-6,33,1,WOOL)
B(-6,34,-4,WOOL)
B(-6,34,-3,WOOL)
B(-6,34,-2,WOOL)
B(-6,34,-1,WOOL)
B(-6,34,0,WOOL)
B(-6,34,1,WOOL)
B(-6,35,-5,WOOL)
B(-6,35,-4,WOOL)
B(-6,35,-3,WOOL)
B(-6,35,-2,WOOL)
B(-6,35,-1,WOOL)
B(-6,35,0,WOOL)
B(-6,35,1,WOOL)
B(-6,36,-5,WOOL)
B(-6,36,-4,WOOL)
B(-6,36,-3,WOOL)
B(-6,36,-2,WOOL)
B(-6,36,-1,WOOL)
B(-6,36,0,WOOL)
B(-6,36,1,WOOL)
B(-6,37,-3,WOOL)
B(-6,37,-2,WOOL)
B(-6,37,-1,WOOL)
B(-6,37,0,WOOL)
B(-6,38,-4,WOOL)
B(-6,38,-3,WOOL)
B(-6,38,-2,WOOL)
B(-6,38,-1,WOOL)
B(-6,38,0,WOOL)
B(-6,38,1,WOOL)
B(-6,39,-5,WOOL)
B(-6,39,-4,WOOL)
B(-6,39,-3,WOOL)
B(-6,39,-2,WOOL)
B(-6,39,-1,WOOL)
B(-6,39,0,WOOL)
B(-6,39,1,WOOL)
B(-6,39,2,WOOL)
B(-6,40,-5,WOOL)
B(-6,40,-4,WOOL)
B(-6,40,-3,WOOL)
B(-6,40,-2,WOOL)
B(-6,40,-1,WOOL)
B(-6,40,0,WOOL)
B(-6,40,1,WOOL)
B(-6,40,2,WOOL)
B(-6,41,-5,WOOL)
B(-6,41,-4,WOOL)
B(-6,41,-3,WOOL)
B(-6,41,-2,WOOL)
B(-6,41,-1,WOOL)
B(-6,41,0,WOOL)
B(-6,41,1,WOOL)
B(-6,41,2,WOOL)
B(-6,42,-5,WOOL)
B(-6,42,-4,WOOL)
B(-6,42,-3,WOOL)
B(-6,42,-2,WOOL)
B(-6,42,-1,WOOL)
B(-6,42,0,WOOL)
B(-6,42,1,WOOL)
B(-6,42,2,WOOL)
B(-6,43,-5,WOOL)
B(-6,43,-4,WOOL)
B(-6,43,-3,WOOL)
B(-6,43,-2,WOOL)
B(-6,43,-1,WOOL)
B(-6,43,0,WOOL)
B(-6,43,1,WOOL)
B(-6,43,2,WOOL)
B(-6,44,-5,WOOL)
B(-6,44,-4,WOOL)
B(-6,44,-3,WOOL)
B(-6,44,-2,WOOL)
B(-6,44,-1,WOOL)
B(-6,44,0,WOOL)
B(-6,44,1,WOOL)
B(-5,5,-5,WOOL)
B(-5,5,-4,WOOL)
B(-5,5,-3,WOOL)
B(-5,5,-2,WOOL)
B(-5,6,-5,WOOL)
B(-5,6,-4,WOOL)
B(-5,6,-3,WOOL)
B(-5,6,-2,WOOL)
B(-5,7,-5,WOOL)
B(-5,7,-4,WOOL)
B(-5,7,-3,WOOL)
B(-5,7,-2,WOOL)
B(-5,7,-1,WOOL)
B(-5,7,0,WOOL)
B(-5,7,1,WOOL)
B(-5,8,-5,WOOL)
B(-5,8,-4,WOOL)
B(-5,8,-3,WOOL)
B(-5,8,-2,WOOL)
B(-5,8,-1,WOOL)
B(-5,9,-3,WOOL)
B(-5,9,-2,WOOL)
B(-5,9,-1,WOOL)
B(-5,9,0,WOOL)
B(-5,10,-3,WOOL)
B(-5,10,-2,WOOL)
B(-5,10,-1,WOOL)
B(-5,10,0,WOOL)
B(-5,11,-4,WOOL)
B(-5,11,-3,WOOL)
B(-5,11,-2,WOOL)
B(-5,11,-1,WOOL)
B(-5,11,0,WOOL)
B(-5,11,1,WOOL)
B(-5,12,-4,WOOL)
B(-5,12,-3,WOOL)
B(-5,12,-2,WOOL)
B(-5,12,-1,WOOL)
B(-5,12,0,WOOL)
B(-5,12,1,WOOL)
B(-5,13,-4,WOOL)
B(-5,13,-3,WOOL)
B(-5,13,-2,WOOL)
B(-5,13,-1,WOOL)
B(-5,13,0,WOOL)
B(-5,13,1,WOOL)
B(-5,14,-4,WOOL)
B(-5,14,-3,WOOL)
B(-5,14,-2,WOOL)
B(-5,14,-1,WOOL)
B(-5,14,0,WOOL)
B(-5,14,1,WOOL)
B(-5,15,-4,WOOL)
B(-5,15,-3,WOOL)
B(-5,15,-2,WOOL)
B(-5,15,-1,WOOL)
B(-5,15,0,WOOL)
B(-5,15,1,WOOL)
B(-5,16,-4,WOOL)
B(-5,16,-3,WOOL)
B(-5,16,-2,WOOL)
B(-5,16,-1,WOOL)
B(-5,16,0,WOOL)
B(-5,16,1,WOOL)
B(-5,17,-5,WOOL)
B(-5,17,-4,WOOL)
B(-5,17,-3,WOOL)
B(-5,17,-2,WOOL)
B(-5,17,-1,WOOL)
B(-5,17,0,WOOL)
B(-5,17,1,WOOL)
B(-5,17,2,WOOL)
B(-5,18,-4,WOOL)
B(-5,18,-3,WOOL)
B(-5,18,-2,WOOL)
B(-5,18,-1,WOOL)
B(-5,18,0,WOOL)
B(-5,18,1,WOOL)
B(-5,19,-5,WOOL)
B(-5,19,-4,WOOL)
B(-5,19,-3,WOOL)
B(-5,19,-2,WOOL)
B(-5,19,-1,WOOL)
B(-5,19,0,WOOL)
B(-5,19,1,WOOL)
B(-5,19,2,WOOL)
B(-5,20,-5,WOOL)
B(-5,20,-4,WOOL)
B(-5,20,-3,WOOL)
B(-5,20,-2,WOOL)
B(-5,20,-1,WOOL)
B(-5,20,0,WOOL)
B(-5,20,1,WOOL)
B(-5,20,2,WOOL)
B(-5,21,-5,WOOL)
B(-5,21,-4,WOOL)
B(-5,21,-3,WOOL)
B(-5,21,-2,WOOL)
B(-5,21,-1,WOOL)
B(-5,21,0,WOOL)
B(-5,21,1,WOOL)
B(-5,21,2,WOOL)
B(-5,22,-5,WOOL)
B(-5,22,-4,WOOL)
B(-5,22,-3,WOOL)
B(-5,22,-2,WOOL)
B(-5,22,-1,WOOL)
B(-5,22,0,WOOL)
B(-5,22,1,WOOL)
B(-5,22,2,WOOL)
B(-5,23,-4,WOOL)
B(-5,23,-3,WOOL)
B(-5,23,-2,WOOL)
B(-5,23,-1,WOOL)
B(-5,23,0,WOOL)
B(-5,23,1,WOOL)
B(-5,24,-4,WOOL)
B(-5,24,-3,WOOL)
B(-5,24,-2,WOOL)
B(-5,24,-1,WOOL)
B(-5,24,0,WOOL)
B(-5,24,1,WOOL)
B(-5,25,-4,WOOL)
B(-5,25,-3,WOOL)
B(-5,25,-2,WOOL)
B(-5,25,-1,WOOL)
B(-5,25,0,WOOL)
B(-5,25,1,WOOL)
B(-5,26,-4,WOOL)
B(-5,26,-3,WOOL)
B(-5,26,-2,WOOL)
B(-5,26,-1,WOOL)
B(-5,26,0,WOOL)
B(-5,26,1,WOOL)
B(-5,27,-4,WOOL)
B(-5,27,-3,WOOL)
B(-5,27,-2,WOOL)
B(-5,27,-1,WOOL)
B(-5,27,0,WOOL)
B(-5,27,1,WOOL)
B(-5,28,-4,WOOL)
B(-5,28,-3,WOOL)
B(-5,28,-2,WOOL)
B(-5,28,-1,WOOL)
B(-5,28,0,WOOL)
B(-5,28,1,WOOL)
B(-5,29,-4,WOOL)
B(-5,29,-3,WOOL)
B(-5,29,-2,WOOL)
B(-5,29,-1,WOOL)
B(-5,29,0,WOOL)
B(-5,29,1,WOOL)
B(-5,30,-4,WOOL)
B(-5,30,-3,WOOL)
B(-5,30,-2,WOOL)
B(-5,30,-1,WOOL)
B(-5,30,0,WOOL)
B(-5,30,1,WOOL)
B(-5,31,-4,WOOL)
B(-5,31,-3,WOOL)
B(-5,31,-2,WOOL)
B(-5,31,-1,WOOL)
B(-5,31,0,WOOL)
B(-5,31,1,WOOL)
B(-5,32,-4,WOOL)
B(-5,32,-3,WOOL)
B(-5,32,-2,WOOL)
B(-5,32,-1,WOOL)
B(-5,32,0,WOOL)
B(-5,32,1,WOOL)
B(-5,33,-4,WOOL)
B(-5,33,-3,WOOL)
B(-5,33,-2,WOOL)
B(-5,33,-1,WOOL)
B(-5,33,0,WOOL)
B(-5,33,1,WOOL)
B(-5,34,-4,WOOL)
B(-5,34,-3,WOOL)
B(-5,34,-2,WOOL)
B(-5,34,-1,WOOL)
B(-5,34,0,WOOL)
B(-5,34,1,WOOL)
B(-5,35,-4,WOOL)
B(-5,35,-3,WOOL)
B(-5,35,-2,WOOL)
B(-5,35,-1,WOOL)
B(-5,35,0,WOOL)
B(-5,35,1,WOOL)
B(-5,36,-4,WOOL)
B(-5,36,-3,WOOL)
B(-5,36,-2,WOOL)
B(-5,36,-1,WOOL)
B(-5,36,0,WOOL)
B(-5,36,1,WOOL)
B(-5,37,-3,WOOL)
B(-5,37,-2,WOOL)
B(-5,37,-1,WOOL)
B(-5,37,0,WOOL)
B(-5,38,-4,WOOL)
B(-5,38,-3,WOOL)
B(-5,38,-2,WOOL)
B(-5,38,-1,WOOL)
B(-5,38,0,WOOL)
B(-5,38,1,WOOL)
B(-5,39,-5,WOOL)
B(-5,39,-4,WOOL)
B(-5,39,-3,WOOL)
B(-5,39,-2,WOOL)
B(-5,39,-1,WOOL)
B(-5,39,0,WOOL)
B(-5,39,1,WOOL)
B(-5,39,2,WOOL)
B(-5,40,-5,WOOL)
B(-5,40,-4,WOOL)
B(-5,40,-3,WOOL)
B(-5,40,-2,WOOL)
B(-5,40,-1,WOOL)
B(-5,40,0,WOOL)
B(-5,40,1,WOOL)
B(-5,41,-4,WOOL)
B(-5,41,-3,WOOL)
B(-5,41,-2,WOOL)
B(-5,41,-1,WOOL)
B(-5,41,0,WOOL)
B(-5,41,1,WOOL)
B(-5,42,-4,WOOL)
B(-5,42,-3,WOOL)
B(-5,42,-2,WOOL)
B(-5,42,-1,WOOL)
B(-5,42,0,WOOL)
B(-5,42,1,WOOL)
B(-5,43,-4,WOOL)
B(-5,43,-3,WOOL)
B(-5,43,-2,WOOL)
B(-5,43,-1,WOOL)
B(-5,43,0,WOOL)
B(-5,43,1,WOOL)
B(-5,44,-4,WOOL)
B(-5,44,-3,WOOL)
B(-5,44,-2,WOOL)
B(-5,44,-1,WOOL)
B(-5,44,0,WOOL)
B(-5,44,1,WOOL)
B(-4,5,-3,WOOL)
B(-4,6,-3,WOOL)
B(-4,6,-2,WOOL)
B(-4,7,-4,WOOL)
B(-4,7,-3,WOOL)
B(-4,7,-2,WOOL)
B(-4,7,-1,WOOL)
B(-4,8,-4,WOOL)
B(-4,8,-3,WOOL)
B(-4,8,-2,WOOL)
B(-4,9,-3,WOOL)
B(-4,9,-2,WOOL)
B(-4,9,-1,WOOL)
B(-4,9,0,WOOL)
B(-4,10,-3,WOOL)
B(-4,10,-2,WOOL)
B(-4,10,-1,WOOL)
B(-4,10,0,WOOL)
B(-4,11,-4,WOOL)
B(-4,11,-3,WOOL)
B(-4,11,-2,WOOL)
B(-4,11,-1,WOOL)
B(-4,11,0,WOOL)
B(-4,11,1,WOOL)
B(-4,12,-4,WOOL)
B(-4,12,-3,WOOL)
B(-4,12,-2,WOOL)
B(-4,12,-1,WOOL)
B(-4,12,0,WOOL)
B(-4,12,1,WOOL)
B(-4,13,-4,WOOL)
B(-4,13,-3,WOOL)
B(-4,13,-2,WOOL)
B(-4,13,-1,WOOL)
B(-4,13,0,WOOL)
B(-4,13,1,WOOL)
B(-4,14,-4,WOOL)
B(-4,14,-3,WOOL)
B(-4,14,-2,WOOL)
B(-4,14,-1,WOOL)
B(-4,14,0,WOOL)
B(-4,14,1,WOOL)
B(-4,15,-4,WOOL)
B(-4,15,-3,WOOL)
B(-4,15,-2,WOOL)
B(-4,15,-1,WOOL)
B(-4,15,0,WOOL)
B(-4,15,1,WOOL)
B(-4,16,-4,WOOL)
B(-4,16,-3,WOOL)
B(-4,16,-2,WOOL)
B(-4,16,-1,WOOL)
B(-4,16,0,WOOL)
B(-4,16,1,WOOL)
B(-4,17,-5,WOOL)
B(-4,17,-4,WOOL)
B(-4,17,-3,WOOL)
B(-4,17,-2,WOOL)
B(-4,17,-1,WOOL)
B(-4,17,0,WOOL)
B(-4,17,1,WOOL)
B(-4,18,-4,WOOL)
B(-4,18,-3,WOOL)
B(-4,18,-2,WOOL)
B(-4,18,-1,WOOL)
B(-4,18,0,WOOL)
B(-4,18,1,WOOL)
B(-4,19,-5,WOOL)
B(-4,19,-4,WOOL)
B(-4,19,-3,WOOL)
B(-4,19,-2,WOOL)
B(-4,19,-1,WOOL)
B(-4,19,0,WOOL)
B(-4,19,1,WOOL)
B(-4,19,2,WOOL)
B(-4,20,-5,WOOL)
B(-4,20,-4,WOOL)
B(-4,20,-3,WOOL)
B(-4,20,-2,WOOL)
B(-4,20,-1,WOOL)
B(-4,20,0,WOOL)
B(-4,20,1,WOOL)
B(-4,21,-5,WOOL)
B(-4,21,-4,WOOL)
B(-4,21,-3,WOOL)
B(-4,21,-2,WOOL)
B(-4,21,-1,WOOL)
B(-4,21,0,WOOL)
B(-4,21,1,WOOL)
B(-4,22,-5,WOOL)
B(-4,22,-4,WOOL)
B(-4,22,-3,WOOL)
B(-4,22,-2,WOOL)
B(-4,22,-1,WOOL)
B(-4,22,0,WOOL)
B(-4,22,1,WOOL)
B(-4,23,-4,WOOL)
B(-4,23,-3,WOOL)
B(-4,23,-2,WOOL)
B(-4,23,-1,WOOL)
B(-4,23,0,WOOL)
B(-4,23,1,WOOL)
B(-4,24,-4,WOOL)
B(-4,24,-3,WOOL)
B(-4,24,-2,WOOL)
B(-4,24,-1,WOOL)
B(-4,24,0,WOOL)
B(-4,24,1,WOOL)
B(-4,25,-4,WOOL)
B(-4,25,-3,WOOL)
B(-4,25,-2,WOOL)
B(-4,25,-1,WOOL)
B(-4,25,0,WOOL)
B(-4,25,1,WOOL)
B(-4,26,-4,WOOL)
B(-4,26,-3,WOOL)
B(-4,26,-2,WOOL)
B(-4,26,-1,WOOL)
B(-4,26,0,WOOL)
B(-4,26,1,WOOL)
B(-4,27,-4,WOOL)
B(-4,27,-3,WOOL)
B(-4,27,-2,WOOL)
B(-4,27,-1,WOOL)
B(-4,27,0,WOOL)
B(-4,27,1,WOOL)
B(-4,28,-4,WOOL)
B(-4,28,-3,WOOL)
B(-4,28,-2,WOOL)
B(-4,28,-1,WOOL)
B(-4,28,0,WOOL)
B(-4,28,1,WOOL)
B(-4,29,-4,WOOL)
B(-4,29,-3,WOOL)
B(-4,29,-2,WOOL)
B(-4,29,-1,WOOL)
B(-4,29,0,WOOL)
B(-4,29,1,WOOL)
B(-4,30,-4,WOOL)
B(-4,30,-3,WOOL)
B(-4,30,-2,WOOL)
B(-4,30,-1,WOOL)
B(-4,30,0,WOOL)
B(-4,30,1,WOOL)
B(-4,31,-4,WOOL)
B(-4,31,-3,WOOL)
B(-4,31,-2,WOOL)
B(-4,31,-1,WOOL)
B(-4,31,0,WOOL)
B(-4,31,1,WOOL)
B(-4,32,-4,WOOL)
B(-4,32,-3,WOOL)
B(-4,32,-2,WOOL)
B(-4,32,-1,WOOL)
B(-4,32,0,WOOL)
B(-4,32,1,WOOL)
B(-4,33,-4,WOOL)
B(-4,33,-3,WOOL)
B(-4,33,-2,WOOL)
B(-4,33,-1,WOOL)
B(-4,33,0,WOOL)
B(-4,33,1,WOOL)
B(-4,34,-4,WOOL)
B(-4,34,-3,WOOL)
B(-4,34,-2,WOOL)
B(-4,34,-1,WOOL)
B(-4,34,0,WOOL)
B(-4,34,1,WOOL)
B(-4,35,-4,WOOL)
B(-4,35,-3,WOOL)
B(-4,35,-2,WOOL)
B(-4,35,-1,WOOL)
B(-4,35,0,WOOL)
B(-4,35,1,WOOL)
B(-4,36,-4,WOOL)
B(-4,36,-3,WOOL)
B(-4,36,-2,WOOL)
B(-4,36,-1,WOOL)
B(-4,36,0,WOOL)
B(-4,36,1,WOOL)
B(-4,37,-3,WOOL)
B(-4,37,-2,WOOL)
B(-4,37,-1,WOOL)
B(-4,37,0,WOOL)
B(-4,38,-4,WOOL)
B(-4,38,-3,WOOL)
B(-4,38,-2,WOOL)
B(-4,38,-1,WOOL)
B(-4,38,0,WOOL)
B(-4,38,1,WOOL)
B(-4,39,-5,WOOL)
B(-4,39,-4,WOOL)
B(-4,39,-3,WOOL)
B(-4,39,-2,WOOL)
B(-4,39,-1,WOOL)
B(-4,39,0,WOOL)
B(-4,39,1,WOOL)
B(-4,39,2,WOOL)
B(-4,40,-5,WOOL)
B(-4,40,-4,WOOL)
B(-4,40,-3,WOOL)
B(-4,40,-2,WOOL)
B(-4,40,-1,WOOL)
B(-4,40,0,WOOL)
B(-4,40,1,WOOL)
B(-4,41,-4,WOOL)
B(-4,41,-3,WOOL)
B(-4,41,-2,WOOL)
B(-4,41,-1,WOOL)
B(-4,41,0,WOOL)
B(-4,41,1,WOOL)
B(-4,42,-3,WOOL)
B(-4,42,-2,WOOL)
B(-4,42,-1,WOOL)
B(-4,43,-3,WOOL)
B(-4,43,-2,WOOL)
B(-4,43,-1,WOOL)
B(-4,44,-2,WOOL)
B(-4,44,-1,WOOL)
B(-3,7,-2,WOOL)
B(-3,8,-3,WOOL)
B(-3,8,-2,WOOL)
B(-3,9,-3,WOOL)
B(-3,9,-2,WOOL)
B(-3,9,-1,WOOL)
B(-3,9,0,WOOL)
B(-3,10,-3,WOOL)
B(-3,10,-2,WOOL)
B(-3,10,-1,WOOL)
B(-3,10,0,WOOL)
B(-3,11,-3,WOOL)
B(-3,11,-2,WOOL)
B(-3,11,-1,WOOL)
B(-3,11,0,WOOL)
B(-3,12,-3,WOOL)
B(-3,12,-2,WOOL)
B(-3,12,-1,WOOL)
B(-3,12,0,WOOL)
B(-3,13,-4,WOOL)
B(-3,13,-3,WOOL)
B(-3,13,-2,WOOL)
B(-3,13,-1,WOOL)
B(-3,13,0,WOOL)
B(-3,14,-4,WOOL)
B(-3,14,-3,WOOL)
B(-3,14,-2,WOOL)
B(-3,14,-1,WOOL)
B(-3,14,0,WOOL)
B(-3,15,-3,WOOL)
B(-3,15,-2,WOOL)
B(-3,15,-1,WOOL)
B(-3,15,0,WOOL)
B(-3,16,-3,WOOL)
B(-3,16,-2,WOOL)
B(-3,16,-1,WOOL)
B(-3,16,0,WOOL)
B(-3,17,-4,WOOL)
B(-3,17,-3,WOOL)
B(-3,17,-2,WOOL)
B(-3,17,-1,WOOL)
B(-3,17,0,WOOL)
B(-3,17,1,WOOL)
B(-3,18,-3,WOOL)
B(-3,18,-2,WOOL)
B(-3,18,-1,WOOL)
B(-3,18,0,WOOL)
B(-3,19,-4,WOOL)
B(-3,19,-3,WOOL)
B(-3,19,-2,WOOL)
B(-3,19,-1,WOOL)
B(-3,19,0,WOOL)
B(-3,19,1,WOOL)
B(-3,20,-4,WOOL)
B(-3,20,-3,WOOL)
B(-3,20,-2,WOOL)
B(-3,20,-1,WOOL)
B(-3,20,0,WOOL)
B(-3,20,1,WOOL)
B(-3,21,-4,WOOL)
B(-3,21,-3,WOOL)
B(-3,21,-2,WOOL)
B(-3,21,-1,WOOL)
B(-3,21,0,WOOL)
B(-3,21,1,WOOL)
B(-3,22,-4,WOOL)
B(-3,22,-3,WOOL)
B(-3,22,-2,WOOL)
B(-3,22,-1,WOOL)
B(-3,22,0,WOOL)
B(-3,22,1,WOOL)
B(-3,23,-3,WOOL)
B(-3,23,-2,WOOL)
B(-3,23,-1,WOOL)
B(-3,23,0,WOOL)
B(-3,24,-3,WOOL)
B(-3,24,-2,WOOL)
B(-3,24,-1,WOOL)
B(-3,24,0,WOOL)
B(-3,25,-3,WOOL)
B(-3,25,-2,WOOL)
B(-3,25,-1,WOOL)
B(-3,25,0,WOOL)
B(-3,26,-3,WOOL)
B(-3,26,-2,WOOL)
B(-3,26,-1,WOOL)
B(-3,26,0,WOOL)
B(-3,27,-3,WOOL)
B(-3,27,-2,WOOL)
B(-3,27,-1,WOOL)
B(-3,27,0,WOOL)
B(-3,28,-3,WOOL)
B(-3,28,-2,WOOL)
B(-3,28,-1,WOOL)
B(-3,28,0,WOOL)
B(-3,29,-3,WOOL)
B(-3,29,-2,WOOL)
B(-3,29,-1,WOOL)
B(-3,29,0,WOOL)
B(-3,30,-3,WOOL)
B(-3,30,-2,WOOL)
B(-3,30,-1,WOOL)
B(-3,30,0,WOOL)
B(-3,31,-3,WOOL)
B(-3,31,-2,WOOL)
B(-3,31,-1,WOOL)
B(-3,31,0,WOOL)
B(-3,32,-3,WOOL)
B(-3,32,-2,WOOL)
B(-3,32,-1,WOOL)
B(-3,32,0,WOOL)
B(-3,33,-3,WOOL)
B(-3,33,-2,WOOL)
B(-3,33,-1,WOOL)
B(-3,33,0,WOOL)
B(-3,34,-3,WOOL)
B(-3,34,-2,WOOL)
B(-3,34,-1,WOOL)
B(-3,34,0,WOOL)
B(-3,35,-4,WOOL)
B(-3,35,-3,WOOL)
B(-3,35,-2,WOOL)
B(-3,35,-1,WOOL)
B(-3,35,0,WOOL)
B(-3,36,-4,WOOL)
B(-3,36,-3,WOOL)
B(-3,36,-2,WOOL)
B(-3,36,-1,WOOL)
B(-3,36,0,WOOL)
B(-3,37,-2,WOOL)
B(-3,37,-1,WOOL)
B(-3,38,-3,WOOL)
B(-3,38,-2,WOOL)
B(-3,38,-1,WOOL)
B(-3,38,0,WOOL)
B(-3,39,-4,WOOL)
B(-3,39,-3,WOOL)
B(-3,39,-2,WOOL)
B(-3,39,-1,WOOL)
B(-3,39,0,WOOL)
B(-3,39,1,WOOL)
B(-3,40,-4,WOOL)
B(-3,40,-3,WOOL)
B(-3,40,-2,WOOL)
B(-3,40,-1,WOOL)
B(-3,40,0,WOOL)
B(-3,40,1,WOOL)
B(-3,41,-4,WOOL)
B(-3,41,-3,WOOL)
B(-3,41,-2,WOOL)
B(-3,41,-1,WOOL)
B(-3,41,0,WOOL)
B(-3,41,1,WOOL)
B(-2,11,-2,WOOL)
B(-2,11,-1,WOOL)
B(-2,12,-2,WOOL)
B(-2,12,-1,WOOL)
B(-2,13,-3,WOOL)
B(-2,13,-2,WOOL)
B(-2,13,-1,WOOL)
B(-2,13,0,WOOL)
B(-2,14,-3,WOOL)
B(-2,14,-2,WOOL)
B(-2,14,-1,WOOL)
B(-2,14,0,WOOL)
B(-2,15,-3,WOOL)
B(-2,15,-2,WOOL)
B(-2,15,-1,WOOL)
B(-2,15,0,WOOL)
B(-2,16,-3,WOOL)
B(-2,16,-2,WOOL)
B(-2,16,-1,WOOL)
B(-2,16,0,WOOL)
B(-2,17,-3,WOOL)
B(-2,17,-2,WOOL)
B(-2,17,-1,WOOL)
B(-2,17,0,WOOL)
B(-2,18,-2,WOOL)
B(-2,18,-1,WOOL)
B(-2,18,0,WOOL)
B(-2,19,-3,WOOL)
B(-2,19,-2,WOOL)
B(-2,19,-1,WOOL)
B(-2,19,0,WOOL)
B(-2,19,1,WOOL)
B(-2,20,-3,WOOL)
B(-2,20,-2,WOOL)
B(-2,20,-1,WOOL)
B(-2,20,0,WOOL)
B(-2,20,1,WOOL)
B(-2,21,-3,WOOL)
B(-2,21,-2,WOOL)
B(-2,21,-1,WOOL)
B(-2,21,0,WOOL)
B(-2,21,1,WOOL)
B(-2,22,-3,WOOL)
B(-2,22,-2,WOOL)
B(-2,22,-1,WOOL)
B(-2,22,0,WOOL)
B(-2,22,1,WOOL)
B(-2,23,-3,WOOL)
B(-2,23,-2,WOOL)
B(-2,23,-1,WOOL)
B(-2,23,0,WOOL)
B(-2,24,-3,WOOL)
B(-2,24,-2,WOOL)
B(-2,24,-1,WOOL)
B(-2,24,0,WOOL)
B(-2,25,-3,WOOL)
B(-2,25,-2,WOOL)
B(-2,25,-1,WOOL)
B(-2,25,0,WOOL)
B(-2,26,-3,WOOL)
B(-2,26,-2,WOOL)
B(-2,26,-1,WOOL)
B(-2,26,0,WOOL)
B(-2,27,-3,WOOL)
B(-2,27,-2,WOOL)
B(-2,27,-1,WOOL)
B(-2,27,0,WOOL)
B(-2,28,-3,WOOL)
B(-2,28,-2,WOOL)
B(-2,28,-1,WOOL)
B(-2,28,0,WOOL)
B(-2,29,-3,WOOL)
B(-2,29,-2,WOOL)
B(-2,29,-1,WOOL)
B(-2,29,0,WOOL)
B(-2,30,-3,WOOL)
B(-2,30,-2,WOOL)
B(-2,30,-1,WOOL)
B(-2,30,0,WOOL)
B(-2,31,-3,WOOL)
B(-2,31,-2,WOOL)
B(-2,31,-1,WOOL)
B(-2,31,0,WOOL)
B(-2,32,-3,WOOL)
B(-2,32,-2,WOOL)
B(-2,32,-1,WOOL)
B(-2,32,0,WOOL)
B(-2,33,-3,WOOL)
B(-2,33,-2,WOOL)
B(-2,33,-1,WOOL)
B(-2,33,0,WOOL)
B(-2,34,-2,WOOL)
B(-2,34,-1,WOOL)
B(-2,34,0,WOOL)
B(-2,35,-3,WOOL)
B(-2,35,-2,WOOL)
B(-2,35,-1,WOOL)
B(-2,35,0,WOOL)
B(-2,36,-3,WOOL)
B(-2,36,-2,WOOL)
B(-2,36,-1,WOOL)
B(-2,36,0,WOOL)
B(-2,37,-2,WOOL)
B(-2,37,-1,WOOL)
B(-2,37,0,WOOL)
B(-2,38,-2,WOOL)
B(-2,38,-1,WOOL)
B(-2,38,0,WOOL)
B(-2,39,-3,WOOL)
B(-2,39,-2,WOOL)
B(-2,39,-1,WOOL)
B(-2,39,0,WOOL)
B(-2,40,-3,WOOL)
B(-2,40,-2,WOOL)
B(-2,40,-1,WOOL)
B(-2,40,0,WOOL)
B(-2,41,-3,WOOL)
B(-2,41,-2,WOOL)
B(-2,41,-1,WOOL)
B(-2,41,0,WOOL)
B(-1,13,-2,WOOL)
B(-1,13,-1,WOOL)
B(-1,13,0,WOOL)
B(-1,14,-2,WOOL)
B(-1,14,-1,WOOL)
B(-1,14,0,WOOL)
B(-1,15,-2,WOOL)
B(-1,15,-1,WOOL)
B(-1,15,0,WOOL)
B(-1,16,-2,WOOL)
B(-1,16,-1,WOOL)
B(-1,16,0,WOOL)
B(-1,17,-3,WOOL)
B(-1,17,-2,WOOL)
B(-1,17,-1,WOOL)
B(-1,17,0,WOOL)
B(-1,18,-2,WOOL)
B(-1,18,-1,WOOL)
B(-1,18,0,WOOL)
B(-1,19,-3,WOOL)
B(-1,19,-2,WOOL)
B(-1,19,-1,WOOL)
B(-1,19,0,WOOL)
B(-1,19,1,WOOL)
B(-1,20,-3,WOOL)
B(-1,20,-2,WOOL)
B(-1,20,-1,WOOL)
B(-1,20,0,WOOL)
B(-1,20,1,WOOL)
B(-1,21,-3,WOOL)
B(-1,21,-2,WOOL)
B(-1,21,-1,WOOL)
B(-1,21,0,WOOL)
B(-1,21,1,WOOL)
B(-1,22,-3,WOOL)
B(-1,22,-2,WOOL)
B(-1,22,-1,WOOL)
B(-1,22,0,WOOL)
B(-1,22,1,WOOL)
B(-1,23,-2,WOOL)
B(-1,23,-1,WOOL)
B(-1,23,0,WOOL)
B(-1,24,-2,WOOL)
B(-1,24,-1,WOOL)
B(-1,24,0,WOOL)
B(-1,25,-2,WOOL)
B(-1,25,-1,WOOL)
B(-1,25,0,WOOL)
B(-1,26,-2,WOOL)
B(-1,26,-1,WOOL)
B(-1,26,0,WOOL)
B(-1,27,-2,WOOL)
B(-1,27,-1,WOOL)
B(-1,27,0,WOOL)
B(-1,28,-2,WOOL)
B(-1,28,-1,WOOL)
B(-1,28,0,WOOL)
B(-1,29,-2,WOOL)
B(-1,29,-1,WOOL)
B(-1,29,0,WOOL)
B(-1,30,-2,WOOL)
B(-1,30,-1,WOOL)
B(-1,30,0,WOOL)
B(-1,31,-2,WOOL)
B(-1,31,-1,WOOL)
B(-1,31,0,WOOL)
B(-1,32,-2,WOOL)
B(-1,32,-1,WOOL)
B(-1,32,0,WOOL)
B(-1,33,-2,WOOL)
B(-1,33,-1,WOOL)
B(-1,33,0,WOOL)
B(-1,34,-2,WOOL)
B(-1,34,-1,WOOL)
B(-1,34,0,WOOL)
B(-1,35,-2,WOOL)
B(-1,35,-1,WOOL)
B(-1,35,0,WOOL)
B(-1,36,-2,WOOL)
B(-1,36,-1,WOOL)
B(-1,36,0,WOOL)
B(-1,37,-1,WOOL)
B(0,14,-2,WOOL)
B(0,14,-1,WOOL)
B(0,14,0,WOOL)
B(0,15,-2,WOOL)
B(0,15,-1,WOOL)
B(0,15,0,WOOL)
B(0,16,-2,WOOL)
B(0,16,-1,WOOL)
B(0,16,0,WOOL)
B(0,17,-2,WOOL)
B(0,17,-1,WOOL)
B(0,17,0,WOOL)
B(0,18,-2,WOOL)
B(0,18,-1,WOOL)
B(0,18,0,WOOL)
B(0,19,-2,WOOL)
B(0,19,-1,WOOL)
B(0,19,0,WOOL)
B(0,19,1,WOOL)
B(0,20,-2,WOOL)
B(0,20,-1,WOOL)
B(0,20,0,WOOL)
B(0,20,1,WOOL)
B(0,21,-2,WOOL)
B(0,21,-1,WOOL)
B(0,21,0,WOOL)
B(0,21,1,WOOL)
B(0,22,-2,WOOL)
B(0,22,-1,WOOL)
B(0,22,0,WOOL)
B(0,22,1,WOOL)
B(0,23,-2,WOOL)
B(0,23,-1,WOOL)
B(0,23,0,WOOL)
B(0,24,-2,WOOL)
B(0,24,-1,WOOL)
B(0,24,0,WOOL)
B(0,25,-2,WOOL)
B(0,25,-1,WOOL)
B(0,25,0,WOOL)
B(0,26,-2,WOOL)
B(0,26,-1,WOOL)
B(0,26,0,WOOL)
B(0,27,-2,WOOL)
B(0,27,-1,WOOL)
B(0,27,0,WOOL)
B(0,28,-2,WOOL)
B(0,28,-1,WOOL)
B(0,28,0,WOOL)
B(0,29,-2,WOOL)
B(0,29,-1,WOOL)
B(0,29,0,WOOL)
B(0,30,-2,WOOL)
B(0,30,-1,WOOL)
B(0,30,0,WOOL)
B(0,31,-2,WOOL)
B(0,31,-1,WOOL)
B(0,31,0,WOOL)
B(0,32,-2,WOOL)
B(0,32,-1,WOOL)
B(0,32,0,WOOL)
B(0,33,-2,WOOL)
B(0,33,-1,WOOL)
B(0,33,0,WOOL)
B(0,34,-2,WOOL)
B(0,34,-1,WOOL)
B(0,34,0,WOOL)
B(0,35,-2,WOOL)
B(0,35,-1,WOOL)
B(0,35,0,WOOL)
B(0,36,-2,WOOL)
B(0,36,-1,WOOL)
B(0,36,0,WOOL)
B(1,16,-1,WOOL)
B(1,16,0,WOOL)
B(1,17,-1,WOOL)
B(1,17,0,WOOL)
B(1,18,-1,WOOL)
B(1,18,0,WOOL)
B(1,19,-2,WOOL)
B(1,19,-1,WOOL)
B(1,19,0,WOOL)
B(1,19,1,WOOL)
B(1,20,-2,WOOL)
B(1,20,-1,WOOL)
B(1,20,0,WOOL)
B(1,20,1,WOOL)
B(1,21,-2,WOOL)
B(1,21,-1,WOOL)
B(1,21,0,WOOL)
B(1,21,1,WOOL)
B(1,22,-2,WOOL)
B(1,22,-1,WOOL)
B(1,22,0,WOOL)
B(1,22,1,WOOL)
B(1,23,-1,WOOL)
B(1,23,0,WOOL)
B(1,24,-1,WOOL)
B(1,24,0,WOOL)
B(1,24,1,WOOL)
B(1,25,-1,WOOL)
B(1,25,0,WOOL)
B(1,25,1,WOOL)
B(1,26,-1,WOOL)
B(1,26,0,WOOL)
B(1,26,1,WOOL)
B(1,27,-1,WOOL)
B(1,27,0,WOOL)
B(1,28,-1,WOOL)
B(1,28,0,WOOL)
B(1,29,-1,WOOL)
B(1,29,0,WOOL)
B(1,30,-1,WOOL)
B(1,30,0,WOOL)
B(1,31,-1,WOOL)
B(1,31,0,WOOL)
B(1,32,-1,WOOL)
B(1,32,0,WOOL)
B(1,33,-1,WOOL)
B(1,33,0,WOOL)
B(1,34,-1,WOOL)
B(1,34,0,WOOL)
B(1,35,-1,WOOL)
B(1,35,0,WOOL)
B(1,35,1,WOOL)
B(2,19,-1,WOOL)
B(2,19,0,WOOL)
B(2,20,-1,WOOL)
B(2,20,0,WOOL)
B(2,21,-1,WOOL)
B(2,21,0,WOOL)
B(2,22,-1,WOOL)
B(2,22,0,WOOL)
B(2,23,-1,WOOL)
B(2,23,0,WOOL)
B(2,24,-1,WOOL)
B(2,24,0,WOOL)
B(2,25,-1,WOOL)
B(2,25,0,WOOL)
B(2,26,-1,WOOL)
B(2,26,0,WOOL)
B(2,27,-1,WOOL)
B(2,27,0,WOOL)
B(2,28,-1,WOOL)
B(2,28,0,WOOL)
B(2,29,0,WOOL)
B(2,35,-1,WOOL)
B(2,35,0,WOOL)

#######################################################################
# +-----------------------------------------------------------------+ #
# |                            BO3 checks                           | #
# +-----------------------------------------------------------------+ #
#######################################################################


#######################################################################
# +-----------------------------------------------------------------+ #
# |                             Branches                            | #
# +-----------------------------------------------------------------+ #
#######################################################################


#######################################################################
# +-----------------------------------------------------------------+ #
# |                         EntityFunctions                         | #
# +-----------------------------------------------------------------+ #
#######################################################################

