#######################################################################
# +-----------------------------------------------------------------+ #
# |                            BO3 object                           | #
# +-----------------------------------------------------------------+ #
#######################################################################

# The descriptions in this file are true only for TerrainControl. They are not true for the Minecraft Worlds mod!
# Minecraft Worlds completely reimplemented BO3s, check the MCW documentation on the mc/mctcp forums for how to use BO3s with MCW
# or watch the video's on my YT channel at https://www.youtube.com/user/PeeGee85. You can check out the "Editing and importing schematics & BO3s" 
# series of video's, in part 2 I explain BO3s. 

# This is the config file of a custom object.
# If you add this object correctly to your BiomeConfigs, it will spawn in the world.

# This is the creator of this BO3 object
Author: Unknown

# A short description of this BO3 object
Description: This BO3 was converted from a schematic using the MineCraft Worlds Editor. Unfortunately the author and description information for the schematic could not be found. If you know who the author of the schematic is then please tell the author of this BO3!

# The BO3 version, don't change this! It can be used by external applications to do a version check.
Version: 3

# The settings mode, WriteAll, WriteWithoutComments or WriteDisable. See WorldConfig.
SettingsMode: WriteDisable

#######################################################################
# +-----------------------------------------------------------------+ #
# |                          Main settings                          | #
# +-----------------------------------------------------------------+ #
#######################################################################

# This needs to be set to true to spawn the object in the Tree and Sapling resources.
Tree: false

# The frequency of the BO3 from 1 to 200. Tries this many times to spawn this BO3 when using the CustomObject(...) resource.
# Ignored by Tree(..), Sapling(..) and CustomStructure(..)
Frequency: 40

# The rarity of the BO3 from 0 to 100. Each spawn attempt has rarity% chance to succeed when using the CustomObject(...) resource.
# Ignored by Tree(..), Sapling(..) and CustomStructure(..)
Rarity: 100.0

# If you set this to true, the BO3 will be placed with a random rotation.
RotateRandomly: false

# The spawn height of the BO3 - randomY, highestBlock or highestSolidBlock.
SpawnHeight: randomY

# The height limits for the BO3.
MinHeight: 41

MaxHeight: 53

# Objects can have other objects attached to it: branches. Branches can also
# have branches attached to it, which can also have branches, etc. This is the
# maximum branch depth for this objects.
MaxBranchDepth: 10

# When spawned with the UseWorld keyword, this BO3 should NOT spawn in the following biomes.
# If you writer.write the BO3 name directly in the BiomeConfigs, this will be ignored.
ExcludedBiomes: All

#######################################################################
# +-----------------------------------------------------------------+ #
# |                      Source block settings                      | #
# +-----------------------------------------------------------------+ #
#######################################################################

# The B(s) the BO3 should spawn in.
SourceBlocks: AIR,STATIONARY_WATER

# The maximum percentage of the BO3 that can be outside the SourceBlock.
# The BO3 won't be placed on a location with more blocks outside the SourceBlock than this percentage.
MaxPercentageOutsideSourceBlock: 100

# What to do when a block is about to be placed outside the SourceBlock? (dontPlace, placeAnyway)
OutsideSourceBlock: placeAnyway

#######################################################################
# +-----------------------------------------------------------------+ #
# |                              Blocks                             | #
# +-----------------------------------------------------------------+ #
#######################################################################

# All the blocks used in the BO3 are listed here. Possible blocks:
# B(x,y,z,id[.data][,nbtfile.nbt)
# RB(x,y,z,id[:data][,nbtfile.nbt],chance[,id[:data][,nbtfile.nbt],chance[,...]])
# So RB(0,0,0,CHEST,chest.nbt,50,CHEST,anotherchest.nbt,100) will spawn a chest at
# the BO3 origin, and give it a 50% chance to have the contents of chest.nbt, or, if that
# fails, a 100% percent chance to have the contents of anotherchest.nbt.

B(-7,19,8,1)
B(-7,20,7,1)
B(-7,20,8,1)
B(-7,21,5,1)
B(-7,21,6,1)
B(-7,21,7,1)
B(-7,21,8,1)
B(-7,22,4,1)
B(-7,22,5,1)
B(-7,22,6,1)
B(-7,23,5,1)
B(-7,23,6,1)
B(-6,16,7,1)
B(-6,16,8,1)
B(-6,17,6,1)
B(-6,17,7,1)
B(-6,17,8,1)
B(-6,18,6,1)
B(-6,18,7,1)
B(-6,18,8,1)
B(-6,19,4,1)
B(-6,19,5,1)
B(-6,19,6,1)
B(-6,19,7,1)
B(-6,19,8,1)
B(-6,20,3,1)
B(-6,20,4,1)
B(-6,20,5,1)
B(-6,20,6,1)
B(-6,20,7,1)
B(-6,20,8,1)
B(-6,21,3,1)
B(-6,21,4,1)
B(-6,21,5,1)
B(-6,21,6,1)
B(-6,21,7,1)
B(-6,21,8,1)
B(-6,22,3,1)
B(-6,22,4,1)
B(-6,22,5,1)
B(-6,22,6,1)
B(-6,22,7,1)
B(-6,22,8,1)
B(-6,23,3,1)
B(-6,23,4,1)
B(-6,23,5,1)
B(-6,23,6,1)
B(-6,23,7,1)
B(-6,23,8,1)
B(-6,24,4,1)
B(-6,24,5,1)
B(-6,24,6,1)
B(-6,24,7,1)
B(-6,25,5,1)
B(-6,25,6,1)
B(-6,25,7,1)
B(-6,26,5,1)
B(-6,26,6,1)
B(-5,12,7,1)
B(-5,12,8,1)
B(-5,13,7,1)
B(-5,13,8,1)
B(-5,14,6,1)
B(-5,14,7,1)
B(-5,14,8,1)
B(-5,15,4,1)
B(-5,15,6,1)
B(-5,15,7,1)
B(-5,15,8,1)
B(-5,16,4,1)
B(-5,16,5,1)
B(-5,16,6,1)
B(-5,16,7,1)
B(-5,16,8,1)
B(-5,17,4,1)
B(-5,17,5,1)
B(-5,17,6,1)
B(-5,17,7,1)
B(-5,17,8,1)
B(-5,18,3,1)
B(-5,18,4,1)
B(-5,18,5,1)
B(-5,18,6,1)
B(-5,18,7,1)
B(-5,18,8,1)
B(-5,19,3,1)
B(-5,19,4,1)
B(-5,19,5,1)
B(-5,19,6,1)
B(-5,19,7,1)
B(-5,19,8,1)
B(-5,20,2,1)
B(-5,20,3,1)
B(-5,20,4,1)
B(-5,20,5,1)
B(-5,20,6,1)
B(-5,20,7,1)
B(-5,20,8,1)
B(-5,21,1,1)
B(-5,21,2,1)
B(-5,21,3,1)
B(-5,21,4,1)
B(-5,21,5,1)
B(-5,21,6,1)
B(-5,21,7,1)
B(-5,21,8,1)
B(-5,22,1,1)
B(-5,22,2,1)
B(-5,22,3,1)
B(-5,22,4,1)
B(-5,22,5,1)
B(-5,22,6,1)
B(-5,22,7,1)
B(-5,22,8,1)
B(-5,23,2,1)
B(-5,23,3,1)
B(-5,23,4,1)
B(-5,23,5,1)
B(-5,23,6,1)
B(-5,23,7,1)
B(-5,23,8,1)
B(-5,24,3,1)
B(-5,24,4,1)
B(-5,24,5,1)
B(-5,24,6,1)
B(-5,24,7,1)
B(-5,24,8,1)
B(-5,25,4,1)
B(-5,25,5,1)
B(-5,25,6,1)
B(-5,25,7,1)
B(-5,25,8,1)
B(-5,26,5,1)
B(-5,26,6,1)
B(-5,26,7,1)
B(-5,27,5,1)
B(-5,27,6,1)
B(-5,27,7,1)
B(-5,28,6,1)
B(-5,28,7,1)
B(-4,7,8,1)
B(-4,8,7,1)
B(-4,8,8,1)
B(-4,9,7,1)
B(-4,9,8,1)
B(-4,10,7,1)
B(-4,10,8,1)
B(-4,11,6,1)
B(-4,11,7,1)
B(-4,11,8,1)
B(-4,12,4,1)
B(-4,12,6,1)
B(-4,12,7,1)
B(-4,12,8,1)
B(-4,13,4,1)
B(-4,13,5,1)
B(-4,13,6,1)
B(-4,13,7,1)
B(-4,13,8,1)
B(-4,14,4,1)
B(-4,14,5,1)
B(-4,14,6,1)
B(-4,14,7,1)
B(-4,14,8,1)
B(-4,15,4,1)
B(-4,15,5,1)
B(-4,15,6,1)
B(-4,15,7,1)
B(-4,15,8,1)
B(-4,16,3,1)
B(-4,16,4,1)
B(-4,16,5,1)
B(-4,16,6,1)
B(-4,16,7,1)
B(-4,16,8,1)
B(-4,17,1,1)
B(-4,17,2,1)
B(-4,17,3,1)
B(-4,17,4,1)
B(-4,17,5,1)
B(-4,17,6,1)
B(-4,17,7,1)
B(-4,17,8,1)
B(-4,18,0,1)
B(-4,18,1,1)
B(-4,18,2,1)
B(-4,18,3,1)
B(-4,18,4,1)
B(-4,18,5,1)
B(-4,18,6,1)
B(-4,18,7,1)
B(-4,18,8,1)
B(-4,19,0,1)
B(-4,19,1,1)
B(-4,19,2,1)
B(-4,19,3,1)
B(-4,19,4,1)
B(-4,19,5,1)
B(-4,19,6,1)
B(-4,19,7,1)
B(-4,19,8,1)
B(-4,20,0,1)
B(-4,20,1,1)
B(-4,20,2,1)
B(-4,20,3,1)
B(-4,20,4,1)
B(-4,20,5,1)
B(-4,20,6,1)
B(-4,20,7,1)
B(-4,20,8,1)
B(-4,21,0,1)
B(-4,21,1,1)
B(-4,21,2,1)
B(-4,21,3,1)
B(-4,21,4,1)
B(-4,21,5,1)
B(-4,21,6,1)
B(-4,21,7,1)
B(-4,21,8,1)
B(-4,22,-1,1)
B(-4,22,0,1)
B(-4,22,1,1)
B(-4,22,2,1)
B(-4,22,3,1)
B(-4,22,4,1)
B(-4,22,5,1)
B(-4,22,6,1)
B(-4,22,7,1)
B(-4,22,8,1)
B(-4,23,0,1)
B(-4,23,1,1)
B(-4,23,2,1)
B(-4,23,3,1)
B(-4,23,4,1)
B(-4,23,5,1)
B(-4,23,6,1)
B(-4,23,7,1)
B(-4,23,8,1)
B(-4,24,1,1)
B(-4,24,2,1)
B(-4,24,3,1)
B(-4,24,4,1)
B(-4,24,5,1)
B(-4,24,6,1)
B(-4,24,7,1)
B(-4,24,8,1)
B(-4,25,3,1)
B(-4,25,4,1)
B(-4,25,5,1)
B(-4,25,6,1)
B(-4,25,7,1)
B(-4,25,8,1)
B(-4,26,3,1)
B(-4,26,4,1)
B(-4,26,5,1)
B(-4,26,6,1)
B(-4,26,7,1)
B(-4,26,8,1)
B(-4,27,3,1)
B(-4,27,4,1)
B(-4,27,5,1)
B(-4,27,6,1)
B(-4,27,7,1)
B(-4,27,8,1)
B(-4,28,5,1)
B(-4,28,6,1)
B(-4,28,7,1)
B(-4,28,8,1)
B(-4,29,5,1)
B(-4,29,6,1)
B(-4,29,7,1)
B(-4,30,6,1)
B(-4,30,7,1)
B(-3,6,8,1)
B(-3,7,7,1)
B(-3,7,8,1)
B(-3,8,7,1)
B(-3,8,8,1)
B(-3,9,7,1)
B(-3,9,8,1)
B(-3,10,6,1)
B(-3,10,7,1)
B(-3,10,8,1)
B(-3,11,5,1)
B(-3,11,6,1)
B(-3,11,7,1)
B(-3,11,8,1)
B(-3,12,2,1)
B(-3,12,5,1)
B(-3,12,6,1)
B(-3,12,7,1)
B(-3,12,8,1)
B(-3,13,1,1)
B(-3,13,2,1)
B(-3,13,4,1)
B(-3,13,5,1)
B(-3,13,6,1)
B(-3,13,7,1)
B(-3,13,8,1)
B(-3,14,1,1)
B(-3,14,2,1)
B(-3,14,3,1)
B(-3,14,4,1)
B(-3,14,5,1)
B(-3,14,6,1)
B(-3,14,7,1)
B(-3,14,8,1)
B(-3,15,1,1)
B(-3,15,2,1)
B(-3,15,3,1)
B(-3,15,4,1)
B(-3,15,5,1)
B(-3,15,6,1)
B(-3,15,7,1)
B(-3,15,8,1)
B(-3,16,1,1)
B(-3,16,2,1)
B(-3,16,3,1)
B(-3,16,4,1)
B(-3,16,5,1)
B(-3,16,6,1)
B(-3,16,7,1)
B(-3,16,8,1)
B(-3,17,1,1)
B(-3,17,2,1)
B(-3,17,3,1)
B(-3,17,4,1)
B(-3,17,5,1)
B(-3,17,6,1)
B(-3,17,7,1)
B(-3,17,8,1)
B(-3,18,1,1)
B(-3,18,2,1)
B(-3,18,3,1)
B(-3,18,4,1)
B(-3,18,5,1)
B(-3,18,6,1)
B(-3,18,7,1)
B(-3,18,8,1)
B(-3,19,0,1)
B(-3,19,1,1)
B(-3,19,2,1)
B(-3,19,3,1)
B(-3,19,4,1)
B(-3,19,5,1)
B(-3,19,6,1)
B(-3,19,7,1)
B(-3,19,8,1)
B(-3,20,-1,1)
B(-3,20,0,1)
B(-3,20,1,1)
B(-3,20,2,1)
B(-3,20,3,1)
B(-3,20,4,1)
B(-3,20,5,1)
B(-3,20,6,1)
B(-3,20,7,1)
B(-3,20,8,1)
B(-3,21,-1,1)
B(-3,21,0,1)
B(-3,21,1,1)
B(-3,21,2,1)
B(-3,21,3,1)
B(-3,21,4,1)
B(-3,21,5,1)
B(-3,21,6,1)
B(-3,21,7,1)
B(-3,21,8,1)
B(-3,22,-1,1)
B(-3,22,0,1)
B(-3,22,1,1)
B(-3,22,2,1)
B(-3,22,3,1)
B(-3,22,4,1)
B(-3,22,5,1)
B(-3,22,6,1)
B(-3,22,7,1)
B(-3,22,8,1)
B(-3,23,-1,1)
B(-3,23,0,1)
B(-3,23,1,1)
B(-3,23,2,1)
B(-3,23,3,1)
B(-3,23,4,1)
B(-3,23,5,1)
B(-3,23,6,1)
B(-3,23,7,1)
B(-3,23,8,1)
B(-3,24,0,1)
B(-3,24,1,1)
B(-3,24,2,1)
B(-3,24,3,1)
B(-3,24,4,1)
B(-3,24,5,1)
B(-3,24,6,1)
B(-3,24,7,1)
B(-3,24,8,1)
B(-3,25,1,1)
B(-3,25,2,1)
B(-3,25,3,1)
B(-3,25,4,1)
B(-3,25,5,1)
B(-3,25,6,1)
B(-3,25,7,1)
B(-3,25,8,1)
B(-3,26,2,1)
B(-3,26,3,1)
B(-3,26,4,1)
B(-3,26,5,1)
B(-3,26,6,1)
B(-3,26,7,1)
B(-3,26,8,1)
B(-3,27,2,1)
B(-3,27,3,1)
B(-3,27,4,1)
B(-3,27,5,1)
B(-3,27,6,1)
B(-3,27,7,1)
B(-3,27,8,1)
B(-3,28,3,1)
B(-3,28,4,1)
B(-3,28,5,1)
B(-3,28,6,1)
B(-3,28,7,1)
B(-3,28,8,1)
B(-3,29,3,1)
B(-3,29,4,1)
B(-3,29,5,1)
B(-3,29,6,1)
B(-3,29,7,1)
B(-3,29,8,1)
B(-3,30,5,1)
B(-3,30,6,1)
B(-3,30,7,1)
B(-3,30,8,1)
B(-3,31,6,1)
B(-3,31,7,1)
B(-3,32,6,1)
B(-3,32,7,1)
B(-2,6,8,1)
B(-2,7,7,1)
B(-2,7,8,1)
B(-2,8,1,1)
B(-2,8,7,1)
B(-2,8,8,1)
B(-2,9,1,1)
B(-2,9,7,1)
B(-2,9,8,1)
B(-2,10,1,1)
B(-2,10,6,1)
B(-2,10,7,1)
B(-2,10,8,1)
B(-2,11,1,1)
B(-2,11,2,1)
B(-2,11,5,1)
B(-2,11,6,1)
B(-2,11,7,1)
B(-2,11,8,1)
B(-2,12,1,1)
B(-2,12,2,1)
B(-2,12,4,1)
B(-2,12,5,1)
B(-2,12,6,1)
B(-2,12,7,1)
B(-2,12,8,1)
B(-2,13,1,1)
B(-2,13,2,1)
B(-2,13,3,1)
B(-2,13,4,1)
B(-2,13,5,1)
B(-2,13,6,1)
B(-2,13,7,1)
B(-2,13,8,1)
B(-2,14,1,1)
B(-2,14,2,1)
B(-2,14,3,1)
B(-2,14,4,1)
B(-2,14,5,1)
B(-2,14,6,1)
B(-2,14,7,1)
B(-2,14,8,1)
B(-2,15,1,16)
B(-2,15,2,1)
B(-2,15,3,1)
B(-2,15,4,1)
B(-2,15,5,1)
B(-2,15,6,1)
B(-2,15,7,1)
B(-2,15,8,1)
B(-2,16,0,1)
B(-2,16,1,1)
B(-2,16,2,1)
B(-2,16,3,1)
B(-2,16,4,1)
B(-2,16,5,1)
B(-2,16,6,1)
B(-2,16,7,1)
B(-2,16,8,1)
B(-2,17,0,1)
B(-2,17,1,1)
B(-2,17,2,1)
B(-2,17,3,1)
B(-2,17,4,1)
B(-2,17,5,1)
B(-2,17,6,1)
B(-2,17,7,1)
B(-2,17,8,1)
B(-2,18,0,1)
B(-2,18,1,1)
B(-2,18,2,1)
B(-2,18,3,1)
B(-2,18,4,1)
B(-2,18,5,1)
B(-2,18,6,1)
B(-2,18,7,1)
B(-2,18,8,1)
B(-2,19,-3,1)
B(-2,19,-2,1)
B(-2,19,-1,1)
B(-2,19,0,1)
B(-2,19,1,1)
B(-2,19,2,1)
B(-2,19,3,1)
B(-2,19,4,1)
B(-2,19,5,1)
B(-2,19,6,1)
B(-2,19,7,1)
B(-2,19,8,1)
B(-2,20,-3,1)
B(-2,20,-2,1)
B(-2,20,-1,1)
B(-2,20,0,1)
B(-2,20,1,1)
B(-2,20,2,1)
B(-2,20,3,1)
B(-2,20,4,1)
B(-2,20,5,1)
B(-2,20,6,1)
B(-2,20,7,1)
B(-2,20,8,1)
B(-2,21,-3,1)
B(-2,21,-2,1)
B(-2,21,-1,1)
B(-2,21,0,1)
B(-2,21,1,1)
B(-2,21,2,1)
B(-2,21,3,1)
B(-2,21,4,1)
B(-2,21,5,1)
B(-2,21,6,1)
B(-2,21,7,1)
B(-2,21,8,1)
B(-2,22,-4,1)
B(-2,22,-3,1)
B(-2,22,-2,1)
B(-2,22,-1,1)
B(-2,22,0,1)
B(-2,22,1,1)
B(-2,22,2,1)
B(-2,22,3,1)
B(-2,22,4,1)
B(-2,22,5,1)
B(-2,22,6,1)
B(-2,22,7,1)
B(-2,22,8,1)
B(-2,23,-3,1)
B(-2,23,-2,1)
B(-2,23,-1,1)
B(-2,23,0,1)
B(-2,23,1,1)
B(-2,23,2,1)
B(-2,23,3,1)
B(-2,23,4,1)
B(-2,23,5,1)
B(-2,23,6,1)
B(-2,23,7,1)
B(-2,23,8,1)
B(-2,24,-2,1)
B(-2,24,-1,1)
B(-2,24,0,1)
B(-2,24,1,1)
B(-2,24,2,1)
B(-2,24,3,1)
B(-2,24,4,1)
B(-2,24,5,1)
B(-2,24,6,1)
B(-2,24,7,1)
B(-2,24,8,1)
B(-2,25,-2,1)
B(-2,25,-1,1)
B(-2,25,0,1)
B(-2,25,1,1)
B(-2,25,2,1)
B(-2,25,3,1)
B(-2,25,4,1)
B(-2,25,5,1)
B(-2,25,6,1)
B(-2,25,7,1)
B(-2,25,8,1)
B(-2,26,-2,1)
B(-2,26,-1,1)
B(-2,26,0,1)
B(-2,26,1,1)
B(-2,26,2,1)
B(-2,26,3,1)
B(-2,26,4,1)
B(-2,26,5,1)
B(-2,26,6,1)
B(-2,26,7,1)
B(-2,26,8,1)
B(-2,27,1,1)
B(-2,27,2,1)
B(-2,27,3,1)
B(-2,27,4,1)
B(-2,27,5,1)
B(-2,27,6,1)
B(-2,27,7,1)
B(-2,27,8,1)
B(-2,28,2,1)
B(-2,28,3,1)
B(-2,28,4,1)
B(-2,28,5,1)
B(-2,28,6,1)
B(-2,28,7,1)
B(-2,28,8,1)
B(-2,29,2,1)
B(-2,29,3,1)
B(-2,29,4,1)
B(-2,29,5,1)
B(-2,29,6,1)
B(-2,29,7,1)
B(-2,29,8,1)
B(-2,30,3,1)
B(-2,30,4,1)
B(-2,30,5,1)
B(-2,30,6,1)
B(-2,30,7,1)
B(-2,30,8,1)
B(-2,31,4,1)
B(-2,31,5,1)
B(-2,31,6,1)
B(-2,31,7,1)
B(-2,31,8,1)
B(-2,32,5,1)
B(-2,32,6,1)
B(-2,32,7,1)
B(-2,32,8,1)
B(-2,33,5,1)
B(-2,33,6,1)
B(-2,33,7,1)
B(-1,5,8,1)
B(-1,6,8,1)
B(-1,7,7,1)
B(-1,7,8,1)
B(-1,8,1,1)
B(-1,8,7,1)
B(-1,8,8,1)
B(-1,9,0,1)
B(-1,9,1,1)
B(-1,9,2,1)
B(-1,9,6,1)
B(-1,9,7,1)
B(-1,9,8,1)
B(-1,10,0,1)
B(-1,10,1,1)
B(-1,10,2,1)
B(-1,10,5,1)
B(-1,10,6,1)
B(-1,10,7,1)
B(-1,10,8,1)
B(-1,11,0,1)
B(-1,11,1,1)
B(-1,11,2,1)
B(-1,11,3,1)
B(-1,11,4,1)
B(-1,11,5,1)
B(-1,11,6,1)
B(-1,11,7,1)
B(-1,11,8,1)
B(-1,12,0,1)
B(-1,12,1,1)
B(-1,12,2,1)
B(-1,12,3,1)
B(-1,12,4,1)
B(-1,12,5,1)
B(-1,12,6,1)
B(-1,12,7,1)
B(-1,12,8,1)
B(-1,13,0,1)
B(-1,13,1,1)
B(-1,13,2,1)
B(-1,13,3,1)
B(-1,13,4,1)
B(-1,13,5,1)
B(-1,13,6,1)
B(-1,13,7,1)
B(-1,13,8,1)
B(-1,14,0,1)
B(-1,14,1,1)
B(-1,14,2,1)
B(-1,14,3,1)
B(-1,14,4,1)
B(-1,14,5,1)
B(-1,14,6,1)
B(-1,14,7,1)
B(-1,14,8,1)
B(-1,15,0,1)
B(-1,15,1,1)
B(-1,15,2,1)
B(-1,15,3,1)
B(-1,15,4,1)
B(-1,15,5,1)
B(-1,15,6,1)
B(-1,15,7,1)
B(-1,15,8,1)
B(-1,16,-4,1)
B(-1,16,0,16)
B(-1,16,1,1)
B(-1,16,2,1)
B(-1,16,3,1)
B(-1,16,4,1)
B(-1,16,5,1)
B(-1,16,6,1)
B(-1,16,7,1)
B(-1,16,8,1)
B(-1,17,-4,1)
B(-1,17,0,1)
B(-1,17,1,1)
B(-1,17,2,1)
B(-1,17,3,1)
B(-1,17,4,1)
B(-1,17,5,1)
B(-1,17,6,16)
B(-1,17,7,16)
B(-1,17,8,1)
B(-1,18,-4,1)
B(-1,18,-3,1)
B(-1,18,-2,1)
B(-1,18,-1,1)
B(-1,18,0,1)
B(-1,18,1,1)
B(-1,18,2,1)
B(-1,18,3,1)
B(-1,18,4,1)
B(-1,18,5,1)
B(-1,18,6,1)
B(-1,18,7,16)
B(-1,18,8,1)
B(-1,19,-4,1)
B(-1,19,-3,1)
B(-1,19,-2,1)
B(-1,19,-1,1)
B(-1,19,0,1)
B(-1,19,1,1)
B(-1,19,2,1)
B(-1,19,3,1)
B(-1,19,4,1)
B(-1,19,5,1)
B(-1,19,6,1)
B(-1,19,7,1)
B(-1,19,8,1)
B(-1,20,-4,1)
B(-1,20,-3,1)
B(-1,20,-2,1)
B(-1,20,-1,1)
B(-1,20,0,1)
B(-1,20,1,1)
B(-1,20,2,1)
B(-1,20,3,1)
B(-1,20,4,1)
B(-1,20,5,1)
B(-1,20,6,1)
B(-1,20,7,1)
B(-1,20,8,1)
B(-1,21,-4,1)
B(-1,21,-3,1)
B(-1,21,-2,1)
B(-1,21,-1,1)
B(-1,21,0,1)
B(-1,21,1,1)
B(-1,21,2,1)
B(-1,21,3,1)
B(-1,21,4,1)
B(-1,21,5,1)
B(-1,21,6,1)
B(-1,21,7,1)
B(-1,21,8,1)
B(-1,22,-6,1)
B(-1,22,-5,1)
B(-1,22,-3,1)
B(-1,22,-2,1)
B(-1,22,-1,1)
B(-1,22,0,1)
B(-1,22,1,1)
B(-1,22,2,1)
B(-1,22,3,1)
B(-1,22,4,1)
B(-1,22,5,1)
B(-1,22,6,1)
B(-1,22,7,1)
B(-1,22,8,1)
B(-1,23,-6,1)
B(-1,23,-5,1)
B(-1,23,-3,1)
B(-1,23,-2,1)
B(-1,23,-1,1)
B(-1,23,0,1)
B(-1,23,1,1)
B(-1,23,2,1)
B(-1,23,3,1)
B(-1,23,4,1)
B(-1,23,5,1)
B(-1,23,6,1)
B(-1,23,7,1)
B(-1,23,8,1)
B(-1,24,-6,1)
B(-1,24,-3,1)
B(-1,24,-2,1)
B(-1,24,-1,1)
B(-1,24,0,1)
B(-1,24,1,1)
B(-1,24,2,1)
B(-1,24,3,1)
B(-1,24,4,1)
B(-1,24,5,1)
B(-1,24,6,1)
B(-1,24,7,1)
B(-1,24,8,1)
B(-1,25,-3,1)
B(-1,25,-2,1)
B(-1,25,-1,1)
B(-1,25,0,1)
B(-1,25,1,1)
B(-1,25,2,1)
B(-1,25,3,1)
B(-1,25,4,1)
B(-1,25,5,1)
B(-1,25,6,1)
B(-1,25,7,1)
B(-1,25,8,1)
B(-1,26,-3,1)
B(-1,26,-2,1)
B(-1,26,-1,1)
B(-1,26,0,1)
B(-1,26,1,1)
B(-1,26,2,1)
B(-1,26,3,1)
B(-1,26,4,1)
B(-1,26,5,1)
B(-1,26,6,1)
B(-1,26,7,1)
B(-1,26,8,1)
B(-1,27,-2,1)
B(-1,27,-1,1)
B(-1,27,0,1)
B(-1,27,1,1)
B(-1,27,2,1)
B(-1,27,3,1)
B(-1,27,4,1)
B(-1,27,5,1)
B(-1,27,6,1)
B(-1,27,7,1)
B(-1,27,8,1)
B(-1,28,-1,1)
B(-1,28,0,1)
B(-1,28,1,1)
B(-1,28,2,1)
B(-1,28,3,1)
B(-1,28,4,1)
B(-1,28,5,1)
B(-1,28,6,1)
B(-1,28,7,1)
B(-1,28,8,1)
B(-1,29,-1,1)
B(-1,29,0,1)
B(-1,29,1,1)
B(-1,29,2,1)
B(-1,29,3,1)
B(-1,29,4,1)
B(-1,29,5,1)
B(-1,29,6,1)
B(-1,29,7,1)
B(-1,29,8,1)
B(-1,30,0,1)
B(-1,30,2,1)
B(-1,30,3,1)
B(-1,30,4,1)
B(-1,30,5,1)
B(-1,30,6,1)
B(-1,30,7,1)
B(-1,30,8,1)
B(-1,31,0,1)
B(-1,31,2,1)
B(-1,31,3,1)
B(-1,31,4,1)
B(-1,31,5,1)
B(-1,31,6,1)
B(-1,31,7,1)
B(-1,31,8,1)
B(-1,32,4,1)
B(-1,32,5,1)
B(-1,32,6,1)
B(-1,32,7,1)
B(-1,32,8,1)
B(-1,33,4,1)
B(-1,33,5,1)
B(-1,33,6,1)
B(-1,33,7,1)
B(-1,33,8,1)
B(-1,34,5,1)
B(-1,34,6,1)
B(-1,34,7,1)
B(-1,34,8,1)
B(-1,35,5,1)
B(0,8,-1,1)
B(0,8,6,1)
B(0,8,7,1)
B(0,8,8,1)
B(0,9,-1,1)
B(0,9,0,1)
B(0,9,1,1)
B(0,9,5,1)
B(0,9,6,1)
B(0,9,7,1)
B(0,9,8,1)
B(0,10,-2,1)
B(0,10,-1,1)
B(0,10,0,1)
B(0,10,1,1)
B(0,10,3,1)
B(0,10,5,1)
B(0,10,6,1)
B(0,10,7,1)
B(0,10,8,1)
B(0,11,-2,1)
B(0,11,-1,1)
B(0,11,0,1)
B(0,11,1,1)
B(0,11,2,1)
B(0,11,3,1)
B(0,11,5,1)
B(0,11,6,1)
B(0,11,7,1)
B(0,11,8,1)
B(0,12,-2,1)
B(0,12,-1,1)
B(0,12,0,1)
B(0,12,1,1)
B(0,12,2,1)
B(0,12,3,1)
B(0,12,4,3:6)
B(0,12,5,1)
B(0,12,6,1)
B(0,12,7,1)
B(0,12,8,1)
B(0,13,-2,1)
B(0,13,-1,1)
B(0,13,0,1)
B(0,13,1,1)
B(0,13,2,1)
B(0,13,3,1)
B(0,13,4,3:6)
B(0,13,5,1)
B(0,13,6,1)
B(0,13,7,1)
B(0,13,8,1)
B(0,14,-2,1)
B(0,14,-1,1)
B(0,14,0,1)
B(0,14,1,1)
B(0,14,2,1)
B(0,14,3,1)
B(0,14,4,1)
B(0,14,5,1)
B(0,14,6,1)
B(0,14,7,1)
B(0,14,8,1)
B(0,15,-2,1)
B(0,15,-1,1)
B(0,15,0,1)
B(0,15,1,1)
B(0,15,2,1)
B(0,15,3,1)
B(0,15,4,1)
B(0,15,5,1)
B(0,15,6,1)
B(0,15,7,1)
B(0,15,8,1)
B(0,16,-3,1)
B(0,16,-2,16)
B(0,16,-1,16)
B(0,16,0,1)
B(0,16,1,1)
B(0,16,2,1)
B(0,16,3,1)
B(0,16,4,1)
B(0,16,5,1)
B(0,16,6,1)
B(0,16,7,1)
B(0,16,8,1)
B(0,17,-5,1)
B(0,17,-3,1)
B(0,17,-2,16)
B(0,17,-1,16)
B(0,17,0,1)
B(0,17,1,1)
B(0,17,2,1)
B(0,17,3,1)
B(0,17,4,1)
B(0,17,5,1)
B(0,17,6,1)
B(0,17,7,1)
B(0,17,8,1)
B(0,18,-5,1)
B(0,18,-4,1)
B(0,18,-3,1)
B(0,18,-2,1)
B(0,18,-1,1)
B(0,18,0,1)
B(0,18,1,1)
B(0,18,2,1)
B(0,18,3,1)
B(0,18,4,1)
B(0,18,5,1)
B(0,18,6,1)
B(0,18,7,1)
B(0,18,8,1)
B(0,19,-6,1)
B(0,19,-5,1)
B(0,19,-4,1)
B(0,19,-3,1)
B(0,19,-2,1)
B(0,19,-1,1)
B(0,19,0,1)
B(0,19,1,1)
B(0,19,2,1)
B(0,19,3,1)
B(0,19,4,1)
B(0,19,5,1)
B(0,19,6,1)
B(0,19,7,1)
B(0,19,8,1)
B(0,20,-6,1)
B(0,20,-5,1)
B(0,20,-4,1)
B(0,20,-3,1)
B(0,20,-2,1)
B(0,20,-1,1)
B(0,20,0,1)
B(0,20,1,1)
B(0,20,2,1)
B(0,20,3,1)
B(0,20,4,1)
B(0,20,5,1)
B(0,20,6,1)
B(0,20,7,1)
B(0,20,8,1)
B(0,21,-6,1)
B(0,21,-5,1)
B(0,21,-4,1)
B(0,21,-3,1)
B(0,21,-2,1)
B(0,21,-1,1)
B(0,21,0,1)
B(0,21,1,1)
B(0,21,2,1)
B(0,21,3,1)
B(0,21,4,1)
B(0,21,5,1)
B(0,21,6,1)
B(0,21,7,1)
B(0,21,8,1)
B(0,22,-7,1)
B(0,22,-6,1)
B(0,22,-5,1)
B(0,22,-4,1)
B(0,22,-3,1)
B(0,22,-2,1)
B(0,22,-1,1)
B(0,22,0,1)
B(0,22,1,1)
B(0,22,2,1)
B(0,22,3,1)
B(0,22,4,1)
B(0,22,5,1)
B(0,22,6,1)
B(0,22,7,1)
B(0,22,8,1)
B(0,23,-7,1)
B(0,23,-6,1)
B(0,23,-5,1)
B(0,23,-4,1)
B(0,23,-3,1)
B(0,23,-2,1)
B(0,23,-1,1)
B(0,23,0,1)
B(0,23,1,1)
B(0,23,2,1)
B(0,23,3,1)
B(0,23,4,1)
B(0,23,5,1)
B(0,23,6,1)
B(0,23,7,1)
B(0,23,8,1)
B(0,24,-7,1)
B(0,24,-6,1)
B(0,24,-5,1)
B(0,24,-4,1)
B(0,24,-3,1)
B(0,24,-2,1)
B(0,24,-1,1)
B(0,24,0,1)
B(0,24,1,1)
B(0,24,2,1)
B(0,24,3,1)
B(0,24,4,1)
B(0,24,5,1)
B(0,24,6,1)
B(0,24,7,1)
B(0,24,8,1)
B(0,25,-6,1)
B(0,25,-5,1)
B(0,25,-4,1)
B(0,25,-3,1)
B(0,25,-2,1)
B(0,25,-1,1)
B(0,25,0,1)
B(0,25,1,1)
B(0,25,2,1)
B(0,25,3,1)
B(0,25,4,1)
B(0,25,5,1)
B(0,25,6,1)
B(0,25,7,1)
B(0,25,8,1)
B(0,26,-6,1)
B(0,26,-4,1)
B(0,26,-3,1)
B(0,26,-2,1)
B(0,26,-1,1)
B(0,26,0,1)
B(0,26,1,1)
B(0,26,2,1)
B(0,26,3,1)
B(0,26,4,1)
B(0,26,5,1)
B(0,26,6,1)
B(0,26,7,1)
B(0,26,8,1)
B(0,27,-4,1)
B(0,27,-3,16)
B(0,27,-2,1)
B(0,27,-1,1)
B(0,27,0,1)
B(0,27,1,1)
B(0,27,2,1)
B(0,27,3,1)
B(0,27,4,1)
B(0,27,5,1)
B(0,27,6,1)
B(0,27,7,1)
B(0,27,8,1)
B(0,28,-3,1)
B(0,28,-2,1)
B(0,28,-1,1)
B(0,28,0,1)
B(0,28,1,1)
B(0,28,2,1)
B(0,28,3,1)
B(0,28,4,1)
B(0,28,5,1)
B(0,28,6,1)
B(0,28,7,1)
B(0,28,8,1)
B(0,29,-3,1)
B(0,29,-2,1)
B(0,29,-1,1)
B(0,29,0,1)
B(0,29,1,1)
B(0,29,2,1)
B(0,29,3,1)
B(0,29,4,1)
B(0,29,5,1)
B(0,29,6,1)
B(0,29,7,1)
B(0,29,8,1)
B(0,30,-3,1)
B(0,30,-2,1)
B(0,30,-1,1)
B(0,30,0,1)
B(0,30,1,1)
B(0,30,2,1)
B(0,30,3,3:6)
B(0,30,4,1)
B(0,30,5,1)
B(0,30,6,1)
B(0,30,7,1)
B(0,30,8,1)
B(0,31,-3,1)
B(0,31,-2,1)
B(0,31,-1,1)
B(0,31,0,1)
B(0,31,1,1)
B(0,31,2,1)
B(0,31,3,3:6)
B(0,31,4,1)
B(0,31,5,1)
B(0,31,6,1)
B(0,31,7,1)
B(0,31,8,1)
B(0,32,-3,1)
B(0,32,-2,1)
B(0,32,-1,1)
B(0,32,0,1)
B(0,32,1,1)
B(0,32,2,1)
B(0,32,3,13:1)
B(0,32,4,1)
B(0,32,5,1)
B(0,32,6,1)
B(0,32,7,1)
B(0,32,8,1)
B(0,33,-3,1)
B(0,33,-2,1)
B(0,33,-1,1)
B(0,33,0,1)
B(0,33,2,1)
B(0,33,3,13:1)
B(0,33,4,1)
B(0,33,5,1)
B(0,33,6,1)
B(0,33,7,1)
B(0,33,8,1)
B(0,34,-2,1)
B(0,34,-1,1)
B(0,34,0,1)
B(0,34,3,13:1)
B(0,34,4,1)
B(0,34,5,1)
B(0,34,6,1)
B(0,34,7,1)
B(0,34,8,1)
B(0,35,-2,1)
B(0,35,5,1)
B(0,35,6,1)
B(0,35,7,1)
B(0,35,8,1)
B(0,36,8,1)
B(1,8,6,1)
B(1,9,6,1)
B(1,9,7,1)
B(1,9,8,1)
B(1,10,5,1)
B(1,10,6,1)
B(1,10,7,1)
B(1,10,8,1)
B(1,11,5,1)
B(1,11,6,1)
B(1,11,7,1)
B(1,11,8,1)
B(1,12,1,1)
B(1,12,3,1)
B(1,12,4,1)
B(1,12,5,1)
B(1,12,6,1)
B(1,12,7,1)
B(1,12,8,1)
B(1,13,1,1)
B(1,13,3,1)
B(1,13,4,1)
B(1,13,5,1)
B(1,13,6,1)
B(1,13,7,1)
B(1,13,8,1)
B(1,14,0,1)
B(1,14,1,1)
B(1,14,2,1)
B(1,14,3,1)
B(1,14,4,1)
B(1,14,5,1)
B(1,14,6,1)
B(1,14,7,1)
B(1,14,8,1)
B(1,15,-5,1)
B(1,15,0,1)
B(1,15,1,1)
B(1,15,2,1)
B(1,15,3,1)
B(1,15,4,1)
B(1,15,5,1)
B(1,15,6,1)
B(1,15,7,1)
B(1,15,8,1)
B(1,16,-5,1)
B(1,16,0,1)
B(1,16,1,1)
B(1,16,2,1)
B(1,16,3,1)
B(1,16,4,1)
B(1,16,5,1)
B(1,16,6,1)
B(1,16,7,1)
B(1,16,8,1)
B(1,17,-5,1)
B(1,17,0,1)
B(1,17,1,1)
B(1,17,2,1)
B(1,17,3,1)
B(1,17,4,1)
B(1,17,5,1)
B(1,17,6,1)
B(1,17,7,1)
B(1,17,8,1)
B(1,18,-5,1)
B(1,18,-3,1)
B(1,18,-2,1)
B(1,18,-1,1)
B(1,18,0,1)
B(1,18,1,1)
B(1,18,2,1)
B(1,18,3,1)
B(1,18,4,1)
B(1,18,5,1)
B(1,18,6,1)
B(1,18,7,1)
B(1,18,8,1)
B(1,19,-5,1)
B(1,19,-4,1)
B(1,19,-3,1)
B(1,19,-2,1)
B(1,19,-1,1)
B(1,19,0,1)
B(1,19,1,1)
B(1,19,2,1)
B(1,19,3,1)
B(1,19,4,1)
B(1,19,5,1)
B(1,19,6,1)
B(1,19,7,1)
B(1,19,8,1)
B(1,20,-5,1)
B(1,20,-4,1)
B(1,20,-3,1)
B(1,20,-2,1)
B(1,20,-1,1)
B(1,20,0,1)
B(1,20,1,1)
B(1,20,2,1)
B(1,20,3,1)
B(1,20,4,1)
B(1,20,5,1)
B(1,20,6,1)
B(1,20,7,1)
B(1,20,8,1)
B(1,21,-5,1)
B(1,21,-4,1)
B(1,21,-3,1)
B(1,21,-2,1)
B(1,21,-1,1)
B(1,21,0,1)
B(1,21,1,1)
B(1,21,2,1)
B(1,21,3,1)
B(1,21,4,1)
B(1,21,5,1)
B(1,21,6,1)
B(1,21,7,1)
B(1,21,8,1)
B(1,22,-6,1)
B(1,22,-5,1)
B(1,22,-4,1)
B(1,22,-3,1)
B(1,22,-2,1)
B(1,22,-1,1)
B(1,22,0,1)
B(1,22,1,1)
B(1,22,2,1)
B(1,22,3,1)
B(1,22,4,1)
B(1,22,5,1)
B(1,22,6,1)
B(1,22,7,1)
B(1,22,8,1)
B(1,23,-6,1)
B(1,23,-5,1)
B(1,23,-4,1)
B(1,23,-3,1)
B(1,23,-2,1)
B(1,23,-1,1)
B(1,23,0,1)
B(1,23,1,1)
B(1,23,2,1)
B(1,23,3,1)
B(1,23,4,1)
B(1,23,5,1)
B(1,23,6,1)
B(1,23,7,1)
B(1,23,8,1)
B(1,24,-5,1)
B(1,24,-4,1)
B(1,24,-3,1)
B(1,24,-2,1)
B(1,24,-1,1)
B(1,24,0,1)
B(1,24,1,1)
B(1,24,2,1)
B(1,24,3,1)
B(1,24,4,1)
B(1,24,5,1)
B(1,24,6,1)
B(1,24,7,1)
B(1,24,8,1)
B(1,25,-5,1)
B(1,25,-4,1)
B(1,25,-3,1)
B(1,25,-2,1)
B(1,25,-1,1)
B(1,25,0,1)
B(1,25,1,1)
B(1,25,2,1)
B(1,25,3,1)
B(1,25,4,1)
B(1,25,5,1)
B(1,25,6,16)
B(1,25,7,1)
B(1,25,8,1)
B(1,26,-5,1)
B(1,26,-3,1)
B(1,26,-2,1)
B(1,26,-1,1)
B(1,26,0,1)
B(1,26,1,1)
B(1,26,2,1)
B(1,26,3,1)
B(1,26,4,1)
B(1,26,5,16)
B(1,26,6,16)
B(1,26,7,1)
B(1,26,8,1)
B(1,27,-5,1)
B(1,27,-2,1)
B(1,27,-1,1)
B(1,27,0,1)
B(1,27,1,1)
B(1,27,2,1)
B(1,27,3,1)
B(1,27,4,1)
B(1,27,5,1)
B(1,27,6,1)
B(1,27,7,1)
B(1,27,8,1)
B(1,28,-1,1)
B(1,28,0,1)
B(1,28,1,1)
B(1,28,2,1)
B(1,28,3,1)
B(1,28,4,1)
B(1,28,5,1)
B(1,28,6,1)
B(1,28,7,1)
B(1,28,8,1)
B(1,29,-1,1)
B(1,29,0,1)
B(1,29,1,1)
B(1,29,2,1)
B(1,29,3,1)
B(1,29,4,1)
B(1,29,5,1)
B(1,29,6,1)
B(1,29,7,1)
B(1,29,8,1)
B(1,30,-1,1)
B(1,30,0,1)
B(1,30,1,1)
B(1,30,2,1)
B(1,30,3,1)
B(1,30,4,1)
B(1,30,5,1)
B(1,30,6,1)
B(1,30,7,1)
B(1,30,8,1)
B(1,31,-1,1)
B(1,31,0,1)
B(1,31,1,1)
B(1,31,2,1)
B(1,31,3,1)
B(1,31,4,1)
B(1,31,5,1)
B(1,31,6,1)
B(1,31,7,1)
B(1,31,8,1)
B(1,32,-1,1)
B(1,32,0,1)
B(1,32,1,1)
B(1,32,2,1)
B(1,32,3,1)
B(1,32,4,1)
B(1,32,5,1)
B(1,32,6,1)
B(1,32,7,1)
B(1,32,8,1)
B(1,33,-1,1)
B(1,33,0,1)
B(1,33,1,1)
B(1,33,4,1)
B(1,33,5,1)
B(1,33,6,1)
B(1,33,7,1)
B(1,33,8,1)
B(1,34,-1,1)
B(1,34,0,1)
B(1,34,1,1)
B(1,34,5,1)
B(1,34,6,1)
B(1,34,7,1)
B(1,34,8,1)
B(1,35,0,1)
B(1,35,6,1)
B(1,35,7,1)
B(1,35,8,1)
B(1,36,6,1)
B(1,36,7,1)
B(1,36,8,1)
B(1,37,7,1)
B(1,37,8,1)
B(1,38,7,1)
B(1,38,8,1)
B(1,39,8,1)
B(1,40,8,1)
B(2,10,6,1)
B(2,10,7,1)
B(2,10,8,1)
B(2,11,6,1)
B(2,11,7,1)
B(2,11,8,1)
B(2,12,5,1)
B(2,12,6,1)
B(2,12,7,1)
B(2,12,8,1)
B(2,13,4,1)
B(2,13,5,1)
B(2,13,6,1)
B(2,13,7,1)
B(2,13,8,1)
B(2,14,3,1)
B(2,14,4,1)
B(2,14,5,1)
B(2,14,6,1)
B(2,14,7,1)
B(2,14,8,1)
B(2,15,3,1)
B(2,15,4,1)
B(2,15,5,1)
B(2,15,6,1)
B(2,15,7,1)
B(2,15,8,1)
B(2,16,2,1)
B(2,16,3,1)
B(2,16,4,1)
B(2,16,5,1)
B(2,16,6,1)
B(2,16,7,1)
B(2,16,8,1)
B(2,17,-1,1)
B(2,17,0,1)
B(2,17,1,1)
B(2,17,2,1)
B(2,17,3,1)
B(2,17,4,1)
B(2,17,5,1)
B(2,17,6,1)
B(2,17,7,1)
B(2,17,8,1)
B(2,18,-1,1)
B(2,18,0,1)
B(2,18,1,1)
B(2,18,2,1)
B(2,18,3,1)
B(2,18,4,1)
B(2,18,5,1)
B(2,18,6,1)
B(2,18,7,1)
B(2,18,8,1)
B(2,19,-3,1)
B(2,19,-2,1)
B(2,19,-1,1)
B(2,19,0,1)
B(2,19,1,1)
B(2,19,2,1)
B(2,19,3,1)
B(2,19,4,1)
B(2,19,5,1)
B(2,19,6,1)
B(2,19,7,1)
B(2,19,8,1)
B(2,20,-3,1)
B(2,20,-2,1)
B(2,20,-1,1)
B(2,20,0,1)
B(2,20,1,1)
B(2,20,2,1)
B(2,20,3,1)
B(2,20,4,1)
B(2,20,5,1)
B(2,20,6,1)
B(2,20,7,1)
B(2,20,8,1)
B(2,21,-3,1)
B(2,21,-2,1)
B(2,21,-1,1)
B(2,21,0,1)
B(2,21,1,1)
B(2,21,2,1)
B(2,21,3,1)
B(2,21,4,1)
B(2,21,5,1)
B(2,21,6,1)
B(2,21,7,1)
B(2,21,8,1)
B(2,22,-3,1)
B(2,22,-2,1)
B(2,22,-1,1)
B(2,22,0,1)
B(2,22,1,1)
B(2,22,2,1)
B(2,22,3,1)
B(2,22,4,1)
B(2,22,5,1)
B(2,22,6,1)
B(2,22,7,1)
B(2,22,8,1)
B(2,23,-3,1)
B(2,23,-2,1)
B(2,23,-1,1)
B(2,23,0,1)
B(2,23,1,1)
B(2,23,2,1)
B(2,23,3,1)
B(2,23,4,1)
B(2,23,5,1)
B(2,23,6,1)
B(2,23,7,1)
B(2,23,8,1)
B(2,24,-3,1)
B(2,24,-2,1)
B(2,24,-1,1)
B(2,24,0,1)
B(2,24,1,1)
B(2,24,2,1)
B(2,24,3,1)
B(2,24,4,1)
B(2,24,5,1)
B(2,24,6,1)
B(2,24,7,1)
B(2,24,8,1)
B(2,25,-2,1)
B(2,25,-1,1)
B(2,25,0,1)
B(2,25,1,1)
B(2,25,2,1)
B(2,25,3,1)
B(2,25,4,1)
B(2,25,5,1)
B(2,25,6,1)
B(2,25,7,1)
B(2,25,8,1)
B(2,26,-2,1)
B(2,26,-1,1)
B(2,26,0,1)
B(2,26,1,1)
B(2,26,2,1)
B(2,26,3,1)
B(2,26,4,1)
B(2,26,5,1)
B(2,26,6,1)
B(2,26,7,1)
B(2,26,8,1)
B(2,27,-1,1)
B(2,27,0,1)
B(2,27,1,1)
B(2,27,2,1)
B(2,27,3,1)
B(2,27,4,1)
B(2,27,5,1)
B(2,27,6,1)
B(2,27,7,1)
B(2,27,8,1)
B(2,28,0,16)
B(2,28,1,1)
B(2,28,2,1)
B(2,28,3,1)
B(2,28,4,1)
B(2,28,5,1)
B(2,28,6,1)
B(2,28,7,1)
B(2,28,8,1)
B(2,29,0,1)
B(2,29,1,1)
B(2,29,2,1)
B(2,29,3,1)
B(2,29,4,1)
B(2,29,5,1)
B(2,29,6,1)
B(2,29,7,1)
B(2,29,8,1)
B(2,30,0,1)
B(2,30,1,1)
B(2,30,2,1)
B(2,30,3,1)
B(2,30,4,1)
B(2,30,5,1)
B(2,30,6,1)
B(2,30,7,1)
B(2,30,8,1)
B(2,31,0,1)
B(2,31,1,1)
B(2,31,3,1)
B(2,31,4,1)
B(2,31,5,1)
B(2,31,6,1)
B(2,31,7,1)
B(2,31,8,1)
B(2,32,0,1)
B(2,32,1,1)
B(2,32,4,1)
B(2,32,5,1)
B(2,32,6,1)
B(2,32,7,1)
B(2,32,8,1)
B(2,33,0,1)
B(2,33,5,1)
B(2,33,6,1)
B(2,33,7,1)
B(2,33,8,1)
B(2,34,0,1)
B(2,34,6,1)
B(2,34,7,1)
B(2,34,8,1)
B(2,35,0,1)
B(2,35,6,1)
B(2,35,7,1)
B(2,35,8,1)
B(2,36,6,1)
B(2,36,7,1)
B(2,36,8,1)
B(2,37,7,1)
B(2,37,8,1)
B(2,38,8,1)
B(2,39,8,1)
B(3,11,7,1)
B(3,11,8,1)
B(3,12,7,1)
B(3,12,8,1)
B(3,13,6,1)
B(3,13,7,1)
B(3,13,8,1)
B(3,14,4,1)
B(3,14,5,1)
B(3,14,6,1)
B(3,14,7,1)
B(3,14,8,1)
B(3,15,4,1)
B(3,15,5,1)
B(3,15,6,1)
B(3,15,7,1)
B(3,15,8,1)
B(3,16,3,1)
B(3,16,4,1)
B(3,16,5,1)
B(3,16,6,1)
B(3,16,7,1)
B(3,16,8,1)
B(3,17,3,1)
B(3,17,4,1)
B(3,17,5,1)
B(3,17,6,1)
B(3,17,7,1)
B(3,17,8,1)
B(3,18,0,1)
B(3,18,1,1)
B(3,18,2,1)
B(3,18,3,1)
B(3,18,4,1)
B(3,18,5,1)
B(3,18,6,1)
B(3,18,7,1)
B(3,18,8,1)
B(3,19,-1,1)
B(3,19,0,1)
B(3,19,1,1)
B(3,19,2,1)
B(3,19,3,1)
B(3,19,4,1)
B(3,19,5,1)
B(3,19,6,1)
B(3,19,7,1)
B(3,19,8,1)
B(3,20,-1,1)
B(3,20,0,1)
B(3,20,1,1)
B(3,20,2,1)
B(3,20,3,1)
B(3,20,4,1)
B(3,20,5,1)
B(3,20,6,1)
B(3,20,7,1)
B(3,20,8,1)
B(3,21,-1,1)
B(3,21,0,1)
B(3,21,1,1)
B(3,21,2,1)
B(3,21,3,1)
B(3,21,4,1)
B(3,21,5,1)
B(3,21,6,1)
B(3,21,7,1)
B(3,21,8,1)
B(3,22,-2,1)
B(3,22,-1,1)
B(3,22,0,1)
B(3,22,1,1)
B(3,22,2,1)
B(3,22,3,1)
B(3,22,4,1)
B(3,22,5,1)
B(3,22,6,1)
B(3,22,7,1)
B(3,22,8,1)
B(3,23,-2,1)
B(3,23,-1,1)
B(3,23,0,1)
B(3,23,1,1)
B(3,23,2,1)
B(3,23,3,1)
B(3,23,4,1)
B(3,23,5,1)
B(3,23,6,1)
B(3,23,7,1)
B(3,23,8,1)
B(3,24,-1,1)
B(3,24,0,1)
B(3,24,1,1)
B(3,24,2,1)
B(3,24,3,1)
B(3,24,4,1)
B(3,24,5,1)
B(3,24,6,1)
B(3,24,7,1)
B(3,24,8,1)
B(3,25,-1,1)
B(3,25,0,1)
B(3,25,1,1)
B(3,25,2,1)
B(3,25,3,1)
B(3,25,4,1)
B(3,25,5,1)
B(3,25,6,1)
B(3,25,7,1)
B(3,25,8,1)
B(3,26,-1,1)
B(3,26,0,1)
B(3,26,1,1)
B(3,26,2,1)
B(3,26,3,1)
B(3,26,4,1)
B(3,26,5,1)
B(3,26,6,1)
B(3,26,7,1)
B(3,26,8,1)
B(3,27,0,1)
B(3,27,1,1)
B(3,27,2,1)
B(3,27,3,1)
B(3,27,4,1)
B(3,27,5,1)
B(3,27,6,1)
B(3,27,7,1)
B(3,27,8,1)
B(3,28,0,1)
B(3,28,1,1)
B(3,28,2,1)
B(3,28,3,1)
B(3,28,4,1)
B(3,28,5,1)
B(3,28,6,1)
B(3,28,7,1)
B(3,28,8,1)
B(3,29,0,1)
B(3,29,1,1)
B(3,29,2,1)
B(3,29,3,1)
B(3,29,4,1)
B(3,29,5,1)
B(3,29,6,1)
B(3,29,7,1)
B(3,29,8,1)
B(3,30,0,1)
B(3,30,1,1)
B(3,30,3,1)
B(3,30,4,1)
B(3,30,5,1)
B(3,30,6,1)
B(3,30,7,1)
B(3,30,8,1)
B(3,31,1,1)
B(3,31,4,1)
B(3,31,5,1)
B(3,31,6,1)
B(3,31,7,1)
B(3,31,8,1)
B(3,32,4,1)
B(3,32,5,1)
B(3,32,6,1)
B(3,32,7,1)
B(3,32,8,1)
B(3,33,5,1)
B(3,33,6,1)
B(3,33,7,1)
B(3,33,8,1)
B(3,34,6,1)
B(3,34,7,1)
B(3,34,8,1)
B(3,35,6,1)
B(3,35,7,1)
B(3,35,8,1)
B(3,36,6,1)
B(3,36,7,1)
B(3,36,8,1)
B(3,37,7,1)
B(3,37,8,1)
B(3,38,8,1)
B(3,39,8,1)
B(4,13,7,1)
B(4,13,8,1)
B(4,14,6,1)
B(4,14,7,1)
B(4,14,8,1)
B(4,15,6,1)
B(4,15,7,1)
B(4,15,8,1)
B(4,16,4,1)
B(4,16,5,1)
B(4,16,6,1)
B(4,16,7,1)
B(4,16,8,1)
B(4,17,4,1)
B(4,17,5,1)
B(4,17,6,1)
B(4,17,7,1)
B(4,17,8,1)
B(4,18,0,1)
B(4,18,1,1)
B(4,18,2,1)
B(4,18,4,1)
B(4,18,5,1)
B(4,18,6,1)
B(4,18,7,1)
B(4,18,8,1)
B(4,19,-1,1)
B(4,19,0,1)
B(4,19,1,1)
B(4,19,2,1)
B(4,19,3,1)
B(4,19,4,1)
B(4,19,5,1)
B(4,19,6,1)
B(4,19,7,1)
B(4,19,8,1)
B(4,20,-1,1)
B(4,20,0,1)
B(4,20,1,1)
B(4,20,2,1)
B(4,20,3,1)
B(4,20,4,1)
B(4,20,5,1)
B(4,20,6,1)
B(4,20,7,1)
B(4,20,8,1)
B(4,21,-1,1)
B(4,21,0,1)
B(4,21,1,1)
B(4,21,2,1)
B(4,21,3,1)
B(4,21,4,1)
B(4,21,5,1)
B(4,21,6,1)
B(4,21,7,1)
B(4,21,8,1)
B(4,22,-1,1)
B(4,22,0,1)
B(4,22,1,1)
B(4,22,2,1)
B(4,22,3,1)
B(4,22,4,1)
B(4,22,5,1)
B(4,22,6,1)
B(4,22,7,1)
B(4,22,8,1)
B(4,23,-1,1)
B(4,23,0,1)
B(4,23,1,1)
B(4,23,2,1)
B(4,23,3,1)
B(4,23,4,1)
B(4,23,5,1)
B(4,23,6,1)
B(4,23,7,1)
B(4,23,8,1)
B(4,24,-1,1)
B(4,24,0,1)
B(4,24,1,1)
B(4,24,2,1)
B(4,24,3,1)
B(4,24,4,1)
B(4,24,5,1)
B(4,24,6,1)
B(4,24,7,1)
B(4,24,8,1)
B(4,25,-1,1)
B(4,25,0,1)
B(4,25,1,1)
B(4,25,2,1)
B(4,25,3,1)
B(4,25,4,1)
B(4,25,5,1)
B(4,25,6,1)
B(4,25,7,1)
B(4,25,8,1)
B(4,26,0,1)
B(4,26,1,1)
B(4,26,2,1)
B(4,26,3,1)
B(4,26,4,1)
B(4,26,5,1)
B(4,26,6,1)
B(4,26,7,1)
B(4,26,8,1)
B(4,27,2,1)
B(4,27,3,1)
B(4,27,4,1)
B(4,27,5,1)
B(4,27,6,1)
B(4,27,7,1)
B(4,27,8,1)
B(4,28,3,1)
B(4,28,4,1)
B(4,28,5,1)
B(4,28,6,1)
B(4,28,7,1)
B(4,28,8,1)
B(4,29,3,1)
B(4,29,4,1)
B(4,29,5,1)
B(4,29,6,1)
B(4,29,7,1)
B(4,29,8,1)
B(4,30,3,1)
B(4,30,4,1)
B(4,30,5,1)
B(4,30,6,1)
B(4,30,7,1)
B(4,30,8,1)
B(4,31,3,1)
B(4,31,5,1)
B(4,31,6,1)
B(4,31,7,1)
B(4,31,8,1)
B(4,32,5,1)
B(4,32,6,1)
B(4,32,7,1)
B(4,32,8,1)
B(4,33,6,1)
B(4,33,7,1)
B(4,33,8,1)
B(4,34,6,1)
B(4,34,7,1)
B(4,34,8,1)
B(4,35,6,1)
B(4,35,7,1)
B(4,35,8,1)
B(4,36,7,1)
B(4,36,8,1)
B(5,15,7,1)
B(5,15,8,1)
B(5,16,6,1)
B(5,16,7,1)
B(5,16,8,1)
B(5,17,6,1)
B(5,17,7,1)
B(5,17,8,1)
B(5,18,5,1)
B(5,18,6,1)
B(5,18,7,1)
B(5,18,8,1)
B(5,19,2,1)
B(5,19,3,1)
B(5,19,4,1)
B(5,19,5,1)
B(5,19,6,1)
B(5,19,7,1)
B(5,19,8,1)
B(5,20,1,1)
B(5,20,2,1)
B(5,20,3,1)
B(5,20,4,1)
B(5,20,5,1)
B(5,20,6,1)
B(5,20,7,1)
B(5,20,8,1)
B(5,21,0,1)
B(5,21,1,1)
B(5,21,2,1)
B(5,21,3,1)
B(5,21,4,1)
B(5,21,5,1)
B(5,21,6,1)
B(5,21,7,1)
B(5,21,8,1)
B(5,22,1,1)
B(5,22,2,1)
B(5,22,3,1)
B(5,22,4,1)
B(5,22,5,1)
B(5,22,6,1)
B(5,22,7,1)
B(5,22,8,1)
B(5,23,1,1)
B(5,23,2,1)
B(5,23,3,1)
B(5,23,4,1)
B(5,23,5,1)
B(5,23,6,1)
B(5,23,7,1)
B(5,23,8,1)
B(5,24,2,1)
B(5,24,3,1)
B(5,24,4,1)
B(5,24,5,1)
B(5,24,6,1)
B(5,24,7,1)
B(5,24,8,1)
B(5,25,2,1)
B(5,25,3,1)
B(5,25,4,1)
B(5,25,5,1)
B(5,25,6,1)
B(5,25,7,1)
B(5,25,8,1)
B(5,26,3,1)
B(5,26,4,1)
B(5,26,5,1)
B(5,26,6,1)
B(5,26,7,1)
B(5,26,8,1)
B(5,27,3,1)
B(5,27,4,1)
B(5,27,5,1)
B(5,27,6,1)
B(5,27,7,1)
B(5,27,8,1)
B(5,28,3,1)
B(5,28,5,1)
B(5,28,6,1)
B(5,28,7,1)
B(5,28,8,1)
B(5,29,5,1)
B(5,29,6,1)
B(5,29,7,1)
B(5,29,8,1)
B(5,30,6,1)
B(5,30,7,1)
B(5,30,8,1)
B(5,31,6,1)
B(5,31,7,1)
B(6,17,6,1)
B(6,17,7,1)
B(6,18,6,1)
B(6,18,7,1)
B(6,18,8,1)
B(6,19,5,1)
B(6,19,6,1)
B(6,19,7,1)
B(6,19,8,1)
B(6,20,4,1)
B(6,20,5,1)
B(6,20,6,1)
B(6,20,7,1)
B(6,20,8,1)
B(6,21,4,1)
B(6,21,5,1)
B(6,21,6,1)
B(6,21,7,1)
B(6,21,8,1)
B(6,22,2,1)
B(6,22,3,1)
B(6,22,4,1)
B(6,22,5,1)
B(6,22,6,1)
B(6,22,7,1)
B(6,22,8,1)
B(6,23,2,1)
B(6,23,3,1)
B(6,23,4,1)
B(6,23,5,1)
B(6,23,6,1)
B(6,23,7,1)
B(6,23,8,1)
B(6,24,3,1)
B(6,24,4,1)
B(6,24,5,1)
B(6,24,6,1)
B(6,24,7,1)
B(6,24,8,1)
B(6,25,5,1)
B(6,25,6,1)
B(6,25,7,1)
B(6,25,8,1)
B(6,26,5,1)
B(6,26,6,1)
B(6,26,7,1)
B(6,26,8,1)
B(6,27,6,1)
B(6,27,7,1)
B(6,27,8,1)
B(7,20,6,1)
B(7,20,7,1)
B(7,21,5,1)
B(7,21,6,1)
B(7,21,7,1)
B(7,22,4,1)
B(7,22,5,1)
B(7,22,6,1)
B(7,22,7,1)
B(7,22,8,1)
B(7,23,6,1)
B(7,23,7,1)
B(7,23,8,1)
B(7,24,7,1)
B(7,24,8,1)

# 

#######################################################################
# +-----------------------------------------------------------------+ #
# |                            BO3 checks                           | #
# +-----------------------------------------------------------------+ #
#######################################################################

# Require a condition at a certain location in order for the BO3 to be spawned.
# BlockCheck(x,y,z,BlockName[,BlockName[,...]]) - one of the blocks must be at the location
# BlockCheckNot(x,y,z,BlockName[,BlockName[,...]]) - all the blocks must not be at the location
# LightCheck(x,y,z,minLightLevel,maxLightLevel) - light must be between min and max (inclusive)

# You can use "Solid" as a BlockName for matching all solid blocks or "All" to match all blocks that aren't air.

# Examples:
#   BlockCheck(0,-1,0,GRASS,DIRT,biomesoplenty:grass:0,biomesoplenty:grass:1,biomesoplenty:grass:2,biomesoplenty:grass:3,biomesoplenty:grass:4,biomesoplenty:grass:5,biomesoplenty:grass:6,biomesoplenty:grass:7,biomesoplenty:dirt:0,biomesoplenty:dirt:1,biomesoplenty:dirt:2,biomesoplenty:dirt:3,biomesoplenty:dirt:4,biomesoplenty:dirt:5,biomesoplenty:dirt:6,biomesoplenty:dirt:7,biomesoplenty:dirt:8,biomesoplenty:dirt:9,biomesoplenty:dirt:10,biomesoplenty:dried_sand:0,biomesoplenty:hard_ice:0,biomesoplenty:white_sand:0,biomesoplenty:white_sandstone:0,biomesoplenty:mud:0,biomesoplenty:ash_block:0)  Require grass or dirt just below the object
#   BlockCheck(0,-1,0,Solid)       Require any solid block just below the object
#   BlockCheck(0,-1,0,WOOL)        Require any type of wool just below the object
#   BlockCheck(0,-1,0,WOOL:0)      Require white wool just below the object
#   BlockCheckNot(0,0,0,WOOL:0)   Require that there is no white wool below the object
#   LightCheck(0,0,0,0,1)          Require almost complete darkness just below the object

#######################################################################
# +-----------------------------------------------------------------+ #
# |                             Branches                            | #
# +-----------------------------------------------------------------+ #
#######################################################################

# Branches are objects that will spawn when this object spawns when it is used in
# the CustomStructure resource. Branches can also have branches, making complex
# structures possible. See the wiki for more details.

# Regular Branches spawn each branch with an independent chance of spawning.
# Branch(x,y,z,branchName,rotation,chance[,anotherBranchName,rotation,chance[,...]][IndividualChance])
# branchName - name of the object to spawn.
# rotation - NORTH, SOUTH, EAST or WEST.
# IndividualChance - The chance each branch has to spawn, assumed to be 100 when left blank

# WBR(x,y,z,branchName,rotation,chance[,anotherBranchName,rotation,chance[,...]][MaxChanceOutOf])
# MaxChanceOutOf - The chance all branches have to spawn out of, assumed to be 100 when left blank
Branch(0,0,16,patchyrocksmallC0R1,NORTH,100)