
#######################################################################
# +-----------------------------------------------------------------+ #
# |                            BO3 object                           | #
# +-----------------------------------------------------------------+ #
#######################################################################

Author: LordSmellyPants

Description: No description given

Version: 3

SettingsMode: WriteWithoutComments


#######################################################################
# +-----------------------------------------------------------------+ #
# |                          Main settings                          | #
# +-----------------------------------------------------------------+ #
#######################################################################

Tree: false

Frequency: 1

Rarity: 10.0

RotateRandomly: true

SpawnHeight: randomY

SpawnHeightOffset: 0

SpawnHeightVariance: 0

##############################
# Height Limits for the BO3. #
##############################

MinHeight: 30

MaxHeight: 33

######################
# Extrusion settings #
######################

ExtrudeMode: None

ExtrudeThroughBlocks: AIR

MaxBranchDepth: 10

ExcludedBiomes: All


#######################################################################
# +-----------------------------------------------------------------+ #
# |                      Source block settings                      | #
# +-----------------------------------------------------------------+ #
#######################################################################

SourceBlocks: AIR

MaxPercentageOutsideSourceBlock: 50

OutsideSourceBlock: placeAnyway


#######################################################################
# +-----------------------------------------------------------------+ #
# |                              Blocks                             | #
# +-----------------------------------------------------------------+ #
#######################################################################

B(-2,-1,-1,SANDSTONE)
B(-2,-1,0,SANDSTONE)
B(-2,-1,1,SANDSTONE)
B(-2,-1,2,SANDSTONE)
B(-2,-1,3,SANDSTONE)
B(-2,0,-1,SANDSTONE)
B(-2,0,0,SANDSTONE)
B(-2,0,1,SANDSTONE)
B(-2,0,2,AIR)
B(-2,0,3,SANDSTONE)
B(-2,1,-1,SANDSTONE)
B(-2,1,0,STEP:9)
B(-2,1,1,SANDSTONE)
B(-2,1,2,AIR)
B(-2,1,3,SANDSTONE)
B(-2,2,-1,SANDSTONE)
B(-2,2,0,SANDSTONE)
B(-2,2,1,SANDSTONE)
B(-2,2,2,STEP:9)
B(-2,2,3,SANDSTONE)
B(-2,3,-1,STAINED_CLAY:1)
B(-2,3,0,STAINED_CLAY:1)
B(-2,3,1,SANDSTONE)
B(-2,3,2,STAINED_CLAY:1)
B(-2,3,3,STAINED_CLAY:1)
B(-1,-1,-1,SANDSTONE)
B(-1,-1,0,SANDSTONE)
B(-1,-1,1,SANDSTONE)
B(-1,-1,2,SANDSTONE)
B(-1,-1,3,SANDSTONE)
B(-1,0,-1,SANDSTONE)
RB(-1,0,0,FURNACE:4,../../Structures/nbt/Misc/Furnace.nbt,30,FURNACE,../../Structures/nbt/Misc/Furnace2.nbt,30,FURNACE,../../Structures/nbt/Misc/Furnace3.nbt,100)
B(-1,0,1,AIR)
B(-1,0,2,AIR)
B(-1,0,3,SANDSTONE)
B(-1,1,-1,SANDSTONE)
B(-1,1,0,STEP:9)
B(-1,1,1,AIR)
B(-1,1,2,AIR)
B(-1,1,3,STEP:1)
B(-1,2,-1,SANDSTONE)
B(-1,2,0,BOOKSHELF)
B(-1,2,1,AIR)
B(-1,2,2,AIR)
B(-1,2,3,SANDSTONE)
B(-1,3,-1,STAINED_CLAY:1)
B(-1,3,0,STAINED_CLAY:1)
B(-1,3,1,STAINED_CLAY:1)
B(-1,3,2,STAINED_CLAY:1)
B(-1,3,3,STAINED_CLAY:1)
B(0,-1,-1,SANDSTONE)
B(0,-1,0,SANDSTONE)
B(0,-1,1,SANDSTONE)
B(0,-1,2,SANDSTONE)
B(0,-1,3,SANDSTONE)
B(0,0,-1,SANDSTONE)
B(0,0,0,SANDSTONE)
B(0,0,1,AIR)
B(0,0,2,AIR)
B(0,0,3,SANDSTONE)
B(0,1,-1,SANDSTONE)
B(0,1,0,SANDSTONE)
B(0,1,1,AIR)
B(0,1,2,AIR)
B(0,1,3,SANDSTONE)
B(0,2,-1,SANDSTONE)
B(0,2,0,SKULL:1)
B(0,2,1,AIR)
B(0,2,2,AIR)
B(0,2,3,SANDSTONE)
B(0,3,-1,SANDSTONE)
B(0,3,0,STAINED_CLAY:1)
B(0,3,1,STAINED_CLAY:1)
B(0,3,2,STAINED_CLAY:1)
B(0,3,3,SANDSTONE)
B(1,-1,-1,SANDSTONE)
B(1,-1,0,SANDSTONE)
B(1,-1,1,SANDSTONE)
B(1,-1,2,SANDSTONE)
B(1,-1,3,SANDSTONE)
B(1,0,-1,SANDSTONE)
RB(1,0,0,MOB_SPAWNER,../../Structures/nbt/Spawner/Skeleton.nbt,50,MOB_SPAWNER,../../Structures/nbt/Spawner/Zombie.nbt,100)
B(1,0,1,AIR)
B(1,0,2,AIR)
B(1,0,3,SANDSTONE)
B(1,1,-1,STEP:9)
B(1,1,0,AIR)
B(1,1,1,AIR)
B(1,1,2,AIR)
B(1,1,3,SANDSTONE)
B(1,2,-1,SANDSTONE)
B(1,2,0,AIR)
B(1,2,1,AIR)
B(1,2,2,AIR)
B(1,2,3,STEP:9)
B(1,3,-1,SANDSTONE)
B(1,3,0,STAINED_CLAY:1)
B(1,3,1,STAINED_CLAY:1)
B(1,3,2,STAINED_CLAY:1)
B(1,3,3,SANDSTONE)
B(2,-1,-1,SANDSTONE)
B(2,-1,0,SANDSTONE)
B(2,-1,1,SANDSTONE)
B(2,-1,2,SANDSTONE)
B(2,-1,3,SANDSTONE)
B(2,0,-1,SANDSTONE)
B(2,0,0,AIR)
B(2,0,1,AIR)
B(2,0,2,AIR)
B(2,0,3,SANDSTONE)
B(2,1,-1,SANDSTONE)
B(2,1,0,AIR)
B(2,1,1,AIR)
B(2,1,2,AIR)
B(2,1,3,SANDSTONE)
B(2,2,-1,SANDSTONE)
B(2,2,0,AIR)
B(2,2,1,AIR)
B(2,2,2,AIR)
B(2,2,3,SANDSTONE)
B(2,3,-1,STAINED_CLAY:1)
B(2,3,0,STAINED_CLAY:1)
B(2,3,1,STAINED_CLAY:1)
B(2,3,2,STAINED_CLAY:1)
B(2,3,3,STAINED_CLAY:1)
B(3,-1,-1,SANDSTONE)
B(3,-1,0,SANDSTONE)
B(3,-1,1,SANDSTONE)
B(3,-1,2,SANDSTONE)
B(3,-1,3,SANDSTONE)
B(3,0,-1,SANDSTONE)
B(3,0,0,SANDSTONE)
B(3,0,1,SANDSTONE)
B(3,0,2,SANDSTONE)
B(3,0,3,SANDSTONE)
B(3,1,-1,SANDSTONE)
B(3,1,0,SANDSTONE)
B(3,1,1,SANDSTONE)
B(3,1,2,SANDSTONE)
B(3,1,3,SANDSTONE)
B(3,2,-1,SANDSTONE)
B(3,2,0,SANDSTONE)
B(3,2,1,STEP:1)
B(3,2,2,SANDSTONE)
B(3,2,3,SANDSTONE)
B(3,3,-1,STAINED_CLAY:1)
B(3,3,0,STAINED_CLAY:1)
B(3,3,1,SANDSTONE)
B(3,3,2,STAINED_CLAY:1)
B(3,3,3,STAINED_CLAY:1)

#######################################################################
# +-----------------------------------------------------------------+ #
# |                            BO3 checks                           | #
# +-----------------------------------------------------------------+ #
#######################################################################

BlockCheck(0,-1,0,SAND,SANDSTONE)
BlockCheck(0,1,0,AIR)

#######################################################################
# +-----------------------------------------------------------------+ #
# |                             Branches                            | #
# +-----------------------------------------------------------------+ #
#######################################################################


#######################################################################
# +-----------------------------------------------------------------+ #
# |                         EntityFunctions                         | #
# +-----------------------------------------------------------------+ #
#######################################################################

