
#######################################################################
# +-----------------------------------------------------------------+ #
# |                            BO3 object                           | #
# +-----------------------------------------------------------------+ #
#######################################################################

Author: LordSmellyPants

Description: No description given

Version: 3

SettingsMode: WriteWithoutComments


#######################################################################
# +-----------------------------------------------------------------+ #
# |                          Main settings                          | #
# +-----------------------------------------------------------------+ #
#######################################################################

Tree: true

Frequency: 1

Rarity: 100.0

RotateRandomly: true

SpawnHeight: highestSolidBlock

SpawnHeightOffset: 0

SpawnHeightVariance: 0

##############################
# Height Limits for the BO3. #
##############################

MinHeight: 63

MaxHeight: 70

######################
# Extrusion settings #
######################

ExtrudeMode: None

ExtrudeThroughBlocks: AIR

MaxBranchDepth: 10

ExcludedBiomes: All


#######################################################################
# +-----------------------------------------------------------------+ #
# |                      Source block settings                      | #
# +-----------------------------------------------------------------+ #
#######################################################################

SourceBlocks: AIR

MaxPercentageOutsideSourceBlock: 0

OutsideSourceBlock: placeAnyway

DoReplaceBlocks: true

IsOTGPlus: false


#######################################################################
# +-----------------------------------------------------------------+ #
# |                              Blocks                             | #
# +-----------------------------------------------------------------+ #
#######################################################################

Block(-14,5,2,LEAVES:1)
Block(-14,6,2,LEAVES:1)
Block(-14,6,4,LEAVES:1)
Block(-14,7,3,LEAVES:1)
Block(-13,5,5,LEAVES:1)
Block(-13,6,1,LEAVES:1)
Block(-13,6,3,LEAVES:1)
Block(-13,7,2,LEAVES:1)
Block(-13,7,3,LEAVES:1)
Block(-13,7,4,LEAVES:1)
Block(-13,8,3,LEAVES:1)
Block(-13,19,2,LEAVES:1)
Block(-12,6,2,LEAVES:1)
Block(-12,6,4,LEAVES:1)
Block(-12,7,2,LEAVES:1)
Block(-12,7,3,LEAVES:1)
Block(-12,7,4,LEAVES:1)
Block(-12,8,3,LEAVES:1)
Block(-12,18,3,LEAVES:1)
Block(-12,19,1,LEAVES:1)
Block(-12,19,3,LEAVES:1)
Block(-12,20,2,LEAVES:1)
Block(-11,6,1,LEAVES:1)
Block(-11,6,5,LEAVES:1)
Block(-11,7,1,LEAVES:1)
Block(-11,7,2,LEAVES:1)
Block(-11,7,3,LOG:13)
Block(-11,7,4,LEAVES:1)
Block(-11,8,-3,LEAVES:1)
Block(-11,8,2,LEAVES:1)
Block(-11,8,3,LEAVES:1)
Block(-11,14,-5,LEAVES:1)
Block(-11,15,-4,LEAVES:1)
Block(-11,18,0,LEAVES:1)
Block(-11,19,2,LEAVES:1)
Block(-11,19,4,LEAVES:1)
Block(-11,20,1,LEAVES:1)
Block(-11,20,2,LEAVES:1)
Block(-11,20,3,LEAVES:1)
Block(-11,21,2,LEAVES:1)
Block(-10,6,3,LEAVES:1)
Block(-10,7,-3,LEAVES:1)
Block(-10,7,0,LEAVES:1)
Block(-10,7,2,LEAVES:1)
Block(-10,7,3,LEAVES:1)
Block(-10,7,4,LEAVES:1)
Block(-10,7,5,LEAVES:1)
Block(-10,8,-4,LEAVES:1)
Block(-10,8,-3,LEAVES:1)
Block(-10,8,-2,LEAVES:1)
Block(-10,8,1,LEAVES:1)
Block(-10,8,2,LOG:13)
Block(-10,8,3,LEAVES:1)
Block(-10,8,4,LEAVES:1)
Block(-10,9,-3,LEAVES:1)
Block(-10,9,2,LEAVES:1)
Block(-10,9,3,LEAVES:1)
Block(-10,13,-3,LEAVES:1)
Block(-10,14,-6,LEAVES:1)
Block(-10,14,-4,LEAVES:1)
Block(-10,15,-5,LEAVES:1)
Block(-10,15,-4,LEAVES:1)
Block(-10,15,-3,LEAVES:1)
Block(-10,16,-4,LEAVES:1)
Block(-10,18,2,LEAVES:1)
Block(-10,19,1,LEAVES:1)
Block(-10,19,2,LEAVES:1)
Block(-10,20,1,LEAVES:1)
Block(-10,20,2,LEAVES:1)
Block(-10,20,3,LEAVES:1)
Block(-10,20,4,LEAVES:1)
Block(-10,21,2,LEAVES:1)
Block(-10,21,3,LEAVES:1)
Block(-9,6,5,LEAVES:1)
Block(-9,7,-3,LEAVES:1)
Block(-9,7,-1,LEAVES:1)
Block(-9,7,4,LEAVES:1)
Block(-9,8,-4,LEAVES:1)
Block(-9,8,-3,LOG:13)
Block(-9,8,-2,LEAVES:1)
Block(-9,8,-1,LEAVES:1)
Block(-9,8,1,LEAVES:1)
Block(-9,8,2,LOG:13)
Block(-9,8,3,LEAVES:1)
Block(-9,9,-3,LEAVES:1)
Block(-9,9,-2,LEAVES:1)
Block(-9,9,2,LEAVES:1)
Block(-9,9,3,LEAVES:1)
Block(-9,11,10,LEAVES:1)
Block(-9,12,8,LEAVES:1)
Block(-9,13,9,LEAVES:1)
Block(-9,13,10,LEAVES:1)
Block(-9,14,-3,LEAVES:1)
Block(-9,14,-1,LEAVES:1)
Block(-9,15,-5,LEAVES:1)
Block(-9,15,-4,LOG:13)
Block(-9,15,-3,LEAVES:1)
Block(-9,15,-2,LEAVES:1)
Block(-9,16,-4,LEAVES:1)
Block(-9,16,-3,LEAVES:1)
Block(-9,19,0,LEAVES:1)
Block(-9,19,2,LEAVES:1)
Block(-9,19,4,LEAVES:1)
Block(-9,20,1,LEAVES:1)
Block(-9,20,2,LOG:13)
Block(-9,20,3,LEAVES:1)
Block(-9,21,1,LEAVES:1)
Block(-9,21,2,LEAVES:1)
Block(-9,21,3,LEAVES:1)
Block(-9,22,2,LEAVES:1)
Block(-8,8,-4,LEAVES:1)
Block(-8,8,0,LEAVES:1)
Block(-8,8,2,LEAVES:1)
Block(-8,8,3,LEAVES:1)
Block(-8,9,-3,LEAVES:1)
Block(-8,9,-2,LOG:13)
Block(-8,9,-1,LEAVES:1)
Block(-8,9,1,LEAVES:1)
Block(-8,9,2,LOG:13)
Block(-8,9,3,LEAVES:1)
Block(-8,9,4,LEAVES:1)
Block(-8,10,-2,LEAVES:1)
Block(-8,10,-1,LEAVES:1)
Block(-8,10,2,LEAVES:1)
Block(-8,10,3,LEAVES:1)
Block(-8,12,10,LEAVES:1)
Block(-8,13,6,LEAVES:1)
Block(-8,13,8,LEAVES:1)
Block(-8,13,9,LOG:13)
Block(-8,13,10,LEAVES:1)
Block(-8,13,11,LEAVES:1)
Block(-8,14,-5,LEAVES:1)
Block(-8,14,7,LEAVES:1)
Block(-8,14,8,LEAVES:1)
Block(-8,14,9,LEAVES:1)
Block(-8,14,10,LEAVES:1)
Block(-8,15,-4,LEAVES:1)
Block(-8,15,-1,LEAVES:1)
Block(-8,16,-4,LEAVES:1)
Block(-8,16,-3,LOG:13)
Block(-8,16,-2,LEAVES:1)
Block(-8,17,-3,LEAVES:1)
Block(-8,20,2,LEAVES:1)
Block(-8,20,4,LEAVES:1)
Block(-8,21,1,LEAVES:1)
Block(-8,21,2,LOG:13)
Block(-8,21,3,LEAVES:1)
Block(-8,22,2,LEAVES:1)
Block(-7,7,-5,LEAVES:1)
Block(-7,8,-3,LEAVES:1)
Block(-7,8,-1,LEAVES:1)
Block(-7,8,1,LEAVES:1)
Block(-7,8,4,LEAVES:1)
Block(-7,9,-4,LEAVES:1)
Block(-7,9,-3,LEAVES:1)
Block(-7,9,-2,LOG:13)
Block(-7,9,-1,LEAVES:1)
Block(-7,9,0,LEAVES:1)
Block(-7,9,1,LOG:13)
Block(-7,9,2,LEAVES:1)
Block(-7,9,3,LEAVES:1)
Block(-7,10,-3,LEAVES:1)
Block(-7,10,-2,LEAVES:1)
Block(-7,10,-1,LEAVES:1)
Block(-7,10,0,LEAVES:1)
Block(-7,10,1,LEAVES:1)
Block(-7,11,-1,LEAVES:1)
Block(-7,11,9,LEAVES:1)
Block(-7,12,11,LEAVES:1)
Block(-7,13,7,LEAVES:1)
Block(-7,13,9,LEAVES:1)
Block(-7,13,10,LEAVES:1)
Block(-7,14,6,LEAVES:1)
Block(-7,14,7,LEAVES:1)
Block(-7,14,8,LOG:13)
Block(-7,14,9,LEAVES:1)
Block(-7,15,-4,LEAVES:1)
Block(-7,15,-2,LEAVES:1)
Block(-7,15,7,LEAVES:1)
Block(-7,15,8,LEAVES:1)
Block(-7,16,-5,LEAVES:1)
Block(-7,16,-4,LEAVES:1)
Block(-7,16,-3,LOG:13)
Block(-7,16,-2,LEAVES:1)
Block(-7,16,-1,LEAVES:1)
Block(-7,17,-4,LEAVES:1)
Block(-7,17,-3,LEAVES:1)
Block(-7,17,-2,LEAVES:1)
Block(-7,17,-1,LEAVES:1)
Block(-7,18,-2,LEAVES:1)
Block(-7,19,3,LEAVES:1)
Block(-7,20,0,LEAVES:1)
Block(-7,20,3,LEAVES:1)
Block(-7,21,1,LEAVES:1)
Block(-7,21,2,LOG:13)
Block(-7,21,3,LEAVES:1)
Block(-7,21,4,LEAVES:1)
Block(-7,22,2,LEAVES:1)
Block(-7,22,3,LEAVES:1)
Block(-6,7,0,LEAVES:1)
Block(-6,8,-4,LEAVES:1)
Block(-6,8,1,LEAVES:1)
Block(-6,8,2,LEAVES:1)
Block(-6,9,-3,LEAVES:1)
Block(-6,9,-1,LEAVES:1)
Block(-6,9,1,LEAVES:1)
Block(-6,9,2,LEAVES:1)
Block(-6,9,3,LEAVES:1)
Block(-6,10,-2,LEAVES:1)
Block(-6,10,-1,LOG:13)
Block(-6,10,0,LOG:13)
Block(-6,10,1,LEAVES:1)
Block(-6,10,2,LEAVES:1)
Block(-6,11,-1,LEAVES:1)
Block(-6,11,0,LEAVES:1)
Block(-6,11,1,LEAVES:1)
Block(-6,12,9,LEAVES:1)
Block(-6,13,5,LEAVES:1)
Block(-6,13,8,LEAVES:1)
Block(-6,14,-4,LEAVES:1)
Block(-6,14,6,LEAVES:1)
Block(-6,14,7,LOG:13)
Block(-6,14,8,LEAVES:1)
Block(-6,14,9,LEAVES:1)
Block(-6,15,-5,LEAVES:1)
Block(-6,15,0,LEAVES:1)
Block(-6,15,5,LEAVES:1)
Block(-6,15,6,LEAVES:1)
Block(-6,15,7,LEAVES:1)
Block(-6,15,8,LEAVES:1)
Block(-6,16,-4,LEAVES:1)
Block(-6,16,-3,LEAVES:1)
Block(-6,16,0,LEAVES:1)
Block(-6,17,-3,LEAVES:1)
Block(-6,17,-2,LOG:13)
Block(-6,17,-1,LEAVES:1)
Block(-6,18,-2,LEAVES:1)
Block(-6,21,3,LEAVES:1)
Block(-6,22,0,LEAVES:1)
Block(-6,22,1,LEAVES:1)
Block(-6,22,2,LOG:13)
Block(-6,22,3,LEAVES:1)
Block(-6,23,-3,LEAVES:1)
Block(-6,23,1,LEAVES:1)
Block(-6,23,2,LEAVES:1)
Block(-5,-7,-3,LOG:1)
Block(-5,-7,1,LOG:1)
Block(-5,-6,-3,LOG:13)
Block(-5,-6,1,LOG:13)
Block(-5,8,-3,LEAVES:1)
Block(-5,8,0,LEAVES:1)
Block(-5,8,3,LEAVES:1)
Block(-5,9,-2,LEAVES:1)
Block(-5,9,0,LEAVES:1)
Block(-5,9,2,LEAVES:1)
Block(-5,10,-1,LEAVES:1)
Block(-5,10,0,LOG:13)
Block(-5,10,1,LEAVES:1)
Block(-5,11,0,LEAVES:1)
Block(-5,12,8,LEAVES:1)
Block(-5,14,5,LEAVES:1)
Block(-5,14,6,LEAVES:1)
Block(-5,14,7,LEAVES:1)
Block(-5,14,8,LEAVES:1)
Block(-5,15,-2,LEAVES:1)
Block(-5,15,4,LEAVES:1)
Block(-5,15,5,LEAVES:1)
Block(-5,15,6,LOG:13)
Block(-5,15,7,LEAVES:1)
Block(-5,16,-2,LEAVES:1)
Block(-5,16,-1,LEAVES:1)
Block(-5,16,5,LEAVES:1)
Block(-5,16,6,LEAVES:1)
Block(-5,17,-3,LEAVES:1)
Block(-5,17,-2,LOG:13)
Block(-5,17,-1,LEAVES:1)
Block(-5,17,0,LEAVES:1)
Block(-5,18,-7,LEAVES:1)
Block(-5,18,-2,LEAVES:1)
Block(-5,18,-1,LEAVES:1)
Block(-5,19,-6,LEAVES:1)
Block(-5,19,5,LEAVES:1)
Block(-5,20,3,LEAVES:1)
Block(-5,21,0,LEAVES:1)
Block(-5,21,2,LEAVES:1)
Block(-5,22,-4,LEAVES:1)
Block(-5,22,-1,LEAVES:1)
Block(-5,22,0,LEAVES:1)
Block(-5,22,1,LEAVES:1)
Block(-5,22,2,LOG:13)
Block(-5,22,3,LEAVES:1)
Block(-5,23,-2,LEAVES:1)
Block(-5,23,0,LEAVES:1)
Block(-5,23,1,LEAVES:1)
Block(-5,23,2,LEAVES:1)
Block(-5,24,-4,LEAVES:1)
Block(-5,24,-3,LEAVES:1)
Block(-5,24,-1,LEAVES:1)
Block(-5,24,1,LEAVES:1)
Block(-5,25,-2,LEAVES:1)
Block(-5,28,0,LEAVES:1)
Block(-4,-7,-3,LOG:1)
Block(-4,-7,-1,LOG:1)
Block(-4,-7,2,LOG:1)
Block(-4,-7,3,LOG:1)
Block(-4,-6,-3,LOG:13)
Block(-4,-6,-1,LOG:13)
Block(-4,-6,2,LOG:13)
Block(-4,-6,3,LOG:13)
Block(-4,-5,-3,LOG:1)
Block(-4,-5,2,LOG:13)
Block(-4,-4,2,LOG:1)
Block(-4,6,-11,LEAVES:1)
Block(-4,7,-13,LEAVES:1)
Block(-4,7,-11,LEAVES:1)
Block(-4,7,-10,LEAVES:1)
Block(-4,8,-12,LEAVES:1)
Block(-4,8,-8,LEAVES:1)
Block(-4,8,10,LEAVES:1)
Block(-4,9,-9,LEAVES:1)
Block(-4,9,-1,LEAVES:1)
Block(-4,9,1,LEAVES:1)
Block(-4,10,-2,LEAVES:1)
Block(-4,10,-1,LEAVES:1)
Block(-4,10,0,LOG:13)
Block(-4,10,1,LEAVES:1)
Block(-4,11,-1,LEAVES:1)
Block(-4,11,0,LEAVES:1)
Block(-4,11,1,LEAVES:1)
Block(-4,13,7,LEAVES:1)
Block(-4,14,3,LEAVES:1)
Block(-4,14,7,LEAVES:1)
Block(-4,15,4,LEAVES:1)
Block(-4,15,5,LOG:13)
Block(-4,15,6,LEAVES:1)
Block(-4,16,-3,LEAVES:1)
Block(-4,16,3,LEAVES:1)
Block(-4,16,4,LEAVES:1)
Block(-4,16,5,LEAVES:1)
Block(-4,17,-1,LEAVES:1)
Block(-4,17,1,LEAVES:1)
Block(-4,18,-2,LEAVES:1)
Block(-4,18,-1,LOG:13)
Block(-4,18,0,LEAVES:1)
Block(-4,19,-7,LEAVES:1)
Block(-4,19,-6,LEAVES:1)
Block(-4,19,-5,LEAVES:1)
Block(-4,19,-1,LEAVES:1)
Block(-4,19,7,LEAVES:1)
Block(-4,20,-6,LEAVES:1)
Block(-4,20,4,LEAVES:1)
Block(-4,20,5,LEAVES:1)
Block(-4,21,3,LEAVES:1)
Block(-4,22,-1,LEAVES:1)
Block(-4,22,0,LEAVES:1)
Block(-4,22,1,LEAVES:1)
Block(-4,22,2,LEAVES:1)
Block(-4,23,-4,LEAVES:1)
Block(-4,23,0,LEAVES:1)
Block(-4,23,1,LOG:13)
Block(-4,23,2,LEAVES:1)
Block(-4,24,-5,LEAVES:1)
Block(-4,24,-4,LEAVES:1)
Block(-4,24,-3,LOG:13)
Block(-4,24,-2,LEAVES:1)
Block(-4,24,1,LEAVES:1)
Block(-4,25,-4,LEAVES:1)
Block(-4,25,-3,LEAVES:1)
Block(-4,25,-2,LOG:13)
Block(-4,25,-1,LEAVES:1)
Block(-4,26,-2,LEAVES:1)
Block(-4,26,-1,LEAVES:1)
Block(-4,28,1,LEAVES:1)
Block(-4,29,0,LEAVES:1)
Block(-4,32,0,LEAVES:1)
Block(-3,-7,-2,LOG:1)
Block(-3,-7,0,LOG:1)
Block(-3,-7,1,LOG:1)
Block(-3,-7,2,LOG:1)
Block(-3,-6,-2,LOG:13)
Block(-3,-6,0,LOG:13)
Block(-3,-6,1,LOG:13)
Block(-3,-6,2,LOG:13)
Block(-3,-5,-2,LOG:13)
Block(-3,-5,0,LOG:13)
Block(-3,-5,1,LOG:13)
Block(-3,-4,-2,LOG:1)
Block(-3,-4,1,LOG:13)
Block(-3,-3,1,LOG:13)
Block(-3,6,-14,LEAVES:1)
Block(-3,7,-12,LEAVES:1)
Block(-3,7,11,LEAVES:1)
Block(-3,8,-13,LEAVES:1)
Block(-3,8,-12,LEAVES:1)
Block(-3,8,-11,LEAVES:1)
Block(-3,8,-10,LEAVES:1)
Block(-3,8,-7,LEAVES:1)
Block(-3,8,9,LEAVES:1)
Block(-3,8,11,LEAVES:1)
Block(-3,9,-12,LEAVES:1)
Block(-3,9,-10,LEAVES:1)
Block(-3,9,-9,LEAVES:1)
Block(-3,9,-8,LEAVES:1)
Block(-3,9,-5,LEAVES:1)
Block(-3,9,-2,LEAVES:1)
Block(-3,9,0,LEAVES:1)
Block(-3,9,7,LEAVES:1)
Block(-3,9,9,LEAVES:1)
Block(-3,9,10,LEAVES:1)
Block(-3,10,-9,LEAVES:1)
Block(-3,10,-6,LEAVES:1)
Block(-3,10,-1,LEAVES:1)
Block(-3,10,0,LEAVES:1)
Block(-3,10,2,LEAVES:1)
Block(-3,11,-1,LEAVES:1)
Block(-3,11,0,LOG:13)
Block(-3,11,1,LEAVES:1)
Block(-3,12,0,LEAVES:1)
Block(-3,13,5,LEAVES:1)
Block(-3,14,5,LEAVES:1)
Block(-3,14,6,LEAVES:1)
Block(-3,15,2,LEAVES:1)
Block(-3,15,3,LEAVES:1)
Block(-3,15,5,LEAVES:1)
Block(-3,15,6,LEAVES:1)
Block(-3,15,7,LEAVES:1)
Block(-3,16,-2,LEAVES:1)
Block(-3,16,2,LEAVES:1)
Block(-3,16,3,LEAVES:1)
Block(-3,16,4,LOG:13)
Block(-3,16,5,LEAVES:1)
Block(-3,16,6,LEAVES:1)
Block(-3,17,-2,LEAVES:1)
Block(-3,17,-1,LEAVES:1)
Block(-3,17,3,LEAVES:1)
Block(-3,17,4,LEAVES:1)
Block(-3,17,5,LEAVES:1)
Block(-3,18,-4,LEAVES:1)
Block(-3,18,-2,LEAVES:1)
Block(-3,18,-1,LEAVES:1)
Block(-3,18,0,LOG:13)
Block(-3,18,1,LEAVES:1)
Block(-3,18,6,LEAVES:1)
Block(-3,18,8,LEAVES:1)
Block(-3,18,10,LEAVES:1)
Block(-3,19,-8,LEAVES:1)
Block(-3,19,-7,LEAVES:1)
Block(-3,19,-6,LOG:13)
Block(-3,19,-5,LEAVES:1)
Block(-3,19,-1,LEAVES:1)
Block(-3,19,0,LEAVES:1)
Block(-3,19,5,LEAVES:1)
Block(-3,19,6,LEAVES:1)
Block(-3,19,8,LEAVES:1)
Block(-3,19,9,LEAVES:1)
Block(-3,20,-7,LEAVES:1)
Block(-3,20,-6,LEAVES:1)
Block(-3,20,-5,LEAVES:1)
Block(-3,20,-3,LEAVES:1)
Block(-3,20,4,LEAVES:1)
Block(-3,20,5,LEAVES:1)
Block(-3,20,6,LEAVES:1)
Block(-3,20,7,LEAVES:1)
Block(-3,21,-4,LEAVES:1)
Block(-3,21,-1,LEAVES:1)
Block(-3,21,2,LEAVES:1)
Block(-3,21,5,LEAVES:1)
Block(-3,22,1,LEAVES:1)
Block(-3,22,2,LEAVES:1)
Block(-3,23,-5,LEAVES:1)
Block(-3,23,-1,LEAVES:1)
Block(-3,23,0,LEAVES:1)
Block(-3,23,1,LOG:13)
Block(-3,23,2,LEAVES:1)
Block(-3,23,3,LEAVES:1)
Block(-3,24,-4,LEAVES:1)
Block(-3,24,-3,LEAVES:1)
Block(-3,24,1,LEAVES:1)
Block(-3,24,2,LEAVES:1)
Block(-3,25,-3,LEAVES:1)
Block(-3,25,-2,LEAVES:1)
Block(-3,25,1,LEAVES:1)
Block(-3,26,-3,LEAVES:1)
Block(-3,26,-2,LEAVES:1)
Block(-3,26,-1,LOG:13)
Block(-3,26,0,LEAVES:1)
Block(-3,27,-2,LEAVES:1)
Block(-3,27,-1,LEAVES:1)
Block(-3,28,-2,LEAVES:1)
Block(-3,28,0,LEAVES:1)
Block(-3,29,-1,LEAVES:1)
Block(-3,29,0,LOG:13)
Block(-3,29,1,LEAVES:1)
Block(-3,30,0,LEAVES:1)
Block(-3,31,-2,LEAVES:1)
Block(-3,32,2,LEAVES:1)
Block(-3,33,0,LEAVES:1)
Block(-3,34,1,LEAVES:1)
Block(-2,-7,-4,LOG:1)
Block(-2,-7,-3,LOG:1)
Block(-2,-7,3,LOG:1)
Block(-2,-6,-4,LOG:13)
Block(-2,-6,-3,LOG:13)
Block(-2,-6,-2,LOG:13)
Block(-2,-6,-1,LOG:13)
Block(-2,-6,0,LOG:13)
Block(-2,-6,1,LOG:13)
Block(-2,-6,2,LOG:13)
Block(-2,-6,3,LOG:13)
Block(-2,-5,-3,LOG:13)
Block(-2,-5,-2,LOG:13)
Block(-2,-5,-1,LOG:13)
Block(-2,-5,0,LOG:13)
Block(-2,-5,1,LOG:13)
Block(-2,-5,2,LOG:13)
Block(-2,-5,3,LOG:9)
Block(-2,-4,-3,LOG:1)
Block(-2,-4,-2,LOG:13)
Block(-2,-4,-1,LOG:13)
Block(-2,-4,0,LOG:13)
Block(-2,-4,1,LOG:13)
Block(-2,-4,2,LOG:1)
Block(-2,-3,-1,LOG:13)
Block(-2,-3,0,LOG:13)
Block(-2,-3,1,LOG:13)
Block(-2,-2,-1,LOG:13)
Block(-2,-2,0,LOG:13)
Block(-2,-2,1,LOG:13)
Block(-2,-1,-1,LOG:13)
Block(-2,-1,0,LOG:13)
Block(-2,-1,1,LOG:13)
Block(-2,0,0,LOG:13)
Block(-2,0,1,LOG:13)
Block(-2,1,0,LOG:13)
Block(-2,1,1,LOG:13)
Block(-2,2,0,LOG:13)
Block(-2,2,1,LOG:13)
Block(-2,3,0,LOG:13)
Block(-2,3,1,LOG:13)
Block(-2,4,0,LOG:13)
Block(-2,4,1,LOG:13)
Block(-2,5,0,LOG:13)
Block(-2,5,1,LOG:13)
Block(-2,6,0,LOG:13)
Block(-2,6,1,LOG:13)
Block(-2,7,-14,LEAVES:1)
Block(-2,7,-11,LEAVES:1)
Block(-2,7,1,LOG:13)
Block(-2,8,-14,LEAVES:1)
Block(-2,8,-13,LEAVES:1)
Block(-2,8,-12,LEAVES:1)
Block(-2,8,-11,LOG:13)
Block(-2,8,-10,LOG:13)
Block(-2,8,-9,LEAVES:1)
Block(-2,8,1,LOG:13)
Block(-2,8,10,LEAVES:1)
Block(-2,9,-13,LEAVES:1)
Block(-2,9,-12,LEAVES:1)
Block(-2,9,-11,LEAVES:1)
Block(-2,9,-10,LEAVES:1)
Block(-2,9,-9,LOG:13)
Block(-2,9,-8,LOG:13)
Block(-2,9,-7,LEAVES:1)
Block(-2,9,-6,LEAVES:1)
Block(-2,9,1,LOG:13)
Block(-2,9,6,LEAVES:1)
Block(-2,9,8,LEAVES:1)
Block(-2,9,9,LOG:13)
Block(-2,9,10,LEAVES:1)
Block(-2,9,11,LEAVES:1)
Block(-2,10,-9,LEAVES:1)
Block(-2,10,-8,LEAVES:1)
Block(-2,10,-7,LEAVES:1)
Block(-2,10,-6,LEAVES:1)
Block(-2,10,-5,LEAVES:1)
Block(-2,10,1,LEAVES:1)
Block(-2,10,4,LEAVES:1)
Block(-2,10,7,LEAVES:1)
Block(-2,10,8,LEAVES:1)
Block(-2,10,9,LEAVES:1)
Block(-2,10,10,LEAVES:1)
Block(-2,11,-6,LEAVES:1)
Block(-2,11,-5,LEAVES:1)
Block(-2,11,-1,LEAVES:1)
Block(-2,11,0,LOG:13)
Block(-2,11,1,LEAVES:1)
Block(-2,11,4,LEAVES:1)
Block(-2,12,0,LEAVES:1)
Block(-2,12,3,LEAVES:1)
Block(-2,12,5,LEAVES:1)
Block(-2,14,7,LEAVES:1)
Block(-2,15,3,LEAVES:1)
Block(-2,15,5,LEAVES:1)
Block(-2,15,6,LEAVES:1)
Block(-2,16,2,LEAVES:1)
Block(-2,16,3,LOG:13)
Block(-2,16,4,LEAVES:1)
Block(-2,16,5,LEAVES:1)
Block(-2,17,-3,LEAVES:1)
Block(-2,17,1,LEAVES:1)
Block(-2,17,2,LEAVES:1)
Block(-2,17,3,LEAVES:1)
Block(-2,17,10,LEAVES:1)
Block(-2,18,-8,LEAVES:1)
Block(-2,18,-6,LEAVES:1)
Block(-2,18,-1,LEAVES:1)
Block(-2,18,0,LOG:13)
Block(-2,18,1,LEAVES:1)
Block(-2,18,2,LEAVES:1)
Block(-2,18,9,LEAVES:1)
Block(-2,19,-7,LEAVES:1)
Block(-2,19,-6,LEAVES:1)
Block(-2,19,0,LEAVES:1)
Block(-2,19,1,LEAVES:1)
Block(-2,19,5,LEAVES:1)
Block(-2,19,7,LEAVES:1)
Block(-2,19,8,LOG:13)
Block(-2,19,9,LEAVES:1)
Block(-2,19,10,LEAVES:1)
Block(-2,20,-7,LEAVES:1)
Block(-2,20,-6,LEAVES:1)
Block(-2,20,-5,LOG:13)
Block(-2,20,-4,LEAVES:1)
Block(-2,20,-2,LEAVES:1)
Block(-2,20,1,LEAVES:1)
Block(-2,20,5,LEAVES:1)
Block(-2,20,6,LOG:13)
Block(-2,20,7,LOG:13)
Block(-2,20,8,LEAVES:1)
Block(-2,20,9,LEAVES:1)
Block(-2,21,-6,LEAVES:1)
Block(-2,21,-5,LEAVES:1)
Block(-2,21,-4,LEAVES:1)
Block(-2,21,-3,LEAVES:1)
Block(-2,21,4,LEAVES:1)
Block(-2,21,5,LEAVES:1)
Block(-2,21,6,LEAVES:1)
Block(-2,21,7,LEAVES:1)
Block(-2,22,-4,LEAVES:1)
Block(-2,22,-2,LEAVES:1)
Block(-2,22,0,LEAVES:1)
Block(-2,22,3,LEAVES:1)
Block(-2,22,4,LEAVES:1)
Block(-2,22,5,LEAVES:1)
Block(-2,23,0,LEAVES:1)
Block(-2,23,1,LOG:13)
Block(-2,23,2,LEAVES:1)
Block(-2,24,0,LEAVES:1)
Block(-2,24,1,LEAVES:1)
Block(-2,24,2,LEAVES:1)
Block(-2,25,-3,LEAVES:1)
Block(-2,25,-2,LEAVES:1)
Block(-2,25,0,LEAVES:1)
Block(-2,26,-2,LEAVES:1)
Block(-2,26,-1,LEAVES:1)
Block(-2,26,0,LOG:13)
Block(-2,26,1,LEAVES:1)
Block(-2,27,0,LEAVES:1)
Block(-2,27,1,LEAVES:1)
Block(-2,27,6,LEAVES:1)
Block(-2,28,0,LEAVES:1)
Block(-2,29,-1,LEAVES:1)
Block(-2,29,0,LOG:13)
Block(-2,29,1,LEAVES:1)
Block(-2,29,2,LEAVES:1)
Block(-2,29,3,LEAVES:1)
Block(-2,30,-3,LEAVES:1)
Block(-2,30,-2,LEAVES:1)
Block(-2,30,0,LEAVES:1)
Block(-2,30,1,LEAVES:1)
Block(-2,30,4,LEAVES:1)
Block(-2,31,-3,LEAVES:1)
Block(-2,31,-2,LEAVES:1)
Block(-2,31,-1,LEAVES:1)
Block(-2,31,1,LEAVES:1)
Block(-2,31,3,LEAVES:1)
Block(-2,32,-1,LEAVES:1)
Block(-2,32,0,LEAVES:1)
Block(-2,33,-2,LEAVES:1)
Block(-2,33,0,LEAVES:1)
Block(-2,33,1,LEAVES:1)
Block(-2,34,0,LEAVES:1)
Block(-2,34,1,LOG:13)
Block(-2,34,2,LEAVES:1)
Block(-2,35,1,LEAVES:1)
Block(-2,42,1,LEAVES:1)
Block(-1,-7,-5,LOG:1)
Block(-1,-7,-4,LOG:1)
Block(-1,-7,-3,LOG:9)
Block(-1,-7,-2,LOG:1)
Block(-1,-7,4,LOG:1)
Block(-1,-7,5,LOG:1)
Block(-1,-6,-5,LOG:13)
Block(-1,-6,-3,LOG:1)
Block(-1,-6,-2,LOG:13)
Block(-1,-6,-1,LOG:13)
Block(-1,-6,0,LOG:13)
Block(-1,-6,1,LOG:13)
Block(-1,-6,2,LOG:13)
Block(-1,-6,4,LOG:13)
Block(-1,-6,5,LOG:13)
Block(-1,-5,-2,LOG:13)
Block(-1,-5,-1,LOG:13)
Block(-1,-5,0,LOG:13)
Block(-1,-5,1,LOG:13)
Block(-1,-5,2,LOG:13)
Block(-1,-5,4,LOG:13)
Block(-1,-4,-2,LOG:13)
Block(-1,-4,-1,LOG:13)
Block(-1,-4,0,LOG:13)
Block(-1,-4,1,LOG:13)
Block(-1,-4,2,LOG:13)
Block(-1,-3,-2,LOG:13)
Block(-1,-3,-1,LOG:13)
Block(-1,-3,0,LOG:13)
Block(-1,-3,1,LOG:13)
Block(-1,-3,2,LOG:13)
Block(-1,-2,-2,LOG:1)
Block(-1,-2,-1,LOG:13)
Block(-1,-2,0,LOG:13)
Block(-1,-2,1,LOG:13)
Block(-1,-2,2,LOG:13)
Block(-1,-1,-1,LOG:13)
Block(-1,-1,0,LOG:13)
Block(-1,-1,1,LOG:13)
Block(-1,0,-1,LOG:1)
Block(-1,0,0,LOG:1)
Block(-1,0,1,LOG:13)
Block(-1,1,-1,LOG:13)
Block(-1,1,0,LOG:13)
Block(-1,1,1,LOG:13)
Block(-1,2,-1,LOG:13)
Block(-1,2,0,LOG:13)
Block(-1,2,1,LOG:13)
Block(-1,3,-1,LOG:13)
Block(-1,3,0,LOG:13)
Block(-1,3,1,LOG:13)
Block(-1,4,-1,LOG:13)
Block(-1,4,0,LOG:13)
Block(-1,4,1,LOG:13)
Block(-1,5,-1,LOG:13)
Block(-1,5,0,LOG:13)
Block(-1,5,1,LOG:13)
Block(-1,6,-13,LEAVES:1)
Block(-1,6,-1,LOG:13)
Block(-1,6,0,LOG:13)
Block(-1,6,1,LOG:13)
Block(-1,7,-12,LEAVES:1)
Block(-1,7,-10,LEAVES:1)
Block(-1,7,-1,LOG:13)
Block(-1,7,0,LOG:13)
Block(-1,7,1,LOG:13)
Block(-1,8,-13,LEAVES:1)
Block(-1,8,-12,LEAVES:1)
Block(-1,8,-11,LEAVES:1)
Block(-1,8,-10,LEAVES:1)
Block(-1,8,-9,LEAVES:1)
Block(-1,8,-8,LEAVES:1)
Block(-1,8,-1,LOG:13)
Block(-1,8,0,LOG:13)
Block(-1,8,1,LOG:13)
Block(-1,8,11,LEAVES:1)
Block(-1,9,-10,LEAVES:1)
Block(-1,9,-9,LEAVES:1)
Block(-1,9,-8,LEAVES:1)
Block(-1,9,-7,LEAVES:1)
Block(-1,9,-4,LEAVES:1)
Block(-1,9,-1,LOG:13)
Block(-1,9,0,LOG:13)
Block(-1,9,1,LOG:13)
Block(-1,9,5,LEAVES:1)
Block(-1,9,7,LEAVES:1)
Block(-1,9,10,LEAVES:1)
Block(-1,10,-8,LEAVES:1)
Block(-1,10,-7,LOG:13)
Block(-1,10,-6,LOG:13)
Block(-1,10,-5,LEAVES:1)
Block(-1,10,-3,LEAVES:1)
Block(-1,10,0,LOG:13)
Block(-1,10,1,LOG:13)
Block(-1,10,6,LEAVES:1)
Block(-1,10,7,LEAVES:1)
Block(-1,10,8,LOG:13)
Block(-1,10,9,LEAVES:1)
Block(-1,11,-8,LEAVES:1)
Block(-1,11,-7,LEAVES:1)
Block(-1,11,-6,LEAVES:1)
Block(-1,11,-5,LOG:13)
Block(-1,11,-4,LEAVES:1)
Block(-1,11,0,LOG:13)
Block(-1,11,1,LOG:13)
Block(-1,11,5,LEAVES:1)
Block(-1,11,7,LEAVES:1)
Block(-1,11,8,LEAVES:1)
Block(-1,12,-5,LEAVES:1)
Block(-1,12,-2,LEAVES:1)
Block(-1,12,0,LOG:13)
Block(-1,12,1,LOG:13)
Block(-1,12,4,LEAVES:1)
Block(-1,12,5,LEAVES:1)
Block(-1,12,6,LEAVES:1)
Block(-1,13,-2,LEAVES:1)
Block(-1,13,-1,LEAVES:1)
Block(-1,13,0,LOG:13)
Block(-1,13,1,LOG:13)
Block(-1,13,2,LEAVES:1)
Block(-1,13,3,LEAVES:1)
Block(-1,13,5,LEAVES:1)
Block(-1,14,0,LOG:13)
Block(-1,14,1,LOG:13)
Block(-1,14,5,LEAVES:1)
Block(-1,15,0,LOG:13)
Block(-1,15,1,LOG:13)
Block(-1,15,3,LEAVES:1)
Block(-1,16,-2,LEAVES:1)
Block(-1,16,0,LOG:13)
Block(-1,16,1,LOG:13)
Block(-1,16,2,LEAVES:1)
Block(-1,16,3,LEAVES:1)
Block(-1,16,4,LEAVES:1)
Block(-1,17,-2,LEAVES:1)
Block(-1,17,0,LOG:13)
Block(-1,17,1,LOG:13)
Block(-1,17,2,LOG:13)
Block(-1,17,3,LEAVES:1)
Block(-1,17,4,LEAVES:1)
Block(-1,17,7,LEAVES:1)
Block(-1,18,-1,LEAVES:1)
Block(-1,18,0,LEAVES:1)
Block(-1,18,1,LOG:13)
Block(-1,18,2,LEAVES:1)
Block(-1,18,3,LEAVES:1)
Block(-1,18,8,LEAVES:1)
Block(-1,19,-6,LEAVES:1)
Block(-1,19,-3,LEAVES:1)
Block(-1,19,-1,LEAVES:1)
Block(-1,19,0,LOG:13)
Block(-1,19,1,LOG:13)
Block(-1,19,7,LEAVES:1)
Block(-1,19,8,LEAVES:1)
Block(-1,19,9,LEAVES:1)
Block(-1,20,-7,LEAVES:1)
Block(-1,20,-6,LEAVES:1)
Block(-1,20,-5,LEAVES:1)
Block(-1,20,-3,LEAVES:1)
Block(-1,20,1,LOG:13)
Block(-1,20,2,LEAVES:1)
Block(-1,20,5,LEAVES:1)
Block(-1,20,6,LEAVES:1)
Block(-1,20,7,LEAVES:1)
Block(-1,20,8,LEAVES:1)
Block(-1,21,-6,LEAVES:1)
Block(-1,21,-5,LEAVES:1)
Block(-1,21,-4,LOG:13)
Block(-1,21,-3,LOG:13)
Block(-1,21,-2,LEAVES:1)
Block(-1,21,1,LOG:13)
Block(-1,21,3,LEAVES:1)
Block(-1,21,4,LOG:13)
Block(-1,21,5,LOG:13)
Block(-1,21,6,LEAVES:1)
Block(-1,21,7,LEAVES:1)
Block(-1,22,-4,LEAVES:1)
Block(-1,22,-3,LEAVES:1)
Block(-1,22,-2,LEAVES:1)
Block(-1,22,-1,LEAVES:1)
Block(-1,22,1,LOG:13)
Block(-1,22,2,LOG:13)
Block(-1,22,3,LOG:13)
Block(-1,22,4,LEAVES:1)
Block(-1,22,5,LEAVES:1)
Block(-1,23,-2,LEAVES:1)
Block(-1,23,1,LOG:13)
Block(-1,23,2,LEAVES:1)
Block(-1,23,3,LEAVES:1)
Block(-1,23,4,LEAVES:1)
Block(-1,24,-3,LEAVES:1)
Block(-1,24,1,LOG:13)
Block(-1,24,2,LEAVES:1)
Block(-1,24,3,LEAVES:1)
Block(-1,25,-2,LEAVES:1)
Block(-1,25,0,LEAVES:1)
Block(-1,25,1,LOG:13)
Block(-1,25,2,LEAVES:1)
Block(-1,26,-1,LEAVES:1)
Block(-1,26,0,LEAVES:1)
Block(-1,26,1,LEAVES:1)
Block(-1,27,-1,LEAVES:1)
Block(-1,27,0,LEAVES:1)
Block(-1,27,1,LOG:13)
Block(-1,28,-1,LEAVES:1)
Block(-1,28,2,LEAVES:1)
Block(-1,28,5,LEAVES:1)
Block(-1,28,6,LEAVES:1)
Block(-1,29,-3,LEAVES:1)
Block(-1,29,0,LEAVES:1)
Block(-1,29,1,LEAVES:1)
Block(-1,29,4,LEAVES:1)
Block(-1,29,6,LEAVES:1)
Block(-1,29,7,LEAVES:1)
Block(-1,30,-4,LEAVES:1)
Block(-1,30,-3,LOG:13)
Block(-1,30,-2,LEAVES:1)
Block(-1,30,0,LEAVES:1)
Block(-1,30,1,LOG:13)
Block(-1,30,2,LEAVES:1)
Block(-1,30,4,LEAVES:1)
Block(-1,30,5,LEAVES:1)
Block(-1,31,-3,LEAVES:1)
Block(-1,31,-2,LOG:13)
Block(-1,31,-1,LOG:13)
Block(-1,31,0,LEAVES:1)
Block(-1,31,1,LEAVES:1)
Block(-1,31,2,LEAVES:1)
Block(-1,31,4,LEAVES:1)
Block(-1,32,-2,LEAVES:1)
Block(-1,32,-1,LEAVES:1)
Block(-1,32,0,LEAVES:1)
Block(-1,32,1,LEAVES:1)
Block(-1,32,3,LEAVES:1)
Block(-1,33,2,LEAVES:1)
Block(-1,34,-1,LEAVES:1)
Block(-1,34,1,LEAVES:1)
Block(-1,35,0,LEAVES:1)
Block(-1,35,1,LOG:13)
Block(-1,35,2,LEAVES:1)
Block(-1,35,3,LEAVES:1)
Block(-1,36,1,LEAVES:1)
Block(-1,37,2,LEAVES:1)
Block(-1,38,1,LEAVES:1)
Block(-1,38,2,LEAVES:1)
Block(-1,39,0,LEAVES:1)
Block(-1,39,1,LEAVES:1)
Block(-1,41,1,LEAVES:1)
Block(-1,42,0,LEAVES:1)
Block(-1,42,1,LOG:13)
Block(-1,42,2,LEAVES:1)
Block(-1,43,1,LEAVES:1)
Block(-1,44,1,LEAVES:1)
Block(0,-7,-3,LOG:1)
Block(0,-7,-2,LOG:1)
Block(0,-7,2,LOG:1)
Block(0,-7,3,LOG:1)
Block(0,-7,4,LOG:1)
Block(0,-6,-3,LOG:13)
Block(0,-6,-2,LOG:13)
Block(0,-6,-1,LOG:13)
Block(0,-6,0,LOG:13)
Block(0,-6,1,LOG:13)
Block(0,-6,2,LOG:13)
Block(0,-6,3,LOG:13)
Block(0,-5,-2,LOG:1)
Block(0,-5,-1,LOG:13)
Block(0,-5,0,LOG:13)
Block(0,-5,1,LOG:13)
Block(0,-5,2,LOG:13)
Block(0,-5,3,LOG:13)
Block(0,-4,-1,LOG:13)
Block(0,-4,0,LOG:13)
Block(0,-4,1,LOG:13)
Block(0,-4,2,LOG:13)
Block(0,-4,3,LOG:1)
Block(0,-3,-1,LOG:13)
Block(0,-3,0,LOG:13)
Block(0,-3,1,LOG:13)
Block(0,-3,2,LOG:13)
Block(0,-2,-1,LOG:13)
Block(0,-2,0,LOG:13)
Block(0,-2,1,LOG:13)
Block(0,-2,2,LOG:13)
Block(0,-1,-1,LOG:13)
Block(0,-1,0,LOG:13)
Block(0,-1,1,LOG:13)
Block(0,-1,2,LOG:13)
Block(0,0,-1,LOG:13)
Block(0,0,0,LOG:13)
Block(0,0,1,LOG:13)
Block(0,0,2,LOG:13)
Block(0,1,-1,LOG:13)
Block(0,1,0,LOG:13)
Block(0,1,1,LOG:13)
Block(0,1,2,LOG:13)
Block(0,2,-1,LOG:13)
Block(0,2,0,LOG:13)
Block(0,2,1,LOG:13)
Block(0,2,2,LOG:13)
Block(0,3,0,LOG:13)
Block(0,3,1,LOG:13)
Block(0,3,2,LOG:13)
Block(0,4,0,LOG:13)
Block(0,4,1,LOG:13)
Block(0,4,2,LOG:13)
Block(0,5,0,LOG:13)
Block(0,5,1,LOG:13)
Block(0,5,2,LOG:13)
Block(0,6,-10,LEAVES:1)
Block(0,6,0,LOG:13)
Block(0,6,1,LOG:13)
Block(0,6,2,LOG:13)
Block(0,7,-11,LEAVES:1)
Block(0,7,0,LOG:13)
Block(0,7,1,LOG:13)
Block(0,7,2,LOG:13)
Block(0,8,-10,LEAVES:1)
Block(0,8,0,LOG:13)
Block(0,8,1,LOG:13)
Block(0,8,2,LOG:13)
Block(0,9,-8,LEAVES:1)
Block(0,9,-6,LEAVES:1)
Block(0,9,0,LOG:13)
Block(0,9,1,LOG:13)
Block(0,9,2,LOG:13)
Block(0,9,9,LEAVES:1)
Block(0,10,-9,LEAVES:1)
Block(0,10,-8,LEAVES:1)
Block(0,10,-7,LEAVES:1)
Block(0,10,-6,LEAVES:1)
Block(0,10,-4,LEAVES:1)
Block(0,10,0,LOG:13)
Block(0,10,1,LOG:13)
Block(0,10,2,LOG:13)
Block(0,10,7,LOG:13)
Block(0,10,8,LEAVES:1)
Block(0,11,-8,LEAVES:1)
Block(0,11,-5,LEAVES:1)
Block(0,11,-4,LOG:13)
Block(0,11,-3,LEAVES:1)
Block(0,11,0,LOG:13)
Block(0,11,1,LOG:13)
Block(0,11,2,LOG:13)
Block(0,11,5,LEAVES:1)
Block(0,11,6,LEAVES:1)
Block(0,11,7,LEAVES:1)
Block(0,12,-4,LEAVES:1)
Block(0,12,-3,LEAVES:1)
Block(0,12,-2,LEAVES:1)
Block(0,12,0,LOG:13)
Block(0,12,1,LOG:13)
Block(0,12,2,LOG:13)
Block(0,12,3,LEAVES:1)
Block(0,12,4,LOG:13)
Block(0,12,5,LOG:13)
Block(0,12,6,LEAVES:1)
Block(0,13,-3,LEAVES:1)
Block(0,13,-2,LOG:13)
Block(0,13,-1,LOG:13)
Block(0,13,0,LOG:13)
Block(0,13,1,LOG:13)
Block(0,13,2,LOG:13)
Block(0,13,3,LOG:13)
Block(0,13,4,LEAVES:1)
Block(0,13,5,LEAVES:1)
Block(0,14,-2,LEAVES:1)
Block(0,14,0,LOG:13)
Block(0,14,1,LOG:13)
Block(0,14,2,LEAVES:1)
Block(0,14,3,LEAVES:1)
Block(0,15,-4,LEAVES:1)
Block(0,15,0,LOG:13)
Block(0,15,1,LOG:13)
Block(0,15,2,LEAVES:1)
Block(0,15,4,LEAVES:1)
Block(0,16,0,LOG:13)
Block(0,16,1,LOG:13)
Block(0,16,3,LEAVES:1)
Block(0,17,-3,LEAVES:1)
Block(0,17,-1,LEAVES:1)
Block(0,17,0,LOG:13)
Block(0,17,1,LOG:13)
Block(0,17,2,LEAVES:1)
Block(0,17,3,LEAVES:1)
Block(0,18,-2,LEAVES:1)
Block(0,18,-1,LOG:13)
Block(0,18,0,LOG:13)
Block(0,18,1,LOG:13)
Block(0,18,6,LEAVES:1)
Block(0,19,-7,LEAVES:1)
Block(0,19,-1,LEAVES:1)
Block(0,19,0,LOG:13)
Block(0,19,1,LOG:13)
Block(0,19,6,LEAVES:1)
Block(0,20,-6,LEAVES:1)
Block(0,20,-3,LEAVES:1)
Block(0,20,-1,LEAVES:1)
Block(0,20,0,LOG:13)
Block(0,20,1,LOG:13)
Block(0,20,6,LEAVES:1)
Block(0,20,7,LEAVES:1)
Block(0,21,-4,LEAVES:1)
Block(0,21,-3,LEAVES:1)
Block(0,21,-2,LEAVES:1)
Block(0,21,-1,LEAVES:1)
Block(0,21,0,LOG:13)
Block(0,21,1,LOG:13)
Block(0,21,2,LEAVES:1)
Block(0,21,3,LEAVES:1)
Block(0,21,4,LEAVES:1)
Block(0,21,5,LEAVES:1)
Block(0,22,-4,LEAVES:1)
Block(0,22,-3,LEAVES:1)
Block(0,22,-2,LOG:13)
Block(0,22,-1,LOG:13)
Block(0,22,0,LOG:13)
Block(0,22,1,LOG:13)
Block(0,22,2,LEAVES:1)
Block(0,22,4,LEAVES:1)
Block(0,23,-3,LEAVES:1)
Block(0,23,-2,LEAVES:1)
Block(0,23,-1,LEAVES:1)
Block(0,23,0,LOG:13)
Block(0,23,1,LOG:13)
Block(0,23,2,LEAVES:1)
Block(0,23,3,LEAVES:1)
Block(0,24,0,LEAVES:1)
Block(0,24,1,LOG:13)
Block(0,24,2,LEAVES:1)
Block(0,25,1,LOG:13)
Block(0,26,0,LEAVES:1)
Block(0,26,1,LOG:13)
Block(0,27,1,LOG:13)
Block(0,27,6,LEAVES:1)
Block(0,27,8,LEAVES:1)
Block(0,28,1,LOG:13)
Block(0,28,2,LEAVES:1)
Block(0,28,3,LEAVES:1)
Block(0,28,6,LEAVES:1)
Block(0,28,7,LEAVES:1)
Block(0,29,-5,LEAVES:1)
Block(0,29,-4,LEAVES:1)
Block(0,29,-1,LEAVES:1)
Block(0,29,0,LEAVES:1)
Block(0,29,1,LOG:13)
Block(0,29,2,LEAVES:1)
Block(0,29,5,LEAVES:1)
Block(0,29,6,LOG:13)
Block(0,29,7,LEAVES:1)
Block(0,29,8,LEAVES:1)
Block(0,30,-4,LEAVES:1)
Block(0,30,-3,LEAVES:1)
Block(0,30,0,LEAVES:1)
Block(0,30,1,LOG:13)
Block(0,30,2,LEAVES:1)
Block(0,30,3,LEAVES:1)
Block(0,30,4,LEAVES:1)
Block(0,30,5,LOG:13)
Block(0,30,6,LEAVES:1)
Block(0,30,7,LEAVES:1)
Block(0,31,-2,LEAVES:1)
Block(0,31,-1,LEAVES:1)
Block(0,31,0,LEAVES:1)
Block(0,31,1,LOG:13)
Block(0,31,2,LEAVES:1)
Block(0,31,3,LEAVES:1)
Block(0,31,4,LOG:13)
Block(0,31,5,LEAVES:1)
Block(0,32,-1,LEAVES:1)
Block(0,32,0,LOG:13)
Block(0,32,1,LOG:13)
Block(0,32,2,LEAVES:1)
Block(0,32,3,LOG:13)
Block(0,32,4,LEAVES:1)
Block(0,33,0,LEAVES:1)
Block(0,33,1,LOG:13)
Block(0,33,2,LOG:13)
Block(0,33,3,LEAVES:1)
Block(0,34,-2,LEAVES:1)
Block(0,34,0,LEAVES:1)
Block(0,34,1,LOG:13)
Block(0,34,2,LEAVES:1)
Block(0,35,-1,LEAVES:1)
Block(0,35,0,LEAVES:1)
Block(0,35,1,LOG:13)
Block(0,35,4,LEAVES:1)
Block(0,35,5,LEAVES:1)
Block(0,36,0,LEAVES:1)
Block(0,36,1,LOG:13)
Block(0,36,2,LEAVES:1)
Block(0,36,3,LEAVES:1)
Block(0,37,1,LOG:13)
Block(0,37,2,LOG:13)
Block(0,37,3,LEAVES:1)
Block(0,38,0,LEAVES:1)
Block(0,38,1,LOG:13)
Block(0,38,2,LEAVES:1)
Block(0,39,-1,LEAVES:1)
Block(0,39,0,LOG:13)
Block(0,39,1,LOG:13)
Block(0,40,0,LEAVES:1)
Block(0,40,1,LOG:13)
Block(0,41,1,LOG:13)
Block(0,41,2,LEAVES:1)
Block(0,42,-1,LEAVES:1)
Block(0,42,1,LOG:13)
Block(0,43,0,LEAVES:1)
Block(0,43,1,LOG:13)
Block(0,43,2,LEAVES:1)
Block(0,44,1,LOG:13)
Block(0,45,1,LOG:13)
Block(0,46,1,LOG:13)
Block(0,47,1,LEAVES:1)
Block(1,-7,-4,LOG:1)
Block(1,-7,-1,LOG:1)
Block(1,-7,2,LOG:5)
Block(1,-7,4,LOG:1)
Block(1,-6,-4,LOG:13)
Block(1,-6,-1,LOG:13)
Block(1,-6,0,LOG:13)
Block(1,-6,1,LOG:13)
Block(1,-6,2,LOG:13)
Block(1,-6,4,LOG:13)
Block(1,-5,-1,LOG:13)
Block(1,-5,0,LOG:13)
Block(1,-5,1,LOG:13)
Block(1,-5,2,LOG:13)
Block(1,-4,0,LOG:13)
Block(1,-4,1,LOG:13)
Block(1,-4,2,LOG:13)
Block(1,-3,0,LOG:13)
Block(1,-3,1,LOG:13)
Block(1,-3,2,LOG:13)
Block(1,-2,0,LOG:13)
Block(1,-2,1,LOG:13)
Block(1,-1,0,LOG:13)
Block(1,-1,1,LOG:13)
Block(1,0,0,LOG:13)
Block(1,0,1,LOG:13)
Block(1,1,1,LOG:13)
Block(1,2,1,LOG:13)
Block(1,3,1,LOG:13)
Block(1,4,1,LOG:13)
Block(1,5,1,LOG:13)
Block(1,6,1,LOG:13)
Block(1,7,1,LOG:13)
Block(1,7,10,LEAVES:1)
Block(1,7,12,LEAVES:1)
Block(1,8,-9,LEAVES:1)
Block(1,8,-6,LEAVES:1)
Block(1,8,1,LOG:13)
Block(1,8,10,LEAVES:1)
Block(1,9,-7,LEAVES:1)
Block(1,9,11,LEAVES:1)
Block(1,10,-8,LEAVES:1)
Block(1,10,-7,LEAVES:1)
Block(1,10,7,LEAVES:1)
Block(1,10,8,LEAVES:1)
Block(1,10,9,LEAVES:1)
Block(1,11,-6,LEAVES:1)
Block(1,11,-5,LEAVES:1)
Block(1,11,-4,LEAVES:1)
Block(1,11,-2,LEAVES:1)
Block(1,11,6,LOG:13)
Block(1,11,7,LEAVES:1)
Block(1,12,-5,LEAVES:1)
Block(1,12,-4,LEAVES:1)
Block(1,12,-3,LOG:13)
Block(1,12,-2,LEAVES:1)
Block(1,12,-1,LEAVES:1)
Block(1,12,5,LEAVES:1)
Block(1,12,6,LEAVES:1)
Block(1,13,-4,LEAVES:1)
Block(1,13,-3,LEAVES:1)
Block(1,13,-2,LEAVES:1)
Block(1,13,-1,LEAVES:1)
Block(1,13,2,LEAVES:1)
Block(1,13,3,LOG:13)
Block(1,13,4,LEAVES:1)
Block(1,14,-2,LEAVES:1)
Block(1,14,3,LEAVES:1)
Block(1,15,-5,LEAVES:1)
Block(1,15,-1,LEAVES:1)
Block(1,16,-4,LEAVES:1)
Block(1,16,-1,LEAVES:1)
Block(1,16,0,LOG:13)
Block(1,16,1,LEAVES:1)
Block(1,17,-5,LEAVES:1)
Block(1,17,-4,LEAVES:1)
Block(1,17,-3,LOG:13)
Block(1,17,0,LEAVES:1)
Block(1,17,2,LEAVES:1)
Block(1,18,-3,LEAVES:1)
Block(1,18,-2,LOG:13)
Block(1,18,-1,LEAVES:1)
Block(1,18,0,LEAVES:1)
Block(1,18,2,LEAVES:1)
Block(1,19,-2,LEAVES:1)
Block(1,19,-1,LEAVES:1)
Block(1,20,3,LEAVES:1)
Block(1,20,5,LEAVES:1)
Block(1,21,-5,LEAVES:1)
Block(1,21,-3,LEAVES:1)
Block(1,21,2,LOG:13)
Block(1,21,3,LEAVES:1)
Block(1,21,4,LEAVES:1)
Block(1,22,-4,LEAVES:1)
Block(1,22,-3,LEAVES:1)
Block(1,22,-2,LEAVES:1)
Block(1,22,-1,LEAVES:1)
Block(1,22,2,LOG:13)
Block(1,22,3,LEAVES:1)
Block(1,23,-3,LEAVES:1)
Block(1,23,2,LEAVES:1)
Block(1,25,-1,LEAVES:1)
Block(1,25,1,LEAVES:1)
Block(1,26,-1,LEAVES:1)
Block(1,26,0,LOG:13)
Block(1,26,1,LEAVES:1)
Block(1,26,2,LEAVES:1)
Block(1,27,0,LEAVES:1)
Block(1,27,1,LEAVES:1)
Block(1,27,2,LEAVES:1)
Block(1,28,-2,LEAVES:1)
Block(1,28,-1,LEAVES:1)
Block(1,28,0,LEAVES:1)
Block(1,28,1,LEAVES:1)
Block(1,28,6,LEAVES:1)
Block(1,29,-3,LEAVES:1)
Block(1,29,0,LEAVES:1)
Block(1,29,1,LOG:13)
Block(1,29,2,LEAVES:1)
Block(1,29,3,LEAVES:1)
Block(1,29,5,LEAVES:1)
Block(1,29,6,LEAVES:1)
Block(1,29,7,LEAVES:1)
Block(1,30,1,LEAVES:1)
Block(1,30,5,LEAVES:1)
Block(1,30,6,LEAVES:1)
Block(1,31,0,LEAVES:1)
Block(1,31,1,LOG:13)
Block(1,31,2,LEAVES:1)
Block(1,31,4,LEAVES:1)
Block(1,32,0,LEAVES:1)
Block(1,32,1,LEAVES:1)
Block(1,32,3,LEAVES:1)
Block(1,33,-2,LEAVES:1)
Block(1,33,2,LEAVES:1)
Block(1,34,-1,LEAVES:1)
Block(1,34,1,LEAVES:1)
Block(1,35,0,LEAVES:1)
Block(1,35,1,LEAVES:1)
Block(1,35,2,LEAVES:1)
Block(1,35,3,LEAVES:1)
Block(1,36,0,LEAVES:1)
Block(1,36,1,LOG:13)
Block(1,36,2,LEAVES:1)
Block(1,36,3,LOG:13)
Block(1,36,4,LEAVES:1)
Block(1,37,1,LEAVES:1)
Block(1,37,2,LEAVES:1)
Block(1,37,3,LEAVES:1)
Block(1,39,0,LEAVES:1)
Block(1,39,1,LEAVES:1)
Block(1,42,1,LEAVES:1)
Block(1,43,0,LEAVES:1)
Block(1,44,1,LEAVES:1)
Block(2,-7,-2,LOG:1)
Block(2,-7,-1,LOG:1)
Block(2,-7,0,LOG:1)
Block(2,-7,2,LOG:1)
Block(2,-6,-2,LOG:13)
Block(2,-6,-1,LOG:13)
Block(2,-6,0,LOG:13)
Block(2,-6,1,LOG:13)
Block(2,-6,2,LOG:13)
Block(2,-5,-2,LOG:13)
Block(2,-5,-1,LOG:13)
Block(2,-5,0,LOG:13)
Block(2,-5,1,LOG:13)
Block(2,-5,2,LOG:13)
Block(2,-4,-2,LOG:13)
Block(2,-4,-1,LOG:13)
Block(2,-4,0,LOG:13)
Block(2,-4,1,LOG:13)
Block(2,-4,2,LOG:13)
Block(2,-3,-1,LOG:13)
Block(2,-3,1,LOG:13)
Block(2,-3,2,LOG:1)
Block(2,-2,-1,LOG:1)
Block(2,-2,1,LOG:13)
Block(2,-1,1,LOG:1)
Block(2,8,11,LEAVES:1)
Block(2,8,12,LEAVES:1)
Block(2,8,14,LEAVES:1)
Block(2,9,-9,LEAVES:1)
Block(2,9,9,LEAVES:1)
Block(2,9,10,LEAVES:1)
Block(2,9,11,LEAVES:1)
Block(2,9,12,LEAVES:1)
Block(2,9,13,LEAVES:1)
Block(2,10,-8,LEAVES:1)
Block(2,10,-7,LEAVES:1)
Block(2,10,-6,LEAVES:1)
Block(2,10,-5,LEAVES:1)
Block(2,10,7,LEAVES:1)
Block(2,10,8,LOG:13)
Block(2,10,9,LOG:13)
Block(2,10,10,LEAVES:1)
Block(2,10,11,LEAVES:1)
Block(2,11,-7,LEAVES:1)
Block(2,11,-6,LEAVES:1)
Block(2,11,-5,LOG:13)
Block(2,11,-2,LEAVES:1)
Block(2,11,6,LEAVES:1)
Block(2,11,7,LOG:13)
Block(2,11,8,LEAVES:1)
Block(2,11,9,LEAVES:1)
Block(2,12,-5,LEAVES:1)
Block(2,12,-4,LOG:13)
Block(2,12,-3,LEAVES:1)
Block(2,12,-2,LEAVES:1)
Block(2,12,-1,LEAVES:1)
Block(2,12,3,LEAVES:1)
Block(2,12,4,LOG:13)
Block(2,12,5,LEAVES:1)
Block(2,12,6,LEAVES:1)
Block(2,12,7,LEAVES:1)
Block(2,13,-4,LEAVES:1)
Block(2,13,-2,LEAVES:1)
Block(2,13,3,LEAVES:1)
Block(2,13,4,LEAVES:1)
Block(2,13,5,LEAVES:1)
Block(2,14,0,LEAVES:1)
Block(2,14,2,LEAVES:1)
Block(2,15,-2,LEAVES:1)
Block(2,15,0,LEAVES:1)
Block(2,15,1,LEAVES:1)
Block(2,16,-5,LEAVES:1)
Block(2,16,-4,LEAVES:1)
Block(2,16,-1,LEAVES:1)
Block(2,16,0,LOG:13)
Block(2,16,1,LEAVES:1)
Block(2,16,2,LEAVES:1)
Block(2,17,-6,LEAVES:1)
Block(2,17,-5,LEAVES:1)
Block(2,17,-4,LOG:13)
Block(2,17,-3,LEAVES:1)
Block(2,17,-2,LEAVES:1)
Block(2,17,0,LEAVES:1)
Block(2,17,2,LEAVES:1)
Block(2,18,-5,LEAVES:1)
Block(2,18,-4,LEAVES:1)
Block(2,18,-3,LEAVES:1)
Block(2,18,-2,LEAVES:1)
Block(2,18,-1,LEAVES:1)
Block(2,18,7,LEAVES:1)
Block(2,19,4,LEAVES:1)
Block(2,20,-4,LEAVES:1)
Block(2,20,2,LEAVES:1)
Block(2,20,3,LEAVES:1)
Block(2,20,4,LOG:13)
Block(2,20,5,LEAVES:1)
Block(2,20,6,LEAVES:1)
Block(2,21,1,LEAVES:1)
Block(2,21,2,LOG:13)
Block(2,21,3,LOG:13)
Block(2,21,4,LEAVES:1)
Block(2,21,5,LEAVES:1)
Block(2,22,-3,LEAVES:1)
Block(2,22,2,LEAVES:1)
Block(2,22,3,LEAVES:1)
Block(2,23,-3,LEAVES:1)
Block(2,24,-2,LEAVES:1)
Block(2,25,-2,LEAVES:1)
Block(2,25,-1,LOG:13)
Block(2,25,0,LEAVES:1)
Block(2,26,-1,LEAVES:1)
Block(2,26,0,LEAVES:1)
Block(2,26,1,LEAVES:1)
Block(2,28,-1,LEAVES:1)
Block(2,28,0,LEAVES:1)
Block(2,28,5,LEAVES:1)
Block(2,28,7,LEAVES:1)
Block(2,29,-2,LEAVES:1)
Block(2,29,-1,LEAVES:1)
Block(2,29,0,LOG:13)
Block(2,29,1,LEAVES:1)
Block(2,30,0,LEAVES:1)
Block(2,30,2,LEAVES:1)
Block(2,30,3,LEAVES:1)
Block(2,30,5,LEAVES:1)
Block(2,31,1,LEAVES:1)
Block(2,31,2,LOG:13)
Block(2,31,3,LEAVES:1)
Block(2,32,2,LEAVES:1)
Block(2,34,-2,LEAVES:1)
Block(2,34,0,LEAVES:1)
Block(2,35,-1,LEAVES:1)
Block(2,35,0,LOG:13)
Block(2,35,1,LEAVES:1)
Block(2,35,2,LEAVES:1)
Block(2,36,0,LEAVES:1)
Block(2,36,1,LEAVES:1)
Block(2,36,3,LEAVES:1)
Block(2,38,0,LEAVES:1)
Block(2,41,1,LEAVES:1)
Block(3,-7,-3,LOG:1)
Block(3,-7,0,LOG:1)
Block(3,-7,1,LOG:1)
Block(3,-7,3,LOG:1)
Block(3,-6,-3,LOG:13)
Block(3,-6,-2,LOG:13)
Block(3,-6,0,LOG:13)
Block(3,-6,1,LOG:13)
Block(3,-6,3,LOG:13)
Block(3,-5,-2,LOG:13)
Block(3,-5,1,LOG:13)
Block(3,-5,3,LOG:13)
Block(3,-4,1,LOG:13)
Block(3,-4,3,LOG:1)
Block(3,8,12,LEAVES:1)
Block(3,8,13,LEAVES:1)
Block(3,9,-7,LEAVES:1)
Block(3,9,8,LEAVES:1)
Block(3,9,9,LEAVES:1)
Block(3,9,10,LOG:13)
Block(3,9,11,LOG:13)
Block(3,9,12,LEAVES:1)
Block(3,9,13,LEAVES:1)
Block(3,9,14,LEAVES:1)
Block(3,10,-9,LEAVES:1)
Block(3,10,-8,LEAVES:1)
Block(3,10,-7,LOG:13)
Block(3,10,-6,LEAVES:1)
Block(3,10,-5,LEAVES:1)
Block(3,10,-3,LEAVES:1)
Block(3,10,7,LEAVES:1)
Block(3,10,8,LEAVES:1)
Block(3,10,9,LEAVES:1)
Block(3,10,10,LEAVES:1)
Block(3,10,11,LEAVES:1)
Block(3,10,12,LEAVES:1)
Block(3,10,13,LEAVES:1)
Block(3,11,-7,LEAVES:1)
Block(3,11,-6,LOG:13)
Block(3,11,-5,LEAVES:1)
Block(3,11,-4,LEAVES:1)
Block(3,11,4,LEAVES:1)
Block(3,11,7,LEAVES:1)
Block(3,11,8,LEAVES:1)
Block(3,12,-6,LEAVES:1)
Block(3,12,-4,LEAVES:1)
Block(3,12,-2,LEAVES:1)
Block(3,12,3,LEAVES:1)
Block(3,12,4,LEAVES:1)
Block(3,12,5,LEAVES:1)
Block(3,13,4,LEAVES:1)
Block(3,14,-1,LEAVES:1)
Block(3,14,1,LEAVES:1)
Block(3,15,-1,LEAVES:1)
Block(3,15,0,LOG:13)
Block(3,15,1,LEAVES:1)
Block(3,15,2,LEAVES:1)
Block(3,16,-6,LEAVES:1)
Block(3,16,-3,LEAVES:1)
Block(3,16,-2,LEAVES:1)
Block(3,16,-1,LEAVES:1)
Block(3,16,0,LEAVES:1)
Block(3,16,1,LEAVES:1)
Block(3,17,-5,LEAVES:1)
Block(3,17,-4,LEAVES:1)
Block(3,17,-3,LEAVES:1)
Block(3,18,1,LEAVES:1)
Block(3,18,8,LEAVES:1)
Block(3,19,2,LEAVES:1)
Block(3,19,4,LEAVES:1)
Block(3,19,6,LEAVES:1)
Block(3,19,7,LEAVES:1)
Block(3,20,0,LEAVES:1)
Block(3,20,1,LEAVES:1)
Block(3,20,2,LOG:13)
Block(3,20,3,LEAVES:1)
Block(3,20,4,LEAVES:1)
Block(3,20,5,LOG:13)
Block(3,20,6,LEAVES:1)
Block(3,21,0,LEAVES:1)
Block(3,21,1,LEAVES:1)
Block(3,21,2,LEAVES:1)
Block(3,21,3,LEAVES:1)
Block(3,21,4,LEAVES:1)
Block(3,21,5,LEAVES:1)
Block(3,22,-5,LEAVES:1)
Block(3,22,-2,LEAVES:1)
Block(3,22,1,LEAVES:1)
Block(3,23,-4,LEAVES:1)
Block(3,23,-2,LEAVES:1)
Block(3,23,-1,LEAVES:1)
Block(3,23,0,LEAVES:1)
Block(3,24,-3,LEAVES:1)
Block(3,24,-2,LOG:13)
Block(3,24,-1,LEAVES:1)
Block(3,24,0,LEAVES:1)
Block(3,25,-2,LEAVES:1)
Block(3,25,-1,LEAVES:1)
Block(3,25,0,LEAVES:1)
Block(3,26,-1,LEAVES:1)
Block(3,26,0,LEAVES:1)
Block(3,27,-1,LEAVES:1)
Block(3,27,5,LEAVES:1)
Block(3,28,-2,LEAVES:1)
Block(3,28,-1,LOG:13)
Block(3,28,0,LEAVES:1)
Block(3,28,1,LEAVES:1)
Block(3,28,4,LEAVES:1)
Block(3,29,-1,LEAVES:1)
Block(3,29,0,LEAVES:1)
Block(3,29,3,LEAVES:1)
Block(3,29,4,LEAVES:1)
Block(3,30,2,LEAVES:1)
Block(3,30,3,LOG:13)
Block(3,30,4,LEAVES:1)
Block(3,31,2,LEAVES:1)
Block(3,31,3,LEAVES:1)
Block(3,34,-1,LEAVES:1)
Block(3,34,1,LEAVES:1)
Block(3,35,0,LEAVES:1)
Block(3,35,1,LEAVES:1)
Block(3,35,4,LEAVES:1)
Block(4,-7,-2,LOG:1)
Block(4,-7,0,LOG:1)
Block(4,-7,4,LOG:1)
Block(4,-6,-2,LOG:13)
Block(4,-6,0,LOG:13)
Block(4,-6,4,LOG:13)
Block(4,-5,0,LOG:13)
Block(4,-4,0,LOG:1)
Block(4,7,14,LEAVES:1)
Block(4,8,-10,LEAVES:1)
Block(4,8,8,LEAVES:1)
Block(4,8,9,LEAVES:1)
Block(4,8,14,LEAVES:1)
Block(4,9,-9,LEAVES:1)
Block(4,9,7,LEAVES:1)
Block(4,9,10,LEAVES:1)
Block(4,9,11,LEAVES:1)
Block(4,9,12,LEAVES:1)
Block(4,9,13,LEAVES:1)
Block(4,10,-10,LEAVES:1)
Block(4,10,-9,LEAVES:1)
Block(4,10,-8,LOG:13)
Block(4,10,-7,LEAVES:1)
Block(4,10,-4,LEAVES:1)
Block(4,10,3,LEAVES:1)
Block(4,10,8,LEAVES:1)
Block(4,10,12,LEAVES:1)
Block(4,11,-9,LEAVES:1)
Block(4,11,-8,LEAVES:1)
Block(4,11,-6,LEAVES:1)
Block(4,11,-5,LEAVES:1)
Block(4,11,-4,LEAVES:1)
Block(4,11,3,LEAVES:1)
Block(4,11,5,LEAVES:1)
Block(4,12,4,LEAVES:1)
Block(4,13,-3,LEAVES:1)
Block(4,13,0,LEAVES:1)
Block(4,13,3,LEAVES:1)
Block(4,14,-2,LEAVES:1)
Block(4,14,0,LEAVES:1)
Block(4,14,2,LEAVES:1)
Block(4,15,-4,LEAVES:1)
Block(4,15,-1,LEAVES:1)
Block(4,15,0,LOG:13)
Block(4,15,1,LEAVES:1)
Block(4,16,-4,LEAVES:1)
Block(4,16,0,LEAVES:1)
Block(4,18,3,LEAVES:1)
Block(4,19,1,LEAVES:1)
Block(4,19,5,LEAVES:1)
Block(4,19,6,LOG:13)
Block(4,19,7,LEAVES:1)
Block(4,19,8,LEAVES:1)
Block(4,20,0,LEAVES:1)
Block(4,20,1,LOG:13)
Block(4,20,2,LEAVES:1)
Block(4,20,3,LEAVES:1)
Block(4,20,4,LEAVES:1)
Block(4,20,5,LEAVES:1)
Block(4,20,6,LEAVES:1)
Block(4,21,-5,LEAVES:1)
Block(4,21,1,LEAVES:1)
Block(4,21,2,LEAVES:1)
Block(4,22,-4,LEAVES:1)
Block(4,23,-5,LEAVES:1)
Block(4,23,-4,LOG:13)
Block(4,23,-3,LEAVES:1)
Block(4,23,-1,LEAVES:1)
Block(4,24,-4,LEAVES:1)
Block(4,24,-3,LOG:13)
Block(4,24,-2,LEAVES:1)
Block(4,24,-1,LEAVES:1)
Block(4,24,0,LEAVES:1)
Block(4,25,-3,LEAVES:1)
Block(4,25,-1,LEAVES:1)
Block(4,27,-2,LEAVES:1)
Block(4,27,1,LEAVES:1)
Block(4,27,4,LEAVES:1)
Block(4,28,-1,LEAVES:1)
Block(4,28,1,LEAVES:1)
Block(4,28,3,LEAVES:1)
Block(4,28,4,LEAVES:1)
Block(4,28,5,LEAVES:1)
Block(4,29,0,LEAVES:1)
Block(4,29,2,LEAVES:1)
Block(4,29,3,LEAVES:1)
Block(4,29,4,LOG:13)
Block(4,29,5,LEAVES:1)
Block(4,30,1,LEAVES:1)
Block(4,30,3,LEAVES:1)
Block(4,30,4,LEAVES:1)
Block(4,34,1,LEAVES:1)
Block(5,-7,1,LOG:1)
Block(5,-6,1,LOG:13)
Block(5,8,-8,LEAVES:1)
Block(5,8,11,LEAVES:1)
Block(5,8,13,LEAVES:1)
Block(5,9,-10,LEAVES:1)
Block(5,9,-8,LEAVES:1)
Block(5,9,12,LEAVES:1)
Block(5,10,-9,LEAVES:1)
Block(5,10,-8,LEAVES:1)
Block(5,10,-7,LEAVES:1)
Block(5,10,-5,LEAVES:1)
Block(5,11,-8,LEAVES:1)
Block(5,12,0,LEAVES:1)
Block(5,13,-2,LEAVES:1)
Block(5,13,-1,LEAVES:1)
Block(5,13,4,LEAVES:1)
Block(5,14,-3,LEAVES:1)
Block(5,14,-2,LEAVES:1)
Block(5,14,-1,LEAVES:1)
Block(5,14,1,LEAVES:1)
Block(5,14,3,LEAVES:1)
Block(5,15,-2,LEAVES:1)
Block(5,15,-1,LEAVES:1)
Block(5,15,0,LOG:13)
Block(5,15,1,LOG:13)
Block(5,15,2,LEAVES:1)
Block(5,16,-1,LEAVES:1)
Block(5,16,0,LEAVES:1)
Block(5,16,1,LEAVES:1)
Block(5,18,0,LEAVES:1)
Block(5,18,6,LEAVES:1)
Block(5,18,8,LEAVES:1)
Block(5,19,-1,LEAVES:1)
Block(5,19,0,LEAVES:1)
Block(5,19,1,LOG:13)
Block(5,19,2,LEAVES:1)
Block(5,19,4,LEAVES:1)
Block(5,19,5,LEAVES:1)
Block(5,19,6,LEAVES:1)
Block(5,19,7,LEAVES:1)
Block(5,20,0,LEAVES:1)
Block(5,20,1,LEAVES:1)
Block(5,20,6,LEAVES:1)
Block(5,22,-4,LEAVES:1)
Block(5,22,-2,LEAVES:1)
Block(5,23,-5,LEAVES:1)
Block(5,23,-4,LEAVES:1)
Block(5,23,-3,LEAVES:1)
Block(5,23,-2,LEAVES:1)
Block(5,23,0,LEAVES:1)
Block(5,24,-4,LEAVES:1)
Block(5,24,-3,LEAVES:1)
Block(5,24,-1,LEAVES:1)
Block(5,26,4,LEAVES:1)
Block(5,28,2,LEAVES:1)
Block(5,28,4,LEAVES:1)
Block(5,29,2,LEAVES:1)
Block(5,29,3,LEAVES:1)
Block(5,29,4,LEAVES:1)
Block(5,29,5,LEAVES:1)
Block(5,30,4,LEAVES:1)
Block(6,9,-9,LEAVES:1)
Block(6,10,-8,LEAVES:1)
Block(6,12,5,LEAVES:1)
Block(6,13,-4,LEAVES:1)
Block(6,13,-1,LEAVES:1)
Block(6,13,1,LEAVES:1)
Block(6,13,3,LEAVES:1)
Block(6,14,-3,LEAVES:1)
Block(6,14,-2,LEAVES:1)
Block(6,14,-1,LOG:13)
Block(6,14,0,LEAVES:1)
Block(6,14,1,LEAVES:1)
Block(6,14,2,LOG:13)
Block(6,14,3,LEAVES:1)
Block(6,14,4,LEAVES:1)
Block(6,15,-1,LEAVES:1)
Block(6,15,0,LEAVES:1)
Block(6,15,1,LEAVES:1)
Block(6,15,2,LEAVES:1)
Block(6,15,3,LEAVES:1)
Block(6,16,1,LEAVES:1)
Block(6,18,-1,LEAVES:1)
Block(6,18,1,LEAVES:1)
Block(6,18,4,LEAVES:1)
Block(6,19,0,LEAVES:1)
Block(6,19,1,LEAVES:1)
Block(6,19,2,LEAVES:1)
Block(6,19,3,LEAVES:1)
Block(6,19,6,LEAVES:1)
Block(6,20,1,LEAVES:1)
Block(6,20,2,LEAVES:1)
Block(6,21,1,LEAVES:1)
Block(6,22,-5,LEAVES:1)
Block(6,22,0,LEAVES:1)
Block(6,23,-4,LEAVES:1)
Block(6,23,-3,LEAVES:1)
Block(6,27,2,LEAVES:1)
Block(6,29,4,LEAVES:1)
Block(7,13,-3,LEAVES:1)
Block(7,13,-2,LEAVES:1)
Block(7,13,0,LEAVES:1)
Block(7,13,4,LEAVES:1)
Block(7,14,-4,LEAVES:1)
Block(7,14,-3,LEAVES:1)
Block(7,14,-2,LOG:13)
Block(7,14,-1,LEAVES:1)
Block(7,14,1,LEAVES:1)
Block(7,14,2,LOG:13)
Block(7,14,3,LEAVES:1)
Block(7,15,-3,LEAVES:1)
Block(7,15,-2,LEAVES:1)
Block(7,15,1,LEAVES:1)
Block(7,15,2,LEAVES:1)
Block(7,17,0,LEAVES:1)
Block(7,18,3,LEAVES:1)
Block(7,19,1,LEAVES:1)
Block(7,19,2,LEAVES:1)
Block(8,11,-5,LEAVES:1)
Block(8,12,-4,LEAVES:1)
Block(8,12,1,LEAVES:1)
Block(8,12,3,LEAVES:1)
Block(8,13,-3,LEAVES:1)
Block(8,13,-2,LOG:13)
Block(8,13,-1,LEAVES:1)
Block(8,13,1,LEAVES:1)
Block(8,13,2,LEAVES:1)
Block(8,13,3,LOG:13)
Block(8,13,4,LEAVES:1)
Block(8,14,-3,LEAVES:1)
Block(8,14,-2,LEAVES:1)
Block(8,14,2,LEAVES:1)
Block(8,14,3,LEAVES:1)
Block(8,18,1,LEAVES:1)
Block(9,11,-3,LEAVES:1)
Block(9,12,-5,LEAVES:1)
Block(9,12,-4,LEAVES:1)
Block(9,12,-3,LEAVES:1)
Block(9,12,-2,LEAVES:1)
Block(9,12,0,LEAVES:1)
Block(9,12,3,LEAVES:1)
Block(9,13,-4,LEAVES:1)
Block(9,13,-3,LEAVES:1)
Block(9,13,-2,LOG:13)
Block(9,13,-1,LEAVES:1)
Block(9,13,2,LEAVES:1)
Block(9,13,3,LEAVES:1)
Block(9,13,4,LEAVES:1)
Block(9,14,-3,LEAVES:1)
Block(9,14,-2,LEAVES:1)
Block(9,14,3,LEAVES:1)
Block(10,11,-5,LEAVES:1)
Block(10,11,-1,LEAVES:1)
Block(10,12,-4,LEAVES:1)
Block(10,12,-3,LOG:13)
Block(10,12,-2,LEAVES:1)
Block(10,12,-1,LEAVES:1)
Block(10,13,-3,LEAVES:1)
Block(10,13,-2,LEAVES:1)
Block(10,13,3,LEAVES:1)
Block(11,11,-4,LEAVES:1)
Block(11,11,-2,LEAVES:1)
Block(11,12,-4,LEAVES:1)
Block(11,12,-3,LEAVES:1)
Block(11,12,-2,LEAVES:1)
Block(11,13,-3,LEAVES:1)
Block(12,10,-5,LEAVES:1)
Block(12,11,-3,LEAVES:1)
Block(12,11,-1,LEAVES:1)
Block(12,12,-4,LEAVES:1)
Block(12,12,-3,LEAVES:1)
Block(12,12,-2,LEAVES:1)
Block(12,13,-3,LEAVES:1)
Block(13,10,-2,LEAVES:1)
Block(13,11,-4,LEAVES:1)
Block(13,11,-2,LEAVES:1)
Block(13,12,-3,LEAVES:1)

#######################################################################
# +-----------------------------------------------------------------+ #
# |                            BO3 checks                           | #
# +-----------------------------------------------------------------+ #
#######################################################################


#######################################################################
# +-----------------------------------------------------------------+ #
# |                             Branches                            | #
# +-----------------------------------------------------------------+ #
#######################################################################


#######################################################################
# +-----------------------------------------------------------------+ #
# |                             Entities                            | #
# +-----------------------------------------------------------------+ #
#######################################################################


#######################################################################
# +-----------------------------------------------------------------+ #
# |                            Particles                            | #
# +-----------------------------------------------------------------+ #
#######################################################################


#######################################################################
# +-----------------------------------------------------------------+ #
# |                             Spawners                            | #
# +-----------------------------------------------------------------+ #
#######################################################################


#######################################################################
# +-----------------------------------------------------------------+ #
# |                             ModData                             | #
# +-----------------------------------------------------------------+ #
#######################################################################

