
#######################################################################
# +-----------------------------------------------------------------+ #
# |                            BO3 object                           | #
# +-----------------------------------------------------------------+ #
#######################################################################

Author: Unknown

Description: Converted version of the BO2 SpruceBaldCypress2

Version: 3

SettingsMode: WriteWithoutComments


#######################################################################
# +-----------------------------------------------------------------+ #
# |                          Main settings                          | #
# +-----------------------------------------------------------------+ #
#######################################################################

Tree: true

Frequency: 1

Rarity: 30.0

RotateRandomly: true

SpawnHeight: highestSolidBlock

SpawnHeightOffset: 0

SpawnHeightVariance: 0

##############################
# Height Limits for the BO3. #
##############################

MinHeight: 61

MaxHeight: 64

######################
# Extrusion settings #
######################

ExtrudeMode: None

ExtrudeThroughBlocks: AIR

MaxBranchDepth: 10

ExcludedBiomes: All


#######################################################################
# +-----------------------------------------------------------------+ #
# |                      Source block settings                      | #
# +-----------------------------------------------------------------+ #
#######################################################################

SourceBlocks: STONE:1,STONE:3,STONE:5,DIRT:1,DIRT,SAND,GRASS,DIRT:2,STATIONARY_WATER,HARD_CLAY,STAINED_CLAY,CLAY,SANDSTONE,SAND:1,AIR,STONE,GRAVEL,LONG_GRASS,LONG_GRASS:1,LONG_GRASS:2,DEAD_BUSH,YELLOW_FLOWER,RED_ROSE,BROWN_MUSHROOM,RED_MUSHROOM,biomesoplenty:plant_0:1,biomesoplenty:plant_0:2,biomesoplenty:plant_0:3,biomesoplenty:plant_0:4,biomesoplenty:plant_0:5,biomesoplenty:plant_0:6,biomesoplenty:plant_0:7,biomesoplenty:plant_0:8,biomesoplenty:plant_0:9,biomesoplenty:plant_0:10,biomesoplenty:plant_0:11,biomesoplenty:plant_0:12,biomesoplenty:plant_0:13,biomesoplenty:plant_0:14,biomesoplenty:flower_0:1,biomesoplenty:flower_0:2,biomesoplenty:flower_0:3,biomesoplenty:flower_0:4,biomesoplenty:flower_0:5,biomesoplenty:flower_0:6,biomesoplenty:flower_0:7,biomesoplenty:flower_0:8,biomesoplenty:flower_0:9,biomesoplenty:flower_0:10,biomesoplenty:flower_0:11,biomesoplenty:flower_0:12,biomesoplenty:flower_0:13,biomesoplenty:flower_0:14,biomesoplenty:plant_1,biomesoplenty:grass:0,biomesoplenty:grass:1,biomesoplenty:grass,biomesoplenty:grass:3,biomesoplenty:grass:4,biomesoplenty:grass:5,biomesoplenty:grass:6,biomesoplenty:grass:7,biomesoplenty:dirt,biomesoplenty:dirt:1,biomesoplenty:dirt:2,biomesoplenty:dirt:8,biomesoplenty:dirt:9,biomesoplenty:dirt:10,biomesoplenty:dried_sand,biomesoplenty:hard_ice,biomesoplenty:white_sand,biomesoplenty:white_sandstone,biomesoplenty:mud,biomesoplenty:ash_block

MaxPercentageOutsideSourceBlock: 0

OutsideSourceBlock: placeAnyway

DoReplaceBlocks: true

IsOTGPlus: false


#######################################################################
# +-----------------------------------------------------------------+ #
# |                              Blocks                             | #
# +-----------------------------------------------------------------+ #
#######################################################################

Block(-3,31,-7,LEAVES:1)
Block(-3,30,-7,LEAVES:1)
Block(1,8,-4,LOG:13)
Block(1,9,-4,LOG:13)
Block(1,6,-4,LOG:13)
Block(1,7,-4,LOG:13)
Block(0,33,-6,LEAVES:1)
Block(0,31,-6,LEAVES:1)
Block(0,30,-6,LEAVES:1)
Block(0,19,9,LEAVES:1)
Block(0,34,-6,LEAVES:1)
Block(2,26,4,LEAVES:1)
Block(2,27,4,LEAVES:1)
Block(2,25,4,LEAVES:1)
Block(2,20,4,LEAVES:1)
Block(4,30,-2,LEAVES:1)
Block(2,21,4,LEAVES:1)
Block(4,31,-2,LEAVES:1)
Block(2,11,-5,LOG:13)
Block(2,10,-5,LOG:13)
Block(-7,26,-3,LEAVES:1)
Block(-7,27,-3,LEAVES:1)
Block(1,19,-1,LOG:13)
Block(5,27,1,LEAVES:1)
Block(5,26,1,LEAVES:1)
Block(5,25,1,LEAVES:1)
Block(5,24,1,LEAVES:1)
Block(5,28,1,LEAVES:1)
Block(-2,34,-3,LEAVES:1)
Block(0,10,-6,LOG:13)
Block(4,25,-2,LEAVES:1)
Block(5,31,-6,LEAVES:1)
Block(4,24,-2,LEAVES:1)
Block(5,30,-6,LEAVES:1)
Block(-4,19,5,LEAVES:1)
Block(4,27,-2,LEAVES:1)
Block(4,28,-2,LEAVES:1)
Block(6,20,5,LEAVES:1)
Block(6,27,-1,LEAVES:1)
Block(6,24,-1,LEAVES:1)
Block(6,25,-1,LEAVES:1)
Block(6,21,5,LEAVES:1)
Block(-2,33,-3,LEAVES:1)
Block(-2,32,-3,LEAVES:1)
Block(-2,31,-3,LEAVES:1)
Block(-2,30,-3,LEAVES:1)
Block(2,34,-5,LEAVES:1)
Block(2,33,-5,LEAVES:1)
Block(2,31,-5,LEAVES:1)
Block(2,30,-5,LEAVES:1)
Block(-5,27,-4,LEAVES:1)
Block(-5,26,-4,LOG:13)
Block(0,6,-6,LOG:13)
Block(2,26,-3,LEAVES:1)
Block(2,27,-3,LEAVES:1)
Block(1,8,-2,LOG:13)
Block(1,9,-2,LOG:13)
Block(1,6,-2,LOG:13)
Block(-2,6,-5,LOG:13)
Block(1,7,-2,LOG:13)
Block(0,8,-6,LOG:13)
Block(-5,30,-4,LEAVES:1)
Block(0,7,-6,LOG:13)
Block(0,9,-6,LOG:13)
Block(-3,26,3,LEAVES:1)
Block(6,20,3,LEAVES:1)
Block(6,21,3,LEAVES:1)
Block(2,33,-3,LEAVES:1)
Block(2,34,-3,LEAVES:1)
Block(2,31,-3,LEAVES:1)
Block(2,32,-3,LEAVES:1)
Block(1,24,2,LEAVES:1)
Block(2,30,-3,LEAVES:1)
Block(6,24,3,LEAVES:1)
Block(1,25,2,LEAVES:1)
Block(1,26,2,LEAVES:1)
Block(1,27,2,LEAVES:1)
Block(6,25,3,LEAVES:1)
Block(1,28,2,LEAVES:1)
Block(3,20,6,LEAVES:1)
Block(3,21,6,LEAVES:1)
Block(0,30,-4,LOG:13)
Block(0,31,-4,LOG:13)
Block(0,34,-4,LEAVES:1)
Block(0,35,-4,LEAVES:1)
Block(0,32,-4,LOG:13)
Block(0,33,-4,LOG:13)
Block(2,25,2,LEAVES:1)
Block(2,24,2,LEAVES:1)
Block(2,20,2,LOG:13)
Block(-1,20,6,LEAVES:1)
Block(2,27,2,LEAVES:1)
Block(2,26,2,LEAVES:1)
Block(2,28,2,LEAVES:1)
Block(2,8,-2,LOG:13)
Block(2,7,-2,LOG:13)
Block(2,6,-2,LOG:13)
Block(-1,19,6,LOG:13)
Block(2,9,-2,LOG:13)
Block(0,6,-4,LOG:13)
Block(3,20,4,LOG:13)
Block(2,30,-7,LEAVES:1)
Block(0,8,-4,LOG:13)
Block(0,7,-4,LOG:13)
Block(-1,26,-1,LEAVES:1)
Block(-1,27,-1,LEAVES:1)
Block(-2,27,1,LEAVES:1)
Block(-2,26,1,LEAVES:1)
Block(-2,7,-3,LOG:13)
Block(-1,32,-1,LEAVES:1)
Block(3,24,4,LEAVES:1)
Block(0,9,-4,LOG:13)
Block(1,19,4,LEAVES:1)
Block(5,30,-4,LEAVES:1)
Block(6,30,-3,LEAVES:1)
Block(3,21,4,LEAVES:1)
Block(-2,6,-3,LOG:13)
Block(5,31,-4,LEAVES:1)
Block(3,26,4,LEAVES:1)
Block(3,25,4,LEAVES:1)
Block(-1,1,-7,LOG:13)
Block(-1,0,-7,LOG:13)
Block(6,21,7,LEAVES:1)
Block(6,20,7,LEAVES:1)
Block(-1,33,-1,LEAVES:1)
Block(-1,2,-7,LOG:13)
Block(0,33,0,LEAVES:1)
Block(0,32,0,LEAVES:1)
Block(-3,19,5,LEAVES:1)
Block(-6,27,-1,LEAVES:1)
Block(2,32,0,LEAVES:1)
Block(-5,26,-2,LEAVES:1)
Block(-6,26,-1,LEAVES:1)
Block(2,33,0,LEAVES:1)
Block(-5,27,-2,LEAVES:1)
Block(0,25,0,LOG:13)
Block(0,28,0,LEAVES:1)
Block(0,27,0,LEAVES:1)
Block(0,26,0,LEAVES:1)
Block(-3,20,5,LEAVES:1)
Block(3,30,-7,LEAVES:1)
Block(4,31,-4,LEAVES:1)
Block(4,30,-4,LEAVES:1)
Block(3,31,-7,LEAVES:1)
Block(1,20,4,LEAVES:1)
Block(1,26,4,LEAVES:1)
Block(2,6,-4,LOG:13)
Block(1,27,4,LEAVES:1)
Block(-7,26,-1,LEAVES:1)
Block(2,9,-4,LOG:13)
Block(2,8,-4,LOG:13)
Block(2,7,-4,LOG:13)
Block(5,26,3,LEAVES:1)
Block(0,6,-2,LOG:13)
Block(0,8,-2,LOG:13)
Block(0,7,-2,LOG:13)
Block(5,24,3,LEAVES:1)
Block(0,9,-2,LOG:13)
Block(5,25,3,LEAVES:1)
Block(-1,10,-3,LOG:13)
Block(-1,12,-3,LOG:13)
Block(-2,32,-1,LEAVES:1)
Block(-1,11,-3,LOG:13)
Block(-2,33,-1,LEAVES:1)
Block(0,25,2,LEAVES:1)
Block(0,26,2,LOG:13)
Block(0,27,2,LEAVES:1)
Block(-4,27,-2,LEAVES:1)
Block(-4,26,-2,LEAVES:1)
Block(5,20,3,LEAVES:1)
Block(5,21,3,LEAVES:1)
Block(4,30,-6,LEAVES:1)
Block(4,31,-6,LEAVES:1)
Block(-2,19,3,LEAVES:1)
Block(-1,20,8,LEAVES:1)
Block(2,28,0,LEAVES:1)
Block(-1,14,-3,LOG:13)
Block(2,24,0,LOG:13)
Block(3,31,-5,LEAVES:1)
Block(-1,13,-3,LOG:13)
Block(2,25,0,LOG:13)
Block(3,30,-5,LEAVES:1)
Block(2,26,0,LEAVES:1)
Block(3,33,-5,LEAVES:1)
Block(2,27,0,LEAVES:1)
Block(1,34,-6,LEAVES:1)
Block(1,33,-6,LEAVES:1)
Block(0,19,2,LOG:13)
Block(-2,26,-1,LEAVES:1)
Block(-1,19,8,LEAVES:1)
Block(1,30,-6,LEAVES:1)
Block(1,31,-6,LEAVES:1)
Block(7,24,0,LEAVES:1)
Block(6,30,-5,LEAVES:1)
Block(1,19,6,LEAVES:1)
Block(4,20,8,LEAVES:1)
Block(4,21,8,LEAVES:1)
Block(2,0,-6,LOG:13)
Block(2,4,-6,LOG:13)
Block(2,3,-6,LOG:13)
Block(2,2,-6,LOG:13)
Block(2,1,-6,LOG:13)
Block(2,6,-6,LOG:13)
Block(2,5,-6,LOG:13)
Block(3,5,-3,LOG:13)
Block(0,27,-1,LEAVES:1)
Block(3,6,-3,LOG:13)
Block(0,26,-1,LEAVES:1)
Block(3,7,-3,LOG:13)
Block(3,8,-3,LOG:13)
Block(3,9,-3,LOG:13)
Block(7,24,2,LEAVES:1)
Block(1,33,-5,LEAVES:1)
Block(1,32,-5,LEAVES:1)
Block(1,34,-5,LEAVES:1)
Block(5,20,7,LEAVES:1)
Block(5,21,7,LEAVES:1)
Block(0,25,-1,LOG:13)
Block(1,31,-5,LEAVES:1)
Block(0,24,-1,LOG:13)
Block(1,30,-5,LEAVES:1)
Block(2,-4,-1,LOG:13)
Block(2,-3,-1,LOG:13)
Block(2,-2,-1,LOG:13)
Block(2,-1,-1,LOG:13)
Block(0,32,-1,LEAVES:1)
Block(0,34,-1,LEAVES:1)
Block(0,33,-1,LEAVES:1)
Block(5,24,-1,LEAVES:1)
Block(5,25,-1,LEAVES:1)
Block(5,26,-1,LEAVES:1)
Block(5,27,-1,LEAVES:1)
Block(5,28,-1,LEAVES:1)
Block(-2,26,3,LEAVES:1)
Block(-2,27,3,LEAVES:1)
Block(1,20,7,LEAVES:1)
Block(-8,26,-3,LEAVES:1)
Block(-1,32,-3,LEAVES:1)
Block(-1,31,-3,LEAVES:1)
Block(-1,34,-3,LEAVES:1)
Block(-8,27,-3,LEAVES:1)
Block(-1,33,-3,LEAVES:1)
Block(-1,30,-3,LEAVES:1)
Block(-4,31,-7,LEAVES:1)
Block(-4,30,-7,LEAVES:1)
Block(-1,6,-2,LOG:13)
Block(-3,19,8,LEAVES:1)
Block(-1,9,-2,LOG:13)
Block(-1,8,-2,LOG:13)
Block(4,20,4,LEAVES:1)
Block(-1,7,-2,LOG:13)
Block(4,21,4,LEAVES:1)
Block(4,24,4,LEAVES:1)
Block(4,25,4,LEAVES:1)
Block(0,10,-1,LOG:13)
Block(1,19,7,LEAVES:1)
Block(0,12,-1,LOG:13)
Block(0,11,-1,LOG:13)
Block(-3,20,8,LEAVES:1)
Block(3,3,-5,LOG:13)
Block(3,4,-5,LOG:13)
Block(3,5,-5,LOG:13)
Block(3,6,-5,LOG:13)
Block(3,7,-5,LOG:13)
Block(-6,27,-3,LEAVES:1)
Block(-3,30,-3,LEAVES:1)
Block(3,8,-5,LOG:13)
Block(3,9,-5,LOG:13)
Block(-3,32,-3,LEAVES:1)
Block(-3,31,-3,LEAVES:1)
Block(-6,26,-3,LEAVES:1)
Block(3,0,-5,LOG:13)
Block(3,1,-5,LOG:13)
Block(3,2,-5,LOG:13)
Block(-1,-2,-7,LOG:13)
Block(-1,-1,-7,LOG:13)
Block(-1,33,-5,LEAVES:1)
Block(-1,34,-5,LEAVES:1)
Block(-1,31,-5,LEAVES:1)
Block(-1,32,-5,LEAVES:1)
Block(-1,30,-5,LEAVES:1)
Block(-3,26,-3,LEAVES:1)
Block(3,10,-3,LOG:13)
Block(-1,-8,-7,LOG:13)
Block(-1,-7,-7,LOG:13)
Block(-1,-6,-7,LOG:13)
Block(4,21,6,LEAVES:1)
Block(-1,-5,-7,LOG:13)
Block(4,20,6,LEAVES:1)
Block(-1,-4,-7,LOG:13)
Block(-1,-3,-7,LOG:13)
Block(-7,26,-7,LEAVES:1)
Block(-3,33,-3,LEAVES:1)
Block(5,31,-3,LEAVES:1)
Block(5,30,-3,LEAVES:1)
Block(1,11,-5,LOG:13)
Block(-1,26,0,LEAVES:1)
Block(1,10,-5,LOG:13)
Block(-1,27,0,LEAVES:1)
Block(1,13,-5,LOG:13)
Block(1,12,-5,LOG:13)
Block(0,26,4,LEAVES:1)
Block(1,14,-5,LOG:13)
Block(2,20,7,LEAVES:1)
Block(0,27,4,LEAVES:1)
Block(2,21,7,LEAVES:1)
Block(3,28,-3,LEAVES:1)
Block(3,27,-3,LEAVES:1)
Block(5,21,5,LEAVES:1)
Block(5,20,5,LEAVES:1)
Block(0,20,4,LEAVES:1)
Block(0,-2,-1,LOG:13)
Block(0,-1,-1,LOG:13)
Block(0,-4,-1,LOG:13)
Block(0,-3,-1,LOG:13)
Block(3,33,-3,LEAVES:1)
Block(-2,19,5,LEAVES:1)
Block(3,32,-3,LEAVES:1)
Block(3,-1,-5,LOG:13)
Block(-1,9,-4,LOG:13)
Block(-1,8,-4,LOG:13)
Block(-1,7,-4,LOG:13)
Block(-1,6,-4,LOG:13)
Block(3,31,-3,LEAVES:1)
Block(3,30,-3,LEAVES:1)
Block(0,19,4,LEAVES:1)
Block(3,28,1,LEAVES:1)
Block(3,26,1,LEAVES:1)
Block(-2,20,5,LEAVES:1)
Block(3,27,1,LEAVES:1)
Block(3,-3,-5,LOG:13)
Block(3,-2,-5,LOG:13)
Block(3,-4,-5,LOG:13)
Block(-1,32,0,LEAVES:1)
Block(3,24,1,LOG:13)
Block(-1,33,0,LEAVES:1)
Block(3,25,1,LOG:13)
Block(1,16,-3,LOG:13)
Block(1,17,-3,LOG:13)
Block(1,18,-3,LOG:13)
Block(-6,27,-7,LEAVES:1)
Block(1,19,-3,LOG:13)
Block(-6,26,-7,LEAVES:1)
Block(3,27,-1,LEAVES:1)
Block(-8,27,-5,LEAVES:1)
Block(3,28,-1,LEAVES:1)
Block(1,10,-3,LOG:13)
Block(1,11,-3,LOG:13)
Block(1,12,-3,LOG:13)
Block(1,13,-3,LOG:13)
Block(3,24,-1,LEAVES:1)
Block(1,14,-3,LOG:13)
Block(3,25,-1,LEAVES:1)
Block(1,15,-3,LOG:13)
Block(3,26,-1,LEAVES:1)
Block(0,20,6,LEAVES:1)
Block(-8,26,-5,LEAVES:1)
Block(-1,20,4,LEAVES:1)
Block(3,30,-1,LEAVES:1)
Block(3,31,-1,LEAVES:1)
Block(-2,33,-5,LEAVES:1)
Block(-2,20,7,LEAVES:1)
Block(3,32,-1,LEAVES:1)
Block(-2,34,-5,LEAVES:1)
Block(-2,30,-5,LOG:13)
Block(2,19,7,LEAVES:1)
Block(-2,31,-5,LEAVES:1)
Block(-1,19,4,LOG:13)
Block(-2,19,7,LEAVES:1)
Block(0,19,6,LEAVES:1)
Block(-3,30,-5,LEAVES:1)
Block(0,28,-3,LOG:13)
Block(0,29,-3,LOG:13)
Block(-3,33,-5,LEAVES:1)
Block(-3,31,-5,LEAVES:1)
Block(4,28,2,LEAVES:1)
Block(-9,26,-5,LEAVES:1)
Block(4,27,2,LEAVES:1)
Block(4,26,2,LEAVES:1)
Block(4,25,2,LEAVES:1)
Block(4,24,2,LEAVES:1)
Block(4,21,2,LEAVES:1)
Block(4,20,2,LEAVES:1)
Block(1,30,-3,LOG:13)
Block(1,31,-3,LOG:13)
Block(1,32,-3,LOG:13)
Block(1,33,-3,LOG:13)
Block(1,34,-3,LEAVES:1)
Block(7,20,4,LEAVES:1)
Block(1,35,-3,LEAVES:1)
Block(0,22,-3,LOG:13)
Block(-3,26,-5,LEAVES:1)
Block(0,23,-3,LOG:13)
Block(0,20,-3,LOG:13)
Block(0,21,-3,LOG:13)
Block(0,26,-3,LOG:13)
Block(0,27,-3,LOG:13)
Block(0,24,-3,LOG:13)
Block(-1,26,4,LEAVES:1)
Block(0,25,-3,LOG:13)
Block(-1,27,4,LEAVES:1)
Block(1,27,-3,LOG:13)
Block(1,28,-3,LOG:13)
Block(-5,26,-7,LEAVES:1)
Block(1,29,-3,LOG:13)
Block(2,13,-3,LOG:13)
Block(2,14,-3,LOG:13)
Block(1,20,-3,LOG:13)
Block(2,11,-3,LOG:13)
Block(1,21,-3,LOG:13)
Block(2,12,-3,LOG:13)
Block(1,22,-3,LOG:13)
Block(1,23,-3,LOG:13)
Block(2,10,-3,LOG:13)
Block(1,24,-3,LOG:13)
Block(-9,26,-3,LEAVES:1)
Block(0,30,-3,LOG:13)
Block(1,25,-3,LOG:13)
Block(1,26,-3,LOG:13)
Block(0,33,-3,LOG:13)
Block(0,34,-3,LEAVES:1)
Block(0,31,-3,LOG:13)
Block(0,32,-3,LOG:13)
Block(0,35,-3,LEAVES:1)
Block(-4,26,-5,LEAVES:1)
Block(-4,27,-5,LEAVES:1)
Block(3,20,8,LEAVES:1)
Block(2,21,5,LEAVES:1)
Block(4,30,-1,LEAVES:1)
Block(1,8,-6,LOG:13)
Block(1,9,-6,LOG:13)
Block(1,6,-6,LOG:13)
Block(1,7,-6,LOG:13)
Block(7,20,6,LEAVES:1)
Block(4,-2,-3,LOG:13)
Block(2,20,5,LEAVES:1)
Block(4,-1,-3,LOG:13)
Block(1,33,-1,LEAVES:1)
Block(1,32,-1,LEAVES:1)
Block(-4,31,-5,LEAVES:1)
Block(-4,30,-5,LEAVES:1)
Block(-1,27,2,LEAVES:1)
Block(4,-3,-3,LOG:13)
Block(-1,26,2,LEAVES:1)
Block(0,19,-3,LOG:13)
Block(1,19,0,LOG:13)
Block(0,17,-3,LOG:13)
Block(0,18,-3,LOG:13)
Block(1,28,-1,LEAVES:1)
Block(1,27,-1,LEAVES:1)
Block(1,26,-1,LOG:13)
Block(1,25,-1,LEAVES:1)
Block(0,11,-3,LOG:13)
Block(1,24,-1,LOG:13)
Block(4,24,-1,LEAVES:1)
Block(0,12,-3,LOG:13)
Block(4,25,-1,LEAVES:1)
Block(0,10,-3,LOG:13)
Block(0,15,-3,LOG:13)
Block(4,28,-1,LEAVES:1)
Block(0,16,-3,LOG:13)
Block(0,13,-3,LOG:13)
Block(4,26,-1,LEAVES:1)
Block(0,14,-3,LOG:13)
Block(4,27,-1,LEAVES:1)
Block(1,28,0,LEAVES:1)
Block(1,27,0,LEAVES:1)
Block(1,26,0,LOG:13)
Block(1,25,0,LOG:13)
Block(1,24,0,LEAVES:1)
Block(-6,26,-5,LEAVES:1)
Block(2,28,-1,LEAVES:1)
Block(1,20,0,LOG:13)
Block(-6,27,-5,LEAVES:1)
Block(2,25,-1,LEAVES:1)
Block(2,24,-1,LEAVES:1)
Block(2,27,-1,LOG:13)
Block(2,26,-1,LEAVES:1)
Block(-1,33,-7,LEAVES:1)
Block(-1,31,-7,LEAVES:1)
Block(-1,30,-7,LEAVES:1)
Block(-4,20,6,LEAVES:1)
Block(-3,26,1,LEAVES:1)
Block(1,33,0,LEAVES:1)
Block(1,32,0,LEAVES:1)
Block(-2,31,-7,LEAVES:1)
Block(-2,30,-7,LEAVES:1)
Block(2,19,5,LEAVES:1)
Block(2,32,-1,LEAVES:1)
Block(2,33,-1,LEAVES:1)
Block(-7,27,-5,LEAVES:1)
Block(-7,26,-5,LEAVES:1)
Block(2,30,-1,LEAVES:1)
Block(-4,19,6,LEAVES:1)
Block(6,24,1,LEAVES:1)
Block(6,25,1,LEAVES:1)
Block(6,26,1,LEAVES:1)
Block(6,27,1,LEAVES:1)
Block(2,34,-4,LEAVES:1)
Block(2,33,-4,LEAVES:1)
Block(2,32,-4,LEAVES:1)
Block(2,31,-4,LEAVES:1)
Block(2,30,-4,LOG:13)
Block(1,24,1,LEAVES:1)
Block(1,25,1,LEAVES:1)
Block(1,26,1,LEAVES:1)
Block(1,27,1,LEAVES:1)
Block(1,28,1,LEAVES:1)
Block(3,20,7,LEAVES:1)
Block(3,21,7,LEAVES:1)
Block(-5,27,-5,LEAVES:1)
Block(-5,26,-5,LEAVES:1)
Block(2,-1,-6,LOG:13)
Block(2,-2,-6,LOG:13)
Block(2,-3,-6,LOG:13)
Block(-2,34,-2,LEAVES:1)
Block(-2,33,-2,LEAVES:1)
Block(-5,31,-5,LEAVES:1)
Block(-5,30,-5,LEAVES:1)
Block(-1,20,7,LEAVES:1)
Block(0,20,8,LEAVES:1)
Block(2,25,3,LEAVES:1)
Block(2,26,3,LEAVES:1)
Block(2,24,3,LEAVES:1)
Block(2,21,3,LEAVES:1)
Block(-3,27,2,LEAVES:1)
Block(2,20,3,LEAVES:1)
Block(-3,26,2,LEAVES:1)
Block(-2,10,-4,LOG:13)
Block(2,27,3,LEAVES:1)
Block(1,9,-3,LOG:13)
Block(1,7,-3,LOG:13)
Block(1,8,-3,LOG:13)
Block(-7,26,-4,LEAVES:1)
Block(1,6,-3,LOG:13)
Block(-7,27,-4,LEAVES:1)
Block(-1,19,7,LEAVES:1)
Block(-3,30,-8,LEAVES:1)
Block(-2,19,9,LEAVES:1)
Block(1,32,1,LEAVES:1)
Block(0,19,8,LEAVES:1)
Block(4,28,0,LEAVES:1)
Block(4,26,0,LEAVES:1)
Block(-1,20,5,LEAVES:1)
Block(4,27,0,LEAVES:1)
Block(4,24,0,LEAVES:1)
Block(-2,31,-4,LEAVES:1)
Block(4,25,0,LEAVES:1)
Block(-2,32,-4,LEAVES:1)
Block(-2,33,-4,LEAVES:1)
Block(-2,34,-4,LEAVES:1)
Block(-2,30,-4,LEAVES:1)
Block(-2,25,-4,LOG:13)
Block(-7,27,-2,LEAVES:1)
Block(-7,26,-2,LEAVES:1)
Block(-1,19,5,LOG:13)
Block(5,26,0,LEAVES:1)
Block(5,25,0,LEAVES:1)
Block(-2,27,0,LEAVES:1)
Block(5,24,0,LEAVES:1)
Block(-2,26,0,LEAVES:1)
Block(5,28,0,LEAVES:1)
Block(5,27,0,LEAVES:1)
Block(2,1,-1,LOG:13)
Block(2,0,-1,LOG:13)
Block(2,5,-1,LOG:13)
Block(0,32,-5,LEAVES:1)
Block(2,4,-1,LOG:13)
Block(0,31,-5,LEAVES:1)
Block(2,3,-1,LOG:13)
Block(0,30,-5,LEAVES:1)
Block(2,2,-1,LOG:13)
Block(2,9,-1,LOG:13)
Block(2,8,-1,LOG:13)
Block(-1,26,5,LEAVES:1)
Block(2,7,-1,LOG:13)
Block(0,34,-5,LEAVES:1)
Block(2,6,-1,LOG:13)
Block(0,33,-5,LEAVES:1)
Block(4,30,-3,LEAVES:1)
Block(-4,26,-3,LEAVES:1)
Block(6,20,4,LEAVES:1)
Block(-4,27,-3,LEAVES:1)
Block(6,21,4,LEAVES:1)
Block(4,31,-3,LEAVES:1)
Block(2,14,-4,LOG:13)
Block(2,13,-4,LOG:13)
Block(2,12,-4,LOG:13)
Block(1,7,-1,LOG:13)
Block(2,11,-4,LOG:13)
Block(2,10,-4,LOG:13)
Block(1,25,3,LEAVES:1)
Block(1,6,-1,LOG:13)
Block(1,27,3,LEAVES:1)
Block(1,26,3,LEAVES:1)
Block(-4,30,-3,LEAVES:1)
Block(-4,31,-3,LEAVES:1)
Block(-5,26,-3,LEAVES:1)
Block(-5,27,-3,LEAVES:1)
Block(-3,19,4,LEAVES:1)
Block(0,10,-5,LOG:13)
Block(0,14,-5,LOG:13)
Block(4,27,-3,LEAVES:1)
Block(0,13,-5,LOG:13)
Block(0,12,-5,LOG:13)
Block(0,11,-5,LOG:13)
Block(-3,20,4,LEAVES:1)
Block(3,30,-6,LEAVES:1)
Block(2,24,1,LEAVES:1)
Block(-1,20,9,LEAVES:1)
Block(4,30,-5,LEAVES:1)
Block(2,20,1,LOG:13)
Block(4,31,-5,LEAVES:1)
Block(4,20,7,LEAVES:1)
Block(2,26,1,LEAVES:1)
Block(4,21,7,LEAVES:1)
Block(2,25,1,LEAVES:1)
Block(2,28,1,LEAVES:1)
Block(3,31,-6,LEAVES:1)
Block(2,27,1,LEAVES:1)
Block(0,19,1,LOG:13)
Block(-1,19,9,LEAVES:1)
Block(5,24,4,LEAVES:1)
Block(-6,26,-2,LEAVES:1)
Block(-6,27,-2,LEAVES:1)
Block(-1,10,-2,LOG:13)
Block(-1,11,-2,LOG:13)
Block(2,7,-3,LOG:13)
Block(5,20,4,LEAVES:1)
Block(2,6,-3,LOG:13)
Block(5,21,4,LEAVES:1)
Block(2,9,-3,LOG:13)
Block(2,8,-3,LOG:13)
Block(0,7,-5,LOG:13)
Block(0,6,-5,LOG:13)
Block(-2,33,0,LEAVES:1)
Block(-2,32,0,LEAVES:1)
Block(-2,6,-4,LOG:13)
Block(-2,7,-4,LOG:13)
Block(-2,8,-4,LOG:13)
Block(-2,9,-4,LOG:13)
Block(0,9,-5,LOG:13)
Block(0,8,-5,LOG:13)
Block(3,21,5,LEAVES:1)
Block(3,20,5,LEAVES:1)
Block(-1,7,-6,LOG:13)
Block(-1,6,-6,LOG:13)
Block(-1,5,-6,LOG:13)
Block(-1,4,-6,LOG:13)
Block(-1,3,-6,LOG:13)
Block(-2,-4,-2,LOG:13)
Block(-2,-3,-2,LOG:13)
Block(-2,-2,-2,LOG:13)
Block(-2,-1,-2,LOG:13)
Block(-2,-8,-2,LOG:13)
Block(-2,-7,-2,LOG:13)
Block(-2,-6,-2,LOG:13)
Block(-2,-5,-2,LOG:13)
Block(6,20,6,LEAVES:1)
Block(6,21,6,LEAVES:1)
Block(-1,34,-2,LEAVES:1)
Block(1,20,5,LEAVES:1)
Block(1,21,5,LEAVES:1)
Block(1,26,5,LEAVES:1)
Block(-3,19,6,LEAVES:1)
Block(-5,26,-1,LEAVES:1)
Block(7,25,1,LEAVES:1)
Block(7,24,1,LEAVES:1)
Block(3,28,3,LEAVES:1)
Block(6,30,-4,LEAVES:1)
Block(6,31,-4,LEAVES:1)
Block(1,19,5,LEAVES:1)
Block(3,21,3,LEAVES:1)
Block(3,20,3,LOG:13)
Block(2,9,-5,LOG:13)
Block(3,27,3,LEAVES:1)
Block(2,8,-5,LOG:13)
Block(3,26,3,LEAVES:1)
Block(2,7,-5,LOG:13)
Block(-3,20,6,LEAVES:1)
Block(3,25,3,LEAVES:1)
Block(2,6,-5,LOG:13)
Block(3,24,3,LEAVES:1)
Block(0,7,-3,LOG:13)
Block(0,6,-3,LOG:13)
Block(0,9,-3,LOG:13)
Block(0,8,-3,LOG:13)
Block(-2,32,-2,LEAVES:1)
Block(-2,31,-2,LEAVES:1)
Block(-2,30,-2,LEAVES:1)
Block(-2,9,-2,LOG:13)
Block(-2,8,-2,LOG:13)
Block(-2,3,-2,LOG:13)
Block(-2,2,-2,LOG:13)
Block(-2,1,-2,LOG:13)
Block(-2,0,-2,LOG:13)
Block(-2,7,-2,LOG:13)
Block(0,33,1,LEAVES:1)
Block(-2,6,-2,LOG:13)
Block(0,32,1,LEAVES:1)
Block(1,33,-7,LEAVES:1)
Block(-2,5,-2,LOG:13)
Block(-2,4,-2,LOG:13)
Block(5,25,2,LEAVES:1)
Block(5,26,2,LEAVES:1)
Block(5,27,2,LEAVES:1)
Block(5,28,2,LEAVES:1)
Block(2,30,-6,LEAVES:1)
Block(5,24,2,LEAVES:1)
Block(2,31,-6,LEAVES:1)
Block(-1,27,-2,LEAVES:1)
Block(-2,27,2,LEAVES:1)
Block(2,33,-6,LEAVES:1)
Block(2,34,-6,LEAVES:1)
Block(-2,26,2,LEAVES:1)
Block(-1,26,-2,LEAVES:1)
Block(0,26,1,LOG:13)
Block(-1,30,-2,LEAVES:1)
Block(0,31,-7,LEAVES:1)
Block(0,25,1,LEAVES:1)
Block(-1,32,-2,LEAVES:1)
Block(0,33,-7,LEAVES:1)
Block(-1,33,-2,LEAVES:1)
Block(0,34,-7,LEAVES:1)
Block(0,27,1,LEAVES:1)
Block(0,30,-7,LEAVES:1)
Block(5,30,-5,LEAVES:1)
Block(5,31,-5,LEAVES:1)
Block(-3,32,-1,LEAVES:1)
Block(5,20,2,LEAVES:1)
Block(-2,30,-8,LEAVES:1)
Block(-3,19,7,LEAVES:1)
Block(-2,19,4,LEAVES:1)
Block(-1,14,-4,LOG:13)
Block(-2,31,-8,LEAVES:1)
Block(-2,20,4,LEAVES:1)
Block(-3,20,7,LEAVES:1)
Block(5,24,-2,LEAVES:1)
Block(5,27,-2,LEAVES:1)
Block(5,28,-2,LEAVES:1)
Block(-3,30,-2,LEAVES:1)
Block(-2,27,4,LEAVES:1)
Block(-1,9,-3,LOG:13)
Block(-2,26,4,LEAVES:1)
Block(-1,8,-3,LOG:13)
Block(1,20,6,LEAVES:1)
Block(-1,25,-4,LOG:13)
Block(-1,7,-3,LOG:13)
Block(-1,6,-3,LOG:13)
Block(-1,27,1,LEAVES:1)
Block(-1,33,-4,LEAVES:1)
Block(-1,32,-4,LEAVES:1)
Block(-1,34,-4,LEAVES:1)
Block(0,26,3,LEAVES:1)
Block(0,27,3,LEAVES:1)
Block(-1,31,-4,LEAVES:1)
Block(-1,30,-4,LOG:13)
Block(-1,26,1,LEAVES:1)
Block(0,5,-1,LOG:13)
Block(3,6,-2,LOG:13)
Block(0,4,-1,LOG:13)
Block(0,7,-1,LOG:13)
Block(0,6,-1,LOG:13)
Block(0,9,-1,LOG:13)
Block(0,8,-1,LOG:13)
Block(3,34,-4,LEAVES:1)
Block(3,33,-4,LEAVES:1)
Block(4,30,-7,LEAVES:1)
Block(0,1,-1,LOG:13)
Block(3,30,-4,LOG:13)
Block(0,0,-1,LOG:13)
Block(0,3,-1,LOG:13)
Block(0,2,-1,LOG:13)
Block(3,31,-4,LEAVES:1)
Block(6,28,0,LEAVES:1)
Block(0,19,3,LEAVES:1)
Block(3,27,2,LEAVES:1)
Block(3,28,2,LEAVES:1)
Block(-3,33,-2,LEAVES:1)
Block(-3,-1,-4,LOG:13)
Block(-3,32,-2,LEAVES:1)
Block(-1,32,1,LEAVES:1)
Block(3,20,2,LEAVES:1)
Block(-3,-4,-4,LOG:13)
Block(6,24,0,LEAVES:1)
Block(3,25,2,LEAVES:1)
Block(6,25,0,LEAVES:1)
Block(3,26,2,LEAVES:1)
Block(-3,-2,-4,LOG:13)
Block(-3,-3,-4,LOG:13)
Block(3,24,2,LEAVES:1)
Block(6,27,0,LEAVES:1)
Block(-6,27,-4,LEAVES:1)
Block(-6,26,-4,LOG:13)
Block(-1,11,-4,LOG:13)
Block(-1,10,-4,LOG:13)
Block(-1,13,-4,LOG:13)
Block(-1,12,-4,LOG:13)
Block(5,21,6,LEAVES:1)
Block(5,20,6,LEAVES:1)
Block(1,29,-4,LOG:13)
Block(3,31,-2,LEAVES:1)
Block(1,28,-4,LOG:13)
Block(3,32,-2,LEAVES:1)
Block(3,33,-2,LEAVES:1)
Block(3,30,-2,LEAVES:1)
Block(1,21,-4,LOG:13)
Block(3,26,0,LEAVES:1)
Block(1,20,-4,LOG:13)
Block(3,25,0,LEAVES:1)
Block(1,23,-4,LOG:13)
Block(3,28,0,LEAVES:1)
Block(1,22,-4,LOG:13)
Block(3,27,0,LOG:13)
Block(1,19,8,LEAVES:1)
Block(1,25,-4,LOG:13)
Block(1,24,-4,LOG:13)
Block(0,19,5,LEAVES:1)
Block(1,27,-4,LOG:13)
Block(1,26,-4,LOG:13)
Block(3,24,0,LOG:13)
Block(1,18,-4,LOG:13)
Block(1,17,-4,LOG:13)
Block(-1,9,-5,LOG:13)
Block(-1,8,-5,LOG:13)
Block(1,19,-4,LOG:13)
Block(-1,7,-5,LOG:13)
Block(-1,6,-5,LOG:13)
Block(1,10,-4,LOG:13)
Block(1,12,-4,LOG:13)
Block(1,11,-4,LOG:13)
Block(1,14,-4,LOG:13)
Block(1,13,-4,LOG:13)
Block(1,16,-4,LOG:13)
Block(1,15,-4,LOG:13)
Block(3,6,-4,LOG:13)
Block(3,7,-4,LOG:13)
Block(4,20,5,LOG:13)
Block(4,21,5,LEAVES:1)
Block(5,30,-2,LEAVES:1)
Block(5,31,-2,LEAVES:1)
Block(-3,33,-4,LEAVES:1)
Block(-3,30,-4,LEAVES:1)
Block(-3,31,-4,LEAVES:1)
Block(1,20,8,LEAVES:1)
Block(1,32,-4,LOG:13)
Block(1,31,-4,LOG:13)
Block(-8,26,-2,LEAVES:1)
Block(1,34,-4,LEAVES:1)
Block(-8,27,-2,LEAVES:1)
Block(1,33,-4,LOG:13)
Block(1,35,-4,LEAVES:1)
Block(-3,26,-4,LOG:13)
Block(-3,27,-4,LEAVES:1)
Block(1,30,-4,LOG:13)
Block(0,18,-4,LOG:13)
Block(0,19,-4,LOG:13)
Block(-7,26,-6,LEAVES:1)
Block(2,10,-2,LOG:13)
Block(-7,27,-6,LEAVES:1)
Block(2,11,-2,LOG:13)
Block(-9,27,-4,LEAVES:1)
Block(-9,26,-4,LEAVES:1)
Block(4,3,-3,LOG:13)
Block(0,12,-4,LOG:13)
Block(-4,19,7,LEAVES:1)
Block(4,2,-3,LOG:13)
Block(0,13,-4,LOG:13)
Block(0,10,-4,LOG:13)
Block(6,25,2,LEAVES:1)
Block(-3,34,-4,LEAVES:1)
Block(4,4,-3,LOG:13)
Block(0,11,-4,LOG:13)
Block(6,24,2,LEAVES:1)
Block(0,16,-4,LOG:13)
Block(0,17,-4,LOG:13)
Block(4,1,-3,LOG:13)
Block(0,14,-4,LOG:13)
Block(4,0,-3,LOG:13)
Block(0,15,-4,LOG:13)
Block(0,29,-4,LOG:13)
Block(-4,26,-4,LOG:13)
Block(-4,27,-4,LEAVES:1)
Block(4,27,1,LEAVES:1)
Block(4,28,1,LEAVES:1)
Block(4,25,1,LEAVES:1)
Block(4,26,1,LEAVES:1)
Block(4,24,1,LOG:13)
Block(2,27,-2,LOG:13)
Block(2,28,-2,LEAVES:1)
Block(2,25,-2,LEAVES:1)
Block(2,26,-2,LEAVES:1)
Block(1,30,-2,LEAVES:1)
Block(1,31,-2,LEAVES:1)
Block(1,32,-2,LEAVES:1)
Block(7,21,5,LEAVES:1)
Block(1,33,-2,LEAVES:1)
Block(0,20,-4,LOG:13)
Block(7,20,5,LEAVES:1)
Block(1,34,-2,LEAVES:1)
Block(0,23,-4,LOG:13)
Block(0,24,-4,LOG:13)
Block(0,21,-4,LOG:13)
Block(0,22,-4,LOG:13)
Block(0,27,-4,LOG:13)
Block(0,28,-4,LOG:13)
Block(-4,30,-4,LEAVES:1)
Block(0,25,-4,LOG:13)
Block(-4,31,-4,LEAVES:1)
Block(0,26,-4,LOG:13)
Block(-2,34,-6,LEAVES:1)
Block(-2,33,-6,LEAVES:1)
Block(-2,19,6,LEAVES:1)
Block(-2,30,-6,LEAVES:1)
Block(2,19,6,LEAVES:1)
Block(-2,31,-6,LEAVES:1)
Block(2,34,-2,LEAVES:1)
Block(2,32,-2,LEAVES:1)
Block(2,33,-2,LEAVES:1)
Block(-2,20,6,LEAVES:1)
Block(2,30,-2,LEAVES:1)
Block(2,31,-2,LEAVES:1)
Block(3,28,-2,LEAVES:1)
Block(-1,34,-6,LEAVES:1)
Block(3,24,-2,LEAVES:1)
Block(3,25,-2,LEAVES:1)
Block(0,27,5,LEAVES:1)
Block(-1,33,-6,LEAVES:1)
Block(3,26,-2,LEAVES:1)
Block(-1,30,-6,LEAVES:1)
Block(3,27,-2,LEAVES:1)
Block(-1,31,-6,LEAVES:1)
Block(2,21,6,LEAVES:1)
Block(2,20,6,LEAVES:1)
Block(0,26,5,LEAVES:1)
Block(0,20,5,LEAVES:1)
Block(-8,26,-6,LEAVES:1)
Block(-8,27,-6,LEAVES:1)
Block(-2,20,8,LEAVES:1)
Block(-2,19,8,LEAVES:1)
Block(0,33,-2,LEAVES:1)
Block(0,32,-2,LOG:13)
Block(0,34,-2,LEAVES:1)
Block(-3,31,-6,LEAVES:1)
Block(-1,6,-1,LOG:13)
Block(0,20,7,LEAVES:1)
Block(-3,30,-6,LEAVES:1)
Block(-6,27,-6,LEAVES:1)
Block(-6,26,-6,LEAVES:1)
Block(-8,27,-4,LEAVES:1)
Block(-3,0,-4,LOG:13)
Block(-8,26,-4,LEAVES:1)
Block(-3,1,-4,LOG:13)
Block(-3,2,-4,LOG:13)
Block(-3,3,-4,LOG:13)
Block(-3,4,-4,LOG:13)
Block(-3,5,-4,LOG:13)
Block(-3,6,-4,LOG:13)
Block(-1,30,-8,LEAVES:1)
Block(5,20,8,LEAVES:1)
Block(0,19,-2,LOG:13)
Block(-5,27,-6,LEAVES:1)
Block(-5,26,-6,LEAVES:1)
Block(-1,20,3,LEAVES:1)
Block(1,26,-2,LOG:13)
Block(1,27,-2,LEAVES:1)
Block(1,28,-2,LEAVES:1)
Block(1,9,-5,LOG:13)
Block(1,7,-5,LOG:13)
Block(-1,19,3,LOG:13)
Block(1,8,-5,LOG:13)
Block(1,6,-5,LOG:13)
Block(0,19,7,LEAVES:1)
Block(0,11,-2,LOG:13)
Block(0,10,-2,LOG:13)
Block(-5,30,-6,LEAVES:1)
Block(0,13,-2,LOG:13)
Block(0,12,-2,LOG:13)
Block(0,14,-2,LOG:13)
Block(0,27,-2,LEAVES:1)
Block(-4,27,-6,LEAVES:1)
Block(-4,26,-6,LEAVES:1)
Block(4,27,3,LEAVES:1)
Block(4,26,3,LEAVES:1)
Block(4,25,3,LEAVES:1)
Block(4,24,3,LEAVES:1)
Block(4,21,3,LEAVES:1)
Block(4,20,3,LEAVES:1)
Block(1,10,-2,LOG:13)
Block(1,11,-2,LOG:13)
Block(1,12,-2,LOG:13)
Block(1,13,-2,LOG:13)
Block(1,14,-2,LOG:13)
Block(-4,30,-6,LEAVES:1)
Block(0,24,-2,LOG:13)
Block(-1,26,3,LEAVES:1)
Block(-4,31,-6,LEAVES:1)
Block(0,26,-2,LEAVES:1)
Block(-1,27,3,LEAVES:1)

#######################################################################
# +-----------------------------------------------------------------+ #
# |                            BO3 checks                           | #
# +-----------------------------------------------------------------+ #
#######################################################################

BlockCheck(0,-1,0,GRASS,DIRT:0,DIRT:1,DIRT:2,biomesoplenty:grass:0,biomesoplenty:grass:1,biomesoplenty:grass,biomesoplenty:grass:3,biomesoplenty:grass:4,biomesoplenty:grass:5,biomesoplenty:grass:6,biomesoplenty:grass:7,biomesoplenty:dirt,biomesoplenty:dirt:1,biomesoplenty:dirt:2,biomesoplenty:dirt:8,biomesoplenty:dirt:9,biomesoplenty:dirt:10,biomesoplenty:dried_sand,biomesoplenty:hard_ice,biomesoplenty:white_sand,biomesoplenty:white_sandstone,biomesoplenty:mud,biomesoplenty:ash_block)

#######################################################################
# +-----------------------------------------------------------------+ #
# |                             Branches                            | #
# +-----------------------------------------------------------------+ #
#######################################################################


#######################################################################
# +-----------------------------------------------------------------+ #
# |                             Entities                            | #
# +-----------------------------------------------------------------+ #
#######################################################################


#######################################################################
# +-----------------------------------------------------------------+ #
# |                            Particles                            | #
# +-----------------------------------------------------------------+ #
#######################################################################


#######################################################################
# +-----------------------------------------------------------------+ #
# |                             Spawners                            | #
# +-----------------------------------------------------------------+ #
#######################################################################


#######################################################################
# +-----------------------------------------------------------------+ #
# |                             ModData                             | #
# +-----------------------------------------------------------------+ #
#######################################################################

