
#######################################################################
# +-----------------------------------------------------------------+ #
# |                            BO3 object                           | #
# +-----------------------------------------------------------------+ #
#######################################################################

Author: Unknown

Description: Converted version of the BO2 SpruceBaldCypress6

Version: 3

SettingsMode: WriteWithoutComments


#######################################################################
# +-----------------------------------------------------------------+ #
# |                          Main settings                          | #
# +-----------------------------------------------------------------+ #
#######################################################################

Tree: true

Frequency: 1

Rarity: 30.0

RotateRandomly: true

SpawnHeight: highestSolidBlock

SpawnHeightOffset: 0

SpawnHeightVariance: 0

##############################
# Height Limits for the BO3. #
##############################

MinHeight: 61

MaxHeight: 64

######################
# Extrusion settings #
######################

ExtrudeMode: None

ExtrudeThroughBlocks: AIR

MaxBranchDepth: 10

ExcludedBiomes: All


#######################################################################
# +-----------------------------------------------------------------+ #
# |                      Source block settings                      | #
# +-----------------------------------------------------------------+ #
#######################################################################

SourceBlocks: STONE:1,STONE:3,STONE:5,DIRT:1,DIRT,SAND,GRASS,DIRT:2,STATIONARY_WATER,HARD_CLAY,STAINED_CLAY,CLAY,SANDSTONE,SAND:1,AIR,STONE,GRAVEL,LONG_GRASS,LONG_GRASS:1,LONG_GRASS:2,DEAD_BUSH,YELLOW_FLOWER,RED_ROSE,BROWN_MUSHROOM,RED_MUSHROOM,biomesoplenty:plant_0:1,biomesoplenty:plant_0:2,biomesoplenty:plant_0:3,biomesoplenty:plant_0:4,biomesoplenty:plant_0:5,biomesoplenty:plant_0:6,biomesoplenty:plant_0:7,biomesoplenty:plant_0:8,biomesoplenty:plant_0:9,biomesoplenty:plant_0:10,biomesoplenty:plant_0:11,biomesoplenty:plant_0:12,biomesoplenty:plant_0:13,biomesoplenty:plant_0:14,biomesoplenty:flower_0:1,biomesoplenty:flower_0:2,biomesoplenty:flower_0:3,biomesoplenty:flower_0:4,biomesoplenty:flower_0:5,biomesoplenty:flower_0:6,biomesoplenty:flower_0:7,biomesoplenty:flower_0:8,biomesoplenty:flower_0:9,biomesoplenty:flower_0:10,biomesoplenty:flower_0:11,biomesoplenty:flower_0:12,biomesoplenty:flower_0:13,biomesoplenty:flower_0:14,biomesoplenty:plant_1,biomesoplenty:grass:0,biomesoplenty:grass:1,biomesoplenty:grass,biomesoplenty:grass:3,biomesoplenty:grass:4,biomesoplenty:grass:5,biomesoplenty:grass:6,biomesoplenty:grass:7,biomesoplenty:dirt,biomesoplenty:dirt:1,biomesoplenty:dirt:2,biomesoplenty:dirt:8,biomesoplenty:dirt:9,biomesoplenty:dirt:10,biomesoplenty:dried_sand,biomesoplenty:hard_ice,biomesoplenty:white_sand,biomesoplenty:white_sandstone,biomesoplenty:mud,biomesoplenty:ash_block

MaxPercentageOutsideSourceBlock: 0

OutsideSourceBlock: placeAnyway

DoReplaceBlocks: true

IsOTGPlus: false


#######################################################################
# +-----------------------------------------------------------------+ #
# |                              Blocks                             | #
# +-----------------------------------------------------------------+ #
#######################################################################

Block(2,19,4,LEAVES:1)
Block(2,18,4,LEAVES:1)
Block(2,18,10,LEAVES:1)
Block(1,8,-4,LOG:13)
Block(1,9,-4,LOG:13)
Block(1,6,-4,LOG:13)
Block(1,7,-4,LOG:13)
Block(1,5,-4,LOG:13)
Block(0,32,-6,LEAVES:1)
Block(0,19,9,LEAVES:1)
Block(0,18,9,LEAVES:1)
Block(-1,25,6,LEAVES:1)
Block(-1,24,6,LEAVES:1)
Block(6,18,5,LEAVES:1)
Block(6,19,5,LEAVES:1)
Block(8,23,0,LEAVES:1)
Block(8,22,0,LEAVES:1)
Block(2,22,4,LEAVES:1)
Block(4,32,-2,LEAVES:1)
Block(4,33,-2,LEAVES:1)
Block(4,30,-2,LEAVES:1)
Block(2,21,4,LEAVES:1)
Block(-7,20,-3,LOG:13)
Block(-7,21,-3,LEAVES:1)
Block(11,22,2,LEAVES:1)
Block(4,34,-2,LEAVES:1)
Block(-6,23,0,LEAVES:1)
Block(5,23,1,LEAVES:1)
Block(5,22,1,LEAVES:1)
Block(-6,24,0,LEAVES:1)
Block(1,19,-1,LOG:13)
Block(5,21,1,LEAVES:1)
Block(1,18,-1,LOG:13)
Block(1,17,-1,LOG:13)
Block(1,16,-1,LOG:13)
Block(1,15,-1,LOG:13)
Block(-4,25,5,LEAVES:1)
Block(1,14,-1,LOG:13)
Block(-4,24,5,LEAVES:1)
Block(9,23,2,LEAVES:1)
Block(9,22,2,LEAVES:1)
Block(5,29,1,LEAVES:1)
Block(2,29,-5,LEAVES:1)
Block(-2,34,-3,LEAVES:1)
Block(1,13,-1,LOG:13)
Block(1,12,-1,LOG:13)
Block(6,30,-1,LEAVES:1)
Block(1,11,-1,LOG:13)
Block(1,10,-1,LOG:13)
Block(-8,21,6,LEAVES:1)
Block(1,18,2,LOG:13)
Block(4,29,-2,LOG:13)
Block(-4,25,-10,LEAVES:1)
Block(-12,20,-5,LEAVES:1)
Block(6,22,-1,LEAVES:1)
Block(6,23,-1,LEAVES:1)
Block(6,21,5,LEAVES:1)
Block(6,22,5,LEAVES:1)
Block(-7,24,2,LEAVES:1)
Block(-7,22,2,LEAVES:1)
Block(-7,23,2,LEAVES:1)
Block(-2,33,-3,LEAVES:1)
Block(-7,21,2,LEAVES:1)
Block(-2,32,-3,LEAVES:1)
Block(-4,24,-10,LEAVES:1)
Block(-4,23,-10,LEAVES:1)
Block(6,29,-1,LEAVES:1)
Block(-2,30,-3,LEAVES:1)
Block(7,18,7,LEAVES:1)
Block(7,19,7,LEAVES:1)
Block(-10,20,-6,LEAVES:1)
Block(-2,29,-3,LEAVES:1)
Block(2,33,-5,LEAVES:1)
Block(-10,21,-6,LEAVES:1)
Block(2,32,-5,LEAVES:1)
Block(3,19,8,LEAVES:1)
Block(2,30,-5,LEAVES:1)
Block(3,18,8,LEAVES:1)
Block(0,23,-6,LEAVES:1)
Block(-6,21,0,LEAVES:1)
Block(0,23,-10,LEAVES:1)
Block(0,25,-10,LEAVES:1)
Block(0,24,-10,LEAVES:1)
Block(0,5,0,LOG:13)
Block(-4,21,3,LEAVES:1)
Block(0,7,0,LOG:13)
Block(-4,22,3,LEAVES:1)
Block(2,32,2,LEAVES:1)
Block(0,6,0,LOG:13)
Block(-4,23,3,LEAVES:1)
Block(2,31,2,LEAVES:1)
Block(2,29,-3,LEAVES:1)
Block(1,8,-2,LOG:13)
Block(1,9,-2,LOG:13)
Block(1,31,2,LEAVES:1)
Block(1,6,-2,LOG:13)
Block(-8,21,4,LEAVES:1)
Block(1,32,2,LEAVES:1)
Block(1,7,-2,LOG:13)
Block(-8,22,4,LEAVES:1)
Block(1,4,-2,DIRT)
Block(1,5,-2,LOG:13)
Block(9,22,-2,LEAVES:1)
Block(4,29,-4,LEAVES:1)
Block(-3,24,-9,LEAVES:1)
Block(-3,25,-9,LEAVES:1)
Block(-3,25,3,LEAVES:1)
Block(-3,24,3,LEAVES:1)
Block(-3,23,3,LEAVES:1)
Block(-8,20,-7,LEAVES:1)
Block(-3,29,3,LEAVES:1)
Block(6,22,3,LEAVES:1)
Block(6,21,3,LEAVES:1)
Block(-3,23,-9,LEAVES:1)
Block(-1,24,-10,LEAVES:1)
Block(-1,25,-10,LEAVES:1)
Block(-1,23,-10,LEAVES:1)
Block(9,19,2,LEAVES:1)
Block(2,33,-3,LEAVES:1)
Block(9,18,2,LEAVES:1)
Block(2,34,-3,LEAVES:1)
Block(2,32,-3,LEAVES:1)
Block(2,30,-3,LEAVES:1)
Block(6,23,3,LEAVES:1)
Block(3,18,6,LEAVES:1)
Block(3,19,6,LEAVES:1)
Block(3,21,6,LEAVES:1)
Block(3,22,6,LEAVES:1)
Block(8,19,2,LEAVES:1)
Block(8,18,2,LEAVES:1)
Block(2,18,2,LOG:13)
Block(10,22,0,LEAVES:1)
Block(-7,24,0,LEAVES:1)
Block(10,23,0,LEAVES:1)
Block(-9,21,-2,LEAVES:1)
Block(0,34,-4,LEAVES:1)
Block(0,32,-4,LEAVES:1)
Block(-9,20,-2,LEAVES:1)
Block(0,33,-4,LEAVES:1)
Block(-2,-4,1,LOG:13)
Block(-2,-3,1,LOG:13)
Block(-2,-2,1,LOG:13)
Block(-2,-1,1,LOG:13)
Block(2,8,-2,LOG:13)
Block(0,9,0,LOG:13)
Block(-4,24,3,LEAVES:1)
Block(2,7,-2,LOG:13)
Block(0,8,0,LOG:13)
Block(-4,25,3,LEAVES:1)
Block(2,6,-2,LOG:13)
Block(2,5,-2,LOG:13)
Block(8,22,2,LEAVES:1)
Block(-1,19,6,LEAVES:1)
Block(8,23,2,LEAVES:1)
Block(-1,18,6,LEAVES:1)
Block(2,9,-2,LOG:13)
Block(-3,25,-11,LEAVES:1)
Block(0,6,-4,LOG:13)
Block(-2,29,1,LEAVES:1)
Block(0,5,-4,LOG:13)
Block(-2,25,1,LEAVES:1)
Block(9,22,0,LEAVES:1)
Block(-2,24,1,LEAVES:1)
Block(-1,28,-1,LOG:13)
Block(-1,29,-1,LEAVES:1)
Block(-2,23,1,LOG:13)
Block(-3,24,-11,LEAVES:1)
Block(-3,23,-11,LEAVES:1)
Block(-1,30,-1,LEAVES:1)
Block(1,24,-8,LEAVES:1)
Block(-2,30,1,LEAVES:1)
Block(-1,31,-1,LEAVES:1)
Block(-1,32,-1,LEAVES:1)
Block(10,23,2,LEAVES:1)
Block(9,23,0,LEAVES:1)
Block(10,22,2,LEAVES:1)
Block(3,22,4,LEAVES:1)
Block(5,30,-4,LEAVES:1)
Block(6,30,-3,LEAVES:1)
Block(1,18,4,LOG:13)
Block(3,21,4,LEAVES:1)
Block(-2,5,-3,LOG:13)
Block(1,23,-8,LEAVES:1)
Block(6,29,-3,LEAVES:1)
Block(6,21,7,LEAVES:1)
Block(-4,30,1,LEAVES:1)
Block(-2,32,1,LEAVES:1)
Block(-1,33,-1,LEAVES:1)
Block(-2,31,1,LEAVES:1)
Block(-1,34,-1,LEAVES:1)
Block(8,22,-2,LEAVES:1)
Block(-4,29,1,LEAVES:1)
Block(0,34,0,LEAVES:1)
Block(0,33,0,LEAVES:1)
Block(-4,24,1,LEAVES:1)
Block(-4,23,1,LOG:13)
Block(8,23,-2,LEAVES:1)
Block(0,32,0,LEAVES:1)
Block(0,31,0,LOG:13)
Block(0,30,0,LEAVES:1)
Block(-5,24,-2,LEAVES:1)
Block(2,31,0,LEAVES:1)
Block(-5,23,-2,LEAVES:1)
Block(2,32,0,LEAVES:1)
Block(2,33,0,LEAVES:1)
Block(2,34,0,LEAVES:1)
Block(-5,20,-2,LOG:13)
Block(7,29,-3,LEAVES:1)
Block(2,30,0,LEAVES:1)
Block(-6,24,-1,LEAVES:1)
Block(-6,23,-1,LEAVES:1)
Block(0,23,0,LOG:13)
Block(-1,10,-1,LOG:13)
Block(0,29,0,LEAVES:1)
Block(-3,24,5,LEAVES:1)
Block(4,30,-4,LEAVES:1)
Block(-3,25,5,LEAVES:1)
Block(5,29,-4,LEAVES:1)
Block(4,32,-4,LEAVES:1)
Block(-1,11,-1,LOG:13)
Block(-1,12,-1,LOG:13)
Block(-1,13,-1,LOG:13)
Block(0,13,0,LOG:13)
Block(0,12,0,LOG:13)
Block(0,11,0,LOG:13)
Block(7,30,-3,LEAVES:1)
Block(1,24,4,LEAVES:1)
Block(0,17,0,LOG:13)
Block(-7,23,-1,LEAVES:1)
Block(1,25,4,LEAVES:1)
Block(2,5,-4,LOG:13)
Block(-7,24,-1,LEAVES:1)
Block(0,10,0,LOG:13)
Block(0,4,-2,DIRT)
Block(8,18,4,LEAVES:1)
Block(-4,30,-2,LEAVES:1)
Block(2,10,0,LOG:13)
Block(0,6,-2,LOG:13)
Block(0,5,-2,LOG:13)
Block(0,8,-2,LOG:13)
Block(5,22,3,LEAVES:1)
Block(0,7,-2,LOG:13)
Block(0,9,-2,LOG:13)
Block(8,19,4,LEAVES:1)
Block(-1,10,-3,LOG:13)
Block(-2,34,-1,LEAVES:1)
Block(0,29,2,LEAVES:1)
Block(-2,32,-1,LEAVES:1)
Block(-2,33,-1,LEAVES:1)
Block(0,24,2,LEAVES:1)
Block(0,25,2,LEAVES:1)
Block(-4,29,-2,LEAVES:1)
Block(3,29,-5,LEAVES:1)
Block(5,21,3,LOG:13)
Block(-4,23,-2,LEAVES:1)
Block(-2,6,-1,LOG:13)
Block(-2,5,-1,LOG:13)
Block(3,19,10,LEAVES:1)
Block(5,29,-6,LEAVES:1)
Block(5,18,3,LOG:13)
Block(-9,22,1,LEAVES:1)
Block(4,30,-6,LEAVES:1)
Block(-9,21,1,LEAVES:1)
Block(3,18,10,LEAVES:1)
Block(2,29,0,LEAVES:1)
Block(5,19,3,LEAVES:1)
Block(-2,30,-1,LEAVES:1)
Block(-7,22,4,LEAVES:1)
Block(3,30,-5,LEAVES:1)
Block(-2,31,-1,LEAVES:1)
Block(-7,21,4,LEAVES:1)
Block(3,33,-5,LEAVES:1)
Block(3,32,-5,LEAVES:1)
Block(1,33,-6,LEAVES:1)
Block(0,23,-8,LEAVES:1)
Block(0,24,-8,LEAVES:1)
Block(-1,19,8,LEAVES:1)
Block(8,21,4,LEAVES:1)
Block(-2,29,-1,LEAVES:1)
Block(0,25,-8,LEAVES:1)
Block(0,18,11,LEAVES:1)
Block(8,23,4,LEAVES:1)
Block(1,32,-6,LEAVES:1)
Block(-1,18,8,LOG:13)
Block(8,22,4,LEAVES:1)
Block(7,22,0,LEAVES:1)
Block(7,23,0,LEAVES:1)
Block(4,18,8,LEAVES:1)
Block(6,30,-5,LEAVES:1)
Block(4,19,8,LEAVES:1)
Block(6,19,7,LEAVES:1)
Block(6,18,7,LEAVES:1)
Block(1,18,6,LEAVES:1)
Block(1,19,6,LEAVES:1)
Block(4,29,-6,LEAVES:1)
Block(6,29,-5,LEAVES:1)
Block(3,19,4,LEAVES:1)
Block(3,18,4,LEAVES:1)
Block(-5,24,5,LEAVES:1)
Block(-5,21,5,LEAVES:1)
Block(-5,22,5,LEAVES:1)
Block(3,5,-3,LOG:13)
Block(-9,21,-7,LEAVES:1)
Block(-2,23,-11,LEAVES:1)
Block(0,27,-1,LOG:13)
Block(-9,20,-7,LEAVES:1)
Block(0,26,-1,LOG:13)
Block(0,29,-1,LOG:13)
Block(0,28,-1,LOG:13)
Block(7,23,2,LEAVES:1)
Block(-2,25,-11,LEAVES:1)
Block(-2,24,-11,LEAVES:1)
Block(1,33,-5,LEAVES:1)
Block(-5,21,2,LEAVES:1)
Block(1,32,-5,LEAVES:1)
Block(-5,22,2,LEAVES:1)
Block(7,22,2,LEAVES:1)
Block(7,21,2,LEAVES:1)
Block(-5,23,2,LEAVES:1)
Block(1,34,-5,LEAVES:1)
Block(-8,23,0,LEAVES:1)
Block(-8,21,0,LEAVES:1)
Block(-11,21,-6,LEAVES:1)
Block(-9,21,3,LEAVES:1)
Block(-6,22,5,LEAVES:1)
Block(3,31,1,LEAVES:1)
Block(-11,20,-6,LEAVES:1)
Block(-9,22,3,LEAVES:1)
Block(0,21,-1,LOG:13)
Block(5,22,7,LEAVES:1)
Block(0,20,-1,LOG:13)
Block(-6,21,5,LEAVES:1)
Block(0,23,-1,LOG:13)
Block(5,21,7,LEAVES:1)
Block(0,22,-1,LOG:13)
Block(8,21,5,LEAVES:1)
Block(0,25,-1,LOG:13)
Block(0,24,-1,LOG:13)
Block(-1,5,0,LOG:13)
Block(3,8,0,LOG:13)
Block(3,7,0,LOG:13)
Block(3,6,0,LOG:13)
Block(-1,7,0,LOG:13)
Block(5,19,7,LEAVES:1)
Block(3,5,0,LOG:13)
Block(-1,6,0,LOG:13)
Block(1,24,-11,LEAVES:1)
Block(-1,9,0,LOG:13)
Block(1,23,-11,LEAVES:1)
Block(-1,8,0,LOG:13)
Block(5,18,7,LEAVES:1)
Block(-6,20,-5,LEAVES:1)
Block(0,30,-1,LOG:13)
Block(0,32,-1,LOG:13)
Block(0,31,-1,LOG:13)
Block(0,34,-1,LEAVES:1)
Block(0,33,-1,LOG:13)
Block(-4,24,-7,LEAVES:1)
Block(0,35,-1,LEAVES:1)
Block(-4,25,-7,LEAVES:1)
Block(-1,18,10,LEAVES:1)
Block(-1,29,-3,LEAVES:1)
Block(5,29,-1,LEAVES:1)
Block(-1,19,10,LEAVES:1)
Block(-2,29,3,LEAVES:1)
Block(-2,25,-9,LEAVES:1)
Block(-2,23,-9,LEAVES:1)
Block(-2,24,3,LOG:13)
Block(-2,24,-9,LOG:13)
Block(-2,25,3,LEAVES:1)
Block(-1,32,-3,LEAVES:1)
Block(-1,31,-3,LEAVES:1)
Block(-1,34,-3,LEAVES:1)
Block(-2,30,3,LEAVES:1)
Block(-1,33,-3,LEAVES:1)
Block(4,18,4,LEAVES:1)
Block(3,0,0,LOG:13)
Block(4,19,4,LEAVES:1)
Block(-8,20,-3,LOG:13)
Block(3,4,0,LOG:13)
Block(3,3,0,LOG:13)
Block(-8,21,-3,LEAVES:1)
Block(3,2,0,LOG:13)
Block(3,1,0,LOG:13)
Block(-1,6,-2,LOG:13)
Block(0,16,-1,LOG:13)
Block(-1,5,-2,LOG:13)
Block(0,15,-1,LOG:13)
Block(0,18,-1,LOG:13)
Block(0,17,-1,LOG:13)
Block(-3,18,8,LEAVES:1)
Block(0,19,-1,LOG:13)
Block(-3,19,8,LEAVES:1)
Block(7,19,2,LEAVES:1)
Block(7,18,2,LEAVES:1)
Block(2,18,9,LEAVES:1)
Block(-1,9,-2,LOG:13)
Block(2,19,9,LEAVES:1)
Block(-1,8,-2,LOG:13)
Block(-1,7,-2,LOG:13)
Block(4,21,4,LEAVES:1)
Block(4,22,4,LEAVES:1)
Block(10,18,4,LEAVES:1)
Block(10,19,4,LEAVES:1)
Block(1,18,7,LEAVES:1)
Block(1,19,10,LEAVES:1)
Block(1,18,10,LEAVES:1)
Block(0,31,2,LEAVES:1)
Block(0,32,2,LEAVES:1)
Block(0,10,-1,LOG:13)
Block(1,19,7,LEAVES:1)
Block(0,12,-1,LOG:13)
Block(0,11,-1,LOG:13)
Block(0,14,-1,LOG:13)
Block(5,30,-1,LEAVES:1)
Block(0,13,-1,LOG:13)
Block(0,30,2,LEAVES:1)
Block(5,29,-3,LEAVES:1)
Block(7,29,-1,LEAVES:1)
Block(7,23,-1,LEAVES:1)
Block(-6,20,-3,LEAVES:1)
Block(7,22,-1,LEAVES:1)
Block(-2,25,5,LEAVES:1)
Block(-2,24,5,LEAVES:1)
Block(-1,33,-5,LEAVES:1)
Block(4,18,6,LOG:13)
Block(-1,32,-5,LEAVES:1)
Block(4,19,6,LEAVES:1)
Block(-8,20,-1,LEAVES:1)
Block(-3,29,-3,LEAVES:1)
Block(-3,24,-10,LEAVES:1)
Block(-3,25,-10,LEAVES:1)
Block(8,18,7,LEAVES:1)
Block(7,18,4,LOG:13)
Block(7,19,4,LEAVES:1)
Block(4,21,6,LEAVES:1)
Block(-2,5,0,LOG:13)
Block(4,22,6,LEAVES:1)
Block(-3,23,-10,LEAVES:1)
Block(-3,33,-3,LEAVES:1)
Block(-4,18,8,LEAVES:1)
Block(-1,10,0,LOG:13)
Block(-4,19,8,LEAVES:1)
Block(2,23,-10,LEAVES:1)
Block(5,30,-3,LEAVES:1)
Block(3,29,-3,LOG:13)
Block(-1,29,0,LEAVES:1)
Block(-5,25,-9,LEAVES:1)
Block(-5,24,-9,LEAVES:1)
Block(5,21,5,LEAVES:1)
Block(0,24,4,LEAVES:1)
Block(5,22,5,LEAVES:1)
Block(0,25,4,LEAVES:1)
Block(-1,23,0,LOG:13)
Block(-11,20,-4,LEAVES:1)
Block(-11,21,-4,LEAVES:1)
Block(-1,4,-4,LOG:13)
Block(5,18,5,LEAVES:1)
Block(-7,22,6,LEAVES:1)
Block(-1,3,-4,LOG:13)
Block(-1,2,-4,LOG:13)
Block(-1,1,-4,LOG:13)
Block(5,19,5,LEAVES:1)
Block(-1,0,-4,LOG:13)
Block(3,33,-3,LEAVES:1)
Block(3,32,-3,LEAVES:1)
Block(-2,18,5,LEAVES:1)
Block(3,34,-3,LEAVES:1)
Block(-1,8,-4,LOG:13)
Block(-5,24,2,LEAVES:1)
Block(-1,7,-4,LOG:13)
Block(-1,6,-4,LOG:13)
Block(-1,5,-4,LOG:13)
Block(-7,21,6,LEAVES:1)
Block(3,30,-3,LEAVES:1)
Block(3,29,1,LEAVES:1)
Block(-1,23,-5,LOG:13)
Block(-1,30,0,LEAVES:1)
Block(-1,31,0,LEAVES:1)
Block(-1,32,0,LEAVES:1)
Block(-4,25,-9,LEAVES:1)
Block(-1,33,0,LEAVES:1)
Block(-1,34,0,LEAVES:1)
Block(-4,23,-9,LEAVES:1)
Block(-4,24,-9,LEAVES:1)
Block(1,9,0,LOG:13)
Block(1,8,0,LOG:13)
Block(1,7,0,LOG:13)
Block(3,21,-1,LOG:13)
Block(1,10,-3,LOG:13)
Block(3,29,-1,LEAVES:1)
Block(1,11,-3,LOG:13)
Block(1,12,-3,LOG:13)
Block(1,13,-3,LOG:13)
Block(-8,20,-5,LEAVES:1)
Block(0,25,6,LEAVES:1)
Block(0,24,6,LEAVES:1)
Block(-8,21,-5,LEAVES:1)
Block(-3,18,10,LEAVES:1)
Block(-3,19,10,LEAVES:1)
Block(3,30,-1,LEAVES:1)
Block(3,31,-1,LEAVES:1)
Block(3,32,-1,LEAVES:1)
Block(3,33,-1,LEAVES:1)
Block(2,18,7,LEAVES:1)
Block(-2,24,7,LEAVES:1)
Block(2,19,7,LEAVES:1)
Block(-2,25,7,LEAVES:1)
Block(-10,20,-4,LEAVES:1)
Block(1,18,9,LEAVES:1)
Block(1,19,9,LEAVES:1)
Block(-1,25,-7,LEAVES:1)
Block(-2,18,7,LEAVES:1)
Block(-1,24,-7,LEAVES:1)
Block(0,18,6,LOG:13)
Block(-2,19,7,LEAVES:1)
Block(-1,23,-7,LOG:13)
Block(3,34,-1,LEAVES:1)
Block(0,19,6,LEAVES:1)
Block(-10,21,-4,LEAVES:1)
Block(-9,20,-5,LEAVES:1)
Block(-9,21,-5,LEAVES:1)
Block(4,22,2,LEAVES:1)
Block(4,21,2,LOG:13)
Block(3,-3,1,LOG:13)
Block(1,30,-3,LEAVES:1)
Block(1,31,-3,LOG:13)
Block(3,-1,1,LOG:13)
Block(7,21,4,LEAVES:1)
Block(1,32,-3,LOG:13)
Block(3,-2,1,LOG:13)
Block(7,22,4,LEAVES:1)
Block(1,33,-3,LEAVES:1)
Block(1,-1,-5,LOG:13)
Block(1,34,-3,LEAVES:1)
Block(1,-3,-5,LOG:13)
Block(-9,22,5,LEAVES:1)
Block(1,-2,-5,LOG:13)
Block(-9,21,5,LEAVES:1)
Block(4,4,-2,LOG:13)
Block(9,18,5,LEAVES:1)
Block(-1,24,4,LEAVES:1)
Block(4,3,-2,LOG:13)
Block(-6,21,3,LEAVES:1)
Block(-1,25,4,LEAVES:1)
Block(9,19,5,LEAVES:1)
Block(0,21,-3,LOG:13)
Block(4,0,-2,LOG:13)
Block(-6,24,3,LEAVES:1)
Block(4,2,-2,LOG:13)
Block(6,19,3,LEAVES:1)
Block(-6,22,3,LEAVES:1)
Block(4,1,-2,LOG:13)
Block(6,18,3,LOG:13)
Block(-6,23,3,LEAVES:1)
Block(-2,19,10,LEAVES:1)
Block(5,19,9,LEAVES:1)
Block(5,18,9,LEAVES:1)
Block(-2,18,10,LEAVES:1)
Block(1,29,-3,LEAVES:1)
Block(1,6,0,LOG:13)
Block(0,33,-3,LEAVES:1)
Block(1,5,0,LOG:13)
Block(11,22,0,LEAVES:1)
Block(0,34,-3,LEAVES:1)
Block(-9,21,-3,LEAVES:1)
Block(0,31,-3,LEAVES:1)
Block(-9,20,-3,LEAVES:1)
Block(0,32,-3,LEAVES:1)
Block(-1,30,2,LEAVES:1)
Block(2,21,5,LEAVES:1)
Block(4,30,-1,LEAVES:1)
Block(-2,24,-7,LEAVES:1)
Block(-2,23,-7,LEAVES:1)
Block(-2,25,-7,LEAVES:1)
Block(6,18,1,LEAVES:1)
Block(10,22,-1,LEAVES:1)
Block(-1,29,2,LEAVES:1)
Block(2,7,0,LOG:13)
Block(7,22,6,LEAVES:1)
Block(2,6,0,LOG:13)
Block(7,21,6,LEAVES:1)
Block(2,9,0,LOG:13)
Block(2,8,0,LOG:13)
Block(10,23,-1,LEAVES:1)
Block(1,35,-1,LEAVES:1)
Block(1,34,-1,LEAVES:1)
Block(1,33,-1,LOG:13)
Block(4,33,-1,LEAVES:1)
Block(1,32,-1,LOG:13)
Block(-1,25,2,LEAVES:1)
Block(1,31,-1,LOG:13)
Block(-1,24,2,LOG:13)
Block(1,30,-1,LOG:13)
Block(-11,21,-2,LEAVES:1)
Block(-11,20,-2,LEAVES:1)
Block(1,29,-1,LOG:13)
Block(1,28,-1,LOG:13)
Block(1,27,-1,LOG:13)
Block(1,13,0,LOG:13)
Block(1,26,-1,LOG:13)
Block(1,12,0,LOG:13)
Block(1,25,-1,LOG:13)
Block(1,11,0,LOG:13)
Block(1,10,0,LOG:13)
Block(-5,24,0,LEAVES:1)
Block(-5,23,0,LEAVES:1)
Block(-5,29,0,LEAVES:1)
Block(2,13,-1,LOG:13)
Block(2,10,-1,LOG:13)
Block(2,12,-1,LOG:13)
Block(2,11,-1,LOG:13)
Block(-5,30,0,LEAVES:1)
Block(0,11,-3,LOG:13)
Block(1,24,-1,LOG:13)
Block(-1,32,2,LEAVES:1)
Block(0,12,-3,LOG:13)
Block(1,23,-1,LOG:13)
Block(-1,31,2,LEAVES:1)
Block(1,22,-1,LOG:13)
Block(0,10,-3,LOG:13)
Block(1,21,-1,LOG:13)
Block(1,20,-1,LOG:13)
Block(4,29,-1,LEAVES:1)
Block(0,13,-3,LOG:13)
Block(1,29,0,LEAVES:1)
Block(0,23,-12,LEAVES:1)
Block(2,29,-1,LEAVES:1)
Block(2,21,-1,LOG:13)
Block(-8,22,2,LEAVES:1)
Block(-8,21,2,LEAVES:1)
Block(-5,21,0,LOG:13)
Block(-8,23,2,LEAVES:1)
Block(-1,23,-12,LEAVES:1)
Block(-3,23,1,LOG:13)
Block(-3,24,1,LEAVES:1)
Block(-4,24,6,LEAVES:1)
Block(-3,25,-7,LEAVES:1)
Block(-3,24,-7,LEAVES:1)
Block(-3,23,-7,LEAVES:1)
Block(-4,25,6,LEAVES:1)
Block(1,34,0,LEAVES:1)
Block(1,33,0,LEAVES:1)
Block(1,32,0,LEAVES:1)
Block(2,5,0,LOG:13)
Block(-10,21,3,LEAVES:1)
Block(-3,29,1,LEAVES:1)
Block(1,31,0,LEAVES:1)
Block(-10,22,3,LEAVES:1)
Block(1,30,0,LEAVES:1)
Block(7,19,6,LEAVES:1)
Block(7,18,6,LEAVES:1)
Block(2,19,5,LEAVES:1)
Block(2,18,5,LOG:13)
Block(-1,24,-12,LEAVES:1)
Block(2,32,-1,LEAVES:1)
Block(2,31,-1,LEAVES:1)
Block(-7,21,-5,LEAVES:1)
Block(2,34,-1,LEAVES:1)
Block(-7,20,-5,LEAVES:1)
Block(2,33,-1,LEAVES:1)
Block(-10,21,-2,LEAVES:1)
Block(2,30,-1,LEAVES:1)
Block(-10,20,-2,LEAVES:1)
Block(6,21,1,LEAVES:1)
Block(6,22,1,LEAVES:1)
Block(6,23,1,LEAVES:1)
Block(-3,30,1,LEAVES:1)
Block(-3,31,1,LEAVES:1)
Block(5,18,2,LEAVES:1)
Block(-4,24,-11,LEAVES:1)
Block(5,19,2,LEAVES:1)
Block(-4,25,-11,LEAVES:1)
Block(2,34,-4,LEAVES:1)
Block(2,33,-4,LEAVES:1)
Block(-10,20,-7,LEAVES:1)
Block(2,32,-4,LEAVES:1)
Block(2,30,-4,LEAVES:1)
Block(-4,25,4,LEAVES:1)
Block(3,18,7,LOG:13)
Block(3,19,7,LEAVES:1)
Block(9,18,3,LEAVES:1)
Block(9,19,3,LEAVES:1)
Block(1,29,1,LEAVES:1)
Block(-4,21,4,LEAVES:1)
Block(9,22,3,LEAVES:1)
Block(9,23,3,LEAVES:1)
Block(-4,23,4,LEAVES:1)
Block(-4,24,4,LEAVES:1)
Block(-2,-3,-4,LOG:13)
Block(-2,-4,-4,LOG:13)
Block(-2,-5,-4,LOG:13)
Block(-2,34,-2,LEAVES:1)
Block(-2,-6,-4,LOG:13)
Block(-2,33,-2,LEAVES:1)
Block(-2,-1,-4,LOG:13)
Block(-2,-2,-4,LOG:13)
Block(-9,20,-1,LEAVES:1)
Block(-9,21,-1,LEAVES:1)
Block(-2,-7,-4,LOG:13)
Block(-2,-8,-4,LOG:13)
Block(-3,23,-8,LEAVES:1)
Block(-3,25,2,LEAVES:1)
Block(-3,24,-8,LEAVES:1)
Block(-3,24,2,LEAVES:1)
Block(-3,23,2,LEAVES:1)
Block(-3,25,-8,LEAVES:1)
Block(2,21,3,LEAVES:1)
Block(-1,24,7,LEAVES:1)
Block(-3,29,2,LEAVES:1)
Block(1,9,-3,LOG:13)
Block(-7,21,-4,LEAVES:1)
Block(1,7,-3,LOG:13)
Block(-7,20,-4,LEAVES:1)
Block(1,8,-3,LOG:13)
Block(1,5,-3,LOG:13)
Block(1,6,-3,LOG:13)
Block(-1,19,7,LEAVES:1)
Block(-3,30,2,LEAVES:1)
Block(-1,18,7,LOG:13)
Block(8,18,1,LEAVES:1)
Block(-1,23,-9,LOG:13)
Block(-1,24,-9,LEAVES:1)
Block(-1,25,-9,LEAVES:1)
Block(-2,18,9,LEAVES:1)
Block(-2,19,9,LEAVES:1)
Block(1,31,1,LEAVES:1)
Block(1,32,1,LEAVES:1)
Block(0,19,8,LEAVES:1)
Block(1,33,1,LEAVES:1)
Block(1,34,1,LEAVES:1)
Block(0,18,8,LEAVES:1)
Block(8,23,1,LEAVES:1)
Block(5,30,0,LEAVES:1)
Block(-12,20,-4,LEAVES:1)
Block(4,29,0,LEAVES:1)
Block(-12,21,-4,LEAVES:1)
Block(-7,22,1,LEAVES:1)
Block(-7,21,1,LEAVES:1)
Block(-2,32,-4,LEAVES:1)
Block(4,22,0,LOG:13)
Block(-7,24,1,LEAVES:1)
Block(-2,33,-4,LEAVES:1)
Block(-7,23,1,LEAVES:1)
Block(-2,34,-4,LEAVES:1)
Block(6,29,-2,LEAVES:1)
Block(-7,20,-2,LEAVES:1)
Block(-7,21,-2,LEAVES:1)
Block(-1,18,5,LEAVES:1)
Block(-6,21,1,LOG:13)
Block(-1,19,5,LEAVES:1)
Block(8,22,1,LOG:13)
Block(-6,23,1,LEAVES:1)
Block(-6,22,1,LEAVES:1)
Block(5,22,0,LOG:13)
Block(-2,28,0,LOG:13)
Block(-2,29,0,LOG:13)
Block(-2,23,0,LEAVES:1)
Block(5,29,0,LEAVES:1)
Block(1,25,-9,LEAVES:1)
Block(2,5,-1,LOG:13)
Block(0,32,-5,LEAVES:1)
Block(2,9,-1,LOG:13)
Block(-1,25,5,LEAVES:1)
Block(2,8,-1,LOG:13)
Block(2,7,-1,LOG:13)
Block(0,34,-5,LEAVES:1)
Block(2,6,-1,LOG:13)
Block(-1,24,5,LEAVES:1)
Block(0,33,-5,LEAVES:1)
Block(1,24,-9,LEAVES:1)
Block(1,23,-9,LEAVES:1)
Block(4,30,-3,LEAVES:1)
Block(6,22,4,LEAVES:1)
Block(4,33,-3,LEAVES:1)
Block(4,32,-3,LEAVES:1)
Block(6,21,4,LEAVES:1)
Block(1,9,-1,LOG:13)
Block(1,7,-1,LOG:13)
Block(1,8,-1,LOG:13)
Block(1,5,-1,LOG:13)
Block(-10,20,-5,LEAVES:1)
Block(8,23,-1,LEAVES:1)
Block(1,6,-1,LOG:13)
Block(-10,21,-5,LEAVES:1)
Block(8,22,-1,LEAVES:1)
Block(1,24,3,LEAVES:1)
Block(1,4,-1,DIRT)
Block(-6,24,1,LEAVES:1)
Block(9,23,1,LEAVES:1)
Block(9,22,1,LEAVES:1)
Block(2,29,-4,LEAVES:1)
Block(4,30,0,LEAVES:1)
Block(-8,22,5,LEAVES:1)
Block(6,30,-2,LEAVES:1)
Block(1,18,3,LOG:13)
Block(-8,21,5,LEAVES:1)
Block(6,19,4,LEAVES:1)
Block(9,22,-1,LEAVES:1)
Block(4,29,-3,LOG:13)
Block(6,18,4,LEAVES:1)
Block(9,23,-1,LEAVES:1)
Block(-3,25,4,LEAVES:1)
Block(-3,24,4,LEAVES:1)
Block(4,30,-5,LEAVES:1)
Block(4,21,7,LEAVES:1)
Block(-7,22,5,LEAVES:1)
Block(-7,21,5,LEAVES:1)
Block(0,23,-9,LEAVES:1)
Block(0,25,-9,LEAVES:1)
Block(7,30,-2,LEAVES:1)
Block(0,24,-9,LEAVES:1)
Block(0,18,1,LOG:13)
Block(-1,18,9,LEAVES:1)
Block(-1,19,9,LEAVES:1)
Block(2,33,1,LEAVES:1)
Block(2,32,1,LEAVES:1)
Block(8,19,3,LEAVES:1)
Block(2,31,1,LEAVES:1)
Block(8,18,3,LEAVES:1)
Block(-6,23,-2,LEAVES:1)
Block(-6,20,-2,LOG:13)
Block(-1,10,-2,LOG:13)
Block(-1,11,-2,LOG:13)
Block(1,31,3,LEAVES:1)
Block(2,7,-3,LOG:13)
Block(2,6,-3,LOG:13)
Block(2,5,-3,LOG:13)
Block(5,22,4,LEAVES:1)
Block(5,21,4,LOG:13)
Block(2,8,-3,LOG:13)
Block(4,29,-5,LEAVES:1)
Block(5,19,4,LEAVES:1)
Block(5,18,4,LEAVES:1)
Block(2,23,-8,LEAVES:1)
Block(-2,34,0,LEAVES:1)
Block(-4,30,2,LEAVES:1)
Block(-2,31,0,LEAVES:1)
Block(-2,30,0,LEAVES:1)
Block(6,29,-4,LEAVES:1)
Block(-2,33,0,LEAVES:1)
Block(-2,32,0,LEAVES:1)
Block(0,19,10,LEAVES:1)
Block(-5,23,4,LEAVES:1)
Block(0,18,10,LEAVES:1)
Block(-5,22,4,LEAVES:1)
Block(-4,29,2,LEAVES:1)
Block(-5,25,4,LEAVES:1)
Block(3,19,5,LEAVES:1)
Block(-5,24,4,LEAVES:1)
Block(-2,6,-4,LOG:13)
Block(-4,25,2,LEAVES:1)
Block(-5,21,4,LEAVES:1)
Block(-4,24,2,LEAVES:1)
Block(-4,23,2,LEAVES:1)
Block(-2,2,-4,LOG:13)
Block(-2,3,-4,LOG:13)
Block(-2,4,-4,LOG:13)
Block(-2,5,-4,LOG:13)
Block(3,18,5,LOG:13)
Block(8,23,3,LEAVES:1)
Block(-2,0,-4,LOG:13)
Block(8,22,3,LEAVES:1)
Block(-2,1,-4,LOG:13)
Block(8,21,3,LEAVES:1)
Block(3,21,5,LEAVES:1)
Block(-4,21,2,LEAVES:1)
Block(-3,24,-12,LEAVES:1)
Block(4,19,7,LEAVES:1)
Block(10,22,1,LEAVES:1)
Block(4,18,7,LEAVES:1)
Block(10,23,1,LEAVES:1)
Block(6,19,8,LEAVES:1)
Block(6,18,8,LEAVES:1)
Block(3,22,5,LEAVES:1)
Block(6,21,6,LEAVES:1)
Block(-1,-8,-4,LOG:13)
Block(7,19,1,LEAVES:1)
Block(6,22,6,LEAVES:1)
Block(-1,-5,-4,LOG:13)
Block(-4,30,0,LEAVES:1)
Block(-1,-4,-4,LOG:13)
Block(-1,-7,-4,LOG:13)
Block(7,18,1,LEAVES:1)
Block(-1,-6,-4,LOG:13)
Block(-1,-1,-4,LOG:13)
Block(-1,34,-2,LEAVES:1)
Block(-1,-3,-4,LOG:13)
Block(3,5,-1,LOG:13)
Block(-2,32,2,LEAVES:1)
Block(-1,-2,-4,LOG:13)
Block(3,6,-1,LOG:13)
Block(3,18,3,LOG:13)
Block(-4,23,0,LEAVES:1)
Block(-4,24,0,LEAVES:1)
Block(-4,21,0,LOG:13)
Block(1,24,5,LEAVES:1)
Block(-4,29,0,LEAVES:1)
Block(-3,19,6,LEAVES:1)
Block(-5,23,-1,LEAVES:1)
Block(-5,24,-1,LEAVES:1)
Block(-3,18,6,LEAVES:1)
Block(7,29,-4,LEAVES:1)
Block(7,23,1,LEAVES:1)
Block(7,22,1,LOG:13)
Block(-5,24,-10,LEAVES:1)
Block(-5,29,-1,LEAVES:1)
Block(4,18,9,LEAVES:1)
Block(4,19,9,LEAVES:1)
Block(6,30,-4,LEAVES:1)
Block(1,19,5,LEAVES:1)
Block(6,18,6,LEAVES:1)
Block(-9,21,2,LEAVES:1)
Block(3,22,3,LEAVES:1)
Block(3,21,3,LEAVES:1)
Block(-9,22,2,LEAVES:1)
Block(10,23,3,LEAVES:1)
Block(-3,24,6,LEAVES:1)
Block(1,18,5,LEAVES:1)
Block(10,22,3,LEAVES:1)
Block(-3,25,6,LEAVES:1)
Block(6,19,6,LEAVES:1)
Block(0,5,-3,LOG:13)
Block(0,7,-3,LOG:13)
Block(0,6,-3,LOG:13)
Block(0,9,-3,LOG:13)
Block(5,29,-5,LEAVES:1)
Block(0,8,-3,LOG:13)
Block(-3,30,-1,LEAVES:1)
Block(-7,23,3,LEAVES:1)
Block(-1,19,-2,LOG:13)
Block(-7,24,3,LEAVES:1)
Block(-1,12,-2,LOG:13)
Block(-7,21,3,LOG:13)
Block(-2,32,-2,LEAVES:1)
Block(-1,13,-2,LOG:13)
Block(-7,22,3,LEAVES:1)
Block(-2,31,-2,LEAVES:1)
Block(-2,30,-2,LEAVES:1)
Block(10,18,3,LEAVES:1)
Block(-3,29,-1,LEAVES:1)
Block(0,23,-7,LEAVES:1)
Block(0,34,1,LEAVES:1)
Block(-2,29,-2,LEAVES:1)
Block(-3,20,-1,LOG:13)
Block(-3,23,-1,LEAVES:1)
Block(0,24,-7,LEAVES:1)
Block(-3,24,-1,LEAVES:1)
Block(0,33,1,LEAVES:1)
Block(-2,6,-2,LOG:13)
Block(0,25,-7,LEAVES:1)
Block(0,32,1,LEAVES:1)
Block(-2,5,-2,LOG:13)
Block(0,31,1,LEAVES:1)
Block(-4,30,-1,LEAVES:1)
Block(0,30,1,LEAVES:1)
Block(5,21,2,LEAVES:1)
Block(5,22,2,LEAVES:1)
Block(8,18,5,LEAVES:1)
Block(-2,29,2,LEAVES:1)
Block(8,19,5,LEAVES:1)
Block(-1,27,-2,LOG:13)
Block(2,32,-6,LEAVES:1)
Block(-2,25,2,LEAVES:1)
Block(-1,29,-2,LEAVES:1)
Block(-2,23,2,LEAVES:1)
Block(-2,20,-2,LOG:13)
Block(-2,24,2,LEAVES:1)
Block(-1,30,-2,LEAVES:1)
Block(-2,30,2,LEAVES:1)
Block(-1,31,-2,LEAVES:1)
Block(-2,31,2,LEAVES:1)
Block(1,23,-7,LEAVES:1)
Block(-1,32,-2,LEAVES:1)
Block(1,24,-7,LEAVES:1)
Block(-1,33,-2,LEAVES:1)
Block(-4,29,-1,LEAVES:1)
Block(0,29,1,LEAVES:1)
Block(3,29,-6,LEAVES:1)
Block(5,30,-5,LEAVES:1)
Block(-3,31,-1,LEAVES:1)
Block(-4,24,-1,LEAVES:1)
Block(-3,33,-1,LEAVES:1)
Block(-4,23,-1,LEAVES:1)
Block(4,18,10,LEAVES:1)
Block(-4,20,-1,LOG:13)
Block(-3,19,7,LEAVES:1)
Block(-3,18,7,LEAVES:1)
Block(-1,22,-4,LOG:13)
Block(10,18,5,LEAVES:1)
Block(-3,24,7,LEAVES:1)
Block(0,32,3,LEAVES:1)
Block(0,31,3,LEAVES:1)
Block(-1,5,-3,LOG:13)
Block(5,29,-2,LEAVES:1)
Block(-3,30,-2,LEAVES:1)
Block(-2,25,-8,LEAVES:1)
Block(-2,24,-8,LEAVES:1)
Block(-1,9,-3,LOG:13)
Block(-1,8,-3,LOG:13)
Block(-2,25,4,LEAVES:1)
Block(-1,7,-3,LOG:13)
Block(-2,23,-8,LOG:13)
Block(-2,24,4,LOG:13)
Block(-1,6,-3,LOG:13)
Block(-1,33,-4,LEAVES:1)
Block(-3,29,-2,LEAVES:1)
Block(-1,32,-4,LEAVES:1)
Block(-1,29,1,LEAVES:1)
Block(-1,34,-4,LEAVES:1)
Block(0,25,3,LEAVES:1)
Block(4,18,5,LEAVES:1)
Block(3,29,-4,LEAVES:1)
Block(4,19,5,LEAVES:1)
Block(0,24,3,LEAVES:1)
Block(-1,23,1,LOG:13)
Block(-1,24,1,LEAVES:1)
Block(0,5,-1,LOG:13)
Block(3,6,-2,LOG:13)
Block(0,4,-1,DIRT)
Block(3,7,-2,LOG:13)
Block(0,7,-1,LOG:13)
Block(3,8,-2,LOG:13)
Block(0,6,-1,LOG:13)
Block(3,9,-2,LOG:13)
Block(0,9,-1,LOG:13)
Block(-10,21,4,LEAVES:1)
Block(0,8,-1,LOG:13)
Block(8,18,6,LEAVES:1)
Block(8,19,6,LEAVES:1)
Block(3,34,-4,LEAVES:1)
Block(3,33,-4,LEAVES:1)
Block(-5,29,1,LEAVES:1)
Block(-5,23,1,LOG:13)
Block(3,30,-4,LEAVES:1)
Block(-5,24,1,LEAVES:1)
Block(3,32,-4,LEAVES:1)
Block(3,5,-2,LOG:13)
Block(6,29,0,LEAVES:1)
Block(-10,20,-1,LEAVES:1)
Block(3,21,2,LEAVES:1)
Block(-1,30,1,LEAVES:1)
Block(-3,33,-2,LEAVES:1)
Block(3,22,2,LEAVES:1)
Block(-1,31,1,LEAVES:1)
Block(6,22,0,LOG:13)
Block(-1,32,1,LEAVES:1)
Block(6,23,0,LEAVES:1)
Block(-1,33,1,LEAVES:1)
Block(-3,34,-2,LEAVES:1)
Block(3,6,1,LOG:13)
Block(3,5,1,LOG:13)
Block(3,4,1,LOG:13)
Block(-6,21,-4,LEAVES:1)
Block(-6,20,-4,LEAVES:1)
Block(-8,21,1,LEAVES:1)
Block(-5,21,1,LEAVES:1)
Block(-5,22,1,LEAVES:1)
Block(-8,24,1,LEAVES:1)
Block(-8,22,1,LEAVES:1)
Block(-8,23,1,LEAVES:1)
Block(5,21,6,LEAVES:1)
Block(5,22,6,LEAVES:1)
Block(5,18,6,LEAVES:1)
Block(5,19,6,LEAVES:1)
Block(1,29,-4,LEAVES:1)
Block(3,32,-2,LEAVES:1)
Block(3,33,-2,LEAVES:1)
Block(3,34,-2,LEAVES:1)
Block(2,18,8,LEAVES:1)
Block(2,19,8,LEAVES:1)
Block(3,30,-2,LEAVES:1)
Block(-1,-2,1,LOG:13)
Block(-1,-3,1,LOG:13)
Block(-1,-4,1,LOG:13)
Block(-1,-5,1,LOG:13)
Block(-1,-6,1,LOG:13)
Block(1,19,8,LEAVES:1)
Block(-1,-7,1,LOG:13)
Block(1,18,8,LEAVES:1)
Block(3,29,0,LEAVES:1)
Block(-1,-8,1,LOG:13)
Block(0,18,5,LOG:13)
Block(3,3,1,LOG:13)
Block(-4,24,-8,LEAVES:1)
Block(3,2,1,LOG:13)
Block(3,21,0,LOG:13)
Block(-4,25,-8,LEAVES:1)
Block(3,1,1,LOG:13)
Block(-1,-1,1,LOG:13)
Block(3,0,1,LOG:13)
Block(-4,23,-8,LEAVES:1)
Block(-2,25,-12,LEAVES:1)
Block(-9,20,-6,LEAVES:1)
Block(-9,21,-6,LEAVES:1)
Block(-2,23,-12,LEAVES:1)
Block(-2,24,-12,LEAVES:1)
Block(-5,22,3,LEAVES:1)
Block(-5,21,3,LEAVES:1)
Block(-5,24,3,LEAVES:1)
Block(-5,23,3,LEAVES:1)
Block(-11,20,-5,LEAVES:1)
Block(3,31,0,LEAVES:1)
Block(-6,21,6,LEAVES:1)
Block(3,30,0,LEAVES:1)
Block(3,33,0,LEAVES:1)
Block(3,32,0,LEAVES:1)
Block(-11,21,-5,LEAVES:1)
Block(3,34,0,LEAVES:1)
Block(-3,18,9,LEAVES:1)
Block(-3,19,9,LEAVES:1)
Block(7,19,3,LEAVES:1)
Block(7,18,3,LEAVES:1)
Block(4,21,5,LEAVES:1)
Block(4,22,5,LEAVES:1)
Block(5,30,-2,LEAVES:1)
Block(-1,4,1,LOG:13)
Block(-1,3,1,LOG:13)
Block(-1,6,1,LOG:13)
Block(-1,5,1,LOG:13)
Block(-1,8,1,LOG:13)
Block(-4,18,9,LEAVES:1)
Block(7,29,-2,LEAVES:1)
Block(-1,7,1,LOG:13)
Block(2,23,-9,LEAVES:1)
Block(-1,9,1,LOG:13)
Block(2,24,-9,LEAVES:1)
Block(7,22,-2,LEAVES:1)
Block(7,22,3,LEAVES:1)
Block(1,32,-4,LEAVES:1)
Block(7,23,3,LEAVES:1)
Block(1,34,-4,LEAVES:1)
Block(7,21,3,LEAVES:1)
Block(1,33,-4,LEAVES:1)
Block(-9,21,4,LEAVES:1)
Block(-9,22,4,LEAVES:1)
Block(-1,0,1,LOG:13)
Block(-8,20,-2,LEAVES:1)
Block(-8,21,-2,LEAVES:1)
Block(-1,2,1,LOG:13)
Block(-1,1,1,LOG:13)
Block(6,21,2,LEAVES:1)
Block(-2,18,11,LEAVES:1)
Block(3,-8,0,LOG:13)
Block(7,19,5,LEAVES:1)
Block(7,18,5,LEAVES:1)
Block(-1,25,-11,LEAVES:1)
Block(-1,23,-11,LEAVES:1)
Block(4,30,1,LEAVES:1)
Block(-1,24,-11,LEAVES:1)
Block(2,12,-2,LOG:13)
Block(2,13,-2,LOG:13)
Block(2,10,-2,LOG:13)
Block(2,11,-2,LOG:13)
Block(-7,21,-6,LEAVES:1)
Block(6,23,2,LEAVES:1)
Block(6,22,2,LEAVES:1)
Block(-4,18,7,LEAVES:1)
Block(-9,21,-4,LEAVES:1)
Block(-9,20,-4,LOG:13)
Block(4,29,1,LEAVES:1)
Block(-7,21,0,LEAVES:1)
Block(-7,23,0,LEAVES:1)
Block(2,29,-2,LOG:13)
Block(-7,20,-6,LEAVES:1)
Block(-7,22,0,LEAVES:1)
Block(4,21,1,LOG:13)
Block(6,19,2,LEAVES:1)
Block(-8,22,3,LEAVES:1)
Block(1,30,-2,LOG:13)
Block(-8,21,3,LEAVES:1)
Block(1,31,-2,LOG:13)
Block(7,22,5,LEAVES:1)
Block(1,32,-2,LOG:13)
Block(7,21,5,LEAVES:1)
Block(1,33,-2,LOG:13)
Block(1,34,-2,LEAVES:1)
Block(1,35,-2,LEAVES:1)
Block(-5,24,-8,LEAVES:1)
Block(9,19,6,LEAVES:1)
Block(9,18,6,LEAVES:1)
Block(0,22,-4,LOG:13)
Block(-6,22,2,LEAVES:1)
Block(-6,21,2,LOG:13)
Block(6,18,2,LEAVES:1)
Block(-6,24,2,LEAVES:1)
Block(-6,23,2,LEAVES:1)
Block(2,18,6,LOG:13)
Block(0,6,1,LOG:13)
Block(0,5,1,LOG:13)
Block(1,6,1,LOG:13)
Block(-2,19,6,LEAVES:1)
Block(-2,18,6,LEAVES:1)
Block(2,19,6,LEAVES:1)
Block(-2,24,6,LEAVES:1)
Block(2,34,-2,LEAVES:1)
Block(-1,23,-6,LOG:13)
Block(2,32,-2,LEAVES:1)
Block(-1,24,-6,LEAVES:1)
Block(2,33,-2,LEAVES:1)
Block(2,30,-2,LEAVES:1)
Block(2,31,-2,LEAVES:1)
Block(-12,20,-3,LEAVES:1)
Block(0,25,-11,LEAVES:1)
Block(0,23,-11,LEAVES:1)
Block(0,24,-11,LEAVES:1)
Block(-2,23,-6,LEAVES:1)
Block(-2,25,-6,LEAVES:1)
Block(-2,6,1,LOG:13)
Block(-2,24,-6,LEAVES:1)
Block(-2,5,1,LOG:13)
Block(-2,4,1,LOG:13)
Block(-2,3,1,LOG:13)
Block(-2,2,1,LOG:13)
Block(-2,25,6,LEAVES:1)
Block(-2,1,1,LOG:13)
Block(-2,0,1,LOG:13)
Block(3,29,-2,LOG:13)
Block(0,24,5,LEAVES:1)
Block(-8,20,-6,LEAVES:1)
Block(-8,21,-6,LEAVES:1)
Block(0,25,5,LEAVES:1)
Block(-11,20,-3,LEAVES:1)
Block(-11,21,-3,LEAVES:1)
Block(-3,23,0,LEAVES:1)
Block(1,23,-10,LEAVES:1)
Block(9,22,4,LEAVES:1)
Block(1,24,-10,LEAVES:1)
Block(-3,24,-6,LEAVES:1)
Block(4,19,3,LEAVES:1)
Block(-3,24,0,LEAVES:1)
Block(4,18,3,LOG:13)
Block(-10,21,2,LEAVES:1)
Block(-3,29,0,LEAVES:1)
Block(-2,18,8,LEAVES:1)
Block(-2,19,8,LEAVES:1)
Block(-1,25,-8,LEAVES:1)
Block(-1,24,-8,LEAVES:1)
Block(-1,23,-8,LEAVES:1)
Block(-10,21,-3,LEAVES:1)
Block(11,22,1,LEAVES:1)
Block(-10,20,-3,LEAVES:1)
Block(0,31,-2,LOG:13)
Block(11,23,1,LEAVES:1)
Block(0,30,-2,LOG:13)
Block(0,33,-2,LOG:13)
Block(0,32,-2,LOG:13)
Block(0,35,-2,LEAVES:1)
Block(-3,30,0,LEAVES:1)
Block(0,34,-2,LEAVES:1)
Block(-1,7,-1,LOG:13)
Block(-1,6,-1,LOG:13)
Block(-1,5,-1,LOG:13)
Block(-3,31,0,LEAVES:1)
Block(-3,32,0,LEAVES:1)
Block(6,30,0,LEAVES:1)
Block(-1,19,11,LEAVES:1)
Block(-1,9,-1,LOG:13)
Block(-1,8,-1,LOG:13)
Block(-1,18,11,LEAVES:1)
Block(1,5,1,LOG:13)
Block(-8,21,-4,LEAVES:1)
Block(-8,20,-4,LEAVES:1)
Block(0,17,-2,LOG:13)
Block(0,16,-2,LOG:13)
Block(0,19,-2,LOG:13)
Block(0,18,-2,LOG:13)
Block(5,19,8,LEAVES:1)
Block(5,18,8,LEAVES:1)
Block(1,26,-2,LOG:13)
Block(1,27,-2,LOG:13)
Block(1,28,-2,LOG:13)
Block(1,29,-2,LOG:13)
Block(1,20,-2,LOG:13)
Block(1,21,-2,LOG:13)
Block(1,3,-5,LOG:13)
Block(1,22,-2,LOG:13)
Block(1,4,-5,LOG:13)
Block(2,5,1,LOG:13)
Block(1,23,-2,LOG:13)
Block(1,1,-5,LOG:13)
Block(0,18,7,LEAVES:1)
Block(1,24,-2,LOG:13)
Block(1,2,-5,LOG:13)
Block(0,19,7,LEAVES:1)
Block(1,25,-2,LOG:13)
Block(1,0,-5,LOG:13)
Block(3,19,9,LEAVES:1)
Block(0,11,-2,LOG:13)
Block(0,10,-2,LOG:13)
Block(0,13,-2,LOG:13)
Block(0,12,-2,LOG:13)
Block(0,15,-2,LOG:13)
Block(3,18,9,LEAVES:1)
Block(0,14,-2,LOG:13)
Block(0,28,-2,LOG:13)
Block(0,27,-2,LOG:13)
Block(0,29,-2,LOG:13)
Block(-1,31,3,LEAVES:1)
Block(1,15,-2,LOG:13)
Block(1,16,-2,LOG:13)
Block(1,17,-2,LOG:13)
Block(1,18,-2,LOG:13)
Block(1,19,-2,LOG:13)
Block(-2,25,-10,LEAVES:1)
Block(4,22,3,LEAVES:1)
Block(-2,24,-10,LEAVES:1)
Block(4,21,3,LEAVES:1)
Block(-2,23,-10,LEAVES:1)
Block(4,-8,-2,LOG:13)
Block(3,-1,0,LOG:13)
Block(-1,29,3,LEAVES:1)
Block(4,-6,-2,LOG:13)
Block(3,-3,0,LOG:13)
Block(4,-7,-2,LOG:13)
Block(3,-2,0,LOG:13)
Block(1,10,-2,LOG:13)
Block(3,-5,0,LOG:13)
Block(1,11,-2,LOG:13)
Block(3,-4,0,LOG:13)
Block(1,12,-2,LOG:13)
Block(3,-7,0,LOG:13)
Block(1,13,-2,LOG:13)
Block(3,-6,0,LOG:13)
Block(1,14,-2,LOG:13)
Block(0,20,-2,LOG:13)
Block(-6,21,4,LEAVES:1)
Block(4,-1,-2,LOG:13)
Block(-6,22,4,LEAVES:1)
Block(9,18,4,LEAVES:1)
Block(0,22,-2,LOG:13)
Block(-1,24,3,LEAVES:1)
Block(9,19,4,LEAVES:1)
Block(0,21,-2,LOG:13)
Block(4,-4,-2,LOG:13)
Block(0,24,-2,LOG:13)
Block(4,-5,-2,LOG:13)
Block(0,23,-2,LOG:13)
Block(-1,25,3,LEAVES:1)
Block(4,-2,-2,LOG:13)
Block(-6,23,4,LEAVES:1)
Block(0,26,-2,LOG:13)
Block(4,-3,-2,LOG:13)
Block(0,25,-2,LOG:13)

#######################################################################
# +-----------------------------------------------------------------+ #
# |                            BO3 checks                           | #
# +-----------------------------------------------------------------+ #
#######################################################################

BlockCheck(0,-1,0,GRASS,DIRT:0,DIRT:1,DIRT:2,biomesoplenty:grass:0,biomesoplenty:grass:1,biomesoplenty:grass,biomesoplenty:grass:3,biomesoplenty:grass:4,biomesoplenty:grass:5,biomesoplenty:grass:6,biomesoplenty:grass:7,biomesoplenty:dirt,biomesoplenty:dirt:1,biomesoplenty:dirt:2,biomesoplenty:dirt:8,biomesoplenty:dirt:9,biomesoplenty:dirt:10,biomesoplenty:dried_sand,biomesoplenty:hard_ice,biomesoplenty:white_sand,biomesoplenty:white_sandstone,biomesoplenty:mud,biomesoplenty:ash_block)

#######################################################################
# +-----------------------------------------------------------------+ #
# |                             Branches                            | #
# +-----------------------------------------------------------------+ #
#######################################################################


#######################################################################
# +-----------------------------------------------------------------+ #
# |                             Entities                            | #
# +-----------------------------------------------------------------+ #
#######################################################################


#######################################################################
# +-----------------------------------------------------------------+ #
# |                            Particles                            | #
# +-----------------------------------------------------------------+ #
#######################################################################


#######################################################################
# +-----------------------------------------------------------------+ #
# |                             Spawners                            | #
# +-----------------------------------------------------------------+ #
#######################################################################


#######################################################################
# +-----------------------------------------------------------------+ #
# |                             ModData                             | #
# +-----------------------------------------------------------------+ #
#######################################################################

