{
	"registryname": "advanced_carpenter",
    "localizedname": "Advanced Carpenter",
    "parts": [
        {"x": -1,"y": -1,"z": 0,"elements": ["modularmachinery:blockcasing@0"]},
        {"x": -1,"y": -1,"z": 1,"elements": ["modularmachinery:blockcasing@0"]},
        {"x": -1,"y": -1,"z": 2,"elements": ["modularmachinery:blockcasing@0"]},
        {"x": -1,"y": -1,"z": 3,"elements": ["modularmachinery:blockcasing@0"]},
        {"x": -1,"y": -1,"z": 4,"elements": ["modularmachinery:blockcasing@0"]},
        {"x": -1,"y": 0,"z" : 0,"elements": ["casings"]},
        {"x": -1,"y": 0,"z" : 1,"elements": ["thermalfoundation:fluid_cryotheum@0"]},
        {"x": -1,"y": 0,"z" : 2,"elements": ["thermalfoundation:fluid_cryotheum@0"]},
        {"x": -1,"y": 0,"z" : 3,"elements": ["thermalfoundation:fluid_cryotheum@0"]},
        {"x": -1,"y": 0,"z" : 4,"elements": ["casings_modular"]},
        {"x": -1,"y": 1,"z" : 0,"elements": ["modularmachinery:blockcasing@0"]},
        {"x": -1,"y": 1,"z" : 1,"elements": ["appliedenergistics2:dense_energy_cell@0"]},
        {"x": -1,"y": 1,"z" : 2,"elements": ["appliedenergistics2:dense_energy_cell@0"]},
        {"x": -1,"y": 1,"z" : 3,"elements": ["appliedenergistics2:dense_energy_cell@0"]},
        {"x": -1,"y": 1,"z" : 4,"elements": ["modularmachinery:blockcasing@0"]},
        {"x": -1,"y": 2,"z" : 1,"elements": ["modularmachinery:blockcasing@0"]},
        {"x": -1,"y": 2,"z" : 2,"elements": ["modularmachinery:blockcasing@0"]},
        {"x": -1,"y": 2,"z" : 3,"elements": ["modularmachinery:blockcasing@0"]},
        {"x": -2,"y": -1,"z": 1,"elements": ["modularmachinery:blockcasing@0"]},
        {"x": -2,"y": -1,"z": 2,"elements": ["modularmachinery:blockcasing@0"]},
        {"x": -2,"y": -1,"z": 3,"elements": ["modularmachinery:blockcasing@0"]},
        {"x": -2,"y": 0,"z" : 1,"elements": ["casings"]},
        {"x": -2,"y": 0,"z" : 2,"elements": ["casings_modular"]},
        {"x": -2,"y": 0,"z" : 3,"elements": ["casings"]},
        {"x": -2,"y": 1,"z" : 1,"elements": ["modularmachinery:blockcasing@0"]},
        {"x": -2,"y": 1,"z" : 2,"elements": ["modularmachinery:blockcasing@1"]},
        {"x": -2,"y": 1,"z" : 3,"elements": ["modularmachinery:blockcasing@0"]},
        {"x": 0,"y" : -1,"z": 0,"elements": ["modularmachinery:blockcasing@0"]},
        {"x": 0,"y" : -1,"z": 1,"elements": ["modularmachinery:blockcasing@0"]},
        {"x": 0,"y" : -1,"z": 2,"elements": ["modularmachinery:blockcasing@0"]},
        {"x": 0,"y" : -1,"z": 3,"elements": ["modularmachinery:blockcasing@0"]},
        {"x": 0,"y" : -1,"z": 4,"elements": ["modularmachinery:blockcasing@0"]},
        {"x": 0,"y" : 0,"z" : 1,"elements": ["thermalfoundation:fluid_cryotheum@0"]},
        {"x": 0,"y" : 0,"z" : 2,"elements": ["thermalfoundation:fluid_cryotheum@0"]},
        {"x": 0,"y" : 0,"z" : 3,"elements": ["thermalfoundation:fluid_cryotheum@0"]},
        {"x": 0,"y" : 0,"z" : 4,"elements": ["casings_energy_in"]},
        {"x": 0,"y" : 1,"z" : 0,"elements": ["modularmachinery:blockcasing@0"]},
        {"x": 0,"y" : 1,"z" : 1,"elements": ["appliedenergistics2:dense_energy_cell@0"]},
        {"x": 0,"y" : 1,"z" : 2,"elements": ["appliedenergistics2:dense_energy_cell@0"]},
        {"x": 0,"y" : 1,"z" : 3,"elements": ["appliedenergistics2:dense_energy_cell@0"]},
        {"x": 0,"y" : 1,"z" : 4,"elements": ["modularmachinery:blockcasing@0"]},
        {"x": 0,"y" : 2,"z" : 1,"elements": ["modularmachinery:blockcasing@0"]},
        {"x": 0,"y" : 2,"z" : 2,"elements": ["modularmachinery:blockcasing@1"]},
        {"x": 0,"y" : 2,"z" : 3,"elements": ["modularmachinery:blockcasing@0"]},
        {"x": 1,"y" : -1,"z": 0,"elements": ["modularmachinery:blockcasing@0"]},
        {"x": 1,"y" : -1,"z": 1,"elements": ["modularmachinery:blockcasing@0"]},
        {"x": 1,"y" : -1,"z": 2,"elements": ["modularmachinery:blockcasing@0"]},
        {"x": 1,"y" : -1,"z": 3,"elements": ["modularmachinery:blockcasing@0"]},
        {"x": 1,"y" : -1,"z": 4,"elements": ["modularmachinery:blockcasing@0"]},
        {"x": 1,"y" : 0,"z" : 0,"elements": ["casings"]},
        {"x": 1,"y" : 0,"z" : 1,"elements": ["thermalfoundation:fluid_cryotheum@0"]},
        {"x": 1,"y" : 0,"z" : 2,"elements": ["thermalfoundation:fluid_cryotheum@0"]},
        {"x": 1,"y" : 0,"z" : 3,"elements": ["thermalfoundation:fluid_cryotheum@0"]},
        {"x": 1,"y" : 0,"z" : 4,"elements": ["casings_modular"]},
        {"x": 1,"y" : 1,"z" : 0,"elements": ["modularmachinery:blockcasing@0"]},
        {"x": 1,"y" : 1,"z" : 1,"elements": ["appliedenergistics2:dense_energy_cell@0"]},
        {"x": 1,"y" : 1,"z" : 2,"elements": ["appliedenergistics2:dense_energy_cell@0"]},
        {"x": 1,"y" : 1,"z" : 3,"elements": ["appliedenergistics2:dense_energy_cell@0"]},
        {"x": 1,"y" : 1,"z" : 4,"elements": ["modularmachinery:blockcasing@0"]},
        {"x": 1,"y" : 2,"z" : 1,"elements": ["modularmachinery:blockcasing@0"]},
        {"x": 1,"y" : 2,"z" : 2,"elements": ["modularmachinery:blockcasing@0"]},
        {"x": 1,"y" : 2,"z" : 3,"elements": ["modularmachinery:blockcasing@0"]},
        {"x": 2,"y" : -1,"z": 1,"elements": ["modularmachinery:blockcasing@0"]},
        {"x": 2,"y" : -1,"z": 2,"elements": ["modularmachinery:blockcasing@0"]},
        {"x": 2,"y" : -1,"z": 3,"elements": ["modularmachinery:blockcasing@0"]},
        {"x": 2,"y" : 0,"z" : 1,"elements": ["casings"]},
        {"x": 2,"y" : 0,"z" : 2,"elements": ["casings_modular"]},
        {"x": 2,"y" : 0,"z" : 3,"elements": ["casings"]},
        {"x": 2,"y" : 1,"z" : 1,"elements": ["modularmachinery:blockcasing@0"]},
        {"x": 2,"y" : 1,"z" : 2,"elements": ["modularmachinery:blockcasing@1"]},
        {"x": 2,"y" : 1,"z" : 3,"elements": ["modularmachinery:blockcasing@0"]}
    ]}