{
    "registryname": "armor_foundry",
    "localizedname": "Armor Foundry",
    "requires-blueprint": true,
    "color": "A85015",
    "parts": [
        { "x": -1, "y": 0, "z": 0, "elements": "modularmachinery:blockcasing@3" },
        { "x": -1, "y": 0, "z": 1, "elements": "modularmachinery:blockcasing@0" },
        { "x": -1, "y": 0, "z": 2, "elements": "modularmachinery:blockcasing@0" },
        { "x": -1, "y": 0, "z": 3, "elements": "modularmachinery:blockcasing@0" },
        { "x": -1, "y": 0, "z": 4, "elements": "casings_energy_in" },
        { "x": -1, "y": 0, "z": 5, "elements": "avaritia:block_resource@0" },
        { "x": -1, "y": 1, "z": 1, "elements": "extrautils2:drum@3" },
        { "x": -1, "y": 1, "z": 2, "elements": "immersiveengineering:metal_device1@6" },
        { "x": -1, "y": 1, "z": 3, "elements": "immersiveengineering:metal_device1@6" },
        { "x": -1, "y": 1, "z": 4, "elements": "modularmachinery:blockcasing@3" },
        { "x": -1, "y": 1, "z": 5, "elements": "quark:smoker@0" },
        { "x": -1, "y": 2, "z": 3, "elements": "immersiveengineering:metal_device1@6" },
        { "x": -1, "y": 2, "z": 4, "elements": "modularmachinery:blockcasing@3" },
        { "x": -1, "y": 3, "z": 3, "elements": "immersiveengineering:metal_device1@6" },
        { "x": -1, "y": 3, "z": 4, "elements": "casings_modular" },
        { "x": 0, "y": 0, "z": 1,  "elements": "modularmachinery:blockcasing@0" },
        { "x": 0, "y": 0, "z": 2,  "elements": "modularmachinery:blockcasing@0" },
        { "x": 0, "y": 0, "z": 3,  "elements": "modularmachinery:blockcasing@0" },
        { "x": 0, "y": 0, "z": 4,  "elements": "modularmachinery:blockcasing@0" },
        { "x": 0, "y": 0, "z": 5,  "elements": "modularmachinery:blockcasing@0" },
        { "x": 0, "y": 1, "z": 0,  "elements": "casings_modular" },
        { "x": 0, "y": 1, "z": 1,  "elements": "industrialforegoing:conveyor", "nbt": {"Facing":"north"} },
        { "x": 0, "y": 1, "z": 3,  "elements": "modularmachinery:blockcasing@3" },
        { "x": 0, "y": 1, "z": 4,  "elements": "modularmachinery:blockcasing@0" },
        { "x": 0, "y": 1, "z": 5,  "elements": "modularmachinery:blockcasing@0" },
        { "x": 0, "y": 1, "z": 2,  "elements": "industrialforegoing:conveyor", "nbt": {"Facing":"north"} },
        { "x": 0, "y": 2, "z": 3,  "elements": "casings_modular" },
        { "x": 0, "y": 2, "z": 4,  "elements": ["minecraft:unpowered_comparator@0",
                                                "minecraft:unpowered_comparator@1",
                                                "minecraft:unpowered_comparator@2",
                                                "minecraft:unpowered_comparator@3",
                                                "minecraft:unpowered_comparator@4",
                                                "minecraft:unpowered_comparator@5",
                                                "minecraft:unpowered_comparator@6",
                                                "minecraft:unpowered_comparator@7",
                                                "minecraft:unpowered_comparator@8",
                                                "minecraft:unpowered_comparator@9",
                                                "minecraft:unpowered_comparator@10",
                                                "minecraft:unpowered_comparator@11",
                                                "minecraft:unpowered_comparator@12",
                                                "minecraft:unpowered_comparator@13",
                                                "minecraft:unpowered_comparator@14",
                                                "minecraft:unpowered_comparator@15"] },
        { "x": 0, "y": 2, "z": 5,  "elements": "twilightforest:fire_jet@6" },
        { "x": 1, "y": 0, "z": 0,  "elements": "modularmachinery:blockcasing@3" },
        { "x": 1, "y": 0, "z": 1,  "elements": "modularmachinery:blockcasing@0" },
        { "x": 1, "y": 0, "z": 2,  "elements": "modularmachinery:blockcasing@0" },
        { "x": 1, "y": 0, "z": 3,  "elements": "modularmachinery:blockcasing@0" },
        { "x": 1, "y": 0, "z": 4,  "elements": "casings_energy_in" },
        { "x": 1, "y": 0, "z": 5,  "elements": "avaritia:block_resource@0" },
        { "x": 1, "y": 1, "z": 1,  "elements": "extrautils2:drum@3" },
        { "x": 1, "y": 1, "z": 2,  "elements": "immersiveengineering:metal_device1@6" },
        { "x": 1, "y": 1, "z": 3,  "elements": "immersiveengineering:metal_device1@6" },
        { "x": 1, "y": 1, "z": 4,  "elements": "modularmachinery:blockcasing@3" },
        { "x": 1, "y": 1, "z": 5,  "elements": "quark:smoker@0" },
        { "x": 1, "y": 2, "z": 3,  "elements": "immersiveengineering:metal_device1@6" },
        { "x": 1, "y": 2, "z": 4,  "elements": "modularmachinery:blockcasing@3" },
        { "x": 1, "y": 3, "z": 3,  "elements": "immersiveengineering:metal_device1@6" },
        { "x": 1, "y": 3, "z": 4,  "elements": "casings_modular" }
    ]}