#######################################################################
# +-----------------------------------------------------------------+ #
# |                            BO3 object                           | #
# +-----------------------------------------------------------------+ #
#######################################################################

# The descriptions in this file are true only for TerrainControl. They are not true for the Minecraft Worlds mod!
# Minecraft Worlds completely reimplemented BO3s, check the MCW documentation on the mc/mctcp forums for how to use BO3s with MCW
# or watch the video's on my YT channel at https://www.youtube.com/user/PeeGee85. You can check out the "Editing and importing schematics & BO3s" 
# series of video's, in part 2 I explain BO3s. 

# This is the config file of a custom object.
# If you add this object correctly to your BiomeConfigs, it will spawn in the world.

# This is the creator of this BO3 object
Author: Unknown

# A short description of this BO3 object
Description: This BO3 was converted from a schematic using the MineCraft Worlds Editor. Unfortunately the author and description information for the schematic could not be found. If you know who the author of the schematic is then please tell the author of this BO3!

# The BO3 version, don't change this! It can be used by external applications to do a version check.
Version: 3

# The settings mode, WriteAll, WriteWithoutComments or WriteDisable. See WorldConfig.
SettingsMode: WriteDisable

#######################################################################
# +-----------------------------------------------------------------+ #
# |                          Main settings                          | #
# +-----------------------------------------------------------------+ #
#######################################################################

# This needs to be set to true to spawn the object in the Tree and Sapling resources.
Tree: false

# The frequency of the BO3 from 1 to 200. Tries this many times to spawn this BO3 when using the CustomObject(...) resource.
# Ignored by Tree(..), Sapling(..) and CustomStructure(..)
Frequency: 40

# The rarity of the BO3 from 0 to 100. Each spawn attempt has rarity% chance to succeed when using the CustomObject(...) resource.
# Ignored by Tree(..), Sapling(..) and CustomStructure(..)
Rarity: 100.0

# If you set this to true, the BO3 will be placed with a random rotation.
RotateRandomly: false

# The spawn height of the BO3 - randomY, highestBlock or highestSolidBlock.
SpawnHeight: randomY

# The height limits for the BO3.
MinHeight: 0

MaxHeight: 256

# Objects can have other objects attached to it: branches. Branches can also
# have branches attached to it, which can also have branches, etc. This is the
# maximum branch depth for this objects.
MaxBranchDepth: 10

# When spawned with the UseWorld keyword, this BO3 should NOT spawn in the following biomes.
# If you writer.write the BO3 name directly in the BiomeConfigs, this will be ignored.
ExcludedBiomes: All

#######################################################################
# +-----------------------------------------------------------------+ #
# |                      Source block settings                      | #
# +-----------------------------------------------------------------+ #
#######################################################################

# The block(s) the BO3 should spawn in.
SourceBlocks: AIR

# The maximum percentage of the BO3 that can be outside the SourceBlock.
# The BO3 won't be placed on a location with more blocks outside the SourceBlock than this percentage.
MaxPercentageOutsideSourceBlock: 100

# What to do when a block is about to be placed outside the SourceBlock? (dontPlace, placeAnyway)
OutsideSourceBlock: placeAnyway

#######################################################################
# +-----------------------------------------------------------------+ #
# |                              Blocks                             | #
# +-----------------------------------------------------------------+ #
#######################################################################

# All the blocks used in the BO3 are listed here. Possible blocks:
# Block(x,y,z,id[.data][,nbtfile.nbt)
# RandomBlock(x,y,z,id[:data][,nbtfile.nbt],chance[,id[:data][,nbtfile.nbt],chance[,...]])
# So RandomBlock(0,0,0,CHEST,chest.nbt,50,CHEST,anotherchest.nbt,100) will spawn a chest at
# the BO3 origin, and give it a 50% chance to have the contents of chest.nbt, or, if that
# fails, a 100% percent chance to have the contents of anotherchest.nbt.

Block(-7,18,8,125:5)
Block(-6,18,8,5:1)
Block(-5,18,8,5:1)
Block(-5,19,8,126:1)
Block(-5,26,8,159:13)
Block(-4,18,8,5:1)
Block(-4,19,8,126:1)
Block(-4,25,4,5:5)
Block(-4,25,7,159:13)
Block(-4,26,8,159:13)
Block(-3,18,8,5:1)
Block(-3,19,8,126:1)
Block(-3,22,5,17:5)
Block(-3,24,4,126:13)
Block(-3,24,6,159:13)
Block(-3,25,4,5:5)
Block(-3,25,7,159:13)
Block(-3,26,8,159:13)
Block(-2,0,5,17:1)
Block(-2,1,5,17:1)
Block(-2,2,5,17:1)
Block(-2,3,5,17:1)
Block(-2,4,5,17:1)
Block(-2,5,5,17:1)
Block(-2,6,5,17:1)
Block(-2,7,5,17:1)
Block(-2,8,5,17:1)
Block(-2,9,5,17:1)
Block(-2,10,5,17:1)
Block(-2,11,5,17:1)
Block(-2,12,5,17:1)
Block(-2,13,5,17:1)
Block(-2,13,6,17:9)
Block(-2,13,7,17:9)
Block(-2,13,8,17:9)
Block(-2,14,5,17:1)
Block(-2,14,6,134:4)
Block(-2,14,7,134:4)
Block(-2,14,8,134:4)
Block(-2,15,5,17:1)
Block(-2,15,6,134)
Block(-2,15,8,134)
Block(-2,16,5,17:1)
Block(-2,16,6,134:4)
Block(-2,16,7,134:4)
Block(-2,16,8,134:4)
Block(-2,17,5,17:1)
Block(-2,17,6,134:4)
Block(-2,17,7,134:4)
Block(-2,17,8,134:4)
Block(-2,18,5,17:1)
Block(-2,18,6,17:9)
Block(-2,18,7,17:9)
Block(-2,18,8,17:9)
Block(-2,19,5,17:1)
Block(-2,19,6,134:4)
Block(-2,19,7,134:4)
Block(-2,19,8,134:4)
Block(-2,20,5,17:1)
Block(-2,20,6,134)
Block(-2,20,7,134)
Block(-2,20,8,134)
Block(-2,21,5,17:1)
Block(-2,21,6,134:4)
Block(-2,21,7,134:4)
Block(-2,21,8,134:4)
Block(-2,22,5,17:5)
Block(-2,22,6,17:9)
Block(-2,22,7,17:9)
Block(-2,22,8,17:9)
Block(-2,23,5,159:13)
Block(-2,23,6,134:4)
Block(-2,23,7,134:4)
Block(-2,23,8,134:4)
Block(-2,24,4,5:5)
Block(-2,24,6,159:13)
Block(-2,24,7,5:1)
Block(-2,24,8,5:1)
Block(-2,25,4,126:5)
Block(-2,25,7,159:13)
Block(-2,25,8,5:1)
Block(-2,26,8,159:13)
Block(-1,13,5,17:5)
Block(-1,13,6,5:1)
Block(-1,13,7,5:1)
Block(-1,13,8,5:1)
Block(-1,14,-2,AIR)
Block(-1,14,-1,AIR)
Block(-1,14,0,AIR)
Block(-1,14,1,AIR)
Block(-1,14,2,AIR)
Block(-1,14,3,AIR)
Block(-1,14,4,AIR)
Block(-1,14,5,134:6)
Block(-1,14,6,134:7)
Block(-1,14,7,134:5)
Block(-1,14,8,134:5)
Block(-1,15,-2,AIR)
Block(-1,15,-1,AIR)
Block(-1,15,0,AIR)
Block(-1,15,1,AIR)
Block(-1,15,2,AIR)
Block(-1,15,3,AIR)
Block(-1,15,4,AIR)
Block(-1,15,5,134:2)
Block(-1,15,6,5:1)
Block(-1,15,7,160:9)
Block(-1,15,8,5:1)
Block(-1,16,-2,AIR)
Block(-1,16,-1,AIR)
Block(-1,16,0,AIR)
Block(-1,16,1,AIR)
Block(-1,16,2,AIR)
Block(-1,16,3,AIR)
Block(-1,16,4,AIR)
Block(-1,16,5,134:6)
Block(-1,16,6,134:1)
Block(-1,16,7,134:1)
Block(-1,16,8,134:1)
Block(-1,17,-2,AIR)
Block(-1,17,-1,AIR)
Block(-1,17,0,AIR)
Block(-1,17,1,AIR)
Block(-1,17,2,AIR)
Block(-1,17,3,AIR)
Block(-1,17,4,AIR)
Block(-1,17,5,134:6)
Block(-1,17,6,AIR)
Block(-1,17,7,AIR)
Block(-1,17,8,126:9)
Block(-1,18,-2,126:13)
Block(-1,18,-1,126:13)
Block(-1,18,0,5:5)
Block(-1,18,1,5:5)
Block(-1,18,2,5:5)
Block(-1,18,3,5:5)
Block(-1,18,4,5:5)
Block(-1,18,5,17:5)
Block(-1,18,6,5:1)
Block(-1,18,7,5:1)
Block(-1,18,8,5:1)
Block(-1,19,-3,164:6)
Block(-1,19,-2,5:5)
Block(-1,19,-1,5:5)
Block(-1,19,0,126:5)
Block(-1,19,1,126:5)
Block(-1,19,2,AIR)
Block(-1,19,3,126:5)
Block(-1,19,4,126:5)
Block(-1,19,5,5:1)
Block(-1,19,6,134:7)
Block(-1,19,7,AIR)
Block(-1,19,8,AIR)
Block(-1,20,-3,126:5)
Block(-1,20,-2,AIR)
Block(-1,20,-1,AIR)
Block(-1,20,0,AIR)
Block(-1,20,1,AIR)
Block(-1,20,2,AIR)
Block(-1,20,3,AIR)
Block(-1,20,4,AIR)
Block(-1,20,5,134:2)
Block(-1,20,6,5:1)
Block(-1,20,7,AIR)
Block(-1,20,8,AIR)
Block(-1,21,-2,AIR)
Block(-1,21,-1,AIR)
Block(-1,21,0,AIR)
Block(-1,21,1,AIR)
Block(-1,21,2,AIR)
Block(-1,21,3,AIR)
Block(-1,21,4,AIR)
Block(-1,21,5,134:6)
Block(-1,21,6,134)
Block(-1,21,7,AIR)
Block(-1,21,8,AIR)
Block(-1,22,-2,AIR)
Block(-1,22,-1,AIR)
Block(-1,22,0,AIR)
Block(-1,22,1,AIR)
Block(-1,22,2,AIR)
Block(-1,22,3,AIR)
Block(-1,22,4,AIR)
Block(-1,22,5,17:5)
Block(-1,22,6,5:1)
Block(-1,22,7,5:1)
Block(-1,22,8,5:1)
Block(-1,23,-2,AIR)
Block(-1,23,-1,AIR)
Block(-1,23,0,AIR)
Block(-1,23,1,AIR)
Block(-1,23,2,AIR)
Block(-1,23,3,AIR)
Block(-1,23,4,126:13)
Block(-1,23,5,159:13)
Block(-1,23,6,AIR)
Block(-1,23,7,AIR)
Block(-1,23,8,AIR)
Block(-1,24,4,5:5)
Block(-1,24,6,159:13)
Block(-1,24,7,AIR)
Block(-1,24,8,AIR)
Block(-1,25,7,159:13)
Block(-1,25,8,AIR)
Block(-1,26,7,AIR)
Block(-1,26,8,159:13)
Block(0,13,5,17:5)
Block(0,13,6,5:1)
Block(0,13,7,5:1)
Block(0,13,8,5:1)
Block(0,14,-2,AIR)
Block(0,14,-1,AIR)
Block(0,14,0,AIR)
Block(0,14,1,AIR)
Block(0,14,2,AIR)
Block(0,14,3,AIR)
Block(0,14,4,AIR)
Block(0,14,5,134:6)
Block(0,14,6,134:7)
Block(0,14,7,AIR)
Block(0,14,8,AIR)
Block(0,15,-2,AIR)
Block(0,15,-1,AIR)
Block(0,15,0,AIR)
Block(0,15,1,AIR)
Block(0,15,2,AIR)
Block(0,15,3,AIR)
Block(0,15,4,AIR)
Block(0,15,5,AIR)
Block(0,15,6,160:9)
Block(0,15,7,AIR)
Block(0,15,8,AIR)
Block(0,16,-2,AIR)
Block(0,16,-1,AIR)
Block(0,16,0,AIR)
Block(0,16,1,AIR)
Block(0,16,2,AIR)
Block(0,16,3,AIR)
Block(0,16,4,AIR)
Block(0,16,5,134:6)
Block(0,16,6,134)
Block(0,16,7,AIR)
Block(0,16,8,AIR)
Block(0,17,-2,AIR)
Block(0,17,-1,AIR)
Block(0,17,0,AIR)
Block(0,17,1,AIR)
Block(0,17,2,AIR)
Block(0,17,3,AIR)
Block(0,17,4,AIR)
Block(0,17,5,134:6)
Block(0,17,6,AIR)
Block(0,17,7,AIR)
Block(0,17,8,126:9)
Block(0,18,-2,AIR)
Block(0,18,-1,AIR)
Block(0,18,0,AIR)
Block(0,18,1,AIR)
Block(0,18,2,AIR)
Block(0,18,3,AIR)
Block(0,18,4,AIR)
Block(0,18,5,17:5)
Block(0,18,6,5:1)
Block(0,18,7,5:1)
Block(0,18,8,5:1)
Block(0,19,-2,AIR)
Block(0,19,-1,159:13)
Block(0,19,0,159:13)
Block(0,19,1,159:13)
Block(0,19,2,159:13)
Block(0,19,3,159:13)
Block(0,19,4,159:13)
Block(0,19,5,5:1)
Block(0,19,6,134:7)
Block(0,19,7,AIR)
Block(0,19,8,AIR)
Block(0,20,-2,AIR)
Block(0,20,-1,AIR)
Block(0,20,0,AIR)
Block(0,20,1,AIR)
Block(0,20,2,AIR)
Block(0,20,3,AIR)
Block(0,20,4,AIR)
Block(0,20,5,AIR)
Block(0,20,6,160:9)
Block(0,20,7,AIR)
Block(0,20,8,AIR)
Block(0,21,-2,AIR)
Block(0,21,-1,AIR)
Block(0,21,0,AIR)
Block(0,21,1,AIR)
Block(0,21,2,AIR)
Block(0,21,3,AIR)
Block(0,21,4,AIR)
Block(0,21,5,134:6)
Block(0,21,6,134)
Block(0,21,7,AIR)
Block(0,21,8,AIR)
Block(0,22,-2,AIR)
Block(0,22,-1,AIR)
Block(0,22,0,AIR)
Block(0,22,1,AIR)
Block(0,22,2,AIR)
Block(0,22,3,AIR)
Block(0,22,4,AIR)
Block(0,22,5,17:5)
Block(0,22,6,5:1)
Block(0,22,7,5:1)
Block(0,22,8,5:1)
Block(0,23,-2,AIR)
Block(0,23,-1,AIR)
Block(0,23,0,AIR)
Block(0,23,1,AIR)
Block(0,23,2,AIR)
Block(0,23,3,AIR)
Block(0,23,4,126:13)
Block(0,23,5,159:13)
Block(0,23,6,AIR)
Block(0,23,7,AIR)
Block(0,23,8,AIR)
Block(0,24,4,5:5)
Block(0,24,6,159:13)
Block(0,24,7,AIR)
Block(0,24,8,AIR)
Block(0,25,7,159:13)
Block(0,25,8,AIR)
Block(0,26,7,AIR)
Block(0,26,8,159:13)
Block(0,27,8,191)
Block(0,28,8,191)
Block(0,29,8,191)
Block(0,30,8,35:15)
Block(0,31,8,191)
Block(1,0,-1,17:1)
Block(1,1,-1,17:1)
Block(1,2,-1,17:1)
Block(1,3,-1,17:1)
Block(1,4,-1,17:1)
Block(1,5,-1,17:1)
Block(1,6,-1,17:1)
Block(1,7,-1,17:1)
Block(1,8,-1,17:1)
Block(1,9,-1,17:1)
Block(1,10,-1,17:1)
Block(1,11,-1,17:1)
Block(1,12,-1,17:1)
Block(1,13,-1,17:1)
Block(1,13,5,17:5)
Block(1,13,6,5:1)
Block(1,13,7,5:1)
Block(1,13,8,5:1)
Block(1,14,-2,AIR)
Block(1,14,-1,17:1)
Block(1,14,0,AIR)
Block(1,14,1,AIR)
Block(1,14,2,AIR)
Block(1,14,3,AIR)
Block(1,14,4,AIR)
Block(1,14,5,134:6)
Block(1,14,6,134:7)
Block(1,14,7,AIR)
Block(1,14,8,AIR)
Block(1,15,-2,AIR)
Block(1,15,-1,17:1)
Block(1,15,0,AIR)
Block(1,15,1,AIR)
Block(1,15,2,AIR)
Block(1,15,3,AIR)
Block(1,15,4,AIR)
Block(1,15,5,134:2)
Block(1,15,6,5:1)
Block(1,15,7,AIR)
Block(1,15,8,AIR)
Block(1,16,-2,AIR)
Block(1,16,-1,17:1)
Block(1,16,0,AIR)
Block(1,16,1,AIR)
Block(1,16,2,AIR)
Block(1,16,3,AIR)
Block(1,16,4,AIR)
Block(1,16,5,134:6)
Block(1,16,6,134)
Block(1,16,7,AIR)
Block(1,16,8,AIR)
Block(1,17,-2,AIR)
Block(1,17,-1,17:1)
Block(1,17,0,AIR)
Block(1,17,1,AIR)
Block(1,17,2,AIR)
Block(1,17,3,AIR)
Block(1,17,4,AIR)
Block(1,17,5,134:6)
Block(1,17,6,126:9)
Block(1,17,7,126:9)
Block(1,17,8,126:9)
Block(1,18,-2,AIR)
Block(1,18,-1,17:1)
Block(1,18,0,AIR)
Block(1,18,1,AIR)
Block(1,18,2,AIR)
Block(1,18,3,AIR)
Block(1,18,4,AIR)
Block(1,18,5,17:5)
Block(1,18,6,5:1)
Block(1,18,7,5:1)
Block(1,18,8,5:1)
Block(1,19,-3,159:13)
Block(1,19,-2,159:13)
Block(1,19,-1,159:13)
Block(1,19,0,159:13)
Block(1,19,1,159:13)
Block(1,19,2,159:13)
Block(1,19,3,159:13)
Block(1,19,4,159:13)
Block(1,19,5,5:1)
Block(1,19,6,134:7)
Block(1,19,7,171:8)
Block(1,19,8,171:8)
Block(1,20,-2,AIR)
Block(1,20,-1,AIR)
Block(1,20,0,159:13)
Block(1,20,1,159:13)
Block(1,20,2,159:13)
Block(1,20,3,159:13)
Block(1,20,4,159:13)
Block(1,20,5,134:2)
Block(1,20,6,5:1)
Block(1,20,7,AIR)
Block(1,20,8,AIR)
Block(1,21,-2,AIR)
Block(1,21,-1,AIR)
Block(1,21,0,AIR)
Block(1,21,1,AIR)
Block(1,21,2,AIR)
Block(1,21,3,AIR)
Block(1,21,4,AIR)
Block(1,21,5,134:6)
Block(1,21,6,134)
Block(1,21,7,AIR)
Block(1,21,8,AIR)
Block(1,22,-2,AIR)
Block(1,22,-1,AIR)
Block(1,22,0,AIR)
Block(1,22,1,AIR)
Block(1,22,2,AIR)
Block(1,22,3,AIR)
Block(1,22,4,AIR)
Block(1,22,5,17:5)
Block(1,22,6,5:1)
Block(1,22,7,5:1)
Block(1,22,8,5:1)
Block(1,23,-2,AIR)
Block(1,23,-1,AIR)
Block(1,23,0,AIR)
Block(1,23,1,AIR)
Block(1,23,2,AIR)
Block(1,23,3,AIR)
Block(1,23,4,5:5)
Block(1,23,5,159:13)
Block(1,23,6,AIR)
Block(1,23,7,AIR)
Block(1,23,8,AIR)
Block(1,24,4,126:5)
Block(1,24,6,159:13)
Block(1,24,7,AIR)
Block(1,24,8,AIR)
Block(1,25,7,159:13)
Block(1,25,8,159:13)
Block(1,26,7,AIR)
Block(1,26,8,159:13)
Block(2,0,-5,17:1)
Block(2,0,5,17:1)
Block(2,1,-5,17:1)
Block(2,1,5,17:1)
Block(2,2,-5,17:1)
Block(2,2,5,17:1)
Block(2,3,-5,17:1)
Block(2,3,5,17:1)
Block(2,4,-5,17:1)
Block(2,4,5,17:1)
Block(2,5,-5,17:1)
Block(2,5,5,17:1)
Block(2,6,-5,17:1)
Block(2,6,5,17:1)
Block(2,7,-5,17:1)
Block(2,7,5,17:1)
Block(2,8,-5,17:1)
Block(2,8,5,17:1)
Block(2,9,-5,17:1)
Block(2,9,5,17:1)
Block(2,10,-5,17:1)
Block(2,10,5,17:1)
Block(2,11,-5,17:1)
Block(2,11,5,17:1)
Block(2,12,-5,17:1)
Block(2,12,5,17:1)
Block(2,13,-6,17:9)
Block(2,13,-5,17:9)
Block(2,13,-4,17:9)
Block(2,13,-3,17:9)
Block(2,13,-2,17:9)
Block(2,13,-1,17:9)
Block(2,13,0,17:9)
Block(2,13,1,17:9)
Block(2,13,2,17:9)
Block(2,13,3,17:9)
Block(2,13,4,17:9)
Block(2,13,5,17:5)
Block(2,13,6,5:1)
Block(2,13,7,5:1)
Block(2,13,8,5:1)
Block(2,14,-2,AIR)
Block(2,14,-1,AIR)
Block(2,14,0,AIR)
Block(2,14,1,AIR)
Block(2,14,2,AIR)
Block(2,14,3,AIR)
Block(2,14,4,AIR)
Block(2,14,5,17:1)
Block(2,14,6,AIR)
Block(2,14,7,AIR)
Block(2,14,8,AIR)
Block(2,15,-2,AIR)
Block(2,15,-1,AIR)
Block(2,15,0,AIR)
Block(2,15,1,AIR)
Block(2,15,2,AIR)
Block(2,15,3,AIR)
Block(2,15,4,AIR)
Block(2,15,5,17:1)
Block(2,15,6,AIR)
Block(2,15,7,AIR)
Block(2,15,8,AIR)
Block(2,16,-2,AIR)
Block(2,16,-1,AIR)
Block(2,16,0,AIR)
Block(2,16,1,AIR)
Block(2,16,2,AIR)
Block(2,16,3,AIR)
Block(2,16,4,AIR)
Block(2,16,5,17:1)
Block(2,16,6,AIR)
Block(2,16,7,AIR)
Block(2,16,8,AIR)
Block(2,17,-2,AIR)
Block(2,17,-1,AIR)
Block(2,17,0,AIR)
Block(2,17,1,AIR)
Block(2,17,2,AIR)
Block(2,17,3,AIR)
Block(2,17,4,AIR)
Block(2,17,5,17:1)
Block(2,17,6,AIR)
Block(2,17,7,AIR)
Block(2,17,8,AIR)
Block(2,18,-2,AIR)
Block(2,18,-1,AIR)
Block(2,18,0,AIR)
Block(2,18,1,AIR)
Block(2,18,2,AIR)
Block(2,18,3,AIR)
Block(2,18,4,AIR)
Block(2,18,5,17:1)
Block(2,18,6,5:1)
Block(2,18,7,5:1)
Block(2,18,8,5:1)
Block(2,19,-2,AIR)
Block(2,19,-1,17:5)
Block(2,19,0,AIR)
Block(2,19,1,AIR)
Block(2,19,2,AIR)
Block(2,19,3,AIR)
Block(2,19,4,AIR)
Block(2,19,5,17:1)
Block(2,19,6,191)
Block(2,19,7,171:8)
Block(2,19,8,171:7)
Block(2,20,-4,159:13)
Block(2,20,-3,159:13)
Block(2,20,-2,159:13)
Block(2,20,-1,159:13)
Block(2,20,0,159:13)
Block(2,20,1,159:13)
Block(2,20,2,159:13)
Block(2,20,3,159:13)
Block(2,20,4,159:13)
Block(2,20,5,17:1)
Block(2,20,6,191)
Block(2,20,7,AIR)
Block(2,20,8,133)
Block(2,21,-2,AIR)
Block(2,21,-1,AIR)
Block(2,21,0,AIR)
Block(2,21,1,AIR)
Block(2,21,2,AIR)
Block(2,21,3,AIR)
Block(2,21,4,AIR)
Block(2,21,5,17:1)
Block(2,21,6,56)
Block(2,21,7,AIR)
Block(2,21,8,AIR)
Block(2,22,-2,AIR)
Block(2,22,-1,AIR)
Block(2,22,0,AIR)
Block(2,22,1,AIR)
Block(2,22,2,AIR)
Block(2,22,3,AIR)
Block(2,22,4,AIR)
Block(2,22,5,17:5)
Block(2,22,6,5:1)
Block(2,22,7,5:1)
Block(2,22,8,5:1)
Block(2,23,-2,AIR)
Block(2,23,-1,AIR)
Block(2,23,0,AIR)
Block(2,23,1,AIR)
Block(2,23,2,AIR)
Block(2,23,3,AIR)
Block(2,23,4,5:5)
Block(2,23,5,159:13)
Block(2,23,6,AIR)
Block(2,23,7,AIR)
Block(2,23,8,AIR)
Block(2,24,4,126:5)
Block(2,24,6,159:13)
Block(2,24,7,159:13)
Block(2,24,8,AIR)
Block(2,25,7,AIR)
Block(2,25,8,159:13)
Block(2,26,7,AIR)
Block(2,26,8,159:13)
Block(3,13,5,17:5)
Block(3,13,6,5:1)
Block(3,13,7,5:1)
Block(3,13,8,5:1)
Block(3,14,-4,53:4)
Block(3,14,-3,53:4)
Block(3,14,-2,53:4)
Block(3,14,-1,53:4)
Block(3,14,0,53:4)
Block(3,14,1,53:4)
Block(3,14,2,53:4)
Block(3,14,3,53:4)
Block(3,14,4,53:4)
Block(3,14,5,53:4)
Block(3,14,6,53:4)
Block(3,14,7,AIR)
Block(3,14,8,AIR)
Block(3,15,-4,126)
Block(3,15,-3,126)
Block(3,15,-2,126)
Block(3,15,-1,126)
Block(3,15,0,126)
Block(3,15,1,126)
Block(3,15,2,126)
Block(3,15,3,126)
Block(3,15,4,126)
Block(3,15,5,126)
Block(3,15,6,126)
Block(3,15,7,AIR)
Block(3,15,8,AIR)
Block(3,16,-2,AIR)
Block(3,16,-1,AIR)
Block(3,16,0,AIR)
Block(3,16,1,AIR)
Block(3,16,2,AIR)
Block(3,16,3,AIR)
Block(3,16,4,AIR)
Block(3,16,5,AIR)
Block(3,16,6,AIR)
Block(3,16,7,AIR)
Block(3,16,8,AIR)
Block(3,17,-2,AIR)
Block(3,17,-1,AIR)
Block(3,17,0,AIR)
Block(3,17,1,67:4)
Block(3,17,2,AIR)
Block(3,17,3,AIR)
Block(3,17,4,AIR)
Block(3,17,5,AIR)
Block(3,17,6,AIR)
Block(3,17,7,AIR)
Block(3,17,8,AIR)
Block(3,18,-2,AIR)
Block(3,18,-1,AIR)
Block(3,18,0,AIR)
Block(3,18,1,33)
Block(3,18,2,AIR)
Block(3,18,3,AIR)
Block(3,18,4,AIR)
Block(3,18,5,AIR)
Block(3,18,6,5:1)
Block(3,18,7,5:1)
Block(3,18,8,5:1)
Block(3,19,-2,AIR)
Block(3,19,-1,17:5)
Block(3,19,0,AIR)
Block(3,19,1,101)
Block(3,19,2,AIR)
Block(3,19,3,AIR)
Block(3,19,4,AIR)
Block(3,19,5,17:5)
Block(3,19,6,136:7)
Block(3,19,7,171:8)
Block(3,19,8,171:7)
Block(3,20,-2,AIR)
Block(3,20,-1,5:1)
Block(3,20,0,AIR)
Block(3,20,1,101)
Block(3,20,2,AIR)
Block(3,20,3,AIR)
Block(3,20,4,AIR)
Block(3,20,5,5:1)
Block(3,20,6,140)
Block(3,20,7,AIR)
Block(3,20,8,AIR)
Block(3,21,-5,159:13)
Block(3,21,-4,159:13)
Block(3,21,-3,159:13)
Block(3,21,-2,159:13)
Block(3,21,-1,159:13)
Block(3,21,0,159:13)
Block(3,21,1,159:13)
Block(3,21,2,159:13)
Block(3,21,3,159:13)
Block(3,21,4,159:13)
Block(3,21,5,5:1)
Block(3,21,6,AIR)
Block(3,21,7,AIR)
Block(3,21,8,AIR)
Block(3,22,-2,AIR)
Block(3,22,-1,AIR)
Block(3,22,0,AIR)
Block(3,22,1,AIR)
Block(3,22,2,AIR)
Block(3,22,3,AIR)
Block(3,22,4,AIR)
Block(3,22,5,17:5)
Block(3,22,6,5:1)
Block(3,22,7,5:1)
Block(3,22,8,5:1)
Block(3,23,-2,AIR)
Block(3,23,-1,AIR)
Block(3,23,0,AIR)
Block(3,23,1,AIR)
Block(3,23,2,AIR)
Block(3,23,3,AIR)
Block(3,23,4,5:5)
Block(3,23,5,159:13)
Block(3,23,6,159:13)
Block(3,23,7,AIR)
Block(3,23,8,AIR)
Block(3,24,4,126:5)
Block(3,24,7,159:13)
Block(3,24,8,AIR)
Block(3,25,7,AIR)
Block(3,25,8,159:13)
Block(3,26,7,AIR)
Block(3,26,8,AIR)
Block(4,13,5,17:5)
Block(4,13,6,5:1)
Block(4,13,7,5:1)
Block(4,13,8,5:1)
Block(4,14,-4,5)
Block(4,14,-3,5)
Block(4,14,-2,5)
Block(4,14,-1,5)
Block(4,14,0,5)
Block(4,14,1,5)
Block(4,14,2,5)
Block(4,14,3,5)
Block(4,14,4,5)
Block(4,14,5,5)
Block(4,14,6,5)
Block(4,14,7,AIR)
Block(4,14,8,AIR)
Block(4,15,-2,AIR)
Block(4,15,-1,17:11)
Block(4,15,0,17:11)
Block(4,15,1,17:11)
Block(4,15,2,17:11)
Block(4,15,3,17:11)
Block(4,15,4,AIR)
Block(4,15,5,AIR)
Block(4,15,6,AIR)
Block(4,15,7,AIR)
Block(4,15,8,AIR)
Block(4,16,-2,AIR)
Block(4,16,-1,AIR)
Block(4,16,0,109:7)
Block(4,16,1,109:6)
Block(4,16,2,109)
Block(4,16,3,AIR)
Block(4,16,4,AIR)
Block(4,16,5,AIR)
Block(4,16,6,AIR)
Block(4,16,7,AIR)
Block(4,16,8,AIR)
Block(4,17,-2,AIR)
Block(4,17,-1,AIR)
Block(4,17,0,109:6)
Block(4,17,1,98:2)
Block(4,17,2,109:7)
Block(4,17,3,AIR)
Block(4,17,4,AIR)
Block(4,17,5,AIR)
Block(4,17,6,AIR)
Block(4,17,7,AIR)
Block(4,17,8,AIR)
Block(4,18,-2,AIR)
Block(4,18,-1,AIR)
Block(4,18,0,109)
Block(4,18,1,109:2)
Block(4,18,2,109:7)
Block(4,18,3,AIR)
Block(4,18,4,AIR)
Block(4,18,5,AIR)
Block(4,18,6,5:1)
Block(4,18,7,5:1)
Block(4,18,8,5:1)
Block(4,19,-2,AIR)
Block(4,19,-1,17:5)
Block(4,19,0,AIR)
Block(4,19,1,AIR)
Block(4,19,2,AIR)
Block(4,19,3,AIR)
Block(4,19,4,AIR)
Block(4,19,5,17:5)
Block(4,19,6,126:11)
Block(4,19,7,171:8)
Block(4,19,8,171:7)
Block(4,20,-2,AIR)
Block(4,20,-1,5:1)
Block(4,20,0,AIR)
Block(4,20,1,101)
Block(4,20,2,AIR)
Block(4,20,3,AIR)
Block(4,20,4,AIR)
Block(4,20,5,5:1)
Block(4,20,6,144:1)
Block(4,20,7,AIR)
Block(4,20,8,AIR)
Block(4,21,-2,AIR)
Block(4,21,-1,5:1)
Block(4,21,0,101)
Block(4,21,1,101)
Block(4,21,2,101)
Block(4,21,3,101)
Block(4,21,4,101)
Block(4,21,5,5:1)
Block(4,21,6,AIR)
Block(4,21,7,AIR)
Block(4,21,8,AIR)
Block(4,22,-6,164:6)
Block(4,22,-5,5:5)
Block(4,22,-4,5:5)
Block(4,22,-3,5:5)
Block(4,22,-2,5:5)
Block(4,22,-1,5:5)
Block(4,22,0,5:5)
Block(4,22,1,5:5)
Block(4,22,2,5:5)
Block(4,22,3,5:5)
Block(4,22,4,5:5)
Block(4,22,5,17:5)
Block(4,22,6,5:1)
Block(4,22,7,5:1)
Block(4,22,8,5:1)
Block(4,23,-6,5:5)
Block(4,23,-5,5:5)
Block(4,23,-4,5:5)
Block(4,23,-3,126:5)
Block(4,23,-2,126:5)
Block(4,23,-1,126:5)
Block(4,23,0,126:5)
Block(4,23,1,AIR)
Block(4,23,2,AIR)
Block(4,23,3,AIR)
Block(4,23,4,125:5)
Block(4,23,5,126:5)
Block(4,23,6,159:13)
Block(4,23,7,AIR)
Block(4,23,8,AIR)
Block(4,24,-6,164:2)
Block(4,24,-5,164:7)
Block(4,24,7,159:13)
Block(4,24,8,AIR)
Block(4,25,7,AIR)
Block(4,25,8,159:13)
Block(4,26,7,AIR)
Block(4,26,8,AIR)
Block(5,13,5,17:5)
Block(5,13,6,5:1)
Block(5,13,7,5:1)
Block(5,13,8,5:1)
Block(5,14,-4,53:5)
Block(5,14,-3,53:5)
Block(5,14,-2,53:5)
Block(5,14,-1,53:5)
Block(5,14,0,53:5)
Block(5,14,1,53:5)
Block(5,14,2,53:5)
Block(5,14,3,53:5)
Block(5,14,4,53:5)
Block(5,14,5,53:5)
Block(5,14,6,53:5)
Block(5,14,7,AIR)
Block(5,14,8,AIR)
Block(5,15,-4,126)
Block(5,15,-3,126)
Block(5,15,-2,126)
Block(5,15,-1,126)
Block(5,15,0,126)
Block(5,15,1,126)
Block(5,15,2,126)
Block(5,15,3,126)
Block(5,15,4,126)
Block(5,15,5,126)
Block(5,15,6,126)
Block(5,15,7,AIR)
Block(5,15,8,AIR)
Block(5,16,-2,AIR)
Block(5,16,-1,AIR)
Block(5,16,0,AIR)
Block(5,16,1,AIR)
Block(5,16,2,AIR)
Block(5,16,3,AIR)
Block(5,16,4,AIR)
Block(5,16,5,AIR)
Block(5,16,6,AIR)
Block(5,16,7,AIR)
Block(5,16,8,AIR)
Block(5,17,-2,AIR)
Block(5,17,-1,AIR)
Block(5,17,0,AIR)
Block(5,17,1,67:5)
Block(5,17,2,AIR)
Block(5,17,3,AIR)
Block(5,17,4,AIR)
Block(5,17,5,AIR)
Block(5,17,6,AIR)
Block(5,17,7,AIR)
Block(5,17,8,AIR)
Block(5,18,-2,AIR)
Block(5,18,-1,AIR)
Block(5,18,0,AIR)
Block(5,18,1,33)
Block(5,18,2,AIR)
Block(5,18,3,AIR)
Block(5,18,4,AIR)
Block(5,18,5,AIR)
Block(5,18,6,5:1)
Block(5,18,7,5:1)
Block(5,18,8,5:1)
Block(5,19,-2,AIR)
Block(5,19,-1,17:5)
Block(5,19,0,AIR)
Block(5,19,1,101)
Block(5,19,2,AIR)
Block(5,19,3,AIR)
Block(5,19,4,AIR)
Block(5,19,5,17:5)
Block(5,19,6,136:7)
Block(5,19,7,171:8)
Block(5,19,8,171:8)
Block(5,20,-2,AIR)
Block(5,20,-1,5:1)
Block(5,20,0,AIR)
Block(5,20,1,101)
Block(5,20,2,AIR)
Block(5,20,3,AIR)
Block(5,20,4,AIR)
Block(5,20,5,5:1)
Block(5,20,6,140)
Block(5,20,7,AIR)
Block(5,20,8,AIR)
Block(5,21,-5,159:13)
Block(5,21,-4,159:13)
Block(5,21,-3,159:13)
Block(5,21,-2,159:13)
Block(5,21,-1,159:13)
Block(5,21,0,159:13)
Block(5,21,1,159:13)
Block(5,21,2,159:13)
Block(5,21,3,159:13)
Block(5,21,4,159:13)
Block(5,21,5,5:1)
Block(5,21,6,AIR)
Block(5,21,7,AIR)
Block(5,21,8,AIR)
Block(5,22,-2,AIR)
Block(5,22,-1,AIR)
Block(5,22,0,AIR)
Block(5,22,1,AIR)
Block(5,22,2,AIR)
Block(5,22,3,AIR)
Block(5,22,4,AIR)
Block(5,22,5,17:5)
Block(5,22,6,5:1)
Block(5,22,7,5:1)
Block(5,22,8,5:1)
Block(5,23,-2,AIR)
Block(5,23,-1,AIR)
Block(5,23,0,AIR)
Block(5,23,1,AIR)
Block(5,23,2,AIR)
Block(5,23,3,AIR)
Block(5,23,4,5:5)
Block(5,23,5,159:13)
Block(5,23,6,159:13)
Block(5,23,7,AIR)
Block(5,23,8,AIR)
Block(5,24,4,126:5)
Block(5,24,7,159:13)
Block(5,24,8,AIR)
Block(5,25,7,AIR)
Block(5,25,8,159:13)
Block(5,26,7,AIR)
Block(5,26,8,AIR)
Block(6,0,-5,17:1)
Block(6,1,-5,17:1)
Block(6,2,-5,17:1)
Block(6,3,-5,17:1)
Block(6,4,-5,17:1)
Block(6,5,-5,17:1)
Block(6,6,-5,17:1)
Block(6,7,-5,17:1)
Block(6,8,-5,17:1)
Block(6,9,-5,17:1)
Block(6,10,-5,17:1)
Block(6,11,-5,17:1)
Block(6,12,-5,17:1)
Block(6,13,-6,17:9)
Block(6,13,-5,17:9)
Block(6,13,-4,17:9)
Block(6,13,-3,17:9)
Block(6,13,-2,17:9)
Block(6,13,-1,17:9)
Block(6,13,0,17:9)
Block(6,13,1,17:9)
Block(6,13,2,17:9)
Block(6,13,3,17:9)
Block(6,13,4,17:9)
Block(6,13,5,17:5)
Block(6,13,6,5:1)
Block(6,13,7,5:1)
Block(6,13,8,5:1)
Block(6,14,-2,AIR)
Block(6,14,-1,AIR)
Block(6,14,0,17:7)
Block(6,14,1,17:7)
Block(6,14,2,17:7)
Block(6,14,3,AIR)
Block(6,14,4,AIR)
Block(6,14,5,17:1)
Block(6,14,6,AIR)
Block(6,14,7,AIR)
Block(6,14,8,5:3)
Block(6,15,-2,AIR)
Block(6,15,-1,AIR)
Block(6,15,0,AIR)
Block(6,15,1,17:7)
Block(6,15,2,AIR)
Block(6,15,3,AIR)
Block(6,15,4,AIR)
Block(6,15,5,17:1)
Block(6,15,6,AIR)
Block(6,15,7,AIR)
Block(6,15,8,AIR)
Block(6,16,-2,AIR)
Block(6,16,-1,AIR)
Block(6,16,0,AIR)
Block(6,16,1,AIR)
Block(6,16,2,AIR)
Block(6,16,3,AIR)
Block(6,16,4,AIR)
Block(6,16,5,17:1)
Block(6,16,6,AIR)
Block(6,16,7,AIR)
Block(6,16,8,AIR)
Block(6,17,-2,AIR)
Block(6,17,-1,AIR)
Block(6,17,0,AIR)
Block(6,17,1,AIR)
Block(6,17,2,AIR)
Block(6,17,3,AIR)
Block(6,17,4,134:6)
Block(6,17,5,17:1)
Block(6,17,6,AIR)
Block(6,17,7,AIR)
Block(6,17,8,AIR)
Block(6,18,-2,AIR)
Block(6,18,-1,AIR)
Block(6,18,0,AIR)
Block(6,18,1,AIR)
Block(6,18,2,AIR)
Block(6,18,3,AIR)
Block(6,18,4,91)
Block(6,18,5,17:1)
Block(6,18,6,5:1)
Block(6,18,7,5:1)
Block(6,18,8,5:1)
Block(6,19,-2,AIR)
Block(6,19,-1,17:5)
Block(6,19,0,AIR)
Block(6,19,1,AIR)
Block(6,19,2,AIR)
Block(6,19,3,AIR)
Block(6,19,4,AIR)
Block(6,19,5,17:1)
Block(6,19,6,191)
Block(6,19,7,171:8)
Block(6,19,8,171:7)
Block(6,20,-4,159:13)
Block(6,20,-3,159:13)
Block(6,20,-2,159:13)
Block(6,20,-1,159:13)
Block(6,20,0,159:13)
Block(6,20,1,159:13)
Block(6,20,2,159:13)
Block(6,20,3,159:13)
Block(6,20,4,159:13)
Block(6,20,5,17:1)
Block(6,20,6,191)
Block(6,20,7,AIR)
Block(6,20,8,AIR)
Block(6,21,-2,AIR)
Block(6,21,-1,AIR)
Block(6,21,0,AIR)
Block(6,21,1,AIR)
Block(6,21,2,AIR)
Block(6,21,3,AIR)
Block(6,21,4,AIR)
Block(6,21,5,17:1)
Block(6,21,6,56)
Block(6,21,7,AIR)
Block(6,21,8,AIR)
Block(6,22,-2,AIR)
Block(6,22,-1,AIR)
Block(6,22,0,AIR)
Block(6,22,1,AIR)
Block(6,22,2,AIR)
Block(6,22,3,AIR)
Block(6,22,4,AIR)
Block(6,22,5,17:5)
Block(6,22,6,5:1)
Block(6,22,7,5:1)
Block(6,22,8,5:1)
Block(6,23,-2,AIR)
Block(6,23,-1,AIR)
Block(6,23,0,AIR)
Block(6,23,1,AIR)
Block(6,23,2,AIR)
Block(6,23,3,AIR)
Block(6,23,4,5:5)
Block(6,23,5,159:13)
Block(6,23,6,AIR)
Block(6,23,7,AIR)
Block(6,23,8,AIR)
Block(6,24,4,126:5)
Block(6,24,6,159:13)
Block(6,24,7,159:13)
Block(6,24,8,AIR)
Block(6,25,7,AIR)
Block(6,25,8,159:13)
Block(6,26,7,AIR)
Block(6,26,8,159:13)
Block(7,0,-1,17:1)
Block(7,1,-1,17:1)
Block(7,2,-1,17:1)
Block(7,3,-1,17:1)
Block(7,4,-1,17:1)
Block(7,5,-1,17:1)
Block(7,6,-1,17:1)
Block(7,7,-1,17:1)
Block(7,8,-1,17:1)
Block(7,9,-1,17:1)
Block(7,10,-1,17:1)
Block(7,11,-1,17:1)
Block(7,12,-1,17:1)
Block(7,13,-1,17:1)
Block(7,13,0,126:8)
Block(7,13,1,126:8)
Block(7,13,2,126:8)
Block(7,13,3,126:8)
Block(7,13,4,126:8)
Block(7,13,5,17:5)
Block(7,13,6,5:1)
Block(7,13,7,5:1)
Block(7,13,8,5:1)
Block(7,14,-2,AIR)
Block(7,14,-1,17:1)
Block(7,14,0,54:2)
Block(7,14,1,17:7)
Block(7,14,2,17:7)
Block(7,14,3,AIR)
Block(7,14,4,AIR)
Block(7,14,5,AIR)
Block(7,14,6,AIR)
Block(7,14,7,AIR)
Block(7,14,8,5:3)
Block(7,15,-2,AIR)
Block(7,15,-1,17:1)
Block(7,15,0,AIR)
Block(7,15,1,17:7)
Block(7,15,2,AIR)
Block(7,15,3,AIR)
Block(7,15,4,AIR)
Block(7,15,5,AIR)
Block(7,15,6,AIR)
Block(7,15,7,AIR)
Block(7,15,8,5:3)
Block(7,16,-2,AIR)
Block(7,16,-1,17:1)
Block(7,16,0,AIR)
Block(7,16,1,AIR)
Block(7,16,2,AIR)
Block(7,16,3,AIR)
Block(7,16,4,AIR)
Block(7,16,5,134:6)
Block(7,16,6,134)
Block(7,16,7,AIR)
Block(7,16,8,126:3)
Block(7,17,-2,AIR)
Block(7,17,-1,17:1)
Block(7,17,0,AIR)
Block(7,17,1,AIR)
Block(7,17,2,AIR)
Block(7,17,3,AIR)
Block(7,17,4,AIR)
Block(7,17,5,134:6)
Block(7,17,6,126:9)
Block(7,17,7,126:9)
Block(7,17,8,126:9)
Block(7,18,-2,AIR)
Block(7,18,-1,17:1)
Block(7,18,0,AIR)
Block(7,18,1,AIR)
Block(7,18,2,AIR)
Block(7,18,3,AIR)
Block(7,18,4,AIR)
Block(7,18,5,17:5)
Block(7,18,6,5:1)
Block(7,18,7,5:1)
Block(7,18,8,5:1)
Block(7,19,-3,159:13)
Block(7,19,-2,159:13)
Block(7,19,-1,159:13)
Block(7,19,0,159:13)
Block(7,19,1,159:13)
Block(7,19,2,159:13)
Block(7,19,3,159:13)
Block(7,19,4,159:13)
Block(7,19,5,5:1)
Block(7,19,6,134:7)
Block(7,19,7,171:8)
Block(7,19,8,171:8)
Block(7,20,-2,AIR)
Block(7,20,-1,159:13)
Block(7,20,0,159:13)
Block(7,20,1,159:13)
Block(7,20,2,159:13)
Block(7,20,3,159:13)
Block(7,20,4,159:13)
Block(7,20,5,5:1)
Block(7,20,6,5:1)
Block(7,20,7,AIR)
Block(7,20,8,AIR)
Block(7,21,-2,AIR)
Block(7,21,-1,AIR)
Block(7,21,0,AIR)
Block(7,21,1,AIR)
Block(7,21,2,AIR)
Block(7,21,3,AIR)
Block(7,21,4,AIR)
Block(7,21,5,134:6)
Block(7,21,6,134)
Block(7,21,7,AIR)
Block(7,21,8,AIR)
Block(7,22,-2,AIR)
Block(7,22,-1,AIR)
Block(7,22,0,AIR)
Block(7,22,1,AIR)
Block(7,22,2,AIR)
Block(7,22,3,AIR)
Block(7,22,4,AIR)
Block(7,22,5,17:5)
Block(7,22,6,5:1)
Block(7,22,7,5:1)
Block(7,22,8,5:1)
Block(7,23,-2,AIR)
Block(7,23,-1,AIR)
Block(7,23,0,AIR)
Block(7,23,1,AIR)
Block(7,23,2,AIR)
Block(7,23,3,AIR)
Block(7,23,4,5:5)
Block(7,23,5,159:13)
Block(7,23,6,AIR)
Block(7,23,7,AIR)
Block(7,23,8,AIR)
Block(7,24,4,126:5)
Block(7,24,6,159:13)
Block(7,24,7,AIR)
Block(7,24,8,AIR)
Block(7,25,7,159:13)
Block(7,25,8,159:13)
Block(7,26,7,AIR)
Block(7,26,8,159:13)


#######################################################################
# +-----------------------------------------------------------------+ #
# |                            BO3 checks                           | #
# +-----------------------------------------------------------------+ #
#######################################################################

# Require a condition at a certain location in order for the BO3 to be spawned.
# BlockCheck(x,y,z,BlockName[,BlockName[,...]]) - one of the blocks must be at the location
# BlockCheckNot(x,y,z,BlockName[,BlockName[,...]]) - all the blocks must not be at the location
# LightCheck(x,y,z,minLightLevel,maxLightLevel) - light must be between min and max (inclusive)

# You can use "Solid" as a BlockName for matching all solid blocks or "All" to match all blocks that aren't air.

# Examples:
#   BlockCheck(0,-1,0,GRASS,DIRT,biomesoplenty:grass:0,biomesoplenty:grass:1,biomesoplenty:grass:2,biomesoplenty:grass:3,biomesoplenty:grass:4,biomesoplenty:grass:5,biomesoplenty:grass:6,biomesoplenty:grass:7,biomesoplenty:dirt:0,biomesoplenty:dirt:1,biomesoplenty:dirt:2,biomesoplenty:dirt:3,biomesoplenty:dirt:4,biomesoplenty:dirt:5,biomesoplenty:dirt:6,biomesoplenty:dirt:7,biomesoplenty:dirt:8,biomesoplenty:dirt:9,biomesoplenty:dirt:10,biomesoplenty:dried_sand:0,biomesoplenty:hard_ice:0,biomesoplenty:white_sand:0,biomesoplenty:white_sandstone:0,biomesoplenty:mud:0,biomesoplenty:ash_block:0)  Require grass or dirt just below the object
#   BlockCheck(0,-1,0,Solid)       Require any solid block just below the object
#   BlockCheck(0,-1,0,WOOL)        Require any type of wool just below the object
#   BlockCheck(0,-1,0,WOOL:0)      Require white wool just below the object
#   BlockCheckNot(0,-1,0,WOOL:0)   Require that there is no white wool below the object
#   LightCheck(0,0,0,0,1)          Require almost complete darkness just below the object

#######################################################################
# +-----------------------------------------------------------------+ #
# |                             Branches                            | #
# +-----------------------------------------------------------------+ #
#######################################################################

# Branches are objects that will spawn when this object spawns when it is used in
# the CustomStructure resource. Branches can also have branches, making complex
# structures possible. See the wiki for more details.

# Regular Branches spawn each branch with an independent chance of spawning.
# Branch(x,y,z,branchName,rotation,chance[,anotherBranchName,rotation,chance[,...]][IndividualChance])
# branchName - name of the object to spawn.
# rotation - NORTH, SOUTH, EAST or WEST.
# IndividualChance - The chance each branch has to spawn, assumed to be 100 when left blank

# WeightedBranch(x,y,z,branchName,rotation,chance[,anotherBranchName,rotation,chance[,...]][MaxChanceOutOf])
# MaxChanceOutOf - The chance all branches have to spawn out of, assumed to be 100 when left blank
Branch(16,0,0,Longhouse2C1R0,NORTH,100)
Branch(0,0,16,Longhouse2C0R1,NORTH,100)
