
#######################################################################
# +-----------------------------------------------------------------+ #
# |                            BO3 object                           | #
# +-----------------------------------------------------------------+ #
#######################################################################

# This is the config file of a custom object.
# If you add this object correctly to your BiomeConfigs, it will spawn in the world.

# This is the creator of this BO3 object
Author: LordSmellyPants

# A short description of this BO3 object
Description: No description given

# The BO3 version, don't change this! It can be used by external applications to do a version check.
Version: 3

# The settings mode, WriteAll, WriteWithoutComments or WriteDisable. See WorldConfig.
SettingsMode: WriteDisable


#######################################################################
# +-----------------------------------------------------------------+ #
# |                          Main settings                          | #
# +-----------------------------------------------------------------+ #
#######################################################################

# This needs to be set to true to spawn the object in the Tree and Sapling resources.
Tree: true

# The frequency of the BO3 from 1 to 200. Tries this many times to spawn this BO3 when using the CustomObject(...) resource.
# Ignored by Tree(..), Sapling(..) and CustomStructure(..)
Frequency: 1

# The rarity of the BO3 from 0 to 100. Each spawn attempt has rarity% chance to succeed when using the CustomObject(...) resource.
# Ignored by Tree(..), Sapling(..) and CustomStructure(..)
Rarity: 25.0

# If you set this to true, the BO3 will be placed with a random rotation.
RotateRandomly: true

# The spawn height of the BO3 - atMinY, randomY, highestBlock or highestSolidBlock.
SpawnHeight: randomY

# The offset from the spawn height to spawn this BO3
# Ex. SpawnHeight = highestSolidBlock, SpawnHeightOffset = 3; This object will spawn 3 blocks above the highest solid block
SpawnHeightOffset: 0

# A random amount to offset the spawn location from the spawn offset height
# Ex. SpawnHeightOffset = 3, SpawnHeightVariance = 3; This object will spawn 3 to 6 blocks above the original spot it would have spawned
SpawnHeightVariance: 0

##############################
# Height Limits for the BO3. #
##############################

# When in randomY mode used as the minimum Y or in atMinY mode as the actual Y to spawn this BO3 at.
MinHeight: 0
# When in randomY mode used as the maximum Y to spawn this BO3 at.
MaxHeight: 256


######################
# Extrusion settings #
######################

# The style of extrusion you wish to use - BottomDown, TopUp, None (Default)
ExtrudeMode: None

# The blocks to extrude your BO3 through
ExtrudeThroughBlocks: AIR

# Objects can have other objects attacthed to it: branches. Branches can also
# have branches attached to it, which can also have branches, etc. This is the
# maximum branch depth for this objects.
MaxBranchDepth: 10

# When spawned with the UseWorld keyword, this BO3 should NOT spawn in the following biomes.
# If you write the BO3 name directly in the BiomeConfigs, this will be ignored.
ExcludedBiomes: All


#######################################################################
# +-----------------------------------------------------------------+ #
# |                      Source block settings                      | #
# +-----------------------------------------------------------------+ #
#######################################################################

# The B(s) the BO3 should spawn in.
SourceBlocks: AIR

# The maximum percentage of the BO3 that can be outside the SourceBlock.
# The BO3 won't be placed on a location with more blocks outside the SourceBlock than this percentage.
MaxPercentageOutsideSourceBlock: 100

# What to do when a block is about to be placed outside the SourceBlock? (dontPlace, placeAnyway)
OutsideSourceBlock: placeAnyway


#######################################################################
# +-----------------------------------------------------------------+ #
# |                              Blocks                             | #
# +-----------------------------------------------------------------+ #
#######################################################################

# All the blocks used in the BO3 are listed here. Possible blocks:
# B(x,y,z,id[.data][,nbtfile.nbt)
# RB(x,y,z,id[:data][,nbtfile.nbt],chance[,id[:data][,nbtfile.nbt],chance[,...]])
#  So RB(0,0,0,CHEST,chest.nbt,50,CHEST,anotherchest.nbt,100) will spawn a chest at
#  the BO3 origin, and give it a 50% chance to have the contents of chest.nbt, or, if that
#  fails, a 100% percent chance to have the contents of anotherchest.nbt.
# MinecraftObject(x,y,z,name)
#  Spawns an object in the Mojang NBT structure format. For example, 
#  MinecraftObject(0,0,0,minecraft:igloo/igloo_bottom)
#  spawns the bottom part of an igloo.

B(-8,-31,-7,1)
B(-8,-31,-6,1)
B(-8,-31,-5,1)
B(-8,-31,-4,1)
B(-8,-31,-3,1)
B(-8,-31,-2,1)
B(-8,-31,-1,1)
B(-8,-31,0,1)
B(-8,-31,1,1)
B(-8,-31,2,1)
B(-8,-31,3,1)
B(-8,-31,4,1)
B(-8,-31,5,1)
B(-8,-31,6,1)
B(-8,-31,7,1)
B(-8,-31,8,1)
B(-8,-30,-7,1)
B(-8,-30,-6,1)
B(-8,-30,-5,1)
B(-8,-30,-4,1)
B(-8,-30,-3,1)
B(-8,-30,-2,1)
B(-8,-30,-1,1)
B(-8,-30,0,1)
B(-8,-30,1,1)
B(-8,-30,2,1)
B(-8,-30,3,1)
B(-8,-30,4,1)
B(-8,-30,5,1)
B(-8,-30,6,1)
B(-8,-30,7,1)
B(-8,-30,8,1)
B(-8,-29,-7,1)
B(-8,-29,-6,1)
B(-8,-29,-5,1)
B(-8,-29,-4,1)
B(-8,-29,-3,1)
B(-8,-29,-2,1)
B(-8,-29,-1,1)
B(-8,-29,0,1)
B(-8,-29,1,1)
B(-8,-29,2,1)
B(-8,-29,3,1)
B(-8,-29,4,1)
B(-8,-29,5,1)
B(-8,-29,6,1)
B(-8,-29,7,1)
B(-8,-29,8,1)
B(-8,-28,-7,1)
B(-8,-28,-6,1)
B(-8,-28,-5,1)
B(-8,-28,-4,1)
B(-8,-28,-3,1)
B(-8,-28,-2,1)
B(-8,-28,-1,1)
B(-8,-28,0,1)
B(-8,-28,1,1)
B(-8,-28,2,1)
B(-8,-28,3,1)
B(-8,-28,4,1)
B(-8,-28,5,1)
B(-8,-28,6,1)
B(-8,-28,7,1)
B(-8,-28,8,1)
B(-8,-27,-7,1)
B(-8,-27,-6,1)
B(-8,-27,-5,1)
B(-8,-27,-4,1)
B(-8,-27,-3,1)
B(-8,-27,-2,1)
B(-8,-27,-1,1)
B(-8,-27,0,1)
B(-8,-27,1,1)
B(-8,-27,2,1)
B(-8,-27,3,1)
B(-8,-27,4,1)
B(-8,-27,5,1)
B(-8,-27,6,1)
B(-8,-27,7,1)
B(-8,-27,8,1)
B(-8,-26,-7,1)
B(-8,-26,-6,1)
B(-8,-26,-5,1)
B(-8,-26,-4,1)
B(-8,-26,-3,1)
B(-8,-26,-2,1)
B(-8,-26,-1,1)
B(-8,-26,0,1)
B(-8,-26,1,1)
B(-8,-26,2,1)
B(-8,-26,3,1)
B(-8,-26,4,1)
B(-8,-26,5,1)
B(-8,-26,6,1)
B(-8,-26,7,1)
B(-8,-26,8,1)
B(-8,-25,-7,1)
B(-8,-25,-6,1)
B(-8,-25,-5,1)
B(-8,-25,-4,1)
B(-8,-25,-3,1)
B(-8,-25,-2,1)
B(-8,-25,-1,1)
B(-8,-25,0,1)
B(-8,-25,1,1)
B(-8,-25,2,1)
B(-8,-25,3,1)
B(-8,-25,4,1)
B(-8,-25,5,1)
B(-8,-25,6,1)
B(-8,-25,7,1)
B(-8,-25,8,1)
B(-8,-24,-7,1)
B(-8,-24,-6,1)
B(-8,-24,-5,1)
B(-8,-24,-4,1)
B(-8,-24,-3,1)
B(-8,-24,-2,1)
B(-8,-24,-1,1)
B(-8,-24,0,1)
B(-8,-24,1,1)
B(-8,-24,2,1)
B(-8,-24,3,1)
B(-8,-24,4,1)
B(-8,-24,5,1)
B(-8,-24,6,1)
B(-8,-24,7,1)
B(-8,-24,8,1)
B(-8,-23,-7,1)
B(-8,-23,-6,1)
B(-8,-23,-5,1)
B(-8,-23,-4,1)
B(-8,-23,-3,1)
B(-8,-23,-2,1)
B(-8,-23,-1,1)
B(-8,-23,0,1)
B(-8,-23,1,1)
B(-8,-23,2,1)
B(-8,-23,3,1)
B(-8,-23,4,1)
B(-8,-23,5,1)
B(-8,-23,6,1)
B(-8,-23,7,1)
B(-8,-23,8,1)
B(-8,-22,-7,1)
B(-8,-22,-6,1)
B(-8,-22,-5,1)
B(-8,-22,-4,1)
B(-8,-22,-3,1)
B(-8,-22,-2,1)
B(-8,-22,-1,1)
B(-8,-22,0,1)
B(-8,-22,1,1)
B(-8,-22,2,1)
B(-8,-22,3,1)
B(-8,-22,4,1)
B(-8,-22,5,1)
B(-8,-22,6,1)
B(-8,-22,7,1)
B(-8,-22,8,1)
B(-8,-21,-5,1)
B(-8,-21,-4,1)
B(-8,-21,-3,1)
B(-8,-21,-2,1)
B(-8,-21,-1,1)
B(-8,-21,0,1)
B(-8,-21,1,1)
B(-8,-21,2,1)
B(-8,-21,3,1)
B(-8,-21,4,1)
B(-8,-21,5,1)
B(-8,-21,6,1)
B(-8,-21,7,1)
B(-8,-21,8,1)
B(-8,-20,-6,1)
B(-8,-20,-5,1)
B(-8,-20,-4,1)
B(-8,-20,-3,1)
B(-8,-20,-2,1)
B(-8,-20,-1,1)
B(-8,-20,0,1)
B(-8,-20,1,1)
B(-8,-20,2,1)
B(-8,-20,3,1)
B(-8,-20,4,1)
B(-8,-20,5,1)
B(-8,-20,6,1)
B(-8,-20,7,1)
B(-8,-20,8,1)
B(-8,-19,-6,1)
B(-8,-19,-5,1)
B(-8,-19,-4,1)
B(-8,-19,-3,1)
B(-8,-19,-2,1)
B(-8,-19,-1,1)
B(-8,-19,0,1)
B(-8,-19,1,1)
B(-8,-19,2,1)
B(-8,-19,3,1)
B(-8,-19,4,1)
B(-8,-19,5,1)
B(-8,-19,6,1)
B(-8,-19,7,1)
B(-8,-19,8,1)
B(-8,-18,-7,1)
B(-8,-18,-6,1)
B(-8,-18,-5,1)
B(-8,-18,-4,1)
B(-8,-18,-3,1)
B(-8,-18,-2,1)
B(-8,-18,-1,1)
B(-8,-18,0,1)
B(-8,-18,1,1)
B(-8,-18,2,1)
B(-8,-18,3,1)
B(-8,-18,4,1)
B(-8,-18,5,1)
B(-8,-18,6,1)
B(-8,-18,7,1)
B(-8,-18,8,1)
B(-8,-17,-7,1)
B(-8,-17,-6,1)
B(-8,-17,-5,1)
B(-8,-17,-4,1)
B(-8,-17,-3,1)
B(-8,-17,-2,1)
B(-8,-17,-1,1)
B(-8,-17,0,1)
B(-8,-17,1,1)
B(-8,-17,2,1)
B(-8,-17,3,1)
B(-8,-17,4,1)
B(-8,-17,5,1)
B(-8,-17,6,1)
B(-8,-17,7,1)
B(-8,-17,8,1)
B(-8,-16,-7,1)
B(-8,-16,-6,1)
B(-8,-16,-5,1)
B(-8,-16,-4,1)
B(-8,-16,-3,1)
B(-8,-16,-2,1)
B(-8,-16,-1,1)
B(-8,-16,0,1)
B(-8,-16,1,1)
B(-8,-16,2,1)
B(-8,-16,3,1)
B(-8,-16,4,1)
B(-8,-16,5,1)
B(-8,-16,6,1)
B(-8,-16,7,1)
B(-8,-16,8,1)
B(-8,-15,-7,1)
B(-8,-15,-6,1)
B(-8,-15,-5,1)
B(-8,-15,-4,1)
B(-8,-15,-3,1)
B(-8,-15,-2,1)
B(-8,-15,-1,1)
B(-8,-15,0,1)
B(-8,-15,1,1)
B(-8,-15,2,1)
B(-8,-15,3,1)
B(-8,-15,4,1)
B(-8,-15,5,1)
B(-8,-15,6,1)
B(-8,-15,7,1)
B(-8,-15,8,1)
B(-8,-14,-7,1)
B(-8,-14,-6,1)
B(-8,-14,-5,1)
B(-8,-14,-4,1)
B(-8,-14,-3,1)
B(-8,-14,-2,1)
B(-8,-14,-1,1)
B(-8,-14,0,1)
B(-8,-14,1,1)
B(-8,-14,2,1)
B(-8,-14,3,1)
B(-8,-14,4,1)
B(-8,-14,5,1)
B(-8,-14,6,1)
B(-8,-14,7,1)
B(-8,-14,8,1)
B(-8,-13,-7,1)
B(-8,-13,-6,1)
B(-8,-13,-5,1)
B(-8,-13,-4,1)
B(-8,-13,-3,1)
B(-8,-13,-2,1)
B(-8,-13,-1,1)
B(-8,-13,0,1)
B(-8,-13,1,1)
B(-8,-13,2,1)
B(-8,-13,3,1)
B(-8,-13,4,1)
B(-8,-13,5,1)
B(-8,-13,6,1)
B(-8,-13,7,1)
B(-8,-13,8,1)
B(-8,-12,-7,1)
B(-8,-12,-6,1)
B(-8,-12,-5,1)
B(-8,-12,-4,1)
B(-8,-12,-3,1)
B(-8,-12,-2,1)
B(-8,-12,-1,1)
B(-8,-12,0,1)
B(-8,-12,1,1)
B(-8,-12,2,1)
B(-8,-12,3,1)
B(-8,-12,4,1)
B(-8,-12,5,1)
B(-8,-12,6,1)
B(-8,-12,7,1)
B(-8,-12,8,1)
B(-8,-11,-7,1)
B(-8,-11,-6,1)
B(-8,-11,-5,1)
B(-8,-11,-4,1)
B(-8,-11,-3,1)
B(-8,-11,-2,1)
B(-8,-11,-1,1)
B(-8,-11,0,1)
B(-8,-11,1,1)
B(-8,-11,2,1)
B(-8,-11,3,1)
B(-8,-11,4,1)
B(-8,-11,5,1)
B(-8,-11,6,1)
B(-8,-11,7,1)
B(-8,-11,8,1)
B(-8,-10,-7,1)
B(-8,-10,-6,1)
B(-8,-10,-5,1)
B(-8,-10,-4,1)
B(-8,-10,-3,1)
B(-8,-10,-2,1)
B(-8,-10,-1,1)
B(-8,-10,0,1)
B(-8,-10,1,1)
B(-8,-10,2,1)
B(-8,-10,3,1)
B(-8,-10,4,1)
B(-8,-10,5,1)
B(-8,-10,6,1)
B(-8,-10,7,1)
B(-8,-10,8,1)
B(-8,-9,-7,1)
B(-8,-9,-6,1)
B(-8,-9,-5,1)
B(-8,-9,-4,1)
B(-8,-9,-3,1)
B(-8,-9,-2,1)
B(-8,-9,-1,1)
B(-8,-9,0,1)
B(-8,-9,1,1)
B(-8,-9,2,1)
B(-8,-9,3,1)
B(-8,-9,4,1)
B(-8,-9,5,1)
B(-8,-9,6,1)
B(-8,-9,7,1)
B(-8,-9,8,1)
B(-8,-8,-7,1)
B(-8,-8,-6,1)
B(-8,-8,-5,1)
B(-8,-8,-4,1)
B(-8,-8,-3,1)
B(-8,-8,-2,1)
B(-8,-8,-1,1)
B(-8,-8,0,1)
B(-8,-8,1,1)
B(-8,-8,2,1)
B(-8,-8,3,1)
B(-8,-8,4,1)
B(-8,-8,5,1)
B(-8,-8,6,1)
B(-8,-8,7,1)
B(-8,-8,8,1)
B(-8,-7,-7,1)
B(-8,-7,-6,1)
B(-8,-7,-5,1)
B(-8,-7,-4,1)
B(-8,-7,-3,1)
B(-8,-7,-2,1)
B(-8,-7,-1,1)
B(-8,-7,0,1)
B(-8,-7,1,1)
B(-8,-7,2,1)
B(-8,-7,3,1)
B(-8,-7,4,1)
B(-8,-7,5,1)
B(-8,-7,6,1)
B(-8,-7,7,1)
B(-8,-7,8,1)
B(-8,-6,-6,1)
B(-8,-6,-5,1)
B(-8,-6,-4,1)
B(-8,-6,-3,1)
B(-8,-6,-2,1)
B(-8,-6,-1,1)
B(-8,-6,0,1)
B(-8,-6,1,1)
B(-8,-6,2,1)
B(-8,-6,3,1)
B(-8,-6,4,1)
B(-8,-6,5,1)
B(-8,-6,6,1)
B(-8,-6,7,1)
B(-8,-6,8,1)
B(-8,-5,-6,1)
B(-8,-5,-5,1)
B(-8,-5,-4,1)
B(-8,-5,-3,1)
B(-8,-5,-2,1)
B(-8,-5,-1,1)
B(-8,-5,0,1)
B(-8,-5,1,1)
B(-8,-5,2,1)
B(-8,-5,3,1)
B(-8,-5,4,1)
B(-8,-5,5,1)
B(-8,-5,6,1)
B(-8,-5,7,1)
B(-8,-5,8,1)
B(-8,-4,-5,1)
B(-8,-4,-4,1)
B(-8,-4,-3,1)
B(-8,-4,-2,1)
B(-8,-4,-1,1)
B(-8,-4,0,1)
B(-8,-4,1,1)
B(-8,-4,2,1)
B(-8,-4,3,1)
B(-8,-4,4,1)
B(-8,-4,5,1)
B(-8,-4,6,1)
B(-8,-4,7,1)
B(-8,-4,8,1)
B(-8,-3,-5,1)
B(-8,-3,-4,1)
B(-8,-3,-3,1)
B(-8,-3,-2,1)
B(-8,-3,-1,1)
B(-8,-3,0,1)
B(-8,-3,1,1)
B(-8,-3,2,1)
B(-8,-3,3,1)
B(-8,-3,4,1)
B(-8,-3,5,1)
B(-8,-3,6,1)
B(-8,-3,7,1)
B(-8,-3,8,1)
B(-8,-2,-6,AIR)
B(-8,-2,-5,AIR)
B(-8,-2,-4,1)
B(-8,-2,-3,1)
B(-8,-2,-2,1)
B(-8,-2,-1,1)
B(-8,-2,0,1)
B(-8,-2,1,1)
B(-8,-2,2,1)
B(-8,-2,3,1)
B(-8,-2,4,1)
B(-8,-2,5,1)
B(-8,-2,6,1)
B(-8,-2,7,1)
B(-8,-2,8,1)
B(-8,-1,-6,AIR)
B(-8,-1,-5,AIR)
B(-8,-1,-4,AIR)
B(-8,-1,-3,1)
B(-8,-1,-2,1)
B(-8,-1,-1,1)
B(-8,-1,0,1)
B(-8,-1,1,1)
B(-8,-1,2,1)
B(-8,-1,3,1)
B(-8,-1,4,1)
B(-8,-1,5,1)
B(-8,-1,6,1)
B(-8,-1,7,1)
B(-8,-1,8,1)
B(-8,0,-6,AIR)
B(-8,0,-5,AIR)
B(-8,0,-4,AIR)
B(-8,0,-3,1)
B(-8,0,-2,1)
B(-8,0,-1,98)
B(-8,0,0,98)
B(-8,0,1,AIR)
B(-8,0,2,AIR)
B(-8,0,3,AIR)
B(-8,0,4,AIR)
B(-8,0,5,AIR)
B(-8,0,6,98)
B(-8,0,7,98)
B(-8,0,8,1)
B(-8,1,-6,AIR)
B(-8,1,-5,44:13)
B(-8,1,-4,AIR)
B(-8,1,-3,44:13)
B(-8,1,-2,98)
B(-8,1,-1,98)
B(-8,1,0,98)
B(-8,1,1,AIR)
B(-8,1,2,AIR)
B(-8,1,3,AIR)
B(-8,1,4,AIR)
B(-8,1,5,AIR)
B(-8,1,6,98)
B(-8,1,7,98)
B(-8,1,8,1)
B(-8,2,-6,98)
B(-8,2,-5,98)
B(-8,2,-4,98)
B(-8,2,-3,98)
B(-8,2,-2,98)
B(-8,2,-1,98)
B(-8,2,0,98)
B(-8,2,1,5:5)
B(-8,2,2,98)
B(-8,2,3,98)
B(-8,2,4,98)
B(-8,2,5,5:5)
B(-8,2,6,98)
B(-8,2,7,98)
B(-8,2,8,1)
B(-8,3,-6,98)
B(-8,3,-5,98)
B(-8,3,-4,44:5)
B(-8,3,-3,98)
B(-8,3,-2,98)
B(-8,3,-1,98)
B(-8,3,0,98)
B(-8,3,1,AIR)
B(-8,3,2,AIR)
B(-8,3,3,AIR)
B(-8,3,4,AIR)
B(-8,3,5,AIR)
B(-8,3,6,44:5)
B(-8,3,7,98)
B(-8,3,8,1)
B(-8,4,-6,44)
B(-8,4,-5,44)
B(-8,4,-4,AIR)
B(-8,4,-3,98)
B(-8,4,-2,98)
B(-8,4,-1,98)
B(-8,4,0,98)
B(-8,4,1,AIR)
B(-8,4,2,AIR)
B(-8,4,3,AIR)
B(-8,4,4,AIR)
B(-8,4,5,AIR)
B(-8,4,6,AIR)
B(-8,4,7,98)
B(-8,4,8,1)
B(-8,5,-6,AIR)
B(-8,5,-5,AIR)
B(-8,5,-4,AIR)
B(-8,5,-3,44:5)
B(-8,5,-2,98)
B(-8,5,-1,98)
B(-8,5,0,98)
B(-8,5,1,AIR)
B(-8,5,2,AIR)
B(-8,5,3,AIR)
B(-8,5,4,AIR)
B(-8,5,5,AIR)
B(-8,5,6,AIR)
B(-8,5,7,98)
B(-8,5,8,1)
B(-8,6,-6,AIR)
B(-8,6,-5,AIR)
B(-8,6,-4,AIR)
B(-8,6,-3,AIR)
B(-8,6,-2,AIR)
B(-8,6,-1,98)
B(-8,6,0,98)
B(-8,6,1,AIR)
B(-8,6,2,AIR)
B(-8,6,3,AIR)
B(-8,6,4,AIR)
B(-8,6,5,AIR)
B(-8,6,6,AIR)
B(-8,6,7,98)
B(-8,6,8,1)
B(-8,7,-6,AIR)
B(-8,7,-5,AIR)
B(-8,7,-4,AIR)
B(-8,7,-3,AIR)
B(-8,7,-2,AIR)
B(-8,7,-1,98)
B(-8,7,0,98)
B(-8,7,1,AIR)
B(-8,7,2,AIR)
B(-8,7,3,AIR)
B(-8,7,4,AIR)
B(-8,7,5,AIR)
B(-8,7,6,AIR)
B(-8,7,7,98)
B(-8,7,8,1)
B(-8,8,-6,AIR)
B(-8,8,-5,AIR)
B(-8,8,-4,AIR)
B(-8,8,-3,AIR)
B(-8,8,-2,AIR)
B(-8,8,-1,98)
B(-8,8,0,98)
B(-8,8,1,AIR)
B(-8,8,2,AIR)
B(-8,8,3,AIR)
B(-8,8,4,AIR)
B(-8,8,5,AIR)
B(-8,8,6,AIR)
B(-8,8,7,98)
B(-8,8,8,1)
B(-8,9,-6,AIR)
B(-8,9,-5,AIR)
B(-8,9,-4,AIR)
B(-8,9,-3,AIR)
B(-8,9,-2,AIR)
B(-8,9,-1,98)
B(-8,9,0,98)
B(-8,9,1,AIR)
B(-8,9,2,AIR)
B(-8,9,3,AIR)
B(-8,9,4,AIR)
B(-8,9,5,AIR)
B(-8,9,6,98)
B(-8,9,7,98)
B(-8,9,8,1)
B(-8,10,-6,AIR)
B(-8,10,-5,AIR)
B(-8,10,-4,AIR)
B(-8,10,-3,AIR)
B(-8,10,-2,AIR)
B(-8,10,-1,98)
B(-8,10,0,98)
B(-8,10,1,AIR)
B(-8,10,2,AIR)
B(-8,10,3,AIR)
B(-8,10,4,98)
B(-8,10,5,98)
B(-8,10,6,98)
B(-8,10,7,98)
B(-8,10,8,98)
B(-8,11,-6,AIR)
B(-8,11,-5,AIR)
B(-8,11,-4,AIR)
B(-8,11,-3,AIR)
B(-8,11,-2,98)
B(-8,11,-1,98)
B(-8,11,0,44:5)
B(-8,11,1,98:3)
B(-8,11,2,98)
B(-8,11,3,98)
B(-8,11,4,98)
B(-8,11,5,98)
B(-8,11,6,98)
B(-8,11,7,98)
B(-8,11,8,98)
B(-8,12,-6,AIR)
B(-8,12,-5,AIR)
B(-8,12,-4,AIR)
B(-8,12,-3,AIR)
B(-8,12,-2,44:5)
B(-8,12,-1,98)
B(-8,12,0,AIR)
B(-8,12,1,AIR)
B(-8,12,2,AIR)
B(-8,12,3,AIR)
B(-8,12,4,AIR)
B(-8,12,5,AIR)
B(-8,12,6,47)
B(-8,12,7,98)
B(-8,12,8,44:5)
B(-8,13,-6,AIR)
B(-8,13,-5,AIR)
B(-8,13,-4,AIR)
B(-8,13,-3,AIR)
B(-8,13,-2,AIR)
B(-8,13,-1,98)
B(-8,13,0,AIR)
B(-8,13,1,AIR)
B(-8,13,2,AIR)
B(-8,13,3,AIR)
B(-8,13,4,AIR)
B(-8,13,5,AIR)
B(-8,13,6,126:5)
B(-8,13,7,98)
B(-8,13,8,AIR)
B(-8,14,-6,AIR)
B(-8,14,-5,AIR)
B(-8,14,-4,AIR)
B(-8,14,-3,AIR)
B(-8,14,-2,AIR)
B(-8,14,-1,101)
B(-8,14,0,AIR)
B(-8,14,1,AIR)
B(-8,14,2,AIR)
B(-8,14,3,AIR)
B(-8,14,4,AIR)
B(-8,14,5,AIR)
B(-8,14,6,AIR)
B(-8,14,7,98)
B(-8,14,8,AIR)
B(-8,15,-6,AIR)
B(-8,15,-5,AIR)
B(-8,15,-4,AIR)
B(-8,15,-3,AIR)
B(-8,15,-2,AIR)
B(-8,15,-1,101)
B(-8,15,0,AIR)
B(-8,15,1,AIR)
B(-8,15,2,AIR)
B(-8,15,3,AIR)
B(-8,15,4,AIR)
B(-8,15,5,AIR)
B(-8,15,6,AIR)
B(-8,15,7,159:7)
B(-8,15,8,AIR)
B(-8,16,-6,AIR)
B(-8,16,-5,AIR)
B(-8,16,-4,AIR)
B(-8,16,-3,AIR)
B(-8,16,-2,AIR)
B(-8,16,-1,101)
B(-8,16,0,AIR)
B(-8,16,1,AIR)
B(-8,16,2,AIR)
B(-8,16,3,AIR)
B(-8,16,4,AIR)
B(-8,16,5,AIR)
B(-8,16,6,AIR)
B(-8,16,7,159:7)
B(-8,16,8,AIR)
B(-8,17,-6,AIR)
B(-8,17,-5,AIR)
B(-8,17,-4,AIR)
B(-8,17,-3,AIR)
B(-8,17,-2,44:13)
B(-8,17,-1,98)
B(-8,17,0,AIR)
B(-8,17,1,AIR)
B(-8,17,2,AIR)
B(-8,17,3,AIR)
B(-8,17,4,AIR)
B(-8,17,5,AIR)
B(-8,17,6,AIR)
B(-8,17,7,98)
B(-8,17,8,44:13)
B(-8,18,-6,AIR)
B(-8,18,-5,AIR)
B(-8,18,-4,AIR)
B(-8,18,-3,AIR)
B(-8,18,-2,98)
B(-8,18,-1,98)
B(-8,18,0,98)
B(-8,18,1,AIR)
B(-8,18,2,AIR)
B(-8,18,3,AIR)
B(-8,18,4,AIR)
B(-8,18,5,AIR)
B(-8,18,6,98)
B(-8,18,7,98)
B(-8,18,8,98)
B(-8,19,-6,AIR)
B(-8,19,-5,AIR)
B(-8,19,-4,AIR)
B(-8,19,-3,AIR)
B(-8,19,-2,44:5)
B(-8,19,-1,AIR)
B(-8,19,0,98)
B(-8,19,1,98)
B(-8,19,2,98)
B(-8,19,3,98)
B(-8,19,4,98)
B(-8,19,5,98)
B(-8,19,6,98)
B(-8,19,7,AIR)
B(-8,19,8,44:5)
B(-8,20,-6,AIR)
B(-8,20,-5,AIR)
B(-8,20,-4,AIR)
B(-8,20,-3,AIR)
B(-8,20,-2,AIR)
B(-8,20,-1,AIR)
B(-8,20,0,98)
B(-8,20,1,98)
B(-8,20,2,98)
B(-8,20,3,98:3)
B(-8,20,4,98)
B(-8,20,5,98)
B(-8,20,6,98)
B(-8,20,7,AIR)
B(-8,20,8,AIR)
B(-8,21,-6,AIR)
B(-8,21,-5,AIR)
B(-8,21,-4,AIR)
B(-8,21,-3,AIR)
B(-8,21,-2,AIR)
B(-8,21,-1,AIR)
B(-8,21,0,44)
B(-8,21,1,98)
B(-8,21,2,159:7)
B(-8,21,3,159:7)
B(-8,21,4,159:7)
B(-8,21,5,98)
B(-8,21,6,44)
B(-8,21,7,AIR)
B(-8,21,8,AIR)
B(-8,22,-6,AIR)
B(-8,22,-5,AIR)
B(-8,22,-4,AIR)
B(-8,22,-3,AIR)
B(-8,22,-2,AIR)
B(-8,22,-1,AIR)
B(-8,22,0,AIR)
B(-8,22,1,98)
B(-8,22,2,159:7)
B(-8,22,3,101)
B(-8,22,4,159:7)
B(-8,22,5,98)
B(-8,22,6,AIR)
B(-8,22,7,AIR)
B(-8,22,8,AIR)
B(-8,23,-6,AIR)
B(-8,23,-5,AIR)
B(-8,23,-4,AIR)
B(-8,23,-3,AIR)
B(-8,23,-2,AIR)
B(-8,23,-1,AIR)
B(-8,23,0,AIR)
B(-8,23,1,98)
B(-8,23,2,159:7)
B(-8,23,3,101)
B(-8,23,4,159:7)
B(-8,23,5,98)
B(-8,23,6,AIR)
B(-8,23,7,AIR)
B(-8,23,8,AIR)
B(-8,24,-6,AIR)
B(-8,24,-5,AIR)
B(-8,24,-4,AIR)
B(-8,24,-3,AIR)
B(-8,24,-2,AIR)
B(-8,24,-1,AIR)
B(-8,24,0,AIR)
B(-8,24,1,98)
B(-8,24,2,159:7)
B(-8,24,3,101)
B(-8,24,4,159:7)
B(-8,24,5,98)
B(-8,24,6,AIR)
B(-8,24,7,AIR)
B(-8,24,8,AIR)
B(-8,25,-6,AIR)
B(-8,25,-5,AIR)
B(-8,25,-4,AIR)
B(-8,25,-3,AIR)
B(-8,25,-2,AIR)
B(-8,25,-1,AIR)
B(-8,25,0,AIR)
B(-8,25,1,98)
B(-8,25,2,159:7)
B(-8,25,3,159:7)
B(-8,25,4,159:7)
B(-8,25,5,98)
B(-8,25,6,AIR)
B(-8,25,7,AIR)
B(-8,25,8,AIR)
B(-8,26,-6,AIR)
B(-8,26,-5,AIR)
B(-8,26,-4,AIR)
B(-8,26,-3,AIR)
B(-8,26,-2,AIR)
B(-8,26,-1,AIR)
B(-8,26,0,AIR)
B(-8,26,1,98)
B(-8,26,2,159:7)
B(-8,26,3,101)
B(-8,26,4,159:7)
B(-8,26,5,98)
B(-8,26,6,AIR)
B(-8,26,7,AIR)
B(-8,26,8,AIR)
B(-8,27,-6,AIR)
B(-8,27,-5,AIR)
B(-8,27,-4,AIR)
B(-8,27,-3,AIR)
B(-8,27,-2,AIR)
B(-8,27,-1,AIR)
B(-8,27,0,AIR)
B(-8,27,1,98)
B(-8,27,2,159:7)
B(-8,27,3,101)
B(-8,27,4,159:7)
B(-8,27,5,98)
B(-8,27,6,AIR)
B(-8,27,7,AIR)
B(-8,27,8,AIR)
B(-8,28,-6,AIR)
B(-8,28,-5,AIR)
B(-8,28,-4,AIR)
B(-8,28,-3,AIR)
B(-8,28,-2,AIR)
B(-8,28,-1,AIR)
B(-8,28,0,AIR)
B(-8,28,1,98)
B(-8,28,2,159:7)
B(-8,28,3,101)
B(-8,28,4,159:7)
B(-8,28,5,98)
B(-8,28,6,AIR)
B(-8,28,7,AIR)
B(-8,28,8,AIR)
B(-8,29,-6,AIR)
B(-8,29,-5,AIR)
B(-8,29,-4,AIR)
B(-8,29,-3,AIR)
B(-8,29,-2,AIR)
B(-8,29,-1,AIR)
B(-8,29,0,44:13)
B(-8,29,1,98)
B(-8,29,2,159:7)
B(-8,29,3,159:7)
B(-8,29,4,159:7)
B(-8,29,5,98)
B(-8,29,6,44:13)
B(-8,29,7,AIR)
B(-8,29,8,AIR)
B(-8,30,-6,AIR)
B(-8,30,-5,AIR)
B(-8,30,-4,AIR)
B(-8,30,-3,AIR)
B(-8,30,-2,AIR)
B(-8,30,-1,AIR)
B(-8,30,0,98)
B(-8,30,1,98)
B(-8,30,2,98)
B(-8,30,3,98)
B(-8,30,4,98)
B(-8,30,5,98)
B(-8,30,6,98)
B(-8,30,7,AIR)
B(-8,30,8,AIR)
B(-8,31,-6,AIR)
B(-8,31,-5,AIR)
B(-8,31,-4,AIR)
B(-8,31,-3,AIR)
B(-8,31,-2,AIR)
B(-8,31,-1,AIR)
B(-8,31,0,98)
B(-8,31,1,AIR)
B(-8,31,2,AIR)
B(-8,31,3,AIR)
B(-8,31,4,AIR)
B(-8,31,5,AIR)
B(-8,31,6,98)
B(-8,31,7,AIR)
B(-8,31,8,AIR)
B(-8,32,-6,AIR)
B(-8,32,-5,AIR)
B(-8,32,-4,AIR)
B(-8,32,-3,AIR)
B(-8,32,-2,AIR)
B(-8,32,-1,AIR)
B(-8,32,0,44)
B(-8,32,1,AIR)
B(-8,32,2,AIR)
B(-8,32,3,AIR)
B(-8,32,4,AIR)
B(-8,32,5,AIR)
B(-8,32,6,44)
B(-8,32,7,AIR)
B(-8,32,8,AIR)
B(-7,-31,-7,1)
B(-7,-31,-6,1)
B(-7,-31,-5,1)
B(-7,-31,-4,1)
B(-7,-31,-3,1)
B(-7,-31,-2,1)
B(-7,-31,-1,1)
B(-7,-31,0,1)
B(-7,-31,1,1)
B(-7,-31,2,1)
B(-7,-31,3,1)
B(-7,-31,4,1)
B(-7,-31,5,1)
B(-7,-31,6,1)
B(-7,-31,7,1)
B(-7,-31,8,1)
B(-7,-30,-7,1)
B(-7,-30,-6,1)
B(-7,-30,-5,1)
B(-7,-30,-4,1)
B(-7,-30,-3,1)
B(-7,-30,-2,1)
B(-7,-30,-1,1)
B(-7,-30,0,1)
B(-7,-30,1,1)
B(-7,-30,2,1)
B(-7,-30,3,1)
B(-7,-30,4,1)
B(-7,-30,5,1)
B(-7,-30,6,1)
B(-7,-30,7,1)
B(-7,-30,8,1)
B(-7,-29,-7,1)
B(-7,-29,-6,1)
B(-7,-29,-5,1)
B(-7,-29,-4,1)
B(-7,-29,-3,1)
B(-7,-29,-2,1)
B(-7,-29,-1,1)
B(-7,-29,0,1)
B(-7,-29,1,1)
B(-7,-29,2,1)
B(-7,-29,3,1)
B(-7,-29,4,1)
B(-7,-29,5,1)
B(-7,-29,6,1)
B(-7,-29,7,1)
B(-7,-29,8,1)
B(-7,-28,-7,1)
B(-7,-28,-6,1)
B(-7,-28,-5,1)
B(-7,-28,-4,1)
B(-7,-28,-3,1)
B(-7,-28,-2,1)
B(-7,-28,-1,1)
B(-7,-28,0,1)
B(-7,-28,1,1)
B(-7,-28,2,1)
B(-7,-28,3,1)
B(-7,-28,4,1)
B(-7,-28,5,1)
B(-7,-28,6,1)
B(-7,-28,7,1)
B(-7,-28,8,1)
B(-7,-27,-7,1)
B(-7,-27,-6,1)
B(-7,-27,-5,1)
B(-7,-27,-4,1)
B(-7,-27,-3,1)
B(-7,-27,-2,1)
B(-7,-27,-1,1)
B(-7,-27,0,1)
B(-7,-27,1,1)
B(-7,-27,2,1)
B(-7,-27,3,1)
B(-7,-27,4,1)
B(-7,-27,5,1)
B(-7,-27,6,1)
B(-7,-27,7,1)
B(-7,-27,8,1)
B(-7,-26,-7,1)
B(-7,-26,-6,1)
B(-7,-26,-5,1)
B(-7,-26,-4,1)
B(-7,-26,-3,1)
B(-7,-26,-2,1)
B(-7,-26,-1,1)
B(-7,-26,0,1)
B(-7,-26,1,1)
B(-7,-26,2,1)
B(-7,-26,3,1)
B(-7,-26,4,1)
B(-7,-26,5,1)
B(-7,-26,6,1)
B(-7,-26,7,1)
B(-7,-26,8,1)
B(-7,-25,-7,1)
B(-7,-25,-6,1)
B(-7,-25,-5,1)
B(-7,-25,-4,1)
B(-7,-25,-3,1)
B(-7,-25,-2,1)
B(-7,-25,-1,1)
B(-7,-25,0,1)
B(-7,-25,1,1)
B(-7,-25,2,1)
B(-7,-25,3,1)
B(-7,-25,4,1)
B(-7,-25,5,1)
B(-7,-25,6,1)
B(-7,-25,7,1)
B(-7,-25,8,1)
B(-7,-24,-7,1)
B(-7,-24,-6,1)
B(-7,-24,-5,1)
B(-7,-24,-4,1)
B(-7,-24,-3,1)
B(-7,-24,-2,1)
B(-7,-24,-1,1)
B(-7,-24,0,1)
B(-7,-24,1,1)
B(-7,-24,2,1)
B(-7,-24,3,1)
B(-7,-24,4,1)
B(-7,-24,5,1)
B(-7,-24,6,1)
B(-7,-24,7,1)
B(-7,-24,8,1)
B(-7,-23,-7,1)
B(-7,-23,-6,1)
B(-7,-23,-5,1)
B(-7,-23,-4,1)
B(-7,-23,-3,1)
B(-7,-23,-2,1)
B(-7,-23,-1,1)
B(-7,-23,0,1)
B(-7,-23,1,1)
B(-7,-23,2,1)
B(-7,-23,3,1)
B(-7,-23,4,1)
B(-7,-23,5,1)
B(-7,-23,6,1)
B(-7,-23,7,1)
B(-7,-23,8,1)
B(-7,-22,-7,1)
B(-7,-22,-6,1)
B(-7,-22,-5,1)
B(-7,-22,-4,1)
B(-7,-22,-3,1)
B(-7,-22,-2,1)
B(-7,-22,-1,1)
B(-7,-22,0,1)
B(-7,-22,1,1)
B(-7,-22,2,1)
B(-7,-22,3,1)
B(-7,-22,4,1)
B(-7,-22,5,1)
B(-7,-22,6,1)
B(-7,-22,7,1)
B(-7,-22,8,1)
B(-7,-21,-6,1)
B(-7,-21,-5,1)
B(-7,-21,-4,1)
B(-7,-21,-3,1)
B(-7,-21,-2,1)
B(-7,-21,-1,1)
B(-7,-21,0,1)
B(-7,-21,1,1)
B(-7,-21,2,1)
B(-7,-21,3,1)
B(-7,-21,4,1)
B(-7,-21,5,1)
B(-7,-21,6,1)
B(-7,-21,7,1)
B(-7,-21,8,1)
B(-7,-20,-6,1)
B(-7,-20,-5,1)
B(-7,-20,-4,1)
B(-7,-20,-3,1)
B(-7,-20,-2,1)
B(-7,-20,-1,1)
B(-7,-20,0,1)
B(-7,-20,1,1)
B(-7,-20,2,1)
B(-7,-20,3,1)
B(-7,-20,4,1)
B(-7,-20,5,1)
B(-7,-20,6,1)
B(-7,-20,7,1)
B(-7,-20,8,1)
B(-7,-19,-6,1)
B(-7,-19,-5,1)
B(-7,-19,-4,1)
B(-7,-19,-3,1)
B(-7,-19,-2,1)
B(-7,-19,-1,1)
B(-7,-19,0,1)
B(-7,-19,1,1)
B(-7,-19,2,1)
B(-7,-19,3,1)
B(-7,-19,4,1)
B(-7,-19,5,1)
B(-7,-19,6,1)
B(-7,-19,7,1)
B(-7,-19,8,1)
B(-7,-18,-7,1)
B(-7,-18,-6,1)
B(-7,-18,-5,1)
B(-7,-18,-4,1)
B(-7,-18,-3,1)
B(-7,-18,-2,1)
B(-7,-18,-1,1)
B(-7,-18,0,1)
B(-7,-18,1,1)
B(-7,-18,2,1)
B(-7,-18,3,1)
B(-7,-18,4,1)
B(-7,-18,5,1)
B(-7,-18,6,1)
B(-7,-18,7,1)
B(-7,-18,8,1)
B(-7,-17,-7,1)
B(-7,-17,-6,1)
B(-7,-17,-5,1)
B(-7,-17,-4,1)
B(-7,-17,-3,1)
B(-7,-17,-2,1)
B(-7,-17,-1,1)
B(-7,-17,0,1)
B(-7,-17,1,1)
B(-7,-17,2,1)
B(-7,-17,3,1)
B(-7,-17,4,1)
B(-7,-17,5,1)
B(-7,-17,6,1)
B(-7,-17,7,1)
B(-7,-17,8,1)
B(-7,-16,-7,1)
B(-7,-16,-6,1)
B(-7,-16,-5,1)
B(-7,-16,-4,1)
B(-7,-16,-3,1)
B(-7,-16,-2,1)
B(-7,-16,-1,1)
B(-7,-16,0,1)
B(-7,-16,1,1)
B(-7,-16,2,1)
B(-7,-16,3,1)
B(-7,-16,4,1)
B(-7,-16,5,1)
B(-7,-16,6,1)
B(-7,-16,7,1)
B(-7,-16,8,1)
B(-7,-15,-7,1)
B(-7,-15,-6,1)
B(-7,-15,-5,1)
B(-7,-15,-4,1)
B(-7,-15,-3,1)
B(-7,-15,-2,1)
B(-7,-15,-1,1)
B(-7,-15,0,1)
B(-7,-15,1,1)
B(-7,-15,2,1)
B(-7,-15,3,1)
B(-7,-15,4,1)
B(-7,-15,5,1)
B(-7,-15,6,1)
B(-7,-15,7,1)
B(-7,-15,8,1)
B(-7,-14,-7,1)
B(-7,-14,-6,1)
B(-7,-14,-5,1)
B(-7,-14,-4,1)
B(-7,-14,-3,1)
B(-7,-14,-2,1)
B(-7,-14,-1,1)
B(-7,-14,0,1)
B(-7,-14,1,1)
B(-7,-14,2,1)
B(-7,-14,3,1)
B(-7,-14,4,1)
B(-7,-14,5,1)
B(-7,-14,6,1)
B(-7,-14,7,1)
B(-7,-14,8,1)
B(-7,-13,-7,1)
B(-7,-13,-6,1)
B(-7,-13,-5,1)
B(-7,-13,-4,1)
B(-7,-13,-3,1)
B(-7,-13,-2,1)
B(-7,-13,-1,1)
B(-7,-13,0,1)
B(-7,-13,1,1)
B(-7,-13,2,1)
B(-7,-13,3,1)
B(-7,-13,4,1)
B(-7,-13,5,1)
B(-7,-13,6,1)
B(-7,-13,7,1)
B(-7,-13,8,1)
B(-7,-12,-7,1)
B(-7,-12,-6,1)
B(-7,-12,-5,1)
B(-7,-12,-4,1)
B(-7,-12,-3,1)
B(-7,-12,-2,1)
B(-7,-12,-1,1)
B(-7,-12,0,1)
B(-7,-12,1,1)
B(-7,-12,2,1)
B(-7,-12,3,1)
B(-7,-12,4,1)
B(-7,-12,5,1)
B(-7,-12,6,1)
B(-7,-12,7,1)
B(-7,-12,8,1)
B(-7,-11,-7,1)
B(-7,-11,-6,1)
B(-7,-11,-5,1)
B(-7,-11,-4,1)
B(-7,-11,-3,1)
B(-7,-11,-2,1)
B(-7,-11,-1,1)
B(-7,-11,0,1)
B(-7,-11,1,1)
B(-7,-11,2,1)
B(-7,-11,3,1)
B(-7,-11,4,1)
B(-7,-11,5,1)
B(-7,-11,6,1)
B(-7,-11,7,1)
B(-7,-11,8,1)
B(-7,-10,-7,1)
B(-7,-10,-6,1)
B(-7,-10,-5,1)
B(-7,-10,-4,1)
B(-7,-10,-3,1)
B(-7,-10,-2,1)
B(-7,-10,-1,1)
B(-7,-10,0,1)
B(-7,-10,1,1)
B(-7,-10,2,1)
B(-7,-10,3,1)
B(-7,-10,4,1)
B(-7,-10,5,1)
B(-7,-10,6,1)
B(-7,-10,7,1)
B(-7,-10,8,1)
B(-7,-9,-7,1)
B(-7,-9,-6,1)
B(-7,-9,-5,1)
B(-7,-9,-4,1)
B(-7,-9,-3,1)
B(-7,-9,-2,1)
B(-7,-9,-1,1)
B(-7,-9,0,1)
B(-7,-9,1,1)
B(-7,-9,2,1)
B(-7,-9,3,1)
B(-7,-9,4,1)
B(-7,-9,5,1)
B(-7,-9,6,1)
B(-7,-9,7,1)
B(-7,-9,8,1)
B(-7,-8,-7,1)
B(-7,-8,-6,1)
B(-7,-8,-5,1)
B(-7,-8,-4,1)
B(-7,-8,-3,1)
B(-7,-8,-2,1)
B(-7,-8,-1,1)
B(-7,-8,0,1)
B(-7,-8,1,1)
B(-7,-8,2,1)
B(-7,-8,3,1)
B(-7,-8,4,1)
B(-7,-8,5,1)
B(-7,-8,6,1)
B(-7,-8,7,1)
B(-7,-8,8,1)
B(-7,-7,-7,1)
B(-7,-7,-6,1)
B(-7,-7,-5,1)
B(-7,-7,-4,1)
B(-7,-7,-3,1)
B(-7,-7,-2,1)
B(-7,-7,-1,1)
B(-7,-7,0,1)
B(-7,-7,1,1)
B(-7,-7,2,1)
B(-7,-7,3,1)
B(-7,-7,4,1)
B(-7,-7,5,1)
B(-7,-7,6,1)
B(-7,-7,7,1)
B(-7,-7,8,1)
B(-7,-6,-6,1)
B(-7,-6,-5,1)
B(-7,-6,-4,1)
B(-7,-6,-3,1)
B(-7,-6,-2,1)
B(-7,-6,-1,1)
B(-7,-6,0,1)
B(-7,-6,1,1)
B(-7,-6,2,1)
B(-7,-6,3,1)
B(-7,-6,4,1)
B(-7,-6,5,1)
B(-7,-6,6,1)
B(-7,-6,7,1)
B(-7,-6,8,1)
B(-7,-5,-6,1)
B(-7,-5,-5,1)
B(-7,-5,-4,1)
B(-7,-5,-3,1)
B(-7,-5,-2,1)
B(-7,-5,-1,1)
B(-7,-5,0,1)
B(-7,-5,1,1)
B(-7,-5,2,1)
B(-7,-5,3,1)
B(-7,-5,4,1)
B(-7,-5,5,1)
B(-7,-5,6,1)
B(-7,-5,7,1)
B(-7,-5,8,1)
B(-7,-4,-6,1)
B(-7,-4,-5,1)
B(-7,-4,-4,1)
B(-7,-4,-3,1)
B(-7,-4,-2,1)
B(-7,-4,-1,1)
B(-7,-4,0,1)
B(-7,-4,1,1)
B(-7,-4,2,1)
B(-7,-4,3,1)
B(-7,-4,4,1)
B(-7,-4,5,1)
B(-7,-4,6,1)
B(-7,-4,7,1)
B(-7,-4,8,1)
B(-7,-3,-4,1)
B(-7,-3,-3,1)
B(-7,-3,-2,1)
B(-7,-3,-1,1)
B(-7,-3,0,1)
B(-7,-3,1,1)
B(-7,-3,2,1)
B(-7,-3,3,1)
B(-7,-3,4,1)
B(-7,-3,5,1)
B(-7,-3,6,1)
B(-7,-3,7,1)
B(-7,-3,8,1)
B(-7,-2,-6,AIR)
B(-7,-2,-5,AIR)
B(-7,-2,-4,1)
B(-7,-2,-3,1)
B(-7,-2,-2,1)
B(-7,-2,-1,1)
B(-7,-2,0,1)
B(-7,-2,1,1)
B(-7,-2,2,1)
B(-7,-2,3,1)
B(-7,-2,4,1)
B(-7,-2,5,1)
B(-7,-2,6,1)
B(-7,-2,7,1)
B(-7,-2,8,1)
B(-7,-1,-6,AIR)
B(-7,-1,-5,AIR)
B(-7,-1,-4,AIR)
B(-7,-1,-3,1)
B(-7,-1,-2,1)
B(-7,-1,-1,1)
B(-7,-1,0,98)
B(-7,-1,1,1)
B(-7,-1,2,1)
B(-7,-1,3,1)
B(-7,-1,4,1)
B(-7,-1,5,1)
B(-7,-1,6,1)
B(-7,-1,7,1)
B(-7,-1,8,1)
B(-7,0,-6,AIR)
B(-7,0,-5,AIR)
B(-7,0,-4,AIR)
B(-7,0,-3,1)
B(-7,0,-2,1)
B(-7,0,-1,98)
B(-7,0,0,98)
B(-7,0,1,AIR)
B(-7,0,2,AIR)
B(-7,0,3,AIR)
B(-7,0,4,AIR)
B(-7,0,5,AIR)
B(-7,0,6,98)
B(-7,0,7,98)
B(-7,0,8,1)
B(-7,1,-6,AIR)
B(-7,1,-5,AIR)
B(-7,1,-4,AIR)
B(-7,1,-3,AIR)
B(-7,1,-2,98)
B(-7,1,-1,98)
B(-7,1,0,98)
B(-7,1,1,AIR)
B(-7,1,2,AIR)
B(-7,1,3,AIR)
B(-7,1,4,AIR)
B(-7,1,5,AIR)
B(-7,1,6,98)
B(-7,1,7,98)
B(-7,1,8,1)
B(-7,2,-6,AIR)
B(-7,2,-5,AIR)
B(-7,2,-4,AIR)
B(-7,2,-3,AIR)
B(-7,2,-2,98)
B(-7,2,-1,98)
B(-7,2,0,98)
B(-7,2,1,5:5)
B(-7,2,2,98)
B(-7,2,3,98)
B(-7,2,4,98)
B(-7,2,5,5:5)
B(-7,2,6,43:5)
B(-7,2,7,98)
B(-7,2,8,1)
B(-7,3,-6,AIR)
B(-7,3,-5,AIR)
B(-7,3,-4,AIR)
B(-7,3,-3,AIR)
B(-7,3,-2,98)
B(-7,3,-1,98)
B(-7,3,0,98)
B(-7,3,1,AIR)
B(-7,3,2,AIR)
B(-7,3,3,AIR)
B(-7,3,4,AIR)
B(-7,3,5,AIR)
B(-7,3,6,AIR)
B(-7,3,7,98)
B(-7,3,8,1)
B(-7,4,-6,AIR)
B(-7,4,-5,AIR)
B(-7,4,-4,AIR)
B(-7,4,-3,AIR)
B(-7,4,-2,98)
B(-7,4,-1,98)
B(-7,4,0,98)
B(-7,4,1,AIR)
B(-7,4,2,AIR)
B(-7,4,3,AIR)
B(-7,4,4,AIR)
B(-7,4,5,AIR)
B(-7,4,6,AIR)
B(-7,4,7,98)
B(-7,4,8,1)
B(-7,5,-6,AIR)
B(-7,5,-5,AIR)
B(-7,5,-4,AIR)
B(-7,5,-3,AIR)
B(-7,5,-2,98)
B(-7,5,-1,98)
B(-7,5,0,98)
B(-7,5,1,AIR)
B(-7,5,2,AIR)
B(-7,5,3,AIR)
B(-7,5,4,AIR)
B(-7,5,5,AIR)
B(-7,5,6,AIR)
B(-7,5,7,98)
B(-7,5,8,1)
B(-7,6,-6,AIR)
B(-7,6,-5,AIR)
B(-7,6,-4,AIR)
B(-7,6,-3,AIR)
B(-7,6,-2,AIR)
B(-7,6,-1,98)
B(-7,6,0,98)
B(-7,6,1,AIR)
B(-7,6,2,AIR)
B(-7,6,3,AIR)
B(-7,6,4,AIR)
B(-7,6,5,AIR)
B(-7,6,6,AIR)
B(-7,6,7,98)
B(-7,6,8,1)
B(-7,7,-6,AIR)
B(-7,7,-5,AIR)
B(-7,7,-4,AIR)
B(-7,7,-3,AIR)
B(-7,7,-2,AIR)
B(-7,7,-1,98)
B(-7,7,0,98)
B(-7,7,1,AIR)
B(-7,7,2,AIR)
B(-7,7,3,AIR)
B(-7,7,4,AIR)
B(-7,7,5,AIR)
B(-7,7,6,AIR)
B(-7,7,7,98)
B(-7,7,8,1)
B(-7,8,-6,AIR)
B(-7,8,-5,AIR)
B(-7,8,-4,AIR)
B(-7,8,-3,AIR)
B(-7,8,-2,AIR)
B(-7,8,-1,98)
B(-7,8,0,98)
B(-7,8,1,AIR)
B(-7,8,2,AIR)
B(-7,8,3,AIR)
B(-7,8,4,AIR)
B(-7,8,5,AIR)
B(-7,8,6,AIR)
B(-7,8,7,98)
B(-7,8,8,1)
B(-7,9,-6,AIR)
B(-7,9,-5,AIR)
B(-7,9,-4,AIR)
B(-7,9,-3,AIR)
B(-7,9,-2,AIR)
B(-7,9,-1,98)
B(-7,9,0,98)
B(-7,9,1,AIR)
B(-7,9,2,AIR)
B(-7,9,3,AIR)
B(-7,9,4,AIR)
B(-7,9,5,AIR)
B(-7,9,6,98)
B(-7,9,7,98)
B(-7,9,8,1)
B(-7,10,-6,AIR)
B(-7,10,-5,AIR)
B(-7,10,-4,AIR)
B(-7,10,-3,AIR)
B(-7,10,-2,AIR)
B(-7,10,-1,98)
B(-7,10,0,98)
B(-7,10,1,AIR)
B(-7,10,2,AIR)
B(-7,10,3,AIR)
B(-7,10,4,98)
B(-7,10,5,98)
B(-7,10,6,98)
B(-7,10,7,98)
B(-7,10,8,AIR)
B(-7,11,-6,AIR)
B(-7,11,-5,AIR)
B(-7,11,-4,AIR)
B(-7,11,-3,AIR)
B(-7,11,-2,98)
B(-7,11,-1,98)
B(-7,11,0,98:3)
B(-7,11,1,98:3)
B(-7,11,2,98)
B(-7,11,3,98)
B(-7,11,4,98)
B(-7,11,5,98)
B(-7,11,6,98)
B(-7,11,7,98)
B(-7,11,8,98)
B(-7,12,-6,AIR)
B(-7,12,-5,AIR)
B(-7,12,-4,AIR)
B(-7,12,-3,AIR)
B(-7,12,-2,44:5)
B(-7,12,-1,98)
B(-7,12,0,AIR)
B(-7,12,1,AIR)
B(-7,12,2,AIR)
B(-7,12,3,AIR)
B(-7,12,4,AIR)
B(-7,12,5,47)
B(-7,12,6,AIR)
B(-7,12,7,98)
B(-7,12,8,44:5)
B(-7,13,-6,AIR)
B(-7,13,-5,AIR)
B(-7,13,-4,AIR)
B(-7,13,-3,AIR)
B(-7,13,-2,AIR)
B(-7,13,-1,98)
B(-7,13,0,AIR)
B(-7,13,1,AIR)
B(-7,13,2,AIR)
B(-7,13,3,AIR)
B(-7,13,4,AIR)
B(-7,13,5,126:5)
B(-7,13,6,126:5)
B(-7,13,7,98)
B(-7,13,8,AIR)
B(-7,14,-6,AIR)
B(-7,14,-5,AIR)
B(-7,14,-4,AIR)
B(-7,14,-3,AIR)
B(-7,14,-2,AIR)
B(-7,14,-1,159:7)
B(-7,14,0,AIR)
B(-7,14,1,AIR)
B(-7,14,2,AIR)
B(-7,14,3,AIR)
B(-7,14,4,AIR)
B(-7,14,5,AIR)
B(-7,14,6,AIR)
B(-7,14,7,159:7)
B(-7,14,8,AIR)
B(-7,15,-6,AIR)
B(-7,15,-5,AIR)
B(-7,15,-4,AIR)
B(-7,15,-3,AIR)
B(-7,15,-2,AIR)
B(-7,15,-1,159:7)
B(-7,15,0,AIR)
B(-7,15,1,AIR)
B(-7,15,2,AIR)
B(-7,15,3,AIR)
B(-7,15,4,AIR)
B(-7,15,5,AIR)
B(-7,15,6,AIR)
B(-7,15,7,159:7)
B(-7,15,8,AIR)
B(-7,16,-6,AIR)
B(-7,16,-5,AIR)
B(-7,16,-4,AIR)
B(-7,16,-3,AIR)
B(-7,16,-2,AIR)
B(-7,16,-1,159:7)
B(-7,16,0,AIR)
B(-7,16,1,AIR)
B(-7,16,2,AIR)
B(-7,16,3,AIR)
B(-7,16,4,AIR)
B(-7,16,5,AIR)
B(-7,16,6,AIR)
B(-7,16,7,159:7)
B(-7,16,8,AIR)
B(-7,17,-6,AIR)
B(-7,17,-5,AIR)
B(-7,17,-4,AIR)
B(-7,17,-3,AIR)
B(-7,17,-2,AIR)
B(-7,17,-1,98)
B(-7,17,0,98)
B(-7,17,1,AIR)
B(-7,17,2,AIR)
B(-7,17,3,AIR)
B(-7,17,4,AIR)
B(-7,17,5,AIR)
B(-7,17,6,98)
B(-7,17,7,98)
B(-7,17,8,AIR)
B(-7,18,-6,AIR)
B(-7,18,-5,AIR)
B(-7,18,-4,AIR)
B(-7,18,-3,AIR)
B(-7,18,-2,98)
B(-7,18,-1,98)
B(-7,18,0,98)
B(-7,18,1,98)
B(-7,18,2,AIR)
B(-7,18,3,AIR)
B(-7,18,4,AIR)
B(-7,18,5,98)
B(-7,18,6,98)
B(-7,18,7,98)
B(-7,18,8,98)
B(-7,19,-6,AIR)
B(-7,19,-5,AIR)
B(-7,19,-4,AIR)
B(-7,19,-3,AIR)
B(-7,19,-2,44:5)
B(-7,19,-1,AIR)
B(-7,19,0,98)
B(-7,19,1,98)
B(-7,19,2,98)
B(-7,19,3,98)
B(-7,19,4,98)
B(-7,19,5,98)
B(-7,19,6,98)
B(-7,19,7,AIR)
B(-7,19,8,44:5)
B(-7,20,-6,AIR)
B(-7,20,-5,AIR)
B(-7,20,-4,AIR)
B(-7,20,-3,AIR)
B(-7,20,-2,AIR)
B(-7,20,-1,AIR)
B(-7,20,0,98)
B(-7,20,1,98)
B(-7,20,2,44:5)
B(-7,20,3,98)
B(-7,20,4,44:5)
B(-7,20,5,98)
B(-7,20,6,98)
B(-7,20,7,AIR)
B(-7,20,8,AIR)
B(-7,21,-6,AIR)
B(-7,21,-5,AIR)
B(-7,21,-4,AIR)
B(-7,21,-3,AIR)
B(-7,21,-2,AIR)
B(-7,21,-1,AIR)
B(-7,21,0,44)
B(-7,21,1,44)
B(-7,21,2,AIR)
B(-7,21,3,44)
B(-7,21,4,AIR)
B(-7,21,5,44)
B(-7,21,6,44)
B(-7,21,7,AIR)
B(-7,21,8,AIR)
B(-7,22,-6,AIR)
B(-7,22,-5,AIR)
B(-7,22,-4,AIR)
B(-7,22,-3,AIR)
B(-7,22,-2,AIR)
B(-7,22,-1,AIR)
B(-7,22,0,AIR)
B(-7,22,1,AIR)
B(-7,22,2,AIR)
B(-7,22,3,AIR)
B(-7,22,4,AIR)
B(-7,22,5,AIR)
B(-7,22,6,AIR)
B(-7,22,7,AIR)
B(-7,22,8,AIR)
B(-7,23,-6,AIR)
B(-7,23,-5,AIR)
B(-7,23,-4,AIR)
B(-7,23,-3,AIR)
B(-7,23,-2,AIR)
B(-7,23,-1,AIR)
B(-7,23,0,AIR)
B(-7,23,1,AIR)
B(-7,23,2,AIR)
B(-7,23,3,AIR)
B(-7,23,4,AIR)
B(-7,23,5,AIR)
B(-7,23,6,AIR)
B(-7,23,7,AIR)
B(-7,23,8,AIR)
B(-7,24,-6,AIR)
B(-7,24,-5,AIR)
B(-7,24,-4,AIR)
B(-7,24,-3,AIR)
B(-7,24,-2,AIR)
B(-7,24,-1,AIR)
B(-7,24,0,AIR)
B(-7,24,1,AIR)
B(-7,24,2,AIR)
B(-7,24,3,AIR)
B(-7,24,4,AIR)
B(-7,24,5,AIR)
B(-7,24,6,AIR)
B(-7,24,7,AIR)
B(-7,24,8,AIR)
B(-7,25,-6,AIR)
B(-7,25,-5,AIR)
B(-7,25,-4,AIR)
B(-7,25,-3,AIR)
B(-7,25,-2,AIR)
B(-7,25,-1,AIR)
B(-7,25,0,AIR)
B(-7,25,1,AIR)
B(-7,25,2,AIR)
B(-7,25,3,AIR)
B(-7,25,4,AIR)
B(-7,25,5,AIR)
B(-7,25,6,AIR)
B(-7,25,7,AIR)
B(-7,25,8,AIR)
B(-7,26,-6,AIR)
B(-7,26,-5,AIR)
B(-7,26,-4,AIR)
B(-7,26,-3,AIR)
B(-7,26,-2,AIR)
B(-7,26,-1,AIR)
B(-7,26,0,AIR)
B(-7,26,1,AIR)
B(-7,26,2,AIR)
B(-7,26,3,AIR)
B(-7,26,4,AIR)
B(-7,26,5,AIR)
B(-7,26,6,AIR)
B(-7,26,7,AIR)
B(-7,26,8,AIR)
B(-7,27,-6,AIR)
B(-7,27,-5,AIR)
B(-7,27,-4,AIR)
B(-7,27,-3,AIR)
B(-7,27,-2,AIR)
B(-7,27,-1,AIR)
B(-7,27,0,AIR)
B(-7,27,1,AIR)
B(-7,27,2,AIR)
B(-7,27,3,AIR)
B(-7,27,4,AIR)
B(-7,27,5,AIR)
B(-7,27,6,AIR)
B(-7,27,7,AIR)
B(-7,27,8,AIR)
B(-7,28,-6,AIR)
B(-7,28,-5,AIR)
B(-7,28,-4,AIR)
B(-7,28,-3,AIR)
B(-7,28,-2,AIR)
B(-7,28,-1,AIR)
B(-7,28,0,AIR)
B(-7,28,1,AIR)
B(-7,28,2,AIR)
B(-7,28,3,AIR)
B(-7,28,4,AIR)
B(-7,28,5,AIR)
B(-7,28,6,AIR)
B(-7,28,7,AIR)
B(-7,28,8,AIR)
B(-7,29,-6,AIR)
B(-7,29,-5,AIR)
B(-7,29,-4,AIR)
B(-7,29,-3,AIR)
B(-7,29,-2,AIR)
B(-7,29,-1,AIR)
B(-7,29,0,AIR)
B(-7,29,1,44:13)
B(-7,29,2,AIR)
B(-7,29,3,44:13)
B(-7,29,4,AIR)
B(-7,29,5,44:13)
B(-7,29,6,AIR)
B(-7,29,7,AIR)
B(-7,29,8,AIR)
B(-7,30,-6,AIR)
B(-7,30,-5,AIR)
B(-7,30,-4,AIR)
B(-7,30,-3,AIR)
B(-7,30,-2,AIR)
B(-7,30,-1,AIR)
B(-7,30,0,98)
B(-7,30,1,98)
B(-7,30,2,98)
B(-7,30,3,98)
B(-7,30,4,98)
B(-7,30,5,98)
B(-7,30,6,98)
B(-7,30,7,AIR)
B(-7,30,8,AIR)
B(-7,31,-6,AIR)
B(-7,31,-5,AIR)
B(-7,31,-4,AIR)
B(-7,31,-3,AIR)
B(-7,31,-2,AIR)
B(-7,31,-1,AIR)
B(-7,31,0,98)
B(-7,31,1,98)
B(-7,31,2,AIR)
B(-7,31,3,AIR)
B(-7,31,4,AIR)
B(-7,31,5,98)
B(-7,31,6,98)
B(-7,31,7,AIR)
B(-7,31,8,AIR)
B(-7,32,-6,AIR)
B(-7,32,-5,AIR)
B(-7,32,-4,AIR)
B(-7,32,-3,AIR)
B(-7,32,-2,AIR)
B(-7,32,-1,AIR)
B(-7,32,0,44)
B(-7,32,1,44)
B(-7,32,2,AIR)
B(-7,32,3,AIR)
B(-7,32,4,AIR)
B(-7,32,5,44)
B(-7,32,6,44)
B(-7,32,7,AIR)
B(-7,32,8,AIR)
B(-6,-31,-7,1)
B(-6,-31,-6,1)
B(-6,-31,-5,1)
B(-6,-31,-4,1)
B(-6,-31,-3,1)
B(-6,-31,-2,1)
B(-6,-31,-1,1)
B(-6,-31,0,1)
B(-6,-31,1,1)
B(-6,-31,2,1)
B(-6,-31,3,1)
B(-6,-31,4,1)
B(-6,-31,5,1)
B(-6,-31,6,1)
B(-6,-31,7,1)
B(-6,-31,8,1)
B(-6,-30,-7,1)
B(-6,-30,-6,1)
B(-6,-30,-5,1)
B(-6,-30,-4,1)
B(-6,-30,-3,1)
B(-6,-30,-2,1)
B(-6,-30,-1,1)
B(-6,-30,0,1)
B(-6,-30,1,1)
B(-6,-30,2,1)
B(-6,-30,3,1)
B(-6,-30,4,1)
B(-6,-30,5,1)
B(-6,-30,6,1)
B(-6,-30,7,1)
B(-6,-30,8,1)
B(-6,-29,-7,1)
B(-6,-29,-6,1)
B(-6,-29,-5,1)
B(-6,-29,-4,1)
B(-6,-29,-3,1)
B(-6,-29,-2,1)
B(-6,-29,-1,1)
B(-6,-29,0,1)
B(-6,-29,1,1)
B(-6,-29,2,1)
B(-6,-29,3,1)
B(-6,-29,4,1)
B(-6,-29,5,1)
B(-6,-29,6,1)
B(-6,-29,7,1)
B(-6,-29,8,1)
B(-6,-28,-7,1)
B(-6,-28,-6,1)
B(-6,-28,-5,1)
B(-6,-28,-4,1)
B(-6,-28,-3,1)
B(-6,-28,-2,1)
B(-6,-28,-1,1)
B(-6,-28,0,1)
B(-6,-28,1,1)
B(-6,-28,2,1)
B(-6,-28,3,1)
B(-6,-28,4,1)
B(-6,-28,5,1)
B(-6,-28,6,1)
B(-6,-28,7,1)
B(-6,-28,8,1)
B(-6,-27,-7,1)
B(-6,-27,-6,1)
B(-6,-27,-5,1)
B(-6,-27,-4,1)
B(-6,-27,-3,1)
B(-6,-27,-2,1)
B(-6,-27,-1,1)
B(-6,-27,0,1)
B(-6,-27,1,1)
B(-6,-27,2,1)
B(-6,-27,3,1)
B(-6,-27,4,1)
B(-6,-27,5,1)
B(-6,-27,6,1)
B(-6,-27,7,1)
B(-6,-27,8,1)
B(-6,-26,-7,1)
B(-6,-26,-6,1)
B(-6,-26,-5,1)
B(-6,-26,-4,1)
B(-6,-26,-3,1)
B(-6,-26,-2,1)
B(-6,-26,-1,1)
B(-6,-26,0,1)
B(-6,-26,1,1)
B(-6,-26,2,1)
B(-6,-26,3,1)
B(-6,-26,4,1)
B(-6,-26,5,1)
B(-6,-26,6,1)
B(-6,-26,7,1)
B(-6,-26,8,1)
B(-6,-25,-7,1)
B(-6,-25,-6,1)
B(-6,-25,-5,1)
B(-6,-25,-4,1)
B(-6,-25,-3,1)
B(-6,-25,-2,1)
B(-6,-25,-1,1)
B(-6,-25,0,1)
B(-6,-25,1,1)
B(-6,-25,2,1)
B(-6,-25,3,1)
B(-6,-25,4,1)
B(-6,-25,5,1)
B(-6,-25,6,1)
B(-6,-25,7,1)
B(-6,-25,8,1)
B(-6,-24,-7,1)
B(-6,-24,-6,1)
B(-6,-24,-5,1)
B(-6,-24,-4,1)
B(-6,-24,-3,1)
B(-6,-24,-2,1)
B(-6,-24,-1,1)
B(-6,-24,0,1)
B(-6,-24,1,1)
B(-6,-24,2,1)
B(-6,-24,3,1)
B(-6,-24,4,1)
B(-6,-24,5,1)
B(-6,-24,6,1)
B(-6,-24,7,1)
B(-6,-24,8,1)
B(-6,-23,-6,1)
B(-6,-23,-5,1)
B(-6,-23,-4,1)
B(-6,-23,-3,1)
B(-6,-23,-2,1)
B(-6,-23,-1,1)
B(-6,-23,0,1)
B(-6,-23,1,1)
B(-6,-23,2,1)
B(-6,-23,3,1)
B(-6,-23,4,1)
B(-6,-23,5,1)
B(-6,-23,6,1)
B(-6,-23,7,1)
B(-6,-23,8,1)
B(-6,-22,-6,1)
B(-6,-22,-5,1)
B(-6,-22,-4,1)
B(-6,-22,-3,1)
B(-6,-22,-2,1)
B(-6,-22,-1,1)
B(-6,-22,0,1)
B(-6,-22,1,1)
B(-6,-22,2,1)
B(-6,-22,3,1)
B(-6,-22,4,1)
B(-6,-22,5,1)
B(-6,-22,6,1)
B(-6,-22,7,1)
B(-6,-22,8,1)
B(-6,-21,-6,1)
B(-6,-21,-5,1)
B(-6,-21,-4,1)
B(-6,-21,-3,1)
B(-6,-21,-2,1)
B(-6,-21,-1,1)
B(-6,-21,0,1)
B(-6,-21,1,1)
B(-6,-21,2,1)
B(-6,-21,3,1)
B(-6,-21,4,1)
B(-6,-21,5,1)
B(-6,-21,6,1)
B(-6,-21,7,1)
B(-6,-21,8,1)
B(-6,-20,-6,1)
B(-6,-20,-5,1)
B(-6,-20,-4,1)
B(-6,-20,-3,1)
B(-6,-20,-2,1)
B(-6,-20,-1,1)
B(-6,-20,0,1)
B(-6,-20,1,1)
B(-6,-20,2,1)
B(-6,-20,3,1)
B(-6,-20,4,1)
B(-6,-20,5,1)
B(-6,-20,6,1)
B(-6,-20,7,1)
B(-6,-20,8,1)
B(-6,-19,-6,1)
B(-6,-19,-5,1)
B(-6,-19,-4,1)
B(-6,-19,-3,1)
B(-6,-19,-2,1)
B(-6,-19,-1,1)
B(-6,-19,0,1)
B(-6,-19,1,1)
B(-6,-19,2,1)
B(-6,-19,3,1)
B(-6,-19,4,1)
B(-6,-19,5,1)
B(-6,-19,6,1)
B(-6,-19,7,1)
B(-6,-19,8,1)
B(-6,-18,-6,1)
B(-6,-18,-5,1)
B(-6,-18,-4,1)
B(-6,-18,-3,1)
B(-6,-18,-2,1)
B(-6,-18,-1,1)
B(-6,-18,0,1)
B(-6,-18,1,1)
B(-6,-18,2,1)
B(-6,-18,3,1)
B(-6,-18,4,1)
B(-6,-18,5,1)
B(-6,-18,6,1)
B(-6,-18,7,1)
B(-6,-18,8,1)
B(-6,-17,-7,1)
B(-6,-17,-6,1)
B(-6,-17,-5,1)
B(-6,-17,-4,1)
B(-6,-17,-3,1)
B(-6,-17,-2,1)
B(-6,-17,-1,1)
B(-6,-17,0,1)
B(-6,-17,1,1)
B(-6,-17,2,1)
B(-6,-17,3,1)
B(-6,-17,4,1)
B(-6,-17,5,1)
B(-6,-17,6,1)
B(-6,-17,7,1)
B(-6,-17,8,1)
B(-6,-16,-7,1)
B(-6,-16,-6,1)
B(-6,-16,-5,1)
B(-6,-16,-4,1)
B(-6,-16,-3,1)
B(-6,-16,-2,1)
B(-6,-16,-1,1)
B(-6,-16,0,1)
B(-6,-16,1,1)
B(-6,-16,2,1)
B(-6,-16,3,1)
B(-6,-16,4,1)
B(-6,-16,5,1)
B(-6,-16,6,1)
B(-6,-16,7,1)
B(-6,-16,8,1)
B(-6,-15,-7,1)
B(-6,-15,-6,1)
B(-6,-15,-5,1)
B(-6,-15,-4,1)
B(-6,-15,-3,1)
B(-6,-15,-2,1)
B(-6,-15,-1,1)
B(-6,-15,0,1)
B(-6,-15,1,1)
B(-6,-15,2,1)
B(-6,-15,3,1)
B(-6,-15,4,1)
B(-6,-15,5,1)
B(-6,-15,6,1)
B(-6,-15,7,1)
B(-6,-15,8,1)
B(-6,-14,-7,1)
B(-6,-14,-6,1)
B(-6,-14,-5,1)
B(-6,-14,-4,1)
B(-6,-14,-3,1)
B(-6,-14,-2,1)
B(-6,-14,-1,1)
B(-6,-14,0,1)
B(-6,-14,1,1)
B(-6,-14,2,1)
B(-6,-14,3,1)
B(-6,-14,4,1)
B(-6,-14,5,1)
B(-6,-14,6,1)
B(-6,-14,7,1)
B(-6,-14,8,1)
B(-6,-13,-7,1)
B(-6,-13,-6,1)
B(-6,-13,-5,1)
B(-6,-13,-4,1)
B(-6,-13,-3,1)
B(-6,-13,-2,1)
B(-6,-13,-1,1)
B(-6,-13,0,1)
B(-6,-13,1,1)
B(-6,-13,2,1)
B(-6,-13,3,1)
B(-6,-13,4,1)
B(-6,-13,5,1)
B(-6,-13,6,1)
B(-6,-13,7,1)
B(-6,-13,8,1)
B(-6,-12,-7,1)
B(-6,-12,-6,1)
B(-6,-12,-5,1)
B(-6,-12,-4,1)
B(-6,-12,-3,1)
B(-6,-12,-2,1)
B(-6,-12,-1,1)
B(-6,-12,0,1)
B(-6,-12,1,1)
B(-6,-12,2,1)
B(-6,-12,3,1)
B(-6,-12,4,1)
B(-6,-12,5,1)
B(-6,-12,6,1)
B(-6,-12,7,1)
B(-6,-12,8,1)
B(-6,-11,-7,1)
B(-6,-11,-6,1)
B(-6,-11,-5,1)
B(-6,-11,-4,1)
B(-6,-11,-3,1)
B(-6,-11,-2,1)
B(-6,-11,-1,1)
B(-6,-11,0,1)
B(-6,-11,1,1)
B(-6,-11,2,1)
B(-6,-11,3,1)
B(-6,-11,4,1)
B(-6,-11,5,1)
B(-6,-11,6,1)
B(-6,-11,7,1)
B(-6,-11,8,1)
B(-6,-10,-7,1)
B(-6,-10,-6,1)
B(-6,-10,-5,1)
B(-6,-10,-4,1)
B(-6,-10,-3,1)
B(-6,-10,-2,1)
B(-6,-10,-1,1)
B(-6,-10,0,1)
B(-6,-10,1,1)
B(-6,-10,2,1)
B(-6,-10,3,1)
B(-6,-10,4,1)
B(-6,-10,5,1)
B(-6,-10,6,1)
B(-6,-10,7,1)
B(-6,-10,8,1)
B(-6,-9,-7,1)
B(-6,-9,-6,1)
B(-6,-9,-5,1)
B(-6,-9,-4,1)
B(-6,-9,-3,1)
B(-6,-9,-2,1)
B(-6,-9,-1,1)
B(-6,-9,0,1)
B(-6,-9,1,1)
B(-6,-9,2,1)
B(-6,-9,3,1)
B(-6,-9,4,1)
B(-6,-9,5,1)
B(-6,-9,6,1)
B(-6,-9,7,1)
B(-6,-9,8,1)
B(-6,-8,-7,1)
B(-6,-8,-6,1)
B(-6,-8,-5,1)
B(-6,-8,-4,1)
B(-6,-8,-3,1)
B(-6,-8,-2,1)
B(-6,-8,-1,1)
B(-6,-8,0,1)
B(-6,-8,1,1)
B(-6,-8,2,1)
B(-6,-8,3,1)
B(-6,-8,4,1)
B(-6,-8,5,1)
B(-6,-8,6,1)
B(-6,-8,7,1)
B(-6,-8,8,1)
B(-6,-7,-7,1)
B(-6,-7,-6,1)
B(-6,-7,-5,1)
B(-6,-7,-4,1)
B(-6,-7,-3,1)
B(-6,-7,-2,1)
B(-6,-7,-1,1)
B(-6,-7,0,1)
B(-6,-7,1,1)
B(-6,-7,2,1)
B(-6,-7,3,1)
B(-6,-7,4,1)
B(-6,-7,5,1)
B(-6,-7,6,1)
B(-6,-7,7,1)
B(-6,-7,8,1)
B(-6,-6,-6,1)
B(-6,-6,-5,1)
B(-6,-6,-4,1)
B(-6,-6,-3,1)
B(-6,-6,-2,1)
B(-6,-6,-1,1)
B(-6,-6,0,1)
B(-6,-6,1,1)
B(-6,-6,2,1)
B(-6,-6,3,1)
B(-6,-6,4,1)
B(-6,-6,5,1)
B(-6,-6,6,1)
B(-6,-6,7,1)
B(-6,-6,8,1)
B(-6,-5,-5,1)
B(-6,-5,-4,1)
B(-6,-5,-3,1)
B(-6,-5,-2,1)
B(-6,-5,-1,1)
B(-6,-5,0,1)
B(-6,-5,1,1)
B(-6,-5,2,1)
B(-6,-5,3,1)
B(-6,-5,4,1)
B(-6,-5,5,1)
B(-6,-5,6,1)
B(-6,-5,7,1)
B(-6,-5,8,1)
B(-6,-4,-4,1)
B(-6,-4,-3,1)
B(-6,-4,-2,1)
B(-6,-4,-1,1)
B(-6,-4,0,1)
B(-6,-4,1,1)
B(-6,-4,2,1)
B(-6,-4,3,1)
B(-6,-4,4,1)
B(-6,-4,5,1)
B(-6,-4,6,1)
B(-6,-4,7,1)
B(-6,-4,8,1)
B(-6,-3,-4,1)
B(-6,-3,-3,1)
B(-6,-3,-2,1)
B(-6,-3,-1,1)
B(-6,-3,0,1)
B(-6,-3,1,1)
B(-6,-3,2,1)
B(-6,-3,3,1)
B(-6,-3,4,1)
B(-6,-3,5,1)
B(-6,-3,6,1)
B(-6,-3,7,1)
B(-6,-3,8,1)
B(-6,-2,-6,AIR)
B(-6,-2,-5,AIR)
B(-6,-2,-4,1)
B(-6,-2,-3,1)
B(-6,-2,-2,1)
B(-6,-2,-1,1)
B(-6,-2,0,1)
B(-6,-2,1,1)
B(-6,-2,2,1)
B(-6,-2,3,1)
B(-6,-2,4,1)
B(-6,-2,5,1)
B(-6,-2,6,1)
B(-6,-2,7,1)
B(-6,-2,8,1)
B(-6,-1,-6,AIR)
B(-6,-1,-5,AIR)
B(-6,-1,-4,AIR)
B(-6,-1,-3,1)
B(-6,-1,-2,1)
B(-6,-1,-1,1)
B(-6,-1,0,1)
B(-6,-1,1,1)
B(-6,-1,2,1)
B(-6,-1,3,1)
B(-6,-1,4,1)
B(-6,-1,5,1)
B(-6,-1,6,1)
B(-6,-1,7,1)
B(-6,-1,8,1)
B(-6,0,-6,AIR)
B(-6,0,-5,AIR)
B(-6,0,-4,AIR)
B(-6,0,-3,1)
B(-6,0,-2,1)
B(-6,0,-1,1)
B(-6,0,0,98)
B(-6,0,1,98)
B(-6,0,2,98)
B(-6,0,3,98)
B(-6,0,4,98)
B(-6,0,5,98)
B(-6,0,6,98)
B(-6,0,7,1)
B(-6,0,8,1)
B(-6,1,-6,AIR)
B(-6,1,-5,AIR)
B(-6,1,-4,AIR)
B(-6,1,-3,AIR)
B(-6,1,-2,98)
B(-6,1,-1,1)
B(-6,1,0,98)
B(-6,1,1,98)
B(-6,1,2,98)
B(-6,1,3,98)
B(-6,1,4,98)
B(-6,1,5,98)
B(-6,1,6,98)
B(-6,1,7,1)
B(-6,1,8,1)
B(-6,2,-6,AIR)
B(-6,2,-5,AIR)
B(-6,2,-4,AIR)
B(-6,2,-3,AIR)
B(-6,2,-2,98)
B(-6,2,-1,1)
B(-6,2,0,98)
B(-6,2,1,98)
B(-6,2,2,98)
B(-6,2,3,98)
B(-6,2,4,98)
B(-6,2,5,98)
B(-6,2,6,98)
B(-6,2,7,1)
B(-6,2,8,1)
B(-6,3,-6,AIR)
B(-6,3,-5,AIR)
B(-6,3,-4,AIR)
B(-6,3,-3,AIR)
B(-6,3,-2,98)
B(-6,3,-1,1)
B(-6,3,0,98)
B(-6,3,1,98)
B(-6,3,2,98)
B(-6,3,3,98)
B(-6,3,4,98)
B(-6,3,5,98)
B(-6,3,6,98)
B(-6,3,7,1)
B(-6,3,8,1)
B(-6,4,-6,AIR)
B(-6,4,-5,AIR)
B(-6,4,-4,AIR)
B(-6,4,-3,AIR)
B(-6,4,-2,98)
B(-6,4,-1,1)
B(-6,4,0,98)
B(-6,4,1,98)
B(-6,4,2,98)
B(-6,4,3,98)
B(-6,4,4,98)
B(-6,4,5,98)
B(-6,4,6,98)
B(-6,4,7,1)
B(-6,4,8,1)
B(-6,5,-6,AIR)
B(-6,5,-5,AIR)
B(-6,5,-4,AIR)
B(-6,5,-3,AIR)
B(-6,5,-2,98)
B(-6,5,-1,98)
B(-6,5,0,98)
B(-6,5,1,98)
B(-6,5,2,98)
B(-6,5,3,98)
B(-6,5,4,98)
B(-6,5,5,98)
B(-6,5,6,98)
B(-6,5,7,1)
B(-6,5,8,1)
B(-6,6,-6,AIR)
B(-6,6,-5,AIR)
B(-6,6,-4,AIR)
B(-6,6,-3,AIR)
B(-6,6,-2,98)
B(-6,6,-1,98)
B(-6,6,0,98)
B(-6,6,1,98)
B(-6,6,2,98)
B(-6,6,3,98)
B(-6,6,4,98)
B(-6,6,5,98)
B(-6,6,6,98)
B(-6,6,7,1)
B(-6,6,8,98)
B(-6,7,-6,AIR)
B(-6,7,-5,AIR)
B(-6,7,-4,AIR)
B(-6,7,-3,AIR)
B(-6,7,-2,98)
B(-6,7,-1,98)
B(-6,7,0,98)
B(-6,7,1,98)
B(-6,7,2,98)
B(-6,7,3,98)
B(-6,7,4,98)
B(-6,7,5,98)
B(-6,7,6,98)
B(-6,7,7,1)
B(-6,7,8,98)
B(-6,8,-6,AIR)
B(-6,8,-5,AIR)
B(-6,8,-4,AIR)
B(-6,8,-3,AIR)
B(-6,8,-2,98)
B(-6,8,-1,98)
B(-6,8,0,98)
B(-6,8,1,98)
B(-6,8,2,98)
B(-6,8,3,98)
B(-6,8,4,98)
B(-6,8,5,98)
B(-6,8,6,98)
B(-6,8,7,98)
B(-6,8,8,98)
B(-6,9,-6,AIR)
B(-6,9,-5,AIR)
B(-6,9,-4,AIR)
B(-6,9,-3,AIR)
B(-6,9,-2,98)
B(-6,9,-1,98)
B(-6,9,0,98)
B(-6,9,1,98)
B(-6,9,2,98)
B(-6,9,3,98)
B(-6,9,4,98)
B(-6,9,5,98)
B(-6,9,6,98)
B(-6,9,7,98)
B(-6,9,8,98)
B(-6,10,-6,AIR)
B(-6,10,-5,AIR)
B(-6,10,-4,AIR)
B(-6,10,-3,AIR)
B(-6,10,-2,AIR)
B(-6,10,-1,98)
B(-6,10,0,98)
B(-6,10,1,98)
B(-6,10,2,98)
B(-6,10,3,98)
B(-6,10,4,98)
B(-6,10,5,98)
B(-6,10,6,98)
B(-6,10,7,98)
B(-6,10,8,AIR)
B(-6,11,-6,AIR)
B(-6,11,-5,AIR)
B(-6,11,-4,AIR)
B(-6,11,-3,AIR)
B(-6,11,-2,98)
B(-6,11,-1,98)
B(-6,11,0,98)
B(-6,11,1,98)
B(-6,11,2,98)
B(-6,11,3,98)
B(-6,11,4,98)
B(-6,11,5,98)
B(-6,11,6,98)
B(-6,11,7,98)
B(-6,11,8,98)
B(-6,12,-6,AIR)
B(-6,12,-5,AIR)
B(-6,12,-4,AIR)
B(-6,12,-3,AIR)
B(-6,12,-2,98)
B(-6,12,-1,98)
B(-6,12,0,98)
B(-6,12,1,98)
B(-6,12,2,98)
B(-6,12,3,98)
B(-6,12,4,98)
B(-6,12,5,98)
B(-6,12,6,98)
B(-6,12,7,98)
B(-6,12,8,98)
B(-6,13,-6,AIR)
B(-6,13,-5,AIR)
B(-6,13,-4,AIR)
B(-6,13,-3,AIR)
B(-6,13,-2,44)
B(-6,13,-1,98)
B(-6,13,0,98)
B(-6,13,1,98)
B(-6,13,2,98)
B(-6,13,3,98)
B(-6,13,4,98)
B(-6,13,5,98)
B(-6,13,6,98)
B(-6,13,7,98)
B(-6,13,8,44)
B(-6,14,-6,AIR)
B(-6,14,-5,AIR)
B(-6,14,-4,AIR)
B(-6,14,-3,AIR)
B(-6,14,-2,AIR)
B(-6,14,-1,98)
B(-6,14,0,159:7)
B(-6,14,1,159:7)
B(-6,14,2,159:7)
B(-6,14,3,101)
B(-6,14,4,159:7)
B(-6,14,5,159:7)
B(-6,14,6,159:7)
B(-6,14,7,98)
B(-6,14,8,AIR)
B(-6,15,-6,AIR)
B(-6,15,-5,AIR)
B(-6,15,-4,AIR)
B(-6,15,-3,AIR)
B(-6,15,-2,AIR)
B(-6,15,-1,98)
B(-6,15,0,159:7)
B(-6,15,1,159:7)
B(-6,15,2,159:7)
B(-6,15,3,101)
B(-6,15,4,159:7)
B(-6,15,5,159:7)
B(-6,15,6,159:7)
B(-6,15,7,98)
B(-6,15,8,AIR)
B(-6,16,-6,AIR)
B(-6,16,-5,AIR)
B(-6,16,-4,AIR)
B(-6,16,-3,AIR)
B(-6,16,-2,AIR)
B(-6,16,-1,98)
B(-6,16,0,159:7)
B(-6,16,1,159:7)
B(-6,16,2,159:7)
B(-6,16,3,101)
B(-6,16,4,159:7)
B(-6,16,5,159:7)
B(-6,16,6,159:7)
B(-6,16,7,98)
B(-6,16,8,AIR)
B(-6,17,-6,AIR)
B(-6,17,-5,AIR)
B(-6,17,-4,AIR)
B(-6,17,-3,AIR)
B(-6,17,-2,44:13)
B(-6,17,-1,98)
B(-6,17,0,98)
B(-6,17,1,98)
B(-6,17,2,98)
B(-6,17,3,98)
B(-6,17,4,98)
B(-6,17,5,98)
B(-6,17,6,98)
B(-6,17,7,98)
B(-6,17,8,44:13)
B(-6,18,-6,AIR)
B(-6,18,-5,AIR)
B(-6,18,-4,AIR)
B(-6,18,-3,AIR)
B(-6,18,-2,98)
B(-6,18,-1,98)
B(-6,18,0,98)
B(-6,18,1,98)
B(-6,18,2,98)
B(-6,18,3,98)
B(-6,18,4,98)
B(-6,18,5,98)
B(-6,18,6,98)
B(-6,18,7,98)
B(-6,18,8,98)
B(-6,19,-6,AIR)
B(-6,19,-5,AIR)
B(-6,19,-4,AIR)
B(-6,19,-3,AIR)
B(-6,19,-2,98)
B(-6,19,-1,AIR)
B(-6,19,0,AIR)
B(-6,19,1,AIR)
B(-6,19,2,AIR)
B(-6,19,3,AIR)
B(-6,19,4,AIR)
B(-6,19,5,AIR)
B(-6,19,6,AIR)
B(-6,19,7,AIR)
B(-6,19,8,98)
B(-6,20,-6,AIR)
B(-6,20,-5,AIR)
B(-6,20,-4,AIR)
B(-6,20,-3,AIR)
B(-6,20,-2,44)
B(-6,20,-1,AIR)
B(-6,20,0,AIR)
B(-6,20,1,AIR)
B(-6,20,2,AIR)
B(-6,20,3,AIR)
B(-6,20,4,AIR)
B(-6,20,5,AIR)
B(-6,20,6,AIR)
B(-6,20,7,AIR)
B(-6,20,8,44)
B(-6,21,-6,AIR)
B(-6,21,-5,AIR)
B(-6,21,-4,AIR)
B(-6,21,-3,AIR)
B(-6,21,-2,AIR)
B(-6,21,-1,AIR)
B(-6,21,0,AIR)
B(-6,21,1,AIR)
B(-6,21,2,AIR)
B(-6,21,3,AIR)
B(-6,21,4,AIR)
B(-6,21,5,AIR)
B(-6,21,6,AIR)
B(-6,21,7,AIR)
B(-6,21,8,AIR)
B(-6,22,-6,AIR)
B(-6,22,-5,AIR)
B(-6,22,-4,AIR)
B(-6,22,-3,AIR)
B(-6,22,-2,AIR)
B(-6,22,-1,AIR)
B(-6,22,0,AIR)
B(-6,22,1,AIR)
B(-6,22,2,AIR)
B(-6,22,3,AIR)
B(-6,22,4,AIR)
B(-6,22,5,AIR)
B(-6,22,6,AIR)
B(-6,22,7,AIR)
B(-6,22,8,AIR)
B(-6,23,-6,AIR)
B(-6,23,-5,AIR)
B(-6,23,-4,AIR)
B(-6,23,-3,AIR)
B(-6,23,-2,AIR)
B(-6,23,-1,AIR)
B(-6,23,0,AIR)
B(-6,23,1,AIR)
B(-6,23,2,AIR)
B(-6,23,3,AIR)
B(-6,23,4,AIR)
B(-6,23,5,AIR)
B(-6,23,6,AIR)
B(-6,23,7,AIR)
B(-6,23,8,AIR)
B(-6,24,-6,AIR)
B(-6,24,-5,AIR)
B(-6,24,-4,AIR)
B(-6,24,-3,AIR)
B(-6,24,-2,AIR)
B(-6,24,-1,AIR)
B(-6,24,0,AIR)
B(-6,24,1,AIR)
B(-6,24,2,AIR)
B(-6,24,3,AIR)
B(-6,24,4,AIR)
B(-6,24,5,AIR)
B(-6,24,6,AIR)
B(-6,24,7,AIR)
B(-6,24,8,AIR)
B(-6,25,-6,AIR)
B(-6,25,-5,AIR)
B(-6,25,-4,AIR)
B(-6,25,-3,AIR)
B(-6,25,-2,AIR)
B(-6,25,-1,AIR)
B(-6,25,0,AIR)
B(-6,25,1,AIR)
B(-6,25,2,AIR)
B(-6,25,3,AIR)
B(-6,25,4,AIR)
B(-6,25,5,AIR)
B(-6,25,6,AIR)
B(-6,25,7,AIR)
B(-6,25,8,AIR)
B(-6,26,-6,AIR)
B(-6,26,-5,AIR)
B(-6,26,-4,AIR)
B(-6,26,-3,AIR)
B(-6,26,-2,AIR)
B(-6,26,-1,AIR)
B(-6,26,0,AIR)
B(-6,26,1,AIR)
B(-6,26,2,AIR)
B(-6,26,3,AIR)
B(-6,26,4,AIR)
B(-6,26,5,AIR)
B(-6,26,6,AIR)
B(-6,26,7,AIR)
B(-6,26,8,AIR)
B(-6,27,-6,AIR)
B(-6,27,-5,AIR)
B(-6,27,-4,AIR)
B(-6,27,-3,AIR)
B(-6,27,-2,AIR)
B(-6,27,-1,AIR)
B(-6,27,0,AIR)
B(-6,27,1,AIR)
B(-6,27,2,AIR)
B(-6,27,3,AIR)
B(-6,27,4,AIR)
B(-6,27,5,AIR)
B(-6,27,6,AIR)
B(-6,27,7,AIR)
B(-6,27,8,AIR)
B(-6,28,-6,AIR)
B(-6,28,-5,AIR)
B(-6,28,-4,AIR)
B(-6,28,-3,AIR)
B(-6,28,-2,AIR)
B(-6,28,-1,AIR)
B(-6,28,0,AIR)
B(-6,28,1,AIR)
B(-6,28,2,AIR)
B(-6,28,3,AIR)
B(-6,28,4,AIR)
B(-6,28,5,AIR)
B(-6,28,6,AIR)
B(-6,28,7,AIR)
B(-6,28,8,AIR)
B(-6,29,-6,AIR)
B(-6,29,-5,AIR)
B(-6,29,-4,AIR)
B(-6,29,-3,AIR)
B(-6,29,-2,AIR)
B(-6,29,-1,AIR)
B(-6,29,0,AIR)
B(-6,29,1,AIR)
B(-6,29,2,AIR)
B(-6,29,3,AIR)
B(-6,29,4,AIR)
B(-6,29,5,AIR)
B(-6,29,6,AIR)
B(-6,29,7,AIR)
B(-6,29,8,AIR)
B(-6,30,-6,AIR)
B(-6,30,-5,AIR)
B(-6,30,-4,AIR)
B(-6,30,-3,AIR)
B(-6,30,-2,AIR)
B(-6,30,-1,AIR)
B(-6,30,0,AIR)
B(-6,30,1,AIR)
B(-6,30,2,AIR)
B(-6,30,3,AIR)
B(-6,30,4,AIR)
B(-6,30,5,AIR)
B(-6,30,6,AIR)
B(-6,30,7,AIR)
B(-6,30,8,AIR)
B(-6,31,-6,AIR)
B(-6,31,-5,AIR)
B(-6,31,-4,AIR)
B(-6,31,-3,AIR)
B(-6,31,-2,AIR)
B(-6,31,-1,AIR)
B(-6,31,0,AIR)
B(-6,31,1,AIR)
B(-6,31,2,AIR)
B(-6,31,3,AIR)
B(-6,31,4,AIR)
B(-6,31,5,AIR)
B(-6,31,6,AIR)
B(-6,31,7,AIR)
B(-6,31,8,AIR)
B(-6,32,-6,AIR)
B(-6,32,-5,AIR)
B(-6,32,-4,AIR)
B(-6,32,-3,AIR)
B(-6,32,-2,AIR)
B(-6,32,-1,AIR)
B(-6,32,0,AIR)
B(-6,32,1,AIR)
B(-6,32,2,AIR)
B(-6,32,3,AIR)
B(-6,32,4,AIR)
B(-6,32,5,AIR)
B(-6,32,6,AIR)
B(-6,32,7,AIR)
B(-6,32,8,AIR)
B(-5,-31,-7,1)
B(-5,-31,-6,1)
B(-5,-31,-5,1)
B(-5,-31,-4,1)
B(-5,-31,-3,1)
B(-5,-31,-2,1)
B(-5,-31,-1,1)
B(-5,-31,0,1)
B(-5,-31,1,1)
B(-5,-31,2,1)
B(-5,-31,3,1)
B(-5,-31,4,1)
B(-5,-31,5,1)
B(-5,-31,6,1)
B(-5,-31,7,1)
B(-5,-31,8,1)
B(-5,-30,-7,1)
B(-5,-30,-6,1)
B(-5,-30,-5,1)
B(-5,-30,-4,1)
B(-5,-30,-3,1)
B(-5,-30,-2,1)
B(-5,-30,-1,1)
B(-5,-30,0,1)
B(-5,-30,1,1)
B(-5,-30,2,1)
B(-5,-30,3,1)
B(-5,-30,4,1)
B(-5,-30,5,1)
B(-5,-30,6,1)
B(-5,-30,7,1)
B(-5,-30,8,1)
B(-5,-29,-7,1)
B(-5,-29,-6,1)
B(-5,-29,-5,1)
B(-5,-29,-4,1)
B(-5,-29,-3,1)
B(-5,-29,-2,1)
B(-5,-29,-1,1)
B(-5,-29,0,1)
B(-5,-29,1,1)
B(-5,-29,2,1)
B(-5,-29,3,1)
B(-5,-29,4,1)
B(-5,-29,5,1)
B(-5,-29,6,1)
B(-5,-29,7,1)
B(-5,-29,8,1)
B(-5,-28,-7,1)
B(-5,-28,-6,1)
B(-5,-28,-5,1)
B(-5,-28,-4,1)
B(-5,-28,-3,1)
B(-5,-28,-2,1)
B(-5,-28,-1,1)
B(-5,-28,0,1)
B(-5,-28,1,1)
B(-5,-28,2,1)
B(-5,-28,3,1)
B(-5,-28,4,1)
B(-5,-28,5,1)
B(-5,-28,6,1)
B(-5,-28,7,1)
B(-5,-28,8,1)
B(-5,-27,-7,1)
B(-5,-27,-6,1)
B(-5,-27,-5,1)
B(-5,-27,-4,1)
B(-5,-27,-3,1)
B(-5,-27,-2,1)
B(-5,-27,-1,1)
B(-5,-27,0,1)
B(-5,-27,1,1)
B(-5,-27,2,1)
B(-5,-27,3,1)
B(-5,-27,4,1)
B(-5,-27,5,1)
B(-5,-27,6,1)
B(-5,-27,7,1)
B(-5,-27,8,1)
B(-5,-26,-7,1)
B(-5,-26,-6,1)
B(-5,-26,-5,1)
B(-5,-26,-4,1)
B(-5,-26,-3,1)
B(-5,-26,-2,1)
B(-5,-26,-1,1)
B(-5,-26,0,1)
B(-5,-26,1,1)
B(-5,-26,2,1)
B(-5,-26,3,1)
B(-5,-26,4,1)
B(-5,-26,5,1)
B(-5,-26,6,1)
B(-5,-26,7,1)
B(-5,-26,8,1)
B(-5,-25,-7,1)
B(-5,-25,-6,1)
B(-5,-25,-5,1)
B(-5,-25,-4,1)
B(-5,-25,-3,1)
B(-5,-25,-2,1)
B(-5,-25,-1,1)
B(-5,-25,0,1)
B(-5,-25,1,1)
B(-5,-25,2,1)
B(-5,-25,3,1)
B(-5,-25,4,1)
B(-5,-25,5,1)
B(-5,-25,6,1)
B(-5,-25,7,1)
B(-5,-25,8,1)
B(-5,-24,-7,1)
B(-5,-24,-6,1)
B(-5,-24,-5,1)
B(-5,-24,-4,1)
B(-5,-24,-3,1)
B(-5,-24,-2,1)
B(-5,-24,-1,1)
B(-5,-24,0,1)
B(-5,-24,1,1)
B(-5,-24,2,1)
B(-5,-24,3,1)
B(-5,-24,4,1)
B(-5,-24,5,1)
B(-5,-24,6,1)
B(-5,-24,7,1)
B(-5,-24,8,1)
B(-5,-23,-7,1)
B(-5,-23,-6,1)
B(-5,-23,-5,1)
B(-5,-23,-4,1)
B(-5,-23,-3,1)
B(-5,-23,-2,1)
B(-5,-23,-1,1)
B(-5,-23,0,1)
B(-5,-23,1,1)
B(-5,-23,2,1)
B(-5,-23,3,1)
B(-5,-23,4,1)
B(-5,-23,5,1)
B(-5,-23,6,1)
B(-5,-23,7,1)
B(-5,-23,8,1)
B(-5,-22,-7,1)
B(-5,-22,-6,1)
B(-5,-22,-5,1)
B(-5,-22,-4,1)
B(-5,-22,-3,1)
B(-5,-22,-2,1)
B(-5,-22,-1,1)
B(-5,-22,0,1)
B(-5,-22,1,1)
B(-5,-22,2,1)
B(-5,-22,3,1)
B(-5,-22,4,1)
B(-5,-22,5,1)
B(-5,-22,6,1)
B(-5,-22,7,1)
B(-5,-22,8,1)
B(-5,-21,-6,1)
B(-5,-21,-5,1)
B(-5,-21,-4,1)
B(-5,-21,-3,1)
B(-5,-21,-2,1)
B(-5,-21,-1,1)
B(-5,-21,0,1)
B(-5,-21,1,1)
B(-5,-21,2,1)
B(-5,-21,3,1)
B(-5,-21,4,1)
B(-5,-21,5,1)
B(-5,-21,6,1)
B(-5,-21,7,1)
B(-5,-21,8,1)
B(-5,-20,-7,1)
B(-5,-20,-6,1)
B(-5,-20,-5,1)
B(-5,-20,-4,1)
B(-5,-20,-3,1)
B(-5,-20,-2,1)
B(-5,-20,-1,1)
B(-5,-20,0,1)
B(-5,-20,1,1)
B(-5,-20,2,1)
B(-5,-20,3,1)
B(-5,-20,4,1)
B(-5,-20,5,1)
B(-5,-20,6,1)
B(-5,-20,7,1)
B(-5,-20,8,1)
B(-5,-19,-7,1)
B(-5,-19,-6,1)
B(-5,-19,-5,1)
B(-5,-19,-4,1)
B(-5,-19,-3,1)
B(-5,-19,-2,1)
B(-5,-19,-1,1)
B(-5,-19,0,1)
B(-5,-19,1,1)
B(-5,-19,2,1)
B(-5,-19,3,1)
B(-5,-19,4,1)
B(-5,-19,5,1)
B(-5,-19,6,1)
B(-5,-19,7,1)
B(-5,-19,8,1)
B(-5,-18,-7,1)
B(-5,-18,-6,1)
B(-5,-18,-5,1)
B(-5,-18,-4,1)
B(-5,-18,-3,1)
B(-5,-18,-2,1)
B(-5,-18,-1,1)
B(-5,-18,0,1)
B(-5,-18,1,1)
B(-5,-18,2,1)
B(-5,-18,3,1)
B(-5,-18,4,1)
B(-5,-18,5,1)
B(-5,-18,6,1)
B(-5,-18,7,1)
B(-5,-18,8,1)
B(-5,-17,-7,1)
B(-5,-17,-6,1)
B(-5,-17,-5,1)
B(-5,-17,-4,1)
B(-5,-17,-3,1)
B(-5,-17,-2,1)
B(-5,-17,-1,1)
B(-5,-17,0,1)
B(-5,-17,1,1)
B(-5,-17,2,1)
B(-5,-17,3,1)
B(-5,-17,4,1)
B(-5,-17,5,1)
B(-5,-17,6,1)
B(-5,-17,7,1)
B(-5,-17,8,1)
B(-5,-16,-7,1)
B(-5,-16,-6,1)
B(-5,-16,-5,1)
B(-5,-16,-4,1)
B(-5,-16,-3,1)
B(-5,-16,-2,1)
B(-5,-16,-1,1)
B(-5,-16,0,1)
B(-5,-16,1,1)
B(-5,-16,2,1)
B(-5,-16,3,1)
B(-5,-16,4,1)
B(-5,-16,5,1)
B(-5,-16,6,1)
B(-5,-16,7,1)
B(-5,-16,8,1)
B(-5,-15,-7,1)
B(-5,-15,-6,1)
B(-5,-15,-5,1)
B(-5,-15,-4,1)
B(-5,-15,-3,1)
B(-5,-15,-2,1)
B(-5,-15,-1,1)
B(-5,-15,0,1)
B(-5,-15,1,1)
B(-5,-15,2,1)
B(-5,-15,3,1)
B(-5,-15,4,1)
B(-5,-15,5,1)
B(-5,-15,6,1)
B(-5,-15,7,1)
B(-5,-15,8,1)
B(-5,-14,-7,1)
B(-5,-14,-6,1)
B(-5,-14,-5,1)
B(-5,-14,-4,1)
B(-5,-14,-3,1)
B(-5,-14,-2,1)
B(-5,-14,-1,1)
B(-5,-14,0,1)
B(-5,-14,1,1)
B(-5,-14,2,1)
B(-5,-14,3,1)
B(-5,-14,4,1)
B(-5,-14,5,1)
B(-5,-14,6,1)
B(-5,-14,7,1)
B(-5,-14,8,1)
B(-5,-13,-7,1)
B(-5,-13,-6,1)
B(-5,-13,-5,1)
B(-5,-13,-4,1)
B(-5,-13,-3,1)
B(-5,-13,-2,1)
B(-5,-13,-1,1)
B(-5,-13,0,1)
B(-5,-13,1,1)
B(-5,-13,2,1)
B(-5,-13,3,1)
B(-5,-13,4,1)
B(-5,-13,5,1)
B(-5,-13,6,1)
B(-5,-13,7,1)
B(-5,-13,8,1)
B(-5,-12,-7,1)
B(-5,-12,-6,1)
B(-5,-12,-5,1)
B(-5,-12,-4,1)
B(-5,-12,-3,1)
B(-5,-12,-2,1)
B(-5,-12,-1,1)
B(-5,-12,0,1)
B(-5,-12,1,1)
B(-5,-12,2,1)
B(-5,-12,3,1)
B(-5,-12,4,1)
B(-5,-12,5,1)
B(-5,-12,6,1)
B(-5,-12,7,1)
B(-5,-12,8,1)
B(-5,-11,-7,1)
B(-5,-11,-6,1)
B(-5,-11,-5,1)
B(-5,-11,-4,1)
B(-5,-11,-3,1)
B(-5,-11,-2,1)
B(-5,-11,-1,1)
B(-5,-11,0,1)
B(-5,-11,1,1)
B(-5,-11,2,1)
B(-5,-11,3,1)
B(-5,-11,4,1)
B(-5,-11,5,1)
B(-5,-11,6,1)
B(-5,-11,7,1)
B(-5,-11,8,1)
B(-5,-10,-7,1)
B(-5,-10,-6,1)
B(-5,-10,-5,1)
B(-5,-10,-4,1)
B(-5,-10,-3,1)
B(-5,-10,-2,1)
B(-5,-10,-1,1)
B(-5,-10,0,1)
B(-5,-10,1,1)
B(-5,-10,2,1)
B(-5,-10,3,1)
B(-5,-10,4,1)
B(-5,-10,5,1)
B(-5,-10,6,1)
B(-5,-10,7,1)
B(-5,-10,8,1)
B(-5,-9,-7,1)
B(-5,-9,-6,1)
B(-5,-9,-5,1)
B(-5,-9,-4,1)
B(-5,-9,-3,1)
B(-5,-9,-2,1)
B(-5,-9,-1,1)
B(-5,-9,0,1)
B(-5,-9,1,1)
B(-5,-9,2,1)
B(-5,-9,3,1)
B(-5,-9,4,1)
B(-5,-9,5,1)
B(-5,-9,6,1)
B(-5,-9,7,1)
B(-5,-9,8,1)
B(-5,-8,-7,1)
B(-5,-8,-6,1)
B(-5,-8,-5,1)
B(-5,-8,-4,1)
B(-5,-8,-3,1)
B(-5,-8,-2,1)
B(-5,-8,-1,1)
B(-5,-8,0,1)
B(-5,-8,1,1)
B(-5,-8,2,1)
B(-5,-8,3,1)
B(-5,-8,4,1)
B(-5,-8,5,1)
B(-5,-8,6,1)
B(-5,-8,7,1)
B(-5,-8,8,1)
B(-5,-7,-7,1)
B(-5,-7,-6,1)
B(-5,-7,-5,1)
B(-5,-7,-4,1)
B(-5,-7,-3,1)
B(-5,-7,-2,1)
B(-5,-7,-1,1)
B(-5,-7,0,1)
B(-5,-7,1,1)
B(-5,-7,2,1)
B(-5,-7,3,1)
B(-5,-7,4,1)
B(-5,-7,5,1)
B(-5,-7,6,1)
B(-5,-7,7,1)
B(-5,-7,8,1)
B(-5,-6,-7,1)
B(-5,-6,-6,1)
B(-5,-6,-5,1)
B(-5,-6,-4,1)
B(-5,-6,-3,1)
B(-5,-6,-2,1)
B(-5,-6,-1,1)
B(-5,-6,0,1)
B(-5,-6,1,1)
B(-5,-6,2,1)
B(-5,-6,3,1)
B(-5,-6,4,1)
B(-5,-6,5,1)
B(-5,-6,6,1)
B(-5,-6,7,1)
B(-5,-6,8,1)
B(-5,-5,-6,1)
B(-5,-5,-5,1)
B(-5,-5,-4,1)
B(-5,-5,-3,1)
B(-5,-5,-2,1)
B(-5,-5,-1,1)
B(-5,-5,0,1)
B(-5,-5,1,1)
B(-5,-5,2,1)
B(-5,-5,3,1)
B(-5,-5,4,1)
B(-5,-5,5,1)
B(-5,-5,6,1)
B(-5,-5,7,1)
B(-5,-5,8,1)
B(-5,-4,-4,1)
B(-5,-4,-3,1)
B(-5,-4,-2,1)
B(-5,-4,-1,1)
B(-5,-4,0,1)
B(-5,-4,1,1)
B(-5,-4,2,1)
B(-5,-4,3,1)
B(-5,-4,4,1)
B(-5,-4,5,1)
B(-5,-4,6,1)
B(-5,-4,7,1)
B(-5,-4,8,1)
B(-5,-3,-4,1)
B(-5,-3,-3,1)
B(-5,-3,-2,1)
B(-5,-3,-1,1)
B(-5,-3,0,1)
B(-5,-3,1,1)
B(-5,-3,2,1)
B(-5,-3,3,1)
B(-5,-3,4,1)
B(-5,-3,5,1)
B(-5,-3,6,1)
B(-5,-3,7,1)
B(-5,-3,8,1)
B(-5,-2,-6,AIR)
B(-5,-2,-5,AIR)
B(-5,-2,-4,AIR)
B(-5,-2,-3,1)
B(-5,-2,-2,1)
B(-5,-2,-1,1)
B(-5,-2,0,1)
B(-5,-2,1,1)
B(-5,-2,2,1)
B(-5,-2,3,1)
B(-5,-2,4,1)
B(-5,-2,5,1)
B(-5,-2,6,1)
B(-5,-2,7,1)
B(-5,-2,8,1)
B(-5,-1,-6,AIR)
B(-5,-1,-5,AIR)
B(-5,-1,-4,AIR)
B(-5,-1,-3,1)
B(-5,-1,-2,1)
B(-5,-1,-1,1)
B(-5,-1,0,1)
B(-5,-1,1,1)
B(-5,-1,2,1)
B(-5,-1,3,1)
B(-5,-1,4,1)
B(-5,-1,5,1)
B(-5,-1,6,1)
B(-5,-1,7,1)
B(-5,-1,8,1)
B(-5,0,-6,AIR)
B(-5,0,-5,AIR)
B(-5,0,-4,AIR)
B(-5,0,-3,AIR)
B(-5,0,-2,98)
B(-5,0,-1,1)
B(-5,0,0,1)
B(-5,0,1,1)
B(-5,0,2,1)
B(-5,0,3,1)
B(-5,0,4,1)
B(-5,0,5,1)
B(-5,0,6,1)
B(-5,0,7,1)
B(-5,0,8,1)
B(-5,1,-6,AIR)
B(-5,1,-5,AIR)
B(-5,1,-4,AIR)
B(-5,1,-3,AIR)
B(-5,1,-2,98)
B(-5,1,-1,1)
B(-5,1,0,1)
B(-5,1,1,1)
B(-5,1,2,1)
B(-5,1,3,1)
B(-5,1,4,1)
B(-5,1,5,1)
B(-5,1,6,1)
B(-5,1,7,1)
B(-5,1,8,1)
B(-5,2,-6,AIR)
B(-5,2,-5,AIR)
B(-5,2,-4,AIR)
B(-5,2,-3,AIR)
B(-5,2,-2,98)
B(-5,2,-1,98)
B(-5,2,0,1)
B(-5,2,1,1)
B(-5,2,2,1)
B(-5,2,3,1)
B(-5,2,4,1)
B(-5,2,5,1)
B(-5,2,6,1)
B(-5,2,7,1)
B(-5,2,8,1)
B(-5,3,-6,AIR)
B(-5,3,-5,AIR)
B(-5,3,-4,AIR)
B(-5,3,-3,AIR)
B(-5,3,-2,98)
B(-5,3,-1,98)
B(-5,3,0,1)
B(-5,3,1,1)
B(-5,3,2,1)
B(-5,3,3,1)
B(-5,3,4,1)
B(-5,3,5,1)
B(-5,3,6,1)
B(-5,3,7,1)
B(-5,3,8,1)
B(-5,4,-6,AIR)
B(-5,4,-5,AIR)
B(-5,4,-4,AIR)
B(-5,4,-3,AIR)
B(-5,4,-2,98)
B(-5,4,-1,98)
B(-5,4,0,98)
B(-5,4,1,98)
B(-5,4,2,98)
B(-5,4,3,98)
B(-5,4,4,98)
B(-5,4,5,98)
B(-5,4,6,98)
B(-5,4,7,98)
B(-5,4,8,98)
B(-5,5,-6,AIR)
B(-5,5,-5,AIR)
B(-5,5,-4,AIR)
B(-5,5,-3,AIR)
B(-5,5,-2,98)
B(-5,5,-1,98)
B(-5,5,0,98)
B(-5,5,1,98)
B(-5,5,2,98)
B(-5,5,3,98)
B(-5,5,4,98)
B(-5,5,5,98)
B(-5,5,6,98)
B(-5,5,7,98)
B(-5,5,8,98)
B(-5,6,-6,AIR)
B(-5,6,-5,AIR)
B(-5,6,-4,AIR)
B(-5,6,-3,AIR)
B(-5,6,-2,98)
B(-5,6,-1,98)
B(-5,6,0,AIR)
B(-5,6,1,AIR)
B(-5,6,2,98)
B(-5,6,3,159:7)
B(-5,6,4,98)
B(-5,6,5,AIR)
B(-5,6,6,AIR)
B(-5,6,7,98)
B(-5,6,8,98)
B(-5,7,-6,AIR)
B(-5,7,-5,AIR)
B(-5,7,-4,AIR)
B(-5,7,-3,AIR)
B(-5,7,-2,98)
B(-5,7,-1,98)
B(-5,7,0,AIR)
B(-5,7,1,AIR)
B(-5,7,2,98)
B(-5,7,3,159:7)
B(-5,7,4,98)
B(-5,7,5,AIR)
B(-5,7,6,AIR)
B(-5,7,7,98)
B(-5,7,8,98)
B(-5,8,-6,AIR)
B(-5,8,-5,AIR)
B(-5,8,-4,AIR)
B(-5,8,-3,AIR)
B(-5,8,-2,98)
B(-5,8,-1,98)
B(-5,8,0,AIR)
B(-5,8,1,AIR)
B(-5,8,2,98)
B(-5,8,3,159:7)
B(-5,8,4,98)
B(-5,8,5,AIR)
B(-5,8,6,AIR)
B(-5,8,7,98)
B(-5,8,8,98)
B(-5,9,-6,AIR)
B(-5,9,-5,AIR)
B(-5,9,-4,AIR)
B(-5,9,-3,AIR)
B(-5,9,-2,98)
B(-5,9,-1,98)
B(-5,9,0,AIR)
B(-5,9,1,AIR)
B(-5,9,2,98)
B(-5,9,3,98)
B(-5,9,4,98)
B(-5,9,5,AIR)
B(-5,9,6,AIR)
B(-5,9,7,98)
B(-5,9,8,98)
B(-5,10,-6,AIR)
B(-5,10,-5,AIR)
B(-5,10,-4,AIR)
B(-5,10,-3,AIR)
B(-5,10,-2,AIR)
B(-5,10,-1,AIR)
B(-5,10,0,AIR)
B(-5,10,1,AIR)
B(-5,10,2,44:13)
B(-5,10,3,44:13)
B(-5,10,4,44:13)
B(-5,10,5,AIR)
B(-5,10,6,AIR)
B(-5,10,7,AIR)
B(-5,10,8,AIR)
B(-5,11,-6,AIR)
B(-5,11,-5,AIR)
B(-5,11,-4,AIR)
B(-5,11,-3,AIR)
B(-5,11,-2,98)
B(-5,11,-1,98)
B(-5,11,0,98)
B(-5,11,1,98)
B(-5,11,2,98)
B(-5,11,3,98:3)
B(-5,11,4,98)
B(-5,11,5,98)
B(-5,11,6,98)
B(-5,11,7,98)
B(-5,11,8,98)
B(-5,12,-6,AIR)
B(-5,12,-5,AIR)
B(-5,12,-4,AIR)
B(-5,12,-3,AIR)
B(-5,12,-2,98)
B(-5,12,-1,98)
B(-5,12,0,44:5)
B(-5,12,1,44:5)
B(-5,12,2,98)
B(-5,12,3,98)
B(-5,12,4,98)
B(-5,12,5,44:5)
B(-5,12,6,44:5)
B(-5,12,7,98)
B(-5,12,8,98)
B(-5,13,-6,AIR)
B(-5,13,-5,AIR)
B(-5,13,-4,AIR)
B(-5,13,-3,AIR)
B(-5,13,-2,44)
B(-5,13,-1,44)
B(-5,13,0,AIR)
B(-5,13,1,AIR)
B(-5,13,2,44)
B(-5,13,3,44)
B(-5,13,4,44)
B(-5,13,5,AIR)
B(-5,13,6,AIR)
B(-5,13,7,44)
B(-5,13,8,44)
B(-5,14,-6,AIR)
B(-5,14,-5,AIR)
B(-5,14,-4,AIR)
B(-5,14,-3,AIR)
B(-5,14,-2,AIR)
B(-5,14,-1,AIR)
B(-5,14,0,AIR)
B(-5,14,1,AIR)
B(-5,14,2,AIR)
B(-5,14,3,AIR)
B(-5,14,4,AIR)
B(-5,14,5,AIR)
B(-5,14,6,AIR)
B(-5,14,7,AIR)
B(-5,14,8,AIR)
B(-5,15,-6,AIR)
B(-5,15,-5,AIR)
B(-5,15,-4,AIR)
B(-5,15,-3,AIR)
B(-5,15,-2,AIR)
B(-5,15,-1,AIR)
B(-5,15,0,AIR)
B(-5,15,1,AIR)
B(-5,15,2,AIR)
B(-5,15,3,AIR)
B(-5,15,4,AIR)
B(-5,15,5,AIR)
B(-5,15,6,AIR)
B(-5,15,7,AIR)
B(-5,15,8,AIR)
B(-5,16,-6,AIR)
B(-5,16,-5,AIR)
B(-5,16,-4,AIR)
B(-5,16,-3,AIR)
B(-5,16,-2,AIR)
B(-5,16,-1,AIR)
B(-5,16,0,AIR)
B(-5,16,1,AIR)
B(-5,16,2,AIR)
B(-5,16,3,AIR)
B(-5,16,4,AIR)
B(-5,16,5,AIR)
B(-5,16,6,AIR)
B(-5,16,7,AIR)
B(-5,16,8,AIR)
B(-5,17,-6,AIR)
B(-5,17,-5,AIR)
B(-5,17,-4,AIR)
B(-5,17,-3,AIR)
B(-5,17,-2,AIR)
B(-5,17,-1,44:13)
B(-5,17,0,AIR)
B(-5,17,1,44:13)
B(-5,17,2,AIR)
B(-5,17,3,44:13)
B(-5,17,4,AIR)
B(-5,17,5,44:13)
B(-5,17,6,AIR)
B(-5,17,7,44:13)
B(-5,17,8,AIR)
B(-5,18,-6,AIR)
B(-5,18,-5,AIR)
B(-5,18,-4,AIR)
B(-5,18,-3,AIR)
B(-5,18,-2,98)
B(-5,18,-1,98)
B(-5,18,0,98)
B(-5,18,1,98)
B(-5,18,2,98)
B(-5,18,3,98)
B(-5,18,4,98)
B(-5,18,5,98)
B(-5,18,6,98)
B(-5,18,7,98)
B(-5,18,8,98)
B(-5,19,-6,AIR)
B(-5,19,-5,AIR)
B(-5,19,-4,AIR)
B(-5,19,-3,AIR)
B(-5,19,-2,98)
B(-5,19,-1,98)
B(-5,19,0,44:5)
B(-5,19,1,44:5)
B(-5,19,2,98)
B(-5,19,3,98)
B(-5,19,4,98)
B(-5,19,5,44:5)
B(-5,19,6,44:5)
B(-5,19,7,98)
B(-5,19,8,98)
B(-5,20,-6,AIR)
B(-5,20,-5,AIR)
B(-5,20,-4,AIR)
B(-5,20,-3,AIR)
B(-5,20,-2,44)
B(-5,20,-1,44)
B(-5,20,0,AIR)
B(-5,20,1,AIR)
B(-5,20,2,44)
B(-5,20,3,44)
B(-5,20,4,44)
B(-5,20,5,AIR)
B(-5,20,6,AIR)
B(-5,20,7,44)
B(-5,20,8,44)
B(-5,21,-6,AIR)
B(-5,21,-5,AIR)
B(-5,21,-4,AIR)
B(-5,21,-3,AIR)
B(-5,21,-2,AIR)
B(-5,21,-1,AIR)
B(-5,21,0,AIR)
B(-5,21,1,AIR)
B(-5,21,2,AIR)
B(-5,21,3,AIR)
B(-5,21,4,AIR)
B(-5,21,5,AIR)
B(-5,21,6,AIR)
B(-5,21,7,AIR)
B(-5,21,8,AIR)
B(-5,22,-6,AIR)
B(-5,22,-5,AIR)
B(-5,22,-4,AIR)
B(-5,22,-3,AIR)
B(-5,22,-2,AIR)
B(-5,22,-1,AIR)
B(-5,22,0,AIR)
B(-5,22,1,AIR)
B(-5,22,2,AIR)
B(-5,22,3,AIR)
B(-5,22,4,AIR)
B(-5,22,5,AIR)
B(-5,22,6,AIR)
B(-5,22,7,AIR)
B(-5,22,8,AIR)
B(-5,23,-6,AIR)
B(-5,23,-5,AIR)
B(-5,23,-4,AIR)
B(-5,23,-3,AIR)
B(-5,23,-2,AIR)
B(-5,23,-1,AIR)
B(-5,23,0,AIR)
B(-5,23,1,AIR)
B(-5,23,2,AIR)
B(-5,23,3,AIR)
B(-5,23,4,AIR)
B(-5,23,5,AIR)
B(-5,23,6,AIR)
B(-5,23,7,AIR)
B(-5,23,8,AIR)
B(-5,24,-6,AIR)
B(-5,24,-5,AIR)
B(-5,24,-4,AIR)
B(-5,24,-3,AIR)
B(-5,24,-2,AIR)
B(-5,24,-1,AIR)
B(-5,24,0,AIR)
B(-5,24,1,AIR)
B(-5,24,2,AIR)
B(-5,24,3,AIR)
B(-5,24,4,AIR)
B(-5,24,5,AIR)
B(-5,24,6,AIR)
B(-5,24,7,AIR)
B(-5,24,8,AIR)
B(-5,25,-6,AIR)
B(-5,25,-5,AIR)
B(-5,25,-4,AIR)
B(-5,25,-3,AIR)
B(-5,25,-2,AIR)
B(-5,25,-1,AIR)
B(-5,25,0,AIR)
B(-5,25,1,AIR)
B(-5,25,2,AIR)
B(-5,25,3,AIR)
B(-5,25,4,AIR)
B(-5,25,5,AIR)
B(-5,25,6,AIR)
B(-5,25,7,AIR)
B(-5,25,8,AIR)
B(-5,26,-6,AIR)
B(-5,26,-5,AIR)
B(-5,26,-4,AIR)
B(-5,26,-3,AIR)
B(-5,26,-2,AIR)
B(-5,26,-1,AIR)
B(-5,26,0,AIR)
B(-5,26,1,AIR)
B(-5,26,2,AIR)
B(-5,26,3,AIR)
B(-5,26,4,AIR)
B(-5,26,5,AIR)
B(-5,26,6,AIR)
B(-5,26,7,AIR)
B(-5,26,8,AIR)
B(-5,27,-6,AIR)
B(-5,27,-5,AIR)
B(-5,27,-4,AIR)
B(-5,27,-3,AIR)
B(-5,27,-2,AIR)
B(-5,27,-1,AIR)
B(-5,27,0,AIR)
B(-5,27,1,AIR)
B(-5,27,2,AIR)
B(-5,27,3,AIR)
B(-5,27,4,AIR)
B(-5,27,5,AIR)
B(-5,27,6,AIR)
B(-5,27,7,AIR)
B(-5,27,8,AIR)
B(-5,28,-6,AIR)
B(-5,28,-5,AIR)
B(-5,28,-4,AIR)
B(-5,28,-3,AIR)
B(-5,28,-2,AIR)
B(-5,28,-1,AIR)
B(-5,28,0,AIR)
B(-5,28,1,AIR)
B(-5,28,2,AIR)
B(-5,28,3,AIR)
B(-5,28,4,AIR)
B(-5,28,5,AIR)
B(-5,28,6,AIR)
B(-5,28,7,AIR)
B(-5,28,8,AIR)
B(-5,29,-6,AIR)
B(-5,29,-5,AIR)
B(-5,29,-4,AIR)
B(-5,29,-3,AIR)
B(-5,29,-2,AIR)
B(-5,29,-1,AIR)
B(-5,29,0,AIR)
B(-5,29,1,AIR)
B(-5,29,2,AIR)
B(-5,29,3,AIR)
B(-5,29,4,AIR)
B(-5,29,5,AIR)
B(-5,29,6,AIR)
B(-5,29,7,AIR)
B(-5,29,8,AIR)
B(-5,30,-6,AIR)
B(-5,30,-5,AIR)
B(-5,30,-4,AIR)
B(-5,30,-3,AIR)
B(-5,30,-2,AIR)
B(-5,30,-1,AIR)
B(-5,30,0,AIR)
B(-5,30,1,AIR)
B(-5,30,2,AIR)
B(-5,30,3,AIR)
B(-5,30,4,AIR)
B(-5,30,5,AIR)
B(-5,30,6,AIR)
B(-5,30,7,AIR)
B(-5,30,8,AIR)
B(-5,31,-6,AIR)
B(-5,31,-5,AIR)
B(-5,31,-4,AIR)
B(-5,31,-3,AIR)
B(-5,31,-2,AIR)
B(-5,31,-1,AIR)
B(-5,31,0,AIR)
B(-5,31,1,AIR)
B(-5,31,2,AIR)
B(-5,31,3,AIR)
B(-5,31,4,AIR)
B(-5,31,5,AIR)
B(-5,31,6,AIR)
B(-5,31,7,AIR)
B(-5,31,8,AIR)
B(-5,32,-6,AIR)
B(-5,32,-5,AIR)
B(-5,32,-4,AIR)
B(-5,32,-3,AIR)
B(-5,32,-2,AIR)
B(-5,32,-1,AIR)
B(-5,32,0,AIR)
B(-5,32,1,AIR)
B(-5,32,2,AIR)
B(-5,32,3,AIR)
B(-5,32,4,AIR)
B(-5,32,5,AIR)
B(-5,32,6,AIR)
B(-5,32,7,AIR)
B(-5,32,8,AIR)
B(-4,-31,-7,1)
B(-4,-31,-6,1)
B(-4,-31,-5,1)
B(-4,-31,-4,1)
B(-4,-31,-3,1)
B(-4,-31,-2,1)
B(-4,-31,-1,1)
B(-4,-31,0,1)
B(-4,-31,1,1)
B(-4,-31,2,1)
B(-4,-31,3,1)
B(-4,-31,4,1)
B(-4,-31,5,1)
B(-4,-31,6,1)
B(-4,-31,7,1)
B(-4,-31,8,1)
B(-4,-30,-7,1)
B(-4,-30,-6,1)
B(-4,-30,-5,1)
B(-4,-30,-4,1)
B(-4,-30,-3,1)
B(-4,-30,-2,1)
B(-4,-30,-1,1)
B(-4,-30,0,1)
B(-4,-30,1,1)
B(-4,-30,2,1)
B(-4,-30,3,1)
B(-4,-30,4,1)
B(-4,-30,5,1)
B(-4,-30,6,1)
B(-4,-30,7,1)
B(-4,-30,8,1)
B(-4,-29,-7,1)
B(-4,-29,-6,1)
B(-4,-29,-5,1)
B(-4,-29,-4,1)
B(-4,-29,-3,1)
B(-4,-29,-2,1)
B(-4,-29,-1,1)
B(-4,-29,0,1)
B(-4,-29,1,1)
B(-4,-29,2,1)
B(-4,-29,3,1)
B(-4,-29,4,1)
B(-4,-29,5,1)
B(-4,-29,6,1)
B(-4,-29,7,1)
B(-4,-29,8,1)
B(-4,-28,-7,1)
B(-4,-28,-6,1)
B(-4,-28,-5,1)
B(-4,-28,-4,1)
B(-4,-28,-3,1)
B(-4,-28,-2,1)
B(-4,-28,-1,1)
B(-4,-28,0,1)
B(-4,-28,1,1)
B(-4,-28,2,1)
B(-4,-28,3,1)
B(-4,-28,4,1)
B(-4,-28,5,1)
B(-4,-28,6,1)
B(-4,-28,7,1)
B(-4,-28,8,1)
B(-4,-27,-7,1)
B(-4,-27,-6,1)
B(-4,-27,-5,1)
B(-4,-27,-4,1)
B(-4,-27,-3,1)
B(-4,-27,-2,1)
B(-4,-27,-1,1)
B(-4,-27,0,1)
B(-4,-27,1,1)
B(-4,-27,2,1)
B(-4,-27,3,1)
B(-4,-27,4,1)
B(-4,-27,5,1)
B(-4,-27,6,1)
B(-4,-27,7,1)
B(-4,-27,8,1)
B(-4,-26,-7,1)
B(-4,-26,-6,1)
B(-4,-26,-5,1)
B(-4,-26,-4,1)
B(-4,-26,-3,1)
B(-4,-26,-2,1)
B(-4,-26,-1,1)
B(-4,-26,0,1)
B(-4,-26,1,1)
B(-4,-26,2,1)
B(-4,-26,3,1)
B(-4,-26,4,1)
B(-4,-26,5,1)
B(-4,-26,6,1)
B(-4,-26,7,1)
B(-4,-26,8,1)
B(-4,-25,-7,1)
B(-4,-25,-6,1)
B(-4,-25,-5,1)
B(-4,-25,-4,1)
B(-4,-25,-3,1)
B(-4,-25,-2,1)
B(-4,-25,-1,1)
B(-4,-25,0,1)
B(-4,-25,1,1)
B(-4,-25,2,1)
B(-4,-25,3,1)
B(-4,-25,4,1)
B(-4,-25,5,1)
B(-4,-25,6,1)
B(-4,-25,7,1)
B(-4,-25,8,1)
B(-4,-24,-7,1)
B(-4,-24,-6,1)
B(-4,-24,-5,1)
B(-4,-24,-4,1)
B(-4,-24,-3,1)
B(-4,-24,-2,1)
B(-4,-24,-1,1)
B(-4,-24,0,1)
B(-4,-24,1,1)
B(-4,-24,2,1)
B(-4,-24,3,1)
B(-4,-24,4,1)
B(-4,-24,5,1)
B(-4,-24,6,1)
B(-4,-24,7,1)
B(-4,-24,8,1)
B(-4,-23,-7,1)
B(-4,-23,-6,1)
B(-4,-23,-5,1)
B(-4,-23,-4,1)
B(-4,-23,-3,1)
B(-4,-23,-2,1)
B(-4,-23,-1,1)
B(-4,-23,0,1)
B(-4,-23,1,1)
B(-4,-23,2,1)
B(-4,-23,3,1)
B(-4,-23,4,1)
B(-4,-23,5,1)
B(-4,-23,6,1)
B(-4,-23,7,1)
B(-4,-23,8,1)
B(-4,-22,-7,1)
B(-4,-22,-6,1)
B(-4,-22,-5,1)
B(-4,-22,-4,1)
B(-4,-22,-3,1)
B(-4,-22,-2,1)
B(-4,-22,-1,1)
B(-4,-22,0,1)
B(-4,-22,1,1)
B(-4,-22,2,1)
B(-4,-22,3,1)
B(-4,-22,4,1)
B(-4,-22,5,1)
B(-4,-22,6,1)
B(-4,-22,7,1)
B(-4,-22,8,1)
B(-4,-21,-7,1)
B(-4,-21,-6,1)
B(-4,-21,-5,1)
B(-4,-21,-4,1)
B(-4,-21,-3,1)
B(-4,-21,-2,1)
B(-4,-21,-1,1)
B(-4,-21,0,1)
B(-4,-21,1,1)
B(-4,-21,2,1)
B(-4,-21,3,1)
B(-4,-21,4,1)
B(-4,-21,5,1)
B(-4,-21,6,1)
B(-4,-21,7,1)
B(-4,-21,8,1)
B(-4,-20,-7,1)
B(-4,-20,-6,1)
B(-4,-20,-5,1)
B(-4,-20,-4,1)
B(-4,-20,-3,1)
B(-4,-20,-2,1)
B(-4,-20,-1,1)
B(-4,-20,0,1)
B(-4,-20,1,1)
B(-4,-20,2,1)
B(-4,-20,3,1)
B(-4,-20,4,1)
B(-4,-20,5,1)
B(-4,-20,6,1)
B(-4,-20,7,1)
B(-4,-20,8,1)
B(-4,-19,-7,1)
B(-4,-19,-6,1)
B(-4,-19,-5,1)
B(-4,-19,-4,1)
B(-4,-19,-3,1)
B(-4,-19,-2,1)
B(-4,-19,-1,1)
B(-4,-19,0,1)
B(-4,-19,1,1)
B(-4,-19,2,1)
B(-4,-19,3,1)
B(-4,-19,4,1)
B(-4,-19,5,1)
B(-4,-19,6,1)
B(-4,-19,7,1)
B(-4,-19,8,1)
B(-4,-18,-7,1)
B(-4,-18,-6,1)
B(-4,-18,-5,1)
B(-4,-18,-4,1)
B(-4,-18,-3,1)
B(-4,-18,-2,1)
B(-4,-18,-1,1)
B(-4,-18,0,1)
B(-4,-18,1,1)
B(-4,-18,2,1)
B(-4,-18,3,1)
B(-4,-18,4,1)
B(-4,-18,5,1)
B(-4,-18,6,1)
B(-4,-18,7,1)
B(-4,-18,8,1)
B(-4,-17,-7,1)
B(-4,-17,-6,1)
B(-4,-17,-5,1)
B(-4,-17,-4,1)
B(-4,-17,-3,1)
B(-4,-17,-2,1)
B(-4,-17,-1,1)
B(-4,-17,0,1)
B(-4,-17,1,1)
B(-4,-17,2,1)
B(-4,-17,3,1)
B(-4,-17,4,1)
B(-4,-17,5,1)
B(-4,-17,6,1)
B(-4,-17,7,1)
B(-4,-17,8,1)
B(-4,-16,-7,1)
B(-4,-16,-6,1)
B(-4,-16,-5,1)
B(-4,-16,-4,1)
B(-4,-16,-3,1)
B(-4,-16,-2,1)
B(-4,-16,-1,1)
B(-4,-16,0,1)
B(-4,-16,1,1)
B(-4,-16,2,1)
B(-4,-16,3,1)
B(-4,-16,4,1)
B(-4,-16,5,1)
B(-4,-16,6,1)
B(-4,-16,7,1)
B(-4,-16,8,1)
B(-4,-15,-7,1)
B(-4,-15,-6,1)
B(-4,-15,-5,1)
B(-4,-15,-4,1)
B(-4,-15,-3,1)
B(-4,-15,-2,1)
B(-4,-15,-1,1)
B(-4,-15,0,1)
B(-4,-15,1,1)
B(-4,-15,2,1)
B(-4,-15,3,1)
B(-4,-15,4,1)
B(-4,-15,5,1)
B(-4,-15,6,1)
B(-4,-15,7,1)
B(-4,-15,8,1)
B(-4,-14,-7,1)
B(-4,-14,-6,1)
B(-4,-14,-5,1)
B(-4,-14,-4,1)
B(-4,-14,-3,1)
B(-4,-14,-2,1)
B(-4,-14,-1,1)
B(-4,-14,0,1)
B(-4,-14,1,1)
B(-4,-14,2,1)
B(-4,-14,3,1)
B(-4,-14,4,1)
B(-4,-14,5,1)
B(-4,-14,6,1)
B(-4,-14,7,1)
B(-4,-14,8,1)
B(-4,-13,-7,1)
B(-4,-13,-6,1)
B(-4,-13,-5,1)
B(-4,-13,-4,1)
B(-4,-13,-3,1)
B(-4,-13,-2,1)
B(-4,-13,-1,1)
B(-4,-13,0,1)
B(-4,-13,1,1)
B(-4,-13,2,1)
B(-4,-13,3,1)
B(-4,-13,4,1)
B(-4,-13,5,1)
B(-4,-13,6,1)
B(-4,-13,7,1)
B(-4,-13,8,1)
B(-4,-12,-7,1)
B(-4,-12,-6,1)
B(-4,-12,-5,1)
B(-4,-12,-4,1)
B(-4,-12,-3,1)
B(-4,-12,-2,1)
B(-4,-12,-1,1)
B(-4,-12,0,1)
B(-4,-12,1,1)
B(-4,-12,2,1)
B(-4,-12,3,1)
B(-4,-12,4,1)
B(-4,-12,5,1)
B(-4,-12,6,1)
B(-4,-12,7,1)
B(-4,-12,8,1)
B(-4,-11,-7,1)
B(-4,-11,-6,1)
B(-4,-11,-5,1)
B(-4,-11,-4,1)
B(-4,-11,-3,1)
B(-4,-11,-2,1)
B(-4,-11,-1,1)
B(-4,-11,0,1)
B(-4,-11,1,1)
B(-4,-11,2,1)
B(-4,-11,3,1)
B(-4,-11,4,1)
B(-4,-11,5,1)
B(-4,-11,6,1)
B(-4,-11,7,1)
B(-4,-11,8,1)
B(-4,-10,-7,1)
B(-4,-10,-6,1)
B(-4,-10,-5,1)
B(-4,-10,-4,1)
B(-4,-10,-3,1)
B(-4,-10,-2,1)
B(-4,-10,-1,1)
B(-4,-10,0,1)
B(-4,-10,1,1)
B(-4,-10,2,1)
B(-4,-10,3,1)
B(-4,-10,4,1)
B(-4,-10,5,1)
B(-4,-10,6,1)
B(-4,-10,7,1)
B(-4,-10,8,1)
B(-4,-9,-7,1)
B(-4,-9,-6,1)
B(-4,-9,-5,1)
B(-4,-9,-4,1)
B(-4,-9,-3,1)
B(-4,-9,-2,1)
B(-4,-9,-1,1)
B(-4,-9,0,1)
B(-4,-9,1,1)
B(-4,-9,2,1)
B(-4,-9,3,1)
B(-4,-9,4,1)
B(-4,-9,5,1)
B(-4,-9,6,1)
B(-4,-9,7,1)
B(-4,-9,8,1)
B(-4,-8,-7,1)
B(-4,-8,-6,1)
B(-4,-8,-5,1)
B(-4,-8,-4,1)
B(-4,-8,-3,1)
B(-4,-8,-2,1)
B(-4,-8,-1,1)
B(-4,-8,0,1)
B(-4,-8,1,1)
B(-4,-8,2,1)
B(-4,-8,3,1)
B(-4,-8,4,1)
B(-4,-8,5,1)
B(-4,-8,6,1)
B(-4,-8,7,1)
B(-4,-8,8,1)
B(-4,-7,-7,1)
B(-4,-7,-6,1)
B(-4,-7,-5,1)
B(-4,-7,-4,1)
B(-4,-7,-3,1)
B(-4,-7,-2,1)
B(-4,-7,-1,1)
B(-4,-7,0,1)
B(-4,-7,1,1)
B(-4,-7,2,1)
B(-4,-7,3,1)
B(-4,-7,4,1)
B(-4,-7,5,1)
B(-4,-7,6,1)
B(-4,-7,7,1)
B(-4,-7,8,1)
B(-4,-6,-7,1)
B(-4,-6,-6,1)
B(-4,-6,-5,1)
B(-4,-6,-4,1)
B(-4,-6,-3,1)
B(-4,-6,-2,1)
B(-4,-6,-1,1)
B(-4,-6,0,1)
B(-4,-6,1,1)
B(-4,-6,2,1)
B(-4,-6,3,1)
B(-4,-6,4,1)
B(-4,-6,5,1)
B(-4,-6,6,1)
B(-4,-6,7,1)
B(-4,-6,8,1)
B(-4,-5,-5,1)
B(-4,-5,-4,1)
B(-4,-5,-3,1)
B(-4,-5,-2,1)
B(-4,-5,-1,1)
B(-4,-5,0,1)
B(-4,-5,1,1)
B(-4,-5,2,1)
B(-4,-5,3,1)
B(-4,-5,4,1)
B(-4,-5,5,1)
B(-4,-5,6,1)
B(-4,-5,7,1)
B(-4,-5,8,1)
B(-4,-4,-4,1)
B(-4,-4,-3,1)
B(-4,-4,-2,1)
B(-4,-4,-1,1)
B(-4,-4,0,1)
B(-4,-4,1,1)
B(-4,-4,2,1)
B(-4,-4,3,1)
B(-4,-4,4,1)
B(-4,-4,5,1)
B(-4,-4,6,1)
B(-4,-4,7,1)
B(-4,-4,8,1)
B(-4,-3,-3,1)
B(-4,-3,-2,1)
B(-4,-3,-1,1)
B(-4,-3,0,1)
B(-4,-3,1,1)
B(-4,-3,2,1)
B(-4,-3,3,1)
B(-4,-3,4,1)
B(-4,-3,5,1)
B(-4,-3,6,1)
B(-4,-3,7,1)
B(-4,-3,8,1)
B(-4,-2,-6,AIR)
B(-4,-2,-5,AIR)
B(-4,-2,-4,AIR)
B(-4,-2,-3,1)
B(-4,-2,-2,1)
B(-4,-2,-1,1)
B(-4,-2,0,1)
B(-4,-2,1,1)
B(-4,-2,2,1)
B(-4,-2,3,1)
B(-4,-2,4,1)
B(-4,-2,5,1)
B(-4,-2,6,1)
B(-4,-2,7,1)
B(-4,-2,8,1)
B(-4,-1,-6,AIR)
B(-4,-1,-5,AIR)
B(-4,-1,-4,AIR)
B(-4,-1,-3,AIR)
B(-4,-1,-2,1)
B(-4,-1,-1,1)
B(-4,-1,0,1)
B(-4,-1,1,1)
B(-4,-1,2,1)
B(-4,-1,3,1)
B(-4,-1,4,1)
B(-4,-1,5,1)
B(-4,-1,6,1)
B(-4,-1,7,1)
B(-4,-1,8,1)
B(-4,0,-6,AIR)
B(-4,0,-5,AIR)
B(-4,0,-4,AIR)
B(-4,0,-3,AIR)
B(-4,0,-2,AIR)
B(-4,0,-1,1)
B(-4,0,0,1)
B(-4,0,1,1)
B(-4,0,2,1)
B(-4,0,3,1)
B(-4,0,4,1)
B(-4,0,5,1)
B(-4,0,6,1)
B(-4,0,7,1)
B(-4,0,8,1)
B(-4,1,-6,AIR)
B(-4,1,-5,AIR)
B(-4,1,-4,AIR)
B(-4,1,-3,AIR)
B(-4,1,-2,AIR)
B(-4,1,-1,1)
B(-4,1,0,1)
B(-4,1,1,1)
B(-4,1,2,1)
B(-4,1,3,1)
B(-4,1,4,1)
B(-4,1,5,1)
B(-4,1,6,1)
B(-4,1,7,1)
B(-4,1,8,1)
B(-4,2,-6,AIR)
B(-4,2,-5,AIR)
B(-4,2,-4,AIR)
B(-4,2,-3,AIR)
B(-4,2,-2,AIR)
B(-4,2,-1,AIR)
B(-4,2,0,1)
B(-4,2,1,1)
B(-4,2,2,1)
B(-4,2,3,1)
B(-4,2,4,1)
B(-4,2,5,1)
B(-4,2,6,1)
B(-4,2,7,1)
B(-4,2,8,1)
B(-4,3,-6,AIR)
B(-4,3,-5,AIR)
B(-4,3,-4,AIR)
B(-4,3,-3,AIR)
B(-4,3,-2,AIR)
B(-4,3,-1,AIR)
B(-4,3,0,1)
B(-4,3,1,1)
B(-4,3,2,1)
B(-4,3,3,1)
B(-4,3,4,1)
B(-4,3,5,1)
B(-4,3,6,1)
B(-4,3,7,1)
B(-4,3,8,1)
B(-4,4,-6,AIR)
B(-4,4,-5,AIR)
B(-4,4,-4,AIR)
B(-4,4,-3,AIR)
B(-4,4,-2,AIR)
B(-4,4,-1,AIR)
B(-4,4,0,AIR)
B(-4,4,1,AIR)
B(-4,4,2,1)
B(-4,4,3,1)
B(-4,4,4,1)
B(-4,4,5,1)
B(-4,4,6,1)
B(-4,4,7,AIR)
B(-4,4,8,AIR)
B(-4,5,-6,AIR)
B(-4,5,-5,AIR)
B(-4,5,-4,AIR)
B(-4,5,-3,AIR)
B(-4,5,-2,AIR)
B(-4,5,-1,AIR)
B(-4,5,0,AIR)
B(-4,5,1,AIR)
B(-4,5,2,AIR)
B(-4,5,3,1)
B(-4,5,4,1)
B(-4,5,5,1)
B(-4,5,6,AIR)
B(-4,5,7,AIR)
B(-4,5,8,AIR)
B(-4,6,-6,AIR)
B(-4,6,-5,AIR)
B(-4,6,-4,AIR)
B(-4,6,-3,AIR)
B(-4,6,-2,AIR)
B(-4,6,-1,AIR)
B(-4,6,0,AIR)
B(-4,6,1,AIR)
B(-4,6,2,AIR)
B(-4,6,3,1)
B(-4,6,4,1)
B(-4,6,5,AIR)
B(-4,6,6,AIR)
B(-4,6,7,AIR)
B(-4,6,8,AIR)
B(-4,7,-6,AIR)
B(-4,7,-5,AIR)
B(-4,7,-4,AIR)
B(-4,7,-3,AIR)
B(-4,7,-2,AIR)
B(-4,7,-1,AIR)
B(-4,7,0,AIR)
B(-4,7,1,AIR)
B(-4,7,2,AIR)
B(-4,7,3,1)
B(-4,7,4,AIR)
B(-4,7,5,AIR)
B(-4,7,6,AIR)
B(-4,7,7,AIR)
B(-4,7,8,AIR)
B(-4,8,-6,AIR)
B(-4,8,-5,AIR)
B(-4,8,-4,AIR)
B(-4,8,-3,AIR)
B(-4,8,-2,AIR)
B(-4,8,-1,AIR)
B(-4,8,0,AIR)
B(-4,8,1,AIR)
B(-4,8,2,AIR)
B(-4,8,3,AIR)
B(-4,8,4,AIR)
B(-4,8,5,AIR)
B(-4,8,6,AIR)
B(-4,8,7,AIR)
B(-4,8,8,AIR)
B(-4,9,-6,AIR)
B(-4,9,-5,AIR)
B(-4,9,-4,AIR)
B(-4,9,-3,AIR)
B(-4,9,-2,AIR)
B(-4,9,-1,AIR)
B(-4,9,0,AIR)
B(-4,9,1,AIR)
B(-4,9,2,AIR)
B(-4,9,3,AIR)
B(-4,9,4,AIR)
B(-4,9,5,AIR)
B(-4,9,6,AIR)
B(-4,9,7,AIR)
B(-4,9,8,AIR)
B(-4,10,-6,AIR)
B(-4,10,-5,AIR)
B(-4,10,-4,AIR)
B(-4,10,-3,AIR)
B(-4,10,-2,AIR)
B(-4,10,-1,AIR)
B(-4,10,0,AIR)
B(-4,10,1,AIR)
B(-4,10,2,AIR)
B(-4,10,3,AIR)
B(-4,10,4,AIR)
B(-4,10,5,AIR)
B(-4,10,6,AIR)
B(-4,10,7,AIR)
B(-4,10,8,AIR)
B(-4,11,-6,AIR)
B(-4,11,-5,AIR)
B(-4,11,-4,AIR)
B(-4,11,-3,AIR)
B(-4,11,-2,AIR)
B(-4,11,-1,AIR)
B(-4,11,0,AIR)
B(-4,11,1,AIR)
B(-4,11,2,AIR)
B(-4,11,3,AIR)
B(-4,11,4,AIR)
B(-4,11,5,AIR)
B(-4,11,6,AIR)
B(-4,11,7,AIR)
B(-4,11,8,AIR)
B(-4,12,-6,AIR)
B(-4,12,-5,AIR)
B(-4,12,-4,AIR)
B(-4,12,-3,AIR)
B(-4,12,-2,AIR)
B(-4,12,-1,AIR)
B(-4,12,0,AIR)
B(-4,12,1,AIR)
B(-4,12,2,AIR)
B(-4,12,3,AIR)
B(-4,12,4,AIR)
B(-4,12,5,AIR)
B(-4,12,6,AIR)
B(-4,12,7,AIR)
B(-4,12,8,AIR)
B(-4,13,-6,AIR)
B(-4,13,-5,AIR)
B(-4,13,-4,AIR)
B(-4,13,-3,AIR)
B(-4,13,-2,AIR)
B(-4,13,-1,AIR)
B(-4,13,0,AIR)
B(-4,13,1,AIR)
B(-4,13,2,AIR)
B(-4,13,3,AIR)
B(-4,13,4,AIR)
B(-4,13,5,AIR)
B(-4,13,6,AIR)
B(-4,13,7,AIR)
B(-4,13,8,AIR)
B(-4,14,-6,AIR)
B(-4,14,-5,AIR)
B(-4,14,-4,AIR)
B(-4,14,-3,AIR)
B(-4,14,-2,AIR)
B(-4,14,-1,AIR)
B(-4,14,0,AIR)
B(-4,14,1,AIR)
B(-4,14,2,AIR)
B(-4,14,3,AIR)
B(-4,14,4,AIR)
B(-4,14,5,AIR)
B(-4,14,6,AIR)
B(-4,14,7,AIR)
B(-4,14,8,AIR)
B(-4,15,-6,AIR)
B(-4,15,-5,AIR)
B(-4,15,-4,AIR)
B(-4,15,-3,AIR)
B(-4,15,-2,AIR)
B(-4,15,-1,AIR)
B(-4,15,0,AIR)
B(-4,15,1,AIR)
B(-4,15,2,AIR)
B(-4,15,3,AIR)
B(-4,15,4,AIR)
B(-4,15,5,AIR)
B(-4,15,6,AIR)
B(-4,15,7,AIR)
B(-4,15,8,AIR)
B(-4,16,-6,AIR)
B(-4,16,-5,AIR)
B(-4,16,-4,AIR)
B(-4,16,-3,AIR)
B(-4,16,-2,AIR)
B(-4,16,-1,AIR)
B(-4,16,0,AIR)
B(-4,16,1,AIR)
B(-4,16,2,AIR)
B(-4,16,3,AIR)
B(-4,16,4,AIR)
B(-4,16,5,AIR)
B(-4,16,6,AIR)
B(-4,16,7,AIR)
B(-4,16,8,AIR)
B(-4,17,-6,AIR)
B(-4,17,-5,AIR)
B(-4,17,-4,AIR)
B(-4,17,-3,AIR)
B(-4,17,-2,AIR)
B(-4,17,-1,AIR)
B(-4,17,0,AIR)
B(-4,17,1,AIR)
B(-4,17,2,AIR)
B(-4,17,3,AIR)
B(-4,17,4,AIR)
B(-4,17,5,AIR)
B(-4,17,6,AIR)
B(-4,17,7,AIR)
B(-4,17,8,AIR)
B(-4,18,-6,AIR)
B(-4,18,-5,AIR)
B(-4,18,-4,AIR)
B(-4,18,-3,AIR)
B(-4,18,-2,AIR)
B(-4,18,-1,AIR)
B(-4,18,0,AIR)
B(-4,18,1,AIR)
B(-4,18,2,AIR)
B(-4,18,3,AIR)
B(-4,18,4,AIR)
B(-4,18,5,AIR)
B(-4,18,6,AIR)
B(-4,18,7,AIR)
B(-4,18,8,AIR)
B(-4,19,-6,AIR)
B(-4,19,-5,AIR)
B(-4,19,-4,AIR)
B(-4,19,-3,AIR)
B(-4,19,-2,AIR)
B(-4,19,-1,AIR)
B(-4,19,0,AIR)
B(-4,19,1,AIR)
B(-4,19,2,AIR)
B(-4,19,3,AIR)
B(-4,19,4,AIR)
B(-4,19,5,AIR)
B(-4,19,6,AIR)
B(-4,19,7,AIR)
B(-4,19,8,AIR)
B(-4,20,-6,AIR)
B(-4,20,-5,AIR)
B(-4,20,-4,AIR)
B(-4,20,-3,AIR)
B(-4,20,-2,AIR)
B(-4,20,-1,AIR)
B(-4,20,0,AIR)
B(-4,20,1,AIR)
B(-4,20,2,AIR)
B(-4,20,3,AIR)
B(-4,20,4,AIR)
B(-4,20,5,AIR)
B(-4,20,6,AIR)
B(-4,20,7,AIR)
B(-4,20,8,AIR)
B(-4,21,-6,AIR)
B(-4,21,-5,AIR)
B(-4,21,-4,AIR)
B(-4,21,-3,AIR)
B(-4,21,-2,AIR)
B(-4,21,-1,AIR)
B(-4,21,0,AIR)
B(-4,21,1,AIR)
B(-4,21,2,AIR)
B(-4,21,3,AIR)
B(-4,21,4,AIR)
B(-4,21,5,AIR)
B(-4,21,6,AIR)
B(-4,21,7,AIR)
B(-4,21,8,AIR)
B(-4,22,-6,AIR)
B(-4,22,-5,AIR)
B(-4,22,-4,AIR)
B(-4,22,-3,AIR)
B(-4,22,-2,AIR)
B(-4,22,-1,AIR)
B(-4,22,0,AIR)
B(-4,22,1,AIR)
B(-4,22,2,AIR)
B(-4,22,3,AIR)
B(-4,22,4,AIR)
B(-4,22,5,AIR)
B(-4,22,6,AIR)
B(-4,22,7,AIR)
B(-4,22,8,AIR)
B(-4,23,-6,AIR)
B(-4,23,-5,AIR)
B(-4,23,-4,AIR)
B(-4,23,-3,AIR)
B(-4,23,-2,AIR)
B(-4,23,-1,AIR)
B(-4,23,0,AIR)
B(-4,23,1,AIR)
B(-4,23,2,AIR)
B(-4,23,3,AIR)
B(-4,23,4,AIR)
B(-4,23,5,AIR)
B(-4,23,6,AIR)
B(-4,23,7,AIR)
B(-4,23,8,AIR)
B(-4,24,-6,AIR)
B(-4,24,-5,AIR)
B(-4,24,-4,AIR)
B(-4,24,-3,AIR)
B(-4,24,-2,AIR)
B(-4,24,-1,AIR)
B(-4,24,0,AIR)
B(-4,24,1,AIR)
B(-4,24,2,AIR)
B(-4,24,3,AIR)
B(-4,24,4,AIR)
B(-4,24,5,AIR)
B(-4,24,6,AIR)
B(-4,24,7,AIR)
B(-4,24,8,AIR)
B(-4,25,-6,AIR)
B(-4,25,-5,AIR)
B(-4,25,-4,AIR)
B(-4,25,-3,AIR)
B(-4,25,-2,AIR)
B(-4,25,-1,AIR)
B(-4,25,0,AIR)
B(-4,25,1,AIR)
B(-4,25,2,AIR)
B(-4,25,3,AIR)
B(-4,25,4,AIR)
B(-4,25,5,AIR)
B(-4,25,6,AIR)
B(-4,25,7,AIR)
B(-4,25,8,AIR)
B(-4,26,-6,AIR)
B(-4,26,-5,AIR)
B(-4,26,-4,AIR)
B(-4,26,-3,AIR)
B(-4,26,-2,AIR)
B(-4,26,-1,AIR)
B(-4,26,0,AIR)
B(-4,26,1,AIR)
B(-4,26,2,AIR)
B(-4,26,3,AIR)
B(-4,26,4,AIR)
B(-4,26,5,AIR)
B(-4,26,6,AIR)
B(-4,26,7,AIR)
B(-4,26,8,AIR)
B(-4,27,-6,AIR)
B(-4,27,-5,AIR)
B(-4,27,-4,AIR)
B(-4,27,-3,AIR)
B(-4,27,-2,AIR)
B(-4,27,-1,AIR)
B(-4,27,0,AIR)
B(-4,27,1,AIR)
B(-4,27,2,AIR)
B(-4,27,3,AIR)
B(-4,27,4,AIR)
B(-4,27,5,AIR)
B(-4,27,6,AIR)
B(-4,27,7,AIR)
B(-4,27,8,AIR)
B(-4,28,-6,AIR)
B(-4,28,-5,AIR)
B(-4,28,-4,AIR)
B(-4,28,-3,AIR)
B(-4,28,-2,AIR)
B(-4,28,-1,AIR)
B(-4,28,0,AIR)
B(-4,28,1,AIR)
B(-4,28,2,AIR)
B(-4,28,3,AIR)
B(-4,28,4,AIR)
B(-4,28,5,AIR)
B(-4,28,6,AIR)
B(-4,28,7,AIR)
B(-4,28,8,AIR)
B(-4,29,-6,AIR)
B(-4,29,-5,AIR)
B(-4,29,-4,AIR)
B(-4,29,-3,AIR)
B(-4,29,-2,AIR)
B(-4,29,-1,AIR)
B(-4,29,0,AIR)
B(-4,29,1,AIR)
B(-4,29,2,AIR)
B(-4,29,3,AIR)
B(-4,29,4,AIR)
B(-4,29,5,AIR)
B(-4,29,6,AIR)
B(-4,29,7,AIR)
B(-4,29,8,AIR)
B(-4,30,-6,AIR)
B(-4,30,-5,AIR)
B(-4,30,-4,AIR)
B(-4,30,-3,AIR)
B(-4,30,-2,AIR)
B(-4,30,-1,AIR)
B(-4,30,0,AIR)
B(-4,30,1,AIR)
B(-4,30,2,AIR)
B(-4,30,3,AIR)
B(-4,30,4,AIR)
B(-4,30,5,AIR)
B(-4,30,6,AIR)
B(-4,30,7,AIR)
B(-4,30,8,AIR)
B(-4,31,-6,AIR)
B(-4,31,-5,AIR)
B(-4,31,-4,AIR)
B(-4,31,-3,AIR)
B(-4,31,-2,AIR)
B(-4,31,-1,AIR)
B(-4,31,0,AIR)
B(-4,31,1,AIR)
B(-4,31,2,AIR)
B(-4,31,3,AIR)
B(-4,31,4,AIR)
B(-4,31,5,AIR)
B(-4,31,6,AIR)
B(-4,31,7,AIR)
B(-4,31,8,AIR)
B(-4,32,-6,AIR)
B(-4,32,-5,AIR)
B(-4,32,-4,AIR)
B(-4,32,-3,AIR)
B(-4,32,-2,AIR)
B(-4,32,-1,AIR)
B(-4,32,0,AIR)
B(-4,32,1,AIR)
B(-4,32,2,AIR)
B(-4,32,3,AIR)
B(-4,32,4,AIR)
B(-4,32,5,AIR)
B(-4,32,6,AIR)
B(-4,32,7,AIR)
B(-4,32,8,AIR)
B(-3,-31,-7,1)
B(-3,-31,-6,1)
B(-3,-31,-5,1)
B(-3,-31,-4,1)
B(-3,-31,-3,1)
B(-3,-31,-2,1)
B(-3,-31,-1,1)
B(-3,-31,0,1)
B(-3,-31,1,1)
B(-3,-31,2,1)
B(-3,-31,3,1)
B(-3,-31,4,1)
B(-3,-31,5,1)
B(-3,-31,6,1)
B(-3,-31,7,1)
B(-3,-31,8,1)
B(-3,-30,-7,1)
B(-3,-30,-6,1)
B(-3,-30,-5,1)
B(-3,-30,-4,1)
B(-3,-30,-3,1)
B(-3,-30,-2,1)
B(-3,-30,-1,1)
B(-3,-30,0,1)
B(-3,-30,1,1)
B(-3,-30,2,1)
B(-3,-30,3,1)
B(-3,-30,4,1)
B(-3,-30,5,1)
B(-3,-30,6,1)
B(-3,-30,7,1)
B(-3,-30,8,1)
B(-3,-29,-7,1)
B(-3,-29,-6,1)
B(-3,-29,-5,1)
B(-3,-29,-4,1)
B(-3,-29,-3,1)
B(-3,-29,-2,1)
B(-3,-29,-1,1)
B(-3,-29,0,1)
B(-3,-29,1,1)
B(-3,-29,2,1)
B(-3,-29,3,1)
B(-3,-29,4,1)
B(-3,-29,5,1)
B(-3,-29,6,1)
B(-3,-29,7,1)
B(-3,-29,8,1)
B(-3,-28,-7,1)
B(-3,-28,-6,1)
B(-3,-28,-5,1)
B(-3,-28,-4,1)
B(-3,-28,-3,1)
B(-3,-28,-2,1)
B(-3,-28,-1,1)
B(-3,-28,0,1)
B(-3,-28,1,1)
B(-3,-28,2,1)
B(-3,-28,3,1)
B(-3,-28,4,1)
B(-3,-28,5,1)
B(-3,-28,6,1)
B(-3,-28,7,1)
B(-3,-28,8,1)
B(-3,-27,-7,1)
B(-3,-27,-6,1)
B(-3,-27,-5,1)
B(-3,-27,-4,1)
B(-3,-27,-3,1)
B(-3,-27,-2,1)
B(-3,-27,-1,1)
B(-3,-27,0,1)
B(-3,-27,1,1)
B(-3,-27,2,1)
B(-3,-27,3,1)
B(-3,-27,4,1)
B(-3,-27,5,1)
B(-3,-27,6,1)
B(-3,-27,7,1)
B(-3,-27,8,1)
B(-3,-26,-7,1)
B(-3,-26,-6,1)
B(-3,-26,-5,1)
B(-3,-26,-4,1)
B(-3,-26,-3,1)
B(-3,-26,-2,1)
B(-3,-26,-1,1)
B(-3,-26,0,1)
B(-3,-26,1,1)
B(-3,-26,2,1)
B(-3,-26,3,1)
B(-3,-26,4,1)
B(-3,-26,5,1)
B(-3,-26,6,1)
B(-3,-26,7,1)
B(-3,-26,8,1)
B(-3,-25,-7,1)
B(-3,-25,-6,1)
B(-3,-25,-5,1)
B(-3,-25,-4,1)
B(-3,-25,-3,1)
B(-3,-25,-2,1)
B(-3,-25,-1,1)
B(-3,-25,0,1)
B(-3,-25,1,1)
B(-3,-25,2,1)
B(-3,-25,3,1)
B(-3,-25,4,1)
B(-3,-25,5,1)
B(-3,-25,6,1)
B(-3,-25,7,1)
B(-3,-25,8,1)
B(-3,-24,-7,1)
B(-3,-24,-6,1)
B(-3,-24,-5,1)
B(-3,-24,-4,1)
B(-3,-24,-3,1)
B(-3,-24,-2,1)
B(-3,-24,-1,1)
B(-3,-24,0,1)
B(-3,-24,1,1)
B(-3,-24,2,1)
B(-3,-24,3,1)
B(-3,-24,4,1)
B(-3,-24,5,1)
B(-3,-24,6,1)
B(-3,-24,7,1)
B(-3,-24,8,1)
B(-3,-23,-6,1)
B(-3,-23,-5,1)
B(-3,-23,-4,1)
B(-3,-23,-3,1)
B(-3,-23,-2,1)
B(-3,-23,-1,1)
B(-3,-23,0,1)
B(-3,-23,1,1)
B(-3,-23,2,1)
B(-3,-23,3,1)
B(-3,-23,4,1)
B(-3,-23,5,1)
B(-3,-23,6,1)
B(-3,-23,7,1)
B(-3,-23,8,1)
B(-3,-22,-7,1)
B(-3,-22,-6,1)
B(-3,-22,-5,1)
B(-3,-22,-4,1)
B(-3,-22,-3,1)
B(-3,-22,-2,1)
B(-3,-22,-1,1)
B(-3,-22,0,1)
B(-3,-22,1,1)
B(-3,-22,2,1)
B(-3,-22,3,1)
B(-3,-22,4,1)
B(-3,-22,5,1)
B(-3,-22,6,1)
B(-3,-22,7,1)
B(-3,-22,8,1)
B(-3,-21,-7,1)
B(-3,-21,-6,1)
B(-3,-21,-5,1)
B(-3,-21,-4,1)
B(-3,-21,-3,1)
B(-3,-21,-2,1)
B(-3,-21,-1,1)
B(-3,-21,0,1)
B(-3,-21,1,1)
B(-3,-21,2,1)
B(-3,-21,3,1)
B(-3,-21,4,1)
B(-3,-21,5,1)
B(-3,-21,6,1)
B(-3,-21,7,1)
B(-3,-21,8,1)
B(-3,-20,-7,1)
B(-3,-20,-6,1)
B(-3,-20,-5,1)
B(-3,-20,-4,1)
B(-3,-20,-3,1)
B(-3,-20,-2,1)
B(-3,-20,-1,1)
B(-3,-20,0,1)
B(-3,-20,1,1)
B(-3,-20,2,1)
B(-3,-20,3,1)
B(-3,-20,4,1)
B(-3,-20,5,1)
B(-3,-20,6,1)
B(-3,-20,7,1)
B(-3,-20,8,1)
B(-3,-19,-7,1)
B(-3,-19,-6,1)
B(-3,-19,-5,1)
B(-3,-19,-4,1)
B(-3,-19,-3,1)
B(-3,-19,-2,1)
B(-3,-19,-1,1)
B(-3,-19,0,1)
B(-3,-19,1,1)
B(-3,-19,2,1)
B(-3,-19,3,1)
B(-3,-19,4,1)
B(-3,-19,5,1)
B(-3,-19,6,1)
B(-3,-19,7,1)
B(-3,-19,8,1)
B(-3,-18,-7,1)
B(-3,-18,-6,1)
B(-3,-18,-5,1)
B(-3,-18,-4,1)
B(-3,-18,-3,1)
B(-3,-18,-2,1)
B(-3,-18,-1,1)
B(-3,-18,0,1)
B(-3,-18,1,1)
B(-3,-18,2,1)
B(-3,-18,3,1)
B(-3,-18,4,1)
B(-3,-18,5,1)
B(-3,-18,6,1)
B(-3,-18,7,1)
B(-3,-18,8,1)
B(-3,-17,-7,1)
B(-3,-17,-6,1)
B(-3,-17,-5,1)
B(-3,-17,-4,1)
B(-3,-17,-3,1)
B(-3,-17,-2,1)
B(-3,-17,-1,1)
B(-3,-17,0,1)
B(-3,-17,1,1)
B(-3,-17,2,1)
B(-3,-17,3,1)
B(-3,-17,4,1)
B(-3,-17,5,1)
B(-3,-17,6,1)
B(-3,-17,7,1)
B(-3,-17,8,1)
B(-3,-16,-7,1)
B(-3,-16,-6,1)
B(-3,-16,-5,1)
B(-3,-16,-4,1)
B(-3,-16,-3,1)
B(-3,-16,-2,1)
B(-3,-16,-1,1)
B(-3,-16,0,1)
B(-3,-16,1,1)
B(-3,-16,2,1)
B(-3,-16,3,1)
B(-3,-16,4,1)
B(-3,-16,5,1)
B(-3,-16,6,1)
B(-3,-16,7,1)
B(-3,-16,8,1)
B(-3,-15,-7,1)
B(-3,-15,-6,1)
B(-3,-15,-5,1)
B(-3,-15,-4,1)
B(-3,-15,-3,1)
B(-3,-15,-2,1)
B(-3,-15,-1,1)
B(-3,-15,0,1)
B(-3,-15,1,1)
B(-3,-15,2,1)
B(-3,-15,3,1)
B(-3,-15,4,1)
B(-3,-15,5,1)
B(-3,-15,6,1)
B(-3,-15,7,1)
B(-3,-15,8,1)
B(-3,-14,-7,1)
B(-3,-14,-6,1)
B(-3,-14,-5,1)
B(-3,-14,-4,1)
B(-3,-14,-3,1)
B(-3,-14,-2,1)
B(-3,-14,-1,1)
B(-3,-14,0,1)
B(-3,-14,1,1)
B(-3,-14,2,1)
B(-3,-14,3,1)
B(-3,-14,4,1)
B(-3,-14,5,1)
B(-3,-14,6,1)
B(-3,-14,7,1)
B(-3,-14,8,1)
B(-3,-13,-7,1)
B(-3,-13,-6,1)
B(-3,-13,-5,1)
B(-3,-13,-4,1)
B(-3,-13,-3,1)
B(-3,-13,-2,1)
B(-3,-13,-1,1)
B(-3,-13,0,1)
B(-3,-13,1,1)
B(-3,-13,2,1)
B(-3,-13,3,1)
B(-3,-13,4,1)
B(-3,-13,5,1)
B(-3,-13,6,1)
B(-3,-13,7,1)
B(-3,-13,8,1)
B(-3,-12,-7,1)
B(-3,-12,-6,1)
B(-3,-12,-5,1)
B(-3,-12,-4,1)
B(-3,-12,-3,1)
B(-3,-12,-2,1)
B(-3,-12,-1,1)
B(-3,-12,0,1)
B(-3,-12,1,1)
B(-3,-12,2,1)
B(-3,-12,3,1)
B(-3,-12,4,1)
B(-3,-12,5,1)
B(-3,-12,6,1)
B(-3,-12,7,1)
B(-3,-12,8,1)
B(-3,-11,-7,1)
B(-3,-11,-6,1)
B(-3,-11,-5,1)
B(-3,-11,-4,1)
B(-3,-11,-3,1)
B(-3,-11,-2,1)
B(-3,-11,-1,1)
B(-3,-11,0,1)
B(-3,-11,1,1)
B(-3,-11,2,1)
B(-3,-11,3,1)
B(-3,-11,4,1)
B(-3,-11,5,1)
B(-3,-11,6,1)
B(-3,-11,7,1)
B(-3,-11,8,1)
B(-3,-10,-7,1)
B(-3,-10,-6,1)
B(-3,-10,-5,1)
B(-3,-10,-4,1)
B(-3,-10,-3,1)
B(-3,-10,-2,1)
B(-3,-10,-1,1)
B(-3,-10,0,1)
B(-3,-10,1,1)
B(-3,-10,2,1)
B(-3,-10,3,1)
B(-3,-10,4,1)
B(-3,-10,5,1)
B(-3,-10,6,1)
B(-3,-10,7,1)
B(-3,-10,8,1)
B(-3,-9,-7,1)
B(-3,-9,-6,1)
B(-3,-9,-5,1)
B(-3,-9,-4,1)
B(-3,-9,-3,1)
B(-3,-9,-2,1)
B(-3,-9,-1,1)
B(-3,-9,0,1)
B(-3,-9,1,1)
B(-3,-9,2,1)
B(-3,-9,3,1)
B(-3,-9,4,1)
B(-3,-9,5,1)
B(-3,-9,6,1)
B(-3,-9,7,1)
B(-3,-9,8,1)
B(-3,-8,-7,1)
B(-3,-8,-6,1)
B(-3,-8,-5,1)
B(-3,-8,-4,1)
B(-3,-8,-3,1)
B(-3,-8,-2,1)
B(-3,-8,-1,1)
B(-3,-8,0,1)
B(-3,-8,1,1)
B(-3,-8,2,1)
B(-3,-8,3,1)
B(-3,-8,4,1)
B(-3,-8,5,1)
B(-3,-8,6,1)
B(-3,-8,7,1)
B(-3,-8,8,1)
B(-3,-7,-7,1)
B(-3,-7,-6,1)
B(-3,-7,-5,1)
B(-3,-7,-4,1)
B(-3,-7,-3,1)
B(-3,-7,-2,1)
B(-3,-7,-1,1)
B(-3,-7,0,1)
B(-3,-7,1,1)
B(-3,-7,2,1)
B(-3,-7,3,1)
B(-3,-7,4,1)
B(-3,-7,5,1)
B(-3,-7,6,1)
B(-3,-7,7,1)
B(-3,-7,8,1)
B(-3,-6,-7,1)
B(-3,-6,-6,1)
B(-3,-6,-5,1)
B(-3,-6,-4,1)
B(-3,-6,-3,1)
B(-3,-6,-2,1)
B(-3,-6,-1,1)
B(-3,-6,0,1)
B(-3,-6,1,1)
B(-3,-6,2,1)
B(-3,-6,3,1)
B(-3,-6,4,1)
B(-3,-6,5,1)
B(-3,-6,6,1)
B(-3,-6,7,1)
B(-3,-6,8,1)
B(-3,-5,-5,1)
B(-3,-5,-4,1)
B(-3,-5,-3,1)
B(-3,-5,-2,1)
B(-3,-5,-1,1)
B(-3,-5,0,1)
B(-3,-5,1,1)
B(-3,-5,2,1)
B(-3,-5,3,1)
B(-3,-5,4,1)
B(-3,-5,5,1)
B(-3,-5,6,1)
B(-3,-5,7,1)
B(-3,-5,8,1)
B(-3,-4,-4,1)
B(-3,-4,-3,1)
B(-3,-4,-2,1)
B(-3,-4,-1,1)
B(-3,-4,0,1)
B(-3,-4,1,1)
B(-3,-4,2,1)
B(-3,-4,3,1)
B(-3,-4,4,1)
B(-3,-4,5,1)
B(-3,-4,6,1)
B(-3,-4,7,1)
B(-3,-4,8,1)
B(-3,-3,-3,1)
B(-3,-3,-2,1)
B(-3,-3,-1,1)
B(-3,-3,0,1)
B(-3,-3,1,1)
B(-3,-3,2,1)
B(-3,-3,3,1)
B(-3,-3,4,1)
B(-3,-3,5,1)
B(-3,-3,6,1)
B(-3,-3,7,1)
B(-3,-3,8,1)
B(-3,-2,-6,AIR)
B(-3,-2,-5,AIR)
B(-3,-2,-4,AIR)
B(-3,-2,-3,AIR)
B(-3,-2,-2,1)
B(-3,-2,-1,1)
B(-3,-2,0,1)
B(-3,-2,1,1)
B(-3,-2,2,1)
B(-3,-2,3,1)
B(-3,-2,4,1)
B(-3,-2,5,1)
B(-3,-2,6,1)
B(-3,-2,7,1)
B(-3,-2,8,1)
B(-3,-1,-6,AIR)
B(-3,-1,-5,AIR)
B(-3,-1,-4,AIR)
B(-3,-1,-3,AIR)
B(-3,-1,-2,AIR)
B(-3,-1,-1,AIR)
B(-3,-1,0,1)
B(-3,-1,1,1)
B(-3,-1,2,AIR)
B(-3,-1,3,AIR)
B(-3,-1,4,1)
B(-3,-1,5,1)
B(-3,-1,6,1)
B(-3,-1,7,1)
B(-3,-1,8,1)
B(-3,0,-6,AIR)
B(-3,0,-5,AIR)
B(-3,0,-4,AIR)
B(-3,0,-3,AIR)
B(-3,0,-2,AIR)
B(-3,0,-1,AIR)
B(-3,0,0,AIR)
B(-3,0,1,AIR)
B(-3,0,2,AIR)
B(-3,0,3,AIR)
B(-3,0,4,AIR)
B(-3,0,5,AIR)
B(-3,0,6,1)
B(-3,0,7,1)
B(-3,0,8,1)
B(-3,1,-6,AIR)
B(-3,1,-5,AIR)
B(-3,1,-4,AIR)
B(-3,1,-3,AIR)
B(-3,1,-2,AIR)
B(-3,1,-1,AIR)
B(-3,1,0,AIR)
B(-3,1,1,AIR)
B(-3,1,2,AIR)
B(-3,1,3,AIR)
B(-3,1,4,AIR)
B(-3,1,5,AIR)
B(-3,1,6,AIR)
B(-3,1,7,1)
B(-3,1,8,1)
B(-3,2,-6,AIR)
B(-3,2,-5,AIR)
B(-3,2,-4,AIR)
B(-3,2,-3,AIR)
B(-3,2,-2,AIR)
B(-3,2,-1,AIR)
B(-3,2,0,AIR)
B(-3,2,1,AIR)
B(-3,2,2,AIR)
B(-3,2,3,AIR)
B(-3,2,4,AIR)
B(-3,2,5,AIR)
B(-3,2,6,AIR)
B(-3,2,7,AIR)
B(-3,2,8,AIR)
B(-3,3,-6,AIR)
B(-3,3,-5,AIR)
B(-3,3,-4,AIR)
B(-3,3,-3,AIR)
B(-3,3,-2,AIR)
B(-3,3,-1,AIR)
B(-3,3,0,AIR)
B(-3,3,1,AIR)
B(-3,3,2,AIR)
B(-3,3,3,AIR)
B(-3,3,4,AIR)
B(-3,3,5,AIR)
B(-3,3,6,AIR)
B(-3,3,7,AIR)
B(-3,3,8,AIR)
B(-3,4,-6,AIR)
B(-3,4,-5,AIR)
B(-3,4,-4,AIR)
B(-3,4,-3,AIR)
B(-3,4,-2,AIR)
B(-3,4,-1,AIR)
B(-3,4,0,AIR)
B(-3,4,1,AIR)
B(-3,4,2,AIR)
B(-3,4,3,AIR)
B(-3,4,4,AIR)
B(-3,4,5,AIR)
B(-3,4,6,AIR)
B(-3,4,7,AIR)
B(-3,4,8,AIR)
B(-3,5,-6,AIR)
B(-3,5,-5,AIR)
B(-3,5,-4,AIR)
B(-3,5,-3,AIR)
B(-3,5,-2,AIR)
B(-3,5,-1,AIR)
B(-3,5,0,AIR)
B(-3,5,1,AIR)
B(-3,5,2,AIR)
B(-3,5,3,AIR)
B(-3,5,4,AIR)
B(-3,5,5,AIR)
B(-3,5,6,AIR)
B(-3,5,7,AIR)
B(-3,5,8,AIR)
B(-3,6,-6,AIR)
B(-3,6,-5,AIR)
B(-3,6,-4,AIR)
B(-3,6,-3,AIR)
B(-3,6,-2,AIR)
B(-3,6,-1,AIR)
B(-3,6,0,AIR)
B(-3,6,1,AIR)
B(-3,6,2,AIR)
B(-3,6,3,AIR)
B(-3,6,4,AIR)
B(-3,6,5,AIR)
B(-3,6,6,AIR)
B(-3,6,7,AIR)
B(-3,6,8,AIR)
B(-3,7,-6,AIR)
B(-3,7,-5,AIR)
B(-3,7,-4,AIR)
B(-3,7,-3,AIR)
B(-3,7,-2,AIR)
B(-3,7,-1,AIR)
B(-3,7,0,AIR)
B(-3,7,1,AIR)
B(-3,7,2,AIR)
B(-3,7,3,AIR)
B(-3,7,4,AIR)
B(-3,7,5,AIR)
B(-3,7,6,AIR)
B(-3,7,7,AIR)
B(-3,7,8,AIR)
B(-3,8,-6,AIR)
B(-3,8,-5,AIR)
B(-3,8,-4,AIR)
B(-3,8,-3,AIR)
B(-3,8,-2,AIR)
B(-3,8,-1,AIR)
B(-3,8,0,AIR)
B(-3,8,1,AIR)
B(-3,8,2,AIR)
B(-3,8,3,AIR)
B(-3,8,4,AIR)
B(-3,8,5,AIR)
B(-3,8,6,AIR)
B(-3,8,7,AIR)
B(-3,8,8,AIR)
B(-3,9,-6,AIR)
B(-3,9,-5,AIR)
B(-3,9,-4,AIR)
B(-3,9,-3,AIR)
B(-3,9,-2,AIR)
B(-3,9,-1,AIR)
B(-3,9,0,AIR)
B(-3,9,1,AIR)
B(-3,9,2,AIR)
B(-3,9,3,AIR)
B(-3,9,4,AIR)
B(-3,9,5,AIR)
B(-3,9,6,AIR)
B(-3,9,7,AIR)
B(-3,9,8,AIR)
B(-3,10,-6,AIR)
B(-3,10,-5,AIR)
B(-3,10,-4,AIR)
B(-3,10,-3,AIR)
B(-3,10,-2,AIR)
B(-3,10,-1,AIR)
B(-3,10,0,AIR)
B(-3,10,1,AIR)
B(-3,10,2,AIR)
B(-3,10,3,AIR)
B(-3,10,4,AIR)
B(-3,10,5,AIR)
B(-3,10,6,AIR)
B(-3,10,7,AIR)
B(-3,10,8,AIR)
B(-3,11,-6,AIR)
B(-3,11,-5,AIR)
B(-3,11,-4,AIR)
B(-3,11,-3,AIR)
B(-3,11,-2,AIR)
B(-3,11,-1,AIR)
B(-3,11,0,AIR)
B(-3,11,1,AIR)
B(-3,11,2,AIR)
B(-3,11,3,AIR)
B(-3,11,4,AIR)
B(-3,11,5,AIR)
B(-3,11,6,AIR)
B(-3,11,7,AIR)
B(-3,11,8,AIR)
B(-3,12,-6,AIR)
B(-3,12,-5,AIR)
B(-3,12,-4,AIR)
B(-3,12,-3,AIR)
B(-3,12,-2,AIR)
B(-3,12,-1,AIR)
B(-3,12,0,AIR)
B(-3,12,1,AIR)
B(-3,12,2,AIR)
B(-3,12,3,AIR)
B(-3,12,4,AIR)
B(-3,12,5,AIR)
B(-3,12,6,AIR)
B(-3,12,7,AIR)
B(-3,12,8,AIR)
B(-3,13,-6,AIR)
B(-3,13,-5,AIR)
B(-3,13,-4,AIR)
B(-3,13,-3,AIR)
B(-3,13,-2,AIR)
B(-3,13,-1,AIR)
B(-3,13,0,AIR)
B(-3,13,1,AIR)
B(-3,13,2,AIR)
B(-3,13,3,AIR)
B(-3,13,4,AIR)
B(-3,13,5,AIR)
B(-3,13,6,AIR)
B(-3,13,7,AIR)
B(-3,13,8,AIR)
B(-3,14,-6,AIR)
B(-3,14,-5,AIR)
B(-3,14,-4,AIR)
B(-3,14,-3,AIR)
B(-3,14,-2,AIR)
B(-3,14,-1,AIR)
B(-3,14,0,AIR)
B(-3,14,1,AIR)
B(-3,14,2,AIR)
B(-3,14,3,AIR)
B(-3,14,4,AIR)
B(-3,14,5,AIR)
B(-3,14,6,AIR)
B(-3,14,7,AIR)
B(-3,14,8,AIR)
B(-3,15,-6,AIR)
B(-3,15,-5,AIR)
B(-3,15,-4,AIR)
B(-3,15,-3,AIR)
B(-3,15,-2,AIR)
B(-3,15,-1,AIR)
B(-3,15,0,AIR)
B(-3,15,1,AIR)
B(-3,15,2,AIR)
B(-3,15,3,AIR)
B(-3,15,4,AIR)
B(-3,15,5,AIR)
B(-3,15,6,AIR)
B(-3,15,7,AIR)
B(-3,15,8,AIR)
B(-3,16,-6,AIR)
B(-3,16,-5,AIR)
B(-3,16,-4,AIR)
B(-3,16,-3,AIR)
B(-3,16,-2,AIR)
B(-3,16,-1,AIR)
B(-3,16,0,AIR)
B(-3,16,1,AIR)
B(-3,16,2,AIR)
B(-3,16,3,AIR)
B(-3,16,4,AIR)
B(-3,16,5,AIR)
B(-3,16,6,AIR)
B(-3,16,7,AIR)
B(-3,16,8,AIR)
B(-3,17,-6,AIR)
B(-3,17,-5,AIR)
B(-3,17,-4,AIR)
B(-3,17,-3,AIR)
B(-3,17,-2,AIR)
B(-3,17,-1,AIR)
B(-3,17,0,AIR)
B(-3,17,1,AIR)
B(-3,17,2,AIR)
B(-3,17,3,AIR)
B(-3,17,4,AIR)
B(-3,17,5,AIR)
B(-3,17,6,AIR)
B(-3,17,7,AIR)
B(-3,17,8,AIR)
B(-3,18,-6,AIR)
B(-3,18,-5,AIR)
B(-3,18,-4,AIR)
B(-3,18,-3,AIR)
B(-3,18,-2,AIR)
B(-3,18,-1,AIR)
B(-3,18,0,AIR)
B(-3,18,1,AIR)
B(-3,18,2,AIR)
B(-3,18,3,AIR)
B(-3,18,4,AIR)
B(-3,18,5,AIR)
B(-3,18,6,AIR)
B(-3,18,7,AIR)
B(-3,18,8,AIR)
B(-3,19,-6,AIR)
B(-3,19,-5,AIR)
B(-3,19,-4,AIR)
B(-3,19,-3,AIR)
B(-3,19,-2,AIR)
B(-3,19,-1,AIR)
B(-3,19,0,AIR)
B(-3,19,1,AIR)
B(-3,19,2,AIR)
B(-3,19,3,AIR)
B(-3,19,4,AIR)
B(-3,19,5,AIR)
B(-3,19,6,AIR)
B(-3,19,7,AIR)
B(-3,19,8,AIR)
B(-3,20,-6,AIR)
B(-3,20,-5,AIR)
B(-3,20,-4,AIR)
B(-3,20,-3,AIR)
B(-3,20,-2,AIR)
B(-3,20,-1,AIR)
B(-3,20,0,AIR)
B(-3,20,1,AIR)
B(-3,20,2,AIR)
B(-3,20,3,AIR)
B(-3,20,4,AIR)
B(-3,20,5,AIR)
B(-3,20,6,AIR)
B(-3,20,7,AIR)
B(-3,20,8,AIR)
B(-3,21,-6,AIR)
B(-3,21,-5,AIR)
B(-3,21,-4,AIR)
B(-3,21,-3,AIR)
B(-3,21,-2,AIR)
B(-3,21,-1,AIR)
B(-3,21,0,AIR)
B(-3,21,1,AIR)
B(-3,21,2,AIR)
B(-3,21,3,AIR)
B(-3,21,4,AIR)
B(-3,21,5,AIR)
B(-3,21,6,AIR)
B(-3,21,7,AIR)
B(-3,21,8,AIR)
B(-3,22,-6,AIR)
B(-3,22,-5,AIR)
B(-3,22,-4,AIR)
B(-3,22,-3,AIR)
B(-3,22,-2,AIR)
B(-3,22,-1,AIR)
B(-3,22,0,AIR)
B(-3,22,1,AIR)
B(-3,22,2,AIR)
B(-3,22,3,AIR)
B(-3,22,4,AIR)
B(-3,22,5,AIR)
B(-3,22,6,AIR)
B(-3,22,7,AIR)
B(-3,22,8,AIR)
B(-3,23,-6,AIR)
B(-3,23,-5,AIR)
B(-3,23,-4,AIR)
B(-3,23,-3,AIR)
B(-3,23,-2,AIR)
B(-3,23,-1,AIR)
B(-3,23,0,AIR)
B(-3,23,1,AIR)
B(-3,23,2,AIR)
B(-3,23,3,AIR)
B(-3,23,4,AIR)
B(-3,23,5,AIR)
B(-3,23,6,AIR)
B(-3,23,7,AIR)
B(-3,23,8,AIR)
B(-3,24,-6,AIR)
B(-3,24,-5,AIR)
B(-3,24,-4,AIR)
B(-3,24,-3,AIR)
B(-3,24,-2,AIR)
B(-3,24,-1,AIR)
B(-3,24,0,AIR)
B(-3,24,1,AIR)
B(-3,24,2,AIR)
B(-3,24,3,AIR)
B(-3,24,4,AIR)
B(-3,24,5,AIR)
B(-3,24,6,AIR)
B(-3,24,7,AIR)
B(-3,24,8,AIR)
B(-3,25,-6,AIR)
B(-3,25,-5,AIR)
B(-3,25,-4,AIR)
B(-3,25,-3,AIR)
B(-3,25,-2,AIR)
B(-3,25,-1,AIR)
B(-3,25,0,AIR)
B(-3,25,1,AIR)
B(-3,25,2,AIR)
B(-3,25,3,AIR)
B(-3,25,4,AIR)
B(-3,25,5,AIR)
B(-3,25,6,AIR)
B(-3,25,7,AIR)
B(-3,25,8,AIR)
B(-3,26,-6,AIR)
B(-3,26,-5,AIR)
B(-3,26,-4,AIR)
B(-3,26,-3,AIR)
B(-3,26,-2,AIR)
B(-3,26,-1,AIR)
B(-3,26,0,AIR)
B(-3,26,1,AIR)
B(-3,26,2,AIR)
B(-3,26,3,AIR)
B(-3,26,4,AIR)
B(-3,26,5,AIR)
B(-3,26,6,AIR)
B(-3,26,7,AIR)
B(-3,26,8,AIR)
B(-3,27,-6,AIR)
B(-3,27,-5,AIR)
B(-3,27,-4,AIR)
B(-3,27,-3,AIR)
B(-3,27,-2,AIR)
B(-3,27,-1,AIR)
B(-3,27,0,AIR)
B(-3,27,1,AIR)
B(-3,27,2,AIR)
B(-3,27,3,AIR)
B(-3,27,4,AIR)
B(-3,27,5,AIR)
B(-3,27,6,AIR)
B(-3,27,7,AIR)
B(-3,27,8,AIR)
B(-3,28,-6,AIR)
B(-3,28,-5,AIR)
B(-3,28,-4,AIR)
B(-3,28,-3,AIR)
B(-3,28,-2,AIR)
B(-3,28,-1,AIR)
B(-3,28,0,AIR)
B(-3,28,1,AIR)
B(-3,28,2,AIR)
B(-3,28,3,AIR)
B(-3,28,4,AIR)
B(-3,28,5,AIR)
B(-3,28,6,AIR)
B(-3,28,7,AIR)
B(-3,28,8,AIR)
B(-3,29,-6,AIR)
B(-3,29,-5,AIR)
B(-3,29,-4,AIR)
B(-3,29,-3,AIR)
B(-3,29,-2,AIR)
B(-3,29,-1,AIR)
B(-3,29,0,AIR)
B(-3,29,1,AIR)
B(-3,29,2,AIR)
B(-3,29,3,AIR)
B(-3,29,4,AIR)
B(-3,29,5,AIR)
B(-3,29,6,AIR)
B(-3,29,7,AIR)
B(-3,29,8,AIR)
B(-3,30,-6,AIR)
B(-3,30,-5,AIR)
B(-3,30,-4,AIR)
B(-3,30,-3,AIR)
B(-3,30,-2,AIR)
B(-3,30,-1,AIR)
B(-3,30,0,AIR)
B(-3,30,1,AIR)
B(-3,30,2,AIR)
B(-3,30,3,AIR)
B(-3,30,4,AIR)
B(-3,30,5,AIR)
B(-3,30,6,AIR)
B(-3,30,7,AIR)
B(-3,30,8,AIR)
B(-3,31,-6,AIR)
B(-3,31,-5,AIR)
B(-3,31,-4,AIR)
B(-3,31,-3,AIR)
B(-3,31,-2,AIR)
B(-3,31,-1,AIR)
B(-3,31,0,AIR)
B(-3,31,1,AIR)
B(-3,31,2,AIR)
B(-3,31,3,AIR)
B(-3,31,4,AIR)
B(-3,31,5,AIR)
B(-3,31,6,AIR)
B(-3,31,7,AIR)
B(-3,31,8,AIR)
B(-3,32,-6,AIR)
B(-3,32,-5,AIR)
B(-3,32,-4,AIR)
B(-3,32,-3,AIR)
B(-3,32,-2,AIR)
B(-3,32,-1,AIR)
B(-3,32,0,AIR)
B(-3,32,1,AIR)
B(-3,32,2,AIR)
B(-3,32,3,AIR)
B(-3,32,4,AIR)
B(-3,32,5,AIR)
B(-3,32,6,AIR)
B(-3,32,7,AIR)
B(-3,32,8,AIR)
B(-2,-31,-7,1)
B(-2,-31,-6,1)
B(-2,-31,-5,1)
B(-2,-31,-4,1)
B(-2,-31,-3,1)
B(-2,-31,-2,1)
B(-2,-31,-1,1)
B(-2,-31,0,1)
B(-2,-31,1,1)
B(-2,-31,2,1)
B(-2,-31,3,1)
B(-2,-31,4,1)
B(-2,-31,5,1)
B(-2,-31,6,1)
B(-2,-31,7,1)
B(-2,-31,8,1)
B(-2,-30,-7,1)
B(-2,-30,-6,1)
B(-2,-30,-5,1)
B(-2,-30,-4,1)
B(-2,-30,-3,1)
B(-2,-30,-2,1)
B(-2,-30,-1,1)
B(-2,-30,0,1)
B(-2,-30,1,1)
B(-2,-30,2,1)
B(-2,-30,3,1)
B(-2,-30,4,1)
B(-2,-30,5,1)
B(-2,-30,6,1)
B(-2,-30,7,1)
B(-2,-30,8,1)
B(-2,-29,-7,1)
B(-2,-29,-6,1)
B(-2,-29,-5,1)
B(-2,-29,-4,1)
B(-2,-29,-3,1)
B(-2,-29,-2,1)
B(-2,-29,-1,1)
B(-2,-29,0,1)
B(-2,-29,1,1)
B(-2,-29,2,1)
B(-2,-29,3,1)
B(-2,-29,4,1)
B(-2,-29,5,1)
B(-2,-29,6,1)
B(-2,-29,7,1)
B(-2,-29,8,1)
B(-2,-28,-7,1)
B(-2,-28,-6,1)
B(-2,-28,-5,1)
B(-2,-28,-4,1)
B(-2,-28,-3,1)
B(-2,-28,-2,1)
B(-2,-28,-1,1)
B(-2,-28,0,1)
B(-2,-28,1,1)
B(-2,-28,2,1)
B(-2,-28,3,1)
B(-2,-28,4,1)
B(-2,-28,5,1)
B(-2,-28,6,1)
B(-2,-28,7,1)
B(-2,-28,8,1)
B(-2,-27,-7,1)
B(-2,-27,-6,1)
B(-2,-27,-5,1)
B(-2,-27,-4,1)
B(-2,-27,-3,1)
B(-2,-27,-2,1)
B(-2,-27,-1,1)
B(-2,-27,0,1)
B(-2,-27,1,1)
B(-2,-27,2,1)
B(-2,-27,3,1)
B(-2,-27,4,1)
B(-2,-27,5,1)
B(-2,-27,6,1)
B(-2,-27,7,1)
B(-2,-27,8,1)
B(-2,-26,-7,1)
B(-2,-26,-6,1)
B(-2,-26,-5,1)
B(-2,-26,-4,1)
B(-2,-26,-3,1)
B(-2,-26,-2,1)
B(-2,-26,-1,1)
B(-2,-26,0,1)
B(-2,-26,1,1)
B(-2,-26,2,1)
B(-2,-26,3,1)
B(-2,-26,4,1)
B(-2,-26,5,1)
B(-2,-26,6,1)
B(-2,-26,7,1)
B(-2,-26,8,1)
B(-2,-25,-7,1)
B(-2,-25,-6,1)
B(-2,-25,-5,1)
B(-2,-25,-4,1)
B(-2,-25,-3,1)
B(-2,-25,-2,1)
B(-2,-25,-1,1)
B(-2,-25,0,1)
B(-2,-25,1,1)
B(-2,-25,2,1)
B(-2,-25,3,1)
B(-2,-25,4,1)
B(-2,-25,5,1)
B(-2,-25,6,1)
B(-2,-25,7,1)
B(-2,-25,8,1)
B(-2,-24,-7,1)
B(-2,-24,-6,1)
B(-2,-24,-5,1)
B(-2,-24,-4,1)
B(-2,-24,-3,1)
B(-2,-24,-2,1)
B(-2,-24,-1,1)
B(-2,-24,0,1)
B(-2,-24,1,1)
B(-2,-24,2,1)
B(-2,-24,3,1)
B(-2,-24,4,1)
B(-2,-24,5,1)
B(-2,-24,6,1)
B(-2,-24,7,1)
B(-2,-24,8,1)
B(-2,-23,-7,1)
B(-2,-23,-6,1)
B(-2,-23,-5,1)
B(-2,-23,-4,1)
B(-2,-23,-3,1)
B(-2,-23,-2,1)
B(-2,-23,-1,1)
B(-2,-23,0,1)
B(-2,-23,1,1)
B(-2,-23,2,1)
B(-2,-23,3,1)
B(-2,-23,4,1)
B(-2,-23,5,1)
B(-2,-23,6,1)
B(-2,-23,7,1)
B(-2,-23,8,1)
B(-2,-22,-7,1)
B(-2,-22,-6,1)
B(-2,-22,-5,1)
B(-2,-22,-4,1)
B(-2,-22,-3,1)
B(-2,-22,-2,1)
B(-2,-22,-1,1)
B(-2,-22,0,1)
B(-2,-22,1,1)
B(-2,-22,2,1)
B(-2,-22,3,1)
B(-2,-22,4,1)
B(-2,-22,5,1)
B(-2,-22,6,1)
B(-2,-22,7,1)
B(-2,-22,8,1)
B(-2,-21,-7,1)
B(-2,-21,-6,1)
B(-2,-21,-5,1)
B(-2,-21,-4,1)
B(-2,-21,-3,1)
B(-2,-21,-2,1)
B(-2,-21,-1,1)
B(-2,-21,0,1)
B(-2,-21,1,1)
B(-2,-21,2,1)
B(-2,-21,3,1)
B(-2,-21,4,1)
B(-2,-21,5,1)
B(-2,-21,6,1)
B(-2,-21,7,1)
B(-2,-21,8,1)
B(-2,-20,-7,1)
B(-2,-20,-6,1)
B(-2,-20,-5,1)
B(-2,-20,-4,1)
B(-2,-20,-3,1)
B(-2,-20,-2,1)
B(-2,-20,-1,1)
B(-2,-20,0,1)
B(-2,-20,1,1)
B(-2,-20,2,1)
B(-2,-20,3,1)
B(-2,-20,4,1)
B(-2,-20,5,1)
B(-2,-20,6,1)
B(-2,-20,7,1)
B(-2,-20,8,1)
B(-2,-19,-7,1)
B(-2,-19,-6,1)
B(-2,-19,-5,1)
B(-2,-19,-4,1)
B(-2,-19,-3,1)
B(-2,-19,-2,1)
B(-2,-19,-1,1)
B(-2,-19,0,1)
B(-2,-19,1,1)
B(-2,-19,2,1)
B(-2,-19,3,1)
B(-2,-19,4,1)
B(-2,-19,5,1)
B(-2,-19,6,1)
B(-2,-19,7,1)
B(-2,-19,8,1)
B(-2,-18,-7,1)
B(-2,-18,-6,1)
B(-2,-18,-5,1)
B(-2,-18,-4,1)
B(-2,-18,-3,1)
B(-2,-18,-2,1)
B(-2,-18,-1,1)
B(-2,-18,0,1)
B(-2,-18,1,1)
B(-2,-18,2,1)
B(-2,-18,3,1)
B(-2,-18,4,1)
B(-2,-18,5,1)
B(-2,-18,6,1)
B(-2,-18,7,1)
B(-2,-18,8,1)
B(-2,-17,-7,1)
B(-2,-17,-6,1)
B(-2,-17,-5,1)
B(-2,-17,-4,1)
B(-2,-17,-3,1)
B(-2,-17,-2,1)
B(-2,-17,-1,1)
B(-2,-17,0,1)
B(-2,-17,1,1)
B(-2,-17,2,1)
B(-2,-17,3,1)
B(-2,-17,4,1)
B(-2,-17,5,1)
B(-2,-17,6,1)
B(-2,-17,7,1)
B(-2,-17,8,1)
B(-2,-16,-7,1)
B(-2,-16,-6,1)
B(-2,-16,-5,1)
B(-2,-16,-4,1)
B(-2,-16,-3,1)
B(-2,-16,-2,1)
B(-2,-16,-1,1)
B(-2,-16,0,1)
B(-2,-16,1,1)
B(-2,-16,2,1)
B(-2,-16,3,1)
B(-2,-16,4,1)
B(-2,-16,5,1)
B(-2,-16,6,1)
B(-2,-16,7,1)
B(-2,-16,8,1)
B(-2,-15,-7,1)
B(-2,-15,-6,1)
B(-2,-15,-5,1)
B(-2,-15,-4,1)
B(-2,-15,-3,1)
B(-2,-15,-2,1)
B(-2,-15,-1,1)
B(-2,-15,0,1)
B(-2,-15,1,1)
B(-2,-15,2,1)
B(-2,-15,3,1)
B(-2,-15,4,1)
B(-2,-15,5,1)
B(-2,-15,6,1)
B(-2,-15,7,1)
B(-2,-15,8,1)
B(-2,-14,-7,1)
B(-2,-14,-6,1)
B(-2,-14,-5,1)
B(-2,-14,-4,1)
B(-2,-14,-3,1)
B(-2,-14,-2,1)
B(-2,-14,-1,1)
B(-2,-14,0,1)
B(-2,-14,1,1)
B(-2,-14,2,1)
B(-2,-14,3,1)
B(-2,-14,4,1)
B(-2,-14,5,1)
B(-2,-14,6,1)
B(-2,-14,7,1)
B(-2,-14,8,1)
B(-2,-13,-7,1)
B(-2,-13,-6,1)
B(-2,-13,-5,1)
B(-2,-13,-4,1)
B(-2,-13,-3,1)
B(-2,-13,-2,1)
B(-2,-13,-1,1)
B(-2,-13,0,1)
B(-2,-13,1,1)
B(-2,-13,2,1)
B(-2,-13,3,1)
B(-2,-13,4,1)
B(-2,-13,5,1)
B(-2,-13,6,1)
B(-2,-13,7,1)
B(-2,-13,8,1)
B(-2,-12,-7,1)
B(-2,-12,-6,1)
B(-2,-12,-5,1)
B(-2,-12,-4,1)
B(-2,-12,-3,1)
B(-2,-12,-2,1)
B(-2,-12,-1,1)
B(-2,-12,0,1)
B(-2,-12,1,1)
B(-2,-12,2,1)
B(-2,-12,3,1)
B(-2,-12,4,1)
B(-2,-12,5,1)
B(-2,-12,6,1)
B(-2,-12,7,1)
B(-2,-12,8,1)
B(-2,-11,-7,1)
B(-2,-11,-6,1)
B(-2,-11,-5,1)
B(-2,-11,-4,1)
B(-2,-11,-3,1)
B(-2,-11,-2,1)
B(-2,-11,-1,1)
B(-2,-11,0,1)
B(-2,-11,1,1)
B(-2,-11,2,1)
B(-2,-11,3,1)
B(-2,-11,4,1)
B(-2,-11,5,1)
B(-2,-11,6,1)
B(-2,-11,7,1)
B(-2,-11,8,1)
B(-2,-10,-7,1)
B(-2,-10,-6,1)
B(-2,-10,-5,1)
B(-2,-10,-4,1)
B(-2,-10,-3,1)
B(-2,-10,-2,1)
B(-2,-10,-1,1)
B(-2,-10,0,1)
B(-2,-10,1,1)
B(-2,-10,2,1)
B(-2,-10,3,1)
B(-2,-10,4,1)
B(-2,-10,5,1)
B(-2,-10,6,1)
B(-2,-10,7,1)
B(-2,-10,8,1)
B(-2,-9,-7,1)
B(-2,-9,-6,1)
B(-2,-9,-5,1)
B(-2,-9,-4,1)
B(-2,-9,-3,1)
B(-2,-9,-2,1)
B(-2,-9,-1,1)
B(-2,-9,0,1)
B(-2,-9,1,1)
B(-2,-9,2,1)
B(-2,-9,3,1)
B(-2,-9,4,1)
B(-2,-9,5,1)
B(-2,-9,6,1)
B(-2,-9,7,1)
B(-2,-9,8,1)
B(-2,-8,-7,1)
B(-2,-8,-6,1)
B(-2,-8,-5,1)
B(-2,-8,-4,1)
B(-2,-8,-3,1)
B(-2,-8,-2,1)
B(-2,-8,-1,1)
B(-2,-8,0,1)
B(-2,-8,1,1)
B(-2,-8,2,1)
B(-2,-8,3,1)
B(-2,-8,4,1)
B(-2,-8,5,1)
B(-2,-8,6,1)
B(-2,-8,7,1)
B(-2,-8,8,1)
B(-2,-7,-7,1)
B(-2,-7,-6,1)
B(-2,-7,-5,1)
B(-2,-7,-4,1)
B(-2,-7,-3,1)
B(-2,-7,-2,1)
B(-2,-7,-1,1)
B(-2,-7,0,1)
B(-2,-7,1,1)
B(-2,-7,2,1)
B(-2,-7,3,1)
B(-2,-7,4,1)
B(-2,-7,5,1)
B(-2,-7,6,1)
B(-2,-7,7,1)
B(-2,-7,8,1)
B(-2,-6,-7,1)
B(-2,-6,-6,1)
B(-2,-6,-5,1)
B(-2,-6,-4,1)
B(-2,-6,-3,1)
B(-2,-6,-2,1)
B(-2,-6,-1,1)
B(-2,-6,0,1)
B(-2,-6,1,1)
B(-2,-6,2,1)
B(-2,-6,3,1)
B(-2,-6,4,1)
B(-2,-6,5,1)
B(-2,-6,6,1)
B(-2,-6,7,1)
B(-2,-6,8,1)
B(-2,-5,-6,1)
B(-2,-5,-5,1)
B(-2,-5,-4,1)
B(-2,-5,-3,1)
B(-2,-5,-2,1)
B(-2,-5,-1,1)
B(-2,-5,0,1)
B(-2,-5,1,1)
B(-2,-5,2,1)
B(-2,-5,3,1)
B(-2,-5,4,1)
B(-2,-5,5,1)
B(-2,-5,6,1)
B(-2,-5,7,1)
B(-2,-5,8,1)
B(-2,-4,-2,1)
B(-2,-4,-1,1)
B(-2,-4,0,1)
B(-2,-4,1,1)
B(-2,-4,5,1)
B(-2,-4,6,1)
B(-2,-4,7,1)
B(-2,-4,8,1)
B(-2,-3,6,1)
B(-2,-3,7,1)
B(-2,-3,8,1)
B(-2,-2,-6,AIR)
B(-2,-2,-5,AIR)
B(-2,-2,-4,AIR)
B(-2,-2,-3,AIR)
B(-2,-2,-2,AIR)
B(-2,-2,-1,AIR)
B(-2,-2,0,AIR)
B(-2,-2,1,AIR)
B(-2,-2,2,AIR)
B(-2,-2,3,AIR)
B(-2,-2,4,AIR)
B(-2,-2,5,AIR)
B(-2,-2,6,1)
B(-2,-2,7,1)
B(-2,-2,8,1)
B(-2,-1,-6,AIR)
B(-2,-1,-5,AIR)
B(-2,-1,-4,AIR)
B(-2,-1,-3,AIR)
B(-2,-1,-2,AIR)
B(-2,-1,-1,AIR)
B(-2,-1,0,AIR)
B(-2,-1,1,AIR)
B(-2,-1,2,AIR)
B(-2,-1,3,AIR)
B(-2,-1,4,AIR)
B(-2,-1,5,AIR)
B(-2,-1,6,AIR)
B(-2,-1,7,1)
B(-2,-1,8,1)
B(-2,0,-6,AIR)
B(-2,0,-5,AIR)
B(-2,0,-4,AIR)
B(-2,0,-3,AIR)
B(-2,0,-2,AIR)
B(-2,0,-1,AIR)
B(-2,0,0,AIR)
B(-2,0,1,AIR)
B(-2,0,2,AIR)
B(-2,0,3,AIR)
B(-2,0,4,AIR)
B(-2,0,5,AIR)
B(-2,0,6,AIR)
B(-2,0,7,AIR)
B(-2,0,8,1)
B(-2,1,-6,AIR)
B(-2,1,-5,AIR)
B(-2,1,-4,AIR)
B(-2,1,-3,AIR)
B(-2,1,-2,AIR)
B(-2,1,-1,AIR)
B(-2,1,0,AIR)
B(-2,1,1,AIR)
B(-2,1,2,AIR)
B(-2,1,3,AIR)
B(-2,1,4,AIR)
B(-2,1,5,AIR)
B(-2,1,6,AIR)
B(-2,1,7,AIR)
B(-2,1,8,AIR)
B(-2,2,-6,AIR)
B(-2,2,-5,AIR)
B(-2,2,-4,AIR)
B(-2,2,-3,AIR)
B(-2,2,-2,AIR)
B(-2,2,-1,AIR)
B(-2,2,0,AIR)
B(-2,2,1,AIR)
B(-2,2,2,AIR)
B(-2,2,3,AIR)
B(-2,2,4,AIR)
B(-2,2,5,AIR)
B(-2,2,6,AIR)
B(-2,2,7,AIR)
B(-2,2,8,AIR)
B(-2,3,-6,AIR)
B(-2,3,-5,AIR)
B(-2,3,-4,AIR)
B(-2,3,-3,AIR)
B(-2,3,-2,AIR)
B(-2,3,-1,AIR)
B(-2,3,0,AIR)
B(-2,3,1,AIR)
B(-2,3,2,AIR)
B(-2,3,3,AIR)
B(-2,3,4,AIR)
B(-2,3,5,AIR)
B(-2,3,6,AIR)
B(-2,3,7,AIR)
B(-2,3,8,AIR)
B(-2,4,-6,AIR)
B(-2,4,-5,AIR)
B(-2,4,-4,AIR)
B(-2,4,-3,AIR)
B(-2,4,-2,AIR)
B(-2,4,-1,AIR)
B(-2,4,0,AIR)
B(-2,4,1,AIR)
B(-2,4,2,AIR)
B(-2,4,3,AIR)
B(-2,4,4,AIR)
B(-2,4,5,AIR)
B(-2,4,6,AIR)
B(-2,4,7,AIR)
B(-2,4,8,AIR)
B(-2,5,-6,AIR)
B(-2,5,-5,AIR)
B(-2,5,-4,AIR)
B(-2,5,-3,AIR)
B(-2,5,-2,AIR)
B(-2,5,-1,AIR)
B(-2,5,0,AIR)
B(-2,5,1,AIR)
B(-2,5,2,AIR)
B(-2,5,3,AIR)
B(-2,5,4,AIR)
B(-2,5,5,AIR)
B(-2,5,6,AIR)
B(-2,5,7,AIR)
B(-2,5,8,AIR)
B(-2,6,-6,AIR)
B(-2,6,-5,AIR)
B(-2,6,-4,AIR)
B(-2,6,-3,AIR)
B(-2,6,-2,AIR)
B(-2,6,-1,AIR)
B(-2,6,0,AIR)
B(-2,6,1,AIR)
B(-2,6,2,AIR)
B(-2,6,3,AIR)
B(-2,6,4,AIR)
B(-2,6,5,AIR)
B(-2,6,6,AIR)
B(-2,6,7,AIR)
B(-2,6,8,AIR)
B(-2,7,-6,AIR)
B(-2,7,-5,AIR)
B(-2,7,-4,AIR)
B(-2,7,-3,AIR)
B(-2,7,-2,AIR)
B(-2,7,-1,AIR)
B(-2,7,0,AIR)
B(-2,7,1,AIR)
B(-2,7,2,AIR)
B(-2,7,3,AIR)
B(-2,7,4,AIR)
B(-2,7,5,AIR)
B(-2,7,6,AIR)
B(-2,7,7,AIR)
B(-2,7,8,AIR)
B(-2,8,-6,AIR)
B(-2,8,-5,AIR)
B(-2,8,-4,AIR)
B(-2,8,-3,AIR)
B(-2,8,-2,AIR)
B(-2,8,-1,AIR)
B(-2,8,0,AIR)
B(-2,8,1,AIR)
B(-2,8,2,AIR)
B(-2,8,3,AIR)
B(-2,8,4,AIR)
B(-2,8,5,AIR)
B(-2,8,6,AIR)
B(-2,8,7,AIR)
B(-2,8,8,AIR)
B(-2,9,-6,AIR)
B(-2,9,-5,AIR)
B(-2,9,-4,AIR)
B(-2,9,-3,AIR)
B(-2,9,-2,AIR)
B(-2,9,-1,AIR)
B(-2,9,0,AIR)
B(-2,9,1,AIR)
B(-2,9,2,AIR)
B(-2,9,3,AIR)
B(-2,9,4,AIR)
B(-2,9,5,AIR)
B(-2,9,6,AIR)
B(-2,9,7,AIR)
B(-2,9,8,AIR)
B(-2,10,-6,AIR)
B(-2,10,-5,AIR)
B(-2,10,-4,AIR)
B(-2,10,-3,AIR)
B(-2,10,-2,AIR)
B(-2,10,-1,AIR)
B(-2,10,0,AIR)
B(-2,10,1,AIR)
B(-2,10,2,AIR)
B(-2,10,3,AIR)
B(-2,10,4,AIR)
B(-2,10,5,AIR)
B(-2,10,6,AIR)
B(-2,10,7,AIR)
B(-2,10,8,AIR)
B(-2,11,-6,AIR)
B(-2,11,-5,AIR)
B(-2,11,-4,AIR)
B(-2,11,-3,AIR)
B(-2,11,-2,AIR)
B(-2,11,-1,AIR)
B(-2,11,0,AIR)
B(-2,11,1,AIR)
B(-2,11,2,AIR)
B(-2,11,3,AIR)
B(-2,11,4,AIR)
B(-2,11,5,AIR)
B(-2,11,6,AIR)
B(-2,11,7,AIR)
B(-2,11,8,AIR)
B(-2,12,-6,AIR)
B(-2,12,-5,AIR)
B(-2,12,-4,AIR)
B(-2,12,-3,AIR)
B(-2,12,-2,AIR)
B(-2,12,-1,AIR)
B(-2,12,0,AIR)
B(-2,12,1,AIR)
B(-2,12,2,AIR)
B(-2,12,3,AIR)
B(-2,12,4,AIR)
B(-2,12,5,AIR)
B(-2,12,6,AIR)
