[META]
version=2.0
spawnOnBlockType=49,11
spawnSunlight=True
spawnDarkness=True
spawnWater=False
spawnLava=False
underFill=False
randomRotation=True
dig=True
tree=False
branch=False
needsFoundation=True
rarity=25
collisionPercentage=5
spawnElevationMin=0
spawnElevationMax=58
spawnInBiome=Custom
[DATA]
1,-1,-8:49
1,0,-8:49
1,1,-8:49
0,-3,-7:49
0,-2,-7:49
1,-2,-7:49
0,-1,-7:49
1,-1,-7:49
2,-1,-7:49
-1,0,-7:49
0,0,-7:49
1,0,-7:49
2,0,-7:49
3,0,-7:49
-1,1,-7:49
0,1,-7:49
1,1,-7:49
1,2,-7:49
0,-4,-6:49
-1,-3,-6:49
0,-3,-6:49
1,-3,-6:49
0,-2,-6:49
1,-2,-6:49
-2,-1,-6:49
-1,-1,-6:49
0,-1,-6:49
1,-1,-6:49
2,-1,-6:49
3,-1,-6:49
-3,0,-6:49
-2,0,-6:49
-1,0,-6:49
0,0,-6:49
1,0,-6:49
2,0,-6:49
3,0,-6:49
4,0,-6:49
-4,1,-6:49
-3,1,-6:49
-2,1,-6:49
-1,1,-6:49
0,1,-6:49
1,1,-6:49
2,1,-6:49
-2,2,-6:49
-1,2,-6:49
0,2,-6:49
1,2,-6:49
2,2,-6:49
-1,3,-6:49
0,3,-6:49
1,3,-6:49
0,4,-6:49
0,-4,-5:49
-2,-3,-5:49
-1,-3,-5:49
0,-3,-5:49
1,-3,-5:49
2,-3,-5:49
-2,-2,-5:49
-1,-2,-5:49
0,-2,-5:49
1,-2,-5:49
2,-2,-5:49
-3,-1,-5:49
-2,-1,-5:49
-1,-1,-5:49
0,-1,-5:49
1,-1,-5:49
2,-1,-5:49
3,-1,-5:49
-4,0,-5:49
-3,0,-5:49
-2,0,-5:49
-1,0,-5:49
0,0,-5:49
1,0,-5:49
2,0,-5:49
3,0,-5:49
4,0,-5:49
-4,1,-5:49
-3,1,-5:49
-2,1,-5:49
-1,1,-5:49
0,1,-5:49
1,1,-5:49
2,1,-5:49
3,1,-5:49
4,1,-5:49
-3,2,-5:49
-2,2,-5:49
-1,2,-5:49
0,2,-5:49
1,2,-5:49
2,2,-5:49
3,2,-5:49
-2,3,-5:49
-1,3,-5:49
0,3,-5:49
1,3,-5:49
-1,4,-5:49
0,4,-5:49
0,-4,-4:49
1,-4,-4:49
-2,-3,-4:49
-1,-3,-4:49
0,-3,-4:49
1,-3,-4:49
2,-3,-4:49
-2,-2,-4:49
-1,-2,-4:49
0,-2,-4:49
1,-2,-4:49
2,-2,-4:49
3,-2,-4:49
-3,-1,-4:49
-2,-1,-4:49
-1,-1,-4:11
0,-1,-4:11
1,-1,-4:11
2,-1,-4:49
3,-1,-4:49
4,-1,-4:49
-3,0,-4:49
-2,0,-4:49
-1,0,-4:11
0,0,-4:11
1,0,-4:11
2,0,-4:49
3,0,-4:49
4,0,-4:49
-3,1,-4:49
-2,1,-4:49
-1,1,-4:49
0,1,-4:49
1,1,-4:49
2,1,-4:49
3,1,-4:49
4,1,-4:49
-2,2,-4:49
-1,2,-4:49
0,2,-4:49
1,2,-4:49
2,2,-4:49
-2,3,-4:49
-1,3,-4:49
0,3,-4:49
1,3,-4:49
2,3,-4:49
-1,4,-4:49
0,4,-4:49
1,4,-4:49
0,-4,-3:49
-1,-3,-3:49
0,-3,-3:49
1,-3,-3:49
-2,-2,-3:49
-1,-2,-3:49
0,-2,-3:11
1,-2,-3:11
2,-2,-3:49
-2,-1,-3:49
-1,-1,-3:11
0,-1,-3:11
1,-1,-3:11
2,-1,-3:11
3,-1,-3:49
-2,0,-3:49
-1,0,-3:11
0,0,-3:11
1,0,-3:11
2,0,-3:11
3,0,-3:49
-2,1,-3:49
-1,1,-3:11
0,1,-3:11
1,1,-3:49
2,1,-3:49
3,1,-3:49
-2,2,-3:49
-1,2,-3:49
0,2,-3:49
1,2,-3:49
2,2,-3:49
-1,3,-3:49
0,3,-3:49
1,3,-3:49
0,4,-3:49
0,-3,-2:49
-1,-2,-2:49
0,-2,-2:49
1,-2,-2:49
-2,-1,-2:49
-1,-1,-2:11
0,-1,-2:11
1,-1,-2:11
2,-1,-2:49
-2,0,-2:49
-1,0,-2:11
0,0,-2:11
1,0,-2:11
2,0,-2:49
3,0,-2:49
-2,1,-2:49
-1,1,-2:11
0,1,-2:11
1,1,-2:49
2,1,-2:49
-1,2,-2:49
0,2,-2:49
1,2,-2:49
0,3,-2:49
1,3,-2:49
0,-2,-1:49
-1,-1,-1:49
1,-1,-1:49
-2,0,-1:49
-1,0,-1:49
-1,1,-1:49
1,1,-1:49
0,2,-1:49
1,3,-1:49
-1,-1,0:49
-2,0,0:49
-1,0,0:49
1,3,0:49
-1,-1,1:49
-2,0,1:49
-2,0,2:49
-2,0,3:49

