#######################################################################
# +-----------------------------------------------------------------+ #
# |                            BO3 object                           | #
# +-----------------------------------------------------------------+ #
#######################################################################

# The descriptions in this file are true only for TerrainControl. They are not true for the Minecraft Worlds mod!
# Minecraft Worlds completely reimplemented BO3s, check the MCW documentation on the mc/mctcp forums for how to use BO3s with MCW
# or watch the video's on my YT channel at https://www.youtube.com/user/PeeGee85. You can check out the "Editing and importing schematics & BO3s" 
# series of video's, in part 2 I explain BO3s. 

# This is the config file of a custom object.
# If you add this object correctly to your BiomeConfigs, it will spawn in the world.

# This is the creator of this BO3 object
Author: Unknown

# A short description of this BO3 object
Description: This BO3 was converted from a schematic using the MineCraft Worlds Editor. Unfortunately the author and description information for the schematic could not be found. If you know who the author of the schematic is then please tell the author of this BO3!

# The BO3 version, don't change this! It can be used by external applications to do a version check.
Version: 3

# The settings mode, WriteAll, WriteWithoutComments or WriteDisable. See WorldConfig.
SettingsMode: WriteDisable

#######################################################################
# +-----------------------------------------------------------------+ #
# |                          Main settings                          | #
# +-----------------------------------------------------------------+ #
#######################################################################

# This needs to be set to true to spawn the object in the Tree and Sapling resources.
Tree: false

# The frequency of the BO3 from 1 to 200. Tries this many times to spawn this BO3 when using the CustomObject(...) resource.
# Ignored by Tree(..), Sapling(..) and CustomStructure(..)
Frequency: 40

# The rarity of the BO3 from 0 to 100. Each spawn attempt has rarity% chance to succeed when using the CustomObject(...) resource.
# Ignored by Tree(..), Sapling(..) and CustomStructure(..)
Rarity: 100.0

# If you set this to true, the BO3 will be placed with a random rotation.
RotateRandomly: false

# The spawn height of the BO3 - randomY, highestBlock or highestSolidBlock.
SpawnHeight: randomY

# The height limits for the BO3.
MinHeight: 0

MaxHeight: 256

# Objects can have other objects attached to it: branches. Branches can also
# have branches attached to it, which can also have branches, etc. This is the
# maximum branch depth for this objects.
MaxBranchDepth: 10

# When spawned with the UseWorld keyword, this BO3 should NOT spawn in the following biomes.
# If you writer.write the BO3 name directly in the BiomeConfigs, this will be ignored.
ExcludedBiomes: All

#######################################################################
# +-----------------------------------------------------------------+ #
# |                      Source block settings                      | #
# +-----------------------------------------------------------------+ #
#######################################################################

# The B(s) the BO3 should spawn in.
SourceBlocks: AIR

# The maximum percentage of the BO3 that can be outside the SourceBlock.
# The BO3 won't be placed on a location with more blocks outside the SourceBlock than this percentage.
MaxPercentageOutsideSourceBlock: 100

# What to do when a block is about to be placed outside the SourceBlock? (dontPlace, placeAnyway)
OutsideSourceBlock: placeAnyway

#######################################################################
# +-----------------------------------------------------------------+ #
# |                              Blocks                             | #
# +-----------------------------------------------------------------+ #
#######################################################################

# All the blocks used in the BO3 are listed here. Possible blocks:
# B(x,y,z,id[.data][,nbtfile.nbt)
# RB(x,y,z,id[:data][,nbtfile.nbt],chance[,id[:data][,nbtfile.nbt],chance[,...]])
# So RB(0,0,0,CHEST,chest.nbt,50,CHEST,anotherchest.nbt,100) will spawn a chest at
# the BO3 origin, and give it a 50% chance to have the contents of chest.nbt, or, if that
# fails, a 100% percent chance to have the contents of anotherchest.nbt.

B(-4,38,8,174)
B(-4,39,6,174)
B(-4,39,8,174)
B(-4,40,5,174)
B(-4,40,6,174)
B(-4,40,7,174)
B(-4,40,8,174)
B(-4,41,5,174)
B(-4,41,6,174)
B(-4,41,7,174)
B(-4,41,8,174)
B(-4,42,5,174)
B(-4,42,6,174)
B(-4,42,7,174)
B(-4,42,8,174)
B(-4,43,7,174)
B(-4,43,8,174)
B(-4,44,8,174)
B(-3,35,6,174)
B(-3,36,6,174)
B(-3,36,7,174)
B(-3,37,5,174)
B(-3,37,6,174)
B(-3,37,7,174)
B(-3,37,8,174)
B(-3,38,5,174)
B(-3,38,6,174)
B(-3,38,7,174)
B(-3,38,8,174)
B(-3,39,4,174)
B(-3,39,5,174)
B(-3,39,6,174)
B(-3,39,7,174)
B(-3,39,8,174)
B(-3,40,3,174)
B(-3,40,4,174)
B(-3,40,5,174)
B(-3,40,6,174)
B(-3,40,7,174)
B(-3,40,8,174)
B(-3,41,3,174)
B(-3,41,4,174)
B(-3,41,5,174)
B(-3,41,6,174)
B(-3,41,7,174)
B(-3,41,8,174)
B(-3,42,2,174)
B(-3,42,3,174)
B(-3,42,4,174)
B(-3,42,5,174)
B(-3,42,6,174)
B(-3,42,7,174)
B(-3,42,8,174)
B(-3,43,3,174)
B(-3,43,4,174)
B(-3,43,5,174)
B(-3,43,6,174)
B(-3,43,7,174)
B(-3,43,8,174)
B(-3,44,4,174)
B(-3,44,5,174)
B(-3,44,6,174)
B(-3,44,7,174)
B(-3,44,8,174)
B(-3,45,3,174)
B(-3,45,4,174)
B(-3,45,5,174)
B(-3,45,6,174)
B(-3,45,7,174)
B(-3,45,8,174)
B(-3,46,4,174)
B(-3,46,5,174)
B(-3,46,6,174)
B(-3,46,7,174)
B(-3,46,8,174)
B(-3,47,3,174)
B(-3,47,4,174)
B(-3,47,5,174)
B(-3,47,6,174)
B(-3,47,7,174)
B(-3,47,8,174)
B(-3,48,3,174)
B(-3,48,4,174)
B(-3,48,5,174)
B(-3,48,6,174)
B(-3,48,7,174)
B(-3,49,4,174)
B(-3,49,5,174)
B(-3,49,6,174)
B(-3,49,7,174)
B(-2,31,4,174)
B(-2,32,4,174)
B(-2,32,5,174)
B(-2,32,6,174)
B(-2,33,4,174)
B(-2,33,5,174)
B(-2,33,6,174)
B(-2,34,3,174)
B(-2,34,4,174)
B(-2,34,5,174)
B(-2,34,6,174)
B(-2,35,2,174)
B(-2,35,3,174)
B(-2,35,4,174)
B(-2,35,5,174)
B(-2,35,6,174)
B(-2,35,7,174)
B(-2,36,1,174)
B(-2,36,2,174)
B(-2,36,3,174)
B(-2,36,4,174)
B(-2,36,5,174)
B(-2,36,6,174)
B(-2,36,7,174)
B(-2,36,8,174)
B(-2,37,1,174)
B(-2,37,2,174)
B(-2,37,3,174)
B(-2,37,4,174)
B(-2,37,5,174)
B(-2,37,6,174)
B(-2,37,7,174)
B(-2,37,8,174)
B(-2,38,2,174)
B(-2,38,3,174)
B(-2,38,4,174)
B(-2,38,5,174)
B(-2,38,6,174)
B(-2,38,7,174)
B(-2,38,8,174)
B(-2,39,1,174)
B(-2,39,2,174)
B(-2,39,3,174)
B(-2,39,4,174)
B(-2,39,5,174)
B(-2,39,6,174)
B(-2,39,7,174)
B(-2,39,8,174)
B(-2,40,2,174)
B(-2,40,3,174)
B(-2,40,4,174)
B(-2,40,5,174)
B(-2,40,6,174)
B(-2,40,7,174)
B(-2,40,8,174)
B(-2,41,2,174)
B(-2,41,3,174)
B(-2,41,4,174)
B(-2,41,5,174)
B(-2,41,6,174)
B(-2,41,7,174)
B(-2,41,8,174)
B(-2,42,1,174)
B(-2,42,2,174)
B(-2,42,3,174)
B(-2,42,4,174)
B(-2,42,5,174)
B(-2,42,6,174)
B(-2,42,7,174)
B(-2,42,8,174)
B(-2,43,1,174)
B(-2,43,2,174)
B(-2,43,3,174)
B(-2,43,4,174)
B(-2,43,5,174)
B(-2,43,6,174)
B(-2,43,7,174)
B(-2,43,8,174)
B(-2,44,1,174)
B(-2,44,2,174)
B(-2,44,3,174)
B(-2,44,4,174)
B(-2,44,5,174)
B(-2,44,6,174)
B(-2,44,7,174)
B(-2,44,8,174)
B(-2,45,0,174)
B(-2,45,1,174)
B(-2,45,2,174)
B(-2,45,3,174)
B(-2,45,4,174)
B(-2,45,5,174)
B(-2,45,6,174)
B(-2,45,7,174)
B(-2,45,8,174)
B(-2,46,1,174)
B(-2,46,2,174)
B(-2,46,3,174)
B(-2,46,4,174)
B(-2,46,5,174)
B(-2,46,6,174)
B(-2,46,7,174)
B(-2,46,8,174)
B(-2,47,1,174)
B(-2,47,2,174)
B(-2,47,3,174)
B(-2,47,4,174)
B(-2,47,5,174)
B(-2,47,6,174)
B(-2,47,7,174)
B(-2,47,8,174)
B(-2,48,2,174)
B(-2,48,3,174)
B(-2,48,4,174)
B(-2,48,5,174)
B(-2,48,6,174)
B(-2,48,7,174)
B(-2,48,8,174)
B(-2,49,2,174)
B(-2,49,3,174)
B(-2,49,4,174)
B(-2,49,5,174)
B(-2,49,6,174)
B(-2,49,7,174)
B(-2,49,8,174)
B(-2,50,3,174)
B(-2,50,4,174)
B(-2,50,5,174)
B(-2,50,6,174)
B(-2,50,7,174)
B(-2,51,4,174)
B(-2,51,5,174)
B(-2,51,6,174)
B(-2,51,7,174)
B(-1,30,4,174)
B(-1,31,3,174)
B(-1,31,4,174)
B(-1,31,5,174)
B(-1,31,6,174)
B(-1,32,3,174)
B(-1,32,4,174)
B(-1,32,5,174)
B(-1,32,6,174)
B(-1,32,7,174)
B(-1,33,3,174)
B(-1,33,4,174)
B(-1,33,5,174)
B(-1,33,6,174)
B(-1,33,7,174)
B(-1,33,8,174)
B(-1,34,2,174)
B(-1,34,3,174)
B(-1,34,4,174)
B(-1,34,5,174)
B(-1,34,6,174)
B(-1,34,7,174)
B(-1,35,0,174)
B(-1,35,1,174)
B(-1,35,2,174)
B(-1,35,3,174)
B(-1,35,4,174)
B(-1,35,5,174)
B(-1,35,6,174)
B(-1,35,7,174)
B(-1,35,8,174)
B(-1,36,0,174)
B(-1,36,1,174)
B(-1,36,2,174)
B(-1,36,3,174)
B(-1,36,4,174)
B(-1,36,5,174)
B(-1,36,6,174)
B(-1,36,7,174)
B(-1,36,8,174)
B(-1,37,-1,174)
B(-1,37,0,174)
B(-1,37,1,174)
B(-1,37,2,174)
B(-1,37,3,174)
B(-1,37,4,174)
B(-1,37,5,174)
B(-1,37,6,174)
B(-1,37,7,174)
B(-1,37,8,174)
B(-1,38,0,174)
B(-1,38,1,174)
B(-1,38,2,174)
B(-1,38,3,174)
B(-1,38,4,174)
B(-1,38,5,174)
B(-1,38,6,174)
B(-1,38,7,174)
B(-1,38,8,174)
B(-1,39,-1,174)
B(-1,39,0,174)
B(-1,39,1,174)
B(-1,39,2,174)
B(-1,39,3,174)
B(-1,39,4,174)
B(-1,39,5,174)
B(-1,39,6,174)
B(-1,39,7,174)
B(-1,39,8,174)
B(-1,40,-2,174)
B(-1,40,0,174)
B(-1,40,1,174)
B(-1,40,2,174)
B(-1,40,3,174)
B(-1,40,4,174)
B(-1,40,5,174)
B(-1,40,6,174)
B(-1,40,7,174)
B(-1,40,8,174)
B(-1,41,0,174)
B(-1,41,1,174)
B(-1,41,2,174)
B(-1,41,3,174)
B(-1,41,4,174)
B(-1,41,5,174)
B(-1,41,6,174)
B(-1,41,7,174)
B(-1,41,8,174)
B(-1,42,-1,174)
B(-1,42,0,174)
B(-1,42,1,174)
B(-1,42,2,174)
B(-1,42,3,174)
B(-1,42,4,174)
B(-1,42,5,174)
B(-1,42,6,174)
B(-1,42,7,174)
B(-1,42,8,174)
B(-1,43,-2,174)
B(-1,43,-1,174)
B(-1,43,0,174)
B(-1,43,1,174)
B(-1,43,2,174)
B(-1,43,3,174)
B(-1,43,4,174)
B(-1,43,5,174)
B(-1,43,6,174)
B(-1,43,7,174)
B(-1,43,8,174)
B(-1,44,-2,174)
B(-1,44,-1,174)
B(-1,44,0,174)
B(-1,44,1,174)
B(-1,44,2,174)
B(-1,44,3,174)
B(-1,44,4,174)
B(-1,44,5,174)
B(-1,44,6,174)
B(-1,44,7,174)
B(-1,44,8,174)
B(-1,45,-1,174)
B(-1,45,0,174)
B(-1,45,1,174)
B(-1,45,2,174)
B(-1,45,3,174)
B(-1,45,4,174)
B(-1,45,5,174)
B(-1,45,6,174)
B(-1,45,7,174)
B(-1,45,8,174)
B(-1,46,-1,174)
B(-1,46,0,174)
B(-1,46,1,174)
B(-1,46,2,174)
B(-1,46,3,174)
B(-1,46,4,174)
B(-1,46,5,174)
B(-1,46,6,174)
B(-1,46,7,174)
B(-1,46,8,174)
B(-1,47,0,174)
B(-1,47,1,174)
B(-1,47,2,174)
B(-1,47,3,174)
B(-1,47,4,174)
B(-1,47,5,174)
B(-1,47,6,174)
B(-1,47,7,174)
B(-1,47,8,174)
B(-1,48,1,174)
B(-1,48,2,174)
B(-1,48,3,174)
B(-1,48,4,174)
B(-1,48,5,174)
B(-1,48,6,174)
B(-1,48,7,174)
B(-1,48,8,174)
B(-1,49,2,174)
B(-1,49,3,174)
B(-1,49,4,174)
B(-1,49,5,174)
B(-1,49,6,174)
B(-1,49,7,174)
B(-1,49,8,174)
B(-1,50,3,174)
B(-1,50,4,174)
B(-1,50,5,174)
B(-1,50,6,174)
B(-1,50,7,174)
B(-1,50,8,174)
B(-1,51,3,174)
B(-1,51,4,174)
B(-1,51,5,174)
B(-1,51,6,174)
B(-1,51,7,174)
B(-1,51,8,174)
B(0,29,4,174)
B(0,29,6,174)
B(0,30,4,174)
B(0,30,5,174)
B(0,30,6,174)
B(0,30,7,174)
B(0,30,8,174)
B(0,31,3,174)
B(0,31,4,174)
B(0,31,5,174)
B(0,31,6,174)
B(0,31,7,174)
B(0,32,3,174)
B(0,32,4,174)
B(0,32,5,174)
B(0,32,6,174)
B(0,32,7,174)
B(0,32,8,174)
B(0,33,1,174)
B(0,33,2,174)
B(0,33,3,174)
B(0,33,4,174)
B(0,33,5,174)
B(0,33,6,174)
B(0,33,7,174)
B(0,33,8,174)
B(0,34,0,174)
B(0,34,1,174)
B(0,34,2,174)
B(0,34,3,174)
B(0,34,4,174)
B(0,34,5,174)
B(0,34,6,174)
B(0,34,7,174)
B(0,34,8,174)
B(0,35,-1,174)
B(0,35,0,174)
B(0,35,1,174)
B(0,35,2,174)
B(0,35,3,174)
B(0,35,4,174)
B(0,35,5,174)
B(0,35,6,174)
B(0,35,7,174)
B(0,35,8,174)
B(0,36,-1,174)
B(0,36,0,174)
B(0,36,1,174)
B(0,36,2,174)
B(0,36,3,174)
B(0,36,4,174)
B(0,36,5,174)
B(0,36,6,174)
B(0,36,7,174)
B(0,36,8,174)
B(0,37,-2,174)
B(0,37,-1,174)
B(0,37,0,174)
B(0,37,1,174)
B(0,37,2,174)
B(0,37,3,174)
B(0,37,4,174)
B(0,37,5,174)
B(0,37,6,174)
B(0,37,7,174)
B(0,37,8,174)
B(0,38,-1,174)
B(0,38,0,174)
B(0,38,1,174)
B(0,38,2,174)
B(0,38,3,174)
B(0,38,4,174)
B(0,38,5,174)
B(0,38,6,174)
B(0,38,7,174)
B(0,38,8,174)
B(0,39,-2,174)
B(0,39,-1,174)
B(0,39,0,174)
B(0,39,1,174)
B(0,39,2,174)
B(0,39,3,174)
B(0,39,4,174)
B(0,39,5,174)
B(0,39,6,174)
B(0,39,7,174)
B(0,39,8,174)
B(0,40,-2,174)
B(0,40,-1,174)
B(0,40,0,174)
B(0,40,1,174)
B(0,40,2,174)
B(0,40,3,174)
B(0,40,4,174)
B(0,40,5,174)
B(0,40,6,174)
B(0,40,7,174)
B(0,40,8,174)
B(0,41,-2,174)
B(0,41,-1,174)
B(0,41,0,174)
B(0,41,1,174)
B(0,41,2,174)
B(0,41,3,174)
B(0,41,4,174)
B(0,41,5,174)
B(0,41,6,174)
B(0,41,7,174)
B(0,41,8,174)
B(0,42,-2,174)
B(0,42,-1,174)
B(0,42,0,174)
B(0,42,1,174)
B(0,42,2,174)
B(0,42,3,174)
B(0,42,4,174)
B(0,42,5,174)
B(0,42,6,174)
B(0,42,7,174)
B(0,42,8,174)
B(0,43,-2,174)
B(0,43,-1,174)
B(0,43,0,174)
B(0,43,1,174)
B(0,43,2,174)
B(0,43,3,174)
B(0,43,4,174)
B(0,43,5,174)
B(0,43,6,174)
B(0,43,7,174)
B(0,43,8,174)
B(0,44,-2,174)
B(0,44,-1,174)
B(0,44,0,174)
B(0,44,1,174)
B(0,44,2,174)
B(0,44,3,174)
B(0,44,4,174)
B(0,44,5,174)
B(0,44,6,174)
B(0,44,7,174)
B(0,44,8,174)
B(0,45,-2,174)
B(0,45,-1,174)
B(0,45,0,174)
B(0,45,1,174)
B(0,45,2,174)
B(0,45,3,174)
B(0,45,4,174)
B(0,45,5,174)
B(0,45,6,174)
B(0,45,7,174)
B(0,45,8,174)
B(0,46,-1,174)
B(0,46,0,174)
B(0,46,1,174)
B(0,46,2,174)
B(0,46,3,174)
B(0,46,4,174)
B(0,46,5,174)
B(0,46,6,174)
B(0,46,7,174)
B(0,46,8,174)
B(0,47,-1,174)
B(0,47,0,174)
B(0,47,1,174)
B(0,47,2,174)
B(0,47,3,174)
B(0,47,4,174)
B(0,47,5,174)
B(0,47,6,174)
B(0,47,7,174)
B(0,47,8,174)
B(0,48,0,174)
B(0,48,1,174)
B(0,48,2,174)
B(0,48,3,174)
B(0,48,4,174)
B(0,48,5,174)
B(0,48,6,174)
B(0,48,7,174)
B(0,48,8,174)
B(0,49,1,174)
B(0,49,2,174)
B(0,49,3,174)
B(0,49,4,174)
B(0,49,5,174)
B(0,49,6,174)
B(0,49,7,174)
B(0,49,8,174)
B(0,50,2,174)
B(0,50,3,174)
B(0,50,4,174)
B(0,50,5,174)
B(0,50,6,174)
B(0,50,7,174)
B(0,50,8,174)
B(0,51,3,174)
B(0,51,4,174)
B(0,51,5,174)
B(0,51,6,174)
B(0,51,7,174)
B(0,51,8,174)
B(0,52,4,174)
B(0,52,5,174)
B(0,52,6,174)
B(0,52,7,174)
B(0,52,8,174)
B(1,27,3,174)
B(1,27,4,174)
B(1,27,5,174)
B(1,27,6,174)
B(1,28,3,174)
B(1,28,4,174)
B(1,28,5,174)
B(1,28,6,174)
B(1,28,7,174)
B(1,29,2,174)
B(1,29,3,174)
B(1,29,4,174)
B(1,29,5,174)
B(1,29,6,174)
B(1,29,7,174)
B(1,29,8,174)
B(1,30,1,174)
B(1,30,2,174)
B(1,30,3,174)
B(1,30,4,174)
B(1,30,5,174)
B(1,30,6,174)
B(1,30,7,174)
B(1,30,8,174)
B(1,31,0,174)
B(1,31,1,174)
B(1,31,2,174)
B(1,31,3,174)
B(1,31,4,174)
B(1,31,5,174)
B(1,31,6,174)
B(1,31,7,174)
B(1,31,8,174)
B(1,32,0,174)
B(1,32,1,174)
B(1,32,2,174)
B(1,32,3,174)
B(1,32,4,174)
B(1,32,5,174)
B(1,32,6,174)
B(1,32,7,174)
B(1,32,8,174)
B(1,33,0,174)
B(1,33,1,174)
B(1,33,2,174)
B(1,33,3,174)
B(1,33,4,174)
B(1,33,5,174)
B(1,33,6,174)
B(1,33,7,174)
B(1,33,8,174)
B(1,34,-1,174)
B(1,34,0,174)
B(1,34,1,174)
B(1,34,2,174)
B(1,34,3,174)
B(1,34,4,174)
B(1,34,5,174)
B(1,34,6,174)
B(1,34,7,174)
B(1,34,8,174)
B(1,35,-1,174)
B(1,35,0,174)
B(1,35,1,174)
B(1,35,2,174)
B(1,35,3,174)
B(1,35,4,174)
B(1,35,5,174)
B(1,35,6,174)
B(1,35,7,174)
B(1,35,8,174)
B(1,36,-1,174)
B(1,36,0,174)
B(1,36,1,174)
B(1,36,2,174)
B(1,36,3,174)
B(1,36,4,174)
B(1,36,5,174)
B(1,36,6,174)
B(1,36,7,174)
B(1,36,8,174)
B(1,37,-2,174)
B(1,37,-1,174)
B(1,37,0,174)
B(1,37,1,174)
B(1,37,2,174)
B(1,37,3,174)
B(1,37,4,174)
B(1,37,5,174)
B(1,37,6,174)
B(1,37,7,174)
B(1,37,8,174)
B(1,38,-1,174)
B(1,38,0,174)
B(1,38,1,174)
B(1,38,2,174)
B(1,38,3,174)
B(1,38,4,174)
B(1,38,5,174)
B(1,38,6,174)
B(1,38,7,174)
B(1,38,8,174)
B(1,39,-2,174)
B(1,39,-1,174)
B(1,39,0,174)
B(1,39,1,174)
B(1,39,2,174)
B(1,39,3,174)
B(1,39,4,174)
B(1,39,5,174)
B(1,39,6,174)
B(1,39,7,174)
B(1,39,8,174)
B(1,40,-2,174)
B(1,40,-1,174)
B(1,40,0,174)
B(1,40,1,174)
B(1,40,2,174)
B(1,40,3,174)
B(1,40,4,174)
B(1,40,5,174)
B(1,40,6,174)
B(1,40,7,174)
B(1,40,8,174)
B(1,41,-2,174)
B(1,41,-1,174)
B(1,41,0,174)
B(1,41,1,174)
B(1,41,2,174)
B(1,41,3,174)
B(1,41,4,174)
B(1,41,5,174)
B(1,41,6,174)
B(1,41,7,174)
B(1,41,8,174)
B(1,42,-2,174)
B(1,42,-1,174)
B(1,42,0,174)
B(1,42,1,174)
B(1,42,2,174)
B(1,42,3,174)
B(1,42,4,174)
B(1,42,5,174)
B(1,42,6,174)
B(1,42,7,174)
B(1,42,8,174)
B(1,43,-2,174)
B(1,43,-1,174)
B(1,43,0,174)
B(1,43,1,174)
B(1,43,2,174)
B(1,43,3,174)
B(1,43,4,174)
B(1,43,5,174)
B(1,43,6,174)
B(1,43,7,174)
B(1,43,8,174)
B(1,44,-2,174)
B(1,44,-1,174)
B(1,44,0,174)
B(1,44,1,174)
B(1,44,2,174)
B(1,44,3,174)
B(1,44,4,174)
B(1,44,5,174)
B(1,44,6,174)
B(1,44,7,174)
B(1,44,8,174)
B(1,45,-2,174)
B(1,45,-1,174)
B(1,45,0,174)
B(1,45,1,174)
B(1,45,2,174)
B(1,45,3,174)
B(1,45,4,174)
B(1,45,5,174)
B(1,45,6,174)
B(1,45,7,174)
B(1,45,8,174)
B(1,46,-2,174)
B(1,46,-1,174)
B(1,46,0,174)
B(1,46,1,174)
B(1,46,2,174)
B(1,46,3,174)
B(1,46,4,174)
B(1,46,5,174)
B(1,46,6,174)
B(1,46,7,174)
B(1,46,8,174)
B(1,47,-1,174)
B(1,47,0,174)
B(1,47,1,174)
B(1,47,2,174)
B(1,47,3,174)
B(1,47,4,174)
B(1,47,5,174)
B(1,47,6,174)
B(1,47,7,174)
B(1,47,8,174)
B(1,48,-1,174)
B(1,48,0,174)
B(1,48,1,174)
B(1,48,2,174)
B(1,48,3,174)
B(1,48,4,174)
B(1,48,5,174)
B(1,48,6,174)
B(1,48,7,174)
B(1,48,8,174)
B(1,49,0,174)
B(1,49,1,174)
B(1,49,2,174)
B(1,49,3,174)
B(1,49,4,174)
B(1,49,5,174)
B(1,49,6,174)
B(1,49,7,174)
B(1,49,8,174)
B(1,50,0,174)
B(1,50,1,174)
B(1,50,2,174)
B(1,50,3,174)
B(1,50,4,174)
B(1,50,5,174)
B(1,50,6,174)
B(1,50,7,174)
B(1,50,8,174)
B(1,51,1,174)
B(1,51,2,174)
B(1,51,3,174)
B(1,51,4,174)
B(1,51,5,174)
B(1,51,6,174)
B(1,51,7,174)
B(1,51,8,174)
B(1,52,2,174)
B(1,52,3,174)
B(1,52,4,174)
B(1,52,5,174)
B(1,52,6,174)
B(1,52,7,174)
B(1,52,8,174)
B(1,53,3,174)
B(1,53,4,174)
B(1,53,5,174)
B(1,53,6,174)
B(1,53,7,174)
B(1,54,3,174)
B(1,54,4,174)
B(1,54,5,174)
B(1,54,6,174)
B(2,26,3,174)
B(2,26,5,174)
B(2,26,6,174)
B(2,27,3,174)
B(2,27,4,174)
B(2,27,5,174)
B(2,27,6,174)
B(2,27,7,174)
B(2,28,2,174)
B(2,28,3,174)
B(2,28,4,174)
B(2,28,5,174)
B(2,28,6,174)
B(2,28,7,174)
B(2,28,8,174)
B(2,29,0,174)
B(2,29,1,174)
B(2,29,2,174)
B(2,29,3,174)
B(2,29,4,174)
B(2,29,5,174)
B(2,29,6,174)
B(2,29,7,174)
B(2,29,8,174)
B(2,30,0,174)
B(2,30,1,174)
B(2,30,2,174)
B(2,30,3,174)
B(2,30,4,174)
B(2,30,5,174)
B(2,30,6,174)
B(2,30,7,174)
B(2,30,8,174)
B(2,31,0,174)
B(2,31,1,174)
B(2,31,2,174)
B(2,31,3,174)
B(2,31,4,174)
B(2,31,5,174)
B(2,31,6,174)
B(2,31,7,174)
B(2,31,8,174)
B(2,32,-1,174)
B(2,32,0,174)
B(2,32,1,174)
B(2,32,2,174)
B(2,32,3,174)
B(2,32,4,174)
B(2,32,5,174)
B(2,32,6,174)
B(2,32,7,174)
B(2,32,8,174)
B(2,33,-1,174)
B(2,33,0,174)
B(2,33,1,174)
B(2,33,2,174)
B(2,33,3,174)
B(2,33,4,174)
B(2,33,5,174)
B(2,33,6,174)
B(2,33,7,174)
B(2,33,8,174)
B(2,34,-2,174)
B(2,34,-1,174)
B(2,34,0,174)
B(2,34,1,174)
B(2,34,2,174)
B(2,34,3,174)
B(2,34,4,174)
B(2,34,5,174)
B(2,34,6,174)
B(2,34,7,174)
B(2,34,8,174)
B(2,35,-1,174)
B(2,35,0,174)
B(2,35,1,174)
B(2,35,2,174)
B(2,35,3,174)
B(2,35,4,174)
B(2,35,5,174)
B(2,35,6,174)
B(2,35,7,174)
B(2,35,8,174)
B(2,36,-2,174)
B(2,36,-1,174)
B(2,36,0,174)
B(2,36,1,174)
B(2,36,2,174)
B(2,36,3,174)
B(2,36,4,174)
B(2,36,5,174)
B(2,36,6,174)
B(2,36,7,174)
B(2,36,8,174)
B(2,37,-2,174)
B(2,37,-1,174)
B(2,37,0,174)
B(2,37,1,174)
B(2,37,2,174)
B(2,37,3,174)
B(2,37,4,174)
B(2,37,5,174)
B(2,37,6,174)
B(2,37,7,174)
B(2,37,8,174)
B(2,38,-2,174)
B(2,38,-1,174)
B(2,38,0,174)
B(2,38,1,174)
B(2,38,2,174)
B(2,38,3,174)
B(2,38,4,174)
B(2,38,5,174)
B(2,38,6,174)
B(2,38,7,174)
B(2,38,8,174)
B(2,39,-2,174)
B(2,39,-1,174)
B(2,39,0,174)
B(2,39,1,174)
B(2,39,2,174)
B(2,39,3,174)
B(2,39,4,174)
B(2,39,5,174)
B(2,39,6,174)
B(2,39,7,174)
B(2,39,8,174)
B(2,40,-2,174)
B(2,40,-1,174)
B(2,40,0,174)
B(2,40,1,174)
B(2,40,2,174)
B(2,40,3,174)
B(2,40,4,174)
B(2,40,5,174)
B(2,40,6,174)
B(2,40,7,174)
B(2,40,8,174)
B(2,41,-2,174)
B(2,41,-1,174)
B(2,41,0,174)
B(2,41,1,174)
B(2,41,2,174)
B(2,41,3,174)
B(2,41,4,174)
B(2,41,5,174)
B(2,41,6,174)
B(2,41,7,174)
B(2,41,8,174)
B(2,42,-2,174)
B(2,42,-1,174)
B(2,42,0,174)
B(2,42,1,174)
B(2,42,2,174)
B(2,42,3,174)
B(2,42,4,174)
B(2,42,5,174)
B(2,42,6,174)
B(2,42,7,174)
B(2,42,8,174)
B(2,43,-3,174)
B(2,43,-2,174)
B(2,43,-1,174)
B(2,43,0,174)
B(2,43,1,174)
B(2,43,2,174)
B(2,43,3,174)
B(2,43,4,174)
B(2,43,5,174)
B(2,43,6,174)
B(2,43,7,174)
B(2,43,8,174)
B(2,44,-3,174)
B(2,44,-2,174)
B(2,44,-1,174)
B(2,44,0,174)
B(2,44,1,174)
B(2,44,2,174)
B(2,44,3,174)
B(2,44,4,174)
B(2,44,5,174)
B(2,44,6,174)
B(2,44,7,174)
B(2,44,8,174)
B(2,45,-2,174)
B(2,45,-1,174)
B(2,45,0,174)
B(2,45,1,174)
B(2,45,2,174)
B(2,45,3,174)
B(2,45,4,174)
B(2,45,5,174)
B(2,45,6,174)
B(2,45,7,174)
B(2,45,8,174)
B(2,46,-2,174)
B(2,46,-1,174)
B(2,46,0,174)
B(2,46,1,174)
B(2,46,2,174)
B(2,46,3,174)
B(2,46,4,174)
B(2,46,5,174)
B(2,46,6,174)
B(2,46,7,174)
B(2,46,8,174)
B(2,47,-2,174)
B(2,47,-1,174)
B(2,47,0,174)
B(2,47,1,174)
B(2,47,2,174)
B(2,47,3,174)
B(2,47,4,174)
B(2,47,5,174)
B(2,47,6,174)
B(2,47,7,174)
B(2,47,8,174)
B(2,48,-1,174)
B(2,48,0,174)
B(2,48,1,174)
B(2,48,2,174)
B(2,48,3,174)
B(2,48,4,174)
B(2,48,5,174)
B(2,48,6,174)
B(2,48,7,174)
B(2,48,8,174)
B(2,49,-1,174)
B(2,49,0,174)
B(2,49,1,174)
B(2,49,2,174)
B(2,49,3,174)
B(2,49,4,174)
B(2,49,5,174)
B(2,49,6,174)
B(2,49,7,174)
B(2,49,8,174)
B(2,50,0,174)
B(2,50,1,174)
B(2,50,2,174)
B(2,50,3,174)
B(2,50,4,174)
B(2,50,5,174)
B(2,50,6,174)
B(2,50,7,174)
B(2,50,8,174)
B(2,51,0,174)
B(2,51,1,174)
B(2,51,2,174)
B(2,51,3,174)
B(2,51,4,174)
B(2,51,5,174)
B(2,51,6,174)
B(2,51,7,174)
B(2,51,8,174)
B(2,52,0,174)
B(2,52,1,174)
B(2,52,2,174)
B(2,52,3,174)
B(2,52,4,174)
B(2,52,5,174)
B(2,52,6,174)
B(2,52,7,174)
B(2,52,8,174)
B(2,53,2,174)
B(2,53,3,174)
B(2,53,4,174)
B(2,53,5,174)
B(2,53,6,174)
B(2,53,7,174)
B(2,53,8,174)
B(2,54,3,174)
B(2,54,4,174)
B(2,54,5,174)
B(2,54,6,174)
B(2,54,7,174)
B(2,55,3,174)
B(2,55,5,174)
B(2,55,6,174)
B(3,25,3,174)
B(3,25,6,174)
B(3,26,3,174)
B(3,26,4,174)
B(3,26,5,174)
B(3,26,6,174)
B(3,26,7,174)
B(3,27,3,174)
B(3,27,4,174)
B(3,27,5,174)
B(3,27,6,174)
B(3,27,7,174)
B(3,27,8,174)
B(3,28,1,174)
B(3,28,2,174)
B(3,28,3,174)
B(3,28,4,174)
B(3,28,5,174)
B(3,28,6,174)
B(3,28,7,174)
B(3,28,8,174)
B(3,29,0,174)
B(3,29,1,174)
B(3,29,2,174)
B(3,29,3,174)
B(3,29,4,174)
B(3,29,5,174)
B(3,29,6,174)
B(3,29,7,174)
B(3,29,8,174)
B(3,30,0,174)
B(3,30,1,174)
B(3,30,2,174)
B(3,30,3,174)
B(3,30,4,174)
B(3,30,5,174)
B(3,30,6,174)
B(3,30,7,174)
B(3,30,8,174)
B(3,31,-1,174)
B(3,31,0,174)
B(3,31,1,174)
B(3,31,2,174)
B(3,31,3,174)
B(3,31,4,174)
B(3,31,5,174)
B(3,31,6,174)
B(3,31,7,174)
B(3,31,8,174)
B(3,32,-1,174)
B(3,32,0,174)
B(3,32,1,174)
B(3,32,2,174)
B(3,32,3,174)
B(3,32,4,174)
B(3,32,5,174)
B(3,32,6,174)
B(3,32,7,174)
B(3,32,8,174)
B(3,33,-2,174)
B(3,33,-1,174)
B(3,33,0,174)
B(3,33,1,174)
B(3,33,2,174)
B(3,33,3,174)
B(3,33,4,174)
B(3,33,5,174)
B(3,33,6,174)
B(3,33,7,174)
B(3,33,8,174)
B(3,34,-2,174)
B(3,34,-1,174)
B(3,34,0,174)
B(3,34,1,174)
B(3,34,2,174)
B(3,34,3,174)
B(3,34,4,174)
B(3,34,5,174)
B(3,34,6,174)
B(3,34,7,174)
B(3,34,8,174)
B(3,35,-2,174)
B(3,35,-1,174)
B(3,35,0,174)
B(3,35,1,174)
B(3,35,2,174)
B(3,35,3,174)
B(3,35,4,174)
B(3,35,5,174)
B(3,35,6,174)
B(3,35,7,174)
B(3,35,8,174)
B(3,36,-2,174)
B(3,36,-1,174)
B(3,36,0,174)
B(3,36,1,174)
B(3,36,2,174)
B(3,36,3,174)
B(3,36,4,174)
B(3,36,5,174)
B(3,36,6,174)
B(3,36,7,174)
B(3,36,8,174)
B(3,37,-3,174)
B(3,37,-2,174)
B(3,37,-1,174)
B(3,37,0,174)
B(3,37,1,174)
B(3,37,2,174)
B(3,37,3,174)
B(3,37,4,174)
B(3,37,5,174)
B(3,37,6,174)
B(3,37,7,174)
B(3,37,8,174)
B(3,38,-3,174)
B(3,38,-2,174)
B(3,38,-1,174)
B(3,38,0,174)
B(3,38,1,174)
B(3,38,2,174)
B(3,38,3,174)
B(3,38,4,174)
B(3,38,5,174)
B(3,38,6,174)
B(3,38,7,174)
B(3,38,8,174)
B(3,39,-3,174)
B(3,39,-2,174)
B(3,39,-1,174)
B(3,39,0,174)
B(3,39,1,174)
B(3,39,2,174)
B(3,39,3,174)
B(3,39,4,174)
B(3,39,5,174)
B(3,39,6,174)
B(3,39,7,174)
B(3,39,8,174)
B(3,40,-3,174)
B(3,40,-2,174)
B(3,40,-1,174)
B(3,40,0,174)
B(3,40,1,174)
B(3,40,2,174)
B(3,40,3,174)
B(3,40,4,174)
B(3,40,5,174)
B(3,40,6,174)
B(3,40,7,174)
B(3,40,8,174)
B(3,41,-3,174)
B(3,41,-2,174)
B(3,41,-1,174)
B(3,41,0,174)
B(3,41,1,174)
B(3,41,2,174)
B(3,41,3,174)
B(3,41,4,174)
B(3,41,5,174)
B(3,41,6,174)
B(3,41,7,174)
B(3,41,8,174)
B(3,42,-3,174)
B(3,42,-2,174)
B(3,42,-1,174)
B(3,42,0,174)
B(3,42,1,174)
B(3,42,2,174)
B(3,42,3,174)
B(3,42,4,174)
B(3,42,5,174)
B(3,42,6,174)
B(3,42,7,174)
B(3,42,8,174)
B(3,43,-3,174)
B(3,43,-2,174)
B(3,43,-1,174)
B(3,43,0,174)
B(3,43,1,174)
B(3,43,2,174)
B(3,43,3,174)
B(3,43,4,174)
B(3,43,5,174)
B(3,43,6,174)
B(3,43,7,174)
B(3,43,8,174)
B(3,44,-3,174)
B(3,44,-2,174)
B(3,44,-1,174)
B(3,44,0,174)
B(3,44,1,174)
B(3,44,2,174)
B(3,44,3,174)
B(3,44,4,174)
B(3,44,5,174)
B(3,44,6,174)
B(3,44,7,174)
B(3,44,8,174)
B(3,45,-3,174)
B(3,45,-2,174)
B(3,45,-1,174)
B(3,45,0,174)
B(3,45,1,174)
B(3,45,2,174)
B(3,45,3,174)
B(3,45,4,174)
B(3,45,5,174)
B(3,45,6,174)
B(3,45,7,174)
B(3,45,8,174)
B(3,46,-2,174)
B(3,46,-1,174)
B(3,46,0,174)
B(3,46,1,174)
B(3,46,2,174)
B(3,46,3,174)
B(3,46,4,174)
B(3,46,5,174)
B(3,46,6,174)
B(3,46,7,174)
B(3,46,8,174)
B(3,47,-2,174)
B(3,47,-1,174)
B(3,47,0,174)
B(3,47,1,174)
B(3,47,2,174)
B(3,47,3,174)
B(3,47,4,174)
B(3,47,5,174)
B(3,47,6,174)
B(3,47,7,174)
B(3,47,8,174)
B(3,48,-2,174)
B(3,48,-1,174)
B(3,48,0,174)
B(3,48,1,174)
B(3,48,2,174)
B(3,48,3,174)
B(3,48,4,174)
B(3,48,5,174)
B(3,48,6,174)
B(3,48,7,174)
B(3,48,8,174)
B(3,49,-1,174)
B(3,49,0,174)
B(3,49,1,174)
B(3,49,2,174)
B(3,49,3,174)
B(3,49,4,174)
B(3,49,5,174)
B(3,49,6,174)
B(3,49,7,174)
B(3,49,8,174)
B(3,50,-1,174)
B(3,50,0,174)
B(3,50,1,174)
B(3,50,2,174)
B(3,50,3,174)
B(3,50,4,174)
B(3,50,5,174)
B(3,50,6,174)
B(3,50,7,174)
B(3,50,8,174)
B(3,51,0,174)
B(3,51,1,174)
B(3,51,2,174)
B(3,51,3,174)
B(3,51,4,174)
B(3,51,5,174)
B(3,51,6,174)
B(3,51,7,174)
B(3,51,8,174)
B(3,52,0,174)
B(3,52,1,174)
B(3,52,2,174)
B(3,52,3,174)
B(3,52,4,174)
B(3,52,5,174)
B(3,52,6,174)
B(3,52,7,174)
B(3,52,8,174)
B(3,53,1,174)
B(3,53,2,174)
B(3,53,3,174)
B(3,53,4,174)
B(3,53,5,174)
B(3,53,6,174)
B(3,53,7,174)
B(3,53,8,174)
B(3,54,3,174)
B(3,54,4,174)
B(3,54,5,174)
B(3,54,6,174)
B(3,54,7,174)
B(3,55,3,174)
B(3,55,5,174)
B(3,55,6,174)
B(4,25,3,174)
B(4,25,4,174)
B(4,25,5,174)
B(4,25,6,174)
B(4,25,7,174)
B(4,26,2,174)
B(4,26,3,174)
B(4,26,4,174)
B(4,26,5,174)
B(4,26,6,174)
B(4,26,7,174)
B(4,26,8,174)
B(4,27,1,174)
B(4,27,2,174)
B(4,27,3,174)
B(4,27,4,174)
B(4,27,5,174)
B(4,27,6,174)
B(4,27,7,174)
B(4,27,8,174)
B(4,28,-1,174)
B(4,28,0,174)
B(4,28,1,174)
B(4,28,2,174)
B(4,28,3,174)
B(4,28,4,174)
B(4,28,5,174)
B(4,28,6,174)
B(4,28,7,174)
B(4,28,8,174)
B(4,29,-1,174)
B(4,29,0,174)
B(4,29,1,174)
B(4,29,2,174)
B(4,29,3,174)
B(4,29,4,174)
B(4,29,5,174)
B(4,29,6,174)
B(4,29,7,174)
B(4,29,8,174)
B(4,30,-1,174)
B(4,30,0,174)
B(4,30,1,174)
B(4,30,2,174)
B(4,30,3,174)
B(4,30,4,174)
B(4,30,5,174)
B(4,30,6,174)
B(4,30,7,174)
B(4,30,8,174)
B(4,31,-2,174)
B(4,31,-1,174)
B(4,31,0,174)
B(4,31,1,174)
B(4,31,2,174)
B(4,31,3,174)
B(4,31,4,174)
B(4,31,5,174)
B(4,31,6,174)
B(4,31,7,174)
B(4,31,8,174)
B(4,32,-2,174)
B(4,32,-1,174)
B(4,32,0,174)
B(4,32,1,174)
B(4,32,2,174)
B(4,32,3,174)
B(4,32,4,174)
B(4,32,5,174)
B(4,32,6,174)
B(4,32,7,174)
B(4,32,8,174)
B(4,33,-2,174)
B(4,33,-1,174)
B(4,33,0,174)
B(4,33,1,174)
B(4,33,2,174)
B(4,33,3,174)
B(4,33,4,174)
B(4,33,5,174)
B(4,33,6,174)
B(4,33,7,174)
B(4,33,8,174)
B(4,34,-2,174)
B(4,34,-1,174)
B(4,34,0,174)
B(4,34,1,174)
B(4,34,2,174)
B(4,34,3,174)
B(4,34,4,174)
B(4,34,5,174)
B(4,34,6,174)
B(4,34,7,174)
B(4,34,8,174)
B(4,35,-2,174)
B(4,35,-1,174)
B(4,35,0,174)
B(4,35,1,174)
B(4,35,2,174)
B(4,35,3,174)
B(4,35,4,174)
B(4,35,5,174)
B(4,35,6,174)
B(4,35,7,174)
B(4,35,8,174)
B(4,36,-3,174)
B(4,36,-2,174)
B(4,36,-1,174)
B(4,36,0,174)
B(4,36,1,174)
B(4,36,2,174)
B(4,36,3,174)
B(4,36,4,174)
B(4,36,5,174)
B(4,36,6,174)
B(4,36,7,174)
B(4,36,8,174)
B(4,37,-3,174)
B(4,37,-2,174)
B(4,37,-1,174)
B(4,37,0,174)
B(4,37,1,174)
B(4,37,2,174)
B(4,37,3,174)
B(4,37,4,174)
B(4,37,5,174)
B(4,37,6,174)
B(4,37,7,174)
B(4,37,8,174)
B(4,38,-3,174)
B(4,38,-2,174)
B(4,38,-1,174)
B(4,38,0,174)
B(4,38,1,174)
B(4,38,2,174)
B(4,38,3,174)
B(4,38,4,174)
B(4,38,5,174)
B(4,38,6,174)
B(4,38,7,174)
B(4,38,8,174)
B(4,39,-3,174)
B(4,39,-2,174)
B(4,39,-1,174)
B(4,39,0,174)
B(4,39,1,174)
B(4,39,2,174)
B(4,39,3,174)
B(4,39,4,174)
B(4,39,5,174)
B(4,39,6,174)
B(4,39,7,174)
B(4,39,8,174)
B(4,40,-3,174)
B(4,40,-2,174)
B(4,40,-1,174)
B(4,40,0,174)
B(4,40,1,174)
B(4,40,2,174)
B(4,40,3,174)
B(4,40,4,174)
B(4,40,5,174)
B(4,40,6,174)
B(4,40,7,174)
B(4,40,8,174)
B(4,41,-3,174)
B(4,41,-2,174)
B(4,41,-1,174)
B(4,41,0,174)
B(4,41,1,174)
B(4,41,2,174)
B(4,41,3,174)
B(4,41,4,174)
B(4,41,5,174)
B(4,41,6,174)
B(4,41,7,174)
B(4,41,8,174)
B(4,42,-3,174)
B(4,42,-2,174)
B(4,42,-1,174)
B(4,42,0,174)
B(4,42,1,174)
B(4,42,2,174)
B(4,42,3,174)
B(4,42,4,174)
B(4,42,5,174)
B(4,42,6,174)
B(4,42,7,174)
B(4,42,8,174)
B(4,43,-3,174)
B(4,43,-2,174)
B(4,43,-1,174)
B(4,43,0,174)
B(4,43,1,174)
B(4,43,2,174)
B(4,43,3,174)
B(4,43,4,174)
B(4,43,5,174)
B(4,43,6,174)
B(4,43,7,174)
B(4,43,8,174)
B(4,44,-3,174)
B(4,44,-2,174)
B(4,44,-1,174)
B(4,44,0,174)
B(4,44,1,174)
B(4,44,2,174)
B(4,44,3,174)
B(4,44,4,174)
B(4,44,5,174)
B(4,44,6,174)
B(4,44,7,174)
B(4,44,8,174)
B(4,45,-3,174)
B(4,45,-2,174)
B(4,45,-1,174)
B(4,45,0,174)
B(4,45,1,174)
B(4,45,2,174)
B(4,45,3,174)
B(4,45,4,174)
B(4,45,5,174)
B(4,45,6,174)
B(4,45,7,174)
B(4,45,8,174)
B(4,46,-3,174)
B(4,46,-2,174)
B(4,46,-1,174)
B(4,46,0,174)
B(4,46,1,174)
B(4,46,2,174)
B(4,46,3,174)
B(4,46,4,174)
B(4,46,5,174)
B(4,46,6,174)
B(4,46,7,174)
B(4,46,8,174)
B(4,47,-2,174)
B(4,47,-1,174)
B(4,47,0,174)
B(4,47,1,174)
B(4,47,2,174)
B(4,47,3,174)
B(4,47,4,174)
B(4,47,5,174)
B(4,47,6,174)
B(4,47,7,174)
B(4,47,8,174)
B(4,48,-2,174)
B(4,48,-1,174)
B(4,48,0,174)
B(4,48,1,174)
B(4,48,2,174)
B(4,48,3,174)
B(4,48,4,174)
B(4,48,5,174)
B(4,48,6,174)
B(4,48,7,174)
B(4,48,8,174)
B(4,49,-2,174)
B(4,49,-1,174)
B(4,49,0,174)
B(4,49,1,174)
B(4,49,2,174)
B(4,49,3,174)
B(4,49,4,174)
B(4,49,5,174)
B(4,49,6,174)
B(4,49,7,174)
B(4,49,8,174)
B(4,50,-1,174)
B(4,50,0,174)
B(4,50,1,174)
B(4,50,2,174)
B(4,50,3,174)
B(4,50,4,174)
B(4,50,5,174)
B(4,50,6,174)
B(4,50,7,174)
B(4,50,8,174)
B(4,51,-1,174)
B(4,51,0,174)
B(4,51,1,174)
B(4,51,2,174)
B(4,51,3,174)
B(4,51,4,174)
B(4,51,5,174)
B(4,51,6,174)
B(4,51,7,174)
B(4,51,8,174)
B(4,52,-1,174)
B(4,52,0,174)
B(4,52,1,174)
B(4,52,2,174)
B(4,52,3,174)
B(4,52,4,174)
B(4,52,5,174)
B(4,52,6,174)
B(4,52,7,174)
B(4,52,8,174)
B(4,53,-1,174)
B(4,53,0,174)
B(4,53,1,174)
B(4,53,2,174)
B(4,53,3,174)
B(4,53,4,174)
B(4,53,5,174)
B(4,53,6,174)
B(4,53,7,174)
B(4,53,8,174)
B(4,54,1,174)
B(4,54,2,174)
B(4,54,3,174)
B(4,54,4,174)
B(4,54,5,174)
B(4,54,6,174)
B(4,54,7,174)
B(4,54,8,174)
B(4,55,2,174)
B(4,55,3,174)
B(4,55,4,174)
B(4,55,5,174)
B(4,55,6,174)
B(4,55,7,174)
B(4,56,6,174)
B(4,59,-4,174)
B(4,60,-4,174)
B(4,61,-6,174)
B(4,61,-5,174)
B(4,61,-4,174)
B(4,61,-3,174)
B(4,62,-7,174)
B(4,62,-6,174)
B(4,62,-5,174)
B(4,63,-7,174)
B(4,64,-7,174)
B(4,65,-7,174)
B(5,18,-7,174)
B(5,23,2,174)
B(5,24,2,174)
B(5,24,3,174)
B(5,24,4,174)
B(5,25,1,174)
B(5,25,2,174)
B(5,25,3,174)
B(5,25,4,174)
B(5,25,5,174)
B(5,25,6,174)
B(5,25,7,174)
B(5,26,1,174)
B(5,26,2,174)
B(5,26,3,174)
B(5,26,4,174)
B(5,26,5,174)
B(5,26,6,174)
B(5,26,7,174)
B(5,26,8,174)
B(5,27,0,174)
B(5,27,1,174)
B(5,27,2,174)
B(5,27,3,174)
B(5,27,4,174)
B(5,27,5,174)
B(5,27,6,174)
B(5,27,7,174)
B(5,27,8,174)
B(5,28,-1,174)
B(5,28,0,174)
B(5,28,1,174)
B(5,28,2,174)
B(5,28,3,174)
B(5,28,4,174)
B(5,28,5,174)
B(5,28,6,174)
B(5,28,7,174)
B(5,28,8,174)
B(5,29,-1,174)
B(5,29,0,174)
B(5,29,1,174)
B(5,29,2,174)
B(5,29,3,174)
B(5,29,4,174)
B(5,29,5,174)
B(5,29,6,174)
B(5,29,7,174)
B(5,29,8,174)
B(5,30,-2,174)
B(5,30,-1,174)
B(5,30,0,174)
B(5,30,1,174)
B(5,30,2,174)
B(5,30,3,174)
B(5,30,4,174)
B(5,30,5,174)
B(5,30,6,174)
B(5,30,7,174)
B(5,30,8,174)
B(5,31,-2,174)
B(5,31,-1,174)
B(5,31,0,174)
B(5,31,1,174)
B(5,31,2,174)
B(5,31,3,174)
B(5,31,4,174)
B(5,31,5,174)
B(5,31,6,174)
B(5,31,7,174)
B(5,31,8,174)
B(5,32,-2,174)
B(5,32,-1,174)
B(5,32,0,174)
B(5,32,1,174)
B(5,32,2,174)
B(5,32,3,174)
B(5,32,4,174)
B(5,32,5,174)
B(5,32,6,174)
B(5,32,7,174)
B(5,32,8,174)
B(5,33,-2,174)
B(5,33,-1,174)
B(5,33,0,174)
B(5,33,1,174)
B(5,33,2,174)
B(5,33,3,174)
B(5,33,4,174)
B(5,33,5,174)
B(5,33,6,174)
B(5,33,7,174)
B(5,33,8,174)
B(5,34,-2,174)
B(5,34,-1,174)
B(5,34,0,174)
B(5,34,1,174)
B(5,34,2,174)
B(5,34,3,174)
B(5,34,4,174)
B(5,34,5,174)
B(5,34,6,174)
B(5,34,7,174)
B(5,34,8,174)
B(5,35,-3,174)
B(5,35,-2,174)
B(5,35,-1,174)
B(5,35,0,174)
B(5,35,1,174)
B(5,35,2,174)
B(5,35,3,174)
B(5,35,4,174)
B(5,35,5,174)
B(5,35,6,174)
B(5,35,7,174)
B(5,35,8,174)
B(5,36,-3,174)
B(5,36,-2,174)
B(5,36,-1,174)
B(5,36,0,174)
B(5,36,1,174)
B(5,36,2,174)
B(5,36,3,174)
B(5,36,4,174)
B(5,36,5,174)
B(5,36,6,174)
B(5,36,7,174)
B(5,36,8,174)
B(5,37,-3,174)
B(5,37,-2,174)
B(5,37,-1,174)
B(5,37,0,174)
B(5,37,1,174)
B(5,37,2,174)
B(5,37,3,174)
B(5,37,4,174)
B(5,37,5,174)
B(5,37,6,174)
B(5,37,7,174)
B(5,37,8,174)
B(5,38,-3,174)
B(5,38,-2,174)
B(5,38,-1,174)
B(5,38,0,174)
B(5,38,1,174)
B(5,38,2,174)
B(5,38,3,174)
B(5,38,4,174)
B(5,38,5,174)
B(5,38,6,174)
B(5,38,7,174)
B(5,38,8,174)
B(5,39,-3,174)
B(5,39,-2,174)
B(5,39,-1,174)
B(5,39,0,174)
B(5,39,1,174)
B(5,39,2,174)
B(5,39,3,174)
B(5,39,4,174)
B(5,39,5,174)
B(5,39,6,174)
B(5,39,7,174)
B(5,39,8,174)
B(5,40,-3,174)
B(5,40,-2,174)
B(5,40,-1,174)
B(5,40,0,174)
B(5,40,1,174)
B(5,40,2,174)
B(5,40,3,174)
B(5,40,4,174)
B(5,40,5,174)
B(5,40,6,174)
B(5,40,7,174)
B(5,40,8,174)
B(5,41,-3,174)
B(5,41,-2,174)
B(5,41,-1,174)
B(5,41,0,174)
B(5,41,1,174)
B(5,41,2,174)
B(5,41,3,174)
B(5,41,4,174)
B(5,41,5,174)
B(5,41,6,174)
B(5,41,7,174)
B(5,41,8,174)
B(5,42,-3,174)
B(5,42,-2,174)
B(5,42,-1,174)
B(5,42,0,174)
B(5,42,1,174)
B(5,42,2,174)
B(5,42,3,174)
B(5,42,4,174)
B(5,42,5,174)
B(5,42,6,174)
B(5,42,7,174)
B(5,42,8,174)
B(5,43,-3,174)
B(5,43,-2,174)
B(5,43,-1,174)
B(5,43,0,174)
B(5,43,1,174)
B(5,43,2,174)
B(5,43,3,174)
B(5,43,4,174)
B(5,43,5,174)
B(5,43,6,174)
B(5,43,7,174)
B(5,43,8,174)
B(5,44,-3,174)
B(5,44,-2,174)
B(5,44,-1,174)
B(5,44,0,174)
B(5,44,1,174)
B(5,44,2,174)
B(5,44,3,174)
B(5,44,4,174)
B(5,44,5,174)
B(5,44,6,174)
B(5,44,7,174)
B(5,44,8,174)
B(5,45,-3,174)
B(5,45,-2,174)
B(5,45,-1,174)
B(5,45,0,174)
B(5,45,1,174)
B(5,45,2,174)
B(5,45,3,174)
B(5,45,4,174)
B(5,45,5,174)
B(5,45,6,174)
B(5,45,7,174)
B(5,45,8,174)
B(5,46,-3,174)
B(5,46,-2,174)
B(5,46,-1,174)
B(5,46,0,174)
B(5,46,1,174)
B(5,46,2,174)
B(5,46,3,174)
B(5,46,4,174)
B(5,46,5,174)
B(5,46,6,174)
B(5,46,7,174)
B(5,46,8,174)
B(5,47,-3,174)
B(5,47,-2,174)
B(5,47,-1,174)
B(5,47,0,174)
B(5,47,1,174)
B(5,47,2,174)
B(5,47,3,174)
B(5,47,4,174)
B(5,47,5,174)
B(5,47,6,174)
B(5,47,7,174)
B(5,47,8,174)
B(5,48,-2,174)
B(5,48,-1,174)
B(5,48,0,174)
B(5,48,1,174)
B(5,48,2,174)
B(5,48,3,174)
B(5,48,4,174)
B(5,48,5,174)
B(5,48,6,174)
B(5,48,7,174)
B(5,48,8,174)
B(5,49,-2,174)
B(5,49,-1,174)
B(5,49,0,174)
B(5,49,1,174)
B(5,49,2,174)
B(5,49,3,174)
B(5,49,4,174)
B(5,49,5,174)
B(5,49,6,174)
B(5,49,7,174)
B(5,49,8,174)
B(5,50,-2,174)
B(5,50,-1,174)
B(5,50,0,174)
B(5,50,1,174)
B(5,50,2,174)
B(5,50,3,174)
B(5,50,4,174)
B(5,50,5,174)
B(5,50,6,174)
B(5,50,7,174)
B(5,50,8,174)
B(5,51,-2,174)
B(5,51,-1,174)
B(5,51,0,174)
B(5,51,1,174)
B(5,51,2,174)
B(5,51,3,174)
B(5,51,4,174)
B(5,51,5,174)
B(5,51,6,174)
B(5,51,7,174)
B(5,51,8,174)
B(5,52,-4,174)
B(5,52,-1,174)
B(5,52,0,174)
B(5,52,1,174)
B(5,52,2,174)
B(5,52,3,174)
B(5,52,4,174)
B(5,52,5,174)
B(5,52,6,174)
B(5,52,7,174)
B(5,52,8,174)
B(5,53,-4,174)
B(5,53,-1,174)
B(5,53,0,174)
B(5,53,1,174)
B(5,53,2,174)
B(5,53,3,174)
B(5,53,4,174)
B(5,53,5,174)
B(5,53,6,174)
B(5,53,7,174)
B(5,53,8,174)
B(5,54,-4,174)
B(5,54,0,174)
B(5,54,1,174)
B(5,54,2,174)
B(5,54,3,174)
B(5,54,4,174)
B(5,54,5,174)
B(5,54,6,174)
B(5,54,7,174)
B(5,54,8,174)
B(5,55,-4,174)
B(5,55,1,174)
B(5,55,2,174)
B(5,55,3,174)
B(5,55,4,174)
B(5,55,5,174)
B(5,55,6,174)
B(5,55,7,174)
B(5,56,-4,174)
B(5,56,1,174)
B(5,56,2,174)
B(5,56,3,174)
B(5,56,4,174)
B(5,56,5,174)
B(5,56,6,174)
B(5,57,-4,174)
B(5,58,-4,174)
B(5,59,-4,174)
B(5,60,-5,174)
B(5,60,-4,174)
B(5,60,-3,174)
B(5,61,-7,174)
B(5,61,-6,174)
B(5,61,-5,174)
B(5,61,-4,174)
B(5,61,-3,174)
B(5,61,-2,174)
B(5,62,-7,174)
B(5,62,-6,174)
B(5,62,-5,174)
B(5,62,-4,174)
B(5,62,-3,174)
B(5,63,-7,174)
B(5,63,-6,174)
B(5,63,-5,174)
B(5,64,-7,174)
B(5,64,-6,174)
B(5,65,-7,174)
B(6,16,-7,174)
B(6,16,-4,174)
B(6,17,-7,174)
B(6,17,-4,174)
B(6,17,-3,174)
B(6,18,-7,174)
B(6,18,-6,174)
B(6,18,-5,174)
B(6,19,-7,174)
B(6,19,-6,174)
B(6,19,-5,174)
B(6,19,-4,174)
B(6,19,-2,174)
B(6,20,-5,174)
B(6,20,-4,174)
B(6,20,-3,174)
B(6,20,-2,174)
B(6,20,-1,174)
B(6,20,0,174)
B(6,21,0,174)
B(6,21,1,174)
B(6,22,2,174)
B(6,22,3,174)
B(6,23,1,174)
B(6,23,2,174)
B(6,23,3,174)
B(6,23,4,174)
B(6,24,1,174)
B(6,24,2,174)
B(6,24,3,174)
B(6,24,4,174)
B(6,24,5,174)
B(6,25,1,174)
B(6,25,2,174)
B(6,25,3,174)
B(6,25,4,174)
B(6,25,5,174)
B(6,25,6,174)
B(6,26,0,174)
B(6,26,1,174)
B(6,26,2,174)
B(6,26,3,174)
B(6,26,4,174)
B(6,26,5,174)
B(6,26,6,174)
B(6,26,7,174)
B(6,26,8,174)
B(6,27,-1,174)
B(6,27,0,174)
B(6,27,1,174)
B(6,27,2,174)
B(6,27,3,174)
B(6,27,4,174)
B(6,27,5,174)
B(6,27,6,174)
B(6,27,7,174)
B(6,27,8,174)
B(6,28,-1,174)
B(6,28,0,174)
B(6,28,1,174)
B(6,28,2,174)
B(6,28,3,174)
B(6,28,4,174)
B(6,28,5,174)
B(6,28,6,174)
B(6,28,7,174)
B(6,28,8,174)
B(6,29,-1,174)
B(6,29,0,174)
B(6,29,1,174)
B(6,29,2,174)
B(6,29,3,174)
B(6,29,4,174)
B(6,29,5,174)
B(6,29,6,174)
B(6,29,7,174)
B(6,29,8,174)
B(6,30,-2,174)
B(6,30,-1,174)
B(6,30,0,174)
B(6,30,1,174)
B(6,30,2,174)
B(6,30,3,174)
B(6,30,4,174)
B(6,30,5,174)
B(6,30,6,174)
B(6,30,7,174)
B(6,30,8,174)
B(6,31,-2,174)
B(6,31,-1,174)
B(6,31,0,174)
B(6,31,1,174)
B(6,31,2,174)
B(6,31,3,174)
B(6,31,4,174)
B(6,31,5,174)
B(6,31,6,174)
B(6,31,7,174)
B(6,31,8,174)
B(6,32,-2,174)
B(6,32,-1,174)
B(6,32,0,174)
B(6,32,1,174)
B(6,32,2,174)
B(6,32,3,174)
B(6,32,4,174)
B(6,32,5,174)
B(6,32,6,174)
B(6,32,7,174)
B(6,32,8,174)
B(6,33,-2,174)
B(6,33,-1,174)
B(6,33,0,174)
B(6,33,1,174)
B(6,33,2,174)
B(6,33,3,174)
B(6,33,4,174)
B(6,33,5,174)
B(6,33,6,174)
B(6,33,7,174)
B(6,33,8,174)
B(6,34,-2,174)
B(6,34,-1,174)
B(6,34,0,174)
B(6,34,1,174)
B(6,34,2,174)
B(6,34,3,174)
B(6,34,4,174)
B(6,34,5,174)
B(6,34,6,174)
B(6,34,7,174)
B(6,34,8,174)
B(6,35,-3,174)
B(6,35,-2,174)
B(6,35,-1,174)
B(6,35,0,174)
B(6,35,1,174)
B(6,35,2,174)
B(6,35,3,174)
B(6,35,4,174)
B(6,35,5,174)
B(6,35,6,174)
B(6,35,7,174)
B(6,35,8,174)
B(6,36,-3,174)
B(6,36,-2,174)
B(6,36,-1,174)
B(6,36,0,174)
B(6,36,1,174)
B(6,36,2,174)
B(6,36,3,174)
B(6,36,4,174)
B(6,36,5,174)
B(6,36,6,174)
B(6,36,7,174)
B(6,36,8,174)
B(6,37,-3,174)
B(6,37,-2,174)
B(6,37,-1,174)
B(6,37,0,174)
B(6,37,1,174)
B(6,37,2,174)
B(6,37,3,174)
B(6,37,4,174)
B(6,37,5,174)
B(6,37,6,174)
B(6,37,7,174)
B(6,37,8,174)
B(6,38,-3,174)
B(6,38,-2,174)
B(6,38,-1,174)
B(6,38,0,174)
B(6,38,1,174)
B(6,38,2,174)
B(6,38,3,174)
B(6,38,4,174)
B(6,38,5,174)
B(6,38,6,174)
B(6,38,7,174)
B(6,38,8,174)
B(6,39,-3,174)
B(6,39,-2,174)
B(6,39,-1,174)
B(6,39,0,174)
B(6,39,1,174)
B(6,39,2,174)
B(6,39,3,174)
B(6,39,4,174)
B(6,39,5,174)
B(6,39,6,174)
B(6,39,7,174)
B(6,39,8,174)
B(6,40,-3,174)
B(6,40,-2,174)
B(6,40,-1,174)
B(6,40,0,174)
B(6,40,1,174)
B(6,40,2,174)
B(6,40,3,174)
B(6,40,4,174)
B(6,40,5,174)
B(6,40,6,174)
B(6,40,7,174)
B(6,40,8,174)
B(6,41,-3,174)
B(6,41,-2,174)
B(6,41,-1,174)
B(6,41,0,174)
B(6,41,1,174)
B(6,41,2,174)
B(6,41,3,174)
B(6,41,4,174)
B(6,41,5,174)
B(6,41,6,174)
B(6,41,7,174)
B(6,41,8,174)
B(6,42,-3,174)
B(6,42,-2,174)
B(6,42,-1,174)
B(6,42,0,174)
B(6,42,1,174)
B(6,42,2,174)
B(6,42,3,174)
B(6,42,4,174)
B(6,42,5,174)
B(6,42,6,174)
B(6,42,7,174)
B(6,42,8,174)
B(6,43,-3,174)
B(6,43,-2,174)
B(6,43,-1,174)
B(6,43,0,174)
B(6,43,1,174)
B(6,43,2,174)
B(6,43,3,174)
B(6,43,4,174)
B(6,43,5,174)
B(6,43,6,174)
B(6,43,7,174)
B(6,43,8,174)
B(6,44,-3,174)
B(6,44,-2,174)
B(6,44,-1,174)
B(6,44,0,174)
B(6,44,1,174)
B(6,44,2,174)
B(6,44,3,174)
B(6,44,4,174)
B(6,44,5,174)
B(6,44,6,174)
B(6,44,7,174)
B(6,44,8,174)
B(6,45,-3,174)
B(6,45,-2,174)
B(6,45,-1,174)
B(6,45,0,174)
B(6,45,1,174)
B(6,45,2,174)
B(6,45,3,174)
B(6,45,4,174)
B(6,45,5,174)
B(6,45,6,174)
B(6,45,7,174)
B(6,45,8,174)
B(6,46,-3,174)
B(6,46,-2,174)
B(6,46,-1,174)
B(6,46,0,174)
B(6,46,1,174)
B(6,46,2,174)
B(6,46,3,174)
B(6,46,4,174)
B(6,46,5,174)
B(6,46,6,174)
B(6,46,7,174)
B(6,46,8,174)
B(6,47,-3,174)
B(6,47,-2,174)
B(6,47,-1,174)
B(6,47,0,174)
B(6,47,1,174)
B(6,47,2,174)
B(6,47,3,174)
B(6,47,4,174)
B(6,47,5,174)
B(6,47,6,174)
B(6,47,7,174)
B(6,47,8,174)
B(6,48,-2,174)
B(6,48,-1,174)
B(6,48,0,174)
B(6,48,1,174)
B(6,48,2,174)
B(6,48,3,174)
B(6,48,4,174)
B(6,48,5,174)
B(6,48,6,174)
B(6,48,7,174)
B(6,48,8,174)
B(6,49,-2,174)
B(6,49,-1,174)
B(6,49,0,174)
B(6,49,1,174)
B(6,49,2,174)
B(6,49,3,174)
B(6,49,4,174)
B(6,49,5,174)
B(6,49,6,174)
B(6,49,7,174)
B(6,49,8,174)
B(6,50,-2,174)
B(6,50,-1,174)
B(6,50,0,174)
B(6,50,1,174)
B(6,50,2,174)
B(6,50,3,174)
B(6,50,4,174)
B(6,50,5,174)
B(6,50,6,174)
B(6,50,7,174)
B(6,50,8,174)
B(6,51,-2,174)
B(6,51,-1,174)
B(6,51,0,174)
B(6,51,1,174)
B(6,51,2,174)
B(6,51,3,174)
B(6,51,4,174)
B(6,51,5,174)
B(6,51,6,174)
B(6,51,7,174)
B(6,51,8,174)
B(6,52,-1,174)
B(6,52,0,174)
B(6,52,1,174)
B(6,52,2,174)
B(6,52,3,174)
B(6,52,4,174)
B(6,52,5,174)
B(6,52,6,174)
B(6,52,7,174)
B(6,52,8,174)
B(6,53,-1,174)
B(6,53,0,174)
B(6,53,1,174)
B(6,53,2,174)
B(6,53,3,174)
B(6,53,4,174)
B(6,53,5,174)
B(6,53,6,174)
B(6,53,7,174)
B(6,53,8,174)
B(6,54,-1,174)
B(6,54,0,174)
B(6,54,1,174)
B(6,54,2,174)
B(6,54,3,174)
B(6,54,4,174)
B(6,54,5,174)
B(6,54,6,174)
B(6,54,7,174)
B(6,54,8,174)
B(6,55,0,174)
B(6,55,1,174)
B(6,55,2,174)
B(6,55,3,174)
B(6,55,4,174)
B(6,55,5,174)
B(6,55,6,174)
B(6,55,7,174)
B(6,56,1,174)
B(6,56,2,174)
B(6,56,3,174)
B(6,56,4,174)
B(6,56,5,174)
B(6,57,1,174)
B(6,57,2,174)
B(6,57,3,174)
B(6,57,4,174)
B(6,58,1,174)
B(6,58,2,174)
B(6,58,3,174)
B(6,59,-4,174)
B(6,59,-3,174)
B(6,59,2,174)
B(6,60,-7,174)
B(6,60,-6,174)
B(6,60,-5,174)
B(6,60,-4,174)
B(6,60,-3,174)
B(6,60,-2,174)
B(6,60,0,174)
B(6,60,1,174)
B(6,61,-7,174)
B(6,61,-6,174)
B(6,61,-5,174)
B(6,61,-4,174)
B(6,61,-3,174)
B(6,61,-2,174)
B(6,61,-1,174)
B(6,61,0,174)
B(6,62,-7,174)
B(6,62,-6,174)
B(6,62,-5,174)
B(6,62,-4,174)
B(6,62,-3,174)
B(6,63,-7,174)
B(6,63,-6,174)
B(6,63,-5,174)
B(6,63,-4,174)
B(6,63,-3,174)
B(6,64,-7,174)
B(6,64,-6,174)
B(6,64,-5,174)
B(6,64,-4,174)
B(6,64,-3,174)
B(6,65,-7,174)
B(6,65,-6,174)
B(6,65,-5,174)
B(6,65,-4,174)
B(7,15,-7,174)
B(7,15,-6,174)
B(7,15,-5,174)
B(7,15,-4,174)
B(7,16,-7,174)
B(7,16,-6,174)
B(7,16,-5,174)
B(7,16,-4,174)
B(7,16,-3,174)
B(7,16,-2,174)
B(7,17,-7,174)
B(7,17,-6,174)
B(7,17,-5,174)
B(7,17,-4,174)
B(7,17,-3,174)
B(7,17,-2,174)
B(7,18,-7,174)
B(7,18,-6,174)
B(7,18,-5,174)
B(7,18,-4,174)
B(7,18,-3,174)
B(7,18,-2,174)
B(7,18,-1,174)
B(7,19,-7,174)
B(7,19,-6,174)
B(7,19,-5,174)
B(7,19,-4,174)
B(7,19,-3,174)
B(7,19,-2,174)
B(7,19,-1,174)
B(7,19,0,174)
B(7,20,-7,174)
B(7,20,-6,174)
B(7,20,-5,174)
B(7,20,-4,174)
B(7,20,-3,174)
B(7,20,-2,174)
B(7,20,-1,174)
B(7,20,0,174)
B(7,20,3,174)
B(7,21,-7,174)
B(7,21,-6,174)
B(7,21,-5,174)
B(7,21,-4,174)
B(7,21,-3,174)
B(7,21,-2,174)
B(7,21,-1,174)
B(7,21,0,174)
B(7,21,1,174)
B(7,21,2,174)
B(7,21,3,174)
B(7,21,4,174)
B(7,22,-2,174)
B(7,22,-1,174)
B(7,22,0,174)
B(7,22,1,174)
B(7,22,2,174)
B(7,22,3,174)
B(7,22,4,174)
B(7,23,-1,174)
B(7,23,0,174)
B(7,23,1,174)
B(7,23,2,174)
B(7,23,3,174)
B(7,23,4,174)
B(7,23,5,174)
B(7,24,-1,174)
B(7,24,0,174)
B(7,24,1,174)
B(7,24,2,174)
B(7,24,3,174)
B(7,24,4,174)
B(7,24,5,174)
B(7,24,6,174)
B(7,25,0,174)
B(7,25,1,174)
B(7,25,2,174)
B(7,25,3,174)
B(7,25,4,174)
B(7,25,5,174)
B(7,25,6,174)
B(7,26,-1,174)
B(7,26,0,174)
B(7,26,1,174)
B(7,26,2,174)
B(7,26,3,174)
B(7,26,4,174)
B(7,26,5,174)
B(7,26,6,174)
B(7,26,7,174)
B(7,27,-1,174)
B(7,27,0,174)
B(7,27,1,174)
B(7,27,2,174)
B(7,27,3,174)
B(7,27,4,174)
B(7,27,5,174)
B(7,27,6,174)
B(7,27,7,174)
B(7,27,8,174)
B(7,28,-1,174)
B(7,28,0,174)
B(7,28,1,174)
B(7,28,2,174)
B(7,28,3,174)
B(7,28,4,174)
B(7,28,5,174)
B(7,28,6,174)
B(7,28,7,174)
B(7,28,8,174)
B(7,29,-2,174)
B(7,29,-1,174)
B(7,29,0,174)
B(7,29,1,174)
B(7,29,2,174)
B(7,29,3,174)
B(7,29,4,174)
B(7,29,5,174)
B(7,29,6,174)
B(7,29,7,174)
B(7,29,8,174)
B(7,30,-2,174)
B(7,30,-1,174)
B(7,30,0,174)
B(7,30,1,174)
B(7,30,2,174)
B(7,30,3,174)
B(7,30,4,174)
B(7,30,5,174)
B(7,30,6,174)
B(7,30,7,174)
B(7,30,8,174)
B(7,31,-2,174)
B(7,31,-1,174)
B(7,31,0,174)
B(7,31,1,174)
B(7,31,2,174)
B(7,31,3,174)
B(7,31,4,174)
B(7,31,5,174)
B(7,31,6,174)
B(7,31,7,174)
B(7,31,8,174)
B(7,32,-2,174)
B(7,32,-1,174)
B(7,32,0,174)
B(7,32,1,174)
B(7,32,2,174)
B(7,32,3,174)
B(7,32,4,174)
B(7,32,5,174)
B(7,32,6,174)
B(7,32,7,174)
B(7,32,8,174)
B(7,33,-2,174)
B(7,33,-1,174)
B(7,33,0,174)
B(7,33,1,174)
B(7,33,2,174)
B(7,33,3,174)
B(7,33,4,174)
B(7,33,5,174)
B(7,33,6,174)
B(7,33,7,174)
B(7,33,8,174)
B(7,34,-2,174)
B(7,34,-1,174)
B(7,34,0,174)
B(7,34,1,174)
B(7,34,2,174)
B(7,34,3,174)
B(7,34,4,174)
B(7,34,5,174)
B(7,34,6,174)
B(7,34,7,174)
B(7,34,8,174)
B(7,35,-3,174)
B(7,35,-2,174)
B(7,35,-1,174)
B(7,35,0,174)
B(7,35,1,174)
B(7,35,2,174)
B(7,35,3,174)
B(7,35,4,174)
B(7,35,5,174)
B(7,35,6,174)
B(7,35,7,174)
B(7,35,8,174)
B(7,36,-3,174)
B(7,36,-2,174)
B(7,36,-1,174)
B(7,36,0,174)
B(7,36,1,174)
B(7,36,2,174)
B(7,36,3,174)
B(7,36,4,174)
B(7,36,5,174)
B(7,36,6,174)
B(7,36,7,174)
B(7,36,8,174)
B(7,37,-3,174)
B(7,37,-2,174)
B(7,37,-1,174)
B(7,37,0,174)
B(7,37,1,174)
B(7,37,2,174)
B(7,37,3,174)
B(7,37,4,174)
B(7,37,5,174)
B(7,37,6,174)
B(7,37,7,174)
B(7,37,8,174)
B(7,38,-3,174)
B(7,38,-2,174)
B(7,38,-1,174)
B(7,38,0,174)
B(7,38,1,174)
B(7,38,2,174)
B(7,38,3,174)
B(7,38,4,174)
B(7,38,5,174)
B(7,38,6,174)
B(7,38,7,174)
B(7,38,8,174)
B(7,39,-3,174)
B(7,39,-2,174)
B(7,39,-1,174)
B(7,39,0,174)
B(7,39,1,174)
B(7,39,2,174)
B(7,39,3,174)
B(7,39,4,174)
B(7,39,5,174)
B(7,39,6,174)
B(7,39,7,174)
B(7,39,8,174)
B(7,40,-3,174)
B(7,40,-2,174)
B(7,40,-1,174)
B(7,40,0,174)
B(7,40,1,174)
B(7,40,2,174)
B(7,40,3,174)
B(7,40,4,174)
B(7,40,5,174)
B(7,40,6,174)
B(7,40,7,174)
B(7,40,8,174)
B(7,41,-3,174)
B(7,41,-2,174)
B(7,41,-1,174)
B(7,41,0,174)
B(7,41,1,174)
B(7,41,2,174)
B(7,41,3,174)
B(7,41,4,174)
B(7,41,5,174)
B(7,41,6,174)
B(7,41,7,174)
B(7,41,8,174)
B(7,42,-3,174)
B(7,42,-2,174)
B(7,42,-1,174)
B(7,42,0,174)
B(7,42,1,174)
B(7,42,2,174)
B(7,42,3,174)
B(7,42,4,174)
B(7,42,5,174)
B(7,42,6,174)
B(7,42,7,174)
B(7,42,8,174)
B(7,43,-3,174)
B(7,43,-2,174)
B(7,43,-1,174)
B(7,43,0,174)
B(7,43,1,174)
B(7,43,2,174)
B(7,43,3,174)
B(7,43,4,174)
B(7,43,5,174)
B(7,43,6,174)
B(7,43,7,174)
B(7,43,8,174)
B(7,44,-3,174)
B(7,44,-2,174)
B(7,44,-1,174)
B(7,44,0,174)
B(7,44,1,174)
B(7,44,2,174)
B(7,44,3,174)
B(7,44,4,174)
B(7,44,5,174)
B(7,44,6,174)
B(7,44,7,174)
B(7,44,8,174)
B(7,45,-3,174)
B(7,45,-2,174)
B(7,45,-1,174)
B(7,45,0,174)
B(7,45,1,174)
B(7,45,2,174)
B(7,45,3,174)
B(7,45,4,174)
B(7,45,5,174)
B(7,45,6,174)
B(7,45,7,174)
B(7,45,8,174)
B(7,46,-3,174)
B(7,46,-2,174)
B(7,46,-1,174)
B(7,46,0,174)
B(7,46,1,174)
B(7,46,2,174)
B(7,46,3,174)
B(7,46,4,174)
B(7,46,5,174)
B(7,46,6,174)
B(7,46,7,174)
B(7,46,8,174)
B(7,47,-3,174)
B(7,47,-2,174)
B(7,47,-1,174)
B(7,47,0,174)
B(7,47,1,174)
B(7,47,2,174)
B(7,47,3,174)
B(7,47,4,174)
B(7,47,5,174)
B(7,47,6,174)
B(7,47,7,174)
B(7,47,8,174)
B(7,48,-2,174)
B(7,48,-1,174)
B(7,48,0,174)
B(7,48,1,174)
B(7,48,2,174)
B(7,48,3,174)
B(7,48,4,174)
B(7,48,5,174)
B(7,48,6,174)
B(7,48,7,174)
B(7,48,8,174)
B(7,49,-2,174)
B(7,49,-1,174)
B(7,49,0,174)
B(7,49,1,174)
B(7,49,2,174)
B(7,49,3,174)
B(7,49,4,174)
B(7,49,5,174)
B(7,49,6,174)
B(7,49,7,174)
B(7,49,8,174)
B(7,50,-2,174)
B(7,50,-1,174)
B(7,50,0,174)
B(7,50,1,174)
B(7,50,2,174)
B(7,50,3,174)
B(7,50,4,174)
B(7,50,5,174)
B(7,50,6,174)
B(7,50,7,174)
B(7,50,8,174)
B(7,51,-2,174)
B(7,51,-1,174)
B(7,51,0,174)
B(7,51,1,174)
B(7,51,2,174)
B(7,51,3,174)
B(7,51,4,174)
B(7,51,5,174)
B(7,51,6,174)
B(7,51,7,174)
B(7,51,8,174)
B(7,52,-2,174)
B(7,52,-1,174)
B(7,52,0,174)
B(7,52,1,174)
B(7,52,2,174)
B(7,52,3,174)
B(7,52,4,174)
B(7,52,5,174)
B(7,52,6,174)
B(7,52,7,174)
B(7,52,8,174)
B(7,53,-1,174)
B(7,53,0,174)
B(7,53,1,174)
B(7,53,2,174)
B(7,53,3,174)
B(7,53,4,174)
B(7,53,5,174)
B(7,53,6,174)
B(7,53,7,174)
B(7,53,8,174)
B(7,54,-1,174)
B(7,54,0,174)
B(7,54,1,174)
B(7,54,2,174)
B(7,54,3,174)
B(7,54,4,174)
B(7,54,5,174)
B(7,54,6,174)
B(7,54,7,174)
B(7,55,-1,174)
B(7,55,0,174)
B(7,55,1,174)
B(7,55,2,174)
B(7,55,3,174)
B(7,55,4,174)
B(7,55,5,174)
B(7,55,6,174)
B(7,56,0,174)
B(7,56,1,174)
B(7,56,2,174)
B(7,56,3,174)
B(7,56,4,174)
B(7,56,5,174)
B(7,56,6,174)
B(7,57,1,174)
B(7,57,2,174)
B(7,57,3,174)
B(7,57,4,174)
B(7,58,0,174)
B(7,58,1,174)
B(7,58,2,174)
B(7,58,3,174)
B(7,59,-4,174)
B(7,59,-3,174)
B(7,59,-2,174)
B(7,59,0,174)
B(7,59,1,174)
B(7,59,2,174)
B(7,60,-7,174)
B(7,60,-6,174)
B(7,60,-5,174)
B(7,60,-4,174)
B(7,60,-3,174)
B(7,60,-2,174)
B(7,60,-1,174)
B(7,60,0,174)
B(7,60,1,174)
B(7,61,-7,174)
B(7,61,-6,174)
B(7,61,-5,174)
B(7,61,-4,174)
B(7,61,-3,174)
B(7,61,-2,174)
B(7,61,-1,174)
B(7,61,0,174)
B(7,62,-7,174)
B(7,62,-6,174)
B(7,62,-5,174)
B(7,62,-4,174)
B(7,62,-3,174)
B(7,62,-2,174)
B(7,62,-1,174)
B(7,63,-7,174)
B(7,63,-6,174)
B(7,63,-5,174)
B(7,63,-4,174)
B(7,63,-3,174)
B(7,63,-2,174)
B(7,63,-1,174)
B(7,64,-7,174)
B(7,64,-6,174)
B(7,64,-5,174)
B(7,64,-4,174)
B(7,64,-3,174)
B(7,64,-2,174)
B(7,65,-7,174)
B(7,65,-6,174)
B(7,65,-5,174)
B(7,65,-4,174)
B(7,65,-3,174)
B(7,65,-2,174)
B(7,66,-7,174)
B(7,66,-6,174)
B(7,66,-5,174)
B(7,66,-4,174)


#######################################################################
# +-----------------------------------------------------------------+ #
# |                            BO3 checks                           | #
# +-----------------------------------------------------------------+ #
#######################################################################

# Require a condition at a certain location in order for the BO3 to be spawned.
# BlockCheck(x,y,z,BlockName[,BlockName[,...]]) - one of the blocks must be at the location
# BlockCheckNot(x,y,z,BlockName[,BlockName[,...]]) - all the blocks must not be at the location
# LightCheck(x,y,z,minLightLevel,maxLightLevel) - light must be between min and max (inclusive)

# You can use "Solid" as a BlockName for matching all solid blocks or "All" to match all blocks that aren't air.

# Examples:
#   BlockCheck(0,-1,0,GRASS,DIRT,biomesoplenty:grass:0,biomesoplenty:grass:1,biomesoplenty:grass:2,biomesoplenty:grass:3,biomesoplenty:grass:4,biomesoplenty:grass:5,biomesoplenty:grass:6,biomesoplenty:grass:7,biomesoplenty:dirt:0,biomesoplenty:dirt:1,biomesoplenty:dirt:2,biomesoplenty:dirt:3,biomesoplenty:dirt:4,biomesoplenty:dirt:5,biomesoplenty:dirt:6,biomesoplenty:dirt:7,biomesoplenty:dirt:8,biomesoplenty:dirt:9,biomesoplenty:dirt:10,biomesoplenty:dried_sand:0,biomesoplenty:hard_ice:0,biomesoplenty:white_sand:0,biomesoplenty:white_sandstone:0,biomesoplenty:mud:0,biomesoplenty:ash_block:0)  Require grass or dirt just below the object
#   BlockCheck(0,-1,0,Solid)       Require any solid block just below the object
#   BlockCheck(0,-1,0,WOOL)        Require any type of wool just below the object
#   BlockCheck(0,-1,0,WOOL:0)      Require white wool just below the object
#   BlockCheckNot(0,-1,0,WOOL:0)   Require that there is no white wool below the object
#   LightCheck(0,0,0,0,1)          Require almost complete darkness just below the object

#######################################################################
# +-----------------------------------------------------------------+ #
# |                             Branches                            | #
# +-----------------------------------------------------------------+ #
#######################################################################

# Branches are objects that will spawn when this object spawns when it is used in
# the CustomStructure resource. Branches can also have branches, making complex
# structures possible. See the wiki for more details.

# Regular Branches spawn each branch with an independent chance of spawning.
# Branch(x,y,z,branchName,rotation,chance[,anotherBranchName,rotation,chance[,...]][IndividualChance])
# branchName - name of the object to spawn.
# rotation - NORTH, SOUTH, EAST or WEST.
# IndividualChance - The chance each branch has to spawn, assumed to be 100 when left blank

# WBR(x,y,z,branchName,rotation,chance[,anotherBranchName,rotation,chance[,...]][MaxChanceOutOf])
# MaxChanceOutOf - The chance all branches have to spawn out of, assumed to be 100 when left blank
Branch(16,0,0,IceGlacierCave1C2R3,NORTH,100)
