#######################################################################
# +-----------------------------------------------------------------+ #
# |                            BO3 object                           | #
# +-----------------------------------------------------------------+ #
#######################################################################

# The descriptions in this file are true only for TerrainControl. They are not true for the Minecraft Worlds mod!
# Minecraft Worlds completely reimplemented BO3s, check the MCW documentation on the mc/mctcp forums for how to use BO3s with MCW
# or watch the video's on my YT channel at https://www.youtube.com/user/PeeGee85. You can check out the "Editing and importing schematics & BO3s" 
# series of video's, in part 2 I explain BO3s. 

# This is the config file of a custom object.
# If you add this object correctly to your BiomeConfigs, it will spawn in the world.

# This is the creator of this BO3 object
Author: Unknown

# A short description of this BO3 object
Description: This BO3 was converted from a schematic using the MineCraft Worlds Editor. Unfortunately the author and description information for the schematic could not be found. If you know who the author of the schematic is then please tell the author of this BO3!

# The BO3 version, don't change this! It can be used by external applications to do a version check.
Version: 3

# The settings mode, WriteAll, WriteWithoutComments or WriteDisable. See WorldConfig.
SettingsMode: WriteDisable

#######################################################################
# +-----------------------------------------------------------------+ #
# |                          Main settings                          | #
# +-----------------------------------------------------------------+ #
#######################################################################

# This needs to be set to true to spawn the object in the Tree and Sapling resources.
Tree: false

# The frequency of the BO3 from 1 to 200. Tries this many times to spawn this BO3 when using the CustomObject(...) resource.
# Ignored by Tree(..), Sapling(..) and CustomStructure(..)
Frequency: 40

# The rarity of the BO3 from 0 to 100. Each spawn attempt has rarity% chance to succeed when using the CustomObject(...) resource.
# Ignored by Tree(..), Sapling(..) and CustomStructure(..)
Rarity: 100.0

# If you set this to true, the BO3 will be placed with a random rotation.
RotateRandomly: false

# The spawn height of the BO3 - randomY, highestBlock or highestSolidBlock.
SpawnHeight: randomY

# The height limits for the BO3.
MinHeight: 0

MaxHeight: 256

# Objects can have other objects attached to it: branches. Branches can also
# have branches attached to it, which can also have branches, etc. This is the
# maximum branch depth for this objects.
MaxBranchDepth: 10

# When spawned with the UseWorld keyword, this BO3 should NOT spawn in the following biomes.
# If you writer.write the BO3 name directly in the BiomeConfigs, this will be ignored.
ExcludedBiomes: All

#######################################################################
# +-----------------------------------------------------------------+ #
# |                      Source block settings                      | #
# +-----------------------------------------------------------------+ #
#######################################################################

# The B(s) the BO3 should spawn in.
SourceBlocks: AIR

# The maximum percentage of the BO3 that can be outside the SourceBlock.
# The BO3 won't be placed on a location with more blocks outside the SourceBlock than this percentage.
MaxPercentageOutsideSourceBlock: 100

# What to do when a block is about to be placed outside the SourceBlock? (dontPlace, placeAnyway)
OutsideSourceBlock: placeAnyway

#######################################################################
# +-----------------------------------------------------------------+ #
# |                              Blocks                             | #
# +-----------------------------------------------------------------+ #
#######################################################################

# All the blocks used in the BO3 are listed here. Possible blocks:
# B(x,y,z,id[.data][,nbtfile.nbt)
# RB(x,y,z,id[:data][,nbtfile.nbt],chance[,id[:data][,nbtfile.nbt],chance[,...]])
# So RB(0,0,0,CHEST,chest.nbt,50,CHEST,anotherchest.nbt,100) will spawn a chest at
# the BO3 origin, and give it a 50% chance to have the contents of chest.nbt, or, if that
# fails, a 100% percent chance to have the contents of anotherchest.nbt.

B(-8,22,-7,174)
B(-8,23,-7,174)
B(-8,24,-7,174)
B(-8,24,-6,174)
B(-8,25,-7,174)
B(-8,25,-6,174)
B(-8,26,-7,174)
B(-8,26,-6,174)
B(-8,26,-5,174)
B(-8,27,-7,174)
B(-8,27,-6,174)
B(-8,27,-5,174)
B(-8,28,-7,174)
B(-8,28,-6,174)
B(-8,28,-5,174)
B(-8,28,-4,174)
B(-8,29,-7,174)
B(-8,29,-6,174)
B(-8,29,-5,174)
B(-8,29,-4,174)
B(-8,29,-3,174)
B(-8,30,-7,174)
B(-8,30,-6,174)
B(-8,30,-5,174)
B(-8,30,-4,174)
B(-8,30,-3,174)
B(-8,30,-2,174)
B(-8,31,-7,174)
B(-8,31,-6,174)
B(-8,31,-5,174)
B(-8,31,-4,174)
B(-8,31,-3,174)
B(-8,31,-2,174)
B(-8,32,-7,174)
B(-8,32,-6,174)
B(-8,32,-5,174)
B(-8,32,-4,174)
B(-8,32,-3,174)
B(-8,32,-2,174)
B(-8,32,-1,174)
B(-8,33,-7,174)
B(-8,33,-6,174)
B(-8,33,-5,174)
B(-8,33,-4,174)
B(-8,33,-3,174)
B(-8,33,-2,174)
B(-8,33,-1,174)
B(-8,33,0,174)
B(-8,34,-7,174)
B(-8,34,-6,174)
B(-8,34,-5,174)
B(-8,34,-4,174)
B(-8,34,-3,174)
B(-8,34,-2,174)
B(-8,34,-1,174)
B(-8,34,0,174)
B(-8,35,-7,174)
B(-8,35,-6,174)
B(-8,35,-5,174)
B(-8,35,-4,174)
B(-8,35,-3,174)
B(-8,35,-2,174)
B(-8,35,-1,174)
B(-8,35,0,174)
B(-8,36,-7,174)
B(-8,36,-6,174)
B(-8,36,-5,174)
B(-8,36,-4,174)
B(-8,36,-3,174)
B(-8,36,-2,174)
B(-8,36,-1,174)
B(-8,36,0,174)
B(-8,37,-7,174)
B(-8,37,-6,174)
B(-8,37,-5,174)
B(-8,37,-4,174)
B(-8,37,-3,174)
B(-8,37,-2,174)
B(-8,37,-1,174)
B(-8,37,0,174)
B(-8,38,-7,174)
B(-8,38,-6,174)
B(-8,38,-5,174)
B(-8,38,-4,174)
B(-8,38,-3,174)
B(-8,38,-2,174)
B(-8,38,-1,174)
B(-8,38,0,174)
B(-8,38,1,174)
B(-8,39,-7,174)
B(-8,39,-6,174)
B(-8,39,-5,174)
B(-8,39,-4,174)
B(-8,39,-3,174)
B(-8,39,-2,174)
B(-8,39,-1,174)
B(-8,39,0,174)
B(-8,39,1,174)
B(-8,40,-7,174)
B(-8,40,-6,174)
B(-8,40,-5,174)
B(-8,40,-4,174)
B(-8,40,-3,174)
B(-8,40,-2,174)
B(-8,40,-1,174)
B(-8,40,0,174)
B(-8,40,1,174)
B(-8,41,-7,174)
B(-8,41,-6,174)
B(-8,41,-5,174)
B(-8,41,-4,174)
B(-8,41,-3,174)
B(-8,41,-2,174)
B(-8,41,-1,174)
B(-8,41,0,174)
B(-8,41,1,174)
B(-8,42,-7,174)
B(-8,42,-6,174)
B(-8,42,-5,174)
B(-8,42,-4,174)
B(-8,42,-3,174)
B(-8,42,-2,174)
B(-8,42,-1,174)
B(-8,42,0,174)
B(-8,43,-7,174)
B(-8,43,-6,174)
B(-8,43,-5,174)
B(-8,43,-4,174)
B(-8,43,-3,174)
B(-8,43,-2,174)
B(-8,43,-1,174)
B(-8,43,0,174)
B(-8,44,-7,174)
B(-8,44,-6,174)
B(-8,44,-5,174)
B(-8,44,-4,174)
B(-8,44,-3,174)
B(-8,44,-2,174)
B(-8,44,-1,174)
B(-8,44,0,174)
B(-8,45,-7,174)
B(-8,45,-6,174)
B(-8,45,-5,174)
B(-8,45,-4,174)
B(-8,45,-3,174)
B(-8,45,-2,174)
B(-8,45,-1,174)
B(-8,45,0,174)
B(-8,46,-7,174)
B(-8,46,-6,174)
B(-8,46,-5,174)
B(-8,46,-4,174)
B(-8,46,-3,174)
B(-8,46,-2,174)
B(-8,46,-1,174)
B(-8,46,0,174)
B(-8,47,-7,174)
B(-8,47,-6,174)
B(-8,47,-5,174)
B(-8,47,-4,174)
B(-8,47,-3,174)
B(-8,47,-2,174)
B(-8,47,-1,174)
B(-8,48,-7,174)
B(-8,48,-6,174)
B(-8,48,-5,174)
B(-8,48,-4,174)
B(-8,48,-3,174)
B(-8,48,-2,174)
B(-8,48,-1,174)
B(-8,49,-7,174)
B(-8,49,-6,174)
B(-8,49,-5,174)
B(-8,49,-4,174)
B(-8,49,-3,174)
B(-8,49,-2,174)
B(-8,50,-7,174)
B(-8,50,-6,174)
B(-8,50,-5,174)
B(-8,50,-4,174)
B(-8,50,-3,174)
B(-8,50,-2,174)
B(-8,51,-7,174)
B(-8,51,-6,174)
B(-8,51,-5,174)
B(-8,51,-4,174)
B(-8,51,-3,174)
B(-8,52,-7,174)
B(-8,52,-6,174)
B(-8,52,-5,174)
B(-8,52,-4,174)
B(-8,52,-3,174)
B(-8,53,-7,174)
B(-8,53,-6,174)
B(-8,53,-5,174)
B(-8,53,-4,174)
B(-8,53,-3,174)
B(-8,54,-7,174)
B(-8,54,-6,174)
B(-8,54,-5,174)
B(-8,54,-4,174)
B(-8,54,-3,174)
B(-8,55,-7,174)
B(-8,55,-6,174)
B(-8,55,-5,174)
B(-8,55,-4,174)
B(-8,56,-7,174)
B(-8,56,-6,174)
B(-8,56,-5,174)
B(-8,57,-7,174)
B(-8,57,-6,174)
B(-8,57,-5,174)
B(-8,58,-7,174)
B(-8,58,-6,174)
B(-8,59,-7,174)
B(-7,24,-7,174)
B(-7,25,-7,174)
B(-7,26,-7,174)
B(-7,26,-6,174)
B(-7,27,-7,174)
B(-7,27,-6,174)
B(-7,27,-5,174)
B(-7,28,-7,174)
B(-7,28,-6,174)
B(-7,28,-5,174)
B(-7,28,-4,174)
B(-7,29,-7,174)
B(-7,29,-6,174)
B(-7,29,-5,174)
B(-7,29,-4,174)
B(-7,29,-3,174)
B(-7,30,-7,174)
B(-7,30,-6,174)
B(-7,30,-5,174)
B(-7,30,-4,174)
B(-7,30,-3,174)
B(-7,30,-2,174)
B(-7,31,-7,174)
B(-7,31,-6,174)
B(-7,31,-5,174)
B(-7,31,-4,174)
B(-7,31,-3,174)
B(-7,31,-2,174)
B(-7,32,-7,174)
B(-7,32,-6,174)
B(-7,32,-5,174)
B(-7,32,-4,174)
B(-7,32,-3,174)
B(-7,32,-2,174)
B(-7,33,-7,174)
B(-7,33,-6,174)
B(-7,33,-5,174)
B(-7,33,-4,174)
B(-7,33,-3,174)
B(-7,33,-2,174)
B(-7,33,-1,174)
B(-7,34,-7,174)
B(-7,34,-6,174)
B(-7,34,-5,174)
B(-7,34,-4,174)
B(-7,34,-3,174)
B(-7,34,-2,174)
B(-7,34,-1,174)
B(-7,35,-7,174)
B(-7,35,-6,174)
B(-7,35,-5,174)
B(-7,35,-4,174)
B(-7,35,-3,174)
B(-7,35,-2,174)
B(-7,35,-1,174)
B(-7,36,-7,174)
B(-7,36,-6,174)
B(-7,36,-5,174)
B(-7,36,-4,174)
B(-7,36,-3,174)
B(-7,36,-2,174)
B(-7,36,-1,174)
B(-7,37,-7,174)
B(-7,37,-6,174)
B(-7,37,-5,174)
B(-7,37,-4,174)
B(-7,37,-3,174)
B(-7,37,-2,174)
B(-7,37,-1,174)
B(-7,37,0,174)
B(-7,38,-7,174)
B(-7,38,-6,174)
B(-7,38,-5,174)
B(-7,38,-4,174)
B(-7,38,-3,174)
B(-7,38,-2,174)
B(-7,38,-1,174)
B(-7,38,0,174)
B(-7,39,-7,174)
B(-7,39,-6,174)
B(-7,39,-5,174)
B(-7,39,-4,174)
B(-7,39,-3,174)
B(-7,39,-2,174)
B(-7,39,-1,174)
B(-7,39,0,174)
B(-7,40,-7,174)
B(-7,40,-6,174)
B(-7,40,-5,174)
B(-7,40,-4,174)
B(-7,40,-3,174)
B(-7,40,-2,174)
B(-7,40,-1,174)
B(-7,40,0,174)
B(-7,40,1,174)
B(-7,41,-7,174)
B(-7,41,-6,174)
B(-7,41,-5,174)
B(-7,41,-4,174)
B(-7,41,-3,174)
B(-7,41,-2,174)
B(-7,41,-1,174)
B(-7,41,0,174)
B(-7,41,1,174)
B(-7,42,-7,174)
B(-7,42,-6,174)
B(-7,42,-5,174)
B(-7,42,-4,174)
B(-7,42,-3,174)
B(-7,42,-2,174)
B(-7,42,-1,174)
B(-7,42,0,174)
B(-7,43,-7,174)
B(-7,43,-6,174)
B(-7,43,-5,174)
B(-7,43,-4,174)
B(-7,43,-3,174)
B(-7,43,-2,174)
B(-7,43,-1,174)
B(-7,43,0,174)
B(-7,44,-7,174)
B(-7,44,-6,174)
B(-7,44,-5,174)
B(-7,44,-4,174)
B(-7,44,-3,174)
B(-7,44,-2,174)
B(-7,44,-1,174)
B(-7,44,0,174)
B(-7,45,-7,174)
B(-7,45,-6,174)
B(-7,45,-5,174)
B(-7,45,-4,174)
B(-7,45,-3,174)
B(-7,45,-2,174)
B(-7,45,-1,174)
B(-7,45,0,174)
B(-7,46,-7,174)
B(-7,46,-6,174)
B(-7,46,-5,174)
B(-7,46,-4,174)
B(-7,46,-3,174)
B(-7,46,-2,174)
B(-7,46,-1,174)
B(-7,46,0,174)
B(-7,47,-7,174)
B(-7,47,-6,174)
B(-7,47,-5,174)
B(-7,47,-4,174)
B(-7,47,-3,174)
B(-7,47,-2,174)
B(-7,47,-1,174)
B(-7,48,-7,174)
B(-7,48,-6,174)
B(-7,48,-5,174)
B(-7,48,-4,174)
B(-7,48,-3,174)
B(-7,48,-2,174)
B(-7,48,-1,174)
B(-7,49,-7,174)
B(-7,49,-6,174)
B(-7,49,-5,174)
B(-7,49,-4,174)
B(-7,49,-3,174)
B(-7,49,-2,174)
B(-7,50,-7,174)
B(-7,50,-6,174)
B(-7,50,-5,174)
B(-7,50,-4,174)
B(-7,50,-3,174)
B(-7,51,-7,174)
B(-7,51,-6,174)
B(-7,51,-5,174)
B(-7,51,-4,174)
B(-7,51,-3,174)
B(-7,52,-7,174)
B(-7,52,-6,174)
B(-7,52,-5,174)
B(-7,52,-4,174)
B(-7,52,-3,174)
B(-7,53,-7,174)
B(-7,53,-6,174)
B(-7,53,-5,174)
B(-7,53,-4,174)
B(-7,53,-3,174)
B(-7,54,-7,174)
B(-7,54,-6,174)
B(-7,54,-5,174)
B(-7,54,-4,174)
B(-7,55,-7,174)
B(-7,55,-6,174)
B(-7,55,-5,174)
B(-7,56,-7,174)
B(-7,56,-6,174)
B(-7,57,-7,174)
B(-7,57,-6,174)
B(-7,57,-5,174)
B(-6,25,-7,174)
B(-6,26,-7,174)
B(-6,27,-7,174)
B(-6,27,-6,174)
B(-6,27,-5,174)
B(-6,28,-7,174)
B(-6,28,-6,174)
B(-6,28,-5,174)
B(-6,28,-4,174)
B(-6,29,-7,174)
B(-6,29,-6,174)
B(-6,29,-5,174)
B(-6,29,-4,174)
B(-6,29,-3,174)
B(-6,30,-7,174)
B(-6,30,-6,174)
B(-6,30,-5,174)
B(-6,30,-4,174)
B(-6,30,-3,174)
B(-6,31,-7,174)
B(-6,31,-6,174)
B(-6,31,-5,174)
B(-6,31,-4,174)
B(-6,31,-3,174)
B(-6,31,-2,174)
B(-6,32,-7,174)
B(-6,32,-6,174)
B(-6,32,-5,174)
B(-6,32,-4,174)
B(-6,32,-3,174)
B(-6,33,-7,174)
B(-6,33,-6,174)
B(-6,33,-5,174)
B(-6,33,-4,174)
B(-6,33,-3,174)
B(-6,34,-7,174)
B(-6,34,-6,174)
B(-6,34,-5,174)
B(-6,34,-4,174)
B(-6,34,-3,174)
B(-6,34,-2,174)
B(-6,35,-7,174)
B(-6,35,-6,174)
B(-6,35,-5,174)
B(-6,35,-4,174)
B(-6,35,-3,174)
B(-6,35,-2,174)
B(-6,35,-1,174)
B(-6,36,-7,174)
B(-6,36,-6,174)
B(-6,36,-5,174)
B(-6,36,-4,174)
B(-6,36,-3,174)
B(-6,36,-2,174)
B(-6,36,-1,174)
B(-6,37,-7,174)
B(-6,37,-6,174)
B(-6,37,-5,174)
B(-6,37,-4,174)
B(-6,37,-3,174)
B(-6,37,-2,174)
B(-6,37,-1,174)
B(-6,38,-7,174)
B(-6,38,-6,174)
B(-6,38,-5,174)
B(-6,38,-4,174)
B(-6,38,-3,174)
B(-6,38,-2,174)
B(-6,38,-1,174)
B(-6,39,-7,174)
B(-6,39,-6,174)
B(-6,39,-5,174)
B(-6,39,-4,174)
B(-6,39,-3,174)
B(-6,39,-2,174)
B(-6,40,-7,174)
B(-6,40,-6,174)
B(-6,40,-5,174)
B(-6,40,-4,174)
B(-6,40,-3,174)
B(-6,40,-2,174)
B(-6,40,-1,174)
B(-6,41,-7,174)
B(-6,41,-6,174)
B(-6,41,-5,174)
B(-6,41,-4,174)
B(-6,41,-3,174)
B(-6,41,-2,174)
B(-6,41,-1,174)
B(-6,41,0,174)
B(-6,42,-7,174)
B(-6,42,-6,174)
B(-6,42,-5,174)
B(-6,42,-4,174)
B(-6,42,-3,174)
B(-6,42,-2,174)
B(-6,42,-1,174)
B(-6,43,-7,174)
B(-6,43,-6,174)
B(-6,43,-5,174)
B(-6,43,-4,174)
B(-6,43,-3,174)
B(-6,43,-2,174)
B(-6,43,-1,174)
B(-6,43,0,174)
B(-6,44,-7,174)
B(-6,44,-6,174)
B(-6,44,-5,174)
B(-6,44,-4,174)
B(-6,44,-3,174)
B(-6,44,-2,174)
B(-6,44,-1,174)
B(-6,44,0,174)
B(-6,45,-7,174)
B(-6,45,-6,174)
B(-6,45,-5,174)
B(-6,45,-4,174)
B(-6,45,-3,174)
B(-6,45,-2,174)
B(-6,45,-1,174)
B(-6,46,-7,174)
B(-6,46,-6,174)
B(-6,46,-5,174)
B(-6,46,-4,174)
B(-6,46,-3,174)
B(-6,46,-2,174)
B(-6,46,-1,174)
B(-6,47,-7,174)
B(-6,47,-6,174)
B(-6,47,-5,174)
B(-6,47,-4,174)
B(-6,47,-3,174)
B(-6,47,-2,174)
B(-6,47,-1,174)
B(-6,48,-7,174)
B(-6,48,-6,174)
B(-6,48,-5,174)
B(-6,48,-4,174)
B(-6,48,-3,174)
B(-6,48,-2,174)
B(-6,49,-7,174)
B(-6,49,-6,174)
B(-6,49,-5,174)
B(-6,49,-4,174)
B(-6,49,-3,174)
B(-6,49,-2,174)
B(-6,50,-7,174)
B(-6,50,-6,174)
B(-6,50,-5,174)
B(-6,50,-4,174)
B(-6,50,-3,174)
B(-6,50,-2,174)
B(-6,51,-7,174)
B(-6,51,-6,174)
B(-6,51,-5,174)
B(-6,51,-4,174)
B(-6,51,-3,174)
B(-6,52,-7,174)
B(-6,52,-6,174)
B(-6,52,-5,174)
B(-6,52,-4,174)
B(-6,52,-3,174)
B(-6,53,-7,174)
B(-6,53,-6,174)
B(-6,53,-5,174)
B(-6,53,-4,174)
B(-6,53,-3,174)
B(-6,54,-7,174)
B(-6,54,-6,174)
B(-6,54,-5,174)
B(-6,55,-7,174)
B(-6,55,-6,174)
B(-5,25,-7,174)
B(-5,25,-6,174)
B(-5,26,-7,174)
B(-5,27,-7,174)
B(-5,27,-6,174)
B(-5,28,-7,174)
B(-5,28,-6,174)
B(-5,29,-7,174)
B(-5,29,-6,174)
B(-5,29,-5,174)
B(-5,30,-7,174)
B(-5,30,-6,174)
B(-5,30,-5,174)
B(-5,31,-6,174)
B(-5,31,-5,174)
B(-5,32,-7,174)
B(-5,32,-6,174)
B(-5,32,-5,174)
B(-5,33,-7,174)
B(-5,33,-6,174)
B(-5,33,-5,174)
B(-5,34,-7,174)
B(-5,34,-6,174)
B(-5,34,-5,174)
B(-5,34,-4,174)
B(-5,34,-3,174)
B(-5,35,-7,174)
B(-5,35,-6,174)
B(-5,35,-5,174)
B(-5,35,-4,174)
B(-5,35,-3,174)
B(-5,35,-2,174)
B(-5,36,-7,174)
B(-5,36,-6,174)
B(-5,36,-5,174)
B(-5,36,-4,174)
B(-5,36,-3,174)
B(-5,36,-2,174)
B(-5,36,-1,174)
B(-5,37,-7,174)
B(-5,37,-6,174)
B(-5,37,-5,174)
B(-5,37,-4,174)
B(-5,37,-3,174)
B(-5,38,-7,174)
B(-5,38,-6,174)
B(-5,38,-5,174)
B(-5,38,-4,174)
B(-5,39,-7,174)
B(-5,39,-6,174)
B(-5,39,-5,174)
B(-5,39,-4,174)
B(-5,40,-7,174)
B(-5,40,-6,174)
B(-5,40,-5,174)
B(-5,40,-4,174)
B(-5,40,-3,174)
B(-5,41,-7,174)
B(-5,41,-6,174)
B(-5,41,-5,174)
B(-5,41,-4,174)
B(-5,41,-3,174)
B(-5,41,-2,174)
B(-5,41,-1,174)
B(-5,42,-7,174)
B(-5,42,-6,174)
B(-5,42,-5,174)
B(-5,42,-4,174)
B(-5,42,-3,174)
B(-5,43,-7,174)
B(-5,43,-6,174)
B(-5,43,-5,174)
B(-5,43,-4,174)
B(-5,43,-3,174)
B(-5,43,-2,174)
B(-5,43,-1,174)
B(-5,44,-7,174)
B(-5,44,-6,174)
B(-5,44,-5,174)
B(-5,44,-4,174)
B(-5,44,-3,174)
B(-5,44,-2,174)
B(-5,45,-7,174)
B(-5,45,-6,174)
B(-5,45,-5,174)
B(-5,45,-4,174)
B(-5,45,-3,174)
B(-5,45,-2,174)
B(-5,46,-7,174)
B(-5,46,-6,174)
B(-5,46,-5,174)
B(-5,46,-4,174)
B(-5,46,-3,174)
B(-5,46,-2,174)
B(-5,47,-7,174)
B(-5,47,-6,174)
B(-5,47,-5,174)
B(-5,47,-4,174)
B(-5,47,-3,174)
B(-5,47,-2,174)
B(-5,48,-7,174)
B(-5,48,-6,174)
B(-5,48,-5,174)
B(-5,48,-4,174)
B(-5,48,-3,174)
B(-5,48,-2,174)
B(-5,49,-7,174)
B(-5,49,-6,174)
B(-5,49,-5,174)
B(-5,49,-4,174)
B(-5,49,-3,174)
B(-5,49,-2,174)
B(-5,50,-7,174)
B(-5,50,-6,174)
B(-5,50,-5,174)
B(-5,50,-4,174)
B(-5,50,-3,174)
B(-5,50,-2,174)
B(-5,51,-7,174)
B(-5,51,-6,174)
B(-5,51,-5,174)
B(-5,51,-4,174)
B(-5,51,-3,174)
B(-5,52,-7,174)
B(-5,52,-6,174)
B(-5,52,-5,174)
B(-5,52,-4,174)
B(-5,53,-6,174)
B(-5,53,-5,174)
B(-5,54,-5,174)
B(-4,25,-7,174)
B(-4,25,-6,174)
B(-4,26,-6,174)
B(-4,26,-5,174)
B(-4,27,-7,174)
B(-4,27,-6,174)
B(-4,28,-6,174)
B(-4,29,-6,174)
B(-4,29,-5,174)
B(-4,32,-6,174)
B(-4,33,-6,174)
B(-4,33,-5,174)
B(-4,34,-5,174)
B(-4,41,-7,174)
B(-4,41,-4,174)
B(-4,41,-3,174)
B(-4,42,-7,174)
B(-4,43,-7,174)
B(-4,43,-6,174)
B(-4,43,-4,174)
B(-4,44,-7,174)
B(-4,44,-6,174)
B(-4,44,-5,174)
B(-4,44,-4,174)
B(-4,44,-3,174)
B(-4,45,-7,174)
B(-4,45,-6,174)
B(-4,45,-5,174)
B(-4,45,-4,174)
B(-4,45,-3,174)
B(-4,45,-2,174)
B(-4,46,-7,174)
B(-4,46,-6,174)
B(-4,46,-5,174)
B(-4,46,-4,174)
B(-4,46,-3,174)
B(-4,46,-2,174)
B(-4,47,-7,174)
B(-4,47,-6,174)
B(-4,47,-5,174)
B(-4,47,-4,174)
B(-4,47,-3,174)
B(-4,47,-2,174)
B(-4,48,-7,174)
B(-4,48,-6,174)
B(-4,48,-5,174)
B(-4,48,-4,174)
B(-4,48,-3,174)
B(-4,48,-2,174)
B(-4,49,-7,174)
B(-4,49,-6,174)
B(-4,49,-5,174)
B(-4,49,-4,174)
B(-4,49,-3,174)
B(-4,49,-2,174)
B(-4,50,-7,174)
B(-4,50,-6,174)
B(-4,50,-5,174)
B(-4,50,-4,174)
B(-4,50,-3,174)
B(-4,50,-2,174)
B(-4,51,-4,174)
B(-3,43,-4,174)
B(-3,43,-3,174)
B(-3,44,-5,174)
B(-3,44,-4,174)
B(-3,44,-3,174)
B(-3,44,-2,174)
B(-3,45,-7,174)
B(-3,45,-6,174)
B(-3,45,-5,174)
B(-3,45,-4,174)
B(-3,45,-3,174)
B(-3,45,-2,174)
B(-3,46,-7,174)
B(-3,46,-6,174)
B(-3,46,-5,174)
B(-3,46,-4,174)
B(-3,46,-3,174)
B(-3,46,-2,174)
B(-3,47,-7,174)
B(-3,47,-6,174)
B(-3,47,-5,174)
B(-3,47,-4,174)
B(-3,47,-3,174)
B(-3,47,-2,174)
B(-3,48,-6,174)
B(-3,48,-5,174)
B(-3,48,-4,174)
B(-3,48,-3,174)
B(-3,48,-2,174)
B(-3,49,-6,174)
B(-3,49,-5,174)
B(-3,49,-4,174)
B(-3,49,-3,174)
B(-3,49,-2,174)
B(-3,50,-4,174)
B(-3,50,-3,174)
B(-3,50,-2,174)
B(-2,43,-3,174)
B(-2,44,-4,174)
B(-2,44,-3,174)
B(-2,44,-2,174)
B(-2,45,-5,174)
B(-2,45,-4,174)
B(-2,45,-3,174)
B(-2,45,-2,174)
B(-2,46,-6,174)
B(-2,46,-5,174)
B(-2,46,-4,174)
B(-2,46,-3,174)
B(-2,46,-2,174)
B(-2,46,-1,174)
B(-2,47,-5,174)
B(-2,47,-4,174)
B(-2,47,-3,174)
B(-2,47,-2,174)
B(-2,48,-4,174)
B(-2,48,-3,174)
B(-1,44,-3,174)
B(-1,45,-4,174)
B(-1,45,-3,174)
B(-1,45,-2,174)
B(-1,46,-5,174)
B(-1,46,-4,174)
B(-1,46,-3,174)


#######################################################################
# +-----------------------------------------------------------------+ #
# |                            BO3 checks                           | #
# +-----------------------------------------------------------------+ #
#######################################################################

# Require a condition at a certain location in order for the BO3 to be spawned.
# BlockCheck(x,y,z,BlockName[,BlockName[,...]]) - one of the blocks must be at the location
# BlockCheckNot(x,y,z,BlockName[,BlockName[,...]]) - all the blocks must not be at the location
# LightCheck(x,y,z,minLightLevel,maxLightLevel) - light must be between min and max (inclusive)

# You can use "Solid" as a BlockName for matching all solid blocks or "All" to match all blocks that aren't air.

# Examples:
#   BlockCheck(0,-1,0,GRASS,DIRT,biomesoplenty:grass:0,biomesoplenty:grass:1,biomesoplenty:grass:2,biomesoplenty:grass:3,biomesoplenty:grass:4,biomesoplenty:grass:5,biomesoplenty:grass:6,biomesoplenty:grass:7,biomesoplenty:dirt:0,biomesoplenty:dirt:1,biomesoplenty:dirt:2,biomesoplenty:dirt:3,biomesoplenty:dirt:4,biomesoplenty:dirt:5,biomesoplenty:dirt:6,biomesoplenty:dirt:7,biomesoplenty:dirt:8,biomesoplenty:dirt:9,biomesoplenty:dirt:10,biomesoplenty:dried_sand:0,biomesoplenty:hard_ice:0,biomesoplenty:white_sand:0,biomesoplenty:white_sandstone:0,biomesoplenty:mud:0,biomesoplenty:ash_block:0)  Require grass or dirt just below the object
#   BlockCheck(0,-1,0,Solid)       Require any solid block just below the object
#   BlockCheck(0,-1,0,WOOL)        Require any type of wool just below the object
#   BlockCheck(0,-1,0,WOOL:0)      Require white wool just below the object
#   BlockCheckNot(0,-1,0,WOOL:0)   Require that there is no white wool below the object
#   LightCheck(0,0,0,0,1)          Require almost complete darkness just below the object

#######################################################################
# +-----------------------------------------------------------------+ #
# |                             Branches                            | #
# +-----------------------------------------------------------------+ #
#######################################################################

# Branches are objects that will spawn when this object spawns when it is used in
# the CustomStructure resource. Branches can also have branches, making complex
# structures possible. See the wiki for more details.

# Regular Branches spawn each branch with an independent chance of spawning.
# Branch(x,y,z,branchName,rotation,chance[,anotherBranchName,rotation,chance[,...]][IndividualChance])
# branchName - name of the object to spawn.
# rotation - NORTH, SOUTH, EAST or WEST.
# IndividualChance - The chance each branch has to spawn, assumed to be 100 when left blank

# WBR(x,y,z,branchName,rotation,chance[,anotherBranchName,rotation,chance[,...]][MaxChanceOutOf])
# MaxChanceOutOf - The chance all branches have to spawn out of, assumed to be 100 when left blank
Branch(16,0,0,IceGlacierCave1C4R4,NORTH,100)
