
#######################################################################
# +-----------------------------------------------------------------+ #
# |                            BO3 object                           | #
# +-----------------------------------------------------------------+ #
#######################################################################

Author: LordSmellyPants

Description: No description given

Version: 3

SettingsMode: WriteWithoutComments


#######################################################################
# +-----------------------------------------------------------------+ #
# |                          Main settings                          | #
# +-----------------------------------------------------------------+ #
#######################################################################

Tree: true

Frequency: 1

Rarity: 100.0

RotateRandomly: true

SpawnHeight: highestSolidBlock

SpawnHeightOffset: 0

SpawnHeightVariance: 0

##############################
# Height Limits for the BO3. #
##############################

MinHeight: 63

MaxHeight: 70

######################
# Extrusion settings #
######################

ExtrudeMode: None

ExtrudeThroughBlocks: AIR

MaxBranchDepth: 10

ExcludedBiomes: All


#######################################################################
# +-----------------------------------------------------------------+ #
# |                      Source block settings                      | #
# +-----------------------------------------------------------------+ #
#######################################################################

SourceBlocks: AIR

MaxPercentageOutsideSourceBlock: 0

OutsideSourceBlock: placeAnyway

DoReplaceBlocks: true

IsOTGPlus: false


#######################################################################
# +-----------------------------------------------------------------+ #
# |                              Blocks                             | #
# +-----------------------------------------------------------------+ #
#######################################################################

Block(-13,11,-3,LEAVES:1)
Block(-13,11,-2,LEAVES:1)
Block(-13,20,3,LEAVES:1)
Block(-12,11,-2,LOG:13)
Block(-12,12,-2,LEAVES:1)
Block(-12,20,3,LEAVES:1)
Block(-12,20,4,LEAVES:1)
Block(-11,12,-2,LOG:13)
Block(-11,20,3,LOG:13)
Block(-10,12,-3,LEAVES:1)
Block(-10,12,-2,LOG:13)
Block(-10,20,2,LEAVES:1)
Block(-10,20,3,LOG:13)
Block(-9,13,-2,LOG:13)
Block(-9,14,13,LOG:13)
Block(-9,14,14,LEAVES:1)
Block(-9,21,3,LOG:13)
Block(-9,21,4,LEAVES:1)
Block(-9,22,-3,LEAVES:1)
Block(-8,13,-2,LOG:13)
Block(-8,13,-1,LEAVES:1)
Block(-8,13,0,LEAVES:1)
Block(-8,14,-1,LEAVES:1)
Block(-8,15,11,LEAVES:1)
Block(-8,15,12,LOG:13)
Block(-8,21,2,LEAVES:1)
Block(-8,21,3,LOG:13)
Block(-8,22,-4,LEAVES:1)
Block(-8,22,-3,LOG:13)
Block(-8,22,1,LEAVES:1)
Block(-8,22,2,LEAVES:1)
Block(-8,28,1,LEAVES:1)
Block(-7,14,-1,LOG:13)
Block(-7,15,11,LOG:13)
Block(-7,15,12,LEAVES:1)
Block(-7,22,-2,LOG:13)
Block(-7,22,-1,LEAVES:1)
Block(-7,22,2,LOG:13)
Block(-7,28,1,LEAVES:1)
Block(-7,28,2,LEAVES:1)
Block(-6,14,-2,LEAVES:1)
Block(-6,14,-1,LOG:13)
Block(-6,16,9,LEAVES:1)
Block(-6,16,10,LOG:13)
Block(-6,22,2,LOG:13)
Block(-6,22,3,LEAVES:1)
Block(-6,23,-2,LOG:13)
Block(-6,28,1,LOG:13)
Block(-6,29,1,LEAVES:1)
Block(-5,-5,0,LOG:1)
Block(-5,-5,4,LOG:1)
Block(-5,-4,0,LOG:13)
Block(-5,-4,4,LOG:1)
Block(-5,14,-1,LOG:13)
Block(-5,16,9,LOG:13)
Block(-5,23,-2,LEAVES:1)
Block(-5,23,-1,LOG:13)
Block(-5,23,2,LOG:13)
Block(-5,29,1,LOG:13)
Block(-5,32,-6,LEAVES:1)
Block(-5,34,0,LEAVES:1)
Block(-5,34,1,LEAVES:1)
Block(-5,35,0,LEAVES:1)
Block(-4,-5,-2,LOG:1)
Block(-4,-5,0,LOG:5)
Block(-4,-5,1,LOG:1)
Block(-4,-5,4,LOG:1)
Block(-4,-5,5,LOG:1)
Block(-4,-4,-2,LOG:13)
Block(-4,-4,1,LOG:13)
Block(-4,-4,4,LOG:13)
Block(-4,-4,5,LOG:13)
Block(-4,-3,1,LOG:13)
Block(-4,-3,4,LOG:13)
Block(-4,-2,1,LOG:1)
Block(-4,14,-1,LEAVES:1)
Block(-4,15,-1,LEAVES:1)
Block(-4,15,0,LOG:13)
Block(-4,16,-9,LEAVES:1)
Block(-4,16,9,LEAVES:1)
Block(-4,16,10,LEAVES:1)
Block(-4,17,-7,LEAVES:1)
Block(-4,17,7,LEAVES:1)
Block(-4,17,8,LOG:13)
Block(-4,17,9,LEAVES:1)
Block(-4,23,1,LOG:13)
Block(-4,24,-1,LOG:13)
Block(-4,24,0,LEAVES:1)
Block(-4,29,1,LOG:13)
Block(-4,29,2,LEAVES:1)
Block(-4,32,-7,LEAVES:1)
Block(-4,32,-6,LOG:13)
Block(-4,34,-1,LEAVES:1)
Block(-4,34,0,LOG:13)
Block(-4,34,5,LEAVES:1)
Block(-4,39,-5,LEAVES:1)
Block(-4,46,-4,LOG:13)
Block(-4,47,4,LOG:13)
Block(-4,52,-1,LOG:13)
Block(-3,-5,-3,LOG:1)
Block(-3,-5,-1,LOG:9)
Block(-3,-5,0,LOG:1)
Block(-3,-5,1,LOG:1)
Block(-3,-5,3,LOG:1)
Block(-3,-5,4,LOG:1)
Block(-3,-4,-3,LOG:13)
Block(-3,-4,-2,LOG:13)
Block(-3,-4,-1,LOG:1)
Block(-3,-4,0,LOG:13)
Block(-3,-4,3,LOG:13)
Block(-3,-3,-3,LOG:13)
Block(-3,-3,-2,LOG:13)
Block(-3,-3,0,LOG:13)
Block(-3,-3,3,LOG:1)
Block(-3,-2,0,LOG:13)
Block(-3,-1,0,LOG:13)
Block(-3,0,0,LOG:1)
Block(-3,15,0,LOG:13)
Block(-3,15,1,LEAVES:1)
Block(-3,16,-11,LEAVES:1)
Block(-3,16,-10,LEAVES:1)
Block(-3,16,-9,LOG:13)
Block(-3,17,-9,LEAVES:1)
Block(-3,17,-8,LOG:13)
Block(-3,17,-7,LOG:13)
Block(-3,17,7,LOG:13)
Block(-3,24,0,LOG:13)
Block(-3,30,1,LOG:13)
Block(-3,32,-5,LOG:13)
Block(-3,34,5,LOG:13)
Block(-3,34,6,LEAVES:1)
Block(-3,35,0,LOG:13)
Block(-3,35,1,LEAVES:1)
Block(-3,39,-5,LOG:13)
Block(-3,46,-3,LOG:13)
Block(-3,48,3,LOG:13)
Block(-3,52,-1,LOG:13)
Block(-2,-5,-2,LOG:1)
Block(-2,-5,1,LOG:1)
Block(-2,-5,2,LOG:1)
Block(-2,-5,5,LOG:1)
Block(-2,-4,-1,LOG:13)
Block(-2,-4,0,LOG:13)
Block(-2,-4,1,LOG:13)
Block(-2,-4,2,LOG:13)
Block(-2,-4,3,LOG:13)
Block(-2,-4,4,LOG:13)
Block(-2,-4,5,LOG:13)
Block(-2,-3,-1,LOG:13)
Block(-2,-3,0,LOG:13)
Block(-2,-3,1,LOG:13)
Block(-2,-3,2,LOG:13)
Block(-2,-3,3,LOG:13)
Block(-2,-2,-1,LOG:13)
Block(-2,-2,0,LOG:13)
Block(-2,-2,1,LOG:13)
Block(-2,-2,2,LOG:13)
Block(-2,-2,3,LOG:13)
Block(-2,-1,-1,LOG:13)
Block(-2,-1,0,LOG:13)
Block(-2,-1,1,LOG:13)
Block(-2,-1,2,LOG:13)
Block(-2,-1,3,LOG:1)
Block(-2,0,0,LOG:13)
Block(-2,0,1,LOG:13)
Block(-2,0,2,LOG:13)
Block(-2,1,0,LOG:13)
Block(-2,1,1,LOG:13)
Block(-2,2,0,LOG:13)
Block(-2,2,1,LOG:13)
Block(-2,3,0,LOG:13)
Block(-2,3,1,LOG:13)
Block(-2,4,0,LOG:13)
Block(-2,5,0,LOG:13)
Block(-2,6,0,LOG:13)
Block(-2,16,-1,LEAVES:1)
Block(-2,16,0,LOG:13)
Block(-2,16,9,LOG:13)
Block(-2,17,-7,LEAVES:1)
Block(-2,17,7,LEAVES:1)
Block(-2,17,8,LOG:13)
Block(-2,18,-7,LEAVES:1)
Block(-2,18,-6,LOG:13)
Block(-2,18,-5,LEAVES:1)
Block(-2,18,5,LEAVES:1)
Block(-2,18,6,LOG:13)
Block(-2,18,7,LEAVES:1)
Block(-2,22,9,LOG:13)
Block(-2,22,10,LEAVES:1)
Block(-2,24,-1,LEAVES:1)
Block(-2,24,0,LEAVES:1)
Block(-2,25,0,LEAVES:1)
Block(-2,25,1,LOG:13)
Block(-2,30,-1,LEAVES:1)
Block(-2,30,0,LEAVES:1)
Block(-2,30,1,LOG:13)
Block(-2,31,0,LEAVES:1)
Block(-2,33,-5,LOG:13)
Block(-2,35,0,LEAVES:1)
Block(-2,35,1,LOG:13)
Block(-2,35,3,LEAVES:1)
Block(-2,35,4,LOG:13)
Block(-2,36,0,LEAVES:1)
Block(-2,40,-4,LOG:13)
Block(-2,40,-3,LEAVES:1)
Block(-2,41,-3,LEAVES:1)
Block(-2,47,-2,LOG:13)
Block(-2,49,2,LOG:13)
Block(-2,53,0,LOG:13)
Block(-2,57,2,LOG:13)
Block(-2,62,0,LEAVES:1)
Block(-1,-5,-4,LOG:1)
Block(-1,-5,-3,LOG:1)
Block(-1,-5,-2,LOG:1)
Block(-1,-5,4,LOG:1)
Block(-1,-4,-4,LOG:13)
Block(-1,-4,-2,LOG:13)
Block(-1,-4,-1,LOG:13)
Block(-1,-4,0,LOG:13)
Block(-1,-4,1,LOG:13)
Block(-1,-4,2,LOG:13)
Block(-1,-4,3,LOG:13)
Block(-1,-4,4,LOG:13)
Block(-1,-3,-1,LOG:13)
Block(-1,-3,0,LOG:13)
Block(-1,-3,1,LOG:13)
Block(-1,-3,2,LOG:13)
Block(-1,-3,3,LOG:13)
Block(-1,-3,4,LOG:13)
Block(-1,-2,-1,LOG:13)
Block(-1,-2,0,LOG:13)
Block(-1,-2,1,LOG:13)
Block(-1,-2,2,LOG:13)
Block(-1,-2,3,LOG:13)
Block(-1,-2,4,LOG:1)
Block(-1,-1,-1,LOG:13)
Block(-1,-1,0,LOG:13)
Block(-1,-1,1,LOG:13)
Block(-1,-1,2,LOG:13)
Block(-1,-1,3,LOG:13)
Block(-1,0,-1,LOG:13)
Block(-1,0,0,LOG:13)
Block(-1,0,1,LOG:13)
Block(-1,0,2,LOG:13)
Block(-1,1,-1,LOG:1)
Block(-1,1,0,LOG:13)
Block(-1,1,1,LOG:13)
Block(-1,1,2,LOG:13)
Block(-1,2,0,LOG:13)
Block(-1,2,1,LOG:13)
Block(-1,3,0,LOG:13)
Block(-1,3,1,LOG:13)
Block(-1,4,0,LOG:13)
Block(-1,4,1,LOG:13)
Block(-1,5,0,LOG:13)
Block(-1,5,1,LOG:13)
Block(-1,6,0,LOG:13)
Block(-1,6,1,LOG:13)
Block(-1,7,0,LOG:13)
Block(-1,7,1,LOG:13)
Block(-1,8,0,LOG:13)
Block(-1,8,1,LOG:13)
Block(-1,9,0,LOG:13)
Block(-1,9,1,LOG:13)
Block(-1,10,0,LOG:13)
Block(-1,11,0,LOG:13)
Block(-1,12,0,LOG:13)
Block(-1,13,0,LOG:13)
Block(-1,14,0,LOG:13)
Block(-1,15,0,LOG:13)
Block(-1,15,10,LOG:13)
Block(-1,15,11,LEAVES:1)
Block(-1,16,0,LOG:13)
Block(-1,16,9,LEAVES:1)
Block(-1,18,5,LOG:13)
Block(-1,19,-5,LOG:13)
Block(-1,19,-4,LEAVES:1)
Block(-1,23,7,LEAVES:1)
Block(-1,23,8,LOG:13)
Block(-1,25,1,LOG:13)
Block(-1,25,5,LEAVES:1)
Block(-1,31,0,LOG:13)
Block(-1,34,-4,LOG:13)
Block(-1,35,3,LOG:13)
Block(-1,35,4,LEAVES:1)
Block(-1,36,1,LOG:13)
Block(-1,36,2,LOG:13)
Block(-1,39,3,LEAVES:1)
Block(-1,40,1,LEAVES:1)
Block(-1,41,-3,LOG:13)
Block(-1,41,-2,LOG:13)
Block(-1,47,-1,LOG:13)
Block(-1,49,1,LOG:13)
Block(-1,53,0,LOG:13)
Block(-1,54,-3,LOG:13)
Block(-1,55,-2,LOG:13)
Block(-1,55,0,LEAVES:1)
Block(-1,58,1,LOG:13)
Block(-1,62,0,LOG:13)
Block(0,-5,-3,LOG:1)
Block(0,-5,3,LOG:1)
Block(0,-5,5,LOG:1)
Block(0,-5,6,LOG:1)
Block(0,-4,-3,LOG:13)
Block(0,-4,-2,LOG:13)
Block(0,-4,-1,LOG:13)
Block(0,-4,0,LOG:13)
Block(0,-4,1,LOG:13)
Block(0,-4,2,LOG:13)
Block(0,-4,3,LOG:13)
Block(0,-4,6,LOG:13)
Block(0,-3,-2,LOG:13)
Block(0,-3,-1,LOG:13)
Block(0,-3,0,LOG:13)
Block(0,-3,1,LOG:13)
Block(0,-3,2,LOG:13)
Block(0,-3,3,LOG:13)
Block(0,-2,-1,LOG:13)
Block(0,-2,0,LOG:13)
Block(0,-2,1,LOG:13)
Block(0,-2,2,LOG:13)
Block(0,-2,3,LOG:13)
Block(0,-1,-1,LOG:13)
Block(0,-1,0,LOG:13)
Block(0,-1,1,LOG:13)
Block(0,-1,2,LOG:13)
Block(0,0,-1,LOG:13)
Block(0,0,0,LOG:13)
Block(0,0,1,LOG:13)
Block(0,0,2,LOG:13)
Block(0,1,-1,LOG:13)
Block(0,1,0,LOG:13)
Block(0,1,1,LOG:13)
Block(0,1,2,LOG:13)
Block(0,2,-1,LOG:13)
Block(0,2,0,LOG:13)
Block(0,2,1,LOG:13)
Block(0,2,2,LOG:13)
Block(0,3,-1,LOG:13)
Block(0,3,0,LOG:13)
Block(0,3,1,LOG:13)
Block(0,3,2,LOG:13)
Block(0,4,-1,LOG:13)
Block(0,4,0,LOG:13)
Block(0,4,1,LOG:13)
Block(0,4,2,LOG:13)
Block(0,5,-1,LOG:13)
Block(0,5,0,LOG:13)
Block(0,5,1,LOG:13)
Block(0,5,2,LOG:13)
Block(0,6,-1,LOG:13)
Block(0,6,0,LOG:13)
Block(0,6,1,LOG:13)
Block(0,6,2,LOG:13)
Block(0,7,-1,LOG:13)
Block(0,7,0,LOG:13)
Block(0,7,1,LOG:13)
Block(0,7,2,LOG:13)
Block(0,8,-1,LOG:13)
Block(0,8,0,LOG:13)
Block(0,8,1,LOG:13)
Block(0,8,2,LOG:13)
Block(0,9,-1,LOG:13)
Block(0,9,0,LOG:13)
Block(0,9,1,LOG:13)
Block(0,9,2,LOG:13)
Block(0,10,-1,LOG:13)
Block(0,10,0,LOG:13)
Block(0,10,1,LOG:13)
Block(0,10,2,LOG:13)
Block(0,11,-1,LOG:13)
Block(0,11,0,LOG:13)
Block(0,11,1,LOG:13)
Block(0,11,2,LOG:13)
Block(0,12,-1,LOG:13)
Block(0,12,0,LOG:13)
Block(0,12,1,LOG:13)
Block(0,12,2,LOG:13)
Block(0,13,-1,LOG:13)
Block(0,13,0,LOG:13)
Block(0,13,1,LOG:13)
Block(0,14,-1,LOG:13)
Block(0,14,0,LOG:13)
Block(0,14,1,LOG:13)
Block(0,15,-1,LOG:13)
Block(0,15,0,LOG:13)
Block(0,15,1,LOG:13)
Block(0,15,11,LOG:13)
Block(0,16,-1,LOG:13)
Block(0,16,0,LOG:13)
Block(0,16,1,LOG:13)
Block(0,17,-1,LOG:13)
Block(0,17,0,LOG:13)
Block(0,17,1,LOG:13)
Block(0,18,-1,LOG:13)
Block(0,18,0,LOG:13)
Block(0,18,1,LOG:13)
Block(0,18,5,LEAVES:1)
Block(0,19,-4,LOG:13)
Block(0,19,-3,LEAVES:1)
Block(0,19,-1,LOG:13)
Block(0,19,0,LOG:13)
Block(0,19,1,LOG:13)
Block(0,19,4,LOG:13)
Block(0,19,5,LEAVES:1)
Block(0,20,-2,LOG:13)
Block(0,20,-1,LOG:13)
Block(0,20,0,LOG:13)
Block(0,20,1,LOG:13)
Block(0,21,0,LOG:13)
Block(0,21,1,LOG:13)
Block(0,22,0,LOG:13)
Block(0,22,1,LOG:13)
Block(0,23,0,LOG:13)
Block(0,23,1,LOG:13)
Block(0,23,7,LOG:13)
Block(0,24,0,LOG:13)
Block(0,24,1,LOG:13)
Block(0,25,0,LOG:13)
Block(0,25,1,LOG:13)
Block(0,25,4,LOG:13)
Block(0,25,5,LOG:13)
Block(0,26,0,LOG:13)
Block(0,26,1,LOG:13)
Block(0,26,2,LOG:13)
Block(0,26,3,LOG:13)
Block(0,27,0,LOG:13)
Block(0,27,1,LOG:13)
Block(0,28,-3,LEAVES:1)
Block(0,28,0,LOG:13)
Block(0,28,1,LOG:13)
Block(0,29,-2,LOG:13)
Block(0,29,-1,LOG:13)
Block(0,29,0,LOG:13)
Block(0,29,1,LOG:13)
Block(0,30,0,LOG:13)
Block(0,30,1,LOG:13)
Block(0,30,2,LEAVES:1)
Block(0,31,0,LOG:13)
Block(0,31,1,LOG:13)
Block(0,32,0,LOG:13)
Block(0,32,1,LOG:13)
Block(0,33,-5,LEAVES:1)
Block(0,33,-4,LOG:13)
Block(0,33,0,LOG:13)
Block(0,33,1,LOG:13)
Block(0,34,-3,LOG:13)
Block(0,34,0,LOG:13)
Block(0,34,1,LOG:13)
Block(0,35,-1,LEAVES:1)
Block(0,35,0,LOG:13)
Block(0,35,1,LOG:13)
Block(0,36,0,LOG:13)
Block(0,36,1,LOG:13)
Block(0,36,2,LEAVES:1)
Block(0,37,0,LOG:13)
Block(0,37,1,LOG:13)
Block(0,38,0,LOG:13)
Block(0,38,6,LEAVES:1)
Block(0,39,0,LOG:13)
Block(0,39,3,LOG:13)
Block(0,40,0,LOG:13)
Block(0,40,1,LOG:13)
Block(0,40,2,LOG:13)
Block(0,41,-2,LEAVES:1)
Block(0,41,0,LOG:13)
Block(0,41,1,LEAVES:1)
Block(0,42,-2,LEAVES:1)
Block(0,42,-1,LOG:13)
Block(0,42,0,LOG:13)
Block(0,43,-1,LEAVES:1)
Block(0,43,0,LOG:13)
Block(0,44,0,LOG:13)
Block(0,45,0,LOG:13)
Block(0,46,0,LOG:13)
Block(0,46,1,LEAVES:1)
Block(0,47,-1,LEAVES:1)
Block(0,47,0,LOG:13)
Block(0,48,0,LOG:13)
Block(0,49,0,LOG:13)
Block(0,50,0,LOG:13)
Block(0,50,1,LEAVES:1)
Block(0,51,0,LOG:13)
Block(0,52,0,LOG:13)
Block(0,53,0,LOG:13)
Block(0,54,0,LOG:13)
Block(0,55,-1,LOG:13)
Block(0,55,0,LOG:13)
Block(0,56,0,LOG:13)
Block(0,56,1,LEAVES:1)
Block(0,57,0,LOG:13)
Block(0,58,0,LOG:13)
Block(0,59,-1,LOG:13)
Block(0,59,0,LOG:13)
Block(0,59,1,LEAVES:1)
Block(0,60,0,LOG:13)
Block(0,60,1,LEAVES:1)
Block(0,61,0,LOG:13)
Block(0,62,0,LOG:13)
Block(0,63,0,LOG:13)
Block(0,64,-1,LEAVES:1)
Block(0,64,0,LOG:13)
Block(0,64,1,LEAVES:1)
Block(0,65,0,LOG:13)
Block(0,66,0,LOG:13)
Block(0,67,0,LOG:13)
Block(0,68,0,LOG:13)
Block(0,69,0,LOG:13)
Block(1,-5,-5,LOG:1)
Block(1,-5,-4,LOG:1)
Block(1,-5,-3,LOG:1)
Block(1,-5,3,LOG:1)
Block(1,-5,4,LOG:1)
Block(1,-5,5,LOG:1)
Block(1,-4,-5,LOG:9)
Block(1,-4,-4,LOG:13)
Block(1,-4,-3,LOG:13)
Block(1,-4,-1,LOG:13)
Block(1,-4,0,LOG:13)
Block(1,-4,1,LOG:13)
Block(1,-4,2,LOG:13)
Block(1,-4,3,LOG:13)
Block(1,-4,4,LOG:9)
Block(1,-4,5,LOG:13)
Block(1,-3,-3,LOG:13)
Block(1,-3,-1,LOG:13)
Block(1,-3,0,LOG:13)
Block(1,-3,1,LOG:13)
Block(1,-3,2,LOG:13)
Block(1,-3,3,LOG:13)
Block(1,-3,5,LOG:1)
Block(1,-2,-1,LOG:13)
Block(1,-2,0,LOG:13)
Block(1,-2,1,LOG:13)
Block(1,-2,2,LOG:13)
Block(1,-2,3,LOG:13)
Block(1,-1,-1,LOG:13)
Block(1,-1,0,LOG:13)
Block(1,-1,1,LOG:13)
Block(1,-1,2,LOG:13)
Block(1,-1,3,LOG:13)
Block(1,0,-1,LOG:1)
Block(1,0,0,LOG:1)
Block(1,0,1,LOG:13)
Block(1,0,2,LOG:13)
Block(1,0,3,LOG:13)
Block(1,1,-1,LOG:1)
Block(1,1,0,LOG:1)
Block(1,1,1,LOG:13)
Block(1,1,2,LOG:13)
Block(1,2,-1,LOG:1)
Block(1,2,0,LOG:1)
Block(1,2,1,LOG:13)
Block(1,2,2,LOG:13)
Block(1,3,0,LOG:1)
Block(1,3,1,LOG:13)
Block(1,3,2,LOG:13)
Block(1,4,0,LOG:13)
Block(1,4,1,LOG:13)
Block(1,4,2,LOG:13)
Block(1,5,0,LOG:13)
Block(1,5,1,LOG:13)
Block(1,5,2,LOG:13)
Block(1,6,0,LOG:13)
Block(1,6,1,LOG:13)
Block(1,6,2,LOG:13)
Block(1,7,0,LOG:13)
Block(1,7,1,LOG:13)
Block(1,7,2,LOG:13)
Block(1,8,0,LOG:13)
Block(1,8,1,LOG:13)
Block(1,8,2,LOG:13)
Block(1,9,0,LOG:13)
Block(1,9,1,LOG:13)
Block(1,9,2,LOG:13)
Block(1,10,0,LOG:13)
Block(1,10,1,LOG:13)
Block(1,10,2,LOG:13)
Block(1,11,0,LOG:13)
Block(1,11,1,LOG:13)
Block(1,11,2,LOG:13)
Block(1,12,0,LOG:13)
Block(1,12,1,LOG:13)
Block(1,12,2,LOG:13)
Block(1,13,0,LOG:13)
Block(1,13,1,LOG:13)
Block(1,13,2,LOG:13)
Block(1,14,0,LOG:13)
Block(1,14,1,LOG:13)
Block(1,14,2,LOG:13)
Block(1,15,0,LOG:13)
Block(1,15,1,LOG:13)
Block(1,15,2,LOG:13)
Block(1,15,11,LEAVES:1)
Block(1,16,0,LOG:13)
Block(1,16,1,LOG:13)
Block(1,16,2,LOG:13)
Block(1,17,0,LOG:13)
Block(1,17,1,LOG:13)
Block(1,17,2,LOG:13)
Block(1,18,-5,LEAVES:1)
Block(1,18,0,LOG:13)
Block(1,18,1,LOG:13)
Block(1,18,2,LOG:13)
Block(1,18,5,LEAVES:1)
Block(1,19,-3,LOG:13)
Block(1,19,-2,LEAVES:1)
Block(1,19,0,LOG:13)
Block(1,19,1,LOG:13)
Block(1,19,2,LOG:13)
Block(1,19,3,LOG:13)
Block(1,20,-2,LEAVES:1)
Block(1,20,0,LOG:13)
Block(1,20,1,LOG:13)
Block(1,20,2,LOG:13)
Block(1,21,0,LOG:13)
Block(1,21,1,LOG:13)
Block(1,21,2,LOG:13)
Block(1,22,0,LOG:13)
Block(1,22,1,LOG:13)
Block(1,22,2,LOG:13)
Block(1,23,0,LOG:13)
Block(1,23,1,LOG:13)
Block(1,23,2,LOG:13)
Block(1,24,0,LOG:13)
Block(1,24,1,LOG:13)
Block(1,24,6,LOG:13)
Block(1,25,0,LOG:13)
Block(1,25,1,LOG:13)
Block(1,26,0,LOG:13)
Block(1,26,1,LOG:13)
Block(1,26,3,LOG:13)
Block(1,27,-5,LEAVES:1)
Block(1,27,0,LOG:13)
Block(1,27,1,LOG:13)
Block(1,28,-3,LOG:13)
Block(1,28,-2,LEAVES:1)
Block(1,28,0,LOG:13)
Block(1,28,1,LOG:13)
Block(1,29,-2,LEAVES:1)
Block(1,29,0,LOG:13)
Block(1,29,1,LOG:13)
Block(1,30,0,LOG:13)
Block(1,30,2,LOG:13)
Block(1,30,3,LOG:13)
Block(1,31,0,LOG:13)
Block(1,31,1,LOG:13)
Block(1,32,-8,LEAVES:1)
Block(1,32,-7,LEAVES:1)
Block(1,32,-6,LOG:13)
Block(1,32,0,LOG:13)
Block(1,33,-5,LOG:13)
Block(1,33,0,LOG:13)
Block(1,34,-3,LEAVES:1)
Block(1,34,0,LOG:13)
Block(1,35,-3,LEAVES:1)
Block(1,35,-2,LOG:13)
Block(1,35,-1,LOG:13)
Block(1,35,0,LOG:13)
Block(1,36,-1,LEAVES:1)
Block(1,36,0,LOG:13)
Block(1,37,0,LOG:13)
Block(1,38,0,LOG:13)
Block(1,38,5,LOG:13)
Block(1,38,6,LOG:13)
Block(1,39,0,LOG:13)
Block(1,39,3,LEAVES:1)
Block(1,39,4,LOG:13)
Block(1,40,0,LOG:13)
Block(1,41,-2,LEAVES:1)
Block(1,41,0,LOG:13)
Block(1,42,0,LOG:13)
Block(1,43,0,LOG:13)
Block(1,44,0,LOG:13)
Block(1,45,0,LOG:13)
Block(1,46,0,LEAVES:1)
Block(1,48,1,LOG:13)
Block(1,50,-1,LOG:13)
Block(1,54,1,LOG:13)
Block(1,58,-2,LOG:13)
Block(1,59,1,LEAVES:1)
Block(1,61,1,LOG:13)
Block(1,65,0,LOG:13)
Block(1,65,1,LEAVES:1)
Block(1,67,0,LEAVES:1)
Block(2,-5,-2,LOG:1)
Block(2,-5,1,LOG:1)
Block(2,-5,2,LOG:1)
Block(2,-5,3,LOG:1)
Block(2,-5,4,LOG:1)
Block(2,-5,5,LOG:1)
Block(2,-4,-2,LOG:13)
Block(2,-4,-1,LOG:13)
Block(2,-4,0,LOG:13)
Block(2,-4,1,LOG:13)
Block(2,-4,2,LOG:13)
Block(2,-4,3,LOG:13)
Block(2,-4,4,LOG:13)
Block(2,-4,5,LOG:13)
Block(2,-3,-2,LOG:13)
Block(2,-3,-1,LOG:13)
Block(2,-3,0,LOG:13)
Block(2,-3,1,LOG:13)
Block(2,-3,2,LOG:13)
Block(2,-3,3,LOG:13)
Block(2,-3,4,LOG:13)
Block(2,-2,-1,LOG:1)
Block(2,-2,0,LOG:13)
Block(2,-2,1,LOG:13)
Block(2,-2,2,LOG:13)
Block(2,-2,3,LOG:13)
Block(2,-1,0,LOG:13)
Block(2,-1,1,LOG:13)
Block(2,-1,2,LOG:13)
Block(2,-1,3,LOG:1)
Block(2,0,0,LOG:13)
Block(2,0,1,LOG:13)
Block(2,0,2,LOG:13)
Block(2,1,0,LOG:13)
Block(2,1,1,LOG:13)
Block(2,1,2,LOG:13)
Block(2,2,0,LOG:13)
Block(2,2,1,LOG:13)
Block(2,2,2,LOG:13)
Block(2,3,0,LOG:13)
Block(2,3,1,LOG:13)
Block(2,4,0,LOG:13)
Block(2,4,1,LOG:13)
Block(2,5,0,LOG:13)
Block(2,5,1,LOG:13)
Block(2,6,0,LOG:13)
Block(2,6,1,LOG:13)
Block(2,7,0,LOG:13)
Block(2,7,1,LOG:13)
Block(2,8,0,LOG:13)
Block(2,8,1,LOG:13)
Block(2,9,0,LOG:13)
Block(2,9,1,LOG:13)
Block(2,10,0,LOG:13)
Block(2,10,1,LOG:13)
Block(2,11,0,LOG:13)
Block(2,11,1,LOG:13)
Block(2,12,0,LOG:13)
Block(2,12,1,LOG:13)
Block(2,13,0,LOG:13)
Block(2,13,1,LOG:13)
Block(2,14,0,LOG:13)
Block(2,14,1,LOG:13)
Block(2,15,0,LOG:13)
Block(2,15,1,LOG:13)
Block(2,16,0,LOG:13)
Block(2,16,1,LOG:13)
Block(2,17,0,LOG:13)
Block(2,17,1,LOG:13)
Block(2,18,-5,LEAVES:1)
Block(2,18,0,LOG:13)
Block(2,18,1,LOG:13)
Block(2,19,-5,LEAVES:1)
Block(2,19,-4,LOG:13)
Block(2,19,-2,LEAVES:1)
Block(2,19,0,LOG:13)
Block(2,20,0,LOG:13)
Block(2,21,0,LOG:13)
Block(2,22,0,LOG:13)
Block(2,22,11,LEAVES:1)
Block(2,23,0,LOG:13)
Block(2,23,8,LOG:13)
Block(2,23,9,LOG:13)
Block(2,24,0,LOG:13)
Block(2,24,7,LOG:13)
Block(2,25,0,LOG:13)
Block(2,25,4,LOG:13)
Block(2,25,5,LEAVES:1)
Block(2,26,0,LOG:13)
Block(2,27,-5,LEAVES:1)
Block(2,27,0,LOG:13)
Block(2,28,-5,LEAVES:1)
Block(2,28,-4,LOG:13)
Block(2,28,-2,LEAVES:1)
Block(2,29,5,LEAVES:1)
Block(2,30,3,LEAVES:1)
Block(2,30,4,LOG:13)
Block(2,32,-7,LEAVES:1)
Block(2,32,0,LOG:13)
Block(2,32,1,LEAVES:1)
Block(2,37,7,LOG:13)
Block(2,37,8,LEAVES:1)
Block(2,39,0,LOG:13)
Block(2,45,0,LEAVES:1)
Block(2,45,1,LOG:13)
Block(2,45,2,LEAVES:1)
Block(2,47,4,LOG:13)
Block(2,48,2,LOG:13)
Block(2,48,3,LOG:13)
Block(2,50,-2,LOG:13)
Block(2,54,2,LOG:13)
Block(2,60,2,LOG:13)
Block(3,-5,-2,LOG:1)
Block(3,-5,0,LOG:1)
Block(3,-5,3,LOG:5)
Block(3,-4,-2,LOG:13)
Block(3,-4,0,LOG:13)
Block(3,-4,3,LOG:13)
Block(3,-3,0,LOG:13)
Block(3,-3,3,LOG:13)
Block(3,-2,0,LOG:13)
Block(3,-1,0,LOG:13)
Block(3,0,0,LOG:13)
Block(3,1,0,LOG:1)
Block(3,17,-7,LEAVES:1)
Block(3,17,1,LOG:13)
Block(3,18,-6,LOG:13)
Block(3,18,-5,LOG:13)
Block(3,18,-4,LEAVES:1)
Block(3,22,10,LOG:13)
Block(3,22,11,LOG:13)
Block(3,22,12,LEAVES:1)
Block(3,22,13,LEAVES:1)
Block(3,23,0,LOG:13)
Block(3,23,8,LEAVES:1)
Block(3,25,4,LEAVES:1)
Block(3,26,-7,LEAVES:1)
Block(3,27,-6,LOG:13)
Block(3,27,-5,LOG:13)
Block(3,27,-4,LEAVES:1)
Block(3,28,7,LEAVES:1)
Block(3,29,5,LOG:13)
Block(3,29,6,LOG:13)
Block(3,29,7,LEAVES:1)
Block(3,32,0,LOG:13)
Block(3,37,7,LEAVES:1)
Block(3,38,-1,LOG:13)
Block(3,38,0,LEAVES:1)
Block(3,38,1,LEAVES:1)
Block(3,39,0,LEAVES:1)
Block(3,44,1,LOG:13)
Block(3,49,-3,LOG:13)
Block(3,53,2,LOG:13)
Block(4,-5,-3,LOG:1)
Block(4,-5,-2,LOG:1)
Block(4,-5,-1,LOG:1)
Block(4,-5,2,LOG:1)
Block(4,-5,3,LOG:1)
Block(4,-4,-3,LOG:13)
Block(4,-4,-1,LOG:13)
Block(4,-4,2,LOG:13)
Block(4,-4,3,LOG:13)
Block(4,-3,-1,LOG:13)
Block(4,-3,2,LOG:1)
Block(4,16,-9,LEAVES:1)
Block(4,17,-7,LOG:13)
Block(4,17,-6,LEAVES:1)
Block(4,17,2,LOG:13)
Block(4,18,-6,LEAVES:1)
Block(4,22,12,LEAVES:1)
Block(4,23,-1,LOG:13)
Block(4,23,0,LOG:13)
Block(4,25,-9,LEAVES:1)
Block(4,26,-7,LOG:13)
Block(4,26,-6,LEAVES:1)
Block(4,27,-6,LEAVES:1)
Block(4,27,9,LEAVES:1)
Block(4,28,7,LOG:13)
Block(4,28,8,LOG:13)
Block(4,31,-1,LEAVES:1)
Block(4,31,0,LOG:13)
Block(4,38,-1,LOG:13)
Block(4,43,0,LEAVES:1)
Block(4,43,1,LEAVES:1)
Block(4,43,2,LOG:13)
Block(4,43,3,LEAVES:1)
Block(4,44,1,LEAVES:1)
Block(4,49,-4,LOG:13)
Block(5,-5,-1,LOG:1)
Block(5,-5,2,LOG:1)
Block(5,-4,-1,LOG:13)
Block(5,-4,2,LOG:13)
Block(5,16,-9,LOG:13)
Block(5,16,1,LEAVES:1)
Block(5,16,2,LEAVES:1)
Block(5,16,3,LOG:13)
Block(5,16,4,LEAVES:1)
Block(5,17,-9,LEAVES:1)
Block(5,17,-8,LOG:13)
Block(5,17,-6,LEAVES:1)
Block(5,17,2,LEAVES:1)
Block(5,22,-3,LEAVES:1)
Block(5,22,-2,LOG:13)
Block(5,22,0,LOG:13)
Block(5,25,-9,LOG:13)
Block(5,26,-9,LEAVES:1)
Block(5,26,-8,LOG:13)
Block(5,26,-6,LEAVES:1)
Block(5,27,9,LOG:13)
Block(5,27,10,LEAVES:1)
Block(5,28,7,LEAVES:1)
Block(5,30,-1,LOG:13)
Block(5,31,1,LOG:13)
Block(5,37,-2,LEAVES:1)
Block(5,37,-1,LOG:13)
Block(5,42,3,LEAVES:1)
Block(5,43,3,LOG:13)
Block(6,15,-12,LEAVES:1)
Block(6,15,-11,LOG:13)
Block(6,16,-10,LOG:13)
Block(6,16,-9,LEAVES:1)
Block(6,16,4,LOG:13)
Block(6,22,-2,LEAVES:1)
Block(6,22,0,LOG:13)
Block(6,22,1,LEAVES:1)
Block(6,24,-12,LEAVES:1)
Block(6,24,-11,LOG:13)
Block(6,25,-10,LOG:13)
Block(6,25,-9,LEAVES:1)
Block(6,30,-2,LOG:13)
Block(6,30,-1,LEAVES:1)
Block(6,30,1,LEAVES:1)
Block(6,30,2,LOG:13)
Block(6,30,3,LEAVES:1)
Block(6,31,1,LEAVES:1)
Block(6,37,-1,LOG:13)
Block(6,43,3,LEAVES:1)
Block(7,15,-11,LEAVES:1)
Block(7,15,4,LEAVES:1)
Block(7,15,5,LOG:13)
Block(7,15,6,LEAVES:1)
Block(7,16,4,LEAVES:1)
Block(7,21,-1,LOG:13)
Block(7,24,-11,LEAVES:1)
Block(7,30,-3,LEAVES:1)
Block(7,30,-2,LEAVES:1)
Block(7,30,2,LOG:13)
Block(7,36,-1,LOG:13)
Block(7,37,-1,LEAVES:1)
Block(8,15,6,LOG:13)
Block(8,20,0,LOG:13)
Block(8,20,1,LEAVES:1)
Block(8,21,-2,LOG:13)
Block(8,29,3,LOG:13)
Block(8,29,4,LEAVES:1)
Block(8,30,-2,LEAVES:1)
Block(8,36,-2,LEAVES:1)
Block(8,36,-1,LEAVES:1)
Block(9,14,6,LEAVES:1)
Block(9,14,7,LOG:13)
Block(9,14,8,LEAVES:1)
Block(9,15,6,LEAVES:1)
Block(9,20,-3,LEAVES:1)
Block(9,20,-2,LOG:13)
Block(9,20,1,LOG:13)
Block(9,29,3,LOG:13)
Block(9,36,-1,LEAVES:1)
Block(10,14,6,LEAVES:1)
Block(10,14,8,LOG:13)
Block(10,19,2,LOG:13)
Block(10,20,-2,LOG:13)
Block(10,28,3,LEAVES:1)
Block(10,28,4,LOG:13)
Block(10,29,3,LEAVES:1)
Block(11,13,9,LOG:13)
Block(11,13,10,LEAVES:1)
Block(11,19,-3,LOG:13)
Block(11,19,2,LEAVES:1)
Block(12,13,9,LEAVES:1)
Block(12,13,10,LOG:13)
Block(12,19,-3,LOG:13)
Block(12,19,-2,LEAVES:1)
Block(13,12,11,LOG:13)
Block(13,19,-4,LEAVES:1)
Block(13,19,-3,LEAVES:1)

#######################################################################
# +-----------------------------------------------------------------+ #
# |                            BO3 checks                           | #
# +-----------------------------------------------------------------+ #
#######################################################################

BlockCheck(0,-1,0,GRASS,DIRT,biomesoplenty:grass:0,biomesoplenty:grass:1,biomesoplenty:grass,biomesoplenty:grass:3,biomesoplenty:grass:4,biomesoplenty:grass:5,biomesoplenty:grass:6,biomesoplenty:grass:7,biomesoplenty:dirt,biomesoplenty:dirt:1,biomesoplenty:dirt:2,biomesoplenty:dirt:8,biomesoplenty:dirt:9,biomesoplenty:dirt:10,biomesoplenty:dried_sand,biomesoplenty:hard_ice,biomesoplenty:white_sand,biomesoplenty:white_sandstone,biomesoplenty:mud,biomesoplenty:ash_block)

#######################################################################
# +-----------------------------------------------------------------+ #
# |                             Branches                            | #
# +-----------------------------------------------------------------+ #
#######################################################################


#######################################################################
# +-----------------------------------------------------------------+ #
# |                             Entities                            | #
# +-----------------------------------------------------------------+ #
#######################################################################


#######################################################################
# +-----------------------------------------------------------------+ #
# |                            Particles                            | #
# +-----------------------------------------------------------------+ #
#######################################################################


#######################################################################
# +-----------------------------------------------------------------+ #
# |                             Spawners                            | #
# +-----------------------------------------------------------------+ #
#######################################################################


#######################################################################
# +-----------------------------------------------------------------+ #
# |                             ModData                             | #
# +-----------------------------------------------------------------+ #
#######################################################################

