
#######################################################################
# +-----------------------------------------------------------------+ #
# |                            BO3 object                           | #
# +-----------------------------------------------------------------+ #
#######################################################################

Author: LordSmellyPants

Description: No description given

Version: 3

SettingsMode: WriteWithoutComments


#######################################################################
# +-----------------------------------------------------------------+ #
# |                          Main settings                          | #
# +-----------------------------------------------------------------+ #
#######################################################################

Tree: true

Frequency: 1

Rarity: 100.0

RotateRandomly: true

SpawnHeight: highestSolidBlock

SpawnHeightOffset: 0

SpawnHeightVariance: 0

##############################
# Height Limits for the BO3. #
##############################

MinHeight: 63

MaxHeight: 70

######################
# Extrusion settings #
######################

ExtrudeMode: None

ExtrudeThroughBlocks: AIR

MaxBranchDepth: 10

ExcludedBiomes: All


#######################################################################
# +-----------------------------------------------------------------+ #
# |                      Source block settings                      | #
# +-----------------------------------------------------------------+ #
#######################################################################

SourceBlocks: AIR

MaxPercentageOutsideSourceBlock: 0

OutsideSourceBlock: placeAnyway

DoReplaceBlocks: true

IsOTGPlus: false


#######################################################################
# +-----------------------------------------------------------------+ #
# |                              Blocks                             | #
# +-----------------------------------------------------------------+ #
#######################################################################

Block(-14,12,3,LEAVES:1)
Block(-14,13,3,LEAVES:1)
Block(-14,13,5,LEAVES:1)
Block(-14,14,4,LEAVES:1)
Block(-13,13,4,LEAVES:1)
Block(-13,14,3,LEAVES:1)
Block(-13,14,4,LEAVES:1)
Block(-13,14,5,LEAVES:1)
Block(-13,15,4,LEAVES:1)
Block(-12,7,-13,LEAVES:1)
Block(-12,8,-11,LEAVES:1)
Block(-12,9,-13,LEAVES:1)
Block(-12,9,-12,LEAVES:1)
Block(-12,13,2,LEAVES:1)
Block(-12,13,5,LEAVES:1)
Block(-12,14,3,LEAVES:1)
Block(-12,14,4,LOG:13)
Block(-12,14,5,LEAVES:1)
Block(-12,15,4,LEAVES:1)
Block(-11,8,-13,LEAVES:1)
Block(-11,9,-14,LEAVES:1)
Block(-11,9,-13,LEAVES:1)
Block(-11,9,-12,LOG:13)
Block(-11,9,-11,LEAVES:1)
Block(-11,9,-9,LEAVES:1)
Block(-11,10,-13,LEAVES:1)
Block(-11,10,-12,LEAVES:1)
Block(-11,10,-11,LEAVES:1)
Block(-11,10,-10,LEAVES:1)
Block(-11,13,3,LEAVES:1)
Block(-11,13,4,LEAVES:1)
Block(-11,13,6,LEAVES:1)
Block(-11,14,2,LEAVES:1)
Block(-11,14,3,LEAVES:1)
Block(-11,14,4,LOG:13)
Block(-11,14,5,LEAVES:1)
Block(-11,14,6,LEAVES:1)
Block(-11,15,3,LEAVES:1)
Block(-11,15,4,LEAVES:1)
Block(-11,15,5,LEAVES:1)
Block(-11,17,-6,LEAVES:1)
Block(-11,18,-7,LEAVES:1)
Block(-11,23,-2,LEAVES:1)
Block(-11,24,-1,LEAVES:1)
Block(-11,29,2,LEAVES:1)
Block(-11,30,1,LEAVES:1)
Block(-10,7,-12,LEAVES:1)
Block(-10,8,-14,LEAVES:1)
Block(-10,9,-13,LEAVES:1)
Block(-10,9,-12,LEAVES:1)
Block(-10,9,-10,LEAVES:1)
Block(-10,10,-12,LEAVES:1)
Block(-10,10,-11,LOG:13)
Block(-10,10,-10,LEAVES:1)
Block(-10,10,-9,LEAVES:1)
Block(-10,11,-11,LEAVES:1)
Block(-10,11,-10,LEAVES:1)
Block(-10,12,4,LEAVES:1)
Block(-10,14,1,LEAVES:1)
Block(-10,14,3,LEAVES:1)
Block(-10,14,4,LEAVES:1)
Block(-10,14,5,LEAVES:1)
Block(-10,15,1,LEAVES:1)
Block(-10,15,2,LEAVES:1)
Block(-10,15,3,LEAVES:1)
Block(-10,15,4,LOG:13)
Block(-10,15,5,LEAVES:1)
Block(-10,15,6,LEAVES:1)
Block(-10,16,-8,LEAVES:1)
Block(-10,16,2,LEAVES:1)
Block(-10,16,4,LEAVES:1)
Block(-10,16,5,LEAVES:1)
Block(-10,17,-7,LEAVES:1)
Block(-10,18,-8,LEAVES:1)
Block(-10,18,-7,LEAVES:1)
Block(-10,18,-6,LEAVES:1)
Block(-10,19,-7,LEAVES:1)
Block(-10,23,-1,LEAVES:1)
Block(-10,24,-2,LEAVES:1)
Block(-10,24,-1,LEAVES:1)
Block(-10,24,0,LEAVES:1)
Block(-10,29,0,LEAVES:1)
Block(-10,29,1,LEAVES:1)
Block(-10,30,0,LEAVES:1)
Block(-10,30,1,LEAVES:1)
Block(-10,30,2,LEAVES:1)
Block(-10,31,1,LEAVES:1)
Block(-9,8,-12,LEAVES:1)
Block(-9,9,-11,LEAVES:1)
Block(-9,9,-8,LEAVES:1)
Block(-9,10,-12,LEAVES:1)
Block(-9,10,-11,LEAVES:1)
Block(-9,10,-10,LOG:13)
Block(-9,10,-9,LEAVES:1)
Block(-9,11,-11,LEAVES:1)
Block(-9,11,-10,LEAVES:1)
Block(-9,11,-9,LEAVES:1)
Block(-9,11,-8,LEAVES:1)
Block(-9,13,1,LEAVES:1)
Block(-9,14,1,LEAVES:1)
Block(-9,14,2,LEAVES:1)
Block(-9,14,6,LEAVES:1)
Block(-9,15,0,LEAVES:1)
Block(-9,15,1,LEAVES:1)
Block(-9,15,2,LEAVES:1)
Block(-9,15,3,LOG:13)
Block(-9,15,4,LEAVES:1)
Block(-9,15,5,LEAVES:1)
Block(-9,16,-6,LEAVES:1)
Block(-9,16,1,LEAVES:1)
Block(-9,16,2,LEAVES:1)
Block(-9,16,3,LEAVES:1)
Block(-9,17,-5,LEAVES:1)
Block(-9,17,2,LEAVES:1)
Block(-9,18,-8,LEAVES:1)
Block(-9,18,-7,LOG:13)
Block(-9,18,-6,LEAVES:1)
Block(-9,19,-7,LEAVES:1)
Block(-9,19,-6,LEAVES:1)
Block(-9,19,-5,LEAVES:1)
Block(-9,23,-3,LEAVES:1)
Block(-9,23,1,LEAVES:1)
Block(-9,24,-2,LEAVES:1)
Block(-9,24,-1,LOG:13)
Block(-9,24,0,LEAVES:1)
Block(-9,25,-1,LEAVES:1)
Block(-9,29,3,LEAVES:1)
Block(-9,30,0,LEAVES:1)
Block(-9,30,1,LOG:13)
Block(-9,30,2,LEAVES:1)
Block(-9,31,1,LEAVES:1)
Block(-9,31,2,LEAVES:1)
Block(-9,31,3,LEAVES:1)
Block(-8,8,-11,LEAVES:1)
Block(-8,10,-11,LEAVES:1)
Block(-8,10,-10,LEAVES:1)
Block(-8,10,-9,LEAVES:1)
Block(-8,10,-8,LEAVES:1)
Block(-8,11,-10,LEAVES:1)
Block(-8,11,-9,LOG:13)
Block(-8,11,-8,LEAVES:1)
Block(-8,11,-7,LEAVES:1)
Block(-8,12,-9,LEAVES:1)
Block(-8,12,-8,LEAVES:1)
Block(-8,13,3,LEAVES:1)
Block(-8,13,5,LEAVES:1)
Block(-8,13,7,LEAVES:1)
Block(-8,14,0,LEAVES:1)
Block(-8,14,4,LEAVES:1)
Block(-8,14,6,LEAVES:1)
Block(-8,15,1,LEAVES:1)
Block(-8,15,2,LEAVES:1)
Block(-8,15,3,LEAVES:1)
Block(-8,16,0,LEAVES:1)
Block(-8,16,1,LEAVES:1)
Block(-8,16,2,LOG:13)
Block(-8,16,3,LEAVES:1)
Block(-8,16,4,LEAVES:1)
Block(-8,17,-8,LEAVES:1)
Block(-8,17,-4,LEAVES:1)
Block(-8,17,2,LEAVES:1)
Block(-8,17,3,LEAVES:1)
Block(-8,18,-7,LEAVES:1)
Block(-8,18,-5,LEAVES:1)
Block(-8,19,-7,LEAVES:1)
Block(-8,19,-6,LOG:13)
Block(-8,19,-5,LEAVES:1)
Block(-8,19,-4,LEAVES:1)
Block(-8,20,-6,LEAVES:1)
Block(-8,20,-5,LEAVES:1)
Block(-8,23,-1,LEAVES:1)
Block(-8,24,-3,LEAVES:1)
Block(-8,24,-2,LEAVES:1)
Block(-8,24,-1,LOG:13)
Block(-8,24,0,LEAVES:1)
Block(-8,24,1,LEAVES:1)
Block(-8,25,-3,LEAVES:1)
Block(-8,25,-2,LEAVES:1)
Block(-8,25,-1,LEAVES:1)
Block(-8,26,-2,LEAVES:1)
Block(-8,29,1,LEAVES:1)
Block(-8,30,1,LEAVES:1)
Block(-8,30,2,LEAVES:1)
Block(-8,30,3,LEAVES:1)
Block(-8,30,4,LEAVES:1)
Block(-8,31,1,LEAVES:1)
Block(-8,31,2,LOG:13)
Block(-8,31,3,LEAVES:1)
Block(-8,31,4,LEAVES:1)
Block(-8,32,2,LEAVES:1)
Block(-8,32,3,LEAVES:1)
Block(-7,9,-10,LEAVES:1)
Block(-7,10,-10,LEAVES:1)
Block(-7,10,-6,LEAVES:1)
Block(-7,11,-9,LEAVES:1)
Block(-7,11,-8,LOG:13)
Block(-7,11,-7,LEAVES:1)
Block(-7,12,-8,LEAVES:1)
Block(-7,12,-7,LEAVES:1)
Block(-7,12,-6,LEAVES:1)
Block(-7,12,6,LEAVES:1)
Block(-7,13,6,LEAVES:1)
Block(-7,14,-1,LEAVES:1)
Block(-7,14,3,LEAVES:1)
Block(-7,14,5,LEAVES:1)
Block(-7,14,6,LEAVES:1)
Block(-7,14,7,LEAVES:1)
Block(-7,15,0,LEAVES:1)
Block(-7,15,4,LEAVES:1)
Block(-7,15,5,LEAVES:1)
Block(-7,16,-1,LEAVES:1)
Block(-7,16,0,LEAVES:1)
Block(-7,16,1,LOG:13)
Block(-7,16,2,LEAVES:1)
Block(-7,16,3,LEAVES:1)
Block(-7,17,0,LEAVES:1)
Block(-7,17,1,LEAVES:1)
Block(-7,18,-6,LEAVES:1)
Block(-7,18,-3,LEAVES:1)
Block(-7,19,-7,LEAVES:1)
Block(-7,19,-6,LEAVES:1)
Block(-7,19,-5,LOG:13)
Block(-7,19,-4,LEAVES:1)
Block(-7,19,-3,LEAVES:1)
Block(-7,19,-1,LEAVES:1)
Block(-7,20,-6,LEAVES:1)
Block(-7,20,-5,LEAVES:1)
Block(-7,20,-4,LEAVES:1)
Block(-7,20,-2,LEAVES:1)
Block(-7,23,-4,LEAVES:1)
Block(-7,24,-3,LEAVES:1)
Block(-7,24,-1,LEAVES:1)
Block(-7,25,-2,LEAVES:1)
Block(-7,25,-1,LOG:13)
Block(-7,25,0,LEAVES:1)
Block(-7,25,1,LEAVES:1)
Block(-7,25,2,LEAVES:1)
Block(-7,26,-1,LEAVES:1)
Block(-7,29,4,LEAVES:1)
Block(-7,30,0,LEAVES:1)
Block(-7,31,1,LEAVES:1)
Block(-7,31,2,LOG:13)
Block(-7,31,3,LEAVES:1)
Block(-7,32,1,LEAVES:1)
Block(-7,32,2,LEAVES:1)
Block(-7,34,-5,LEAVES:1)
Block(-7,35,4,LEAVES:1)
Block(-7,35,7,LEAVES:1)
Block(-7,36,5,LEAVES:1)
Block(-7,36,6,LEAVES:1)
Block(-6,9,-8,LEAVES:1)
Block(-6,10,-9,LEAVES:1)
Block(-6,10,-8,LEAVES:1)
Block(-6,11,-10,LEAVES:1)
Block(-6,11,-9,LEAVES:1)
Block(-6,11,-8,LEAVES:1)
Block(-6,11,-6,LEAVES:1)
Block(-6,11,-5,LEAVES:1)
Block(-6,12,-9,LEAVES:1)
Block(-6,12,-8,LEAVES:1)
Block(-6,12,-7,LOG:13)
Block(-6,12,-6,LEAVES:1)
Block(-6,12,-5,LEAVES:1)
Block(-6,12,8,LEAVES:1)
Block(-6,13,-8,LEAVES:1)
Block(-6,13,-7,LEAVES:1)
Block(-6,13,-6,LEAVES:1)
Block(-6,13,5,LEAVES:1)
Block(-6,13,7,LEAVES:1)
Block(-6,14,5,LEAVES:1)
Block(-6,14,6,LOG:13)
Block(-6,14,7,LEAVES:1)
Block(-6,14,8,LEAVES:1)
Block(-6,15,-1,LEAVES:1)
Block(-6,15,1,LEAVES:1)
Block(-6,15,3,LEAVES:1)
Block(-6,15,4,LOG:13)
Block(-6,15,5,LOG:13)
Block(-6,15,6,LEAVES:1)
Block(-6,16,0,LEAVES:1)
Block(-6,16,1,LOG:13)
Block(-6,16,2,LEAVES:1)
Block(-6,16,3,LEAVES:1)
Block(-6,16,4,LEAVES:1)
Block(-6,16,5,LEAVES:1)
Block(-6,17,1,LEAVES:1)
Block(-6,17,2,LEAVES:1)
Block(-6,18,-7,LEAVES:1)
Block(-6,19,-6,LEAVES:1)
Block(-6,19,-5,LEAVES:1)
Block(-6,19,-4,LEAVES:1)
Block(-6,19,-2,LEAVES:1)
Block(-6,20,-5,LEAVES:1)
Block(-6,20,-4,LOG:13)
Block(-6,20,-3,LEAVES:1)
Block(-6,20,-2,LEAVES:1)
Block(-6,20,-1,LEAVES:1)
Block(-6,21,-4,LEAVES:1)
Block(-6,21,-2,LEAVES:1)
Block(-6,24,-1,LEAVES:1)
Block(-6,24,2,LEAVES:1)
Block(-6,25,-2,LEAVES:1)
Block(-6,25,-1,LEAVES:1)
Block(-6,25,0,LOG:13)
Block(-6,25,1,LEAVES:1)
Block(-6,25,2,LEAVES:1)
Block(-6,25,3,LEAVES:1)
Block(-6,26,-1,LEAVES:1)
Block(-6,26,0,LEAVES:1)
Block(-6,26,1,LEAVES:1)
Block(-6,26,2,LEAVES:1)
Block(-6,30,2,LEAVES:1)
Block(-6,30,4,LEAVES:1)
Block(-6,30,6,LEAVES:1)
Block(-6,31,1,LEAVES:1)
Block(-6,31,2,LEAVES:1)
Block(-6,31,4,LEAVES:1)
Block(-6,31,5,LEAVES:1)
Block(-6,32,0,LEAVES:1)
Block(-6,32,1,LEAVES:1)
Block(-6,32,2,LOG:13)
Block(-6,32,3,LEAVES:1)
Block(-6,33,1,LEAVES:1)
Block(-6,33,2,LEAVES:1)
Block(-6,34,-6,LEAVES:1)
Block(-6,34,-3,LEAVES:1)
Block(-6,35,-4,LEAVES:1)
Block(-6,35,5,LEAVES:1)
Block(-6,36,4,LEAVES:1)
Block(-6,36,5,LOG:13)
Block(-6,36,6,LEAVES:1)
Block(-6,36,7,LEAVES:1)
Block(-6,37,4,LEAVES:1)
Block(-6,37,5,LEAVES:1)
Block(-6,37,6,LEAVES:1)
Block(-6,40,-2,LEAVES:1)
Block(-6,40,0,LEAVES:1)
Block(-6,41,-1,LEAVES:1)
Block(-5,8,-10,LEAVES:1)
Block(-5,10,-10,LEAVES:1)
Block(-5,11,-9,LEAVES:1)
Block(-5,11,-8,LEAVES:1)
Block(-5,11,-6,LEAVES:1)
Block(-5,11,-4,LEAVES:1)
Block(-5,12,-8,LEAVES:1)
Block(-5,12,-7,LEAVES:1)
Block(-5,12,-6,LOG:13)
Block(-5,12,-5,LEAVES:1)
Block(-5,13,-6,LEAVES:1)
Block(-5,13,-5,LEAVES:1)
Block(-5,13,-4,LEAVES:1)
Block(-5,13,6,LEAVES:1)
Block(-5,13,8,LEAVES:1)
Block(-5,14,-7,LEAVES:1)
Block(-5,14,4,LEAVES:1)
Block(-5,14,6,LEAVES:1)
Block(-5,14,7,LEAVES:1)
Block(-5,15,-2,LEAVES:1)
Block(-5,15,2,LEAVES:1)
Block(-5,15,4,LEAVES:1)
Block(-5,15,5,LEAVES:1)
Block(-5,16,-1,LEAVES:1)
Block(-5,16,1,LEAVES:1)
Block(-5,16,2,LOG:13)
Block(-5,16,3,LOG:13)
Block(-5,16,4,LEAVES:1)
Block(-5,16,5,LEAVES:1)
Block(-5,17,-2,LEAVES:1)
Block(-5,17,-1,LEAVES:1)
Block(-5,17,0,LEAVES:1)
Block(-5,17,1,LOG:13)
Block(-5,17,2,LEAVES:1)
Block(-5,17,3,LEAVES:1)
Block(-5,17,4,LEAVES:1)
Block(-5,18,-5,LEAVES:1)
Block(-5,18,-2,LEAVES:1)
Block(-5,18,-1,LEAVES:1)
Block(-5,18,1,LEAVES:1)
Block(-5,19,-4,LEAVES:1)
Block(-5,19,-2,LEAVES:1)
Block(-5,19,0,LEAVES:1)
Block(-5,20,-5,LEAVES:1)
Block(-5,20,-4,LEAVES:1)
Block(-5,20,-3,LOG:13)
Block(-5,20,-2,LEAVES:1)
Block(-5,20,-1,LEAVES:1)
Block(-5,21,-4,LEAVES:1)
Block(-5,21,-3,LEAVES:1)
Block(-5,21,-2,LEAVES:1)
Block(-5,21,-1,LEAVES:1)
Block(-5,22,-2,LEAVES:1)
Block(-5,24,-3,LEAVES:1)
Block(-5,24,1,LEAVES:1)
Block(-5,24,3,LEAVES:1)
Block(-5,25,-1,LEAVES:1)
Block(-5,25,1,LEAVES:1)
Block(-5,25,2,LEAVES:1)
Block(-5,26,-1,LEAVES:1)
Block(-5,26,0,LOG:13)
Block(-5,26,1,LEAVES:1)
Block(-5,26,8,LEAVES:1)
Block(-5,26,10,LEAVES:1)
Block(-5,27,0,LEAVES:1)
Block(-5,27,6,LEAVES:1)
Block(-5,27,9,LEAVES:1)
Block(-5,28,7,LEAVES:1)
Block(-5,30,5,LEAVES:1)
Block(-5,31,0,LEAVES:1)
Block(-5,31,3,LEAVES:1)
Block(-5,31,4,LOG:13)
Block(-5,31,5,LEAVES:1)
Block(-5,31,6,LEAVES:1)
Block(-5,32,1,LEAVES:1)
Block(-5,32,2,LEAVES:1)
Block(-5,32,3,LOG:13)
Block(-5,32,4,LEAVES:1)
Block(-5,32,5,LEAVES:1)
Block(-5,33,2,LEAVES:1)
Block(-5,33,3,LEAVES:1)
Block(-5,34,-4,LEAVES:1)
Block(-5,34,-2,LEAVES:1)
Block(-5,34,3,LEAVES:1)
Block(-5,34,6,LEAVES:1)
Block(-5,35,-5,LEAVES:1)
Block(-5,35,-4,LOG:13)
Block(-5,35,-3,LEAVES:1)
Block(-5,35,4,LEAVES:1)
Block(-5,36,-4,LEAVES:1)
Block(-5,36,1,LEAVES:1)
Block(-5,36,3,LEAVES:1)
Block(-5,36,4,LOG:13)
Block(-5,36,5,LEAVES:1)
Block(-5,36,6,LEAVES:1)
Block(-5,37,3,LEAVES:1)
Block(-5,37,4,LEAVES:1)
Block(-5,37,5,LEAVES:1)
Block(-5,38,4,LEAVES:1)
Block(-5,40,-3,LEAVES:1)
Block(-5,40,-1,LEAVES:1)
Block(-5,41,-2,LEAVES:1)
Block(-5,41,-1,LOG:13)
Block(-5,41,0,LEAVES:1)
Block(-5,42,-1,LEAVES:1)
Block(-5,45,2,LEAVES:1)
Block(-4,-6,1,LOG:1)
Block(-4,-5,1,LOG:13)
Block(-4,-4,1,LOG:13)
Block(-4,-3,1,LOG:1)
Block(-4,9,-11,LEAVES:1)
Block(-4,9,-9,LEAVES:1)
Block(-4,10,-10,LEAVES:1)
Block(-4,10,-8,LEAVES:1)
Block(-4,11,-9,LEAVES:1)
Block(-4,11,-8,LOG:13)
Block(-4,11,-6,LEAVES:1)
Block(-4,12,-8,LEAVES:1)
Block(-4,12,-7,LOG:13)
Block(-4,12,-6,LEAVES:1)
Block(-4,12,-5,LEAVES:1)
Block(-4,12,-4,LEAVES:1)
Block(-4,13,-7,LEAVES:1)
Block(-4,13,-6,LEAVES:1)
Block(-4,13,-5,LOG:13)
Block(-4,13,-4,LEAVES:1)
Block(-4,13,-3,LEAVES:1)
Block(-4,14,-6,LEAVES:1)
Block(-4,14,-5,LEAVES:1)
Block(-4,14,-4,LEAVES:1)
Block(-4,14,5,LEAVES:1)
Block(-4,15,-10,LEAVES:1)
Block(-4,15,-9,LEAVES:1)
Block(-4,15,-8,LEAVES:1)
Block(-4,15,-6,LEAVES:1)
Block(-4,15,3,LEAVES:1)
Block(-4,15,4,LEAVES:1)
Block(-4,15,5,LEAVES:1)
Block(-4,16,-7,LEAVES:1)
Block(-4,16,-4,LEAVES:1)
Block(-4,16,-2,LEAVES:1)
Block(-4,16,-1,LEAVES:1)
Block(-4,16,1,LEAVES:1)
Block(-4,16,2,LEAVES:1)
Block(-4,16,3,LEAVES:1)
Block(-4,16,4,LEAVES:1)
Block(-4,17,-3,LEAVES:1)
Block(-4,17,-2,LEAVES:1)
Block(-4,17,-1,LEAVES:1)
Block(-4,17,0,LOG:13)
Block(-4,17,1,LEAVES:1)
Block(-4,17,2,LEAVES:1)
Block(-4,18,-2,LEAVES:1)
Block(-4,18,-1,LEAVES:1)
Block(-4,18,0,LEAVES:1)
Block(-4,18,1,LEAVES:1)
Block(-4,19,-1,LEAVES:1)
Block(-4,20,-4,LEAVES:1)
Block(-4,20,-3,LEAVES:1)
Block(-4,20,1,LEAVES:1)
Block(-4,21,-3,LEAVES:1)
Block(-4,21,-2,LOG:13)
Block(-4,21,-1,LEAVES:1)
Block(-4,21,0,LEAVES:1)
Block(-4,22,-2,LEAVES:1)
Block(-4,22,0,LEAVES:1)
Block(-4,25,-2,LEAVES:1)
Block(-4,25,0,LEAVES:1)
Block(-4,25,1,LEAVES:1)
Block(-4,26,-4,LEAVES:1)
Block(-4,26,-1,LEAVES:1)
Block(-4,26,0,LOG:13)
Block(-4,26,1,LEAVES:1)
Block(-4,26,2,LEAVES:1)
Block(-4,27,-2,LEAVES:1)
Block(-4,27,-1,LEAVES:1)
Block(-4,27,0,LEAVES:1)
Block(-4,27,1,LEAVES:1)
Block(-4,27,8,LEAVES:1)
Block(-4,27,9,LOG:13)
Block(-4,27,10,LEAVES:1)
Block(-4,28,-2,LEAVES:1)
Block(-4,28,0,LEAVES:1)
Block(-4,28,6,LEAVES:1)
Block(-4,28,7,LEAVES:1)
Block(-4,28,8,LEAVES:1)
Block(-4,28,9,LEAVES:1)
Block(-4,29,5,LEAVES:1)
Block(-4,29,7,LEAVES:1)
Block(-4,30,3,LEAVES:1)
Block(-4,31,4,LEAVES:1)
Block(-4,31,5,LEAVES:1)
Block(-4,32,2,LEAVES:1)
Block(-4,32,3,LEAVES:1)
Block(-4,33,1,LEAVES:1)
Block(-4,33,2,LEAVES:1)
Block(-4,33,3,LOG:13)
Block(-4,33,4,LEAVES:1)
Block(-4,34,-5,LEAVES:1)
Block(-4,34,-3,LEAVES:1)
Block(-4,34,2,LEAVES:1)
Block(-4,34,3,LEAVES:1)
Block(-4,35,-4,LEAVES:1)
Block(-4,35,-3,LOG:13)
Block(-4,35,-2,LEAVES:1)
Block(-4,35,-1,LEAVES:1)
Block(-4,35,5,LEAVES:1)
Block(-4,36,-3,LEAVES:1)
Block(-4,36,-2,LEAVES:1)
Block(-4,36,0,LEAVES:1)
Block(-4,36,3,LEAVES:1)
Block(-4,36,4,LEAVES:1)
Block(-4,37,2,LEAVES:1)
Block(-4,37,3,LOG:13)
Block(-4,37,4,LEAVES:1)
Block(-4,38,2,LEAVES:1)
Block(-4,38,3,LEAVES:1)
Block(-4,40,1,LEAVES:1)
Block(-4,41,-2,LEAVES:1)
Block(-4,41,-1,LOG:13)
Block(-4,41,0,LEAVES:1)
Block(-4,41,1,LEAVES:1)
Block(-4,42,-1,LEAVES:1)
Block(-4,42,0,LEAVES:1)
Block(-4,43,-2,LEAVES:1)
Block(-4,45,1,LEAVES:1)
Block(-4,45,3,LEAVES:1)
Block(-4,46,2,LEAVES:1)
Block(-4,51,0,LEAVES:1)
Block(-3,-6,-3,LOG:1)
Block(-3,-6,0,LOG:1)
Block(-3,-5,-3,LOG:13)
Block(-3,-5,0,LOG:13)
Block(-3,-4,-3,LOG:13)
Block(-3,-4,0,LOG:13)
Block(-3,-3,0,LOG:13)
Block(-3,-2,0,LOG:13)
Block(-3,-1,0,LOG:1)
Block(-3,8,-10,LEAVES:1)
Block(-3,9,-10,LEAVES:1)
Block(-3,10,-11,LEAVES:1)
Block(-3,10,-10,LEAVES:1)
Block(-3,10,-9,LOG:13)
Block(-3,10,-8,LEAVES:1)
Block(-3,10,-6,LEAVES:1)
Block(-3,11,-10,LEAVES:1)
Block(-3,11,-9,LEAVES:1)
Block(-3,11,-8,LEAVES:1)
Block(-3,11,-7,LEAVES:1)
Block(-3,11,-5,LEAVES:1)
Block(-3,11,-3,LEAVES:1)
Block(-3,12,-8,LEAVES:1)
Block(-3,12,-7,LEAVES:1)
Block(-3,12,-6,LEAVES:1)
Block(-3,12,-4,LEAVES:1)
Block(-3,13,-6,LEAVES:1)
Block(-3,13,-5,LEAVES:1)
Block(-3,13,-4,LOG:13)
Block(-3,13,-3,LEAVES:1)
Block(-3,14,-10,LEAVES:1)
Block(-3,14,-9,LEAVES:1)
Block(-3,14,-4,LEAVES:1)
Block(-3,14,-3,LEAVES:1)
Block(-3,14,3,LEAVES:1)
Block(-3,15,-11,LEAVES:1)
Block(-3,15,-10,LEAVES:1)
Block(-3,15,-9,LOG:13)
Block(-3,15,-7,LEAVES:1)
Block(-3,15,-5,LEAVES:1)
Block(-3,15,-1,LEAVES:1)
Block(-3,15,4,LEAVES:1)
Block(-3,16,-10,LEAVES:1)
Block(-3,16,-9,LEAVES:1)
Block(-3,16,-8,LEAVES:1)
Block(-3,16,-7,LEAVES:1)
Block(-3,16,-6,LEAVES:1)
Block(-3,16,-3,LEAVES:1)
Block(-3,16,2,LEAVES:1)
Block(-3,17,-7,LEAVES:1)
Block(-3,17,-2,LEAVES:1)
Block(-3,17,-1,LEAVES:1)
Block(-3,17,0,LEAVES:1)
Block(-3,17,1,LEAVES:1)
Block(-3,18,-2,LEAVES:1)
Block(-3,18,-1,LOG:13)
Block(-3,18,0,LEAVES:1)
Block(-3,19,-3,LEAVES:1)
Block(-3,19,-1,LEAVES:1)
Block(-3,19,1,LEAVES:1)
Block(-3,20,-2,LEAVES:1)
Block(-3,20,-1,LEAVES:1)
Block(-3,20,0,LEAVES:1)
Block(-3,21,-3,LEAVES:1)
Block(-3,21,-2,LEAVES:1)
Block(-3,21,-1,LOG:13)
Block(-3,21,0,LEAVES:1)
Block(-3,21,1,LEAVES:1)
Block(-3,22,-2,LEAVES:1)
Block(-3,22,-1,LEAVES:1)
Block(-3,22,0,LEAVES:1)
Block(-3,22,1,LEAVES:1)
Block(-3,23,0,LEAVES:1)
Block(-3,25,2,LEAVES:1)
Block(-3,25,10,LEAVES:1)
Block(-3,26,-10,LEAVES:1)
Block(-3,26,-8,LEAVES:1)
Block(-3,26,-1,LEAVES:1)
Block(-3,26,1,LEAVES:1)
Block(-3,26,9,LEAVES:1)
Block(-3,27,-9,LEAVES:1)
Block(-3,27,-7,LEAVES:1)
Block(-3,27,-3,LEAVES:1)
Block(-3,27,-2,LEAVES:1)
Block(-3,27,-1,LEAVES:1)
Block(-3,27,0,LOG:13)
Block(-3,27,1,LEAVES:1)
Block(-3,27,4,LEAVES:1)
Block(-3,27,9,LEAVES:1)
Block(-3,27,10,LEAVES:1)
Block(-3,28,-6,LEAVES:1)
Block(-3,28,-2,LEAVES:1)
Block(-3,28,-1,LEAVES:1)
Block(-3,28,0,LEAVES:1)
Block(-3,28,5,LEAVES:1)
Block(-3,28,6,LEAVES:1)
Block(-3,28,7,LOG:13)
Block(-3,28,8,LOG:13)
Block(-3,28,9,LEAVES:1)
Block(-3,28,10,LEAVES:1)
Block(-3,29,-1,LEAVES:1)
Block(-3,29,4,LEAVES:1)
Block(-3,29,5,LEAVES:1)
Block(-3,29,6,LEAVES:1)
Block(-3,29,7,LEAVES:1)
Block(-3,29,8,LEAVES:1)
Block(-3,29,9,LEAVES:1)
Block(-3,30,5,LEAVES:1)
Block(-3,32,0,LEAVES:1)
Block(-3,32,3,LEAVES:1)
Block(-3,33,1,LEAVES:1)
Block(-3,33,2,LOG:13)
Block(-3,33,3,LEAVES:1)
Block(-3,33,4,LEAVES:1)
Block(-3,34,-4,LEAVES:1)
Block(-3,34,0,LEAVES:1)
Block(-3,34,1,LEAVES:1)
Block(-3,34,2,LEAVES:1)
Block(-3,34,3,LEAVES:1)
Block(-3,35,-3,LEAVES:1)
Block(-3,35,-2,LEAVES:1)
Block(-3,35,0,LEAVES:1)
Block(-3,35,3,LEAVES:1)
Block(-3,36,-3,LEAVES:1)
Block(-3,36,-2,LOG:13)
Block(-3,36,-1,LEAVES:1)
Block(-3,36,1,LEAVES:1)
Block(-3,37,-2,LEAVES:1)
Block(-3,37,0,LEAVES:1)
Block(-3,37,3,LEAVES:1)
Block(-3,38,1,LEAVES:1)
Block(-3,38,2,LOG:13)
Block(-3,38,3,LEAVES:1)
Block(-3,39,2,LEAVES:1)
Block(-3,40,-2,LEAVES:1)
Block(-3,41,-1,LEAVES:1)
Block(-3,41,0,LEAVES:1)
Block(-3,42,-4,LEAVES:1)
Block(-3,42,-1,LEAVES:1)
Block(-3,42,0,LOG:13)
Block(-3,42,1,LEAVES:1)
Block(-3,43,-3,LEAVES:1)
Block(-3,43,0,LEAVES:1)
Block(-3,44,-2,LEAVES:1)
Block(-3,45,2,LEAVES:1)
Block(-3,45,4,LEAVES:1)
Block(-3,46,0,LEAVES:1)
Block(-3,46,1,LEAVES:1)
Block(-3,46,2,LOG:13)
Block(-3,46,3,LEAVES:1)
Block(-3,47,1,LEAVES:1)
Block(-3,47,2,LEAVES:1)
Block(-3,49,-1,LEAVES:1)
Block(-3,50,0,LEAVES:1)
Block(-3,51,-1,LEAVES:1)
Block(-3,51,0,LEAVES:1)
Block(-3,51,1,LEAVES:1)
Block(-3,52,0,LEAVES:1)
Block(-3,53,0,LEAVES:1)
Block(-2,-6,-4,LOG:1)
Block(-2,-6,-2,LOG:1)
Block(-2,-6,-1,LOG:1)
Block(-2,-6,1,LOG:1)
Block(-2,-5,-4,LOG:13)
Block(-2,-5,-3,LOG:13)
Block(-2,-5,-2,LOG:13)
Block(-2,-5,-1,LOG:13)
Block(-2,-5,0,LOG:13)
Block(-2,-5,1,LOG:13)
Block(-2,-4,-4,LOG:13)
Block(-2,-4,-3,LOG:13)
Block(-2,-4,-2,LOG:13)
Block(-2,-4,-1,LOG:13)
Block(-2,-4,0,LOG:13)
Block(-2,-4,1,LOG:13)
Block(-2,-3,-4,LOG:1)
Block(-2,-3,-3,LOG:13)
Block(-2,-3,-2,LOG:13)
Block(-2,-3,-1,LOG:13)
Block(-2,-3,0,LOG:13)
Block(-2,-2,-2,LOG:13)
Block(-2,-2,-1,LOG:13)
Block(-2,-2,0,LOG:13)
Block(-2,-1,-2,LOG:13)
Block(-2,-1,-1,LOG:13)
Block(-2,-1,0,LOG:13)
Block(-2,0,-2,LOG:13)
Block(-2,0,-1,LOG:13)
Block(-2,0,0,LOG:13)
Block(-2,1,-1,LOG:13)
Block(-2,1,0,LOG:13)
Block(-2,2,-1,LOG:13)
Block(-2,2,0,LOG:13)
Block(-2,3,-1,LOG:13)
Block(-2,3,0,LOG:13)
Block(-2,4,-1,LOG:13)
Block(-2,4,0,LOG:13)
Block(-2,5,-1,LOG:13)
Block(-2,5,0,LOG:13)
Block(-2,6,-1,LOG:13)
Block(-2,6,0,LOG:13)
Block(-2,7,-1,LOG:13)
Block(-2,7,0,LOG:13)
Block(-2,8,-1,LOG:13)
Block(-2,8,0,LOG:13)
Block(-2,9,-11,LEAVES:1)
Block(-2,9,-8,LEAVES:1)
Block(-2,9,-1,LOG:13)
Block(-2,9,0,LOG:13)
Block(-2,10,-11,LEAVES:1)
Block(-2,10,-10,LOG:13)
Block(-2,10,-9,LEAVES:1)
Block(-2,10,-7,LEAVES:1)
Block(-2,10,0,LOG:13)
Block(-2,11,-10,LEAVES:1)
Block(-2,11,-8,LEAVES:1)
Block(-2,11,0,LOG:13)
Block(-2,12,-4,LEAVES:1)
Block(-2,12,-3,LEAVES:1)
Block(-2,12,0,LOG:13)
Block(-2,13,-5,LEAVES:1)
Block(-2,13,-4,LEAVES:1)
Block(-2,13,-3,LEAVES:1)
Block(-2,13,0,LOG:13)
Block(-2,14,-5,LEAVES:1)
Block(-2,14,-4,LEAVES:1)
Block(-2,14,-3,LOG:13)
Block(-2,14,-2,LEAVES:1)
Block(-2,14,0,LOG:13)
Block(-2,15,-10,LEAVES:1)
Block(-2,15,-9,LEAVES:1)
Block(-2,15,-4,LEAVES:1)
Block(-2,15,-3,LEAVES:1)
Block(-2,16,-9,LEAVES:1)
Block(-2,16,-8,LOG:13)
Block(-2,16,-7,LOG:13)
Block(-2,16,-5,LEAVES:1)
Block(-2,16,-3,LEAVES:1)
Block(-2,16,-2,LEAVES:1)
Block(-2,17,-8,LEAVES:1)
Block(-2,17,-7,LEAVES:1)
Block(-2,17,-6,LEAVES:1)
Block(-2,17,-4,LEAVES:1)
Block(-2,17,0,LEAVES:1)
Block(-2,18,-1,LOG:13)
Block(-2,18,0,LEAVES:1)
Block(-2,19,-1,LEAVES:1)
Block(-2,20,-2,LEAVES:1)
Block(-2,20,1,LEAVES:1)
Block(-2,21,-2,LEAVES:1)
Block(-2,21,-1,LEAVES:1)
Block(-2,21,0,LEAVES:1)
Block(-2,21,3,LEAVES:1)
Block(-2,22,-1,LEAVES:1)
Block(-2,22,0,LOG:13)
Block(-2,22,1,LEAVES:1)
Block(-2,22,2,LEAVES:1)
Block(-2,22,3,LEAVES:1)
Block(-2,23,0,LEAVES:1)
Block(-2,23,2,LEAVES:1)
Block(-2,25,-11,LEAVES:1)
Block(-2,26,-11,LEAVES:1)
Block(-2,26,-6,LEAVES:1)
Block(-2,27,-10,LEAVES:1)
Block(-2,27,-9,LEAVES:1)
Block(-2,27,-8,LEAVES:1)
Block(-2,27,-6,LEAVES:1)
Block(-2,27,-4,LEAVES:1)
Block(-2,27,-2,LEAVES:1)
Block(-2,27,-1,LEAVES:1)
Block(-2,27,0,LOG:13)
Block(-2,27,1,LEAVES:1)
Block(-2,27,9,LEAVES:1)
Block(-2,27,10,LEAVES:1)
Block(-2,28,-9,LEAVES:1)
Block(-2,28,-8,LEAVES:1)
Block(-2,28,-7,LEAVES:1)
Block(-2,28,-6,LEAVES:1)
Block(-2,28,-5,LEAVES:1)
Block(-2,28,-3,LEAVES:1)
Block(-2,28,0,LEAVES:1)
Block(-2,28,7,LEAVES:1)
Block(-2,28,8,LEAVES:1)
Block(-2,28,9,LEAVES:1)
Block(-2,29,-6,LEAVES:1)
Block(-2,29,-5,LEAVES:1)
Block(-2,29,-4,LEAVES:1)
Block(-2,29,-1,LEAVES:1)
Block(-2,29,4,LEAVES:1)
Block(-2,29,5,LOG:13)
Block(-2,29,6,LOG:13)
Block(-2,29,7,LEAVES:1)
Block(-2,30,-2,LEAVES:1)
Block(-2,30,2,LEAVES:1)
Block(-2,30,4,LEAVES:1)
Block(-2,30,5,LEAVES:1)
Block(-2,30,6,LEAVES:1)
Block(-2,31,1,LEAVES:1)
Block(-2,32,4,LEAVES:1)
Block(-2,33,0,LEAVES:1)
Block(-2,33,2,LEAVES:1)
Block(-2,33,3,LEAVES:1)
Block(-2,33,4,LEAVES:1)
Block(-2,34,-2,LEAVES:1)
Block(-2,34,-1,LEAVES:1)
Block(-2,34,0,LEAVES:1)
Block(-2,34,1,LOG:13)
Block(-2,34,2,LEAVES:1)
Block(-2,35,-1,LEAVES:1)
Block(-2,35,1,LEAVES:1)
Block(-2,36,-4,LEAVES:1)
Block(-2,36,-2,LEAVES:1)
Block(-2,36,-1,LOG:13)
Block(-2,36,0,LEAVES:1)
Block(-2,36,2,LEAVES:1)
Block(-2,37,-3,LEAVES:1)
Block(-2,37,-1,LEAVES:1)
Block(-2,37,1,LEAVES:1)
Block(-2,38,0,LEAVES:1)
Block(-2,38,1,LOG:13)
Block(-2,38,2,LEAVES:1)
Block(-2,39,1,LEAVES:1)
Block(-2,40,1,LEAVES:1)
Block(-2,41,0,LEAVES:1)
Block(-2,41,2,LEAVES:1)
Block(-2,42,-5,LEAVES:1)
Block(-2,42,-3,LEAVES:1)
Block(-2,42,-1,LEAVES:1)
Block(-2,42,0,LOG:13)
Block(-2,42,1,LEAVES:1)
Block(-2,43,-4,LEAVES:1)
Block(-2,43,-3,LOG:13)
Block(-2,43,-2,LEAVES:1)
Block(-2,43,0,LEAVES:1)
Block(-2,44,-3,LEAVES:1)
Block(-2,44,-2,LOG:13)
Block(-2,44,-1,LEAVES:1)
Block(-2,44,0,LEAVES:1)
Block(-2,45,-2,LEAVES:1)
Block(-2,45,0,LEAVES:1)
Block(-2,45,3,LEAVES:1)
Block(-2,46,-1,LEAVES:1)
Block(-2,46,1,LEAVES:1)
Block(-2,46,2,LEAVES:1)
Block(-2,47,0,LEAVES:1)
Block(-2,47,1,LOG:13)
Block(-2,47,2,LEAVES:1)
Block(-2,48,-1,LEAVES:1)
Block(-2,48,1,LEAVES:1)
Block(-2,50,0,LEAVES:1)
Block(-2,51,-1,LEAVES:1)
Block(-2,51,0,LOG:13)
Block(-2,51,1,LEAVES:1)
Block(-2,52,0,LEAVES:1)
Block(-2,53,-1,LEAVES:1)
Block(-2,53,1,LEAVES:1)
Block(-2,54,0,LEAVES:1)
Block(-2,55,0,LEAVES:1)
Block(-2,56,0,LEAVES:1)
Block(-2,58,0,LEAVES:1)
Block(-1,-6,-3,LOG:1)
Block(-1,-6,2,LOG:1)
Block(-1,-6,3,LOG:1)
Block(-1,-6,4,LOG:1)
Block(-1,-5,-3,LOG:13)
Block(-1,-5,-2,LOG:13)
Block(-1,-5,-1,LOG:13)
Block(-1,-5,0,LOG:13)
Block(-1,-5,1,LOG:13)
Block(-1,-5,3,LOG:13)
Block(-1,-5,4,LOG:1)
Block(-1,-4,-3,LOG:13)
Block(-1,-4,-2,LOG:13)
Block(-1,-4,-1,LOG:13)
Block(-1,-4,0,LOG:13)
Block(-1,-4,1,LOG:13)
Block(-1,-4,3,LOG:13)
Block(-1,-3,-3,LOG:13)
Block(-1,-3,-2,LOG:13)
Block(-1,-3,-1,LOG:13)
Block(-1,-3,0,LOG:13)
Block(-1,-3,1,LOG:13)
Block(-1,-2,-3,LOG:13)
Block(-1,-2,-2,LOG:13)
Block(-1,-2,-1,LOG:13)
Block(-1,-2,0,LOG:13)
Block(-1,-2,1,LOG:13)
Block(-1,-1,-3,LOG:1)
Block(-1,-1,-2,LOG:13)
Block(-1,-1,-1,LOG:13)
Block(-1,-1,0,LOG:13)
Block(-1,-1,1,LOG:13)
Block(-1,0,-2,LOG:13)
Block(-1,0,-1,LOG:13)
Block(-1,0,0,LOG:13)
Block(-1,1,-2,LOG:13)
Block(-1,1,-1,LOG:13)
Block(-1,1,0,LOG:13)
Block(-1,2,-2,LOG:13)
Block(-1,2,-1,LOG:13)
Block(-1,2,0,LOG:13)
Block(-1,3,-2,LOG:13)
Block(-1,3,-1,LOG:13)
Block(-1,3,0,LOG:13)
Block(-1,4,-2,LOG:13)
Block(-1,4,-1,LOG:13)
Block(-1,4,0,LOG:13)
Block(-1,5,-2,LOG:13)
Block(-1,5,-1,LOG:13)
Block(-1,5,0,LOG:13)
Block(-1,6,-2,LOG:13)
Block(-1,6,-1,LOG:13)
Block(-1,6,0,LOG:13)
Block(-1,7,-2,LOG:13)
Block(-1,7,-1,LOG:13)
Block(-1,7,0,LOG:13)
Block(-1,8,-12,LEAVES:1)
Block(-1,8,-8,LEAVES:1)
Block(-1,8,-2,LOG:13)
Block(-1,8,-1,LOG:13)
Block(-1,8,0,LOG:13)
Block(-1,9,-10,LEAVES:1)
Block(-1,9,-9,LEAVES:1)
Block(-1,9,-2,LOG:13)
Block(-1,9,-1,LOG:13)
Block(-1,9,0,LOG:13)
Block(-1,10,-11,LEAVES:1)
Block(-1,10,-10,LEAVES:1)
Block(-1,10,-9,LEAVES:1)
Block(-1,10,-2,LOG:13)
Block(-1,10,-1,LOG:13)
Block(-1,10,0,LOG:13)
Block(-1,11,-10,LEAVES:1)
Block(-1,11,-2,LOG:13)
Block(-1,11,-1,LOG:13)
Block(-1,11,0,LOG:13)
Block(-1,12,-5,LEAVES:1)
Block(-1,12,-2,LOG:13)
Block(-1,12,-1,LOG:13)
Block(-1,12,0,LOG:13)
Block(-1,12,9,LEAVES:1)
Block(-1,13,-5,LEAVES:1)
Block(-1,13,-4,LEAVES:1)
Block(-1,13,-3,LEAVES:1)
Block(-1,13,-2,LEAVES:1)
Block(-1,13,-1,LOG:13)
Block(-1,13,0,LOG:13)
Block(-1,13,10,LEAVES:1)
Block(-1,14,-9,LEAVES:1)
Block(-1,14,-4,LEAVES:1)
Block(-1,14,-3,LEAVES:1)
Block(-1,14,-2,LOG:13)
Block(-1,14,-1,LOG:13)
Block(-1,14,0,LOG:13)
Block(-1,14,9,LEAVES:1)
Block(-1,15,-9,LEAVES:1)
Block(-1,15,-7,LEAVES:1)
Block(-1,15,-2,LEAVES:1)
Block(-1,15,-1,LOG:13)
Block(-1,15,0,LOG:13)
Block(-1,16,-8,LEAVES:1)
Block(-1,16,-7,LEAVES:1)
Block(-1,16,-6,LEAVES:1)
Block(-1,16,-4,LEAVES:1)
Block(-1,16,-1,LOG:13)
Block(-1,16,0,LOG:13)
Block(-1,16,2,LEAVES:1)
Block(-1,17,-8,LEAVES:1)
Block(-1,17,-7,LEAVES:1)
Block(-1,17,-6,LOG:13)
Block(-1,17,-5,LEAVES:1)
Block(-1,17,-4,LEAVES:1)
Block(-1,17,-3,LEAVES:1)
Block(-1,17,-1,LOG:13)
Block(-1,17,0,LOG:13)
Block(-1,17,3,LEAVES:1)
Block(-1,18,-7,LEAVES:1)
Block(-1,18,-6,LEAVES:1)
Block(-1,18,-4,LEAVES:1)
Block(-1,18,-3,LEAVES:1)
Block(-1,18,-2,LEAVES:1)
Block(-1,18,-1,LOG:13)
Block(-1,18,0,LOG:13)
Block(-1,18,1,LEAVES:1)
Block(-1,19,-1,LOG:13)
Block(-1,19,0,LOG:13)
Block(-1,20,-1,LOG:13)
Block(-1,20,0,LOG:13)
Block(-1,21,-1,LOG:13)
Block(-1,21,0,LOG:13)
Block(-1,22,0,LOG:13)
Block(-1,23,0,LOG:13)
Block(-1,24,0,LOG:13)
Block(-1,25,-9,LEAVES:1)
Block(-1,25,0,LOG:13)
Block(-1,26,-12,LEAVES:1)
Block(-1,26,-10,LEAVES:1)
Block(-1,26,-9,LEAVES:1)
Block(-1,26,-8,LEAVES:1)
Block(-1,26,0,LOG:13)
Block(-1,26,8,LEAVES:1)
Block(-1,27,-11,LEAVES:1)
Block(-1,27,-10,LEAVES:1)
Block(-1,27,-9,LEAVES:1)
Block(-1,27,-8,LOG:13)
Block(-1,27,-7,LEAVES:1)
Block(-1,27,0,LOG:13)
Block(-1,27,7,LEAVES:1)
Block(-1,27,8,LEAVES:1)
Block(-1,28,-10,LEAVES:1)
Block(-1,28,-9,LEAVES:1)
Block(-1,28,-8,LEAVES:1)
Block(-1,28,-7,LOG:13)
Block(-1,28,-6,LOG:13)
Block(-1,28,-4,LEAVES:1)
Block(-1,28,-2,LEAVES:1)
Block(-1,28,0,LOG:13)
Block(-1,28,3,LEAVES:1)
Block(-1,28,5,LEAVES:1)
Block(-1,29,-8,LEAVES:1)
Block(-1,29,-7,LEAVES:1)
Block(-1,29,-6,LEAVES:1)
Block(-1,29,-5,LOG:13)
Block(-1,29,-4,LOG:13)
Block(-1,29,-3,LEAVES:1)
Block(-1,29,-2,LEAVES:1)
Block(-1,29,0,LOG:13)
Block(-1,29,2,LEAVES:1)
Block(-1,29,4,LEAVES:1)
Block(-1,29,5,LEAVES:1)
Block(-1,29,6,LEAVES:1)
Block(-1,30,-5,LEAVES:1)
Block(-1,30,-4,LEAVES:1)
Block(-1,30,-3,LEAVES:1)
Block(-1,30,-2,LEAVES:1)
Block(-1,30,-1,LEAVES:1)
Block(-1,30,0,LOG:13)
Block(-1,30,3,LEAVES:1)
Block(-1,30,4,LOG:13)
Block(-1,30,5,LEAVES:1)
Block(-1,31,-2,LEAVES:1)
Block(-1,31,0,LOG:13)
Block(-1,31,1,LEAVES:1)
Block(-1,31,2,LEAVES:1)
Block(-1,31,4,LEAVES:1)
Block(-1,31,5,LEAVES:1)
Block(-1,32,0,LOG:13)
Block(-1,32,1,LEAVES:1)
Block(-1,33,0,LOG:13)
Block(-1,33,1,LEAVES:1)
Block(-1,34,0,LOG:13)
Block(-1,34,1,LEAVES:1)
Block(-1,34,2,LEAVES:1)
Block(-1,35,-1,LEAVES:1)
Block(-1,35,0,LOG:13)
Block(-1,35,1,LEAVES:1)
Block(-1,35,2,LEAVES:1)
Block(-1,35,4,LEAVES:1)
Block(-1,36,-2,LEAVES:1)
Block(-1,36,-1,LEAVES:1)
Block(-1,36,0,LOG:13)
Block(-1,36,1,LEAVES:1)
Block(-1,36,3,LEAVES:1)
Block(-1,37,-1,LEAVES:1)
Block(-1,37,0,LOG:13)
Block(-1,37,2,LEAVES:1)
Block(-1,38,-2,LEAVES:1)
Block(-1,38,0,LOG:13)
Block(-1,38,1,LEAVES:1)
Block(-1,39,-1,LEAVES:1)
Block(-1,39,0,LOG:13)
Block(-1,39,1,LEAVES:1)
Block(-1,40,0,LOG:13)
Block(-1,40,1,LEAVES:1)
Block(-1,41,-1,LEAVES:1)
Block(-1,41,0,LOG:13)
Block(-1,42,-4,LEAVES:1)
Block(-1,42,0,LOG:13)
Block(-1,42,1,LEAVES:1)
Block(-1,42,2,LEAVES:1)
Block(-1,43,-3,LEAVES:1)
Block(-1,43,-1,LEAVES:1)
Block(-1,43,0,LOG:13)
Block(-1,43,1,LEAVES:1)
Block(-1,44,-2,LEAVES:1)
Block(-1,44,-1,LOG:13)
Block(-1,44,0,LOG:13)
Block(-1,44,1,LEAVES:1)
Block(-1,45,-1,LEAVES:1)
Block(-1,45,0,LOG:13)
Block(-1,45,1,LEAVES:1)
Block(-1,46,-3,LEAVES:1)
Block(-1,46,0,LOG:13)
Block(-1,46,1,LEAVES:1)
Block(-1,47,-2,LEAVES:1)
Block(-1,47,-1,LEAVES:1)
Block(-1,47,0,LOG:13)
Block(-1,47,1,LEAVES:1)
Block(-1,48,-2,LEAVES:1)
Block(-1,48,-1,LOG:13)
Block(-1,48,0,LOG:13)
Block(-1,48,1,LEAVES:1)
Block(-1,48,2,LEAVES:1)
Block(-1,48,3,LEAVES:1)
Block(-1,49,-1,LEAVES:1)
Block(-1,49,0,LOG:13)
Block(-1,49,1,LEAVES:1)
Block(-1,50,0,LOG:13)
Block(-1,50,1,LEAVES:1)
Block(-1,51,0,LOG:13)
Block(-1,51,2,LEAVES:1)
Block(-1,52,-1,LEAVES:1)
Block(-1,52,0,LOG:13)
Block(-1,52,1,LEAVES:1)
Block(-1,53,-2,LEAVES:1)
Block(-1,53,-1,LEAVES:1)
Block(-1,53,0,LOG:13)
Block(-1,53,1,LEAVES:1)
Block(-1,53,2,LEAVES:1)
Block(-1,54,-1,LEAVES:1)
Block(-1,54,0,LOG:13)
Block(-1,54,1,LEAVES:1)
Block(-1,55,-1,LEAVES:1)
Block(-1,55,0,LOG:13)
Block(-1,56,0,LOG:13)
Block(-1,57,-1,LEAVES:1)
Block(-1,57,0,LOG:13)
Block(-1,57,1,LEAVES:1)
Block(-1,58,0,LOG:13)
Block(-1,58,1,LEAVES:1)
Block(-1,59,0,LEAVES:1)
Block(0,-6,-3,LOG:1)
Block(0,-6,2,LOG:1)
Block(0,-5,-3,LOG:13)
Block(0,-5,-2,LOG:13)
Block(0,-5,-1,LOG:13)
Block(0,-5,0,LOG:13)
Block(0,-5,1,LOG:13)
Block(0,-5,2,LOG:13)
Block(0,-4,-3,LOG:1)
Block(0,-4,-2,LOG:13)
Block(0,-4,-1,LOG:13)
Block(0,-4,0,LOG:13)
Block(0,-4,1,LOG:13)
Block(0,-4,2,LOG:13)
Block(0,-3,-2,LOG:13)
Block(0,-3,-1,LOG:13)
Block(0,-3,0,LOG:13)
Block(0,-3,1,LOG:13)
Block(0,-3,2,LOG:1)
Block(0,-2,-2,LOG:13)
Block(0,-2,-1,LOG:13)
Block(0,-2,0,LOG:13)
Block(0,-2,1,LOG:13)
Block(0,-1,-2,LOG:13)
Block(0,-1,-1,LOG:13)
Block(0,-1,0,LOG:13)
Block(0,-1,1,LOG:13)
Block(0,0,-2,LOG:13)
Block(0,0,-1,LOG:1)
Block(0,0,0,LOG:13)
Block(0,0,1,LOG:13)
Block(0,1,-2,LOG:13)
Block(0,1,-1,LOG:13)
Block(0,1,0,LOG:13)
Block(0,1,1,LOG:13)
Block(0,2,-2,LOG:13)
Block(0,2,-1,LOG:13)
Block(0,2,0,LOG:13)
Block(0,2,1,LOG:13)
Block(0,3,-2,LOG:13)
Block(0,3,-1,LOG:13)
Block(0,3,0,LOG:13)
Block(0,3,1,LOG:13)
Block(0,4,-2,LOG:13)
Block(0,4,-1,LOG:13)
Block(0,4,0,LOG:13)
Block(0,4,1,LOG:13)
Block(0,5,-2,LOG:13)
Block(0,5,-1,LOG:13)
Block(0,5,0,LOG:13)
Block(0,5,1,LOG:13)
Block(0,6,-1,LOG:13)
Block(0,6,0,LOG:13)
Block(0,6,1,LOG:13)
Block(0,7,-1,LOG:13)
Block(0,7,0,LOG:13)
Block(0,7,1,LOG:13)
Block(0,8,-10,LEAVES:1)
Block(0,8,-1,LOG:13)
Block(0,8,0,LOG:13)
Block(0,8,1,LOG:13)
Block(0,9,-11,LEAVES:1)
Block(0,9,-1,LOG:13)
Block(0,9,0,LOG:13)
Block(0,9,1,LOG:13)
Block(0,10,-10,LEAVES:1)
Block(0,10,-1,LOG:13)
Block(0,10,0,LOG:13)
Block(0,10,1,LOG:13)
Block(0,11,-1,LOG:13)
Block(0,11,0,LOG:13)
Block(0,11,1,LOG:13)
Block(0,12,-3,LEAVES:1)
Block(0,12,-1,LOG:13)
Block(0,12,0,LOG:13)
Block(0,12,1,LOG:13)
Block(0,12,7,LEAVES:1)
Block(0,12,11,LEAVES:1)
Block(0,13,-4,LEAVES:1)
Block(0,13,-1,LOG:13)
Block(0,13,0,LOG:13)
Block(0,13,1,LOG:13)
Block(0,13,8,LEAVES:1)
Block(0,13,9,LEAVES:1)
Block(0,14,-10,LEAVES:1)
Block(0,14,-6,LEAVES:1)
Block(0,14,-2,LEAVES:1)
Block(0,14,-1,LOG:13)
Block(0,14,0,LOG:13)
Block(0,14,1,LOG:13)
Block(0,14,8,LEAVES:1)
Block(0,14,9,LEAVES:1)
Block(0,14,10,LEAVES:1)
Block(0,15,-8,LEAVES:1)
Block(0,15,-5,LEAVES:1)
Block(0,15,-1,LOG:13)
Block(0,15,0,LOG:13)
Block(0,15,1,LOG:13)
Block(0,15,9,LEAVES:1)
Block(0,16,-7,LEAVES:1)
Block(0,16,-5,LEAVES:1)
Block(0,16,-3,LEAVES:1)
Block(0,16,-1,LOG:13)
Block(0,16,0,LOG:13)
Block(0,16,1,LOG:13)
Block(0,16,4,LEAVES:1)
Block(0,17,-7,LEAVES:1)
Block(0,17,-6,LOG:13)
Block(0,17,-5,LOG:13)
Block(0,17,-4,LOG:13)
Block(0,17,-3,LEAVES:1)
Block(0,17,-1,LOG:13)
Block(0,17,0,LOG:13)
Block(0,17,1,LEAVES:1)
Block(0,17,2,LEAVES:1)
Block(0,17,3,LEAVES:1)
Block(0,17,4,LEAVES:1)
Block(0,18,-6,LEAVES:1)
Block(0,18,-5,LEAVES:1)
Block(0,18,-4,LEAVES:1)
Block(0,18,-3,LOG:13)
Block(0,18,-2,LOG:13)
Block(0,18,-1,LOG:13)
Block(0,18,0,LOG:13)
Block(0,18,1,LOG:13)
Block(0,18,2,LEAVES:1)
Block(0,18,3,LEAVES:1)
Block(0,19,-3,LEAVES:1)
Block(0,19,-2,LEAVES:1)
Block(0,19,-1,LOG:13)
Block(0,19,0,LOG:13)
Block(0,19,1,LEAVES:1)
Block(0,20,-1,LOG:13)
Block(0,20,0,LOG:13)
Block(0,21,-1,LOG:13)
Block(0,21,0,LOG:13)
Block(0,22,-1,LOG:13)
Block(0,22,0,LOG:13)
Block(0,23,-1,LOG:13)
Block(0,23,0,LOG:13)
Block(0,24,-1,LOG:13)
Block(0,24,0,LOG:13)
Block(0,25,-1,LOG:13)
Block(0,25,0,LOG:13)
Block(0,26,-11,LEAVES:1)
Block(0,26,-9,LEAVES:1)
Block(0,26,-1,LOG:13)
Block(0,26,0,LOG:13)
Block(0,27,-10,LEAVES:1)
Block(0,27,-9,LEAVES:1)
Block(0,27,-8,LEAVES:1)
Block(0,27,-1,LOG:13)
Block(0,27,0,LOG:13)
Block(0,28,-8,LEAVES:1)
Block(0,28,-7,LEAVES:1)
Block(0,28,-6,LEAVES:1)
Block(0,28,-1,LOG:13)
Block(0,28,0,LOG:13)
Block(0,28,6,LEAVES:1)
Block(0,29,-5,LEAVES:1)
Block(0,29,-4,LEAVES:1)
Block(0,29,-3,LEAVES:1)
Block(0,29,-2,LEAVES:1)
Block(0,29,0,LOG:13)
Block(0,29,5,LEAVES:1)
Block(0,30,-5,LEAVES:1)
Block(0,30,-4,LEAVES:1)
Block(0,30,-3,LOG:13)
Block(0,30,-2,LOG:13)
Block(0,30,-1,LOG:13)
Block(0,30,0,LOG:13)
Block(0,30,2,LEAVES:1)
Block(0,30,3,LOG:13)
Block(0,30,4,LEAVES:1)
Block(0,30,5,LEAVES:1)
Block(0,31,-4,LEAVES:1)
Block(0,31,-3,LEAVES:1)
Block(0,31,-2,LEAVES:1)
Block(0,31,-1,LEAVES:1)
Block(0,31,0,LOG:13)
Block(0,31,1,LOG:13)
Block(0,31,2,LOG:13)
Block(0,31,3,LEAVES:1)
Block(0,32,0,LOG:13)
Block(0,32,1,LEAVES:1)
Block(0,32,2,LEAVES:1)
Block(0,33,0,LOG:13)
Block(0,34,0,LOG:13)
Block(0,34,1,LEAVES:1)
Block(0,34,6,LEAVES:1)
Block(0,35,8,LEAVES:1)
Block(0,36,-3,LEAVES:1)
Block(0,36,-1,LEAVES:1)
Block(0,36,1,LEAVES:1)
Block(0,36,4,LEAVES:1)
Block(0,36,5,LEAVES:1)
Block(0,36,6,LEAVES:1)
Block(0,36,7,LEAVES:1)
Block(0,37,1,LOG:13)
Block(0,37,2,LEAVES:1)
Block(0,37,3,LEAVES:1)
Block(0,38,-3,LEAVES:1)
Block(0,38,-1,LEAVES:1)
Block(0,38,1,LEAVES:1)
Block(0,39,-2,LEAVES:1)
Block(0,39,-1,LOG:13)
Block(0,39,0,LEAVES:1)
Block(0,40,-1,LEAVES:1)
Block(0,41,0,LEAVES:1)
Block(0,42,-1,LEAVES:1)
Block(0,42,1,LEAVES:1)
Block(0,42,3,LEAVES:1)
Block(0,43,-2,LEAVES:1)
Block(0,43,0,LEAVES:1)
Block(0,43,1,LOG:13)
Block(0,43,2,LEAVES:1)
Block(0,44,-1,LEAVES:1)
Block(0,44,0,LEAVES:1)
Block(0,44,1,LEAVES:1)
Block(0,46,-2,LEAVES:1)
Block(0,46,0,LEAVES:1)
Block(0,47,-3,LEAVES:1)
Block(0,47,-2,LOG:13)
Block(0,47,-1,LEAVES:1)
Block(0,47,1,LEAVES:1)
Block(0,48,-2,LEAVES:1)
Block(0,48,-1,LEAVES:1)
Block(0,48,0,LEAVES:1)
Block(0,48,1,LEAVES:1)
Block(0,48,4,LEAVES:1)
Block(0,49,1,LEAVES:1)
Block(0,49,2,LEAVES:1)
Block(0,50,0,LEAVES:1)
Block(0,50,1,LOG:13)
Block(0,50,2,LEAVES:1)
Block(0,51,1,LEAVES:1)
Block(0,52,0,LEAVES:1)
Block(0,53,-1,LEAVES:1)
Block(0,53,0,LEAVES:1)
Block(0,53,1,LEAVES:1)
Block(0,54,-1,LEAVES:1)
Block(0,54,0,LOG:13)
Block(0,54,1,LEAVES:1)
Block(0,55,0,LEAVES:1)
Block(0,56,-1,LEAVES:1)
Block(0,56,0,LEAVES:1)
Block(0,56,1,LEAVES:1)
Block(0,57,0,LEAVES:1)
Block(1,-6,-2,LOG:1)
Block(1,-6,1,LOG:1)
Block(1,-5,-2,LOG:13)
Block(1,-5,-1,LOG:13)
Block(1,-5,0,LOG:13)
Block(1,-5,1,LOG:13)
Block(1,-4,-2,LOG:13)
Block(1,-4,-1,LOG:13)
Block(1,-4,0,LOG:13)
Block(1,-4,1,LOG:13)
Block(1,-3,-2,LOG:1)
Block(1,-3,-1,LOG:13)
Block(1,-3,0,LOG:13)
Block(1,-3,1,LOG:13)
Block(1,-2,-1,LOG:13)
Block(1,-2,0,LOG:13)
Block(1,-2,1,LOG:13)
Block(1,-1,-1,LOG:13)
Block(1,-1,0,LOG:13)
Block(1,0,-1,LOG:1)
Block(1,0,0,LOG:13)
Block(1,1,-1,LOG:13)
Block(1,1,0,LOG:13)
Block(1,2,-1,LOG:13)
Block(1,2,0,LOG:13)
Block(1,3,0,LOG:13)
Block(1,4,0,LOG:13)
Block(1,5,0,LOG:13)
Block(1,6,0,LOG:13)
Block(1,7,0,LOG:13)
Block(1,8,0,LOG:13)
Block(1,9,-4,LEAVES:1)
Block(1,9,0,LOG:13)
Block(1,10,-3,LEAVES:1)
Block(1,10,-2,LEAVES:1)
Block(1,11,-2,LEAVES:1)
Block(1,11,-1,LOG:13)
Block(1,11,0,LEAVES:1)
Block(1,12,-1,LEAVES:1)
Block(1,13,-13,LEAVES:1)
Block(1,13,-11,LEAVES:1)
Block(1,13,7,LEAVES:1)
Block(1,13,10,LEAVES:1)
Block(1,14,-11,LEAVES:1)
Block(1,14,6,LEAVES:1)
Block(1,14,8,LEAVES:1)
Block(1,14,9,LOG:13)
Block(1,14,10,LEAVES:1)
Block(1,15,-10,LEAVES:1)
Block(1,15,-9,LEAVES:1)
Block(1,15,-7,LEAVES:1)
Block(1,15,-6,LEAVES:1)
Block(1,15,7,LEAVES:1)
Block(1,15,9,LEAVES:1)
Block(1,16,-8,LEAVES:1)
Block(1,16,-7,LOG:13)
Block(1,16,-6,LEAVES:1)
Block(1,16,-4,LEAVES:1)
Block(1,16,2,LEAVES:1)
Block(1,16,3,LEAVES:1)
Block(1,17,-7,LEAVES:1)
Block(1,17,-6,LEAVES:1)
Block(1,17,-5,LEAVES:1)
Block(1,17,-4,LEAVES:1)
Block(1,17,-2,LEAVES:1)
Block(1,17,2,LEAVES:1)
Block(1,17,3,LEAVES:1)
Block(1,17,4,LEAVES:1)
Block(1,18,-6,LEAVES:1)
Block(1,18,-4,LEAVES:1)
Block(1,18,-3,LEAVES:1)
Block(1,18,-2,LEAVES:1)
Block(1,18,1,LEAVES:1)
Block(1,18,2,LOG:13)
Block(1,18,3,LEAVES:1)
Block(1,18,4,LEAVES:1)
Block(1,19,2,LEAVES:1)
Block(1,19,3,LEAVES:1)
Block(1,25,-10,LEAVES:1)
Block(1,26,-8,LEAVES:1)
Block(1,26,-1,LEAVES:1)
Block(1,26,0,LOG:13)
Block(1,26,1,LEAVES:1)
Block(1,27,-6,LEAVES:1)
Block(1,27,0,LEAVES:1)
Block(1,28,-4,LEAVES:1)
Block(1,28,5,LEAVES:1)
Block(1,28,8,LEAVES:1)
Block(1,29,-5,LEAVES:1)
Block(1,29,-4,LEAVES:1)
Block(1,29,-3,LEAVES:1)
Block(1,29,-1,LEAVES:1)
Block(1,29,3,LEAVES:1)
Block(1,29,4,LOG:13)
Block(1,29,5,LEAVES:1)
Block(1,29,6,LEAVES:1)
Block(1,29,7,LEAVES:1)
Block(1,30,-4,LEAVES:1)
Block(1,30,-3,LEAVES:1)
Block(1,30,-2,LEAVES:1)
Block(1,30,-1,LEAVES:1)
Block(1,30,2,LEAVES:1)
Block(1,30,3,LEAVES:1)
Block(1,30,4,LEAVES:1)
Block(1,30,5,LEAVES:1)
Block(1,31,-1,LEAVES:1)
Block(1,31,1,LEAVES:1)
Block(1,31,2,LEAVES:1)
Block(1,31,3,LEAVES:1)
Block(1,35,4,LEAVES:1)
Block(1,35,6,LEAVES:1)
Block(1,35,7,LEAVES:1)
Block(1,36,3,LEAVES:1)
Block(1,36,4,LOG:13)
Block(1,36,5,LOG:13)
Block(1,36,6,LEAVES:1)
Block(1,36,7,LEAVES:1)
Block(1,36,8,LEAVES:1)
Block(1,37,-4,LEAVES:1)
Block(1,37,-1,LEAVES:1)
Block(1,37,1,LEAVES:1)
Block(1,37,2,LOG:13)
Block(1,37,3,LOG:13)
Block(1,37,4,LEAVES:1)
Block(1,37,5,LEAVES:1)
Block(1,37,6,LEAVES:1)
Block(1,37,7,LEAVES:1)
Block(1,38,-3,LEAVES:1)
Block(1,38,0,LEAVES:1)
Block(1,38,2,LEAVES:1)
Block(1,38,3,LEAVES:1)
Block(1,39,-3,LEAVES:1)
Block(1,39,-2,LOG:13)
Block(1,39,-1,LEAVES:1)
Block(1,40,-2,LEAVES:1)
Block(1,42,0,LEAVES:1)
Block(1,42,2,LEAVES:1)
Block(1,42,4,LEAVES:1)
Block(1,43,1,LEAVES:1)
Block(1,43,2,LOG:13)
Block(1,43,3,LEAVES:1)
Block(1,44,2,LEAVES:1)
Block(1,46,-4,LEAVES:1)
Block(1,46,-1,LEAVES:1)
Block(1,47,-2,LEAVES:1)
Block(1,47,0,LEAVES:1)
Block(1,48,2,LEAVES:1)
Block(1,49,1,LEAVES:1)
Block(1,49,2,LOG:13)
Block(1,49,3,LEAVES:1)
Block(1,50,1,LEAVES:1)
Block(1,50,2,LEAVES:1)
Block(1,54,0,LEAVES:1)
Block(1,56,0,LEAVES:1)
Block(2,-6,-3,LOG:1)
Block(2,-6,-1,LOG:1)
Block(2,-6,1,LOG:1)
Block(2,-5,-3,LOG:13)
Block(2,-5,-2,LOG:13)
Block(2,-5,-1,LOG:1)
Block(2,-5,0,LOG:13)
Block(2,-5,1,LOG:13)
Block(2,-4,-3,LOG:13)
Block(2,-4,-2,LOG:13)
Block(2,-4,-1,LOG:1)
Block(2,-4,0,LOG:13)
Block(2,-4,1,LOG:13)
Block(2,-3,-3,LOG:13)
Block(2,-3,-2,LOG:13)
Block(2,-3,0,LOG:13)
Block(2,-3,1,LOG:13)
Block(2,-2,-2,LOG:13)
Block(2,-2,0,LOG:13)
Block(2,-2,1,LOG:1)
Block(2,-1,-2,LOG:1)
Block(2,-1,0,LOG:13)
Block(2,0,0,LOG:1)
Block(2,9,-3,LEAVES:1)
Block(2,9,-2,LEAVES:1)
Block(2,9,0,LEAVES:1)
Block(2,10,-4,LEAVES:1)
Block(2,10,-3,LEAVES:1)
Block(2,10,-2,LEAVES:1)
Block(2,10,-1,LEAVES:1)
Block(2,11,-3,LEAVES:1)
Block(2,11,-2,LEAVES:1)
Block(2,11,-1,LOG:13)
Block(2,11,0,LEAVES:1)
Block(2,12,-14,LEAVES:1)
Block(2,12,-2,LEAVES:1)
Block(2,12,-1,LEAVES:1)
Block(2,12,9,LEAVES:1)
Block(2,13,-14,LEAVES:1)
Block(2,13,-12,LEAVES:1)
Block(2,13,9,LEAVES:1)
Block(2,14,-13,LEAVES:1)
Block(2,14,-12,LEAVES:1)
Block(2,14,-11,LEAVES:1)
Block(2,14,-10,LEAVES:1)
Block(2,14,5,LEAVES:1)
Block(2,14,7,LEAVES:1)
Block(2,14,8,LOG:13)
Block(2,14,9,LEAVES:1)
Block(2,14,10,LEAVES:1)
Block(2,15,-11,LEAVES:1)
Block(2,15,-10,LOG:13)
Block(2,15,-9,LOG:13)
Block(2,15,-8,LEAVES:1)
Block(2,15,-6,LEAVES:1)
Block(2,15,2,LEAVES:1)
Block(2,15,4,LEAVES:1)
Block(2,15,6,LEAVES:1)
Block(2,15,7,LEAVES:1)
Block(2,15,8,LEAVES:1)
Block(2,15,9,LEAVES:1)
Block(2,16,-10,LEAVES:1)
Block(2,16,-9,LEAVES:1)
Block(2,16,-8,LOG:13)
Block(2,16,-7,LEAVES:1)
Block(2,16,-6,LEAVES:1)
Block(2,16,-5,LEAVES:1)
Block(2,16,3,LEAVES:1)
Block(2,16,5,LEAVES:1)
Block(2,16,6,LEAVES:1)
Block(2,16,7,LEAVES:1)
Block(2,17,-8,LEAVES:1)
Block(2,17,-6,LEAVES:1)
Block(2,17,-3,LEAVES:1)
Block(2,17,2,LEAVES:1)
Block(2,17,3,LOG:13)
Block(2,17,4,LEAVES:1)
Block(2,17,5,LEAVES:1)
Block(2,18,2,LEAVES:1)
Block(2,18,3,LEAVES:1)
Block(2,23,-4,LEAVES:1)
Block(2,24,-4,LEAVES:1)
Block(2,25,-3,LEAVES:1)
Block(2,25,-2,LEAVES:1)
Block(2,25,0,LEAVES:1)
Block(2,25,2,LEAVES:1)
Block(2,26,-2,LEAVES:1)
Block(2,26,-1,LOG:13)
Block(2,26,0,LOG:13)
Block(2,26,1,LEAVES:1)
Block(2,27,-1,LEAVES:1)
Block(2,27,0,LEAVES:1)
Block(2,28,-2,LEAVES:1)
Block(2,28,3,LEAVES:1)
Block(2,28,7,LEAVES:1)
Block(2,29,-4,LEAVES:1)
Block(2,29,-3,LEAVES:1)
Block(2,29,4,LEAVES:1)
Block(2,29,5,LOG:13)
Block(2,29,6,LEAVES:1)
Block(2,29,7,LEAVES:1)
Block(2,29,8,LEAVES:1)
Block(2,30,-2,LEAVES:1)
Block(2,30,3,LEAVES:1)
Block(2,30,5,LEAVES:1)
Block(2,30,6,LEAVES:1)
Block(2,30,7,LEAVES:1)
Block(2,34,4,LEAVES:1)
Block(2,34,7,LEAVES:1)
Block(2,35,6,LEAVES:1)
Block(2,36,1,LEAVES:1)
Block(2,36,4,LEAVES:1)
Block(2,36,5,LEAVES:1)
Block(2,36,6,LEAVES:1)
Block(2,36,7,LEAVES:1)
Block(2,37,-5,LEAVES:1)
Block(2,37,-3,LEAVES:1)
Block(2,37,0,LEAVES:1)
Block(2,37,2,LEAVES:1)
Block(2,37,3,LEAVES:1)
Block(2,37,6,LEAVES:1)
Block(2,38,-4,LEAVES:1)
Block(2,38,-3,LOG:13)
Block(2,38,-2,LEAVES:1)
Block(2,39,-3,LEAVES:1)
Block(2,39,-2,LEAVES:1)
Block(2,41,2,LEAVES:1)
Block(2,42,1,LEAVES:1)
Block(2,42,2,LOG:13)
Block(2,42,3,LEAVES:1)
Block(2,43,2,LEAVES:1)
Block(2,46,-3,LEAVES:1)
Block(2,48,0,LEAVES:1)
Block(2,48,3,LEAVES:1)
Block(2,49,2,LEAVES:1)
Block(3,-6,-3,LOG:1)
Block(3,-6,-2,LOG:1)
Block(3,-6,-1,LOG:1)
Block(3,-6,0,LOG:1)
Block(3,-6,2,LOG:1)
Block(3,-5,-3,LOG:13)
Block(3,-5,-2,LOG:5)
Block(3,-5,0,LOG:13)
Block(3,-5,2,LOG:13)
Block(3,-4,-3,LOG:13)
Block(3,-4,0,LOG:13)
Block(3,-4,2,LOG:1)
Block(3,-3,0,LOG:1)
Block(3,8,-2,LEAVES:1)
Block(3,8,0,LEAVES:1)
Block(3,9,-4,LEAVES:1)
Block(3,9,-1,LEAVES:1)
Block(3,10,-3,LEAVES:1)
Block(3,10,-2,LOG:13)
Block(3,10,-1,LEAVES:1)
Block(3,10,0,LEAVES:1)
Block(3,11,-2,LEAVES:1)
Block(3,11,-1,LEAVES:1)
Block(3,13,-13,LEAVES:1)
Block(3,13,-10,LEAVES:1)
Block(3,13,8,LEAVES:1)
Block(3,13,10,LEAVES:1)
Block(3,14,-14,LEAVES:1)
Block(3,14,-13,LEAVES:1)
Block(3,14,-12,LEAVES:1)
Block(3,14,-11,LOG:13)
Block(3,14,-10,LEAVES:1)
Block(3,14,7,LEAVES:1)
Block(3,14,9,LEAVES:1)
Block(3,15,-13,LEAVES:1)
Block(3,15,-12,LEAVES:1)
Block(3,15,-11,LEAVES:1)
Block(3,15,-10,LEAVES:1)
Block(3,15,-9,LEAVES:1)
Block(3,15,-8,LEAVES:1)
Block(3,15,-5,LEAVES:1)
Block(3,15,5,LEAVES:1)
Block(3,15,7,LOG:13)
Block(3,15,8,LEAVES:1)
Block(3,16,-10,LEAVES:1)
Block(3,16,-9,LEAVES:1)
Block(3,16,-8,LEAVES:1)
Block(3,16,-7,LEAVES:1)
Block(3,16,-6,LEAVES:1)
Block(3,16,3,LEAVES:1)
Block(3,16,4,LEAVES:1)
Block(3,16,5,LEAVES:1)
Block(3,16,6,LOG:13)
Block(3,16,7,LEAVES:1)
Block(3,17,-8,LEAVES:1)
Block(3,17,2,LEAVES:1)
Block(3,17,3,LEAVES:1)
Block(3,17,4,LOG:13)
Block(3,17,5,LEAVES:1)
Block(3,17,6,LEAVES:1)
Block(3,18,3,LEAVES:1)
Block(3,18,4,LEAVES:1)
Block(3,18,5,LEAVES:1)
Block(3,23,2,LEAVES:1)
Block(3,24,-3,LEAVES:1)
Block(3,24,2,LEAVES:1)
Block(3,25,-4,LEAVES:1)
Block(3,25,-3,LEAVES:1)
Block(3,25,-2,LOG:13)
Block(3,25,0,LOG:13)
Block(3,25,1,LEAVES:1)
Block(3,26,-3,LEAVES:1)
Block(3,26,-2,LEAVES:1)
Block(3,26,-1,LEAVES:1)
Block(3,26,0,LEAVES:1)
Block(3,27,8,LEAVES:1)
Block(3,28,4,LEAVES:1)
Block(3,28,6,LEAVES:1)
Block(3,28,8,LEAVES:1)
Block(3,29,5,LEAVES:1)
Block(3,29,6,LEAVES:1)
Block(3,29,7,LEAVES:1)
Block(3,30,6,LEAVES:1)
Block(3,35,5,LEAVES:1)
Block(3,36,2,LEAVES:1)
Block(3,36,6,LEAVES:1)
Block(3,37,-4,LEAVES:1)
Block(3,37,-2,LEAVES:1)
Block(3,38,-5,LEAVES:1)
Block(3,38,-4,LOG:13)
Block(3,38,-3,LEAVES:1)
Block(3,39,-4,LEAVES:1)
Block(3,41,1,LEAVES:1)
Block(3,42,2,LEAVES:1)
Block(3,48,1,LEAVES:1)
Block(4,-6,-1,LOG:1)
Block(4,-5,-1,LOG:13)
Block(4,-4,-1,LOG:13)
Block(4,7,-5,LEAVES:1)
Block(4,8,-4,LEAVES:1)
Block(4,8,-1,LEAVES:1)
Block(4,9,-5,LEAVES:1)
Block(4,9,-4,LEAVES:1)
Block(4,9,-3,LEAVES:1)
Block(4,9,-2,LEAVES:1)
Block(4,10,-4,LEAVES:1)
Block(4,10,-3,LOG:13)
Block(4,10,-2,LEAVES:1)
Block(4,10,-1,LEAVES:1)
Block(4,11,-3,LEAVES:1)
Block(4,12,9,LEAVES:1)
Block(4,13,-14,LEAVES:1)
Block(4,13,-12,LEAVES:1)
Block(4,14,-13,LEAVES:1)
Block(4,14,-12,LEAVES:1)
Block(4,14,-11,LEAVES:1)
Block(4,14,-10,LEAVES:1)
Block(4,14,-9,LEAVES:1)
Block(4,14,9,LEAVES:1)
Block(4,15,-10,LEAVES:1)
Block(4,15,-7,LEAVES:1)
Block(4,15,3,LEAVES:1)
Block(4,15,5,LEAVES:1)
Block(4,15,7,LEAVES:1)
Block(4,15,8,LEAVES:1)
Block(4,16,-8,LEAVES:1)
Block(4,16,4,LEAVES:1)
Block(4,16,5,LOG:13)
Block(4,16,6,LEAVES:1)
Block(4,16,7,LEAVES:1)
Block(4,17,3,LEAVES:1)
Block(4,17,4,LEAVES:1)
Block(4,17,5,LEAVES:1)
Block(4,22,1,LEAVES:1)
Block(4,24,-4,LEAVES:1)
Block(4,24,0,LEAVES:1)
Block(4,24,1,LEAVES:1)
Block(4,25,-3,LEAVES:1)
Block(4,25,-2,LEAVES:1)
Block(4,25,-1,LEAVES:1)
Block(4,25,0,LOG:13)
Block(4,25,1,LEAVES:1)
Block(4,25,2,LEAVES:1)
Block(4,26,-2,LEAVES:1)
Block(4,26,0,LEAVES:1)
Block(4,26,1,LEAVES:1)
Block(4,27,5,LEAVES:1)
Block(4,28,5,LEAVES:1)
Block(4,28,7,LEAVES:1)
Block(4,29,6,LEAVES:1)
Block(4,37,-5,LEAVES:1)
Block(4,37,-3,LEAVES:1)
Block(4,38,-4,LEAVES:1)
Block(5,8,-6,LEAVES:1)
Block(5,8,-5,LEAVES:1)
Block(5,8,-2,LEAVES:1)
Block(5,9,-5,LEAVES:1)
Block(5,9,-4,LOG:13)
Block(5,9,-3,LEAVES:1)
Block(5,9,-2,LEAVES:1)
Block(5,9,-1,LEAVES:1)
Block(5,10,-4,LEAVES:1)
Block(5,10,-3,LEAVES:1)
Block(5,10,-2,LEAVES:1)
Block(5,11,-3,LEAVES:1)
Block(5,12,-13,LEAVES:1)
Block(5,13,-11,LEAVES:1)
Block(5,13,-9,LEAVES:1)
Block(5,13,7,LEAVES:1)
Block(5,14,-10,LEAVES:1)
Block(5,14,7,LEAVES:1)
Block(5,14,8,LEAVES:1)
Block(5,15,4,LEAVES:1)
Block(5,15,5,LEAVES:1)
Block(5,15,7,LEAVES:1)
Block(5,15,8,LEAVES:1)
Block(5,15,9,LEAVES:1)
Block(5,16,4,LEAVES:1)
Block(5,16,5,LEAVES:1)
Block(5,16,6,LOG:13)
Block(5,16,7,LEAVES:1)
Block(5,16,8,LEAVES:1)
Block(5,17,5,LEAVES:1)
Block(5,17,6,LEAVES:1)
Block(5,17,7,LEAVES:1)
Block(5,22,2,LEAVES:1)
Block(5,23,1,LEAVES:1)
Block(5,24,-2,LEAVES:1)
Block(5,24,-1,LOG:13)
Block(5,24,0,LEAVES:1)
Block(5,25,-2,LEAVES:1)
Block(5,25,-1,LEAVES:1)
Block(5,25,0,LEAVES:1)
Block(5,25,1,LEAVES:1)
Block(6,6,-7,LEAVES:1)
Block(6,6,-2,LEAVES:1)
Block(6,7,-6,LEAVES:1)
Block(6,7,-3,LEAVES:1)
Block(6,8,-7,LEAVES:1)
Block(6,8,-6,LEAVES:1)
Block(6,8,-5,LEAVES:1)
Block(6,8,-4,LEAVES:1)
Block(6,8,-1,LEAVES:1)
Block(6,9,-6,LEAVES:1)
Block(6,9,-5,LEAVES:1)
Block(6,9,-4,LOG:13)
Block(6,9,-3,LEAVES:1)
Block(6,9,-2,LEAVES:1)
Block(6,10,-5,LEAVES:1)
Block(6,10,-4,LEAVES:1)
Block(6,10,-3,LEAVES:1)
Block(6,13,9,LEAVES:1)
Block(6,14,5,LEAVES:1)
Block(6,14,9,LEAVES:1)
Block(6,15,6,LEAVES:1)
Block(6,15,7,LOG:13)
Block(6,15,8,LEAVES:1)
Block(6,16,5,LEAVES:1)
Block(6,16,6,LEAVES:1)
Block(6,16,7,LEAVES:1)
Block(6,22,-4,LEAVES:1)
Block(6,22,1,LEAVES:1)
Block(6,22,3,LEAVES:1)
Block(6,23,-3,LEAVES:1)
Block(6,23,-2,LEAVES:1)
Block(6,23,-1,LEAVES:1)
Block(6,23,0,LOG:13)
Block(6,23,1,LEAVES:1)
Block(6,23,2,LEAVES:1)
Block(6,24,-3,LEAVES:1)
Block(6,24,-2,LOG:13)
Block(6,24,-1,LEAVES:1)
Block(6,24,0,LEAVES:1)
Block(6,24,1,LEAVES:1)
Block(6,25,-2,LEAVES:1)
Block(7,5,-6,LEAVES:1)
Block(7,6,-4,LEAVES:1)
Block(7,7,-5,LEAVES:1)
Block(7,7,-4,LEAVES:1)
Block(7,8,-6,LEAVES:1)
Block(7,8,-5,LOG:13)
Block(7,8,-4,LEAVES:1)
Block(7,8,-3,LEAVES:1)
Block(7,9,-5,LEAVES:1)
Block(7,9,-4,LEAVES:1)
Block(7,12,10,LEAVES:1)
Block(7,14,7,LEAVES:1)
Block(7,14,8,LEAVES:1)
Block(7,14,9,LEAVES:1)
Block(7,14,10,LEAVES:1)
Block(7,15,6,LEAVES:1)
Block(7,15,7,LEAVES:1)
Block(7,15,8,LOG:13)
Block(7,15,9,LEAVES:1)
Block(7,16,7,LEAVES:1)
Block(7,16,8,LEAVES:1)
Block(7,21,-4,LEAVES:1)
Block(7,22,-3,LEAVES:1)
Block(7,22,2,LEAVES:1)
Block(7,23,-4,LEAVES:1)
Block(7,23,-3,LEAVES:1)
Block(7,23,-2,LOG:13)
Block(7,23,-1,LEAVES:1)
Block(7,23,0,LEAVES:1)
Block(7,23,1,LOG:13)
Block(7,23,2,LEAVES:1)
Block(7,24,-3,LEAVES:1)
Block(7,24,-2,LEAVES:1)
Block(7,24,1,LEAVES:1)
Block(8,6,-8,LEAVES:1)
Block(8,6,-6,LEAVES:1)
Block(8,7,-7,LEAVES:1)
Block(8,7,-5,LEAVES:1)
Block(8,7,-3,LEAVES:1)
Block(8,8,-7,LEAVES:1)
Block(8,8,-6,LOG:13)
Block(8,8,-5,LEAVES:1)
Block(8,8,-4,LEAVES:1)
Block(8,9,-6,LEAVES:1)
Block(8,12,11,LEAVES:1)
Block(8,13,7,LEAVES:1)
Block(8,13,10,LEAVES:1)
Block(8,14,8,LEAVES:1)
Block(8,14,9,LOG:13)
Block(8,14,10,LEAVES:1)
Block(8,14,11,LEAVES:1)
Block(8,15,7,LEAVES:1)
Block(8,15,8,LEAVES:1)
Block(8,15,9,LEAVES:1)
Block(8,15,10,LEAVES:1)
Block(8,21,-4,LEAVES:1)
Block(8,21,3,LEAVES:1)
Block(8,22,-3,LEAVES:1)
Block(8,22,-2,LEAVES:1)
Block(8,22,0,LEAVES:1)
Block(8,22,2,LOG:13)
Block(8,22,3,LEAVES:1)
Block(8,23,-3,LEAVES:1)
Block(8,23,-2,LOG:13)
Block(8,23,-1,LEAVES:1)
Block(8,23,1,LEAVES:1)
Block(8,23,2,LEAVES:1)
Block(8,24,-2,LEAVES:1)
Block(9,6,-7,LEAVES:1)
Block(9,6,-5,LEAVES:1)
Block(9,6,-3,LEAVES:1)
Block(9,7,-8,LEAVES:1)
Block(9,7,-7,LEAVES:1)
Block(9,7,-6,LOG:13)
Block(9,7,-5,LEAVES:1)
Block(9,7,-4,LEAVES:1)
Block(9,8,-7,LEAVES:1)
Block(9,8,-6,LEAVES:1)
Block(9,8,-5,LEAVES:1)
Block(9,9,-6,LEAVES:1)
Block(9,11,11,LEAVES:1)
Block(9,12,13,LEAVES:1)
Block(9,13,9,LEAVES:1)
Block(9,13,11,LEAVES:1)
Block(9,13,12,LEAVES:1)
Block(9,14,8,LEAVES:1)
Block(9,14,9,LEAVES:1)
Block(9,14,10,LOG:13)
Block(9,14,11,LEAVES:1)
Block(9,15,9,LEAVES:1)
Block(9,15,10,LEAVES:1)
Block(9,20,-1,LEAVES:1)
Block(9,21,-1,LEAVES:1)
Block(9,21,2,LEAVES:1)
Block(9,21,4,LEAVES:1)
Block(9,22,-4,LEAVES:1)
Block(9,22,-3,LOG:13)
Block(9,22,-2,LEAVES:1)
Block(9,22,1,LEAVES:1)
Block(9,22,2,LEAVES:1)
Block(9,22,3,LEAVES:1)
Block(9,23,-3,LEAVES:1)
Block(9,23,-2,LEAVES:1)
Block(9,23,2,LEAVES:1)
Block(10,5,-6,LEAVES:1)
Block(10,5,-4,LEAVES:1)
Block(10,6,-8,LEAVES:1)
Block(10,6,-7,LEAVES:1)
Block(10,7,-8,LEAVES:1)
Block(10,7,-7,LOG:13)
Block(10,7,-6,LEAVES:1)
Block(10,7,-5,LEAVES:1)
Block(10,8,-7,LEAVES:1)
Block(10,8,-6,LEAVES:1)
Block(10,12,12,LEAVES:1)
Block(10,13,8,LEAVES:1)
Block(10,13,10,LEAVES:1)
Block(10,13,11,LOG:13)
Block(10,13,12,LEAVES:1)
Block(10,13,13,LEAVES:1)
Block(10,14,9,LEAVES:1)
Block(10,14,10,LEAVES:1)
Block(10,14,11,LEAVES:1)
Block(10,14,12,LEAVES:1)
Block(10,20,3,LEAVES:1)
Block(10,21,-5,LEAVES:1)
Block(10,21,-2,LEAVES:1)
Block(10,21,1,LEAVES:1)
Block(10,21,3,LEAVES:1)
Block(10,22,-4,LEAVES:1)
Block(10,22,-3,LOG:13)
Block(10,22,-2,LEAVES:1)
Block(10,22,-1,LEAVES:1)
Block(10,22,2,LEAVES:1)
Block(10,23,-3,LEAVES:1)
Block(10,23,-2,LEAVES:1)
Block(11,4,-9,LEAVES:1)
Block(11,5,-8,LEAVES:1)
Block(11,6,-9,LEAVES:1)
Block(11,6,-8,LEAVES:1)
Block(11,6,-7,LOG:13)
Block(11,6,-6,LEAVES:1)
Block(11,7,-8,LEAVES:1)
Block(11,7,-7,LEAVES:1)
Block(11,11,12,LEAVES:1)
Block(11,12,10,LEAVES:1)
Block(11,13,11,LEAVES:1)
Block(11,13,12,LEAVES:1)
Block(11,20,-1,LEAVES:1)
Block(11,21,-3,LEAVES:1)
Block(11,21,-2,LEAVES:1)
Block(11,22,-5,LEAVES:1)
Block(11,22,-4,LEAVES:1)
Block(11,22,-3,LEAVES:1)
Block(11,22,-2,LEAVES:1)
Block(11,23,-4,LEAVES:1)
Block(11,23,-3,LEAVES:1)
Block(12,5,-7,LEAVES:1)
Block(12,5,-5,LEAVES:1)
Block(12,6,-8,LEAVES:1)
Block(12,6,-7,LEAVES:1)
Block(12,6,-6,LEAVES:1)
Block(12,7,-7,LEAVES:1)
Block(12,21,-5,LEAVES:1)
Block(12,21,-3,LEAVES:1)
Block(12,22,-4,LEAVES:1)
Block(12,22,-3,LEAVES:1)
Block(12,22,-2,LEAVES:1)
Block(12,23,-3,LEAVES:1)
Block(13,4,-6,LEAVES:1)
Block(13,5,-8,LEAVES:1)
Block(13,5,-6,LEAVES:1)
Block(13,6,-7,LEAVES:1)
Block(13,20,-4,LEAVES:1)
Block(13,21,-4,LEAVES:1)
Block(13,21,-2,LEAVES:1)
Block(13,22,-3,LEAVES:1)

#######################################################################
# +-----------------------------------------------------------------+ #
# |                            BO3 checks                           | #
# +-----------------------------------------------------------------+ #
#######################################################################


#######################################################################
# +-----------------------------------------------------------------+ #
# |                             Branches                            | #
# +-----------------------------------------------------------------+ #
#######################################################################


#######################################################################
# +-----------------------------------------------------------------+ #
# |                             Entities                            | #
# +-----------------------------------------------------------------+ #
#######################################################################


#######################################################################
# +-----------------------------------------------------------------+ #
# |                            Particles                            | #
# +-----------------------------------------------------------------+ #
#######################################################################


#######################################################################
# +-----------------------------------------------------------------+ #
# |                             Spawners                            | #
# +-----------------------------------------------------------------+ #
#######################################################################


#######################################################################
# +-----------------------------------------------------------------+ #
# |                             ModData                             | #
# +-----------------------------------------------------------------+ #
#######################################################################

