#######################################################################
# +-----------------------------------------------------------------+ #
# |                            BO3 object                           | #
# +-----------------------------------------------------------------+ #
#######################################################################

# The descriptions in this file are true only for TerrainControl. They are not true for the Minecraft Worlds mod!
# Minecraft Worlds completely reimplemented BO3s, check the MCW documentation on the mc/mctcp forums for how to use BO3s with MCW
# or watch the video's on my YT channel at https://www.youtube.com/user/PeeGee85. You can check out the "Editing and importing schematics & BO3s" 
# series of video's, in part 2 I explain BO3s. 

# This is the config file of a custom object.
# If you add this object correctly to your BiomeConfigs, it will spawn in the world.

# This is the creator of this BO3 object
Author: Unknown

# A short description of this BO3 object
Description: This BO3 was converted from a schematic using the MineCraft Worlds Editor. Unfortunately the author and description information for the schematic could not be found. If you know who the author of the schematic is then please tell the author of this BO3!

# The BO3 version, don't change this! It can be used by external applications to do a version check.
Version: 3

# The settings mode, WriteAll, WriteWithoutComments or WriteDisable. See WorldConfig.
SettingsMode: WriteDisable

#######################################################################
# +-----------------------------------------------------------------+ #
# |                          Main settings                          | #
# +-----------------------------------------------------------------+ #
#######################################################################

# This needs to be set to true to spawn the object in the Tree and Sapling resources.
Tree: false

# The frequency of the BO3 from 1 to 200. Tries this many times to spawn this BO3 when using the CustomObject(...) resource.
# Ignored by Tree(..), Sapling(..) and CustomStructure(..)
Frequency: 40

# The rarity of the BO3 from 0 to 100. Each spawn attempt has rarity% chance to succeed when using the CustomObject(...) resource.
# Ignored by Tree(..), Sapling(..) and CustomStructure(..)
Rarity: 100.0

# If you set this to true, the BO3 will be placed with a random rotation.
RotateRandomly: false

# The spawn height of the BO3 - randomY, highestBlock or highestSolidBlock.
SpawnHeight: randomY

# The height limits for the BO3.
MinHeight: 0

MaxHeight: 256

# Objects can have other objects attached to it: branches. Branches can also
# have branches attached to it, which can also have branches, etc. This is the
# maximum branch depth for this objects.
MaxBranchDepth: 10

# When spawned with the UseWorld keyword, this BO3 should NOT spawn in the following biomes.
# If you writer.write the BO3 name directly in the BiomeConfigs, this will be ignored.
ExcludedBiomes: All

#######################################################################
# +-----------------------------------------------------------------+ #
# |                      Source block settings                      | #
# +-----------------------------------------------------------------+ #
#######################################################################

# The B(s) the BO3 should spawn in.
SourceBlocks: AIR

# The maximum percentage of the BO3 that can be outside the SourceBlock.
# The BO3 won't be placed on a location with more blocks outside the SourceBlock than this percentage.
MaxPercentageOutsideSourceBlock: 100

# What to do when a block is about to be placed outside the SourceBlock? (dontPlace, placeAnyway)
OutsideSourceBlock: placeAnyway

#######################################################################
# +-----------------------------------------------------------------+ #
# |                              Blocks                             | #
# +-----------------------------------------------------------------+ #
#######################################################################

# All the blocks used in the BO3 are listed here. Possible blocks:
# B(x,y,z,id[.data][,nbtfile.nbt)
# RB(x,y,z,id[:data][,nbtfile.nbt],chance[,id[:data][,nbtfile.nbt],chance[,...]])
# So RB(0,0,0,CHEST,chest.nbt,50,CHEST,anotherchest.nbt,100) will spawn a chest at
# the BO3 origin, and give it a 50% chance to have the contents of chest.nbt, or, if that
# fails, a 100% percent chance to have the contents of anotherchest.nbt.

B(-8,11,-7,174)
B(-8,11,-6,174)
B(-8,11,-5,174)
B(-8,11,-1,174)
B(-8,11,0,174)
B(-8,11,1,174)
B(-8,11,2,174)
B(-8,11,3,174)
B(-8,11,4,174)
B(-8,11,5,174)
B(-8,12,-7,174)
B(-8,12,-6,174)
B(-8,12,-5,174)
B(-8,12,-4,174)
B(-8,12,-3,174)
B(-8,12,-2,174)
B(-8,12,-1,174)
B(-8,12,0,174)
B(-8,12,1,174)
B(-8,12,2,174)
B(-8,12,3,174)
B(-8,12,4,174)
B(-8,12,5,174)
B(-8,12,6,174)
B(-8,13,-7,174)
B(-8,13,-6,174)
B(-8,13,-5,174)
B(-8,13,-4,174)
B(-8,13,-3,174)
B(-8,13,-2,174)
B(-8,13,-1,174)
B(-8,13,0,174)
B(-8,13,1,174)
B(-8,13,2,174)
B(-8,13,3,174)
B(-8,13,4,174)
B(-8,13,5,174)
B(-8,13,6,174)
B(-8,13,7,174)
B(-8,14,-7,174)
B(-8,14,-6,174)
B(-8,14,-5,174)
B(-8,14,-4,174)
B(-8,14,-3,174)
B(-8,14,-2,174)
B(-8,14,-1,174)
B(-8,14,0,174)
B(-8,14,1,174)
B(-8,14,2,174)
B(-8,14,3,174)
B(-8,14,4,174)
B(-8,14,5,174)
B(-8,14,6,174)
B(-8,14,7,174)
B(-8,15,-7,174)
B(-8,15,-6,174)
B(-8,15,-5,174)
B(-8,15,-4,174)
B(-8,15,-3,174)
B(-8,15,-2,174)
B(-8,15,-1,174)
B(-8,15,0,174)
B(-8,15,1,174)
B(-8,15,2,174)
B(-8,15,3,174)
B(-8,15,4,174)
B(-8,15,5,174)
B(-8,15,6,174)
B(-8,15,7,174)
B(-8,16,-7,174)
B(-8,16,-6,174)
B(-8,16,-5,174)
B(-8,16,-4,174)
B(-8,16,-3,174)
B(-8,16,-2,174)
B(-8,16,-1,174)
B(-8,16,0,174)
B(-8,16,1,174)
B(-8,16,2,174)
B(-8,16,3,174)
B(-8,16,4,174)
B(-8,16,5,174)
B(-8,16,6,174)
B(-8,16,7,174)
B(-8,16,8,174)
B(-8,17,-7,174)
B(-8,17,-6,174)
B(-8,17,-5,174)
B(-8,17,-4,174)
B(-8,17,-3,174)
B(-8,17,-2,174)
B(-8,17,-1,174)
B(-8,17,0,174)
B(-8,17,1,174)
B(-8,17,2,174)
B(-8,17,3,174)
B(-8,17,4,174)
B(-8,17,5,174)
B(-8,17,6,174)
B(-8,17,7,174)
B(-8,17,8,174)
B(-8,18,-7,174)
B(-8,18,-6,174)
B(-8,18,-5,174)
B(-8,18,-4,174)
B(-8,18,-3,174)
B(-8,18,-2,174)
B(-8,18,-1,174)
B(-8,18,0,174)
B(-8,18,1,174)
B(-8,18,2,174)
B(-8,18,3,174)
B(-8,18,4,174)
B(-8,18,5,174)
B(-8,18,6,174)
B(-8,18,7,174)
B(-8,18,8,174)
B(-8,19,-7,174)
B(-8,19,-6,174)
B(-8,19,-5,174)
B(-8,19,-4,174)
B(-8,19,-3,174)
B(-8,19,-2,174)
B(-8,19,-1,174)
B(-8,19,0,174)
B(-8,19,1,174)
B(-8,19,2,174)
B(-8,19,3,174)
B(-8,19,4,174)
B(-8,19,5,174)
B(-8,19,6,174)
B(-8,19,7,174)
B(-8,19,8,174)
B(-8,20,-7,174)
B(-8,20,-6,174)
B(-8,20,-5,174)
B(-8,20,-4,174)
B(-8,20,-3,174)
B(-8,20,-2,174)
B(-8,20,-1,174)
B(-8,20,0,174)
B(-8,20,1,174)
B(-8,20,2,174)
B(-8,20,3,174)
B(-8,20,4,174)
B(-8,20,5,174)
B(-8,20,6,174)
B(-8,20,7,174)
B(-8,20,8,174)
B(-8,21,-7,174)
B(-8,21,-6,174)
B(-8,21,-5,174)
B(-8,21,-4,174)
B(-8,21,-3,174)
B(-8,21,-2,174)
B(-8,21,-1,174)
B(-8,21,0,174)
B(-8,21,1,174)
B(-8,21,2,174)
B(-8,21,3,174)
B(-8,21,4,174)
B(-8,21,5,174)
B(-8,21,6,174)
B(-8,21,7,174)
B(-8,21,8,174)
B(-8,22,-1,174)
B(-8,22,0,174)
B(-8,22,1,174)
B(-8,22,2,174)
B(-8,22,3,174)
B(-8,22,4,174)
B(-8,22,5,174)
B(-8,22,6,174)
B(-8,22,7,174)
B(-8,22,8,174)
B(-8,23,0,174)
B(-8,23,1,174)
B(-8,23,2,174)
B(-8,23,3,174)
B(-8,23,4,174)
B(-8,23,5,174)
B(-8,23,6,174)
B(-8,23,7,174)
B(-8,23,8,174)
B(-8,24,1,174)
B(-8,24,2,174)
B(-8,24,3,174)
B(-8,24,4,174)
B(-8,24,5,174)
B(-8,24,6,174)
B(-8,24,7,174)
B(-8,24,8,174)
B(-8,25,3,174)
B(-8,25,4,174)
B(-8,25,5,174)
B(-8,25,6,174)
B(-8,25,7,174)
B(-8,26,3,174)
B(-8,26,4,174)
B(-8,26,5,174)
B(-8,26,6,174)
B(-8,27,4,174)
B(-8,27,5,174)
B(-8,27,6,174)
B(-8,28,4,174)
B(-8,28,5,174)
B(-8,28,6,174)
B(-8,54,4,174)
B(-8,55,4,174)
B(-8,56,4,174)
B(-8,57,4,174)
B(-8,58,4,174)
B(-8,59,0,174)
B(-8,59,1,174)
B(-8,59,2,174)
B(-8,59,3,174)
B(-8,59,4,174)
B(-8,60,-7,174)
B(-8,60,-6,174)
B(-8,60,-5,174)
B(-8,60,-4,174)
B(-8,60,-3,174)
B(-8,60,-2,174)
B(-8,60,-1,174)
B(-8,60,0,174)
B(-8,60,1,174)
B(-8,60,2,174)
B(-8,60,3,174)
B(-8,60,4,174)
B(-8,60,5,174)
B(-8,61,-7,174)
B(-8,61,-6,174)
B(-8,61,-5,174)
B(-8,61,-4,174)
B(-8,61,-3,174)
B(-8,61,-2,174)
B(-8,61,-1,174)
B(-8,61,0,174)
B(-8,61,1,174)
B(-8,61,2,174)
B(-8,61,3,174)
B(-8,61,4,174)
B(-8,61,5,174)
B(-8,61,6,174)
B(-8,62,-7,174)
B(-8,62,-6,174)
B(-8,62,-5,174)
B(-8,62,-4,174)
B(-8,62,-3,174)
B(-8,62,-2,174)
B(-8,62,-1,174)
B(-8,62,0,174)
B(-8,62,1,174)
B(-8,62,2,174)
B(-8,62,3,174)
B(-8,62,4,174)
B(-8,62,5,174)
B(-8,62,6,174)
B(-8,63,-7,174)
B(-8,63,-6,174)
B(-8,63,-5,174)
B(-8,63,-4,174)
B(-8,63,-3,174)
B(-8,63,-2,174)
B(-8,63,-1,174)
B(-8,63,0,174)
B(-8,63,1,174)
B(-8,63,2,174)
B(-8,63,3,174)
B(-8,63,4,174)
B(-8,63,5,174)
B(-8,63,6,174)
B(-8,63,7,174)
B(-8,64,-7,174)
B(-8,64,-6,174)
B(-8,64,-5,174)
B(-8,64,-4,174)
B(-8,64,-3,174)
B(-8,64,-2,174)
B(-8,64,-1,174)
B(-8,64,0,174)
B(-8,64,1,174)
B(-8,64,2,174)
B(-8,64,3,174)
B(-8,64,4,174)
B(-8,64,5,174)
B(-8,64,6,174)
B(-8,64,7,174)
B(-8,64,8,174)
B(-8,65,-7,174)
B(-8,65,-6,174)
B(-8,65,-5,174)
B(-8,65,-4,174)
B(-8,65,-3,174)
B(-8,65,-2,174)
B(-8,65,-1,174)
B(-8,65,0,174)
B(-8,65,1,174)
B(-8,65,2,174)
B(-8,65,3,174)
B(-8,65,4,174)
B(-8,65,5,174)
B(-8,65,6,174)
B(-8,65,7,174)
B(-8,65,8,174)
B(-8,66,-7,174)
B(-8,66,-6,174)
B(-8,66,-5,174)
B(-8,66,-4,174)
B(-8,66,-3,174)
B(-8,66,-2,174)
B(-8,66,-1,174)
B(-8,66,0,174)
B(-8,66,1,174)
B(-8,66,2,174)
B(-8,66,3,174)
B(-8,66,4,174)
B(-8,66,5,174)
B(-8,66,6,174)
B(-8,66,7,174)
B(-8,66,8,174)
B(-8,67,-7,174)
B(-8,67,-6,174)
B(-8,67,-5,174)
B(-8,67,-4,174)
B(-8,67,-3,174)
B(-8,67,-2,174)
B(-8,67,-1,174)
B(-8,67,0,174)
B(-8,67,1,174)
B(-8,67,2,174)
B(-8,67,3,174)
B(-8,67,4,174)
B(-8,67,5,174)
B(-8,67,6,174)
B(-8,67,7,174)
B(-8,67,8,174)
B(-8,68,-7,174)
B(-8,68,-6,174)
B(-8,68,-5,174)
B(-8,68,-4,174)
B(-8,68,-3,174)
B(-8,68,-2,174)
B(-8,68,-1,174)
B(-8,68,0,174)
B(-8,68,1,174)
B(-8,68,2,174)
B(-8,68,3,174)
B(-8,68,4,174)
B(-8,68,5,174)
B(-8,68,6,174)
B(-8,68,7,174)
B(-8,68,8,174)
B(-8,69,-7,174)
B(-8,69,-6,174)
B(-8,69,-5,174)
B(-8,69,-4,174)
B(-8,69,-3,174)
B(-8,69,-2,174)
B(-8,69,-1,174)
B(-8,69,0,174)
B(-8,69,1,174)
B(-8,69,2,174)
B(-8,69,3,174)
B(-8,69,4,174)
B(-8,69,5,174)
B(-8,69,6,174)
B(-8,69,7,174)
B(-8,69,8,174)
B(-8,70,-7,174)
B(-8,70,-6,174)
B(-8,70,-5,174)
B(-8,70,-1,174)
B(-8,70,0,174)
B(-8,70,1,174)
B(-8,70,2,174)
B(-8,70,3,174)
B(-8,70,4,174)
B(-8,70,5,174)
B(-8,70,6,174)
B(-8,70,7,174)
B(-8,70,8,174)
B(-8,71,4,174)
B(-8,71,5,174)
B(-8,71,6,174)
B(-8,71,7,174)
B(-8,71,8,174)
B(-8,72,5,174)
B(-8,72,6,174)
B(-8,72,7,174)
B(-8,72,8,174)
B(-7,10,2,174)
B(-7,11,-7,174)
B(-7,11,-6,174)
B(-7,11,0,174)
B(-7,11,1,174)
B(-7,11,2,174)
B(-7,11,3,174)
B(-7,11,4,174)
B(-7,12,-7,174)
B(-7,12,-6,174)
B(-7,12,-5,174)
B(-7,12,-4,174)
B(-7,12,-3,174)
B(-7,12,-2,174)
B(-7,12,-1,174)
B(-7,12,0,174)
B(-7,12,1,174)
B(-7,12,2,174)
B(-7,12,3,174)
B(-7,12,4,174)
B(-7,13,-7,174)
B(-7,13,-6,174)
B(-7,13,-5,174)
B(-7,13,-4,174)
B(-7,13,-3,174)
B(-7,13,-2,174)
B(-7,13,-1,174)
B(-7,13,0,174)
B(-7,13,1,174)
B(-7,13,2,174)
B(-7,13,3,174)
B(-7,13,4,174)
B(-7,13,5,174)
B(-7,14,-7,174)
B(-7,14,-6,174)
B(-7,14,-5,174)
B(-7,14,-4,174)
B(-7,14,-3,174)
B(-7,14,-2,174)
B(-7,14,-1,174)
B(-7,14,0,174)
B(-7,14,1,174)
B(-7,14,2,174)
B(-7,14,3,174)
B(-7,14,4,174)
B(-7,14,5,174)
B(-7,14,6,174)
B(-7,15,-7,174)
B(-7,15,-6,174)
B(-7,15,-5,174)
B(-7,15,-4,174)
B(-7,15,-3,174)
B(-7,15,-2,174)
B(-7,15,-1,174)
B(-7,15,0,174)
B(-7,15,1,174)
B(-7,15,2,174)
B(-7,15,3,174)
B(-7,15,4,174)
B(-7,15,5,174)
B(-7,15,6,174)
B(-7,16,-7,174)
B(-7,16,-6,174)
B(-7,16,-5,174)
B(-7,16,-4,174)
B(-7,16,-3,174)
B(-7,16,-2,174)
B(-7,16,-1,174)
B(-7,16,0,174)
B(-7,16,1,174)
B(-7,16,2,174)
B(-7,16,3,174)
B(-7,16,4,174)
B(-7,16,5,174)
B(-7,16,6,174)
B(-7,17,-7,174)
B(-7,17,-6,174)
B(-7,17,-5,174)
B(-7,17,-4,174)
B(-7,17,-3,174)
B(-7,17,-2,174)
B(-7,17,-1,174)
B(-7,17,0,174)
B(-7,17,1,174)
B(-7,17,2,174)
B(-7,17,3,174)
B(-7,17,4,174)
B(-7,17,5,174)
B(-7,17,6,174)
B(-7,18,-7,174)
B(-7,18,-6,174)
B(-7,18,-5,174)
B(-7,18,-4,174)
B(-7,18,-3,174)
B(-7,18,-2,174)
B(-7,18,-1,174)
B(-7,18,0,174)
B(-7,18,1,174)
B(-7,18,2,174)
B(-7,18,3,174)
B(-7,18,4,174)
B(-7,18,5,174)
B(-7,18,6,174)
B(-7,19,-7,174)
B(-7,19,-6,174)
B(-7,19,-5,174)
B(-7,19,-4,174)
B(-7,19,-3,174)
B(-7,19,-2,174)
B(-7,19,-1,174)
B(-7,19,0,174)
B(-7,19,1,174)
B(-7,19,2,174)
B(-7,19,3,174)
B(-7,19,4,174)
B(-7,19,5,174)
B(-7,19,6,174)
B(-7,20,-7,174)
B(-7,20,-6,174)
B(-7,20,-5,174)
B(-7,20,-4,174)
B(-7,20,-3,174)
B(-7,20,-2,174)
B(-7,20,-1,174)
B(-7,20,0,174)
B(-7,20,1,174)
B(-7,20,2,174)
B(-7,20,3,174)
B(-7,20,4,174)
B(-7,20,5,174)
B(-7,20,6,174)
B(-7,21,-7,174)
B(-7,21,-6,174)
B(-7,21,-5,174)
B(-7,21,-4,174)
B(-7,21,-3,174)
B(-7,21,-2,174)
B(-7,21,-1,174)
B(-7,21,0,174)
B(-7,21,1,174)
B(-7,21,2,174)
B(-7,21,3,174)
B(-7,21,4,174)
B(-7,21,5,174)
B(-7,21,6,174)
B(-7,22,0,174)
B(-7,22,1,174)
B(-7,22,2,174)
B(-7,22,3,174)
B(-7,22,4,174)
B(-7,22,5,174)
B(-7,22,6,174)
B(-7,23,1,174)
B(-7,23,2,174)
B(-7,23,3,174)
B(-7,23,4,174)
B(-7,23,5,174)
B(-7,23,6,174)
B(-7,24,2,174)
B(-7,24,3,174)
B(-7,24,4,174)
B(-7,24,5,174)
B(-7,25,3,174)
B(-7,25,4,174)
B(-7,25,5,174)
B(-7,56,-6,174)
B(-7,57,-6,174)
B(-7,58,-6,174)
B(-7,59,-6,174)
B(-7,60,-7,174)
B(-7,60,-6,174)
B(-7,60,-5,174)
B(-7,60,-4,174)
B(-7,60,-3,174)
B(-7,60,-2,174)
B(-7,60,-1,174)
B(-7,60,0,174)
B(-7,60,1,174)
B(-7,60,2,174)
B(-7,60,3,174)
B(-7,60,4,174)
B(-7,61,-7,174)
B(-7,61,-6,174)
B(-7,61,-5,174)
B(-7,61,-4,174)
B(-7,61,-3,174)
B(-7,61,-2,174)
B(-7,61,-1,174)
B(-7,61,0,174)
B(-7,61,1,174)
B(-7,61,2,174)
B(-7,61,3,174)
B(-7,61,4,174)
B(-7,61,5,174)
B(-7,62,-7,174)
B(-7,62,-6,174)
B(-7,62,-5,174)
B(-7,62,-4,174)
B(-7,62,-3,174)
B(-7,62,-2,174)
B(-7,62,-1,174)
B(-7,62,0,174)
B(-7,62,1,174)
B(-7,62,2,174)
B(-7,62,3,174)
B(-7,62,4,174)
B(-7,62,5,174)
B(-7,62,6,174)
B(-7,63,-7,174)
B(-7,63,-6,174)
B(-7,63,-5,174)
B(-7,63,-4,174)
B(-7,63,-3,174)
B(-7,63,-2,174)
B(-7,63,-1,174)
B(-7,63,0,174)
B(-7,63,1,174)
B(-7,63,2,174)
B(-7,63,3,174)
B(-7,63,4,174)
B(-7,63,5,174)
B(-7,63,6,174)
B(-7,64,-7,174)
B(-7,64,-6,174)
B(-7,64,-5,174)
B(-7,64,-4,174)
B(-7,64,-3,174)
B(-7,64,-2,174)
B(-7,64,-1,174)
B(-7,64,0,174)
B(-7,64,1,174)
B(-7,64,2,174)
B(-7,64,3,174)
B(-7,64,4,174)
B(-7,64,5,174)
B(-7,64,6,174)
B(-7,64,7,174)
B(-7,64,8,174)
B(-7,65,-7,174)
B(-7,65,-6,174)
B(-7,65,-5,174)
B(-7,65,-4,174)
B(-7,65,-3,174)
B(-7,65,-2,174)
B(-7,65,-1,174)
B(-7,65,0,174)
B(-7,65,1,174)
B(-7,65,2,174)
B(-7,65,3,174)
B(-7,65,4,174)
B(-7,65,5,174)
B(-7,65,6,174)
B(-7,65,7,174)
B(-7,65,8,174)
B(-7,66,-7,174)
B(-7,66,-6,174)
B(-7,66,-5,174)
B(-7,66,-4,174)
B(-7,66,-3,174)
B(-7,66,-2,174)
B(-7,66,-1,174)
B(-7,66,0,174)
B(-7,66,1,174)
B(-7,66,2,174)
B(-7,66,3,174)
B(-7,66,4,174)
B(-7,66,5,174)
B(-7,66,6,174)
B(-7,66,7,174)
B(-7,66,8,174)
B(-7,67,-7,174)
B(-7,67,-6,174)
B(-7,67,-5,174)
B(-7,67,-4,174)
B(-7,67,-3,174)
B(-7,67,-2,174)
B(-7,67,-1,174)
B(-7,67,0,174)
B(-7,67,1,174)
B(-7,67,2,174)
B(-7,67,3,174)
B(-7,67,4,174)
B(-7,67,5,174)
B(-7,67,6,174)
B(-7,67,7,174)
B(-7,67,8,174)
B(-7,68,-7,174)
B(-7,68,-6,174)
B(-7,68,-5,174)
B(-7,68,-4,174)
B(-7,68,-3,174)
B(-7,68,-2,174)
B(-7,68,-1,174)
B(-7,68,0,174)
B(-7,68,1,174)
B(-7,68,2,174)
B(-7,68,3,174)
B(-7,68,4,174)
B(-7,68,5,174)
B(-7,68,6,174)
B(-7,68,7,174)
B(-7,68,8,174)
B(-7,69,-7,174)
B(-7,69,-6,174)
B(-7,69,-5,174)
B(-7,69,-4,174)
B(-7,69,-3,174)
B(-7,69,-2,174)
B(-7,69,-1,174)
B(-7,69,0,174)
B(-7,69,1,174)
B(-7,69,2,174)
B(-7,69,3,174)
B(-7,69,4,174)
B(-7,69,5,174)
B(-7,69,6,174)
B(-7,69,7,174)
B(-7,69,8,174)
B(-7,70,-7,174)
B(-7,70,-6,174)
B(-7,70,0,174)
B(-7,70,1,174)
B(-7,70,2,174)
B(-7,70,3,174)
B(-7,70,4,174)
B(-7,70,5,174)
B(-7,70,6,174)
B(-7,70,7,174)
B(-7,70,8,174)
B(-7,71,5,174)
B(-7,71,6,174)
B(-7,71,7,174)
B(-7,71,8,174)
B(-7,72,6,174)
B(-7,72,7,174)
B(-7,72,8,174)
B(-6,11,-7,174)
B(-6,12,-7,174)
B(-6,12,-6,174)
B(-6,12,-5,174)
B(-6,12,-4,174)
B(-6,12,-1,174)
B(-6,12,0,174)
B(-6,12,1,174)
B(-6,12,2,174)
B(-6,13,-7,174)
B(-6,13,-6,174)
B(-6,13,-5,174)
B(-6,13,-4,174)
B(-6,13,-3,174)
B(-6,13,-2,174)
B(-6,13,-1,174)
B(-6,13,0,174)
B(-6,13,1,174)
B(-6,13,2,174)
B(-6,13,3,174)
B(-6,13,4,174)
B(-6,14,-7,174)
B(-6,14,-6,174)
B(-6,14,-5,174)
B(-6,14,-4,174)
B(-6,14,-3,174)
B(-6,14,-2,174)
B(-6,14,-1,174)
B(-6,14,0,174)
B(-6,14,1,174)
B(-6,14,2,174)
B(-6,14,3,174)
B(-6,14,4,174)
B(-6,14,5,174)
B(-6,15,-7,174)
B(-6,15,-6,174)
B(-6,15,-5,174)
B(-6,15,-4,174)
B(-6,15,-3,174)
B(-6,15,-2,174)
B(-6,15,-1,174)
B(-6,15,0,174)
B(-6,15,1,174)
B(-6,15,2,174)
B(-6,15,3,174)
B(-6,15,4,174)
B(-6,15,5,174)
B(-6,16,-7,174)
B(-6,16,-6,174)
B(-6,16,-5,174)
B(-6,16,-4,174)
B(-6,16,-3,174)
B(-6,16,-2,174)
B(-6,16,-1,174)
B(-6,16,0,174)
B(-6,16,1,174)
B(-6,16,2,174)
B(-6,16,3,174)
B(-6,16,4,174)
B(-6,16,5,174)
B(-6,17,-7,174)
B(-6,17,-6,174)
B(-6,17,-5,174)
B(-6,17,-4,174)
B(-6,17,-3,174)
B(-6,17,-2,174)
B(-6,17,-1,174)
B(-6,17,0,174)
B(-6,17,1,174)
B(-6,17,2,174)
B(-6,17,3,174)
B(-6,17,4,174)
B(-6,17,5,174)
B(-6,18,-7,174)
B(-6,18,-6,174)
B(-6,18,-5,174)
B(-6,18,-4,174)
B(-6,18,-3,174)
B(-6,18,-2,174)
B(-6,18,-1,174)
B(-6,18,0,174)
B(-6,18,1,174)
B(-6,18,2,174)
B(-6,18,3,174)
B(-6,18,4,174)
B(-6,18,5,174)
B(-6,19,-7,174)
B(-6,19,-6,174)
B(-6,19,-5,174)
B(-6,19,-4,174)
B(-6,19,-3,174)
B(-6,19,-2,174)
B(-6,19,-1,174)
B(-6,19,0,174)
B(-6,19,1,174)
B(-6,19,2,174)
B(-6,19,3,174)
B(-6,19,4,174)
B(-6,19,5,174)
B(-6,20,-7,174)
B(-6,20,-6,174)
B(-6,20,-5,174)
B(-6,20,-4,174)
B(-6,20,-3,174)
B(-6,20,-2,174)
B(-6,20,-1,174)
B(-6,20,0,174)
B(-6,20,1,174)
B(-6,20,2,174)
B(-6,20,3,174)
B(-6,20,4,174)
B(-6,21,-7,174)
B(-6,21,-6,174)
B(-6,21,-5,174)
B(-6,21,-4,174)
B(-6,21,-3,174)
B(-6,21,-2,174)
B(-6,21,-1,174)
B(-6,21,0,174)
B(-6,21,1,174)
B(-6,21,2,174)
B(-6,21,3,174)
B(-6,21,4,174)
B(-6,22,2,174)
B(-6,22,3,174)
B(-6,22,4,174)
B(-6,38,-2,174)
B(-6,38,-1,174)
B(-6,38,0,174)
B(-6,38,1,174)
B(-6,38,2,174)
B(-6,39,-4,174)
B(-6,39,-3,174)
B(-6,39,-2,174)
B(-6,39,-1,174)
B(-6,39,0,174)
B(-6,39,1,174)
B(-6,39,2,174)
B(-6,39,3,174)
B(-6,40,-4,174)
B(-6,40,-3,174)
B(-6,40,-2,174)
B(-6,40,-1,174)
B(-6,40,0,174)
B(-6,40,1,174)
B(-6,40,2,174)
B(-6,41,-4,174)
B(-6,41,0,174)
B(-6,57,0,174)
B(-6,58,0,174)
B(-6,59,-6,174)
B(-6,59,0,174)
B(-6,60,-7,174)
B(-6,60,-6,174)
B(-6,60,-5,174)
B(-6,60,-4,174)
B(-6,60,-3,174)
B(-6,60,-2,174)
B(-6,60,-1,174)
B(-6,60,0,174)
B(-6,61,-7,174)
B(-6,61,-6,174)
B(-6,61,-5,174)
B(-6,61,-4,174)
B(-6,61,-3,174)
B(-6,61,-2,174)
B(-6,61,-1,174)
B(-6,61,0,174)
B(-6,61,1,174)
B(-6,61,2,174)
B(-6,61,3,174)
B(-6,62,-7,174)
B(-6,62,-6,174)
B(-6,62,-5,174)
B(-6,62,-4,174)
B(-6,62,-3,174)
B(-6,62,-2,174)
B(-6,62,-1,174)
B(-6,62,0,174)
B(-6,62,1,174)
B(-6,62,2,174)
B(-6,62,3,174)
B(-6,62,4,174)
B(-6,62,5,174)
B(-6,63,-7,174)
B(-6,63,-6,174)
B(-6,63,-5,174)
B(-6,63,-4,174)
B(-6,63,-3,174)
B(-6,63,-2,174)
B(-6,63,-1,174)
B(-6,63,0,174)
B(-6,63,1,174)
B(-6,63,2,174)
B(-6,63,3,174)
B(-6,63,4,174)
B(-6,64,-7,174)
B(-6,64,-6,174)
B(-6,64,-5,174)
B(-6,64,-4,174)
B(-6,64,-3,174)
B(-6,64,-2,174)
B(-6,64,-1,174)
B(-6,64,0,174)
B(-6,64,1,174)
B(-6,64,2,174)
B(-6,64,3,174)
B(-6,64,4,174)
B(-6,64,5,174)
B(-6,64,6,174)
B(-6,64,8,174)
B(-6,65,-7,174)
B(-6,65,-6,174)
B(-6,65,-5,174)
B(-6,65,-4,174)
B(-6,65,-3,174)
B(-6,65,-2,174)
B(-6,65,-1,174)
B(-6,65,0,174)
B(-6,65,1,174)
B(-6,65,2,174)
B(-6,65,3,174)
B(-6,65,4,174)
B(-6,65,5,174)
B(-6,65,6,174)
B(-6,65,7,174)
B(-6,65,8,174)
B(-6,66,-7,174)
B(-6,66,-6,174)
B(-6,66,-5,174)
B(-6,66,-4,174)
B(-6,66,-3,174)
B(-6,66,-2,174)
B(-6,66,-1,174)
B(-6,66,0,174)
B(-6,66,1,174)
B(-6,66,2,174)
B(-6,66,3,174)
B(-6,66,4,174)
B(-6,66,5,174)
B(-6,66,6,174)
B(-6,66,7,174)
B(-6,66,8,174)
B(-6,67,-7,174)
B(-6,67,-6,174)
B(-6,67,-5,174)
B(-6,67,-4,174)
B(-6,67,-3,174)
B(-6,67,-2,174)
B(-6,67,-1,174)
B(-6,67,0,174)
B(-6,67,1,174)
B(-6,67,2,174)
B(-6,67,3,174)
B(-6,67,4,174)
B(-6,67,5,174)
B(-6,67,6,174)
B(-6,67,7,174)
B(-6,67,8,174)
B(-6,68,-7,174)
B(-6,68,-6,174)
B(-6,68,-5,174)
B(-6,68,-4,174)
B(-6,68,-3,174)
B(-6,68,-2,174)
B(-6,68,-1,174)
B(-6,68,0,174)
B(-6,68,1,174)
B(-6,68,2,174)
B(-6,68,3,174)
B(-6,68,4,174)
B(-6,68,5,174)
B(-6,68,6,174)
B(-6,68,7,174)
B(-6,68,8,174)
B(-6,69,-7,174)
B(-6,69,-6,174)
B(-6,69,-5,174)
B(-6,69,-4,174)
B(-6,69,-1,174)
B(-6,69,0,174)
B(-6,69,1,174)
B(-6,69,2,174)
B(-6,69,3,174)
B(-6,69,4,174)
B(-6,69,5,174)
B(-6,69,6,174)
B(-6,69,7,174)
B(-6,69,8,174)
B(-6,70,-7,174)
B(-6,70,0,174)
B(-6,70,1,174)
B(-6,70,2,174)
B(-6,70,3,174)
B(-6,70,4,174)
B(-6,70,5,174)
B(-6,70,6,174)
B(-6,70,7,174)
B(-6,70,8,174)
B(-5,12,-7,174)
B(-5,12,-6,174)
B(-5,12,-5,174)
B(-5,13,-7,174)
B(-5,13,-6,174)
B(-5,13,-5,174)
B(-5,13,-4,174)
B(-5,13,-3,174)
B(-5,13,-2,174)
B(-5,13,-1,174)
B(-5,13,0,174)
B(-5,13,1,174)
B(-5,13,2,174)
B(-5,14,-7,174)
B(-5,14,-6,174)
B(-5,14,-5,174)
B(-5,14,-4,174)
B(-5,14,-3,174)
B(-5,14,-2,174)
B(-5,14,-1,174)
B(-5,14,0,174)
B(-5,14,1,174)
B(-5,14,2,174)
B(-5,15,-7,174)
B(-5,15,-6,174)
B(-5,15,-5,174)
B(-5,15,-4,174)
B(-5,15,-3,174)
B(-5,15,-2,174)
B(-5,15,-1,174)
B(-5,15,0,174)
B(-5,15,1,174)
B(-5,15,2,174)
B(-5,16,-7,174)
B(-5,16,-6,174)
B(-5,16,-5,174)
B(-5,16,-4,174)
B(-5,16,-3,174)
B(-5,16,-2,174)
B(-5,16,-1,174)
B(-5,16,0,174)
B(-5,16,1,174)
B(-5,16,2,174)
B(-5,17,-7,174)
B(-5,17,-6,174)
B(-5,17,-5,174)
B(-5,17,-4,174)
B(-5,17,-3,174)
B(-5,17,-2,174)
B(-5,17,-1,174)
B(-5,17,0,174)
B(-5,17,1,174)
B(-5,17,2,174)
B(-5,17,3,174)
B(-5,18,-7,174)
B(-5,18,-6,174)
B(-5,18,-5,174)
B(-5,18,-4,174)
B(-5,18,-3,174)
B(-5,18,-2,174)
B(-5,18,-1,174)
B(-5,18,0,174)
B(-5,18,1,174)
B(-5,18,2,174)
B(-5,18,3,174)
B(-5,19,-7,174)
B(-5,19,-6,174)
B(-5,19,-5,174)
B(-5,19,-4,174)
B(-5,19,-3,174)
B(-5,19,-2,174)
B(-5,19,-1,174)
B(-5,19,0,174)
B(-5,19,1,174)
B(-5,19,2,174)
B(-5,19,3,174)
B(-5,20,-7,174)
B(-5,20,-6,174)
B(-5,20,-5,174)
B(-5,20,-4,174)
B(-5,20,-3,174)
B(-5,20,-2,174)
B(-5,20,-1,174)
B(-5,20,0,174)
B(-5,20,1,174)
B(-5,20,2,174)
B(-5,20,3,174)
B(-5,21,-7,174)
B(-5,21,-6,174)
B(-5,21,-5,174)
B(-5,21,-4,174)
B(-5,21,-3,174)
B(-5,21,-2,174)
B(-5,21,-1,174)
B(-5,21,0,174)
B(-5,21,1,174)
B(-5,21,2,174)
B(-5,21,3,174)
B(-5,22,-7,174)
B(-5,22,-6,174)
B(-5,22,-5,174)
B(-5,34,-2,174)
B(-5,34,-1,174)
B(-5,34,0,174)
B(-5,34,1,174)
B(-5,34,2,174)
B(-5,34,3,174)
B(-5,35,-4,174)
B(-5,35,-3,174)
B(-5,35,-2,174)
B(-5,35,-1,174)
B(-5,35,0,174)
B(-5,35,1,174)
B(-5,35,2,174)
B(-5,35,3,174)
B(-5,35,4,174)
B(-5,36,-5,174)
B(-5,36,-4,174)
B(-5,36,-3,174)
B(-5,36,-2,174)
B(-5,36,-1,174)
B(-5,36,0,174)
B(-5,36,1,174)
B(-5,36,2,174)
B(-5,36,3,174)
B(-5,36,4,174)
B(-5,37,-5,174)
B(-5,37,-4,174)
B(-5,37,-3,174)
B(-5,37,-2,174)
B(-5,37,-1,174)
B(-5,37,0,174)
B(-5,37,1,174)
B(-5,37,2,174)
B(-5,37,3,174)
B(-5,37,4,174)
B(-5,37,5,174)
B(-5,38,-5,174)
B(-5,38,-4,174)
B(-5,38,-3,174)
B(-5,38,-2,174)
B(-5,38,-1,174)
B(-5,38,0,174)
B(-5,38,1,174)
B(-5,38,2,174)
B(-5,38,3,174)
B(-5,38,4,174)
B(-5,38,5,174)
B(-5,38,8,174)
B(-5,39,-5,174)
B(-5,39,-4,174)
B(-5,39,-3,174)
B(-5,39,-2,174)
B(-5,39,-1,174)
B(-5,39,0,174)
B(-5,39,1,174)
B(-5,39,2,174)
B(-5,39,3,174)
B(-5,39,4,174)
B(-5,39,5,174)
B(-5,39,6,174)
B(-5,39,7,174)
B(-5,40,-5,174)
B(-5,40,-4,174)
B(-5,40,-3,174)
B(-5,40,-2,174)
B(-5,40,-1,174)
B(-5,40,0,174)
B(-5,40,1,174)
B(-5,40,2,174)
B(-5,40,3,174)
B(-5,40,4,174)
B(-5,40,5,174)
B(-5,40,6,174)
B(-5,41,-5,174)
B(-5,41,-4,174)
B(-5,41,-3,174)
B(-5,41,-2,174)
B(-5,41,-1,174)
B(-5,41,0,174)
B(-5,41,1,174)
B(-5,41,2,174)
B(-5,41,3,174)
B(-5,41,4,174)
B(-5,41,6,174)
B(-5,42,-5,174)
B(-5,42,-4,174)
B(-5,42,-3,174)
B(-5,42,-2,174)
B(-5,42,-1,174)
B(-5,42,0,174)
B(-5,42,1,174)
B(-5,42,2,174)
B(-5,42,3,174)
B(-5,43,-1,174)
B(-5,43,0,174)
B(-5,43,1,174)
B(-5,43,2,174)
B(-5,44,2,174)
B(-5,59,-7,174)
B(-5,59,-6,174)
B(-5,59,-5,174)
B(-5,60,-7,174)
B(-5,60,-6,174)
B(-5,60,-5,174)
B(-5,60,-4,174)
B(-5,60,-3,174)
B(-5,60,-2,174)
B(-5,60,-1,174)
B(-5,61,-7,174)
B(-5,61,-6,174)
B(-5,61,-5,174)
B(-5,61,-4,174)
B(-5,61,-3,174)
B(-5,61,-2,174)
B(-5,61,-1,174)
B(-5,61,0,174)
B(-5,61,1,174)
B(-5,61,2,174)
B(-5,62,-7,174)
B(-5,62,-6,174)
B(-5,62,-5,174)
B(-5,62,-4,174)
B(-5,62,-3,174)
B(-5,62,-2,174)
B(-5,62,-1,174)
B(-5,62,0,174)
B(-5,62,1,174)
B(-5,62,2,174)
B(-5,62,3,174)
B(-5,63,-7,174)
B(-5,63,-6,174)
B(-5,63,-5,174)
B(-5,63,-4,174)
B(-5,63,-3,174)
B(-5,63,-2,174)
B(-5,63,-1,174)
B(-5,63,0,174)
B(-5,63,1,174)
B(-5,63,2,174)
B(-5,63,3,174)
B(-5,64,-7,174)
B(-5,64,-6,174)
B(-5,64,-5,174)
B(-5,64,-4,174)
B(-5,64,-3,174)
B(-5,64,-2,174)
B(-5,64,-1,174)
B(-5,64,0,174)
B(-5,64,1,174)
B(-5,64,2,174)
B(-5,64,3,174)
B(-5,64,4,174)
B(-5,64,5,174)
B(-5,64,6,174)
B(-5,64,7,174)
B(-5,65,-7,174)
B(-5,65,-6,174)
B(-5,65,-5,174)
B(-5,65,-4,174)
B(-5,65,-3,174)
B(-5,65,-2,174)
B(-5,65,-1,174)
B(-5,65,0,174)
B(-5,65,1,174)
B(-5,65,2,174)
B(-5,65,3,174)
B(-5,65,4,174)
B(-5,65,5,174)
B(-5,65,6,174)
B(-5,65,7,174)
B(-5,65,8,174)
B(-5,66,-7,174)
B(-5,66,-6,174)
B(-5,66,-5,174)
B(-5,66,-4,174)
B(-5,66,-3,174)
B(-5,66,-2,174)
B(-5,66,-1,174)
B(-5,66,0,174)
B(-5,66,1,174)
B(-5,66,2,174)
B(-5,66,3,174)
B(-5,66,4,174)
B(-5,66,5,174)
B(-5,66,6,174)
B(-5,66,7,174)
B(-5,66,8,174)
B(-5,67,-7,174)
B(-5,67,-6,174)
B(-5,67,-5,174)
B(-5,67,-4,174)
B(-5,67,-3,174)
B(-5,67,-2,174)
B(-5,67,-1,174)
B(-5,67,0,174)
B(-5,67,1,174)
B(-5,67,2,174)
B(-5,67,3,174)
B(-5,67,4,174)
B(-5,67,5,174)
B(-5,67,6,174)
B(-5,67,7,174)
B(-5,67,8,174)
B(-5,68,-7,174)
B(-5,68,-6,174)
B(-5,68,-5,174)
B(-5,68,-4,174)
B(-5,68,-3,174)
B(-5,68,-2,174)
B(-5,68,-1,174)
B(-5,68,0,174)
B(-5,68,1,174)
B(-5,68,2,174)
B(-5,68,3,174)
B(-5,68,4,174)
B(-5,68,5,174)
B(-5,68,6,174)
B(-5,68,7,174)
B(-5,68,8,174)
B(-5,69,-7,174)
B(-5,69,-6,174)
B(-5,69,-5,174)
B(-5,69,-1,174)
B(-5,69,0,174)
B(-5,69,1,174)
B(-5,69,2,174)
B(-5,69,3,174)
B(-5,69,4,174)
B(-5,69,5,174)
B(-5,69,6,174)
B(-5,69,7,174)
B(-5,69,8,174)
B(-5,70,0,174)
B(-5,70,1,174)
B(-5,70,2,174)
B(-5,70,3,174)
B(-5,70,4,174)
B(-5,70,5,174)
B(-5,70,6,174)
B(-5,70,7,174)
B(-4,13,-7,174)
B(-4,13,-6,174)
B(-4,13,-5,174)
B(-4,13,-4,174)
B(-4,13,-2,174)
B(-4,13,-1,174)
B(-4,13,0,174)
B(-4,13,1,174)
B(-4,14,-7,174)
B(-4,14,-6,174)
B(-4,14,-5,174)
B(-4,14,-4,174)
B(-4,14,-3,174)
B(-4,14,-2,174)
B(-4,14,-1,174)
B(-4,14,0,174)
B(-4,14,1,174)
B(-4,14,2,174)
B(-4,15,-7,174)
B(-4,15,-6,174)
B(-4,15,-5,174)
B(-4,15,-4,174)
B(-4,15,-3,174)
B(-4,15,-2,174)
B(-4,15,-1,174)
B(-4,15,0,174)
B(-4,15,1,174)
B(-4,15,2,174)
B(-4,16,-7,174)
B(-4,16,-6,174)
B(-4,16,-5,174)
B(-4,16,-4,174)
B(-4,16,-3,174)
B(-4,16,-2,174)
B(-4,16,-1,174)
B(-4,16,0,174)
B(-4,16,1,174)
B(-4,16,2,174)
B(-4,17,-7,174)
B(-4,17,-6,174)
B(-4,17,-5,174)
B(-4,17,-4,174)
B(-4,17,-3,174)
B(-4,17,-2,174)
B(-4,17,-1,174)
B(-4,17,0,174)
B(-4,17,1,174)
B(-4,17,2,174)
B(-4,18,-7,174)
B(-4,18,-6,174)
B(-4,18,-5,174)
B(-4,18,-4,174)
B(-4,18,-3,174)
B(-4,18,-2,174)
B(-4,18,-1,174)
B(-4,18,0,174)
B(-4,18,1,174)
B(-4,18,2,174)
B(-4,18,3,174)
B(-4,19,-7,174)
B(-4,19,-6,174)
B(-4,19,-5,174)
B(-4,19,-4,174)
B(-4,19,-3,174)
B(-4,19,-2,174)
B(-4,19,-1,174)
B(-4,19,0,174)
B(-4,19,1,174)
B(-4,19,2,174)
B(-4,19,3,174)
B(-4,20,-7,174)
B(-4,20,-6,174)
B(-4,20,-5,174)
B(-4,20,-4,174)
B(-4,20,-3,174)
B(-4,20,-2,174)
B(-4,20,-1,174)
B(-4,20,0,174)
B(-4,20,1,174)
B(-4,20,2,174)
B(-4,20,3,174)
B(-4,21,-7,174)
B(-4,21,-6,174)
B(-4,21,-5,174)
B(-4,21,-4,174)
B(-4,21,-3,174)
B(-4,21,-2,174)
B(-4,21,-1,174)
B(-4,21,0,174)
B(-4,21,1,174)
B(-4,22,-7,174)
B(-4,22,-6,174)
B(-4,22,-5,174)
B(-4,22,-4,174)
B(-4,32,-2,174)
B(-4,32,-1,174)
B(-4,32,0,174)
B(-4,33,-4,174)
B(-4,33,-3,174)
B(-4,33,-2,174)
B(-4,33,-1,174)
B(-4,33,0,174)
B(-4,33,1,174)
B(-4,33,2,174)
B(-4,33,3,174)
B(-4,33,4,174)
B(-4,34,-5,174)
B(-4,34,-4,174)
B(-4,34,-3,174)
B(-4,34,-2,174)
B(-4,34,-1,174)
B(-4,34,0,174)
B(-4,34,1,174)
B(-4,34,2,174)
B(-4,34,3,174)
B(-4,34,4,174)
B(-4,34,5,174)
B(-4,35,-6,174)
B(-4,35,-5,174)
B(-4,35,-4,174)
B(-4,35,-3,174)
B(-4,35,-2,174)
B(-4,35,-1,174)
B(-4,35,0,174)
B(-4,35,1,174)
B(-4,35,2,174)
B(-4,35,3,174)
B(-4,35,4,174)
B(-4,35,5,174)
B(-4,35,6,174)
B(-4,35,7,174)
B(-4,35,8,174)
B(-4,36,-7,174)
B(-4,36,-6,174)
B(-4,36,-5,174)
B(-4,36,-4,174)
B(-4,36,-3,174)
B(-4,36,-2,174)
B(-4,36,-1,174)
B(-4,36,0,174)
B(-4,36,1,174)
B(-4,36,2,174)
B(-4,36,3,174)
B(-4,36,4,174)
B(-4,36,5,174)
B(-4,36,6,174)
B(-4,36,7,174)
B(-4,36,8,174)
B(-4,37,-7,174)
B(-4,37,-6,174)
B(-4,37,-5,174)
B(-4,37,-4,174)
B(-4,37,-3,174)
B(-4,37,-2,174)
B(-4,37,-1,174)
B(-4,37,0,174)
B(-4,37,1,174)
B(-4,37,2,174)
B(-4,37,3,174)
B(-4,37,4,174)
B(-4,37,5,174)
B(-4,37,6,174)
B(-4,37,7,174)
B(-4,37,8,174)
B(-4,38,-7,174)
B(-4,38,-6,174)
B(-4,38,-5,174)
B(-4,38,-4,174)
B(-4,38,-3,174)
B(-4,38,-2,174)
B(-4,38,-1,174)
B(-4,38,0,174)
B(-4,38,1,174)
B(-4,38,2,174)
B(-4,38,3,174)
B(-4,38,4,174)
B(-4,38,5,174)
B(-4,38,6,174)
B(-4,38,7,174)
B(-4,38,8,174)
B(-4,39,-6,174)
B(-4,39,-5,174)
B(-4,39,-4,174)
B(-4,39,-3,174)
B(-4,39,-2,174)
B(-4,39,-1,174)
B(-4,39,0,174)
B(-4,39,1,174)
B(-4,39,2,174)
B(-4,39,3,174)
B(-4,39,4,174)
B(-4,39,5,174)
B(-4,39,6,174)
B(-4,39,7,174)
B(-4,39,8,174)
B(-4,40,-5,174)
B(-4,40,-4,174)
B(-4,40,-3,174)
B(-4,40,-2,174)
B(-4,40,-1,174)
B(-4,40,0,174)
B(-4,40,1,174)
B(-4,40,2,174)
B(-4,40,3,174)
B(-4,40,4,174)
B(-4,40,5,174)
B(-4,40,6,174)
B(-4,40,7,174)
B(-4,40,8,174)
B(-4,41,-5,174)
B(-4,41,-4,174)
B(-4,41,-3,174)
B(-4,41,-2,174)
B(-4,41,-1,174)
B(-4,41,0,174)
B(-4,41,1,174)
B(-4,41,2,174)
B(-4,41,3,174)
B(-4,41,4,174)
B(-4,41,5,174)
B(-4,41,6,174)
B(-4,41,7,174)
B(-4,41,8,174)
B(-4,42,-5,174)
B(-4,42,-4,174)
B(-4,42,-3,174)
B(-4,42,-2,174)
B(-4,42,-1,174)
B(-4,42,0,174)
B(-4,42,1,174)
B(-4,42,2,174)
B(-4,42,3,174)
B(-4,42,4,174)
B(-4,42,5,174)
B(-4,42,6,174)
B(-4,43,-5,174)
B(-4,43,-4,174)
B(-4,43,-3,174)
B(-4,43,-2,174)
B(-4,43,-1,174)
B(-4,43,0,174)
B(-4,43,1,174)
B(-4,43,2,174)
B(-4,43,3,174)
B(-4,43,4,174)
B(-4,43,5,174)
B(-4,44,-3,174)
B(-4,44,-2,174)
B(-4,44,-1,174)
B(-4,44,0,174)
B(-4,44,1,174)
B(-4,44,2,174)
B(-4,44,4,174)
B(-4,44,5,174)
B(-4,45,-3,174)
B(-4,45,-2,174)
B(-4,45,-1,174)
B(-4,45,0,174)
B(-4,45,1,174)
B(-4,45,5,174)
B(-4,46,-2,174)
B(-4,46,-1,174)
B(-4,47,-2,174)
B(-4,55,3,174)
B(-4,56,3,174)
B(-4,57,-1,174)
B(-4,57,3,174)
B(-4,58,-1,174)
B(-4,58,3,174)
B(-4,59,-7,174)
B(-4,59,-6,174)
B(-4,59,-5,174)
B(-4,59,-4,174)
B(-4,59,-1,174)
B(-4,59,3,174)
B(-4,60,-7,174)
B(-4,60,-6,174)
B(-4,60,-5,174)
B(-4,60,-4,174)
B(-4,60,-3,174)
B(-4,60,-2,174)
B(-4,60,-1,174)
B(-4,60,0,174)
B(-4,60,3,174)
B(-4,61,-7,174)
B(-4,61,-6,174)
B(-4,61,-5,174)
B(-4,61,-4,174)
B(-4,61,-3,174)
B(-4,61,-2,174)
B(-4,61,-1,174)
B(-4,61,0,174)
B(-4,61,1,174)
B(-4,61,2,174)
B(-4,61,3,174)
B(-4,62,-7,174)
B(-4,62,-6,174)
B(-4,62,-5,174)
B(-4,62,-4,174)
B(-4,62,-3,174)
B(-4,62,-2,174)
B(-4,62,-1,174)
B(-4,62,0,174)
B(-4,62,1,174)
B(-4,62,2,174)
B(-4,62,3,174)
B(-4,63,-7,174)
B(-4,63,-6,174)
B(-4,63,-5,174)
B(-4,63,-4,174)
B(-4,63,-3,174)
B(-4,63,-2,174)
B(-4,63,-1,174)
B(-4,63,0,174)
B(-4,63,1,174)
B(-4,63,2,174)
B(-4,63,3,174)
B(-4,63,5,174)
B(-4,64,-7,174)
B(-4,64,-6,174)
B(-4,64,-5,174)
B(-4,64,-4,174)
B(-4,64,-3,174)
B(-4,64,-2,174)
B(-4,64,-1,174)
B(-4,64,0,174)
B(-4,64,1,174)
B(-4,64,2,174)
B(-4,64,3,174)
B(-4,64,4,174)
B(-4,64,5,174)
B(-4,64,6,174)
B(-4,64,7,174)
B(-4,65,-7,174)
B(-4,65,-6,174)
B(-4,65,-5,174)
B(-4,65,-4,174)
B(-4,65,-3,174)
B(-4,65,-2,174)
B(-4,65,-1,174)
B(-4,65,0,174)
B(-4,65,1,174)
B(-4,65,2,174)
B(-4,65,3,174)
B(-4,65,4,174)
B(-4,65,5,174)
B(-4,65,6,174)
B(-4,65,7,174)
B(-4,65,8,174)
B(-4,66,-7,174)
B(-4,66,-6,174)
B(-4,66,-5,174)
B(-4,66,-4,174)
B(-4,66,-3,174)
B(-4,66,-2,174)
B(-4,66,-1,174)
B(-4,66,0,174)
B(-4,66,1,174)
B(-4,66,2,174)
B(-4,66,3,174)
B(-4,66,4,174)
B(-4,66,5,174)
B(-4,66,6,174)
B(-4,66,7,174)
B(-4,66,8,174)
B(-4,67,-7,174)
B(-4,67,-6,174)
B(-4,67,-5,174)
B(-4,67,-4,174)
B(-4,67,-3,174)
B(-4,67,-2,174)
B(-4,67,-1,174)
B(-4,67,0,174)
B(-4,67,1,174)
B(-4,67,2,174)
B(-4,67,3,174)
B(-4,67,4,174)
B(-4,67,5,174)
B(-4,67,6,174)
B(-4,67,7,174)
B(-4,67,8,174)
B(-4,68,-7,174)
B(-4,68,-6,174)
B(-4,68,-5,174)
B(-4,68,-4,174)
B(-4,68,-2,174)
B(-4,68,-1,174)
B(-4,68,0,174)
B(-4,68,1,174)
B(-4,68,2,174)
B(-4,68,3,174)
B(-4,68,4,174)
B(-4,68,5,174)
B(-4,68,6,174)
B(-4,68,7,174)
B(-4,68,8,174)
B(-4,69,-1,174)
B(-4,69,0,174)
B(-4,69,1,174)
B(-4,69,2,174)
B(-4,69,3,174)
B(-4,69,4,174)
B(-4,69,5,174)
B(-4,69,6,174)
B(-4,69,7,174)
B(-4,70,0,174)
B(-4,70,1,174)
B(-4,70,2,174)
B(-4,70,3,174)
B(-4,70,4,174)
B(-4,70,5,174)
B(-4,70,6,174)
B(-4,70,7,174)
B(-3,14,-7,174)
B(-3,14,-6,174)
B(-3,14,-5,174)
B(-3,14,-4,174)
B(-3,14,-3,174)
B(-3,14,-2,174)
B(-3,14,-1,174)
B(-3,14,0,174)
B(-3,14,1,174)
B(-3,15,-7,174)
B(-3,15,-6,174)
B(-3,15,-5,174)
B(-3,15,-4,174)
B(-3,15,-3,174)
B(-3,15,-2,174)
B(-3,15,-1,174)
B(-3,15,0,174)
B(-3,15,1,174)
B(-3,16,-7,174)
B(-3,16,-6,174)
B(-3,16,-5,174)
B(-3,16,-4,174)
B(-3,16,-3,174)
B(-3,16,-2,174)
B(-3,16,-1,174)
B(-3,16,0,174)
B(-3,16,1,174)
B(-3,16,2,174)
B(-3,17,-7,174)
B(-3,17,-6,174)
B(-3,17,-5,174)
B(-3,17,-4,174)
B(-3,17,-3,174)
B(-3,17,-2,174)
B(-3,17,-1,174)
B(-3,17,0,174)
B(-3,17,1,174)
B(-3,17,2,174)
B(-3,18,-7,174)
B(-3,18,-6,174)
B(-3,18,-5,174)
B(-3,18,-4,174)
B(-3,18,-3,174)
B(-3,18,-2,174)
B(-3,18,-1,174)
B(-3,18,0,174)
B(-3,18,1,174)
B(-3,18,2,174)
B(-3,19,-7,174)
B(-3,19,-6,174)
B(-3,19,-5,174)
B(-3,19,-4,174)
B(-3,19,-3,174)
B(-3,19,-2,174)
B(-3,19,-1,174)
B(-3,19,0,174)
B(-3,19,1,174)
B(-3,19,2,174)
B(-3,20,-7,174)
B(-3,20,-6,174)
B(-3,20,-5,174)
B(-3,20,-4,174)
B(-3,20,-3,174)
B(-3,20,-2,174)
B(-3,20,-1,174)
B(-3,20,0,174)
B(-3,20,1,174)
B(-3,20,2,174)
B(-3,21,-7,174)
B(-3,21,-6,174)
B(-3,21,-5,174)
B(-3,21,-4,174)
B(-3,21,-3,174)
B(-3,21,-2,174)
B(-3,21,-1,174)
B(-3,21,0,174)
B(-3,22,-7,174)
B(-3,22,-6,174)
B(-3,22,-5,174)
B(-3,22,-4,174)
B(-3,22,-3,174)
B(-3,30,-2,174)
B(-3,30,-1,174)
B(-3,30,0,174)
B(-3,31,-4,174)
B(-3,31,-3,174)
B(-3,31,-2,174)
B(-3,31,-1,174)
B(-3,31,0,174)
B(-3,31,1,174)
B(-3,31,2,174)
B(-3,31,3,174)
B(-3,32,-5,174)
B(-3,32,-4,174)
B(-3,32,-3,174)
B(-3,32,-2,174)
B(-3,32,-1,174)
B(-3,32,0,174)
B(-3,32,1,174)
B(-3,32,2,174)
B(-3,32,3,174)
B(-3,32,4,174)
B(-3,32,5,174)
B(-3,32,6,174)
B(-3,33,-6,174)
B(-3,33,-5,174)
B(-3,33,-4,174)
B(-3,33,-3,174)
B(-3,33,-2,174)
B(-3,33,-1,174)
B(-3,33,0,174)
B(-3,33,1,174)
B(-3,33,2,174)
B(-3,33,3,174)
B(-3,33,4,174)
B(-3,33,5,174)
B(-3,33,6,174)
B(-3,34,-7,174)
B(-3,34,-6,174)
B(-3,34,-5,174)
B(-3,34,-4,174)
B(-3,34,-3,174)
B(-3,34,-2,174)
B(-3,34,-1,174)
B(-3,34,0,174)
B(-3,34,1,174)
B(-3,34,2,174)
B(-3,34,3,174)
B(-3,34,4,174)
B(-3,34,5,174)
B(-3,34,6,174)
B(-3,34,7,174)
B(-3,34,8,174)
B(-3,35,-7,174)
B(-3,35,-6,174)
B(-3,35,-5,174)
B(-3,35,-4,174)
B(-3,35,-3,174)
B(-3,35,-2,174)
B(-3,35,-1,174)
B(-3,35,0,174)
B(-3,35,1,174)
B(-3,35,2,174)
B(-3,35,3,174)
B(-3,35,4,174)
B(-3,35,5,174)
B(-3,35,6,174)
B(-3,35,7,174)
B(-3,35,8,174)
B(-3,36,-7,174)
B(-3,36,-6,174)
B(-3,36,-5,174)
B(-3,36,-4,174)
B(-3,36,-3,174)
B(-3,36,-2,174)
B(-3,36,-1,174)
B(-3,36,0,174)
B(-3,36,1,174)
B(-3,36,2,174)
B(-3,36,3,174)
B(-3,36,4,174)
B(-3,36,5,174)
B(-3,36,6,174)
B(-3,36,7,174)
B(-3,36,8,174)
B(-3,37,-7,174)
B(-3,37,-6,174)
B(-3,37,-5,174)
B(-3,37,-4,174)
B(-3,37,-3,174)
B(-3,37,-2,174)
B(-3,37,-1,174)
B(-3,37,0,174)
B(-3,37,1,174)
B(-3,37,2,174)
B(-3,37,3,174)
B(-3,37,4,174)
B(-3,37,5,174)
B(-3,37,6,174)
B(-3,37,7,174)
B(-3,37,8,174)
B(-3,38,-7,174)
B(-3,38,-6,174)
B(-3,38,-5,174)
B(-3,38,-4,174)
B(-3,38,-3,174)
B(-3,38,-2,174)
B(-3,38,-1,174)
B(-3,38,0,174)
B(-3,38,1,174)
B(-3,38,2,174)
B(-3,38,3,174)
B(-3,38,4,174)
B(-3,38,5,174)
B(-3,38,6,174)
B(-3,38,7,174)
B(-3,38,8,174)
B(-3,39,-7,174)
B(-3,39,-6,174)
B(-3,39,-5,174)
B(-3,39,-4,174)
B(-3,39,-3,174)
B(-3,39,-2,174)
B(-3,39,-1,174)
B(-3,39,0,174)
B(-3,39,1,174)
B(-3,39,2,174)
B(-3,39,3,174)
B(-3,39,4,174)
B(-3,39,5,174)
B(-3,39,6,174)
B(-3,39,7,174)
B(-3,39,8,174)
B(-3,40,-7,174)
B(-3,40,-6,174)
B(-3,40,-5,174)
B(-3,40,-4,174)
B(-3,40,-3,174)
B(-3,40,-2,174)
B(-3,40,-1,174)
B(-3,40,0,174)
B(-3,40,1,174)
B(-3,40,2,174)
B(-3,40,3,174)
B(-3,40,4,174)
B(-3,40,5,174)
B(-3,40,6,174)
B(-3,40,7,174)
B(-3,40,8,174)
B(-3,41,-7,174)
B(-3,41,-6,174)
B(-3,41,-5,174)
B(-3,41,-4,174)
B(-3,41,-3,174)
B(-3,41,-2,174)
B(-3,41,-1,174)
B(-3,41,0,174)
B(-3,41,1,174)
B(-3,41,2,174)
B(-3,41,3,174)
B(-3,41,4,174)
B(-3,41,5,174)
B(-3,41,6,174)
B(-3,41,7,174)
B(-3,41,8,174)
B(-3,42,-7,174)
B(-3,42,-6,174)
B(-3,42,-5,174)
B(-3,42,-4,174)
B(-3,42,-3,174)
B(-3,42,-2,174)
B(-3,42,-1,174)
B(-3,42,0,174)
B(-3,42,1,174)
B(-3,42,2,174)
B(-3,42,3,174)
B(-3,42,4,174)
B(-3,42,5,174)
B(-3,42,6,174)
B(-3,42,7,174)
B(-3,42,8,174)
B(-3,43,-7,174)
B(-3,43,-6,174)
B(-3,43,-5,174)
B(-3,43,-4,174)
B(-3,43,-3,174)
B(-3,43,-2,174)
B(-3,43,-1,174)
B(-3,43,0,174)
B(-3,43,1,174)
B(-3,43,2,174)
B(-3,43,3,174)
B(-3,43,4,174)
B(-3,43,5,174)
B(-3,43,6,174)
B(-3,43,7,174)
B(-3,44,-7,174)
B(-3,44,-6,174)
B(-3,44,-5,174)
B(-3,44,-4,174)
B(-3,44,-3,174)
B(-3,44,-2,174)
B(-3,44,-1,174)
B(-3,44,0,174)
B(-3,44,1,174)
B(-3,44,2,174)
B(-3,44,3,174)
B(-3,44,4,174)
B(-3,44,5,174)
B(-3,44,6,174)
B(-3,45,-5,174)
B(-3,45,-4,174)
B(-3,45,-3,174)
B(-3,45,-2,174)
B(-3,45,-1,174)
B(-3,45,0,174)
B(-3,45,1,174)
B(-3,45,2,174)
B(-3,45,3,174)
B(-3,45,4,174)
B(-3,45,5,174)
B(-3,45,6,174)
B(-3,46,-4,174)
B(-3,46,-3,174)
B(-3,46,-2,174)
B(-3,46,-1,174)
B(-3,46,0,174)
B(-3,46,1,174)
B(-3,46,2,174)
B(-3,46,4,174)
B(-3,46,5,174)
B(-3,47,-6,174)
B(-3,47,-5,174)
B(-3,47,-4,174)
B(-3,47,-3,174)
B(-3,47,-2,174)
B(-3,47,-1,174)
B(-3,47,0,174)
B(-3,48,-4,174)
B(-3,48,-3,174)
B(-3,48,-2,174)
B(-3,48,-1,174)
B(-3,48,0,174)
B(-3,49,0,174)
B(-3,59,-7,174)
B(-3,59,-6,174)
B(-3,59,-5,174)
B(-3,59,-4,174)
B(-3,59,7,174)
B(-3,60,-7,174)
B(-3,60,-6,174)
B(-3,60,-5,174)
B(-3,60,-4,174)
B(-3,60,-3,174)
B(-3,60,-2,174)
B(-3,60,-1,174)
B(-3,60,0,174)
B(-3,60,7,174)
B(-3,61,-7,174)
B(-3,61,-6,174)
B(-3,61,-5,174)
B(-3,61,-4,174)
B(-3,61,-3,174)
B(-3,61,-2,174)
B(-3,61,-1,174)
B(-3,61,0,174)
B(-3,61,1,174)
B(-3,61,7,174)
B(-3,62,-7,174)
B(-3,62,-6,174)
B(-3,62,-5,174)
B(-3,62,-4,174)
B(-3,62,-3,174)
B(-3,62,-2,174)
B(-3,62,-1,174)
B(-3,62,0,174)
B(-3,62,1,174)
B(-3,62,2,174)
B(-3,62,3,174)
B(-3,62,7,174)
B(-3,63,-7,174)
B(-3,63,-6,174)
B(-3,63,-5,174)
B(-3,63,-4,174)
B(-3,63,-3,174)
B(-3,63,-2,174)
B(-3,63,-1,174)
B(-3,63,0,174)
B(-3,63,1,174)
B(-3,63,2,174)
B(-3,63,3,174)
B(-3,63,4,174)
B(-3,63,7,174)
B(-3,64,-7,174)
B(-3,64,-6,174)
B(-3,64,-5,174)
B(-3,64,-4,174)
B(-3,64,-3,174)
B(-3,64,-2,174)
B(-3,64,-1,174)
B(-3,64,0,174)
B(-3,64,1,174)
B(-3,64,2,174)
B(-3,64,3,174)
B(-3,64,4,174)
B(-3,64,5,174)
B(-3,64,6,174)
B(-3,64,7,174)
B(-3,65,-7,174)
B(-3,65,-6,174)
B(-3,65,-5,174)
B(-3,65,-4,174)
B(-3,65,-3,174)
B(-3,65,-2,174)
B(-3,65,-1,174)
B(-3,65,0,174)
B(-3,65,1,174)
B(-3,65,2,174)
B(-3,65,3,174)
B(-3,65,4,174)
B(-3,65,5,174)
B(-3,65,6,174)
B(-3,65,7,174)
B(-3,65,8,174)
B(-3,66,-7,174)
B(-3,66,-6,174)
B(-3,66,-5,174)
B(-3,66,-4,174)
B(-3,66,-3,174)
B(-3,66,-2,174)
B(-3,66,-1,174)
B(-3,66,0,174)
B(-3,66,1,174)
B(-3,66,2,174)
B(-3,66,3,174)
B(-3,66,4,174)
B(-3,66,5,174)
B(-3,66,6,174)
B(-3,66,7,174)
B(-3,66,8,174)
B(-3,67,-7,174)
B(-3,67,-6,174)
B(-3,67,-5,174)
B(-3,67,-4,174)
B(-3,67,-3,174)
B(-3,67,-2,174)
B(-3,67,-1,174)
B(-3,67,0,174)
B(-3,67,1,174)
B(-3,67,2,174)
B(-3,67,3,174)
B(-3,67,4,174)
B(-3,67,5,174)
B(-3,67,6,174)
B(-3,67,7,174)
B(-3,67,8,174)
B(-3,68,-1,174)
B(-3,68,0,174)
B(-3,68,1,174)
B(-3,68,2,174)
B(-3,68,3,174)
B(-3,68,4,174)
B(-3,68,5,174)
B(-3,68,6,174)
B(-3,68,7,174)
B(-3,68,8,174)
B(-3,69,0,174)
B(-3,69,1,174)
B(-3,69,2,174)
B(-3,69,3,174)
B(-3,69,4,174)
B(-3,69,5,174)
B(-3,69,6,174)
B(-3,69,7,174)
B(-3,70,1,174)
B(-3,70,2,174)
B(-3,70,3,174)
B(-3,70,4,174)
B(-3,70,5,174)
B(-3,70,6,174)
B(-2,14,-6,174)
B(-2,14,-5,174)
B(-2,14,-4,174)
B(-2,14,-3,174)
B(-2,14,-2,174)
B(-2,14,-1,174)
B(-2,14,0,174)
B(-2,15,-7,174)
B(-2,15,-6,174)
B(-2,15,-5,174)
B(-2,15,-4,174)
B(-2,15,-3,174)
B(-2,15,-2,174)
B(-2,15,-1,174)
B(-2,15,0,174)
B(-2,15,1,174)
B(-2,16,-7,174)
B(-2,16,-6,174)
B(-2,16,-5,174)
B(-2,16,-4,174)
B(-2,16,-3,174)
B(-2,16,-2,174)
B(-2,16,-1,174)
B(-2,16,0,174)
B(-2,16,1,174)
B(-2,17,-7,174)
B(-2,17,-6,174)
B(-2,17,-5,174)
B(-2,17,-4,174)
B(-2,17,-3,174)
B(-2,17,-2,174)
B(-2,17,-1,174)
B(-2,17,0,174)
B(-2,17,1,174)
B(-2,18,-7,174)
B(-2,18,-6,174)
B(-2,18,-5,174)
B(-2,18,-4,174)
B(-2,18,-3,174)
B(-2,18,-2,174)
B(-2,18,-1,174)
B(-2,18,0,174)
B(-2,18,1,174)
B(-2,19,-7,174)
B(-2,19,-6,174)
B(-2,19,-5,174)
B(-2,19,-4,174)
B(-2,19,-3,174)
B(-2,19,-2,174)
B(-2,19,-1,174)
B(-2,19,0,174)
B(-2,19,1,174)
B(-2,20,-7,174)
B(-2,20,-6,174)
B(-2,20,-5,174)
B(-2,20,-4,174)
B(-2,20,-3,174)
B(-2,20,-2,174)
B(-2,20,-1,174)
B(-2,20,0,174)
B(-2,20,1,174)
B(-2,21,-7,174)
B(-2,21,-6,174)
B(-2,21,-5,174)
B(-2,21,-4,174)
B(-2,21,-3,174)
B(-2,21,-2,174)
B(-2,21,-1,174)
B(-2,21,0,174)
B(-2,22,-7,174)
B(-2,22,-6,174)
B(-2,22,-5,174)
B(-2,22,-4,174)
B(-2,22,-3,174)
B(-2,22,-2,174)
B(-2,29,-5,174)
B(-2,29,-4,174)
B(-2,29,-3,174)
B(-2,29,-2,174)
B(-2,29,-1,174)
B(-2,29,0,174)
B(-2,30,-6,174)
B(-2,30,-5,174)
B(-2,30,-4,174)
B(-2,30,-3,174)
B(-2,30,-2,174)
B(-2,30,-1,174)
B(-2,30,0,174)
B(-2,30,1,174)
B(-2,30,2,174)
B(-2,30,3,174)
B(-2,30,4,174)
B(-2,30,5,174)
B(-2,30,6,174)
B(-2,31,-7,174)
B(-2,31,-6,174)
B(-2,31,-5,174)
B(-2,31,-4,174)
B(-2,31,-3,174)
B(-2,31,-2,174)
B(-2,31,-1,174)
B(-2,31,0,174)
B(-2,31,1,174)
B(-2,31,2,174)
B(-2,31,3,174)
B(-2,31,4,174)
B(-2,31,5,174)
B(-2,31,6,174)
B(-2,32,-7,174)
B(-2,32,-6,174)
B(-2,32,-5,174)
B(-2,32,-4,174)
B(-2,32,-3,174)
B(-2,32,-2,174)
B(-2,32,-1,174)
B(-2,32,0,174)
B(-2,32,1,174)
B(-2,32,2,174)
B(-2,32,3,174)
B(-2,32,4,174)
B(-2,32,5,174)
B(-2,32,6,174)
B(-2,32,7,174)
B(-2,33,-7,174)
B(-2,33,-6,174)
B(-2,33,-5,174)
B(-2,33,-4,174)
B(-2,33,-3,174)
B(-2,33,-2,174)
B(-2,33,-1,174)
B(-2,33,0,174)
B(-2,33,1,174)
B(-2,33,2,174)
B(-2,33,3,174)
B(-2,33,4,174)
B(-2,33,5,174)
B(-2,33,6,174)
B(-2,33,7,174)
B(-2,33,8,174)
B(-2,34,-7,174)
B(-2,34,-6,174)
B(-2,34,-5,174)
B(-2,34,-4,174)
B(-2,34,-3,174)
B(-2,34,-2,174)
B(-2,34,-1,174)
B(-2,34,0,174)
B(-2,34,1,174)
B(-2,34,2,174)
B(-2,34,3,174)
B(-2,34,4,174)
B(-2,34,5,174)
B(-2,34,6,174)
B(-2,34,7,174)
B(-2,34,8,174)
B(-2,35,-7,174)
B(-2,35,-6,174)
B(-2,35,-5,174)
B(-2,35,-4,174)
B(-2,35,-3,174)
B(-2,35,-2,174)
B(-2,35,-1,174)
B(-2,35,0,174)
B(-2,35,1,174)
B(-2,35,2,174)
B(-2,35,3,174)
B(-2,35,4,174)
B(-2,35,5,174)
B(-2,35,6,174)
B(-2,35,7,174)
B(-2,35,8,174)
B(-2,36,-7,174)
B(-2,36,-6,174)
B(-2,36,-5,174)
B(-2,36,-4,174)
B(-2,36,-3,174)
B(-2,36,-2,174)
B(-2,36,-1,174)
B(-2,36,0,174)
B(-2,36,1,174)
B(-2,36,2,174)
B(-2,36,3,174)
B(-2,36,4,174)
B(-2,36,5,174)
B(-2,36,6,174)
B(-2,36,7,174)
B(-2,36,8,174)
B(-2,37,-7,174)
B(-2,37,-6,174)
B(-2,37,-5,174)
B(-2,37,-4,174)
B(-2,37,-3,174)
B(-2,37,-2,174)
B(-2,37,-1,174)
B(-2,37,0,174)
B(-2,37,1,174)
B(-2,37,2,174)
B(-2,37,3,174)
B(-2,37,4,174)
B(-2,37,5,174)
B(-2,37,6,174)
B(-2,37,7,174)
B(-2,37,8,174)
B(-2,38,-7,174)
B(-2,38,-6,174)
B(-2,38,-5,174)
B(-2,38,-4,174)
B(-2,38,-3,174)
B(-2,38,-2,174)
B(-2,38,-1,174)
B(-2,38,0,174)
B(-2,38,1,174)
B(-2,38,2,174)
B(-2,38,3,174)
B(-2,38,4,174)
B(-2,38,5,174)
B(-2,38,6,174)
B(-2,38,7,174)
B(-2,38,8,174)
B(-2,39,-7,174)
B(-2,39,-6,174)
B(-2,39,-5,174)
B(-2,39,-4,174)
B(-2,39,-3,174)
B(-2,39,-2,174)
B(-2,39,-1,174)
B(-2,39,0,174)
B(-2,39,1,174)
B(-2,39,2,174)
B(-2,39,3,174)
B(-2,39,4,174)
B(-2,39,5,174)
B(-2,39,6,174)
B(-2,39,7,174)
B(-2,39,8,174)
B(-2,40,-7,174)
B(-2,40,-6,174)
B(-2,40,-5,174)
B(-2,40,-4,174)
B(-2,40,-3,174)
B(-2,40,-2,174)
B(-2,40,-1,174)
B(-2,40,0,174)
B(-2,40,1,174)
B(-2,40,2,174)
B(-2,40,3,174)
B(-2,40,4,174)
B(-2,40,5,174)
B(-2,40,6,174)
B(-2,40,7,174)
B(-2,40,8,174)
B(-2,41,-7,174)
B(-2,41,-6,174)
B(-2,41,-5,174)
B(-2,41,-4,174)
B(-2,41,-3,174)
B(-2,41,-2,174)
B(-2,41,-1,174)
B(-2,41,0,174)
B(-2,41,1,174)
B(-2,41,2,174)
B(-2,41,3,174)
B(-2,41,4,174)
B(-2,41,5,174)
B(-2,41,6,174)
B(-2,41,7,174)
B(-2,41,8,174)
B(-2,42,-7,174)
B(-2,42,-6,174)
B(-2,42,-5,174)
B(-2,42,-4,174)
B(-2,42,-3,174)
B(-2,42,-2,174)
B(-2,42,-1,174)
B(-2,42,0,174)
B(-2,42,1,174)
B(-2,42,2,174)
B(-2,42,3,174)
B(-2,42,4,174)
B(-2,42,5,174)
B(-2,42,6,174)
B(-2,42,7,174)
B(-2,42,8,174)
B(-2,43,-7,174)
B(-2,43,-6,174)
B(-2,43,-5,174)
B(-2,43,-4,174)
B(-2,43,-3,174)
B(-2,43,-2,174)
B(-2,43,-1,174)
B(-2,43,0,174)
B(-2,43,1,174)
B(-2,43,2,174)
B(-2,43,3,174)
B(-2,43,4,174)
B(-2,43,5,174)
B(-2,43,6,174)
B(-2,43,7,174)
B(-2,44,-7,174)
B(-2,44,-6,174)
B(-2,44,-5,174)
B(-2,44,-4,174)
B(-2,44,-3,174)
B(-2,44,-2,174)
B(-2,44,-1,174)
B(-2,44,0,174)
B(-2,44,1,174)
B(-2,44,2,174)
B(-2,44,3,174)
B(-2,44,4,174)
B(-2,44,5,174)
B(-2,44,6,174)
B(-2,45,-7,174)
B(-2,45,-6,174)
B(-2,45,-5,174)
B(-2,45,-4,174)
B(-2,45,-3,174)
B(-2,45,-2,174)
B(-2,45,-1,174)
B(-2,45,0,174)
B(-2,45,1,174)
B(-2,45,2,174)
B(-2,45,3,174)
B(-2,45,4,174)
B(-2,45,5,174)
B(-2,45,6,174)
B(-2,46,-6,174)
B(-2,46,-5,174)
B(-2,46,-4,174)
B(-2,46,-3,174)
B(-2,46,-2,174)
B(-2,46,-1,174)
B(-2,46,0,174)
B(-2,46,1,174)
B(-2,46,2,174)
B(-2,46,3,174)
B(-2,46,4,174)
B(-2,46,5,174)
B(-2,46,6,174)
B(-2,47,-7,174)
B(-2,47,-6,174)
B(-2,47,-5,174)
B(-2,47,-4,174)
B(-2,47,-3,174)
B(-2,47,-2,174)
B(-2,47,-1,174)
B(-2,47,0,174)
B(-2,47,1,174)
B(-2,47,2,174)
B(-2,47,3,174)
B(-2,47,4,174)
B(-2,47,5,174)
B(-2,48,-7,174)
B(-2,48,-6,174)
B(-2,48,-5,174)
B(-2,48,-4,174)
B(-2,48,-3,174)
B(-2,48,-2,174)
B(-2,48,-1,174)
B(-2,48,0,174)
B(-2,48,1,174)
B(-2,48,3,174)
B(-2,48,4,174)
B(-2,48,5,174)
B(-2,49,-6,174)
B(-2,49,-5,174)
B(-2,49,-4,174)
B(-2,49,-3,174)
B(-2,49,-2,174)
B(-2,49,-1,174)
B(-2,49,0,174)
B(-2,50,-7,174)
B(-2,50,-6,174)
B(-2,50,-5,174)
B(-2,50,-4,174)
B(-2,50,-3,174)
B(-2,50,-2,174)
B(-2,50,-1,174)
B(-2,50,0,174)
B(-2,51,-6,174)
B(-2,51,-5,174)
B(-2,51,-4,174)
B(-2,51,-3,174)
B(-2,52,-5,174)
B(-2,52,-4,174)
B(-2,53,-5,174)
B(-2,56,-1,174)
B(-2,57,-1,174)
B(-2,58,-1,174)
B(-2,59,-7,174)
B(-2,59,-6,174)
B(-2,59,-5,174)
B(-2,59,-4,174)
B(-2,59,-3,174)
B(-2,59,-1,174)
B(-2,59,0,174)
B(-2,60,-7,174)
B(-2,60,-6,174)
B(-2,60,-5,174)
B(-2,60,-4,174)
B(-2,60,-3,174)
B(-2,60,-2,174)
B(-2,60,-1,174)
B(-2,60,0,174)
B(-2,61,-7,174)
B(-2,61,-6,174)
B(-2,61,-5,174)
B(-2,61,-4,174)
B(-2,61,-3,174)
B(-2,61,-2,174)
B(-2,61,-1,174)
B(-2,61,0,174)
B(-2,61,1,174)
B(-2,61,2,174)
B(-2,61,3,174)
B(-2,62,-7,174)
B(-2,62,-6,174)
B(-2,62,-5,174)
B(-2,62,-4,174)
B(-2,62,-3,174)
B(-2,62,-2,174)
B(-2,62,-1,174)
B(-2,62,0,174)
B(-2,62,1,174)
B(-2,62,2,174)
B(-2,62,3,174)
B(-2,62,4,174)
B(-2,63,-7,174)
B(-2,63,-6,174)
B(-2,63,-5,174)
B(-2,63,-4,174)
B(-2,63,-3,174)
B(-2,63,-2,174)
B(-2,63,-1,174)
B(-2,63,0,174)
B(-2,63,1,174)
B(-2,63,2,174)
B(-2,63,3,174)
B(-2,63,4,174)
B(-2,63,5,174)
B(-2,64,-7,174)
B(-2,64,-6,174)
B(-2,64,-5,174)
B(-2,64,-4,174)
B(-2,64,-3,174)
B(-2,64,-2,174)
B(-2,64,-1,174)
B(-2,64,0,174)
B(-2,64,1,174)
B(-2,64,2,174)
B(-2,64,3,174)
B(-2,64,4,174)
B(-2,64,5,174)
B(-2,64,6,174)
B(-2,64,7,174)
B(-2,64,8,174)
B(-2,65,-7,174)
B(-2,65,-6,174)
B(-2,65,-5,174)
B(-2,65,-4,174)
B(-2,65,-3,174)
B(-2,65,-2,174)
B(-2,65,-1,174)
B(-2,65,0,174)
B(-2,65,1,174)
B(-2,65,2,174)
B(-2,65,3,174)
B(-2,65,4,174)
B(-2,65,5,174)
B(-2,65,6,174)
B(-2,65,7,174)
B(-2,65,8,174)
B(-2,66,-7,174)
B(-2,66,-6,174)
B(-2,66,-5,174)
B(-2,66,-4,174)
B(-2,66,-3,174)
B(-2,66,-2,174)
B(-2,66,-1,174)
B(-2,66,0,174)
B(-2,66,1,174)
B(-2,66,2,174)
B(-2,66,3,174)
B(-2,66,4,174)
B(-2,66,5,174)
B(-2,66,6,174)
B(-2,66,7,174)
B(-2,66,8,174)
B(-2,67,-6,174)
B(-2,67,-5,174)
B(-2,67,-4,174)
B(-2,67,-3,174)
B(-2,67,-2,174)
B(-2,67,-1,174)
B(-2,67,0,174)
B(-2,67,1,174)
B(-2,67,2,174)
B(-2,67,3,174)
B(-2,67,4,174)
B(-2,67,5,174)
B(-2,67,6,174)
B(-2,67,7,174)
B(-2,67,8,174)
B(-2,68,0,174)
B(-2,68,1,174)
B(-2,68,2,174)
B(-2,68,3,174)
B(-2,68,4,174)
B(-2,68,5,174)
B(-2,68,6,174)
B(-2,68,7,174)
B(-2,69,1,174)
B(-2,69,2,174)
B(-2,69,3,174)
B(-2,69,4,174)
B(-2,69,5,174)
B(-2,69,6,174)
B(-2,70,2,174)
B(-2,70,3,174)
B(-2,70,4,174)
B(-2,70,5,174)
B(-1,14,-4,174)
B(-1,14,-3,174)
B(-1,14,-2,174)
B(-1,14,-1,174)
B(-1,14,0,174)
B(-1,15,-7,174)
B(-1,15,-6,174)
B(-1,15,-5,174)
B(-1,15,-4,174)
B(-1,15,-3,174)
B(-1,15,-2,174)
B(-1,15,-1,174)
B(-1,15,0,174)
B(-1,15,1,174)
B(-1,16,-7,174)
B(-1,16,-6,174)
B(-1,16,-5,174)
B(-1,16,-4,174)
B(-1,16,-3,174)
B(-1,16,-2,174)
B(-1,16,-1,174)
B(-1,16,0,174)
B(-1,16,1,174)
B(-1,17,-7,174)
B(-1,17,-6,174)
B(-1,17,-5,174)
B(-1,17,-4,174)
B(-1,17,-3,174)
B(-1,17,-2,174)
B(-1,17,-1,174)
B(-1,17,0,174)
B(-1,17,1,174)
B(-1,18,-7,174)
B(-1,18,-6,174)
B(-1,18,-5,174)
B(-1,18,-4,174)
B(-1,18,-3,174)
B(-1,18,-2,174)
B(-1,18,-1,174)
B(-1,18,0,174)
B(-1,18,1,174)
B(-1,19,-7,174)
B(-1,19,-6,174)
B(-1,19,-5,174)
B(-1,19,-4,174)
B(-1,19,-3,174)
B(-1,19,-2,174)
B(-1,19,-1,174)
B(-1,19,0,174)
B(-1,19,1,174)
B(-1,20,-7,174)
B(-1,20,-6,174)
B(-1,20,-5,174)
B(-1,20,-4,174)
B(-1,20,-3,174)
B(-1,20,-2,174)
B(-1,20,-1,174)
B(-1,20,0,174)
B(-1,20,1,174)
B(-1,21,-7,174)
B(-1,21,-6,174)
B(-1,21,-5,174)
B(-1,21,-4,174)
B(-1,21,-3,174)
B(-1,21,-2,174)
B(-1,21,-1,174)
B(-1,21,0,174)
B(-1,22,-7,174)
B(-1,22,-6,174)
B(-1,22,-5,174)
B(-1,22,-4,174)
B(-1,22,-3,174)
B(-1,22,-2,174)
B(-1,22,-1,174)
B(-1,23,-7,174)
B(-1,23,-6,174)
B(-1,27,-5,174)
B(-1,27,-4,174)
B(-1,27,-3,174)
B(-1,27,-2,174)
B(-1,28,-6,174)
B(-1,28,-5,174)
B(-1,28,-4,174)
B(-1,28,-3,174)
B(-1,28,-2,174)
B(-1,28,-1,174)
B(-1,28,0,174)
B(-1,29,-6,174)
B(-1,29,-5,174)
B(-1,29,-4,174)
B(-1,29,-3,174)
B(-1,29,-2,174)
B(-1,29,-1,174)
B(-1,29,0,174)
B(-1,29,1,174)
B(-1,30,-7,174)
B(-1,30,-6,174)
B(-1,30,-5,174)
B(-1,30,-4,174)
B(-1,30,-3,174)
B(-1,30,-2,174)
B(-1,30,-1,174)
B(-1,30,0,174)
B(-1,30,1,174)
B(-1,30,2,174)
B(-1,30,3,174)
B(-1,30,4,174)
B(-1,30,5,174)
B(-1,30,6,174)
B(-1,30,7,174)
B(-1,30,8,174)
B(-1,31,-7,174)
B(-1,31,-6,174)
B(-1,31,-5,174)
B(-1,31,-4,174)
B(-1,31,-3,174)
B(-1,31,-2,174)
B(-1,31,-1,174)
B(-1,31,0,174)
B(-1,31,1,174)
B(-1,31,2,174)
B(-1,31,3,174)
B(-1,31,4,174)
B(-1,31,5,174)
B(-1,31,6,174)
B(-1,31,7,174)
B(-1,31,8,174)
B(-1,32,-7,174)
B(-1,32,-6,174)
B(-1,32,-5,174)
B(-1,32,-4,174)
B(-1,32,-3,174)
B(-1,32,-2,174)
B(-1,32,-1,174)
B(-1,32,0,174)
B(-1,32,1,174)
B(-1,32,2,174)
B(-1,32,3,174)
B(-1,32,4,174)
B(-1,32,5,174)
B(-1,32,6,174)
B(-1,32,7,174)
B(-1,32,8,174)
B(-1,33,-7,174)
B(-1,33,-6,174)
B(-1,33,-5,174)
B(-1,33,-4,174)
B(-1,33,-3,174)
B(-1,33,-2,174)
B(-1,33,-1,174)
B(-1,33,0,174)
B(-1,33,1,174)
B(-1,33,2,174)
B(-1,33,3,174)
B(-1,33,4,174)
B(-1,33,5,174)
B(-1,33,6,174)
B(-1,33,7,174)
B(-1,33,8,174)
B(-1,34,-7,174)
B(-1,34,-6,174)
B(-1,34,-5,174)
B(-1,34,-4,174)
B(-1,34,-3,174)
B(-1,34,-2,174)
B(-1,34,-1,174)
B(-1,34,0,174)
B(-1,34,1,174)
B(-1,34,2,174)
B(-1,34,3,174)
B(-1,34,4,174)
B(-1,34,5,174)
B(-1,34,6,174)
B(-1,34,7,174)
B(-1,34,8,174)
B(-1,35,-7,174)
B(-1,35,-6,174)
B(-1,35,-5,174)
B(-1,35,-4,174)
B(-1,35,-3,174)
B(-1,35,-2,174)
B(-1,35,-1,174)
B(-1,35,0,174)
B(-1,35,1,174)
B(-1,35,2,174)
B(-1,35,3,174)
B(-1,35,4,174)
B(-1,35,5,174)
B(-1,35,6,174)
B(-1,35,7,174)
B(-1,35,8,174)
B(-1,36,-7,174)
B(-1,36,-6,174)
B(-1,36,-5,174)
B(-1,36,-4,174)
B(-1,36,-3,174)
B(-1,36,-2,174)
B(-1,36,-1,174)
B(-1,36,0,174)
B(-1,36,1,174)
B(-1,36,2,174)
B(-1,36,3,174)
B(-1,36,4,174)
B(-1,36,5,174)
B(-1,36,6,174)
B(-1,36,7,174)
B(-1,36,8,174)
B(-1,37,-7,174)
B(-1,37,-6,174)
B(-1,37,-5,174)
B(-1,37,-4,174)
B(-1,37,-3,174)
B(-1,37,-2,174)
B(-1,37,-1,174)
B(-1,37,0,174)
B(-1,37,1,174)
B(-1,37,2,174)
B(-1,37,3,174)
B(-1,37,4,174)
B(-1,37,5,174)
B(-1,37,6,174)
B(-1,37,7,174)
B(-1,37,8,174)
B(-1,38,-7,174)
B(-1,38,-6,174)
B(-1,38,-5,174)
B(-1,38,-4,174)
B(-1,38,-3,174)
B(-1,38,-2,174)
B(-1,38,-1,174)
B(-1,38,0,174)
B(-1,38,1,174)
B(-1,38,2,174)
B(-1,38,3,174)
B(-1,38,4,174)
B(-1,38,5,174)
B(-1,38,6,174)
B(-1,38,7,174)
B(-1,38,8,174)
B(-1,39,-7,174)
B(-1,39,-6,174)
B(-1,39,-5,174)
B(-1,39,-4,174)
B(-1,39,-3,174)
B(-1,39,-2,174)
B(-1,39,-1,174)
B(-1,39,0,174)
B(-1,39,1,174)
B(-1,39,2,174)
B(-1,39,3,174)
B(-1,39,4,174)
B(-1,39,5,174)
B(-1,39,6,174)
B(-1,39,7,174)
B(-1,39,8,174)
B(-1,40,-7,174)
B(-1,40,-6,174)
B(-1,40,-5,174)
B(-1,40,-4,174)
B(-1,40,-3,174)
B(-1,40,-2,174)
B(-1,40,-1,174)
B(-1,40,0,174)
B(-1,40,1,174)
B(-1,40,2,174)
B(-1,40,3,174)
B(-1,40,4,174)
B(-1,40,5,174)
B(-1,40,6,174)
B(-1,40,7,174)
B(-1,40,8,174)
B(-1,41,-7,174)
B(-1,41,-6,174)
B(-1,41,-5,174)
B(-1,41,-4,174)
B(-1,41,-3,174)
B(-1,41,-2,174)
B(-1,41,-1,174)
B(-1,41,0,174)
B(-1,41,1,174)
B(-1,41,2,174)
B(-1,41,3,174)
B(-1,41,4,174)
B(-1,41,5,174)
B(-1,41,6,174)
B(-1,41,7,174)
B(-1,41,8,174)
B(-1,42,-7,174)
B(-1,42,-6,174)
B(-1,42,-5,174)
B(-1,42,-4,174)
B(-1,42,-3,174)
B(-1,42,-2,174)
B(-1,42,-1,174)
B(-1,42,0,174)
B(-1,42,1,174)
B(-1,42,2,174)
B(-1,42,3,174)
B(-1,42,4,174)
B(-1,42,5,174)
B(-1,42,6,174)
B(-1,42,7,174)
B(-1,42,8,174)
B(-1,43,-7,174)
B(-1,43,-6,174)
B(-1,43,-5,174)
B(-1,43,-4,174)
B(-1,43,-3,174)
B(-1,43,-2,174)
B(-1,43,-1,174)
B(-1,43,0,174)
B(-1,43,1,174)
B(-1,43,2,174)
B(-1,43,3,174)
B(-1,43,4,174)
B(-1,43,5,174)
B(-1,43,6,174)
B(-1,43,7,174)
B(-1,43,8,174)
B(-1,44,-7,174)
B(-1,44,-6,174)
B(-1,44,-5,174)
B(-1,44,-4,174)
B(-1,44,-3,174)
B(-1,44,-2,174)
B(-1,44,-1,174)
B(-1,44,0,174)
B(-1,44,1,174)
B(-1,44,2,174)
B(-1,44,3,174)
B(-1,44,4,174)
B(-1,44,5,174)
B(-1,44,6,174)
B(-1,44,7,174)
B(-1,44,8,174)
B(-1,45,-7,174)
B(-1,45,-6,174)
B(-1,45,-5,174)
B(-1,45,-4,174)
B(-1,45,-3,174)
B(-1,45,-2,174)
B(-1,45,-1,174)
B(-1,45,0,174)
B(-1,45,1,174)
B(-1,45,2,174)
B(-1,45,3,174)
B(-1,45,4,174)
B(-1,45,5,174)
B(-1,45,6,174)
B(-1,45,7,174)
B(-1,45,8,174)
B(-1,46,-7,174)
B(-1,46,-6,174)
B(-1,46,-5,174)
B(-1,46,-4,174)
B(-1,46,-3,174)
B(-1,46,-2,174)
B(-1,46,-1,174)
B(-1,46,0,174)
B(-1,46,1,174)
B(-1,46,2,174)
B(-1,46,3,174)
B(-1,46,4,174)
B(-1,46,5,174)
B(-1,46,6,174)
B(-1,46,7,174)
B(-1,47,-7,174)
B(-1,47,-6,174)
B(-1,47,-5,174)
B(-1,47,-4,174)
B(-1,47,-3,174)
B(-1,47,-2,174)
B(-1,47,-1,174)
B(-1,47,0,174)
B(-1,47,1,174)
B(-1,47,2,174)
B(-1,47,3,174)
B(-1,47,4,174)
B(-1,47,5,174)
B(-1,47,6,174)
B(-1,47,7,174)
B(-1,48,-7,174)
B(-1,48,-6,174)
B(-1,48,-5,174)
B(-1,48,-4,174)
B(-1,48,-3,174)
B(-1,48,-2,174)
B(-1,48,-1,174)
B(-1,48,0,174)
B(-1,48,1,174)
B(-1,48,2,174)
B(-1,48,3,174)
B(-1,48,4,174)
B(-1,48,5,174)
B(-1,48,7,174)
B(-1,49,-7,174)
B(-1,49,-6,174)
B(-1,49,-5,174)
B(-1,49,-4,174)
B(-1,49,-3,174)
B(-1,49,-2,174)
B(-1,49,-1,174)
B(-1,49,0,174)
B(-1,49,1,174)
B(-1,49,3,174)
B(-1,49,4,174)
B(-1,49,5,174)
B(-1,50,-7,174)
B(-1,50,-6,174)
B(-1,50,-5,174)
B(-1,50,-4,174)
B(-1,50,-3,174)
B(-1,50,-2,174)
B(-1,50,-1,174)
B(-1,50,0,174)
B(-1,50,1,174)
B(-1,51,-7,174)
B(-1,51,-6,174)
B(-1,51,-5,174)
B(-1,51,-4,174)
B(-1,51,-3,174)
B(-1,51,-2,174)
B(-1,51,-1,174)
B(-1,51,0,174)
B(-1,51,1,174)
B(-1,52,-6,174)
B(-1,52,-5,174)
B(-1,52,-4,174)
B(-1,52,-3,174)
B(-1,52,-1,174)
B(-1,52,0,174)
B(-1,53,-6,174)
B(-1,53,-5,174)
B(-1,53,-4,174)
B(-1,53,-3,174)
B(-1,54,-5,174)
B(-1,54,-4,174)
B(-1,54,-1,174)
B(-1,55,-4,174)
B(-1,55,-1,174)
B(-1,58,-7,174)
B(-1,59,-7,174)
B(-1,59,-6,174)
B(-1,59,-5,174)
B(-1,59,-4,174)
B(-1,59,-3,174)
B(-1,59,-2,174)
B(-1,60,-7,174)
B(-1,60,-6,174)
B(-1,60,-5,174)
B(-1,60,-4,174)
B(-1,60,-3,174)
B(-1,60,-2,174)
B(-1,60,-1,174)
B(-1,60,5,174)
B(-1,61,-7,174)
B(-1,61,-6,174)
B(-1,61,-5,174)
B(-1,61,-4,174)
B(-1,61,-3,174)
B(-1,61,-2,174)
B(-1,61,-1,174)
B(-1,61,0,174)
B(-1,61,1,174)
B(-1,61,2,174)
B(-1,61,3,174)
B(-1,61,4,174)
B(-1,61,8,174)
B(-1,62,-7,174)
B(-1,62,-6,174)
B(-1,62,-5,174)
B(-1,62,-4,174)
B(-1,62,-3,174)
B(-1,62,-2,174)
B(-1,62,-1,174)
B(-1,62,0,174)
B(-1,62,1,174)
B(-1,62,2,174)
B(-1,62,3,174)
B(-1,62,4,174)
B(-1,62,5,174)
B(-1,62,8,174)
B(-1,63,-7,174)
B(-1,63,-6,174)
B(-1,63,-5,174)
B(-1,63,-4,174)
B(-1,63,-3,174)
B(-1,63,-2,174)
B(-1,63,-1,174)
B(-1,63,0,174)
B(-1,63,1,174)
B(-1,63,2,174)
B(-1,63,3,174)
B(-1,63,4,174)
B(-1,63,5,174)
B(-1,63,8,174)
B(-1,64,-7,174)
B(-1,64,-6,174)
B(-1,64,-5,174)
B(-1,64,-4,174)
B(-1,64,-3,174)
B(-1,64,-2,174)
B(-1,64,-1,174)
B(-1,64,0,174)
B(-1,64,1,174)
B(-1,64,2,174)
B(-1,64,3,174)
B(-1,64,4,174)
B(-1,64,5,174)
B(-1,64,6,174)
B(-1,64,8,174)
B(-1,65,-7,174)
B(-1,65,-6,174)
B(-1,65,-5,174)
B(-1,65,-4,174)
B(-1,65,-3,174)
B(-1,65,-2,174)
B(-1,65,-1,174)
B(-1,65,0,174)
B(-1,65,1,174)
B(-1,65,2,174)
B(-1,65,3,174)
B(-1,65,4,174)
B(-1,65,5,174)
B(-1,65,6,174)
B(-1,65,7,174)
B(-1,65,8,174)
B(-1,66,-7,174)
B(-1,66,-6,174)
B(-1,66,-5,174)
B(-1,66,-4,174)
B(-1,66,-3,174)
B(-1,66,-2,174)
B(-1,66,-1,174)
B(-1,66,0,174)
B(-1,66,1,174)
B(-1,66,2,174)
B(-1,66,3,174)
B(-1,66,4,174)
B(-1,66,5,174)
B(-1,66,6,174)
B(-1,66,7,174)
B(-1,66,8,174)
B(-1,67,-4,174)
B(-1,67,-3,174)
B(-1,67,-2,174)
B(-1,67,-1,174)
B(-1,67,0,174)
B(-1,67,1,174)
B(-1,67,2,174)
B(-1,67,3,174)
B(-1,67,4,174)
B(-1,67,5,174)
B(-1,67,6,174)
B(-1,67,7,174)
B(-1,68,3,174)
B(-1,68,4,174)
B(-1,68,5,174)
B(-1,68,6,174)
B(0,14,-2,174)
B(0,14,-1,174)
B(0,14,0,174)
B(0,15,-7,174)
B(0,15,-6,174)
B(0,15,-5,174)
B(0,15,-4,174)
B(0,15,-3,174)
B(0,15,-2,174)
B(0,15,-1,174)
B(0,15,0,174)
B(0,15,1,174)
B(0,16,-7,174)
B(0,16,-6,174)
B(0,16,-5,174)
B(0,16,-4,174)
B(0,16,-3,174)
B(0,16,-2,174)
B(0,16,-1,174)
B(0,16,0,174)
B(0,16,1,174)
B(0,17,-7,174)
B(0,17,-6,174)
B(0,17,-5,174)
B(0,17,-4,174)
B(0,17,-3,174)
B(0,17,-2,174)
B(0,17,-1,174)
B(0,17,0,174)
B(0,17,1,174)
B(0,17,2,174)
B(0,18,-7,174)
B(0,18,-6,174)
B(0,18,-5,174)
B(0,18,-4,174)
B(0,18,-3,174)
B(0,18,-2,174)
B(0,18,-1,174)
B(0,18,0,174)
B(0,18,1,174)
B(0,18,2,174)
B(0,19,-7,174)
B(0,19,-6,174)
B(0,19,-5,174)
B(0,19,-4,174)
B(0,19,-3,174)
B(0,19,-2,174)
B(0,19,-1,174)
B(0,19,0,174)
B(0,19,1,174)
B(0,19,2,174)
B(0,20,-7,174)
B(0,20,-6,174)
B(0,20,-5,174)
B(0,20,-4,174)
B(0,20,-3,174)
B(0,20,-2,174)
B(0,20,-1,174)
B(0,20,0,174)
B(0,20,1,174)
B(0,21,-7,174)
B(0,21,-6,174)
B(0,21,-5,174)
B(0,21,-4,174)
B(0,21,-3,174)
B(0,21,-2,174)
B(0,21,-1,174)
B(0,21,0,174)
B(0,22,-7,174)
B(0,22,-6,174)
B(0,22,-5,174)
B(0,22,-4,174)
B(0,22,-3,174)
B(0,22,-2,174)
B(0,22,-1,174)
B(0,22,0,174)
B(0,23,-7,174)
B(0,23,-6,174)
B(0,23,-5,174)
B(0,23,-4,174)
B(0,23,-3,174)
B(0,23,-2,174)
B(0,23,-1,174)
B(0,23,0,174)
B(0,23,1,174)
B(0,24,-7,174)
B(0,24,-6,174)
B(0,24,-5,174)
B(0,24,-4,174)
B(0,24,-3,174)
B(0,24,-2,174)
B(0,24,-1,174)
B(0,24,0,174)
B(0,24,1,174)
B(0,24,2,174)
B(0,24,3,174)
B(0,25,-7,174)
B(0,25,-6,174)
B(0,25,-5,174)
B(0,25,-4,174)
B(0,25,-3,174)
B(0,25,-2,174)
B(0,25,-1,174)
B(0,25,0,174)
B(0,25,1,174)
B(0,25,2,174)
B(0,25,3,174)
B(0,26,-6,174)
B(0,26,-5,174)
B(0,26,-4,174)
B(0,26,-3,174)
B(0,26,-2,174)
B(0,26,-1,174)
B(0,26,0,174)
B(0,26,1,174)
B(0,26,2,174)
B(0,26,3,174)
B(0,27,-7,174)
B(0,27,-6,174)
B(0,27,-5,174)
B(0,27,-4,174)
B(0,27,-3,174)
B(0,27,-2,174)
B(0,27,-1,174)
B(0,27,0,174)
B(0,27,1,174)
B(0,27,2,174)
B(0,27,3,174)
B(0,27,4,174)
B(0,28,-7,174)
B(0,28,-6,174)
B(0,28,-5,174)
B(0,28,-4,174)
B(0,28,-3,174)
B(0,28,-2,174)
B(0,28,-1,174)
B(0,28,0,174)
B(0,28,1,174)
B(0,28,2,174)
B(0,28,3,174)
B(0,28,4,174)
B(0,28,5,174)
B(0,29,-7,174)
B(0,29,-6,174)
B(0,29,-5,174)
B(0,29,-4,174)
B(0,29,-3,174)
B(0,29,-2,174)
B(0,29,-1,174)
B(0,29,0,174)
B(0,29,1,174)
B(0,29,2,174)
B(0,29,3,174)
B(0,29,4,174)
B(0,29,5,174)
B(0,29,6,174)
B(0,29,7,174)
B(0,29,8,174)
B(0,30,-7,174)
B(0,30,-6,174)
B(0,30,-5,174)
B(0,30,-4,174)
B(0,30,-3,174)
B(0,30,-2,174)
B(0,30,-1,174)
B(0,30,0,174)
B(0,30,1,174)
B(0,30,2,174)
B(0,30,3,174)
B(0,30,4,174)
B(0,30,5,174)
B(0,30,6,174)
B(0,30,7,174)
B(0,30,8,174)
B(0,31,-7,174)
B(0,31,-6,174)
B(0,31,-5,174)
B(0,31,-4,174)
B(0,31,-3,174)
B(0,31,-2,174)
B(0,31,-1,174)
B(0,31,0,174)
B(0,31,1,174)
B(0,31,2,174)
B(0,31,3,174)
B(0,31,4,174)
B(0,31,5,174)
B(0,31,6,174)
B(0,31,7,174)
B(0,31,8,174)
B(0,32,-7,174)
B(0,32,-6,174)
B(0,32,-5,174)
B(0,32,-4,174)
B(0,32,-3,174)
B(0,32,-2,174)
B(0,32,-1,174)
B(0,32,0,174)
B(0,32,1,174)
B(0,32,2,174)
B(0,32,3,174)
B(0,32,4,174)
B(0,32,5,174)
B(0,32,6,174)
B(0,32,7,174)
B(0,32,8,174)
B(0,33,-7,174)
B(0,33,-6,174)
B(0,33,-5,174)
B(0,33,-4,174)
B(0,33,-3,174)
B(0,33,-2,174)
B(0,33,-1,174)
B(0,33,0,174)
B(0,33,1,174)
B(0,33,2,174)
B(0,33,3,174)
B(0,33,4,174)
B(0,33,5,174)
B(0,33,6,174)
B(0,33,7,174)
B(0,33,8,174)
B(0,34,-7,174)
B(0,34,-6,174)
B(0,34,-5,174)
B(0,34,-4,174)
B(0,34,-3,174)
B(0,34,-2,174)
B(0,34,-1,174)
B(0,34,0,174)
B(0,34,1,174)
B(0,34,2,174)
B(0,34,3,174)
B(0,34,4,174)
B(0,34,5,174)
B(0,34,6,174)
B(0,34,7,174)
B(0,34,8,174)
B(0,35,-7,174)
B(0,35,-6,174)
B(0,35,-5,174)
B(0,35,-4,174)
B(0,35,-3,174)
B(0,35,-2,174)
B(0,35,-1,174)
B(0,35,0,174)
B(0,35,1,174)
B(0,35,2,174)
B(0,35,3,174)
B(0,35,4,174)
B(0,35,5,174)
B(0,35,6,174)
B(0,35,7,174)
B(0,35,8,174)
B(0,36,-7,174)
B(0,36,-6,174)
B(0,36,-5,174)
B(0,36,-4,174)
B(0,36,-3,174)
B(0,36,-2,174)
B(0,36,-1,174)
B(0,36,0,174)
B(0,36,1,174)
B(0,36,2,174)
B(0,36,3,174)
B(0,36,4,174)
B(0,36,5,174)
B(0,36,6,174)
B(0,36,7,174)
B(0,36,8,174)
B(0,37,-7,174)
B(0,37,-6,174)
B(0,37,-5,174)
B(0,37,-4,174)
B(0,37,-3,174)
B(0,37,-2,174)
B(0,37,-1,174)
B(0,37,0,174)
B(0,37,1,174)
B(0,37,2,174)
B(0,37,3,174)
B(0,37,4,174)
B(0,37,5,174)
B(0,37,6,174)
B(0,37,7,174)
B(0,37,8,174)
B(0,38,-7,174)
B(0,38,-6,174)
B(0,38,-5,174)
B(0,38,-4,174)
B(0,38,-3,174)
B(0,38,-2,174)
B(0,38,-1,174)
B(0,38,0,174)
B(0,38,1,174)
B(0,38,2,174)
B(0,38,3,174)
B(0,38,4,174)
B(0,38,5,174)
B(0,38,6,174)
B(0,38,7,174)
B(0,38,8,174)
B(0,39,-7,174)
B(0,39,-6,174)
B(0,39,-5,174)
B(0,39,-4,174)
B(0,39,-3,174)
B(0,39,-2,174)
B(0,39,-1,174)
B(0,39,0,174)
B(0,39,1,174)
B(0,39,2,174)
B(0,39,3,174)
B(0,39,4,174)
B(0,39,5,174)
B(0,39,6,174)
B(0,39,7,174)
B(0,39,8,174)
B(0,40,-7,174)
B(0,40,-6,174)
B(0,40,-5,174)
B(0,40,-4,174)
B(0,40,-3,174)
B(0,40,-2,174)
B(0,40,-1,174)
B(0,40,0,174)
B(0,40,1,174)
B(0,40,2,174)
B(0,40,3,174)
B(0,40,4,174)
B(0,40,5,174)
B(0,40,6,174)
B(0,40,7,174)
B(0,40,8,174)
B(0,41,-7,174)
B(0,41,-6,174)
B(0,41,-5,174)
B(0,41,-4,174)
B(0,41,-3,174)
B(0,41,-2,174)
B(0,41,-1,174)
B(0,41,0,174)
B(0,41,1,174)
B(0,41,2,174)
B(0,41,3,174)
B(0,41,4,174)
B(0,41,5,174)
B(0,41,6,174)
B(0,41,7,174)
B(0,41,8,174)
B(0,42,-7,174)
B(0,42,-6,174)
B(0,42,-5,174)
B(0,42,-4,174)
B(0,42,-3,174)
B(0,42,-2,174)
B(0,42,-1,174)
B(0,42,0,174)
B(0,42,1,174)
B(0,42,2,174)
B(0,42,3,174)
B(0,42,4,174)
B(0,42,5,174)
B(0,42,6,174)
B(0,42,7,174)
B(0,42,8,174)
B(0,43,-7,174)
B(0,43,-6,174)
B(0,43,-5,174)
B(0,43,-4,174)
B(0,43,-3,174)
B(0,43,-2,174)
B(0,43,-1,174)
B(0,43,0,174)
B(0,43,1,174)
B(0,43,2,174)
B(0,43,3,174)
B(0,43,4,174)
B(0,43,5,174)
B(0,43,6,174)
B(0,43,7,174)
B(0,43,8,174)
B(0,44,-7,174)
B(0,44,-6,174)
B(0,44,-5,174)
B(0,44,-4,174)
B(0,44,-3,174)
B(0,44,-2,174)
B(0,44,-1,174)
B(0,44,0,174)
B(0,44,1,174)
B(0,44,2,174)
B(0,44,3,174)
B(0,44,4,174)
B(0,44,5,174)
B(0,44,6,174)
B(0,44,7,174)
B(0,44,8,174)
B(0,45,-7,174)
B(0,45,-6,174)
B(0,45,-5,174)
B(0,45,-4,174)
B(0,45,-3,174)
B(0,45,-2,174)
B(0,45,-1,174)
B(0,45,0,174)
B(0,45,1,174)
B(0,45,2,174)
B(0,45,3,174)
B(0,45,4,174)
B(0,45,5,174)
B(0,45,6,174)
B(0,45,7,174)
B(0,45,8,174)
B(0,46,-7,174)
B(0,46,-6,174)
B(0,46,-5,174)
B(0,46,-4,174)
B(0,46,-3,174)
B(0,46,-2,174)
B(0,46,-1,174)
B(0,46,0,174)
B(0,46,1,174)
B(0,46,2,174)
B(0,46,3,174)
B(0,46,4,174)
B(0,46,5,174)
B(0,46,6,174)
B(0,46,7,174)
B(0,46,8,174)
B(0,47,-7,174)
B(0,47,-6,174)
B(0,47,-5,174)
B(0,47,-4,174)
B(0,47,-3,174)
B(0,47,-2,174)
B(0,47,-1,174)
B(0,47,0,174)
B(0,47,1,174)
B(0,47,2,174)
B(0,47,3,174)
B(0,47,4,174)
B(0,47,5,174)
B(0,47,6,174)
B(0,47,7,174)
B(0,47,8,174)
B(0,48,-7,174)
B(0,48,-6,174)
B(0,48,-5,174)
B(0,48,-4,174)
B(0,48,-3,174)
B(0,48,-2,174)
B(0,48,-1,174)
B(0,48,0,174)
B(0,48,1,174)
B(0,48,2,174)
B(0,48,3,174)
B(0,48,4,174)
B(0,48,5,174)
B(0,48,6,174)
B(0,48,7,174)
B(0,48,8,174)
B(0,49,-7,174)
B(0,49,-6,174)
B(0,49,-5,174)
B(0,49,-4,174)
B(0,49,-3,174)
B(0,49,-2,174)
B(0,49,-1,174)
B(0,49,0,174)
B(0,49,1,174)
B(0,49,2,174)
B(0,49,3,174)
B(0,49,4,174)
B(0,49,5,174)
B(0,49,7,174)
B(0,49,8,174)
B(0,50,-7,174)
B(0,50,-6,174)
B(0,50,-5,174)
B(0,50,-4,174)
B(0,50,-3,174)
B(0,50,-2,174)
B(0,50,-1,174)
B(0,50,0,174)
B(0,50,1,174)
B(0,50,2,174)
B(0,50,3,174)
B(0,50,4,174)
B(0,50,5,174)
B(0,50,8,174)
B(0,51,-7,174)
B(0,51,-6,174)
B(0,51,-5,174)
B(0,51,-4,174)
B(0,51,-3,174)
B(0,51,-2,174)
B(0,51,-1,174)
B(0,51,0,174)
B(0,51,1,174)
B(0,51,2,174)
B(0,51,3,174)
B(0,51,4,174)
B(0,51,5,174)
B(0,51,7,174)
B(0,51,8,174)
B(0,52,-7,174)
B(0,52,-6,174)
B(0,52,-5,174)
B(0,52,-4,174)
B(0,52,-3,174)
B(0,52,-2,174)
B(0,52,-1,174)
B(0,52,0,174)
B(0,52,1,174)
B(0,52,2,174)
B(0,52,3,174)
B(0,52,4,174)
B(0,52,5,174)
B(0,52,7,174)
B(0,52,8,174)
B(0,53,-7,174)
B(0,53,-6,174)
B(0,53,-5,174)
B(0,53,-4,174)
B(0,53,-3,174)
B(0,53,-2,174)
B(0,53,-1,174)
B(0,53,0,174)
B(0,53,1,174)
B(0,53,2,174)
B(0,53,3,174)
B(0,53,4,174)
B(0,54,-7,174)
B(0,54,-6,174)
B(0,54,-5,174)
B(0,54,-4,174)
B(0,54,-3,174)
B(0,54,-2,174)
B(0,54,-1,174)
B(0,54,0,174)
B(0,54,1,174)
B(0,54,2,174)
B(0,54,3,174)
B(0,55,-6,174)
B(0,55,-5,174)
B(0,55,-4,174)
B(0,55,-3,174)
B(0,55,-2,174)
B(0,55,-1,174)
B(0,55,0,174)
B(0,55,1,174)
B(0,55,2,174)
B(0,55,3,174)
B(0,56,-7,174)
B(0,56,-6,174)
B(0,56,-5,174)
B(0,56,-4,174)
B(0,56,-3,174)
B(0,56,-2,174)
B(0,56,-1,174)
B(0,56,0,174)
B(0,56,1,174)
B(0,56,2,174)
B(0,56,3,174)
B(0,57,-7,174)
B(0,57,-6,174)
B(0,57,-5,174)
B(0,57,-4,174)
B(0,57,-3,174)
B(0,57,-2,174)
B(0,57,-1,174)
B(0,57,0,174)
B(0,57,1,174)
B(0,57,2,174)
B(0,57,3,174)
B(0,57,4,174)
B(0,58,-7,174)
B(0,58,-6,174)
B(0,58,-5,174)
B(0,58,-4,174)
B(0,58,-3,174)
B(0,58,-2,174)
B(0,58,-1,174)
B(0,58,0,174)
B(0,58,1,174)
B(0,58,4,174)
B(0,58,5,174)
B(0,58,6,174)
B(0,59,-7,174)
B(0,59,-6,174)
B(0,59,-5,174)
B(0,59,-4,174)
B(0,59,-3,174)
B(0,59,-2,174)
B(0,59,-1,174)
B(0,59,0,174)
B(0,59,3,174)
B(0,59,4,174)
B(0,59,5,174)
B(0,59,6,174)
B(0,59,7,174)
B(0,60,-7,174)
B(0,60,-6,174)
B(0,60,-5,174)
B(0,60,-4,174)
B(0,60,-3,174)
B(0,60,-2,174)
B(0,60,-1,174)
B(0,60,0,174)
B(0,60,2,174)
B(0,60,3,174)
B(0,60,4,174)
B(0,60,5,174)
B(0,60,6,174)
B(0,60,7,174)
B(0,61,-7,174)
B(0,61,-6,174)
B(0,61,-5,174)
B(0,61,-4,174)
B(0,61,-3,174)
B(0,61,-2,174)
B(0,61,-1,174)
B(0,61,0,174)
B(0,61,1,174)
B(0,61,2,174)
B(0,61,3,174)
B(0,61,4,174)
B(0,61,5,174)
B(0,61,6,174)
B(0,61,7,174)
B(0,62,-7,174)
B(0,62,-6,174)
B(0,62,-5,174)
B(0,62,-4,174)
B(0,62,-3,174)
B(0,62,-2,174)
B(0,62,-1,174)
B(0,62,0,174)
B(0,62,1,174)
B(0,62,2,174)
B(0,62,3,174)
B(0,62,4,174)
B(0,62,5,174)
B(0,62,6,174)
B(0,63,-7,174)
B(0,63,-6,174)
B(0,63,-5,174)
B(0,63,-4,174)
B(0,63,-3,174)
B(0,63,-2,174)
B(0,63,-1,174)
B(0,63,0,174)
B(0,63,1,174)
B(0,63,2,174)
B(0,63,3,174)
B(0,63,4,174)
B(0,63,5,174)
B(0,64,-7,174)
B(0,64,-6,174)
B(0,64,-5,174)
B(0,64,-4,174)
B(0,64,-3,174)
B(0,64,-2,174)
B(0,64,-1,174)
B(0,64,0,174)
B(0,64,1,174)
B(0,64,2,174)
B(0,64,3,174)
B(0,64,4,174)
B(0,64,5,174)
B(0,65,-7,174)
B(0,65,-6,174)
B(0,65,-5,174)
B(0,65,-4,174)
B(0,65,-3,174)
B(0,65,-2,174)
B(0,65,-1,174)
B(0,65,0,174)
B(0,65,1,174)
B(0,65,2,174)
B(0,65,3,174)
B(0,65,4,174)
B(0,65,5,174)
B(0,65,6,174)
B(0,65,7,174)
B(0,66,-7,174)
B(0,66,-6,174)
B(0,66,-5,174)
B(0,66,-4,174)
B(0,66,-3,174)
B(0,66,-2,174)
B(0,66,-1,174)
B(0,66,0,174)
B(0,66,1,174)
B(0,66,2,174)
B(0,66,3,174)
B(0,66,4,174)
B(0,66,5,174)
B(0,67,-2,174)
B(0,67,-1,174)
B(0,67,0,174)
B(0,67,1,174)
B(0,67,2,174)
B(0,67,3,174)
B(0,67,4,174)
B(0,67,5,174)
B(1,15,-7,174)
B(1,15,-4,174)
B(1,15,-3,174)
B(1,15,-2,174)
B(1,15,-1,174)
B(1,15,0,174)
B(1,16,-7,174)
B(1,16,-6,174)
B(1,16,-5,174)
B(1,16,-4,174)
B(1,16,-3,174)
B(1,16,-2,174)
B(1,16,-1,174)
B(1,16,0,174)
B(1,16,1,174)
B(1,17,-7,174)
B(1,17,-6,174)
B(1,17,-5,174)
B(1,17,-4,174)
B(1,17,-3,174)
B(1,17,-2,174)
B(1,17,-1,174)
B(1,17,0,174)
B(1,17,1,174)
B(1,17,2,174)
B(1,18,-7,174)
B(1,18,-6,174)
B(1,18,-5,174)
B(1,18,-4,174)
B(1,18,-3,174)
B(1,18,-2,174)
B(1,18,-1,174)
B(1,18,0,174)
B(1,18,1,174)
B(1,18,2,174)
B(1,19,-7,174)
B(1,19,-6,174)
B(1,19,-5,174)
B(1,19,-4,174)
B(1,19,-3,174)
B(1,19,-2,174)
B(1,19,-1,174)
B(1,19,0,174)
B(1,19,1,174)
B(1,19,2,174)
B(1,20,-7,174)
B(1,20,-6,174)
B(1,20,-5,174)
B(1,20,-4,174)
B(1,20,-3,174)
B(1,20,-2,174)
B(1,20,-1,174)
B(1,20,0,174)
B(1,20,1,174)
B(1,20,2,174)
B(1,21,-7,174)
B(1,21,-6,174)
B(1,21,-5,174)
B(1,21,-4,174)
B(1,21,-3,174)
B(1,21,-2,174)
B(1,21,-1,174)
B(1,21,0,174)
B(1,21,1,174)
B(1,21,2,174)
B(1,22,-7,174)
B(1,22,-6,174)
B(1,22,-5,174)
B(1,22,-4,174)
B(1,22,-3,174)
B(1,22,-2,174)
B(1,22,-1,174)
B(1,22,0,174)
B(1,22,1,174)
B(1,22,2,174)
B(1,22,3,174)
B(1,23,-7,174)
B(1,23,-6,174)
B(1,23,-5,174)
B(1,23,-4,174)
B(1,23,-3,174)
B(1,23,-2,174)
B(1,23,-1,174)
B(1,23,0,174)
B(1,23,1,174)
B(1,23,2,174)
B(1,23,3,174)
B(1,24,-7,174)
B(1,24,-6,174)
B(1,24,-5,174)
B(1,24,-4,174)
B(1,24,-3,174)
B(1,24,-2,174)
B(1,24,-1,174)
B(1,24,0,174)
B(1,24,1,174)
B(1,24,2,174)
B(1,24,3,174)
B(1,24,4,174)
B(1,24,5,174)
B(1,25,-7,174)
B(1,25,-6,174)
B(1,25,-5,174)
B(1,25,-4,174)
B(1,25,-3,174)
B(1,25,-2,174)
B(1,25,-1,174)
B(1,25,0,174)
B(1,25,1,174)
B(1,25,2,174)
B(1,25,3,174)
B(1,25,4,174)
B(1,25,5,174)
B(1,25,6,174)
B(1,25,8,174)
B(1,26,-7,174)
B(1,26,-6,174)
B(1,26,-5,174)
B(1,26,-4,174)
B(1,26,-3,174)
B(1,26,-2,174)
B(1,26,-1,174)
B(1,26,0,174)
B(1,26,1,174)
B(1,26,2,174)
B(1,26,3,174)
B(1,26,4,174)
B(1,26,5,174)
B(1,26,6,174)
B(1,26,7,174)
B(1,26,8,174)
B(1,27,-7,174)
B(1,27,-6,174)
B(1,27,-5,174)
B(1,27,-4,174)
B(1,27,-3,174)
B(1,27,-2,174)
B(1,27,-1,174)
B(1,27,0,174)
B(1,27,1,174)
B(1,27,2,174)
B(1,27,3,174)
B(1,27,4,174)
B(1,27,5,174)
B(1,27,6,174)
B(1,27,7,174)
B(1,27,8,174)
B(1,28,-7,174)
B(1,28,-6,174)
B(1,28,-5,174)
B(1,28,-4,174)
B(1,28,-3,174)
B(1,28,-2,174)
B(1,28,-1,174)
B(1,28,0,174)
B(1,28,1,174)
B(1,28,2,174)
B(1,28,3,174)
B(1,28,4,174)
B(1,28,5,174)
B(1,28,6,174)
B(1,28,7,174)
B(1,28,8,174)
B(1,29,-7,174)
B(1,29,-6,174)
B(1,29,-5,174)
B(1,29,-4,174)
B(1,29,-3,174)
B(1,29,-2,174)
B(1,29,-1,174)
B(1,29,0,174)
B(1,29,1,174)
B(1,29,2,174)
B(1,29,3,174)
B(1,29,4,174)
B(1,29,5,174)
B(1,29,6,174)
B(1,29,7,174)
B(1,29,8,174)
B(1,30,-7,174)
B(1,30,-6,174)
B(1,30,-5,174)
B(1,30,-4,174)
B(1,30,-3,174)
B(1,30,-2,174)
B(1,30,-1,174)
B(1,30,0,174)
B(1,30,1,174)
B(1,30,2,174)
B(1,30,3,174)
B(1,30,4,174)
B(1,30,5,174)
B(1,30,6,174)
B(1,30,7,174)
B(1,30,8,174)
B(1,31,-7,174)
B(1,31,-6,174)
B(1,31,-5,174)
B(1,31,-4,174)
B(1,31,-3,174)
B(1,31,-2,174)
B(1,31,-1,174)
B(1,31,0,174)
B(1,31,1,174)
B(1,31,2,174)
B(1,31,3,174)
B(1,31,4,174)
B(1,31,5,174)
B(1,31,6,174)
B(1,31,7,174)
B(1,31,8,174)
B(1,32,-7,174)
B(1,32,-6,174)
B(1,32,-5,174)
B(1,32,-4,174)
B(1,32,-3,174)
B(1,32,-2,174)
B(1,32,-1,174)
B(1,32,0,174)
B(1,32,1,174)
B(1,32,2,174)
B(1,32,3,174)
B(1,32,4,174)
B(1,32,5,174)
B(1,32,6,174)
B(1,32,7,174)
B(1,32,8,174)
B(1,33,-7,174)
B(1,33,-6,174)
B(1,33,-5,174)
B(1,33,-4,174)
B(1,33,-3,174)
B(1,33,-2,174)
B(1,33,-1,174)
B(1,33,0,174)
B(1,33,1,174)
B(1,33,2,174)
B(1,33,3,174)
B(1,33,4,174)
B(1,33,5,174)
B(1,33,6,174)
B(1,33,7,174)
B(1,33,8,174)
B(1,34,-7,174)
B(1,34,-6,174)
B(1,34,-5,174)
B(1,34,-4,174)
B(1,34,-3,174)
B(1,34,-2,174)
B(1,34,-1,174)
B(1,34,0,174)
B(1,34,1,174)
B(1,34,2,174)
B(1,34,3,174)
B(1,34,4,174)
B(1,34,5,174)
B(1,34,6,174)
B(1,34,7,174)
B(1,34,8,174)
B(1,35,-7,174)
B(1,35,-6,174)
B(1,35,-5,174)
B(1,35,-4,174)
B(1,35,-3,174)
B(1,35,-2,174)
B(1,35,-1,174)
B(1,35,0,174)
B(1,35,1,174)
B(1,35,2,174)
B(1,35,3,174)
B(1,35,4,174)
B(1,35,5,174)
B(1,35,6,174)
B(1,35,7,174)
B(1,35,8,174)
B(1,36,-7,174)
B(1,36,-6,174)
B(1,36,-5,174)
B(1,36,-4,174)
B(1,36,-3,174)
B(1,36,-2,174)
B(1,36,-1,174)
B(1,36,0,174)
B(1,36,1,174)
B(1,36,2,174)
B(1,36,3,174)
B(1,36,4,174)
B(1,36,5,174)
B(1,36,6,174)
B(1,36,7,174)
B(1,36,8,174)
B(1,37,-7,174)
B(1,37,-6,174)
B(1,37,-5,174)
B(1,37,-4,174)
B(1,37,-3,174)
B(1,37,-2,174)
B(1,37,-1,174)
B(1,37,0,174)
B(1,37,1,174)
B(1,37,2,174)
B(1,37,3,174)
B(1,37,4,174)
B(1,37,5,174)
B(1,37,6,174)
B(1,37,7,174)
B(1,37,8,174)
B(1,38,-7,174)
B(1,38,-6,174)
B(1,38,-5,174)
B(1,38,-4,174)
B(1,38,-3,174)
B(1,38,-2,174)
B(1,38,-1,174)
B(1,38,0,174)
B(1,38,1,174)
B(1,38,2,174)
B(1,38,3,174)
B(1,38,4,174)
B(1,38,5,174)
B(1,38,6,174)
B(1,38,7,174)
B(1,38,8,174)
B(1,39,-7,174)
B(1,39,-6,174)
B(1,39,-5,174)
B(1,39,-4,174)
B(1,39,-3,174)
B(1,39,-2,174)
B(1,39,-1,174)
B(1,39,0,174)
B(1,39,1,174)
B(1,39,2,174)
B(1,39,3,174)
B(1,39,4,174)
B(1,39,5,174)
B(1,39,6,174)
B(1,39,7,174)
B(1,39,8,174)
B(1,40,-7,174)
B(1,40,-6,174)
B(1,40,-5,174)
B(1,40,-4,174)
B(1,40,-3,174)
B(1,40,-2,174)
B(1,40,-1,174)
B(1,40,0,174)
B(1,40,1,174)
B(1,40,2,174)
B(1,40,3,174)
B(1,40,4,174)
B(1,40,5,174)
B(1,40,6,174)
B(1,40,7,174)
B(1,40,8,174)
B(1,41,-7,174)
B(1,41,-6,174)
B(1,41,-5,174)
B(1,41,-4,174)
B(1,41,-3,174)
B(1,41,-2,174)
B(1,41,-1,174)
B(1,41,0,174)
B(1,41,1,174)
B(1,41,2,174)
B(1,41,3,174)
B(1,41,4,174)
B(1,41,5,174)
B(1,41,6,174)
B(1,41,7,174)
B(1,41,8,174)
B(1,42,-7,174)
B(1,42,-6,174)
B(1,42,-5,174)
B(1,42,-4,174)
B(1,42,-3,174)
B(1,42,-2,174)
B(1,42,-1,174)
B(1,42,0,174)
B(1,42,1,174)
B(1,42,2,174)
B(1,42,3,174)
B(1,42,4,174)
B(1,42,5,174)
B(1,42,6,174)
B(1,42,7,174)
B(1,42,8,174)
B(1,43,-7,174)
B(1,43,-6,174)
B(1,43,-5,174)
B(1,43,-4,174)
B(1,43,-3,174)
B(1,43,-2,174)
B(1,43,-1,174)
B(1,43,0,174)
B(1,43,1,174)
B(1,43,2,174)
B(1,43,3,174)
B(1,43,4,174)
B(1,43,5,174)
B(1,43,6,174)
B(1,43,7,174)
B(1,43,8,174)
B(1,44,-7,174)
B(1,44,-6,174)
B(1,44,-5,174)
B(1,44,-4,174)
B(1,44,-3,174)
B(1,44,-2,174)
B(1,44,-1,174)
B(1,44,0,174)
B(1,44,1,174)
B(1,44,2,174)
B(1,44,3,174)
B(1,44,4,174)
B(1,44,5,174)
B(1,44,6,174)
B(1,44,7,174)
B(1,44,8,174)
B(1,45,-7,174)
B(1,45,-6,174)
B(1,45,-5,174)
B(1,45,-4,174)
B(1,45,-3,174)
B(1,45,-2,174)
B(1,45,-1,174)
B(1,45,0,174)
B(1,45,1,174)
B(1,45,2,174)
B(1,45,3,174)
B(1,45,4,174)
B(1,45,5,174)
B(1,45,6,174)
B(1,45,7,174)
B(1,45,8,174)
B(1,46,-7,174)
B(1,46,-6,174)
B(1,46,-5,174)
B(1,46,-4,174)
B(1,46,-3,174)
B(1,46,-2,174)
B(1,46,-1,174)
B(1,46,0,174)
B(1,46,1,174)
B(1,46,2,174)
B(1,46,3,174)
B(1,46,4,174)
B(1,46,5,174)
B(1,46,6,174)
B(1,46,7,174)
B(1,46,8,174)
B(1,47,-7,174)
B(1,47,-6,174)
B(1,47,-5,174)
B(1,47,-4,174)
B(1,47,-3,174)
B(1,47,-2,174)
B(1,47,-1,174)
B(1,47,0,174)
B(1,47,1,174)
B(1,47,2,174)
B(1,47,3,174)
B(1,47,4,174)
B(1,47,5,174)
B(1,47,6,174)
B(1,47,7,174)
B(1,47,8,174)
B(1,48,-7,174)
B(1,48,-6,174)
B(1,48,-5,174)
B(1,48,-4,174)
B(1,48,-3,174)
B(1,48,-2,174)
B(1,48,-1,174)
B(1,48,0,174)
B(1,48,1,174)
B(1,48,2,174)
B(1,48,3,174)
B(1,48,4,174)
B(1,48,5,174)
B(1,48,6,174)
B(1,48,7,174)
B(1,48,8,174)
B(1,49,-7,174)
B(1,49,-6,174)
B(1,49,-5,174)
B(1,49,-4,174)
B(1,49,-3,174)
B(1,49,-2,174)
B(1,49,-1,174)
B(1,49,0,174)
B(1,49,1,174)
B(1,49,2,174)
B(1,49,3,174)
B(1,49,4,174)
B(1,49,5,174)
B(1,49,6,174)
B(1,49,7,174)
B(1,49,8,174)
B(1,50,-7,174)
B(1,50,-6,174)
B(1,50,-5,174)
B(1,50,-4,174)
B(1,50,-3,174)
B(1,50,-2,174)
B(1,50,-1,174)
B(1,50,0,174)
B(1,50,1,174)
B(1,50,2,174)
B(1,50,3,174)
B(1,50,4,174)
B(1,50,5,174)
B(1,50,6,174)
B(1,50,7,174)
B(1,50,8,174)
B(1,51,-7,174)
B(1,51,-6,174)
B(1,51,-5,174)
B(1,51,-4,174)
B(1,51,-3,174)
B(1,51,-2,174)
B(1,51,-1,174)
B(1,51,0,174)
B(1,51,1,174)
B(1,51,2,174)
B(1,51,3,174)
B(1,51,4,174)
B(1,51,5,174)
B(1,51,6,174)
B(1,51,7,174)
B(1,51,8,174)
B(1,52,-7,174)
B(1,52,-6,174)
B(1,52,-5,174)
B(1,52,-4,174)
B(1,52,-3,174)
B(1,52,-2,174)
B(1,52,-1,174)
B(1,52,0,174)
B(1,52,1,174)
B(1,52,2,174)
B(1,52,3,174)
B(1,52,4,174)
B(1,52,5,174)
B(1,52,6,174)
B(1,52,7,174)
B(1,52,8,174)
B(1,53,-7,174)
B(1,53,-6,174)
B(1,53,-5,174)
B(1,53,-4,174)
B(1,53,-3,174)
B(1,53,-2,174)
B(1,53,-1,174)
B(1,53,0,174)
B(1,53,1,174)
B(1,53,2,174)
B(1,53,3,174)
B(1,53,4,174)
B(1,53,5,174)
B(1,53,6,174)
B(1,53,7,174)
B(1,53,8,174)
B(1,54,-7,174)
B(1,54,-6,174)
B(1,54,-5,174)
B(1,54,-4,174)
B(1,54,-3,174)
B(1,54,-2,174)
B(1,54,-1,174)
B(1,54,0,174)
B(1,54,1,174)
B(1,54,2,174)
B(1,54,3,174)
B(1,54,4,174)
B(1,54,5,174)
B(1,54,6,174)
B(1,54,7,174)
B(1,54,8,174)
B(1,55,-7,174)
B(1,55,-6,174)
B(1,55,-5,174)
B(1,55,-4,174)
B(1,55,-3,174)
B(1,55,-2,174)
B(1,55,-1,174)
B(1,55,0,174)
B(1,55,1,174)
B(1,55,2,174)
B(1,55,3,174)
B(1,55,4,174)
B(1,55,5,174)
B(1,55,6,174)
B(1,55,7,174)
B(1,55,8,174)
B(1,56,-7,174)
B(1,56,-6,174)
B(1,56,-5,174)
B(1,56,-4,174)
B(1,56,-3,174)
B(1,56,-2,174)
B(1,56,-1,174)
B(1,56,0,174)
B(1,56,1,174)
B(1,56,2,174)
B(1,56,3,174)
B(1,56,4,174)
B(1,56,5,174)
B(1,56,6,174)
B(1,56,7,174)
B(1,56,8,174)
B(1,57,-7,174)
B(1,57,-6,174)
B(1,57,-5,174)
B(1,57,-4,174)
B(1,57,-3,174)
B(1,57,-2,174)
B(1,57,-1,174)
B(1,57,0,174)
B(1,57,1,174)
B(1,57,2,174)
B(1,57,3,174)
B(1,57,4,174)
B(1,57,5,174)
B(1,57,6,174)
B(1,58,-7,174)
B(1,58,-6,174)
B(1,58,-5,174)
B(1,58,-4,174)
B(1,58,-3,174)
B(1,58,-2,174)
B(1,58,-1,174)
B(1,58,0,174)
B(1,58,1,174)
B(1,58,2,174)
B(1,58,3,174)
B(1,58,4,174)
B(1,58,5,174)
B(1,58,6,174)
B(1,58,7,174)
B(1,58,8,174)
B(1,59,-7,174)
B(1,59,-6,174)
B(1,59,-5,174)
B(1,59,-4,174)
B(1,59,-3,174)
B(1,59,-2,174)
B(1,59,-1,174)
B(1,59,0,174)
B(1,59,1,174)
B(1,59,2,174)
B(1,59,3,174)
B(1,59,4,174)
B(1,59,5,174)
B(1,59,6,174)
B(1,59,7,174)
B(1,59,8,174)
B(1,60,-7,174)
B(1,60,-6,174)
B(1,60,-5,174)
B(1,60,-4,174)
B(1,60,-3,174)
B(1,60,-2,174)
B(1,60,-1,174)
B(1,60,0,174)
B(1,60,1,174)
B(1,60,2,174)
B(1,60,3,174)
B(1,60,4,174)
B(1,60,5,174)
B(1,60,6,174)
B(1,60,7,174)
B(1,60,8,174)
B(1,61,-7,174)
B(1,61,-6,174)
B(1,61,-5,174)
B(1,61,-4,174)
B(1,61,-3,174)
B(1,61,-2,174)
B(1,61,-1,174)
B(1,61,0,174)
B(1,61,1,174)
B(1,61,2,174)
B(1,61,3,174)
B(1,61,4,174)
B(1,61,5,174)
B(1,61,6,174)
B(1,61,7,174)
B(1,61,8,174)
B(1,62,-7,174)
B(1,62,-6,174)
B(1,62,-5,174)
B(1,62,-4,174)
B(1,62,-3,174)
B(1,62,-2,174)
B(1,62,-1,174)
B(1,62,0,174)
B(1,62,1,174)
B(1,62,2,174)
B(1,62,3,174)
B(1,62,4,174)
B(1,62,5,174)
B(1,62,6,174)
B(1,62,7,174)
B(1,63,-7,174)
B(1,63,-6,174)
B(1,63,-5,174)
B(1,63,-4,174)
B(1,63,-3,174)
B(1,63,-2,174)
B(1,63,-1,174)
B(1,63,0,174)
B(1,63,1,174)
B(1,63,2,174)
B(1,63,3,174)
B(1,63,4,174)
B(1,63,5,174)
B(1,63,6,174)
B(1,64,-7,174)
B(1,64,-6,174)
B(1,64,-5,174)
B(1,64,-4,174)
B(1,64,-3,174)
B(1,64,-2,174)
B(1,64,-1,174)
B(1,64,0,174)
B(1,64,1,174)
B(1,64,2,174)
B(1,64,3,174)
B(1,64,4,174)
B(1,64,5,174)
B(1,64,6,174)
B(1,65,-7,174)
B(1,65,-6,174)
B(1,65,-5,174)
B(1,65,-4,174)
B(1,65,-3,174)
B(1,65,-2,174)
B(1,65,-1,174)
B(1,65,0,174)
B(1,65,1,174)
B(1,65,2,174)
B(1,65,3,174)
B(1,65,4,174)
B(1,65,5,174)
B(1,65,6,174)
B(1,66,-7,174)
B(1,66,-4,174)
B(1,66,-3,174)
B(1,66,-2,174)
B(1,66,-1,174)
B(1,66,0,174)
B(1,66,1,174)
B(1,66,2,174)
B(1,66,3,174)
B(1,66,4,174)
B(1,66,5,174)
B(1,67,0,174)
B(1,67,1,174)
B(1,67,2,174)
B(1,67,3,174)
B(1,67,4,174)
B(2,15,-1,174)
B(2,15,0,174)
B(2,16,-7,174)
B(2,16,-6,174)
B(2,16,-5,174)
B(2,16,-4,174)
B(2,16,-3,174)
B(2,16,-2,174)
B(2,16,-1,174)
B(2,16,0,174)
B(2,16,1,174)
B(2,17,-7,174)
B(2,17,-6,174)
B(2,17,-5,174)
B(2,17,-4,174)
B(2,17,-3,174)
B(2,17,-2,174)
B(2,17,-1,174)
B(2,17,0,174)
B(2,17,1,174)
B(2,17,2,174)
B(2,18,-7,174)
B(2,18,-6,174)
B(2,18,-5,174)
B(2,18,-4,174)
B(2,18,-3,174)
B(2,18,-2,174)
B(2,18,-1,174)
B(2,18,0,174)
B(2,18,1,174)
B(2,18,2,174)
B(2,19,-7,174)
B(2,19,-6,174)
B(2,19,-5,174)
B(2,19,-4,174)
B(2,19,-3,174)
B(2,19,-2,174)
B(2,19,-1,174)
B(2,19,0,174)
B(2,19,1,174)
B(2,19,2,174)
B(2,19,3,174)
B(2,20,-7,174)
B(2,20,-6,174)
B(2,20,-5,174)
B(2,20,-4,174)
B(2,20,-3,174)
B(2,20,-2,174)
B(2,20,-1,174)
B(2,20,0,174)
B(2,20,1,174)
B(2,20,2,174)
B(2,20,3,174)
B(2,21,-7,174)
B(2,21,-6,174)
B(2,21,-5,174)
B(2,21,-4,174)
B(2,21,-3,174)
B(2,21,-2,174)
B(2,21,-1,174)
B(2,21,0,174)
B(2,21,1,174)
B(2,21,2,174)
B(2,21,3,174)
B(2,22,-7,174)
B(2,22,-6,174)
B(2,22,-5,174)
B(2,22,-4,174)
B(2,22,-3,174)
B(2,22,-2,174)
B(2,22,-1,174)
B(2,22,0,174)
B(2,22,1,174)
B(2,22,2,174)
B(2,22,3,174)
B(2,23,-7,174)
B(2,23,-6,174)
B(2,23,-5,174)
B(2,23,-4,174)
B(2,23,-3,174)
B(2,23,-2,174)
B(2,23,-1,174)
B(2,23,0,174)
B(2,23,1,174)
B(2,23,2,174)
B(2,23,3,174)
B(2,23,4,174)
B(2,24,-7,174)
B(2,24,-6,174)
B(2,24,-5,174)
B(2,24,-4,174)
B(2,24,-3,174)
B(2,24,-2,174)
B(2,24,-1,174)
B(2,24,0,174)
B(2,24,1,174)
B(2,24,2,174)
B(2,24,3,174)
B(2,24,4,174)
B(2,24,5,174)
B(2,24,6,174)
B(2,25,-7,174)
B(2,25,-6,174)
B(2,25,-5,174)
B(2,25,-4,174)
B(2,25,-3,174)
B(2,25,-2,174)
B(2,25,-1,174)
B(2,25,0,174)
B(2,25,1,174)
B(2,25,2,174)
B(2,25,3,174)
B(2,25,4,174)
B(2,25,5,174)
B(2,25,6,174)
B(2,25,7,174)
B(2,25,8,174)
B(2,26,-7,174)
B(2,26,-6,174)
B(2,26,-5,174)
B(2,26,-4,174)
B(2,26,-3,174)
B(2,26,-2,174)
B(2,26,-1,174)
B(2,26,0,174)
B(2,26,1,174)
B(2,26,2,174)
B(2,26,3,174)
B(2,26,4,174)
B(2,26,5,174)
B(2,26,6,174)
B(2,26,7,174)
B(2,26,8,174)
B(2,27,-7,174)
B(2,27,-6,174)
B(2,27,-5,174)
B(2,27,-4,174)
B(2,27,-3,174)
B(2,27,-2,174)
B(2,27,-1,174)
B(2,27,0,174)
B(2,27,1,174)
B(2,27,2,174)
B(2,27,3,174)
B(2,27,4,174)
B(2,27,5,174)
B(2,27,6,174)
B(2,27,7,174)
B(2,27,8,174)
B(2,28,-7,174)
B(2,28,-6,174)
B(2,28,-5,174)
B(2,28,-4,174)
B(2,28,-3,174)
B(2,28,-2,174)
B(2,28,-1,174)
B(2,28,0,174)
B(2,28,1,174)
B(2,28,2,174)
B(2,28,3,174)
B(2,28,4,174)
B(2,28,5,174)
B(2,28,6,174)
B(2,28,7,174)
B(2,28,8,174)
B(2,29,-7,174)
B(2,29,-6,174)
B(2,29,-5,174)
B(2,29,-4,174)
B(2,29,-3,174)
B(2,29,-2,174)
B(2,29,-1,174)
B(2,29,0,174)
B(2,29,1,174)
B(2,29,2,174)
B(2,29,3,174)
B(2,29,4,174)
B(2,29,5,174)
B(2,29,6,174)
B(2,29,7,174)
B(2,29,8,174)
B(2,30,-7,174)
B(2,30,-6,174)
B(2,30,-5,174)
B(2,30,-4,174)
B(2,30,-3,174)
B(2,30,-2,174)
B(2,30,-1,174)
B(2,30,0,174)
B(2,30,1,174)
B(2,30,2,174)
B(2,30,3,174)
B(2,30,4,174)
B(2,30,5,174)
B(2,30,6,174)
B(2,30,7,174)
B(2,30,8,174)
B(2,31,-7,174)
B(2,31,-6,174)
B(2,31,-5,174)
B(2,31,-4,174)
B(2,31,-3,174)
B(2,31,-2,174)
B(2,31,-1,174)
B(2,31,0,174)
B(2,31,1,174)
B(2,31,2,174)
B(2,31,3,174)
B(2,31,4,174)
B(2,31,5,174)
B(2,31,6,174)
B(2,31,7,174)
B(2,31,8,174)
B(2,32,-7,174)
B(2,32,-6,174)
B(2,32,-5,174)
B(2,32,-4,174)
B(2,32,-3,174)
B(2,32,-2,174)
B(2,32,-1,174)
B(2,32,0,174)
B(2,32,1,174)
B(2,32,2,174)
B(2,32,3,174)
B(2,32,4,174)
B(2,32,5,174)
B(2,32,6,174)
B(2,32,7,174)
B(2,32,8,174)
B(2,33,-7,174)
B(2,33,-6,174)
B(2,33,-5,174)
B(2,33,-4,174)
B(2,33,-3,174)
B(2,33,-2,174)
B(2,33,-1,174)
B(2,33,0,174)
B(2,33,1,174)
B(2,33,2,174)
B(2,33,3,174)
B(2,33,4,174)
B(2,33,5,174)
B(2,33,6,174)
B(2,33,7,174)
B(2,33,8,174)
B(2,34,-7,174)
B(2,34,-6,174)
B(2,34,-5,174)
B(2,34,-4,174)
B(2,34,-3,174)
B(2,34,-2,174)
B(2,34,-1,174)
B(2,34,0,174)
B(2,34,1,174)
B(2,34,2,174)
B(2,34,3,174)
B(2,34,4,174)
B(2,34,5,174)
B(2,34,6,174)
B(2,34,7,174)
B(2,34,8,174)
B(2,35,-7,174)
B(2,35,-6,174)
B(2,35,-5,174)
B(2,35,-4,174)
B(2,35,-3,174)
B(2,35,-2,174)
B(2,35,-1,174)
B(2,35,0,174)
B(2,35,1,174)
B(2,35,2,174)
B(2,35,3,174)
B(2,35,4,174)
B(2,35,5,174)
B(2,35,6,174)
B(2,35,7,174)
B(2,35,8,174)
B(2,36,-7,174)
B(2,36,-6,174)
B(2,36,-5,174)
B(2,36,-4,174)
B(2,36,-3,174)
B(2,36,-2,174)
B(2,36,-1,174)
B(2,36,0,174)
B(2,36,1,174)
B(2,36,2,174)
B(2,36,3,174)
B(2,36,4,174)
B(2,36,5,174)
B(2,36,6,174)
B(2,36,7,174)
B(2,36,8,174)
B(2,37,-7,174)
B(2,37,-6,174)
B(2,37,-5,174)
B(2,37,-4,174)
B(2,37,-3,174)
B(2,37,-2,174)
B(2,37,-1,174)
B(2,37,0,174)
B(2,37,1,174)
B(2,37,2,174)
B(2,37,3,174)
B(2,37,4,174)
B(2,37,5,174)
B(2,37,6,174)
B(2,37,7,174)
B(2,37,8,174)
B(2,38,-7,174)
B(2,38,-6,174)
B(2,38,-5,174)
B(2,38,-4,174)
B(2,38,-3,174)
B(2,38,-2,174)
B(2,38,-1,174)
B(2,38,0,174)
B(2,38,1,174)
B(2,38,2,174)
B(2,38,3,174)
B(2,38,4,174)
B(2,38,5,174)
B(2,38,6,174)
B(2,38,7,174)
B(2,38,8,174)
B(2,39,-7,174)
B(2,39,-6,174)
B(2,39,-5,174)
B(2,39,-4,174)
B(2,39,-3,174)
B(2,39,-2,174)
B(2,39,-1,174)
B(2,39,0,174)
B(2,39,1,174)
B(2,39,2,174)
B(2,39,3,174)
B(2,39,4,174)
B(2,39,5,174)
B(2,39,6,174)
B(2,39,7,174)
B(2,39,8,174)
B(2,40,-7,174)
B(2,40,-6,174)
B(2,40,-5,174)
B(2,40,-4,174)
B(2,40,-3,174)
B(2,40,-2,174)
B(2,40,-1,174)
B(2,40,0,174)
B(2,40,1,174)
B(2,40,2,174)
B(2,40,3,174)
B(2,40,4,174)
B(2,40,5,174)
B(2,40,6,174)
B(2,40,7,174)
B(2,40,8,174)
B(2,41,-7,174)
B(2,41,-6,174)
B(2,41,-5,174)
B(2,41,-4,174)
B(2,41,-3,174)
B(2,41,-2,174)
B(2,41,-1,174)
B(2,41,0,174)
B(2,41,1,174)
B(2,41,2,174)
B(2,41,3,174)
B(2,41,4,174)
B(2,41,5,174)
B(2,41,6,174)
B(2,41,7,174)
B(2,41,8,174)
B(2,42,-7,174)
B(2,42,-6,174)
B(2,42,-5,174)
B(2,42,-4,174)
B(2,42,-3,174)
B(2,42,-2,174)
B(2,42,-1,174)
B(2,42,0,174)
B(2,42,1,174)
B(2,42,2,174)
B(2,42,3,174)
B(2,42,4,174)
B(2,42,5,174)
B(2,42,6,174)
B(2,42,7,174)
B(2,42,8,174)
B(2,43,-7,174)
B(2,43,-6,174)
B(2,43,-5,174)
B(2,43,-4,174)
B(2,43,-3,174)
B(2,43,-2,174)
B(2,43,-1,174)
B(2,43,0,174)
B(2,43,1,174)
B(2,43,2,174)
B(2,43,3,174)
B(2,43,4,174)
B(2,43,5,174)
B(2,43,6,174)
B(2,43,7,174)
B(2,43,8,174)
B(2,44,-7,174)
B(2,44,-6,174)
B(2,44,-5,174)
B(2,44,-4,174)
B(2,44,-3,174)
B(2,44,-2,174)
B(2,44,-1,174)
B(2,44,0,174)
B(2,44,1,174)
B(2,44,2,174)
B(2,44,3,174)
B(2,44,4,174)
B(2,44,5,174)
B(2,44,6,174)
B(2,44,7,174)
B(2,44,8,174)
B(2,45,-7,174)
B(2,45,-6,174)
B(2,45,-5,174)
B(2,45,-4,174)
B(2,45,-3,174)
B(2,45,-2,174)
B(2,45,-1,174)
B(2,45,0,174)
B(2,45,1,174)
B(2,45,2,174)
B(2,45,3,174)
B(2,45,4,174)
B(2,45,5,174)
B(2,45,6,174)
B(2,45,7,174)
B(2,45,8,174)
B(2,46,-7,174)
B(2,46,-6,174)
B(2,46,-5,174)
B(2,46,-4,174)
B(2,46,-3,174)
B(2,46,-2,174)
B(2,46,-1,174)
B(2,46,0,174)
B(2,46,1,174)
B(2,46,2,174)
B(2,46,3,174)
B(2,46,4,174)
B(2,46,5,174)
B(2,46,6,174)
B(2,46,7,174)
B(2,46,8,174)
B(2,47,-7,174)
B(2,47,-6,174)
B(2,47,-5,174)
B(2,47,-4,174)
B(2,47,-3,174)
B(2,47,-2,174)
B(2,47,-1,174)
B(2,47,0,174)
B(2,47,1,174)
B(2,47,2,174)
B(2,47,3,174)
B(2,47,4,174)
B(2,47,5,174)
B(2,47,6,174)
B(2,47,7,174)
B(2,47,8,174)
B(2,48,-7,174)
B(2,48,-6,174)
B(2,48,-5,174)
B(2,48,-4,174)
B(2,48,-3,174)
B(2,48,-2,174)
B(2,48,-1,174)
B(2,48,0,174)
B(2,48,1,174)
B(2,48,2,174)
B(2,48,3,174)
B(2,48,4,174)
B(2,48,5,174)
B(2,48,6,174)
B(2,48,7,174)
B(2,48,8,174)
B(2,49,-7,174)
B(2,49,-6,174)
B(2,49,-5,174)
B(2,49,-4,174)
B(2,49,-3,174)
B(2,49,-2,174)
B(2,49,-1,174)
B(2,49,0,174)
B(2,49,1,174)
B(2,49,2,174)
B(2,49,3,174)
B(2,49,4,174)
B(2,49,5,174)
B(2,49,6,174)
B(2,49,7,174)
B(2,49,8,174)
B(2,50,-7,174)
B(2,50,-6,174)
B(2,50,-5,174)
B(2,50,-4,174)
B(2,50,-3,174)
B(2,50,-2,174)
B(2,50,-1,174)
B(2,50,0,174)
B(2,50,1,174)
B(2,50,2,174)
B(2,50,3,174)
B(2,50,4,174)
B(2,50,5,174)
B(2,50,6,174)
B(2,50,7,174)
B(2,50,8,174)
B(2,51,-7,174)
B(2,51,-6,174)
B(2,51,-5,174)
B(2,51,-4,174)
B(2,51,-3,174)
B(2,51,-2,174)
B(2,51,-1,174)
B(2,51,0,174)
B(2,51,1,174)
B(2,51,2,174)
B(2,51,3,174)
B(2,51,4,174)
B(2,51,5,174)
B(2,51,6,174)
B(2,51,7,174)
B(2,51,8,174)
B(2,52,-7,174)
B(2,52,-6,174)
B(2,52,-5,174)
B(2,52,-4,174)
B(2,52,-3,174)
B(2,52,-2,174)
B(2,52,-1,174)
B(2,52,0,174)
B(2,52,1,174)
B(2,52,2,174)
B(2,52,3,174)
B(2,52,4,174)
B(2,52,5,174)
B(2,52,6,174)
B(2,52,7,174)
B(2,52,8,174)
B(2,53,-7,174)
B(2,53,-6,174)
B(2,53,-5,174)
B(2,53,-4,174)
B(2,53,-3,174)
B(2,53,-2,174)
B(2,53,-1,174)
B(2,53,0,174)
B(2,53,1,174)
B(2,53,2,174)
B(2,53,3,174)
B(2,53,4,174)
B(2,53,5,174)
B(2,53,6,174)
B(2,53,7,174)
B(2,53,8,174)
B(2,54,-7,174)
B(2,54,-6,174)
B(2,54,-5,174)
B(2,54,-4,174)
B(2,54,-3,174)
B(2,54,-2,174)
B(2,54,-1,174)
B(2,54,0,174)
B(2,54,1,174)
B(2,54,2,174)
B(2,54,3,174)
B(2,54,4,174)
B(2,54,5,174)
B(2,54,6,174)
B(2,54,7,174)
B(2,54,8,174)
B(2,55,-7,174)
B(2,55,-6,174)
B(2,55,-5,174)
B(2,55,-4,174)
B(2,55,-3,174)
B(2,55,-2,174)
B(2,55,-1,174)
B(2,55,0,174)
B(2,55,1,174)
B(2,55,2,174)
B(2,55,3,174)
B(2,55,4,174)
B(2,55,5,174)
B(2,55,6,174)
B(2,55,7,174)
B(2,55,8,174)
B(2,56,-7,174)
B(2,56,-6,174)
B(2,56,-5,174)
B(2,56,-4,174)
B(2,56,-3,174)
B(2,56,-2,174)
B(2,56,-1,174)
B(2,56,0,174)
B(2,56,1,174)
B(2,56,2,174)
B(2,56,3,174)
B(2,56,4,174)
B(2,56,5,174)
B(2,56,6,174)
B(2,56,7,174)
B(2,56,8,174)
B(2,57,-7,174)
B(2,57,-6,174)
B(2,57,-5,174)
B(2,57,-4,174)
B(2,57,-3,174)
B(2,57,-2,174)
B(2,57,-1,174)
B(2,57,0,174)
B(2,57,1,174)
B(2,57,2,174)
B(2,57,3,174)
B(2,57,4,174)
B(2,57,5,174)
B(2,57,6,174)
B(2,57,7,174)
B(2,57,8,174)
B(2,58,-7,174)
B(2,58,-6,174)
B(2,58,-5,174)
B(2,58,-4,174)
B(2,58,-3,174)
B(2,58,-2,174)
B(2,58,-1,174)
B(2,58,0,174)
B(2,58,1,174)
B(2,58,2,174)
B(2,58,3,174)
B(2,58,4,174)
B(2,58,5,174)
B(2,58,6,174)
B(2,58,7,174)
B(2,58,8,174)
B(2,59,-7,174)
B(2,59,-6,174)
B(2,59,-5,174)
B(2,59,-4,174)
B(2,59,-3,174)
B(2,59,-2,174)
B(2,59,-1,174)
B(2,59,0,174)
B(2,59,1,174)
B(2,59,2,174)
B(2,59,3,174)
B(2,59,4,174)
B(2,59,5,174)
B(2,59,6,174)
B(2,59,7,174)
B(2,59,8,174)
B(2,60,-7,174)
B(2,60,-6,174)
B(2,60,-5,174)
B(2,60,-4,174)
B(2,60,-3,174)
B(2,60,-2,174)
B(2,60,-1,174)
B(2,60,0,174)
B(2,60,1,174)
B(2,60,2,174)
B(2,60,3,174)
B(2,60,4,174)
B(2,60,5,174)
B(2,60,6,174)
B(2,60,7,174)
B(2,60,8,174)
B(2,61,-7,174)
B(2,61,-6,174)
B(2,61,-5,174)
B(2,61,-4,174)
B(2,61,-3,174)
B(2,61,-2,174)
B(2,61,-1,174)
B(2,61,0,174)
B(2,61,1,174)
B(2,61,2,174)
B(2,61,3,174)
B(2,61,4,174)
B(2,61,5,174)
B(2,61,6,174)
B(2,61,7,174)
B(2,61,8,174)
B(2,62,-7,174)
B(2,62,-6,174)
B(2,62,-5,174)
B(2,62,-4,174)
B(2,62,-3,174)
B(2,62,-2,174)
B(2,62,-1,174)
B(2,62,0,174)
B(2,62,1,174)
B(2,62,2,174)
B(2,62,3,174)
B(2,62,4,174)
B(2,62,5,174)
B(2,62,6,174)
B(2,62,7,174)
B(2,62,8,174)
B(2,63,-7,174)
B(2,63,-6,174)
B(2,63,-5,174)
B(2,63,-4,174)
B(2,63,-3,174)
B(2,63,-2,174)
B(2,63,-1,174)
B(2,63,0,174)
B(2,63,1,174)
B(2,63,2,174)
B(2,63,3,174)
B(2,63,4,174)
B(2,63,5,174)
B(2,63,6,174)
B(2,63,7,174)
B(2,64,-7,174)
B(2,64,-6,174)
B(2,64,-5,174)
B(2,64,-4,174)
B(2,64,-3,174)
B(2,64,-2,174)
B(2,64,-1,174)
B(2,64,0,174)
B(2,64,1,174)
B(2,64,2,174)
B(2,64,3,174)
B(2,64,4,174)
B(2,64,5,174)
B(2,64,6,174)
B(2,65,-7,174)
B(2,65,-6,174)
B(2,65,-5,174)
B(2,65,-4,174)
B(2,65,-3,174)
B(2,65,-2,174)
B(2,65,-1,174)
B(2,65,0,174)
B(2,65,1,174)
B(2,65,2,174)
B(2,65,3,174)
B(2,65,4,174)
B(2,65,5,174)
B(2,65,6,174)
B(2,66,-1,174)
B(2,66,0,174)
B(2,66,1,174)
B(2,66,2,174)
B(2,66,3,174)
B(2,66,4,174)
B(2,67,1,174)
B(2,67,2,174)
B(2,67,3,174)
B(3,16,-7,174)
B(3,16,-1,174)
B(3,16,0,174)
B(3,16,1,174)
B(3,17,-7,174)
B(3,17,-6,174)
B(3,17,-5,174)
B(3,17,-4,174)
B(3,17,-3,174)
B(3,17,-2,174)
B(3,17,-1,174)
B(3,17,0,174)
B(3,17,1,174)
B(3,17,2,174)
B(3,18,-7,174)
B(3,18,-6,174)
B(3,18,-5,174)
B(3,18,-4,174)
B(3,18,-3,174)
B(3,18,-2,174)
B(3,18,-1,174)
B(3,18,0,174)
B(3,18,1,174)
B(3,18,2,174)
B(3,19,-7,174)
B(3,19,-6,174)
B(3,19,-5,174)
B(3,19,-4,174)
B(3,19,-3,174)
B(3,19,-2,174)
B(3,19,-1,174)
B(3,19,0,174)
B(3,19,1,174)
B(3,19,2,174)
B(3,19,3,174)
B(3,19,4,174)
B(3,20,-7,174)
B(3,20,-6,174)
B(3,20,-5,174)
B(3,20,-4,174)
B(3,20,-3,174)
B(3,20,-2,174)
B(3,20,-1,174)
B(3,20,0,174)
B(3,20,1,174)
B(3,20,2,174)
B(3,20,3,174)
B(3,20,4,174)
B(3,20,5,174)
B(3,21,-7,174)
B(3,21,-6,174)
B(3,21,-5,174)
B(3,21,-4,174)
B(3,21,-3,174)
B(3,21,-2,174)
B(3,21,-1,174)
B(3,21,0,174)
B(3,21,1,174)
B(3,21,2,174)
B(3,21,3,174)
B(3,21,4,174)
B(3,21,5,174)
B(3,22,-7,174)
B(3,22,-6,174)
B(3,22,-5,174)
B(3,22,-4,174)
B(3,22,-3,174)
B(3,22,-2,174)
B(3,22,-1,174)
B(3,22,0,174)
B(3,22,1,174)
B(3,22,2,174)
B(3,22,3,174)
B(3,22,4,174)
B(3,22,5,174)
B(3,22,6,174)
B(3,23,-7,174)
B(3,23,-6,174)
B(3,23,-5,174)
B(3,23,-4,174)
B(3,23,-3,174)
B(3,23,-2,174)
B(3,23,-1,174)
B(3,23,0,174)
B(3,23,1,174)
B(3,23,2,174)
B(3,23,3,174)
B(3,23,4,174)
B(3,23,5,174)
B(3,23,6,174)
B(3,23,7,174)
B(3,24,-7,174)
B(3,24,-6,174)
B(3,24,-5,174)
B(3,24,-4,174)
B(3,24,-3,174)
B(3,24,-2,174)
B(3,24,-1,174)
B(3,24,0,174)
B(3,24,1,174)
B(3,24,2,174)
B(3,24,3,174)
B(3,24,4,174)
B(3,24,5,174)
B(3,24,6,174)
B(3,24,7,174)
B(3,24,8,174)
B(3,25,-7,174)
B(3,25,-6,174)
B(3,25,-5,174)
B(3,25,-4,174)
B(3,25,-3,174)
B(3,25,-2,174)
B(3,25,-1,174)
B(3,25,0,174)
B(3,25,1,174)
B(3,25,2,174)
B(3,25,3,174)
B(3,25,4,174)
B(3,25,5,174)
B(3,25,6,174)
B(3,25,7,174)
B(3,25,8,174)
B(3,26,-7,174)
B(3,26,-6,174)
B(3,26,-5,174)
B(3,26,-4,174)
B(3,26,-3,174)
B(3,26,-2,174)
B(3,26,-1,174)
B(3,26,0,174)
B(3,26,1,174)
B(3,26,2,174)
B(3,26,3,174)
B(3,26,4,174)
B(3,26,5,174)
B(3,26,6,174)
B(3,26,7,174)
B(3,26,8,174)
B(3,27,-7,174)
B(3,27,-6,174)
B(3,27,-5,174)
B(3,27,-4,174)
B(3,27,-3,174)
B(3,27,-2,174)
B(3,27,-1,174)
B(3,27,0,174)
B(3,27,1,174)
B(3,27,2,174)
B(3,27,3,174)
B(3,27,4,174)
B(3,27,5,174)
B(3,27,6,174)
B(3,27,7,174)
B(3,27,8,174)
B(3,28,-7,174)
B(3,28,-6,174)
B(3,28,-5,174)
B(3,28,-4,174)
B(3,28,-3,174)
B(3,28,-2,174)
B(3,28,-1,174)
B(3,28,0,174)
B(3,28,1,174)
B(3,28,2,174)
B(3,28,3,174)
B(3,28,4,174)
B(3,28,5,174)
B(3,28,6,174)
B(3,28,7,174)
B(3,28,8,174)
B(3,29,-7,174)
B(3,29,-6,174)
B(3,29,-5,174)
B(3,29,-4,174)
B(3,29,-3,174)
B(3,29,-2,174)
B(3,29,-1,174)
B(3,29,0,174)
B(3,29,1,174)
B(3,29,2,174)
B(3,29,3,174)
B(3,29,4,174)
B(3,29,5,174)
B(3,29,6,174)
B(3,29,7,174)
B(3,29,8,174)
B(3,30,-7,174)
B(3,30,-6,174)
B(3,30,-5,174)
B(3,30,-4,174)
B(3,30,-3,174)
B(3,30,-2,174)
B(3,30,-1,174)
B(3,30,0,174)
B(3,30,1,174)
B(3,30,2,174)
B(3,30,3,174)
B(3,30,4,174)
B(3,30,5,174)
B(3,30,6,174)
B(3,30,7,174)
B(3,30,8,174)
B(3,31,-7,174)
B(3,31,-6,174)
B(3,31,-5,174)
B(3,31,-4,174)
B(3,31,-3,174)
B(3,31,-2,174)
B(3,31,-1,174)
B(3,31,0,174)
B(3,31,1,174)
B(3,31,2,174)
B(3,31,3,174)
B(3,31,4,174)
B(3,31,5,174)
B(3,31,6,174)
B(3,31,7,174)
B(3,31,8,174)
B(3,32,-7,174)
B(3,32,-6,174)
B(3,32,-5,174)
B(3,32,-4,174)
B(3,32,-3,174)
B(3,32,-2,174)
B(3,32,-1,174)
B(3,32,0,174)
B(3,32,1,174)
B(3,32,2,174)
B(3,32,3,174)
B(3,32,4,174)
B(3,32,5,174)
B(3,32,6,174)
B(3,32,7,174)
B(3,32,8,174)
B(3,33,-7,174)
B(3,33,-6,174)
B(3,33,-5,174)
B(3,33,-4,174)
B(3,33,-3,174)
B(3,33,-2,174)
B(3,33,-1,174)
B(3,33,0,174)
B(3,33,1,174)
B(3,33,2,174)
B(3,33,3,174)
B(3,33,4,174)
B(3,33,5,174)
B(3,33,6,174)
B(3,33,7,174)
B(3,33,8,174)
B(3,34,-7,174)
B(3,34,-6,174)
B(3,34,-5,174)
B(3,34,-4,174)
B(3,34,-3,174)
B(3,34,-2,174)
B(3,34,-1,174)
B(3,34,0,174)
B(3,34,1,174)
B(3,34,2,174)
B(3,34,3,174)
B(3,34,4,174)
B(3,34,5,174)
B(3,34,6,174)
B(3,34,7,174)
B(3,34,8,174)
B(3,35,-7,174)
B(3,35,-6,174)
B(3,35,-5,174)
B(3,35,-4,174)
B(3,35,-3,174)
B(3,35,-2,174)
B(3,35,-1,174)
B(3,35,0,174)
B(3,35,1,174)
B(3,35,2,174)
B(3,35,3,174)
B(3,35,4,174)
B(3,35,5,174)
B(3,35,6,174)
B(3,35,7,174)
B(3,35,8,174)
B(3,36,-7,174)
B(3,36,-6,174)
B(3,36,-5,174)
B(3,36,-4,174)
B(3,36,-3,174)
B(3,36,-2,174)
B(3,36,-1,174)
B(3,36,0,174)
B(3,36,1,174)
B(3,36,2,174)
B(3,36,3,174)
B(3,36,4,174)
B(3,36,5,174)
B(3,36,6,174)
B(3,36,7,174)
B(3,36,8,174)
B(3,37,-7,174)
B(3,37,-6,174)
B(3,37,-5,174)
B(3,37,-4,174)
B(3,37,-3,174)
B(3,37,-2,174)
B(3,37,-1,174)
B(3,37,0,174)
B(3,37,1,174)
B(3,37,2,174)
B(3,37,3,174)
B(3,37,4,174)
B(3,37,5,174)
B(3,37,6,174)
B(3,37,7,174)
B(3,37,8,174)
B(3,38,-7,174)
B(3,38,-6,174)
B(3,38,-5,174)
B(3,38,-4,174)
B(3,38,-3,174)
B(3,38,-2,174)
B(3,38,-1,174)
B(3,38,0,174)
B(3,38,1,174)
B(3,38,2,174)
B(3,38,3,174)
B(3,38,4,174)
B(3,38,5,174)
B(3,38,6,174)
B(3,38,7,174)
B(3,38,8,174)
B(3,39,-7,174)
B(3,39,-6,174)
B(3,39,-5,174)
B(3,39,-4,174)
B(3,39,-3,174)
B(3,39,-2,174)
B(3,39,-1,174)
B(3,39,0,174)
B(3,39,1,174)
B(3,39,2,174)
B(3,39,3,174)
B(3,39,4,174)
B(3,39,5,174)
B(3,39,6,174)
B(3,39,7,174)
B(3,39,8,174)
B(3,40,-7,174)
B(3,40,-6,174)
B(3,40,-5,174)
B(3,40,-4,174)
B(3,40,-3,174)
B(3,40,-2,174)
B(3,40,-1,174)
B(3,40,0,174)
B(3,40,1,174)
B(3,40,2,174)
B(3,40,3,174)
B(3,40,4,174)
B(3,40,5,174)
B(3,40,6,174)
B(3,40,7,174)
B(3,40,8,174)
B(3,41,-7,174)
B(3,41,-6,174)
B(3,41,-5,174)
B(3,41,-4,174)
B(3,41,-3,174)
B(3,41,-2,174)
B(3,41,-1,174)
B(3,41,0,174)
B(3,41,1,174)
B(3,41,2,174)
B(3,41,3,174)
B(3,41,4,174)
B(3,41,5,174)
B(3,41,6,174)
B(3,41,7,174)
B(3,41,8,174)
B(3,42,-7,174)
B(3,42,-6,174)
B(3,42,-5,174)
B(3,42,-4,174)
B(3,42,-3,174)
B(3,42,-2,174)
B(3,42,-1,174)
B(3,42,0,174)
B(3,42,1,174)
B(3,42,2,174)
B(3,42,3,174)
B(3,42,4,174)
B(3,42,5,174)
B(3,42,6,174)
B(3,42,7,174)
B(3,42,8,174)
B(3,43,-7,174)
B(3,43,-6,174)
B(3,43,-5,174)
B(3,43,-4,174)
B(3,43,-3,174)
B(3,43,-2,174)
B(3,43,-1,174)
B(3,43,0,174)
B(3,43,1,174)
B(3,43,2,174)
B(3,43,3,174)
B(3,43,4,174)
B(3,43,5,174)
B(3,43,6,174)
B(3,43,7,174)
B(3,43,8,174)
B(3,44,-7,174)
B(3,44,-6,174)
B(3,44,-5,174)
B(3,44,-4,174)
B(3,44,-3,174)
B(3,44,-2,174)
B(3,44,-1,174)
B(3,44,0,174)
B(3,44,1,174)
B(3,44,2,174)
B(3,44,3,174)
B(3,44,4,174)
B(3,44,5,174)
B(3,44,6,174)
B(3,44,7,174)
B(3,44,8,174)
B(3,45,-7,174)
B(3,45,-6,174)
B(3,45,-5,174)
B(3,45,-4,174)
B(3,45,-3,174)
B(3,45,-2,174)
B(3,45,-1,174)
B(3,45,0,174)
B(3,45,1,174)
B(3,45,2,174)
B(3,45,3,174)
B(3,45,4,174)
B(3,45,5,174)
B(3,45,6,174)
B(3,45,7,174)
B(3,45,8,174)
B(3,46,-7,174)
B(3,46,-6,174)
B(3,46,-5,174)
B(3,46,-4,174)
B(3,46,-3,174)
B(3,46,-2,174)
B(3,46,-1,174)
B(3,46,0,174)
B(3,46,1,174)
B(3,46,2,174)
B(3,46,3,174)
B(3,46,4,174)
B(3,46,5,174)
B(3,46,6,174)
B(3,46,7,174)
B(3,46,8,174)
B(3,47,-7,174)
B(3,47,-6,174)
B(3,47,-5,174)
B(3,47,-4,174)
B(3,47,-3,174)
B(3,47,-2,174)
B(3,47,-1,174)
B(3,47,0,174)
B(3,47,1,174)
B(3,47,2,174)
B(3,47,3,174)
B(3,47,4,174)
B(3,47,5,174)
B(3,47,6,174)
B(3,47,7,174)
B(3,47,8,174)
B(3,48,-7,174)
B(3,48,-6,174)
B(3,48,-5,174)
B(3,48,-4,174)
B(3,48,-3,174)
B(3,48,-2,174)
B(3,48,-1,174)
B(3,48,0,174)
B(3,48,1,174)
B(3,48,2,174)
B(3,48,3,174)
B(3,48,4,174)
B(3,48,5,174)
B(3,48,6,174)
B(3,48,7,174)
B(3,48,8,174)
B(3,49,-7,174)
B(3,49,-6,174)
B(3,49,-5,174)
B(3,49,-4,174)
B(3,49,-3,174)
B(3,49,-2,174)
B(3,49,-1,174)
B(3,49,0,174)
B(3,49,1,174)
B(3,49,2,174)
B(3,49,3,174)
B(3,49,4,174)
B(3,49,5,174)
B(3,49,6,174)
B(3,49,7,174)
B(3,49,8,174)
B(3,50,-7,174)
B(3,50,-6,174)
B(3,50,-5,174)
B(3,50,-4,174)
B(3,50,-3,174)
B(3,50,-2,174)
B(3,50,-1,174)
B(3,50,0,174)
B(3,50,1,174)
B(3,50,2,174)
B(3,50,3,174)
B(3,50,4,174)
B(3,50,5,174)
B(3,50,6,174)
B(3,50,7,174)
B(3,50,8,174)
B(3,51,-7,174)
B(3,51,-6,174)
B(3,51,-5,174)
B(3,51,-4,174)
B(3,51,-3,174)
B(3,51,-2,174)
B(3,51,-1,174)
B(3,51,0,174)
B(3,51,1,174)
B(3,51,2,174)
B(3,51,3,174)
B(3,51,4,174)
B(3,51,5,174)
B(3,51,6,174)
B(3,51,7,174)
B(3,51,8,174)
B(3,52,-7,174)
B(3,52,-6,174)
B(3,52,-5,174)
B(3,52,-4,174)
B(3,52,-3,174)
B(3,52,-2,174)
B(3,52,-1,174)
B(3,52,0,174)
B(3,52,1,174)
B(3,52,2,174)
B(3,52,3,174)
B(3,52,4,174)
B(3,52,5,174)
B(3,52,6,174)
B(3,52,7,174)
B(3,52,8,174)
B(3,53,-7,174)
B(3,53,-6,174)
B(3,53,-5,174)
B(3,53,-4,174)
B(3,53,-3,174)
B(3,53,-2,174)
B(3,53,-1,174)
B(3,53,0,174)
B(3,53,1,174)
B(3,53,2,174)
B(3,53,3,174)
B(3,53,4,174)
B(3,53,5,174)
B(3,53,6,174)
B(3,53,7,174)
B(3,53,8,174)
B(3,54,-7,174)
B(3,54,-6,174)
B(3,54,-5,174)
B(3,54,-4,174)
B(3,54,-3,174)
B(3,54,-2,174)
B(3,54,-1,174)
B(3,54,0,174)
B(3,54,1,174)
B(3,54,2,174)
B(3,54,3,174)
B(3,54,4,174)
B(3,54,5,174)
B(3,54,6,174)
B(3,54,7,174)
B(3,54,8,174)
B(3,55,-7,174)
B(3,55,-6,174)
B(3,55,-5,174)
B(3,55,-4,174)
B(3,55,-3,174)
B(3,55,-2,174)
B(3,55,-1,174)
B(3,55,0,174)
B(3,55,1,174)
B(3,55,2,174)
B(3,55,3,174)
B(3,55,4,174)
B(3,55,5,174)
B(3,55,6,174)
B(3,55,7,174)
B(3,55,8,174)
B(3,56,-7,174)
B(3,56,-6,174)
B(3,56,-5,174)
B(3,56,-4,174)
B(3,56,-3,174)
B(3,56,-2,174)
B(3,56,-1,174)
B(3,56,0,174)
B(3,56,1,174)
B(3,56,2,174)
B(3,56,3,174)
B(3,56,4,174)
B(3,56,5,174)
B(3,56,6,174)
B(3,56,7,174)
B(3,56,8,174)
B(3,57,-7,174)
B(3,57,-6,174)
B(3,57,-5,174)
B(3,57,-4,174)
B(3,57,-3,174)
B(3,57,-2,174)
B(3,57,-1,174)
B(3,57,0,174)
B(3,57,1,174)
B(3,57,2,174)
B(3,57,3,174)
B(3,57,4,174)
B(3,57,5,174)
B(3,57,6,174)
B(3,57,7,174)
B(3,57,8,174)
B(3,58,-7,174)
B(3,58,-6,174)
B(3,58,-5,174)
B(3,58,-4,174)
B(3,58,-3,174)
B(3,58,-2,174)
B(3,58,-1,174)
B(3,58,0,174)
B(3,58,1,174)
B(3,58,2,174)
B(3,58,3,174)
B(3,58,4,174)
B(3,58,5,174)
B(3,58,6,174)
B(3,58,7,174)
B(3,58,8,174)
B(3,59,-7,174)
B(3,59,-6,174)
B(3,59,-5,174)
B(3,59,-4,174)
B(3,59,-3,174)
B(3,59,-2,174)
B(3,59,-1,174)
B(3,59,0,174)
B(3,59,1,174)
B(3,59,2,174)
B(3,59,3,174)
B(3,59,4,174)
B(3,59,5,174)
B(3,59,6,174)
B(3,59,7,174)
B(3,59,8,174)
B(3,60,-7,174)
B(3,60,-6,174)
B(3,60,-5,174)
B(3,60,-4,174)
B(3,60,-3,174)
B(3,60,-2,174)
B(3,60,-1,174)
B(3,60,0,174)
B(3,60,1,174)
B(3,60,2,174)
B(3,60,3,174)
B(3,60,4,174)
B(3,60,5,174)
B(3,60,6,174)
B(3,60,7,174)
B(3,60,8,174)
B(3,61,-7,174)
B(3,61,-6,174)
B(3,61,-5,174)
B(3,61,-4,174)
B(3,61,-3,174)
B(3,61,-2,174)
B(3,61,-1,174)
B(3,61,0,174)
B(3,61,1,174)
B(3,61,2,174)
B(3,61,3,174)
B(3,61,4,174)
B(3,61,5,174)
B(3,61,6,174)
B(3,61,7,174)
B(3,61,8,174)
B(3,62,-7,174)
B(3,62,-6,174)
B(3,62,-5,174)
B(3,62,-4,174)
B(3,62,-3,174)
B(3,62,-2,174)
B(3,62,-1,174)
B(3,62,0,174)
B(3,62,1,174)
B(3,62,2,174)
B(3,62,3,174)
B(3,62,4,174)
B(3,62,5,174)
B(3,62,6,174)
B(3,62,7,174)
B(3,62,8,174)
B(3,63,-7,174)
B(3,63,-6,174)
B(3,63,-5,174)
B(3,63,-4,174)
B(3,63,-3,174)
B(3,63,-2,174)
B(3,63,-1,174)
B(3,63,0,174)
B(3,63,1,174)
B(3,63,2,174)
B(3,63,3,174)
B(3,63,4,174)
B(3,63,5,174)
B(3,63,6,174)
B(3,63,7,174)
B(3,64,-7,174)
B(3,64,-6,174)
B(3,64,-5,174)
B(3,64,-4,174)
B(3,64,-3,174)
B(3,64,-2,174)
B(3,64,-1,174)
B(3,64,0,174)
B(3,64,1,174)
B(3,64,2,174)
B(3,64,3,174)
B(3,64,4,174)
B(3,64,5,174)
B(3,64,6,174)
B(3,65,-7,174)
B(3,65,-1,174)
B(3,65,0,174)
B(3,65,1,174)
B(3,65,2,174)
B(3,65,3,174)
B(3,65,4,174)
B(3,65,5,174)
B(3,66,1,174)
B(3,66,2,174)
B(3,66,3,174)
B(4,16,0,174)
B(4,16,1,174)
B(4,17,-7,174)
B(4,17,-6,174)
B(4,17,-2,174)
B(4,17,-1,174)
B(4,17,0,174)
B(4,17,1,174)
B(4,18,-7,174)
B(4,18,-6,174)
B(4,18,-5,174)
B(4,18,-4,174)
B(4,18,-3,174)
B(4,18,-2,174)
B(4,18,-1,174)
B(4,18,0,174)
B(4,18,1,174)
B(4,18,2,174)
B(4,19,-7,174)
B(4,19,-6,174)
B(4,19,-5,174)
B(4,19,-4,174)
B(4,19,-3,174)
B(4,19,-2,174)
B(4,19,-1,174)
B(4,19,0,174)
B(4,19,1,174)
B(4,19,2,174)
B(4,19,3,174)
B(4,19,4,174)
B(4,20,-7,174)
B(4,20,-6,174)
B(4,20,-5,174)
B(4,20,-4,174)
B(4,20,-3,174)
B(4,20,-2,174)
B(4,20,-1,174)
B(4,20,0,174)
B(4,20,1,174)
B(4,20,2,174)
B(4,20,3,174)
B(4,20,4,174)
B(4,20,5,174)
B(4,21,-7,174)
B(4,21,-6,174)
B(4,21,-5,174)
B(4,21,-4,174)
B(4,21,-3,174)
